{"op":"mcm","clk":"1361167359","pt":1588396781303,"mc":[{"id":"1.170370565","marketDefinition":{"bspMarket":false,"turnInPlayEnabled":true,"persistenceEnabled":true,"marketBaseRate":5.0,"eventId":"29788457","eventTypeId":"2","numberOfWinners":1,"bettingType":"ODDS","marketType":"SET_BETTING","marketTime":"2020-05-02T16:00:00.000Z","suspendTime":"2020-05-02T16:00:00.000Z","bspReconciled":false,"complete":true,"inPlay":false,"crossMatching":false,"runnersVoidable":false,"numberOfActiveRunners":4,"betDelay":0,"status":"OPEN","runners":[{"status":"ACTIVE","sortPriority":1,"id":11269555,"name":"P Lorenzi 2-0"},{"status":"ACTIVE","sortPriority":2,"id":11269557,"name":"P Lorenzi 2-1"},{"status":"ACTIVE","sortPriority":3,"id":11340557,"name":"S Kirchheimer 2-0"},{"status":"ACTIVE","sortPriority":4,"id":11340560,"name":"S Kirchheimer 2-1"}],"regulators":["MR_INT"],"countryCode":"GB","discountAllowed":false,"timezone":"GMT","openDate":"2020-05-02T16:00:00.000Z","version":3237452932,"name":"Set Betting","eventName":"P Lorenzi v S Kirchheimer"},"rc":[],"con":true,"img":false}]}
{"op":"mcm","clk":"1361167360","pt":1588396781303,"mc":[{"id":"1.170370566","marketDefinition":{"bspMarket":false,"turnInPlayEnabled":true,"persistenceEnabled":true,"marketBaseRate":5.0,"eventId":"29788457","eventTypeId":"2","numberOfWinners":1,"bettingType":"ODDS","marketType":"SET_WINNER","marketTime":"2020-05-02T16:00:00.000Z","suspendTime":"2020-05-02T16:00:00.000Z","bspReconciled":false,"complete":true,"inPlay":false,"crossMatching":false,"runnersVoidable":false,"numberOfActiveRunners":2,"betDelay":0,"status":"OPEN","runners":[{"status":"ACTIVE","sortPriority":1,"id":8509691,"name":"P Lorenzi"},{"status":"ACTIVE","sortPriority":2,"id":9630572,"name":"S Kirchheimer"}],"regulators":["MR_INT"],"countryCode":"GB","discountAllowed":false,"timezone":"GMT","openDate":"2020-05-02T16:00:00.000Z","version":3237452928,"name":"Set 1 Winner","eventName":"P Lorenzi v S Kirchheimer"},"rc":[],"con":true,"img":false}]}
{"op":"mcm","clk":"1361167361","pt":1588396781303,"mc":[{"id":"1.170370567","marketDefinition":{"bspMarket":false,"turnInPlayEnabled":true,"persistenceEnabled":true,"marketBaseRate":5.0,"eventId":"29788457","eventTypeId":"2","numberOfWinners":1,"bettingType":"ODDS","marketType":"SET_WINNER","marketTime":"2020-05-02T16:00:00.000Z","suspendTime":"2020-05-02T16:00:00.000Z","bspReconciled":false,"complete":true,"inPlay":false,"crossMatching":false,"runnersVoidable":false,"numberOfActiveRunners":2,"betDelay":0,"status":"OPEN","runners":[{"status":"ACTIVE","sortPriority":1,"id":8509691,"name":"P Lorenzi"},{"status":"ACTIVE","sortPriority":2,"id":9630572,"name":"S Kirchheimer"}],"regulators":["MR_INT"],"countryCode":"GB","discountAllowed":false,"timezone":"GMT","openDate":"2020-05-02T16:00:00.000Z","version":3237452930,"name":"Set 2 Winner","eventName":"P Lorenzi v S Kirchheimer"},"rc":[],"con":true,"img":false}]}
{"op":"mcm","clk":"1361167362","pt":1588396781303,"mc":[{"id":"1.170370564","marketDefinition":{"bspMarket":false,"turnInPlayEnabled":true,"persistenceEnabled":true,"marketBaseRate":5.0,"eventId":"29788457","eventTypeId":"2","numberOfWinners":1,"bettingType":"ODDS","marketType":"MATCH_ODDS","marketTime":"2020-05-02T16:00:00.000Z","suspendTime":"2020-05-02T16:00:00.000Z","bspReconciled":false,"complete":true,"inPlay":false,"crossMatching":false,"runnersVoidable":false,"numberOfActiveRunners":2,"betDelay":0,"status":"OPEN","runners":[{"status":"ACTIVE","sortPriority":1,"id":8509691,"name":"P Lorenzi"},{"status":"ACTIVE","sortPriority":2,"id":9630572,"name":"S Kirchheimer"}],"regulators":["MR_INT"],"countryCode":"GB","discountAllowed":false,"timezone":"GMT","openDate":"2020-05-02T16:00:00.000Z","version":3237452927,"name":"Match Odds","eventName":"P Lorenzi v S Kirchheimer"},"rc":[],"con":true,"img":false}]}
{"op":"mcm","clk":"1361167458","pt":1588396784305,"mc":[{"id":"1.170370564","marketDefinition":{"bspMarket":false,"turnInPlayEnabled":true,"persistenceEnabled":true,"marketBaseRate":5.0,"eventId":"29788457","eventTypeId":"2","numberOfWinners":1,"bettingType":"ODDS","marketType":"MATCH_ODDS","marketTime":"2020-05-02T16:00:00.000Z","suspendTime":"2020-05-02T16:00:00.000Z","bspReconciled":false,"complete":true,"inPlay":false,"crossMatching":false,"runnersVoidable":false,"numberOfActiveRunners":2,"betDelay":0,"status":"OPEN","runners":[{"status":"ACTIVE","sortPriority":1,"id":8509691,"name":"P Lorenzi"},{"status":"ACTIVE","sortPriority":2,"id":9630572,"name":"S Kirchheimer"}],"regulators":["MR_INT"],"countryCode":"GB","discountAllowed":true,"timezone":"GMT","openDate":"2020-05-02T16:00:00.000Z","version":3237452927,"name":"Match Odds","eventName":"P Lorenzi v S Kirchheimer"},"rc":[],"con":true,"img":false}]}
{"op":"mcm","clk":"1361167459","pt":1588396784305,"mc":[{"id":"1.170370566","marketDefinition":{"bspMarket":false,"turnInPlayEnabled":true,"persistenceEnabled":true,"marketBaseRate":5.0,"eventId":"29788457","eventTypeId":"2","numberOfWinners":1,"bettingType":"ODDS","marketType":"SET_WINNER","marketTime":"2020-05-02T16:00:00.000Z","suspendTime":"2020-05-02T16:00:00.000Z","bspReconciled":false,"complete":true,"inPlay":false,"crossMatching":false,"runnersVoidable":false,"numberOfActiveRunners":2,"betDelay":0,"status":"OPEN","runners":[{"status":"ACTIVE","sortPriority":1,"id":8509691,"name":"P Lorenzi"},{"status":"ACTIVE","sortPriority":2,"id":9630572,"name":"S Kirchheimer"}],"regulators":["MR_INT"],"countryCode":"GB","discountAllowed":true,"timezone":"GMT","openDate":"2020-05-02T16:00:00.000Z","version":3237452928,"name":"Set 1 Winner","eventName":"P Lorenzi v S Kirchheimer"},"rc":[],"con":true,"img":false}]}
{"op":"mcm","clk":"1361167460","pt":1588396784305,"mc":[{"id":"1.170370567","marketDefinition":{"bspMarket":false,"turnInPlayEnabled":true,"persistenceEnabled":true,"marketBaseRate":5.0,"eventId":"29788457","eventTypeId":"2","numberOfWinners":1,"bettingType":"ODDS","marketType":"SET_WINNER","marketTime":"2020-05-02T16:00:00.000Z","suspendTime":"2020-05-02T16:00:00.000Z","bspReconciled":false,"complete":true,"inPlay":false,"crossMatching":false,"runnersVoidable":false,"numberOfActiveRunners":2,"betDelay":0,"status":"OPEN","runners":[{"status":"ACTIVE","sortPriority":1,"id":8509691,"name":"P Lorenzi"},{"status":"ACTIVE","sortPriority":2,"id":9630572,"name":"S Kirchheimer"}],"regulators":["MR_INT"],"countryCode":"GB","discountAllowed":true,"timezone":"GMT","openDate":"2020-05-02T16:00:00.000Z","version":3237452930,"name":"Set 2 Winner","eventName":"P Lorenzi v S Kirchheimer"},"rc":[],"con":true,"img":false}]}
{"op":"mcm","clk":"1361167461","pt":1588396784305,"mc":[{"id":"1.170370565","marketDefinition":{"bspMarket":false,"turnInPlayEnabled":true,"persistenceEnabled":true,"marketBaseRate":5.0,"eventId":"29788457","eventTypeId":"2","numberOfWinners":1,"bettingType":"ODDS","marketType":"SET_BETTING","marketTime":"2020-05-02T16:00:00.000Z","suspendTime":"2020-05-02T16:00:00.000Z","bspReconciled":false,"complete":true,"inPlay":false,"crossMatching":false,"runnersVoidable":false,"numberOfActiveRunners":4,"betDelay":0,"status":"OPEN","runners":[{"status":"ACTIVE","sortPriority":1,"id":11269555,"name":"P Lorenzi 2-0"},{"status":"ACTIVE","sortPriority":2,"id":11269557,"name":"P Lorenzi 2-1"},{"status":"ACTIVE","sortPriority":3,"id":11340557,"name":"S Kirchheimer 2-0"},{"status":"ACTIVE","sortPriority":4,"id":11340560,"name":"S Kirchheimer 2-1"}],"regulators":["MR_INT"],"countryCode":"GB","discountAllowed":true,"timezone":"GMT","openDate":"2020-05-02T16:00:00.000Z","version":3237452932,"name":"Set Betting","eventName":"P Lorenzi v S Kirchheimer"},"rc":[],"con":true,"img":false}]}
{"op":"mcm","clk":"1361184463","pt":1588397321555,"mc":[{"id":"1.170370564","rc":[{"atb":[[1.01,319.94]],"id":9630572}],"con":true,"img":false}]}
{"op":"mcm","clk":"1361184470","pt":1588397321761,"mc":[{"id":"1.170370564","rc":[{"atb":[[1.01,319.94]],"id":8509691}],"con":true,"img":false}]}
{"op":"mcm","clk":"1361190647","pt":1588397499833,"mc":[{"id":"1.170370564","rc":[{"atl":[[990,1.59]],"id":8509691}],"con":true,"img":false}]}
{"op":"mcm","clk":"1361190659","pt":1588397500144,"mc":[{"id":"1.170370564","rc":[{"atl":[[990,1.59]],"id":9630572}],"con":true,"img":false}]}
{"op":"mcm","clk":"1361193618","pt":1588397601249,"mc":[{"id":"1.170370564","rc":[{"atb":[[3.2,13.56]],"id":9630572},{"atb":[[1.3,99.45]],"id":8509691}],"con":true,"img":false}]}
{"op":"mcm","clk":"1361194121","pt":1588397618362,"mc":[{"id":"1.170370564","marketDefinition":{"bspMarket":false,"turnInPlayEnabled":true,"persistenceEnabled":true,"marketBaseRate":5.0,"eventId":"29788457","eventTypeId":"2","numberOfWinners":1,"bettingType":"ODDS","marketType":"MATCH_ODDS","marketTime":"2020-05-02T16:00:00.000Z","suspendTime":"2020-05-02T16:00:00.000Z","bspReconciled":false,"complete":true,"inPlay":false,"crossMatching":true,"runnersVoidable":false,"numberOfActiveRunners":2,"betDelay":0,"status":"OPEN","runners":[{"status":"ACTIVE","sortPriority":1,"id":8509691,"name":"P Lorenzi"},{"status":"ACTIVE","sortPriority":2,"id":9630572,"name":"S Kirchheimer"}],"regulators":["MR_INT"],"countryCode":"GB","discountAllowed":true,"timezone":"GMT","openDate":"2020-05-02T16:00:00.000Z","version":3237452927,"name":"Match Odds","eventName":"P Lorenzi v S Kirchheimer"},"rc":[],"con":true,"img":false}]}
{"op":"mcm","clk":"1361196526","pt":1588397699121,"mc":[{"id":"1.170370565","rc":[{"atb":[[6,10]],"id":11340557},{"atb":[[6,10]],"id":11340560},{"atb":[[2,24.93]],"id":11269555},{"atb":[[3.3,10.84]],"id":11269557}],"con":true,"img":false},{"id":"1.170370566","rc":[{"atb":[[2.62,15.39]],"id":9630572},{"atb":[[1.44,56.67]],"id":8509691}],"con":true,"img":false},{"id":"1.170370567","rc":[{"atb":[[2.74,14.33]],"id":9630572},{"atb":[[1.4,62.34]],"id":8509691}],"con":true,"img":false}]}
{"op":"mcm","clk":"1361196809","pt":1588397708470,"mc":[{"id":"1.170370567","marketDefinition":{"bspMarket":false,"turnInPlayEnabled":true,"persistenceEnabled":true,"marketBaseRate":5.0,"eventId":"29788457","eventTypeId":"2","numberOfWinners":1,"bettingType":"ODDS","marketType":"SET_WINNER","marketTime":"2020-05-02T16:00:00.000Z","suspendTime":"2020-05-02T16:00:00.000Z","bspReconciled":false,"complete":true,"inPlay":false,"crossMatching":true,"runnersVoidable":false,"numberOfActiveRunners":2,"betDelay":0,"status":"OPEN","runners":[{"status":"ACTIVE","sortPriority":1,"id":8509691,"name":"P Lorenzi"},{"status":"ACTIVE","sortPriority":2,"id":9630572,"name":"S Kirchheimer"}],"regulators":["MR_INT"],"countryCode":"GB","discountAllowed":true,"timezone":"GMT","openDate":"2020-05-02T16:00:00.000Z","version":3237452930,"name":"Set 2 Winner","eventName":"P Lorenzi v S Kirchheimer"},"rc":[],"con":true,"img":false}]}
{"op":"mcm","clk":"1361196810","pt":1588397708470,"mc":[{"id":"1.170370566","marketDefinition":{"bspMarket":false,"turnInPlayEnabled":true,"persistenceEnabled":true,"marketBaseRate":5.0,"eventId":"29788457","eventTypeId":"2","numberOfWinners":1,"bettingType":"ODDS","marketType":"SET_WINNER","marketTime":"2020-05-02T16:00:00.000Z","suspendTime":"2020-05-02T16:00:00.000Z","bspReconciled":false,"complete":true,"inPlay":false,"crossMatching":true,"runnersVoidable":false,"numberOfActiveRunners":2,"betDelay":0,"status":"OPEN","runners":[{"status":"ACTIVE","sortPriority":1,"id":8509691,"name":"P Lorenzi"},{"status":"ACTIVE","sortPriority":2,"id":9630572,"name":"S Kirchheimer"}],"regulators":["MR_INT"],"countryCode":"GB","discountAllowed":true,"timezone":"GMT","openDate":"2020-05-02T16:00:00.000Z","version":3237452928,"name":"Set 1 Winner","eventName":"P Lorenzi v S Kirchheimer"},"rc":[],"con":true,"img":false}]}
{"op":"mcm","clk":"1361196811","pt":1588397708470,"mc":[{"id":"1.170370565","marketDefinition":{"bspMarket":false,"turnInPlayEnabled":true,"persistenceEnabled":true,"marketBaseRate":5.0,"eventId":"29788457","eventTypeId":"2","numberOfWinners":1,"bettingType":"ODDS","marketType":"SET_BETTING","marketTime":"2020-05-02T16:00:00.000Z","suspendTime":"2020-05-02T16:00:00.000Z","bspReconciled":false,"complete":true,"inPlay":false,"crossMatching":true,"runnersVoidable":false,"numberOfActiveRunners":4,"betDelay":0,"status":"OPEN","runners":[{"status":"ACTIVE","sortPriority":1,"id":11269555,"name":"P Lorenzi 2-0"},{"status":"ACTIVE","sortPriority":2,"id":11269557,"name":"P Lorenzi 2-1"},{"status":"ACTIVE","sortPriority":3,"id":11340557,"name":"S Kirchheimer 2-0"},{"status":"ACTIVE","sortPriority":4,"id":11340560,"name":"S Kirchheimer 2-1"}],"regulators":["MR_INT"],"countryCode":"GB","discountAllowed":true,"timezone":"GMT","openDate":"2020-05-02T16:00:00.000Z","version":3237452932,"name":"Set Betting","eventName":"P Lorenzi v S Kirchheimer"},"rc":[],"con":true,"img":false}]}
{"op":"mcm","clk":"1361236287","pt":1588399081087,"mc":[{"id":"1.170370564","rc":[{"atl":[[3,25.59]],"id":8509691}],"con":true,"img":false}]}
{"op":"mcm","clk":"1361236616","pt":1588399095819,"mc":[{"id":"1.170370565","rc":[{"atb":[[1.1,121.58]],"id":11340557},{"atb":[[1.1,121.58]],"id":11340560},{"atb":[[1.1,121.58]],"id":11269555},{"atb":[[1.1,121.58]],"id":11269557}],"con":true,"img":false}]}
{"op":"mcm","clk":"1361236884","pt":1588399106409,"mc":[{"id":"1.170370566","rc":[{"atb":[[1.1,121.58]],"id":9630572},{"atb":[[1.1,121.58]],"id":8509691}],"con":true,"img":false}]}
{"op":"mcm","clk":"1361237024","pt":1588399112923,"mc":[{"id":"1.170370567","rc":[{"atb":[[1.1,121.58]],"id":9630572},{"atb":[[1.1,121.58]],"id":8509691}],"con":true,"img":false}]}
{"op":"mcm","clk":"1361263931","pt":1588399935140,"mc":[{"id":"1.170370564","rc":[{"atl":[[990,3.79]],"id":9630572},{"atl":[[990,3.79]],"id":8509691}],"con":true,"img":false}]}
{"op":"mcm","clk":"1361263944","pt":1588399935444,"mc":[{"id":"1.170370565","rc":[{"atb":[[1.02,2]],"id":11340557},{"atb":[[1.02,2]],"id":11340560},{"atb":[[1.02,2]],"id":11269555},{"atb":[[1.02,2]],"id":11269557}],"con":true,"img":false}]}
{"op":"mcm","clk":"1361278781","pt":1588400366472,"mc":[{"id":"1.170370565","rc":[{"atb":[[7,10]],"id":11340557},{"atb":[[1.91,27.4]],"id":11269555}],"con":true,"img":false},{"id":"1.170370566","rc":[{"atb":[[2.74,14.33]],"id":9630572},{"atb":[[1.36,69.27]],"id":8509691}],"con":true,"img":false},{"id":"1.170370567","rc":[{"atb":[[2.88,13.26]],"id":9630572},{"atb":[[1.36,69.27]],"id":8509691}],"con":true,"img":false}]}
{"op":"mcm","clk":"1361278783","pt":1588400366572,"mc":[{"id":"1.170370565","rc":[{"atb":[[6,0]],"id":11340557},{"atb":[[2,0]],"id":11269555}],"con":true,"img":false},{"id":"1.170370566","rc":[{"atb":[[2.62,0]],"id":9630572},{"atb":[[1.44,0]],"id":8509691}],"con":true,"img":false},{"id":"1.170370567","rc":[{"atb":[[2.74,0]],"id":9630572},{"atb":[[1.4,0]],"id":8509691}],"con":true,"img":false}]}
{"op":"mcm","clk":"1361278819","pt":1588400368369,"mc":[{"id":"1.170370564","rc":[{"atb":[[3.5,11.93]],"id":9630572},{"atb":[[1.25,119.35]],"id":8509691}],"con":true,"img":false}]}
{"op":"mcm","clk":"1361278822","pt":1588400368480,"mc":[{"id":"1.170370564","rc":[{"atb":[[3.2,0]],"id":9630572},{"atb":[[1.3,0]],"id":8509691}],"con":true,"img":false}]}
{"op":"mcm","clk":"1361328610","pt":1588402434077,"mc":[{"id":"1.170370565","rc":[{"atb":[[1.91,28.73]],"id":11269555},{"atb":[[3.3,11.36]],"id":11269557}],"con":true,"img":false},{"id":"1.170370566","rc":[{"atb":[[2.74,29.35]],"id":9630572},{"atb":[[1.36,141.9]],"id":8509691}],"con":true,"img":false},{"id":"1.170370567","rc":[{"atb":[[2.88,27.16]],"id":9630572},{"atb":[[1.36,141.9]],"id":8509691}],"con":true,"img":false}]}
{"op":"mcm","clk":"1361328613","pt":1588402434179,"mc":[{"id":"1.170370566","rc":[{"atb":[[2.74,15.02]],"id":9630572},{"atb":[[1.36,72.63]],"id":8509691}],"con":true,"img":false},{"id":"1.170370567","rc":[{"atb":[[2.88,13.9]],"id":9630572},{"atb":[[1.36,72.63]],"id":8509691}],"con":true,"img":false}]}
{"op":"mcm","clk":"1361332590","pt":1588402551164,"mc":[{"id":"1.170370564","rc":[{"atb":[[1.02,159.97]],"id":9630572},{"atb":[[1.02,159.97]],"id":8509691}],"con":true,"img":false}]}
{"op":"mcm","clk":"1361333085","pt":1588402563752,"mc":[{"id":"1.170370564","rc":[{"atb":[[1.1,31.99]],"id":8509691},{"atl":[[1.9,3.19]],"id":8509691}],"con":true,"img":false}]}
{"op":"mcm","clk":"1361344333","pt":1588402816246,"mc":[{"id":"1.170370564","rc":[{"atb":[[1.22,118.38]],"id":8509691}],"con":true,"img":false}]}
{"op":"mcm","clk":"1361344341","pt":1588402816405,"mc":[{"id":"1.170370564","rc":[{"atb":[[2.86,50.39]],"id":9630572}],"con":true,"img":false}]}
{"op":"mcm","clk":"1361352927","pt":1588403024350,"mc":[{"id":"1.170370564","rc":[{"atl":[[4,2]],"id":8509691}],"con":true,"img":false}]}
{"op":"mcm","clk":"1361367575","pt":1588403439326,"mc":[{"id":"1.170370564","rc":[{"atb":[[1.26,6.71]],"id":8509691}],"con":true,"img":false}]}
{"op":"mcm","clk":"1361390286","pt":1588404048959,"mc":[{"id":"1.170370565","rc":[{"atb":[[6.4,10],[7,0]],"id":11340557}],"con":true,"img":false},{"id":"1.170370566","rc":[{"atb":[[2.88,13.9],[2.74,0]],"id":9630572}],"con":true,"img":false}]}
{"op":"mcm","clk":"1361392402","pt":1588404104052,"mc":[{"id":"1.170370564","rc":[{"atb":[[1.01,324.74]],"id":9630572},{"atb":[[1.01,324.74]],"id":8509691}],"con":true,"img":false}]}
{"op":"mcm","clk":"1361459375","pt":1588405754245,"mc":[{"id":"1.170370564","rc":[{"atl":[[4,5]],"id":8509691}],"con":true,"img":false}]}
{"op":"mcm","clk":"1361485352","pt":1588406426513,"mc":[{"id":"1.170370564","rc":[{"atb":[[2.86,0]],"id":9630572}],"con":true,"img":false}]}
{"op":"mcm","clk":"1361485360","pt":1588406426617,"mc":[{"id":"1.170370564","rc":[{"atb":[[2.9,50.39]],"id":9630572}],"con":true,"img":false}]}
{"op":"mcm","clk":"1361492998","pt":1588406628352,"mc":[{"id":"1.170370564","rc":[{"atb":[[2.9,0]],"id":9630572}],"con":true,"img":false}]}
{"op":"mcm","clk":"1361493003","pt":1588406628454,"mc":[{"id":"1.170370564","rc":[{"atb":[[2.86,50.39]],"id":9630572}],"con":true,"img":false}]}
{"op":"mcm","clk":"1361587580","pt":1588408807197,"mc":[{"id":"1.170370564","rc":[{"atb":[[1.01,326.52]],"id":9630572},{"atb":[[1.01,326.52]],"id":8509691}],"con":true,"img":false}]}
{"op":"mcm","clk":"1361587597","pt":1588408807511,"mc":[{"id":"1.170370564","rc":[{"atb":[[1.01,324.96]],"id":9630572},{"atb":[[1.01,324.96]],"id":8509691}],"con":true,"img":false}]}
{"op":"mcm","clk":"1361587610","pt":1588408807721,"mc":[{"id":"1.170370564","rc":[{"atb":[[1.01,324.74]],"id":9630572},{"atb":[[1.01,324.74]],"id":8509691}],"con":true,"img":false}]}
{"op":"mcm","clk":"1361587618","pt":1588408807820,"mc":[{"id":"1.170370564","rc":[{"atb":[[1.02,160.18]],"id":9630572},{"atb":[[1.02,160.18]],"id":8509691}],"con":true,"img":false}]}
{"op":"mcm","clk":"1361587693","pt":1588408809124,"mc":[{"id":"1.170370566","rc":[{"atb":[[1.01,1.77]],"id":9630572},{"atb":[[1.01,1.77]],"id":8509691}],"con":true,"img":false}]}
{"op":"mcm","clk":"1361587707","pt":1588408809381,"mc":[{"id":"1.170370566","rc":[{"atb":[[1.01,0.21]],"id":9630572},{"atb":[[1.01,0.21]],"id":8509691}],"con":true,"img":false}]}
{"op":"mcm","clk":"1361587723","pt":1588408809697,"mc":[{"id":"1.170370566","rc":[{"atb":[[1.01,0]],"id":9630572},{"atb":[[1.01,0]],"id":8509691}],"con":true,"img":false}]}
{"op":"mcm","clk":"1361587730","pt":1588408809796,"mc":[{"id":"1.170370566","rc":[{"atb":[[1.02,0.21]],"id":9630572},{"atb":[[1.02,0.21]],"id":8509691}],"con":true,"img":false}]}
{"op":"mcm","clk":"1361587793","pt":1588408811087,"mc":[{"id":"1.170370567","rc":[{"atb":[[1.01,1.77]],"id":9630572},{"atb":[[1.01,1.77]],"id":8509691}],"con":true,"img":false}]}
{"op":"mcm","clk":"1361587802","pt":1588408811299,"mc":[{"id":"1.170370567","rc":[{"atb":[[1.01,0.21]],"id":9630572},{"atb":[[1.01,0.21]],"id":8509691}],"con":true,"img":false}]}
{"op":"mcm","clk":"1361587819","pt":1588408811607,"mc":[{"id":"1.170370567","rc":[{"atb":[[1.01,0]],"id":9630572},{"atb":[[1.01,0]],"id":8509691}],"con":true,"img":false}]}
{"op":"mcm","clk":"1361587822","pt":1588408811706,"mc":[{"id":"1.170370567","rc":[{"atb":[[1.02,0.21]],"id":9630572},{"atb":[[1.02,0.21]],"id":8509691}],"con":true,"img":false}]}
{"op":"mcm","clk":"1361635127","pt":1588410032271,"mc":[{"id":"1.170370564","rc":[{"atb":[[2.86,0]],"id":9630572}],"con":true,"img":false}]}
{"op":"mcm","clk":"1361635134","pt":1588410032375,"mc":[{"id":"1.170370564","rc":[{"atb":[[3,50.39]],"id":9630572}],"con":true,"img":false}]}
{"op":"mcm","clk":"1361637297","pt":1588410074757,"mc":[{"id":"1.170370564","rc":[{"atb":[[3,0]],"id":9630572},{"atb":[[1.22,0]],"id":8509691}],"con":true,"img":false}]}
{"op":"mcm","clk":"1361637302","pt":1588410074861,"mc":[{"id":"1.170370564","rc":[{"atb":[[3.05,50.39]],"id":9630572},{"atb":[[1.21,118.38]],"id":8509691}],"con":true,"img":false}]}
{"op":"mcm","clk":"1361670445","pt":1588410913952,"mc":[{"id":"1.170370564","rc":[{"atb":[[3.05,0]],"id":9630572},{"atb":[[1.21,0]],"id":8509691}],"con":true,"img":false}]}
{"op":"mcm","clk":"1361670450","pt":1588410914052,"mc":[{"id":"1.170370564","rc":[{"atb":[[3,50.39]],"id":9630572},{"atb":[[1.22,118.38]],"id":8509691}],"con":true,"img":false}]}
{"op":"mcm","clk":"1361757754","pt":1588413085481,"mc":[{"id":"1.170370564","rc":[{"atb":[[1.01,1703.29]],"id":8509691}],"con":true,"img":false}]}
{"op":"mcm","clk":"1361757908","pt":1588413091380,"mc":[{"id":"1.170370564","rc":[{"atb":[[1.02,1538.73]],"id":8509691}],"con":true,"img":false}]}
{"op":"mcm","clk":"1361777070","pt":1588413602294,"mc":[{"id":"1.170370564","rc":[{"atb":[[3.5,29.83]],"id":9630572},{"atb":[[1.25,298.37]],"id":8509691}],"con":true,"img":false}]}
{"op":"mcm","clk":"1361777078","pt":1588413602395,"mc":[{"id":"1.170370564","rc":[{"atb":[[3.5,17.9]],"id":9630572},{"atb":[[1.25,179.02]],"id":8509691}],"con":true,"img":false}]}
{"op":"mcm","clk":"1361777198","pt":1588413604280,"mc":[{"id":"1.170370565","rc":[{"atb":[[1.91,43.1]],"id":11269555},{"atb":[[3.3,17.05]],"id":11269557}],"con":true,"img":false},{"id":"1.170370566","rc":[{"atb":[[2.88,20.86]],"id":9630572},{"atb":[[1.36,108.95]],"id":8509691}],"con":true,"img":false},{"id":"1.170370567","rc":[{"atb":[[2.88,20.86]],"id":9630572},{"atb":[[1.36,108.95]],"id":8509691}],"con":true,"img":false}]}
{"op":"mcm","clk":"1361779722","pt":1588413647928,"mc":[{"id":"1.170370564","rc":[{"atb":[[3,0]],"id":9630572},{"atb":[[1.22,0]],"id":8509691}],"con":true,"img":false}]}
{"op":"mcm","clk":"1361779728","pt":1588413648031,"mc":[{"id":"1.170370564","rc":[{"atb":[[3.05,50.39]],"id":9630572},{"atb":[[1.21,118.38]],"id":8509691}],"con":true,"img":false}]}
{"op":"mcm","clk":"1361811248","pt":1588414196540,"mc":[{"id":"1.170370564","rc":[{"atb":[[1.21,0]],"id":8509691}],"con":true,"img":false}]}
{"op":"mcm","clk":"1361811254","pt":1588414196650,"mc":[{"id":"1.170370564","rc":[{"atb":[[1.22,118.38]],"id":8509691}],"con":true,"img":false}]}
{"op":"mcm","clk":"1361816675","pt":1588414337003,"mc":[{"id":"1.170370565","rc":[{"atb":[[6.4,0],[7.4,10]],"id":11340557},{"atb":[[6.4,10],[6,0]],"id":11340560},{"atb":[[1.8,49.03],[1.91,0]],"id":11269555},{"atb":[[3.4,16.34],[3.3,0]],"id":11269557}],"con":true,"img":false},{"id":"1.170370566","rc":[{"atb":[[2.88,0],[3,19.61]],"id":9630572},{"atb":[[1.36,0],[1.33,118.86]],"id":8509691}],"con":true,"img":false},{"id":"1.170370567","rc":[{"atb":[[2.88,0],[3,19.61]],"id":9630572},{"atb":[[1.36,0],[1.33,118.86]],"id":8509691}],"con":true,"img":false}]}
{"op":"mcm","clk":"1361816742","pt":1588414338759,"mc":[{"id":"1.170370564","rc":[{"atb":[[3.5,0],[3.75,16.27]],"id":9630572},{"atb":[[1.25,0],[1.22,321.81]],"id":8509691}],"con":true,"img":false}]}
{"op":"mcm","clk":"1361832983","pt":1588414842162,"mc":[{"id":"1.170370564","rc":[{"atb":[[1.01,329.74]],"id":9630572},{"atb":[[1.01,1708.29]],"id":8509691}],"con":true,"img":false}]}
{"op":"mcm","clk":"1361834150","pt":1588414873005,"mc":[{"id":"1.170370564","rc":[{"atb":[[1.26,0]],"id":8509691}],"con":true,"img":false}]}
{"op":"mcm","clk":"1361834155","pt":1588414873107,"mc":[{"id":"1.170370564","rc":[{"atb":[[1.23,6.71]],"id":8509691}],"con":true,"img":false}]}
{"op":"mcm","clk":"1361849212","pt":1588415236936,"mc":[{"id":"1.170370564","rc":[{"atb":[[3.05,0]],"id":9630572}],"con":true,"img":false}]}
{"op":"mcm","clk":"1361849219","pt":1588415237038,"mc":[{"id":"1.170370564","rc":[{"atb":[[3,50.39]],"id":9630572}],"con":true,"img":false}]}
{"op":"mcm","clk":"1361861368","pt":1588415518705,"mc":[{"id":"1.170370564","rc":[{"atb":[[1.23,0]],"id":8509691}],"con":true,"img":false}]}
{"op":"mcm","clk":"1361886937","pt":1588416112157,"mc":[{"id":"1.170370564","rc":[{"atb":[[2.12,35.7]],"id":9630572}],"con":true,"img":false}]}
{"op":"mcm","clk":"1361886941","pt":1588416112261,"mc":[{"id":"1.170370564","rc":[{"atb":[[2.12,71.41]],"id":9630572}],"con":true,"img":false}]}
{"op":"mcm","clk":"1361886949","pt":1588416112464,"mc":[{"id":"1.170370564","rc":[{"atb":[[2.12,107.11]],"id":9630572}],"con":true,"img":false}]}
{"op":"mcm","clk":"1361887037","pt":1588416115559,"mc":[{"id":"1.170370564","rc":[{"atb":[[1.55,72.71]],"id":9630572}],"con":true,"img":false}]}
{"op":"mcm","clk":"1361887041","pt":1588416115664,"mc":[{"id":"1.170370564","rc":[{"atb":[[1.55,145.43]],"id":9630572}],"con":true,"img":false}]}
{"op":"mcm","clk":"1361887044","pt":1588416115762,"mc":[{"id":"1.170370564","rc":[{"atb":[[1.55,218.14]],"id":9630572}],"con":true,"img":false}]}
{"op":"mcm","clk":"1361887133","pt":1588416118295,"mc":[{"id":"1.170370564","rc":[{"atb":[[1.11,72.71]],"id":8509691}],"con":true,"img":false}]}
{"op":"mcm","clk":"1361887139","pt":1588416118401,"mc":[{"id":"1.170370564","rc":[{"atb":[[1.11,145.43]],"id":8509691}],"con":true,"img":false}]}
{"op":"mcm","clk":"1361887179","pt":1588416119629,"mc":[{"id":"1.170370564","rc":[{"atb":[[1.11,218.14]],"id":8509691}],"con":true,"img":false}]}
{"op":"mcm","clk":"1361887230","pt":1588416121121,"mc":[{"id":"1.170370564","rc":[{"atb":[[1.03,266.62]],"id":8509691}],"con":true,"img":false}]}
{"op":"mcm","clk":"1361887235","pt":1588416121223,"mc":[{"id":"1.170370564","rc":[{"atb":[[1.03,533.24]],"id":8509691}],"con":true,"img":false}]}
{"op":"mcm","clk":"1361887239","pt":1588416121329,"mc":[{"id":"1.170370564","rc":[{"atb":[[1.03,799.86]],"id":8509691}],"con":true,"img":false}]}
{"op":"mcm","clk":"1361887246","pt":1588416121533,"mc":[{"id":"1.170370564","rc":[{"atb":[[1.03,1066.48]],"id":8509691}],"con":true,"img":false}]}
{"op":"mcm","clk":"1361887251","pt":1588416121636,"mc":[{"id":"1.170370564","rc":[{"atb":[[1.03,1333.1]],"id":8509691}],"con":true,"img":false}]}
{"op":"mcm","clk":"1361887334","pt":1588416124039,"mc":[{"id":"1.170370564","rc":[{"atb":[[1.03,1599.72]],"id":8509691}],"con":true,"img":false}]}
{"op":"mcm","clk":"1361888213","pt":1588416147456,"mc":[{"id":"1.170370564","rc":[{"atb":[[1.23,7.16]],"id":8509691}],"con":true,"img":false}]}
{"op":"mcm","clk":"1361921160","pt":1588417254465,"mc":[{"id":"1.170370564","rc":[{"atb":[[3,0]],"id":9630572}],"con":true,"img":false}]}
{"op":"mcm","clk":"1361921164","pt":1588417254569,"mc":[{"id":"1.170370564","rc":[{"atb":[[3.05,50.39]],"id":9630572}],"con":true,"img":false}]}
{"op":"mcm","clk":"1361956104","pt":1588418481702,"mc":[{"id":"1.170370564","rc":[{"atb":[[3.05,0]],"id":9630572}],"con":true,"img":false}]}
{"op":"mcm","clk":"1361956107","pt":1588418481805,"mc":[{"id":"1.170370564","rc":[{"atb":[[3,50.39]],"id":9630572}],"con":true,"img":false}]}
{"op":"mcm","clk":"1361956853","pt":1588418523472,"mc":[{"id":"1.170370564","rc":[{"atb":[[3,0]],"id":9630572}],"con":true,"img":false}]}
{"op":"mcm","clk":"1361956856","pt":1588418523581,"mc":[{"id":"1.170370564","rc":[{"atb":[[3.05,50.39]],"id":9630572}],"con":true,"img":false}]}
{"op":"mcm","clk":"1361957549","pt":1588418559297,"mc":[{"id":"1.170370564","rc":[{"atb":[[3.05,0]],"id":9630572}],"con":true,"img":false}]}
{"op":"mcm","clk":"1361957553","pt":1588418559401,"mc":[{"id":"1.170370564","rc":[{"atb":[[3,50.39]],"id":9630572}],"con":true,"img":false}]}
{"op":"mcm","clk":"1361996191","pt":1588420537754,"mc":[{"id":"1.170370564","rc":[{"trd":[[1.23,4.08]],"ltp":1.23,"tv":4.08,"id":8509691},{"atb":[[1.23,5.12]],"id":8509691}],"con":true,"img":false}]}
{"op":"mcm","clk":"1362000205","pt":1588420843657,"mc":[{"id":"1.170370564","rc":[{"atb":[[1.22,283.41]],"id":8509691}],"con":true,"img":false}]}
{"op":"mcm","clk":"1362000207","pt":1588420843861,"mc":[{"id":"1.170370564","rc":[{"atb":[[3,0]],"id":9630572},{"atb":[[1.22,203.43]],"id":8509691}],"con":true,"img":false}]}
{"op":"mcm","clk":"1362000209","pt":1588420843964,"mc":[{"id":"1.170370564","rc":[{"atb":[[3.6,50.39]],"id":9630572},{"atb":[[1.21,79.98]],"id":8509691}],"con":true,"img":false}]}
{"op":"mcm","clk":"1362000306","pt":1588420853473,"mc":[{"id":"1.170370564","rc":[{"atb":[[3.6,0]],"id":9630572}],"con":true,"img":false}]}
{"op":"mcm","clk":"1362000314","pt":1588420853782,"mc":[{"id":"1.170370564","rc":[{"atb":[[3.6,89.58]],"id":9630572}],"con":true,"img":false}]}
{"op":"mcm","clk":"1362001394","pt":1588420959233,"mc":[{"id":"1.170370564","rc":[{"atb":[[1.21,39.99]],"id":8509691}],"con":true,"img":false}]}
{"op":"mcm","clk":"1362001399","pt":1588420959543,"mc":[{"id":"1.170370564","rc":[{"atb":[[1.21,0]],"id":8509691}],"con":true,"img":false}]}
{"op":"mcm","clk":"1362001401","pt":1588420959599,"mc":[{"id":"1.170370564","rc":[{"atb":[[1.22,243.42]],"id":8509691}],"con":true,"img":false}]}
{"op":"mcm","clk":"1362002301","pt":1588421035321,"mc":[{"id":"1.170370564","rc":[{"atb":[[3.6,39.99]],"id":9630572}],"con":true,"img":false}]}
{"op":"mcm","clk":"1362011274","pt":1588421792190,"mc":[{"id":"1.170370564","rc":[{"atb":[[1.01,1710.69]],"id":8509691}],"con":true,"img":false}]}
{"op":"mcm","clk":"1362011323","pt":1588421799423,"mc":[{"id":"1.170370564","rc":[{"atb":[[1.01,1711.09]],"id":8509691}],"con":true,"img":false}]}
{"op":"mcm","clk":"1362011423","pt":1588421811129,"mc":[{"id":"1.170370564","rc":[{"atb":[[1.01,1708.29]],"id":8509691}],"con":true,"img":false}]}
{"op":"mcm","clk":"1362011424","pt":1588421811232,"mc":[{"id":"1.170370564","rc":[{"atb":[[1.24,0.39]],"id":8509691}],"con":true,"img":false}]}
{"op":"mcm","clk":"1362040915","pt":1588424183109,"mc":[{"id":"1.170370566","rc":[{"atb":[[1.01,88.65]],"id":9630572}],"con":true,"img":false}]}
{"op":"mcm","clk":"1362040931","pt":1588424183882,"mc":[{"id":"1.170370566","rc":[{"atb":[[1.02,88.86]],"id":9630572}],"con":true,"img":false}]}
{"op":"mcm","clk":"1362040970","pt":1588424186027,"mc":[{"id":"1.170370566","rc":[{"atb":[[1.01,1.77]],"id":8509691}],"con":true,"img":false}]}
{"op":"mcm","clk":"1362040977","pt":1588424186694,"mc":[{"id":"1.170370566","rc":[{"atb":[[1.02,1.98]],"id":8509691}],"con":true,"img":false}]}
{"op":"mcm","clk":"1362041001","pt":1588424188123,"mc":[{"id":"1.170370566","rc":[{"atb":[[1.02,0.21]],"id":8509691}],"con":true,"img":false}]}
{"op":"mcm","clk":"1362041007","pt":1588424188589,"mc":[{"id":"1.170370566","rc":[{"atb":[[1.01,0]],"id":8509691}],"con":true,"img":false}]}
{"op":"mcm","clk":"1362041048","pt":1588424191700,"mc":[{"id":"1.170370566","rc":[{"atb":[[1.02,88.86]],"id":8509691}],"con":true,"img":false}]}
{"op":"mcm","clk":"1362041057","pt":1588424192314,"mc":[{"id":"1.170370566","rc":[{"atb":[[1.01,88.65]],"id":8509691}],"con":true,"img":false}]}
{"op":"mcm","clk":"1362045329","pt":1588424417975,"mc":[{"id":"1.170370564","rc":[{"atb":[[1.23,205.12]],"id":8509691}],"con":true,"img":false}]}
{"op":"mcm","clk":"1362045383","pt":1588424421663,"mc":[{"id":"1.170370564","rc":[{"atb":[[3.8,50]],"id":9630572}],"con":true,"img":false}]}
{"op":"mcm","clk":"1362045463","pt":1588424426176,"mc":[{"id":"1.170370564","rc":[{"atb":[[1.01,9.79]],"id":9630572},{"atl":[[990,2.2]],"id":9630572},{"atb":[[1.01,1388.34]],"id":8509691},{"atl":[[990,2.2]],"id":8509691}],"con":true,"img":false}]}
{"op":"mcm","clk":"1362052451","pt":1588424796108,"mc":[{"id":"1.170370564","rc":[{"atl":[[4.8,2.12]],"id":9630572}],"con":true,"img":false}]}
{"op":"mcm","clk":"1362070271","pt":1588425771822,"mc":[{"id":"1.170370564","rc":[{"atb":[[1.01,1393.34]],"id":8509691}],"con":true,"img":false}]}
{"op":"mcm","clk":"1362070521","pt":1588425786277,"mc":[{"id":"1.170370564","rc":[{"atb":[[1.03,1602.72]],"id":8509691}],"con":true,"img":false}]}
{"op":"mcm","clk":"1362070830","pt":1588425804200,"mc":[{"id":"1.170370564","rc":[{"atb":[[1.01,14.79]],"id":9630572}],"con":true,"img":false}]}
{"op":"mcm","clk":"1362071069","pt":1588425817954,"mc":[{"id":"1.170370564","rc":[{"atb":[[1.03,3]],"id":9630572}],"con":true,"img":false}]}
{"op":"mcm","clk":"1362095861","pt":1588427184424,"mc":[{"id":"1.170370564","rc":[{"trd":[[3.8,0.86]],"ltp":3.8,"tv":0.86,"id":9630572},{"atb":[[3.8,49.14]],"id":9630572},{"trd":[[1.36,2.39]],"ltp":1.36,"tv":2.39,"id":8509691}],"con":true,"img":false}]}
{"op":"mcm","clk":"1362097105","pt":1588427250395,"mc":[{"id":"1.170370564","rc":[{"atb":[[3.6,0]],"id":9630572},{"atb":[[1.22,203.43]],"id":8509691}],"con":true,"img":false}]}
{"op":"mcm","clk":"1362097109","pt":1588427250495,"mc":[{"id":"1.170370564","rc":[{"atb":[[3.65,39.99]],"id":9630572},{"atb":[[1.21,39.99]],"id":8509691}],"con":true,"img":false}]}
{"op":"mcm","clk":"1362098020","pt":1588427303570,"mc":[{"id":"1.170370564","rc":[{"atb":[[3.5,17.9]],"id":9630572},{"atb":[[1.25,179.02]],"id":8509691}],"con":true,"img":false}]}
{"op":"mcm","clk":"1362098023","pt":1588427303671,"mc":[{"id":"1.170370564","rc":[{"atb":[[3.75,0]],"id":9630572},{"atb":[[1.22,0]],"id":8509691}],"con":true,"img":false}]}
{"op":"mcm","clk":"1362098043","pt":1588427304897,"mc":[{"id":"1.170370565","rc":[{"atb":[[6.4,10]],"id":11340557},{"atb":[[1.91,43.1]],"id":11269555},{"atb":[[3.3,17.05]],"id":11269557}],"con":true,"img":false},{"id":"1.170370566","rc":[{"atb":[[2.74,22.54]],"id":9630572},{"atb":[[1.4,98.06]],"id":8509691}],"con":true,"img":false},{"id":"1.170370567","rc":[{"atb":[[2.88,20.86]],"id":9630572},{"atb":[[1.36,108.95]],"id":8509691}],"con":true,"img":false}]}
{"op":"mcm","clk":"1362098045","pt":1588427304951,"mc":[{"id":"1.170370565","rc":[{"atb":[[7.4,0]],"id":11340557},{"atb":[[1.8,0]],"id":11269555},{"atb":[[3.4,0]],"id":11269557}],"con":true,"img":false},{"id":"1.170370566","rc":[{"atb":[[3,0]],"id":9630572},{"atb":[[1.33,0]],"id":8509691}],"con":true,"img":false},{"id":"1.170370567","rc":[{"atb":[[3,0]],"id":9630572},{"atb":[[1.33,0]],"id":8509691}],"con":true,"img":false}]}
{"op":"mcm","clk":"1362100438","pt":1588427452964,"mc":[{"id":"1.170370564","rc":[{"atl":[[1.35,17.49]],"id":8509691}],"con":true,"img":false}]}
{"op":"mcm","clk":"1362104627","pt":1588427732056,"mc":[{"id":"1.170370564","rc":[{"atb":[[1.23,200]],"id":8509691}],"con":true,"img":false}]}
{"op":"mcm","clk":"1362104629","pt":1588427732159,"mc":[{"id":"1.170370564","rc":[{"atb":[[1.26,5.12]],"id":8509691}],"con":true,"img":false}]}
{"op":"mcm","clk":"1362105896","pt":1588427833578,"mc":[{"id":"1.170370564","rc":[{"trd":[[1.26,7]],"ltp":1.26,"tv":7.0,"id":8509691},{"atb":[[1.26,1.62]],"id":8509691}],"con":true,"img":false}]}
{"op":"mcm","clk":"1362106213","pt":1588427863221,"mc":[{"id":"1.170370564","rc":[{"trd":[[4.8,0.57]],"ltp":4.8,"tv":0.57,"id":9630572},{"atl":[[4.8,1.55]],"id":9630572},{"trd":[[1.26,12.45]],"ltp":1.26,"tv":12.45,"id":8509691},{"atb":[[1.26,0]],"id":8509691}],"con":true,"img":false}]}
{"op":"mcm","clk":"1362106579","pt":1588427899430,"mc":[{"id":"1.170370564","rc":[{"atb":[[3.8,0]],"id":9630572}],"con":true,"img":false}]}
{"op":"mcm","clk":"1362106581","pt":1588427899532,"mc":[{"id":"1.170370564","rc":[{"atb":[[3.7,49.14]],"id":9630572}],"con":true,"img":false}]}
{"op":"mcm","clk":"1362106601","pt":1588427901325,"mc":[{"id":"1.170370564","rc":[{"atb":[[1.23,0]],"id":8509691}],"con":true,"img":false}]}
{"op":"mcm","clk":"1362106605","pt":1588427901427,"mc":[{"id":"1.170370564","rc":[{"atb":[[1.22,200]],"id":8509691}],"con":true,"img":false}]}
{"op":"mcm","clk":"1362106660","pt":1588427905470,"mc":[{"id":"1.170370564","rc":[{"atl":[[1000,0.7]],"id":9630572}],"con":true,"img":false}]}
{"op":"mcm","clk":"1362106663","pt":1588427905576,"mc":[{"id":"1.170370564","rc":[{"atl":[[1000,0]],"id":9630572}],"con":true,"img":false}]}
{"op":"mcm","clk":"1362106666","pt":1588427905674,"mc":[{"id":"1.170370564","rc":[{"atl":[[4.7,0.7]],"id":9630572}],"con":true,"img":false}]}
{"op":"mcm","clk":"1362108572","pt":1588428002288,"mc":[{"id":"1.170370565","rc":[{"atb":[[1.91,57.47]],"id":11269555},{"atb":[[3.3,22.73]],"id":11269557}],"con":true,"img":false},{"id":"1.170370566","rc":[{"atb":[[2.74,30.05]],"id":9630572},{"atb":[[1.4,130.75]],"id":8509691}],"con":true,"img":false},{"id":"1.170370567","rc":[{"atb":[[2.88,48.67]],"id":9630572},{"atb":[[1.36,254.22]],"id":8509691}],"con":true,"img":false}]}
{"op":"mcm","clk":"1362108575","pt":1588428002392,"mc":[{"id":"1.170370567","rc":[{"atb":[[2.88,27.81]],"id":9630572},{"atb":[[1.36,145.27]],"id":8509691}],"con":true,"img":false}]}
{"op":"mcm","clk":"1362108615","pt":1588428004873,"mc":[{"id":"1.170370564","rc":[{"atb":[[3.5,41.77]],"id":9630572},{"atb":[[1.25,417.72]],"id":8509691}],"con":true,"img":false}]}
{"op":"mcm","clk":"1362108617","pt":1588428004975,"mc":[{"id":"1.170370564","rc":[{"atb":[[3.5,23.87]],"id":9630572},{"atb":[[1.25,238.7]],"id":8509691}],"con":true,"img":false}]}
{"op":"mcm","clk":"1362109528","pt":1588428068613,"mc":[{"id":"1.170370564","rc":[{"trd":[[1.35,7]],"ltp":1.35,"tv":7.0,"id":8509691},{"atl":[[1.35,13.99]],"id":8509691}],"con":true,"img":false}]}
{"op":"mcm","clk":"1362109964","pt":1588428085931,"mc":[{"id":"1.170370564","rc":[{"atb":[[1.28,6.99]],"id":8509691}],"con":true,"img":false}]}
{"op":"mcm","clk":"1362125329","pt":1588428946490,"mc":[{"id":"1.170370564","rc":[{"atl":[[1.32,180]],"id":8509691}],"con":true,"img":false}]}
{"op":"mcm","clk":"1362126468","pt":1588429011276,"mc":[{"id":"1.170370564","rc":[{"atl":[[1.34,5]],"id":8509691}],"con":true,"img":false}]}
{"op":"mcm","clk":"1362135669","pt":1588429575002,"mc":[{"id":"1.170370564","rc":[{"atb":[[4.2,6.12]],"id":9630572}],"con":true,"img":false}]}
{"op":"mcm","clk":"1362136484","pt":1588429629153,"mc":[{"id":"1.170370564","rc":[{"atb":[[1.21,0]],"id":8509691}],"con":true,"img":false}]}
{"op":"mcm","clk":"1362137061","pt":1588429667122,"mc":[{"id":"1.170370564","rc":[{"atb":[[3.65,0]],"id":9630572}],"con":true,"img":false}]}
{"op":"mcm","clk":"1362137063","pt":1588429667227,"mc":[{"id":"1.170370564","rc":[{"atb":[[3.75,39.99]],"id":9630572}],"con":true,"img":false}]}
{"op":"mcm","clk":"1362137068","pt":1588429667380,"mc":[{"id":"1.170370564","rc":[{"atb":[[1.2,39.99]],"id":8509691}],"con":true,"img":false}]}
{"op":"mcm","clk":"1362138379","pt":1588429750481,"mc":[{"id":"1.170370564","rc":[{"atl":[[4.7,0]],"id":9630572}],"con":true,"img":false}]}
{"op":"mcm","clk":"1362138394","pt":1588429751504,"mc":[{"id":"1.170370564","rc":[{"atl":[[1000,0.74]],"id":9630572}],"con":true,"img":false}]}
{"op":"mcm","clk":"1362138397","pt":1588429751708,"mc":[{"id":"1.170370564","rc":[{"atl":[[1000,0]],"id":9630572}],"con":true,"img":false}]}
{"op":"mcm","clk":"1362138400","pt":1588429751811,"mc":[{"id":"1.170370564","rc":[{"atl":[[4.4,0.74]],"id":9630572}],"con":true,"img":false}]}
{"op":"mcm","clk":"1362138461","pt":1588429755697,"mc":[{"id":"1.170370564","rc":[{"atb":[[3.7,0]],"id":9630572}],"con":true,"img":false}]}
{"op":"mcm","clk":"1362138464","pt":1588429755802,"mc":[{"id":"1.170370564","rc":[{"atb":[[3.8,49.14]],"id":9630572}],"con":true,"img":false}]}
{"op":"mcm","clk":"1362139443","pt":1588429771212,"mc":[{"id":"1.170370564","rc":[{"trd":[[4.4,1.48]],"ltp":4.4,"tv":1.48,"id":9630572},{"atb":[[4.5,99.26]],"id":9630572},{"atl":[[4.4,0]],"id":9630572}],"con":true,"img":false}]}
{"op":"mcm","clk":"1362139540","pt":1588429777933,"mc":[{"id":"1.170370564","rc":[{"atb":[[1.26,65.6]],"id":8509691}],"con":true,"img":false}]}
{"op":"mcm","clk":"1362139729","pt":1588429792964,"mc":[{"id":"1.170370564","rc":[{"atb":[[1.21,87.47]],"id":8509691}],"con":true,"img":false}]}
{"op":"mcm","clk":"1362139747","pt":1588429793983,"mc":[{"id":"1.170370564","rc":[{"trd":[[4.5,0.31]],"ltp":4.5,"tv":0.31,"id":9630572},{"atb":[[4.5,98.95]],"id":9630572},{"trd":[[1.29,1.09]],"ltp":1.29,"tv":1.09,"id":8509691}],"con":true,"img":false}]}
{"op":"mcm","clk":"1362140204","pt":1588429823988,"mc":[{"id":"1.170370564","rc":[{"atb":[[3.9,17.49]],"id":9630572}],"con":true,"img":false}]}
{"op":"mcm","clk":"1362141188","pt":1588429890597,"mc":[{"id":"1.170370564","rc":[{"atl":[[1.29,15.99]],"id":8509691}],"con":true,"img":false}]}
{"op":"mcm","clk":"1362141277","pt":1588429894684,"mc":[{"id":"1.170370564","rc":[{"trd":[[4.9,4.49],[4.8,3.67],[4.6,1.95]],"ltp":4.9,"tv":10.11,"id":9630572},{"atl":[[4.8,0]],"id":9630572},{"trd":[[1.26,29.91],[1.28,6.99]],"ltp":1.26,"tv":36.9,"id":8509691},{"atb":[[1.28,0],[1.26,48.14]],"id":8509691}],"con":true,"img":false}]}
{"op":"mcm","clk":"1362142028","pt":1588429941345,"mc":[{"id":"1.170370564","rc":[{"atb":[[1.27,262.98]],"id":8509691}],"con":true,"img":false}]}
{"op":"mcm","clk":"1362142065","pt":1588429943140,"mc":[{"id":"1.170370564","rc":[{"atb":[[3.5,0]],"id":9630572},{"atb":[[1.25,0]],"id":8509691}],"con":true,"img":false}]}
{"op":"mcm","clk":"1362142167","pt":1588429948468,"mc":[{"id":"1.170370564","rc":[{"atb":[[4.4,2.32]],"id":9630572}],"con":true,"img":false}]}
{"op":"mcm","clk":"1362143598","pt":1588430045226,"mc":[{"id":"1.170370564","rc":[{"trd":[[4.5,29.25]],"ltp":4.5,"tv":29.25,"id":9630572},{"atb":[[4.5,70.01]],"id":9630572},{"trd":[[1.29,134.03]],"ltp":1.29,"tv":134.03,"id":8509691},{"atl":[[1.29,0]],"id":8509691}],"con":true,"img":false}]}
{"op":"mcm","clk":"1362143737","pt":1588430054603,"mc":[{"id":"1.170370564","rc":[{"atb":[[4.4,0]],"id":9630572}],"con":true,"img":false}]}
{"op":"mcm","clk":"1362143928","pt":1588430068340,"mc":[{"id":"1.170370564","rc":[{"atb":[[4.4,2.32]],"id":9630572}],"con":true,"img":false}]}
{"op":"mcm","clk":"1362144084","pt":1588430080466,"mc":[{"id":"1.170370564","rc":[{"trd":[[4.5,64.38]],"ltp":4.5,"tv":64.38,"id":9630572},{"atb":[[4.5,34.87]],"id":9630572},{"trd":[[1.29,256.56]],"ltp":1.29,"tv":256.56,"id":8509691}],"con":true,"img":false}]}
{"op":"mcm","clk":"1362144122","pt":1588430083176,"mc":[{"id":"1.170370564","rc":[{"atl":[[1.28,17.17]],"id":8509691}],"con":true,"img":false}]}
{"op":"mcm","clk":"1362144219","pt":1588430088494,"mc":[{"id":"1.170370564","rc":[{"trd":[[4.5,99.26]],"ltp":4.5,"tv":99.26,"id":9630572},{"atb":[[4.5,0]],"id":9630572},{"trd":[[1.29,378.23],[1.28,41.35]],"ltp":1.29,"tv":419.58,"id":8509691},{"atb":[[1.29,191.07]],"id":8509691},{"atl":[[1.28,0]],"id":8509691}],"con":true,"img":false}]}
{"op":"mcm","clk":"1362144301","pt":1588430093349,"mc":[{"id":"1.170370564","rc":[{"atb":[[3.5,23.87]],"id":9630572},{"atb":[[1.25,238.7]],"id":8509691}],"con":true,"img":false}]}
{"op":"mcm","clk":"1362144414","pt":1588430101065,"mc":[{"id":"1.170370564","rc":[{"atb":[[1.21,0]],"id":8509691}],"con":true,"img":false}]}
{"op":"mcm","clk":"1362144419","pt":1588430101372,"mc":[{"id":"1.170370564","rc":[{"atb":[[1.23,87.47]],"id":8509691}],"con":true,"img":false}]}
{"op":"mcm","clk":"1362144519","pt":1588430107071,"mc":[{"id":"1.170370564","rc":[{"atb":[[1.26,0]],"id":8509691}],"con":true,"img":false}]}
{"op":"mcm","clk":"1362144523","pt":1588430107330,"mc":[{"id":"1.170370564","rc":[{"atb":[[1.26,65.6]],"id":8509691}],"con":true,"img":false}]}
{"op":"mcm","clk":"1362148241","pt":1588430354941,"mc":[{"id":"1.170370564","rc":[{"trd":[[4.4,3.8]],"ltp":4.4,"tv":3.8,"id":9630572},{"atb":[[4.4,0]],"id":9630572},{"trd":[[1.3,7.86]],"ltp":1.3,"tv":7.86,"id":8509691},{"atb":[[1.3,7.73]],"id":8509691}],"con":true,"img":false}]}
{"op":"mcm","clk":"1362148273","pt":1588430363098,"mc":[{"id":"1.170370564","rc":[{"atb":[[4.2,0]],"id":9630572}],"con":true,"img":false}]}
{"op":"mcm","clk":"1362148890","pt":1588430425263,"mc":[{"id":"1.170370564","rc":[{"atb":[[1.3,0]],"id":8509691}],"con":true,"img":false}]}
{"op":"mcm","clk":"1362149818","pt":1588430487949,"mc":[{"id":"1.170370564","rc":[{"atl":[[1.31,3.49]],"id":8509691}],"con":true,"img":false}]}
{"op":"mcm","clk":"1362150883","pt":1588430547245,"mc":[{"id":"1.170370564","rc":[{"atl":[[4.5,2.12]],"id":9630572}],"con":true,"img":false}]}
{"op":"mcm","clk":"1362151459","pt":1588430585298,"mc":[{"id":"1.170370564","rc":[{"atb":[[2.12,142.82]],"id":9630572}],"con":true,"img":false}]}
{"op":"mcm","clk":"1362154783","pt":1588430743578,"mc":[{"id":"1.170370564","rc":[{"trd":[[1.29,394.07]],"ltp":1.29,"tv":394.07,"id":8509691},{"atb":[[1.29,183.15]],"id":8509691}],"con":true,"img":false}]}
{"op":"mcm","clk":"1362156262","pt":1588430834078,"mc":[{"id":"1.170370564","rc":[{"atl":[[1.31,13.99]],"id":8509691}],"con":true,"img":false}]}
{"op":"mcm","clk":"1362158663","pt":1588430965577,"mc":[{"id":"1.170370564","rc":[{"trd":[[1.29,408.07]],"ltp":1.29,"tv":408.07,"id":8509691},{"atb":[[1.29,176.15]],"id":8509691}],"con":true,"img":false}]}
{"op":"mcm","clk":"1362160547","pt":1588431120293,"mc":[{"id":"1.170370564","rc":[{"atl":[[1.32,0]],"id":8509691}],"con":true,"img":false}]}
{"op":"mcm","clk":"1362160549","pt":1588431120400,"mc":[{"id":"1.170370564","rc":[{"atl":[[1.31,193.99]],"id":8509691}],"con":true,"img":false}]}
{"op":"mcm","clk":"1362161286","pt":1588431185775,"mc":[{"id":"1.170370564","rc":[{"atl":[[1.3,19.5]],"id":8509691}],"con":true,"img":false}]}
{"op":"mcm","clk":"1362161795","pt":1588431237750,"mc":[{"id":"1.170370564","rc":[{"atl":[[1.34,20]],"id":8509691}],"con":true,"img":false}]}
{"op":"mcm","clk":"1362163522","pt":1588431407931,"mc":[{"id":"1.170370564","rc":[{"trd":[[4.5,104.28]],"ltp":4.5,"tv":104.28,"id":9630572},{"atl":[[4.5,0]],"id":9630572},{"trd":[[1.29,410.76]],"ltp":1.29,"tv":410.76,"id":8509691},{"atb":[[1.29,173.46]],"id":8509691}],"con":true,"img":false}]}
{"op":"mcm","clk":"1362163910","pt":1588431447058,"mc":[{"id":"1.170370564","rc":[{"atl":[[1.35,0]],"id":8509691}],"con":true,"img":false}]}
{"op":"mcm","clk":"1362163991","pt":1588431454103,"mc":[{"id":"1.170370564","rc":[{"atl":[[1.31,183.49]],"id":8509691}],"con":true,"img":false}]}
{"op":"mcm","clk":"1362168253","pt":1588431598448,"mc":[{"id":"1.170370564","rc":[{"atb":[[3.75,0]],"id":9630572},{"atb":[[1.2,0]],"id":8509691}],"con":true,"img":false}]}
{"op":"mcm","clk":"1362168394","pt":1588431602156,"mc":[{"id":"1.170370564","rc":[{"atb":[[4.1,8.58]],"id":9630572},{"atb":[[1.25,327.35]],"id":8509691}],"con":true,"img":false}]}
{"op":"mcm","clk":"1362168508","pt":1588431605659,"mc":[{"id":"1.170370564","rc":[{"atb":[[1.08,9.71]],"id":8509691}],"con":true,"img":false}]}
{"op":"mcm","clk":"1362168526","pt":1588431605967,"mc":[{"id":"1.170370564","rc":[{"atl":[[1.81,2.32]],"id":8509691}],"con":true,"img":false}]}
{"op":"mcm","clk":"1362168534","pt":1588431606171,"mc":[{"id":"1.170370564","rc":[{"atb":[[1.01,16.79]],"id":9630572}],"con":true,"img":false}]}
{"op":"mcm","clk":"1362168545","pt":1588431606478,"mc":[{"id":"1.170370564","rc":[{"atb":[[1.01,14.88]],"id":9630572},{"atl":[[1000,2]],"id":9630572}],"con":true,"img":false}]}
{"op":"mcm","clk":"1362168553","pt":1588431606784,"mc":[{"id":"1.170370564","rc":[{"atb":[[1.01,14.79]],"id":9630572},{"atl":[[1000,0.54]],"id":9630572}],"con":true,"img":false}]}
{"op":"mcm","clk":"1362168560","pt":1588431606836,"mc":[{"id":"1.170370564","rc":[{"atb":[[3.95,0.09]],"id":9630572}],"con":true,"img":false}]}
{"op":"mcm","clk":"1362168564","pt":1588431606937,"mc":[{"id":"1.170370564","rc":[{"atl":[[1000,0]],"id":9630572}],"con":true,"img":false}]}
{"op":"mcm","clk":"1362168568","pt":1588431607041,"mc":[{"id":"1.170370564","rc":[{"atl":[[7.6,0.54]],"id":9630572}],"con":true,"img":false}]}
{"op":"mcm","clk":"1362169309","pt":1588431627697,"mc":[{"id":"1.170370564","rc":[{"atb":[[4.3,2.22]],"id":9630572}],"con":true,"img":false}]}
{"op":"mcm","clk":"1362177801","pt":1588431861599,"mc":[{"id":"1.170370564","rc":[{"atb":[[3.5,22.3]],"id":9630572},{"atb":[[1.25,311.69]],"id":8509691}],"con":true,"img":false}]}
{"op":"mcm","clk":"1362180939","pt":1588431939940,"mc":[{"id":"1.170370564","rc":[{"trd":[[1.29,550.71]],"ltp":1.29,"tv":550.71,"id":8509691},{"atb":[[1.29,103.48]],"id":8509691}],"con":true,"img":false}]}
{"op":"mcm","clk":"1362181653","pt":1588431958179,"mc":[{"id":"1.170370564","rc":[{"trd":[[1.29,625.9]],"ltp":1.29,"tv":625.9,"id":8509691},{"atb":[[1.29,65.89]],"id":8509691}],"con":true,"img":false}]}
{"op":"mcm","clk":"1362182344","pt":1588431976086,"mc":[{"id":"1.170370564","rc":[{"atb":[[1.2,40.41]],"id":8509691}],"con":true,"img":false}]}
{"op":"mcm","clk":"1362183112","pt":1588431996444,"mc":[{"id":"1.170370564","rc":[{"trd":[[1.29,757.68]],"ltp":1.29,"tv":757.68,"id":8509691},{"atb":[[1.29,0]],"id":8509691},{"atl":[[1.29,78.11]],"id":8509691}],"con":true,"img":false}]}
{"op":"mcm","clk":"1362183145","pt":1588431997314,"mc":[{"id":"1.170370564","rc":[{"atb":[[4.2,8.31]],"id":9630572},{"atb":[[1.23,176.12]],"id":8509691}],"con":true,"img":false}]}
{"op":"mcm","clk":"1362183150","pt":1588431997415,"mc":[{"id":"1.170370564","rc":[{"atb":[[1.25,223.04]],"id":8509691}],"con":true,"img":false}]}
{"op":"mcm","clk":"1362183368","pt":1588432003468,"mc":[{"id":"1.170370564","rc":[{"atl":[[1.29,0]],"id":8509691}],"con":true,"img":false}]}
{"op":"mcm","clk":"1362183403","pt":1588432004339,"mc":[{"id":"1.170370564","rc":[{"atb":[[4.2,0]],"id":9630572},{"atb":[[1.24,89.05]],"id":8509691}],"con":true,"img":false}]}
{"op":"mcm","clk":"1362183791","pt":1588432014742,"mc":[{"id":"1.170370564","rc":[{"trd":[[1.27,156]],"ltp":1.27,"tv":156.0,"id":8509691},{"atb":[[1.27,184.97]],"id":8509691}],"con":true,"img":false}]}
{"op":"mcm","clk":"1362189660","pt":1588432177503,"mc":[{"id":"1.170370564","rc":[{"atb":[[1.02,1378.75]],"id":8509691}],"con":true,"img":false}]}
{"op":"mcm","clk":"1362189665","pt":1588432177606,"mc":[{"id":"1.170370564","rc":[{"atb":[[1.04,159.97]],"id":8509691}],"con":true,"img":false}]}
{"op":"mcm","clk":"1362191809","pt":1588432238225,"mc":[{"id":"1.170370564","rc":[{"atl":[[1.3,45.74]],"id":8509691}],"con":true,"img":false}]}
{"op":"mcm","clk":"1362192287","pt":1588432252925,"mc":[{"id":"1.170370564","rc":[{"trd":[[1.3,46.86]],"ltp":1.3,"tv":46.86,"id":8509691},{"atl":[[1.3,22.12]],"id":8509691}],"con":true,"img":false}]}
{"op":"mcm","clk":"1362192940","pt":1588432271958,"mc":[{"id":"1.170370564","rc":[{"atb":[[1.28,17.49]],"id":8509691}],"con":true,"img":false}]}
{"op":"mcm","clk":"1362196553","pt":1588432370993,"mc":[{"id":"1.170370564","rc":[{"atl":[[1.3,74.61]],"id":8509691}],"con":true,"img":false}]}
{"op":"mcm","clk":"1362196576","pt":1588432371611,"mc":[{"id":"1.170370564","rc":[{"atb":[[1.24,0.39]],"id":8509691}],"con":true,"img":false}]}
{"op":"mcm","clk":"1362208757","pt":1588432714952,"mc":[{"id":"1.170370564","rc":[{"atb":[[1.29,7.28]],"id":8509691}],"con":true,"img":false}]}
{"op":"mcm","clk":"1362208792","pt":1588432715617,"mc":[{"id":"1.170370564","rc":[{"atb":[[1.24,89.05]],"id":8509691}],"con":true,"img":false}]}
{"op":"mcm","clk":"1362209517","pt":1588432733965,"mc":[{"id":"1.170370564","rc":[{"atb":[[1.29,0]],"id":8509691}],"con":true,"img":false}]}
{"op":"mcm","clk":"1362209521","pt":1588432734067,"mc":[{"id":"1.170370564","rc":[{"trd":[[1.3,61.44]],"ltp":1.3,"tv":61.44,"id":8509691},{"atl":[[1.3,67.32]],"id":8509691}],"con":true,"img":false}]}
{"op":"mcm","clk":"1362209538","pt":1588432734679,"mc":[{"id":"1.170370564","rc":[{"atb":[[1.24,0.39]],"id":8509691}],"con":true,"img":false}]}
{"op":"mcm","clk":"1362209704","pt":1588432739654,"mc":[{"id":"1.170370564","rc":[{"trd":[[1.3,109.59]],"ltp":1.3,"tv":109.59,"id":8509691},{"atl":[[1.3,43.24]],"id":8509691}],"con":true,"img":false}]}
{"op":"mcm","clk":"1362209732","pt":1588432740575,"mc":[{"id":"1.170370564","rc":[{"atb":[[1.24,89.05]],"id":8509691}],"con":true,"img":false}]}
{"op":"mcm","clk":"1362209803","pt":1588432743095,"mc":[{"id":"1.170370564","rc":[{"atb":[[1.26,0]],"id":8509691}],"con":true,"img":false}]}
{"op":"mcm","clk":"1362209970","pt":1588432747467,"mc":[{"id":"1.170370565","rc":[{"trd":[[1.91,32.13]],"ltp":1.91,"tv":32.13,"id":11269555},{"atb":[[1.91,41.4]],"id":11269555}],"con":true,"img":false}]}
{"op":"mcm","clk":"1362210022","pt":1588432749322,"mc":[{"id":"1.170370565","rc":[{"atb":[[1.91,98.87]],"id":11269555}],"con":true,"img":false}]}
{"op":"mcm","clk":"1362210027","pt":1588432749427,"mc":[{"id":"1.170370565","rc":[{"atb":[[1.91,57.47]],"id":11269555}],"con":true,"img":false}]}
{"op":"mcm","clk":"1362210961","pt":1588432777928,"mc":[{"id":"1.170370564","rc":[{"atl":[[1.3,69.48]],"id":8509691}],"con":true,"img":false}]}
{"op":"mcm","clk":"1362210988","pt":1588432778648,"mc":[{"id":"1.170370564","rc":[{"atb":[[1.24,0.39]],"id":8509691}],"con":true,"img":false}]}
{"op":"mcm","clk":"1362212861","pt":1588432835082,"mc":[{"id":"1.170370564","rc":[{"atb":[[4,2.02],[4.1,10.62]],"id":9630572},{"atl":[[4.8,2.02],[4.9,2.05]],"id":9630572},{"atb":[[1.26,2.21],[1.25,225.05]],"id":8509691},{"atl":[[1.32,2.11],[1.33,2]],"id":8509691}],"con":true,"img":false}]}
{"op":"mcm","clk":"1362218250","pt":1588433046618,"mc":[{"id":"1.170370564","rc":[{"trd":[[1.27,221.02],[1.28,76.34]],"ltp":1.27,"tv":297.36,"id":8509691},{"atb":[[1.28,0],[1.27,152.47]],"id":8509691}],"con":true,"img":false}]}
{"op":"mcm","clk":"1362218255","pt":1588433046796,"mc":[{"id":"1.170370564","rc":[{"atb":[[1.24,2.41]],"id":8509691}],"con":true,"img":false}]}
{"op":"mcm","clk":"1362218258","pt":1588433046982,"mc":[{"id":"1.170370564","rc":[{"atb":[[1.26,0]],"id":8509691},{"atl":[[1.33,0]],"id":8509691}],"con":true,"img":false}]}
{"op":"mcm","clk":"1362218262","pt":1588433047083,"mc":[{"id":"1.170370564","rc":[{"atb":[[4,0]],"id":9630572},{"atl":[[4.9,0]],"id":9630572}],"con":true,"img":false}]}
{"op":"mcm","clk":"1362218268","pt":1588433047286,"mc":[{"id":"1.170370564","rc":[{"atl":[[5.1,2.05],[5,2]],"id":9630572},{"atl":[[1.33,2.23]],"id":8509691}],"con":true,"img":false}]}
{"op":"mcm","clk":"1362218270","pt":1588433047387,"mc":[{"id":"1.170370564","rc":[{"atl":[[4.8,0]],"id":9630572}],"con":true,"img":false}]}
{"op":"mcm","clk":"1362218275","pt":1588433047593,"mc":[{"id":"1.170370564","rc":[{"atb":[[4,2.02]],"id":9630572}],"con":true,"img":false}]}
{"op":"mcm","clk":"1362231850","pt":1588433658303,"mc":[{"id":"1.170370564","rc":[{"atb":[[1.28,1005.31]],"id":8509691}],"con":true,"img":false}]}
{"op":"mcm","clk":"1362231860","pt":1588433658561,"mc":[{"id":"1.170370564","rc":[{"atb":[[1.26,2.21]],"id":8509691}],"con":true,"img":false}]}
{"op":"mcm","clk":"1362231865","pt":1588433658717,"mc":[{"id":"1.170370564","rc":[{"atb":[[4,0]],"id":9630572},{"atl":[[5.1,0]],"id":9630572},{"atb":[[1.24,0.39]],"id":8509691},{"atl":[[1.33,0]],"id":8509691}],"con":true,"img":false}]}
{"op":"mcm","clk":"1362231870","pt":1588433658817,"mc":[{"id":"1.170370564","rc":[{"atl":[[4.8,2.02],[4.9,2.05]],"id":9630572}],"con":true,"img":false}]}
{"op":"mcm","clk":"1362231874","pt":1588433658921,"mc":[{"id":"1.170370564","rc":[{"atb":[[1.25,223.04],[1.24,89.05]],"id":8509691}],"con":true,"img":false}]}
{"op":"mcm","clk":"1362231878","pt":1588433659021,"mc":[{"id":"1.170370564","rc":[{"atb":[[4,2.02]],"id":9630572},{"atl":[[5,0]],"id":9630572},{"atl":[[1.33,2.14]],"id":8509691}],"con":true,"img":false}]}
{"op":"mcm","clk":"1362231884","pt":1588433659124,"mc":[{"id":"1.170370564","rc":[{"atb":[[1.25,225.05]],"id":8509691}],"con":true,"img":false}]}
{"op":"mcm","clk":"1362232593","pt":1588433679260,"mc":[{"id":"1.170370564","rc":[{"atl":[[1.3,375.33]],"id":8509691}],"con":true,"img":false}]}
{"op":"mcm","clk":"1362232607","pt":1588433679561,"mc":[{"id":"1.170370564","rc":[{"atl":[[4.9,0]],"id":9630572}],"con":true,"img":false}]}
{"op":"mcm","clk":"1362232611","pt":1588433679665,"mc":[{"id":"1.170370564","rc":[{"atb":[[4,0]],"id":9630572},{"atb":[[1.25,223.04]],"id":8509691},{"atl":[[1.33,0]],"id":8509691}],"con":true,"img":false}]}
{"op":"mcm","clk":"1362232619","pt":1588433679817,"mc":[{"id":"1.170370564","rc":[{"atb":[[4,2.02]],"id":9630572},{"atl":[[4.9,2]],"id":9630572},{"atb":[[1.25,225.04]],"id":8509691},{"atl":[[1.33,2.08]],"id":8509691}],"con":true,"img":false}]}
{"op":"mcm","clk":"1362234793","pt":1588433742404,"mc":[{"id":"1.170370564","rc":[{"trd":[[1.28,236.34]],"ltp":1.28,"tv":236.34,"id":8509691},{"atb":[[1.28,925.31]],"id":8509691}],"con":true,"img":false}]}
{"op":"mcm","clk":"1362234805","pt":1588433742713,"mc":[{"id":"1.170370564","rc":[{"atb":[[4,0]],"id":9630572},{"atl":[[4.9,0]],"id":9630572},{"atb":[[1.25,223.04]],"id":8509691},{"atl":[[1.33,0]],"id":8509691}],"con":true,"img":false}]}
{"op":"mcm","clk":"1362234810","pt":1588433742919,"mc":[{"id":"1.170370564","rc":[{"atb":[[4,2.02]],"id":9630572},{"atl":[[4.9,2.05]],"id":9630572},{"atb":[[1.25,225.05]],"id":8509691},{"atl":[[1.33,2.05]],"id":8509691}],"con":true,"img":false}]}
{"op":"mcm","clk":"1362236626","pt":1588433797326,"mc":[{"id":"1.170370566","rc":[{"trd":[[3.5,19.42]],"ltp":3.5,"tv":19.42,"id":9630572},{"trd":[[1.4,48.57]],"ltp":1.4,"tv":48.57,"id":8509691},{"atb":[[1.4,82.18]],"id":8509691}],"con":true,"img":false}]}
{"op":"mcm","clk":"1362236651","pt":1588433797988,"mc":[{"id":"1.170370566","rc":[{"atb":[[1.4,212.93]],"id":8509691}],"con":true,"img":false}]}
{"op":"mcm","clk":"1362236654","pt":1588433798089,"mc":[{"id":"1.170370566","rc":[{"atb":[[1.4,130.75]],"id":8509691}],"con":true,"img":false}]}
{"op":"mcm","clk":"1362237372","pt":1588433821936,"mc":[{"id":"1.170370564","rc":[{"trd":[[1.28,262.58]],"ltp":1.28,"tv":262.58,"id":8509691},{"atb":[[1.28,912.19]],"id":8509691}],"con":true,"img":false}]}
{"op":"mcm","clk":"1362237383","pt":1588433822247,"mc":[{"id":"1.170370564","rc":[{"atb":[[4,0]],"id":9630572},{"atl":[[4.9,0]],"id":9630572},{"atb":[[1.25,223.04]],"id":8509691},{"atl":[[1.33,0]],"id":8509691}],"con":true,"img":false}]}
{"op":"mcm","clk":"1362237389","pt":1588433822452,"mc":[{"id":"1.170370564","rc":[{"atb":[[4,2.02]],"id":9630572},{"atl":[[4.9,2.05]],"id":9630572},{"atb":[[1.25,225.05]],"id":8509691},{"atl":[[1.33,2.14]],"id":8509691}],"con":true,"img":false}]}
{"op":"mcm","clk":"1362240980","pt":1588433935842,"mc":[{"id":"1.170370564","rc":[{"atb":[[1.11,60]],"id":9630572},{"atb":[[1.11,278.14]],"id":8509691}],"con":true,"img":false}]}
{"op":"mcm","clk":"1362240991","pt":1588433936146,"mc":[{"id":"1.170370564","rc":[{"atl":[[4.9,0]],"id":9630572},{"atl":[[1.33,0]],"id":8509691}],"con":true,"img":false}]}
{"op":"mcm","clk":"1362240994","pt":1588433936247,"mc":[{"id":"1.170370564","rc":[{"atb":[[4,0]],"id":9630572},{"atb":[[1.25,223.04]],"id":8509691}],"con":true,"img":false}]}
{"op":"mcm","clk":"1362240997","pt":1588433936353,"mc":[{"id":"1.170370564","rc":[{"atl":[[4.9,2.05]],"id":9630572},{"atl":[[1.33,2.05]],"id":8509691}],"con":true,"img":false}]}
{"op":"mcm","clk":"1362241001","pt":1588433936451,"mc":[{"id":"1.170370564","rc":[{"atb":[[4,2.02]],"id":9630572},{"atb":[[1.25,225.05]],"id":8509691}],"con":true,"img":false}]}
{"op":"mcm","clk":"1362242851","pt":1588433999535,"mc":[{"id":"1.170370564","rc":[{"trd":[[1.28,294.78]],"ltp":1.28,"tv":294.78,"id":8509691},{"atb":[[1.28,896.09]],"id":8509691}],"con":true,"img":false}]}
{"op":"mcm","clk":"1362242862","pt":1588433999840,"mc":[{"id":"1.170370564","rc":[{"atb":[[4,0]],"id":9630572},{"atl":[[4.9,0]],"id":9630572},{"atb":[[1.25,223.04]],"id":8509691},{"atl":[[1.33,0]],"id":8509691}],"con":true,"img":false}]}
{"op":"mcm","clk":"1362242872","pt":1588434000041,"mc":[{"id":"1.170370564","rc":[{"atb":[[4,2.02]],"id":9630572},{"atl":[[4.9,2.05]],"id":9630572},{"atb":[[1.25,225.05]],"id":8509691},{"atl":[[1.33,2.05]],"id":8509691}],"con":true,"img":false}]}
{"op":"mcm","clk":"1362243208","pt":1588434011260,"mc":[{"id":"1.170370564","rc":[{"trd":[[1.3,145.14]],"ltp":1.3,"tv":145.14,"id":8509691},{"atl":[[1.3,357.56]],"id":8509691}],"con":true,"img":false}]}
{"op":"mcm","clk":"1362243217","pt":1588434011564,"mc":[{"id":"1.170370564","rc":[{"atb":[[4,0]],"id":9630572},{"atl":[[4.9,0]],"id":9630572},{"atb":[[1.25,223.04]],"id":8509691},{"atl":[[1.33,0]],"id":8509691}],"con":true,"img":false}]}
{"op":"mcm","clk":"1362243221","pt":1588434011769,"mc":[{"id":"1.170370564","rc":[{"atb":[[4,2]],"id":9630572},{"atl":[[4.9,2.05]],"id":9630572},{"atb":[[1.25,225.05]],"id":8509691},{"atl":[[1.33,2.14]],"id":8509691}],"con":true,"img":false}]}
{"op":"mcm","clk":"1362243433","pt":1588434018569,"mc":[{"id":"1.170370564","rc":[{"atl":[[1.3,365.56]],"id":8509691}],"con":true,"img":false}]}
{"op":"mcm","clk":"1362243447","pt":1588434018871,"mc":[{"id":"1.170370564","rc":[{"atb":[[4,0]],"id":9630572},{"atl":[[4.9,0]],"id":9630572},{"atb":[[1.25,223.04]],"id":8509691},{"atl":[[1.33,0]],"id":8509691}],"con":true,"img":false}]}
{"op":"mcm","clk":"1362243451","pt":1588434019077,"mc":[{"id":"1.170370564","rc":[{"atb":[[4,2.02]],"id":9630572},{"atl":[[4.9,2.05]],"id":9630572},{"atb":[[1.25,225.05]],"id":8509691},{"atl":[[1.33,2.32]],"id":8509691}],"con":true,"img":false}]}
{"op":"mcm","clk":"1362244258","pt":1588434043713,"mc":[{"id":"1.170370564","rc":[{"atl":[[4.5,75.35]],"id":9630572}],"con":true,"img":false}]}
{"op":"mcm","clk":"1362244264","pt":1588434043874,"mc":[{"id":"1.170370564","rc":[{"atl":[[4.7,2.05]],"id":9630572}],"con":true,"img":false}]}
{"op":"mcm","clk":"1362244267","pt":1588434043975,"mc":[{"id":"1.170370564","rc":[{"atl":[[4.9,0]],"id":9630572},{"atb":[[1.25,223.04]],"id":8509691},{"atl":[[1.33,0]],"id":8509691}],"con":true,"img":false}]}
{"op":"mcm","clk":"1362244274","pt":1588434044179,"mc":[{"id":"1.170370564","rc":[{"atb":[[4,0]],"id":9630572}],"con":true,"img":false}]}
{"op":"mcm","clk":"1362244280","pt":1588434044383,"mc":[{"id":"1.170370564","rc":[{"atl":[[4.8,0]],"id":9630572},{"atb":[[1.25,225.05]],"id":8509691},{"atl":[[1.33,2.38]],"id":8509691}],"con":true,"img":false}]}
{"op":"mcm","clk":"1362244283","pt":1588434044486,"mc":[{"id":"1.170370564","rc":[{"atb":[[4,2.02]],"id":9630572}],"con":true,"img":false}]}
{"op":"mcm","clk":"1362244288","pt":1588434044588,"mc":[{"id":"1.170370564","rc":[{"atl":[[4.8,2.02]],"id":9630572}],"con":true,"img":false}]}
{"op":"mcm","clk":"1362244391","pt":1588434048014,"mc":[{"id":"1.170370564","rc":[{"atl":[[1.3,416.19]],"id":8509691}],"con":true,"img":false}]}
{"op":"mcm","clk":"1362244626","pt":1588434055986,"mc":[{"id":"1.170370564","rc":[{"atb":[[1.29,69.97]],"id":8509691}],"con":true,"img":false}]}
{"op":"mcm","clk":"1362244632","pt":1588434056190,"mc":[{"id":"1.170370564","rc":[{"atb":[[1.27,154.71]],"id":8509691}],"con":true,"img":false}]}
{"op":"mcm","clk":"1362244635","pt":1588434056294,"mc":[{"id":"1.170370564","rc":[{"atb":[[4,0]],"id":9630572},{"atl":[[4.8,0]],"id":9630572},{"atb":[[1.25,223.04]],"id":8509691},{"atl":[[1.33,0]],"id":8509691}],"con":true,"img":false}]}
{"op":"mcm","clk":"1362244640","pt":1588434056498,"mc":[{"id":"1.170370564","rc":[{"atb":[[1.26,0]],"id":8509691}],"con":true,"img":false}]}
{"op":"mcm","clk":"1362244645","pt":1588434056602,"mc":[{"id":"1.170370564","rc":[{"atb":[[4,2.02]],"id":9630572},{"atl":[[4.8,2]],"id":9630572},{"atl":[[1.33,2.2]],"id":8509691}],"con":true,"img":false}]}
{"op":"mcm","clk":"1362244647","pt":1588434056700,"mc":[{"id":"1.170370564","rc":[{"atb":[[1.26,2.09]],"id":8509691}],"con":true,"img":false}]}
{"op":"mcm","clk":"1362244658","pt":1588434057008,"mc":[{"id":"1.170370564","rc":[{"atb":[[1.25,311.69]],"id":8509691}],"con":true,"img":false}]}
{"op":"mcm","clk":"1362246226","pt":1588434111422,"mc":[{"id":"1.170370564","rc":[{"atl":[[1.31,3.49]],"id":8509691}],"con":true,"img":false}]}
{"op":"mcm","clk":"1362246232","pt":1588434111531,"mc":[{"id":"1.170370564","rc":[{"trd":[[1.29,897.63]],"ltp":1.29,"tv":897.63,"id":8509691},{"atb":[[1.29,0]],"id":8509691},{"atl":[[1.29,110.02]],"id":8509691}],"con":true,"img":false}]}
{"op":"mcm","clk":"1362246238","pt":1588434111685,"mc":[{"id":"1.170370564","rc":[{"atb":[[4,0]],"id":9630572},{"atl":[[4.8,0]],"id":9630572},{"trd":[[1.29,963.49]],"ltp":1.29,"tv":963.49,"id":8509691},{"atb":[[1.26,0]],"id":8509691},{"atl":[[1.33,0],[1.29,77.09]],"id":8509691}],"con":true,"img":false}]}
{"op":"mcm","clk":"1362246245","pt":1588434111888,"mc":[{"id":"1.170370564","rc":[{"atb":[[4.2,2.02]],"id":9630572},{"atl":[[4.8,2.02]],"id":9630572},{"atb":[[1.26,2.01],[1.27,152.47],[1.25,313.7]],"id":8509691},{"atl":[[1.31,5.54]],"id":8509691}],"con":true,"img":false}]}
{"op":"mcm","clk":"1362246253","pt":1588434112091,"mc":[{"id":"1.170370564","rc":[{"atb":[[4.1,8.58],[4.2,10.33]],"id":9630572},{"atl":[[1.32,0]],"id":8509691}],"con":true,"img":false}]}
{"op":"mcm","clk":"1362246258","pt":1588434112197,"mc":[{"id":"1.170370564","rc":[{"atb":[[1.25,225.05]],"id":8509691}],"con":true,"img":false}]}
{"op":"mcm","clk":"1362246262","pt":1588434112298,"mc":[{"id":"1.170370564","rc":[{"trd":[[4.5,166.15]],"ltp":4.5,"tv":166.15,"id":9630572},{"atb":[[4.1,10.62]],"id":9630572},{"atl":[[4.5,44.42]],"id":9630572},{"atl":[[1.32,2.11]],"id":8509691}],"con":true,"img":false}]}
{"op":"mcm","clk":"1362246381","pt":1588434115912,"mc":[{"id":"1.170370564","rc":[{"atb":[[4.3,0]],"id":9630572}],"con":true,"img":false}]}
{"op":"mcm","clk":"1362246693","pt":1588434125431,"mc":[{"id":"1.170370564","rc":[{"atl":[[1.29,246.15]],"id":8509691}],"con":true,"img":false}]}
{"op":"mcm","clk":"1362246703","pt":1588434125741,"mc":[{"id":"1.170370564","rc":[{"atb":[[4.1,8.58]],"id":9630572},{"atl":[[4.8,0]],"id":9630572},{"atb":[[1.25,223.04]],"id":8509691},{"atl":[[1.32,0]],"id":8509691}],"con":true,"img":false}]}
{"op":"mcm","clk":"1362246705","pt":1588434125799,"mc":[{"id":"1.170370564","rc":[{"atb":[[4.1,10.62]],"id":9630572},{"atl":[[4.8,2.02]],"id":9630572},{"atb":[[1.25,225.05]],"id":8509691},{"atl":[[1.32,2]],"id":8509691}],"con":true,"img":false}]}
{"op":"mcm","clk":"1362247500","pt":1588434151058,"mc":[{"id":"1.170370564","rc":[{"atb":[[4.1,12.95]],"id":9630572}],"con":true,"img":false}]}
{"op":"mcm","clk":"1362247511","pt":1588434151364,"mc":[{"id":"1.170370564","rc":[{"atb":[[4.1,10.91]],"id":9630572},{"atl":[[4.8,0]],"id":9630572},{"atb":[[1.25,223.04]],"id":8509691},{"atl":[[1.32,0]],"id":8509691}],"con":true,"img":false}]}
{"op":"mcm","clk":"1362247521","pt":1588434151576,"mc":[{"id":"1.170370564","rc":[{"atb":[[4.1,12.95]],"id":9630572},{"atl":[[4.8,2.02]],"id":9630572},{"atb":[[1.25,225.05]],"id":8509691},{"atl":[[1.32,2.11]],"id":8509691}],"con":true,"img":false}]}
{"op":"mcm","clk":"1362248619","pt":1588434184422,"mc":[{"id":"1.170370564","rc":[{"atl":[[2,50]],"id":8509691}],"con":true,"img":false}]}
{"op":"mcm","clk":"1362248628","pt":1588434184684,"mc":[{"id":"1.170370564","rc":[{"atb":[[4.1,10.91]],"id":9630572},{"atl":[[4.8,0]],"id":9630572},{"atb":[[1.25,223.04]],"id":8509691},{"atl":[[1.32,0]],"id":8509691}],"con":true,"img":false}]}
{"op":"mcm","clk":"1362248638","pt":1588434184888,"mc":[{"id":"1.170370564","rc":[{"atb":[[4.1,12.95]],"id":9630572},{"atl":[[4.8,2.02]],"id":9630572},{"atb":[[1.25,225.05]],"id":8509691},{"atl":[[1.32,2.11]],"id":8509691}],"con":true,"img":false}]}
{"op":"mcm","clk":"1362248662","pt":1588434185605,"mc":[{"id":"1.170370564","rc":[{"trd":[[1.28,318.77]],"ltp":1.28,"tv":318.77,"id":8509691},{"atb":[[1.28,884.1]],"id":8509691}],"con":true,"img":false}]}
{"op":"mcm","clk":"1362249495","pt":1588434212141,"mc":[{"id":"1.170370564","rc":[{"atl":[[1.3,365.56]],"id":8509691}],"con":true,"img":false}]}
{"op":"mcm","clk":"1362249507","pt":1588434212503,"mc":[{"id":"1.170370564","rc":[{"atb":[[4.1,10.91]],"id":9630572},{"atl":[[4.8,0]],"id":9630572},{"atb":[[1.25,223.04]],"id":8509691},{"atl":[[1.32,0]],"id":8509691}],"con":true,"img":false}]}
{"op":"mcm","clk":"1362249512","pt":1588434212707,"mc":[{"id":"1.170370564","rc":[{"atb":[[4.1,12.91]],"id":9630572},{"atl":[[4.8,2.02]],"id":9630572},{"atb":[[1.25,225.05]],"id":8509691},{"atl":[[1.32,2.11]],"id":8509691}],"con":true,"img":false}]}
{"op":"mcm","clk":"1362250672","pt":1588434255469,"mc":[{"id":"1.170370564","rc":[{"atb":[[4.1,10.58]],"id":9630572}],"con":true,"img":false}]}
{"op":"mcm","clk":"1362250681","pt":1588434255775,"mc":[{"id":"1.170370564","rc":[{"atb":[[4.1,8.58]],"id":9630572},{"atl":[[4.8,0]],"id":9630572},{"atb":[[1.25,223.04]],"id":8509691},{"atl":[[1.32,0]],"id":8509691}],"con":true,"img":false}]}
{"op":"mcm","clk":"1362250685","pt":1588434255978,"mc":[{"id":"1.170370564","rc":[{"atb":[[4.1,10.62]],"id":9630572},{"atl":[[4.8,2.02]],"id":9630572},{"atb":[[1.25,225.05]],"id":8509691},{"atl":[[1.32,2.11]],"id":8509691}],"con":true,"img":false}]}
{"op":"mcm","clk":"1362251626","pt":1588434263188,"mc":[{"id":"1.170370564","rc":[{"atb":[[4.1,12.95]],"id":9630572}],"con":true,"img":false}]}
{"op":"mcm","clk":"1362251632","pt":1588434263496,"mc":[{"id":"1.170370564","rc":[{"atb":[[4.1,10.91]],"id":9630572},{"atl":[[4.8,0]],"id":9630572},{"atb":[[1.25,223.04]],"id":8509691}],"con":true,"img":false}]}
{"op":"mcm","clk":"1362251635","pt":1588434263598,"mc":[{"id":"1.170370564","rc":[{"atl":[[1.32,0]],"id":8509691}],"con":true,"img":false}]}
{"op":"mcm","clk":"1362251640","pt":1588434263800,"mc":[{"id":"1.170370564","rc":[{"atb":[[4.1,12.95]],"id":9630572},{"atl":[[4.8,2.02]],"id":9630572},{"atb":[[1.25,225.05]],"id":8509691},{"atl":[[1.32,2.11]],"id":8509691}],"con":true,"img":false}]}
{"op":"mcm","clk":"1362251877","pt":1588434272875,"mc":[{"id":"1.170370564","rc":[{"atl":[[1.3,367.02]],"id":8509691}],"con":true,"img":false}]}
{"op":"mcm","clk":"1362251886","pt":1588434273183,"mc":[{"id":"1.170370564","rc":[{"atb":[[4.1,10.91]],"id":9630572},{"atl":[[4.8,0]],"id":9630572},{"atb":[[1.25,223.04]],"id":8509691},{"atl":[[1.32,0]],"id":8509691}],"con":true,"img":false}]}
{"op":"mcm","clk":"1362251891","pt":1588434273388,"mc":[{"id":"1.170370564","rc":[{"atb":[[4.1,12.95]],"id":9630572},{"atl":[[4.8,2.02]],"id":9630572},{"atb":[[1.25,225.05]],"id":8509691},{"atl":[[1.32,2.11]],"id":8509691}],"con":true,"img":false}]}
{"op":"mcm","clk":"1362252052","pt":1588434279023,"mc":[{"id":"1.170370564","rc":[{"trd":[[1.28,397.49]],"ltp":1.28,"tv":397.49,"id":8509691},{"atb":[[1.28,844.74]],"id":8509691}],"con":true,"img":false}]}
{"op":"mcm","clk":"1362252060","pt":1588434279333,"mc":[{"id":"1.170370564","rc":[{"atb":[[4.1,10.91]],"id":9630572},{"atl":[[4.8,0]],"id":9630572},{"atb":[[1.25,223.04]],"id":8509691},{"atl":[[1.32,0]],"id":8509691}],"con":true,"img":false}]}
{"op":"mcm","clk":"1362252066","pt":1588434279486,"mc":[{"id":"1.170370564","rc":[{"atb":[[4.1,12.95]],"id":9630572},{"atl":[[4.8,2.02]],"id":9630572},{"atb":[[1.25,225.05]],"id":8509691},{"atl":[[1.32,2.05]],"id":8509691}],"con":true,"img":false}]}
{"op":"mcm","clk":"1362252370","pt":1588434290535,"mc":[{"id":"1.170370564","rc":[{"trd":[[1.28,437.42]],"ltp":1.28,"tv":437.42,"id":8509691},{"atb":[[1.28,824.77]],"id":8509691}],"con":true,"img":false}]}
{"op":"mcm","clk":"1362252380","pt":1588434290844,"mc":[{"id":"1.170370564","rc":[{"atb":[[4.1,10.91]],"id":9630572},{"atl":[[4.8,0]],"id":9630572},{"atb":[[1.25,223.04]],"id":8509691},{"atl":[[1.32,0]],"id":8509691}],"con":true,"img":false}]}
{"op":"mcm","clk":"1362252388","pt":1588434291045,"mc":[{"id":"1.170370564","rc":[{"atb":[[4.1,12.94]],"id":9630572},{"atl":[[4.8,2.02]],"id":9630572},{"atb":[[1.25,225.05]],"id":8509691},{"atl":[[1.32,2.11]],"id":8509691}],"con":true,"img":false}]}
{"op":"mcm","clk":"1362253116","pt":1588434316232,"mc":[{"id":"1.170370564","rc":[{"atb":[[1.01,4101.75]],"id":8509691}],"con":true,"img":false}]}
{"op":"mcm","clk":"1362253124","pt":1588434316542,"mc":[{"id":"1.170370564","rc":[{"atb":[[4.1,10.91]],"id":9630572},{"atl":[[4.8,0]],"id":9630572},{"atb":[[1.25,223.04]],"id":8509691},{"atl":[[1.32,0]],"id":8509691}],"con":true,"img":false}]}
{"op":"mcm","clk":"1362253133","pt":1588434316750,"mc":[{"id":"1.170370564","rc":[{"atb":[[4.1,12.95]],"id":9630572},{"atl":[[4.8,2.02]],"id":9630572},{"atb":[[1.25,225.05]],"id":8509691},{"atl":[[1.32,2.11]],"id":8509691}],"con":true,"img":false}]}
{"op":"mcm","clk":"1362253344","pt":1588434324577,"mc":[{"id":"1.170370564","rc":[{"atb":[[1.02,3184.36]],"id":8509691}],"con":true,"img":false}]}
{"op":"mcm","clk":"1362253358","pt":1588434324887,"mc":[{"id":"1.170370564","rc":[{"atb":[[4.1,10.91]],"id":9630572},{"atl":[[4.8,0]],"id":9630572},{"atb":[[1.25,223.04]],"id":8509691},{"atl":[[1.32,0]],"id":8509691}],"con":true,"img":false}]}
{"op":"mcm","clk":"1362253363","pt":1588434325090,"mc":[{"id":"1.170370564","rc":[{"atb":[[4.1,12.95]],"id":9630572},{"atl":[[4.8,2.02]],"id":9630572},{"atb":[[1.25,225.05]],"id":8509691},{"atl":[[1.32,2.11]],"id":8509691}],"con":true,"img":false}]}
{"op":"mcm","clk":"1362253388","pt":1588434325958,"mc":[{"id":"1.170370564","rc":[{"trd":[[1.28,464.02]],"ltp":1.28,"tv":464.02,"id":8509691},{"atb":[[1.28,811.48]],"id":8509691}],"con":true,"img":false}]}
{"op":"mcm","clk":"1362253564","pt":1588434332172,"mc":[{"id":"1.170370564","rc":[{"atb":[[1.03,2505.53]],"id":8509691}],"con":true,"img":false}]}
{"op":"mcm","clk":"1362253573","pt":1588434332479,"mc":[{"id":"1.170370564","rc":[{"atb":[[4.1,10.91]],"id":9630572},{"atl":[[4.8,0]],"id":9630572},{"atb":[[1.25,223.04]],"id":8509691},{"atl":[[1.32,0]],"id":8509691}],"con":true,"img":false}]}
{"op":"mcm","clk":"1362253579","pt":1588434332683,"mc":[{"id":"1.170370564","rc":[{"atb":[[4.1,12.95]],"id":9630572},{"atl":[[4.8,2.02]],"id":9630572},{"atb":[[1.25,225.05]],"id":8509691},{"atl":[[1.32,2.11]],"id":8509691}],"con":true,"img":false}]}
{"op":"mcm","clk":"1362253783","pt":1588434339899,"mc":[{"id":"1.170370564","rc":[{"atb":[[1.04,1144.84]],"id":8509691}],"con":true,"img":false}]}
{"op":"mcm","clk":"1362253794","pt":1588434340201,"mc":[{"id":"1.170370564","rc":[{"atb":[[4.1,10.91]],"id":9630572},{"atl":[[4.8,0]],"id":9630572},{"atb":[[1.25,223.04]],"id":8509691}],"con":true,"img":false}]}
{"op":"mcm","clk":"1362253795","pt":1588434340254,"mc":[{"id":"1.170370564","rc":[{"atl":[[1.32,0]],"id":8509691}],"con":true,"img":false}]}
{"op":"mcm","clk":"1362253798","pt":1588434340355,"mc":[{"id":"1.170370564","rc":[{"atb":[[4.1,12.95]],"id":9630572},{"atl":[[4.8,2.02]],"id":9630572},{"atb":[[1.25,225.05]],"id":8509691}],"con":true,"img":false}]}
{"op":"mcm","clk":"1362253803","pt":1588434340458,"mc":[{"id":"1.170370564","rc":[{"atl":[[1.32,2.11]],"id":8509691}],"con":true,"img":false}]}
{"op":"mcm","clk":"1362254004","pt":1588434347572,"mc":[{"id":"1.170370564","rc":[{"atb":[[1.05,902.8]],"id":8509691}],"con":true,"img":false}]}
{"op":"mcm","clk":"1362254018","pt":1588434347878,"mc":[{"id":"1.170370564","rc":[{"atb":[[4.1,10.91]],"id":9630572},{"atl":[[4.8,0]],"id":9630572},{"atb":[[1.25,223.04]],"id":8509691},{"atl":[[1.32,0]],"id":8509691}],"con":true,"img":false}]}
{"op":"mcm","clk":"1362254027","pt":1588434348081,"mc":[{"id":"1.170370564","rc":[{"atb":[[4.1,12.95]],"id":9630572},{"atl":[[4.8,2.02]],"id":9630572},{"atb":[[1.25,225.05]],"id":8509691},{"atl":[[1.32,2.11]],"id":8509691}],"con":true,"img":false}]}
{"op":"mcm","clk":"1362254217","pt":1588434354688,"mc":[{"id":"1.170370564","rc":[{"atb":[[1.06,984.87]],"id":8509691}],"con":true,"img":false}]}
{"op":"mcm","clk":"1362254228","pt":1588434354995,"mc":[{"id":"1.170370564","rc":[{"atb":[[4.1,10.91]],"id":9630572},{"atl":[[4.8,0]],"id":9630572},{"atb":[[1.25,223.04]],"id":8509691},{"atl":[[1.32,0]],"id":8509691}],"con":true,"img":false}]}
{"op":"mcm","clk":"1362254236","pt":1588434355201,"mc":[{"id":"1.170370564","rc":[{"atb":[[4.1,12.95]],"id":9630572},{"atl":[[4.8,2.02]],"id":9630572},{"atb":[[1.25,225.05]],"id":8509691},{"atl":[[1.32,2.11]],"id":8509691}],"con":true,"img":false}]}
{"op":"mcm","clk":"1362254338","pt":1588434358930,"mc":[{"id":"1.170370564","rc":[{"trd":[[1.29,1022]],"ltp":1.29,"tv":1022.0,"id":8509691},{"atl":[[1.29,216.89]],"id":8509691}],"con":true,"img":false}]}
{"op":"mcm","clk":"1362254955","pt":1588434378947,"mc":[{"id":"1.170370564","rc":[{"atl":[[1.29,269.37]],"id":8509691}],"con":true,"img":false}]}
{"op":"mcm","clk":"1362254961","pt":1588434379255,"mc":[{"id":"1.170370564","rc":[{"atb":[[4.1,10.91]],"id":9630572},{"atl":[[4.8,0]],"id":9630572},{"atb":[[1.25,223.04]],"id":8509691},{"atl":[[1.32,0]],"id":8509691}],"con":true,"img":false}]}
{"op":"mcm","clk":"1362254969","pt":1588434379464,"mc":[{"id":"1.170370564","rc":[{"atb":[[4.1,12.95]],"id":9630572},{"atl":[[4.8,2]],"id":9630572},{"atb":[[1.25,225.05]],"id":8509691},{"atl":[[1.32,2.11]],"id":8509691}],"con":true,"img":false}]}
{"op":"mcm","clk":"1362255078","pt":1588434382943,"mc":[{"id":"1.170370564","rc":[{"trd":[[1.28,664.02]],"ltp":1.28,"tv":664.02,"id":8509691},{"atb":[[1.28,711.48]],"id":8509691}],"con":true,"img":false}]}
{"op":"mcm","clk":"1362255142","pt":1588434384832,"mc":[{"id":"1.170370564","rc":[{"atb":[[4.1,10.62]],"id":9630572}],"con":true,"img":false}]}
{"op":"mcm","clk":"1362255155","pt":1588434385143,"mc":[{"id":"1.170370564","rc":[{"atb":[[4.1,8.58]],"id":9630572},{"atl":[[4.8,0]],"id":9630572},{"atb":[[1.25,223.04]],"id":8509691},{"atl":[[1.32,0]],"id":8509691}],"con":true,"img":false}]}
{"op":"mcm","clk":"1362255161","pt":1588434385349,"mc":[{"id":"1.170370564","rc":[{"atb":[[4.1,10.62]],"id":9630572},{"atl":[[4.8,2.02]],"id":9630572},{"atb":[[1.25,225.05]],"id":8509691},{"atl":[[1.32,2.08]],"id":8509691}],"con":true,"img":false}]}
{"op":"mcm","clk":"1362255360","pt":1588434391851,"mc":[{"id":"1.170370564","rc":[{"atb":[[4.4,29.25]],"id":9630572}],"con":true,"img":false}]}
{"op":"mcm","clk":"1362255366","pt":1588434392160,"mc":[{"id":"1.170370564","rc":[{"atb":[[4.1,8.58]],"id":9630572},{"atl":[[4.8,0]],"id":9630572},{"atb":[[1.25,223.04]],"id":8509691},{"atl":[[1.32,0]],"id":8509691}],"con":true,"img":false}]}
{"op":"mcm","clk":"1362255372","pt":1588434392362,"mc":[{"id":"1.170370564","rc":[{"atb":[[4.1,10.62]],"id":9630572},{"atl":[[4.8,2.02]],"id":9630572},{"atb":[[1.25,225.05]],"id":8509691},{"atl":[[1.32,2.05]],"id":8509691}],"con":true,"img":false}]}
{"op":"mcm","clk":"1362255379","pt":1588434392778,"mc":[{"id":"1.170370564","rc":[{"atb":[[4.1,12.95]],"id":9630572}],"con":true,"img":false}]}
{"op":"mcm","clk":"1362255479","pt":1588434396458,"mc":[{"id":"1.170370564","rc":[{"atb":[[3.5,0]],"id":9630572},{"atb":[[1.25,2.01]],"id":8509691}],"con":true,"img":false}]}
{"op":"mcm","clk":"1362255864","pt":1588434410010,"mc":[{"id":"1.170370566","rc":[{"atb":[[3,1.74]],"id":9630572}],"con":true,"img":false}]}
{"op":"mcm","clk":"1362256615","pt":1588434438556,"mc":[{"id":"1.170370564","rc":[{"trd":[[1.29,1023.05]],"ltp":1.29,"tv":1023.05,"id":8509691},{"atl":[[1.29,268.85]],"id":8509691}],"con":true,"img":false}]}
{"op":"mcm","clk":"1362256622","pt":1588434438819,"mc":[{"id":"1.170370564","rc":[{"atb":[[4.1,10.91]],"id":9630572},{"atl":[[4.8,0]],"id":9630572},{"atb":[[1.25,0]],"id":8509691},{"atl":[[1.32,0]],"id":8509691}],"con":true,"img":false}]}
{"op":"mcm","clk":"1362256628","pt":1588434439020,"mc":[{"id":"1.170370564","rc":[{"atb":[[4.1,12.95]],"id":9630572},{"atl":[[4.8,2.02]],"id":9630572},{"atb":[[1.25,2.01]],"id":8509691},{"atl":[[1.32,2.11]],"id":8509691}],"con":true,"img":false}]}
{"op":"mcm","clk":"1362256921","pt":1588434450069,"mc":[{"id":"1.170370566","rc":[{"atb":[[3,0]],"id":9630572}],"con":true,"img":false}]}
{"op":"mcm","clk":"1362258099","pt":1588434496623,"mc":[{"id":"1.170370564","rc":[{"atb":[[4.1,10.62]],"id":9630572}],"con":true,"img":false}]}
{"op":"mcm","clk":"1362258105","pt":1588434496827,"mc":[{"id":"1.170370564","rc":[{"atb":[[4.1,8.58]],"id":9630572},{"atl":[[4.8,0]],"id":9630572},{"atb":[[1.25,0]],"id":8509691},{"atl":[[1.32,0]],"id":8509691}],"con":true,"img":false}]}
{"op":"mcm","clk":"1362258109","pt":1588434497031,"mc":[{"id":"1.170370564","rc":[{"atb":[[4.1,10.62]],"id":9630572},{"atl":[[4.8,2.02]],"id":9630572},{"atb":[[1.25,2.01]],"id":8509691},{"atl":[[1.32,2]],"id":8509691}],"con":true,"img":false}]}
{"op":"mcm","clk":"1362258596","pt":1588434514861,"mc":[{"id":"1.170370564","rc":[{"atb":[[4.1,12.95]],"id":9630572}],"con":true,"img":false}]}
{"op":"mcm","clk":"1362258604","pt":1588434515169,"mc":[{"id":"1.170370564","rc":[{"atb":[[4.1,10.91]],"id":9630572},{"atl":[[4.8,0]],"id":9630572},{"atb":[[1.25,0]],"id":8509691},{"atl":[[1.32,0]],"id":8509691}],"con":true,"img":false}]}
{"op":"mcm","clk":"1362258612","pt":1588434515373,"mc":[{"id":"1.170370564","rc":[{"atb":[[4.1,12.95]],"id":9630572},{"atl":[[4.8,2.02]],"id":9630572},{"atb":[[1.25,2.01]],"id":8509691},{"atl":[[1.32,2.05]],"id":8509691}],"con":true,"img":false}]}
{"op":"mcm","clk":"1362259175","pt":1588434537399,"mc":[{"id":"1.170370564","rc":[{"trd":[[4.5,254.99]],"ltp":4.5,"tv":254.99,"id":9630572},{"atl":[[4.5,0]],"id":9630572}],"con":true,"img":false}]}
{"op":"mcm","clk":"1362259179","pt":1588434537606,"mc":[{"id":"1.170370564","rc":[{"atl":[[4.9,2.05]],"id":9630572}],"con":true,"img":false}]}
{"op":"mcm","clk":"1362259182","pt":1588434537706,"mc":[{"id":"1.170370564","rc":[{"atl":[[4.7,0]],"id":9630572},{"atb":[[1.25,0]],"id":8509691},{"atl":[[1.32,0]],"id":8509691}],"con":true,"img":false}]}
{"op":"mcm","clk":"1362259191","pt":1588434537911,"mc":[{"id":"1.170370564","rc":[{"atb":[[4.1,10.91]],"id":9630572}],"con":true,"img":false}]}
{"op":"mcm","clk":"1362259197","pt":1588434538062,"mc":[{"id":"1.170370564","rc":[{"atb":[[4.1,12.95]],"id":9630572},{"atb":[[1.25,2.01]],"id":8509691},{"atl":[[1.32,2.11]],"id":8509691}],"con":true,"img":false}]}
{"op":"mcm","clk":"1362259443","pt":1588434547591,"mc":[{"id":"1.170370564","rc":[{"trd":[[1.29,1024.47]],"ltp":1.29,"tv":1024.47,"id":8509691},{"atl":[[1.29,268.14]],"id":8509691}],"con":true,"img":false}]}
{"op":"mcm","clk":"1362259452","pt":1588434547899,"mc":[{"id":"1.170370564","rc":[{"atb":[[4.1,10.91]],"id":9630572},{"atl":[[4.9,0]],"id":9630572},{"atb":[[1.25,0]],"id":8509691},{"atl":[[1.32,0]],"id":8509691}],"con":true,"img":false}]}
{"op":"mcm","clk":"1362259458","pt":1588434548103,"mc":[{"id":"1.170370564","rc":[{"atb":[[4.1,12.95]],"id":9630572},{"atl":[[4.9,2.05]],"id":9630572},{"atb":[[1.25,2.01]],"id":8509691},{"atl":[[1.32,2.11]],"id":8509691}],"con":true,"img":false}]}
{"op":"mcm","clk":"1362259464","pt":1588434548308,"mc":[{"id":"1.170370564","rc":[{"atl":[[1.29,99.08]],"id":8509691}],"con":true,"img":false}]}
{"op":"mcm","clk":"1362259515","pt":1588434549989,"mc":[{"id":"1.170370564","rc":[{"atb":[[1.24,88.65]],"id":8509691}],"con":true,"img":false}]}
{"op":"mcm","clk":"1362259517","pt":1588434550093,"mc":[{"id":"1.170370564","rc":[{"atb":[[1.28,711.88]],"id":8509691}],"con":true,"img":false}]}
{"op":"mcm","clk":"1362260145","pt":1588434573955,"mc":[{"id":"1.170370564","rc":[{"atb":[[4.5,48.3]],"id":9630572}],"con":true,"img":false}]}
{"op":"mcm","clk":"1362260151","pt":1588434574159,"mc":[{"id":"1.170370564","rc":[{"atb":[[4.3,2.01]],"id":9630572}],"con":true,"img":false}]}
{"op":"mcm","clk":"1362260154","pt":1588434574261,"mc":[{"id":"1.170370564","rc":[{"atb":[[4.1,10.91]],"id":9630572},{"atl":[[4.9,0]],"id":9630572},{"atb":[[1.25,0]],"id":8509691},{"atl":[[1.32,0]],"id":8509691}],"con":true,"img":false}]}
{"op":"mcm","clk":"1362260158","pt":1588434574312,"mc":[{"id":"1.170370564","rc":[{"atb":[[4.3,10.06]],"id":9630572}],"con":true,"img":false}]}
{"op":"mcm","clk":"1362260159","pt":1588434574466,"mc":[{"id":"1.170370564","rc":[{"atb":[[4.2,8.31]],"id":9630572},{"atb":[[1.24,0]],"id":8509691}],"con":true,"img":false}]}
{"op":"mcm","clk":"1362260165","pt":1588434574620,"mc":[{"id":"1.170370564","rc":[{"atb":[[4.2,10.33]],"id":9630572},{"atl":[[4.9,2.05]],"id":9630572},{"atb":[[1.25,2.01]],"id":8509691},{"atl":[[1.32,2.08]],"id":8509691}],"con":true,"img":false}]}
{"op":"mcm","clk":"1362260358","pt":1588434583055,"mc":[{"id":"1.170370564","rc":[{"trd":[[1.28,668.02]],"ltp":1.28,"tv":668.02,"id":8509691},{"atb":[[1.28,709.87]],"id":8509691}],"con":true,"img":false}]}
{"op":"mcm","clk":"1362260367","pt":1588434583360,"mc":[{"id":"1.170370564","rc":[{"atb":[[4.2,8.31]],"id":9630572},{"atl":[[4.9,0]],"id":9630572},{"atb":[[1.25,0]],"id":8509691},{"atl":[[1.32,0]],"id":8509691}],"con":true,"img":false}]}
{"op":"mcm","clk":"1362260374","pt":1588434583564,"mc":[{"id":"1.170370564","rc":[{"atb":[[4.2,10.33]],"id":9630572},{"atl":[[4.9,2.05]],"id":9630572},{"atb":[[1.25,2.01]],"id":8509691},{"atl":[[1.32,2.11]],"id":8509691}],"con":true,"img":false}]}
{"op":"mcm","clk":"1362260596","pt":1588434593772,"mc":[{"id":"1.170370565","rc":[{"atl":[[5,5]],"id":11269557}],"con":true,"img":false}]}
{"op":"mcm","clk":"1362260779","pt":1588434601586,"mc":[{"id":"1.170370566","rc":[{"trd":[[3.5,39.42]],"ltp":3.5,"tv":39.42,"id":9630572},{"trd":[[1.4,98.57]],"ltp":1.4,"tv":98.57,"id":8509691},{"atb":[[1.4,80.75]],"id":8509691}],"con":true,"img":false}]}
{"op":"mcm","clk":"1362260811","pt":1588434602870,"mc":[{"id":"1.170370564","rc":[{"trd":[[1.28,714.02]],"ltp":1.28,"tv":714.02,"id":8509691},{"atb":[[1.28,686.88]],"id":8509691}],"con":true,"img":false}]}
{"op":"mcm","clk":"1362260820","pt":1588434603182,"mc":[{"id":"1.170370564","rc":[{"atb":[[4.2,8.31]],"id":9630572},{"atl":[[4.9,0]],"id":9630572},{"atb":[[1.25,0]],"id":8509691},{"atl":[[1.32,0]],"id":8509691}],"con":true,"img":false}]}
{"op":"mcm","clk":"1362260824","pt":1588434603385,"mc":[{"id":"1.170370564","rc":[{"atb":[[4.2,10.31]],"id":9630572},{"atl":[[4.9,2.05]],"id":9630572},{"atb":[[1.25,2.01]],"id":8509691},{"atl":[[1.32,2.11]],"id":8509691}],"con":true,"img":false}]}
{"op":"mcm","clk":"1362260898","pt":1588434606066,"mc":[{"id":"1.170370566","rc":[{"atb":[[1.4,211.5]],"id":8509691}],"con":true,"img":false}]}
{"op":"mcm","clk":"1362260901","pt":1588434606170,"mc":[{"id":"1.170370566","rc":[{"atb":[[1.4,130.75]],"id":8509691}],"con":true,"img":false}]}
{"op":"mcm","clk":"1362261069","pt":1588434613569,"mc":[{"id":"1.170370565","rc":[{"atb":[[1.92,10]],"id":11269555}],"con":true,"img":false}]}
{"op":"mcm","clk":"1362261126","pt":1588434616277,"mc":[{"id":"1.170370564","rc":[{"atb":[[4.1,8.58]],"id":9630572}],"con":true,"img":false}]}
{"op":"mcm","clk":"1362261135","pt":1588434616583,"mc":[{"id":"1.170370564","rc":[{"atb":[[4.2,8.31]],"id":9630572},{"atl":[[4.9,0]],"id":9630572},{"atb":[[1.25,0]],"id":8509691},{"atl":[[1.32,0]],"id":8509691}],"con":true,"img":false}]}
{"op":"mcm","clk":"1362261141","pt":1588434616789,"mc":[{"id":"1.170370564","rc":[{"atb":[[4.2,10.33]],"id":9630572},{"atl":[[4.9,2.05]],"id":9630572},{"atb":[[1.25,2.01]],"id":8509691},{"atl":[[1.32,2.11]],"id":8509691}],"con":true,"img":false}]}
{"op":"mcm","clk":"1362261250","pt":1588434622207,"mc":[{"id":"1.170370564","rc":[{"atb":[[1.02,161.64]],"id":9630572},{"atb":[[1.02,3185.82]],"id":8509691}],"con":true,"img":false}]}
{"op":"mcm","clk":"1362261256","pt":1588434622511,"mc":[{"id":"1.170370564","rc":[{"atb":[[4.2,8.31]],"id":9630572},{"atl":[[4.9,0]],"id":9630572},{"atb":[[1.25,0]],"id":8509691},{"atl":[[1.32,0]],"id":8509691}],"con":true,"img":false}]}
{"op":"mcm","clk":"1362261260","pt":1588434622717,"mc":[{"id":"1.170370564","rc":[{"atb":[[4.2,10.33]],"id":9630572},{"atl":[[4.9,2.05]],"id":9630572},{"atb":[[1.25,2.01]],"id":8509691},{"atl":[[1.32,2.11]],"id":8509691}],"con":true,"img":false}]}
{"op":"mcm","clk":"1362261270","pt":1588434623225,"mc":[{"id":"1.170370564","rc":[{"atl":[[1000,1.47]],"id":9630572},{"atl":[[1000,1.47]],"id":8509691}],"con":true,"img":false}]}
{"op":"mcm","clk":"1362261274","pt":1588434623326,"mc":[{"id":"1.170370564","rc":[{"atb":[[1.01,16.74]],"id":9630572},{"atl":[[1000,2.94]],"id":8509691}],"con":true,"img":false}]}
{"op":"mcm","clk":"1362261277","pt":1588434623377,"mc":[{"id":"1.170370564","rc":[{"atl":[[1000,2.94]],"id":9630572}],"con":true,"img":false}]}
{"op":"mcm","clk":"1362261279","pt":1588434623481,"mc":[{"id":"1.170370564","rc":[{"atb":[[1.01,4103.7]],"id":8509691}],"con":true,"img":false}]}
{"op":"mcm","clk":"1362261288","pt":1588434623891,"mc":[{"id":"1.170370564","rc":[{"atl":[[1000,1.48]],"id":9630572},{"atl":[[1000,1.48]],"id":8509691}],"con":true,"img":false}]}
{"op":"mcm","clk":"1362261291","pt":1588434623995,"mc":[{"id":"1.170370564","rc":[{"atb":[[1.01,15.28],[4.1,10.91]],"id":9630572},{"atl":[[1000,0.02]],"id":8509691}],"con":true,"img":false}]}
{"op":"mcm","clk":"1362261294","pt":1588434624198,"mc":[{"id":"1.170370564","rc":[{"atl":[[1000,0.02]],"id":9630572}],"con":true,"img":false}]}
{"op":"mcm","clk":"1362261297","pt":1588434624301,"mc":[{"id":"1.170370564","rc":[{"atb":[[1.01,4102.24]],"id":8509691}],"con":true,"img":false}]}
{"op":"mcm","clk":"1362261306","pt":1588434624610,"mc":[{"id":"1.170370564","rc":[{"atl":[[1000,0.01]],"id":9630572},{"atl":[[1000,0.01]],"id":8509691}],"con":true,"img":false}]}
{"op":"mcm","clk":"1362261310","pt":1588434624710,"mc":[{"id":"1.170370564","rc":[{"atb":[[1.01,14.79]],"id":9630572},{"atl":[[20,0.01]],"id":9630572},{"atl":[[10,0.01],[1000,0]],"id":8509691}],"con":true,"img":false}]}
{"op":"mcm","clk":"1362261312","pt":1588434624814,"mc":[{"id":"1.170370564","rc":[{"atb":[[1.03,3.48]],"id":9630572},{"atl":[[20,0.01]],"id":8509691}],"con":true,"img":false}]}
{"op":"mcm","clk":"1362261318","pt":1588434624915,"mc":[{"id":"1.170370564","rc":[{"atl":[[1000,0]],"id":9630572}],"con":true,"img":false}]}
{"op":"mcm","clk":"1362261322","pt":1588434625018,"mc":[{"id":"1.170370564","rc":[{"atl":[[10,0.01]],"id":9630572},{"atb":[[1.01,4101.75]],"id":8509691}],"con":true,"img":false}]}
{"op":"mcm","clk":"1362261325","pt":1588434625119,"mc":[{"id":"1.170370564","rc":[{"atb":[[1.03,2506.01]],"id":8509691}],"con":true,"img":false}]}
{"op":"mcm","clk":"1362261380","pt":1588434628129,"mc":[{"id":"1.170370564","rc":[{"atl":[[1.34,0]],"id":8509691}],"con":true,"img":false}]}
{"op":"mcm","clk":"1362261391","pt":1588434628434,"mc":[{"id":"1.170370564","rc":[{"atb":[[4.2,8.31]],"id":9630572},{"atl":[[4.9,0]],"id":9630572},{"atb":[[1.25,0]],"id":8509691},{"atl":[[1.32,0]],"id":8509691}],"con":true,"img":false}]}
{"op":"mcm","clk":"1362261398","pt":1588434628639,"mc":[{"id":"1.170370564","rc":[{"atb":[[4.2,10.33]],"id":9630572},{"atl":[[4.9,2.05]],"id":9630572},{"atb":[[1.25,2.01]],"id":8509691},{"atl":[[1.32,2.11]],"id":8509691}],"con":true,"img":false}]}
{"op":"mcm","clk":"1362261492","pt":1588434632930,"mc":[{"id":"1.170370565","rc":[{"atb":[[2.1,4.54]],"id":11269555}],"con":true,"img":false}]}
{"op":"mcm","clk":"1362261588","pt":1588434637326,"mc":[{"id":"1.170370564","rc":[{"atl":[[1.31,25.54]],"id":8509691}],"con":true,"img":false}]}
{"op":"mcm","clk":"1362261596","pt":1588434637631,"mc":[{"id":"1.170370564","rc":[{"atb":[[4.2,8.31]],"id":9630572},{"atl":[[4.9,0]],"id":9630572},{"atb":[[1.25,0]],"id":8509691},{"atl":[[1.32,0]],"id":8509691}],"con":true,"img":false}]}
{"op":"mcm","clk":"1362261601","pt":1588434637835,"mc":[{"id":"1.170370564","rc":[{"atb":[[4.2,10.33]],"id":9630572},{"atl":[[4.9,2.05]],"id":9630572},{"atb":[[1.25,2.01]],"id":8509691},{"atl":[[1.32,2.11]],"id":8509691}],"con":true,"img":false}]}
{"op":"mcm","clk":"1362261884","pt":1588434649222,"mc":[{"id":"1.170370565","rc":[{"atb":[[2.1,0]],"id":11269555}],"con":true,"img":false}]}
{"op":"mcm","clk":"1362262081","pt":1588434656527,"mc":[{"id":"1.170370564","rc":[{"trd":[[1.28,724.02]],"ltp":1.28,"tv":724.02,"id":8509691},{"atb":[[1.28,681.88]],"id":8509691}],"con":true,"img":false}]}
{"op":"mcm","clk":"1362262088","pt":1588434656833,"mc":[{"id":"1.170370564","rc":[{"atb":[[4.2,8.31]],"id":9630572},{"atl":[[4.9,0]],"id":9630572},{"atb":[[1.25,0]],"id":8509691},{"atl":[[1.32,0]],"id":8509691}],"con":true,"img":false}]}
{"op":"mcm","clk":"1362262094","pt":1588434657037,"mc":[{"id":"1.170370564","rc":[{"atb":[[4.2,10.33]],"id":9630572},{"atl":[[4.9,2.05]],"id":9630572},{"atb":[[1.25,2.01]],"id":8509691},{"atl":[[1.32,2.11]],"id":8509691}],"con":true,"img":false}]}
{"op":"mcm","clk":"1362262394","pt":1588434668791,"mc":[{"id":"1.170370564","rc":[{"trd":[[1.28,750.61]],"ltp":1.28,"tv":750.61,"id":8509691},{"atb":[[1.28,668.58]],"id":8509691}],"con":true,"img":false}]}
{"op":"mcm","clk":"1362262402","pt":1588434669094,"mc":[{"id":"1.170370564","rc":[{"atb":[[4.2,8.31]],"id":9630572},{"atl":[[4.9,0]],"id":9630572},{"atb":[[1.25,0]],"id":8509691},{"atl":[[1.32,0]],"id":8509691}],"con":true,"img":false}]}
{"op":"mcm","clk":"1362262404","pt":1588434669299,"mc":[{"id":"1.170370564","rc":[{"atb":[[4.2,10.33]],"id":9630572},{"atl":[[4.9,2.05]],"id":9630572},{"atb":[[1.25,2.01]],"id":8509691},{"atl":[[1.32,2.11]],"id":8509691}],"con":true,"img":false}]}
{"op":"mcm","clk":"1362262768","pt":1588434684510,"mc":[{"id":"1.170370564","rc":[{"trd":[[1.29,1040.19]],"ltp":1.29,"tv":1040.19,"id":8509691},{"atl":[[1.29,91.22]],"id":8509691}],"con":true,"img":false}]}
{"op":"mcm","clk":"1362262777","pt":1588434684817,"mc":[{"id":"1.170370564","rc":[{"atb":[[4.2,8.31]],"id":9630572},{"atl":[[4.9,0]],"id":9630572},{"atb":[[1.25,0]],"id":8509691},{"atl":[[1.32,0]],"id":8509691}],"con":true,"img":false}]}
{"op":"mcm","clk":"1362262783","pt":1588434685021,"mc":[{"id":"1.170370564","rc":[{"atb":[[4.2,10.33]],"id":9630572},{"atl":[[4.9,2.05]],"id":9630572},{"atb":[[1.25,2.01]],"id":8509691},{"atl":[[1.32,2.11]],"id":8509691}],"con":true,"img":false}]}
{"op":"mcm","clk":"1362263674","pt":1588434721243,"mc":[{"id":"1.170370564","rc":[{"trd":[[4.6,4.12]],"ltp":4.6,"tv":4.12,"id":9630572},{"trd":[[1.28,758.42]],"ltp":1.28,"tv":758.42,"id":8509691},{"atb":[[1.28,660.77]],"id":8509691}],"con":true,"img":false}]}
{"op":"mcm","clk":"1362263686","pt":1588434721550,"mc":[{"id":"1.170370564","rc":[{"atb":[[4.2,8.31]],"id":9630572},{"atl":[[4.9,0]],"id":9630572},{"atb":[[1.25,0]],"id":8509691},{"atl":[[1.32,0]],"id":8509691}],"con":true,"img":false}]}
{"op":"mcm","clk":"1362263692","pt":1588434721755,"mc":[{"id":"1.170370564","rc":[{"atb":[[4.2,10.33]],"id":9630572},{"atl":[[4.9,2.05]],"id":9630572},{"atb":[[1.25,2.01]],"id":8509691},{"atl":[[1.32,2.08]],"id":8509691}],"con":true,"img":false}]}
{"op":"mcm","clk":"1362263790","pt":1588434725755,"mc":[{"id":"1.170370566","rc":[{"trd":[[3.5,91.42]],"ltp":3.5,"tv":91.42,"id":9630572},{"trd":[[1.4,228.57]],"ltp":1.4,"tv":228.57,"id":8509691},{"atb":[[1.4,0.75]],"id":8509691}],"con":true,"img":false}]}
{"op":"mcm","clk":"1362263819","pt":1588434726574,"mc":[{"id":"1.170370566","rc":[{"atb":[[1.31,168.71]],"id":8509691}],"con":true,"img":false}]}
{"op":"mcm","clk":"1362263823","pt":1588434726676,"mc":[{"id":"1.170370566","rc":[{"atb":[[1.4,0]],"id":8509691}],"con":true,"img":false}]}
{"op":"mcm","clk":"1362264050","pt":1588434735651,"mc":[{"id":"1.170370564","rc":[{"atb":[[4.1,8.58]],"id":9630572}],"con":true,"img":false}]}
{"op":"mcm","clk":"1362264060","pt":1588434735956,"mc":[{"id":"1.170370564","rc":[{"atb":[[4.2,8.31]],"id":9630572},{"atl":[[4.9,0]],"id":9630572},{"atb":[[1.25,0]],"id":8509691},{"atl":[[1.32,0]],"id":8509691}],"con":true,"img":false}]}
{"op":"mcm","clk":"1362264065","pt":1588434736161,"mc":[{"id":"1.170370564","rc":[{"atb":[[4.2,10.33]],"id":9630572},{"atl":[[4.9,2.05]],"id":9630572},{"atb":[[1.25,2.01]],"id":8509691},{"atl":[[1.32,2.05]],"id":8509691}],"con":true,"img":false}]}
{"op":"mcm","clk":"1362264240","pt":1588434743458,"mc":[{"id":"1.170370564","rc":[{"atb":[[4.1,10.91]],"id":9630572}],"con":true,"img":false}]}
{"op":"mcm","clk":"1362264246","pt":1588434743661,"mc":[{"id":"1.170370564","rc":[{"atb":[[4.2,8.31]],"id":9630572},{"atl":[[4.9,0]],"id":9630572},{"atb":[[1.25,0]],"id":8509691},{"atl":[[1.32,0]],"id":8509691}],"con":true,"img":false}]}
{"op":"mcm","clk":"1362264248","pt":1588434743865,"mc":[{"id":"1.170370564","rc":[{"atb":[[4.2,10.31]],"id":9630572},{"atl":[[4.9,2.05]],"id":9630572},{"atb":[[1.25,2.01]],"id":8509691},{"atl":[[1.32,2.11]],"id":8509691}],"con":true,"img":false}]}
{"op":"mcm","clk":"1362264460","pt":1588434754371,"mc":[{"id":"1.170370564","rc":[{"trd":[[1.28,817.27]],"ltp":1.28,"tv":817.27,"id":8509691},{"atb":[[1.28,631.34]],"id":8509691}],"con":true,"img":false}]}
{"op":"mcm","clk":"1362264465","pt":1588434754679,"mc":[{"id":"1.170370564","rc":[{"atb":[[4.2,8.31]],"id":9630572},{"atl":[[4.9,0]],"id":9630572},{"atb":[[1.25,0]],"id":8509691},{"atl":[[1.32,0]],"id":8509691}],"con":true,"img":false}]}
{"op":"mcm","clk":"1362264468","pt":1588434754882,"mc":[{"id":"1.170370564","rc":[{"atb":[[4.2,10.33]],"id":9630572},{"atl":[[4.9,2.05]],"id":9630572},{"atb":[[1.25,2.01]],"id":8509691},{"atl":[[1.32,2.11]],"id":8509691}],"con":true,"img":false}]}
{"op":"mcm","clk":"1362264682","pt":1588434763506,"mc":[{"id":"1.170370564","rc":[{"trd":[[1.28,1042.84]],"ltp":1.28,"tv":1042.84,"id":8509691},{"atb":[[1.28,518.56]],"id":8509691}],"con":true,"img":false}]}
{"op":"mcm","clk":"1362264691","pt":1588434763810,"mc":[{"id":"1.170370564","rc":[{"atb":[[4.2,8.31]],"id":9630572},{"atl":[[4.9,0]],"id":9630572},{"atb":[[1.25,0]],"id":8509691},{"atl":[[1.32,0]],"id":8509691}],"con":true,"img":false}]}
{"op":"mcm","clk":"1362264694","pt":1588434764016,"mc":[{"id":"1.170370564","rc":[{"atb":[[4.2,10.33]],"id":9630572},{"atl":[[4.9,2.05]],"id":9630572},{"atb":[[1.25,2.01]],"id":8509691},{"atl":[[1.32,2.02]],"id":8509691}],"con":true,"img":false}]}
{"op":"mcm","clk":"1362265942","pt":1588434818163,"mc":[{"id":"1.170370564","rc":[{"atb":[[4.5,0]],"id":9630572}],"con":true,"img":false}]}
{"op":"mcm","clk":"1362265946","pt":1588434818366,"mc":[{"id":"1.170370564","rc":[{"atb":[[4.1,12.95]],"id":9630572}],"con":true,"img":false}]}
{"op":"mcm","clk":"1362265948","pt":1588434818467,"mc":[{"id":"1.170370564","rc":[{"atl":[[4.9,0]],"id":9630572},{"atb":[[1.25,0]],"id":8509691},{"atl":[[1.32,0]],"id":8509691}],"con":true,"img":false}]}
{"op":"mcm","clk":"1362265950","pt":1588434818569,"mc":[{"id":"1.170370564","rc":[{"atb":[[4.3,8.05]],"id":9630572}],"con":true,"img":false}]}
{"op":"mcm","clk":"1362265954","pt":1588434818672,"mc":[{"id":"1.170370564","rc":[{"atl":[[4.9,2.05]],"id":9630572},{"atb":[[1.25,2.01]],"id":8509691},{"atl":[[1.32,2.11]],"id":8509691}],"con":true,"img":false}]}
{"op":"mcm","clk":"1362265968","pt":1588434819386,"mc":[{"id":"1.170370564","rc":[{"atb":[[1.24,88.65]],"id":8509691}],"con":true,"img":false}]}
{"op":"mcm","clk":"1362265971","pt":1588434819499,"mc":[{"id":"1.170370564","rc":[{"atb":[[4.3,0]],"id":9630572}],"con":true,"img":false}]}
{"op":"mcm","clk":"1362266224","pt":1588434830302,"mc":[{"id":"1.170370564","rc":[{"trd":[[1.28,1546.67]],"ltp":1.28,"tv":1546.67,"id":8509691},{"atb":[[1.28,266.64]],"id":8509691}],"con":true,"img":false}]}
{"op":"mcm","clk":"1362266235","pt":1588434830607,"mc":[{"id":"1.170370564","rc":[{"atb":[[4.1,10.91]],"id":9630572},{"atl":[[4.9,0]],"id":9630572},{"atb":[[1.25,0]],"id":8509691},{"atl":[[1.32,0]],"id":8509691}],"con":true,"img":false}]}
{"op":"mcm","clk":"1362266239","pt":1588434830812,"mc":[{"id":"1.170370564","rc":[{"atb":[[4.1,12.95]],"id":9630572},{"atl":[[4.9,2.05]],"id":9630572},{"atb":[[1.25,2.01]],"id":8509691},{"atl":[[1.32,2.11]],"id":8509691}],"con":true,"img":false}]}
{"op":"mcm","clk":"1362266264","pt":1588434831782,"mc":[{"id":"1.170370564","rc":[{"trd":[[1.28,1884.79]],"ltp":1.28,"tv":1884.79,"id":8509691},{"atb":[[1.28,97.58]],"id":8509691}],"con":true,"img":false}]}
{"op":"mcm","clk":"1362266491","pt":1588434842028,"mc":[{"id":"1.170370564","rc":[{"atb":[[1.28,403.58]],"id":8509691}],"con":true,"img":false}]}
{"op":"mcm","clk":"1362266495","pt":1588434842285,"mc":[{"id":"1.170370564","rc":[{"atb":[[4.1,10.91]],"id":9630572},{"atl":[[4.9,0]],"id":9630572},{"atb":[[1.25,0]],"id":8509691},{"atl":[[1.32,0]],"id":8509691}],"con":true,"img":false}]}
{"op":"mcm","clk":"1362266502","pt":1588434842490,"mc":[{"id":"1.170370564","rc":[{"atb":[[4.1,12.95]],"id":9630572},{"atl":[[4.9,2.05]],"id":9630572},{"atb":[[1.25,2.01]],"id":8509691},{"atl":[[1.32,2.11]],"id":8509691}],"con":true,"img":false}]}
{"op":"mcm","clk":"1362266605","pt":1588434846996,"mc":[{"id":"1.170370564","rc":[{"atl":[[1.3,341.55]],"id":8509691}],"con":true,"img":false}]}
{"op":"mcm","clk":"1362266646","pt":1588434849137,"mc":[{"id":"1.170370564","rc":[{"atl":[[1.3,315.3]],"id":8509691}],"con":true,"img":false}]}
{"op":"mcm","clk":"1362266652","pt":1588434849494,"mc":[{"id":"1.170370564","rc":[{"atb":[[4.1,10.91]],"id":9630572},{"atl":[[4.9,0]],"id":9630572},{"atb":[[1.25,0]],"id":8509691},{"atl":[[1.32,0]],"id":8509691}],"con":true,"img":false}]}
{"op":"mcm","clk":"1362266659","pt":1588434849697,"mc":[{"id":"1.170370564","rc":[{"atb":[[4.1,12.95]],"id":9630572},{"atl":[[4.9,2.05]],"id":9630572},{"atb":[[1.25,2.01]],"id":8509691},{"atl":[[1.32,2.05]],"id":8509691}],"con":true,"img":false}]}
{"op":"mcm","clk":"1362266698","pt":1588434851125,"mc":[{"id":"1.170370564","rc":[{"atl":[[1.31,22.05]],"id":8509691}],"con":true,"img":false}]}
{"op":"mcm","clk":"1362266766","pt":1588434854846,"mc":[{"id":"1.170370564","rc":[{"atb":[[4.1,10.62]],"id":9630572}],"con":true,"img":false}]}
{"op":"mcm","clk":"1362266941","pt":1588434862651,"mc":[{"id":"1.170370564","rc":[{"atb":[[4.1,12.95]],"id":9630572}],"con":true,"img":false}]}
{"op":"mcm","clk":"1362266947","pt":1588434862957,"mc":[{"id":"1.170370564","rc":[{"atb":[[4.1,10.91]],"id":9630572},{"atl":[[4.9,0]],"id":9630572},{"atb":[[1.25,0]],"id":8509691},{"atl":[[1.32,0]],"id":8509691}],"con":true,"img":false}]}
{"op":"mcm","clk":"1362266954","pt":1588434863160,"mc":[{"id":"1.170370564","rc":[{"atb":[[4.1,12.91]],"id":9630572},{"atl":[[4.9,2.05]],"id":9630572},{"atb":[[1.25,2.01]],"id":8509691},{"atl":[[1.32,2.02]],"id":8509691}],"con":true,"img":false}]}
{"op":"mcm","clk":"1362267353","pt":1588434880867,"mc":[{"id":"1.170370564","rc":[{"atb":[[1.26,1675.76]],"id":8509691}],"con":true,"img":false}]}
{"op":"mcm","clk":"1362267360","pt":1588434881175,"mc":[{"id":"1.170370564","rc":[{"atb":[[4.1,10.91]],"id":9630572},{"atl":[[4.9,0]],"id":9630572},{"atb":[[1.25,0]],"id":8509691},{"atl":[[1.32,0]],"id":8509691}],"con":true,"img":false}]}
{"op":"mcm","clk":"1362267364","pt":1588434881380,"mc":[{"id":"1.170370564","rc":[{"atb":[[4.1,12.95]],"id":9630572},{"atl":[[4.9,2.05]],"id":9630572},{"atb":[[1.25,2.01]],"id":8509691},{"atl":[[1.32,2.11]],"id":8509691}],"con":true,"img":false}]}
{"op":"mcm","clk":"1362267744","pt":1588434897962,"mc":[{"id":"1.170370564","rc":[{"trd":[[1.28,1910.78]],"ltp":1.28,"tv":1910.78,"id":8509691},{"atb":[[1.28,390.59]],"id":8509691}],"con":true,"img":false}]}
{"op":"mcm","clk":"1362267751","pt":1588434898265,"mc":[{"id":"1.170370564","rc":[{"atb":[[4.1,10.91]],"id":9630572},{"atl":[[4.9,0]],"id":9630572},{"atb":[[1.25,0]],"id":8509691},{"atl":[[1.32,0]],"id":8509691}],"con":true,"img":false}]}
{"op":"mcm","clk":"1362267758","pt":1588434898468,"mc":[{"id":"1.170370564","rc":[{"atb":[[4.1,12.95]],"id":9630572},{"atl":[[4.9,2.05]],"id":9630572},{"atb":[[1.25,2.01]],"id":8509691},{"atl":[[1.32,2.11]],"id":8509691}],"con":true,"img":false}]}
{"op":"mcm","clk":"1362267805","pt":1588434900102,"mc":[{"id":"1.170370564","rc":[{"trd":[[4.6,11.22]],"ltp":4.6,"tv":11.22,"id":9630572},{"trd":[[1.28,1936.3]],"ltp":1.28,"tv":1936.3,"id":8509691},{"atb":[[1.28,365.07]],"id":8509691}],"con":true,"img":false}]}
{"op":"mcm","clk":"1362268064","pt":1588434912011,"mc":[{"id":"1.170370564","rc":[{"atl":[[1000,3.54]],"id":8509691}],"con":true,"img":false}]}
{"op":"mcm","clk":"1362268071","pt":1588434912215,"mc":[{"id":"1.170370564","rc":[{"atl":[[1000,0.01]],"id":8509691}],"con":true,"img":false}]}
{"op":"mcm","clk":"1362268076","pt":1588434912318,"mc":[{"id":"1.170370564","rc":[{"atb":[[4.1,10.91]],"id":9630572},{"atl":[[4.9,0]],"id":9630572},{"atb":[[1.25,0]],"id":8509691},{"atl":[[1.32,0]],"id":8509691}],"con":true,"img":false}]}
{"op":"mcm","clk":"1362268079","pt":1588434912420,"mc":[{"id":"1.170370564","rc":[{"atl":[[1000,0]],"id":8509691}],"con":true,"img":false}]}
{"op":"mcm","clk":"1362268081","pt":1588434912470,"mc":[{"id":"1.170370564","rc":[{"atb":[[4.1,12.95]],"id":9630572},{"atl":[[4.9,2.05]],"id":9630572},{"trd":[[1.28,1936.32]],"ltp":1.28,"tv":1936.32,"id":8509691},{"atb":[[1.28,365.07],[1.25,2.01]],"id":8509691},{"atl":[[1.32,2.11]],"id":8509691}],"con":true,"img":false}]}
{"op":"mcm","clk":"1362268721","pt":1588434939940,"mc":[{"id":"1.170370565","rc":[{"trd":[[1.92,9.44]],"ltp":1.92,"tv":9.44,"id":11269555},{"atb":[[1.92,5.28]],"id":11269555}],"con":true,"img":false}]}
{"op":"mcm","clk":"1362269423","pt":1588434971569,"mc":[{"id":"1.170370564","rc":[{"atb":[[1.28,59.07]],"id":8509691}],"con":true,"img":false}]}
{"op":"mcm","clk":"1362269434","pt":1588434971875,"mc":[{"id":"1.170370564","rc":[{"atb":[[4.1,10.91]],"id":9630572},{"atl":[[4.9,0]],"id":9630572},{"atb":[[1.25,0]],"id":8509691},{"atl":[[1.32,0]],"id":8509691}],"con":true,"img":false}]}
{"op":"mcm","clk":"1362269441","pt":1588434972080,"mc":[{"id":"1.170370564","rc":[{"atb":[[4.1,12.95]],"id":9630572},{"atl":[[4.9,2.05]],"id":9630572},{"atb":[[1.25,2.01]],"id":8509691},{"atl":[[1.32,2.11]],"id":8509691}],"con":true,"img":false}]}
{"op":"mcm","clk":"1362269530","pt":1588434975497,"mc":[{"id":"1.170370564","rc":[{"trd":[[4.4,9.79]],"ltp":4.4,"tv":9.79,"id":9630572},{"atb":[[4.4,26.25]],"id":9630572}],"con":true,"img":false}]}
{"op":"mcm","clk":"1362269541","pt":1588434975806,"mc":[{"id":"1.170370564","rc":[{"atb":[[4.1,10.62]],"id":9630572}],"con":true,"img":false}]}
{"op":"mcm","clk":"1362269729","pt":1588434983504,"mc":[{"id":"1.170370564","rc":[{"atb":[[4.1,12.95]],"id":9630572}],"con":true,"img":false}]}
{"op":"mcm","clk":"1362269735","pt":1588434983810,"mc":[{"id":"1.170370564","rc":[{"atb":[[4.1,10.91]],"id":9630572},{"atl":[[4.9,0]],"id":9630572},{"atb":[[1.25,0]],"id":8509691},{"atl":[[1.32,0]],"id":8509691}],"con":true,"img":false}]}
{"op":"mcm","clk":"1362269741","pt":1588434984015,"mc":[{"id":"1.170370564","rc":[{"atb":[[4.1,12.95]],"id":9630572},{"atl":[[4.9,2.05]],"id":9630572},{"atb":[[1.25,2.01]],"id":8509691},{"atl":[[1.32,2.11]],"id":8509691}],"con":true,"img":false}]}
{"op":"mcm","clk":"1362269985","pt":1588434995136,"mc":[{"id":"1.170370564","rc":[{"atb":[[1.28,58.67]],"id":8509691}],"con":true,"img":false}]}
{"op":"mcm","clk":"1362269990","pt":1588434995238,"mc":[{"id":"1.170370564","rc":[{"trd":[[1.29,1040.99]],"ltp":1.29,"tv":1040.99,"id":8509691},{"atl":[[1.29,90.82]],"id":8509691}],"con":true,"img":false}]}
{"op":"mcm","clk":"1362269996","pt":1588434995391,"mc":[{"id":"1.170370564","rc":[{"atb":[[4.1,10.91]],"id":9630572},{"atl":[[4.9,0]],"id":9630572},{"atb":[[1.25,0]],"id":8509691},{"atl":[[1.32,0]],"id":8509691}],"con":true,"img":false}]}
{"op":"mcm","clk":"1362269999","pt":1588434995493,"mc":[{"id":"1.170370564","rc":[{"atb":[[4.1,12.95]],"id":9630572},{"atl":[[4.9,2.05]],"id":9630572},{"atb":[[1.25,2.01]],"id":8509691},{"atl":[[1.32,2.05]],"id":8509691}],"con":true,"img":false}]}
{"op":"mcm","clk":"1362270155","pt":1588435001928,"mc":[{"id":"1.170370564","rc":[{"atl":[[4.5,1.05]],"id":9630572}],"con":true,"img":false}]}
{"op":"mcm","clk":"1362270163","pt":1588435002234,"mc":[{"id":"1.170370564","rc":[{"atb":[[4.1,10.91]],"id":9630572},{"atl":[[4.9,0]],"id":9630572},{"atb":[[1.25,0]],"id":8509691},{"atl":[[1000,2.05],[1.32,0]],"id":8509691}],"con":true,"img":false}]}
{"op":"mcm","clk":"1362270172","pt":1588435002437,"mc":[{"id":"1.170370564","rc":[{"atb":[[4.1,12.91]],"id":9630572},{"atl":[[4.9,2.05]],"id":9630572},{"atb":[[1.25,2.01]],"id":8509691},{"atl":[[1000,2.09],[1.32,2.11]],"id":8509691}],"con":true,"img":false}]}
{"op":"mcm","clk":"1362270175","pt":1588435002641,"mc":[{"id":"1.170370564","rc":[{"atl":[[1000,0.04]],"id":8509691}],"con":true,"img":false}]}
{"op":"mcm","clk":"1362270177","pt":1588435002743,"mc":[{"id":"1.170370564","rc":[{"trd":[[1.28,1936.42]],"ltp":1.28,"tv":1936.42,"id":8509691},{"atb":[[1.28,58.61]],"id":8509691}],"con":true,"img":false}]}
{"op":"mcm","clk":"1362270181","pt":1588435002844,"mc":[{"id":"1.170370564","rc":[{"atl":[[1000,0]],"id":8509691}],"con":true,"img":false}]}
{"op":"mcm","clk":"1362270185","pt":1588435002947,"mc":[{"id":"1.170370564","rc":[{"trd":[[1.28,1936.52]],"ltp":1.28,"tv":1936.52,"id":8509691},{"atb":[[1.28,58.56]],"id":8509691}],"con":true,"img":false}]}
{"op":"mcm","clk":"1362270341","pt":1588435009124,"mc":[{"id":"1.170370564","rc":[{"atb":[[1.23,88.65]],"id":8509691}],"con":true,"img":false}]}
{"op":"mcm","clk":"1362270351","pt":1588435009429,"mc":[{"id":"1.170370564","rc":[{"atb":[[4.1,10.91]],"id":9630572},{"atl":[[4.9,0]],"id":9630572},{"atb":[[1.25,0]],"id":8509691},{"atl":[[1.32,0]],"id":8509691}],"con":true,"img":false}]}
{"op":"mcm","clk":"1362270359","pt":1588435009634,"mc":[{"id":"1.170370564","rc":[{"atb":[[4.1,12.95]],"id":9630572},{"atl":[[4.9,2.05]],"id":9630572},{"atb":[[1.25,2.01]],"id":8509691},{"atl":[[1.32,2.11]],"id":8509691}],"con":true,"img":false}]}
{"op":"mcm","clk":"1362270392","pt":1588435011119,"mc":[{"id":"1.170370564","rc":[{"atb":[[3.9,0]],"id":9630572}],"con":true,"img":false}]}
{"op":"mcm","clk":"1362270795","pt":1588435029438,"mc":[{"id":"1.170370564","rc":[{"trd":[[4.5,255.99]],"ltp":4.5,"tv":255.99,"id":9630572},{"atl":[[4.5,0.06]],"id":9630572},{"trd":[[1.28,2057.14]],"ltp":1.28,"tv":2057.14,"id":8509691},{"atb":[[1.28,0]],"id":8509691}],"con":true,"img":false}]}
{"op":"mcm","clk":"1362270797","pt":1588435029539,"mc":[{"id":"1.170370564","rc":[{"atb":[[1.24,90.67]],"id":8509691}],"con":true,"img":false}]}
{"op":"mcm","clk":"1362270798","pt":1588435029643,"mc":[{"id":"1.170370564","rc":[{"atl":[[4.9,0]],"id":9630572},{"atb":[[1.26,1673.75]],"id":8509691},{"atl":[[1.32,0]],"id":8509691}],"con":true,"img":false}]}
{"op":"mcm","clk":"1362270801","pt":1588435029743,"mc":[{"id":"1.170370564","rc":[{"atb":[[4.1,10.91]],"id":9630572}],"con":true,"img":false}]}
{"op":"mcm","clk":"1362270805","pt":1588435029947,"mc":[{"id":"1.170370564","rc":[{"atl":[[4.8,0],[5.1,2.05],[5,2]],"id":9630572},{"atl":[[1.32,2.11]],"id":8509691}],"con":true,"img":false}]}
{"op":"mcm","clk":"1362270809","pt":1588435030152,"mc":[{"id":"1.170370564","rc":[{"atb":[[4.1,12.95]],"id":9630572},{"atl":[[5.2,2.03]],"id":9630572}],"con":true,"img":false}]}
{"op":"mcm","clk":"1362270818","pt":1588435030559,"mc":[{"id":"1.170370564","rc":[{"atb":[[1.24,2.02]],"id":8509691}],"con":true,"img":false}]}
{"op":"mcm","clk":"1362270862","pt":1588435032546,"mc":[{"id":"1.170370564","rc":[{"atb":[[3.5,22.3]],"id":9630572},{"atb":[[1.25,225.05]],"id":8509691}],"con":true,"img":false}]}
{"op":"mcm","clk":"1362272336","pt":1588435095871,"mc":[{"id":"1.170370564","rc":[{"atb":[[4.1,10.62]],"id":9630572}],"con":true,"img":false}]}
{"op":"mcm","clk":"1362272342","pt":1588435096177,"mc":[{"id":"1.170370564","rc":[{"atb":[[4.1,8.58]],"id":9630572},{"atl":[[5.1,0],[5.2,0]],"id":9630572},{"atb":[[1.24,0]],"id":8509691},{"atl":[[1.32,0]],"id":8509691}],"con":true,"img":false}]}
{"op":"mcm","clk":"1362272345","pt":1588435096330,"mc":[{"id":"1.170370564","rc":[{"atb":[[4.1,10.62]],"id":9630572},{"atl":[[5.1,2.05]],"id":9630572},{"atb":[[1.24,2.02]],"id":8509691},{"atl":[[1.32,2.11]],"id":8509691}],"con":true,"img":false}]}
{"op":"mcm","clk":"1362272477","pt":1588435102239,"mc":[{"id":"1.170370564","rc":[{"trd":[[4.5,256.05]],"ltp":4.5,"tv":256.05,"id":9630572},{"atl":[[4.5,0]],"id":9630572},{"trd":[[1.27,225.72],[1.28,2057.37]],"ltp":1.27,"tv":2283.08,"id":8509691},{"atb":[[1.27,150.11]],"id":8509691}],"con":true,"img":false}]}
{"op":"mcm","clk":"1362272487","pt":1588435102545,"mc":[{"id":"1.170370564","rc":[{"atb":[[4.1,8.58]],"id":9630572},{"atl":[[5.1,0]],"id":9630572},{"atb":[[1.24,0]],"id":8509691},{"atl":[[1.32,0]],"id":8509691}],"con":true,"img":false}]}
{"op":"mcm","clk":"1362272498","pt":1588435102749,"mc":[{"id":"1.170370564","rc":[{"atb":[[4.1,10.58]],"id":9630572},{"atl":[[5.1,2.05]],"id":9630572},{"atb":[[1.24,2.02]],"id":8509691},{"atl":[[1.32,2.11]],"id":8509691}],"con":true,"img":false}]}
{"op":"mcm","clk":"1362272518","pt":1588435103564,"mc":[{"id":"1.170370564","rc":[{"atb":[[4.1,12.91]],"id":9630572}],"con":true,"img":false}]}
{"op":"mcm","clk":"1362272958","pt":1588435124374,"mc":[{"id":"1.170370564","rc":[{"atl":[[1.33,2.39]],"id":8509691}],"con":true,"img":false}]}
{"op":"mcm","clk":"1362272968","pt":1588435124679,"mc":[{"id":"1.170370564","rc":[{"atb":[[4.1,10.91]],"id":9630572},{"atl":[[5.1,0]],"id":9630572},{"atb":[[1.24,0]],"id":8509691},{"atl":[[1.32,0]],"id":8509691}],"con":true,"img":false}]}
{"op":"mcm","clk":"1362272974","pt":1588435124882,"mc":[{"id":"1.170370564","rc":[{"atb":[[4.1,12.95]],"id":9630572},{"atl":[[5.1,2.05]],"id":9630572},{"atb":[[1.24,2.02]],"id":8509691},{"atl":[[1.32,2.11]],"id":8509691}],"con":true,"img":false}]}
{"op":"mcm","clk":"1362274503","pt":1588435167224,"mc":[{"id":"1.170370564","rc":[{"trd":[[4.8,41.88]],"ltp":4.8,"tv":41.88,"id":9630572},{"trd":[[1.27,370.12]],"ltp":1.27,"tv":370.12,"id":8509691},{"atb":[[1.27,5.71]],"id":8509691}],"con":true,"img":false}]}
{"op":"mcm","clk":"1362274512","pt":1588435167431,"mc":[{"id":"1.170370564","rc":[{"atb":[[4.1,10.91]],"id":9630572},{"atl":[[5.1,0]],"id":9630572},{"atb":[[1.24,0]],"id":8509691},{"atl":[[1.32,0]],"id":8509691}],"con":true,"img":false}]}
{"op":"mcm","clk":"1362274518","pt":1588435167531,"mc":[{"id":"1.170370564","rc":[{"atl":[[5.2,2.03]],"id":9630572}],"con":true,"img":false}]}
{"op":"mcm","clk":"1362274521","pt":1588435167632,"mc":[{"id":"1.170370564","rc":[{"atl":[[5,0]],"id":9630572}],"con":true,"img":false}]}
{"op":"mcm","clk":"1362274526","pt":1588435167736,"mc":[{"id":"1.170370564","rc":[{"atb":[[4.1,12.94]],"id":9630572},{"atl":[[5.1,2.05]],"id":9630572},{"atb":[[1.24,2.02]],"id":8509691},{"atl":[[1.32,2.11]],"id":8509691}],"con":true,"img":false}]}
{"op":"mcm","clk":"1362274541","pt":1588435168243,"mc":[{"id":"1.170370564","rc":[{"trd":[[1.29,1051.63]],"ltp":1.29,"tv":1051.63,"id":8509691},{"atl":[[1.29,85.5]],"id":8509691}],"con":true,"img":false}]}
{"op":"mcm","clk":"1362274949","pt":1588435189979,"mc":[{"id":"1.170370564","rc":[{"atl":[[1000,1.92]],"id":8509691}],"con":true,"img":false}]}
{"op":"mcm","clk":"1362274956","pt":1588435190282,"mc":[{"id":"1.170370564","rc":[{"atb":[[4.1,10.91]],"id":9630572},{"atl":[[5.2,0]],"id":9630572},{"atb":[[1.24,0]],"id":8509691},{"atl":[[1.32,0]],"id":8509691}],"con":true,"img":false}]}
{"op":"mcm","clk":"1362274959","pt":1588435190486,"mc":[{"id":"1.170370564","rc":[{"atb":[[4.1,12.95]],"id":9630572},{"atl":[[5.2,2.03]],"id":9630572},{"atb":[[1.24,2.02]],"id":8509691},{"atl":[[1.32,2.11]],"id":8509691}],"con":true,"img":false}]}
{"op":"mcm","clk":"1362274964","pt":1588435190638,"mc":[{"id":"1.170370564","rc":[{"atl":[[1000,0.46]],"id":8509691}],"con":true,"img":false}]}
{"op":"mcm","clk":"1362274977","pt":1588435191357,"mc":[{"id":"1.170370564","rc":[{"atl":[[1000,0]],"id":8509691}],"con":true,"img":false}]}
{"op":"mcm","clk":"1362274978","pt":1588435191460,"mc":[{"id":"1.170370564","rc":[{"trd":[[1.27,371.06]],"ltp":1.27,"tv":371.06,"id":8509691},{"atb":[[1.27,5.24]],"id":8509691}],"con":true,"img":false}]}
{"op":"mcm","clk":"1362275352","pt":1588435214891,"mc":[{"id":"1.170370564","rc":[{"trd":[[1.27,373.97]],"ltp":1.27,"tv":373.97,"id":8509691},{"atb":[[1.27,3.79]],"id":8509691}],"con":true,"img":false}]}
{"op":"mcm","clk":"1362275446","pt":1588435220605,"mc":[{"id":"1.170370564","rc":[{"atb":[[4.1,10.62]],"id":9630572}],"con":true,"img":false}]}
{"op":"mcm","clk":"1362275566","pt":1588435228308,"mc":[{"id":"1.170370564","rc":[{"atb":[[4.1,12.95]],"id":9630572}],"con":true,"img":false}]}
{"op":"mcm","clk":"1362275986","pt":1588435250033,"mc":[{"id":"1.170370564","rc":[{"atl":[[1.29,33.02]],"id":8509691}],"con":true,"img":false}]}
{"op":"mcm","clk":"1362275990","pt":1588435250240,"mc":[{"id":"1.170370564","rc":[{"atl":[[1.28,52.48]],"id":8509691}],"con":true,"img":false}]}
{"op":"mcm","clk":"1362275997","pt":1588435250545,"mc":[{"id":"1.170370564","rc":[{"atb":[[4.3,8.05]],"id":9630572},{"atb":[[1.23,0],[1.22,288.65]],"id":8509691}],"con":true,"img":false}]}
{"op":"mcm","clk":"1362277269","pt":1588435320148,"mc":[{"id":"1.170370564","rc":[{"trd":[[1.27,376.88]],"ltp":1.27,"tv":376.88,"id":8509691},{"atb":[[1.27,2.33]],"id":8509691}],"con":true,"img":false}]}
{"op":"mcm","clk":"1362277276","pt":1588435320556,"mc":[{"id":"1.170370564","rc":[{"atb":[[4.2,8.31]],"id":9630572},{"atl":[[5.1,0]],"id":9630572},{"atl":[[1.32,0],[1.31,20]],"id":8509691}],"con":true,"img":false}]}
{"op":"mcm","clk":"1362277279","pt":1588435320658,"mc":[{"id":"1.170370564","rc":[{"atb":[[4.1,10.91]],"id":9630572},{"atl":[[5.2,0]],"id":9630572},{"atb":[[1.25,223.04],[1.24,0]],"id":8509691}],"con":true,"img":false}]}
{"op":"mcm","clk":"1362277550","pt":1588435335452,"mc":[{"id":"1.170370564","rc":[{"atb":[[4.1,8.58]],"id":9630572}],"con":true,"img":false}]}
{"op":"mcm","clk":"1362277691","pt":1588435343987,"mc":[{"id":"1.170370564","rc":[{"atb":[[4.1,10.91]],"id":9630572}],"con":true,"img":false}]}
{"op":"mcm","clk":"1362278072","pt":1588435367219,"mc":[{"id":"1.170370564","rc":[{"atb":[[1.27,395.95]],"id":8509691}],"con":true,"img":false}]}
{"op":"mcm","clk":"1362278082","pt":1588435367576,"mc":[{"id":"1.170370564","rc":[{"atb":[[1.23,88.65]],"id":8509691}],"con":true,"img":false}]}
{"op":"mcm","clk":"1362278102","pt":1588435368595,"mc":[{"id":"1.170370564","rc":[{"trd":[[1.28,2058.32]],"ltp":1.28,"tv":2058.32,"id":8509691},{"atl":[[1.28,52]],"id":8509691}],"con":true,"img":false}]}
{"op":"mcm","clk":"1362278268","pt":1588435378697,"mc":[{"id":"1.170370564","rc":[{"trd":[[1.28,2162.34]],"ltp":1.28,"tv":2162.34,"id":8509691},{"atb":[[1.28,440]],"id":8509691},{"atl":[[1.28,0]],"id":8509691}],"con":true,"img":false}]}
{"op":"mcm","clk":"1362278281","pt":1588435379512,"mc":[{"id":"1.170370564","rc":[{"atb":[[1.24,88.65]],"id":8509691}],"con":true,"img":false}]}
{"op":"mcm","clk":"1362278283","pt":1588435379614,"mc":[{"id":"1.170370564","rc":[{"atb":[[4.3,0]],"id":9630572}],"con":true,"img":false}]}
{"op":"mcm","clk":"1362278351","pt":1588435383342,"mc":[{"id":"1.170370564","rc":[{"atb":[[3.5,0]],"id":9630572},{"atb":[[1.25,0]],"id":8509691}],"con":true,"img":false}]}
{"op":"mcm","clk":"1362278443","pt":1588435389030,"mc":[{"id":"1.170370564","rc":[{"atb":[[1.28,1.77]],"id":9630572},{"atb":[[1.28,441.78]],"id":8509691}],"con":true,"img":false}]}
{"op":"mcm","clk":"1362278695","pt":1588435408160,"mc":[{"id":"1.170370564","rc":[{"atb":[[1.28,0]],"id":9630572},{"atb":[[1.28,440]],"id":8509691}],"con":true,"img":false}]}
{"op":"mcm","clk":"1362279095","pt":1588435444023,"mc":[{"id":"1.170370564","rc":[{"trd":[[1.29,1072.62]],"ltp":1.29,"tv":1072.62,"id":8509691},{"atl":[[1.29,22.52]],"id":8509691}],"con":true,"img":false}]}
{"op":"mcm","clk":"1362279233","pt":1588435455063,"mc":[{"id":"1.170370564","rc":[{"atb":[[4.1,8.58]],"id":9630572}],"con":true,"img":false}]}
{"op":"mcm","clk":"1362279293","pt":1588435460681,"mc":[{"id":"1.170370564","rc":[{"atb":[[1.29,8.86]],"id":9630572},{"trd":[[1.29,1090.36]],"ltp":1.29,"tv":1090.36,"id":8509691},{"atl":[[1.29,13.65]],"id":8509691}],"con":true,"img":false}]}
{"op":"mcm","clk":"1362279317","pt":1588435462462,"mc":[{"id":"1.170370564","rc":[{"trd":[[1.28,2167.14]],"ltp":1.28,"tv":2167.14,"id":8509691},{"atb":[[1.28,437.6]],"id":8509691}],"con":true,"img":false}]}
{"op":"mcm","clk":"1362279326","pt":1588435463432,"mc":[{"id":"1.170370564","rc":[{"atb":[[4.1,10.91]],"id":9630572}],"con":true,"img":false}]}
{"op":"mcm","clk":"1362279471","pt":1588435477773,"mc":[{"id":"1.170370564","rc":[{"trd":[[1.29,1090.92]],"ltp":1.29,"tv":1090.92,"id":8509691},{"atl":[[1.29,13.37]],"id":8509691}],"con":true,"img":false}]}
{"op":"mcm","clk":"1362279562","pt":1588435485996,"mc":[{"id":"1.170370564","rc":[{"atb":[[1.29,0]],"id":9630572}],"con":true,"img":false}]}
{"op":"mcm","clk":"1362279564","pt":1588435486098,"mc":[{"id":"1.170370564","rc":[{"atb":[[1.3,8.86]],"id":9630572}],"con":true,"img":false}]}
{"op":"mcm","clk":"1362279716","pt":1588435500434,"mc":[{"id":"1.170370564","rc":[{"atb":[[4.1,11.19]],"id":9630572}],"con":true,"img":false}]}
{"op":"mcm","clk":"1362279793","pt":1588435507554,"mc":[{"id":"1.170370564","rc":[{"atb":[[1.3,0]],"id":9630572}],"con":true,"img":false}]}
{"op":"mcm","clk":"1362279795","pt":1588435507656,"mc":[{"id":"1.170370564","rc":[{"atb":[[1.29,8.86]],"id":9630572}],"con":true,"img":false}]}
{"op":"mcm","clk":"1362279817","pt":1588435509756,"mc":[{"id":"1.170370564","rc":[{"atb":[[1.29,0]],"id":9630572}],"con":true,"img":false}]}
{"op":"mcm","clk":"1362279904","pt":1588435517843,"mc":[{"id":"1.170370564","rc":[{"atl":[[7,0.28]],"id":9630572}],"con":true,"img":false}]}
{"op":"mcm","clk":"1362279997","pt":1588435525942,"mc":[{"id":"1.170370564","rc":[{"atl":[[1.29,122.41]],"id":8509691}],"con":true,"img":false}]}
{"op":"mcm","clk":"1362280407","pt":1588435561166,"mc":[{"id":"1.170370564","rc":[{"atl":[[1.29,603.5]],"id":8509691}],"con":true,"img":false}]}
{"op":"mcm","clk":"1362280462","pt":1588435566039,"mc":[{"id":"1.170370564","rc":[{"atl":[[1.29,122.41]],"id":8509691}],"con":true,"img":false}]}
{"op":"mcm","clk":"1362280466","pt":1588435566245,"mc":[{"id":"1.170370564","rc":[{"atl":[[1.29,603.5]],"id":8509691}],"con":true,"img":false}]}
{"op":"mcm","clk":"1362280468","pt":1588435566449,"mc":[{"id":"1.170370564","rc":[{"trd":[[1.28,2185]],"ltp":1.28,"tv":2185.0,"id":8509691},{"atb":[[1.28,428.67]],"id":8509691}],"con":true,"img":false}]}
{"op":"mcm","clk":"1362280567","pt":1588435575448,"mc":[{"id":"1.170370564","rc":[{"atb":[[4.1,8.86]],"id":9630572}],"con":true,"img":false}]}
{"op":"mcm","clk":"1362280669","pt":1588435584093,"mc":[{"id":"1.170370564","rc":[{"atb":[[4.1,11.19]],"id":9630572}],"con":true,"img":false}]}
{"op":"mcm","clk":"1362280796","pt":1588435594198,"mc":[{"id":"1.170370564","rc":[{"trd":[[1.28,2187.2]],"ltp":1.28,"tv":2187.2,"id":8509691},{"atb":[[1.28,427.57]],"id":8509691}],"con":true,"img":false}]}
{"op":"mcm","clk":"1362281004","pt":1588435614219,"mc":[{"id":"1.170370564","rc":[{"atb":[[3.8,0]],"id":9630572},{"atb":[[1.22,88.65]],"id":8509691}],"con":true,"img":false}]}
{"op":"mcm","clk":"1362281873","pt":1588435692536,"mc":[{"id":"1.170370564","rc":[{"atb":[[1.09,156.91]],"id":8509691}],"con":true,"img":false}]}
{"op":"mcm","clk":"1362281880","pt":1588435693045,"mc":[{"id":"1.170370564","rc":[{"atb":[[1.08,166.62]],"id":8509691}],"con":true,"img":false}]}
{"op":"mcm","clk":"1362281888","pt":1588435693755,"mc":[{"id":"1.170370564","rc":[{"atb":[[1.07,156.91]],"id":8509691}],"con":true,"img":false}]}
{"op":"mcm","clk":"1362281893","pt":1588435694217,"mc":[{"id":"1.170370564","rc":[{"atb":[[1.06,1141.78]],"id":8509691}],"con":true,"img":false}]}
{"op":"mcm","clk":"1362281903","pt":1588435695141,"mc":[{"id":"1.170370564","rc":[{"atb":[[4.1,8.86]],"id":9630572},{"atb":[[1.08,323.53]],"id":8509691}],"con":true,"img":false}]}
{"op":"mcm","clk":"1362281954","pt":1588435700361,"mc":[{"id":"1.170370564","rc":[{"atb":[[1.28,538.39]],"id":8509691}],"con":true,"img":false}]}
{"op":"mcm","clk":"1362281985","pt":1588435703525,"mc":[{"id":"1.170370564","rc":[{"atb":[[4.1,11.19]],"id":9630572}],"con":true,"img":false}]}
{"op":"mcm","clk":"1362282584","pt":1588435761939,"mc":[{"id":"1.170370564","rc":[{"trd":[[1.28,2211.2]],"ltp":1.28,"tv":2211.2,"id":8509691},{"atb":[[1.28,526.39]],"id":8509691}],"con":true,"img":false}]}
{"op":"mcm","clk":"1362283010","pt":1588435796130,"mc":[{"id":"1.170370564","rc":[{"atl":[[1.29,122.41]],"id":8509691}],"con":true,"img":false}]}
{"op":"mcm","clk":"1362283095","pt":1588435802157,"mc":[{"id":"1.170370564","rc":[{"atl":[[10,0],[20,0]],"id":9630572},{"atl":[[10,0]],"id":8509691}],"con":true,"img":false}]}
{"op":"mcm","clk":"1362283109","pt":1588435803241,"mc":[{"id":"1.170370564","rc":[{"atb":[[1.03,2505.53]],"id":8509691},{"atl":[[20,0]],"id":8509691}],"con":true,"img":false}]}
{"op":"mcm","clk":"1362283111","pt":1588435803345,"mc":[{"id":"1.170370564","rc":[{"atb":[[1.03,3]],"id":9630572}],"con":true,"img":false}]}
{"op":"mcm","clk":"1362283154","pt":1588435806641,"mc":[{"id":"1.170370565","rc":[{"atl":[[2,22.16]],"id":11269555}],"con":true,"img":false}]}
{"op":"mcm","clk":"1362283221","pt":1588435812668,"mc":[{"id":"1.170370564","rc":[{"atl":[[1.29,13.37]],"id":8509691}],"con":true,"img":false}]}
{"op":"mcm","clk":"1362283283","pt":1588435818759,"mc":[{"id":"1.170370564","rc":[{"atb":[[4.1,8.86]],"id":9630572}],"con":true,"img":false}]}
{"op":"mcm","clk":"1362283322","pt":1588435821969,"mc":[{"id":"1.170370564","rc":[{"atb":[[1.28,533.48]],"id":8509691}],"con":true,"img":false}]}
{"op":"mcm","clk":"1362283335","pt":1588435823145,"mc":[{"id":"1.170370564","rc":[{"atb":[[1.28,526.39]],"id":8509691}],"con":true,"img":false}]}
{"op":"mcm","clk":"1362283362","pt":1588435825859,"mc":[{"id":"1.170370564","rc":[{"atl":[[1.3,1300.23]],"id":8509691}],"con":true,"img":false}]}
{"op":"mcm","clk":"1362283376","pt":1588435826980,"mc":[{"id":"1.170370564","rc":[{"atl":[[1.3,315.3]],"id":8509691}],"con":true,"img":false}]}
{"op":"mcm","clk":"1362283380","pt":1588435827287,"mc":[{"id":"1.170370564","rc":[{"atb":[[4.1,11.19]],"id":9630572}],"con":true,"img":false}]}
{"op":"mcm","clk":"1362283384","pt":1588435827747,"mc":[{"id":"1.170370564","rc":[{"atb":[[1.28,1511.32]],"id":8509691}],"con":true,"img":false}]}
{"op":"mcm","clk":"1362283387","pt":1588435827953,"mc":[{"id":"1.170370564","rc":[{"trd":[[1.29,1117.66]],"ltp":1.29,"tv":1117.66,"id":8509691},{"atb":[[1.29,0.02]],"id":8509691},{"atl":[[1.29,0]],"id":8509691}],"con":true,"img":false}]}
{"op":"mcm","clk":"1362283391","pt":1588435828257,"mc":[{"id":"1.170370564","rc":[{"atb":[[1.29,0]],"id":8509691}],"con":true,"img":false}]}
{"op":"mcm","clk":"1362283394","pt":1588435828463,"mc":[{"id":"1.170370565","rc":[{"trd":[[1.91,147.08],[1.92,20]],"ltp":1.91,"tv":167.08,"id":11269555},{"atb":[[1.92,0],[1.91,0]],"id":11269555},{"atl":[[1.91,25.89]],"id":11269555}],"con":true,"img":false}]}
{"op":"mcm","clk":"1362283401","pt":1588435829073,"mc":[{"id":"1.170370564","rc":[{"atb":[[1.28,526.39]],"id":8509691}],"con":true,"img":false}]}
{"op":"mcm","clk":"1362283415","pt":1588435830302,"mc":[{"id":"1.170370565","rc":[{"atl":[[1.91,0]],"id":11269555}],"con":true,"img":false}]}
{"op":"mcm","clk":"1362283417","pt":1588435830404,"mc":[{"id":"1.170370564","rc":[{"trd":[[1.28,2347.2]],"ltp":1.28,"tv":2347.2,"id":8509691},{"atb":[[1.28,458.39]],"id":8509691}],"con":true,"img":false}]}
{"op":"mcm","clk":"1362283420","pt":1588435830553,"mc":[{"id":"1.170370565","rc":[{"atb":[[1.82,63.78]],"id":11269555}],"con":true,"img":false}]}
{"op":"mcm","clk":"1362283422","pt":1588435830655,"mc":[{"id":"1.170370564","rc":[{"atl":[[1.3,1300.23]],"id":8509691}],"con":true,"img":false}]}
{"op":"mcm","clk":"1362283431","pt":1588435831578,"mc":[{"id":"1.170370564","rc":[{"atl":[[1.3,315.3]],"id":8509691}],"con":true,"img":false}]}
{"op":"mcm","clk":"1362283441","pt":1588435832599,"mc":[{"id":"1.170370564","rc":[{"atb":[[1.28,1443.32]],"id":8509691}],"con":true,"img":false}]}
{"op":"mcm","clk":"1362283455","pt":1588435833780,"mc":[{"id":"1.170370564","rc":[{"atb":[[1.28,458.39]],"id":8509691}],"con":true,"img":false}]}
{"op":"mcm","clk":"1362283860","pt":1588435872847,"mc":[{"id":"1.170370564","rc":[{"atl":[[1.29,22]],"id":8509691}],"con":true,"img":false}]}
{"op":"mcm","clk":"1362283948","pt":1588435880455,"mc":[{"id":"1.170370564","rc":[{"atl":[[1.31,0]],"id":8509691}],"con":true,"img":false}]}
{"op":"mcm","clk":"1362284320","pt":1588435912620,"mc":[{"id":"1.170370565","rc":[{"atl":[[1.9,27.99]],"id":11269555}],"con":true,"img":false}]}
{"op":"mcm","clk":"1362284498","pt":1588435927211,"mc":[{"id":"1.170370564","rc":[{"atl":[[4.5,137.41]],"id":9630572}],"con":true,"img":false}]}
{"op":"mcm","clk":"1362284501","pt":1588435927418,"mc":[{"id":"1.170370564","rc":[{"trd":[[4.4,29.03]],"ltp":4.4,"tv":29.03,"id":9630572},{"atb":[[4.4,16.64]],"id":9630572},{"trd":[[1.29,1161.66]],"ltp":1.29,"tv":1161.66,"id":8509691},{"atb":[[1.29,0.03]],"id":8509691},{"atl":[[1.29,0]],"id":8509691}],"con":true,"img":false}]}
{"op":"mcm","clk":"1362284507","pt":1588435927722,"mc":[{"id":"1.170370564","rc":[{"atb":[[1.29,0]],"id":8509691}],"con":true,"img":false}]}
{"op":"mcm","clk":"1362284664","pt":1588435940742,"mc":[{"id":"1.170370565","rc":[{"atl":[[1.9,0]],"id":11269555}],"con":true,"img":false}]}
{"op":"mcm","clk":"1362284745","pt":1588435948750,"mc":[{"id":"1.170370564","rc":[{"trd":[[1.28,2361.38]],"ltp":1.28,"tv":2361.38,"id":8509691},{"atb":[[1.28,451.3]],"id":8509691}],"con":true,"img":false}]}
{"op":"mcm","clk":"1362285449","pt":1588436016132,"mc":[{"id":"1.170370564","rc":[{"atl":[[1.3,313.85]],"id":8509691}],"con":true,"img":false}]}
{"op":"mcm","clk":"1362285781","pt":1588436046000,"mc":[{"id":"1.170370564","rc":[{"trd":[[4.5,258.11]],"ltp":4.5,"tv":258.11,"id":9630572},{"atl":[[4.5,136.38]],"id":9630572}],"con":true,"img":false}]}
{"op":"mcm","clk":"1362287737","pt":1588436173354,"mc":[{"id":"1.170370564","rc":[{"trd":[[1.28,2417.38]],"ltp":1.28,"tv":2417.38,"id":8509691},{"atb":[[1.28,423.3]],"id":8509691}],"con":true,"img":false}]}
{"op":"mcm","clk":"1362287772","pt":1588436177277,"mc":[{"id":"1.170370564","rc":[{"atb":[[4.1,8.86]],"id":9630572}],"con":true,"img":false}]}
{"op":"mcm","clk":"1362287849","pt":1588436184996,"mc":[{"id":"1.170370564","rc":[{"atb":[[4.1,11.19]],"id":9630572}],"con":true,"img":false}]}
{"op":"mcm","clk":"1362288150","pt":1588436213511,"mc":[{"id":"1.170370564","rc":[{"atb":[[1.29,4799.23]],"id":8509691}],"con":true,"img":false}]}
{"op":"mcm","clk":"1362288153","pt":1588436213713,"mc":[{"id":"1.170370564","rc":[{"trd":[[4.4,48.27]],"ltp":4.4,"tv":48.27,"id":9630572},{"atb":[[4.4,7.02]],"id":9630572}],"con":true,"img":false}]}
{"op":"mcm","clk":"1362288165","pt":1588436214529,"mc":[{"id":"1.170370564","rc":[{"atb":[[3.5,22.3]],"id":9630572}],"con":true,"img":false}]}
{"op":"mcm","clk":"1362288231","pt":1588436219999,"mc":[{"id":"1.170370564","rc":[{"trd":[[1.29,10760.13]],"ltp":1.29,"tv":10760.13,"id":8509691},{"atb":[[1.29,0]],"id":8509691},{"atl":[[1.29,2.76]],"id":8509691}],"con":true,"img":false}]}
{"op":"mcm","clk":"1362288234","pt":1588436220204,"mc":[{"id":"1.170370564","rc":[{"trd":[[1.29,10765.66]],"ltp":1.29,"tv":10765.66,"id":8509691},{"atl":[[1.29,0]],"id":8509691}],"con":true,"img":false}]}
{"op":"mcm","clk":"1362288265","pt":1588436222914,"mc":[{"id":"1.170370564","rc":[{"atb":[[1.03,905.8],[1.11,60]],"id":8509691}],"con":true,"img":false}]}
{"op":"mcm","clk":"1362288272","pt":1588436223635,"mc":[{"id":"1.170370564","rc":[{"atb":[[1.55,0],[2.12,0]],"id":9630572}],"con":true,"img":false}]}
{"op":"mcm","clk":"1362288285","pt":1588436224557,"mc":[{"id":"1.170370564","rc":[{"atb":[[1.25,223.04]],"id":8509691}],"con":true,"img":false}]}
{"op":"mcm","clk":"1362288317","pt":1588436227120,"mc":[{"id":"1.170370564","rc":[{"atl":[[1.29,4799.23]],"id":8509691}],"con":true,"img":false}]}
{"op":"mcm","clk":"1362288320","pt":1588436227328,"mc":[{"id":"1.170370564","rc":[{"trd":[[4.5,399.96]],"ltp":4.5,"tv":399.96,"id":9630572},{"atl":[[4.5,65.46]],"id":9630572}],"con":true,"img":false}]}
{"op":"mcm","clk":"1362288395","pt":1588436234230,"mc":[{"id":"1.170370564","rc":[{"trd":[[1.29,20364.12]],"ltp":1.29,"tv":20364.12,"id":8509691},{"atb":[[1.29,2.76]],"id":8509691},{"atl":[[1.29,0]],"id":8509691}],"con":true,"img":false}]}
{"op":"mcm","clk":"1362288398","pt":1588436234439,"mc":[{"id":"1.170370564","rc":[{"trd":[[4.5,423.45]],"ltp":4.5,"tv":423.45,"id":9630572},{"atl":[[4.5,53.71]],"id":9630572}],"con":true,"img":false}]}
{"op":"mcm","clk":"1362288430","pt":1588436237545,"mc":[{"id":"1.170370564","rc":[{"atb":[[4.4,0]],"id":9630572}],"con":true,"img":false}]}
{"op":"mcm","clk":"1362288435","pt":1588436237954,"mc":[{"id":"1.170370564","rc":[{"atb":[[4.2,0]],"id":9630572}],"con":true,"img":false}]}
{"op":"mcm","clk":"1362288519","pt":1588436245568,"mc":[{"id":"1.170370564","rc":[{"trd":[[1.29,20369.66]],"ltp":1.29,"tv":20369.66,"id":8509691},{"atb":[[1.29,0]],"id":8509691},{"atl":[[1.29,1.23]],"id":8509691}],"con":true,"img":false}]}
{"op":"mcm","clk":"1362288521","pt":1588436245773,"mc":[{"id":"1.170370564","rc":[{"trd":[[1.29,20372.12]],"ltp":1.29,"tv":20372.12,"id":8509691},{"atb":[[1.29,0.54]],"id":8509691},{"atl":[[1.29,0]],"id":8509691}],"con":true,"img":false}]}
{"op":"mcm","clk":"1362288525","pt":1588436246083,"mc":[{"id":"1.170370564","rc":[{"atb":[[1.29,0],[1.24,0]],"id":8509691}],"con":true,"img":false}]}
{"op":"mcm","clk":"1362288535","pt":1588436246956,"mc":[{"id":"1.170370564","rc":[{"atb":[[1.24,88.65]],"id":8509691}],"con":true,"img":false}]}
{"op":"mcm","clk":"1362288586","pt":1588436251954,"mc":[{"id":"1.170370564","rc":[{"trd":[[4.5,485.95]],"ltp":4.5,"tv":485.95,"id":9630572},{"atl":[[4.5,22.46]],"id":9630572}],"con":true,"img":false}]}
{"op":"mcm","clk":"1362289121","pt":1588436297764,"mc":[{"id":"1.170370564","rc":[{"atb":[[4.1,8.86]],"id":9630572}],"con":true,"img":false}]}
{"op":"mcm","clk":"1362289213","pt":1588436305441,"mc":[{"id":"1.170370564","rc":[{"atb":[[4.1,11.19]],"id":9630572}],"con":true,"img":false}]}
{"op":"mcm","clk":"1362289514","pt":1588436333790,"mc":[{"id":"1.170370564","rc":[{"trd":[[1.28,2441.38]],"ltp":1.28,"tv":2441.38,"id":8509691},{"atb":[[1.28,411.3]],"id":8509691}],"con":true,"img":false}]}
{"op":"mcm","clk":"1362289608","pt":1588436341872,"mc":[{"id":"1.170370564","rc":[{"atb":[[1.28,417.3]],"id":8509691}],"con":true,"img":false}]}
{"op":"mcm","clk":"1362289611","pt":1588436341975,"mc":[{"id":"1.170370564","rc":[{"trd":[[1.28,2470.53]],"ltp":1.28,"tv":2470.53,"id":8509691},{"atb":[[1.28,402.72]],"id":8509691}],"con":true,"img":false}]}
{"op":"mcm","clk":"1362289920","pt":1588436371922,"mc":[{"id":"1.170370564","rc":[{"atb":[[3.8,59.39]],"id":9630572}],"con":true,"img":false}]}
{"op":"mcm","clk":"1362289970","pt":1588436376943,"mc":[{"id":"1.170370564","rc":[{"trd":[[1.28,2477.28]],"ltp":1.28,"tv":2477.28,"id":8509691},{"atb":[[1.28,399.35]],"id":8509691}],"con":true,"img":false}]}
{"op":"mcm","clk":"1362289972","pt":1588436377146,"mc":[{"id":"1.170370564","rc":[{"atb":[[3.8,0]],"id":9630572}],"con":true,"img":false}]}
{"op":"mcm","clk":"1362289998","pt":1588436379653,"mc":[{"id":"1.170370564","rc":[{"trd":[[1.3,146.77]],"ltp":1.3,"tv":146.77,"id":8509691},{"atl":[[1.3,313.03]],"id":8509691}],"con":true,"img":false}]}
{"op":"mcm","clk":"1362290031","pt":1588436382715,"mc":[{"id":"1.170370564","rc":[{"trd":[[4.3,1.79]],"ltp":4.3,"tv":1.79,"id":9630572},{"trd":[[1.3,152.72]],"ltp":1.3,"tv":152.72,"id":8509691},{"atl":[[1.3,307.08]],"id":8509691}],"con":true,"img":false}]}
{"op":"mcm","clk":"1362290053","pt":1588436384913,"mc":[{"id":"1.170370564","rc":[{"atl":[[1.3,1636.87]],"id":8509691}],"con":true,"img":false}]}
{"op":"mcm","clk":"1362290067","pt":1588436386349,"mc":[{"id":"1.170370564","rc":[{"atb":[[1.09,845.74]],"id":8509691}],"con":true,"img":false}]}
{"op":"mcm","clk":"1362290075","pt":1588436387112,"mc":[{"id":"1.170370564","rc":[{"atb":[[1.08,1012.36]],"id":8509691}],"con":true,"img":false}]}
{"op":"mcm","clk":"1362290084","pt":1588436387935,"mc":[{"id":"1.170370564","rc":[{"atb":[[1.07,845.74]],"id":8509691}],"con":true,"img":false}]}
{"op":"mcm","clk":"1362290108","pt":1588436390640,"mc":[{"id":"1.170370564","rc":[{"atb":[[1.1,720.82]],"id":8509691}],"con":true,"img":false}]}
{"op":"mcm","clk":"1362290124","pt":1588436392024,"mc":[{"id":"1.170370564","rc":[{"atb":[[1.11,748.82]],"id":8509691}],"con":true,"img":false}]}
{"op":"mcm","clk":"1362290219","pt":1588436400226,"mc":[{"id":"1.170370564","rc":[{"atl":[[1.32,3.54]],"id":8509691}],"con":true,"img":false}]}
{"op":"mcm","clk":"1362290223","pt":1588436400535,"mc":[{"id":"1.170370564","rc":[{"atl":[[1.32,0.17]],"id":8509691}],"con":true,"img":false}]}
{"op":"mcm","clk":"1362290404","pt":1588436416374,"mc":[{"id":"1.170370564","rc":[{"atb":[[4.1,8.86]],"id":9630572}],"con":true,"img":false}]}
{"op":"mcm","clk":"1362290472","pt":1588436422972,"mc":[{"id":"1.170370564","rc":[{"atl":[[4.5,199.76]],"id":9630572}],"con":true,"img":false}]}
{"op":"mcm","clk":"1362290489","pt":1588436424198,"mc":[{"id":"1.170370564","rc":[{"atb":[[4.1,11.19]],"id":9630572}],"con":true,"img":false}]}
{"op":"mcm","clk":"1362290730","pt":1588436446038,"mc":[{"id":"1.170370564","rc":[{"trd":[[1.28,2481.66]],"ltp":1.28,"tv":2481.66,"id":8509691},{"atb":[[1.28,397.16]],"id":8509691}],"con":true,"img":false}]}
{"op":"mcm","clk":"1362290825","pt":1588436454511,"mc":[{"id":"1.170370564","rc":[{"atb":[[1.28,391.16]],"id":8509691}],"con":true,"img":false}]}
{"op":"mcm","clk":"1362290836","pt":1588436455125,"mc":[{"id":"1.170370564","rc":[{"atb":[[4.4,10.49]],"id":9630572}],"con":true,"img":false}]}
{"op":"mcm","clk":"1362290852","pt":1588436455890,"mc":[{"id":"1.170370564","rc":[{"atb":[[4.2,8.31]],"id":9630572}],"con":true,"img":false}]}
{"op":"mcm","clk":"1362290904","pt":1588436460140,"mc":[{"id":"1.170370564","rc":[{"atb":[[3.5,0]],"id":9630572},{"atb":[[1.25,0]],"id":8509691}],"con":true,"img":false}]}
{"op":"mcm","clk":"1362290949","pt":1588436464240,"mc":[{"id":"1.170370565","rc":[{"atl":[[1.92,22.16]],"id":11269555}],"con":true,"img":false}]}
{"op":"mcm","clk":"1362291079","pt":1588436480444,"mc":[{"id":"1.170370564","rc":[{"atb":[[1.29,984.92]],"id":8509691}],"con":true,"img":false}]}
{"op":"mcm","clk":"1362291088","pt":1588436481363,"mc":[{"id":"1.170370564","rc":[{"atb":[[1.29,0]],"id":8509691}],"con":true,"img":false}]}
{"op":"mcm","clk":"1362291108","pt":1588436483047,"mc":[{"id":"1.170370564","rc":[{"atb":[[1.28,1376.09]],"id":8509691}],"con":true,"img":false}]}
{"op":"mcm","clk":"1362291120","pt":1588436484321,"mc":[{"id":"1.170370564","rc":[{"atb":[[1.28,391.16]],"id":8509691}],"con":true,"img":false}]}
{"op":"mcm","clk":"1362291183","pt":1588436490961,"mc":[{"id":"1.170370564","rc":[{"trd":[[1.3,158.79]],"ltp":1.3,"tv":158.79,"id":8509691},{"atl":[[1.3,1633.84]],"id":8509691}],"con":true,"img":false}]}
{"op":"mcm","clk":"1362291253","pt":1588436497252,"mc":[{"id":"1.170370564","rc":[{"trd":[[1.28,2482.12]],"ltp":1.28,"tv":2482.12,"id":8509691},{"atb":[[1.28,390.93]],"id":8509691}],"con":true,"img":false}]}
{"op":"mcm","clk":"1362291480","pt":1588436517587,"mc":[{"id":"1.170370564","rc":[{"atl":[[1.29,0.68]],"id":8509691}],"con":true,"img":false}]}
{"op":"mcm","clk":"1362291684","pt":1588436538427,"mc":[{"id":"1.170370564","rc":[{"atb":[[4.1,8.86]],"id":9630572}],"con":true,"img":false}]}
{"op":"mcm","clk":"1362291688","pt":1588436538938,"mc":[{"id":"1.170370564","rc":[{"trd":[[1.29,20373.5]],"ltp":1.29,"tv":20373.5,"id":8509691},{"atb":[[1.29,3.31]],"id":8509691},{"atl":[[1.29,0]],"id":8509691}],"con":true,"img":false}]}
{"op":"mcm","clk":"1362291698","pt":1588436539808,"mc":[{"id":"1.170370565","rc":[{"atb":[[6.6,4]],"id":11340557},{"atb":[[6.6,4]],"id":11340560},{"atb":[[1.74,9]],"id":11269555},{"atb":[[3.35,5]],"id":11269557}],"con":true,"img":false}]}
{"op":"mcm","clk":"1362291777","pt":1588436547046,"mc":[{"id":"1.170370564","rc":[{"atb":[[4.1,11.19]],"id":9630572}],"con":true,"img":false}]}
{"op":"mcm","clk":"1362292345","pt":1588436600566,"mc":[{"id":"1.170370565","rc":[{"atl":[[8.6,6]],"id":11340557},{"atl":[[11.5,6]],"id":11340560},{"atl":[[1.91,4]],"id":11269555},{"atl":[[5,10]],"id":11269557}],"con":true,"img":false}]}
{"op":"mcm","clk":"1362292600","pt":1588436626029,"mc":[{"id":"1.170370564","rc":[{"trd":[[4.4,69.27]],"ltp":4.4,"tv":69.27,"id":9630572},{"atb":[[4.4,0]],"id":9630572},{"atl":[[4.4,29.5]],"id":9630572}],"con":true,"img":false}]}
{"op":"mcm","clk":"1362292610","pt":1588436627101,"mc":[{"id":"1.170370564","rc":[{"atb":[[4.2,0]],"id":9630572},{"atb":[[1.25,88.65]],"id":8509691}],"con":true,"img":false}]}
{"op":"mcm","clk":"1362292640","pt":1588436630313,"mc":[{"id":"1.170370564","rc":[{"atb":[[3.5,22.3]],"id":9630572},{"atb":[[1.25,311.69]],"id":8509691}],"con":true,"img":false}]}
{"op":"mcm","clk":"1362292765","pt":1588436644251,"mc":[{"id":"1.170370564","rc":[{"trd":[[1.29,20374.92]],"ltp":1.29,"tv":20374.92,"id":8509691},{"atb":[[1.29,2.59]],"id":8509691}],"con":true,"img":false}]}
{"op":"mcm","clk":"1362292889","pt":1588436657563,"mc":[{"id":"1.170370564","rc":[{"atb":[[4.1,8.86]],"id":9630572}],"con":true,"img":false}]}
{"op":"mcm","clk":"1362292926","pt":1588436660982,"mc":[{"id":"1.170370564","rc":[{"atb":[[1.29,55.08]],"id":8509691}],"con":true,"img":false}]}
{"op":"mcm","clk":"1362292967","pt":1588436664658,"mc":[{"id":"1.170370564","rc":[{"atb":[[4.1,11.19]],"id":9630572}],"con":true,"img":false}]}
{"op":"mcm","clk":"1362293170","pt":1588436687784,"mc":[{"id":"1.170370564","rc":[{"atl":[[4.4,17.5]],"id":9630572}],"con":true,"img":false}]}
{"op":"mcm","clk":"1362293175","pt":1588436688293,"mc":[{"id":"1.170370564","rc":[{"trd":[[1.3,169.3]],"ltp":1.3,"tv":169.3,"id":8509691},{"atl":[[1.3,1628.58]],"id":8509691}],"con":true,"img":false}]}
{"op":"mcm","clk":"1362293293","pt":1588436700359,"mc":[{"id":"1.170370564","rc":[{"atl":[[1.32,0]],"id":8509691}],"con":true,"img":false}]}
{"op":"mcm","clk":"1362293561","pt":1588436724196,"mc":[{"id":"1.170370564","rc":[{"trd":[[4.4,71.43]],"ltp":4.4,"tv":71.43,"id":9630572},{"atl":[[4.4,16.42]],"id":9630572}],"con":true,"img":false}]}
{"op":"mcm","clk":"1362293700","pt":1588436735503,"mc":[{"id":"1.170370564","rc":[{"atl":[[1.5,8.86]],"id":8509691}],"con":true,"img":false}]}
{"op":"mcm","clk":"1362293714","pt":1588436736579,"mc":[{"id":"1.170370564","rc":[{"trd":[[4.4,84.6]],"ltp":4.4,"tv":84.6,"id":9630572},{"atl":[[4.4,3.25]],"id":9630572},{"trd":[[1.29,20530]],"ltp":1.29,"tv":20530.0,"id":8509691},{"atb":[[1.29,0]],"id":8509691}],"con":true,"img":false}]}
{"op":"mcm","clk":"1362293722","pt":1588436737195,"mc":[{"id":"1.170370564","rc":[{"atb":[[1.25,223.04]],"id":8509691}],"con":true,"img":false}]}
{"op":"mcm","clk":"1362294090","pt":1588436770145,"mc":[{"id":"1.170370564","rc":[{"trd":[[1.3,169.71]],"ltp":1.3,"tv":169.71,"id":8509691},{"atl":[[1.3,1628.38]],"id":8509691}],"con":true,"img":false}]}
{"op":"mcm","clk":"1362294151","pt":1588436776648,"mc":[{"id":"1.170370564","rc":[{"atb":[[4.1,8.86]],"id":9630572}],"con":true,"img":false}]}
{"op":"mcm","clk":"1362294183","pt":1588436779354,"mc":[{"id":"1.170370564","rc":[{"trd":[[1.3,479.71]],"ltp":1.3,"tv":479.71,"id":8509691},{"atl":[[1.3,1473.38]],"id":8509691}],"con":true,"img":false}]}
{"op":"mcm","clk":"1362294286","pt":1588436785668,"mc":[{"id":"1.170370564","rc":[{"atb":[[4.1,11.19]],"id":9630572}],"con":true,"img":false}]}
{"op":"mcm","clk":"1362294373","pt":1588436798754,"mc":[{"id":"1.170370564","rc":[{"trd":[[1.3,483.71]],"ltp":1.3,"tv":483.71,"id":8509691},{"atl":[[1.3,1471.37]],"id":8509691}],"con":true,"img":false}]}
{"op":"mcm","clk":"1362294458","pt":1588436806937,"mc":[{"id":"1.170370564","rc":[{"trd":[[4.4,91.1]],"ltp":4.4,"tv":91.1,"id":9630572},{"atb":[[4.4,7.24]],"id":9630572},{"atl":[[4.4,0]],"id":9630572}],"con":true,"img":false}]}
{"op":"mcm","clk":"1362294473","pt":1588436808165,"mc":[{"id":"1.170370564","rc":[{"atb":[[4.2,8.31]],"id":9630572}],"con":true,"img":false}]}
{"op":"mcm","clk":"1362294596","pt":1588436818986,"mc":[{"id":"1.170370564","rc":[{"atb":[[1.29,52.48]],"id":8509691}],"con":true,"img":false}]}
{"op":"mcm","clk":"1362294643","pt":1588436822826,"mc":[{"id":"1.170370564","rc":[{"atl":[[1.46,2]],"id":8509691}],"con":true,"img":false}]}
{"op":"mcm","clk":"1362295168","pt":1588436873040,"mc":[{"id":"1.170370564","rc":[{"trd":[[1.29,20598.7]],"ltp":1.29,"tv":20598.7,"id":8509691},{"atb":[[1.29,18.13]],"id":8509691}],"con":true,"img":false}]}
{"op":"mcm","clk":"1362295449","pt":1588436900216,"mc":[{"id":"1.170370564","rc":[{"atb":[[4.1,8.86]],"id":9630572}],"con":true,"img":false}]}
{"op":"mcm","clk":"1362295532","pt":1588436908481,"mc":[{"id":"1.170370564","rc":[{"atb":[[4.1,11.19]],"id":9630572}],"con":true,"img":false}]}
{"op":"mcm","clk":"1362295704","pt":1588436925399,"mc":[{"id":"1.170370564","rc":[{"atb":[[1.01,1393.34],[1.03,3],[1.02,1380.21],[1.06,156.91],[1.05,0],[1.04,159.97]],"id":8509691}],"con":true,"img":false}]}
{"op":"mcm","clk":"1362295842","pt":1588436938920,"mc":[{"id":"1.170370564","rc":[{"atb":[[4.4,14.24]],"id":9630572}],"con":true,"img":false}]}
{"op":"mcm","clk":"1362295866","pt":1588436940962,"mc":[{"id":"1.170370564","rc":[{"atb":[[3.5,0]],"id":9630572},{"atb":[[1.25,0]],"id":8509691}],"con":true,"img":false}]}
{"op":"mcm","clk":"1362296004","pt":1588436953341,"mc":[{"id":"1.170370564","rc":[{"trd":[[1.29,20632.72]],"ltp":1.29,"tv":20632.72,"id":8509691},{"atb":[[1.29,1.12]],"id":8509691}],"con":true,"img":false}]}
{"op":"mcm","clk":"1362296047","pt":1588436957474,"mc":[{"id":"1.170370564","rc":[{"atb":[[1.2,0]],"id":8509691}],"con":true,"img":false}]}
{"op":"mcm","clk":"1362296049","pt":1588436957580,"mc":[{"id":"1.170370564","rc":[{"trd":[[4.4,113.13]],"ltp":4.4,"tv":113.13,"id":9630572},{"atb":[[4.4,3.23]],"id":9630572}],"con":true,"img":false}]}
{"op":"mcm","clk":"1362296060","pt":1588436958342,"mc":[{"id":"1.170370564","rc":[{"atb":[[4.2,0]],"id":9630572}],"con":true,"img":false}]}
{"op":"mcm","clk":"1362296845","pt":1588436960846,"mc":[{"id":"1.170370564","rc":[{"atb":[[3.5,22.3]],"id":9630572},{"atb":[[1.25,223.04]],"id":8509691}],"con":true,"img":false}]}
{"op":"mcm","clk":"1362296890","pt":1588436964938,"mc":[{"id":"1.170370564","rc":[{"atb":[[4.4,20.72]],"id":9630572}],"con":true,"img":false}]}
{"op":"mcm","clk":"1362296900","pt":1588436965957,"mc":[{"id":"1.170370564","rc":[{"atb":[[3.5,0]],"id":9630572},{"atb":[[1.25,0]],"id":8509691}],"con":true,"img":false}]}
{"op":"mcm","clk":"1362296903","pt":1588436966161,"mc":[{"id":"1.170370564","rc":[{"atb":[[4.2,8.31]],"id":9630572}],"con":true,"img":false}]}
{"op":"mcm","clk":"1362296995","pt":1588436972350,"mc":[{"id":"1.170370564","rc":[{"trd":[[1.3,483.76]],"ltp":1.3,"tv":483.76,"id":8509691},{"atl":[[1.3,1471.35]],"id":8509691}],"con":true,"img":false}]}
{"op":"mcm","clk":"1362297049","pt":1588436977459,"mc":[{"id":"1.170370564","rc":[{"atl":[[1.31,29.25]],"id":8509691}],"con":true,"img":false}]}
{"op":"mcm","clk":"1362297283","pt":1588436998265,"mc":[{"id":"1.170370564","rc":[{"trd":[[1.28,2482.8],[1.29,20634.97]],"ltp":1.28,"tv":23117.77,"id":8509691},{"atb":[[1.28,390.59],[1.29,0]],"id":8509691}],"con":true,"img":false}]}
{"op":"mcm","clk":"1362297292","pt":1588436998981,"mc":[{"id":"1.170370564","rc":[{"atb":[[1.29,52.48]],"id":8509691}],"con":true,"img":false}]}
{"op":"mcm","clk":"1362297322","pt":1588437001277,"mc":[{"id":"1.170370564","rc":[{"atb":[[4.1,2.61],[4.2,0]],"id":9630572},{"atb":[[1.23,0],[1.22,0],[1.24,0]],"id":8509691}],"con":true,"img":false}]}
{"op":"mcm","clk":"1362297526","pt":1588437021731,"mc":[{"id":"1.170370565","rc":[{"atb":[[1.74,0]],"id":11269555}],"con":true,"img":false}]}
{"op":"mcm","clk":"1362297530","pt":1588437021943,"mc":[{"id":"1.170370565","rc":[{"atb":[[3.35,0]],"id":11269557}],"con":true,"img":false}]}
{"op":"mcm","clk":"1362297534","pt":1588437022139,"mc":[{"id":"1.170370565","rc":[{"atb":[[6.6,0]],"id":11340557}],"con":true,"img":false}]}
{"op":"mcm","clk":"1362297538","pt":1588437022342,"mc":[{"id":"1.170370565","rc":[{"atb":[[6.6,0]],"id":11340560}],"con":true,"img":false}]}
{"op":"mcm","clk":"1362297541","pt":1588437022495,"mc":[{"id":"1.170370565","rc":[{"atl":[[1.91,0]],"id":11269555}],"con":true,"img":false}]}
{"op":"mcm","clk":"1362297544","pt":1588437022700,"mc":[{"id":"1.170370565","rc":[{"atl":[[5,5]],"id":11269557}],"con":true,"img":false}]}
{"op":"mcm","clk":"1362297548","pt":1588437023006,"mc":[{"id":"1.170370565","rc":[{"atl":[[8.6,0]],"id":11340557}],"con":true,"img":false}]}
{"op":"mcm","clk":"1362297551","pt":1588437023208,"mc":[{"id":"1.170370565","rc":[{"atl":[[11.5,0]],"id":11340560}],"con":true,"img":false}]}
{"op":"mcm","clk":"1362297562","pt":1588437024126,"mc":[{"id":"1.170370564","rc":[{"atb":[[4.1,0.28]],"id":9630572}],"con":true,"img":false}]}
{"op":"mcm","clk":"1362297566","pt":1588437024329,"mc":[{"id":"1.170370565","rc":[{"atb":[[6.6,4]],"id":11340557},{"atb":[[6.6,4]],"id":11340560},{"atb":[[1.74,9]],"id":11269555},{"atb":[[3.35,5]],"id":11269557}],"con":true,"img":false}]}
{"op":"mcm","clk":"1362297613","pt":1588437028519,"mc":[{"id":"1.170370564","rc":[{"trd":[[1.3,496.14]],"ltp":1.3,"tv":496.14,"id":8509691},{"atl":[[1.3,1465.16]],"id":8509691}],"con":true,"img":false}]}
{"op":"mcm","clk":"1362297673","pt":1588437032408,"mc":[{"id":"1.170370564","rc":[{"atb":[[4.1,2.61]],"id":9630572}],"con":true,"img":false}]}
{"op":"mcm","clk":"1362298231","pt":1588437085105,"mc":[{"id":"1.170370565","rc":[{"atl":[[8.6,6]],"id":11340557},{"atl":[[11.5,6]],"id":11340560},{"atl":[[1.91,4]],"id":11269555},{"atl":[[5,10]],"id":11269557}],"con":true,"img":false}]}
{"op":"mcm","clk":"1362298729","pt":1588437130770,"mc":[{"id":"1.170370564","rc":[{"trd":[[1.29,20636.14]],"ltp":1.29,"tv":20636.14,"id":8509691},{"atb":[[1.29,51.89]],"id":8509691}],"con":true,"img":false}]}
{"op":"mcm","clk":"1362298786","pt":1588437135978,"mc":[{"id":"1.170370564","rc":[{"atb":[[4.1,0.28]],"id":9630572}],"con":true,"img":false}]}
{"op":"mcm","clk":"1362298855","pt":1588437142670,"mc":[{"id":"1.170370564","rc":[{"trd":[[1.29,20637.09]],"ltp":1.29,"tv":20637.09,"id":8509691},{"atb":[[1.29,51.42]],"id":8509691}],"con":true,"img":false}]}
{"op":"mcm","clk":"1362298903","pt":1588437145939,"mc":[{"id":"1.170370564","rc":[{"atb":[[4.1,2.61]],"id":9630572}],"con":true,"img":false}]}
{"op":"mcm","clk":"1362299273","pt":1588437174185,"mc":[{"id":"1.170370564","rc":[{"trd":[[1.3,502.14]],"ltp":1.3,"tv":502.14,"id":8509691},{"atl":[[1.3,1462.16]],"id":8509691}],"con":true,"img":false}]}
{"op":"mcm","clk":"1362299307","pt":1588437176279,"mc":[{"id":"1.170370564","rc":[{"atb":[[1.29,52.11]],"id":8509691}],"con":true,"img":false}]}
{"op":"mcm","clk":"1362299351","pt":1588437179295,"mc":[{"id":"1.170370564","rc":[{"trd":[[4.4,154.57]],"ltp":4.4,"tv":154.57,"id":9630572},{"atb":[[4.4,0]],"id":9630572},{"atl":[[4.4,0.55]],"id":9630572}],"con":true,"img":false}]}
{"op":"mcm","clk":"1362299373","pt":1588437181178,"mc":[{"id":"1.170370564","rc":[{"atb":[[3.5,22.3]],"id":9630572},{"atb":[[1.25,223.04]],"id":8509691}],"con":true,"img":false}]}
{"op":"mcm","clk":"1362299472","pt":1588437189116,"mc":[{"id":"1.170370564","rc":[{"atl":[[4.4,0]],"id":9630572}],"con":true,"img":false}]}
{"op":"mcm","clk":"1362299942","pt":1588437230961,"mc":[{"id":"1.170370564","rc":[{"atb":[[1.29,104.59]],"id":8509691}],"con":true,"img":false}]}
{"op":"mcm","clk":"1362300212","pt":1588437256910,"mc":[{"id":"1.170370564","rc":[{"atb":[[4.1,0.28]],"id":9630572}],"con":true,"img":false}]}
{"op":"mcm","clk":"1362300281","pt":1588437263910,"mc":[{"id":"1.170370564","rc":[{"atb":[[4.1,2.61]],"id":9630572}],"con":true,"img":false}]}
{"op":"mcm","clk":"1362300621","pt":1588437297794,"mc":[{"id":"1.170370564","rc":[{"trd":[[1.29,20640.64]],"ltp":1.29,"tv":20640.64,"id":8509691},{"atb":[[1.29,102.82]],"id":8509691}],"con":true,"img":false}]}
{"op":"mcm","clk":"1362300645","pt":1588437300284,"mc":[{"id":"1.170370564","rc":[{"trd":[[1.29,20644.18]],"ltp":1.29,"tv":20644.18,"id":8509691},{"atb":[[1.29,101.04]],"id":8509691}],"con":true,"img":false}]}
{"op":"mcm","clk":"1362300702","pt":1588437305555,"mc":[{"id":"1.170370564","rc":[{"trd":[[1.29,20647.73]],"ltp":1.29,"tv":20647.73,"id":8509691},{"atb":[[1.29,99.27]],"id":8509691}],"con":true,"img":false}]}
{"op":"mcm","clk":"1362300736","pt":1588437308976,"mc":[{"id":"1.170370564","rc":[{"atb":[[4.3,9.62]],"id":9630572}],"con":true,"img":false}]}
{"op":"mcm","clk":"1362300742","pt":1588437309484,"mc":[{"id":"1.170370564","rc":[{"trd":[[1.29,20651.27]],"ltp":1.29,"tv":20651.27,"id":8509691},{"atb":[[1.29,97.5]],"id":8509691}],"con":true,"img":false}]}
{"op":"mcm","clk":"1362300758","pt":1588437311061,"mc":[{"id":"1.170370564","rc":[{"trd":[[1.29,20654.82]],"ltp":1.29,"tv":20654.82,"id":8509691},{"atb":[[1.29,95.72]],"id":8509691}],"con":true,"img":false}]}
{"op":"mcm","clk":"1362300814","pt":1588437316677,"mc":[{"id":"1.170370564","rc":[{"trd":[[1.29,20658.37]],"ltp":1.29,"tv":20658.37,"id":8509691},{"atb":[[1.29,93.95]],"id":8509691}],"con":true,"img":false}]}
{"op":"mcm","clk":"1362300843","pt":1588437319995,"mc":[{"id":"1.170370564","rc":[{"trd":[[1.29,20661.91]],"ltp":1.29,"tv":20661.91,"id":8509691},{"atb":[[1.29,92.18]],"id":8509691}],"con":true,"img":false}]}
{"op":"mcm","clk":"1362300871","pt":1588437322809,"mc":[{"id":"1.170370564","rc":[{"trd":[[1.29,20665.46]],"ltp":1.29,"tv":20665.46,"id":8509691},{"atb":[[1.29,90.4]],"id":8509691}],"con":true,"img":false}]}
{"op":"mcm","clk":"1362300905","pt":1588437326379,"mc":[{"id":"1.170370564","rc":[{"atl":[[1.3,1467.16]],"id":8509691}],"con":true,"img":false}]}
{"op":"mcm","clk":"1362300928","pt":1588437328831,"mc":[{"id":"1.170370564","rc":[{"trd":[[1.29,20669.01]],"ltp":1.29,"tv":20669.01,"id":8509691},{"atb":[[1.29,88.63]],"id":8509691}],"con":true,"img":false}]}
{"op":"mcm","clk":"1362300962","pt":1588437331687,"mc":[{"id":"1.170370564","rc":[{"trd":[[1.29,20672.55]],"ltp":1.29,"tv":20672.55,"id":8509691},{"atb":[[1.29,86.86]],"id":8509691}],"con":true,"img":false}]}
{"op":"mcm","clk":"1362301247","pt":1588437360375,"mc":[{"id":"1.170370564","rc":[{"trd":[[1.3,557.26]],"ltp":1.3,"tv":557.26,"id":8509691},{"atl":[[1.3,1439.6]],"id":8509691}],"con":true,"img":false}]}
{"op":"mcm","clk":"1362301296","pt":1588437365088,"mc":[{"id":"1.170370564","rc":[{"trd":[[1.3,677.26]],"ltp":1.3,"tv":677.26,"id":8509691},{"atl":[[1.3,1379.6]],"id":8509691}],"con":true,"img":false}]}
{"op":"mcm","clk":"1362301411","pt":1588437376565,"mc":[{"id":"1.170370564","rc":[{"atb":[[4.1,0.28]],"id":9630572}],"con":true,"img":false}]}
{"op":"mcm","clk":"1362301481","pt":1588437383614,"mc":[{"id":"1.170370564","rc":[{"atb":[[4.1,2.61]],"id":9630572}],"con":true,"img":false}]}
{"op":"mcm","clk":"1362302022","pt":1588437437861,"mc":[{"id":"1.170370564","rc":[{"trd":[[1.3,689.26]],"ltp":1.3,"tv":689.26,"id":8509691},{"atl":[[1.3,1373.6]],"id":8509691}],"con":true,"img":false}]}
{"op":"mcm","clk":"1362302227","pt":1588437461033,"mc":[{"id":"1.170370564","rc":[{"trd":[[1.29,20754.55]],"ltp":1.29,"tv":20754.55,"id":8509691},{"atb":[[1.29,45.86]],"id":8509691}],"con":true,"img":false}]}
{"op":"mcm","clk":"1362302387","pt":1588437475527,"mc":[{"id":"1.170370564","rc":[{"trd":[[1.29,20846.28]],"ltp":1.29,"tv":20846.28,"id":8509691},{"atb":[[1.29,0]],"id":8509691},{"atl":[[1.29,34.12]],"id":8509691}],"con":true,"img":false}]}
{"op":"mcm","clk":"1362302404","pt":1588437476956,"mc":[{"id":"1.170370564","rc":[{"trd":[[1.29,20914.52]],"ltp":1.29,"tv":20914.52,"id":8509691},{"atb":[[1.29,18.35]],"id":8509691},{"atl":[[1.29,0]],"id":8509691}],"con":true,"img":false}]}
{"op":"mcm","clk":"1362302463","pt":1588437482930,"mc":[{"id":"1.170370564","rc":[{"atb":[[4.4,10.49]],"id":9630572}],"con":true,"img":false}]}
{"op":"mcm","clk":"1362302507","pt":1588437486823,"mc":[{"id":"1.170370564","rc":[{"atb":[[3.5,0]],"id":9630572},{"atb":[[1.25,0]],"id":8509691}],"con":true,"img":false}]}
{"op":"mcm","clk":"1362302586","pt":1588437495250,"mc":[{"id":"1.170370564","rc":[{"atb":[[4.1,0.28]],"id":9630572}],"con":true,"img":false}]}
{"op":"mcm","clk":"1362302681","pt":1588437504184,"mc":[{"id":"1.170370564","rc":[{"atb":[[4.1,2.61]],"id":9630572}],"con":true,"img":false}]}
{"op":"mcm","clk":"1362303115","pt":1588437546959,"mc":[{"id":"1.170370564","rc":[{"trd":[[1.3,699.85]],"ltp":1.3,"tv":699.85,"id":8509691},{"atl":[[1.3,1368.31]],"id":8509691}],"con":true,"img":false}]}
{"op":"mcm","clk":"1362303350","pt":1588437571973,"mc":[{"id":"1.170370564","rc":[{"atb":[[4.4,20.99]],"id":9630572}],"con":true,"img":false}]}
{"op":"mcm","clk":"1362304085","pt":1588437639162,"mc":[{"id":"1.170370564","rc":[{"atb":[[4.1,0.28]],"id":9630572}],"con":true,"img":false}]}
{"op":"mcm","clk":"1362304166","pt":1588437646507,"mc":[{"id":"1.170370564","rc":[{"atb":[[4.1,2.61]],"id":9630572}],"con":true,"img":false}]}
{"op":"mcm","clk":"1362304371","pt":1588437667415,"mc":[{"id":"1.170370564","rc":[{"atb":[[1.27,2.33]],"id":8509691}],"con":true,"img":false}]}
{"op":"mcm","clk":"1362304983","pt":1588437736411,"mc":[{"id":"1.170370564","rc":[{"atb":[[4.1,0.28]],"id":9630572}],"con":true,"img":false}]}
{"op":"mcm","clk":"1362305049","pt":1588437743501,"mc":[{"id":"1.170370564","rc":[{"atb":[[4.1,2.61]],"id":9630572}],"con":true,"img":false}]}
{"op":"mcm","clk":"1362305504","pt":1588437793801,"mc":[{"id":"1.170370564","rc":[{"trd":[[1.3,703.87]],"ltp":1.3,"tv":703.87,"id":8509691},{"atl":[[1.3,1366.29]],"id":8509691}],"con":true,"img":false}]}
{"op":"mcm","clk":"1362305687","pt":1588437813200,"mc":[{"id":"1.170370564","rc":[{"trd":[[1.29,20916.16]],"ltp":1.29,"tv":20916.16,"id":8509691},{"atb":[[1.29,17.54]],"id":8509691}],"con":true,"img":false}]}
{"op":"mcm","clk":"1362306071","pt":1588437852952,"mc":[{"id":"1.170370564","rc":[{"trd":[[4.5,489.44]],"ltp":4.5,"tv":489.44,"id":9630572},{"atl":[[4.5,198.02]],"id":9630572}],"con":true,"img":false}]}
{"op":"mcm","clk":"1362306901","pt":1588437861563,"mc":[{"id":"1.170370564","rc":[{"atb":[[4.1,0.28]],"id":9630572}],"con":true,"img":false}]}
{"op":"mcm","clk":"1362306986","pt":1588437870545,"mc":[{"id":"1.170370564","rc":[{"atb":[[4.1,2.61]],"id":9630572}],"con":true,"img":false}]}
{"op":"mcm","clk":"1362307259","pt":1588437887389,"mc":[{"id":"1.170370564","rc":[{"trd":[[4.4,158.68]],"ltp":4.4,"tv":158.68,"id":9630572},{"atb":[[4.4,18.93]],"id":9630572}],"con":true,"img":false}]}
{"op":"mcm","clk":"1362307273","pt":1588437888104,"mc":[{"id":"1.170370564","rc":[{"atb":[[4.3,0]],"id":9630572}],"con":true,"img":false}]}
{"op":"mcm","clk":"1362307366","pt":1588437893819,"mc":[{"id":"1.170370564","rc":[{"trd":[[1.3,703.91]],"ltp":1.3,"tv":703.91,"id":8509691},{"atl":[[1.3,1366.28]],"id":8509691}],"con":true,"img":false}]}
{"op":"mcm","clk":"1362307450","pt":1588437897904,"mc":[{"id":"1.170370564","rc":[{"trd":[[1.3,705.79]],"ltp":1.3,"tv":705.79,"id":8509691},{"atl":[[1.3,1365.34]],"id":8509691}],"con":true,"img":false}]}
{"op":"mcm","clk":"1362307489","pt":1588437899788,"mc":[{"id":"1.170370564","rc":[{"trd":[[1.29,20917.11]],"ltp":1.29,"tv":20917.11,"id":8509691},{"atb":[[1.29,17.06]],"id":8509691}],"con":true,"img":false}]}
{"op":"mcm","clk":"1362308384","pt":1588437944922,"mc":[{"id":"1.170370564","rc":[{"atb":[[4.4,22.43]],"id":9630572}],"con":true,"img":false}]}
{"op":"mcm","clk":"1362308933","pt":1588437969350,"mc":[{"id":"1.170370564","rc":[{"atl":[[4.5,0]],"id":9630572},{"atb":[[1.28,110.81],[1.26,0]],"id":8509691},{"atl":[[1.3,13]],"id":8509691}],"con":true,"img":false}]}
{"op":"mcm","clk":"1362309217","pt":1588437981289,"mc":[{"id":"1.170370564","rc":[{"trd":[[1.3,707.68]],"ltp":1.3,"tv":707.68,"id":8509691},{"atl":[[1.3,12.06]],"id":8509691}],"con":true,"img":false}]}
{"op":"mcm","clk":"1362309275","pt":1588437984096,"mc":[{"id":"1.170370564","rc":[{"atb":[[4.1,0.28]],"id":9630572}],"con":true,"img":false}]}
{"op":"mcm","clk":"1362309455","pt":1588437991804,"mc":[{"id":"1.170370564","rc":[{"atb":[[4.1,2.61]],"id":9630572}],"con":true,"img":false}]}
{"op":"mcm","clk":"1362309631","pt":1588438000399,"mc":[{"id":"1.170370564","rc":[{"trd":[[1.29,20951.25]],"ltp":1.29,"tv":20951.25,"id":8509691},{"atb":[[1.29,0]],"id":8509691},{"atl":[[1.29,32.93]],"id":8509691}],"con":true,"img":false}]}
{"op":"mcm","clk":"1362309728","pt":1588438004633,"mc":[{"id":"1.170370564","rc":[{"atl":[[1.29,49.72]],"id":8509691}],"con":true,"img":false}]}
{"op":"mcm","clk":"1362309740","pt":1588438004938,"mc":[{"id":"1.170370564","rc":[{"atl":[[1.29,16.79]],"id":8509691}],"con":true,"img":false}]}
{"op":"mcm","clk":"1362309742","pt":1588438005042,"mc":[{"id":"1.170370564","rc":[{"trd":[[1.28,2548.66]],"ltp":1.28,"tv":2548.66,"id":8509691},{"atb":[[1.28,77.88]],"id":8509691}],"con":true,"img":false}]}
{"op":"mcm","clk":"1362309791","pt":1588438006931,"mc":[{"id":"1.170370564","rc":[{"atl":[[1.29,0]],"id":8509691}],"con":true,"img":false}]}
{"op":"mcm","clk":"1362309977","pt":1588438015250,"mc":[{"id":"1.170370564","rc":[{"trd":[[4.4,166.93]],"ltp":4.4,"tv":166.93,"id":9630572},{"atb":[[4.4,14.18]],"id":9630572},{"trd":[[1.3,759.73]],"ltp":1.3,"tv":759.73,"id":8509691},{"atl":[[1.3,0]],"id":8509691}],"con":true,"img":false}]}
{"op":"mcm","clk":"1362310137","pt":1588438022443,"mc":[{"id":"1.170370564","rc":[{"trd":[[1.28,2703.84]],"ltp":1.28,"tv":2703.84,"id":8509691},{"atb":[[1.28,0.29]],"id":8509691}],"con":true,"img":false}]}
{"op":"mcm","clk":"1362310142","pt":1588438022750,"mc":[{"id":"1.170370564","rc":[{"atb":[[3.5,22.3]],"id":9630572},{"atb":[[1.25,223.04]],"id":8509691}],"con":true,"img":false}]}
{"op":"mcm","clk":"1362310159","pt":1588438023421,"mc":[{"id":"1.170370564","rc":[{"atb":[[1.28,3.49]],"id":8509691}],"con":true,"img":false}]}
{"op":"mcm","clk":"1362310241","pt":1588438026856,"mc":[{"id":"1.170370564","rc":[{"trd":[[1.28,2710.23]],"ltp":1.28,"tv":2710.23,"id":8509691},{"atb":[[1.28,0.29]],"id":8509691}],"con":true,"img":false}]}
{"op":"mcm","clk":"1362310460","pt":1588438035942,"mc":[{"id":"1.170370564","rc":[{"trd":[[1.27,381.09],[1.28,2710.82]],"ltp":1.27,"tv":3091.91,"id":8509691},{"atb":[[1.28,0],[1.27,0.23]],"id":8509691}],"con":true,"img":false}]}
{"op":"mcm","clk":"1362310471","pt":1588438036555,"mc":[{"id":"1.170370564","rc":[{"atl":[[1000,2.51]],"id":8509691}],"con":true,"img":false}]}
{"op":"mcm","clk":"1362310475","pt":1588438036758,"mc":[{"id":"1.170370564","rc":[{"atl":[[1000,0.5]],"id":8509691}],"con":true,"img":false}]}
{"op":"mcm","clk":"1362310480","pt":1588438036964,"mc":[{"id":"1.170370564","rc":[{"atl":[[1000,0]],"id":8509691}],"con":true,"img":false}]}
{"op":"mcm","clk":"1362310484","pt":1588438037067,"mc":[{"id":"1.170370564","rc":[{"trd":[[1.25,0.56],[1.27,381.55]],"ltp":1.25,"tv":382.11,"id":8509691},{"atb":[[1.27,0],[1.25,222.76]],"id":8509691}],"con":true,"img":false}]}
{"op":"mcm","clk":"1362310502","pt":1588438037787,"mc":[{"id":"1.170370564","rc":[{"atb":[[1.25,445.8]],"id":8509691}],"con":true,"img":false}]}
{"op":"mcm","clk":"1362310505","pt":1588438037882,"mc":[{"id":"1.170370564","rc":[{"atb":[[1.25,223.04]],"id":8509691}],"con":true,"img":false}]}
{"op":"mcm","clk":"1362310712","pt":1588438047989,"mc":[{"id":"1.170370564","rc":[{"atb":[[1.26,1378.54]],"id":8509691},{"atl":[[1.29,1595.74]],"id":8509691}],"con":true,"img":false}]}
{"op":"mcm","clk":"1362311047","pt":1588438062310,"mc":[{"id":"1.170370564","rc":[{"atl":[[1.27,15.99]],"id":8509691}],"con":true,"img":false}]}
{"op":"mcm","clk":"1362311052","pt":1588438062511,"mc":[{"id":"1.170370564","rc":[{"trd":[[1.27,413.55]],"ltp":1.27,"tv":413.55,"id":8509691},{"atb":[[1.27,0.02]],"id":8509691},{"atl":[[1.27,0]],"id":8509691}],"con":true,"img":false}]}
{"op":"mcm","clk":"1362311060","pt":1588438062715,"mc":[{"id":"1.170370564","rc":[{"atb":[[1.27,0]],"id":8509691}],"con":true,"img":false}]}
{"op":"mcm","clk":"1362311138","pt":1588438066025,"mc":[{"id":"1.170370564","rc":[{"atb":[[1.27,26.24]],"id":8509691}],"con":true,"img":false}]}
{"op":"mcm","clk":"1362311292","pt":1588438073114,"mc":[{"id":"1.170370564","rc":[{"trd":[[1.29,21067.18]],"ltp":1.29,"tv":21067.18,"id":8509691},{"atl":[[1.29,1537.77]],"id":8509691}],"con":true,"img":false}]}
{"op":"mcm","clk":"1362311437","pt":1588438080308,"mc":[{"id":"1.170370564","rc":[{"trd":[[1.27,464.74]],"ltp":1.27,"tv":464.74,"id":8509691},{"atb":[[1.27,0.64]],"id":8509691}],"con":true,"img":false}]}
{"op":"mcm","clk":"1362311589","pt":1588438087236,"mc":[{"id":"1.170370564","rc":[{"atb":[[1.28,2.39]],"id":8509691}],"con":true,"img":false}]}
{"op":"mcm","clk":"1362311606","pt":1588438088252,"mc":[{"id":"1.170370564","rc":[{"trd":[[1.27,466.04],[1.28,2715.62]],"ltp":1.27,"tv":3181.66,"id":8509691},{"atb":[[1.28,0],[1.27,0]],"id":8509691},{"atl":[[1.27,12.94]],"id":8509691}],"con":true,"img":false}]}
{"op":"mcm","clk":"1362311612","pt":1588438088455,"mc":[{"id":"1.170370564","rc":[{"trd":[[1.27,491.94]],"ltp":1.27,"tv":491.94,"id":8509691},{"atb":[[1.27,0.01]],"id":8509691},{"atl":[[1.27,0]],"id":8509691}],"con":true,"img":false}]}
{"op":"mcm","clk":"1362311617","pt":1588438088760,"mc":[{"id":"1.170370564","rc":[{"atb":[[1.27,0]],"id":8509691}],"con":true,"img":false}]}
{"op":"mcm","clk":"1362311774","pt":1588438096762,"mc":[{"id":"1.170370564","rc":[{"atb":[[4.1,0.28]],"id":9630572}],"con":true,"img":false}]}
{"op":"mcm","clk":"1362311840","pt":1588438099773,"mc":[{"id":"1.170370564","rc":[{"atl":[[1.27,15.99]],"id":8509691}],"con":true,"img":false}]}
{"op":"mcm","clk":"1362311928","pt":1588438103858,"mc":[{"id":"1.170370564","rc":[{"atb":[[4.1,2.61]],"id":9630572}],"con":true,"img":false}]}
{"op":"mcm","clk":"1362311956","pt":1588438105079,"mc":[{"id":"1.170370564","rc":[{"atb":[[1.11,60]],"id":8509691}],"con":true,"img":false}]}
{"op":"mcm","clk":"1362311972","pt":1588438105541,"mc":[{"id":"1.170370564","rc":[{"atb":[[1.1,31.99]],"id":8509691}],"con":true,"img":false}]}
{"op":"mcm","clk":"1362312015","pt":1588438107783,"mc":[{"id":"1.170370564","rc":[{"atb":[[1.06,845.74]],"id":8509691}],"con":true,"img":false}]}
{"op":"mcm","clk":"1362312022","pt":1588438108142,"mc":[{"id":"1.170370564","rc":[{"atb":[[1.05,688.82]],"id":8509691}],"con":true,"img":false}]}
{"op":"mcm","clk":"1362312047","pt":1588438109365,"mc":[{"id":"1.170370564","rc":[{"atl":[[1.27,0]],"id":8509691}],"con":true,"img":false}]}
{"op":"mcm","clk":"1362312104","pt":1588438112377,"mc":[{"id":"1.170370564","rc":[{"trd":[[1.29,21149.12]],"ltp":1.29,"tv":21149.12,"id":8509691},{"atl":[[1.29,1496.8]],"id":8509691}],"con":true,"img":false}]}
{"op":"mcm","clk":"1362312113","pt":1588438112786,"mc":[{"id":"1.170370564","rc":[{"trd":[[1.26,44.95]],"ltp":1.26,"tv":44.95,"id":8509691},{"atb":[[1.26,1371.02]],"id":8509691}],"con":true,"img":false}]}
{"op":"mcm","clk":"1362312139","pt":1588438113956,"mc":[{"id":"1.170370564","rc":[{"atl":[[1.28,69.97]],"id":8509691}],"con":true,"img":false}]}
{"op":"mcm","clk":"1362312222","pt":1588438118354,"mc":[{"id":"1.170370564","rc":[{"trd":[[1.26,169.73]],"ltp":1.26,"tv":169.73,"id":8509691},{"atb":[[1.26,1308.63]],"id":8509691}],"con":true,"img":false}]}
{"op":"mcm","clk":"1362312349","pt":1588438124683,"mc":[{"id":"1.170370565","rc":[{"atl":[[1.9,31.02]],"id":11269555}],"con":true,"img":false}]}
{"op":"mcm","clk":"1362313149","pt":1588438178728,"mc":[{"id":"1.170370564","rc":[{"trd":[[1.28,2855.57]],"ltp":1.28,"tv":2855.57,"id":8509691},{"atb":[[1.28,63]],"id":8509691},{"atl":[[1.28,0]],"id":8509691}],"con":true,"img":false}]}
{"op":"mcm","clk":"1362313211","pt":1588438183168,"mc":[{"id":"1.170370564","rc":[{"atb":[[3.5,0]],"id":9630572},{"atb":[[1.25,0]],"id":8509691}],"con":true,"img":false}]}
{"op":"mcm","clk":"1362313259","pt":1588438187552,"mc":[{"id":"1.170370564","rc":[{"trd":[[1.28,2861.97]],"ltp":1.28,"tv":2861.97,"id":8509691},{"atb":[[1.28,59.8]],"id":8509691}],"con":true,"img":false}]}
{"op":"mcm","clk":"1362313277","pt":1588438188778,"mc":[{"id":"1.170370564","rc":[{"atb":[[1.27,3.19]],"id":8509691}],"con":true,"img":false}]}
{"op":"mcm","clk":"1362313338","pt":1588438193995,"mc":[{"id":"1.170370564","rc":[{"trd":[[1.28,2981.58]],"ltp":1.28,"tv":2981.58,"id":8509691},{"atb":[[1.28,0]],"id":8509691},{"atl":[[1.28,10.17]],"id":8509691}],"con":true,"img":false}]}
{"op":"mcm","clk":"1362313353","pt":1588438194965,"mc":[{"id":"1.170370564","rc":[{"atl":[[1.28,122.17]],"id":8509691}],"con":true,"img":false}]}
{"op":"mcm","clk":"1362313397","pt":1588438198072,"mc":[{"id":"1.170370564","rc":[{"atb":[[3.5,22.3]],"id":9630572},{"atb":[[1.25,223.04]],"id":8509691}],"con":true,"img":false}]}
{"op":"mcm","clk":"1362313404","pt":1588438198279,"mc":[{"id":"1.170370564","rc":[{"atl":[[1.28,10.17]],"id":8509691}],"con":true,"img":false}]}
{"op":"mcm","clk":"1362313453","pt":1588438199865,"mc":[{"id":"1.170370564","rc":[{"trd":[[1.28,3001.92]],"ltp":1.28,"tv":3001.92,"id":8509691},{"atb":[[1.28,5.65]],"id":8509691},{"atl":[[1.28,0]],"id":8509691}],"con":true,"img":false}]}
{"op":"mcm","clk":"1362313467","pt":1588438200988,"mc":[{"id":"1.170370564","rc":[{"atb":[[1.27,73.17]],"id":8509691}],"con":true,"img":false}]}
{"op":"mcm","clk":"1362313600","pt":1588438208915,"mc":[{"id":"1.170370564","rc":[{"trd":[[1.29,21153.92]],"ltp":1.29,"tv":21153.92,"id":8509691},{"atl":[[1.29,1494.4]],"id":8509691}],"con":true,"img":false}]}
{"op":"mcm","clk":"1362313721","pt":1588438215194,"mc":[{"id":"1.170370564","rc":[{"atb":[[4.1,0.28]],"id":9630572}],"con":true,"img":false}]}
{"op":"mcm","clk":"1362313744","pt":1588438216022,"mc":[{"id":"1.170370564","rc":[{"trd":[[1.28,3012.51]],"ltp":1.28,"tv":3012.51,"id":8509691},{"atb":[[1.28,0.36]],"id":8509691}],"con":true,"img":false}]}
{"op":"mcm","clk":"1362313765","pt":1588438217349,"mc":[{"id":"1.170370564","rc":[{"atb":[[4.1,2.61]],"id":9630572}],"con":true,"img":false}]}
{"op":"mcm","clk":"1362313880","pt":1588438223317,"mc":[{"id":"1.170370564","rc":[{"trd":[[1.29,21158.64]],"ltp":1.29,"tv":21158.64,"id":8509691},{"atl":[[1.29,1492.04]],"id":8509691}],"con":true,"img":false}]}
{"op":"mcm","clk":"1362313945","pt":1588438227396,"mc":[{"id":"1.170370565","rc":[{"atb":[[1.74,0]],"id":11269555}],"con":true,"img":false}]}
{"op":"mcm","clk":"1362313949","pt":1588438227599,"mc":[{"id":"1.170370565","rc":[{"atb":[[3.35,0]],"id":11269557}],"con":true,"img":false}]}
{"op":"mcm","clk":"1362313953","pt":1588438227804,"mc":[{"id":"1.170370565","rc":[{"atb":[[6.6,0]],"id":11340557}],"con":true,"img":false}]}
{"op":"mcm","clk":"1362313957","pt":1588438228005,"mc":[{"id":"1.170370565","rc":[{"atb":[[6.6,0]],"id":11340560}],"con":true,"img":false}]}
{"op":"mcm","clk":"1362313963","pt":1588438228415,"mc":[{"id":"1.170370565","rc":[{"atb":[[6.6,4]],"id":11340557},{"atb":[[6.6,4]],"id":11340560},{"atb":[[1.71,9]],"id":11269555},{"atb":[[3.35,5]],"id":11269557}],"con":true,"img":false}]}
{"op":"mcm","clk":"1362314023","pt":1588438233003,"mc":[{"id":"1.170370564","rc":[{"trd":[[1.29,21163.79]],"ltp":1.29,"tv":21163.79,"id":8509691},{"atl":[[1.29,1489.46]],"id":8509691}],"con":true,"img":false}]}
{"op":"mcm","clk":"1362314156","pt":1588438243117,"mc":[{"id":"1.170370564","rc":[{"atl":[[4.7,69.14]],"id":9630572}],"con":true,"img":false}]}
{"op":"mcm","clk":"1362314320","pt":1588438254957,"mc":[{"id":"1.170370564","rc":[{"atb":[[4.5,10.49]],"id":9630572}],"con":true,"img":false}]}
{"op":"mcm","clk":"1362314363","pt":1588438258164,"mc":[{"id":"1.170370564","rc":[{"atb":[[3.5,0]],"id":9630572},{"trd":[[1.29,21474.95]],"ltp":1.29,"tv":21474.95,"id":8509691},{"atb":[[1.25,0]],"id":8509691},{"atl":[[1.29,1333.89]],"id":8509691}],"con":true,"img":false}]}
{"op":"mcm","clk":"1362314457","pt":1588438265137,"mc":[{"id":"1.170370564","rc":[{"atb":[[1.01,514.79]],"id":9630572},{"atb":[[1.01,1893.34]],"id":8509691}],"con":true,"img":false}]}
{"op":"mcm","clk":"1362314636","pt":1588438278163,"mc":[{"id":"1.170370564","rc":[{"trd":[[1.27,507.22],[1.28,3013.23]],"ltp":1.27,"tv":3520.44,"id":8509691},{"atb":[[1.28,0],[1.27,65.53]],"id":8509691}],"con":true,"img":false}]}
{"op":"mcm","clk":"1362314662","pt":1588438280206,"mc":[{"id":"1.170370564","rc":[{"trd":[[4.7,0.8]],"ltp":4.7,"tv":0.8,"id":9630572},{"atl":[[4.7,68.34]],"id":9630572},{"trd":[[1.27,641.28]],"ltp":1.27,"tv":641.28,"id":8509691},{"atb":[[1.27,0]],"id":8509691}],"con":true,"img":false}]}
{"op":"mcm","clk":"1362314687","pt":1588438281790,"mc":[{"id":"1.170370564","rc":[{"atl":[[1.28,3.19]],"id":8509691}],"con":true,"img":false}]}
{"op":"mcm","clk":"1362314704","pt":1588438283169,"mc":[{"id":"1.170370564","rc":[{"atb":[[3.5,22.3]],"id":9630572},{"atb":[[1.25,223.04]],"id":8509691}],"con":true,"img":false}]}
{"op":"mcm","clk":"1362314710","pt":1588438283476,"mc":[{"id":"1.170370564","rc":[{"atb":[[1.27,3.19]],"id":8509691}],"con":true,"img":false}]}
{"op":"mcm","clk":"1362314720","pt":1588438284291,"mc":[{"id":"1.170370564","rc":[{"trd":[[1.27,646.43]],"ltp":1.27,"tv":646.43,"id":8509691},{"atb":[[1.27,0.62]],"id":8509691}],"con":true,"img":false}]}
{"op":"mcm","clk":"1362314773","pt":1588438288372,"mc":[{"id":"1.170370564","rc":[{"trd":[[4.7,36.3]],"ltp":4.7,"tv":36.3,"id":9630572},{"atl":[[4.7,32.84]],"id":9630572},{"trd":[[1.27,779.05]],"ltp":1.27,"tv":779.05,"id":8509691},{"atb":[[1.27,0]],"id":8509691}],"con":true,"img":false}]}
{"op":"mcm","clk":"1362314949","pt":1588438302729,"mc":[{"id":"1.170370564","rc":[{"trd":[[1.28,3019.63]],"ltp":1.28,"tv":3019.63,"id":8509691},{"atb":[[1.28,1.79]],"id":8509691},{"atl":[[1.28,0]],"id":8509691}],"con":true,"img":false}]}
{"op":"mcm","clk":"1362315033","pt":1588438308912,"mc":[{"id":"1.170370564","rc":[{"atb":[[1.28,0]],"id":8509691},{"atl":[[1.28,26.24]],"id":8509691}],"con":true,"img":false}]}
{"op":"mcm","clk":"1362315156","pt":1588438318314,"mc":[{"id":"1.170370564","rc":[{"trd":[[1.28,3025.17]],"ltp":1.28,"tv":3025.17,"id":8509691},{"atl":[[1.28,23.47]],"id":8509691}],"con":true,"img":false}]}
{"op":"mcm","clk":"1362315234","pt":1588438324145,"mc":[{"id":"1.170370564","rc":[{"atb":[[1.27,69.97]],"id":8509691}],"con":true,"img":false}]}
{"op":"mcm","clk":"1362315306","pt":1588438329060,"mc":[{"id":"1.170370564","rc":[{"atb":[[3.5,0]],"id":9630572},{"atb":[[1.25,0]],"id":8509691}],"con":true,"img":false}]}
{"op":"mcm","clk":"1362315400","pt":1588438335636,"mc":[{"id":"1.170370564","rc":[{"trd":[[1.28,3028.77]],"ltp":1.28,"tv":3028.77,"id":8509691},{"atl":[[1.28,21.67]],"id":8509691}],"con":true,"img":false}]}
{"op":"mcm","clk":"1362315404","pt":1588438335841,"mc":[{"id":"1.170370564","rc":[{"atl":[[4.7,101.1]],"id":9630572}],"con":true,"img":false}]}
{"op":"mcm","clk":"1362315409","pt":1588438336045,"mc":[{"id":"1.170370564","rc":[{"atl":[[1.28,24.87]],"id":8509691}],"con":true,"img":false}]}
{"op":"mcm","clk":"1362315448","pt":1588438339566,"mc":[{"id":"1.170370564","rc":[{"atb":[[1.27,73.17]],"id":8509691}],"con":true,"img":false}]}
{"op":"mcm","clk":"1362315580","pt":1588438349159,"mc":[{"id":"1.170370564","rc":[{"trd":[[1.28,3034.6]],"ltp":1.28,"tv":3034.6,"id":8509691},{"atl":[[1.28,21.95]],"id":8509691}],"con":true,"img":false}]}
{"op":"mcm","clk":"1362315596","pt":1588438349976,"mc":[{"id":"1.170370564","rc":[{"atb":[[4.1,0.28]],"id":9630572}],"con":true,"img":false}]}
{"op":"mcm","clk":"1362315615","pt":1588438351358,"mc":[{"id":"1.170370564","rc":[{"atb":[[4.1,2.61]],"id":9630572}],"con":true,"img":false}]}
{"op":"mcm","clk":"1362315700","pt":1588438359407,"mc":[{"id":"1.170370564","rc":[{"trd":[[4.5,489.68]],"ltp":4.5,"tv":489.68,"id":9630572},{"atb":[[4.5,10.37]],"id":9630572}],"con":true,"img":false}]}
{"op":"mcm","clk":"1362315726","pt":1588438364408,"mc":[{"id":"1.170370564","rc":[{"trd":[[1.27,779.65]],"ltp":1.27,"tv":779.65,"id":8509691},{"atb":[[1.27,72.87]],"id":8509691}],"con":true,"img":false}]}
{"op":"mcm","clk":"1362315766","pt":1588438368904,"mc":[{"id":"1.170370564","rc":[{"trd":[[4.5,496.69]],"ltp":4.5,"tv":496.69,"id":9630572},{"atb":[[4.5,6.87]],"id":9630572}],"con":true,"img":false}]}
{"op":"mcm","clk":"1362315786","pt":1588438370179,"mc":[{"id":"1.170370564","rc":[{"trd":[[1.27,809.64]],"ltp":1.27,"tv":809.64,"id":8509691},{"atb":[[1.27,57.88]],"id":8509691}],"con":true,"img":false}]}
{"op":"mcm","clk":"1362315795","pt":1588438371408,"mc":[{"id":"1.170370564","rc":[{"trd":[[1.27,810.03]],"ltp":1.27,"tv":810.03,"id":8509691},{"atb":[[1.27,57.68]],"id":8509691}],"con":true,"img":false}]}
{"op":"mcm","clk":"1362315816","pt":1588438374422,"mc":[{"id":"1.170370564","rc":[{"atb":[[3.5,22.3]],"id":9630572},{"atb":[[1.25,223.04]],"id":8509691}],"con":true,"img":false}]}
{"op":"mcm","clk":"1362315827","pt":1588438376513,"mc":[{"id":"1.170370564","rc":[{"trd":[[1.27,830.81]],"ltp":1.27,"tv":830.81,"id":8509691},{"atb":[[1.27,47.29]],"id":8509691}],"con":true,"img":false}]}
{"op":"mcm","clk":"1362315861","pt":1588438378908,"mc":[{"id":"1.170370564","rc":[{"atl":[[1.28,48.19]],"id":8509691}],"con":true,"img":false}]}
{"op":"mcm","clk":"1362315870","pt":1588438380333,"mc":[{"id":"1.170370564","rc":[{"trd":[[1.28,3034.89]],"ltp":1.28,"tv":3034.89,"id":8509691},{"atl":[[1.28,48.05]],"id":8509691}],"con":true,"img":false}]}
{"op":"mcm","clk":"1362315937","pt":1588438388721,"mc":[{"id":"1.170370564","rc":[{"trd":[[1.28,3035.82]],"ltp":1.28,"tv":3035.82,"id":8509691},{"atl":[[1.28,47.58]],"id":8509691}],"con":true,"img":false}]}
{"op":"mcm","clk":"1362316014","pt":1588438395145,"mc":[{"id":"1.170370566","rc":[{"atl":[[1.56,0.1]],"id":8509691}],"con":true,"img":false}]}
{"op":"mcm","clk":"1362316022","pt":1588438395960,"mc":[{"id":"1.170370564","rc":[{"trd":[[1.27,918.28]],"ltp":1.27,"tv":918.28,"id":8509691},{"atb":[[1.27,13.56]],"id":8509691}],"con":true,"img":false}]}
{"op":"mcm","clk":"1362316060","pt":1588438401923,"mc":[{"id":"1.170370564","rc":[{"atb":[[4.5,17.37]],"id":9630572}],"con":true,"img":false}]}
{"op":"mcm","clk":"1362316078","pt":1588438403454,"mc":[{"id":"1.170370564","rc":[{"trd":[[1.28,3036.28]],"ltp":1.28,"tv":3036.28,"id":8509691},{"atl":[[1.28,47.35]],"id":8509691}],"con":true,"img":false}]}
{"op":"mcm","clk":"1362316081","pt":1588438404166,"mc":[{"id":"1.170370564","rc":[{"atb":[[3.5,0]],"id":9630572},{"atb":[[1.25,0]],"id":8509691}],"con":true,"img":false}]}
{"op":"mcm","clk":"1362316133","pt":1588438409935,"mc":[{"id":"1.170370564","rc":[{"atb":[[1.27,3.56]],"id":8509691}],"con":true,"img":false}]}
{"op":"mcm","clk":"1362316143","pt":1588438410954,"mc":[{"id":"1.170370564","rc":[{"atl":[[1.28,64.84]],"id":8509691}],"con":true,"img":false}]}
{"op":"mcm","clk":"1362316145","pt":1588438411056,"mc":[{"id":"1.170370564","rc":[{"trd":[[4.7,81.27]],"ltp":4.7,"tv":81.27,"id":9630572},{"atl":[[4.7,56.13]],"id":9630572},{"trd":[[1.27,1091.84]],"ltp":1.27,"tv":1091.84,"id":8509691},{"atb":[[1.27,0]],"id":8509691}],"con":true,"img":false}]}
{"op":"mcm","clk":"1362316148","pt":1588438411567,"mc":[{"id":"1.170370564","rc":[{"trd":[[1.28,3056.28]],"ltp":1.28,"tv":3056.28,"id":8509691},{"atl":[[1.28,54.84]],"id":8509691}],"con":true,"img":false}]}
{"op":"mcm","clk":"1362316168","pt":1588438414068,"mc":[{"id":"1.170370564","rc":[{"atb":[[3.5,22.3]],"id":9630572},{"atb":[[1.25,223.04]],"id":8509691}],"con":true,"img":false}]}
{"op":"mcm","clk":"1362316203","pt":1588438420994,"mc":[{"id":"1.170370564","rc":[{"trd":[[1.28,3056.75]],"ltp":1.28,"tv":3056.75,"id":8509691},{"atl":[[1.28,54.61]],"id":8509691}],"con":true,"img":false}]}
{"op":"mcm","clk":"1362316239","pt":1588438425074,"mc":[{"id":"1.170370564","rc":[{"trd":[[4.7,89.37]],"ltp":4.7,"tv":89.37,"id":9630572},{"atl":[[4.7,48.03]],"id":9630572},{"trd":[[1.27,1121.84]],"ltp":1.27,"tv":1121.84,"id":8509691}],"con":true,"img":false}]}
{"op":"mcm","clk":"1362316411","pt":1588438440031,"mc":[{"id":"1.170370564","rc":[{"trd":[[4.5,507.27]],"ltp":4.5,"tv":507.27,"id":9630572},{"atb":[[4.5,12.08]],"id":9630572}],"con":true,"img":false}]}
{"op":"mcm","clk":"1362316487","pt":1588438444804,"mc":[{"id":"1.170370564","rc":[{"trd":[[4.7,93.56]],"ltp":4.7,"tv":93.56,"id":9630572},{"atl":[[4.7,43.84]],"id":9630572},{"trd":[[1.27,1137.34]],"ltp":1.27,"tv":1137.34,"id":8509691}],"con":true,"img":false}]}
{"op":"mcm","clk":"1362316557","pt":1588438449603,"mc":[{"id":"1.170370564","rc":[{"atb":[[4.1,0.28]],"id":9630572}],"con":true,"img":false}]}
{"op":"mcm","clk":"1362316609","pt":1588438452407,"mc":[{"id":"1.170370564","rc":[{"atb":[[4.1,2.61]],"id":9630572}],"con":true,"img":false}]}
{"op":"mcm","clk":"1362316651","pt":1588438455011,"mc":[{"id":"1.170370566","rc":[{"atl":[[1.56,0]],"id":8509691}],"con":true,"img":false}]}
{"op":"mcm","clk":"1362316670","pt":1588438456439,"mc":[{"id":"1.170370564","rc":[{"atl":[[1.28,126.6]],"id":8509691}],"con":true,"img":false}]}
{"op":"mcm","clk":"1362316692","pt":1588438457920,"mc":[{"id":"1.170370564","rc":[{"atl":[[1.28,152.84]],"id":8509691}],"con":true,"img":false}]}
{"op":"mcm","clk":"1362316695","pt":1588438458022,"mc":[{"id":"1.170370564","rc":[{"trd":[[1.28,3063.15]],"ltp":1.28,"tv":3063.15,"id":8509691},{"atl":[[1.28,149.64]],"id":8509691}],"con":true,"img":false}]}
{"op":"mcm","clk":"1362316757","pt":1588438464354,"mc":[{"id":"1.170370564","rc":[{"atl":[[1.28,151.37]],"id":8509691}],"con":true,"img":false}]}
{"op":"mcm","clk":"1362316805","pt":1588438469058,"mc":[{"id":"1.170370564","rc":[{"atb":[[4.4,10.68]],"id":9630572}],"con":true,"img":false}]}
{"op":"mcm","clk":"1362316806","pt":1588438470028,"mc":[{"id":"1.170370564","rc":[{"atb":[[4.4,10.49]],"id":9630572}],"con":true,"img":false}]}
{"op":"mcm","clk":"1362316808","pt":1588438471050,"mc":[{"id":"1.170370564","rc":[{"atb":[[4.4,0]],"id":9630572}],"con":true,"img":false}]}
{"op":"mcm","clk":"1362316811","pt":1588438471152,"mc":[{"id":"1.170370564","rc":[{"trd":[[1.28,3065.17]],"ltp":1.28,"tv":3065.17,"id":8509691},{"atl":[[1.28,150.35]],"id":8509691}],"con":true,"img":false}]}
{"op":"mcm","clk":"1362316923","pt":1588438480646,"mc":[{"id":"1.170370564","rc":[{"trd":[[4.7,101.66]],"ltp":4.7,"tv":101.66,"id":9630572},{"atl":[[4.7,35.74]],"id":9630572},{"trd":[[1.27,1167.34]],"ltp":1.27,"tv":1167.34,"id":8509691}],"con":true,"img":false}]}
{"op":"mcm","clk":"1362317089","pt":1588438491567,"mc":[{"id":"1.170370564","rc":[{"trd":[[1.28,3068.72]],"ltp":1.28,"tv":3068.72,"id":8509691},{"atl":[[1.28,148.58]],"id":8509691}],"con":true,"img":false}]}
{"op":"mcm","clk":"1362317416","pt":1588438517830,"mc":[{"id":"1.170370564","rc":[{"trd":[[4.7,102.53]],"ltp":4.7,"tv":102.53,"id":9630572},{"atl":[[4.7,34.87]],"id":9630572},{"trd":[[1.27,1170.56]],"ltp":1.27,"tv":1170.56,"id":8509691}],"con":true,"img":false}]}
{"op":"mcm","clk":"1362317573","pt":1588438532570,"mc":[{"id":"1.170370564","rc":[{"trd":[[4.7,105.25]],"ltp":4.7,"tv":105.25,"id":9630572},{"atl":[[4.7,32.15]],"id":9630572},{"trd":[[1.27,1180.64]],"ltp":1.27,"tv":1180.64,"id":8509691}],"con":true,"img":false}]}
{"op":"mcm","clk":"1362317634","pt":1588438537376,"mc":[{"id":"1.170370564","rc":[{"atl":[[1.28,146.86]],"id":8509691}],"con":true,"img":false}]}
{"op":"mcm","clk":"1362317855","pt":1588438556199,"mc":[{"id":"1.170370564","rc":[{"trd":[[4.7,109.07]],"ltp":4.7,"tv":109.07,"id":9630572},{"atl":[[4.7,28.33]],"id":9630572},{"trd":[[1.27,1194.77]],"ltp":1.27,"tv":1194.77,"id":8509691}],"con":true,"img":false}]}
{"op":"mcm","clk":"1362317999","pt":1588438571024,"mc":[{"id":"1.170370564","rc":[{"atb":[[4.1,0.28]],"id":9630572}],"con":true,"img":false}]}
{"op":"mcm","clk":"1362318015","pt":1588438572405,"mc":[{"id":"1.170370564","rc":[{"atb":[[4.1,2.61]],"id":9630572}],"con":true,"img":false}]}
{"op":"mcm","clk":"1362318042","pt":1588438574797,"mc":[{"id":"1.170370564","rc":[{"trd":[[4.7,109.72]],"ltp":4.7,"tv":109.72,"id":9630572},{"atl":[[4.7,27.68]],"id":9630572},{"trd":[[1.27,1197.17]],"ltp":1.27,"tv":1197.17,"id":8509691}],"con":true,"img":false}]}
{"op":"mcm","clk":"1362318045","pt":1588438575309,"mc":[{"id":"1.170370564","rc":[{"trd":[[4.7,110.67]],"ltp":4.7,"tv":110.67,"id":9630572},{"atl":[[4.7,26.73]],"id":9630572},{"trd":[[1.27,1200.67]],"ltp":1.27,"tv":1200.67,"id":8509691}],"con":true,"img":false}]}
{"op":"mcm","clk":"1362318184","pt":1588438586624,"mc":[{"id":"1.170370564","rc":[{"atb":[[1.01,517.99]],"id":9630572}],"con":true,"img":false}]}
{"op":"mcm","clk":"1362318191","pt":1588438587443,"mc":[{"id":"1.170370564","rc":[{"atb":[[1.01,514.82]],"id":9630572}],"con":true,"img":false}]}
{"op":"mcm","clk":"1362318197","pt":1588438588314,"mc":[{"id":"1.170370564","rc":[{"atb":[[1.01,514.79]],"id":9630572}],"con":true,"img":false}]}
{"op":"mcm","clk":"1362318231","pt":1588438591933,"mc":[{"id":"1.170370564","rc":[{"atb":[[4.6,10.49]],"id":9630572}],"con":true,"img":false}]}
{"op":"mcm","clk":"1362318396","pt":1588438609381,"mc":[{"id":"1.170370564","rc":[{"atl":[[1.5,9.33]],"id":8509691}],"con":true,"img":false}]}
{"op":"mcm","clk":"1362318449","pt":1588438615099,"mc":[{"id":"1.170370564","rc":[{"atl":[[1.5,8.86]],"id":8509691}],"con":true,"img":false}]}
{"op":"mcm","clk":"1362318452","pt":1588438616373,"mc":[{"id":"1.170370564","rc":[{"atb":[[1.01,517.99]],"id":9630572}],"con":true,"img":false}]}
{"op":"mcm","clk":"1362318458","pt":1588438617289,"mc":[{"id":"1.170370564","rc":[{"atb":[[1.01,514.81]],"id":9630572}],"con":true,"img":false}]}
{"op":"mcm","clk":"1362318462","pt":1588438618207,"mc":[{"id":"1.170370564","rc":[{"atb":[[1.01,514.79]],"id":9630572}],"con":true,"img":false}]}
{"op":"mcm","clk":"1362318463","pt":1588438618262,"mc":[{"id":"1.170370564","rc":[{"trd":[[4.7,110.7]],"ltp":4.7,"tv":110.7,"id":9630572},{"atl":[[4.7,26.71]],"id":9630572}],"con":true,"img":false}]}
{"op":"mcm","clk":"1362318533","pt":1588438624606,"mc":[{"id":"1.170370564","rc":[{"atb":[[3.5,0]],"id":9630572},{"atb":[[1.25,0]],"id":8509691}],"con":true,"img":false}]}
{"op":"mcm","clk":"1362318552","pt":1588438626296,"mc":[{"id":"1.170370565","rc":[{"atb":[[6.4,0]],"id":11340557},{"atb":[[6.4,0]],"id":11340560},{"atb":[[1.82,0]],"id":11269555},{"atb":[[3.3,0]],"id":11269557}],"con":true,"img":false},{"id":"1.170370566","rc":[{"atb":[[2.74,0]],"id":9630572},{"atb":[[1.31,0]],"id":8509691}],"con":true,"img":false},{"id":"1.170370567","rc":[{"atb":[[2.88,0]],"id":9630572},{"atb":[[1.36,0]],"id":8509691}],"con":true,"img":false}]}
{"op":"mcm","clk":"1362318786","pt":1588438649600,"mc":[{"id":"1.170370565","rc":[{"atl":[[1.91,0]],"id":11269555}],"con":true,"img":false}]}
{"op":"mcm","clk":"1362318788","pt":1588438649803,"mc":[{"id":"1.170370565","rc":[{"atl":[[5,5]],"id":11269557}],"con":true,"img":false}]}
{"op":"mcm","clk":"1362318791","pt":1588438650007,"mc":[{"id":"1.170370565","rc":[{"atl":[[8.6,0]],"id":11340557}],"con":true,"img":false}]}
{"op":"mcm","clk":"1362318795","pt":1588438650211,"mc":[{"id":"1.170370565","rc":[{"atl":[[11.5,0]],"id":11340560}],"con":true,"img":false}]}
{"op":"mcm","clk":"1362318799","pt":1588438650620,"mc":[{"id":"1.170370565","rc":[{"atl":[[9,6]],"id":11340557},{"atl":[[12,6]],"id":11340560},{"atl":[[1.89,4]],"id":11269555},{"atl":[[5.1,4]],"id":11269557}],"con":true,"img":false}]}
{"op":"mcm","clk":"1362318910","pt":1588438666137,"mc":[{"id":"1.170370564","rc":[{"trd":[[4.7,121.52]],"ltp":4.7,"tv":121.52,"id":9630572},{"atl":[[4.7,15.9]],"id":9630572},{"trd":[[1.27,1240.68]],"ltp":1.27,"tv":1240.68,"id":8509691}],"con":true,"img":false}]}
{"op":"mcm","clk":"1362319071","pt":1588438684488,"mc":[{"id":"1.170370564","rc":[{"trd":[[4.7,122.39]],"ltp":4.7,"tv":122.39,"id":9630572},{"atl":[[4.7,15.03]],"id":9630572},{"trd":[[1.27,1243.88]],"ltp":1.27,"tv":1243.88,"id":8509691}],"con":true,"img":false}]}
{"op":"mcm","clk":"1362319113","pt":1588438688162,"mc":[{"id":"1.170370564","rc":[{"atb":[[4.1,2.33]],"id":9630572}],"con":true,"img":false}]}
{"op":"mcm","clk":"1362319132","pt":1588438690101,"mc":[{"id":"1.170370564","rc":[{"atb":[[4.1,0]],"id":9630572},{"atl":[[7,0]],"id":9630572}],"con":true,"img":false}]}
{"op":"mcm","clk":"1362319165","pt":1588438693357,"mc":[{"id":"1.170370564","rc":[{"atb":[[4.1,2.33]],"id":9630572}],"con":true,"img":false}]}
{"op":"mcm","clk":"1362319178","pt":1588438694688,"mc":[{"id":"1.170370564","rc":[{"trd":[[4.7,137.42]],"ltp":4.7,"tv":137.42,"id":9630572},{"atl":[[4.7,0]],"id":9630572},{"trd":[[1.27,1299.53]],"ltp":1.27,"tv":1299.53,"id":8509691},{"atl":[[1.27,24.14]],"id":8509691}],"con":true,"img":false}]}
{"op":"mcm","clk":"1362319179","pt":1588438694891,"mc":[{"id":"1.170370564","rc":[{"trd":[[1.27,1347.81]],"ltp":1.27,"tv":1347.81,"id":8509691},{"atb":[[1.27,0.04]],"id":8509691},{"atl":[[1.27,0]],"id":8509691}],"con":true,"img":false}]}
{"op":"mcm","clk":"1362319185","pt":1588438695197,"mc":[{"id":"1.170370564","rc":[{"atb":[[1.27,0]],"id":8509691}],"con":true,"img":false}]}
{"op":"mcm","clk":"1362319219","pt":1588438699274,"mc":[{"id":"1.170370564","rc":[{"atb":[[1.27,44.32]],"id":8509691}],"con":true,"img":false}]}
{"op":"mcm","clk":"1362319229","pt":1588438700095,"mc":[{"id":"1.170370564","rc":[{"atb":[[1.27,88.65]],"id":8509691}],"con":true,"img":false}]}
{"op":"mcm","clk":"1362319233","pt":1588438700810,"mc":[{"id":"1.170370564","rc":[{"atl":[[1.28,191.18]],"id":8509691}],"con":true,"img":false}]}
{"op":"mcm","clk":"1362319239","pt":1588438701614,"mc":[{"id":"1.170370564","rc":[{"atl":[[1.28,235.51]],"id":8509691}],"con":true,"img":false}]}
{"op":"mcm","clk":"1362319265","pt":1588438704995,"mc":[{"id":"1.170370564","rc":[{"atl":[[1.29,1334.17]],"id":8509691}],"con":true,"img":false}]}
{"op":"mcm","clk":"1362319291","pt":1588438708003,"mc":[{"id":"1.170370564","rc":[{"atl":[[1.34,44.32]],"id":8509691}],"con":true,"img":false}]}
{"op":"mcm","clk":"1362319299","pt":1588438708616,"mc":[{"id":"1.170370564","rc":[{"atl":[[1.34,88.65]],"id":8509691}],"con":true,"img":false}]}
{"op":"mcm","clk":"1362319404","pt":1588438720915,"mc":[{"id":"1.170370564","rc":[{"atl":[[1.42,44.32]],"id":8509691}],"con":true,"img":false}]}
{"op":"mcm","clk":"1362319411","pt":1588438721527,"mc":[{"id":"1.170370564","rc":[{"atl":[[1.42,88.65]],"id":8509691}],"con":true,"img":false}]}
{"op":"mcm","clk":"1362319418","pt":1588438722798,"mc":[{"id":"1.170370564","rc":[{"atb":[[1.24,44.32]],"id":8509691}],"con":true,"img":false}]}
{"op":"mcm","clk":"1362319421","pt":1588438723207,"mc":[{"id":"1.170370564","rc":[{"atb":[[1.23,44.32]],"id":8509691}],"con":true,"img":false}]}
{"op":"mcm","clk":"1362319435","pt":1588438724335,"mc":[{"id":"1.170370564","rc":[{"atb":[[1.2,44.32]],"id":8509691}],"con":true,"img":false}]}
{"op":"mcm","clk":"1362319446","pt":1588438725203,"mc":[{"id":"1.170370564","rc":[{"atb":[[1.18,44.32]],"id":8509691}],"con":true,"img":false}]}
{"op":"mcm","clk":"1362319447","pt":1588438725406,"mc":[{"id":"1.170370564","rc":[{"trd":[[1.27,1369.81]],"ltp":1.27,"tv":1369.81,"id":8509691},{"atb":[[1.27,77.65]],"id":8509691}],"con":true,"img":false}]}
{"op":"mcm","clk":"1362319483","pt":1588438729946,"mc":[{"id":"1.170370564","rc":[{"atb":[[1.16,44.32]],"id":8509691}],"con":true,"img":false}]}
{"op":"mcm","clk":"1362319487","pt":1588438730407,"mc":[{"id":"1.170370564","rc":[{"atb":[[1.16,88.65]],"id":8509691}],"con":true,"img":false}]}
{"op":"mcm","clk":"1362319494","pt":1588438731018,"mc":[{"id":"1.170370564","rc":[{"atb":[[1.14,44.32]],"id":8509691}],"con":true,"img":false}]}
{"op":"mcm","clk":"1362319502","pt":1588438731937,"mc":[{"id":"1.170370564","rc":[{"atb":[[1.13,44.32]],"id":8509691}],"con":true,"img":false}]}
{"op":"mcm","clk":"1362319510","pt":1588438732808,"mc":[{"id":"1.170370564","rc":[{"atb":[[1.12,44.32]],"id":8509691}],"con":true,"img":false}]}
{"op":"mcm","clk":"1362319586","pt":1588438741248,"mc":[{"id":"1.170370564","rc":[{"trd":[[1.27,1466.31]],"ltp":1.27,"tv":1466.31,"id":8509691},{"atb":[[1.27,29.39]],"id":8509691}],"con":true,"img":false}]}
{"op":"mcm","clk":"1362319612","pt":1588438744673,"mc":[{"id":"1.170370564","rc":[{"trd":[[4.6,11.63]],"ltp":4.6,"tv":11.63,"id":9630572},{"atb":[[4.6,10.28]],"id":9630572}],"con":true,"img":false}]}
{"op":"mcm","clk":"1362320504","pt":1588438760980,"mc":[{"id":"1.170370564","rc":[{"atl":[[4.8,17.49]],"id":9630572}],"con":true,"img":false}]}
{"op":"mcm","clk":"1362320621","pt":1588438775769,"mc":[{"id":"1.170370564","rc":[{"atl":[[1.29,1333.89]],"id":8509691}],"con":true,"img":false}]}
{"op":"mcm","clk":"1362320727","pt":1588438787136,"mc":[{"id":"1.170370564","rc":[{"trd":[[4.8,84.38]],"ltp":4.8,"tv":84.38,"id":9630572},{"atl":[[4.8,0]],"id":9630572},{"trd":[[1.27,1494.7]],"ltp":1.27,"tv":1494.7,"id":8509691},{"atb":[[1.27,1.01]],"id":8509691}],"con":true,"img":false}]}
{"op":"mcm","clk":"1362320732","pt":1588438788104,"mc":[{"id":"1.170370564","rc":[{"atl":[[1.28,235.79]],"id":8509691}],"con":true,"img":false}]}
{"op":"mcm","clk":"1362320853","pt":1588438799931,"mc":[{"id":"1.170370564","rc":[{"trd":[[1.27,1496.72]],"ltp":1.27,"tv":1496.72,"id":8509691},{"atb":[[1.27,0]],"id":8509691},{"atl":[[1.27,103.95]],"id":8509691}],"con":true,"img":false}]}
{"op":"mcm","clk":"1362321036","pt":1588438816488,"mc":[{"id":"1.170370564","rc":[{"atb":[[4.1,0]],"id":9630572}],"con":true,"img":false}]}
{"op":"mcm","clk":"1362321060","pt":1588438818982,"mc":[{"id":"1.170370564","rc":[{"atb":[[4.1,2.33]],"id":9630572}],"con":true,"img":false}]}
{"op":"mcm","clk":"1362321175","pt":1588438831692,"mc":[{"id":"1.170370564","rc":[{"trd":[[1.27,1580]],"ltp":1.27,"tv":1580.0,"id":8509691},{"atl":[[1.27,62.31]],"id":8509691}],"con":true,"img":false}]}
{"op":"mcm","clk":"1362321225","pt":1588438836281,"mc":[{"id":"1.170370564","rc":[{"atb":[[1.26,0]],"id":8509691}],"con":true,"img":false}]}
{"op":"mcm","clk":"1362321227","pt":1588438836383,"mc":[{"id":"1.170370564","rc":[{"atb":[[1.25,1308.63]],"id":8509691}],"con":true,"img":false}]}
{"op":"mcm","clk":"1362321250","pt":1588438838782,"mc":[{"id":"1.170370564","rc":[{"atl":[[6.8,3]],"id":9630572}],"con":true,"img":false}]}
{"op":"mcm","clk":"1362321595","pt":1588438867118,"mc":[{"id":"1.170370564","rc":[{"trd":[[1.25,55.68]],"ltp":1.25,"tv":55.68,"id":8509691},{"atb":[[1.25,1281.07]],"id":8509691},{"atl":[[1.27,114.79]],"id":8509691}],"con":true,"img":false}]}
{"op":"mcm","clk":"1362321600","pt":1588438867935,"mc":[{"id":"1.170370565","rc":[{"atb":[[1.75,7.69]],"id":11269555}],"con":true,"img":false}]}
{"op":"mcm","clk":"1362321690","pt":1588438875080,"mc":[{"id":"1.170370564","rc":[{"atl":[[1.28,209.55]],"id":8509691}],"con":true,"img":false}]}
{"op":"mcm","clk":"1362321704","pt":1588438876053,"mc":[{"id":"1.170370564","rc":[{"atl":[[1.28,181.61]],"id":8509691}],"con":true,"img":false}]}
{"op":"mcm","clk":"1362321780","pt":1588438881054,"mc":[{"id":"1.170370564","rc":[{"atb":[[4.5,10.49]],"id":9630572}],"con":true,"img":false}]}
{"op":"mcm","clk":"1362321791","pt":1588438882074,"mc":[{"id":"1.170370564","rc":[{"atb":[[4.5,0]],"id":9630572}],"con":true,"img":false}]}
{"op":"mcm","clk":"1362321827","pt":1588438884883,"mc":[{"id":"1.170370565","rc":[{"trd":[[1.9,20],[1.89,8]],"ltp":1.9,"tv":28.0,"id":11269555},{"atl":[[1.89,0],[1.9,21.02]],"id":11269555}],"con":true,"img":false}]}
{"op":"mcm","clk":"1362321853","pt":1588438887080,"mc":[{"id":"1.170370564","rc":[{"atl":[[1.28,164.12]],"id":8509691}],"con":true,"img":false}]}
{"op":"mcm","clk":"1362321884","pt":1588438891009,"mc":[{"id":"1.170370564","rc":[{"atb":[[1.26,6]],"id":8509691}],"con":true,"img":false}]}
{"op":"mcm","clk":"1362321921","pt":1588438894993,"mc":[{"id":"1.170370564","rc":[{"atb":[[1.26,12]],"id":8509691}],"con":true,"img":false}]}
{"op":"mcm","clk":"1362322078","pt":1588438909945,"mc":[{"id":"1.170370564","rc":[{"trd":[[1.27,1585.15]],"ltp":1.27,"tv":1585.15,"id":8509691},{"atl":[[1.27,112.22]],"id":8509691}],"con":true,"img":false}]}
{"op":"mcm","clk":"1362322145","pt":1588438915659,"mc":[{"id":"1.170370564","rc":[{"trd":[[1.27,1595.37]],"ltp":1.27,"tv":1595.37,"id":8509691},{"atl":[[1.27,107.11]],"id":8509691}],"con":true,"img":false}]}
{"op":"mcm","clk":"1362322276","pt":1588438929557,"mc":[{"id":"1.170370564","rc":[{"atb":[[4.1,0]],"id":9630572}],"con":true,"img":false}]}
{"op":"mcm","clk":"1362322307","pt":1588438933178,"mc":[{"id":"1.170370564","rc":[{"atb":[[4.1,2.33]],"id":9630572}],"con":true,"img":false}]}
{"op":"mcm","clk":"1362322342","pt":1588438938275,"mc":[{"id":"1.170370564","rc":[{"trd":[[1.28,3073.68],[1.27,1809.59]],"ltp":1.28,"tv":4883.26,"id":8509691},{"atl":[[1.28,161.64],[1.27,0]],"id":8509691}],"con":true,"img":false}]}
{"op":"mcm","clk":"1362322524","pt":1588438956219,"mc":[{"id":"1.170370564","rc":[{"trd":[[1.28,3094.35]],"ltp":1.28,"tv":3094.35,"id":8509691},{"atl":[[1.28,151.31]],"id":8509691}],"con":true,"img":false}]}
{"op":"mcm","clk":"1362322695","pt":1588438972941,"mc":[{"id":"1.170370564","rc":[{"atb":[[1.26,81.97]],"id":8509691}],"con":true,"img":false}]}
{"op":"mcm","clk":"1362322724","pt":1588438975038,"mc":[{"id":"1.170370564","rc":[{"trd":[[1.28,3100.35]],"ltp":1.28,"tv":3100.35,"id":8509691},{"atl":[[1.28,148.31]],"id":8509691}],"con":true,"img":false}]}
{"op":"mcm","clk":"1362322737","pt":1588438976314,"mc":[{"id":"1.170370564","rc":[{"atb":[[1.26,417.32]],"id":8509691}],"con":true,"img":false}]}
{"op":"mcm","clk":"1362322752","pt":1588438977640,"mc":[{"id":"1.170370564","rc":[{"atl":[[1.28,148.02]],"id":8509691}],"con":true,"img":false}]}
{"op":"mcm","clk":"1362322778","pt":1588438980345,"mc":[{"id":"1.170370564","rc":[{"atb":[[1.27,9.61]],"id":8509691}],"con":true,"img":false}]}
{"op":"mcm","clk":"1362322798","pt":1588438981934,"mc":[{"id":"1.170370564","rc":[{"atl":[[4.8,17.49]],"id":9630572}],"con":true,"img":false}]}
{"op":"mcm","clk":"1362322842","pt":1588438987454,"mc":[{"id":"1.170370564","rc":[{"atb":[[1.26,81.97]],"id":8509691}],"con":true,"img":false}]}
{"op":"mcm","clk":"1362322862","pt":1588438988834,"mc":[{"id":"1.170370564","rc":[{"trd":[[1.27,1810.17]],"ltp":1.27,"tv":1810.17,"id":8509691},{"atb":[[1.27,9.32]],"id":8509691}],"con":true,"img":false}]}
{"op":"mcm","clk":"1362322863","pt":1588438989750,"mc":[{"id":"1.170370564","rc":[{"atb":[[1.01,1896.54]],"id":8509691}],"con":true,"img":false}]}
{"op":"mcm","clk":"1362322866","pt":1588438990259,"mc":[{"id":"1.170370564","rc":[{"atb":[[1.01,1896.34]],"id":8509691}],"con":true,"img":false}]}
{"op":"mcm","clk":"1362322871","pt":1588438990563,"mc":[{"id":"1.170370564","rc":[{"atb":[[1.01,1893.34]],"id":8509691}],"con":true,"img":false}]}
{"op":"mcm","clk":"1362322872","pt":1588438990666,"mc":[{"id":"1.170370564","rc":[{"atb":[[1.27,12.32]],"id":8509691}],"con":true,"img":false}]}
{"op":"mcm","clk":"1362322958","pt":1588438998971,"mc":[{"id":"1.170370564","rc":[{"trd":[[4.5,508.04],[4.6,32.21]],"ltp":4.5,"tv":540.25,"id":9630572},{"atb":[[4.6,0]],"id":9630572},{"trd":[[1.28,3103.05]],"ltp":1.28,"tv":3103.05,"id":8509691},{"atl":[[1.28,145.32]],"id":8509691}],"con":true,"img":false}]}
{"op":"mcm","clk":"1362323023","pt":1588439006166,"mc":[{"id":"1.170370564","rc":[{"atb":[[1.04,160.25]],"id":8509691}],"con":true,"img":false}]}
{"op":"mcm","clk":"1362323069","pt":1588439009783,"mc":[{"id":"1.170370564","rc":[{"atb":[[1.01,1896.54]],"id":8509691}],"con":true,"img":false}]}
{"op":"mcm","clk":"1362323073","pt":1588439010292,"mc":[{"id":"1.170370564","rc":[{"atb":[[1.01,1896.04]],"id":8509691}],"con":true,"img":false}]}
{"op":"mcm","clk":"1362323075","pt":1588439010598,"mc":[{"id":"1.170370564","rc":[{"atb":[[1.01,1893.34]],"id":8509691}],"con":true,"img":false}]}
{"op":"mcm","clk":"1362323076","pt":1588439010701,"mc":[{"id":"1.170370564","rc":[{"atb":[[1.27,15.02]],"id":8509691}],"con":true,"img":false}]}
{"op":"mcm","clk":"1362323166","pt":1588439020197,"mc":[{"id":"1.170370564","rc":[{"atb":[[1.27,102.5]],"id":8509691}],"con":true,"img":false}]}
{"op":"mcm","clk":"1362323423","pt":1588439048222,"mc":[{"id":"1.170370564","rc":[{"trd":[[1.27,1814.88]],"ltp":1.27,"tv":1814.88,"id":8509691},{"atb":[[1.27,100.14]],"id":8509691}],"con":true,"img":false}]}
{"op":"mcm","clk":"1362323458","pt":1588439050462,"mc":[{"id":"1.170370564","rc":[{"atb":[[1.26,417.32]],"id":8509691}],"con":true,"img":false}]}
{"op":"mcm","clk":"1362323467","pt":1588439051941,"mc":[{"id":"1.170370564","rc":[{"atb":[[4.1,0]],"id":9630572}],"con":true,"img":false}]}
{"op":"mcm","clk":"1362323475","pt":1588439052349,"mc":[{"id":"1.170370564","rc":[{"trd":[[4.5,510.34]],"ltp":4.5,"tv":510.34,"id":9630572},{"trd":[[1.28,3111.14]],"ltp":1.28,"tv":3111.14,"id":8509691},{"atl":[[1.28,137.23]],"id":8509691}],"con":true,"img":false}]}
{"op":"mcm","clk":"1362323496","pt":1588439054234,"mc":[{"id":"1.170370564","rc":[{"atb":[[4.1,2.33]],"id":9630572}],"con":true,"img":false}]}
{"op":"mcm","clk":"1362323608","pt":1588439066272,"mc":[{"id":"1.170370564","rc":[{"atl":[[1.33,0]],"id":8509691}],"con":true,"img":false}]}
{"op":"mcm","clk":"1362323682","pt":1588439073263,"mc":[{"id":"1.170370564","rc":[{"atl":[[1.28,140.43]],"id":8509691}],"con":true,"img":false}]}
{"op":"mcm","clk":"1362323984","pt":1588439100928,"mc":[{"id":"1.170370564","rc":[{"atl":[[1.28,143.63]],"id":8509691}],"con":true,"img":false}]}
{"op":"mcm","clk":"1362324002","pt":1588439102305,"mc":[{"id":"1.170370564","rc":[{"atb":[[1.27,103.34]],"id":8509691}],"con":true,"img":false}]}
{"op":"mcm","clk":"1362324016","pt":1588439103125,"mc":[{"id":"1.170370564","rc":[{"atb":[[1.27,111.42]],"id":8509691}],"con":true,"img":false}]}
{"op":"mcm","clk":"1362324242","pt":1588439121536,"mc":[{"id":"1.170370564","rc":[{"trd":[[1.27,1818.43]],"ltp":1.27,"tv":1818.43,"id":8509691},{"atb":[[1.27,109.65]],"id":8509691}],"con":true,"img":false}]}
