{"op":"mcm","clk":"1362024352","pt":1588422978505,"mc":[{"id":"1.170370557","rc":[{"atb":[[2.6,2.04]],"id":9622734},{"atb":[[1.56,2.08]],"id":9624350},{"atl":[[1.63,2.04]],"id":9624350}],"con":true,"img":false}]}
{"op":"mcm","clk":"1362024355","pt":1588422978608,"mc":[{"id":"1.170370557","rc":[{"atl":[[2.76,2.02]],"id":9622734},{"atb":[[1.48,39.99]],"id":9624350}],"con":true,"img":false}]}
{"op":"mcm","clk":"1362024357","pt":1588422978771,"mc":[{"id":"1.170370557","rc":[{"atb":[[2.14,39.99]],"id":9622734}],"con":true,"img":false}]}
{"op":"mcm","clk":"1362024414","pt":1588422983611,"mc":[{"id":"1.170370557","rc":[{"atb":[[1.48,0]],"id":9624350}],"con":true,"img":false}]}
{"op":"mcm","clk":"1362024418","pt":1588422983715,"mc":[{"id":"1.170370557","rc":[{"atb":[[1.57,42.05]],"id":9624350}],"con":true,"img":false}]}
{"op":"mcm","clk":"1362024646","pt":1588423003494,"mc":[{"id":"1.170370557","rc":[{"atl":[[1000,2.05]],"id":9624350}],"con":true,"img":false}]}
{"op":"mcm","clk":"1362024652","pt":1588423003805,"mc":[{"id":"1.170370557","rc":[{"atb":[[2.6,0]],"id":9622734},{"atl":[[2.76,0]],"id":9622734},{"atb":[[1.56,0]],"id":9624350},{"atl":[[1.63,0],[1000,0.04]],"id":9624350}],"con":true,"img":false}]}
{"op":"mcm","clk":"1362024657","pt":1588423004009,"mc":[{"id":"1.170370557","rc":[{"atb":[[2.6,2.04]],"id":9622734},{"atl":[[2.76,2.02]],"id":9622734},{"atb":[[1.56,2.08]],"id":9624350},{"atl":[[1.63,2.04],[1000,0]],"id":9624350}],"con":true,"img":false}]}
{"op":"mcm","clk":"1362024661","pt":1588423004111,"mc":[{"id":"1.170370557","rc":[{"trd":[[1.59,22.91]],"ltp":1.59,"tv":22.91,"id":9624350},{"atb":[[1.59,44.58]],"id":9624350}],"con":true,"img":false}]}
{"op":"mcm","clk":"1362024925","pt":1588423031429,"mc":[{"id":"1.170370557","rc":[{"trd":[[1.6,311.63]],"ltp":1.6,"tv":311.63,"id":9624350},{"atb":[[1.6,41.87]],"id":9624350},{"atl":[[1.6,0]],"id":9624350}],"con":true,"img":false}]}
{"op":"mcm","clk":"1362024926","pt":1588423031532,"mc":[{"id":"1.170370557","rc":[{"atb":[[1.58,91.82]],"id":9624350},{"atl":[[1.64,2.04]],"id":9624350}],"con":true,"img":false}]}
{"op":"mcm","clk":"1362024932","pt":1588423031739,"mc":[{"id":"1.170370557","rc":[{"atb":[[2.6,0]],"id":9622734},{"atl":[[2.76,0]],"id":9622734},{"atb":[[1.56,0]],"id":9624350},{"atl":[[1.62,94.85]],"id":9624350}],"con":true,"img":false}]}
{"op":"mcm","clk":"1362024937","pt":1588423031944,"mc":[{"id":"1.170370557","rc":[{"atb":[[2.58,2.06]],"id":9622734},{"atl":[[2.72,4.12]],"id":9622734}],"con":true,"img":false}]}
{"op":"mcm","clk":"1362024938","pt":1588423032045,"mc":[{"id":"1.170370557","rc":[{"atb":[[2.62,0]],"id":9622734},{"atb":[[1.57,39.99]],"id":9624350}],"con":true,"img":false}]}
{"op":"mcm","clk":"1362024939","pt":1588423032149,"mc":[{"id":"1.170370557","rc":[{"atb":[[2.6,2.04]],"id":9622734}],"con":true,"img":false}]}
{"op":"mcm","clk":"1362024942","pt":1588423032355,"mc":[{"id":"1.170370557","rc":[{"atl":[[2.74,0]],"id":9622734}],"con":true,"img":false}]}
{"op":"mcm","clk":"1362024947","pt":1588423032563,"mc":[{"id":"1.170370557","rc":[{"atl":[[2.74,2.05]],"id":9622734},{"atb":[[1.57,42.05]],"id":9624350}],"con":true,"img":false}]}
{"op":"mcm","clk":"1362025002","pt":1588423038532,"mc":[{"id":"1.170370557","rc":[{"atb":[[2.14,0]],"id":9622734},{"atb":[[1.57,2.06]],"id":9624350}],"con":true,"img":false}]}
{"op":"mcm","clk":"1362025005","pt":1588423038844,"mc":[{"id":"1.170370557","rc":[{"atb":[[2.58,0]],"id":9622734},{"atl":[[2.74,0]],"id":9622734},{"atb":[[1.57,0]],"id":9624350},{"atl":[[1.64,0]],"id":9624350}],"con":true,"img":false}]}
{"op":"mcm","clk":"1362025008","pt":1588423039051,"mc":[{"id":"1.170370557","rc":[{"atb":[[2.58,2]],"id":9622734},{"atl":[[2.74,2.01]],"id":9622734},{"atb":[[1.57,2.06]],"id":9624350},{"atl":[[1.64,2.18]],"id":9624350}],"con":true,"img":false}]}
{"op":"mcm","clk":"1362025035","pt":1588423041882,"mc":[{"id":"1.170370557","rc":[{"atb":[[1.57,42.05]],"id":9624350}],"con":true,"img":false}]}
{"op":"mcm","clk":"1362025037","pt":1588423042036,"mc":[{"id":"1.170370557","rc":[{"atb":[[2.14,39.99]],"id":9622734}],"con":true,"img":false}]}
{"op":"mcm","clk":"1362025228","pt":1588423061191,"mc":[{"id":"1.170370557","rc":[{"atb":[[1.6,0]],"id":9624350},{"atl":[[1.7,0]],"id":9624350}],"con":true,"img":false}]}
{"op":"mcm","clk":"1362025231","pt":1588423061396,"mc":[{"id":"1.170370557","rc":[{"atb":[[1.56,2.02]],"id":9624350}],"con":true,"img":false}]}
{"op":"mcm","clk":"1362025234","pt":1588423061499,"mc":[{"id":"1.170370557","rc":[{"atb":[[2.58,0]],"id":9622734},{"atl":[[2.74,0]],"id":9622734},{"atb":[[1.58,89.8]],"id":9624350},{"atl":[[1.64,0]],"id":9624350}],"con":true,"img":false}]}
{"op":"mcm","clk":"1362025238","pt":1588423061704,"mc":[{"id":"1.170370557","rc":[{"atb":[[2.58,2.06]],"id":9622734},{"atl":[[2.74,2.25],[2.76,2.02]],"id":9622734},{"atl":[[1.64,2.18]],"id":9624350}],"con":true,"img":false}]}
{"op":"mcm","clk":"1362025239","pt":1588423061807,"mc":[{"id":"1.170370557","rc":[{"atl":[[2.72,2.12]],"id":9622734}],"con":true,"img":false}]}
{"op":"mcm","clk":"1362025425","pt":1588423077902,"mc":[{"id":"1.170370557","rc":[{"atb":[[1.6,63.98]],"id":9624350}],"con":true,"img":false}]}
{"op":"mcm","clk":"1362025427","pt":1588423078106,"mc":[{"id":"1.170370557","rc":[{"atb":[[1.58,91.86]],"id":9624350}],"con":true,"img":false}]}
{"op":"mcm","clk":"1362025428","pt":1588423078208,"mc":[{"id":"1.170370557","rc":[{"atb":[[2.58,0]],"id":9622734},{"atl":[[2.76,0]],"id":9622734},{"atb":[[1.56,0]],"id":9624350},{"atl":[[1.64,0]],"id":9624350}],"con":true,"img":false}]}
{"op":"mcm","clk":"1362025431","pt":1588423078310,"mc":[{"id":"1.170370557","rc":[{"atl":[[2.72,4.28]],"id":9622734}],"con":true,"img":false}]}
{"op":"mcm","clk":"1362025433","pt":1588423078413,"mc":[{"id":"1.170370557","rc":[{"atb":[[1.57,39.99]],"id":9624350}],"con":true,"img":false}]}
{"op":"mcm","clk":"1362025436","pt":1588423078514,"mc":[{"id":"1.170370557","rc":[{"atb":[[2.58,2.06]],"id":9622734},{"atl":[[1.64,2.04]],"id":9624350}],"con":true,"img":false}]}
{"op":"mcm","clk":"1362025438","pt":1588423078718,"mc":[{"id":"1.170370557","rc":[{"atl":[[2.74,0]],"id":9622734}],"con":true,"img":false}]}
{"op":"mcm","clk":"1362025442","pt":1588423078923,"mc":[{"id":"1.170370557","rc":[{"atl":[[2.74,2]],"id":9622734},{"atb":[[1.57,42.05]],"id":9624350}],"con":true,"img":false}]}
{"op":"mcm","clk":"1362025536","pt":1588423088500,"mc":[{"id":"1.170370557","marketDefinition":{"bspMarket":false,"turnInPlayEnabled":true,"persistenceEnabled":true,"marketBaseRate":5.0,"eventId":"29788106","eventTypeId":"2","numberOfWinners":1,"bettingType":"ODDS","marketType":"MATCH_ODDS","marketTime":"2020-05-02T12:50:00.000Z","suspendTime":"2020-05-02T12:50:00.000Z","bspReconciled":false,"complete":true,"inPlay":false,"crossMatching":true,"runnersVoidable":false,"numberOfActiveRunners":2,"betDelay":0,"status":"OPEN","runners":[{"status":"ACTIVE","sortPriority":1,"id":9624350,"name":"Y Hanfmann"},{"status":"ACTIVE","sortPriority":2,"id":9622734,"name":"D Brown"}],"regulators":["MR_INT"],"countryCode":"GB","discountAllowed":true,"timezone":"GMT","openDate":"2020-05-02T12:40:00.000Z","version":3237537505,"name":"Match Odds","eventName":"Y Hanfmann v D Brown"},"rc":[],"con":true,"img":false}]}
{"op":"mcm","clk":"1362025553","pt":1588423090601,"mc":[{"id":"1.170370557","rc":[{"trd":[[1.6,398.53]],"ltp":1.6,"tv":398.53,"id":9624350},{"atb":[[1.6,20.54]],"id":9624350}],"con":true,"img":false}]}
{"op":"mcm","clk":"1362025557","pt":1588423090908,"mc":[{"id":"1.170370557","rc":[{"atb":[[2.58,0]],"id":9622734},{"atl":[[2.74,0]],"id":9622734},{"atb":[[1.57,39.99]],"id":9624350},{"atl":[[1.64,0]],"id":9624350}],"con":true,"img":false}]}
{"op":"mcm","clk":"1362025559","pt":1588423091112,"mc":[{"id":"1.170370557","rc":[{"atb":[[2.58,2]],"id":9622734},{"atl":[[2.74,2.25]],"id":9622734},{"atb":[[1.57,42.05]],"id":9624350},{"atl":[[1.64,2.18]],"id":9624350}],"con":true,"img":false}]}
{"op":"mcm","clk":"1362025565","pt":1588423091503,"mc":[{"id":"1.170370557","marketDefinition":{"bspMarket":false,"turnInPlayEnabled":true,"persistenceEnabled":true,"marketBaseRate":5.0,"eventId":"29788106","eventTypeId":"2","numberOfWinners":1,"bettingType":"ODDS","marketType":"MATCH_ODDS","marketTime":"2020-05-02T12:50:00.000Z","suspendTime":"2020-05-02T12:50:00.000Z","bspReconciled":false,"complete":true,"inPlay":false,"crossMatching":true,"runnersVoidable":false,"numberOfActiveRunners":2,"betDelay":0,"status":"OPEN","runners":[{"status":"ACTIVE","sortPriority":1,"id":9624350,"name":"Y Hanfmann"},{"status":"ACTIVE","sortPriority":2,"id":9622734,"name":"D Brown"}],"regulators":["MR_INT"],"countryCode":"GB","discountAllowed":true,"timezone":"GMT","openDate":"2020-05-02T12:50:00.000Z","version":3237537505,"name":"Match Odds","eventName":"Y Hanfmann v D Brown"},"rc":[],"con":true,"img":false}]}
{"op":"mcm","clk":"1362025697","pt":1588423099248,"mc":[{"id":"1.170370557","rc":[{"atb":[[2.14,0]],"id":9622734},{"atb":[[1.57,2.06]],"id":9624350}],"con":true,"img":false}]}
{"op":"mcm","clk":"1362025700","pt":1588423099555,"mc":[{"id":"1.170370557","rc":[{"atb":[[2.58,0]],"id":9622734},{"atl":[[2.74,0]],"id":9622734},{"atb":[[1.57,0]],"id":9624350},{"atl":[[1.64,0]],"id":9624350}],"con":true,"img":false}]}
{"op":"mcm","clk":"1362025703","pt":1588423099759,"mc":[{"id":"1.170370557","rc":[{"atb":[[2.58,2.04]],"id":9622734},{"atl":[[2.74,2.25]],"id":9622734},{"atb":[[1.57,2.04]],"id":9624350},{"atl":[[1.64,2.04]],"id":9624350}],"con":true,"img":false}]}
{"op":"mcm","clk":"1362025719","pt":1588423100732,"mc":[{"id":"1.170370557","rc":[{"atb":[[1.57,42.03]],"id":9624350}],"con":true,"img":false}]}
{"op":"mcm","clk":"1362025725","pt":1588423100936,"mc":[{"id":"1.170370557","rc":[{"atb":[[2.14,39.99]],"id":9622734}],"con":true,"img":false}]}
{"op":"mcm","clk":"1362026055","pt":1588423132787,"mc":[{"id":"1.170370557","rc":[{"atb":[[1.6,23.02]],"id":9624350}],"con":true,"img":false}]}
{"op":"mcm","clk":"1362026059","pt":1588423133073,"mc":[{"id":"1.170370557","rc":[{"atb":[[2.58,0]],"id":9622734},{"atl":[[2.74,0]],"id":9622734},{"atb":[[1.57,39.99]],"id":9624350},{"atl":[[1.64,0]],"id":9624350}],"con":true,"img":false}]}
{"op":"mcm","clk":"1362026060","pt":1588423133278,"mc":[{"id":"1.170370557","rc":[{"atb":[[2.58,2.06]],"id":9622734},{"atl":[[2.74,2.13]],"id":9622734},{"atb":[[1.57,42.05]],"id":9624350},{"atl":[[1.64,2.04]],"id":9624350}],"con":true,"img":false}]}
{"op":"mcm","clk":"1362026082","pt":1588423135477,"mc":[{"id":"1.170370557","rc":[{"atl":[[2.68,2.48]],"id":9622734}],"con":true,"img":false}]}
{"op":"mcm","clk":"1362026322","pt":1588423159802,"mc":[{"id":"1.170370557","rc":[{"atb":[[2.14,0]],"id":9622734},{"atb":[[1.57,2.06]],"id":9624350}],"con":true,"img":false}]}
{"op":"mcm","clk":"1362026326","pt":1588423160110,"mc":[{"id":"1.170370557","rc":[{"atb":[[1.57,0]],"id":9624350}],"con":true,"img":false}]}
{"op":"mcm","clk":"1362026328","pt":1588423160211,"mc":[{"id":"1.170370557","rc":[{"atb":[[2.58,0]],"id":9622734},{"atl":[[2.74,0]],"id":9622734},{"atl":[[1.64,0]],"id":9624350}],"con":true,"img":false}]}
{"op":"mcm","clk":"1362026332","pt":1588423160417,"mc":[{"id":"1.170370557","rc":[{"atb":[[2.58,2.06]],"id":9622734},{"atl":[[2.74,2.17]],"id":9622734},{"atb":[[1.57,2.06]],"id":9624350},{"atl":[[1.64,2.04]],"id":9624350}],"con":true,"img":false}]}
{"op":"mcm","clk":"1362026408","pt":1588423167031,"mc":[{"id":"1.170370557","rc":[{"atb":[[1.57,42.05]],"id":9624350}],"con":true,"img":false}]}
{"op":"mcm","clk":"1362026413","pt":1588423167235,"mc":[{"id":"1.170370557","rc":[{"atb":[[2.14,39.99]],"id":9622734}],"con":true,"img":false}]}
{"op":"mcm","clk":"1362026416","pt":1588423167338,"mc":[{"id":"1.170370557","rc":[{"atb":[[2.58,0]],"id":9622734},{"atl":[[2.74,0]],"id":9622734},{"atb":[[1.57,39.99]],"id":9624350},{"atl":[[1.64,0]],"id":9624350}],"con":true,"img":false}]}
{"op":"mcm","clk":"1362026419","pt":1588423167542,"mc":[{"id":"1.170370557","rc":[{"atb":[[2.58,2.06]],"id":9622734},{"atl":[[2.74,2.09]],"id":9622734},{"atb":[[1.57,42.05]],"id":9624350},{"atl":[[1.64,2.04]],"id":9624350}],"con":true,"img":false}]}
{"op":"mcm","clk":"1362026827","pt":1588423203003,"mc":[{"id":"1.170370557","rc":[{"atl":[[10,0]],"id":9622734},{"atl":[[20,0]],"id":9624350}],"con":true,"img":false}]}
{"op":"mcm","clk":"1362026830","pt":1588423203106,"mc":[{"id":"1.170370557","rc":[{"atb":[[1.03,0]],"id":9622734},{"atb":[[1.03,0]],"id":9624350}],"con":true,"img":false}]}
{"op":"mcm","clk":"1362026833","pt":1588423203308,"mc":[{"id":"1.170370557","rc":[{"atb":[[2.58,0]],"id":9622734},{"atl":[[2.74,0]],"id":9622734},{"atb":[[1.57,39.99]],"id":9624350},{"atl":[[1.64,0]],"id":9624350}],"con":true,"img":false}]}
{"op":"mcm","clk":"1362026840","pt":1588423203514,"mc":[{"id":"1.170370557","rc":[{"atb":[[2.58,2.06]],"id":9622734},{"atl":[[2.74,2.13]],"id":9622734},{"atb":[[1.57,42.05]],"id":9624350},{"atl":[[1.64,2.18]],"id":9624350}],"con":true,"img":false}]}
{"op":"mcm","clk":"1362026927","pt":1588423209515,"mc":[{"id":"1.170370557","rc":[{"atb":[[1.6,2.48]],"id":9624350}],"con":true,"img":false}]}
{"op":"mcm","clk":"1362026930","pt":1588423209615,"mc":[{"id":"1.170370557","rc":[{"trd":[[1.61,187.84]],"ltp":1.61,"tv":187.84,"id":9624350},{"atl":[[1.61,68.11]],"id":9624350}],"con":true,"img":false}]}
{"op":"mcm","clk":"1362026934","pt":1588423209821,"mc":[{"id":"1.170370557","rc":[{"atb":[[2.58,0]],"id":9622734},{"atl":[[2.74,0]],"id":9622734},{"atb":[[1.57,39.99]],"id":9624350},{"atl":[[1.64,0]],"id":9624350}],"con":true,"img":false}]}
{"op":"mcm","clk":"1362026936","pt":1588423210025,"mc":[{"id":"1.170370557","rc":[{"atb":[[2.58,2]],"id":9622734},{"atl":[[2.74,2.25]],"id":9622734},{"atb":[[1.57,42.01]],"id":9624350},{"atl":[[1.64,2.18]],"id":9624350}],"con":true,"img":false}]}
{"op":"mcm","clk":"1362027045","pt":1588423220427,"mc":[{"id":"1.170370557","rc":[{"atb":[[2.14,0]],"id":9622734},{"atb":[[1.57,2.02]],"id":9624350}],"con":true,"img":false}]}
{"op":"mcm","clk":"1362027052","pt":1588423220735,"mc":[{"id":"1.170370557","rc":[{"atb":[[2.58,0]],"id":9622734},{"atl":[[2.74,0]],"id":9622734},{"atb":[[1.57,0]],"id":9624350},{"atl":[[1.64,0]],"id":9624350}],"con":true,"img":false}]}
{"op":"mcm","clk":"1362027056","pt":1588423220890,"mc":[{"id":"1.170370557","rc":[{"atb":[[2.58,2.06]],"id":9622734},{"atl":[[2.74,2.05]],"id":9622734},{"atb":[[1.57,2.06]],"id":9624350},{"atl":[[1.64,2.04]],"id":9624350}],"con":true,"img":false}]}
{"op":"mcm","clk":"1362027149","pt":1588423228017,"mc":[{"id":"1.170370557","rc":[{"atb":[[1.57,42.05]],"id":9624350}],"con":true,"img":false}]}
{"op":"mcm","clk":"1362027153","pt":1588423228324,"mc":[{"id":"1.170370557","rc":[{"atb":[[2.58,0],[2.14,39.99]],"id":9622734},{"atl":[[2.74,0]],"id":9622734},{"atb":[[1.57,39.99]],"id":9624350},{"atl":[[1.64,0]],"id":9624350}],"con":true,"img":false}]}
{"op":"mcm","clk":"1362027157","pt":1588423228528,"mc":[{"id":"1.170370557","rc":[{"atb":[[2.58,2.06]],"id":9622734},{"atl":[[2.74,2.17]],"id":9622734},{"atb":[[1.57,42.05]],"id":9624350},{"atl":[[1.64,2.18]],"id":9624350}],"con":true,"img":false}]}
{"op":"mcm","clk":"1362027215","pt":1588423234415,"mc":[{"id":"1.170370557","rc":[{"trd":[[2.64,143.95]],"ltp":2.64,"tv":143.95,"id":9622734},{"atb":[[2.64,6.87]],"id":9622734}],"con":true,"img":false}]}
{"op":"mcm","clk":"1362027218","pt":1588423234721,"mc":[{"id":"1.170370557","rc":[{"atb":[[2.58,0]],"id":9622734},{"atl":[[2.74,0]],"id":9622734},{"atb":[[1.57,39.99]],"id":9624350},{"atl":[[1.64,0]],"id":9624350}],"con":true,"img":false}]}
{"op":"mcm","clk":"1362027219","pt":1588423234926,"mc":[{"id":"1.170370557","rc":[{"atb":[[2.58,2.06]],"id":9622734},{"atl":[[2.74,2.25]],"id":9622734},{"atb":[[1.57,42.05]],"id":9624350},{"atl":[[1.64,2.04]],"id":9624350}],"con":true,"img":false}]}
{"op":"mcm","clk":"1362027244","pt":1588423237334,"mc":[{"id":"1.170370557","rc":[{"atb":[[2.24,47.46]],"id":9622734},{"atb":[[1.57,145.31]],"id":9624350}],"con":true,"img":false}]}
{"op":"mcm","clk":"1362027332","pt":1588423245359,"mc":[{"id":"1.170370557","rc":[{"atl":[[1.7,187.96]],"id":9624350}],"con":true,"img":false}]}
{"op":"mcm","clk":"1362027335","pt":1588423245666,"mc":[{"id":"1.170370557","rc":[{"atb":[[2.58,0]],"id":9622734},{"atl":[[2.74,0]],"id":9622734},{"atb":[[1.57,143.25]],"id":9624350},{"atl":[[1.64,0]],"id":9624350}],"con":true,"img":false}]}
{"op":"mcm","clk":"1362027338","pt":1588423245924,"mc":[{"id":"1.170370557","rc":[{"atb":[[2.58,2.06]],"id":9622734},{"atl":[[2.74,2.01]],"id":9622734},{"atb":[[1.57,145.31]],"id":9624350},{"atl":[[1.64,2.01]],"id":9624350}],"con":true,"img":false}]}
{"op":"mcm","clk":"1362027728","pt":1588423281066,"mc":[{"id":"1.170370557","rc":[{"atb":[[2.14,0]],"id":9622734},{"atb":[[1.57,105.32]],"id":9624350}],"con":true,"img":false}]}
{"op":"mcm","clk":"1362027730","pt":1588423281376,"mc":[{"id":"1.170370557","rc":[{"atb":[[2.58,0]],"id":9622734},{"atl":[[2.74,0]],"id":9622734},{"atb":[[1.57,103.26]],"id":9624350},{"atl":[[1.64,0]],"id":9624350}],"con":true,"img":false}]}
{"op":"mcm","clk":"1362027736","pt":1588423281580,"mc":[{"id":"1.170370557","rc":[{"atb":[[2.58,2.02]],"id":9622734},{"atl":[[2.74,2.25]],"id":9622734},{"atb":[[1.57,105.32]],"id":9624350},{"atl":[[1.64,2.18]],"id":9624350}],"con":true,"img":false}]}
{"op":"mcm","clk":"1362027786","pt":1588423286298,"mc":[{"id":"1.170370557","rc":[{"atb":[[1.57,145.31]],"id":9624350}],"con":true,"img":false}]}
{"op":"mcm","clk":"1362027788","pt":1588423286502,"mc":[{"id":"1.170370557","rc":[{"atb":[[2.14,39.99]],"id":9622734}],"con":true,"img":false}]}
{"op":"mcm","clk":"1362028467","pt":1588423341677,"mc":[{"id":"1.170370557","rc":[{"atb":[[2.14,0]],"id":9622734},{"atb":[[1.57,105.32]],"id":9624350}],"con":true,"img":false}]}
{"op":"mcm","clk":"1362028473","pt":1588423341985,"mc":[{"id":"1.170370557","rc":[{"atb":[[2.58,0]],"id":9622734},{"atl":[[2.74,0]],"id":9622734},{"atb":[[1.57,103.26]],"id":9624350},{"atl":[[1.64,0]],"id":9624350}],"con":true,"img":false}]}
{"op":"mcm","clk":"1362028478","pt":1588423342189,"mc":[{"id":"1.170370557","rc":[{"atb":[[2.58,2.06]],"id":9622734},{"atl":[[2.74,2.25]],"id":9622734},{"atb":[[1.57,105.32]],"id":9624350},{"atl":[[1.64,2.18]],"id":9624350}],"con":true,"img":false}]}
{"op":"mcm","clk":"1362028480","pt":1588423342345,"mc":[{"id":"1.170370557","rc":[{"atb":[[2.58,4.12]],"id":9622734},{"atl":[[2.74,4.34]],"id":9622734},{"atb":[[1.57,107.38]],"id":9624350},{"atl":[[1.64,4.22]],"id":9624350}],"con":true,"img":false}]}
{"op":"mcm","clk":"1362028568","pt":1588423348797,"mc":[{"id":"1.170370557","rc":[{"atb":[[1.57,147.37]],"id":9624350}],"con":true,"img":false}]}
{"op":"mcm","clk":"1362028573","pt":1588423348952,"mc":[{"id":"1.170370557","rc":[{"atb":[[2.14,39.99]],"id":9622734}],"con":true,"img":false}]}
{"op":"mcm","clk":"1362028579","pt":1588423349157,"mc":[{"id":"1.170370557","rc":[{"atb":[[2.58,0]],"id":9622734},{"atl":[[2.74,0]],"id":9622734},{"atb":[[1.57,143.25]],"id":9624350},{"atl":[[1.64,0]],"id":9624350}],"con":true,"img":false}]}
{"op":"mcm","clk":"1362028582","pt":1588423349359,"mc":[{"id":"1.170370557","rc":[{"atb":[[2.58,2.06]],"id":9622734},{"atl":[[2.74,2.01]],"id":9622734},{"atb":[[1.57,145.31]],"id":9624350},{"atl":[[1.64,2.04]],"id":9624350}],"con":true,"img":false}]}
{"op":"mcm","clk":"1362029184","pt":1588423402256,"mc":[{"id":"1.170370557","rc":[{"atb":[[2.14,0]],"id":9622734},{"atb":[[1.57,105.32]],"id":9624350}],"con":true,"img":false}]}
{"op":"mcm","clk":"1362029189","pt":1588423402564,"mc":[{"id":"1.170370557","rc":[{"atb":[[2.58,0]],"id":9622734},{"atl":[[2.74,0]],"id":9622734},{"atb":[[1.57,103.26]],"id":9624350},{"atl":[[1.64,0]],"id":9624350}],"con":true,"img":false}]}
{"op":"mcm","clk":"1362029193","pt":1588423402766,"mc":[{"id":"1.170370557","rc":[{"atb":[[2.58,2.02]],"id":9622734},{"atl":[[2.74,2.05]],"id":9622734},{"atb":[[1.57,105.32]],"id":9624350},{"atl":[[1.64,2.04]],"id":9624350}],"con":true,"img":false}]}
{"op":"mcm","clk":"1362029220","pt":1588423406042,"mc":[{"id":"1.170370557","rc":[{"atb":[[1.57,145.31]],"id":9624350}],"con":true,"img":false}]}
{"op":"mcm","clk":"1362029231","pt":1588423406862,"mc":[{"id":"1.170370557","rc":[{"atb":[[2.14,39.99]],"id":9622734}],"con":true,"img":false}]}
{"op":"mcm","clk":"1362029318","pt":1588423415056,"mc":[{"id":"1.170370557","rc":[{"atb":[[1.59,65.85]],"id":9624350}],"con":true,"img":false}]}
{"op":"mcm","clk":"1362029321","pt":1588423415361,"mc":[{"id":"1.170370557","rc":[{"atb":[[2.58,0]],"id":9622734},{"atl":[[2.74,0]],"id":9622734},{"atb":[[1.57,143.25]],"id":9624350},{"atl":[[1.64,0]],"id":9624350}],"con":true,"img":false}]}
{"op":"mcm","clk":"1362029324","pt":1588423415567,"mc":[{"id":"1.170370557","rc":[{"atb":[[2.58,2.06]],"id":9622734},{"atl":[[2.74,2.01]],"id":9622734},{"atb":[[1.57,145.31]],"id":9624350},{"atl":[[1.64,2.18]],"id":9624350}],"con":true,"img":false}]}
{"op":"mcm","clk":"1362030678","pt":1588423462934,"mc":[{"id":"1.170370557","rc":[{"atb":[[2.14,0]],"id":9622734},{"atb":[[1.57,105.32]],"id":9624350}],"con":true,"img":false}]}
{"op":"mcm","clk":"1362030682","pt":1588423463242,"mc":[{"id":"1.170370557","rc":[{"atb":[[2.58,0]],"id":9622734},{"atl":[[2.74,0]],"id":9622734},{"atb":[[1.57,103.26]],"id":9624350},{"atl":[[1.64,0]],"id":9624350}],"con":true,"img":false}]}
{"op":"mcm","clk":"1362030683","pt":1588423463297,"mc":[{"id":"1.170370557","rc":[{"atb":[[1.57,143.25]],"id":9624350}],"con":true,"img":false}]}
{"op":"mcm","clk":"1362030684","pt":1588423463398,"mc":[{"id":"1.170370557","rc":[{"atb":[[2.58,2.06]],"id":9622734},{"atl":[[2.74,2.21]],"id":9622734},{"atb":[[1.57,145.31]],"id":9624350},{"atl":[[1.64,2.18]],"id":9624350}],"con":true,"img":false}]}
{"op":"mcm","clk":"1362030687","pt":1588423463500,"mc":[{"id":"1.170370557","rc":[{"atb":[[2.14,39.99]],"id":9622734}],"con":true,"img":false}]}
{"op":"mcm","clk":"1362031389","pt":1588423523589,"mc":[{"id":"1.170370557","rc":[{"atb":[[2.14,0]],"id":9622734},{"atb":[[1.57,105.32]],"id":9624350}],"con":true,"img":false}]}
{"op":"mcm","clk":"1362031396","pt":1588423523895,"mc":[{"id":"1.170370557","rc":[{"atb":[[2.58,0]],"id":9622734},{"atl":[[2.74,0]],"id":9622734},{"atb":[[1.57,103.26]],"id":9624350},{"atl":[[1.64,0]],"id":9624350}],"con":true,"img":false}]}
{"op":"mcm","clk":"1362031399","pt":1588423524099,"mc":[{"id":"1.170370557","rc":[{"atb":[[2.58,2.06]],"id":9622734},{"atl":[[2.74,2.21]],"id":9622734},{"atb":[[1.57,105.32]],"id":9624350},{"atl":[[1.64,2.01]],"id":9624350}],"con":true,"img":false}]}
{"op":"mcm","clk":"1362031485","pt":1588423530808,"mc":[{"id":"1.170370557","rc":[{"atb":[[1.57,145.31]],"id":9624350}],"con":true,"img":false}]}
{"op":"mcm","clk":"1362031489","pt":1588423531012,"mc":[{"id":"1.170370557","rc":[{"atb":[[2.14,39.99]],"id":9622734}],"con":true,"img":false}]}
{"op":"mcm","clk":"1362031491","pt":1588423531113,"mc":[{"id":"1.170370557","rc":[{"atl":[[2.74,0]],"id":9622734},{"atb":[[1.57,143.25]],"id":9624350},{"atl":[[1.64,0]],"id":9624350}],"con":true,"img":false}]}
{"op":"mcm","clk":"1362031492","pt":1588423531216,"mc":[{"id":"1.170370557","rc":[{"atb":[[2.58,0]],"id":9622734}],"con":true,"img":false}]}
{"op":"mcm","clk":"1362031494","pt":1588423531420,"mc":[{"id":"1.170370557","rc":[{"atb":[[2.58,2.06]],"id":9622734},{"atl":[[2.74,2.17]],"id":9622734},{"atb":[[1.57,145.25]],"id":9624350},{"atl":[[1.64,2.04]],"id":9624350}],"con":true,"img":false}]}
{"op":"mcm","clk":"1362031899","pt":1588423564350,"mc":[{"id":"1.170370557","rc":[{"atb":[[1.57,105.26]],"id":9624350}],"con":true,"img":false}]}
{"op":"mcm","clk":"1362031902","pt":1588423564654,"mc":[{"id":"1.170370557","rc":[{"atb":[[2.58,0]],"id":9622734},{"atl":[[2.74,0]],"id":9622734},{"atb":[[1.57,103.26]],"id":9624350},{"atl":[[1.64,0]],"id":9624350}],"con":true,"img":false}]}
{"op":"mcm","clk":"1362031904","pt":1588423564756,"mc":[{"id":"1.170370557","rc":[{"atb":[[2.14,0]],"id":9622734}],"con":true,"img":false}]}
{"op":"mcm","clk":"1362031907","pt":1588423564859,"mc":[{"id":"1.170370557","rc":[{"atb":[[2.58,2.06],[2.34,39.99]],"id":9622734},{"atl":[[2.74,2.25]],"id":9622734},{"atb":[[1.57,105.32]],"id":9624350},{"atl":[[1.64,2.04]],"id":9624350}],"con":true,"img":false}]}
{"op":"mcm","clk":"1362031938","pt":1588423567371,"mc":[{"id":"1.170370557","rc":[{"atb":[[1.45,39.99]],"id":9624350}],"con":true,"img":false}]}
{"op":"mcm","clk":"1362031940","pt":1588423567575,"mc":[{"id":"1.170370557","rc":[{"atb":[[2.42,39.99]],"id":9622734}],"con":true,"img":false}]}
{"op":"mcm","clk":"1362031962","pt":1588423569369,"mc":[{"id":"1.170370557","rc":[{"atb":[[2.42,0]],"id":9622734}],"con":true,"img":false}]}
{"op":"mcm","clk":"1362031968","pt":1588423569778,"mc":[{"id":"1.170370557","rc":[{"atb":[[2.34,0]],"id":9622734}],"con":true,"img":false}]}
{"op":"mcm","clk":"1362032039","pt":1588423575968,"mc":[{"id":"1.170370557","rc":[{"atb":[[2.42,39.99]],"id":9622734}],"con":true,"img":false}]}
{"op":"mcm","clk":"1362032044","pt":1588423576283,"mc":[{"id":"1.170370557","rc":[{"atb":[[2.58,0]],"id":9622734},{"atl":[[2.74,0]],"id":9622734},{"atb":[[1.57,103.26]],"id":9624350},{"atl":[[1.64,0]],"id":9624350}],"con":true,"img":false}]}
{"op":"mcm","clk":"1362032048","pt":1588423576476,"mc":[{"id":"1.170370557","rc":[{"atb":[[2.58,2.04]],"id":9622734},{"atl":[[2.74,2.25]],"id":9622734},{"atb":[[1.57,105.32]],"id":9624350},{"atl":[[1.64,2.04]],"id":9624350}],"con":true,"img":false}]}
{"op":"mcm","clk":"1362032112","pt":1588423580562,"mc":[{"id":"1.170370557","rc":[{"atb":[[2.42,0]],"id":9622734}],"con":true,"img":false}]}
{"op":"mcm","clk":"1362032115","pt":1588423580665,"mc":[{"id":"1.170370557","rc":[{"atb":[[2.34,39.99]],"id":9622734}],"con":true,"img":false}]}
{"op":"mcm","clk":"1362032167","pt":1588423584395,"mc":[{"id":"1.170370557","rc":[{"atb":[[2.34,0]],"id":9622734},{"atb":[[1.45,0]],"id":9624350}],"con":true,"img":false}]}
{"op":"mcm","clk":"1362032178","pt":1588423584701,"mc":[{"id":"1.170370557","rc":[{"atb":[[2.58,0]],"id":9622734},{"atl":[[2.74,0]],"id":9622734},{"atb":[[1.57,103.26]],"id":9624350},{"atl":[[1.64,0]],"id":9624350}],"con":true,"img":false}]}
{"op":"mcm","clk":"1362032186","pt":1588423584906,"mc":[{"id":"1.170370557","rc":[{"atb":[[2.58,2.06]],"id":9622734},{"atl":[[2.74,2.25]],"id":9622734},{"atb":[[1.57,105.32]],"id":9624350},{"atl":[[1.64,2.18]],"id":9624350}],"con":true,"img":false}]}
{"op":"mcm","clk":"1362032194","pt":1588423585367,"mc":[{"id":"1.170370557","rc":[{"atb":[[1.45,39.99]],"id":9624350}],"con":true,"img":false}]}
{"op":"mcm","clk":"1362032197","pt":1588423585571,"mc":[{"id":"1.170370557","rc":[{"atb":[[2.42,39.99]],"id":9622734}],"con":true,"img":false}]}
{"op":"mcm","clk":"1362032259","pt":1588423589811,"mc":[{"id":"1.170370557","rc":[{"atb":[[2.42,0]],"id":9622734}],"con":true,"img":false}]}
{"op":"mcm","clk":"1362032263","pt":1588423589865,"mc":[{"id":"1.170370557","rc":[{"atb":[[2.34,39.99]],"id":9622734}],"con":true,"img":false}]}
{"op":"mcm","clk":"1362032336","pt":1588423594312,"mc":[{"id":"1.170370557","rc":[{"atb":[[2.34,0]],"id":9622734}],"con":true,"img":false}]}
{"op":"mcm","clk":"1362032339","pt":1588423594365,"mc":[{"id":"1.170370557","rc":[{"atb":[[2.42,39.99]],"id":9622734}],"con":true,"img":false}]}
{"op":"mcm","clk":"1362032345","pt":1588423594571,"mc":[{"id":"1.170370557","rc":[{"atb":[[1.57,103.26]],"id":9624350},{"atl":[[1.64,0]],"id":9624350}],"con":true,"img":false}]}
{"op":"mcm","clk":"1362032347","pt":1588423594674,"mc":[{"id":"1.170370557","rc":[{"atb":[[2.58,0]],"id":9622734},{"atl":[[2.74,0]],"id":9622734}],"con":true,"img":false}]}
{"op":"mcm","clk":"1362032350","pt":1588423594777,"mc":[{"id":"1.170370557","rc":[{"atb":[[1.57,105.32]],"id":9624350},{"atl":[[1.64,2.01]],"id":9624350}],"con":true,"img":false}]}
{"op":"mcm","clk":"1362032352","pt":1588423594880,"mc":[{"id":"1.170370557","rc":[{"atb":[[2.58,2.06]],"id":9622734},{"atl":[[2.74,2.01]],"id":9622734}],"con":true,"img":false}]}
{"op":"mcm","clk":"1362032422","pt":1588423599584,"mc":[{"id":"1.170370557","rc":[{"atb":[[2.42,0]],"id":9622734}],"con":true,"img":false}]}
{"op":"mcm","clk":"1362032423","pt":1588423599688,"mc":[{"id":"1.170370557","rc":[{"atb":[[2.34,39.99]],"id":9622734}],"con":true,"img":false}]}
{"op":"mcm","clk":"1362032486","pt":1588423603976,"mc":[{"id":"1.170370557","rc":[{"atb":[[2.34,0]],"id":9622734}],"con":true,"img":false}]}
{"op":"mcm","clk":"1362032489","pt":1588423604079,"mc":[{"id":"1.170370557","rc":[{"atb":[[2.42,39.99]],"id":9622734}],"con":true,"img":false}]}
{"op":"mcm","clk":"1362032494","pt":1588423604284,"mc":[{"id":"1.170370557","rc":[{"atb":[[2.58,0]],"id":9622734},{"atl":[[2.74,0]],"id":9622734},{"atb":[[1.57,103.26]],"id":9624350},{"atl":[[1.64,0]],"id":9624350}],"con":true,"img":false}]}
{"op":"mcm","clk":"1362032498","pt":1588423604490,"mc":[{"id":"1.170370557","rc":[{"atb":[[2.58,2.06]],"id":9622734},{"atl":[[2.74,2.25]],"id":9622734},{"atb":[[1.57,105.32]],"id":9624350},{"atl":[[1.64,2.04]],"id":9624350}],"con":true,"img":false}]}
{"op":"mcm","clk":"1362032544","pt":1588423608418,"mc":[{"id":"1.170370557","rc":[{"atb":[[2.42,0]],"id":9622734}],"con":true,"img":false}]}
{"op":"mcm","clk":"1362032546","pt":1588423608521,"mc":[{"id":"1.170370557","rc":[{"atb":[[2.34,39.99]],"id":9622734}],"con":true,"img":false}]}
{"op":"mcm","clk":"1362032620","pt":1588423612922,"mc":[{"id":"1.170370557","rc":[{"atb":[[2.34,0]],"id":9622734}],"con":true,"img":false}]}
{"op":"mcm","clk":"1362032623","pt":1588423613022,"mc":[{"id":"1.170370557","rc":[{"atb":[[2.42,39.99]],"id":9622734}],"con":true,"img":false}]}
{"op":"mcm","clk":"1362032627","pt":1588423613227,"mc":[{"id":"1.170370557","rc":[{"atb":[[2.58,0]],"id":9622734},{"atl":[[2.74,0]],"id":9622734},{"atb":[[1.57,103.26]],"id":9624350},{"atl":[[1.64,0]],"id":9624350}],"con":true,"img":false}]}
{"op":"mcm","clk":"1362032633","pt":1588423613431,"mc":[{"id":"1.170370557","rc":[{"atb":[[2.58,2.06]],"id":9622734},{"atl":[[2.74,2.17]],"id":9622734},{"atb":[[1.57,105.32]],"id":9624350},{"atl":[[1.64,2.18]],"id":9624350}],"con":true,"img":false}]}
{"op":"mcm","clk":"1362032684","pt":1588423617111,"mc":[{"id":"1.170370557","rc":[{"atb":[[2.42,0]],"id":9622734}],"con":true,"img":false}]}
{"op":"mcm","clk":"1362032686","pt":1588423617215,"mc":[{"id":"1.170370557","rc":[{"atb":[[2.34,39.99]],"id":9622734}],"con":true,"img":false}]}
{"op":"mcm","clk":"1362032747","pt":1588423621416,"mc":[{"id":"1.170370557","rc":[{"atb":[[2.34,0]],"id":9622734}],"con":true,"img":false}]}
{"op":"mcm","clk":"1362032749","pt":1588423621519,"mc":[{"id":"1.170370557","rc":[{"atb":[[2.42,39.99]],"id":9622734}],"con":true,"img":false}]}
{"op":"mcm","clk":"1362032751","pt":1588423621725,"mc":[{"id":"1.170370557","rc":[{"atb":[[2.58,0]],"id":9622734},{"atl":[[2.74,0]],"id":9622734},{"atb":[[1.57,103.26]],"id":9624350},{"atl":[[1.64,0]],"id":9624350}],"con":true,"img":false}]}
{"op":"mcm","clk":"1362032753","pt":1588423621930,"mc":[{"id":"1.170370557","rc":[{"atb":[[2.58,2.06]],"id":9622734},{"atl":[[2.74,2.21]],"id":9622734},{"atb":[[1.57,105.32]],"id":9624350},{"atl":[[1.64,2.04]],"id":9624350}],"con":true,"img":false}]}
{"op":"mcm","clk":"1362032816","pt":1588423625941,"mc":[{"id":"1.170370557","rc":[{"atb":[[2.42,0]],"id":9622734}],"con":true,"img":false}]}
{"op":"mcm","clk":"1362032819","pt":1588423626044,"mc":[{"id":"1.170370557","rc":[{"atb":[[2.34,39.99]],"id":9622734}],"con":true,"img":false}]}
{"op":"mcm","clk":"1362032877","pt":1588423630342,"mc":[{"id":"1.170370557","rc":[{"atb":[[2.34,0]],"id":9622734}],"con":true,"img":false}]}
{"op":"mcm","clk":"1362032878","pt":1588423630444,"mc":[{"id":"1.170370557","rc":[{"atb":[[2.42,39.99]],"id":9622734}],"con":true,"img":false}]}
{"op":"mcm","clk":"1362032881","pt":1588423630647,"mc":[{"id":"1.170370557","rc":[{"atb":[[2.58,0]],"id":9622734},{"atl":[[2.74,0]],"id":9622734},{"atb":[[1.57,103.26]],"id":9624350},{"atl":[[1.64,0]],"id":9624350}],"con":true,"img":false}]}
{"op":"mcm","clk":"1362032884","pt":1588423630852,"mc":[{"id":"1.170370557","rc":[{"atb":[[2.58,2.06]],"id":9622734},{"atl":[[2.74,2.25]],"id":9622734},{"atb":[[1.57,105.32]],"id":9624350},{"atl":[[1.64,2.04]],"id":9624350}],"con":true,"img":false}]}
{"op":"mcm","clk":"1362032931","pt":1588423634648,"mc":[{"id":"1.170370557","rc":[{"atb":[[2.42,0]],"id":9622734}],"con":true,"img":false}]}
{"op":"mcm","clk":"1362032933","pt":1588423634749,"mc":[{"id":"1.170370557","rc":[{"atb":[[2.34,39.99]],"id":9622734}],"con":true,"img":false}]}
{"op":"mcm","clk":"1362033001","pt":1588423639758,"mc":[{"id":"1.170370557","rc":[{"atb":[[2.34,0]],"id":9622734}],"con":true,"img":false}]}
{"op":"mcm","clk":"1362033003","pt":1588423639860,"mc":[{"id":"1.170370557","rc":[{"atb":[[2.42,39.99]],"id":9622734}],"con":true,"img":false}]}
{"op":"mcm","clk":"1362033006","pt":1588423640065,"mc":[{"id":"1.170370557","rc":[{"atb":[[2.58,0]],"id":9622734},{"atl":[[2.74,0]],"id":9622734},{"atb":[[1.57,103.26]],"id":9624350},{"atl":[[1.64,0]],"id":9624350}],"con":true,"img":false}]}
{"op":"mcm","clk":"1362033008","pt":1588423640270,"mc":[{"id":"1.170370557","rc":[{"atb":[[2.58,2.06]],"id":9622734},{"atl":[[2.74,2.01]],"id":9622734},{"atb":[[1.57,105.32]],"id":9624350},{"atl":[[1.64,2.01]],"id":9624350}],"con":true,"img":false}]}
{"op":"mcm","clk":"1362033089","pt":1588423644976,"mc":[{"id":"1.170370557","rc":[{"atb":[[2.42,0]],"id":9622734},{"atb":[[1.45,0]],"id":9624350}],"con":true,"img":false}]}
{"op":"mcm","clk":"1362033143","pt":1588423648360,"mc":[{"id":"1.170370557","rc":[{"atb":[[1.45,39.99]],"id":9624350}],"con":true,"img":false}]}
{"op":"mcm","clk":"1362033149","pt":1588423648563,"mc":[{"id":"1.170370557","rc":[{"atb":[[2.42,39.99]],"id":9622734}],"con":true,"img":false}]}
{"op":"mcm","clk":"1362033150","pt":1588423648665,"mc":[{"id":"1.170370557","rc":[{"atb":[[2.58,0]],"id":9622734},{"atl":[[2.74,0]],"id":9622734},{"atb":[[1.57,103.26]],"id":9624350},{"atl":[[1.64,0]],"id":9624350}],"con":true,"img":false}]}
{"op":"mcm","clk":"1362033151","pt":1588423648869,"mc":[{"id":"1.170370557","rc":[{"atb":[[2.58,2.06]],"id":9622734},{"atl":[[2.74,2.09]],"id":9622734},{"atb":[[1.57,105.32]],"id":9624350},{"atl":[[1.64,2.04]],"id":9624350}],"con":true,"img":false}]}
{"op":"mcm","clk":"1362033555","pt":1588423683236,"mc":[{"id":"1.170370557","marketDefinition":{"bspMarket":false,"turnInPlayEnabled":true,"persistenceEnabled":true,"marketBaseRate":5.0,"eventId":"29788106","eventTypeId":"2","numberOfWinners":1,"bettingType":"ODDS","marketType":"MATCH_ODDS","marketTime":"2020-05-02T12:55:00.000Z","suspendTime":"2020-05-02T12:55:00.000Z","bspReconciled":false,"complete":true,"inPlay":false,"crossMatching":true,"runnersVoidable":false,"numberOfActiveRunners":2,"betDelay":0,"status":"OPEN","runners":[{"status":"ACTIVE","sortPriority":1,"id":9624350,"name":"Y Hanfmann"},{"status":"ACTIVE","sortPriority":2,"id":9622734,"name":"D Brown"}],"regulators":["MR_INT"],"countryCode":"GB","discountAllowed":true,"timezone":"GMT","openDate":"2020-05-02T12:50:00.000Z","version":3237540776,"name":"Match Odds","eventName":"Y Hanfmann v D Brown"},"rc":[],"con":true,"img":false}]}
{"op":"mcm","clk":"1362033585","pt":1588423685990,"mc":[{"id":"1.170370557","rc":[{"atb":[[2.42,0]],"id":9622734}],"con":true,"img":false}]}
{"op":"mcm","clk":"1362033588","pt":1588423686093,"mc":[{"id":"1.170370557","rc":[{"atb":[[2.34,39.99]],"id":9622734}],"con":true,"img":false}]}
{"op":"mcm","clk":"1362033592","pt":1588423686240,"mc":[{"id":"1.170370557","marketDefinition":{"bspMarket":false,"turnInPlayEnabled":true,"persistenceEnabled":true,"marketBaseRate":5.0,"eventId":"29788106","eventTypeId":"2","numberOfWinners":1,"bettingType":"ODDS","marketType":"MATCH_ODDS","marketTime":"2020-05-02T12:55:00.000Z","suspendTime":"2020-05-02T12:55:00.000Z","bspReconciled":false,"complete":true,"inPlay":false,"crossMatching":true,"runnersVoidable":false,"numberOfActiveRunners":2,"betDelay":0,"status":"OPEN","runners":[{"status":"ACTIVE","sortPriority":1,"id":9624350,"name":"Y Hanfmann"},{"status":"ACTIVE","sortPriority":2,"id":9622734,"name":"D Brown"}],"regulators":["MR_INT"],"countryCode":"GB","discountAllowed":true,"timezone":"GMT","openDate":"2020-05-02T12:55:00.000Z","version":3237540776,"name":"Match Odds","eventName":"Y Hanfmann v D Brown"},"rc":[],"con":true,"img":false}]}
{"op":"mcm","clk":"1362033593","pt":1588423686297,"mc":[{"id":"1.170370557","rc":[{"atb":[[2.58,0]],"id":9622734},{"atl":[[2.74,0]],"id":9622734},{"atb":[[1.57,103.26]],"id":9624350},{"atl":[[1.64,0]],"id":9624350}],"con":true,"img":false}]}
{"op":"mcm","clk":"1362033596","pt":1588423686498,"mc":[{"id":"1.170370557","rc":[{"atb":[[2.58,2.02]],"id":9622734},{"atl":[[2.74,2.25]],"id":9622734},{"atb":[[1.57,105.32]],"id":9624350},{"atl":[[1.64,2.18]],"id":9624350}],"con":true,"img":false}]}
{"op":"mcm","clk":"1362033644","pt":1588423690392,"mc":[{"id":"1.170370557","rc":[{"atb":[[2.34,0]],"id":9622734}],"con":true,"img":false}]}
{"op":"mcm","clk":"1362033647","pt":1588423690493,"mc":[{"id":"1.170370557","rc":[{"atb":[[2.42,39.99]],"id":9622734}],"con":true,"img":false}]}
{"op":"mcm","clk":"1362033713","pt":1588423695106,"mc":[{"id":"1.170370557","rc":[{"atb":[[2.42,0]],"id":9622734}],"con":true,"img":false}]}
{"op":"mcm","clk":"1362033715","pt":1588423695205,"mc":[{"id":"1.170370557","rc":[{"atb":[[2.34,39.99]],"id":9622734}],"con":true,"img":false}]}
{"op":"mcm","clk":"1362033718","pt":1588423695411,"mc":[{"id":"1.170370557","rc":[{"atb":[[2.58,0]],"id":9622734},{"atl":[[2.74,0]],"id":9622734},{"atb":[[1.57,103.26]],"id":9624350},{"atl":[[1.64,0]],"id":9624350}],"con":true,"img":false}]}
{"op":"mcm","clk":"1362033721","pt":1588423695616,"mc":[{"id":"1.170370557","rc":[{"atb":[[2.58,2.06]],"id":9622734},{"atl":[[2.74,2.01]],"id":9622734},{"atb":[[1.57,105.32]],"id":9624350},{"atl":[[1.64,2.18]],"id":9624350}],"con":true,"img":false}]}
{"op":"mcm","clk":"1362033771","pt":1588423699307,"mc":[{"id":"1.170370557","rc":[{"atb":[[2.34,0]],"id":9622734}],"con":true,"img":false}]}
{"op":"mcm","clk":"1362033773","pt":1588423699411,"mc":[{"id":"1.170370557","rc":[{"atb":[[2.42,39.99]],"id":9622734}],"con":true,"img":false}]}
{"op":"mcm","clk":"1362033828","pt":1588423703717,"mc":[{"id":"1.170370557","rc":[{"atb":[[2.42,0]],"id":9622734}],"con":true,"img":false}]}
{"op":"mcm","clk":"1362033829","pt":1588423703820,"mc":[{"id":"1.170370557","rc":[{"atb":[[2.34,39.99]],"id":9622734}],"con":true,"img":false}]}
{"op":"mcm","clk":"1362033835","pt":1588423704026,"mc":[{"id":"1.170370557","rc":[{"atb":[[2.58,0]],"id":9622734},{"atl":[[2.74,0]],"id":9622734},{"atb":[[1.57,103.26]],"id":9624350},{"atl":[[1.64,0]],"id":9624350}],"con":true,"img":false}]}
{"op":"mcm","clk":"1362033839","pt":1588423704229,"mc":[{"id":"1.170370557","rc":[{"atb":[[2.58,2.06]],"id":9622734},{"atl":[[2.74,2.21]],"id":9622734},{"atb":[[1.57,105.32]],"id":9624350},{"atl":[[1.64,2.04]],"id":9624350}],"con":true,"img":false}]}
{"op":"mcm","clk":"1362033860","pt":1588423705617,"mc":[{"id":"1.170370557","rc":[{"atb":[[2.34,0]],"id":9622734},{"atb":[[1.45,0]],"id":9624350}],"con":true,"img":false}]}
{"op":"mcm","clk":"1362033901","pt":1588423708640,"mc":[{"id":"1.170370557","rc":[{"atb":[[1.45,39.99]],"id":9624350}],"con":true,"img":false}]}
{"op":"mcm","clk":"1362033902","pt":1588423708845,"mc":[{"id":"1.170370557","rc":[{"atb":[[2.42,39.99]],"id":9622734}],"con":true,"img":false}]}
{"op":"mcm","clk":"1362033952","pt":1588423713355,"mc":[{"id":"1.170370557","rc":[{"atb":[[2.42,0]],"id":9622734}],"con":true,"img":false}]}
{"op":"mcm","clk":"1362033954","pt":1588423713458,"mc":[{"id":"1.170370557","rc":[{"atb":[[2.34,39.99]],"id":9622734}],"con":true,"img":false}]}
{"op":"mcm","clk":"1362033963","pt":1588423713767,"mc":[{"id":"1.170370557","rc":[{"atb":[[2.58,0]],"id":9622734},{"atl":[[2.74,0]],"id":9622734},{"atb":[[1.57,103.26]],"id":9624350},{"atl":[[1.64,0]],"id":9624350}],"con":true,"img":false}]}
{"op":"mcm","clk":"1362033967","pt":1588423713922,"mc":[{"id":"1.170370557","rc":[{"atb":[[2.58,2.02]],"id":9622734},{"atl":[[2.74,2.21]],"id":9622734},{"atb":[[1.57,105.32]],"id":9624350},{"atl":[[1.64,2.04]],"id":9624350}],"con":true,"img":false}]}
{"op":"mcm","clk":"1362034008","pt":1588423716848,"mc":[{"id":"1.170370557","rc":[{"atl":[[2.68,0]],"id":9622734}],"con":true,"img":false}]}
{"op":"mcm","clk":"1362034012","pt":1588423717051,"mc":[{"id":"1.170370557","rc":[{"atl":[[2.76,2.02]],"id":9622734}],"con":true,"img":false}]}
{"op":"mcm","clk":"1362034015","pt":1588423717155,"mc":[{"id":"1.170370557","rc":[{"atl":[[2.72,2.12]],"id":9622734}],"con":true,"img":false}]}
{"op":"mcm","clk":"1362034024","pt":1588423717768,"mc":[{"id":"1.170370557","rc":[{"atb":[[2.34,0]],"id":9622734}],"con":true,"img":false}]}
{"op":"mcm","clk":"1362034025","pt":1588423717870,"mc":[{"id":"1.170370557","rc":[{"atb":[[2.42,39.99]],"id":9622734}],"con":true,"img":false}]}
{"op":"mcm","clk":"1362034040","pt":1588423719560,"mc":[{"id":"1.170370557","rc":[{"atb":[[1.6,0]],"id":9624350}],"con":true,"img":false}]}
{"op":"mcm","clk":"1362034042","pt":1588423719765,"mc":[{"id":"1.170370557","rc":[{"atb":[[1.56,2.08]],"id":9624350}],"con":true,"img":false}]}
{"op":"mcm","clk":"1362034044","pt":1588423719869,"mc":[{"id":"1.170370557","rc":[{"atb":[[2.58,0]],"id":9622734},{"atb":[[1.58,89.8]],"id":9624350},{"atl":[[1.64,0]],"id":9624350}],"con":true,"img":false}]}
{"op":"mcm","clk":"1362034047","pt":1588423720026,"mc":[{"id":"1.170370557","rc":[{"atb":[[2.58,2.04]],"id":9622734},{"atl":[[1.64,2.04]],"id":9624350}],"con":true,"img":false}]}
{"op":"mcm","clk":"1362034560","pt":1588423760143,"mc":[{"id":"1.170370557","rc":[{"trd":[[1.59,154.63]],"ltp":1.59,"tv":154.63,"id":9624350},{"atb":[[1.59,0]],"id":9624350},{"atl":[[1.59,16.14]],"id":9624350}],"con":true,"img":false}]}
{"op":"mcm","clk":"1362034564","pt":1588423760348,"mc":[{"id":"1.170370557","rc":[{"atb":[[1.55,2.19]],"id":9624350},{"atl":[[1.62,96.94],[1.61,70.25]],"id":9624350}],"con":true,"img":false}]}
{"op":"mcm","clk":"1362034568","pt":1588423760451,"mc":[{"id":"1.170370557","rc":[{"atb":[[2.58,0]],"id":9622734},{"atl":[[2.76,0]],"id":9622734},{"atb":[[1.57,103.26]],"id":9624350},{"atl":[[1.64,0]],"id":9624350}],"con":true,"img":false}]}
{"op":"mcm","clk":"1362034570","pt":1588423760553,"mc":[{"id":"1.170370557","rc":[{"atb":[[2.64,8.94],[2.62,2.04]],"id":9622734},{"atl":[[2.78,2.18]],"id":9622734}],"con":true,"img":false}]}
{"op":"mcm","clk":"1362034574","pt":1588423760656,"mc":[{"id":"1.170370557","rc":[{"atl":[[2.74,0]],"id":9622734},{"atl":[[1.63,0]],"id":9624350}],"con":true,"img":false}]}
{"op":"mcm","clk":"1362034579","pt":1588423760759,"mc":[{"id":"1.170370557","rc":[{"atb":[[2.56,17.04]],"id":9622734},{"atl":[[2.76,2.02]],"id":9622734},{"atb":[[1.53,0],[1.54,8.46]],"id":9624350}],"con":true,"img":false}]}
{"op":"mcm","clk":"1362034580","pt":1588423760815,"mc":[{"id":"1.170370557","rc":[{"atb":[[2.6,0]],"id":9622734}],"con":true,"img":false}]}
{"op":"mcm","clk":"1362034656","pt":1588423766323,"mc":[{"id":"1.170370557","rc":[{"atb":[[2.42,0]],"id":9622734},{"atb":[[1.45,0]],"id":9624350}],"con":true,"img":false}]}
{"op":"mcm","clk":"1362034664","pt":1588423766629,"mc":[{"id":"1.170370557","rc":[{"atb":[[2.62,0]],"id":9622734},{"atl":[[2.78,0.16]],"id":9622734},{"atb":[[1.55,0]],"id":9624350},{"atl":[[1.62,94.85]],"id":9624350}],"con":true,"img":false}]}
{"op":"mcm","clk":"1362034667","pt":1588423766847,"mc":[{"id":"1.170370557","rc":[{"atb":[[2.62,2.04]],"id":9622734},{"atl":[[2.78,2.18]],"id":9622734},{"atb":[[1.55,2.02]],"id":9624350},{"atl":[[1.62,96.94]],"id":9624350}],"con":true,"img":false}]}
{"op":"mcm","clk":"1362034692","pt":1588423768328,"mc":[{"id":"1.170370557","rc":[{"atb":[[1.45,39.99]],"id":9624350}],"con":true,"img":false}]}
{"op":"mcm","clk":"1362034694","pt":1588423768531,"mc":[{"id":"1.170370557","rc":[{"atb":[[2.42,39.99]],"id":9622734}],"con":true,"img":false}]}
{"op":"mcm","clk":"1362034740","pt":1588423771447,"mc":[{"id":"1.170370557","rc":[{"trd":[[2.72,41.79]],"ltp":2.72,"tv":41.79,"id":9622734},{"atl":[[2.72,0]],"id":9622734},{"trd":[[1.58,301.53]],"ltp":1.58,"tv":301.53,"id":9624350},{"atb":[[1.58,0]],"id":9624350},{"atl":[[1.58,23.33]],"id":9624350}],"con":true,"img":false}]}
{"op":"mcm","clk":"1362034745","pt":1588423771652,"mc":[{"id":"1.170370557","rc":[{"atb":[[2.62,18.45],[2.66,2.02],[2.68,2.11]],"id":9622734},{"atl":[[2.82,12],[2.8,2.02],[2.78,0.16],[2.76,0]],"id":9622734},{"atb":[[1.56,0],[1.54,10.58]],"id":9624350},{"atl":[[1.6,2.01]],"id":9624350}],"con":true,"img":false}]}
{"op":"mcm","clk":"1362034753","pt":1588423771959,"mc":[{"id":"1.170370557","rc":[{"atb":[[2.64,6.87]],"id":9622734},{"atl":[[1.61,68.11]],"id":9624350}],"con":true,"img":false}]}
{"op":"mcm","clk":"1362034758","pt":1588423772163,"mc":[{"id":"1.170370557","rc":[{"atl":[[1.61,70.11]],"id":9624350}],"con":true,"img":false}]}
{"op":"mcm","clk":"1362034765","pt":1588423772430,"mc":[{"id":"1.170370557","rc":[{"atb":[[2.62,16.41]],"id":9622734},{"atl":[[1.62,94.85]],"id":9624350}],"con":true,"img":false}]}
{"op":"mcm","clk":"1362034802","pt":1588423775451,"mc":[{"id":"1.170370557","rc":[{"atb":[[1.54,2.58]],"id":9624350}],"con":true,"img":false}]}
{"op":"mcm","clk":"1362034831","pt":1588423777965,"mc":[{"id":"1.170370557","rc":[{"trd":[[1.57,313.31]],"ltp":1.57,"tv":313.31,"id":9624350},{"atb":[[1.57,0]],"id":9624350},{"atl":[[1.57,25.54]],"id":9624350}],"con":true,"img":false}]}
{"op":"mcm","clk":"1362034833","pt":1588423778173,"mc":[{"id":"1.170370557","rc":[{"atb":[[1.53,2.12],[1.52,68.68]],"id":9624350},{"atl":[[1.59,18.2]],"id":9624350}],"con":true,"img":false}]}
{"op":"mcm","clk":"1362034835","pt":1588423778230,"mc":[{"id":"1.170370557","rc":[{"atb":[[2.66,0]],"id":9622734},{"atl":[[2.82,10]],"id":9622734},{"atb":[[1.55,0],[1.54,0.46]],"id":9624350}],"con":true,"img":false}]}
{"op":"mcm","clk":"1362034838","pt":1588423778441,"mc":[{"id":"1.170370557","rc":[{"atb":[[2.7,2.02]],"id":9622734},{"atl":[[2.86,2.25],[2.84,2.03]],"id":9622734},{"atb":[[1.49,120.12]],"id":9624350}],"con":true,"img":false}]}
{"op":"mcm","clk":"1362034841","pt":1588423778537,"mc":[{"id":"1.170370557","rc":[{"atl":[[2.8,0]],"id":9622734},{"atl":[[1.6,0],[1.61,68.11]],"id":9624350}],"con":true,"img":false}]}
{"op":"mcm","clk":"1362034848","pt":1588423778743,"mc":[{"id":"1.170370557","rc":[{"atb":[[2.52,0],[2.68,0]],"id":9622734},{"atb":[[1.51,0],[1.5,54.96],[1.52,17.54]],"id":9624350}],"con":true,"img":false}]}
{"op":"mcm","clk":"1362034851","pt":1588423778948,"mc":[{"id":"1.170370557","rc":[{"atl":[[2.88,2.04]],"id":9622734},{"atb":[[1.51,2.24]],"id":9624350},{"atl":[[1.6,2.01]],"id":9624350}],"con":true,"img":false}]}
{"op":"mcm","clk":"1362034852","pt":1588423779050,"mc":[{"id":"1.170370557","rc":[{"atl":[[2.84,0]],"id":9622734},{"atb":[[1.53,0]],"id":9624350}],"con":true,"img":false}]}
{"op":"mcm","clk":"1362034854","pt":1588423779151,"mc":[{"id":"1.170370557","rc":[{"atb":[[2.68,2.11]],"id":9622734}],"con":true,"img":false}]}
{"op":"mcm","clk":"1362034864","pt":1588423779661,"mc":[{"id":"1.170370557","rc":[{"atb":[[2.68,17.94]],"id":9622734}],"con":true,"img":false}]}
{"op":"mcm","clk":"1362034879","pt":1588423781044,"mc":[{"id":"1.170370557","rc":[{"atb":[[1.52,2.16]],"id":9624350}],"con":true,"img":false}]}
{"op":"mcm","clk":"1362034880","pt":1588423781146,"mc":[{"id":"1.170370557","rc":[{"atb":[[1.51,17.62]],"id":9624350}],"con":true,"img":false}]}
{"op":"mcm","clk":"1362034884","pt":1588423781761,"mc":[{"id":"1.170370557","rc":[{"atb":[[1.49,174.39]],"id":9624350}],"con":true,"img":false}]}
{"op":"mcm","clk":"1362034886","pt":1588423781864,"mc":[{"id":"1.170370557","rc":[{"atb":[[1.5,1.77]],"id":9624350}],"con":true,"img":false}]}
{"op":"mcm","clk":"1362034933","pt":1588423785759,"mc":[{"id":"1.170370557","rc":[{"atb":[[1.51,2.24]],"id":9624350}],"con":true,"img":false}]}
{"op":"mcm","clk":"1362034935","pt":1588423785862,"mc":[{"id":"1.170370557","rc":[{"atb":[[1.5,17.15]],"id":9624350}],"con":true,"img":false}]}
{"op":"mcm","clk":"1362034936","pt":1588423786066,"mc":[{"id":"1.170370557","rc":[{"atb":[[2.68,15.83]],"id":9622734},{"atl":[[2.88,0]],"id":9622734},{"atb":[[1.51,0]],"id":9624350},{"atl":[[1.6,0]],"id":9624350}],"con":true,"img":false}]}
{"op":"mcm","clk":"1362034938","pt":1588423786269,"mc":[{"id":"1.170370557","rc":[{"atb":[[2.68,17.85]],"id":9622734},{"atl":[[2.88,2.04]],"id":9622734},{"atb":[[1.51,2.06]],"id":9624350},{"atl":[[1.6,2.01]],"id":9624350}],"con":true,"img":false}]}
{"op":"mcm","clk":"1362035131","pt":1588423803567,"mc":[{"id":"1.170370557","rc":[{"atb":[[1.49,54.27]],"id":9624350}],"con":true,"img":false}]}
{"op":"mcm","clk":"1362035138","pt":1588423803873,"mc":[{"id":"1.170370557","rc":[{"atb":[[2.68,15.83]],"id":9622734},{"atl":[[2.88,0]],"id":9622734},{"atb":[[1.51,0]],"id":9624350},{"atl":[[1.6,0]],"id":9624350}],"con":true,"img":false}]}
{"op":"mcm","clk":"1362035140","pt":1588423804079,"mc":[{"id":"1.170370557","rc":[{"atb":[[2.68,17.94]],"id":9622734},{"atl":[[2.88,2.04]],"id":9622734},{"atb":[[1.51,2.14]],"id":9624350},{"atl":[[1.6,2.01]],"id":9624350}],"con":true,"img":false}]}
{"op":"mcm","clk":"1362035442","pt":1588423826996,"mc":[{"id":"1.170370557","rc":[{"atb":[[2.42,0]],"id":9622734},{"atb":[[1.45,0]],"id":9624350}],"con":true,"img":false}]}
{"op":"mcm","clk":"1362035446","pt":1588423827199,"mc":[{"id":"1.170370557","rc":[{"atb":[[2.68,15.83]],"id":9622734},{"atl":[[2.88,0]],"id":9622734},{"atb":[[1.51,0]],"id":9624350},{"atl":[[1.6,0]],"id":9624350}],"con":true,"img":false}]}
{"op":"mcm","clk":"1362035451","pt":1588423827403,"mc":[{"id":"1.170370557","rc":[{"atb":[[2.68,17.85]],"id":9622734},{"atl":[[2.88,2.03]],"id":9622734},{"atb":[[1.51,2.32]],"id":9624350},{"atl":[[1.6,2.01]],"id":9624350}],"con":true,"img":false}]}
{"op":"mcm","clk":"1362035458","pt":1588423828017,"mc":[{"id":"1.170370557","rc":[{"atb":[[1.45,39.99]],"id":9624350}],"con":true,"img":false}]}
{"op":"mcm","clk":"1362035461","pt":1588423828221,"mc":[{"id":"1.170370557","rc":[{"atb":[[2.42,39.99]],"id":9622734}],"con":true,"img":false}]}
{"op":"mcm","clk":"1362035505","pt":1588423831602,"mc":[{"id":"1.170370557","rc":[{"atb":[[2.74,2.1]],"id":9622734}],"con":true,"img":false}]}
{"op":"mcm","clk":"1362035638","pt":1588423840825,"mc":[{"id":"1.170370557","rc":[{"atl":[[1.58,0]],"id":9624350}],"con":true,"img":false}]}
{"op":"mcm","clk":"1362035646","pt":1588423841234,"mc":[{"id":"1.170370557","rc":[{"atb":[[2.68,15.83]],"id":9622734},{"atl":[[2.88,0]],"id":9622734},{"atb":[[1.51,0]],"id":9624350},{"atl":[[1.6,0],[1.7,0]],"id":9624350}],"con":true,"img":false}]}
{"op":"mcm","clk":"1362035651","pt":1588423841439,"mc":[{"id":"1.170370557","rc":[{"atb":[[2.68,17.94]],"id":9622734},{"atl":[[2.88,2.04]],"id":9622734},{"atb":[[1.51,2]],"id":9624350},{"atl":[[1.6,2.01]],"id":9624350}],"con":true,"img":false}]}
{"op":"mcm","clk":"1362035656","pt":1588423841802,"mc":[{"id":"1.170370557","rc":[{"atl":[[1.57,0]],"id":9624350}],"con":true,"img":false}]}
{"op":"mcm","clk":"1362035660","pt":1588423841905,"mc":[{"id":"1.170370557","rc":[{"atl":[[1.62,97.1],[1.61,70.12]],"id":9624350}],"con":true,"img":false}]}
{"op":"mcm","clk":"1362035664","pt":1588423842106,"mc":[{"id":"1.170370557","rc":[{"atl":[[1.59,16.14],[1.6,0]],"id":9624350}],"con":true,"img":false}]}
{"op":"mcm","clk":"1362035666","pt":1588423842211,"mc":[{"id":"1.170370557","rc":[{"atl":[[1.6,2.01]],"id":9624350}],"con":true,"img":false}]}
{"op":"mcm","clk":"1362035671","pt":1588423842618,"mc":[{"id":"1.170370557","rc":[{"atl":[[1.59,0]],"id":9624350}],"con":true,"img":false}]}
{"op":"mcm","clk":"1362035673","pt":1588423842721,"mc":[{"id":"1.170370557","rc":[{"atb":[[2.66,16.01],[2.68,2.11]],"id":9622734},{"atb":[[1.5,70.34]],"id":9624350}],"con":true,"img":false}]}
{"op":"mcm","clk":"1362035692","pt":1588423843744,"mc":[{"id":"1.170370557","rc":[{"atb":[[2.64,23.09]],"id":9622734}],"con":true,"img":false}]}
{"op":"mcm","clk":"1362035694","pt":1588423843846,"mc":[{"id":"1.170370557","rc":[{"atb":[[2.66,0]],"id":9622734}],"con":true,"img":false}]}
{"op":"mcm","clk":"1362036033","pt":1588423867352,"mc":[{"id":"1.170370557","rc":[{"atb":[[1.57,11.99]],"id":9624350}],"con":true,"img":false}]}
{"op":"mcm","clk":"1362036037","pt":1588423867560,"mc":[{"id":"1.170370557","rc":[{"atb":[[1.55,2.08],[1.54,2.58]],"id":9624350}],"con":true,"img":false}]}
{"op":"mcm","clk":"1362036040","pt":1588423867661,"mc":[{"id":"1.170370557","rc":[{"atb":[[2.68,0]],"id":9622734},{"atl":[[2.88,0]],"id":9622734},{"atb":[[1.51,0],[1.52,53.3]],"id":9624350},{"atl":[[1.62,94.85],[1.61,68.11]],"id":9624350}],"con":true,"img":false}]}
{"op":"mcm","clk":"1362036044","pt":1588423867866,"mc":[{"id":"1.170370557","rc":[{"atb":[[2.64,6.87],[2.68,2.11]],"id":9622734},{"atl":[[2.82,12.25],[2.8,2.02]],"id":9622734},{"atl":[[1.61,70.25]],"id":9624350}],"con":true,"img":false}]}
{"op":"mcm","clk":"1362036046","pt":1588423867968,"mc":[{"id":"1.170370557","rc":[{"atb":[[1.52,51.14]],"id":9624350}],"con":true,"img":false}]}
{"op":"mcm","clk":"1362036051","pt":1588423868275,"mc":[{"id":"1.170370557","rc":[{"atl":[[2.86,0]],"id":9622734}],"con":true,"img":false}]}
{"op":"mcm","clk":"1362036059","pt":1588423868738,"mc":[{"id":"1.170370557","rc":[{"atb":[[2.6,16.62],[2.62,0]],"id":9622734}],"con":true,"img":false}]}
{"op":"mcm","clk":"1362036076","pt":1588423870069,"mc":[{"id":"1.170370557","rc":[{"atb":[[1.57,0]],"id":9624350}],"con":true,"img":false}]}
{"op":"mcm","clk":"1362036079","pt":1588423870275,"mc":[{"id":"1.170370557","rc":[{"atb":[[1.53,2.16],[1.52,53.14]],"id":9624350}],"con":true,"img":false}]}
{"op":"mcm","clk":"1362036083","pt":1588423870376,"mc":[{"id":"1.170370557","rc":[{"atb":[[1.55,0],[1.54,0.46]],"id":9624350}],"con":true,"img":false}]}
{"op":"mcm","clk":"1362036084","pt":1588423870478,"mc":[{"id":"1.170370557","rc":[{"atl":[[2.86,2.03],[2.84,2.03]],"id":9622734}],"con":true,"img":false}]}
{"op":"mcm","clk":"1362036091","pt":1588423870684,"mc":[{"id":"1.170370557","rc":[{"atl":[[2.8,0],[2.82,10]],"id":9622734}],"con":true,"img":false}]}
{"op":"mcm","clk":"1362036093","pt":1588423870751,"mc":[{"id":"1.170370557","rc":[{"atb":[[2.62,16.41]],"id":9622734}],"con":true,"img":false}]}
{"op":"mcm","clk":"1362036094","pt":1588423870850,"mc":[{"id":"1.170370557","rc":[{"atl":[[2.88,2.04]],"id":9622734}],"con":true,"img":false}]}
{"op":"mcm","clk":"1362036095","pt":1588423870945,"mc":[{"id":"1.170370557","rc":[{"atl":[[2.84,0]],"id":9622734}],"con":true,"img":false}]}
{"op":"mcm","clk":"1362036096","pt":1588423871149,"mc":[{"id":"1.170370557","rc":[{"atb":[[1.51,2.36]],"id":9624350}],"con":true,"img":false}]}
{"op":"mcm","clk":"1362036098","pt":1588423871251,"mc":[{"id":"1.170370557","rc":[{"atb":[[1.53,0]],"id":9624350}],"con":true,"img":false}]}
{"op":"mcm","clk":"1362036102","pt":1588423871764,"mc":[{"id":"1.170370557","rc":[{"atb":[[2.54,0]],"id":9622734},{"atb":[[1.52,2]],"id":9624350}],"con":true,"img":false}]}
{"op":"mcm","clk":"1362036118","pt":1588423872741,"mc":[{"id":"1.170370557","rc":[{"atb":[[2.64,23.09]],"id":9622734}],"con":true,"img":false}]}
{"op":"mcm","clk":"1362036306","pt":1588423887574,"mc":[{"id":"1.170370557","rc":[{"atb":[[2.42,0]],"id":9622734},{"atb":[[1.45,0]],"id":9624350}],"con":true,"img":false}]}
{"op":"mcm","clk":"1362036314","pt":1588423887881,"mc":[{"id":"1.170370557","rc":[{"atb":[[2.68,0]],"id":9622734},{"atl":[[2.88,0]],"id":9622734},{"atb":[[1.51,0]],"id":9624350},{"atl":[[1.61,68.11]],"id":9624350}],"con":true,"img":false}]}
{"op":"mcm","clk":"1362036321","pt":1588423888189,"mc":[{"id":"1.170370557","rc":[{"atb":[[2.68,2.08]],"id":9622734},{"atl":[[2.88,2.04]],"id":9622734},{"atb":[[1.51,2]],"id":9624350},{"atl":[[1.61,70.25]],"id":9624350}],"con":true,"img":false}]}
{"op":"mcm","clk":"1362036396","pt":1588423893809,"mc":[{"id":"1.170370557","rc":[{"trd":[[2.74,2.21]],"ltp":2.74,"tv":2.21,"id":9622734},{"atb":[[2.74,0]],"id":9622734},{"trd":[[1.58,305.19]],"ltp":1.58,"tv":305.19,"id":9624350},{"atb":[[1.58,5.94]],"id":9624350}],"con":true,"img":false}]}
{"op":"mcm","clk":"1362036399","pt":1588423893966,"mc":[{"id":"1.170370557","rc":[{"atb":[[2.66,2]],"id":9622734},{"atb":[[1.56,2.08],[1.55,2.08]],"id":9624350},{"atl":[[1.62,96.94]],"id":9624350}],"con":true,"img":false}]}
{"op":"mcm","clk":"1362036402","pt":1588423894069,"mc":[{"id":"1.170370557","rc":[{"atb":[[2.7,0]],"id":9622734},{"atl":[[1.6,0]],"id":9624350}],"con":true,"img":false}]}
{"op":"mcm","clk":"1362036405","pt":1588423894170,"mc":[{"id":"1.170370557","rc":[{"atb":[[2.64,25.16]],"id":9622734},{"atl":[[2.8,2],[2.78,2.18]],"id":9622734}],"con":true,"img":false}]}
{"op":"mcm","clk":"1362036408","pt":1588423894273,"mc":[{"id":"1.170370557","rc":[{"atb":[[2.68,0]],"id":9622734},{"atb":[[1.52,0]],"id":9624350}],"con":true,"img":false}]}
{"op":"mcm","clk":"1362036409","pt":1588423894374,"mc":[{"id":"1.170370557","rc":[{"atb":[[2.62,18.45]],"id":9622734},{"atl":[[1.63,2.04]],"id":9624350}],"con":true,"img":false}]}
{"op":"mcm","clk":"1362036412","pt":1588423894578,"mc":[{"id":"1.170370557","rc":[{"atb":[[2.66,0]],"id":9622734},{"atl":[[2.88,0],[2.86,0]],"id":9622734},{"atb":[[1.51,0]],"id":9624350},{"atl":[[1.61,68.11]],"id":9624350}],"con":true,"img":false}]}
{"op":"mcm","clk":"1362036415","pt":1588423894682,"mc":[{"id":"1.170370557","rc":[{"atb":[[2.6,18.66]],"id":9622734},{"atb":[[1.52,51.14]],"id":9624350},{"atl":[[1.64,2.18]],"id":9624350}],"con":true,"img":false}]}
{"op":"mcm","clk":"1362036419","pt":1588423894886,"mc":[{"id":"1.170370557","rc":[{"atb":[[2.64,6.87],[2.62,2.04]],"id":9622734},{"atl":[[1.62,94.85]],"id":9624350}],"con":true,"img":false}]}
{"op":"mcm","clk":"1362036421","pt":1588423894988,"mc":[{"id":"1.170370557","rc":[{"atb":[[2.58,2.06]],"id":9622734}],"con":true,"img":false}]}
{"op":"mcm","clk":"1362036424","pt":1588423895091,"mc":[{"id":"1.170370557","rc":[{"atb":[[2.62,0]],"id":9622734}],"con":true,"img":false}]}
{"op":"mcm","clk":"1362036436","pt":1588423895708,"mc":[{"id":"1.170370557","rc":[{"atb":[[2.58,18.89]],"id":9622734}],"con":true,"img":false}]}
{"op":"mcm","clk":"1362036439","pt":1588423895865,"mc":[{"id":"1.170370557","rc":[{"atb":[[2.6,2.04]],"id":9622734}],"con":true,"img":false}]}
{"op":"mcm","clk":"1362036447","pt":1588423896377,"mc":[{"id":"1.170370557","rc":[{"atb":[[1.45,39.99]],"id":9624350}],"con":true,"img":false}]}
{"op":"mcm","clk":"1362036452","pt":1588423896582,"mc":[{"id":"1.170370557","rc":[{"atb":[[2.42,39.99]],"id":9622734}],"con":true,"img":false}]}
{"op":"mcm","clk":"1362036549","pt":1588423904021,"mc":[{"id":"1.170370557","rc":[{"atb":[[1.58,0]],"id":9624350}],"con":true,"img":false}]}
{"op":"mcm","clk":"1362036553","pt":1588423904226,"mc":[{"id":"1.170370557","rc":[{"atb":[[1.53,2.16],[1.54,2.54]],"id":9624350}],"con":true,"img":false}]}
{"op":"mcm","clk":"1362036557","pt":1588423904381,"mc":[{"id":"1.170370557","rc":[{"atb":[[2.58,16.83]],"id":9622734},{"atl":[[2.8,0]],"id":9622734},{"atb":[[1.56,0],[1.55,0]],"id":9624350},{"atl":[[1.64,0]],"id":9624350}],"con":true,"img":false}]}
{"op":"mcm","clk":"1362036559","pt":1588423904587,"mc":[{"id":"1.170370557","rc":[{"atb":[[2.58,18.89]],"id":9622734},{"atl":[[2.82,12.08],[2.84,2.03]],"id":9622734},{"atl":[[1.64,2.18]],"id":9624350}],"con":true,"img":false}]}
{"op":"mcm","clk":"1362036562","pt":1588423904688,"mc":[{"id":"1.170370557","rc":[{"atb":[[2.62,16.41]],"id":9622734},{"atl":[[2.78,0.16]],"id":9622734}],"con":true,"img":false}]}
{"op":"mcm","clk":"1362036564","pt":1588423904893,"mc":[{"id":"1.170370557","rc":[{"atl":[[2.88,2.04],[2.86,2.02]],"id":9622734},{"atb":[[1.52,0]],"id":9624350}],"con":true,"img":false}]}
{"op":"mcm","clk":"1362036566","pt":1588423904996,"mc":[{"id":"1.170370557","rc":[{"atl":[[2.82,10],[2.84,0]],"id":9622734}],"con":true,"img":false}]}
{"op":"mcm","clk":"1362036569","pt":1588423905098,"mc":[{"id":"1.170370557","rc":[{"atb":[[1.51,2.24],[1.52,2.24]],"id":9624350}],"con":true,"img":false}]}
{"op":"mcm","clk":"1362036571","pt":1588423905200,"mc":[{"id":"1.170370557","rc":[{"atb":[[1.53,0],[1.54,0.46]],"id":9624350}],"con":true,"img":false}]}
{"op":"mcm","clk":"1362036577","pt":1588423905405,"mc":[{"id":"1.170370557","rc":[{"atb":[[1.5,72.34],[1.49,56.28]],"id":9624350}],"con":true,"img":false}]}
{"op":"mcm","clk":"1362036580","pt":1588423905509,"mc":[{"id":"1.170370557","rc":[{"atb":[[1.51,0],[1.52,0]],"id":9624350}],"con":true,"img":false}]}
{"op":"mcm","clk":"1362036583","pt":1588423905713,"mc":[{"id":"1.170370557","rc":[{"atb":[[1.51,2.02],[1.52,2.02]],"id":9624350}],"con":true,"img":false}]}
{"op":"mcm","clk":"1362036962","pt":1588423931962,"mc":[{"id":"1.170370557","rc":[{"atl":[[1.7,191.96]],"id":9624350}],"con":true,"img":false}]}
{"op":"mcm","clk":"1362036969","pt":1588423932370,"mc":[{"id":"1.170370557","rc":[{"atb":[[2.58,16.83]],"id":9622734},{"atl":[[2.88,0]],"id":9622734},{"atb":[[1.51,0],[1.5,70.34],[1.49,54.27]],"id":9624350},{"atl":[[1.64,0]],"id":9624350}],"con":true,"img":false}]}
{"op":"mcm","clk":"1362036974","pt":1588423932575,"mc":[{"id":"1.170370557","rc":[{"atb":[[2.58,18.89]],"id":9622734},{"atl":[[2.88,2.04]],"id":9622734},{"atb":[[1.51,2]],"id":9624350},{"atl":[[1.64,2.18]],"id":9624350}],"con":true,"img":false}]}
{"op":"mcm","clk":"1362037147","pt":1588423944187,"mc":[{"id":"1.170370557","rc":[{"atl":[[2.78,2.28]],"id":9622734}],"con":true,"img":false}]}
{"op":"mcm","clk":"1362037149","pt":1588423944391,"mc":[{"id":"1.170370557","rc":[{"atl":[[2.82,12.08],[2.84,2.03]],"id":9622734}],"con":true,"img":false}]}
{"op":"mcm","clk":"1362037151","pt":1588423944494,"mc":[{"id":"1.170370557","rc":[{"atb":[[2.58,16.83]],"id":9622734},{"atl":[[2.88,0]],"id":9622734},{"atb":[[1.51,0]],"id":9624350},{"atl":[[1.64,0]],"id":9624350}],"con":true,"img":false}]}
{"op":"mcm","clk":"1362037154","pt":1588423944650,"mc":[{"id":"1.170370557","rc":[{"atb":[[2.58,18.89]],"id":9622734},{"atb":[[1.53,2],[1.54,2.56]],"id":9624350},{"atl":[[1.64,2.18]],"id":9624350}],"con":true,"img":false}]}
{"op":"mcm","clk":"1362037156","pt":1588423944751,"mc":[{"id":"1.170370557","rc":[{"atb":[[2.6,18.66]],"id":9622734},{"atl":[[2.86,0]],"id":9622734},{"atb":[[1.52,53.16]],"id":9624350}],"con":true,"img":false}]}
{"op":"mcm","clk":"1362037158","pt":1588423944857,"mc":[{"id":"1.170370557","rc":[{"atb":[[2.62,0]],"id":9622734}],"con":true,"img":false}]}
{"op":"mcm","clk":"1362037161","pt":1588423945058,"mc":[{"id":"1.170370557","rc":[{"atb":[[1.52,51.14]],"id":9624350}],"con":true,"img":false}]}
{"op":"mcm","clk":"1362037172","pt":1588423945879,"mc":[{"id":"1.170370557","rc":[{"atb":[[2.6,2.04]],"id":9622734}],"con":true,"img":false}]}
{"op":"mcm","clk":"1362037207","pt":1588423948192,"mc":[{"id":"1.170370557","rc":[{"atb":[[2.42,0]],"id":9622734},{"atb":[[1.45,0]],"id":9624350}],"con":true,"img":false}]}
{"op":"mcm","clk":"1362037339","pt":1588423956391,"mc":[{"id":"1.170370557","rc":[{"atb":[[1.45,39.99]],"id":9624350}],"con":true,"img":false}]}
{"op":"mcm","clk":"1362037342","pt":1588423956581,"mc":[{"id":"1.170370557","rc":[{"atb":[[2.42,39.99]],"id":9622734}],"con":true,"img":false}]}
{"op":"mcm","clk":"1362037344","pt":1588423956684,"mc":[{"id":"1.170370557","rc":[{"atb":[[2.58,16.83]],"id":9622734},{"atl":[[2.84,0]],"id":9622734},{"atb":[[1.53,0]],"id":9624350},{"atl":[[1.64,0]],"id":9624350}],"con":true,"img":false}]}
{"op":"mcm","clk":"1362037347","pt":1588423956891,"mc":[{"id":"1.170370557","rc":[{"atb":[[2.58,18.89]],"id":9622734},{"atl":[[2.84,2]],"id":9622734},{"atb":[[1.53,2.16]],"id":9624350},{"atl":[[1.64,2.04]],"id":9624350}],"con":true,"img":false}]}
{"op":"mcm","clk":"1362037364","pt":1588423957809,"mc":[{"id":"1.170370557","rc":[{"atb":[[2.6,18.66]],"id":9622734}],"con":true,"img":false}]}
{"op":"mcm","clk":"1362038177","pt":1588424008750,"mc":[{"id":"1.170370557","rc":[{"atb":[[2.42,0]],"id":9622734},{"atb":[[1.45,0]],"id":9624350}],"con":true,"img":false}]}
{"op":"mcm","clk":"1362038182","pt":1588424008960,"mc":[{"id":"1.170370557","rc":[{"atb":[[2.58,16.83]],"id":9622734},{"atb":[[1.53,0]],"id":9624350},{"atl":[[1.64,0]],"id":9624350}],"con":true,"img":false}]}
{"op":"mcm","clk":"1362038185","pt":1588424009062,"mc":[{"id":"1.170370557","rc":[{"atl":[[2.84,0]],"id":9622734}],"con":true,"img":false}]}
{"op":"mcm","clk":"1362038188","pt":1588424009269,"mc":[{"id":"1.170370557","rc":[{"atb":[[2.58,18.89]],"id":9622734},{"atl":[[2.84,2.03]],"id":9622734},{"atb":[[1.53,2.16]],"id":9624350},{"atl":[[1.64,2.18]],"id":9624350}],"con":true,"img":false}]}
{"op":"mcm","clk":"1362038205","pt":1588424009883,"mc":[{"id":"1.170370557","rc":[{"atb":[[2.6,2.04]],"id":9622734}],"con":true,"img":false}]}
{"op":"mcm","clk":"1362038321","pt":1588424017004,"mc":[{"id":"1.170370557","rc":[{"atb":[[1.55,26.24]],"id":9624350}],"con":true,"img":false}]}
{"op":"mcm","clk":"1362038329","pt":1588424017312,"mc":[{"id":"1.170370557","rc":[{"atb":[[2.58,16.83]],"id":9622734},{"atl":[[2.84,0]],"id":9622734},{"atb":[[1.53,0]],"id":9624350},{"atl":[[1.64,0]],"id":9624350}],"con":true,"img":false}]}
{"op":"mcm","clk":"1362038335","pt":1588424017470,"mc":[{"id":"1.170370557","rc":[{"atb":[[2.58,18.89]],"id":9622734},{"atl":[[2.84,2.01]],"id":9622734},{"atb":[[1.53,2.08]],"id":9624350},{"atl":[[1.64,2.04]],"id":9624350}],"con":true,"img":false}]}
{"op":"mcm","clk":"1362038728","pt":1588424044132,"mc":[{"id":"1.170370557","rc":[{"trd":[[2.78,2.28]],"ltp":2.78,"tv":2.28,"id":9622734},{"atl":[[2.78,0]],"id":9622734},{"trd":[[1.55,26.56],[1.56,4.07]],"ltp":1.55,"tv":30.63,"id":9624350},{"atb":[[1.55,21.45]],"id":9624350}],"con":true,"img":false}]}
{"op":"mcm","clk":"1362038732","pt":1588424044337,"mc":[{"id":"1.170370557","rc":[{"atl":[[2.88,2.04],[2.86,2.25]],"id":9622734}],"con":true,"img":false}]}
{"op":"mcm","clk":"1362038736","pt":1588424044439,"mc":[{"id":"1.170370557","rc":[{"atb":[[2.58,16.83]],"id":9622734},{"atl":[[2.82,10],[2.84,0]],"id":9622734},{"atb":[[1.53,0]],"id":9624350},{"atl":[[1.64,0]],"id":9624350}],"con":true,"img":false}]}
{"op":"mcm","clk":"1362038741","pt":1588424044645,"mc":[{"id":"1.170370557","rc":[{"atb":[[1.52,53.22]],"id":9624350}],"con":true,"img":false}]}
{"op":"mcm","clk":"1362038743","pt":1588424044748,"mc":[{"id":"1.170370557","rc":[{"atb":[[1.54,0.46]],"id":9624350}],"con":true,"img":false}]}
{"op":"mcm","clk":"1362038745","pt":1588424044852,"mc":[{"id":"1.170370557","rc":[{"atb":[[2.58,18.89]],"id":9622734},{"atb":[[1.53,2.16]],"id":9624350},{"atl":[[1.64,2.04]],"id":9624350}],"con":true,"img":false}]}
{"op":"mcm","clk":"1362038804","pt":1588424048698,"mc":[{"id":"1.170370557","marketDefinition":{"bspMarket":false,"turnInPlayEnabled":true,"persistenceEnabled":true,"marketBaseRate":5.0,"eventId":"29788106","eventTypeId":"2","numberOfWinners":1,"bettingType":"ODDS","marketType":"MATCH_ODDS","marketTime":"2020-05-02T13:00:00.000Z","suspendTime":"2020-05-02T13:00:00.000Z","bspReconciled":false,"complete":true,"inPlay":false,"crossMatching":true,"runnersVoidable":false,"numberOfActiveRunners":2,"betDelay":0,"status":"OPEN","runners":[{"status":"ACTIVE","sortPriority":1,"id":9624350,"name":"Y Hanfmann"},{"status":"ACTIVE","sortPriority":2,"id":9622734,"name":"D Brown"}],"regulators":["MR_INT"],"countryCode":"GB","discountAllowed":true,"timezone":"GMT","openDate":"2020-05-02T12:55:00.000Z","version":3237542456,"name":"Match Odds","eventName":"Y Hanfmann v D Brown"},"rc":[],"con":true,"img":false}]}
{"op":"mcm","clk":"1362038846","pt":1588424051702,"mc":[{"id":"1.170370557","marketDefinition":{"bspMarket":false,"turnInPlayEnabled":true,"persistenceEnabled":true,"marketBaseRate":5.0,"eventId":"29788106","eventTypeId":"2","numberOfWinners":1,"bettingType":"ODDS","marketType":"MATCH_ODDS","marketTime":"2020-05-02T13:00:00.000Z","suspendTime":"2020-05-02T13:00:00.000Z","bspReconciled":false,"complete":true,"inPlay":false,"crossMatching":true,"runnersVoidable":false,"numberOfActiveRunners":2,"betDelay":0,"status":"OPEN","runners":[{"status":"ACTIVE","sortPriority":1,"id":9624350,"name":"Y Hanfmann"},{"status":"ACTIVE","sortPriority":2,"id":9622734,"name":"D Brown"}],"regulators":["MR_INT"],"countryCode":"GB","discountAllowed":true,"timezone":"GMT","openDate":"2020-05-02T13:00:00.000Z","version":3237542456,"name":"Match Odds","eventName":"Y Hanfmann v D Brown"},"rc":[],"con":true,"img":false}]}
{"op":"mcm","clk":"1362038993","pt":1588424061039,"mc":[{"id":"1.170370557","rc":[{"atb":[[2.64,9.12]],"id":9622734}],"con":true,"img":false}]}
{"op":"mcm","clk":"1362038997","pt":1588424061448,"mc":[{"id":"1.170370557","rc":[{"atb":[[2.58,16.83]],"id":9622734},{"atl":[[2.88,0]],"id":9622734},{"atb":[[1.52,51.14]],"id":9624350},{"atl":[[1.64,0]],"id":9624350}],"con":true,"img":false}]}
{"op":"mcm","clk":"1362039000","pt":1588424061652,"mc":[{"id":"1.170370557","rc":[{"atb":[[2.58,18.89]],"id":9622734},{"atl":[[2.88,2.04]],"id":9622734},{"atb":[[1.52,53.38]],"id":9624350},{"atl":[[1.64,2.18]],"id":9624350}],"con":true,"img":false}]}
{"op":"mcm","clk":"1362039973","pt":1588424126134,"mc":[{"id":"1.170370557","rc":[{"atl":[[1.6,10.49]],"id":9624350}],"con":true,"img":false}]}
{"op":"mcm","clk":"1362039977","pt":1588424126291,"mc":[{"id":"1.170370557","rc":[{"atl":[[1.62,96.94]],"id":9624350}],"con":true,"img":false}]}
{"op":"mcm","clk":"1362039980","pt":1588424126497,"mc":[{"id":"1.170370557","rc":[{"atb":[[2.58,16.83]],"id":9622734},{"atl":[[2.88,0]],"id":9622734},{"atb":[[1.52,51.14]],"id":9624350},{"atl":[[1.64,0]],"id":9624350}],"con":true,"img":false}]}
{"op":"mcm","clk":"1362039983","pt":1588424126701,"mc":[{"id":"1.170370557","rc":[{"atb":[[2.62,2.04]],"id":9622734}],"con":true,"img":false}]}
{"op":"mcm","clk":"1362039987","pt":1588424126804,"mc":[{"id":"1.170370557","rc":[{"atb":[[2.6,18.66]],"id":9622734},{"atl":[[1.63,0]],"id":9624350}],"con":true,"img":false}]}
{"op":"mcm","clk":"1362039990","pt":1588424126907,"mc":[{"id":"1.170370557","rc":[{"atl":[[2.88,2.04]],"id":9622734},{"atb":[[1.52,53.28]],"id":9624350}],"con":true,"img":false}]}
{"op":"mcm","clk":"1362039992","pt":1588424127010,"mc":[{"id":"1.170370557","rc":[{"atb":[[2.6,16.62]],"id":9622734}],"con":true,"img":false}]}
{"op":"mcm","clk":"1362039994","pt":1588424127111,"mc":[{"id":"1.170370557","rc":[{"atl":[[1.63,2.04]],"id":9624350}],"con":true,"img":false}]}
{"op":"mcm","clk":"1362039996","pt":1588424127213,"mc":[{"id":"1.170370557","rc":[{"atb":[[2.6,18.66]],"id":9622734}],"con":true,"img":false}]}
{"op":"mcm","clk":"1362040764","pt":1588424173458,"mc":[{"id":"1.170370557","rc":[{"atb":[[2.64,6.87]],"id":9622734}],"con":true,"img":false}]}
{"op":"mcm","clk":"1362040773","pt":1588424173763,"mc":[{"id":"1.170370557","rc":[{"atb":[[2.6,16.62]],"id":9622734},{"atl":[[2.88,0]],"id":9622734},{"atb":[[1.52,51.14]],"id":9624350},{"atl":[[1.63,0]],"id":9624350}],"con":true,"img":false}]}
{"op":"mcm","clk":"1362040778","pt":1588424173967,"mc":[{"id":"1.170370557","rc":[{"atb":[[2.6,18.66]],"id":9622734},{"atl":[[2.88,2.04]],"id":9622734},{"atb":[[1.52,53.38]],"id":9624350},{"atl":[[1.63,2.04]],"id":9624350}],"con":true,"img":false}]}
{"op":"mcm","clk":"1362040892","pt":1588424181935,"mc":[{"id":"1.170370557","rc":[{"atb":[[2.66,2.22]],"id":9622734}],"con":true,"img":false}]}
{"op":"mcm","clk":"1362040897","pt":1588424182140,"mc":[{"id":"1.170370557","rc":[{"atb":[[2.6,16.62]],"id":9622734},{"atl":[[2.88,0]],"id":9622734},{"atb":[[1.52,51.14]],"id":9624350},{"atl":[[1.63,0]],"id":9624350}],"con":true,"img":false}]}
{"op":"mcm","clk":"1362040904","pt":1588424182343,"mc":[{"id":"1.170370557","rc":[{"atb":[[2.6,18.66]],"id":9622734},{"atl":[[2.88,2.04]],"id":9622734},{"atb":[[1.52,53.2]],"id":9624350},{"atl":[[1.63,2.04]],"id":9624350}],"con":true,"img":false}]}
{"op":"mcm","clk":"1362041468","pt":1588424219103,"mc":[{"id":"1.170370557","rc":[{"trd":[[1.55,61.54]],"ltp":1.55,"tv":61.54,"id":9624350},{"atb":[[1.55,3.96]],"id":9624350}],"con":true,"img":false}]}
{"op":"mcm","clk":"1362041471","pt":1588424219310,"mc":[{"id":"1.170370557","rc":[{"atb":[[2.6,16.62]],"id":9622734},{"atl":[[2.88,0]],"id":9622734},{"atb":[[1.52,51.14]],"id":9624350},{"atl":[[1.63,0]],"id":9624350}],"con":true,"img":false}]}
{"op":"mcm","clk":"1362041475","pt":1588424219512,"mc":[{"id":"1.170370557","rc":[{"atb":[[2.6,18.66]],"id":9622734},{"atl":[[2.88,2.04]],"id":9622734},{"atb":[[1.52,53.38]],"id":9624350},{"atl":[[1.63,2.04]],"id":9624350}],"con":true,"img":false}]}
{"op":"mcm","clk":"1362041479","pt":1588424219819,"mc":[{"id":"1.170370557","rc":[{"atb":[[2.62,18.45]],"id":9622734}],"con":true,"img":false}]}
{"op":"mcm","clk":"1362042412","pt":1588424286680,"mc":[{"id":"1.170370557","rc":[{"atb":[[2.26,12.69]],"id":9622734}],"con":true,"img":false}]}
{"op":"mcm","clk":"1362042417","pt":1588424286988,"mc":[{"id":"1.170370557","rc":[{"atb":[[2.6,16.62]],"id":9622734},{"atl":[[2.88,0]],"id":9622734},{"atb":[[1.52,51.14]],"id":9624350},{"atl":[[1.63,0]],"id":9624350}],"con":true,"img":false}]}
{"op":"mcm","clk":"1362042420","pt":1588424287194,"mc":[{"id":"1.170370557","rc":[{"atb":[[2.6,18.66]],"id":9622734},{"atl":[[2.88,2.04]],"id":9622734},{"atb":[[1.52,53.14]],"id":9624350},{"atl":[[1.63,2.04]],"id":9624350}],"con":true,"img":false}]}
{"op":"mcm","clk":"1362042877","pt":1588424319442,"mc":[{"id":"1.170370557","rc":[{"atb":[[2.6,16.62]],"id":9622734},{"atl":[[2.88,0]],"id":9622734},{"atb":[[1.52,51.14]],"id":9624350},{"atl":[[1.63,0]],"id":9624350}],"con":true,"img":false}]}
{"op":"mcm","clk":"1362042882","pt":1588424319654,"mc":[{"id":"1.170370557","rc":[{"atb":[[2.6,18.66]],"id":9622734},{"atl":[[2.88,2.01]],"id":9622734},{"atb":[[1.52,53.38]],"id":9624350},{"atl":[[1.63,2.04]],"id":9624350}],"con":true,"img":false}]}
{"op":"mcm","clk":"1362042888","pt":1588424320053,"mc":[{"id":"1.170370557","rc":[{"atb":[[2.56,0]],"id":9622734},{"atb":[[1.52,2.24]],"id":9624350}],"con":true,"img":false}]}
{"op":"mcm","clk":"1362042902","pt":1588424320919,"mc":[{"id":"1.170370557","rc":[{"atb":[[1.52,53.38]],"id":9624350}],"con":true,"img":false}]}
{"op":"mcm","clk":"1362043082","pt":1588424332779,"mc":[{"id":"1.170370557","rc":[{"atb":[[1.53,0]],"id":9624350}],"con":true,"img":false}]}
{"op":"mcm","clk":"1362043084","pt":1588424332830,"mc":[{"id":"1.170370557","rc":[{"atb":[[2.62,16.41]],"id":9622734}],"con":true,"img":false}]}
{"op":"mcm","clk":"1362043088","pt":1588424333034,"mc":[{"id":"1.170370557","rc":[{"atl":[[2.86,0]],"id":9622734}],"con":true,"img":false}]}
{"op":"mcm","clk":"1362043096","pt":1588424333342,"mc":[{"id":"1.170370557","rc":[{"atl":[[1.62,94.85]],"id":9624350}],"con":true,"img":false}]}
{"op":"mcm","clk":"1362043103","pt":1588424333545,"mc":[{"id":"1.170370557","rc":[{"atl":[[2.88,0]],"id":9622734}],"con":true,"img":false}]}
{"op":"mcm","clk":"1362043106","pt":1588424333648,"mc":[{"id":"1.170370557","rc":[{"atb":[[2.6,16.62]],"id":9622734},{"atb":[[1.52,51.14]],"id":9624350}],"con":true,"img":false}]}
{"op":"mcm","clk":"1362043111","pt":1588424333852,"mc":[{"id":"1.170370557","rc":[{"atl":[[1.63,0]],"id":9624350}],"con":true,"img":false}]}
{"op":"mcm","clk":"1362043114","pt":1588424333955,"mc":[{"id":"1.170370557","rc":[{"atb":[[2.58,0]],"id":9622734},{"atb":[[1.52,0]],"id":9624350}],"con":true,"img":false}]}
{"op":"mcm","clk":"1362043130","pt":1588424334980,"mc":[{"id":"1.170370557","rc":[{"atb":[[2.64,23.09]],"id":9622734}],"con":true,"img":false}]}
{"op":"mcm","clk":"1362044914","pt":1588424393801,"mc":[{"id":"1.170370557","rc":[{"trd":[[2.66,15.02]],"ltp":2.66,"tv":15.02,"id":9622734},{"atb":[[2.66,0]],"id":9622734},{"atl":[[2.66,1.46]],"id":9622734},{"trd":[[1.6,409.03]],"ltp":1.6,"tv":409.03,"id":9624350},{"atl":[[1.6,0]],"id":9624350}],"con":true,"img":false}]}
{"op":"mcm","clk":"1362044919","pt":1588424394107,"mc":[{"id":"1.170370557","rc":[{"trd":[[2.66,17.94]],"ltp":2.66,"tv":17.94,"id":9622734},{"atb":[[2.66,0.31]],"id":9622734},{"atl":[[2.66,0]],"id":9622734}],"con":true,"img":false}]}
{"op":"mcm","clk":"1362044924","pt":1588424394413,"mc":[{"id":"1.170370557","rc":[{"atb":[[2.66,0]],"id":9622734}],"con":true,"img":false}]}
{"op":"mcm","clk":"1362044932","pt":1588424394922,"mc":[{"id":"1.170370557","rc":[{"atb":[[2.64,6.87]],"id":9622734}],"con":true,"img":false}]}
{"op":"mcm","clk":"1362045180","pt":1588424408193,"mc":[{"id":"1.170370557","marketDefinition":{"bspMarket":false,"turnInPlayEnabled":true,"persistenceEnabled":true,"marketBaseRate":5.0,"eventId":"29788106","eventTypeId":"2","numberOfWinners":1,"bettingType":"ODDS","marketType":"MATCH_ODDS","marketTime":"2020-05-02T13:05:00.000Z","suspendTime":"2020-05-02T13:05:00.000Z","bspReconciled":false,"complete":true,"inPlay":false,"crossMatching":true,"runnersVoidable":false,"numberOfActiveRunners":2,"betDelay":0,"status":"OPEN","runners":[{"status":"ACTIVE","sortPriority":1,"id":9624350,"name":"Y Hanfmann"},{"status":"ACTIVE","sortPriority":2,"id":9622734,"name":"D Brown"}],"regulators":["MR_INT"],"countryCode":"GB","discountAllowed":true,"timezone":"GMT","openDate":"2020-05-02T13:00:00.000Z","version":3237546854,"name":"Match Odds","eventName":"Y Hanfmann v D Brown"},"rc":[],"con":true,"img":false}]}
{"op":"mcm","clk":"1362045225","pt":1588424411197,"mc":[{"id":"1.170370557","marketDefinition":{"bspMarket":false,"turnInPlayEnabled":true,"persistenceEnabled":true,"marketBaseRate":5.0,"eventId":"29788106","eventTypeId":"2","numberOfWinners":1,"bettingType":"ODDS","marketType":"MATCH_ODDS","marketTime":"2020-05-02T13:05:00.000Z","suspendTime":"2020-05-02T13:05:00.000Z","bspReconciled":false,"complete":true,"inPlay":false,"crossMatching":true,"runnersVoidable":false,"numberOfActiveRunners":2,"betDelay":0,"status":"OPEN","runners":[{"status":"ACTIVE","sortPriority":1,"id":9624350,"name":"Y Hanfmann"},{"status":"ACTIVE","sortPriority":2,"id":9622734,"name":"D Brown"}],"regulators":["MR_INT"],"countryCode":"GB","discountAllowed":true,"timezone":"GMT","openDate":"2020-05-02T13:05:00.000Z","version":3237546854,"name":"Match Odds","eventName":"Y Hanfmann v D Brown"},"rc":[],"con":true,"img":false}]}
{"op":"mcm","clk":"1362048239","pt":1588424560632,"mc":[{"id":"1.170370557","rc":[{"atb":[[1.4,77.58]],"id":9624350}],"con":true,"img":false}]}
{"op":"mcm","clk":"1362048244","pt":1588424560806,"mc":[{"id":"1.170370557","rc":[{"atb":[[2.6,18.66],[2.58,2.06],[2.08,51.19]],"id":9622734},{"atl":[[2.88,2.04],[2.86,2.03]],"id":9622734},{"atb":[[1.53,2.16],[1.52,2.12]],"id":9624350},{"atl":[[1.64,2.04],[1.63,2.04]],"id":9624350}],"con":true,"img":false}]}
{"op":"mcm","clk":"1362048278","pt":1588424562033,"mc":[{"id":"1.170370557","rc":[{"atb":[[1.52,53.26]],"id":9624350}],"con":true,"img":false}]}
{"op":"mcm","clk":"1362048280","pt":1588424562135,"mc":[{"id":"1.170370557","rc":[{"atb":[[2.62,0]],"id":9622734}],"con":true,"img":false}]}
{"op":"mcm","clk":"1362048284","pt":1588424562289,"mc":[{"id":"1.170370557","rc":[{"trd":[[1.55,69.47]],"ltp":1.55,"tv":69.47,"id":9624350},{"atb":[[1.55,0]],"id":9624350},{"atl":[[1.55,13.76]],"id":9624350}],"con":true,"img":false}]}
{"op":"mcm","clk":"1362048289","pt":1588424562494,"mc":[{"id":"1.170370557","rc":[{"atb":[[1.51,2.2],[1.5,72.34]],"id":9624350},{"atl":[[1.57,2.01],[1.58,2.01]],"id":9624350}],"con":true,"img":false}]}
{"op":"mcm","clk":"1362048293","pt":1588424562597,"mc":[{"id":"1.170370557","rc":[{"atb":[[1.53,0],[1.52,51.14]],"id":9624350}],"con":true,"img":false}]}
{"op":"mcm","clk":"1362048297","pt":1588424562698,"mc":[{"id":"1.170370557","rc":[{"atb":[[2.76,2.15],[2.74,2.02]],"id":9622734}],"con":true,"img":false}]}
{"op":"mcm","clk":"1362048299","pt":1588424562802,"mc":[{"id":"1.170370557","rc":[{"atb":[[1.52,53.38]],"id":9624350}],"con":true,"img":false}]}
{"op":"mcm","clk":"1362048305","pt":1588424563008,"mc":[{"id":"1.170370557","rc":[{"atb":[[2.68,15.83]],"id":9622734},{"atb":[[1.5,19.15],[1.52,2.24]],"id":9624350}],"con":true,"img":false}]}
{"op":"mcm","clk":"1362048358","pt":1588424565214,"mc":[{"id":"1.170370557","rc":[{"atl":[[2.82,12.12]],"id":9622734}],"con":true,"img":false}]}
{"op":"mcm","clk":"1362048378","pt":1588424566035,"mc":[{"id":"1.170370557","rc":[{"atb":[[1.48,55.4]],"id":9624350}],"con":true,"img":false}]}
{"op":"mcm","clk":"1362048382","pt":1588424566137,"mc":[{"id":"1.170370557","rc":[{"atb":[[1.49,0]],"id":9624350}],"con":true,"img":false}]}
{"op":"mcm","clk":"1362049062","pt":1588424601870,"mc":[{"id":"1.170370557","rc":[{"atb":[[1.5,3.77]],"id":9624350}],"con":true,"img":false}]}
{"op":"mcm","clk":"1362049064","pt":1588424601973,"mc":[{"id":"1.170370557","rc":[{"atb":[[1.49,15.38]],"id":9624350}],"con":true,"img":false}]}
{"op":"mcm","clk":"1362049071","pt":1588424602283,"mc":[{"id":"1.170370557","rc":[{"atb":[[2.6,16.62],[2.58,0],[2.74,0]],"id":9622734},{"atl":[[2.88,0]],"id":9622734},{"atb":[[1.51,0],[1.5,1.77]],"id":9624350},{"atl":[[1.64,0],[1.63,0],[1.58,0]],"id":9624350}],"con":true,"img":false}]}
{"op":"mcm","clk":"1362049077","pt":1588424602489,"mc":[{"id":"1.170370557","rc":[{"atb":[[2.74,2.02]],"id":9622734},{"atl":[[2.88,2.04]],"id":9622734},{"atb":[[1.51,2.36]],"id":9624350},{"atl":[[1.58,2.25]],"id":9624350}],"con":true,"img":false}]}
{"op":"mcm","clk":"1362049236","pt":1588424612272,"mc":[{"id":"1.170370557","rc":[{"atb":[[2.08,0]],"id":9622734},{"atb":[[1.4,0]],"id":9624350}],"con":true,"img":false}]}
{"op":"mcm","clk":"1362049246","pt":1588424612581,"mc":[{"id":"1.170370557","rc":[{"atb":[[2.74,0]],"id":9622734},{"atl":[[2.88,0]],"id":9622734},{"atb":[[1.51,0]],"id":9624350},{"atl":[[1.58,0]],"id":9624350}],"con":true,"img":false}]}
{"op":"mcm","clk":"1362049250","pt":1588424612788,"mc":[{"id":"1.170370557","rc":[{"atb":[[2.74,2.02]],"id":9622734},{"atl":[[2.88,2.04]],"id":9622734},{"atb":[[1.51,2.06]],"id":9624350},{"atl":[[1.58,2.25]],"id":9624350}],"con":true,"img":false}]}
{"op":"mcm","clk":"1362049256","pt":1588424613095,"mc":[{"id":"1.170370557","rc":[{"atb":[[1.49,69.65]],"id":9624350}],"con":true,"img":false}]}
{"op":"mcm","clk":"1362049273","pt":1588424614071,"mc":[{"id":"1.170370557","rc":[{"atb":[[1.49,15.38]],"id":9624350}],"con":true,"img":false}]}
{"op":"mcm","clk":"1362049821","pt":1588424647245,"mc":[{"id":"1.170370557","rc":[{"trd":[[1.55,70.53]],"ltp":1.55,"tv":70.53,"id":9624350},{"atl":[[1.55,13.23]],"id":9624350}],"con":true,"img":false}]}
{"op":"mcm","clk":"1362049828","pt":1588424647557,"mc":[{"id":"1.170370557","rc":[{"atb":[[2.74,0]],"id":9622734},{"atl":[[2.88,0]],"id":9622734},{"atb":[[1.51,0]],"id":9624350},{"atl":[[1.58,0]],"id":9624350}],"con":true,"img":false}]}
{"op":"mcm","clk":"1362049832","pt":1588424647712,"mc":[{"id":"1.170370557","rc":[{"atb":[[2.74,2.02]],"id":9622734},{"atl":[[2.88,2.04]],"id":9622734},{"atb":[[1.51,2.34]],"id":9624350},{"atl":[[1.58,2.13]],"id":9624350}],"con":true,"img":false}]}
{"op":"mcm","clk":"1362049838","pt":1588424648019,"mc":[{"id":"1.170370557","rc":[{"atb":[[1.49,69.65]],"id":9624350}],"con":true,"img":false}]}
{"op":"mcm","clk":"1362049866","pt":1588424649147,"mc":[{"id":"1.170370557","rc":[{"atb":[[1.49,15.38]],"id":9624350}],"con":true,"img":false}]}
{"op":"mcm","clk":"1362051742","pt":1588424757174,"mc":[{"id":"1.170370557","rc":[{"trd":[[2.82,9.43]],"ltp":2.82,"tv":9.43,"id":9622734},{"atl":[[2.82,2.69]],"id":9622734},{"trd":[[1.54,35.1]],"ltp":1.54,"tv":35.1,"id":9624350},{"atb":[[1.54,0]],"id":9624350}],"con":true,"img":false}]}
{"op":"mcm","clk":"1362052104","pt":1588424776694,"mc":[{"id":"1.170370557","rc":[{"atl":[[2.82,0.57]],"id":9622734}],"con":true,"img":false}]}
{"op":"mcm","clk":"1362052112","pt":1588424777000,"mc":[{"id":"1.170370557","rc":[{"atb":[[2.76,0]],"id":9622734},{"atl":[[2.86,0]],"id":9622734},{"atb":[[1.52,0]],"id":9624350},{"atl":[[1.57,0]],"id":9624350}],"con":true,"img":false}]}
{"op":"mcm","clk":"1362052117","pt":1588424777102,"mc":[{"id":"1.170370557","rc":[{"atl":[[2.88,0]],"id":9622734},{"atb":[[1.51,0],[1.41,125.16]],"id":9624350},{"atl":[[1.58,0]],"id":9624350}],"con":true,"img":false}]}
{"op":"mcm","clk":"1362052121","pt":1588424777202,"mc":[{"id":"1.170370557","rc":[{"atb":[[2.74,0]],"id":9622734},{"atb":[[1.48,0]],"id":9624350}],"con":true,"img":false}]}
{"op":"mcm","clk":"1362052135","pt":1588424777977,"mc":[{"id":"1.170370557","rc":[{"atb":[[2.64,23.09]],"id":9622734}],"con":true,"img":false}]}
{"op":"mcm","clk":"1362052137","pt":1588424778080,"mc":[{"id":"1.170370557","rc":[{"atb":[[2.68,0]],"id":9622734}],"con":true,"img":false}]}
{"op":"mcm","clk":"1362052752","pt":1588424810831,"mc":[{"id":"1.170370557","rc":[{"atb":[[1.49,0]],"id":9624350}],"con":true,"img":false}]}
{"op":"mcm","clk":"1362052914","pt":1588424816449,"mc":[{"id":"1.170370557","rc":[{"atb":[[1.31,145.11]],"id":9624350}],"con":true,"img":false}]}
{"op":"mcm","clk":"1362052943","pt":1588424817432,"mc":[{"id":"1.170370557","rc":[{"atb":[[1.31,153.11]],"id":9624350}],"con":true,"img":false}]}
{"op":"mcm","clk":"1362053428","pt":1588424842981,"mc":[{"id":"1.170370557","rc":[{"atb":[[1.5,7.89]],"id":9624350}],"con":true,"img":false}]}
{"op":"mcm","clk":"1362053544","pt":1588424850069,"mc":[{"id":"1.170370557","rc":[{"atb":[[2.64,16.21]],"id":9622734}],"con":true,"img":false}]}
{"op":"mcm","clk":"1362053564","pt":1588424851150,"mc":[{"id":"1.170370557","rc":[{"atb":[[2.64,0],[2.62,16.41]],"id":9622734}],"con":true,"img":false}]}
{"op":"mcm","clk":"1362053636","pt":1588424855158,"mc":[{"id":"1.170370557","rc":[{"trd":[[1.55,72.37]],"ltp":1.55,"tv":72.37,"id":9624350},{"atl":[[1.55,12.31]],"id":9624350}],"con":true,"img":false}]}
{"op":"mcm","clk":"1362054970","pt":1588424928978,"mc":[{"id":"1.170370557","rc":[{"trd":[[2.8,4.08]],"ltp":2.8,"tv":4.08,"id":9622734},{"trd":[[1.55,72.75]],"ltp":1.55,"tv":72.75,"id":9624350},{"atl":[[1.55,11.94]],"id":9624350}],"con":true,"img":false}]}
{"op":"mcm","clk":"1362055599","pt":1588424961431,"mc":[{"id":"1.170370557","rc":[{"trd":[[1.55,90.34]],"ltp":1.55,"tv":90.34,"id":9624350},{"atl":[[1.55,3.14]],"id":9624350}],"con":true,"img":false}]}
{"op":"mcm","clk":"1362055701","pt":1588424966633,"mc":[{"id":"1.170370557","rc":[{"atl":[[1.7,0]],"id":9624350}],"con":true,"img":false}]}
{"op":"mcm","clk":"1362056064","pt":1588424984038,"mc":[{"id":"1.170370557","rc":[{"atl":[[1.7,199.96]],"id":9624350}],"con":true,"img":false}]}
{"op":"mcm","clk":"1362056443","pt":1588425008123,"mc":[{"id":"1.170370557","marketDefinition":{"bspMarket":false,"turnInPlayEnabled":true,"persistenceEnabled":true,"marketBaseRate":5.0,"eventId":"29788106","eventTypeId":"2","numberOfWinners":1,"bettingType":"ODDS","marketType":"MATCH_ODDS","marketTime":"2020-05-02T13:15:00.000Z","suspendTime":"2020-05-02T13:15:00.000Z","bspReconciled":false,"complete":true,"inPlay":false,"crossMatching":true,"runnersVoidable":false,"numberOfActiveRunners":2,"betDelay":0,"status":"OPEN","runners":[{"status":"ACTIVE","sortPriority":1,"id":9624350,"name":"Y Hanfmann"},{"status":"ACTIVE","sortPriority":2,"id":9622734,"name":"D Brown"}],"regulators":["MR_INT"],"countryCode":"GB","discountAllowed":true,"timezone":"GMT","openDate":"2020-05-02T13:05:00.000Z","version":3237559226,"name":"Match Odds","eventName":"Y Hanfmann v D Brown"},"rc":[],"con":true,"img":false}]}
{"op":"mcm","clk":"1362056549","pt":1588425013132,"mc":[{"id":"1.170370557","marketDefinition":{"bspMarket":false,"turnInPlayEnabled":true,"persistenceEnabled":true,"marketBaseRate":5.0,"eventId":"29788106","eventTypeId":"2","numberOfWinners":1,"bettingType":"ODDS","marketType":"MATCH_ODDS","marketTime":"2020-05-02T13:15:00.000Z","suspendTime":"2020-05-02T13:15:00.000Z","bspReconciled":false,"complete":true,"inPlay":false,"crossMatching":true,"runnersVoidable":false,"numberOfActiveRunners":2,"betDelay":0,"status":"OPEN","runners":[{"status":"ACTIVE","sortPriority":1,"id":9624350,"name":"Y Hanfmann"},{"status":"ACTIVE","sortPriority":2,"id":9622734,"name":"D Brown"}],"regulators":["MR_INT"],"countryCode":"GB","discountAllowed":true,"timezone":"GMT","openDate":"2020-05-02T13:15:00.000Z","version":3237559226,"name":"Match Odds","eventName":"Y Hanfmann v D Brown"},"rc":[],"con":true,"img":false}]}
{"op":"mcm","clk":"1362058714","pt":1588425163337,"mc":[{"id":"1.170370557","rc":[{"atl":[[2.98,2.12]],"id":9622734}],"con":true,"img":false}]}
{"op":"mcm","clk":"1362059835","pt":1588425222901,"mc":[{"id":"1.170370557","rc":[{"atb":[[1.42,6.29]],"id":9624350}],"con":true,"img":false}]}
{"op":"mcm","clk":"1362060275","pt":1588425243483,"mc":[{"id":"1.170370557","marketDefinition":{"bspMarket":false,"turnInPlayEnabled":true,"persistenceEnabled":true,"marketBaseRate":5.0,"eventId":"29788106","eventTypeId":"2","numberOfWinners":1,"bettingType":"ODDS","marketType":"MATCH_ODDS","marketTime":"2020-05-02T13:20:00.000Z","suspendTime":"2020-05-02T13:20:00.000Z","bspReconciled":false,"complete":true,"inPlay":false,"crossMatching":true,"runnersVoidable":false,"numberOfActiveRunners":2,"betDelay":0,"status":"OPEN","runners":[{"status":"ACTIVE","sortPriority":1,"id":9624350,"name":"Y Hanfmann"},{"status":"ACTIVE","sortPriority":2,"id":9622734,"name":"D Brown"}],"regulators":["MR_INT"],"countryCode":"GB","discountAllowed":true,"timezone":"GMT","openDate":"2020-05-02T13:15:00.000Z","version":3237562990,"name":"Match Odds","eventName":"Y Hanfmann v D Brown"},"rc":[],"con":true,"img":false}]}
{"op":"mcm","clk":"1362060346","pt":1588425246487,"mc":[{"id":"1.170370557","marketDefinition":{"bspMarket":false,"turnInPlayEnabled":true,"persistenceEnabled":true,"marketBaseRate":5.0,"eventId":"29788106","eventTypeId":"2","numberOfWinners":1,"bettingType":"ODDS","marketType":"MATCH_ODDS","marketTime":"2020-05-02T13:20:00.000Z","suspendTime":"2020-05-02T13:20:00.000Z","bspReconciled":false,"complete":true,"inPlay":false,"crossMatching":true,"runnersVoidable":false,"numberOfActiveRunners":2,"betDelay":0,"status":"OPEN","runners":[{"status":"ACTIVE","sortPriority":1,"id":9624350,"name":"Y Hanfmann"},{"status":"ACTIVE","sortPriority":2,"id":9622734,"name":"D Brown"}],"regulators":["MR_INT"],"countryCode":"GB","discountAllowed":true,"timezone":"GMT","openDate":"2020-05-02T13:20:00.000Z","version":3237562990,"name":"Match Odds","eventName":"Y Hanfmann v D Brown"},"rc":[],"con":true,"img":false}]}
{"op":"mcm","clk":"1362061802","pt":1588425279479,"mc":[{"id":"1.170370557","rc":[{"trd":[[1.55,96.64]],"ltp":1.55,"tv":96.64,"id":9624350},{"atb":[[1.55,86.85]],"id":9624350},{"atl":[[1.55,0]],"id":9624350}],"con":true,"img":false}]}
{"op":"mcm","clk":"1362061817","pt":1588425280262,"mc":[{"id":"1.170370557","rc":[{"atb":[[2.6,0],[2.58,16.83],[2.62,0]],"id":9622734},{"atb":[[1.52,51.14]],"id":9624350}],"con":true,"img":false}]}
{"op":"mcm","clk":"1362062085","pt":1588425295208,"mc":[{"id":"1.170370557","rc":[{"atb":[[1.56,7.99]],"id":9624350}],"con":true,"img":false}]}
{"op":"mcm","clk":"1362062099","pt":1588425295964,"mc":[{"id":"1.170370557","rc":[{"atl":[[1.59,17.49]],"id":9624350}],"con":true,"img":false}]}
{"op":"mcm","clk":"1362062282","pt":1588425306603,"mc":[{"id":"1.170370557","rc":[{"atb":[[1.55,0]],"id":9624350}],"con":true,"img":false}]}
{"op":"mcm","clk":"1362062297","pt":1588425307277,"mc":[{"id":"1.170370557","rc":[{"atb":[[2.56,17.04],[2.58,0]],"id":9622734},{"atb":[[1.52,0]],"id":9624350}],"con":true,"img":false}]}
{"op":"mcm","clk":"1362062338","pt":1588425309175,"mc":[{"id":"1.170370557","rc":[{"atb":[[1.56,0]],"id":9624350}],"con":true,"img":false}]}
{"op":"mcm","clk":"1362062358","pt":1588425310112,"mc":[{"id":"1.170370557","rc":[{"atb":[[1.51,7.99]],"id":9624350}],"con":true,"img":false}]}
{"op":"mcm","clk":"1362062360","pt":1588425310214,"mc":[{"id":"1.170370557","rc":[{"atb":[[2.62,16.41]],"id":9622734}],"con":true,"img":false}]}
{"op":"mcm","clk":"1362062380","pt":1588425311395,"mc":[{"id":"1.170370557","rc":[{"atb":[[1.42,14.29]],"id":9624350}],"con":true,"img":false}]}
{"op":"mcm","clk":"1362062383","pt":1588425311596,"mc":[{"id":"1.170370557","rc":[{"atb":[[1.42,22.29]],"id":9624350}],"con":true,"img":false}]}
{"op":"mcm","clk":"1362062397","pt":1588425312319,"mc":[{"id":"1.170370557","rc":[{"atb":[[1.42,85.61]],"id":9624350}],"con":true,"img":false}]}
{"op":"mcm","clk":"1362062508","pt":1588425318996,"mc":[{"id":"1.170370557","rc":[{"atb":[[1.52,17.49]],"id":9624350}],"con":true,"img":false}]}
{"op":"mcm","clk":"1362062510","pt":1588425319207,"mc":[{"id":"1.170370557","rc":[{"atb":[[1.5,61.08]],"id":9624350}],"con":true,"img":false}]}
{"op":"mcm","clk":"1362062535","pt":1588425320632,"mc":[{"id":"1.170370557","rc":[{"atb":[[1.57,90]],"id":9624350}],"con":true,"img":false}]}
{"op":"mcm","clk":"1362062553","pt":1588425321299,"mc":[{"id":"1.170370557","rc":[{"atb":[[1.51,60.14]],"id":9624350}],"con":true,"img":false}]}
{"op":"mcm","clk":"1362062557","pt":1588425321406,"mc":[{"id":"1.170370557","rc":[{"atb":[[2.62,0]],"id":9622734}],"con":true,"img":false}]}
{"op":"mcm","clk":"1362063483","pt":1588425373672,"mc":[{"id":"1.170370557","rc":[{"trd":[[1.59,188.63]],"ltp":1.59,"tv":188.63,"id":9624350},{"atl":[[1.59,0.49]],"id":9624350}],"con":true,"img":false}]}
{"op":"mcm","clk":"1362063493","pt":1588425374341,"mc":[{"id":"1.170370557","rc":[{"atb":[[1.41,60.29]],"id":9624350}],"con":true,"img":false}]}
{"op":"mcm","clk":"1362063508","pt":1588425375264,"mc":[{"id":"1.170370557","rc":[{"atb":[[1.53,50.17]],"id":9624350}],"con":true,"img":false}]}
{"op":"mcm","clk":"1362064762","pt":1588425448071,"mc":[{"id":"1.170370557","rc":[{"atb":[[1.57,0]],"id":9624350}],"con":true,"img":false}]}
{"op":"mcm","clk":"1362064781","pt":1588425449353,"mc":[{"id":"1.170370557","rc":[{"atb":[[2.62,16.41]],"id":9622734}],"con":true,"img":false}]}
{"op":"mcm","clk":"1362064785","pt":1588425449455,"mc":[{"id":"1.170370557","rc":[{"atb":[[1.51,7.99],[1.53,0]],"id":9624350}],"con":true,"img":false}]}
{"op":"mcm","clk":"1362064958","pt":1588425460564,"mc":[{"id":"1.170370557","rc":[{"atb":[[1.43,37.2]],"id":9624350}],"con":true,"img":false}]}
{"op":"mcm","clk":"1362064961","pt":1588425460769,"mc":[{"id":"1.170370557","rc":[{"atb":[[1.43,74.4]],"id":9624350}],"con":true,"img":false}]}
{"op":"mcm","clk":"1362064982","pt":1588425462464,"mc":[{"id":"1.170370557","rc":[{"atb":[[1.41,1.77]],"id":9624350}],"con":true,"img":false}]}
{"op":"mcm","clk":"1362065348","pt":1588425487110,"mc":[{"id":"1.170370557","rc":[{"atb":[[1.55,103]],"id":9624350}],"con":true,"img":false}]}
{"op":"mcm","clk":"1362065366","pt":1588425488343,"mc":[{"id":"1.170370557","rc":[{"atb":[[2.58,16.83],[2.62,0]],"id":9622734},{"atb":[[1.52,68.63]],"id":9624350}],"con":true,"img":false}]}
{"op":"mcm","clk":"1362066197","pt":1588425543782,"mc":[{"id":"1.170370557","rc":[{"atb":[[1.55,0]],"id":9624350}],"con":true,"img":false}]}
{"op":"mcm","clk":"1362066207","pt":1588425544301,"mc":[{"id":"1.170370557","rc":[{"atb":[[2.62,16.41]],"id":9622734},{"atb":[[1.52,17.49]],"id":9624350}],"con":true,"img":false}]}
{"op":"mcm","clk":"1362066292","pt":1588425550120,"mc":[{"id":"1.170370557","rc":[{"trd":[[1.61,322.86],[1.59,189.61]],"ltp":1.61,"tv":512.47,"id":9624350},{"atl":[[1.59,0],[1.61,0.6]],"id":9624350}],"con":true,"img":false}]}
{"op":"mcm","clk":"1362066310","pt":1588425551305,"mc":[{"id":"1.170370557","rc":[{"atb":[[2.6,16.62],[2.62,0]],"id":9622734}],"con":true,"img":false}]}
{"op":"mcm","clk":"1362066580","pt":1588425568035,"mc":[{"id":"1.170370557","rc":[{"trd":[[1.62,201.99],[1.61,324.06]],"ltp":1.62,"tv":526.05,"id":9624350},{"atl":[[1.62,70.46],[1.61,0]],"id":9624350}],"con":true,"img":false}]}
{"op":"mcm","clk":"1362066648","pt":1588425572045,"mc":[{"id":"1.170370557","rc":[{"atb":[[1.52,0]],"id":9624350}],"con":true,"img":false}]}
{"op":"mcm","clk":"1362066651","pt":1588425572251,"mc":[{"id":"1.170370557","rc":[{"atb":[[1.54,17.49]],"id":9624350}],"con":true,"img":false}]}
{"op":"mcm","clk":"1362066691","pt":1588425574257,"mc":[{"id":"1.170370557","rc":[{"atb":[[1.55,15.99]],"id":9624350}],"con":true,"img":false}]}
{"op":"mcm","clk":"1362066713","pt":1588425575332,"mc":[{"id":"1.170370557","rc":[{"atb":[[2.6,0]],"id":9622734},{"atb":[[1.52,51.14]],"id":9624350}],"con":true,"img":false}]}
{"op":"mcm","clk":"1362066795","pt":1588425579954,"mc":[{"id":"1.170370557","rc":[{"atl":[[1.61,17.49]],"id":9624350}],"con":true,"img":false}]}
{"op":"mcm","clk":"1362067236","pt":1588425603962,"mc":[{"id":"1.170370557","marketDefinition":{"bspMarket":false,"turnInPlayEnabled":true,"persistenceEnabled":true,"marketBaseRate":5.0,"eventId":"29788106","eventTypeId":"2","numberOfWinners":1,"bettingType":"ODDS","marketType":"MATCH_ODDS","marketTime":"2020-05-02T13:25:00.000Z","suspendTime":"2020-05-02T13:25:00.000Z","bspReconciled":false,"complete":true,"inPlay":false,"crossMatching":true,"runnersVoidable":false,"numberOfActiveRunners":2,"betDelay":0,"status":"OPEN","runners":[{"status":"ACTIVE","sortPriority":1,"id":9624350,"name":"Y Hanfmann"},{"status":"ACTIVE","sortPriority":2,"id":9622734,"name":"D Brown"}],"regulators":["MR_INT"],"countryCode":"GB","discountAllowed":true,"timezone":"GMT","openDate":"2020-05-02T13:20:00.000Z","version":3237563970,"name":"Match Odds","eventName":"Y Hanfmann v D Brown"},"rc":[],"con":true,"img":false}]}
{"op":"mcm","clk":"1362067267","pt":1588425605964,"mc":[{"id":"1.170370557","marketDefinition":{"bspMarket":false,"turnInPlayEnabled":true,"persistenceEnabled":true,"marketBaseRate":5.0,"eventId":"29788106","eventTypeId":"2","numberOfWinners":1,"bettingType":"ODDS","marketType":"MATCH_ODDS","marketTime":"2020-05-02T13:25:00.000Z","suspendTime":"2020-05-02T13:25:00.000Z","bspReconciled":false,"complete":true,"inPlay":false,"crossMatching":true,"runnersVoidable":false,"numberOfActiveRunners":2,"betDelay":0,"status":"OPEN","runners":[{"status":"ACTIVE","sortPriority":1,"id":9624350,"name":"Y Hanfmann"},{"status":"ACTIVE","sortPriority":2,"id":9622734,"name":"D Brown"}],"regulators":["MR_INT"],"countryCode":"GB","discountAllowed":true,"timezone":"GMT","openDate":"2020-05-02T13:25:00.000Z","version":3237563970,"name":"Match Odds","eventName":"Y Hanfmann v D Brown"},"rc":[],"con":true,"img":false}]}
{"op":"mcm","clk":"1362067362","pt":1588425611093,"mc":[{"id":"1.170370557","rc":[{"atb":[[1.01,14.79]],"id":9624350}],"con":true,"img":false}]}
{"op":"mcm","clk":"1362067522","pt":1588425620795,"mc":[{"id":"1.170370557","rc":[{"atl":[[2.98,0]],"id":9622734}],"con":true,"img":false}]}
{"op":"mcm","clk":"1362067590","pt":1588425624232,"mc":[{"id":"1.170370557","rc":[{"atb":[[1.03,3]],"id":9624350}],"con":true,"img":false}]}
{"op":"mcm","clk":"1362067744","pt":1588425633025,"mc":[{"id":"1.170370557","rc":[{"trd":[[2.82,10]],"ltp":2.82,"tv":10.0,"id":9622734},{"atl":[[2.82,0]],"id":9622734},{"trd":[[1.52,1.32],[1.55,128.63],[1.54,71.12]],"ltp":1.52,"tv":201.07,"id":9624350},{"atb":[[1.55,0],[1.54,0],[1.52,50.47]],"id":9624350}],"con":true,"img":false}]}
{"op":"mcm","clk":"1362067748","pt":1588425633333,"mc":[{"id":"1.170370557","rc":[{"atb":[[2.6,16.62]],"id":9622734},{"atb":[[1.43,136.25]],"id":9624350}],"con":true,"img":false}]}
{"op":"mcm","clk":"1362067753","pt":1588425633544,"mc":[{"id":"1.170370557","rc":[{"atb":[[1.5,7.89],[1.52,0]],"id":9624350}],"con":true,"img":false}]}
{"op":"mcm","clk":"1362067824","pt":1588425637751,"mc":[{"id":"1.170370557","rc":[{"atl":[[1.61,32.89]],"id":9624350}],"con":true,"img":false}]}
{"op":"mcm","clk":"1362067836","pt":1588425638417,"mc":[{"id":"1.170370557","rc":[{"atb":[[2.62,16.41]],"id":9622734}],"con":true,"img":false}]}
{"op":"mcm","clk":"1362067862","pt":1588425640155,"mc":[{"id":"1.170370557","rc":[{"atl":[[1.6,17.49]],"id":9624350}],"con":true,"img":false}]}
{"op":"mcm","clk":"1362067937","pt":1588425645271,"mc":[{"id":"1.170370557","rc":[{"atl":[[1.61,15.39]],"id":9624350}],"con":true,"img":false}]}
{"op":"mcm","clk":"1362067959","pt":1588425646654,"mc":[{"id":"1.170370557","rc":[{"atb":[[1.01,14.79]],"id":9622734}],"con":true,"img":false}]}
{"op":"mcm","clk":"1362068068","pt":1588425652955,"mc":[{"id":"1.170370557","rc":[{"atb":[[1.52,17.49]],"id":9624350}],"con":true,"img":false}]}
{"op":"mcm","clk":"1362068076","pt":1588425653159,"mc":[{"id":"1.170370557","rc":[{"atb":[[2.58,18.89],[2.56,19.12]],"id":9622734},{"atl":[[3.1,2.05],[3,2],[2.98,2.25],[3.05,2.1]],"id":9622734},{"atb":[[1.5,9.89],[1.49,2.01]],"id":9624350},{"atl":[[1.63,2.04],[1.62,72.71]],"id":9624350}],"con":true,"img":false}]}
{"op":"mcm","clk":"1362068098","pt":1588425654389,"mc":[{"id":"1.170370557","rc":[{"atb":[[1.5,63.08]],"id":9624350}],"con":true,"img":false}]}
{"op":"mcm","clk":"1362068199","pt":1588425659454,"mc":[{"id":"1.170370557","rc":[{"atb":[[1.03,3]],"id":9622734}],"con":true,"img":false}]}
{"op":"mcm","clk":"1362068201","pt":1588425659556,"mc":[{"id":"1.170370557","rc":[{"atb":[[2.6,18.66],[2.62,18.45]],"id":9622734}],"con":true,"img":false}]}
{"op":"mcm","clk":"1362068205","pt":1588425659763,"mc":[{"id":"1.170370557","rc":[{"atb":[[2.56,17.04]],"id":9622734},{"atl":[[3.1,0],[3,0],[3.05,0]],"id":9622734},{"atb":[[1.49,0]],"id":9624350},{"atl":[[1.63,0]],"id":9624350}],"con":true,"img":false}]}
{"op":"mcm","clk":"1362068211","pt":1588425660069,"mc":[{"id":"1.170370557","rc":[{"atb":[[2.58,16.83]],"id":9622734}],"con":true,"img":false}]}
{"op":"mcm","clk":"1362068215","pt":1588425660274,"mc":[{"id":"1.170370557","rc":[{"atl":[[3,2]],"id":9622734},{"atb":[[1.49,2.01]],"id":9624350},{"atl":[[1.63,2.04]],"id":9624350}],"con":true,"img":false}]}
{"op":"mcm","clk":"1362068819","pt":1588425690848,"mc":[{"id":"1.170370557","rc":[{"atb":[[1.55,130.39]],"id":9624350}],"con":true,"img":false}]}
{"op":"mcm","clk":"1362068823","pt":1588425691056,"mc":[{"id":"1.170370557","rc":[{"atl":[[2.88,2.04],[2.86,2.25]],"id":9622734},{"atb":[[1.53,2.16],[1.52,19.53]],"id":9624350}],"con":true,"img":false}]}
{"op":"mcm","clk":"1362068826","pt":1588425691156,"mc":[{"id":"1.170370557","rc":[{"atb":[[2.6,16.62]],"id":9622734},{"atl":[[3,0]],"id":9622734},{"atb":[[1.49,0]],"id":9624350}],"con":true,"img":false}]}
{"op":"mcm","clk":"1362068830","pt":1588425691260,"mc":[{"id":"1.170370557","rc":[{"atl":[[1.63,0]],"id":9624350}],"con":true,"img":false}]}
{"op":"mcm","clk":"1362068832","pt":1588425691411,"mc":[{"id":"1.170370557","rc":[{"atb":[[2.6,2.04],[2.62,2.04]],"id":9622734}],"con":true,"img":false}]}
{"op":"mcm","clk":"1362068834","pt":1588425691517,"mc":[{"id":"1.170370557","rc":[{"atl":[[2.98,0]],"id":9622734},{"atb":[[1.5,61.08]],"id":9624350}],"con":true,"img":false}]}
{"op":"mcm","clk":"1362068836","pt":1588425691618,"mc":[{"id":"1.170370557","rc":[{"atl":[[1.63,2]],"id":9624350}],"con":true,"img":false}]}
{"op":"mcm","clk":"1362068872","pt":1588425693518,"mc":[{"id":"1.170370557","rc":[{"atb":[[1.42,22.29]],"id":9624350}],"con":true,"img":false}]}
{"op":"mcm","clk":"1362068890","pt":1588425694342,"mc":[{"id":"1.170370557","rc":[{"atb":[[1.52,70.67]],"id":9624350}],"con":true,"img":false}]}
{"op":"mcm","clk":"1362069389","pt":1588425723125,"mc":[{"id":"1.170370557","marketDefinition":{"bspMarket":false,"turnInPlayEnabled":true,"persistenceEnabled":true,"marketBaseRate":5.0,"eventId":"29788106","eventTypeId":"2","numberOfWinners":1,"bettingType":"ODDS","marketType":"MATCH_ODDS","marketTime":"2020-05-02T13:30:00.000Z","suspendTime":"2020-05-02T13:30:00.000Z","bspReconciled":false,"complete":true,"inPlay":false,"crossMatching":true,"runnersVoidable":false,"numberOfActiveRunners":2,"betDelay":0,"status":"OPEN","runners":[{"status":"ACTIVE","sortPriority":1,"id":9624350,"name":"Y Hanfmann"},{"status":"ACTIVE","sortPriority":2,"id":9622734,"name":"D Brown"}],"regulators":["MR_INT"],"countryCode":"GB","discountAllowed":true,"timezone":"GMT","openDate":"2020-05-02T13:25:00.000Z","version":3237564022,"name":"Match Odds","eventName":"Y Hanfmann v D Brown"},"rc":[],"con":true,"img":false}]}
{"op":"mcm","clk":"1362069424","pt":1588425724906,"mc":[{"id":"1.170370557","rc":[{"atb":[[1.42,15.99]],"id":9624350}],"con":true,"img":false}]}
{"op":"mcm","clk":"1362069429","pt":1588425725170,"mc":[{"id":"1.170370557","rc":[{"atb":[[2.6,0]],"id":9622734},{"atl":[[2.88,0]],"id":9622734},{"atb":[[1.52,68.63]],"id":9624350},{"atl":[[1.63,0]],"id":9624350}],"con":true,"img":false}]}
{"op":"mcm","clk":"1362069435","pt":1588425725373,"mc":[{"id":"1.170370557","rc":[{"atb":[[2.6,2.04]],"id":9622734},{"atl":[[2.88,2.04]],"id":9622734},{"atb":[[1.52,70.75]],"id":9624350},{"atl":[[1.63,2.04]],"id":9624350}],"con":true,"img":false}]}
{"op":"mcm","clk":"1362069451","pt":1588425726129,"mc":[{"id":"1.170370557","marketDefinition":{"bspMarket":false,"turnInPlayEnabled":true,"persistenceEnabled":true,"marketBaseRate":5.0,"eventId":"29788106","eventTypeId":"2","numberOfWinners":1,"bettingType":"ODDS","marketType":"MATCH_ODDS","marketTime":"2020-05-02T13:30:00.000Z","suspendTime":"2020-05-02T13:30:00.000Z","bspReconciled":false,"complete":true,"inPlay":false,"crossMatching":true,"runnersVoidable":false,"numberOfActiveRunners":2,"betDelay":0,"status":"OPEN","runners":[{"status":"ACTIVE","sortPriority":1,"id":9624350,"name":"Y Hanfmann"},{"status":"ACTIVE","sortPriority":2,"id":9622734,"name":"D Brown"}],"regulators":["MR_INT"],"countryCode":"GB","discountAllowed":true,"timezone":"GMT","openDate":"2020-05-02T13:30:00.000Z","version":3237564022,"name":"Match Odds","eventName":"Y Hanfmann v D Brown"},"rc":[],"con":true,"img":false}]}
{"op":"mcm","clk":"1362070016","pt":1588425758427,"mc":[{"id":"1.170370557","rc":[{"atl":[[2.78,2.12]],"id":9622734}],"con":true,"img":false}]}
{"op":"mcm","clk":"1362070019","pt":1588425758631,"mc":[{"id":"1.170370557","rc":[{"atl":[[2.82,2.25],[2.84,2.03]],"id":9622734}],"con":true,"img":false}]}
{"op":"mcm","clk":"1362070024","pt":1588425758738,"mc":[{"id":"1.170370557","rc":[{"atb":[[2.6,0]],"id":9622734},{"atl":[[2.88,0]],"id":9622734},{"atb":[[1.52,68.63]],"id":9624350},{"atl":[[1.63,0]],"id":9624350}],"con":true,"img":false}]}
{"op":"mcm","clk":"1362070026","pt":1588425758837,"mc":[{"id":"1.170370557","rc":[{"atb":[[1.54,2]],"id":9624350}],"con":true,"img":false}]}
{"op":"mcm","clk":"1362070031","pt":1588425759045,"mc":[{"id":"1.170370557","rc":[{"atl":[[2.86,0]],"id":9622734}],"con":true,"img":false}]}
{"op":"mcm","clk":"1362070032","pt":1588425759146,"mc":[{"id":"1.170370557","rc":[{"atb":[[2.6,2.04]],"id":9622734},{"atl":[[1.63,2.04]],"id":9624350}],"con":true,"img":false}]}
{"op":"mcm","clk":"1362070035","pt":1588425759347,"mc":[{"id":"1.170370557","rc":[{"atb":[[1.53,0]],"id":9624350}],"con":true,"img":false}]}
{"op":"mcm","clk":"1362070039","pt":1588425759555,"mc":[{"id":"1.170370557","rc":[{"atb":[[1.53,2.16]],"id":9624350}],"con":true,"img":false}]}
{"op":"mcm","clk":"1362070444","pt":1588425782386,"mc":[{"id":"1.170370557","rc":[{"atb":[[1.55,260.78]],"id":9624350}],"con":true,"img":false}]}
{"op":"mcm","clk":"1362070451","pt":1588425782779,"mc":[{"id":"1.170370557","rc":[{"atb":[[2.6,0]],"id":9622734},{"atl":[[2.84,0]],"id":9622734},{"atb":[[1.53,0]],"id":9624350},{"atl":[[1.63,0]],"id":9624350}],"con":true,"img":false}]}
{"op":"mcm","clk":"1362070455","pt":1588425782983,"mc":[{"id":"1.170370557","rc":[{"atb":[[2.6,2.04]],"id":9622734},{"atl":[[2.84,2.03]],"id":9622734},{"atb":[[1.53,2.16]],"id":9624350},{"atl":[[1.63,2.04]],"id":9624350}],"con":true,"img":false}]}
{"op":"mcm","clk":"1362071186","pt":1588425824123,"mc":[{"id":"1.170370557","rc":[{"atl":[[2.76,311.17]],"id":9622734}],"con":true,"img":false}]}
{"op":"mcm","clk":"1362071192","pt":1588425824328,"mc":[{"id":"1.170370557","rc":[{"atl":[[2.8,2.02]],"id":9622734}],"con":true,"img":false}]}
{"op":"mcm","clk":"1362071195","pt":1588425824432,"mc":[{"id":"1.170370557","rc":[{"atb":[[2.6,0]],"id":9622734},{"atl":[[2.84,0]],"id":9622734},{"atb":[[1.53,0]],"id":9624350},{"atl":[[1.63,0]],"id":9624350}],"con":true,"img":false}]}
{"op":"mcm","clk":"1362071199","pt":1588425824530,"mc":[{"id":"1.170370557","rc":[{"atb":[[2.58,0]],"id":9622734},{"atb":[[1.43,74.4]],"id":9624350}],"con":true,"img":false}]}
{"op":"mcm","clk":"1362071203","pt":1588425824734,"mc":[{"id":"1.170370557","rc":[{"atl":[[2.82,0]],"id":9622734}],"con":true,"img":false}]}
{"op":"mcm","clk":"1362071207","pt":1588425824942,"mc":[{"id":"1.170370557","rc":[{"atb":[[2.6,2]],"id":9622734},{"atl":[[2.82,2.02]],"id":9622734},{"atb":[[1.53,2.14]],"id":9624350},{"atl":[[1.63,2.04]],"id":9624350}],"con":true,"img":false}]}
{"op":"mcm","clk":"1362071214","pt":1588425825452,"mc":[{"id":"1.170370557","rc":[{"atb":[[1.53,52.31]],"id":9624350}],"con":true,"img":false}]}
{"op":"mcm","clk":"1362072029","pt":1588425875172,"mc":[{"id":"1.170370557","rc":[{"atl":[[2.76,0]],"id":9622734}],"con":true,"img":false}]}
{"op":"mcm","clk":"1362072034","pt":1588425875277,"mc":[{"id":"1.170370557","rc":[{"atl":[[2.84,2.03]],"id":9622734}],"con":true,"img":false}]}
{"op":"mcm","clk":"1362072039","pt":1588425875378,"mc":[{"id":"1.170370557","rc":[{"atb":[[2.6,0]],"id":9622734},{"atl":[[2.8,0]],"id":9622734},{"atb":[[1.53,50.17]],"id":9624350},{"atl":[[1.63,0]],"id":9624350}],"con":true,"img":false}]}
{"op":"mcm","clk":"1362072043","pt":1588425875485,"mc":[{"id":"1.170370557","rc":[{"atb":[[2.58,16.83]],"id":9622734},{"atb":[[1.53,0]],"id":9624350}],"con":true,"img":false}]}
{"op":"mcm","clk":"1362072047","pt":1588425875587,"mc":[{"id":"1.170370557","rc":[{"atb":[[2.6,2.04]],"id":9622734},{"atb":[[1.53,2.16]],"id":9624350},{"atl":[[1.63,2]],"id":9624350}],"con":true,"img":false}]}
{"op":"mcm","clk":"1362072193","pt":1588425884716,"mc":[{"id":"1.170370557","rc":[{"atb":[[1.43,0]],"id":9624350}],"con":true,"img":false}]}
{"op":"mcm","clk":"1362072201","pt":1588425885024,"mc":[{"id":"1.170370557","rc":[{"atb":[[2.6,0]],"id":9622734},{"atl":[[2.84,0]],"id":9622734},{"atb":[[1.53,0]],"id":9624350},{"atl":[[1.63,0]],"id":9624350}],"con":true,"img":false}]}
{"op":"mcm","clk":"1362072204","pt":1588425885229,"mc":[{"id":"1.170370557","rc":[{"atb":[[2.6,2.04]],"id":9622734},{"atl":[[2.84,2.03]],"id":9622734},{"atb":[[1.53,2.16]],"id":9624350},{"atl":[[1.63,2.04]],"id":9624350}],"con":true,"img":false}]}
{"op":"mcm","clk":"1362072211","pt":1588425885692,"mc":[{"id":"1.170370557","rc":[{"atb":[[1.42,0]],"id":9624350}],"con":true,"img":false}]}
{"op":"mcm","clk":"1362072214","pt":1588425885795,"mc":[{"id":"1.170370557","rc":[{"atb":[[1.41,17.77]],"id":9624350}],"con":true,"img":false}]}
{"op":"mcm","clk":"1362072265","pt":1588425888414,"mc":[{"id":"1.170370557","rc":[{"atb":[[1.41,56.78]],"id":9624350}],"con":true,"img":false}]}
{"op":"mcm","clk":"1362072268","pt":1588425888618,"mc":[{"id":"1.170370557","rc":[{"atb":[[1.41,95.8]],"id":9624350}],"con":true,"img":false}]}
{"op":"mcm","clk":"1362072270","pt":1588425888732,"mc":[{"id":"1.170370557","rc":[{"atb":[[1.41,134.82]],"id":9624350}],"con":true,"img":false}]}
{"op":"mcm","clk":"1362072373","pt":1588425895440,"mc":[{"id":"1.170370557","rc":[{"atl":[[1.59,311.71]],"id":9624350}],"con":true,"img":false}]}
{"op":"mcm","clk":"1362072377","pt":1588425895644,"mc":[{"id":"1.170370557","rc":[{"atl":[[1.61,17.39]],"id":9624350}],"con":true,"img":false}]}
{"op":"mcm","clk":"1362072379","pt":1588425895698,"mc":[{"id":"1.170370557","rc":[{"atb":[[2.6,0]],"id":9622734},{"atl":[[2.84,0]],"id":9622734},{"atb":[[1.53,0]],"id":9624350},{"atl":[[1.63,0]],"id":9624350}],"con":true,"img":false}]}
{"op":"mcm","clk":"1362072381","pt":1588425895804,"mc":[{"id":"1.170370557","rc":[{"atb":[[2.64,2.07]],"id":9622734}],"con":true,"img":false}]}
{"op":"mcm","clk":"1362072385","pt":1588425896007,"mc":[{"id":"1.170370557","rc":[{"atl":[[1.62,70.46]],"id":9624350}],"con":true,"img":false}]}
{"op":"mcm","clk":"1362072387","pt":1588425896109,"mc":[{"id":"1.170370557","rc":[{"atl":[[2.84,2.03]],"id":9622734},{"atb":[[1.53,2.14]],"id":9624350}],"con":true,"img":false}]}
{"op":"mcm","clk":"1362072392","pt":1588425896319,"mc":[{"id":"1.170370557","rc":[{"atb":[[2.62,0]],"id":9622734}],"con":true,"img":false}]}
{"op":"mcm","clk":"1362072395","pt":1588425896421,"mc":[{"id":"1.170370557","rc":[{"atl":[[1.62,72.47]],"id":9624350}],"con":true,"img":false}]}
{"op":"mcm","clk":"1362072398","pt":1588425896524,"mc":[{"id":"1.170370557","rc":[{"atb":[[2.62,18.45]],"id":9622734},{"atb":[[1.51,60.14],[1.52,17.49]],"id":9624350}],"con":true,"img":false}]}
{"op":"mcm","clk":"1362072950","pt":1588425925880,"mc":[{"id":"1.170370557","rc":[{"atl":[[1.58,15.69]],"id":9624350}],"con":true,"img":false}]}
{"op":"mcm","clk":"1362072954","pt":1588425926082,"mc":[{"id":"1.170370557","rc":[{"atl":[[1.6,19.5]],"id":9624350}],"con":true,"img":false}]}
{"op":"mcm","clk":"1362072956","pt":1588425926186,"mc":[{"id":"1.170370557","rc":[{"atb":[[1.53,0]],"id":9624350},{"atl":[[1.62,70.46]],"id":9624350}],"con":true,"img":false}]}
{"op":"mcm","clk":"1362072958","pt":1588425926288,"mc":[{"id":"1.170370557","rc":[{"atb":[[2.62,16.41]],"id":9622734},{"atl":[[2.84,0]],"id":9622734}],"con":true,"img":false}]}
{"op":"mcm","clk":"1362072961","pt":1588425926447,"mc":[{"id":"1.170370557","rc":[{"atb":[[2.66,2.02],[2.68,2.11]],"id":9622734},{"atl":[[2.84,2.03]],"id":9622734},{"atb":[[1.53,2.16]],"id":9624350},{"atl":[[1.61,15.39]],"id":9624350}],"con":true,"img":false}]}
{"op":"mcm","clk":"1362072965","pt":1588425926652,"mc":[{"id":"1.170370557","rc":[{"atl":[[1.61,17.4]],"id":9624350}],"con":true,"img":false}]}
{"op":"mcm","clk":"1362072968","pt":1588425926755,"mc":[{"id":"1.170370557","rc":[{"atb":[[2.64,0]],"id":9622734}],"con":true,"img":false}]}
{"op":"mcm","clk":"1362072980","pt":1588425927373,"mc":[{"id":"1.170370557","rc":[{"atl":[[1.61,2.01]],"id":9624350}],"con":true,"img":false}]}
{"op":"mcm","clk":"1362075048","pt":1588426047476,"mc":[{"id":"1.170370557","rc":[{"atb":[[1.1,121.58]],"id":9622734}],"con":true,"img":false}]}
{"op":"mcm","clk":"1362075054","pt":1588426047741,"mc":[{"id":"1.170370557","rc":[{"atb":[[2.66,0]],"id":9622734},{"atl":[[2.84,0]],"id":9622734},{"atb":[[1.53,0]],"id":9624350},{"atl":[[1.61,0]],"id":9624350}],"con":true,"img":false}]}
{"op":"mcm","clk":"1362075058","pt":1588426047943,"mc":[{"id":"1.170370557","rc":[{"atb":[[2.66,2.28]],"id":9622734},{"atl":[[2.84,2.03]],"id":9622734},{"atb":[[1.53,2.16]],"id":9624350},{"atl":[[1.61,2.14]],"id":9624350}],"con":true,"img":false}]}
{"op":"mcm","clk":"1362075868","pt":1588426095150,"mc":[{"id":"1.170370557","rc":[{"atl":[[1.6,2.01]],"id":9624350}],"con":true,"img":false}]}
{"op":"mcm","clk":"1362075873","pt":1588426095318,"mc":[{"id":"1.170370557","rc":[{"atl":[[1.57,17.49]],"id":9624350}],"con":true,"img":false}]}
{"op":"mcm","clk":"1362075876","pt":1588426095417,"mc":[{"id":"1.170370557","rc":[{"atl":[[2.84,0]],"id":9622734},{"atb":[[1.53,0]],"id":9624350}],"con":true,"img":false}]}
{"op":"mcm","clk":"1362075879","pt":1588426095521,"mc":[{"id":"1.170370557","rc":[{"atb":[[2.66,0]],"id":9622734},{"atl":[[1.61,0]],"id":9624350}],"con":true,"img":false}]}
{"op":"mcm","clk":"1362075881","pt":1588426095626,"mc":[{"id":"1.170370557","rc":[{"atb":[[2.7,2.02]],"id":9622734},{"atl":[[2.84,2.03]],"id":9622734},{"atb":[[1.53,2.06]],"id":9624350},{"atl":[[1.59,313.77]],"id":9624350}],"con":true,"img":false}]}
{"op":"mcm","clk":"1362075886","pt":1588426095931,"mc":[{"id":"1.170370557","rc":[{"atb":[[2.68,0]],"id":9622734},{"atl":[[1.6,0]],"id":9624350}],"con":true,"img":false}]}
{"op":"mcm","clk":"1362075890","pt":1588426096132,"mc":[{"id":"1.170370557","rc":[{"atb":[[2.68,2.11]],"id":9622734},{"atl":[[1.6,2.01]],"id":9624350}],"con":true,"img":false}]}
{"op":"mcm","clk":"1362075896","pt":1588426096542,"mc":[{"id":"1.170370557","rc":[{"atb":[[2.64,16.21]],"id":9622734}],"con":true,"img":false}]}
{"op":"mcm","clk":"1362076073","pt":1588426105930,"mc":[{"id":"1.170370557","rc":[{"atl":[[1.59,2.06]],"id":9624350}],"con":true,"img":false}]}
{"op":"mcm","clk":"1362076080","pt":1588426106241,"mc":[{"id":"1.170370557","rc":[{"atl":[[2.84,0]],"id":9622734},{"atb":[[1.53,0]],"id":9624350}],"con":true,"img":false}]}
{"op":"mcm","clk":"1362076083","pt":1588426106338,"mc":[{"id":"1.170370557","rc":[{"atb":[[2.68,0]],"id":9622734},{"atl":[[1.6,0]],"id":9624350}],"con":true,"img":false}]}
{"op":"mcm","clk":"1362076086","pt":1588426106544,"mc":[{"id":"1.170370557","rc":[{"atb":[[2.68,2.11]],"id":9622734},{"atl":[[2.84,2.03]],"id":9622734},{"atb":[[1.53,2.16]],"id":9624350},{"atl":[[1.6,2.01]],"id":9624350}],"con":true,"img":false}]}
{"op":"mcm","clk":"1362078259","pt":1588426184190,"mc":[{"id":"1.170370557","rc":[{"atl":[[1.58,0]],"id":9624350}],"con":true,"img":false}]}
{"op":"mcm","clk":"1362078267","pt":1588426184495,"mc":[{"id":"1.170370557","rc":[{"atb":[[2.68,0]],"id":9622734},{"atl":[[2.84,0]],"id":9622734},{"atb":[[1.53,0]],"id":9624350},{"atl":[[1.6,0]],"id":9624350}],"con":true,"img":false}]}
{"op":"mcm","clk":"1362078270","pt":1588426184597,"mc":[{"id":"1.170370557","rc":[{"atb":[[2.64,0]],"id":9622734},{"atb":[[1.51,7.99]],"id":9624350}],"con":true,"img":false}]}
{"op":"mcm","clk":"1362078273","pt":1588426184699,"mc":[{"id":"1.170370557","rc":[{"atb":[[2.68,2.11]],"id":9622734},{"atl":[[2.84,2.03]],"id":9622734},{"atb":[[1.53,2.16]],"id":9624350},{"atl":[[1.6,2]],"id":9624350}],"con":true,"img":false}]}
{"op":"mcm","clk":"1362078288","pt":1588426185472,"mc":[{"id":"1.170370557","rc":[{"atl":[[1.61,15.39]],"id":9624350}],"con":true,"img":false}]}
{"op":"mcm","clk":"1362078577","pt":1588426200618,"mc":[{"id":"1.170370557","rc":[{"trd":[[2.78,3.63]],"ltp":2.78,"tv":3.63,"id":9622734},{"atl":[[2.78,0.78]],"id":9622734},{"trd":[[1.56,6.47]],"ltp":1.56,"tv":6.47,"id":9624350}],"con":true,"img":false}]}
{"op":"mcm","clk":"1362078581","pt":1588426200823,"mc":[{"id":"1.170370557","rc":[{"atl":[[2.88,2.04],[2.86,2.03]],"id":9622734}],"con":true,"img":false}]}
{"op":"mcm","clk":"1362078585","pt":1588426201027,"mc":[{"id":"1.170370557","rc":[{"atb":[[2.68,0]],"id":9622734},{"atl":[[2.82,0],[2.84,0]],"id":9622734},{"atb":[[1.53,0]],"id":9624350},{"atl":[[1.6,0]],"id":9624350}],"con":true,"img":false}]}
{"op":"mcm","clk":"1362078587","pt":1588426201129,"mc":[{"id":"1.170370557","rc":[{"atl":[[1.57,0]],"id":9624350}],"con":true,"img":false}]}
{"op":"mcm","clk":"1362078588","pt":1588426201182,"mc":[{"id":"1.170370557","rc":[{"atb":[[2.68,2.11]],"id":9622734},{"atb":[[1.53,2.04],[1.54,0],[1.52,19.73]],"id":9624350},{"atl":[[1.6,2.01]],"id":9624350}],"con":true,"img":false}]}
{"op":"mcm","clk":"1362078592","pt":1588426201288,"mc":[{"id":"1.170370557","rc":[{"atl":[[1.58,17.49]],"id":9624350}],"con":true,"img":false}]}
{"op":"mcm","clk":"1362078595","pt":1588426201391,"mc":[{"id":"1.170370557","rc":[{"atb":[[2.64,2.07],[2.66,2]],"id":9622734},{"atl":[[1.62,72.71],[1.61,17.53]],"id":9624350}],"con":true,"img":false}]}
{"op":"mcm","clk":"1362078597","pt":1588426201493,"mc":[{"id":"1.170370557","rc":[{"atb":[[2.7,0]],"id":9622734},{"atl":[[1.59,0]],"id":9624350}],"con":true,"img":false}]}
{"op":"mcm","clk":"1362078600","pt":1588426201594,"mc":[{"id":"1.170370557","rc":[{"atb":[[1.51,60.14]],"id":9624350}],"con":true,"img":false}]}
{"op":"mcm","clk":"1362078621","pt":1588426202617,"mc":[{"id":"1.170370557","rc":[{"atb":[[1.52,70.87]],"id":9624350}],"con":true,"img":false}]}
{"op":"mcm","clk":"1362078759","pt":1588426208723,"mc":[{"id":"1.170370557","marketDefinition":{"bspMarket":false,"turnInPlayEnabled":true,"persistenceEnabled":true,"marketBaseRate":5.0,"eventId":"29788106","eventTypeId":"2","numberOfWinners":1,"bettingType":"ODDS","marketType":"MATCH_ODDS","marketTime":"2020-05-02T13:35:00.000Z","suspendTime":"2020-05-02T13:35:00.000Z","bspReconciled":false,"complete":true,"inPlay":false,"crossMatching":true,"runnersVoidable":false,"numberOfActiveRunners":2,"betDelay":0,"status":"OPEN","runners":[{"status":"ACTIVE","sortPriority":1,"id":9624350,"name":"Y Hanfmann"},{"status":"ACTIVE","sortPriority":2,"id":9622734,"name":"D Brown"}],"regulators":["MR_INT"],"countryCode":"GB","discountAllowed":true,"timezone":"GMT","openDate":"2020-05-02T13:30:00.000Z","version":3237564896,"name":"Match Odds","eventName":"Y Hanfmann v D Brown"},"rc":[],"con":true,"img":false}]}
{"op":"mcm","clk":"1362078829","pt":1588426211726,"mc":[{"id":"1.170370557","marketDefinition":{"bspMarket":false,"turnInPlayEnabled":true,"persistenceEnabled":true,"marketBaseRate":5.0,"eventId":"29788106","eventTypeId":"2","numberOfWinners":1,"bettingType":"ODDS","marketType":"MATCH_ODDS","marketTime":"2020-05-02T13:35:00.000Z","suspendTime":"2020-05-02T13:35:00.000Z","bspReconciled":false,"complete":true,"inPlay":false,"crossMatching":true,"runnersVoidable":false,"numberOfActiveRunners":2,"betDelay":0,"status":"OPEN","runners":[{"status":"ACTIVE","sortPriority":1,"id":9624350,"name":"Y Hanfmann"},{"status":"ACTIVE","sortPriority":2,"id":9622734,"name":"D Brown"}],"regulators":["MR_INT"],"countryCode":"GB","discountAllowed":true,"timezone":"GMT","openDate":"2020-05-02T13:35:00.000Z","version":3237564896,"name":"Match Odds","eventName":"Y Hanfmann v D Brown"},"rc":[],"con":true,"img":false}]}
{"op":"mcm","clk":"1362078932","pt":1588426215908,"mc":[{"id":"1.170370557","rc":[{"atl":[[2.78,0]],"id":9622734}],"con":true,"img":false}]}
{"op":"mcm","clk":"1362078939","pt":1588426216114,"mc":[{"id":"1.170370557","rc":[{"atb":[[1.56,549.64]],"id":9624350}],"con":true,"img":false}]}
{"op":"mcm","clk":"1362078948","pt":1588426216627,"mc":[{"id":"1.170370557","rc":[{"atb":[[2.6,16.62],[2.62,0]],"id":9622734}],"con":true,"img":false}]}
{"op":"mcm","clk":"1362079242","pt":1588426231142,"mc":[{"id":"1.170370557","rc":[{"trd":[[1.56,124.18]],"ltp":1.56,"tv":124.18,"id":9624350},{"atb":[[1.56,490.78]],"id":9624350}],"con":true,"img":false}]}
{"op":"mcm","clk":"1362079246","pt":1588426231342,"mc":[{"id":"1.170370557","rc":[{"atl":[[2.84,2.03]],"id":9622734},{"atb":[[1.54,2.02]],"id":9624350}],"con":true,"img":false}]}
{"op":"mcm","clk":"1362079252","pt":1588426231548,"mc":[{"id":"1.170370557","rc":[{"atb":[[2.64,0],[2.66,0]],"id":9622734},{"atl":[[2.88,0]],"id":9622734},{"atb":[[1.52,68.63]],"id":9624350},{"atl":[[1.62,70.46],[1.61,15.39]],"id":9624350}],"con":true,"img":false}]}
{"op":"mcm","clk":"1362079256","pt":1588426231651,"mc":[{"id":"1.170370557","rc":[{"atb":[[2.66,2.28]],"id":9622734},{"atl":[[1.61,17.4]],"id":9624350}],"con":true,"img":false}]}
{"op":"mcm","clk":"1362079263","pt":1588426231856,"mc":[{"id":"1.170370557","rc":[{"atl":[[2.86,0]],"id":9622734},{"atb":[[1.53,0]],"id":9624350}],"con":true,"img":false}]}
{"op":"mcm","clk":"1362079266","pt":1588426231959,"mc":[{"id":"1.170370557","rc":[{"atl":[[2.86,2.25]],"id":9622734},{"atb":[[1.53,2.16]],"id":9624350}],"con":true,"img":false}]}
{"op":"mcm","clk":"1362079604","pt":1588426248884,"mc":[{"id":"1.170370557","rc":[{"trd":[[1.56,1105.76]],"ltp":1.56,"tv":1105.76,"id":9624350},{"atb":[[1.56,0]],"id":9624350},{"atl":[[1.56,209.21]],"id":9624350}],"con":true,"img":false}]}
{"op":"mcm","clk":"1362079607","pt":1588426249088,"mc":[{"id":"1.170370557","rc":[{"atb":[[1.52,70.87]],"id":9624350},{"atl":[[1.59,2.06],[1.58,19.74]],"id":9624350}],"con":true,"img":false}]}
{"op":"mcm","clk":"1362079611","pt":1588426249292,"mc":[{"id":"1.170370557","rc":[{"atb":[[2.66,0]],"id":9622734},{"atl":[[2.86,0]],"id":9622734},{"atb":[[1.54,0]],"id":9624350},{"atl":[[1.61,15.39]],"id":9624350}],"con":true,"img":false}]}
{"op":"mcm","clk":"1362079613","pt":1588426249396,"mc":[{"id":"1.170370557","rc":[{"atb":[[2.72,2.09],[2.74,2.02]],"id":9622734},{"atl":[[2.88,2.04]],"id":9622734}],"con":true,"img":false}]}
{"op":"mcm","clk":"1362079617","pt":1588426249554,"mc":[{"id":"1.170370557","rc":[{"atb":[[2.68,17.94]],"id":9622734},{"atl":[[2.84,0]],"id":9622734},{"atl":[[1.6,0]],"id":9624350}],"con":true,"img":false}]}
{"op":"mcm","clk":"1362079619","pt":1588426249656,"mc":[{"id":"1.170370557","rc":[{"atl":[[2.86,2.25]],"id":9622734},{"atb":[[1.51,7.99],[1.52,19.73]],"id":9624350}],"con":true,"img":false}]}
{"op":"mcm","clk":"1362079621","pt":1588426249759,"mc":[{"id":"1.170370557","rc":[{"atb":[[2.68,15.83]],"id":9622734}],"con":true,"img":false}]}
{"op":"mcm","clk":"1362079677","pt":1588426253082,"mc":[{"id":"1.170370557","rc":[{"trd":[[1.56,1121.76]],"ltp":1.56,"tv":1121.76,"id":9624350},{"atl":[[1.56,201.21]],"id":9624350}],"con":true,"img":false}]}
{"op":"mcm","clk":"1362080020","pt":1588426274931,"mc":[{"id":"1.170370557","rc":[{"atb":[[1.5,561.08]],"id":9624350}],"con":true,"img":false}]}
{"op":"mcm","clk":"1362080026","pt":1588426275238,"mc":[{"id":"1.170370557","rc":[{"atb":[[2.72,0]],"id":9622734},{"atl":[[2.88,0]],"id":9622734},{"atb":[[1.52,17.49]],"id":9624350},{"atl":[[1.59,0]],"id":9624350}],"con":true,"img":false}]}
{"op":"mcm","clk":"1362080030","pt":1588426275442,"mc":[{"id":"1.170370557","rc":[{"atb":[[2.72,2]],"id":9622734},{"atl":[[2.88,2.04]],"id":9622734},{"atb":[[1.52,19.49]],"id":9624350},{"atl":[[1.59,2.06]],"id":9624350}],"con":true,"img":false}]}
{"op":"mcm","clk":"1362080105","pt":1588426280553,"mc":[{"id":"1.170370557","rc":[{"trd":[[1.55,131.54]],"ltp":1.55,"tv":131.54,"id":9624350},{"atb":[[1.55,259.32]],"id":9624350}],"con":true,"img":false}]}
{"op":"mcm","clk":"1362080111","pt":1588426280912,"mc":[{"id":"1.170370557","rc":[{"atb":[[2.72,0]],"id":9622734},{"atl":[[2.88,0]],"id":9622734},{"atb":[[1.52,17.49]],"id":9624350},{"atl":[[1.59,0]],"id":9624350}],"con":true,"img":false}]}
{"op":"mcm","clk":"1362080114","pt":1588426281116,"mc":[{"id":"1.170370557","rc":[{"atb":[[2.72,2.02]],"id":9622734},{"atl":[[2.88,2.04]],"id":9622734},{"atb":[[1.52,19.73]],"id":9624350},{"atl":[[1.59,2.01]],"id":9624350}],"con":true,"img":false}]}
{"op":"mcm","clk":"1362080544","pt":1588426305568,"mc":[{"id":"1.170370557","rc":[{"trd":[[1.55,486.15]],"ltp":1.55,"tv":486.15,"id":9624350},{"atb":[[1.55,82.02]],"id":9624350}],"con":true,"img":false}]}
{"op":"mcm","clk":"1362080551","pt":1588426305876,"mc":[{"id":"1.170370557","rc":[{"atb":[[2.72,0]],"id":9622734},{"atl":[[2.88,0]],"id":9622734},{"atb":[[1.52,17.49]],"id":9624350},{"atl":[[1.59,0]],"id":9624350}],"con":true,"img":false}]}
{"op":"mcm","clk":"1362080556","pt":1588426306081,"mc":[{"id":"1.170370557","rc":[{"atb":[[2.72,2.09]],"id":9622734},{"atl":[[2.88,2.04]],"id":9622734},{"atb":[[1.52,19.73]],"id":9624350},{"atl":[[1.59,2.06]],"id":9624350}],"con":true,"img":false}]}
{"op":"mcm","clk":"1362080567","pt":1588426306593,"mc":[{"id":"1.170370557","rc":[{"trd":[[1.55,650.19]],"ltp":1.55,"tv":650.19,"id":9624350},{"atb":[[1.55,0]],"id":9624350},{"atl":[[1.55,95.28]],"id":9624350}],"con":true,"img":false}]}
{"op":"mcm","clk":"1362080572","pt":1588426306753,"mc":[{"id":"1.170370557","rc":[{"atb":[[1.51,10.21]],"id":9624350},{"atl":[[1.57,2.01]],"id":9624350}],"con":true,"img":false}]}
{"op":"mcm","clk":"1362080574","pt":1588426306850,"mc":[{"id":"1.170370557","rc":[{"atb":[[1.53,0]],"id":9624350}],"con":true,"img":false}]}
{"op":"mcm","clk":"1362080581","pt":1588426307057,"mc":[{"id":"1.170370557","rc":[{"atb":[[2.76,2.23]],"id":9622734},{"atl":[[2.92,2.06],[2.9,2.05]],"id":9622734},{"atb":[[1.5,563.08],[1.49,2.01]],"id":9624350}],"con":true,"img":false}]}
{"op":"mcm","clk":"1362080583","pt":1588426307159,"mc":[{"id":"1.170370557","rc":[{"atl":[[2.88,0],[2.86,0]],"id":9622734},{"atb":[[1.51,7.99],[1.52,17.49]],"id":9624350},{"atl":[[1.58,17.49]],"id":9624350}],"con":true,"img":false}]}
{"op":"mcm","clk":"1362080587","pt":1588426307365,"mc":[{"id":"1.170370557","rc":[{"atb":[[2.74,0]],"id":9622734}],"con":true,"img":false}]}
{"op":"mcm","clk":"1362080591","pt":1588426307467,"mc":[{"id":"1.170370557","rc":[{"atl":[[2.96,2.05],[2.94,2.01]],"id":9622734},{"atl":[[1.58,19.62]],"id":9624350}],"con":true,"img":false}]}
{"op":"mcm","clk":"1362080597","pt":1588426307672,"mc":[{"id":"1.170370557","rc":[{"atb":[[2.56,0]],"id":9622734},{"atl":[[2.92,0],[2.9,0]],"id":9622734},{"atb":[[1.5,509.89],[1.47,56.58]],"id":9624350}],"con":true,"img":false}]}
{"op":"mcm","clk":"1362080600","pt":1588426307774,"mc":[{"id":"1.170370557","rc":[{"atb":[[2.74,2.02]],"id":9622734},{"atb":[[1.53,262.72]],"id":9624350}],"con":true,"img":false}]}
{"op":"mcm","clk":"1362080602","pt":1588426307876,"mc":[{"id":"1.170370557","rc":[{"atl":[[3,2],[2.98,2.2]],"id":9622734}],"con":true,"img":false}]}
{"op":"mcm","clk":"1362080604","pt":1588426307978,"mc":[{"id":"1.170370557","rc":[{"atl":[[2.96,0],[2.94,0]],"id":9622734}],"con":true,"img":false}]}
{"op":"mcm","clk":"1362080608","pt":1588426308183,"mc":[{"id":"1.170370557","rc":[{"atl":[[2.96,2.07],[2.94,2.08]],"id":9622734},{"atb":[[1.51,10.19]],"id":9624350}],"con":true,"img":false}]}
{"op":"mcm","clk":"1362080612","pt":1588426308593,"mc":[{"id":"1.170370557","rc":[{"atb":[[2.72,17.55]],"id":9622734},{"atb":[[1.48,55.4]],"id":9624350}],"con":true,"img":false}]}
{"op":"mcm","clk":"1362080704","pt":1588426313789,"mc":[{"id":"1.170370557","rc":[{"atb":[[1.06,1378.54]],"id":9624350}],"con":true,"img":false}]}
{"op":"mcm","clk":"1362080711","pt":1588426314198,"mc":[{"id":"1.170370557","rc":[{"atb":[[2.72,15.46],[2.74,0]],"id":9622734},{"atl":[[3,0],[2.98,0]],"id":9622734},{"atb":[[1.5,507.89],[1.49,0],[1.05,1378.54]],"id":9624350},{"atl":[[1.59,0],[1.58,17.49]],"id":9624350}],"con":true,"img":false}]}
{"op":"mcm","clk":"1362080714","pt":1588426314402,"mc":[{"id":"1.170370557","rc":[{"atl":[[2.96,0]],"id":9622734}],"con":true,"img":false}]}
{"op":"mcm","clk":"1362080718","pt":1588426314605,"mc":[{"id":"1.170370557","rc":[{"atb":[[2.74,2.02]],"id":9622734},{"atl":[[2.96,2.12]],"id":9622734},{"atb":[[1.5,509.89],[1.04,1378.54]],"id":9624350},{"atl":[[1.58,19.62]],"id":9624350}],"con":true,"img":false}]}
{"op":"mcm","clk":"1362080725","pt":1588426314962,"mc":[{"id":"1.170370557","rc":[{"atb":[[1.03,1381.54]],"id":9624350}],"con":true,"img":false}]}
{"op":"mcm","clk":"1362080736","pt":1588426315471,"mc":[{"id":"1.170370557","rc":[{"atb":[[1.02,1380.21]],"id":9624350}],"con":true,"img":false}]}
{"op":"mcm","clk":"1362080743","pt":1588426315879,"mc":[{"id":"1.170370557","rc":[{"atb":[[1.01,1393.34]],"id":9624350}],"con":true,"img":false}]}
{"op":"mcm","clk":"1362080756","pt":1588426317004,"mc":[{"id":"1.170370557","rc":[{"atb":[[1.07,1378.54]],"id":9624350}],"con":true,"img":false}]}
{"op":"mcm","clk":"1362080814","pt":1588426320581,"mc":[{"id":"1.170370557","rc":[{"atb":[[2.78,0.11]],"id":9622734}],"con":true,"img":false}]}
{"op":"mcm","clk":"1362080818","pt":1588426320887,"mc":[{"id":"1.170370557","rc":[{"atb":[[2.74,0]],"id":9622734},{"atl":[[2.96,0]],"id":9622734},{"atb":[[1.5,507.89]],"id":9624350},{"atl":[[1.58,17.49]],"id":9624350}],"con":true,"img":false}]}
{"op":"mcm","clk":"1362080821","pt":1588426321092,"mc":[{"id":"1.170370557","rc":[{"atb":[[2.74,2.02]],"id":9622734},{"atl":[[2.96,2.12]],"id":9622734},{"atb":[[1.5,509.89]],"id":9624350},{"atl":[[1.58,19.74]],"id":9624350}],"con":true,"img":false}]}
{"op":"mcm","clk":"1362080959","pt":1588426328990,"mc":[{"id":"1.170370557","rc":[{"atb":[[1.09,1181.73]],"id":9622734}],"con":true,"img":false}]}
{"op":"mcm","clk":"1362080967","pt":1588426329298,"mc":[{"id":"1.170370557","rc":[{"atb":[[1.08,1181.73],[2.74,0]],"id":9622734},{"atl":[[2.96,0]],"id":9622734},{"atb":[[1.5,507.89]],"id":9624350},{"atl":[[1.58,17.49]],"id":9624350}],"con":true,"img":false}]}
{"op":"mcm","clk":"1362080974","pt":1588426329502,"mc":[{"id":"1.170370557","rc":[{"atb":[[2.74,2.02]],"id":9622734},{"atl":[[2.96,2.12]],"id":9622734},{"atb":[[1.5,509.89]],"id":9624350},{"atl":[[1.58,19.74]],"id":9624350}],"con":true,"img":false}]}
{"op":"mcm","clk":"1362080977","pt":1588426329706,"mc":[{"id":"1.170370557","rc":[{"atb":[[1.07,1181.73]],"id":9622734}],"con":true,"img":false}]}
{"op":"mcm","clk":"1362080986","pt":1588426330115,"mc":[{"id":"1.170370557","rc":[{"atb":[[1.06,1181.73]],"id":9622734}],"con":true,"img":false}]}
{"op":"mcm","clk":"1362080997","pt":1588426330628,"mc":[{"id":"1.170370557","rc":[{"atb":[[1.05,1181.73]],"id":9622734}],"con":true,"img":false}]}
{"op":"mcm","clk":"1362081003","pt":1588426330986,"mc":[{"id":"1.170370557","rc":[{"atb":[[1.04,1181.73]],"id":9622734}],"con":true,"img":false}]}
{"op":"mcm","clk":"1362081008","pt":1588426331395,"mc":[{"id":"1.170370557","rc":[{"atb":[[1.03,1184.73]],"id":9622734}],"con":true,"img":false}]}
{"op":"mcm","clk":"1362081017","pt":1588426331905,"mc":[{"id":"1.170370557","rc":[{"atb":[[1.02,1183.4]],"id":9622734}],"con":true,"img":false}]}
{"op":"mcm","clk":"1362081023","pt":1588426332313,"mc":[{"id":"1.170370557","rc":[{"atb":[[1.01,1196.53]],"id":9622734}],"con":true,"img":false}]}
{"op":"mcm","clk":"1362081165","pt":1588426340911,"mc":[{"id":"1.170370557","rc":[{"atb":[[1.54,54.23]],"id":9624350}],"con":true,"img":false}]}
{"op":"mcm","clk":"1362081168","pt":1588426341115,"mc":[{"id":"1.170370557","rc":[{"atb":[[1.52,19.73]],"id":9624350}],"con":true,"img":false}]}
{"op":"mcm","clk":"1362081170","pt":1588426341217,"mc":[{"id":"1.170370557","rc":[{"atb":[[2.74,0]],"id":9622734},{"atl":[[2.96,0]],"id":9622734},{"atb":[[1.5,507.89]],"id":9624350},{"atl":[[1.58,17.49]],"id":9624350}],"con":true,"img":false}]}
{"op":"mcm","clk":"1362081173","pt":1588426341423,"mc":[{"id":"1.170370557","rc":[{"atb":[[2.74,2.02]],"id":9622734},{"atl":[[2.92,2.06],[2.9,2.05]],"id":9622734},{"atb":[[1.51,7.99]],"id":9624350},{"atl":[[1.58,19.74]],"id":9624350}],"con":true,"img":false}]}
{"op":"mcm","clk":"1362081177","pt":1588426341628,"mc":[{"id":"1.170370557","rc":[{"atb":[[2.7,15.64]],"id":9622734},{"atl":[[2.94,0]],"id":9622734},{"atb":[[1.51,10.19],[1.49,54.27]],"id":9624350}],"con":true,"img":false}]}
{"op":"mcm","clk":"1362081180","pt":1588426341731,"mc":[{"id":"1.170370557","rc":[{"atb":[[2.72,0]],"id":9622734}],"con":true,"img":false}]}
{"op":"mcm","clk":"1362081440","pt":1588426357059,"mc":[{"id":"1.170370557","rc":[{"trd":[[2.92,2.06],[2.9,2.05]],"ltp":2.92,"tv":4.1,"id":9622734},{"atl":[[2.92,0],[2.9,0]],"id":9622734},{"trd":[[1.5,1015.79],[1.51,20.39],[1.53,700.3],[1.54,179.59],[1.52,48.66]],"ltp":1.5,"tv":1964.73,"id":9624350},{"atb":[[1.51,0],[1.53,0],[1.54,0],[1.5,0],[1.52,0]],"id":9624350},{"atl":[[1.5,314.4]],"id":9624350}],"con":true,"img":false}]}
{"op":"mcm","clk":"1362081445","pt":1588426357366,"mc":[{"id":"1.170370557","rc":[{"atb":[[2.74,0]],"id":9622734},{"atl":[[1.58,17.49]],"id":9624350}],"con":true,"img":false}]}
{"op":"mcm","clk":"1362081450","pt":1588426357468,"mc":[{"id":"1.170370557","rc":[{"atb":[[2.94,3.09],[2.96,2.88]],"id":9622734},{"atl":[[1.53,3.01],[1.52,3.26]],"id":9624350}],"con":true,"img":false}]}
{"op":"mcm","clk":"1362081457","pt":1588426357622,"mc":[{"id":"1.170370557","rc":[{"atb":[[1.41,199.69]],"id":9624350}],"con":true,"img":false}]}
{"op":"mcm","clk":"1362081460","pt":1588426357725,"mc":[{"id":"1.170370557","rc":[{"atb":[[2.58,0],[2.76,0]],"id":9622734},{"atb":[[1.48,0],[1.49,0],[1.47,0]],"id":9624350},{"atl":[[1.57,0]],"id":9624350}],"con":true,"img":false}]}
{"op":"mcm","clk":"1362081475","pt":1588426358647,"mc":[{"id":"1.170370557","rc":[{"atb":[[2.6,0],[2.98,13.43]],"id":9622734},{"atb":[[1.41,134.82],[1.4,66.48]],"id":9624350}],"con":true,"img":false}]}
{"op":"mcm","clk":"1362081598","pt":1588426364549,"mc":[{"id":"1.170370557","rc":[{"trd":[[3,2.12]],"ltp":3.0,"tv":2.12,"id":9622734},{"trd":[[1.5,1020.04]],"ltp":1.5,"tv":1020.04,"id":9624350},{"atl":[[1.5,310.14]],"id":9624350}],"con":true,"img":false}]}
{"op":"mcm","clk":"1362081610","pt":1588426364856,"mc":[{"id":"1.170370557","rc":[{"atb":[[2.94,0]],"id":9622734},{"atl":[[1.53,0]],"id":9624350}],"con":true,"img":false}]}
{"op":"mcm","clk":"1362081619","pt":1588426365063,"mc":[{"id":"1.170370557","rc":[{"atb":[[2.94,3.09]],"id":9622734},{"atl":[[1.53,3.01]],"id":9624350}],"con":true,"img":false}]}
{"op":"mcm","clk":"1362081644","pt":1588426365831,"mc":[{"id":"1.170370557","rc":[{"atb":[[1.43,177.3]],"id":9624350}],"con":true,"img":false}]}
{"op":"mcm","clk":"1362081670","pt":1588426366650,"mc":[{"id":"1.170370557","rc":[{"atb":[[2.96,16.45]],"id":9622734},{"atb":[[1.41,199.69]],"id":9624350}],"con":true,"img":false}]}
{"op":"mcm","clk":"1362081674","pt":1588426366751,"mc":[{"id":"1.170370557","rc":[{"atb":[[2.98,0]],"id":9622734}],"con":true,"img":false}]}
{"op":"mcm","clk":"1362081713","pt":1588426367935,"mc":[{"id":"1.170370557","rc":[{"atb":[[1.41,339.76]],"id":9624350}],"con":true,"img":false}]}
{"op":"mcm","clk":"1362081734","pt":1588426368957,"mc":[{"id":"1.170370557","rc":[{"atb":[[1.44,69.97]],"id":9624350}],"con":true,"img":false}]}
{"op":"mcm","clk":"1362081750","pt":1588426369572,"mc":[{"id":"1.170370557","rc":[{"atb":[[2.94,16.79]],"id":9622734}],"con":true,"img":false}]}
{"op":"mcm","clk":"1362081756","pt":1588426369675,"mc":[{"id":"1.170370557","rc":[{"atb":[[2.96,2.88]],"id":9622734}],"con":true,"img":false}]}
{"op":"mcm","clk":"1362081772","pt":1588426370083,"mc":[{"id":"1.170370557","rc":[{"atb":[[2.94,13.7]],"id":9622734},{"atl":[[1.53,0]],"id":9624350}],"con":true,"img":false}]}
{"op":"mcm","clk":"1362081778","pt":1588426370290,"mc":[{"id":"1.170370557","rc":[{"atb":[[2.94,16.62]],"id":9622734},{"atl":[[1.53,2.84]],"id":9624350}],"con":true,"img":false}]}
{"op":"mcm","clk":"1362081785","pt":1588426370445,"mc":[{"id":"1.170370557","rc":[{"atb":[[2.94,19.54]],"id":9622734},{"atb":[[1.41,206.71]],"id":9624350},{"atl":[[1.53,5.51]],"id":9624350}],"con":true,"img":false}]}
{"op":"mcm","clk":"1362081815","pt":1588426371471,"mc":[{"id":"1.170370557","rc":[{"atb":[[1.44,106.33]],"id":9624350}],"con":true,"img":false}]}
{"op":"mcm","clk":"1362081847","pt":1588426372755,"mc":[{"id":"1.170370557","rc":[{"atb":[[1.44,217.14]],"id":9624350}],"con":true,"img":false}]}
{"op":"mcm","clk":"1362081968","pt":1588426379273,"mc":[{"id":"1.170370557","rc":[{"atl":[[1.61,0]],"id":9624350}],"con":true,"img":false}]}
{"op":"mcm","clk":"1362081978","pt":1588426379582,"mc":[{"id":"1.170370557","rc":[{"atb":[[2.94,13.7]],"id":9622734},{"atl":[[1.53,0]],"id":9624350}],"con":true,"img":false}]}
{"op":"mcm","clk":"1362081982","pt":1588426379791,"mc":[{"id":"1.170370557","rc":[{"atb":[[2.94,16.62]],"id":9622734},{"atl":[[1.53,3.01]],"id":9624350}],"con":true,"img":false}]}
{"op":"mcm","clk":"1362081988","pt":1588426380205,"mc":[{"id":"1.170370557","rc":[{"atl":[[1.54,23.94]],"id":9624350}],"con":true,"img":false}]}
{"op":"mcm","clk":"1362082112","pt":1588426387103,"mc":[{"id":"1.170370557","rc":[{"atb":[[1.44,147.16]],"id":9624350}],"con":true,"img":false}]}
{"op":"mcm","clk":"1362082116","pt":1588426387307,"mc":[{"id":"1.170370557","rc":[{"atb":[[1.45,69.97]],"id":9624350}],"con":true,"img":false}]}
{"op":"mcm","clk":"1362082118","pt":1588426387409,"mc":[{"id":"1.170370557","rc":[{"atb":[[2.94,13.7]],"id":9622734},{"atl":[[1.53,0]],"id":9624350}],"con":true,"img":false}]}
{"op":"mcm","clk":"1362082122","pt":1588426387614,"mc":[{"id":"1.170370557","rc":[{"atb":[[2.94,16.29]],"id":9622734},{"atl":[[1.53,3.18]],"id":9624350}],"con":true,"img":false}]}
{"op":"mcm","clk":"1362082126","pt":1588426387716,"mc":[{"id":"1.170370557","rc":[{"atb":[[2.94,2.59],[2.92,13.85]],"id":9622734},{"trd":[[1.45,117.7]],"ltp":1.45,"tv":117.7,"id":9624350},{"atb":[[1.45,11.12],[1.42,63.32]],"id":9624350}],"con":true,"img":false}]}
{"op":"mcm","clk":"1362082133","pt":1588426388280,"mc":[{"id":"1.170370557","rc":[{"trd":[[1.45,117.91]],"ltp":1.45,"tv":117.91,"id":9624350},{"atb":[[1.45,11.02]],"id":9624350}],"con":true,"img":false}]}
{"op":"mcm","clk":"1362082140","pt":1588426388686,"mc":[{"id":"1.170370557","rc":[{"atb":[[2.94,16.29]],"id":9622734}],"con":true,"img":false}]}
{"op":"mcm","clk":"1362082143","pt":1588426388789,"mc":[{"id":"1.170370557","rc":[{"atb":[[1.42,0]],"id":9624350}],"con":true,"img":false}]}
{"op":"mcm","clk":"1362082179","pt":1588426390589,"mc":[{"id":"1.170370557","rc":[{"atb":[[2.98,0.11]],"id":9622734}],"con":true,"img":false}]}
{"op":"mcm","clk":"1362082200","pt":1588426392019,"mc":[{"id":"1.170370557","rc":[{"trd":[[1.5,1075.44]],"ltp":1.5,"tv":1075.44,"id":9624350},{"atl":[[1.5,282.44]],"id":9624350}],"con":true,"img":false}]}
{"op":"mcm","clk":"1362082244","pt":1588426394931,"mc":[{"id":"1.170370557","rc":[{"atl":[[1.49,69.97]],"id":9624350}],"con":true,"img":false}]}
{"op":"mcm","clk":"1362082247","pt":1588426395137,"mc":[{"id":"1.170370557","rc":[{"atl":[[1.51,3.5]],"id":9624350}],"con":true,"img":false}]}
{"op":"mcm","clk":"1362082250","pt":1588426395193,"mc":[{"id":"1.170370557","rc":[{"atb":[[2.94,13.7]],"id":9622734},{"atl":[[1.53,0]],"id":9624350}],"con":true,"img":false}]}
{"op":"mcm","clk":"1362082255","pt":1588426395511,"mc":[{"id":"1.170370557","rc":[{"atl":[[1.52,0]],"id":9624350}],"con":true,"img":false}]}
{"op":"mcm","clk":"1362082259","pt":1588426395701,"mc":[{"id":"1.170370557","rc":[{"atb":[[2.94,16.29]],"id":9622734},{"atl":[[1.52,3.26]],"id":9624350}],"con":true,"img":false}]}
{"op":"mcm","clk":"1362082514","pt":1588426415518,"mc":[{"id":"1.170370557","rc":[{"trd":[[1.49,36.42]],"ltp":1.49,"tv":36.42,"id":9624350},{"atl":[[1.49,51.76]],"id":9624350}],"con":true,"img":false}]}
{"op":"mcm","clk":"1362082517","pt":1588426415822,"mc":[{"id":"1.170370557","rc":[{"atb":[[2.94,13.7]],"id":9622734},{"atl":[[1.52,0]],"id":9624350}],"con":true,"img":false}]}
{"op":"mcm","clk":"1362082520","pt":1588426416030,"mc":[{"id":"1.170370557","rc":[{"atb":[[2.94,16.62]],"id":9622734},{"atl":[[1.52,2.76]],"id":9624350}],"con":true,"img":false}]}
{"op":"mcm","clk":"1362082593","pt":1588426421046,"mc":[{"id":"1.170370557","rc":[{"atl":[[1.54,0]],"id":9624350}],"con":true,"img":false}]}
{"op":"mcm","clk":"1362082598","pt":1588426421351,"mc":[{"id":"1.170370557","rc":[{"atb":[[2.94,13.7]],"id":9622734},{"atl":[[1.52,0]],"id":9624350}],"con":true,"img":false}]}
{"op":"mcm","clk":"1362082601","pt":1588426421557,"mc":[{"id":"1.170370557","rc":[{"atb":[[2.94,16.62]],"id":9622734},{"atl":[[1.52,2.76]],"id":9624350}],"con":true,"img":false}]}
{"op":"mcm","clk":"1362082621","pt":1588426423047,"mc":[{"id":"1.170370557","rc":[{"trd":[[1.49,40.5]],"ltp":1.49,"tv":40.5,"id":9624350},{"atl":[[1.49,49.72]],"id":9624350}],"con":true,"img":false}]}
{"op":"mcm","clk":"1362082715","pt":1588426429561,"mc":[{"id":"1.170370557","rc":[{"trd":[[1.49,45.3]],"ltp":1.49,"tv":45.3,"id":9624350},{"atl":[[1.49,47.32]],"id":9624350}],"con":true,"img":false}]}
{"op":"mcm","clk":"1362082720","pt":1588426429868,"mc":[{"id":"1.170370557","rc":[{"atb":[[2.94,13.7]],"id":9622734},{"atl":[[1.52,0]],"id":9624350}],"con":true,"img":false}]}
{"op":"mcm","clk":"1362082723","pt":1588426430071,"mc":[{"id":"1.170370557","rc":[{"atb":[[2.94,16.62]],"id":9622734},{"atl":[[1.52,2.76]],"id":9624350}],"con":true,"img":false}]}
{"op":"mcm","clk":"1362082748","pt":1588426432170,"mc":[{"id":"1.170370557","rc":[{"atb":[[1.45,63.5]],"id":9624350}],"con":true,"img":false}]}
{"op":"mcm","clk":"1362082754","pt":1588426432633,"mc":[{"id":"1.170370557","rc":[{"atb":[[1.42,63.32]],"id":9624350}],"con":true,"img":false}]}
{"op":"mcm","clk":"1362082756","pt":1588426432735,"mc":[{"id":"1.170370557","rc":[{"atb":[[2.94,2.92]],"id":9622734}],"con":true,"img":false}]}
{"op":"mcm","clk":"1362082766","pt":1588426433246,"mc":[{"id":"1.170370557","rc":[{"atl":[[1.54,23.94]],"id":9624350}],"con":true,"img":false}]}
{"op":"mcm","clk":"1362082890","pt":1588426442063,"mc":[{"id":"1.170370557","rc":[{"atb":[[1.45,240.8]],"id":9624350}],"con":true,"img":false}]}
{"op":"mcm","clk":"1362082895","pt":1588426442376,"mc":[{"id":"1.170370557","rc":[{"atb":[[2.94,0]],"id":9622734},{"atl":[[1.52,0]],"id":9624350}],"con":true,"img":false}]}
{"op":"mcm","clk":"1362082899","pt":1588426442582,"mc":[{"id":"1.170370557","rc":[{"atb":[[2.94,2.92]],"id":9622734},{"atl":[[1.52,2.76]],"id":9624350}],"con":true,"img":false}]}
{"op":"mcm","clk":"1362082909","pt":1588426443195,"mc":[{"id":"1.170370557","rc":[{"atl":[[1.49,224.63]],"id":9624350}],"con":true,"img":false}]}
{"op":"mcm","clk":"1362082948","pt":1588426445963,"mc":[{"id":"1.170370557","rc":[{"atl":[[1.48,24.91]],"id":9624350}],"con":true,"img":false}]}
{"op":"mcm","clk":"1362082950","pt":1588426446169,"mc":[{"id":"1.170370557","rc":[{"atb":[[2.98,2.87]],"id":9622734},{"atl":[[1.5,285.15]],"id":9624350}],"con":true,"img":false}]}
{"op":"mcm","clk":"1362082954","pt":1588426446475,"mc":[{"id":"1.170370557","rc":[{"atb":[[2.96,0]],"id":9622734},{"atl":[[1.51,0]],"id":9624350}],"con":true,"img":false}]}
{"op":"mcm","clk":"1362082956","pt":1588426446578,"mc":[{"id":"1.170370557","rc":[{"atb":[[2.96,13.57]],"id":9622734}],"con":true,"img":false}]}
{"op":"mcm","clk":"1362082959","pt":1588426446678,"mc":[{"id":"1.170370557","rc":[{"atb":[[2.96,16.2]],"id":9622734},{"atl":[[1.51,3.01]],"id":9624350}],"con":true,"img":false}]}
{"op":"mcm","clk":"1362082962","pt":1588426446783,"mc":[{"id":"1.170370557","rc":[{"atb":[[1.42,0]],"id":9624350}],"con":true,"img":false}]}
{"op":"mcm","clk":"1362082970","pt":1588426447306,"mc":[{"id":"1.170370557","rc":[{"trd":[[1.48,9.68]],"ltp":1.48,"tv":9.68,"id":9624350},{"atl":[[1.48,22.07],[1.54,0]],"id":9624350}],"con":true,"img":false}]}
{"op":"mcm","clk":"1362082972","pt":1588426447402,"mc":[{"id":"1.170370557","rc":[{"atb":[[2.98,2.76]],"id":9622734}],"con":true,"img":false}]}
{"op":"mcm","clk":"1362082975","pt":1588426447604,"mc":[{"id":"1.170370557","rc":[{"atb":[[2.94,0]],"id":9622734},{"atl":[[1.52,0]],"id":9624350}],"con":true,"img":false}]}
{"op":"mcm","clk":"1362082980","pt":1588426448013,"mc":[{"id":"1.170370557","rc":[{"trd":[[1.45,206.56]],"ltp":1.45,"tv":206.56,"id":9624350},{"atb":[[1.45,196.48]],"id":9624350}],"con":true,"img":false}]}
{"op":"mcm","clk":"1362083004","pt":1588426449609,"mc":[{"id":"1.170370557","rc":[{"atb":[[2.78,0]],"id":9622734}],"con":true,"img":false}]}
{"op":"mcm","clk":"1362083036","pt":1588426451705,"mc":[{"id":"1.170370557","rc":[{"atb":[[1.46,0.53]],"id":9624350}],"con":true,"img":false}]}
{"op":"mcm","clk":"1362083040","pt":1588426452011,"mc":[{"id":"1.170370557","rc":[{"atb":[[2.96,13.57]],"id":9622734},{"atl":[[1.51,0]],"id":9624350}],"con":true,"img":false}]}
{"op":"mcm","clk":"1362083043","pt":1588426452215,"mc":[{"id":"1.170370557","rc":[{"atb":[[2.96,16.45]],"id":9622734},{"atl":[[1.51,3.01]],"id":9624350}],"con":true,"img":false}]}
{"op":"mcm","clk":"1362083210","pt":1588426461889,"mc":[{"id":"1.170370557","rc":[{"atl":[[1.48,92.05]],"id":9624350}],"con":true,"img":false}]}
{"op":"mcm","clk":"1362083214","pt":1588426462199,"mc":[{"id":"1.170370557","rc":[{"atb":[[2.96,13.57]],"id":9622734},{"atl":[[1.51,0]],"id":9624350}],"con":true,"img":false}]}
{"op":"mcm","clk":"1362083220","pt":1588426462403,"mc":[{"id":"1.170370557","rc":[{"atb":[[2.96,16.45]],"id":9622734},{"atl":[[1.51,3.01]],"id":9624350}],"con":true,"img":false}]}
{"op":"mcm","clk":"1362083225","pt":1588426462607,"mc":[{"id":"1.170370557","rc":[{"atl":[[1.83,0.11]],"id":9624350}],"con":true,"img":false}]}
{"op":"mcm","clk":"1362083256","pt":1588426463992,"mc":[{"id":"1.170370557","rc":[{"atl":[[2,50]],"id":9624350}],"con":true,"img":false}]}
{"op":"mcm","clk":"1362083314","pt":1588426467021,"mc":[{"id":"1.170370557","rc":[{"atl":[[1000,1.45]],"id":9622734}],"con":true,"img":false}]}
{"op":"mcm","clk":"1362083338","pt":1588426468108,"mc":[{"id":"1.170370557","rc":[{"atl":[[1.49,177.3]],"id":9624350}],"con":true,"img":false}]}
{"op":"mcm","clk":"1362083345","pt":1588426468415,"mc":[{"id":"1.170370557","rc":[{"atb":[[2.96,13.57]],"id":9622734},{"atl":[[1.51,0]],"id":9624350}],"con":true,"img":false}]}
{"op":"mcm","clk":"1362083348","pt":1588426468618,"mc":[{"id":"1.170370557","rc":[{"atb":[[2.96,16.2]],"id":9622734},{"atl":[[1.51,3.01]],"id":9624350}],"con":true,"img":false}]}
{"op":"mcm","clk":"1362083363","pt":1588426469233,"mc":[{"id":"1.170370557","rc":[{"atl":[[1.58,0]],"id":9624350}],"con":true,"img":false}]}
{"op":"mcm","clk":"1362083392","pt":1588426471234,"mc":[{"id":"1.170370557","rc":[{"trd":[[1.48,48.45]],"ltp":1.48,"tv":48.45,"id":9624350},{"atl":[[1.48,72.66]],"id":9624350}],"con":true,"img":false}]}
{"op":"mcm","clk":"1362083430","pt":1588426473701,"mc":[{"id":"1.170370557","rc":[{"trd":[[1.48,118.45]],"ltp":1.48,"tv":118.45,"id":9624350},{"atl":[[1.48,37.66]],"id":9624350}],"con":true,"img":false}]}
{"op":"mcm","clk":"1362083434","pt":1588426474010,"mc":[{"id":"1.170370557","rc":[{"atb":[[2.96,13.57]],"id":9622734},{"atl":[[1.51,0]],"id":9624350}],"con":true,"img":false}]}
{"op":"mcm","clk":"1362083439","pt":1588426474212,"mc":[{"id":"1.170370557","rc":[{"atb":[[2.96,16.7]],"id":9622734},{"atl":[[1.51,3.01]],"id":9624350}],"con":true,"img":false}]}
{"op":"mcm","clk":"1362083447","pt":1588426474627,"mc":[{"id":"1.170370557","rc":[{"atb":[[1.46,35.31]],"id":9624350}],"con":true,"img":false}]}
{"op":"mcm","clk":"1362083461","pt":1588426475545,"mc":[{"id":"1.170370557","rc":[{"atb":[[2.94,3.44]],"id":9622734}],"con":true,"img":false}]}
{"op":"mcm","clk":"1362083507","pt":1588426477919,"mc":[{"id":"1.170370557","rc":[{"atl":[[1.48,36.7]],"id":9624350}],"con":true,"img":false}]}
{"op":"mcm","clk":"1362083558","pt":1588426480734,"mc":[{"id":"1.170370557","rc":[{"atl":[[1000,2.47]],"id":9622734}],"con":true,"img":false}]}
{"op":"mcm","clk":"1362083568","pt":1588426481043,"mc":[{"id":"1.170370557","rc":[{"atb":[[2.96,13.57]],"id":9622734},{"atl":[[1.51,0]],"id":9624350}],"con":true,"img":false}]}
{"op":"mcm","clk":"1362083574","pt":1588426481249,"mc":[{"id":"1.170370557","rc":[{"atb":[[2.96,16.21]],"id":9622734},{"atl":[[1.51,3.01]],"id":9624350}],"con":true,"img":false}]}
{"op":"mcm","clk":"1362083593","pt":1588426482020,"mc":[{"id":"1.170370557","rc":[{"trd":[[1.48,191.86]],"ltp":1.48,"tv":191.86,"id":9624350},{"atb":[[1.48,35.28]],"id":9624350},{"atl":[[1.48,0]],"id":9624350}],"con":true,"img":false}]}
{"op":"mcm","clk":"1362083600","pt":1588426482225,"mc":[{"id":"1.170370557","rc":[{"atl":[[1.52,3.01]],"id":9624350}],"con":true,"img":false}]}
{"op":"mcm","clk":"1362083604","pt":1588426482329,"mc":[{"id":"1.170370557","rc":[{"atl":[[1.5,282.44]],"id":9624350}],"con":true,"img":false}]}
{"op":"mcm","clk":"1362083606","pt":1588426482433,"mc":[{"id":"1.170370557","rc":[{"atb":[[2.98,0],[2.94,6.36]],"id":9622734}],"con":true,"img":false}]}
{"op":"mcm","clk":"1362083611","pt":1588426482740,"mc":[{"id":"1.170370557","rc":[{"atb":[[2.96,2.64]],"id":9622734},{"atb":[[1.43,239.15]],"id":9624350}],"con":true,"img":false}]}
{"op":"mcm","clk":"1362083631","pt":1588426483454,"mc":[{"id":"1.170370557","rc":[{"trd":[[1.49,399.91]],"ltp":1.49,"tv":399.91,"id":9624350},{"atl":[[1.49,0]],"id":9624350}],"con":true,"img":false}]}
{"op":"mcm","clk":"1362083639","pt":1588426483658,"mc":[{"id":"1.170370557","rc":[{"atl":[[1.53,2.84]],"id":9624350}],"con":true,"img":false}]}
{"op":"mcm","clk":"1362083642","pt":1588426483762,"mc":[{"id":"1.170370557","rc":[{"atl":[[1.51,0]],"id":9624350}],"con":true,"img":false}]}
{"op":"mcm","clk":"1362083865","pt":1588426495459,"mc":[{"id":"1.170370557","rc":[{"atl":[[1.51,295.21]],"id":9624350}],"con":true,"img":false}]}
{"op":"mcm","clk":"1362083871","pt":1588426495768,"mc":[{"id":"1.170370557","rc":[{"atb":[[2.94,3.44]],"id":9622734},{"atl":[[1.53,0]],"id":9624350}],"con":true,"img":false}]}
{"op":"mcm","clk":"1362083876","pt":1588426495973,"mc":[{"id":"1.170370557","rc":[{"atb":[[2.94,6.53]],"id":9622734},{"atl":[[1.53,3.18]],"id":9624350}],"con":true,"img":false}]}
{"op":"mcm","clk":"1362083890","pt":1588426496642,"mc":[{"id":"1.170370557","rc":[{"atl":[[1.51,0]],"id":9624350}],"con":true,"img":false}]}
{"op":"mcm","clk":"1362083904","pt":1588426497255,"mc":[{"id":"1.170370557","rc":[{"atb":[[1.01,1199.12]],"id":9622734}],"con":true,"img":false}]}
{"op":"mcm","clk":"1362083925","pt":1588426498177,"mc":[{"id":"1.170370557","rc":[{"atb":[[1.01,1196.54]],"id":9622734},{"atl":[[1000,0]],"id":9622734}],"con":true,"img":false}]}
{"op":"mcm","clk":"1362083928","pt":1588426498275,"mc":[{"id":"1.170370557","rc":[{"atl":[[3.2,1.02]],"id":9622734}],"con":true,"img":false}]}
{"op":"mcm","clk":"1362083941","pt":1588426498841,"mc":[{"id":"1.170370557","rc":[{"atb":[[1.47,295.21]],"id":9624350}],"con":true,"img":false}]}
{"op":"mcm","clk":"1362083945","pt":1588426499047,"mc":[{"id":"1.170370557","rc":[{"atb":[[1.01,1196.53]],"id":9622734}],"con":true,"img":false}]}
{"op":"mcm","clk":"1362083947","pt":1588426499149,"mc":[{"id":"1.170370557","rc":[{"trd":[[3.1,0.01]],"ltp":3.1,"tv":0.01,"id":9622734},{"trd":[[1.48,191.89]],"ltp":1.48,"tv":191.89,"id":9624350},{"atb":[[1.48,35.25]],"id":9624350}],"con":true,"img":false}]}
{"op":"mcm","clk":"1362083958","pt":1588426499661,"mc":[{"id":"1.170370557","rc":[{"atb":[[2.92,0],[2.9,13.99]],"id":9622734}],"con":true,"img":false}]}
{"op":"mcm","clk":"1362083964","pt":1588426499971,"mc":[{"id":"1.170370557","rc":[{"atl":[[1.49,27.99]],"id":9624350}],"con":true,"img":false}]}
{"op":"mcm","clk":"1362083967","pt":1588426500174,"mc":[{"id":"1.170370557","rc":[{"atl":[[1.51,3.05]],"id":9624350}],"con":true,"img":false}]}
{"op":"mcm","clk":"1362083972","pt":1588426500478,"mc":[{"id":"1.170370557","rc":[{"atl":[[1.52,0]],"id":9624350}],"con":true,"img":false}]}
{"op":"mcm","clk":"1362083976","pt":1588426500684,"mc":[{"id":"1.170370557","rc":[{"atb":[[1.47,0]],"id":9624350}],"con":true,"img":false}]}
{"op":"mcm","clk":"1362083978","pt":1588426500787,"mc":[{"id":"1.170370557","rc":[{"atb":[[2.94,3.44]],"id":9622734},{"atl":[[1.53,0]],"id":9624350}],"con":true,"img":false}]}
{"op":"mcm","clk":"1362083981","pt":1588426500840,"mc":[{"id":"1.170370557","rc":[{"atb":[[1.48,68.58]],"id":9624350}],"con":true,"img":false}]}
{"op":"mcm","clk":"1362083983","pt":1588426500943,"mc":[{"id":"1.170370557","rc":[{"atb":[[2.94,6.53]],"id":9622734},{"trd":[[1.5,1087.46],[1.49,455.89]],"ltp":1.5,"tv":1543.35,"id":9624350},{"atl":[[1.5,276.43],[1.49,0],[1.52,3.26]],"id":9624350}],"con":true,"img":false}]}
{"op":"mcm","clk":"1362083985","pt":1588426501044,"mc":[{"id":"1.170370557","rc":[{"atl":[[1.53,2.67]],"id":9624350}],"con":true,"img":false}]}
{"op":"mcm","clk":"1362083988","pt":1588426501147,"mc":[{"id":"1.170370557","rc":[{"atl":[[1.51,0]],"id":9624350}],"con":true,"img":false}]}
{"op":"mcm","clk":"1362083997","pt":1588426501644,"mc":[{"id":"1.170370557","rc":[{"atb":[[2.88,14.14]],"id":9622734}],"con":true,"img":false}]}
{"op":"mcm","clk":"1362084001","pt":1588426501847,"mc":[{"id":"1.170370557","rc":[{"atb":[[2.9,0]],"id":9622734}],"con":true,"img":false}]}
{"op":"mcm","clk":"1362084036","pt":1588426503752,"mc":[{"id":"1.170370557","rc":[{"atb":[[1.48,35.25]],"id":9624350}],"con":true,"img":false}]}
{"op":"mcm","clk":"1362084061","pt":1588426504783,"mc":[{"id":"1.170370557","rc":[{"atb":[[2.92,13.85]],"id":9622734}],"con":true,"img":false}]}
{"op":"mcm","clk":"1362084074","pt":1588426505397,"mc":[{"id":"1.170370557","rc":[{"atb":[[1.46,34.77]],"id":9624350}],"con":true,"img":false}]}
{"op":"mcm","clk":"1362084081","pt":1588426505659,"mc":[{"id":"1.170370557","rc":[{"atb":[[2.94,3.44]],"id":9622734}],"con":true,"img":false}]}
{"op":"mcm","clk":"1362084086","pt":1588426505865,"mc":[{"id":"1.170370557","rc":[{"atb":[[2.94,6.36]],"id":9622734},{"atb":[[1.49,11.52]],"id":9624350}],"con":true,"img":false}]}
{"op":"mcm","clk":"1362084094","pt":1588426506171,"mc":[{"id":"1.170370557","rc":[{"trd":[[3.05,5.62]],"ltp":3.05,"tv":5.62,"id":9622734},{"atb":[[3.05,0]],"id":9622734},{"trd":[[1.49,467.41]],"ltp":1.49,"tv":467.41,"id":9624350},{"atb":[[1.49,0]],"id":9624350}],"con":true,"img":false}]}
{"op":"mcm","clk":"1362084102","pt":1588426506479,"mc":[{"id":"1.170370557","rc":[{"atb":[[3.05,0]],"id":9622734},{"atl":[[1.53,0]],"id":9624350}],"con":true,"img":false}]}
{"op":"mcm","clk":"1362084105","pt":1588426506685,"mc":[{"id":"1.170370557","rc":[{"atl":[[1.53,2.84]],"id":9624350}],"con":true,"img":false}]}
{"op":"mcm","clk":"1362084107","pt":1588426506786,"mc":[{"id":"1.170370557","rc":[{"trd":[[1.5,1092.78]],"ltp":1.5,"tv":1092.78,"id":9624350},{"atl":[[1.5,273.77]],"id":9624350}],"con":true,"img":false}]}
{"op":"mcm","clk":"1362084189","pt":1588426510573,"mc":[{"id":"1.170370557","rc":[{"atb":[[1.1,124.78]],"id":9622734}],"con":true,"img":false}]}
{"op":"mcm","clk":"1362084244","pt":1588426513289,"mc":[{"id":"1.170370557","rc":[{"atb":[[1.48,0]],"id":9624350}],"con":true,"img":false}]}
{"op":"mcm","clk":"1362084252","pt":1588426513694,"mc":[{"id":"1.170370557","rc":[{"atb":[[1.43,177.3],[1.42,63.32]],"id":9624350}],"con":true,"img":false}]}
{"op":"mcm","clk":"1362084288","pt":1588426516198,"mc":[{"id":"1.170370557","rc":[{"atb":[[1.1,125.57]],"id":9622734}],"con":true,"img":false}]}
{"op":"mcm","clk":"1362084323","pt":1588426518819,"mc":[{"id":"1.170370557","rc":[{"trd":[[3,2.41]],"ltp":3.0,"tv":2.41,"id":9622734},{"trd":[[1.5,1093.34]],"ltp":1.5,"tv":1093.34,"id":9624350},{"atl":[[1.5,273.2]],"id":9624350}],"con":true,"img":false}]}
{"op":"mcm","clk":"1362084344","pt":1588426520203,"mc":[{"id":"1.170370557","rc":[{"trd":[[1.46,69.55]],"ltp":1.46,"tv":69.55,"id":9624350},{"atb":[[1.46,0]],"id":9624350},{"atl":[[1.46,15.22]],"id":9624350}],"con":true,"img":false}]}
{"op":"mcm","clk":"1362084348","pt":1588426520406,"mc":[{"id":"1.170370557","rc":[{"trd":[[1.46,100]],"ltp":1.46,"tv":100.0,"id":9624350},{"atb":[[1.46,0.02]],"id":9624350},{"atl":[[1.46,0]],"id":9624350}],"con":true,"img":false}]}
{"op":"mcm","clk":"1362084354","pt":1588426520715,"mc":[{"id":"1.170370557","rc":[{"atb":[[1.1,122.38]],"id":9622734},{"atb":[[1.46,0]],"id":9624350}],"con":true,"img":false}]}
{"op":"mcm","clk":"1362084359","pt":1588426521021,"mc":[{"id":"1.170370557","rc":[{"atb":[[1.46,52.48]],"id":9624350}],"con":true,"img":false}]}
{"op":"mcm","clk":"1362084367","pt":1588426521380,"mc":[{"id":"1.170370557","rc":[{"atb":[[3.1,0.11]],"id":9622734}],"con":true,"img":false}]}
{"op":"mcm","clk":"1362084377","pt":1588426521993,"mc":[{"id":"1.170370557","rc":[{"atl":[[1.49,34.07]],"id":9624350}],"con":true,"img":false}]}
{"op":"mcm","clk":"1362084405","pt":1588426523481,"mc":[{"id":"1.170370557","rc":[{"atl":[[1.49,70.55]],"id":9624350}],"con":true,"img":false}]}
{"op":"mcm","clk":"1362084410","pt":1588426523792,"mc":[{"id":"1.170370557","rc":[{"atb":[[1.1,121.58]],"id":9622734}],"con":true,"img":false}]}
{"op":"mcm","clk":"1362084503","pt":1588426529222,"mc":[{"id":"1.170370557","rc":[{"atb":[[1.46,124.47]],"id":9624350}],"con":true,"img":false}]}
{"op":"mcm","clk":"1362084552","pt":1588426531829,"mc":[{"id":"1.170370557","rc":[{"atl":[[1.83,0]],"id":9624350}],"con":true,"img":false}]}
{"op":"mcm","clk":"1362084596","pt":1588426534442,"mc":[{"id":"1.170370557","rc":[{"trd":[[1.46,104]],"ltp":1.46,"tv":104.0,"id":9624350},{"atb":[[1.46,122.47]],"id":9624350}],"con":true,"img":false}]}
{"op":"mcm","clk":"1362084610","pt":1588426535315,"mc":[{"id":"1.170370557","rc":[{"atb":[[1.1,124.78]],"id":9622734}],"con":true,"img":false}]}
{"op":"mcm","clk":"1362084712","pt":1588426541515,"mc":[{"id":"1.170370557","rc":[{"atb":[[1.1,125.57]],"id":9622734}],"con":true,"img":false}]}
{"op":"mcm","clk":"1362084773","pt":1588426545046,"mc":[{"id":"1.170370557","rc":[{"atb":[[1.1,122.38]],"id":9622734}],"con":true,"img":false}]}
{"op":"mcm","clk":"1362084805","pt":1588426547452,"mc":[{"id":"1.170370557","rc":[{"atb":[[1.1,121.58]],"id":9622734}],"con":true,"img":false}]}
{"op":"mcm","clk":"1362084820","pt":1588426548374,"mc":[{"id":"1.170370557","rc":[{"atb":[[1.47,179.7]],"id":9624350}],"con":true,"img":false}]}
{"op":"mcm","clk":"1362084826","pt":1588426548631,"mc":[{"id":"1.170370557","rc":[{"atb":[[2.92,0],[2.9,13.99]],"id":9622734},{"atb":[[1.4,0]],"id":9624350}],"con":true,"img":false}]}
{"op":"mcm","clk":"1362084839","pt":1588426549755,"mc":[{"id":"1.170370557","rc":[{"atb":[[1.43,239.15]],"id":9624350}],"con":true,"img":false}]}
{"op":"mcm","clk":"1362084846","pt":1588426550166,"mc":[{"id":"1.170370557","rc":[{"atl":[[1.49,247.86]],"id":9624350}],"con":true,"img":false}]}
{"op":"mcm","clk":"1362084926","pt":1588426554673,"mc":[{"id":"1.170370557","rc":[{"atb":[[1.47,357.01]],"id":9624350}],"con":true,"img":false}]}
{"op":"mcm","clk":"1362084987","pt":1588426558153,"mc":[{"id":"1.170370557","rc":[{"atb":[[1.1,124.78]],"id":9622734}],"con":true,"img":false}]}
{"op":"mcm","clk":"1362085008","pt":1588426559076,"mc":[{"id":"1.170370557","rc":[{"atl":[[1.64,177.3]],"id":9624350}],"con":true,"img":false}]}
{"op":"mcm","clk":"1362085063","pt":1588426561990,"mc":[{"id":"1.170370557","rc":[{"trd":[[3.1,0.12]],"ltp":3.1,"tv":0.12,"id":9622734},{"atb":[[3.1,0]],"id":9622734},{"trd":[[1.49,477.49],[1.48,192.13]],"ltp":1.49,"tv":669.62,"id":9624350},{"atl":[[1.49,242.82]],"id":9624350}],"con":true,"img":false}]}
{"op":"mcm","clk":"1362085068","pt":1588426562348,"mc":[{"id":"1.170370557","rc":[{"atb":[[2.94,3.44],[2.96,0]],"id":9622734},{"atl":[[1.53,0],[1.52,0]],"id":9624350}],"con":true,"img":false}]}
{"op":"mcm","clk":"1362085076","pt":1588426562655,"mc":[{"id":"1.170370557","rc":[{"atb":[[1.48,0.53]],"id":9624350},{"atl":[[1.5,0]],"id":9624350}],"con":true,"img":false}]}
{"op":"mcm","clk":"1362085078","pt":1588426562759,"mc":[{"id":"1.170370557","rc":[{"trd":[[1.47,545.35],[1.48,193.2]],"ltp":1.47,"tv":738.55,"id":9624350},{"atb":[[1.48,0],[1.47,84.33]],"id":9624350}],"con":true,"img":false}]}
{"op":"mcm","clk":"1362085140","pt":1588426566152,"mc":[{"id":"1.170370557","rc":[{"atb":[[1.44,36.35],[1.41,66.64]],"id":9624350},{"atl":[[1.52,177.3]],"id":9624350}],"con":true,"img":false}]}
{"op":"mcm","clk":"1362085155","pt":1588426567176,"mc":[{"id":"1.170370557","rc":[{"atb":[[1.1,125.73]],"id":9622734}],"con":true,"img":false}]}
{"op":"mcm","clk":"1362085218","pt":1588426571577,"mc":[{"id":"1.170370557","rc":[{"atb":[[1.1,122.54]],"id":9622734}],"con":true,"img":false}]}
{"op":"mcm","clk":"1362085241","pt":1588426573163,"mc":[{"id":"1.170370557","rc":[{"atb":[[2.94,0]],"id":9622734},{"trd":[[1.49,521.49]],"ltp":1.49,"tv":521.49,"id":9624350},{"atl":[[1.49,220.82]],"id":9624350}],"con":true,"img":false}]}
{"op":"mcm","clk":"1362085415","pt":1588426582685,"mc":[{"id":"1.170370557","rc":[{"atb":[[1.3,1187.45]],"id":9624350}],"con":true,"img":false}]}
{"op":"mcm","clk":"1362085482","pt":1588426585914,"mc":[{"id":"1.170370557","rc":[{"trd":[[1.49,576.89]],"ltp":1.49,"tv":576.89,"id":9624350},{"atl":[[1.49,193.12]],"id":9624350}],"con":true,"img":false}]}
{"op":"mcm","clk":"1362085584","pt":1588426591026,"mc":[{"id":"1.170370557","rc":[{"atb":[[1.46,157.24]],"id":9624350}],"con":true,"img":false}]}
{"op":"mcm","clk":"1362085669","pt":1588426595129,"mc":[{"id":"1.170370557","rc":[{"atl":[[1.56,201.92]],"id":9624350}],"con":true,"img":false}]}
{"op":"mcm","clk":"1362085677","pt":1588426595536,"mc":[{"id":"1.170370557","rc":[{"atb":[[2.94,3.44]],"id":9622734}],"con":true,"img":false}]}
{"op":"mcm","clk":"1362085730","pt":1588426598009,"mc":[{"id":"1.170370557","rc":[{"atl":[[1.56,201.21]],"id":9624350}],"con":true,"img":false}]}
{"op":"mcm","clk":"1362085820","pt":1588426602416,"mc":[{"id":"1.170370557","rc":[{"trd":[[1.49,581.68]],"ltp":1.49,"tv":581.68,"id":9624350},{"atl":[[1.49,190.72]],"id":9624350}],"con":true,"img":false}]}
{"op":"mcm","clk":"1362086021","pt":1588426611733,"mc":[{"id":"1.170370557","rc":[{"trd":[[1.49,623.69]],"ltp":1.49,"tv":623.69,"id":9624350},{"atl":[[1.49,169.72]],"id":9624350}],"con":true,"img":false}]}
{"op":"mcm","clk":"1362086029","pt":1588426612160,"mc":[{"id":"1.170370557","rc":[{"atb":[[1.31,204.71]],"id":9624350}],"con":true,"img":false}]}
{"op":"mcm","clk":"1362086112","pt":1588426615543,"mc":[{"id":"1.170370557","rc":[{"atl":[[1.78,0.71]],"id":9624350}],"con":true,"img":false}]}
{"op":"mcm","clk":"1362086186","pt":1588426621070,"mc":[{"id":"1.170370557","rc":[{"atb":[[1.48,71.98]],"id":9624350}],"con":true,"img":false}]}
{"op":"mcm","clk":"1362086201","pt":1588426621847,"mc":[{"id":"1.170370557","rc":[{"atb":[[2.9,0]],"id":9622734}],"con":true,"img":false}]}
{"op":"mcm","clk":"1362086221","pt":1588426622776,"mc":[{"id":"1.170370557","rc":[{"trd":[[1.49,624.25]],"ltp":1.49,"tv":624.25,"id":9624350},{"atl":[[1.49,169.44]],"id":9624350}],"con":true,"img":false}]}
{"op":"mcm","clk":"1362086273","pt":1588426625861,"mc":[{"id":"1.170370557","rc":[{"trd":[[3,86.56]],"ltp":3.0,"tv":86.56,"id":9622734},{"atl":[[3,580.73]],"id":9622734},{"trd":[[1.49,793.7]],"ltp":1.49,"tv":793.7,"id":9624350},{"atl":[[1.49,0]],"id":9624350}],"con":true,"img":false}]}
{"op":"mcm","clk":"1362086279","pt":1588426626065,"mc":[{"id":"1.170370557","rc":[{"trd":[[2.94,6.89]],"ltp":2.94,"tv":6.89,"id":9622734},{"atb":[[2.94,0]],"id":9622734}],"con":true,"img":false}]}
{"op":"mcm","clk":"1362086291","pt":1588426626680,"mc":[{"id":"1.170370557","rc":[{"atb":[[2.82,14.6]],"id":9622734}],"con":true,"img":false}]}
{"op":"mcm","clk":"1362086294","pt":1588426626883,"mc":[{"id":"1.170370557","rc":[{"atb":[[2.88,0]],"id":9622734},{"atb":[[1.41,1.77]],"id":9624350}],"con":true,"img":false}]}
{"op":"mcm","clk":"1362086306","pt":1588426627778,"mc":[{"id":"1.170370557","rc":[{"atb":[[1.45,255.58]],"id":9624350}],"con":true,"img":false}]}
{"op":"mcm","clk":"1362086339","pt":1588426630055,"mc":[{"id":"1.170370557","rc":[{"atb":[[1.49,69]],"id":9624350}],"con":true,"img":false}]}
{"op":"mcm","clk":"1362086445","pt":1588426635080,"mc":[{"id":"1.170370557","rc":[{"trd":[[1.52,346.21]],"ltp":1.52,"tv":346.21,"id":9624350},{"atl":[[1.52,28.52]],"id":9624350}],"con":true,"img":false}]}
{"op":"mcm","clk":"1362086463","pt":1588426635796,"mc":[{"id":"1.170370557","rc":[{"atb":[[1.42,0]],"id":9624350}],"con":true,"img":false}]}
{"op":"mcm","clk":"1362086491","pt":1588426636777,"mc":[{"id":"1.170370557","rc":[{"atb":[[1.46,215.06]],"id":9624350}],"con":true,"img":false}]}
{"op":"mcm","clk":"1362086499","pt":1588426637082,"mc":[{"id":"1.170370557","rc":[{"atb":[[1.51,31.37]],"id":9624350}],"con":true,"img":false}]}
{"op":"mcm","clk":"1362086502","pt":1588426637184,"mc":[{"id":"1.170370557","rc":[{"atl":[[1.78,0]],"id":9624350}],"con":true,"img":false}]}
{"op":"mcm","clk":"1362086506","pt":1588426637288,"mc":[{"id":"1.170370557","rc":[{"trd":[[1.52,403.27]],"ltp":1.52,"tv":403.27,"id":9624350},{"atb":[[1.52,24.64]],"id":9624350},{"atl":[[1.52,0]],"id":9624350}],"con":true,"img":false}]}
{"op":"mcm","clk":"1362086511","pt":1588426637594,"mc":[{"id":"1.170370557","rc":[{"atb":[[1.52,0]],"id":9624350}],"con":true,"img":false}]}
{"op":"mcm","clk":"1362086516","pt":1588426637798,"mc":[{"id":"1.170370557","rc":[{"atb":[[2.82,0],[2.74,15.28]],"id":9622734},{"atb":[[1.43,177.3]],"id":9624350}],"con":true,"img":false}]}
{"op":"mcm","clk":"1362086535","pt":1588426638669,"mc":[{"id":"1.170370557","rc":[{"atb":[[1.47,140.92]],"id":9624350}],"con":true,"img":false}]}
{"op":"mcm","clk":"1362086543","pt":1588426638977,"mc":[{"id":"1.170370557","rc":[{"atb":[[1.49,0]],"id":9624350}],"con":true,"img":false}]}
{"op":"mcm","clk":"1362086546","pt":1588426639077,"mc":[{"id":"1.170370557","rc":[{"atb":[[1.52,69]],"id":9624350}],"con":true,"img":false}]}
{"op":"mcm","clk":"1362086560","pt":1588426639691,"mc":[{"id":"1.170370557","rc":[{"atb":[[2.72,15.46]],"id":9622734}],"con":true,"img":false}]}
{"op":"mcm","clk":"1362086566","pt":1588426639896,"mc":[{"id":"1.170370557","rc":[{"atb":[[2.74,0]],"id":9622734},{"atb":[[1.45,196.48]],"id":9624350}],"con":true,"img":false}]}
{"op":"mcm","clk":"1362086582","pt":1588426640666,"mc":[{"id":"1.170370557","rc":[{"atb":[[1.48,127.39]],"id":9624350}],"con":true,"img":false}]}
{"op":"mcm","clk":"1362086592","pt":1588426641173,"mc":[{"id":"1.170370557","rc":[{"atl":[[3.2,0]],"id":9622734}],"con":true,"img":false}]}
{"op":"mcm","clk":"1362086688","pt":1588426645523,"mc":[{"id":"1.170370557","rc":[{"atl":[[3,581.02]],"id":9622734}],"con":true,"img":false}]}
{"op":"mcm","clk":"1362086765","pt":1588426649310,"mc":[{"id":"1.170370557","rc":[{"atl":[[1.53,58]],"id":9624350}],"con":true,"img":false}]}
{"op":"mcm","clk":"1362086775","pt":1588426649818,"mc":[{"id":"1.170370557","rc":[{"atb":[[2.78,14.93]],"id":9622734}],"con":true,"img":false}]}
{"op":"mcm","clk":"1362086778","pt":1588426649920,"mc":[{"id":"1.170370557","rc":[{"atb":[[1.48,71.98]],"id":9624350}],"con":true,"img":false}]}
{"op":"mcm","clk":"1362086781","pt":1588426650022,"mc":[{"id":"1.170370557","rc":[{"trd":[[1.52,407.65]],"ltp":1.52,"tv":407.65,"id":9624350},{"atb":[[1.52,66.81]],"id":9624350}],"con":true,"img":false}]}
{"op":"mcm","clk":"1362086818","pt":1588426651818,"mc":[{"id":"1.170370557","rc":[{"atb":[[1.52,0]],"id":9624350}],"con":true,"img":false}]}
{"op":"mcm","clk":"1362086821","pt":1588426651916,"mc":[{"id":"1.170370557","rc":[{"trd":[[1.55,667.82],[1.53,816.3]],"ltp":1.55,"tv":1484.12,"id":9624350},{"atl":[[1.55,86.47],[1.53,0]],"id":9624350}],"con":true,"img":false}]}
{"op":"mcm","clk":"1362086831","pt":1588426652224,"mc":[{"id":"1.170370557","rc":[{"atl":[[1.67,0.35]],"id":9624350}],"con":true,"img":false}]}
{"op":"mcm","clk":"1362086836","pt":1588426652428,"mc":[{"id":"1.170370557","rc":[{"atb":[[1.83,30]],"id":9622734}],"con":true,"img":false}]}
{"op":"mcm","clk":"1362086846","pt":1588426652790,"mc":[{"id":"1.170370557","rc":[{"atb":[[2.74,15.28],[2.78,0]],"id":9622734}],"con":true,"img":false}]}
{"op":"mcm","clk":"1362086907","pt":1588426655725,"mc":[{"id":"1.170370557","rc":[{"atb":[[1.51,303.34]],"id":9624350}],"con":true,"img":false}]}
{"op":"mcm","clk":"1362086941","pt":1588426657218,"mc":[{"id":"1.170370557","rc":[{"atb":[[1.51,480.65]],"id":9624350}],"con":true,"img":false}]}
{"op":"mcm","clk":"1362086978","pt":1588426658803,"mc":[{"id":"1.170370557","rc":[{"atb":[[1.52,71.98]],"id":9624350}],"con":true,"img":false}]}
{"op":"mcm","clk":"1362086994","pt":1588426659824,"mc":[{"id":"1.170370557","rc":[{"atb":[[2.74,0]],"id":9622734},{"atb":[[1.48,127.39]],"id":9624350}],"con":true,"img":false}]}
{"op":"mcm","clk":"1362087016","pt":1588426661106,"mc":[{"id":"1.170370557","rc":[{"atl":[[2.96,29.93]],"id":9622734}],"con":true,"img":false}]}
{"op":"mcm","clk":"1362087089","pt":1588426665408,"mc":[{"id":"1.170370557","rc":[{"atl":[[1.64,177.48]],"id":9624350}],"con":true,"img":false}]}
{"op":"mcm","clk":"1362087238","pt":1588426676718,"mc":[{"id":"1.170370557","rc":[{"atb":[[2.02,15.68]],"id":9622734}],"con":true,"img":false}]}
{"op":"mcm","clk":"1362087240","pt":1588426676818,"mc":[{"id":"1.170370557","rc":[{"atb":[[2.02,31.37]],"id":9622734}],"con":true,"img":false}]}
{"op":"mcm","clk":"1362087246","pt":1588426677231,"mc":[{"id":"1.170370557","rc":[{"atb":[[2.02,47.05]],"id":9622734}],"con":true,"img":false}]}
{"op":"mcm","clk":"1362087278","pt":1588426679426,"mc":[{"id":"1.170370557","rc":[{"atl":[[1.7,200.25]],"id":9624350}],"con":true,"img":false}]}
{"op":"mcm","clk":"1362087306","pt":1588426681631,"mc":[{"id":"1.170370557","rc":[{"atl":[[1.7,0.28]],"id":9624350}],"con":true,"img":false}]}
{"op":"mcm","clk":"1362087439","pt":1588426691456,"mc":[{"id":"1.170370557","rc":[{"atb":[[1.06,1083.33],[1.07,1083.33],[1.05,1083.33]],"id":9624350}],"con":true,"img":false}]}
{"op":"mcm","clk":"1362087503","pt":1588426696064,"mc":[{"id":"1.170370557","rc":[{"atl":[[1.63,207.96]],"id":9624350}],"con":true,"img":false}]}
{"op":"mcm","clk":"1362087541","pt":1588426699083,"mc":[{"id":"1.170370557","rc":[{"atl":[[2.96,0]],"id":9622734}],"con":true,"img":false}]}
{"op":"mcm","clk":"1362087543","pt":1588426699186,"mc":[{"id":"1.170370557","rc":[{"atl":[[2.92,29.93]],"id":9622734}],"con":true,"img":false}]}
{"op":"mcm","clk":"1362087555","pt":1588426700062,"mc":[{"id":"1.170370557","rc":[{"atb":[[1.52,0]],"id":9624350}],"con":true,"img":false}]}
{"op":"mcm","clk":"1362087612","pt":1588426703965,"mc":[{"id":"1.170370557","rc":[{"atb":[[2.7,15.93]],"id":9622734}],"con":true,"img":false}]}
{"op":"mcm","clk":"1362087622","pt":1588426704575,"mc":[{"id":"1.170370557","rc":[{"atb":[[1.46,143.08],[1.48,55.4]],"id":9624350}],"con":true,"img":false}]}
{"op":"mcm","clk":"1362087691","pt":1588426709599,"mc":[{"id":"1.170370557","rc":[{"trd":[[2.8,45.78]],"ltp":2.8,"tv":45.78,"id":9622734},{"trd":[[1.55,743.14]],"ltp":1.55,"tv":743.14,"id":9624350},{"atl":[[1.55,11.15]],"id":9624350}],"con":true,"img":false}]}
{"op":"mcm","clk":"1362087790","pt":1588426716369,"mc":[{"id":"1.170370557","rc":[{"atb":[[1.52,177.3]],"id":9624350}],"con":true,"img":false}]}
{"op":"mcm","clk":"1362088036","pt":1588426733208,"mc":[{"id":"1.170370557","rc":[{"atl":[[2.92,0]],"id":9622734}],"con":true,"img":false}]}
{"op":"mcm","clk":"1362088102","pt":1588426737809,"mc":[{"id":"1.170370557","rc":[{"atb":[[1.53,71.98]],"id":9624350}],"con":true,"img":false}]}
{"op":"mcm","clk":"1362088118","pt":1588426738831,"mc":[{"id":"1.170370557","rc":[{"atb":[[2.72,0]],"id":9622734},{"atb":[[1.46,85.26]],"id":9624350}],"con":true,"img":false}]}
{"op":"mcm","clk":"1362088122","pt":1588426739138,"mc":[{"id":"1.170370557","rc":[{"trd":[[2.8,47.51]],"ltp":2.8,"tv":47.51,"id":9622734},{"trd":[[1.55,746.26]],"ltp":1.55,"tv":746.26,"id":9624350},{"atl":[[1.55,8.02]],"id":9624350}],"con":true,"img":false}]}
{"op":"mcm","clk":"1362088132","pt":1588426739701,"mc":[{"id":"1.170370557","rc":[{"atb":[[1.49,54.27]],"id":9624350}],"con":true,"img":false}]}
{"op":"mcm","clk":"1362088178","pt":1588426742929,"mc":[{"id":"1.170370557","rc":[{"atb":[[2.68,21.95]],"id":9622734}],"con":true,"img":false}]}
{"op":"mcm","clk":"1362088403","pt":1588426758683,"mc":[{"id":"1.170370557","rc":[{"trd":[[1.53,869.5]],"ltp":1.53,"tv":869.5,"id":9624350},{"atb":[[1.53,45.39]],"id":9624350}],"con":true,"img":false}]}
{"op":"mcm","clk":"1362088559","pt":1588426770081,"mc":[{"id":"1.170370557","rc":[{"atb":[[2.68,15.83]],"id":9622734}],"con":true,"img":false}]}
{"op":"mcm","clk":"1362088563","pt":1588426770285,"mc":[{"id":"1.170370557","rc":[{"atb":[[2.8,6.12]],"id":9622734}],"con":true,"img":false}]}
{"op":"mcm","clk":"1362088571","pt":1588426770745,"mc":[{"id":"1.170370557","rc":[{"atb":[[2.72,15.46]],"id":9622734}],"con":true,"img":false}]}
{"op":"mcm","clk":"1362088588","pt":1588426772071,"mc":[{"id":"1.170370557","rc":[{"atl":[[1.55,34.41]],"id":9624350}],"con":true,"img":false}]}
{"op":"mcm","clk":"1362088601","pt":1588426772891,"mc":[{"id":"1.170370557","rc":[{"atb":[[1.49,0]],"id":9624350}],"con":true,"img":false}]}
{"op":"mcm","clk":"1362088741","pt":1588426782393,"mc":[{"id":"1.170370557","rc":[{"trd":[[1.53,870.56]],"ltp":1.53,"tv":870.56,"id":9624350},{"atb":[[1.53,44.85]],"id":9624350}],"con":true,"img":false}]}
{"op":"mcm","clk":"1362088779","pt":1588426785312,"mc":[{"id":"1.170370557","rc":[{"atl":[[1.67,0]],"id":9624350}],"con":true,"img":false}]}
{"op":"mcm","clk":"1362088809","pt":1588426787209,"mc":[{"id":"1.170370557","rc":[{"atl":[[1.64,177.3]],"id":9624350}],"con":true,"img":false}]}
{"op":"mcm","clk":"1362088818","pt":1588426787719,"mc":[{"id":"1.170370557","rc":[{"atb":[[1.53,0]],"id":9624350},{"atl":[[1.55,8.02]],"id":9624350}],"con":true,"img":false}]}
{"op":"mcm","clk":"1362088823","pt":1588426787978,"mc":[{"id":"1.170370557","rc":[{"trd":[[2.8,64.19]],"ltp":2.8,"tv":64.19,"id":9622734},{"atb":[[2.8,0]],"id":9622734},{"atl":[[2.8,205.36]],"id":9622734},{"trd":[[1.55,754.29]],"ltp":1.55,"tv":754.29,"id":9624350},{"atl":[[1.55,0]],"id":9624350}],"con":true,"img":false}]}
{"op":"mcm","clk":"1362088838","pt":1588426788794,"mc":[{"id":"1.170370557","rc":[{"atb":[[2.72,0],[2.7,0.28]],"id":9622734},{"atb":[[1.5,53.19]],"id":9624350}],"con":true,"img":false}]}
{"op":"mcm","clk":"1362088887","pt":1588426791816,"mc":[{"id":"1.170370557","rc":[{"trd":[[2.8,79.02]],"ltp":2.8,"tv":79.02,"id":9622734},{"atl":[[2.8,190.53]],"id":9622734},{"trd":[[1.55,781.07]],"ltp":1.55,"tv":781.07,"id":9624350}],"con":true,"img":false}]}
{"op":"mcm","clk":"1362088903","pt":1588426792790,"mc":[{"id":"1.170370557","rc":[{"atb":[[1.54,49.25]],"id":9624350}],"con":true,"img":false}]}
{"op":"mcm","clk":"1362088958","pt":1588426797094,"mc":[{"id":"1.170370557","rc":[{"atb":[[1.54,0]],"id":9624350}],"con":true,"img":false}]}
{"op":"mcm","clk":"1362088969","pt":1588426797709,"mc":[{"id":"1.170370557","rc":[{"atl":[[2.8,0]],"id":9622734}],"con":true,"img":false}]}
{"op":"mcm","clk":"1362088972","pt":1588426797809,"mc":[{"id":"1.170370557","rc":[{"trd":[[2.78,116.54]],"ltp":2.78,"tv":116.54,"id":9622734},{"atl":[[2.78,77.62]],"id":9622734},{"trd":[[1.56,1322.97]],"ltp":1.56,"tv":1322.97,"id":9624350},{"atl":[[1.56,0]],"id":9624350}],"con":true,"img":false}]}
{"op":"mcm","clk":"1362088985","pt":1588426798782,"mc":[{"id":"1.170370557","rc":[{"atb":[[2.56,17.04]],"id":9622734}],"con":true,"img":false}]}
{"op":"mcm","clk":"1362088987","pt":1588426798933,"mc":[{"id":"1.170370557","rc":[{"atb":[[2.68,0]],"id":9622734},{"atb":[[1.47,84.33]],"id":9624350}],"con":true,"img":false}]}
{"op":"mcm","clk":"1362089000","pt":1588426799803,"mc":[{"id":"1.170370557","rc":[{"atb":[[1.53,50.17]],"id":9624350}],"con":true,"img":false}]}
{"op":"mcm","clk":"1362089051","pt":1588426803398,"mc":[{"id":"1.170370557","rc":[{"atl":[[1.64,0]],"id":9624350}],"con":true,"img":false}]}
{"op":"mcm","clk":"1362089073","pt":1588426804690,"mc":[{"id":"1.170370557","rc":[{"atl":[[1.61,177.3]],"id":9624350}],"con":true,"img":false}]}
{"op":"mcm","clk":"1362089107","pt":1588426806692,"mc":[{"id":"1.170370557","rc":[{"atb":[[1.57,46.65]],"id":9624350}],"con":true,"img":false}]}
{"op":"mcm","clk":"1362089207","pt":1588426812947,"mc":[{"id":"1.170370557","rc":[{"atb":[[1.54,20]],"id":9624350},{"atl":[[1.6,69.97]],"id":9624350}],"con":true,"img":false}]}
{"op":"mcm","clk":"1362089222","pt":1588426813814,"mc":[{"id":"1.170370557","rc":[{"atb":[[2.58,16.83]],"id":9622734}],"con":true,"img":false}]}
{"op":"mcm","clk":"1362089254","pt":1588426816020,"mc":[{"id":"1.170370557","rc":[{"atl":[[2.78,0]],"id":9622734}],"con":true,"img":false}]}
{"op":"mcm","clk":"1362089257","pt":1588426816115,"mc":[{"id":"1.170370557","rc":[{"trd":[[2.62,82.26],[2.66,60.03],[2.7,0.56]],"ltp":2.62,"tv":142.85,"id":9622734},{"atb":[[2.7,0]],"id":9622734},{"trd":[[1.61,381.43],[1.6,479]],"ltp":1.61,"tv":860.43,"id":9624350},{"atl":[[1.6,0],[1.61,119.93]],"id":9624350}],"con":true,"img":false}]}
{"op":"mcm","clk":"1362089263","pt":1588426816628,"mc":[{"id":"1.170370557","rc":[{"atl":[[1.6,0.17]],"id":9624350}],"con":true,"img":false}]}
{"op":"mcm","clk":"1362089266","pt":1588426816831,"mc":[{"id":"1.170370557","rc":[{"atb":[[2.58,0]],"id":9622734}],"con":true,"img":false}]}
{"op":"mcm","clk":"1362089300","pt":1588426819439,"mc":[{"id":"1.170370557","rc":[{"atb":[[2.66,0.11]],"id":9622734}],"con":true,"img":false}]}
{"op":"mcm","clk":"1362089314","pt":1588426820307,"mc":[{"id":"1.170370557","rc":[{"atb":[[1.57,113.14]],"id":9624350}],"con":true,"img":false}]}
{"op":"mcm","clk":"1362089404","pt":1588426827236,"mc":[{"id":"1.170370557","rc":[{"trd":[[1.57,313.52]],"ltp":1.57,"tv":313.52,"id":9624350},{"atb":[[1.57,113.04]],"id":9624350}],"con":true,"img":false}]}
{"op":"mcm","clk":"1362089673","pt":1588426845386,"mc":[{"id":"1.170370557","rc":[{"atb":[[1.57,66.48]],"id":9624350}],"con":true,"img":false}]}
{"op":"mcm","clk":"1362089773","pt":1588426852966,"mc":[{"id":"1.170370557","rc":[{"atl":[[1.6,26.41]],"id":9624350}],"con":true,"img":false}]}
{"op":"mcm","clk":"1362089787","pt":1588426853794,"mc":[{"id":"1.170370557","rc":[{"atb":[[2.58,16.83]],"id":9622734}],"con":true,"img":false}]}
{"op":"mcm","clk":"1362089860","pt":1588426859203,"mc":[{"id":"1.170370557","rc":[{"trd":[[1.6,498]],"ltp":1.6,"tv":498.0,"id":9624350},{"atl":[[1.6,16.91]],"id":9624350}],"con":true,"img":false}]}
{"op":"mcm","clk":"1362089873","pt":1588426859978,"mc":[{"id":"1.170370557","rc":[{"atb":[[2.58,0]],"id":9622734}],"con":true,"img":false}]}
{"op":"mcm","clk":"1362089903","pt":1588426862500,"mc":[{"id":"1.170370557","rc":[{"atb":[[2.66,0]],"id":9622734}],"con":true,"img":false}]}
{"op":"mcm","clk":"1362089927","pt":1588426863987,"mc":[{"id":"1.170370557","rc":[{"trd":[[1.57,331.25]],"ltp":1.57,"tv":331.25,"id":9624350},{"atb":[[1.57,57.62]],"id":9624350}],"con":true,"img":false}]}
{"op":"mcm","clk":"1362089991","pt":1588426867989,"mc":[{"id":"1.170370557","rc":[{"atl":[[1.6,46.85]],"id":9624350}],"con":true,"img":false}]}
{"op":"mcm","clk":"1362090006","pt":1588426868908,"mc":[{"id":"1.170370557","rc":[{"atb":[[2.58,16.83]],"id":9622734}],"con":true,"img":false}]}
{"op":"mcm","clk":"1362090010","pt":1588426869011,"mc":[{"id":"1.170370557","rc":[{"atb":[[1.58,17.49]],"id":9624350}],"con":true,"img":false}]}
{"op":"mcm","clk":"1362090136","pt":1588426876484,"mc":[{"id":"1.170370557","rc":[{"atl":[[1.6,592.06]],"id":9624350}],"con":true,"img":false}]}
{"op":"mcm","clk":"1362090184","pt":1588426880321,"mc":[{"id":"1.170370557","rc":[{"trd":[[1.6,586.66]],"ltp":1.6,"tv":586.66,"id":9624350},{"atl":[[1.6,547.73]],"id":9624350}],"con":true,"img":false}]}
{"op":"mcm","clk":"1362090261","pt":1588426885697,"mc":[{"id":"1.170370557","rc":[{"trd":[[1.57,446.5],[1.58,340.17]],"ltp":1.57,"tv":786.67,"id":9624350},{"atb":[[1.58,0],[1.57,0]],"id":9624350},{"atl":[[1.57,39.89]],"id":9624350}],"con":true,"img":false}]}
{"op":"mcm","clk":"1362090279","pt":1588426886825,"mc":[{"id":"1.170370557","rc":[{"atb":[[2.68,15.83]],"id":9622734},{"atb":[[1.49,54.27]],"id":9624350}],"con":true,"img":false}]}
{"op":"mcm","clk":"1362090282","pt":1588426886926,"mc":[{"id":"1.170370557","rc":[{"atb":[[1.53,0],[1.5,0]],"id":9624350}],"con":true,"img":false}]}
{"op":"mcm","clk":"1362090325","pt":1588426889029,"mc":[{"id":"1.170370557","rc":[{"atl":[[1.59,66.48]],"id":9624350}],"con":true,"img":false}]}
{"op":"mcm","clk":"1362090344","pt":1588426890206,"mc":[{"id":"1.170370557","rc":[{"atl":[[1.61,0]],"id":9624350}],"con":true,"img":false}]}
{"op":"mcm","clk":"1362090356","pt":1588426891127,"mc":[{"id":"1.170370557","rc":[{"atl":[[1.62,136.95]],"id":9624350}],"con":true,"img":false}]}
{"op":"mcm","clk":"1362090368","pt":1588426891900,"mc":[{"id":"1.170370557","rc":[{"atl":[[1.62,203.43]],"id":9624350}],"con":true,"img":false}]}
{"op":"mcm","clk":"1362090411","pt":1588426895740,"mc":[{"id":"1.170370557","rc":[{"atb":[[1.46,50.48]],"id":9624350}],"con":true,"img":false}]}
{"op":"mcm","clk":"1362090424","pt":1588426896718,"mc":[{"id":"1.170370557","rc":[{"atl":[[1.57,0]],"id":9624350}],"con":true,"img":false}]}
{"op":"mcm","clk":"1362090429","pt":1588426897021,"mc":[{"id":"1.170370557","rc":[{"trd":[[1.54,204.11]],"ltp":1.54,"tv":204.11,"id":9624350},{"atb":[[1.54,7.74]],"id":9624350}],"con":true,"img":false}]}
{"op":"mcm","clk":"1362090440","pt":1588426897745,"mc":[{"id":"1.170370557","rc":[{"atb":[[1.44,0]],"id":9624350}],"con":true,"img":false}]}
{"op":"mcm","clk":"1362090442","pt":1588426897845,"mc":[{"id":"1.170370557","rc":[{"atb":[[2.64,16.21],[2.68,0]],"id":9622734},{"atb":[[1.5,53.19]],"id":9624350}],"con":true,"img":false}]}
{"op":"mcm","clk":"1362090449","pt":1588426898414,"mc":[{"id":"1.170370557","rc":[{"atl":[[1.6,2.52]],"id":9624350}],"con":true,"img":false}]}
{"op":"mcm","clk":"1362090509","pt":1588426901947,"mc":[{"id":"1.170370557","rc":[{"atb":[[1.56,14.34]],"id":9624350}],"con":true,"img":false}]}
{"op":"mcm","clk":"1362090539","pt":1588426903946,"mc":[{"id":"1.170370557","rc":[{"atl":[[1.57,26.24]],"id":9624350}],"con":true,"img":false}]}
{"op":"mcm","clk":"1362090557","pt":1588426904819,"mc":[{"id":"1.170370557","rc":[{"atb":[[2.64,0],[2.62,16.41]],"id":9622734}],"con":true,"img":false}]}
{"op":"mcm","clk":"1362090596","pt":1588426907326,"mc":[{"id":"1.170370557","rc":[{"trd":[[1.56,1351.66]],"ltp":1.56,"tv":1351.66,"id":9624350},{"atb":[[1.56,0]],"id":9624350},{"atl":[[1.56,29.44]],"id":9624350}],"con":true,"img":false}]}
{"op":"mcm","clk":"1362090606","pt":1588426907847,"mc":[{"id":"1.170370557","rc":[{"atb":[[2.72,15.46]],"id":9622734},{"atb":[[1.49,0],[1.5,0]],"id":9624350}],"con":true,"img":false}]}
{"op":"mcm","clk":"1362090629","pt":1588426909635,"mc":[{"id":"1.170370557","rc":[{"atl":[[1.6,265.24]],"id":9624350}],"con":true,"img":false}]}
{"op":"mcm","clk":"1362090691","pt":1588426914661,"mc":[{"id":"1.170370557","rc":[{"trd":[[1.54,219.59]],"ltp":1.54,"tv":219.59,"id":9624350},{"atb":[[1.54,0]],"id":9624350},{"atl":[[1.54,32.26]],"id":9624350}],"con":true,"img":false}]}
{"op":"mcm","clk":"1362090694","pt":1588426914864,"mc":[{"id":"1.170370557","rc":[{"trd":[[1.54,267.85]],"ltp":1.54,"tv":267.85,"id":9624350},{"atl":[[1.54,8.13]],"id":9624350}],"con":true,"img":false}]}
{"op":"mcm","clk":"1362090715","pt":1588426916453,"mc":[{"id":"1.170370557","rc":[{"atl":[[1.54,16.88]],"id":9624350}],"con":true,"img":false}]}
{"op":"mcm","clk":"1362090756","pt":1588426919067,"mc":[{"id":"1.170370557","rc":[{"atb":[[1.53,15.09]],"id":9624350}],"con":true,"img":false}]}
{"op":"mcm","clk":"1362090759","pt":1588426919272,"mc":[{"id":"1.170370557","rc":[{"trd":[[1.54,301.63]],"ltp":1.54,"tv":301.63,"id":9624350},{"atl":[[1.54,0]],"id":9624350}],"con":true,"img":false}]}
{"op":"mcm","clk":"1362090818","pt":1588426924254,"mc":[{"id":"1.170370557","rc":[{"atb":[[1.47,0]],"id":9624350}],"con":true,"img":false}]}
{"op":"mcm","clk":"1362090837","pt":1588426926053,"mc":[{"id":"1.170370557","rc":[{"atl":[[1.57,0]],"id":9624350}],"con":true,"img":false}]}
{"op":"mcm","clk":"1362090839","pt":1588426926157,"mc":[{"id":"1.170370557","rc":[{"atl":[[1.56,55.69]],"id":9624350}],"con":true,"img":false}]}
{"op":"mcm","clk":"1362090897","pt":1588426930274,"mc":[{"id":"1.170370557","rc":[{"trd":[[1.53,874.11]],"ltp":1.53,"tv":874.11,"id":9624350},{"atb":[[1.53,13.31]],"id":9624350}],"con":true,"img":false}]}
{"op":"mcm","clk":"1362090916","pt":1588426931348,"mc":[{"id":"1.170370557","rc":[{"atl":[[1000,3.19]],"id":9624350}],"con":true,"img":false}]}
{"op":"mcm","clk":"1362090920","pt":1588426931658,"mc":[{"id":"1.170370557","rc":[{"atl":[[1000,1.75]],"id":9624350}],"con":true,"img":false}]}
{"op":"mcm","clk":"1362090924","pt":1588426931964,"mc":[{"id":"1.170370557","rc":[{"atl":[[1000,0]],"id":9624350}],"con":true,"img":false}]}
{"op":"mcm","clk":"1362090927","pt":1588426932065,"mc":[{"id":"1.170370557","rc":[{"atl":[[1.55,1.75]],"id":9624350}],"con":true,"img":false}]}
{"op":"mcm","clk":"1362091000","pt":1588426936069,"mc":[{"id":"1.170370557","rc":[{"atb":[[1.53,190.62]],"id":9624350}],"con":true,"img":false}]}
{"op":"mcm","clk":"1362091011","pt":1588426936784,"mc":[{"id":"1.170370557","rc":[{"atb":[[2.7,15.64]],"id":9622734},{"atb":[[1.49,54.27]],"id":9624350}],"con":true,"img":false}]}
{"op":"mcm","clk":"1362091014","pt":1588426936989,"mc":[{"id":"1.170370557","rc":[{"atb":[[2.72,0]],"id":9622734},{"atb":[[1.51,31.37]],"id":9624350},{"atl":[[1.55,0]],"id":9624350}],"con":true,"img":false}]}
{"op":"mcm","clk":"1362091024","pt":1588426937760,"mc":[{"id":"1.170370557","rc":[{"atl":[[1000,3.19]],"id":9624350}],"con":true,"img":false}]}
{"op":"mcm","clk":"1362091029","pt":1588426938066,"mc":[{"id":"1.170370557","rc":[{"atl":[[1000,1.75]],"id":9624350}],"con":true,"img":false}]}
{"op":"mcm","clk":"1362091034","pt":1588426938375,"mc":[{"id":"1.170370557","rc":[{"atl":[[1000,0]],"id":9624350}],"con":true,"img":false}]}
{"op":"mcm","clk":"1362091037","pt":1588426938478,"mc":[{"id":"1.170370557","rc":[{"atb":[[1.52,354.6]],"id":9624350},{"atl":[[1.55,1.75]],"id":9624350}],"con":true,"img":false}]}
{"op":"mcm","clk":"1362091134","pt":1588426945098,"mc":[{"id":"1.170370557","rc":[{"atb":[[1.54,1638.42]],"id":9624350}],"con":true,"img":false}]}
{"op":"mcm","clk":"1362091151","pt":1588426945872,"mc":[{"id":"1.170370557","rc":[{"atb":[[2.68,15.83],[2.7,0]],"id":9622734},{"atb":[[1.49,0]],"id":9624350}],"con":true,"img":false}]}
{"op":"mcm","clk":"1362091165","pt":1588426946593,"mc":[{"id":"1.170370557","rc":[{"atl":[[1.55,0]],"id":9624350}],"con":true,"img":false}]}
{"op":"mcm","clk":"1362091182","pt":1588426947361,"mc":[{"id":"1.170370557","rc":[{"atl":[[1000,3.19]],"id":9624350}],"con":true,"img":false}]}
{"op":"mcm","clk":"1362091188","pt":1588426947674,"mc":[{"id":"1.170370557","rc":[{"atl":[[1000,1.71]],"id":9624350}],"con":true,"img":false}]}
{"op":"mcm","clk":"1362091190","pt":1588426947780,"mc":[{"id":"1.170370557","rc":[{"atb":[[1.49,54.27]],"id":9624350}],"con":true,"img":false}]}
{"op":"mcm","clk":"1362091193","pt":1588426947982,"mc":[{"id":"1.170370557","rc":[{"atl":[[1000,0]],"id":9624350}],"con":true,"img":false}]}
{"op":"mcm","clk":"1362091195","pt":1588426948090,"mc":[{"id":"1.170370557","rc":[{"atl":[[1.58,1.71]],"id":9624350}],"con":true,"img":false}]}
{"op":"mcm","clk":"1362091253","pt":1588426952202,"mc":[{"id":"1.170370557","rc":[{"atl":[[1.6,262.72]],"id":9624350}],"con":true,"img":false}]}
{"op":"mcm","clk":"1362091362","pt":1588426958414,"mc":[{"id":"1.170370557","rc":[{"atb":[[1.52,0]],"id":9624350}],"con":true,"img":false}]}
{"op":"mcm","clk":"1362091372","pt":1588426959097,"mc":[{"id":"1.170370557","rc":[{"atb":[[1.53,367.92]],"id":9624350}],"con":true,"img":false}]}
{"op":"mcm","clk":"1362091413","pt":1588426961100,"mc":[{"id":"1.170370557","rc":[{"atb":[[1.53,545.23]],"id":9624350}],"con":true,"img":false}]}
{"op":"mcm","clk":"1362091434","pt":1588426962377,"mc":[{"id":"1.170370557","rc":[{"trd":[[1.54,319.15]],"ltp":1.54,"tv":319.15,"id":9624350},{"atb":[[1.54,1629.66]],"id":9624350}],"con":true,"img":false}]}
{"op":"mcm","clk":"1362091492","pt":1588426966019,"mc":[{"id":"1.170370557","rc":[{"trd":[[1.56,1381.6]],"ltp":1.56,"tv":1381.6,"id":9624350},{"atl":[[1.56,40.71]],"id":9624350}],"con":true,"img":false}]}
{"op":"mcm","clk":"1362091541","pt":1588426969408,"mc":[{"id":"1.170370557","rc":[{"atb":[[1.53,531.91]],"id":9624350}],"con":true,"img":false}]}
{"op":"mcm","clk":"1362091596","pt":1588426973108,"mc":[{"id":"1.170370557","rc":[{"atb":[[1.46,0]],"id":9624350}],"con":true,"img":false}]}
{"op":"mcm","clk":"1362091601","pt":1588426973415,"mc":[{"id":"1.170370557","rc":[{"atb":[[1.45,177.3]],"id":9624350}],"con":true,"img":false}]}
{"op":"mcm","clk":"1362091784","pt":1588426986743,"mc":[{"id":"1.170370557","rc":[{"trd":[[1.56,1383.74]],"ltp":1.56,"tv":1383.74,"id":9624350},{"atl":[[1.56,39.65]],"id":9624350}],"con":true,"img":false}]}
{"op":"mcm","clk":"1362091809","pt":1588426988229,"mc":[{"id":"1.170370557","rc":[{"trd":[[1.54,1319.15]],"ltp":1.54,"tv":1319.15,"id":9624350},{"atb":[[1.54,1129.66]],"id":9624350}],"con":true,"img":false}]}
{"op":"mcm","clk":"1362091943","pt":1588426996747,"mc":[{"id":"1.170370557","rc":[{"atb":[[1.1,0.95]],"id":9622734},{"atb":[[1.1,0]],"id":9624350}],"con":true,"img":false}]}
{"op":"mcm","clk":"1362091995","pt":1588426999261,"mc":[{"id":"1.170370557","rc":[{"atl":[[1.58,0]],"id":9624350}],"con":true,"img":false}]}
{"op":"mcm","clk":"1362092008","pt":1588427000031,"mc":[{"id":"1.170370557","rc":[{"atl":[[1000,3.19]],"id":9624350}],"con":true,"img":false}]}
{"op":"mcm","clk":"1362092013","pt":1588427000339,"mc":[{"id":"1.170370557","rc":[{"atl":[[1000,1.75]],"id":9624350}],"con":true,"img":false}]}
{"op":"mcm","clk":"1362092023","pt":1588427000648,"mc":[{"id":"1.170370557","rc":[{"atl":[[1000,0]],"id":9624350}],"con":true,"img":false}]}
{"op":"mcm","clk":"1362092025","pt":1588427000751,"mc":[{"id":"1.170370557","rc":[{"atl":[[1.55,1.75]],"id":9624350}],"con":true,"img":false}]}
{"op":"mcm","clk":"1362092043","pt":1588427002035,"mc":[{"id":"1.170370557","rc":[{"atb":[[1.49,0]],"id":9624350}],"con":true,"img":false}]}
{"op":"mcm","clk":"1362092050","pt":1588427002549,"mc":[{"id":"1.170370557","rc":[{"trd":[[1.56,1389.58],[1.55,784.57]],"ltp":1.56,"tv":2174.15,"id":9624350},{"atl":[[1.56,36.73],[1.55,0]],"id":9624350}],"con":true,"img":false}]}
{"op":"mcm","clk":"1362092054","pt":1588427002753,"mc":[{"id":"1.170370557","rc":[{"atb":[[1.51,0]],"id":9624350}],"con":true,"img":false}]}
{"op":"mcm","clk":"1362092060","pt":1588427002958,"mc":[{"id":"1.170370557","rc":[{"atb":[[1.49,54.27]],"id":9624350}],"con":true,"img":false}]}
{"op":"mcm","clk":"1362092129","pt":1588427008448,"mc":[{"id":"1.170370557","rc":[{"atl":[[1000,1.45]],"id":9622734}],"con":true,"img":false}]}
{"op":"mcm","clk":"1362092152","pt":1588427010137,"mc":[{"id":"1.170370557","rc":[{"trd":[[1.54,1324.3]],"ltp":1.54,"tv":1324.3,"id":9624350},{"atb":[[1.54,1127.08]],"id":9624350}],"con":true,"img":false}]}
{"op":"mcm","clk":"1362092186","pt":1588427012449,"mc":[{"id":"1.170370557","rc":[{"atb":[[1.25,159.97]],"id":9622734}],"con":true,"img":false}]}
{"op":"mcm","clk":"1362092191","pt":1588427012654,"mc":[{"id":"1.170370557","rc":[{"atb":[[1.25,319.94]],"id":9622734}],"con":true,"img":false}]}
{"op":"mcm","clk":"1362092194","pt":1588427012756,"mc":[{"id":"1.170370557","rc":[{"atb":[[1.25,479.92]],"id":9622734}],"con":true,"img":false}]}
{"op":"mcm","clk":"1362092209","pt":1588427013934,"mc":[{"id":"1.170370557","rc":[{"atl":[[2.96,103.11]],"id":9622734}],"con":true,"img":false}]}
{"op":"mcm","clk":"1362092234","pt":1588427015981,"mc":[{"id":"1.170370557","rc":[{"atb":[[1.53,0]],"id":9624350}],"con":true,"img":false}]}
{"op":"mcm","clk":"1362092241","pt":1588427016239,"mc":[{"id":"1.170370557","rc":[{"atl":[[1000,2.47]],"id":9622734}],"con":true,"img":false}]}
{"op":"mcm","clk":"1362092252","pt":1588427016957,"mc":[{"id":"1.170370557","rc":[{"trd":[[1.56,1390.5]],"ltp":1.56,"tv":1390.5,"id":9624350},{"atl":[[1.56,36.26]],"id":9624350}],"con":true,"img":false}]}
{"op":"mcm","clk":"1362092260","pt":1588427017674,"mc":[{"id":"1.170370557","rc":[{"atb":[[1.53,177.3]],"id":9624350}],"con":true,"img":false}]}
{"op":"mcm","clk":"1362092270","pt":1588427018288,"mc":[{"id":"1.170370557","rc":[{"atb":[[1.53,354.6]],"id":9624350}],"con":true,"img":false}]}
{"op":"mcm","clk":"1362092283","pt":1588427019159,"mc":[{"id":"1.170370557","rc":[{"atb":[[1.1,0]],"id":9622734},{"atb":[[1.1,399.93]],"id":9624350}],"con":true,"img":false}]}
{"op":"mcm","clk":"1362092286","pt":1588427019262,"mc":[{"id":"1.170370557","rc":[{"trd":[[2.86,0.95]],"ltp":2.86,"tv":0.95,"id":9622734},{"trd":[[1.54,1326.09]],"ltp":1.54,"tv":1326.09,"id":9624350},{"atb":[[1.54,1125.3]],"id":9624350}],"con":true,"img":false}]}
{"op":"mcm","clk":"1362092289","pt":1588427019364,"mc":[{"id":"1.170370557","rc":[{"atb":[[1.1,799.87]],"id":9624350}],"con":true,"img":false}]}
{"op":"mcm","clk":"1362092293","pt":1588427019468,"mc":[{"id":"1.170370557","rc":[{"atb":[[1.1,1199.8]],"id":9624350}],"con":true,"img":false}]}
{"op":"mcm","clk":"1362092296","pt":1588427019570,"mc":[{"id":"1.170370557","rc":[{"atb":[[1.1,1599.74]],"id":9624350}],"con":true,"img":false}]}
{"op":"mcm","clk":"1362092384","pt":1588427024191,"mc":[{"id":"1.170370557","rc":[{"trd":[[1.54,1336.32]],"ltp":1.54,"tv":1336.32,"id":9624350},{"atb":[[1.54,1120.18]],"id":9624350}],"con":true,"img":false}]}
{"op":"mcm","clk":"1362092449","pt":1588427028503,"mc":[{"id":"1.170370557","rc":[{"trd":[[1.54,3576.69]],"ltp":1.54,"tv":3576.69,"id":9624350},{"atb":[[1.54,0]],"id":9624350},{"atl":[[1.54,106.06]],"id":9624350}],"con":true,"img":false}]}
{"op":"mcm","clk":"1362092453","pt":1588427028708,"mc":[{"id":"1.170370557","rc":[{"trd":[[1.54,3624.95]],"ltp":1.54,"tv":3624.95,"id":9624350},{"atl":[[1.54,81.92]],"id":9624350}],"con":true,"img":false}]}
{"op":"mcm","clk":"1362092461","pt":1588427028962,"mc":[{"id":"1.170370557","rc":[{"atb":[[2.56,0]],"id":9622734},{"atb":[[1.49,0]],"id":9624350}],"con":true,"img":false}]}
{"op":"mcm","clk":"1362092477","pt":1588427029889,"mc":[{"id":"1.170370557","rc":[{"atb":[[2.74,15.28]],"id":9622734}],"con":true,"img":false}]}
{"op":"mcm","clk":"1362092534","pt":1588427033780,"mc":[{"id":"1.170370557","rc":[{"trd":[[1.56,1426.64],[1.54,3788.81]],"ltp":1.56,"tv":5215.44,"id":9624350},{"atl":[[1.56,18.2],[1.54,0]],"id":9624350}],"con":true,"img":false}]}
{"op":"mcm","clk":"1362092543","pt":1588427034396,"mc":[{"id":"1.170370557","rc":[{"trd":[[2.78,120.18]],"ltp":2.78,"tv":120.18,"id":9622734},{"trd":[[1.56,1433.14]],"ltp":1.56,"tv":1433.14,"id":9624350},{"atl":[[1.56,11.7]],"id":9624350}],"con":true,"img":false}]}
{"op":"mcm","clk":"1362092553","pt":1588427034909,"mc":[{"id":"1.170370557","rc":[{"atb":[[2.64,16.21],[2.74,0],[2.68,0]],"id":9622734},{"atb":[[1.5,53.19]],"id":9624350}],"con":true,"img":false}]}
{"op":"mcm","clk":"1362092569","pt":1588427035797,"mc":[{"id":"1.170370557","rc":[{"atb":[[1.47,56.58]],"id":9624350}],"con":true,"img":false}]}
{"op":"mcm","clk":"1362092572","pt":1588427035980,"mc":[{"id":"1.170370557","rc":[{"atb":[[1.48,0],[1.54,0.92],[1.5,0]],"id":9624350}],"con":true,"img":false}]}
{"op":"mcm","clk":"1362092577","pt":1588427036288,"mc":[{"id":"1.170370557","rc":[{"atb":[[1.52,177.3]],"id":9624350}],"con":true,"img":false}]}
{"op":"mcm","clk":"1362092588","pt":1588427036800,"mc":[{"id":"1.170370557","rc":[{"atb":[[1.52,354.6]],"id":9624350}],"con":true,"img":false}]}
{"op":"mcm","clk":"1362092601","pt":1588427037409,"mc":[{"id":"1.170370557","rc":[{"atb":[[1.52,531.91]],"id":9624350}],"con":true,"img":false}]}
{"op":"mcm","clk":"1362092606","pt":1588427037612,"mc":[{"id":"1.170370557","rc":[{"trd":[[1.53,1572.97],[1.54,3790.67]],"ltp":1.53,"tv":5363.64,"id":9624350},{"atb":[[1.53,5.17],[1.54,0]],"id":9624350}],"con":true,"img":false}]}
{"op":"mcm","clk":"1362092611","pt":1588427037816,"mc":[{"id":"1.170370557","rc":[{"atb":[[1.5,53.19]],"id":9624350}],"con":true,"img":false}]}
{"op":"mcm","clk":"1362092616","pt":1588427038073,"mc":[{"id":"1.170370557","rc":[{"atb":[[1.53,0]],"id":9624350}],"con":true,"img":false}]}
{"op":"mcm","clk":"1362092631","pt":1588427039296,"mc":[{"id":"1.170370557","rc":[{"atl":[[1.55,177.3]],"id":9624350}],"con":true,"img":false}]}
{"op":"mcm","clk":"1362092635","pt":1588427039604,"mc":[{"id":"1.170370557","rc":[{"atl":[[1000,1.45]],"id":9624350}],"con":true,"img":false}]}
{"op":"mcm","clk":"1362092640","pt":1588427039909,"mc":[{"id":"1.170370557","rc":[{"atb":[[2.72,15.46]],"id":9622734},{"atb":[[1.48,55.4],[1.5,0]],"id":9624350}],"con":true,"img":false}]}
{"op":"mcm","clk":"1362092643","pt":1588427040113,"mc":[{"id":"1.170370557","rc":[{"atb":[[1.52,709.21]],"id":9624350}],"con":true,"img":false}]}
{"op":"mcm","clk":"1362092654","pt":1588427040674,"mc":[{"id":"1.170370557","rc":[{"atb":[[1.52,0]],"id":9624350}],"con":true,"img":false}]}
{"op":"mcm","clk":"1362092680","pt":1588427041901,"mc":[{"id":"1.170370557","rc":[{"atb":[[2.58,0]],"id":9622734},{"atb":[[1.48,0],[1.52,177.3]],"id":9624350}],"con":true,"img":false}]}
{"op":"mcm","clk":"1362092698","pt":1588427042920,"mc":[{"id":"1.170370557","rc":[{"atb":[[1.48,55.4]],"id":9624350}],"con":true,"img":false}]}
{"op":"mcm","clk":"1362092750","pt":1588427047018,"mc":[{"id":"1.170370557","rc":[{"trd":[[2.8,129.02]],"ltp":2.8,"tv":129.02,"id":9622734},{"trd":[[1.55,874.89]],"ltp":1.55,"tv":874.89,"id":9624350},{"atl":[[1.55,86.98]],"id":9624350}],"con":true,"img":false}]}
{"op":"mcm","clk":"1362092762","pt":1588427047990,"mc":[{"id":"1.170370557","rc":[{"atl":[[1000,2.04]],"id":9624350}],"con":true,"img":false}]}
{"op":"mcm","clk":"1362092798","pt":1588427050901,"mc":[{"id":"1.170370557","rc":[{"atl":[[1.55,264.29]],"id":9624350}],"con":true,"img":false}]}
{"op":"mcm","clk":"1362092840","pt":1588427053296,"mc":[{"id":"1.170370557","rc":[{"trd":[[1.52,582.82]],"ltp":1.52,"tv":582.82,"id":9624350},{"atb":[[1.52,89.71]],"id":9624350}],"con":true,"img":false}]}
{"op":"mcm","clk":"1362092875","pt":1588427055234,"mc":[{"id":"1.170370557","rc":[{"atl":[[1.55,441.59]],"id":9624350}],"con":true,"img":false}]}
{"op":"mcm","clk":"1362092927","pt":1588427059120,"mc":[{"id":"1.170370557","rc":[{"trd":[[2.8,176.89]],"ltp":2.8,"tv":176.89,"id":9622734},{"trd":[[1.55,961.37]],"ltp":1.55,"tv":961.37,"id":9624350},{"atl":[[1.55,355.11]],"id":9624350}],"con":true,"img":false}]}
{"op":"mcm","clk":"1362093734","pt":1588427061112,"mc":[{"id":"1.170370557","rc":[{"atl":[[1.54,14.11]],"id":9624350}],"con":true,"img":false}]}
{"op":"mcm","clk":"1362093828","pt":1588427068111,"mc":[{"id":"1.170370557","rc":[{"trd":[[1.52,600.34]],"ltp":1.52,"tv":600.34,"id":9624350},{"atb":[[1.52,80.95]],"id":9624350}],"con":true,"img":false}]}
{"op":"mcm","clk":"1362093863","pt":1588427070354,"mc":[{"id":"1.170370557","rc":[{"atl":[[1.54,0]],"id":9624350}],"con":true,"img":false}]}
{"op":"mcm","clk":"1362093881","pt":1588427071634,"mc":[{"id":"1.170370557","rc":[{"trd":[[1.52,640.34]],"ltp":1.52,"tv":640.34,"id":9624350},{"atb":[[1.52,60.95]],"id":9624350}],"con":true,"img":false}]}
{"op":"mcm","clk":"1362093936","pt":1588427075356,"mc":[{"id":"1.170370557","rc":[{"trd":[[1.55,997.4]],"ltp":1.55,"tv":997.4,"id":9624350},{"atl":[[1.55,337.1]],"id":9624350}],"con":true,"img":false}]}
