{"op":"mcm","clk":"1362427945","pt":1588450173819,"mc":[{"id":"1.170370564","rc":[{"atl":[[1.35,2.12]],"id":8509691}],"con":true,"img":false}]}
{"op":"mcm","clk":"1362427951","pt":1588450174276,"mc":[{"id":"1.170370564","rc":[{"atl":[[1.34,12]],"id":8509691}],"con":true,"img":false}]}
{"op":"mcm","clk":"1362427984","pt":1588450176416,"mc":[{"id":"1.170370564","rc":[{"atb":[[1.24,43.79]],"id":8509691}],"con":true,"img":false}]}
{"op":"mcm","clk":"1362427995","pt":1588450177182,"mc":[{"id":"1.170370567","rc":[{"atb":[[1.13,0]],"id":9630572}],"con":true,"img":false}]}
{"op":"mcm","clk":"1362428020","pt":1588450178610,"mc":[{"id":"1.170370564","rc":[{"atl":[[1.3,48.75]],"id":8509691}],"con":true,"img":false}]}
{"op":"mcm","clk":"1362428062","pt":1588450182288,"mc":[{"id":"1.170370567","rc":[{"atb":[[1.14,523.11]],"id":9630572}],"con":true,"img":false}]}
{"op":"mcm","clk":"1362428084","pt":1588450184019,"mc":[{"id":"1.170370566","rc":[{"atb":[[1.07,0]],"id":8509691}],"con":true,"img":false}]}
{"op":"mcm","clk":"1362428085","pt":1588450184123,"mc":[{"id":"1.170370567","rc":[{"atb":[[1.12,0]],"id":8509691}],"con":true,"img":false}]}
{"op":"mcm","clk":"1362428086","pt":1588450184224,"mc":[{"id":"1.170370564","rc":[{"atl":[[1.34,0]],"id":8509691}],"con":true,"img":false}]}
{"op":"mcm","clk":"1362428115","pt":1588450186718,"mc":[{"id":"1.170370564","rc":[{"atl":[[1.28,295.21]],"id":8509691}],"con":true,"img":false}]}
{"op":"mcm","clk":"1362428119","pt":1588450187024,"mc":[{"id":"1.170370564","rc":[{"atl":[[1.25,240]],"id":8509691}],"con":true,"img":false}]}
{"op":"mcm","clk":"1362428130","pt":1588450187895,"mc":[{"id":"1.170370564","rc":[{"atb":[[1.1,998.72]],"id":8509691}],"con":true,"img":false}]}
{"op":"mcm","clk":"1362428139","pt":1588450188808,"mc":[{"id":"1.170370564","rc":[{"atl":[[1.25,0],[1.29,175]],"id":8509691}],"con":true,"img":false}]}
{"op":"mcm","clk":"1362428145","pt":1588450189117,"mc":[{"id":"1.170370564","rc":[{"atl":[[1.29,350]],"id":8509691}],"con":true,"img":false}]}
{"op":"mcm","clk":"1362428148","pt":1588450189216,"mc":[{"id":"1.170370564","rc":[{"atl":[[1.28,0]],"id":8509691}],"con":true,"img":false}]}
{"op":"mcm","clk":"1362428151","pt":1588450189321,"mc":[{"id":"1.170370564","rc":[{"atl":[[1.29,367.51]],"id":8509691}],"con":true,"img":false}]}
{"op":"mcm","clk":"1362428155","pt":1588450189730,"mc":[{"id":"1.170370564","rc":[{"trd":[[1.24,2655.98]],"ltp":1.24,"tv":2655.98,"id":8509691},{"atb":[[1.24,0]],"id":8509691},{"atl":[[1.24,196.21]],"id":8509691}],"con":true,"img":false}]}
{"op":"mcm","clk":"1362428164","pt":1588450190138,"mc":[{"id":"1.170370564","rc":[{"atl":[[1.28,175]],"id":8509691}],"con":true,"img":false}]}
{"op":"mcm","clk":"1362428168","pt":1588450190240,"mc":[{"id":"1.170370564","rc":[{"atl":[[1.28,350]],"id":8509691}],"con":true,"img":false}]}
{"op":"mcm","clk":"1362428171","pt":1588450190445,"mc":[{"id":"1.170370564","rc":[{"atl":[[1.31,0],[1.24,0]],"id":8509691}],"con":true,"img":false}]}
{"op":"mcm","clk":"1362428176","pt":1588450190803,"mc":[{"id":"1.170370564","rc":[{"atl":[[1.24,196.8]],"id":8509691}],"con":true,"img":false}]}
{"op":"mcm","clk":"1362428202","pt":1588450193518,"mc":[{"id":"1.170370564","rc":[{"atl":[[1.29,350]],"id":8509691}],"con":true,"img":false}]}
{"op":"mcm","clk":"1362428203","pt":1588450193620,"mc":[{"id":"1.170370564","rc":[{"atb":[[1.19,0],[1.15,10]],"id":8509691}],"con":true,"img":false}]}
{"op":"mcm","clk":"1362428223","pt":1588450195914,"mc":[{"id":"1.170370564","rc":[{"atb":[[1.23,1.42]],"id":8509691},{"atl":[[1.37,0]],"id":8509691}],"con":true,"img":false}]}
{"op":"mcm","clk":"1362428224","pt":1588450196115,"mc":[{"id":"1.170370564","rc":[{"atl":[[1.28,0],[1.27,212.02],[1.29,0]],"id":8509691}],"con":true,"img":false}]}
{"op":"mcm","clk":"1362428227","pt":1588450196420,"mc":[{"id":"1.170370566","rc":[{"atb":[[2.12,180.54]],"id":9630572}],"con":true,"img":false}]}
{"op":"mcm","clk":"1362428302","pt":1588450202448,"mc":[{"id":"1.170370564","rc":[{"atb":[[1.14,0]],"id":8509691},{"atl":[[1.3,0]],"id":8509691}],"con":true,"img":false}]}
{"op":"mcm","clk":"1362428320","pt":1588450203317,"mc":[{"id":"1.170370564","rc":[{"trd":[[1.24,2656.33]],"ltp":1.24,"tv":2656.33,"id":8509691},{"atl":[[1.24,196.63]],"id":8509691}],"con":true,"img":false}]}
{"op":"mcm","clk":"1362428326","pt":1588450203827,"mc":[{"id":"1.170370564","rc":[{"trd":[[1.24,2656.54]],"ltp":1.24,"tv":2656.54,"id":8509691},{"atl":[[1.24,196.52]],"id":8509691}],"con":true,"img":false}]}
{"op":"mcm","clk":"1362428343","pt":1588450204956,"mc":[{"id":"1.170370564","rc":[{"trd":[[5.1,201.41]],"ltp":5.1,"tv":201.41,"id":9630572},{"trd":[[1.24,2738.8]],"ltp":1.24,"tv":2738.8,"id":8509691},{"atl":[[1.24,114.26]],"id":8509691}],"con":true,"img":false}]}
{"op":"mcm","clk":"1362428393","pt":1588450207554,"mc":[{"id":"1.170370564","rc":[{"atb":[[1.13,17.75]],"id":8509691}],"con":true,"img":false}]}
{"op":"mcm","clk":"1362428396","pt":1588450207758,"mc":[{"id":"1.170370564","rc":[{"atl":[[1.35,1.95]],"id":8509691}],"con":true,"img":false}]}
{"op":"mcm","clk":"1362428398","pt":1588450207961,"mc":[{"id":"1.170370566","rc":[{"atb":[[1.02,0]],"id":8509691}],"con":true,"img":false}]}
{"op":"mcm","clk":"1362428405","pt":1588450208521,"mc":[{"id":"1.170370564","rc":[{"atb":[[1.18,207.85]],"id":8509691}],"con":true,"img":false}]}
{"op":"mcm","clk":"1362428432","pt":1588450210765,"mc":[{"id":"1.170370564","rc":[{"trd":[[1.23,1107.24]],"ltp":1.23,"tv":1107.24,"id":8509691},{"atb":[[1.23,0]],"id":8509691},{"atl":[[1.23,175.88]],"id":8509691}],"con":true,"img":false}]}
{"op":"mcm","clk":"1362428438","pt":1588450211225,"mc":[{"id":"1.170370566","rc":[{"atb":[[1.02,43.99]],"id":8509691}],"con":true,"img":false}]}
{"op":"mcm","clk":"1362428439","pt":1588450211326,"mc":[{"id":"1.170370564","rc":[{"atl":[[1.22,177.3]],"id":8509691}],"con":true,"img":false}]}
{"op":"mcm","clk":"1362428449","pt":1588450211939,"mc":[{"id":"1.170370567","rc":[{"atb":[[1.08,2.62]],"id":8509691}],"con":true,"img":false}]}
{"op":"mcm","clk":"1362428460","pt":1588450212553,"mc":[{"id":"1.170370566","rc":[{"atb":[[1.02,0]],"id":8509691}],"con":true,"img":false}]}
{"op":"mcm","clk":"1362428498","pt":1588450215837,"mc":[{"id":"1.170370564","rc":[{"trd":[[1.22,2124.58]],"ltp":1.22,"tv":2124.58,"id":8509691},{"atl":[[1.22,8.22]],"id":8509691}],"con":true,"img":false}]}
{"op":"mcm","clk":"1362428522","pt":1588450217778,"mc":[{"id":"1.170370564","rc":[{"trd":[[5.3,29.28],[5.5,12.76]],"ltp":5.3,"tv":42.04,"id":9630572},{"trd":[[1.23,1185.57],[1.22,2132.81]],"ltp":1.23,"tv":3318.38,"id":8509691},{"atl":[[1.23,97.55],[1.22,0]],"id":8509691}],"con":true,"img":false}]}
{"op":"mcm","clk":"1362428533","pt":1588450218239,"mc":[{"id":"1.170370564","rc":[{"trd":[[1.18,990.79]],"ltp":1.18,"tv":990.79,"id":8509691},{"atb":[[1.18,207.79]],"id":8509691}],"con":true,"img":false}]}
{"op":"mcm","clk":"1362428599","pt":1588450221872,"mc":[{"id":"1.170370564","rc":[{"atb":[[1.01,8563.52]],"id":8509691}],"con":true,"img":false}]}
{"op":"mcm","clk":"1362428609","pt":1588450222435,"mc":[{"id":"1.170370564","rc":[{"atb":[[1.22,11.99]],"id":8509691}],"con":true,"img":false}]}
{"op":"mcm","clk":"1362428614","pt":1588450222742,"mc":[{"id":"1.170370564","rc":[{"atb":[[1.19,177.3]],"id":8509691}],"con":true,"img":false}]}
{"op":"mcm","clk":"1362428621","pt":1588450223047,"mc":[{"id":"1.170370567","rc":[{"atb":[[1.08,0]],"id":8509691}],"con":true,"img":false}]}
{"op":"mcm","clk":"1362428648","pt":1588450224939,"mc":[{"id":"1.170370564","rc":[{"trd":[[1.22,2156.81]],"ltp":1.22,"tv":2156.81,"id":8509691},{"atb":[[1.22,0]],"id":8509691},{"atl":[[1.24,0]],"id":8509691}],"con":true,"img":false}]}
{"op":"mcm","clk":"1362428671","pt":1588450226373,"mc":[{"id":"1.170370566","rc":[{"atb":[[1.12,799.87]],"id":9630572}],"con":true,"img":false}]}
{"op":"mcm","clk":"1362428702","pt":1588450228267,"mc":[{"id":"1.170370567","rc":[{"atb":[[1.14,2.62]],"id":8509691}],"con":true,"img":false}]}
{"op":"mcm","clk":"1362428726","pt":1588450229391,"mc":[{"id":"1.170370564","rc":[{"atb":[[1.19,0]],"id":8509691}],"con":true,"img":false}]}
{"op":"mcm","clk":"1362428741","pt":1588450230056,"mc":[{"id":"1.170370564","rc":[{"atl":[[1.23,0]],"id":8509691}],"con":true,"img":false}]}
{"op":"mcm","clk":"1362428754","pt":1588450230872,"mc":[{"id":"1.170370564","rc":[{"trd":[[1.18,997.88]],"ltp":1.18,"tv":997.88,"id":8509691},{"atb":[[1.18,204.25]],"id":8509691}],"con":true,"img":false}]}
{"op":"mcm","clk":"1362428764","pt":1588450231280,"mc":[{"id":"1.170370564","rc":[{"atl":[[1.27,0]],"id":8509691}],"con":true,"img":false}]}
{"op":"mcm","clk":"1362428770","pt":1588450231383,"mc":[{"id":"1.170370564","rc":[{"atb":[[1.13,0]],"id":8509691}],"con":true,"img":false}]}
{"op":"mcm","clk":"1362428798","pt":1588450232761,"mc":[{"id":"1.170370564","rc":[{"trd":[[1.18,1397.87]],"ltp":1.18,"tv":1397.87,"id":8509691},{"atb":[[1.18,4.26]],"id":8509691}],"con":true,"img":false}]}
{"op":"mcm","clk":"1362428827","pt":1588450234090,"mc":[{"id":"1.170370564","rc":[{"atl":[[1.3,1.42]],"id":8509691}],"con":true,"img":false}]}
{"op":"mcm","clk":"1362428872","pt":1588450236487,"mc":[{"id":"1.170370564","rc":[{"atb":[[1.12,17.75]],"id":8509691}],"con":true,"img":false}]}
{"op":"mcm","clk":"1362428932","pt":1588450239905,"mc":[{"id":"1.170370564","rc":[{"atb":[[1.11,503.89]],"id":8509691}],"con":true,"img":false}]}
{"op":"mcm","clk":"1362428956","pt":1588450240976,"mc":[{"id":"1.170370564","rc":[{"trd":[[1.3,5850.57]],"ltp":1.3,"tv":5850.57,"id":8509691},{"atl":[[1.3,0.21]],"id":8509691}],"con":true,"img":false}]}
{"op":"mcm","clk":"1362428976","pt":1588450241892,"mc":[{"id":"1.170370564","rc":[{"atb":[[1.19,43.79]],"id":8509691}],"con":true,"img":false}]}
{"op":"mcm","clk":"1362428989","pt":1588450242405,"mc":[{"id":"1.170370564","rc":[{"atb":[[1.12,0]],"id":8509691}],"con":true,"img":false}]}
{"op":"mcm","clk":"1362429001","pt":1588450242965,"mc":[{"id":"1.170370566","rc":[{"atb":[[2.12,0]],"id":9630572},{"atl":[[1.89,9.62]],"id":8509691}],"con":true,"img":false}]}
{"op":"mcm","clk":"1362429006","pt":1588450243170,"mc":[{"id":"1.170370564","rc":[{"atb":[[1.11,495.83]],"id":8509691}],"con":true,"img":false}]}
{"op":"mcm","clk":"1362429017","pt":1588450243577,"mc":[{"id":"1.170370564","rc":[{"atb":[[1.16,4.79]],"id":8509691}],"con":true,"img":false}]}
{"op":"mcm","clk":"1362429067","pt":1588450246585,"mc":[{"id":"1.170370564","rc":[{"atb":[[1.19,46.23]],"id":8509691}],"con":true,"img":false}]}
{"op":"mcm","clk":"1362429078","pt":1588450247503,"mc":[{"id":"1.170370564","rc":[{"atb":[[1.13,17.75]],"id":8509691}],"con":true,"img":false}]}
{"op":"mcm","clk":"1362429079","pt":1588450247605,"mc":[{"id":"1.170370564","rc":[{"atb":[[3.2,0]],"id":9630572}],"con":true,"img":false}]}
{"op":"mcm","clk":"1362429201","pt":1588450257398,"mc":[{"id":"1.170370564","rc":[{"atb":[[1.19,43.79]],"id":8509691},{"atl":[[1.34,17.51]],"id":8509691}],"con":true,"img":false}]}
{"op":"mcm","clk":"1362429226","pt":1588450258978,"mc":[{"id":"1.170370566","rc":[{"atl":[[1.89,0]],"id":8509691}],"con":true,"img":false}]}
{"op":"mcm","clk":"1362429287","pt":1588450264339,"mc":[{"id":"1.170370564","rc":[{"atl":[[1.47,6.8]],"id":8509691}],"con":true,"img":false}]}
{"op":"mcm","clk":"1362429293","pt":1588450265001,"mc":[{"id":"1.170370564","rc":[{"atl":[[5.3,2.44]],"id":9630572}],"con":true,"img":false}]}
{"op":"mcm","clk":"1362429296","pt":1588450265204,"mc":[{"id":"1.170370564","rc":[{"atl":[[1.47,0]],"id":8509691}],"con":true,"img":false}]}
{"op":"mcm","clk":"1362429305","pt":1588450265916,"mc":[{"id":"1.170370564","rc":[{"atb":[[1.11,511.7]],"id":8509691}],"con":true,"img":false}]}
{"op":"mcm","clk":"1362429309","pt":1588450266323,"mc":[{"id":"1.170370566","rc":[{"atb":[[1.1,0]],"id":9630572}],"con":true,"img":false}]}
{"op":"mcm","clk":"1362429352","pt":1588450270201,"mc":[{"id":"1.170370564","rc":[{"trd":[[4.3,265.5]],"ltp":4.3,"tv":265.5,"id":9630572},{"trd":[[1.3,5850.68]],"ltp":1.3,"tv":5850.68,"id":8509691},{"atl":[[1.3,0.1]],"id":8509691}],"con":true,"img":false}]}
{"op":"mcm","clk":"1362429371","pt":1588450271422,"mc":[{"id":"1.170370566","rc":[{"atb":[[1.14,97.58]],"id":9630572}],"con":true,"img":false}]}
{"op":"mcm","clk":"1362429403","pt":1588450273912,"mc":[{"id":"1.170370564","rc":[{"atb":[[1.13,0]],"id":8509691}],"con":true,"img":false},{"id":"1.170370566","rc":[{"atl":[[6.4,13.55]],"id":8509691}],"con":true,"img":false}]}
{"op":"mcm","clk":"1362429438","pt":1588450276047,"mc":[{"id":"1.170370564","rc":[{"atl":[[1.3,0]],"id":8509691}],"con":true,"img":false}]}
{"op":"mcm","clk":"1362429471","pt":1588450277726,"mc":[{"id":"1.170370564","rc":[{"atb":[[1.3,2.44]],"id":8509691}],"con":true,"img":false}]}
{"op":"mcm","clk":"1362429492","pt":1588450279049,"mc":[{"id":"1.170370564","rc":[{"atb":[[1.12,17.75]],"id":8509691}],"con":true,"img":false}]}
{"op":"mcm","clk":"1362429589","pt":1588450284620,"mc":[{"id":"1.170370564","rc":[{"trd":[[1.3,5855.56]],"ltp":1.3,"tv":5855.56,"id":8509691},{"atb":[[1.3,0]],"id":8509691},{"atl":[[1.3,204.69]],"id":8509691}],"con":true,"img":false}]}
{"op":"mcm","clk":"1362429592","pt":1588450284724,"mc":[{"id":"1.170370564","rc":[{"atb":[[3.5,200]],"id":9630572}],"con":true,"img":false}]}
{"op":"mcm","clk":"1362429594","pt":1588450285234,"mc":[{"id":"1.170370564","rc":[{"trd":[[5.3,31.31]],"ltp":5.3,"tv":31.31,"id":9630572},{"atl":[[5.3,0.41]],"id":9630572},{"trd":[[1.23,1194.33]],"ltp":1.23,"tv":1194.33,"id":8509691}],"con":true,"img":false}]}
{"op":"mcm","clk":"1362429640","pt":1588450287947,"mc":[{"id":"1.170370564","rc":[{"atl":[[1.3,207.31]],"id":8509691}],"con":true,"img":false}]}
{"op":"mcm","clk":"1362429646","pt":1588450288152,"mc":[{"id":"1.170370564","rc":[{"trd":[[5.3,31.72]],"ltp":5.3,"tv":31.72,"id":9630572},{"atl":[[5.3,0]],"id":9630572},{"trd":[[1.23,1196.1]],"ltp":1.23,"tv":1196.1,"id":8509691},{"atl":[[1.23,14.37]],"id":8509691}],"con":true,"img":false}]}
{"op":"mcm","clk":"1362429661","pt":1588450289072,"mc":[{"id":"1.170370564","rc":[{"atl":[[1.3,207.49]],"id":8509691}],"con":true,"img":false}]}
{"op":"mcm","clk":"1362429674","pt":1588450289942,"mc":[{"id":"1.170370564","rc":[{"atl":[[1.5,26.68]],"id":8509691}],"con":true,"img":false}]}
{"op":"mcm","clk":"1362429690","pt":1588450291163,"mc":[{"id":"1.170370564","rc":[{"atb":[[1.19,0]],"id":8509691},{"atl":[[1.34,0]],"id":8509691}],"con":true,"img":false}]}
{"op":"mcm","clk":"1362429722","pt":1588450293048,"mc":[{"id":"1.170370564","rc":[{"atl":[[1.3,204.86]],"id":8509691}],"con":true,"img":false}]}
{"op":"mcm","clk":"1362429800","pt":1588450298191,"mc":[{"id":"1.170370564","rc":[{"trd":[[1.18,1403.12]],"ltp":1.18,"tv":1403.12,"id":8509691},{"atb":[[1.18,1.64]],"id":8509691}],"con":true,"img":false}]}
{"op":"mcm","clk":"1362429802","pt":1588450298548,"mc":[{"id":"1.170370564","rc":[{"trd":[[1.23,1198.94]],"ltp":1.23,"tv":1198.94,"id":8509691},{"atl":[[1.23,12.95]],"id":8509691}],"con":true,"img":false}]}
{"op":"mcm","clk":"1362429846","pt":1588450302162,"mc":[{"id":"1.170370564","rc":[{"atb":[[1.12,0]],"id":8509691}],"con":true,"img":false}]}
{"op":"mcm","clk":"1362429920","pt":1588450307298,"mc":[{"id":"1.170370564","rc":[{"atb":[[1.13,17.75]],"id":8509691}],"con":true,"img":false}]}
{"op":"mcm","clk":"1362429995","pt":1588450314575,"mc":[{"id":"1.170370566","rc":[{"atb":[[1.12,0]],"id":9630572}],"con":true,"img":false}]}
{"op":"mcm","clk":"1362430020","pt":1588450316609,"mc":[{"id":"1.170370564","rc":[{"atl":[[1.3,206.28]],"id":8509691}],"con":true,"img":false}]}
{"op":"mcm","clk":"1362430028","pt":1588450317016,"mc":[{"id":"1.170370564","rc":[{"atb":[[1.12,166.63],[1.15,22.26]],"id":8509691}],"con":true,"img":false}]}
{"op":"mcm","clk":"1362430032","pt":1588450317170,"mc":[{"id":"1.170370564","rc":[{"atb":[[1.11,216.48]],"id":8509691}],"con":true,"img":false}]}
{"op":"mcm","clk":"1362430039","pt":1588450317679,"mc":[{"id":"1.170370564","rc":[{"trd":[[5.3,34.73]],"ltp":5.3,"tv":34.73,"id":9630572},{"atl":[[5.3,7.74]],"id":9630572},{"trd":[[1.23,1211.89]],"ltp":1.23,"tv":1211.89,"id":8509691},{"atl":[[1.23,0]],"id":8509691}],"con":true,"img":false}]}
{"op":"mcm","clk":"1362430046","pt":1588450318188,"mc":[{"id":"1.170370564","rc":[{"atb":[[1.12,0]],"id":8509691}],"con":true,"img":false}]}
{"op":"mcm","clk":"1362430049","pt":1588450318493,"mc":[{"id":"1.170370564","rc":[{"atb":[[1.11,15.86]],"id":8509691}],"con":true,"img":false}]}
{"op":"mcm","clk":"1362430076","pt":1588450320891,"mc":[{"id":"1.170370564","rc":[{"atl":[[1.3,1.59]],"id":8509691}],"con":true,"img":false}]}
{"op":"mcm","clk":"1362430085","pt":1588450321506,"mc":[{"id":"1.170370564","rc":[{"atl":[[1.3,1.42]],"id":8509691}],"con":true,"img":false}]}
{"op":"mcm","clk":"1362430146","pt":1588450326509,"mc":[{"id":"1.170370564","rc":[{"trd":[[5.3,42.47]],"ltp":5.3,"tv":42.47,"id":9630572},{"atl":[[5.3,0]],"id":9630572},{"trd":[[1.23,1245.24]],"ltp":1.23,"tv":1245.24,"id":8509691},{"atl":[[1.23,182.99]],"id":8509691}],"con":true,"img":false}]}
{"op":"mcm","clk":"1362430156","pt":1588450327019,"mc":[{"id":"1.170370564","rc":[{"atl":[[1.23,0]],"id":8509691}],"con":true,"img":false}]}
{"op":"mcm","clk":"1362430164","pt":1588450327324,"mc":[{"id":"1.170370566","rc":[{"atb":[[1.14,0]],"id":9630572}],"con":true,"img":false}]}
{"op":"mcm","clk":"1362430220","pt":1588450331193,"mc":[{"id":"1.170370564","rc":[{"atl":[[1.5,29.88]],"id":8509691}],"con":true,"img":false}]}
{"op":"mcm","clk":"1362430236","pt":1588450332314,"mc":[{"id":"1.170370564","rc":[{"atb":[[1.13,0]],"id":8509691}],"con":true,"img":false}]}
{"op":"mcm","clk":"1362430244","pt":1588450332722,"mc":[{"id":"1.170370564","rc":[{"atl":[[1.3,174.55]],"id":8509691}],"con":true,"img":false}]}
{"op":"mcm","clk":"1362430248","pt":1588450332822,"mc":[{"id":"1.170370566","rc":[{"atb":[[1.2,79.98]],"id":9630572}],"con":true,"img":false}]}
{"op":"mcm","clk":"1362430309","pt":1588450337403,"mc":[{"id":"1.170370564","rc":[{"atb":[[1.12,17.75]],"id":8509691}],"con":true,"img":false}]}
{"op":"mcm","clk":"1362430318","pt":1588450338115,"mc":[{"id":"1.170370564","rc":[{"atl":[[1.23,5]],"id":8509691}],"con":true,"img":false}]}
{"op":"mcm","clk":"1362430361","pt":1588450340813,"mc":[{"id":"1.170370564","rc":[{"atl":[[1.5,26.68]],"id":8509691}],"con":true,"img":false}]}
{"op":"mcm","clk":"1362430380","pt":1588450342035,"mc":[{"id":"1.170370566","rc":[{"atl":[[6.4,0]],"id":8509691}],"con":true,"img":false}]}
{"op":"mcm","clk":"1362430438","pt":1588450345345,"mc":[{"id":"1.170370564","rc":[{"atb":[[1.17,3.54]],"id":8509691}],"con":true,"img":false}]}
{"op":"mcm","clk":"1362430467","pt":1588450347127,"mc":[{"id":"1.170370566","rc":[{"atl":[[5.9,13.55]],"id":8509691}],"con":true,"img":false}]}
{"op":"mcm","clk":"1362430475","pt":1588450347535,"mc":[{"id":"1.170370564","rc":[{"atb":[[1.12,0]],"id":8509691}],"con":true,"img":false}]}
{"op":"mcm","clk":"1362430519","pt":1588450349775,"mc":[{"id":"1.170370564","rc":[{"trd":[[1.23,1252.24]],"ltp":1.23,"tv":1252.24,"id":8509691},{"atl":[[1.23,1.5]],"id":8509691}],"con":true,"img":false}]}
{"op":"mcm","clk":"1362430546","pt":1588450351252,"mc":[{"id":"1.170370566","rc":[{"atb":[[1.2,0]],"id":9630572}],"con":true,"img":false}]}
{"op":"mcm","clk":"1362430591","pt":1588450354153,"mc":[{"id":"1.170370564","rc":[{"atb":[[1.15,10]],"id":8509691}],"con":true,"img":false}]}
{"op":"mcm","clk":"1362430615","pt":1588450356086,"mc":[{"id":"1.170370564","rc":[{"atb":[[1.2,2]],"id":8509691}],"con":true,"img":false}]}
{"op":"mcm","clk":"1362430620","pt":1588450356340,"mc":[{"id":"1.170370566","rc":[{"atb":[[1.21,79.98]],"id":9630572}],"con":true,"img":false}]}
{"op":"mcm","clk":"1362430631","pt":1588450357560,"mc":[{"id":"1.170370564","rc":[{"trd":[[7.4,0.17],[6,1.5],[7,40.29],[6.6,22.07]],"ltp":7.4,"tv":64.03,"id":9630572},{"trd":[[1.16,527.9],[1.18,1404.76],[1.2,1092.03],[1.17,941.93]],"ltp":1.16,"tv":3966.62,"id":8509691},{"atb":[[1.2,0],[1.18,0],[1.16,3.7],[1.17,0]],"id":8509691}],"con":true,"img":false}]}
{"op":"mcm","clk":"1362430641","pt":1588450358477,"mc":[{"id":"1.170370564","rc":[{"atl":[[6.8,10]],"id":9630572}],"con":true,"img":false}]}
{"op":"mcm","clk":"1362430659","pt":1588450360055,"mc":[{"id":"1.170370566","rc":[{"atl":[[5.9,0]],"id":8509691}],"con":true,"img":false}]}
{"op":"mcm","clk":"1362430679","pt":1588450362191,"mc":[{"id":"1.170370564","rc":[{"atb":[[1.16,11.7]],"id":8509691}],"con":true,"img":false}]}
{"op":"mcm","clk":"1362430686","pt":1588450362650,"mc":[{"id":"1.170370566","rc":[{"atb":[[1.21,0]],"id":9630572}],"con":true,"img":false}]}
{"op":"mcm","clk":"1362430720","pt":1588450365195,"mc":[{"id":"1.170370566","rc":[{"atl":[[5.7,13.55]],"id":8509691}],"con":true,"img":false}]}
{"op":"mcm","clk":"1362430728","pt":1588450366060,"mc":[{"id":"1.170370564","rc":[{"atl":[[1.2,4.43]],"id":8509691}],"con":true,"img":false}]}
{"op":"mcm","clk":"1362430737","pt":1588450366874,"mc":[{"id":"1.170370564","rc":[{"trd":[[1.2,1092.07]],"ltp":1.2,"tv":1092.07,"id":8509691},{"atl":[[1.2,4.41]],"id":8509691}],"con":true,"img":false}]}
{"op":"mcm","clk":"1362430742","pt":1588450367484,"mc":[{"id":"1.170370564","rc":[{"trd":[[1.2,1097.32]],"ltp":1.2,"tv":1097.32,"id":8509691},{"atl":[[1.2,1.79]],"id":8509691}],"con":true,"img":false}]}
{"op":"mcm","clk":"1362430764","pt":1588450370385,"mc":[{"id":"1.170370564","rc":[{"atb":[[1.16,3.7]],"id":8509691}],"con":true,"img":false}]}
{"op":"mcm","clk":"1362430775","pt":1588450371808,"mc":[{"id":"1.170370564","rc":[{"trd":[[1.2,1097.83]],"ltp":1.2,"tv":1097.83,"id":8509691},{"atl":[[1.2,1.53]],"id":8509691}],"con":true,"img":false}]}
{"op":"mcm","clk":"1362430805","pt":1588450373896,"mc":[{"id":"1.170370564","rc":[{"atb":[[1.14,16.26]],"id":8509691}],"con":true,"img":false}]}
{"op":"mcm","clk":"1362430811","pt":1588450374303,"mc":[{"id":"1.170370564","rc":[{"atl":[[6.8,0]],"id":9630572}],"con":true,"img":false}]}
{"op":"mcm","clk":"1362430831","pt":1588450375473,"mc":[{"id":"1.170370564","rc":[{"atb":[[1.14,24.26]],"id":8509691}],"con":true,"img":false}]}
{"op":"mcm","clk":"1362430837","pt":1588450376082,"mc":[{"id":"1.170370564","rc":[{"trd":[[1.2,1100.9]],"ltp":1.2,"tv":1100.9,"id":8509691},{"atb":[[1.2,1.97]],"id":8509691},{"atl":[[1.2,0]],"id":8509691}],"con":true,"img":false}]}
{"op":"mcm","clk":"1362430891","pt":1588450381020,"mc":[{"id":"1.170370564","rc":[{"atb":[[1.19,79.98]],"id":8509691}],"con":true,"img":false}]}
{"op":"mcm","clk":"1362430921","pt":1588450383727,"mc":[{"id":"1.170370564","rc":[{"atl":[[1.3,173.13]],"id":8509691}],"con":true,"img":false}]}
{"op":"mcm","clk":"1362430943","pt":1588450385665,"mc":[{"id":"1.170370564","rc":[{"atb":[[1.2,0]],"id":8509691}],"con":true,"img":false}]}
{"op":"mcm","clk":"1362430982","pt":1588450389328,"mc":[{"id":"1.170370564","rc":[{"atb":[[1.15,12.55]],"id":8509691}],"con":true,"img":false}]}
{"op":"mcm","clk":"1362430983","pt":1588450389430,"mc":[{"id":"1.170370564","rc":[{"trd":[[1.19,772.8]],"ltp":1.19,"tv":772.8,"id":8509691},{"atb":[[1.19,77.98]],"id":8509691}],"con":true,"img":false}]}
{"op":"mcm","clk":"1362431040","pt":1588450393957,"mc":[{"id":"1.170370564","rc":[{"atb":[[1.17,4.43]],"id":8509691}],"con":true,"img":false}]}
{"op":"mcm","clk":"1362431049","pt":1588450394669,"mc":[{"id":"1.170370564","rc":[{"trd":[[1.23,1252.44]],"ltp":1.23,"tv":1252.44,"id":8509691},{"atb":[[1.14,16.26]],"id":8509691},{"atl":[[1.23,1.4]],"id":8509691}],"con":true,"img":false}]}
{"op":"mcm","clk":"1362431061","pt":1588450395229,"mc":[{"id":"1.170370564","rc":[{"atb":[[1.17,8.98]],"id":8509691}],"con":true,"img":false}]}
{"op":"mcm","clk":"1362431115","pt":1588450399756,"mc":[{"id":"1.170370564","rc":[{"atb":[[1.12,7.99]],"id":8509691}],"con":true,"img":false}]}
{"op":"mcm","clk":"1362431146","pt":1588450402351,"mc":[{"id":"1.170370564","rc":[{"atl":[[1000,2]],"id":8509691}],"con":true,"img":false}]}
{"op":"mcm","clk":"1362431151","pt":1588450402657,"mc":[{"id":"1.170370564","rc":[{"atl":[[1000,0.2]],"id":8509691}],"con":true,"img":false}]}
{"op":"mcm","clk":"1362431155","pt":1588450402861,"mc":[{"id":"1.170370564","rc":[{"atl":[[1000,0]],"id":8509691}],"con":true,"img":false}]}
{"op":"mcm","clk":"1362431157","pt":1588450402963,"mc":[{"id":"1.170370564","rc":[{"atl":[[1000,2]],"id":8509691}],"con":true,"img":false}]}
{"op":"mcm","clk":"1362431163","pt":1588450403167,"mc":[{"id":"1.170370564","rc":[{"atl":[[1000,0.2]],"id":8509691}],"con":true,"img":false}]}
{"op":"mcm","clk":"1362431167","pt":1588450403371,"mc":[{"id":"1.170370564","rc":[{"atl":[[1000,2]],"id":8509691}],"con":true,"img":false}]}
{"op":"mcm","clk":"1362431170","pt":1588450403576,"mc":[{"id":"1.170370564","rc":[{"atl":[[1000,0.2]],"id":8509691}],"con":true,"img":false}]}
{"op":"mcm","clk":"1362431173","pt":1588450403779,"mc":[{"id":"1.170370564","rc":[{"atl":[[1000,0]],"id":8509691}],"con":true,"img":false}]}
{"op":"mcm","clk":"1362431179","pt":1588450404085,"mc":[{"id":"1.170370564","rc":[{"atl":[[1.28,195]],"id":8509691}],"con":true,"img":false}]}
{"op":"mcm","clk":"1362431188","pt":1588450404543,"mc":[{"id":"1.170370564","rc":[{"trd":[[1.19,778.73]],"ltp":1.19,"tv":778.73,"id":8509691},{"atb":[[1.19,75.01]],"id":8509691}],"con":true,"img":false}]}
{"op":"mcm","clk":"1362431213","pt":1588450406482,"mc":[{"id":"1.170370564","rc":[{"atl":[[1.25,1.42]],"id":8509691}],"con":true,"img":false}]}
{"op":"mcm","clk":"1362431216","pt":1588450406583,"mc":[{"id":"1.170370564","rc":[{"atl":[[1.3,0]],"id":8509691}],"con":true,"img":false}]}
{"op":"mcm","clk":"1362431234","pt":1588450407960,"mc":[{"id":"1.170370564","rc":[{"trd":[[1.28,6745.83],[1.2,1101.3],[1.23,1255.24],[1.25,3895.76]],"ltp":1.28,"tv":12998.13,"id":8509691},{"atl":[[1.28,194.93],[1.23,0],[1.25,0]],"id":8509691}],"con":true,"img":false}]}
{"op":"mcm","clk":"1362431238","pt":1588450408468,"mc":[{"id":"1.170370564","rc":[{"atl":[[1.21,0.2]],"id":8509691}],"con":true,"img":false}]}
{"op":"mcm","clk":"1362431246","pt":1588450408875,"mc":[{"id":"1.170370564","rc":[{"atl":[[1.22,0.2]],"id":8509691}],"con":true,"img":false}]}
{"op":"mcm","clk":"1362431282","pt":1588450411367,"mc":[{"id":"1.170370567","rc":[{"atb":[[2.5,0]],"id":9630572}],"con":true,"img":false}]}
{"op":"mcm","clk":"1362431295","pt":1588450412282,"mc":[{"id":"1.170370564","rc":[{"atl":[[1.27,177.22]],"id":8509691}],"con":true,"img":false}]}
{"op":"mcm","clk":"1362431344","pt":1588450416351,"mc":[{"id":"1.170370564","rc":[{"trd":[[1.21,3214.68]],"ltp":1.21,"tv":3214.68,"id":8509691},{"atl":[[1.21,0.05]],"id":8509691}],"con":true,"img":false}]}
{"op":"mcm","clk":"1362431360","pt":1588450417774,"mc":[{"id":"1.170370564","rc":[{"atl":[[1000,2]],"id":8509691}],"con":true,"img":false}]}
{"op":"mcm","clk":"1362431365","pt":1588450417977,"mc":[{"id":"1.170370564","rc":[{"atl":[[1000,0.2]],"id":8509691}],"con":true,"img":false}]}
{"op":"mcm","clk":"1362431367","pt":1588450418182,"mc":[{"id":"1.170370564","rc":[{"atl":[[1000,0]],"id":8509691}],"con":true,"img":false}]}
{"op":"mcm","clk":"1362431372","pt":1588450418386,"mc":[{"id":"1.170370564","rc":[{"atl":[[1.26,18.25]],"id":8509691}],"con":true,"img":false}]}
{"op":"mcm","clk":"1362431438","pt":1588450423272,"mc":[{"id":"1.170370564","rc":[{"atl":[[1.2,0.2]],"id":8509691}],"con":true,"img":false}]}
{"op":"mcm","clk":"1362431454","pt":1588450424393,"mc":[{"id":"1.170370564","rc":[{"atb":[[1.1,1098.72]],"id":8509691}],"con":true,"img":false}]}
{"op":"mcm","clk":"1362431487","pt":1588450426991,"mc":[{"id":"1.170370564","rc":[{"trd":[[1.2,1101.7]],"ltp":1.2,"tv":1101.7,"id":8509691},{"atb":[[1.2,17.31]],"id":8509691},{"atl":[[1.2,0]],"id":8509691}],"con":true,"img":false}]}
{"op":"mcm","clk":"1362431490","pt":1588450427093,"mc":[{"id":"1.170370564","rc":[{"atl":[[1000,2]],"id":8509691}],"con":true,"img":false}]}
{"op":"mcm","clk":"1362431493","pt":1588450427297,"mc":[{"id":"1.170370564","rc":[{"atl":[[1000,0.2]],"id":8509691}],"con":true,"img":false}]}
{"op":"mcm","clk":"1362431495","pt":1588450427501,"mc":[{"id":"1.170370564","rc":[{"atl":[[1000,2]],"id":8509691}],"con":true,"img":false}]}
{"op":"mcm","clk":"1362431500","pt":1588450427704,"mc":[{"id":"1.170370564","rc":[{"atl":[[1.28,0],[1000,0.2],[1.22,0]],"id":8509691}],"con":true,"img":false}]}
{"op":"mcm","clk":"1362431504","pt":1588450427958,"mc":[{"id":"1.170370564","rc":[{"atl":[[1000,0]],"id":8509691}],"con":true,"img":false}]}
{"op":"mcm","clk":"1362431551","pt":1588450431978,"mc":[{"id":"1.170370564","rc":[{"atl":[[1.35,1.74]],"id":8509691}],"con":true,"img":false}]}
{"op":"mcm","clk":"1362431558","pt":1588450432283,"mc":[{"id":"1.170370564","rc":[{"trd":[[1.26,3783],[1.21,3214.8]],"ltp":1.26,"tv":6997.8,"id":8509691},{"atl":[[1.21,0],[1.26,18.24]],"id":8509691}],"con":true,"img":false}]}
{"op":"mcm","clk":"1362431562","pt":1588450432588,"mc":[{"id":"1.170370564","rc":[{"atl":[[1.21,0.2]],"id":8509691}],"con":true,"img":false}]}
{"op":"mcm","clk":"1362431563","pt":1588450432792,"mc":[{"id":"1.170370564","rc":[{"trd":[[1.2,1102.1]],"ltp":1.2,"tv":1102.1,"id":8509691},{"atb":[[1.2,17.11]],"id":8509691},{"atl":[[1.26,213.17]],"id":8509691}],"con":true,"img":false}]}
{"op":"mcm","clk":"1362431569","pt":1588450433097,"mc":[{"id":"1.170370564","rc":[{"atl":[[1.21,0.4]],"id":8509691}],"con":true,"img":false}]}
{"op":"mcm","clk":"1362431584","pt":1588450434775,"mc":[{"id":"1.170370564","rc":[{"atl":[[1000,2]],"id":8509691}],"con":true,"img":false}]}
{"op":"mcm","clk":"1362431588","pt":1588450434980,"mc":[{"id":"1.170370564","rc":[{"atl":[[1000,0.2]],"id":8509691}],"con":true,"img":false}]}
{"op":"mcm","clk":"1362431591","pt":1588450435286,"mc":[{"id":"1.170370564","rc":[{"atl":[[1000,0]],"id":8509691}],"con":true,"img":false}]}
{"op":"mcm","clk":"1362431603","pt":1588450436201,"mc":[{"id":"1.170370564","rc":[{"atl":[[1.27,0]],"id":8509691}],"con":true,"img":false}]}
{"op":"mcm","clk":"1362431642","pt":1588450439710,"mc":[{"id":"1.170370564","rc":[{"atb":[[1.08,1002.65]],"id":8509691},{"atl":[[1.26,221.92]],"id":8509691}],"con":true,"img":false}]}
{"op":"mcm","clk":"1362431644","pt":1588450440014,"mc":[{"id":"1.170370564","rc":[{"atl":[[1000,2]],"id":8509691}],"con":true,"img":false}]}
{"op":"mcm","clk":"1362431648","pt":1588450440219,"mc":[{"id":"1.170370564","rc":[{"atb":[[1.07,845.74]],"id":8509691},{"atl":[[1000,0.2]],"id":8509691}],"con":true,"img":false}]}
{"op":"mcm","clk":"1362431651","pt":1588450440371,"mc":[{"id":"1.170370564","rc":[{"atl":[[1.21,0.6]],"id":8509691}],"con":true,"img":false}]}
{"op":"mcm","clk":"1362431652","pt":1588450440473,"mc":[{"id":"1.170370564","rc":[{"atl":[[1000,0]],"id":8509691}],"con":true,"img":false}]}
{"op":"mcm","clk":"1362431666","pt":1588450441695,"mc":[{"id":"1.170370564","rc":[{"atl":[[1.21,0]],"id":8509691}],"con":true,"img":false}]}
{"op":"mcm","clk":"1362431677","pt":1588450442410,"mc":[{"id":"1.170370564","rc":[{"atl":[[1.26,26.99]],"id":8509691}],"con":true,"img":false}]}
{"op":"mcm","clk":"1362431682","pt":1588450442715,"mc":[{"id":"1.170370564","rc":[{"atl":[[1.25,180.06]],"id":8509691}],"con":true,"img":false}]}
{"op":"mcm","clk":"1362431695","pt":1588450443992,"mc":[{"id":"1.170370566","rc":[{"atl":[[5.7,0]],"id":8509691}],"con":true,"img":false}]}
{"op":"mcm","clk":"1362431703","pt":1588450444908,"mc":[{"id":"1.170370564","rc":[{"atb":[[1.01,5855.1],[1.03,1336.11],[1.02,3378.43],[1.06,1490.02],[1.05,1599.72],[1.04,1999.66]],"id":8509691}],"con":true,"img":false}]}
{"op":"mcm","clk":"1362431709","pt":1588450445622,"mc":[{"id":"1.170370564","rc":[{"atl":[[1.21,0.2]],"id":8509691}],"con":true,"img":false}]}
{"op":"mcm","clk":"1362431726","pt":1588450446791,"mc":[{"id":"1.170370564","rc":[{"trd":[[1.2,1103.3]],"ltp":1.2,"tv":1103.3,"id":8509691},{"atb":[[1.2,16.51]],"id":8509691}],"con":true,"img":false}]}
{"op":"mcm","clk":"1362431733","pt":1588450447504,"mc":[{"id":"1.170370564","rc":[{"atl":[[1.25,374.99]],"id":8509691}],"con":true,"img":false}]}
{"op":"mcm","clk":"1362431738","pt":1588450447911,"mc":[{"id":"1.170370564","rc":[{"atl":[[1.21,0]],"id":8509691}],"con":true,"img":false}]}
{"op":"mcm","clk":"1362431765","pt":1588450450096,"mc":[{"id":"1.170370564","rc":[{"atl":[[1.26,8.75]],"id":8509691}],"con":true,"img":false}]}
{"op":"mcm","clk":"1362431791","pt":1588450452894,"mc":[{"id":"1.170370564","rc":[{"atb":[[1.2,28.78]],"id":8509691}],"con":true,"img":false}]}
{"op":"mcm","clk":"1362431792","pt":1588450452996,"mc":[{"id":"1.170370564","rc":[{"trd":[[1.2,1103.7]],"ltp":1.2,"tv":1103.7,"id":8509691},{"atb":[[1.2,28.58],[1.1,508.3]],"id":8509691}],"con":true,"img":false}]}
{"op":"mcm","clk":"1362431805","pt":1588450453809,"mc":[{"id":"1.170370564","rc":[{"atb":[[1.18,2.26]],"id":8509691}],"con":true,"img":false}]}
{"op":"mcm","clk":"1362431808","pt":1588450454013,"mc":[{"id":"1.170370564","rc":[{"atb":[[1.09,691.55]],"id":8509691}],"con":true,"img":false}]}
{"op":"mcm","clk":"1362431819","pt":1588450455233,"mc":[{"id":"1.170370564","rc":[{"atl":[[1.24,18.24]],"id":8509691}],"con":true,"img":false}]}
{"op":"mcm","clk":"1362431830","pt":1588450456707,"mc":[{"id":"1.170370564","rc":[{"atb":[[1.01,5857.1]],"id":8509691}],"con":true,"img":false}]}
{"op":"mcm","clk":"1362431834","pt":1588450457010,"mc":[{"id":"1.170370564","rc":[{"atb":[[1.01,5857.3]],"id":8509691}],"con":true,"img":false}]}
{"op":"mcm","clk":"1362431835","pt":1588450457112,"mc":[{"id":"1.170370564","rc":[{"atb":[[1.11,0]],"id":8509691}],"con":true,"img":false}]}
{"op":"mcm","clk":"1362431838","pt":1588450457214,"mc":[{"id":"1.170370564","rc":[{"atb":[[1.01,5855.3]],"id":8509691}],"con":true,"img":false}]}
{"op":"mcm","clk":"1362431842","pt":1588450457519,"mc":[{"id":"1.170370564","rc":[{"atb":[[1.01,5855.1]],"id":8509691}],"con":true,"img":false}]}
{"op":"mcm","clk":"1362431844","pt":1588450457722,"mc":[{"id":"1.170370564","rc":[{"atb":[[1.01,5857.1]],"id":8509691}],"con":true,"img":false}]}
{"op":"mcm","clk":"1362431846","pt":1588450457926,"mc":[{"id":"1.170370564","rc":[{"atb":[[1.01,5857.3]],"id":8509691}],"con":true,"img":false}]}
{"op":"mcm","clk":"1362431850","pt":1588450458129,"mc":[{"id":"1.170370564","rc":[{"atb":[[1.01,5855.1]],"id":8509691}],"con":true,"img":false}]}
{"op":"mcm","clk":"1362431859","pt":1588450458892,"mc":[{"id":"1.170370564","rc":[{"atb":[[1.01,5857.1]],"id":8509691}],"con":true,"img":false}]}
{"op":"mcm","clk":"1362431861","pt":1588450459095,"mc":[{"id":"1.170370564","rc":[{"atb":[[1.01,5857.3]],"id":8509691}],"con":true,"img":false}]}
{"op":"mcm","clk":"1362431864","pt":1588450459400,"mc":[{"id":"1.170370564","rc":[{"atb":[[1.01,5855.3]],"id":8509691}],"con":true,"img":false}]}
{"op":"mcm","clk":"1362432586","pt":1588450459603,"mc":[{"id":"1.170370564","rc":[{"atb":[[1.01,5855.1]],"id":8509691}],"con":true,"img":false}]}
{"op":"mcm","clk":"1362432607","pt":1588450462297,"mc":[{"id":"1.170370564","rc":[{"atb":[[1.12,8.19]],"id":8509691}],"con":true,"img":false}]}
{"op":"mcm","clk":"1362432612","pt":1588450462601,"mc":[{"id":"1.170370564","rc":[{"atb":[[1.12,8.39]],"id":8509691}],"con":true,"img":false}]}
{"op":"mcm","clk":"1362432618","pt":1588450463213,"mc":[{"id":"1.170370564","rc":[{"atb":[[1.11,0.2]],"id":8509691}],"con":true,"img":false}]}
{"op":"mcm","clk":"1362432629","pt":1588450464535,"mc":[{"id":"1.170370564","rc":[{"atb":[[1.1,508.5]],"id":8509691}],"con":true,"img":false}]}
{"op":"mcm","clk":"1362432632","pt":1588450464738,"mc":[{"id":"1.170370564","rc":[{"atb":[[1.1,508.7]],"id":8509691}],"con":true,"img":false}]}
{"op":"mcm","clk":"1362432649","pt":1588450466417,"mc":[{"id":"1.170370564","rc":[{"atl":[[1.24,26.99]],"id":8509691}],"con":true,"img":false}]}
{"op":"mcm","clk":"1362432678","pt":1588450469417,"mc":[{"id":"1.170370566","rc":[{"atl":[[11,89.98]],"id":8509691}],"con":true,"img":false}]}
{"op":"mcm","clk":"1362432722","pt":1588450473746,"mc":[{"id":"1.170370564","rc":[{"atb":[[1.1,108.77]],"id":8509691}],"con":true,"img":false}]}
{"op":"mcm","clk":"1362432738","pt":1588450475019,"mc":[{"id":"1.170370564","rc":[{"atb":[[1.01,5857.1]],"id":8509691}],"con":true,"img":false}]}
{"op":"mcm","clk":"1362432741","pt":1588450475326,"mc":[{"id":"1.170370564","rc":[{"atb":[[1.01,5855.3]],"id":8509691}],"con":true,"img":false}]}
{"op":"mcm","clk":"1362432743","pt":1588450475530,"mc":[{"id":"1.170370564","rc":[{"atb":[[1.01,5857.1]],"id":8509691}],"con":true,"img":false}]}
{"op":"mcm","clk":"1362432747","pt":1588450475834,"mc":[{"id":"1.170370564","rc":[{"atb":[[1.01,5855.3]],"id":8509691}],"con":true,"img":false}]}
{"op":"mcm","clk":"1362432753","pt":1588450476038,"mc":[{"id":"1.170370564","rc":[{"atb":[[1.01,5855.1]],"id":8509691}],"con":true,"img":false}]}
{"op":"mcm","clk":"1362432764","pt":1588450476445,"mc":[{"id":"1.170370564","rc":[{"atb":[[1.01,5857.1]],"id":8509691}],"con":true,"img":false}]}
{"op":"mcm","clk":"1362432769","pt":1588450476751,"mc":[{"id":"1.170370564","rc":[{"atb":[[1.01,5855.3]],"id":8509691}],"con":true,"img":false}]}
{"op":"mcm","clk":"1362432773","pt":1588450477054,"mc":[{"id":"1.170370564","rc":[{"atb":[[1.01,5855.1]],"id":8509691}],"con":true,"img":false}]}
{"op":"mcm","clk":"1362432779","pt":1588450477461,"mc":[{"id":"1.170370564","rc":[{"atb":[[1.2,40.84]],"id":8509691}],"con":true,"img":false}]}
{"op":"mcm","clk":"1362432807","pt":1588450479951,"mc":[{"id":"1.170370564","rc":[{"trd":[[1.24,2792.79]],"ltp":1.24,"tv":2792.79,"id":8509691},{"atb":[[1.24,33.28]],"id":8509691},{"atl":[[1.24,0]],"id":8509691}],"con":true,"img":false}]}
{"op":"mcm","clk":"1362432815","pt":1588450480664,"mc":[{"id":"1.170370564","rc":[{"atb":[[1.11,0.4]],"id":8509691}],"con":true,"img":false}]}
{"op":"mcm","clk":"1362432825","pt":1588450481171,"mc":[{"id":"1.170370564","rc":[{"atb":[[1.12,8.59]],"id":8509691}],"con":true,"img":false}]}
{"op":"mcm","clk":"1362432827","pt":1588450481273,"mc":[{"id":"1.170370564","rc":[{"atb":[[1.08,313.82]],"id":8509691}],"con":true,"img":false}]}
{"op":"mcm","clk":"1362432834","pt":1588450481831,"mc":[{"id":"1.170370564","rc":[{"atb":[[1.07,156.91]],"id":8509691},{"atl":[[1.25,194.93]],"id":8509691}],"con":true,"img":false}]}
{"op":"mcm","clk":"1362432839","pt":1588450482137,"mc":[{"id":"1.170370564","rc":[{"atb":[[1.1,108.97]],"id":8509691}],"con":true,"img":false}]}
{"op":"mcm","clk":"1362432861","pt":1588450484833,"mc":[{"id":"1.170370564","rc":[{"trd":[[1.25,3931.49]],"ltp":1.25,"tv":3931.49,"id":8509691},{"atl":[[1.25,177.07]],"id":8509691}],"con":true,"img":false}]}
{"op":"mcm","clk":"1362432877","pt":1588450487071,"mc":[{"id":"1.170370564","rc":[{"atl":[[1000,2.62]],"id":8509691}],"con":true,"img":false}]}
{"op":"mcm","clk":"1362432883","pt":1588450487580,"mc":[{"id":"1.170370564","rc":[{"trd":[[1.24,2859.37]],"ltp":1.24,"tv":2859.37,"id":8509691},{"atb":[[1.24,0]],"id":8509691},{"atl":[[1.24,148.22]],"id":8509691}],"con":true,"img":false}]}
{"op":"mcm","clk":"1362432886","pt":1588450487986,"mc":[{"id":"1.170370564","rc":[{"atl":[[1000,0.04]],"id":8509691}],"con":true,"img":false}]}
{"op":"mcm","clk":"1362432888","pt":1588450488037,"mc":[{"id":"1.170370564","rc":[{"atl":[[1.24,325.52]],"id":8509691}],"con":true,"img":false}]}
{"op":"mcm","clk":"1362432894","pt":1588450488851,"mc":[{"id":"1.170370564","rc":[{"atl":[[1000,0]],"id":8509691}],"con":true,"img":false}]}
{"op":"mcm","clk":"1362432912","pt":1588450490071,"mc":[{"id":"1.170370564","rc":[{"atl":[[1.24,148.22]],"id":8509691}],"con":true,"img":false}]}
{"op":"mcm","clk":"1362432920","pt":1588450491039,"mc":[{"id":"1.170370564","rc":[{"atl":[[1.25,189.33]],"id":8509691}],"con":true,"img":false}]}
{"op":"mcm","clk":"1362432923","pt":1588450491242,"mc":[{"id":"1.170370564","rc":[{"atl":[[1.24,150.22]],"id":8509691}],"con":true,"img":false}]}
{"op":"mcm","clk":"1362432939","pt":1588450493176,"mc":[{"id":"1.170370564","rc":[{"atb":[[1.21,2.87]],"id":8509691}],"con":true,"img":false}]}
{"op":"mcm","clk":"1362432954","pt":1588450493990,"mc":[{"id":"1.170370564","rc":[{"atl":[[1.24,150.26]],"id":8509691}],"con":true,"img":false}]}
{"op":"mcm","clk":"1362432963","pt":1588450494956,"mc":[{"id":"1.170370564","rc":[{"atb":[[1.01,1855.75],[1.03,3],[1.09,247.18],[1.02,1378.75],[1.06,156.91],[1.05,0],[1.04,0]],"id":8509691}],"con":true,"img":false}]}
{"op":"mcm","clk":"1362432965","pt":1588450495160,"mc":[{"id":"1.170370564","rc":[{"atl":[[1.24,187.86]],"id":8509691}],"con":true,"img":false}]}
{"op":"mcm","clk":"1362433018","pt":1588450501673,"mc":[{"id":"1.170370564","rc":[{"atl":[[1.24,185.86]],"id":8509691}],"con":true,"img":false}]}
{"op":"mcm","clk":"1362433073","pt":1588450506071,"mc":[{"id":"1.170370564","rc":[{"trd":[[1.24,2887.24]],"ltp":1.24,"tv":2887.24,"id":8509691},{"atl":[[1.24,171.93]],"id":8509691}],"con":true,"img":false}]}
{"op":"mcm","clk":"1362433078","pt":1588450506580,"mc":[{"id":"1.170370564","rc":[{"atb":[[1.1,8.97]],"id":8509691}],"con":true,"img":false}]}
{"op":"mcm","clk":"1362433098","pt":1588450508005,"mc":[{"id":"1.170370566","rc":[{"atb":[[1.08,2.62]],"id":8509691}],"con":true,"img":false}]}
{"op":"mcm","clk":"1362433127","pt":1588450511210,"mc":[{"id":"1.170370564","rc":[{"atl":[[1.24,134.33]],"id":8509691}],"con":true,"img":false}]}
{"op":"mcm","clk":"1362433164","pt":1588450514318,"mc":[{"id":"1.170370564","rc":[{"atb":[[5.3,10.75]],"id":9630572}],"con":true,"img":false}]}
{"op":"mcm","clk":"1362433186","pt":1588450516304,"mc":[{"id":"1.170370564","rc":[{"trd":[[1.2,1173.15],[1.21,3220.54]],"ltp":1.2,"tv":4393.69,"id":8509691},{"atb":[[1.2,6.11],[1.21,0]],"id":8509691}],"con":true,"img":false}]}
{"op":"mcm","clk":"1362433237","pt":1588450521392,"mc":[{"id":"1.170370564","rc":[{"atl":[[1.21,6]],"id":8509691}],"con":true,"img":false}]}
{"op":"mcm","clk":"1362433282","pt":1588450525717,"mc":[{"id":"1.170370564","rc":[{"atb":[[5.5,13.29]],"id":9630572}],"con":true,"img":false}]}
{"op":"mcm","clk":"1362433291","pt":1588450526788,"mc":[{"id":"1.170370564","rc":[{"atb":[[1.2,49.91]],"id":8509691}],"con":true,"img":false}]}
{"op":"mcm","clk":"1362433314","pt":1588450529026,"mc":[{"id":"1.170370566","rc":[{"atl":[[10.5,10.93]],"id":8509691}],"con":true,"img":false}]}
{"op":"mcm","clk":"1362433327","pt":1588450530809,"mc":[{"id":"1.170370564","rc":[{"trd":[[5.3,59.11],[5.5,39.35],[5.7,22.76]],"ltp":5.3,"tv":121.22,"id":9630572},{"atb":[[5.5,0],[5.3,2.43]],"id":9630572},{"trd":[[1.21,3226.54]],"ltp":1.21,"tv":3226.54,"id":8509691},{"atl":[[1.21,0]],"id":8509691}],"con":true,"img":false}]}
{"op":"mcm","clk":"1362433333","pt":1588450531318,"mc":[{"id":"1.170370564","rc":[{"atb":[[1.12,0.6]],"id":8509691}],"con":true,"img":false}]}
{"op":"mcm","clk":"1362433343","pt":1588450533106,"mc":[{"id":"1.170370564","rc":[{"atb":[[1.02,0.21]],"id":8509691}],"con":true,"img":false}]}
{"op":"mcm","clk":"1362433361","pt":1588450535136,"mc":[{"id":"1.170370564","rc":[{"atb":[[1.01,477.21]],"id":8509691}],"con":true,"img":false}]}
{"op":"mcm","clk":"1362433374","pt":1588450536414,"mc":[{"id":"1.170370564","rc":[{"atb":[[1.21,7.74],[1.1,16.97]],"id":8509691}],"con":true,"img":false}]}
{"op":"mcm","clk":"1362433377","pt":1588450536821,"mc":[{"id":"1.170370564","rc":[{"atb":[[1.21,20.14]],"id":8509691}],"con":true,"img":false}]}
{"op":"mcm","clk":"1362433431","pt":1588450541620,"mc":[{"id":"1.170370566","rc":[{"atl":[[11,0]],"id":8509691}],"con":true,"img":false}]}
{"op":"mcm","clk":"1362433497","pt":1588450545930,"mc":[{"id":"1.170370564","rc":[{"atb":[[1.21,19.79]],"id":8509691}],"con":true,"img":false}]}
{"op":"mcm","clk":"1362433532","pt":1588450548018,"mc":[{"id":"1.170370564","rc":[{"atb":[[1.18,0]],"id":8509691}],"con":true,"img":false}]}
{"op":"mcm","clk":"1362433537","pt":1588450548220,"mc":[{"id":"1.170370564","rc":[{"atb":[[1.21,12.39]],"id":8509691}],"con":true,"img":false}]}
{"op":"mcm","clk":"1362433611","pt":1588450553562,"mc":[{"id":"1.170370564","rc":[{"trd":[[1.24,2888.37]],"ltp":1.24,"tv":2888.37,"id":8509691},{"atl":[[1.24,133.76]],"id":8509691}],"con":true,"img":false}]}
{"op":"mcm","clk":"1362433612","pt":1588450553766,"mc":[{"id":"1.170370564","rc":[{"trd":[[1.21,3251.34]],"ltp":1.21,"tv":3251.34,"id":8509691},{"atb":[[1.21,0]],"id":8509691},{"atl":[[1.21,50.1]],"id":8509691}],"con":true,"img":false}]}
{"op":"mcm","clk":"1362433642","pt":1588450556056,"mc":[{"id":"1.170370564","rc":[{"atl":[[1.24,177.56]],"id":8509691}],"con":true,"img":false}]}
{"op":"mcm","clk":"1362433645","pt":1588450556261,"mc":[{"id":"1.170370564","rc":[{"atb":[[1.1,116.97]],"id":8509691}],"con":true,"img":false}]}
{"op":"mcm","clk":"1362433657","pt":1588450556768,"mc":[{"id":"1.170370564","rc":[{"atl":[[1.25,12.26]],"id":8509691}],"con":true,"img":false}]}
{"op":"mcm","clk":"1362433670","pt":1588450557229,"mc":[{"id":"1.170370564","rc":[{"atb":[[1.01,474.55]],"id":8509691}],"con":true,"img":false}]}
{"op":"mcm","clk":"1362433715","pt":1588450559669,"mc":[{"id":"1.170370564","rc":[{"trd":[[1.24,2925.75],[1.21,3351.54]],"ltp":1.24,"tv":6277.29,"id":8509691},{"atl":[[1.21,0],[1.24,158.87]],"id":8509691}],"con":true,"img":false}]}
{"op":"mcm","clk":"1362433749","pt":1588450561146,"mc":[{"id":"1.170370564","rc":[{"trd":[[5.3,63.96]],"ltp":5.3,"tv":63.96,"id":9630572},{"atb":[[5.3,0]],"id":9630572},{"atl":[[5.3,6.43]],"id":9630572}],"con":true,"img":false}]}
{"op":"mcm","clk":"1362433770","pt":1588450562371,"mc":[{"id":"1.170370564","rc":[{"trd":[[1.24,2929.35]],"ltp":1.24,"tv":2929.35,"id":8509691},{"atl":[[1.24,157.07]],"id":8509691}],"con":true,"img":false}]}
{"op":"mcm","clk":"1362433800","pt":1588450564068,"mc":[{"id":"1.170370564","rc":[{"trd":[[1.24,2966.11]],"ltp":1.24,"tv":2966.11,"id":8509691},{"atl":[[1.24,138.69]],"id":8509691}],"con":true,"img":false}]}
{"op":"mcm","clk":"1362433826","pt":1588450565143,"mc":[{"id":"1.170370565","rc":[{"atb":[[1.5,0]],"id":11340560}],"con":true,"img":false}]}
{"op":"mcm","clk":"1362433846","pt":1588450566062,"mc":[{"id":"1.170370564","rc":[{"atl":[[5.7,0.1]],"id":9630572}],"con":true,"img":false}]}
{"op":"mcm","clk":"1362433850","pt":1588450566164,"mc":[{"id":"1.170370564","rc":[{"trd":[[5.3,64.47]],"ltp":5.3,"tv":64.47,"id":9630572},{"atl":[[5.3,5.93]],"id":9630572},{"trd":[[1.23,1257.43]],"ltp":1.23,"tv":1257.43,"id":8509691}],"con":true,"img":false}]}
{"op":"mcm","clk":"1362433862","pt":1588450566876,"mc":[{"id":"1.170370564","rc":[{"atb":[[1.2,93.7]],"id":8509691}],"con":true,"img":false}]}
{"op":"mcm","clk":"1362433878","pt":1588450567845,"mc":[{"id":"1.170370564","rc":[{"atb":[[1.21,18.39]],"id":8509691}],"con":true,"img":false}]}
{"op":"mcm","clk":"1362433886","pt":1588450568255,"mc":[{"id":"1.170370564","rc":[{"trd":[[5.3,70.4]],"ltp":5.3,"tv":70.4,"id":9630572},{"atl":[[5.3,0]],"id":9630572},{"trd":[[1.23,1282.99]],"ltp":1.23,"tv":1282.99,"id":8509691},{"atl":[[1.23,18.76]],"id":8509691}],"con":true,"img":false}]}
{"op":"mcm","clk":"1362433888","pt":1588450568357,"mc":[{"id":"1.170370564","rc":[{"atl":[[1.27,13.68]],"id":8509691}],"con":true,"img":false}]}
{"op":"mcm","clk":"1362433900","pt":1588450569071,"mc":[{"id":"1.170370564","rc":[{"atb":[[1.21,24.59]],"id":8509691}],"con":true,"img":false}]}
{"op":"mcm","clk":"1362433912","pt":1588450569680,"mc":[{"id":"1.170370564","rc":[{"atl":[[5.7,0]],"id":9630572}],"con":true,"img":false}]}
{"op":"mcm","clk":"1362433914","pt":1588450569781,"mc":[{"id":"1.170370564","rc":[{"atb":[[1.2,138.03]],"id":8509691}],"con":true,"img":false}]}
{"op":"mcm","clk":"1362433924","pt":1588450570239,"mc":[{"id":"1.170370565","rc":[{"atb":[[1.22,0]],"id":11269555}],"con":true,"img":false}]}
{"op":"mcm","clk":"1362433937","pt":1588450571165,"mc":[{"id":"1.170370564","rc":[{"trd":[[1.23,1286.49]],"ltp":1.23,"tv":1286.49,"id":8509691},{"atl":[[1.23,17.01]],"id":8509691}],"con":true,"img":false}]}
{"op":"mcm","clk":"1362433970","pt":1588450573557,"mc":[{"id":"1.170370564","rc":[{"atb":[[1.21,18.39]],"id":8509691}],"con":true,"img":false}]}
{"op":"mcm","clk":"1362433974","pt":1588450573963,"mc":[{"id":"1.170370564","rc":[{"trd":[[1.23,1303.99]],"ltp":1.23,"tv":1303.99,"id":8509691},{"atb":[[1.21,62.71]],"id":8509691},{"atl":[[1.23,8.26]],"id":8509691}],"con":true,"img":false}]}
{"op":"mcm","clk":"1362433991","pt":1588450575386,"mc":[{"id":"1.170370565","rc":[{"atb":[[1.15,11.99]],"id":11269555}],"con":true,"img":false}]}
{"op":"mcm","clk":"1362434003","pt":1588450576045,"mc":[{"id":"1.170370566","rc":[{"atl":[[10.5,0]],"id":8509691}],"con":true,"img":false}]}
{"op":"mcm","clk":"1362434043","pt":1588450579758,"mc":[{"id":"1.170370564","rc":[{"atl":[[1.23,52.05]],"id":8509691}],"con":true,"img":false}]}
{"op":"mcm","clk":"1362434049","pt":1588450580167,"mc":[{"id":"1.170370564","rc":[{"atl":[[1.22,2]],"id":8509691}],"con":true,"img":false}]}
{"op":"mcm","clk":"1362434059","pt":1588450581284,"mc":[{"id":"1.170370566","rc":[{"atl":[[50,2.62]],"id":8509691}],"con":true,"img":false}]}
{"op":"mcm","clk":"1362434073","pt":1588450582457,"mc":[{"id":"1.170370564","rc":[{"atl":[[1.23,68.05]],"id":8509691}],"con":true,"img":false}]}
{"op":"mcm","clk":"1362434097","pt":1588450584185,"mc":[{"id":"1.170370564","rc":[{"atl":[[1.32,3.99]],"id":8509691}],"con":true,"img":false}]}
{"op":"mcm","clk":"1362434100","pt":1588450584594,"mc":[{"id":"1.170370564","rc":[{"atl":[[1.22,5.99]],"id":8509691}],"con":true,"img":false}]}
{"op":"mcm","clk":"1362434105","pt":1588450584898,"mc":[{"id":"1.170370564","rc":[{"trd":[[1.21,3476.98]],"ltp":1.21,"tv":3476.98,"id":8509691},{"atb":[[1.21,0]],"id":8509691},{"atl":[[1.21,119.28]],"id":8509691}],"con":true,"img":false}]}
{"op":"mcm","clk":"1362434112","pt":1588450585356,"mc":[{"id":"1.170370564","rc":[{"trd":[[1.21,3477.04]],"ltp":1.21,"tv":3477.04,"id":8509691},{"atl":[[1.21,119.25]],"id":8509691}],"con":true,"img":false}]}
{"op":"mcm","clk":"1362434114","pt":1588450585562,"mc":[{"id":"1.170370564","rc":[{"atl":[[1.22,3.99]],"id":8509691}],"con":true,"img":false}]}
{"op":"mcm","clk":"1362434127","pt":1588450587191,"mc":[{"id":"1.170370564","rc":[{"atl":[[1.21,121.25]],"id":8509691}],"con":true,"img":false}]}
{"op":"mcm","clk":"1362434146","pt":1588450588667,"mc":[{"id":"1.170370564","rc":[{"atl":[[6,10.75]],"id":9630572}],"con":true,"img":false}]}
{"op":"mcm","clk":"1362434155","pt":1588450589176,"mc":[{"id":"1.170370564","rc":[{"trd":[[1.21,3477.3]],"ltp":1.21,"tv":3477.3,"id":8509691},{"atl":[[1.21,121.12]],"id":8509691}],"con":true,"img":false}]}
{"op":"mcm","clk":"1362434171","pt":1588450590398,"mc":[{"id":"1.170370564","rc":[{"trd":[[1.21,3652.48]],"ltp":1.21,"tv":3652.48,"id":8509691},{"atl":[[1.21,33.53]],"id":8509691}],"con":true,"img":false}]}
{"op":"mcm","clk":"1362434173","pt":1588450590500,"mc":[{"id":"1.170370564","rc":[{"atl":[[1.3,0.67]],"id":8509691}],"con":true,"img":false}]}
{"op":"mcm","clk":"1362434175","pt":1588450590704,"mc":[{"id":"1.170370564","rc":[{"atl":[[1.23,70.05]],"id":8509691}],"con":true,"img":false}]}
{"op":"mcm","clk":"1362434181","pt":1588450591163,"mc":[{"id":"1.170370564","rc":[{"atb":[[1.2,93.7]],"id":8509691}],"con":true,"img":false}]}
{"op":"mcm","clk":"1362434187","pt":1588450591470,"mc":[{"id":"1.170370564","rc":[{"atl":[[1.21,2]],"id":8509691}],"con":true,"img":false}]}
{"op":"mcm","clk":"1362434192","pt":1588450591976,"mc":[{"id":"1.170370564","rc":[{"trd":[[1.21,3656.48]],"ltp":1.21,"tv":3656.48,"id":8509691},{"atb":[[1.21,37.36]],"id":8509691},{"atl":[[1.21,0]],"id":8509691}],"con":true,"img":false}]}
{"op":"mcm","clk":"1362434200","pt":1588450592486,"mc":[{"id":"1.170370564","rc":[{"atl":[[1.23,54.05]],"id":8509691}],"con":true,"img":false}]}
{"op":"mcm","clk":"1362434205","pt":1588450592797,"mc":[{"id":"1.170370564","rc":[{"trd":[[1.21,3731.2]],"ltp":1.21,"tv":3731.2,"id":8509691},{"atb":[[1.21,0]],"id":8509691},{"atl":[[1.21,10.64]],"id":8509691}],"con":true,"img":false}]}
{"op":"mcm","clk":"1362434233","pt":1588450595391,"mc":[{"id":"1.170370564","rc":[{"trd":[[6,7.76]],"ltp":6.0,"tv":7.76,"id":9630572},{"atl":[[6,4.49]],"id":9630572},{"trd":[[1.2,1391.85]],"ltp":1.2,"tv":1391.85,"id":8509691},{"atb":[[1.2,0]],"id":8509691}],"con":true,"img":false}]}
{"op":"mcm","clk":"1362434255","pt":1588450596714,"mc":[{"id":"1.170370564","rc":[{"trd":[[1.21,3752.48]],"ltp":1.21,"tv":3752.48,"id":8509691},{"atb":[[1.21,33.68]],"id":8509691},{"atl":[[1.21,0]],"id":8509691}],"con":true,"img":false}]}
{"op":"mcm","clk":"1362434270","pt":1588450597582,"mc":[{"id":"1.170370564","rc":[{"atl":[[1.4,0]],"id":8509691}],"con":true,"img":false}]}
{"op":"mcm","clk":"1362434292","pt":1588450599975,"mc":[{"id":"1.170370564","rc":[{"atl":[[1.23,98.38]],"id":8509691}],"con":true,"img":false}]}
{"op":"mcm","clk":"1362434300","pt":1588450600584,"mc":[{"id":"1.170370567","rc":[{"atb":[[1.14,0]],"id":9630572},{"atb":[[1.01,0]],"id":8509691}],"con":true,"img":false}]}
{"op":"mcm","clk":"1362434317","pt":1588450601809,"mc":[{"id":"1.170370564","rc":[{"atb":[[1.21,41.43]],"id":8509691},{"atl":[[3,8.86]],"id":8509691}],"con":true,"img":false}]}
{"op":"mcm","clk":"1362434333","pt":1588450602677,"mc":[{"id":"1.170370564","rc":[{"trd":[[1.21,3820.13]],"ltp":1.21,"tv":3820.13,"id":8509691},{"atb":[[1.21,7.6]],"id":8509691}],"con":true,"img":false}]}
{"op":"mcm","clk":"1362434345","pt":1588450603899,"mc":[{"id":"1.170370564","rc":[{"atb":[[1.21,207.6]],"id":8509691}],"con":true,"img":false}]}
{"op":"mcm","clk":"1362434353","pt":1588450604611,"mc":[{"id":"1.170370564","rc":[{"trd":[[1.21,3852.13]],"ltp":1.21,"tv":3852.13,"id":8509691},{"atb":[[1.21,191.61]],"id":8509691}],"con":true,"img":false}]}
{"op":"mcm","clk":"1362434400","pt":1588450607922,"mc":[{"id":"1.170370565","rc":[{"atb":[[1.15,0]],"id":11269555}],"con":true,"img":false}]}
{"op":"mcm","clk":"1362434405","pt":1588450608382,"mc":[{"id":"1.170370564","rc":[{"atb":[[1.21,221.1]],"id":8509691}],"con":true,"img":false}]}
{"op":"mcm","clk":"1362434485","pt":1588450614490,"mc":[{"id":"1.170370566","rc":[{"atb":[[1.03,79.98]],"id":9630572}],"con":true,"img":false}]}
{"op":"mcm","clk":"1362434488","pt":1588450614592,"mc":[{"id":"1.170370564","rc":[{"trd":[[1.21,3858.53]],"ltp":1.21,"tv":3858.53,"id":8509691},{"atb":[[1.21,217.9]],"id":8509691}],"con":true,"img":false}]}
{"op":"mcm","clk":"1362434507","pt":1588450615713,"mc":[{"id":"1.170370564","rc":[{"trd":[[1.22,2157.59]],"ltp":1.22,"tv":2157.59,"id":8509691},{"atl":[[1.22,3.6]],"id":8509691}],"con":true,"img":false}]}
{"op":"mcm","clk":"1362434509","pt":1588450616121,"mc":[{"id":"1.170370564","rc":[{"trd":[[1.21,3862.53]],"ltp":1.21,"tv":3862.53,"id":8509691},{"atb":[[1.21,215.9]],"id":8509691}],"con":true,"img":false}]}
{"op":"mcm","clk":"1362434554","pt":1588450620195,"mc":[{"id":"1.170370564","rc":[{"atb":[[1.1,16.97]],"id":8509691}],"con":true,"img":false}]}
{"op":"mcm","clk":"1362434591","pt":1588450622336,"mc":[{"id":"1.170370566","rc":[{"atl":[[50,0]],"id":8509691}],"con":true,"img":false}]}
{"op":"mcm","clk":"1362434593","pt":1588450622388,"mc":[{"id":"1.170370564","rc":[{"atb":[[5.3,6.26]],"id":9630572}],"con":true,"img":false}]}
{"op":"mcm","clk":"1362434602","pt":1588450623108,"mc":[{"id":"1.170370564","rc":[{"trd":[[1.21,3946.95]],"ltp":1.21,"tv":3946.95,"id":8509691},{"atb":[[1.21,173.69]],"id":8509691}],"con":true,"img":false}]}
{"op":"mcm","clk":"1362434611","pt":1588450623721,"mc":[{"id":"1.170370564","rc":[{"atb":[[1.21,144.2]],"id":8509691}],"con":true,"img":false}]}
{"op":"mcm","clk":"1362434616","pt":1588450624027,"mc":[{"id":"1.170370564","rc":[{"atl":[[5.7,4.43]],"id":9630572}],"con":true,"img":false}]}
{"op":"mcm","clk":"1362434635","pt":1588450625716,"mc":[{"id":"1.170370567","rc":[{"atb":[[1.14,79.98]],"id":9630572}],"con":true,"img":false}]}
{"op":"mcm","clk":"1362434649","pt":1588450626737,"mc":[{"id":"1.170370564","rc":[{"atl":[[1.26,0]],"id":8509691}],"con":true,"img":false}]}
{"op":"mcm","clk":"1362434651","pt":1588450626840,"mc":[{"id":"1.170370564","rc":[{"atl":[[1.24,94.89]],"id":8509691}],"con":true,"img":false}]}
{"op":"mcm","clk":"1362434653","pt":1588450626940,"mc":[{"id":"1.170370564","rc":[{"trd":[[1.22,2161.59]],"ltp":1.22,"tv":2161.59,"id":8509691},{"atl":[[1.22,1.6]],"id":8509691}],"con":true,"img":false}]}
{"op":"mcm","clk":"1362434656","pt":1588450627042,"mc":[{"id":"1.170370564","rc":[{"atl":[[1.25,0]],"id":8509691}],"con":true,"img":false}]}
{"op":"mcm","clk":"1362434661","pt":1588450627399,"mc":[{"id":"1.170370566","rc":[{"atl":[[34,2.62]],"id":8509691}],"con":true,"img":false}]}
{"op":"mcm","clk":"1362434669","pt":1588450628012,"mc":[{"id":"1.170370564","rc":[{"atl":[[1.23,54.58]],"id":8509691}],"con":true,"img":false}]}
{"op":"mcm","clk":"1362434674","pt":1588450628420,"mc":[{"id":"1.170370564","rc":[{"trd":[[1.22,2164.8]],"ltp":1.22,"tv":2164.8,"id":8509691},{"atb":[[1.22,9.15]],"id":8509691},{"atl":[[1.22,0]],"id":8509691}],"con":true,"img":false}]}
{"op":"mcm","clk":"1362434683","pt":1588450628928,"mc":[{"id":"1.170370564","rc":[{"atb":[[1.22,38.4]],"id":8509691}],"con":true,"img":false}]}
{"op":"mcm","clk":"1362434687","pt":1588450629234,"mc":[{"id":"1.170370564","rc":[{"atl":[[1.23,2]],"id":8509691}],"con":true,"img":false}]}
{"op":"mcm","clk":"1362434699","pt":1588450630101,"mc":[{"id":"1.170370567","rc":[{"atl":[[8.6,0]],"id":8509691}],"con":true,"img":false}]}
{"op":"mcm","clk":"1362434753","pt":1588450635344,"mc":[{"id":"1.170370567","rc":[{"atl":[[8,15.74]],"id":8509691}],"con":true,"img":false}]}
{"op":"mcm","clk":"1362434781","pt":1588450637634,"mc":[{"id":"1.170370566","rc":[{"atb":[[1.03,0]],"id":9630572}],"con":true,"img":false}]}
{"op":"mcm","clk":"1362434811","pt":1588450640534,"mc":[{"id":"1.170370564","rc":[{"trd":[[1.23,1305.31]],"ltp":1.23,"tv":1305.31,"id":8509691},{"atl":[[1.23,1.34]],"id":8509691}],"con":true,"img":false}]}
{"op":"mcm","clk":"1362434815","pt":1588450640737,"mc":[{"id":"1.170370567","rc":[{"atb":[[1.14,0]],"id":9630572}],"con":true,"img":false}]}
{"op":"mcm","clk":"1362434840","pt":1588450642725,"mc":[{"id":"1.170370566","rc":[{"atb":[[1.05,79.98]],"id":9630572}],"con":true,"img":false}]}
{"op":"mcm","clk":"1362434845","pt":1588450643029,"mc":[{"id":"1.170370564","rc":[{"atb":[[1.22,9.15]],"id":8509691}],"con":true,"img":false}]}
{"op":"mcm","clk":"1362434863","pt":1588450644556,"mc":[{"id":"1.170370564","rc":[{"atl":[[1.88,10.51]],"id":8509691}],"con":true,"img":false}]}
{"op":"mcm","clk":"1362434882","pt":1588450645829,"mc":[{"id":"1.170370567","rc":[{"atb":[[1.15,79.98]],"id":9630572}],"con":true,"img":false}]}
{"op":"mcm","clk":"1362434886","pt":1588450646032,"mc":[{"id":"1.170370564","rc":[{"atl":[[1.6,11.75]],"id":8509691}],"con":true,"img":false}]}
{"op":"mcm","clk":"1362434940","pt":1588450649241,"mc":[{"id":"1.170370564","rc":[{"trd":[[1.23,1307.99]],"ltp":1.23,"tv":1307.99,"id":8509691},{"atb":[[1.23,27.67]],"id":8509691},{"atl":[[1.23,0]],"id":8509691}],"con":true,"img":false}]}
{"op":"mcm","clk":"1362434951","pt":1588450650156,"mc":[{"id":"1.170370567","rc":[{"atl":[[8,0]],"id":8509691}],"con":true,"img":false}]}
{"op":"mcm","clk":"1362434972","pt":1588450651533,"mc":[{"id":"1.170370564","rc":[{"trd":[[1.24,2966.14]],"ltp":1.24,"tv":2966.14,"id":8509691},{"atl":[[1.24,94.87]],"id":8509691}],"con":true,"img":false}]}
{"op":"mcm","clk":"1362434980","pt":1588450652143,"mc":[{"id":"1.170370566","rc":[{"atb":[[1.07,79.98]],"id":9630572}],"con":true,"img":false}]}
{"op":"mcm","clk":"1362435023","pt":1588450655348,"mc":[{"id":"1.170370567","rc":[{"atl":[[7.6,15.74]],"id":8509691}],"con":true,"img":false}]}
{"op":"mcm","clk":"1362435030","pt":1588450656061,"mc":[{"id":"1.170370566","rc":[{"atl":[[34,0]],"id":8509691}],"con":true,"img":false}]}
{"op":"mcm","clk":"1362435035","pt":1588450656369,"mc":[{"id":"1.170370564","rc":[{"trd":[[5.3,70.5]],"ltp":5.3,"tv":70.5,"id":9630572},{"atb":[[5.3,6.21]],"id":9630572}],"con":true,"img":false}]}
{"op":"mcm","clk":"1362435041","pt":1588450656776,"mc":[{"id":"1.170370567","rc":[{"atb":[[1.2,79.98]],"id":9630572}],"con":true,"img":false}]}
{"op":"mcm","clk":"1362435083","pt":1588450659947,"mc":[{"id":"1.170370566","rc":[{"atb":[[1.05,0]],"id":9630572}],"con":true,"img":false}]}
{"op":"mcm","clk":"1362435100","pt":1588450660754,"mc":[{"id":"1.170370564","rc":[{"trd":[[1.24,2966.26]],"ltp":1.24,"tv":2966.26,"id":8509691},{"atl":[[1.24,94.81]],"id":8509691}],"con":true,"img":false}]}
{"op":"mcm","clk":"1362435107","pt":1588450661163,"mc":[{"id":"1.170370566","rc":[{"atl":[[20,2.62]],"id":8509691}],"con":true,"img":false}]}
{"op":"mcm","clk":"1362435111","pt":1588450661570,"mc":[{"id":"1.170370566","rc":[{"atb":[[1.07,0]],"id":9630572}],"con":true,"img":false}]}
{"op":"mcm","clk":"1362435114","pt":1588450661773,"mc":[{"id":"1.170370566","rc":[{"atb":[[1.1,79.98]],"id":9630572}],"con":true,"img":false}]}
{"op":"mcm","clk":"1362435127","pt":1588450662640,"mc":[{"id":"1.170370564","rc":[{"atb":[[1.23,0]],"id":8509691}],"con":true,"img":false}]}
{"op":"mcm","clk":"1362435153","pt":1588450664066,"mc":[{"id":"1.170370564","rc":[{"atl":[[1.23,2.39]],"id":8509691}],"con":true,"img":false}]}
{"op":"mcm","clk":"1362435183","pt":1588450666870,"mc":[{"id":"1.170370564","rc":[{"atb":[[5.3,0]],"id":9630572}],"con":true,"img":false}]}
{"op":"mcm","clk":"1362435197","pt":1588450667890,"mc":[{"id":"1.170370564","rc":[{"trd":[[1.24,3016.37],[1.23,1312.79]],"ltp":1.24,"tv":4329.16,"id":8509691},{"atl":[[1.24,69.76],[1.23,0]],"id":8509691}],"con":true,"img":false}]}
{"op":"mcm","clk":"1362435243","pt":1588450671970,"mc":[{"id":"1.170370564","rc":[{"atb":[[5.4,6.21]],"id":9630572}],"con":true,"img":false}]}
{"op":"mcm","clk":"1362435251","pt":1588450672994,"mc":[{"id":"1.170370566","rc":[{"atl":[[20,0]],"id":8509691}],"con":true,"img":false}]}
{"op":"mcm","clk":"1362435291","pt":1588450676199,"mc":[{"id":"1.170370566","rc":[{"trd":[[1.08,5.24]],"ltp":1.08,"tv":5.24,"id":8509691},{"atb":[[1.08,0]],"id":8509691},{"atl":[[1.08,25.64]],"id":8509691}],"con":true,"img":false}]}
{"op":"mcm","clk":"1362435309","pt":1588450678186,"mc":[{"id":"1.170370566","rc":[{"atl":[[10.5,3.93]],"id":8509691}],"con":true,"img":false}]}
{"op":"mcm","clk":"1362435315","pt":1588450678797,"mc":[{"id":"1.170370564","rc":[{"atl":[[1.23,5]],"id":8509691}],"con":true,"img":false}]}
{"op":"mcm","clk":"1362435317","pt":1588450679101,"mc":[{"id":"1.170370567","rc":[{"atl":[[7.6,0]],"id":8509691}],"con":true,"img":false}]}
{"op":"mcm","clk":"1362435369","pt":1588450684203,"mc":[{"id":"1.170370567","rc":[{"atl":[[5.9,15.74]],"id":8509691}],"con":true,"img":false}]}
{"op":"mcm","clk":"1362435379","pt":1588450685177,"mc":[{"id":"1.170370564","rc":[{"atb":[[1.2,2.39]],"id":8509691}],"con":true,"img":false}]}
{"op":"mcm","clk":"1362435397","pt":1588450686100,"mc":[{"id":"1.170370564","rc":[{"trd":[[1.22,2183.11]],"ltp":1.22,"tv":2183.11,"id":8509691},{"atb":[[1.22,0]],"id":8509691},{"atl":[[1.22,286.96]],"id":8509691}],"con":true,"img":false}]}
{"op":"mcm","clk":"1362435413","pt":1588450687174,"mc":[{"id":"1.170370564","rc":[{"trd":[[1.22,2189.55]],"ltp":1.22,"tv":2189.55,"id":8509691},{"atl":[[1.22,283.74]],"id":8509691}],"con":true,"img":false}]}
{"op":"mcm","clk":"1362435422","pt":1588450687686,"mc":[{"id":"1.170370566","rc":[{"atl":[[1.08,0]],"id":8509691}],"con":true,"img":false}]}
{"op":"mcm","clk":"1362435557","pt":1588450696705,"mc":[{"id":"1.170370566","rc":[{"atb":[[1.1,0]],"id":9630572}],"con":true,"img":false}]}
{"op":"mcm","clk":"1362435669","pt":1588450701799,"mc":[{"id":"1.170370566","rc":[{"atb":[[1.12,79.98]],"id":9630572}],"con":true,"img":false}]}
{"op":"mcm","clk":"1362435677","pt":1588450702206,"mc":[{"id":"1.170370564","rc":[{"trd":[[1.21,4018.95]],"ltp":1.21,"tv":4018.95,"id":8509691},{"atb":[[1.21,108.2]],"id":8509691}],"con":true,"img":false}]}
{"op":"mcm","clk":"1362435705","pt":1588450705003,"mc":[{"id":"1.170370564","rc":[{"atl":[[1.22,285.51]],"id":8509691}],"con":true,"img":false}]}
{"op":"mcm","clk":"1362435725","pt":1588450707190,"mc":[{"id":"1.170370566","rc":[{"atb":[[1.02,0.21]],"id":9630572}],"con":true,"img":false}]}
{"op":"mcm","clk":"1362435730","pt":1588450707902,"mc":[{"id":"1.170370566","rc":[{"atb":[[1.01,0]],"id":9630572}],"con":true,"img":false}]}
{"op":"mcm","clk":"1362435745","pt":1588450709228,"mc":[{"id":"1.170370564","rc":[{"atl":[[1.22,283.74]],"id":8509691}],"con":true,"img":false}]}
{"op":"mcm","clk":"1362435772","pt":1588450711211,"mc":[{"id":"1.170370566","rc":[{"atb":[[1.12,0]],"id":9630572}],"con":true,"img":false}]}
{"op":"mcm","clk":"1362435779","pt":1588450711719,"mc":[{"id":"1.170370565","rc":[{"atb":[[32,2.3]],"id":11269555}],"con":true,"img":false}]}
{"op":"mcm","clk":"1362435781","pt":1588450711924,"mc":[{"id":"1.170370564","rc":[{"trd":[[1.22,2196.13]],"ltp":1.22,"tv":2196.13,"id":8509691},{"atl":[[1.22,280.45]],"id":8509691}],"con":true,"img":false}]}
{"op":"mcm","clk":"1362435786","pt":1588450712432,"mc":[{"id":"1.170370564","rc":[{"trd":[[1.22,2201.28]],"ltp":1.22,"tv":2201.28,"id":8509691},{"atl":[[1.22,277.88]],"id":8509691}],"con":true,"img":false}]}
{"op":"mcm","clk":"1362435810","pt":1588450714315,"mc":[{"id":"1.170370564","rc":[{"trd":[[1.21,4022.49]],"ltp":1.21,"tv":4022.49,"id":8509691},{"atb":[[1.21,106.43]],"id":8509691}],"con":true,"img":false},{"id":"1.170370565","rc":[{"atb":[[32,0]],"id":11269555}],"con":true,"img":false}]}
{"op":"mcm","clk":"1362435830","pt":1588450716299,"mc":[{"id":"1.170370564","rc":[{"atb":[[1.2,0],[1.1,8.97],[1.15,10]],"id":8509691}],"con":true,"img":false}]}
{"op":"mcm","clk":"1362435834","pt":1588450716402,"mc":[{"id":"1.170370567","rc":[{"atb":[[1.2,0]],"id":9630572}],"con":true,"img":false}]}
{"op":"mcm","clk":"1362435841","pt":1588450716918,"mc":[{"id":"1.170370564","rc":[{"trd":[[1.22,2757.04]],"ltp":1.22,"tv":2757.04,"id":8509691},{"atb":[[1.22,51.12]],"id":8509691},{"atl":[[1.22,0]],"id":8509691}],"con":true,"img":false}]}
{"op":"mcm","clk":"1362435846","pt":1588450717724,"mc":[{"id":"1.170370567","rc":[{"atb":[[1.15,0]],"id":9630572}],"con":true,"img":false}]}
{"op":"mcm","clk":"1362435885","pt":1588450720930,"mc":[{"id":"1.170370564","rc":[{"atb":[[1.22,54.55]],"id":8509691}],"con":true,"img":false}]}
{"op":"mcm","clk":"1362435892","pt":1588450721540,"mc":[{"id":"1.170370567","rc":[{"atb":[[1.21,79.98]],"id":9630572}],"con":true,"img":false}]}
{"op":"mcm","clk":"1362435925","pt":1588450724645,"mc":[{"id":"1.170370564","rc":[{"atb":[[3.5,0]],"id":9630572}],"con":true,"img":false}]}
{"op":"mcm","clk":"1362435941","pt":1588450726123,"mc":[{"id":"1.170370567","rc":[{"atl":[[5.9,0]],"id":8509691}],"con":true,"img":false}]}
{"op":"mcm","clk":"1362435954","pt":1588450727141,"mc":[{"id":"1.170370564","rc":[{"atb":[[1.22,51.12]],"id":8509691}],"con":true,"img":false}]}
{"op":"mcm","clk":"1362435993","pt":1588450731313,"mc":[{"id":"1.170370567","rc":[{"atl":[[5.7,15.74]],"id":8509691}],"con":true,"img":false}]}
{"op":"mcm","clk":"1362436001","pt":1588450732227,"mc":[{"id":"1.170370564","rc":[{"trd":[[1.23,1319.67]],"ltp":1.23,"tv":1319.67,"id":8509691},{"atl":[[1.23,1.56]],"id":8509691}],"con":true,"img":false}]}
{"op":"mcm","clk":"1362436010","pt":1588450732939,"mc":[{"id":"1.170370564","rc":[{"trd":[[5.4,10]],"ltp":5.4,"tv":10.0,"id":9630572},{"atb":[[5.4,1.21]],"id":9630572}],"con":true,"img":false}]}
{"op":"mcm","clk":"1362436015","pt":1588450733143,"mc":[{"id":"1.170370567","rc":[{"atb":[[1.21,0]],"id":9630572}],"con":true,"img":false}]}
{"op":"mcm","clk":"1362436089","pt":1588450738233,"mc":[{"id":"1.170370567","rc":[{"atb":[[1.22,79.98]],"id":9630572}],"con":true,"img":false}]}
{"op":"mcm","clk":"1362436134","pt":1588450742257,"mc":[{"id":"1.170370567","rc":[{"atl":[[5.7,0]],"id":8509691}],"con":true,"img":false}]}
{"op":"mcm","clk":"1362436198","pt":1588450747371,"mc":[{"id":"1.170370567","rc":[{"atl":[[5.5,15.74]],"id":8509691}],"con":true,"img":false}]}
{"op":"mcm","clk":"1362436220","pt":1588450749768,"mc":[{"id":"1.170370567","rc":[{"atb":[[1.22,0]],"id":9630572}],"con":true,"img":false}]}
{"op":"mcm","clk":"1362436225","pt":1588450750176,"mc":[{"id":"1.170370564","rc":[{"trd":[[5.4,11.21]],"ltp":5.4,"tv":11.21,"id":9630572},{"atb":[[5.4,0]],"id":9630572},{"trd":[[1.23,1328.1]],"ltp":1.23,"tv":1328.1,"id":8509691},{"atb":[[1.23,45.13]],"id":8509691},{"atl":[[1.23,0]],"id":8509691}],"con":true,"img":false}]}
{"op":"mcm","clk":"1362436231","pt":1588450750635,"mc":[{"id":"1.170370564","rc":[{"trd":[[1.23,1344.96]],"ltp":1.23,"tv":1344.96,"id":8509691},{"atb":[[1.23,36.7]],"id":8509691}],"con":true,"img":false}]}
{"op":"mcm","clk":"1362436261","pt":1588450752569,"mc":[{"id":"1.170370564","rc":[{"trd":[[1.23,1418.36]],"ltp":1.23,"tv":1418.36,"id":8509691},{"atb":[[1.23,0]],"id":8509691},{"atl":[[1.23,1715.08]],"id":8509691}],"con":true,"img":false}]}
{"op":"mcm","clk":"1362436264","pt":1588450752774,"mc":[{"id":"1.170370564","rc":[{"atb":[[1.2,16.07]],"id":8509691}],"con":true,"img":false}]}
{"op":"mcm","clk":"1362436268","pt":1588450753078,"mc":[{"id":"1.170370564","rc":[{"atb":[[5.2,4.43]],"id":9630572}],"con":true,"img":false}]}
{"op":"mcm","clk":"1362436283","pt":1588450753945,"mc":[{"id":"1.170370564","rc":[{"atl":[[1.23,1718.51]],"id":8509691}],"con":true,"img":false}]}
{"op":"mcm","clk":"1362436348","pt":1588450759744,"mc":[{"id":"1.170370564","rc":[{"atl":[[1.23,1722.25]],"id":8509691}],"con":true,"img":false}]}
{"op":"mcm","clk":"1362436356","pt":1588450760049,"mc":[{"id":"1.170370564","rc":[{"trd":[[1.22,2859.28]],"ltp":1.22,"tv":2859.28,"id":8509691},{"atb":[[1.22,0]],"id":8509691},{"atl":[[1.22,37.53]],"id":8509691}],"con":true,"img":false}]}
{"op":"mcm","clk":"1362436375","pt":1588450760965,"mc":[{"id":"1.170370564","rc":[{"atb":[[1.2,0]],"id":8509691}],"con":true,"img":false}]}
{"op":"mcm","clk":"1362436397","pt":1588450762491,"mc":[{"id":"1.170370564","rc":[{"atl":[[1.24,0.04]],"id":8509691}],"con":true,"img":false}]}
{"op":"mcm","clk":"1362436403","pt":1588450762952,"mc":[{"id":"1.170370564","rc":[{"trd":[[5.5,40.93]],"ltp":5.5,"tv":40.93,"id":9630572},{"trd":[[1.22,2866.38]],"ltp":1.22,"tv":2866.38,"id":8509691},{"atl":[[1.22,30.43]],"id":8509691}],"con":true,"img":false}]}
{"op":"mcm","clk":"1362436445","pt":1588450766865,"mc":[{"id":"1.170370564","rc":[{"trd":[[1.22,2867.75]],"ltp":1.22,"tv":2867.75,"id":8509691},{"atl":[[1.22,29.75]],"id":8509691}],"con":true,"img":false}]}
{"op":"mcm","clk":"1362436465","pt":1588450768291,"mc":[{"id":"1.170370564","rc":[{"trd":[[1.21,4165.39]],"ltp":1.21,"tv":4165.39,"id":8509691},{"atb":[[1.21,34.98]],"id":8509691}],"con":true,"img":false}]}
{"op":"mcm","clk":"1362436509","pt":1588450771193,"mc":[{"id":"1.170370564","rc":[{"atl":[[1.22,32.95]],"id":8509691}],"con":true,"img":false}]}
{"op":"mcm","clk":"1362436513","pt":1588450771295,"mc":[{"id":"1.170370564","rc":[{"trd":[[1.22,2898.3]],"ltp":1.22,"tv":2898.3,"id":8509691},{"atl":[[1.22,17.67]],"id":8509691}],"con":true,"img":false}]}
{"op":"mcm","clk":"1362436524","pt":1588450772060,"mc":[{"id":"1.170370564","rc":[{"trd":[[1.22,2906.3]],"ltp":1.22,"tv":2906.3,"id":8509691},{"atl":[[1.22,13.67]],"id":8509691}],"con":true,"img":false}]}
{"op":"mcm","clk":"1362436551","pt":1588450774804,"mc":[{"id":"1.170370564","rc":[{"trd":[[1.22,2933.65]],"ltp":1.22,"tv":2933.65,"id":8509691},{"atb":[[1.22,30.11]],"id":8509691},{"atl":[[1.22,0]],"id":8509691}],"con":true,"img":false}]}
{"op":"mcm","clk":"1362436555","pt":1588450775110,"mc":[{"id":"1.170370564","rc":[{"atl":[[5.5,100]],"id":9630572}],"con":true,"img":false}]}
{"op":"mcm","clk":"1362436569","pt":1588450776483,"mc":[{"id":"1.170370564","rc":[{"atb":[[1.22,35.49]],"id":8509691}],"con":true,"img":false}]}
{"op":"mcm","clk":"1362436584","pt":1588450777805,"mc":[{"id":"1.170370564","rc":[{"atb":[[1.22,37.49]],"id":8509691}],"con":true,"img":false}]}
{"op":"mcm","clk":"1362436617","pt":1588450781008,"mc":[{"id":"1.170370564","rc":[{"atb":[[1.21,123.63]],"id":8509691}],"con":true,"img":false}]}
{"op":"mcm","clk":"1362436618","pt":1588450781110,"mc":[{"id":"1.170370566","rc":[{"atl":[[10.5,0]],"id":8509691}],"con":true,"img":false}]}
{"op":"mcm","clk":"1362436636","pt":1588450782382,"mc":[{"id":"1.170370564","rc":[{"atb":[[1.22,35.49]],"id":8509691}],"con":true,"img":false}]}
{"op":"mcm","clk":"1362436665","pt":1588450784009,"mc":[{"id":"1.170370564","rc":[{"atb":[[1.21,126.85]],"id":8509691}],"con":true,"img":false}]}
{"op":"mcm","clk":"1362436683","pt":1588450785585,"mc":[{"id":"1.170370564","rc":[{"atb":[[1.22,43.49]],"id":8509691}],"con":true,"img":false}]}
{"op":"mcm","clk":"1362436696","pt":1588450786603,"mc":[{"id":"1.170370564","rc":[{"trd":[[5.5,53.46]],"ltp":5.5,"tv":53.46,"id":9630572},{"atl":[[5.5,87.47]],"id":9630572},{"trd":[[1.22,3077.15]],"ltp":1.22,"tv":3077.15,"id":8509691},{"atb":[[1.22,0]],"id":8509691}],"con":true,"img":false}]}
{"op":"mcm","clk":"1362436708","pt":1588450787519,"mc":[{"id":"1.170370564","rc":[{"trd":[[1.23,1422.36]],"ltp":1.23,"tv":1422.36,"id":8509691},{"atl":[[1.23,1720.25]],"id":8509691}],"con":true,"img":false}]}
{"op":"mcm","clk":"1362436729","pt":1588450789404,"mc":[{"id":"1.170370564","rc":[{"atl":[[1.23,494]],"id":8509691}],"con":true,"img":false}]}
{"op":"mcm","clk":"1362436912","pt":1588450805331,"mc":[{"id":"1.170370564","rc":[{"trd":[[5.5,53.79]],"ltp":5.5,"tv":53.79,"id":9630572},{"atl":[[5.5,87.3]],"id":9630572}],"con":true,"img":false}]}
{"op":"mcm","clk":"1362436953","pt":1588450807831,"mc":[{"id":"1.170370564","rc":[{"atb":[[4.8,100]],"id":9630572}],"con":true,"img":false}]}
{"op":"mcm","clk":"1362437062","pt":1588450815923,"mc":[{"id":"1.170370566","rc":[{"atb":[[1.03,104.71]],"id":9630572}],"con":true,"img":false}]}
{"op":"mcm","clk":"1362437090","pt":1588450817857,"mc":[{"id":"1.170370564","rc":[{"atl":[[5.8,6.26]],"id":9630572}],"con":true,"img":false}]}
{"op":"mcm","clk":"1362437196","pt":1588450825951,"mc":[{"id":"1.170370564","rc":[{"atb":[[1.22,1926.95]],"id":8509691}],"con":true,"img":false}]}
{"op":"mcm","clk":"1362437201","pt":1588450826155,"mc":[{"id":"1.170370564","rc":[{"trd":[[5.3,92.37]],"ltp":5.3,"tv":92.37,"id":9630572},{"trd":[[1.23,1516.59]],"ltp":1.23,"tv":1516.59,"id":8509691},{"atl":[[1.23,399.76]],"id":8509691}],"con":true,"img":false}]}
{"op":"mcm","clk":"1362437240","pt":1588450829054,"mc":[{"id":"1.170370567","rc":[{"atl":[[5.5,0]],"id":8509691}],"con":true,"img":false}]}
{"op":"mcm","clk":"1362437288","pt":1588450833782,"mc":[{"id":"1.170370564","rc":[{"trd":[[5.5,57.67]],"ltp":5.5,"tv":57.67,"id":9630572},{"atl":[[5.5,85.36]],"id":9630572}],"con":true,"img":false}]}
{"op":"mcm","clk":"1362437303","pt":1588450835159,"mc":[{"id":"1.170370564","rc":[{"trd":[[5.5,79.49]],"ltp":5.5,"tv":79.49,"id":9630572},{"atl":[[5.5,74.45]],"id":9630572}],"con":true,"img":false}]}
{"op":"mcm","clk":"1362437355","pt":1588450838868,"mc":[{"id":"1.170370564","rc":[{"atb":[[1.22,700.71]],"id":8509691}],"con":true,"img":false}]}
{"op":"mcm","clk":"1362437377","pt":1588450840089,"mc":[{"id":"1.170370566","rc":[{"atb":[[1.03,0]],"id":9630572}],"con":true,"img":false}]}
{"op":"mcm","clk":"1362437437","pt":1588450845175,"mc":[{"id":"1.170370564","rc":[{"trd":[[5.5,79.57]],"ltp":5.5,"tv":79.57,"id":9630572},{"atl":[[5.5,74.41]],"id":9630572}],"con":true,"img":false}]}
{"op":"mcm","clk":"1362437456","pt":1588450846294,"mc":[{"id":"1.170370564","rc":[{"atl":[[1.3,0]],"id":8509691}],"con":true,"img":false}]}
{"op":"mcm","clk":"1362437461","pt":1588450846396,"mc":[{"id":"1.170370564","rc":[{"atb":[[1.21,123.63]],"id":8509691}],"con":true,"img":false}]}
{"op":"mcm","clk":"1362437515","pt":1588450849962,"mc":[{"id":"1.170370564","rc":[{"atl":[[8.8,0]],"id":9630572}],"con":true,"img":false}]}
{"op":"mcm","clk":"1362437555","pt":1588450855097,"mc":[{"id":"1.170370564","rc":[{"trd":[[5.3,113.12]],"ltp":5.3,"tv":113.12,"id":9630572},{"trd":[[1.23,1606]],"ltp":1.23,"tv":1606.0,"id":8509691},{"atl":[[1.23,310.35]],"id":8509691}],"con":true,"img":false}]}
{"op":"mcm","clk":"1362437568","pt":1588450856673,"mc":[{"id":"1.170370564","rc":[{"trd":[[1.23,1609.94]],"ltp":1.23,"tv":1609.94,"id":8509691},{"atl":[[1.23,308.39]],"id":8509691}],"con":true,"img":false}]}
{"op":"mcm","clk":"1362437591","pt":1588450859265,"mc":[{"id":"1.170370564","rc":[{"atl":[[1.23,1534.63]],"id":8509691}],"con":true,"img":false}]}
{"op":"mcm","clk":"1362437597","pt":1588450860180,"mc":[{"id":"1.170370564","rc":[{"atl":[[1.29,8.86]],"id":8509691}],"con":true,"img":false}]}
{"op":"mcm","clk":"1362437627","pt":1588450863082,"mc":[{"id":"1.170370564","rc":[{"trd":[[1.23,1612.29]],"ltp":1.23,"tv":1612.29,"id":8509691},{"atl":[[1.23,1533.46]],"id":8509691}],"con":true,"img":false}]}
{"op":"mcm","clk":"1362437647","pt":1588450865484,"mc":[{"id":"1.170370564","rc":[{"atl":[[1.29,0]],"id":8509691}],"con":true,"img":false}]}
{"op":"mcm","clk":"1362437650","pt":1588450865889,"mc":[{"id":"1.170370564","rc":[{"trd":[[1.23,1729.32]],"ltp":1.23,"tv":1729.32,"id":8509691},{"atl":[[1.23,1474.94]],"id":8509691}],"con":true,"img":false}]}
{"op":"mcm","clk":"1362437762","pt":1588450876825,"mc":[{"id":"1.170370564","rc":[{"atb":[[1.22,0]],"id":8509691}],"con":true,"img":false}]}
{"op":"mcm","clk":"1362437763","pt":1588450876927,"mc":[{"id":"1.170370564","rc":[{"atl":[[1.23,1233.41]],"id":8509691}],"con":true,"img":false}]}
{"op":"mcm","clk":"1362437791","pt":1588450879216,"mc":[{"id":"1.170370564","rc":[{"trd":[[5.5,83.27]],"ltp":5.5,"tv":83.27,"id":9630572},{"atl":[[5.5,72.56]],"id":9630572}],"con":true,"img":false}]}
{"op":"mcm","clk":"1362437853","pt":1588450884296,"mc":[{"id":"1.170370564","rc":[{"trd":[[5.3,128.35]],"ltp":5.3,"tv":128.35,"id":9630572},{"trd":[[1.23,1794.94]],"ltp":1.23,"tv":1794.94,"id":8509691},{"atl":[[1.23,1167.79]],"id":8509691}],"con":true,"img":false}]}
{"op":"mcm","clk":"1362437935","pt":1588450891827,"mc":[{"id":"1.170370564","rc":[{"trd":[[5.5,85.93]],"ltp":5.5,"tv":85.93,"id":9630572},{"atl":[[5.5,71.23]],"id":9630572}],"con":true,"img":false}]}
{"op":"mcm","clk":"1362437992","pt":1588450896705,"mc":[{"id":"1.170370564","rc":[{"trd":[[5.5,114.99]],"ltp":5.5,"tv":114.99,"id":9630572},{"atl":[[5.5,42.17]],"id":9630572},{"trd":[[1.22,3208.15]],"ltp":1.22,"tv":3208.15,"id":8509691}],"con":true,"img":false}]}
{"op":"mcm","clk":"1362438071","pt":1588450902550,"mc":[{"id":"1.170370564","rc":[{"atl":[[5.8,0],[6,0]],"id":9630572}],"con":true,"img":false}]}
{"op":"mcm","clk":"1362438089","pt":1588450904636,"mc":[{"id":"1.170370564","rc":[{"atb":[[1.21,34.98]],"id":8509691}],"con":true,"img":false}]}
{"op":"mcm","clk":"1362438099","pt":1588450905752,"mc":[{"id":"1.170370564","rc":[{"trd":[[5.3,178.35]],"ltp":5.3,"tv":178.35,"id":9630572},{"trd":[[1.23,2010.39]],"ltp":1.23,"tv":2010.39,"id":8509691},{"atl":[[1.23,952.34]],"id":8509691}],"con":true,"img":false}]}
{"op":"mcm","clk":"1362438261","pt":1588450917860,"mc":[{"id":"1.170370564","rc":[{"trd":[[5.3,179.41]],"ltp":5.3,"tv":179.41,"id":9630572},{"trd":[[1.23,2014.96]],"ltp":1.23,"tv":2014.96,"id":8509691},{"atl":[[1.23,947.77]],"id":8509691}],"con":true,"img":false}]}
{"op":"mcm","clk":"1362438282","pt":1588450920255,"mc":[{"id":"1.170370564","rc":[{"trd":[[5.5,123.21]],"ltp":5.5,"tv":123.21,"id":9630572},{"atl":[[5.5,38.06]],"id":9630572}],"con":true,"img":false}]}
{"op":"mcm","clk":"1362438287","pt":1588450920658,"mc":[{"id":"1.170370564","rc":[{"trd":[[5.5,123.36]],"ltp":5.5,"tv":123.36,"id":9630572},{"atl":[[5.5,37.91]],"id":9630572},{"trd":[[1.22,3208.82]],"ltp":1.22,"tv":3208.82,"id":8509691}],"con":true,"img":false}]}
{"op":"mcm","clk":"1362438295","pt":1588450921218,"mc":[{"id":"1.170370564","rc":[{"trd":[[5.3,209.31]],"ltp":5.3,"tv":209.31,"id":9630572},{"trd":[[1.23,2143.81]],"ltp":1.23,"tv":2143.81,"id":8509691},{"atl":[[1.23,818.92]],"id":8509691}],"con":true,"img":false}]}
{"op":"mcm","clk":"1362438357","pt":1588450926327,"mc":[{"id":"1.170370564","rc":[{"trd":[[5.5,123.4]],"ltp":5.5,"tv":123.4,"id":9630572},{"atl":[[5.5,37.89]],"id":9630572}],"con":true,"img":false}]}
{"op":"mcm","clk":"1362438407","pt":1588450930459,"mc":[{"id":"1.170370564","rc":[{"atb":[[1.21,0]],"id":8509691}],"con":true,"img":false}]}
{"op":"mcm","clk":"1362438445","pt":1588450933464,"mc":[{"id":"1.170370564","rc":[{"atb":[[1.22,2]],"id":8509691}],"con":true,"img":false}]}
{"op":"mcm","clk":"1362438476","pt":1588450935546,"mc":[{"id":"1.170370564","rc":[{"trd":[[5.3,220.18]],"ltp":5.3,"tv":220.18,"id":9630572},{"trd":[[1.23,2190.65]],"ltp":1.23,"tv":2190.65,"id":8509691},{"atl":[[1.23,772.08]],"id":8509691}],"con":true,"img":false}]}
{"op":"mcm","clk":"1362438543","pt":1588450939765,"mc":[{"id":"1.170370564","rc":[{"trd":[[1.23,2191.49]],"ltp":1.23,"tv":2191.49,"id":8509691},{"atl":[[1.23,771.66]],"id":8509691}],"con":true,"img":false}]}
{"op":"mcm","clk":"1362438550","pt":1588450940173,"mc":[{"id":"1.170370564","rc":[{"trd":[[1.23,2360.46]],"ltp":1.23,"tv":2360.46,"id":8509691},{"atl":[[1.23,687.18]],"id":8509691}],"con":true,"img":false}]}
{"op":"mcm","clk":"1362438583","pt":1588450943276,"mc":[{"id":"1.170370564","rc":[{"trd":[[5.5,125.28]],"ltp":5.5,"tv":125.28,"id":9630572},{"atl":[[5.5,36.95]],"id":9630572}],"con":true,"img":false}]}
{"op":"mcm","clk":"1362438589","pt":1588450943934,"mc":[{"id":"1.170370564","rc":[{"trd":[[1.22,3209.74]],"ltp":1.22,"tv":3209.74,"id":8509691},{"atb":[[1.22,1.54]],"id":8509691}],"con":true,"img":false}]}
{"op":"mcm","clk":"1362438605","pt":1588450945156,"mc":[{"id":"1.170370564","rc":[{"trd":[[5.3,225.47]],"ltp":5.3,"tv":225.47,"id":9630572},{"trd":[[1.23,2383.26]],"ltp":1.23,"tv":2383.26,"id":8509691},{"atl":[[1.23,664.38]],"id":8509691}],"con":true,"img":false}]}
{"op":"mcm","clk":"1362438703","pt":1588450954872,"mc":[{"id":"1.170370564","rc":[{"trd":[[1.23,2384.1]],"ltp":1.23,"tv":2384.1,"id":8509691},{"atl":[[1.23,663.96]],"id":8509691}],"con":true,"img":false}]}
{"op":"mcm","clk":"1362438707","pt":1588450955278,"mc":[{"id":"1.170370564","rc":[{"trd":[[5.5,125.36]],"ltp":5.5,"tv":125.36,"id":9630572},{"atl":[[5.5,36.91]],"id":9630572}],"con":true,"img":false}]}
{"op":"mcm","clk":"1362438712","pt":1588450955583,"mc":[{"id":"1.170370564","rc":[{"trd":[[5.3,238.27]],"ltp":5.3,"tv":238.27,"id":9630572},{"trd":[[1.23,2439.25]],"ltp":1.23,"tv":2439.25,"id":8509691},{"atl":[[1.23,608.81]],"id":8509691}],"con":true,"img":false}]}
{"op":"mcm","clk":"1362438717","pt":1588450955888,"mc":[{"id":"1.170370564","rc":[{"atl":[[1.23,1046.76]],"id":8509691}],"con":true,"img":false}]}
{"op":"mcm","clk":"1362438888","pt":1588450969978,"mc":[{"id":"1.170370564","rc":[{"trd":[[5.5,162.27]],"ltp":5.5,"tv":162.27,"id":9630572},{"atl":[[5.5,0]],"id":9630572},{"trd":[[1.22,3379.22]],"ltp":1.22,"tv":3379.22,"id":8509691},{"atb":[[1.22,0]],"id":8509691},{"atl":[[1.22,970.71]],"id":8509691}],"con":true,"img":false}]}
{"op":"mcm","clk":"1362438903","pt":1588450971962,"mc":[{"id":"1.170370564","rc":[{"trd":[[5.5,162.63]],"ltp":5.5,"tv":162.63,"id":9630572},{"trd":[[1.22,3380.83]],"ltp":1.22,"tv":3380.83,"id":8509691},{"atl":[[1.22,969.11]],"id":8509691}],"con":true,"img":false}]}
{"op":"mcm","clk":"1362438937","pt":1588450976180,"mc":[{"id":"1.170370564","rc":[{"atl":[[1.22,971.11]],"id":8509691}],"con":true,"img":false}]}
{"op":"mcm","clk":"1362438946","pt":1588450977398,"mc":[{"id":"1.170370564","rc":[{"trd":[[1.22,3480.83]],"ltp":1.22,"tv":3480.83,"id":8509691},{"atl":[[1.22,921.11]],"id":8509691}],"con":true,"img":false}]}
{"op":"mcm","clk":"1362438982","pt":1588450981673,"mc":[{"id":"1.170370564","rc":[{"trd":[[5.7,22.79]],"ltp":5.7,"tv":22.79,"id":9630572},{"atl":[[5.7,4.41]],"id":9630572}],"con":true,"img":false}]}
{"op":"mcm","clk":"1362439003","pt":1588450985503,"mc":[{"id":"1.170370564","rc":[{"trd":[[5.7,27.21]],"ltp":5.7,"tv":27.21,"id":9630572},{"atl":[[5.7,0]],"id":9630572},{"trd":[[1.21,4186.19]],"ltp":1.21,"tv":4186.19,"id":8509691},{"atl":[[1.21,23.52]],"id":8509691}],"con":true,"img":false}]}
{"op":"mcm","clk":"1362439011","pt":1588450986470,"mc":[{"id":"1.170370564","rc":[{"trd":[[1.21,4226.19]],"ltp":1.21,"tv":4226.19,"id":8509691},{"atl":[[1.21,3.52]],"id":8509691}],"con":true,"img":false}]}
{"op":"mcm","clk":"1362439016","pt":1588450986979,"mc":[{"id":"1.170370564","rc":[{"atb":[[1.2,44.32]],"id":8509691}],"con":true,"img":false}]}
{"op":"mcm","clk":"1362439024","pt":1588450988101,"mc":[{"id":"1.170370564","rc":[{"atb":[[1.19,119.34]],"id":8509691}],"con":true,"img":false}]}
{"op":"mcm","clk":"1362439029","pt":1588450988815,"mc":[{"id":"1.170370564","rc":[{"trd":[[1.21,4233.25]],"ltp":1.21,"tv":4233.25,"id":8509691},{"atb":[[1.21,1222.71]],"id":8509691},{"atl":[[1.21,0]],"id":8509691}],"con":true,"img":false}]}
{"op":"mcm","clk":"1362439033","pt":1588450989988,"mc":[{"id":"1.170370564","rc":[{"trd":[[1.21,4243.25]],"ltp":1.21,"tv":4243.25,"id":8509691},{"atb":[[1.21,1217.71]],"id":8509691}],"con":true,"img":false}]}
{"op":"mcm","clk":"1362439059","pt":1588450993906,"mc":[{"id":"1.170370564","rc":[{"atl":[[1.22,919.11]],"id":8509691}],"con":true,"img":false}]}
{"op":"mcm","clk":"1362439060","pt":1588450994312,"mc":[{"id":"1.170370564","rc":[{"atb":[[1.2,88.65]],"id":8509691}],"con":true,"img":false}]}
{"op":"mcm","clk":"1362439066","pt":1588450994974,"mc":[{"id":"1.170370564","rc":[{"trd":[[5.5,182.63]],"ltp":5.5,"tv":182.63,"id":9630572},{"trd":[[1.22,3570.99]],"ltp":1.22,"tv":3570.99,"id":8509691},{"atl":[[1.22,828.95]],"id":8509691}],"con":true,"img":false}]}
{"op":"mcm","clk":"1362439079","pt":1588450996295,"mc":[{"id":"1.170370564","rc":[{"trd":[[1.22,3599.79]],"ltp":1.22,"tv":3599.79,"id":8509691},{"atl":[[1.22,814.55]],"id":8509691}],"con":true,"img":false}]}
{"op":"mcm","clk":"1362439098","pt":1588450998581,"mc":[{"id":"1.170370564","rc":[{"trd":[[5.5,185.55]],"ltp":5.5,"tv":185.55,"id":9630572},{"trd":[[1.22,3612.97]],"ltp":1.22,"tv":3612.97,"id":8509691},{"atl":[[1.22,801.36]],"id":8509691}],"con":true,"img":false}]}
{"op":"mcm","clk":"1362439125","pt":1588451001580,"mc":[{"id":"1.170370564","rc":[{"trd":[[1.21,4243.71]],"ltp":1.21,"tv":4243.71,"id":8509691},{"atb":[[1.21,1217.48]],"id":8509691}],"con":true,"img":false}]}
{"op":"mcm","clk":"1362439144","pt":1588451003513,"mc":[{"id":"1.170370564","rc":[{"trd":[[1.22,3613.2]],"ltp":1.22,"tv":3613.2,"id":8509691},{"atl":[[1.22,801.25]],"id":8509691}],"con":true,"img":false}]}
{"op":"mcm","clk":"1362439146","pt":1588451003615,"mc":[{"id":"1.170370564","rc":[{"trd":[[1.22,4794.05]],"ltp":1.22,"tv":4794.05,"id":8509691},{"atl":[[1.22,210.82]],"id":8509691}],"con":true,"img":false}]}
{"op":"mcm","clk":"1362439161","pt":1588451006816,"mc":[{"id":"1.170370566","rc":[{"atl":[[1.69,16.39]],"id":8509691}],"con":true,"img":false}]}
{"op":"mcm","clk":"1362439168","pt":1588451007783,"mc":[{"id":"1.170370564","rc":[{"trd":[[5.5,232.32]],"ltp":5.5,"tv":232.32,"id":9630572},{"atl":[[5.5,130.54]],"id":9630572},{"trd":[[1.22,5004.88]],"ltp":1.22,"tv":5004.88,"id":8509691},{"atl":[[1.22,0]],"id":8509691}],"con":true,"img":false}]}
{"op":"mcm","clk":"1362439182","pt":1588451009921,"mc":[{"id":"1.170370564","rc":[{"atb":[[1.22,180]],"id":8509691}],"con":true,"img":false}]}
{"op":"mcm","clk":"1362439186","pt":1588451010226,"mc":[{"id":"1.170370564","rc":[{"atb":[[1.22,1055.89]],"id":8509691}],"con":true,"img":false}]}
{"op":"mcm","clk":"1362439221","pt":1588451016629,"mc":[{"id":"1.170370564","rc":[{"atl":[[5.5,134.91]],"id":9630572}],"con":true,"img":false}]}
{"op":"mcm","clk":"1362439268","pt":1588451025887,"mc":[{"id":"1.170370564","rc":[{"trd":[[5.3,326.92]],"ltp":5.3,"tv":326.92,"id":9630572},{"trd":[[1.23,2821.25]],"ltp":1.23,"tv":2821.25,"id":8509691},{"atl":[[1.23,664.76]],"id":8509691}],"con":true,"img":false}]}
{"op":"mcm","clk":"1362439297","pt":1588451029799,"mc":[{"id":"1.170370564","rc":[{"atb":[[1.22,875.89]],"id":8509691}],"con":true,"img":false}]}
{"op":"mcm","clk":"1362439303","pt":1588451030916,"mc":[{"id":"1.170370564","rc":[{"atl":[[5.5,130.54]],"id":9630572}],"con":true,"img":false}]}
{"op":"mcm","clk":"1362439308","pt":1588451031526,"mc":[{"id":"1.170370564","rc":[{"trd":[[1.23,4150.77]],"ltp":1.23,"tv":4150.77,"id":8509691},{"atb":[[1.23,24.06]],"id":8509691},{"atl":[[1.23,0]],"id":8509691}],"con":true,"img":false}]}
{"op":"mcm","clk":"1362439325","pt":1588451034933,"mc":[{"id":"1.170370564","rc":[{"atb":[[1.23,204.06]],"id":8509691}],"con":true,"img":false}]}
{"op":"mcm","clk":"1362439326","pt":1588451035035,"mc":[{"id":"1.170370564","rc":[{"trd":[[1.23,4558.91]],"ltp":1.23,"tv":4558.91,"id":8509691},{"atb":[[1.23,0],[1.22,834.71]],"id":8509691}],"con":true,"img":false}]}
{"op":"mcm","clk":"1362439332","pt":1588451036812,"mc":[{"id":"1.170370564","rc":[{"trd":[[5.6,67.29],[5.5,493.4]],"ltp":5.6,"tv":560.68,"id":9630572},{"atl":[[5.5,0]],"id":9630572},{"trd":[[1.22,5215.11]],"ltp":1.22,"tv":5215.11,"id":8509691},{"atb":[[1.22,624.48]],"id":8509691}],"con":true,"img":false}]}
{"op":"mcm","clk":"1362439348","pt":1588451039911,"mc":[{"id":"1.170370564","rc":[{"atb":[[1.13,0.24]],"id":8509691}],"con":true,"img":false}]}
{"op":"mcm","clk":"1362439359","pt":1588451042913,"mc":[{"id":"1.170370564","rc":[{"atb":[[1.23,10.75]],"id":8509691}],"con":true,"img":false}]}
{"op":"mcm","clk":"1362439369","pt":1588451045722,"mc":[{"id":"1.170370564","rc":[{"atb":[[1.2,0]],"id":8509691}],"con":true,"img":false}]}
{"op":"mcm","clk":"1362439380","pt":1588451046433,"mc":[{"id":"1.170370564","rc":[{"atb":[[1.19,75.01]],"id":8509691}],"con":true,"img":false}]}
{"op":"mcm","clk":"1362439388","pt":1588451048010,"mc":[{"id":"1.170370564","rc":[{"trd":[[5.2,12.43]],"ltp":5.2,"tv":12.43,"id":9630572},{"atb":[[5.2,0]],"id":9630572},{"atl":[[5.2,1.39]],"id":9630572}],"con":true,"img":false}]}
{"op":"mcm","clk":"1362439401","pt":1588451050148,"mc":[{"id":"1.170370564","rc":[{"trd":[[5.2,12.85]],"ltp":5.2,"tv":12.85,"id":9630572},{"atl":[[5.2,0.97]],"id":9630572},{"trd":[[1.23,4582.22]],"ltp":1.23,"tv":4582.22,"id":8509691},{"atb":[[1.23,0]],"id":8509691}],"con":true,"img":false}]}
{"op":"mcm","clk":"1362439415","pt":1588451052542,"mc":[{"id":"1.170370564","rc":[{"atl":[[1.45,56.72]],"id":8509691}],"con":true,"img":false}]}
{"op":"mcm","clk":"1362439454","pt":1588451061638,"mc":[{"id":"1.170370564","rc":[{"trd":[[5.2,13.33]],"ltp":5.2,"tv":13.33,"id":9630572},{"atl":[[5.2,0.5]],"id":9630572},{"trd":[[1.23,4584.22]],"ltp":1.23,"tv":4584.22,"id":8509691}],"con":true,"img":false}]}
{"op":"mcm","clk":"1362439468","pt":1588451065246,"mc":[{"id":"1.170370564","rc":[{"trd":[[1.27,5240.15],[1.24,3016.46]],"ltp":1.27,"tv":8256.61,"id":8509691},{"atl":[[1.27,13.56],[1.24,0]],"id":8509691}],"con":true,"img":false}]}
{"op":"mcm","clk":"1362439469","pt":1588451065348,"mc":[{"id":"1.170370564","rc":[{"atb":[[1.22,0]],"id":8509691}],"con":true,"img":false}]}
{"op":"mcm","clk":"1362439471","pt":1588451065755,"mc":[{"id":"1.170370564","rc":[{"trd":[[1.27,5243.43]],"ltp":1.27,"tv":5243.43,"id":8509691},{"atl":[[1.27,11.92]],"id":8509691}],"con":true,"img":false}]}
{"op":"mcm","clk":"1362439481","pt":1588451067534,"mc":[{"id":"1.170370564","rc":[{"trd":[[4.8,364.82]],"ltp":4.8,"tv":364.82,"id":9630572},{"atb":[[4.8,40]],"id":9630572}],"con":true,"img":false}]}
{"op":"mcm","clk":"1362439490","pt":1588451069263,"mc":[{"id":"1.170370564","rc":[{"trd":[[4.8,444.82]],"ltp":4.8,"tv":444.82,"id":9630572},{"atb":[[4.8,0]],"id":9630572},{"atl":[[4.8,59.29]],"id":9630572},{"atb":[[1.21,0]],"id":8509691}],"con":true,"img":false}]}
{"op":"mcm","clk":"1362439493","pt":1588451069721,"mc":[{"id":"1.170370564","rc":[{"atb":[[1.24,7.99]],"id":8509691}],"con":true,"img":false}]}
{"op":"mcm","clk":"1362439494","pt":1588451069823,"mc":[{"id":"1.170370564","rc":[{"trd":[[4.8,465.01]],"ltp":4.8,"tv":465.01,"id":9630572},{"atl":[[4.8,39.1]],"id":9630572},{"trd":[[1.26,3859.91]],"ltp":1.26,"tv":3859.91,"id":8509691}],"con":true,"img":false}]}
{"op":"mcm","clk":"1362439498","pt":1588451070940,"mc":[{"id":"1.170370564","rc":[{"atb":[[1.23,88.12]],"id":8509691}],"con":true,"img":false}]}
{"op":"mcm","clk":"1362439499","pt":1588451071650,"mc":[{"id":"1.170370566","rc":[{"atl":[[1.69,0]],"id":8509691}],"con":true,"img":false}]}
{"op":"mcm","clk":"1362439521","pt":1588451076224,"mc":[{"id":"1.170370564","rc":[{"trd":[[1.27,5243.47]],"ltp":1.27,"tv":5243.47,"id":8509691},{"atl":[[1.27,11.9]],"id":8509691}],"con":true,"img":false}]}
{"op":"mcm","clk":"1362439523","pt":1588451077037,"mc":[{"id":"1.170370564","rc":[{"atl":[[5.2,0]],"id":9630572}],"con":true,"img":false}]}
{"op":"mcm","clk":"1362439529","pt":1588451078458,"mc":[{"id":"1.170370566","rc":[{"atl":[[1.87,14.81]],"id":8509691}],"con":true,"img":false}]}
{"op":"mcm","clk":"1362439538","pt":1588451080946,"mc":[{"id":"1.170370564","rc":[{"trd":[[4.8,469.08]],"ltp":4.8,"tv":469.08,"id":9630572},{"atl":[[4.8,35.02]],"id":9630572},{"trd":[[1.26,3875.43]],"ltp":1.26,"tv":3875.43,"id":8509691}],"con":true,"img":false}]}
{"op":"mcm","clk":"1362439549","pt":1588451082925,"mc":[{"id":"1.170370564","rc":[{"trd":[[4.8,469.61]],"ltp":4.8,"tv":469.61,"id":9630572},{"atl":[[4.8,34.5]],"id":9630572},{"trd":[[1.26,3877.43]],"ltp":1.26,"tv":3877.43,"id":8509691}],"con":true,"img":false}]}
{"op":"mcm","clk":"1362439581","pt":1588451089227,"mc":[{"id":"1.170370564","rc":[{"trd":[[1.27,5244.17]],"ltp":1.27,"tv":5244.17,"id":8509691},{"atl":[[1.27,11.55]],"id":8509691}],"con":true,"img":false}]}
{"op":"mcm","clk":"1362439591","pt":1588451090241,"mc":[{"id":"1.170370566","rc":[{"atl":[[1.87,0]],"id":8509691}],"con":true,"img":false}]}
{"op":"mcm","clk":"1362439600","pt":1588451091259,"mc":[{"id":"1.170370564","rc":[{"trd":[[4.7,363.73]],"ltp":4.7,"tv":363.73,"id":9630572},{"atl":[[4.7,6.88]],"id":9630572},{"trd":[[1.27,5255.72]],"ltp":1.27,"tv":5255.72,"id":8509691},{"atl":[[1.27,0]],"id":8509691}],"con":true,"img":false}]}
{"op":"mcm","clk":"1362439625","pt":1588451095435,"mc":[{"id":"1.170370566","rc":[{"atl":[[1.99,13.91]],"id":8509691}],"con":true,"img":false}]}
{"op":"mcm","clk":"1362439627","pt":1588451095638,"mc":[{"id":"1.170370564","rc":[{"atl":[[4.4,78.01],[4.7,0]],"id":9630572}],"con":true,"img":false}]}
{"op":"mcm","clk":"1362439636","pt":1588451096959,"mc":[{"id":"1.170370564","rc":[{"atb":[[1.27,35.63]],"id":8509691}],"con":true,"img":false}]}
{"op":"mcm","clk":"1362439655","pt":1588451099347,"mc":[{"id":"1.170370564","rc":[{"trd":[[4.4,400.2]],"ltp":4.4,"tv":400.2,"id":9630572},{"atl":[[4.4,75.57]],"id":9630572}],"con":true,"img":false}]}
{"op":"mcm","clk":"1362439660","pt":1588451099754,"mc":[{"id":"1.170370564","rc":[{"trd":[[4.4,403.8]],"ltp":4.4,"tv":403.8,"id":9630572},{"atl":[[4.4,71.97]],"id":9630572},{"trd":[[1.29,24023.07]],"ltp":1.29,"tv":24023.07,"id":8509691}],"con":true,"img":false}]}
{"op":"mcm","clk":"1362439664","pt":1588451100466,"mc":[{"id":"1.170370564","rc":[{"trd":[[4.4,408.49]],"ltp":4.4,"tv":408.49,"id":9630572},{"atl":[[4.4,67.28]],"id":9630572},{"trd":[[1.29,24039.07]],"ltp":1.29,"tv":24039.07,"id":8509691}],"con":true,"img":false}]}
{"op":"mcm","clk":"1362439669","pt":1588451101433,"mc":[{"id":"1.170370564","rc":[{"atl":[[4.4,0]],"id":9630572}],"con":true,"img":false}]}
{"op":"mcm","clk":"1362439693","pt":1588451104142,"mc":[{"id":"1.170370564","rc":[{"trd":[[1.27,5299.72]],"ltp":1.27,"tv":5299.72,"id":8509691},{"atb":[[1.27,13.63]],"id":8509691}],"con":true,"img":false}]}
{"op":"mcm","clk":"1362439710","pt":1588451106540,"mc":[{"id":"1.170370564","rc":[{"trd":[[3.65,102.67],[3.85,61.95],[4.1,311.15]],"ltp":3.65,"tv":475.77,"id":9630572},{"atb":[[3.65,0]],"id":9630572},{"atl":[[3.65,62.71]],"id":9630572},{"trd":[[1.35,896.55],[1.32,1387.4]],"ltp":1.35,"tv":2283.95,"id":8509691},{"atl":[[1.35,0],[1.32,0]],"id":8509691}],"con":true,"img":false}]}
{"op":"mcm","clk":"1362439722","pt":1588451107454,"mc":[{"id":"1.170370564","rc":[{"trd":[[3.65,102.85]],"ltp":3.65,"tv":102.85,"id":9630572},{"atl":[[3.65,62.53]],"id":9630572},{"trd":[[1.37,79.91]],"ltp":1.37,"tv":79.91,"id":8509691}],"con":true,"img":false}]}
{"op":"mcm","clk":"1362439766","pt":1588451112442,"mc":[{"id":"1.170370564","rc":[{"atl":[[1.45,7.09]],"id":8509691}],"con":true,"img":false}]}
{"op":"mcm","clk":"1362439769","pt":1588451112648,"mc":[{"id":"1.170370564","rc":[{"atl":[[3.65,0]],"id":9630572}],"con":true,"img":false}]}
{"op":"mcm","clk":"1362439793","pt":1588451115752,"mc":[{"id":"1.170370564","rc":[{"trd":[[3.6,3.07]],"ltp":3.6,"tv":3.07,"id":9630572},{"atl":[[3.6,56.93]],"id":9630572},{"trd":[[1.38,303.43]],"ltp":1.38,"tv":303.43,"id":8509691},{"atl":[[1.38,0]],"id":8509691}],"con":true,"img":false}]}
{"op":"mcm","clk":"1362439813","pt":1588451117785,"mc":[{"id":"1.170370564","rc":[{"trd":[[3.15,0.93],[3.2,3.21],[3.4,3.31]],"ltp":3.15,"tv":7.45,"id":9630572},{"atl":[[3.1,55.07]],"id":9630572},{"trd":[[1.46,2],[1.45,7.09],[1.41,12.65]],"ltp":1.46,"tv":21.74,"id":8509691},{"atl":[[1.46,0],[1.45,0],[1.41,0]],"id":8509691}],"con":true,"img":false}]}
{"op":"mcm","clk":"1362439832","pt":1588451119970,"mc":[{"id":"1.170370564","rc":[{"trd":[[3.1,9.24]],"ltp":3.1,"tv":9.24,"id":9630572},{"atl":[[3.1,45.82]],"id":9630572},{"trd":[[1.47,19.5]],"ltp":1.47,"tv":19.5,"id":8509691}],"con":true,"img":false}]}
{"op":"mcm","clk":"1362439855","pt":1588451123379,"mc":[{"id":"1.170370564","rc":[{"trd":[[3.1,14.04]],"ltp":3.1,"tv":14.04,"id":9630572},{"atl":[[3.1,43.42]],"id":9630572}],"con":true,"img":false}]}
{"op":"mcm","clk":"1362439857","pt":1588451123990,"mc":[{"id":"1.170370564","rc":[{"atb":[[1.44,32.8]],"id":8509691}],"con":true,"img":false}]}
{"op":"mcm","clk":"1362439862","pt":1588451124295,"mc":[{"id":"1.170370564","rc":[{"atl":[[3.1,0]],"id":9630572}],"con":true,"img":false}]}
{"op":"mcm","clk":"1362439870","pt":1588451124958,"mc":[{"id":"1.170370566","rc":[{"trd":[[1.99,26.59]],"ltp":1.99,"tv":26.59,"id":8509691},{"atl":[[1.99,0.62]],"id":8509691}],"con":true,"img":false}]}
{"op":"mcm","clk":"1362439876","pt":1588451125466,"mc":[{"id":"1.170370564","rc":[{"atb":[[1.24,0]],"id":8509691}],"con":true,"img":false},{"id":"1.170370566","rc":[{"atl":[[1.99,0]],"id":8509691}],"con":true,"img":false}]}
{"op":"mcm","clk":"1362439881","pt":1588451126887,"mc":[{"id":"1.170370564","rc":[{"atb":[[1.01,467.38]],"id":9630572}],"con":true,"img":false}]}
{"op":"mcm","clk":"1362439882","pt":1588451126989,"mc":[{"id":"1.170370564","rc":[{"atb":[[3.1,8.71]],"id":9630572}],"con":true,"img":false}]}
{"op":"mcm","clk":"1362439886","pt":1588451127753,"mc":[{"id":"1.170370564","rc":[{"atb":[[1.01,464.8]],"id":9630572}],"con":true,"img":false}]}
{"op":"mcm","clk":"1362439887","pt":1588451127856,"mc":[{"id":"1.170370564","rc":[{"atl":[[1.45,29.85]],"id":8509691}],"con":true,"img":false}]}
{"op":"mcm","clk":"1362439893","pt":1588451128672,"mc":[{"id":"1.170370564","rc":[{"atb":[[1.01,464.79]],"id":9630572}],"con":true,"img":false}]}
{"op":"mcm","clk":"1362439901","pt":1588451129381,"mc":[{"id":"1.170370564","rc":[{"trd":[[2.9,10.62],[3,13.34],[3.2,16.74],[3.1,31.46],[2.96,1.08],[3.05,1.45]],"ltp":2.9,"tv":74.69,"id":9630572},{"atb":[[2.9,94.69],[3.1,0]],"id":9630572},{"trd":[[1.51,2.12],[1.45,36.95],[1.48,3],[1.5,26.68]],"ltp":1.51,"tv":68.75,"id":8509691},{"atl":[[1.45,0],[1.51,0],[1.48,0],[1.5,0]],"id":8509691}],"con":true,"img":false}]}
{"op":"mcm","clk":"1362439911","pt":1588451130293,"mc":[{"id":"1.170370564","rc":[{"trd":[[1.44,4]],"ltp":1.44,"tv":4.0,"id":8509691},{"atb":[[1.44,30.8]],"id":8509691}],"con":true,"img":false}]}
{"op":"mcm","clk":"1362439928","pt":1588451133800,"mc":[{"id":"1.170370564","rc":[{"atb":[[3.1,0.01]],"id":9630572}],"con":true,"img":false}]}
{"op":"mcm","clk":"1362439938","pt":1588451135983,"mc":[{"id":"1.170370564","rc":[{"trd":[[2.9,38.3],[3.1,31.47]],"ltp":2.9,"tv":69.77,"id":9630572},{"atb":[[2.9,67.01],[3.1,0]],"id":9630572},{"trd":[[1.53,52.46],[1.48,3.02]],"ltp":1.53,"tv":55.48,"id":8509691}],"con":true,"img":false}]}
{"op":"mcm","clk":"1362439941","pt":1588451136391,"mc":[{"id":"1.170370564","rc":[{"atb":[[1.23,0]],"id":8509691}],"con":true,"img":false}]}
{"op":"mcm","clk":"1362439943","pt":1588451136594,"mc":[{"id":"1.170370564","rc":[{"atb":[[1.5,12.7]],"id":8509691}],"con":true,"img":false}]}
{"op":"mcm","clk":"1362439946","pt":1588451136696,"mc":[{"id":"1.170370564","rc":[{"atb":[[1.48,0.28]],"id":8509691}],"con":true,"img":false}]}
{"op":"mcm","clk":"1362439958","pt":1588451140001,"mc":[{"id":"1.170370564","rc":[{"trd":[[2.9,172.32]],"ltp":2.9,"tv":172.32,"id":9630572},{"atb":[[2.9,0]],"id":9630572},{"atl":[[2.9,52.99]],"id":9630572}],"con":true,"img":false}]}
{"op":"mcm","clk":"1362439967","pt":1588451141782,"mc":[{"id":"1.170370564","rc":[{"trd":[[2.9,172.56]],"ltp":2.9,"tv":172.56,"id":9630572},{"atl":[[2.9,52.75]],"id":9630572},{"trd":[[1.52,0.46]],"ltp":1.52,"tv":0.46,"id":8509691}],"con":true,"img":false}]}
{"op":"mcm","clk":"1362439971","pt":1588451142190,"mc":[{"id":"1.170370564","rc":[{"atl":[[1000,2]],"id":8509691}],"con":true,"img":false}]}
{"op":"mcm","clk":"1362439974","pt":1588451142390,"mc":[{"id":"1.170370564","rc":[{"trd":[[2.9,182.08]],"ltp":2.9,"tv":182.08,"id":9630572},{"atl":[[2.9,47.99]],"id":9630572}],"con":true,"img":false}]}
{"op":"mcm","clk":"1362439979","pt":1588451143001,"mc":[{"id":"1.170370564","rc":[{"atl":[[1000,0.01]],"id":8509691}],"con":true,"img":false}]}
{"op":"mcm","clk":"1362439986","pt":1588451143662,"mc":[{"id":"1.170370564","rc":[{"atl":[[1000,0]],"id":8509691}],"con":true,"img":false}]}
{"op":"mcm","clk":"1362439989","pt":1588451144476,"mc":[{"id":"1.170370564","rc":[{"atb":[[1.28,70.92]],"id":8509691}],"con":true,"img":false}]}
{"op":"mcm","clk":"1362440003","pt":1588451147572,"mc":[{"id":"1.170370564","rc":[{"atb":[[1.12,0],[1.1,8.37],[1.11,0]],"id":8509691}],"con":true,"img":false}]}
{"op":"mcm","clk":"1362440006","pt":1588451148182,"mc":[{"id":"1.170370564","rc":[{"atb":[[1.5,0]],"id":8509691}],"con":true,"img":false}]}
{"op":"mcm","clk":"1362440013","pt":1588451148793,"mc":[{"id":"1.170370564","rc":[{"trd":[[2.9,182.09]],"ltp":2.9,"tv":182.09,"id":9630572},{"atl":[[2.9,47.98]],"id":9630572},{"trd":[[1.52,0.47]],"ltp":1.52,"tv":0.47,"id":8509691}],"con":true,"img":false}]}
{"op":"mcm","clk":"1362440017","pt":1588451149097,"mc":[{"id":"1.170370564","rc":[{"trd":[[1.55,0.56]],"ltp":1.55,"tv":0.56,"id":8509691},{"atl":[[1.55,8.58]],"id":8509691}],"con":true,"img":false}]}
{"op":"mcm","clk":"1362440036","pt":1588451152297,"mc":[{"id":"1.170370564","rc":[{"atb":[[1.48,0]],"id":8509691}],"con":true,"img":false}]}
{"op":"mcm","clk":"1362440037","pt":1588451152500,"mc":[{"id":"1.170370564","rc":[{"atb":[[1.01,476.55]],"id":8509691}],"con":true,"img":false}]}
{"op":"mcm","clk":"1362440040","pt":1588451152703,"mc":[{"id":"1.170370564","rc":[{"atb":[[1.01,475.79]],"id":8509691}],"con":true,"img":false}]}
{"op":"mcm","clk":"1362440042","pt":1588451153008,"mc":[{"id":"1.170370564","rc":[{"trd":[[1.65,21.27],[1.6,23.5],[1.55,17.73]],"ltp":1.65,"tv":62.5,"id":8509691},{"atb":[[1.01,474.55],[1.67,11.45]],"id":8509691},{"atl":[[1.6,0],[1.55,0],[1.65,0]],"id":8509691}],"con":true,"img":false}]}
{"op":"mcm","clk":"1362440053","pt":1588451154483,"mc":[{"id":"1.170370564","rc":[{"trd":[[1.67,10.51]],"ltp":1.67,"tv":10.51,"id":8509691},{"atb":[[1.67,6.2]],"id":8509691}],"con":true,"img":false}]}
{"op":"mcm","clk":"1362440063","pt":1588451157987,"mc":[{"id":"1.170370564","rc":[{"trd":[[2.9,278.05],[2.5,4.14]],"ltp":2.9,"tv":282.19,"id":9630572},{"atb":[[2.9,6.72]],"id":9630572},{"atl":[[2.9,0]],"id":9630572},{"trd":[[1.67,16.71]],"ltp":1.67,"tv":16.71,"id":8509691},{"atb":[[1.67,0]],"id":8509691}],"con":true,"img":false}]}
{"op":"mcm","clk":"1362440065","pt":1588451158088,"mc":[{"id":"1.170370564","rc":[{"trd":[[2.9,278.7]],"ltp":2.9,"tv":278.7,"id":9630572},{"atb":[[2.9,6.07]],"id":9630572},{"trd":[[1.53,53.7]],"ltp":1.53,"tv":53.7,"id":8509691}],"con":true,"img":false}]}
{"op":"mcm","clk":"1362440067","pt":1588451158698,"mc":[{"id":"1.170370564","rc":[{"trd":[[1.44,34.15]],"ltp":1.44,"tv":34.15,"id":8509691},{"atb":[[1.44,15.72]],"id":8509691}],"con":true,"img":false}]}
{"op":"mcm","clk":"1362440089","pt":1588451161292,"mc":[{"id":"1.170370564","rc":[{"atb":[[1.01,467.99]],"id":9630572}],"con":true,"img":false}]}
{"op":"mcm","clk":"1362440090","pt":1588451161393,"mc":[{"id":"1.170370564","rc":[{"trd":[[2.9,284.77]],"ltp":2.9,"tv":284.77,"id":9630572},{"atb":[[2.9,0]],"id":9630572},{"trd":[[1.53,65.21]],"ltp":1.53,"tv":65.21,"id":8509691},{"atb":[[1.55,1.19]],"id":8509691}],"con":true,"img":false}]}
{"op":"mcm","clk":"1362440093","pt":1588451161903,"mc":[{"id":"1.170370564","rc":[{"atb":[[1.01,464.8]],"id":9630572}],"con":true,"img":false}]}
{"op":"mcm","clk":"1362440098","pt":1588451162514,"mc":[{"id":"1.170370564","rc":[{"atb":[[1.01,464.79]],"id":9630572}],"con":true,"img":false}]}
{"op":"mcm","clk":"1362440110","pt":1588451163696,"mc":[{"id":"1.170370564","rc":[{"atl":[[1.67,5]],"id":8509691}],"con":true,"img":false}]}
{"op":"mcm","clk":"1362440136","pt":1588451167618,"mc":[{"id":"1.170370564","rc":[{"atb":[[2.5,0]],"id":9630572}],"con":true,"img":false}]}
{"op":"mcm","clk":"1362440152","pt":1588451171229,"mc":[{"id":"1.170370564","rc":[{"atb":[[2.5,0]],"id":9630572}],"con":true,"img":false}]}
{"op":"mcm","clk":"1362440181","pt":1588451176422,"mc":[{"id":"1.170370564","rc":[{"trd":[[1.44,35.75],[1.55,20.12]],"ltp":1.44,"tv":55.87,"id":8509691},{"atb":[[1.44,14.92],[1.55,0]],"id":8509691}],"con":true,"img":false}]}
{"op":"mcm","clk":"1362440182","pt":1588451176522,"mc":[{"id":"1.170370564","rc":[{"trd":[[1.67,16.73]],"ltp":1.67,"tv":16.73,"id":8509691},{"atl":[[1.67,4.99]],"id":8509691}],"con":true,"img":false}]}
{"op":"mcm","clk":"1362440183","pt":1588451177130,"mc":[{"id":"1.170370564","rc":[{"atb":[[1.27,0]],"id":8509691}],"con":true,"img":false}]}
{"op":"mcm","clk":"1362440184","pt":1588451177232,"mc":[{"id":"1.170370564","rc":[{"atb":[[1.01,467.99]],"id":9630572}],"con":true,"img":false}]}
{"op":"mcm","clk":"1362440186","pt":1588451177335,"mc":[{"id":"1.170370564","rc":[{"atb":[[2.3,175]],"id":9630572}],"con":true,"img":false}]}
{"op":"mcm","clk":"1362440188","pt":1588451177539,"mc":[{"id":"1.170370564","rc":[{"trd":[[3.3,3.19]],"ltp":3.3,"tv":3.19,"id":9630572},{"trd":[[1.44,43.09]],"ltp":1.44,"tv":43.09,"id":8509691},{"atb":[[1.44,7.58]],"id":8509691}],"con":true,"img":false}]}
{"op":"mcm","clk":"1362440190","pt":1588451177795,"mc":[{"id":"1.170370564","rc":[{"atb":[[1.01,464.8]],"id":9630572}],"con":true,"img":false}]}
{"op":"mcm","clk":"1362440193","pt":1588451178405,"mc":[{"id":"1.170370564","rc":[{"atb":[[1.01,464.79]],"id":9630572}],"con":true,"img":false}]}
{"op":"mcm","clk":"1362440214","pt":1588451183539,"mc":[{"id":"1.170370564","rc":[{"atb":[[2.82,0]],"id":9630572}],"con":true,"img":false}]}
{"op":"mcm","clk":"1362440219","pt":1588451184096,"mc":[{"id":"1.170370564","rc":[{"atb":[[2.3,0]],"id":9630572}],"con":true,"img":false}]}
{"op":"mcm","clk":"1362440242","pt":1588451189230,"mc":[{"id":"1.170370564","rc":[{"atb":[[2.58,175]],"id":9630572}],"con":true,"img":false}]}
{"op":"mcm","clk":"1362440256","pt":1588451192638,"mc":[{"id":"1.170370566","rc":[{"atb":[[1.01,79.98]],"id":8509691}],"con":true,"img":false}]}
{"op":"mcm","clk":"1362440265","pt":1588451194827,"mc":[{"id":"1.170370564","rc":[{"trd":[[2.42,1.24],[2.82,0.01],[2.48,3.35],[2.58,350]],"ltp":2.42,"tv":354.6,"id":9630572},{"atb":[[2.82,0],[2.58,0]],"id":9630572},{"atl":[[2.38,263.65]],"id":9630572},{"trd":[[1.7,1.77],[1.67,21.72]],"ltp":1.7,"tv":23.49,"id":8509691},{"atl":[[1.67,0],[1.7,0]],"id":8509691}],"con":true,"img":false},{"id":"1.170370566","rc":[{"atb":[[1.01,79.98]],"id":9630572}],"con":true,"img":false}]}
{"op":"mcm","clk":"1362440269","pt":1588451195845,"mc":[{"id":"1.170370564","rc":[{"trd":[[2.38,2.53]],"ltp":2.38,"tv":2.53,"id":9630572},{"atl":[[2.38,261.11]],"id":9630572},{"trd":[[1.72,3.5]],"ltp":1.72,"tv":3.5,"id":8509691}],"con":true,"img":false}]}
{"op":"mcm","clk":"1362440299","pt":1588451200518,"mc":[{"id":"1.170370564","rc":[{"atl":[[2.84,5]],"id":9630572}],"con":true,"img":false}]}
{"op":"mcm","clk":"1362440328","pt":1588451206526,"mc":[{"id":"1.170370567","rc":[{"atb":[[1.01,79.98]],"id":9630572}],"con":true,"img":false}]}
{"op":"mcm","clk":"1362440335","pt":1588451207645,"mc":[{"id":"1.170370564","rc":[{"atb":[[2.3,100]],"id":9630572}],"con":true,"img":false}]}
{"op":"mcm","clk":"1362440338","pt":1588451207848,"mc":[{"id":"1.170370564","rc":[{"trd":[[1.75,0.76]],"ltp":1.75,"tv":0.76,"id":8509691},{"atl":[[1.75,1.39]],"id":8509691}],"con":true,"img":false}]}
{"op":"mcm","clk":"1362440339","pt":1588451207950,"mc":[{"id":"1.170370564","rc":[{"trd":[[2.38,4.45]],"ltp":2.38,"tv":4.45,"id":9630572},{"atl":[[2.38,259.2]],"id":9630572},{"trd":[[1.72,6.14]],"ltp":1.72,"tv":6.14,"id":8509691}],"con":true,"img":false}]}
{"op":"mcm","clk":"1362440349","pt":1588451210743,"mc":[{"id":"1.170370564","rc":[{"trd":[[2.38,8.69]],"ltp":2.38,"tv":8.69,"id":9630572},{"atl":[[2.38,254.95]],"id":9630572},{"trd":[[1.72,12.02]],"ltp":1.72,"tv":12.02,"id":8509691}],"con":true,"img":false}]}
{"op":"mcm","clk":"1362440351","pt":1588451211047,"mc":[{"id":"1.170370564","rc":[{"atl":[[2.84,0]],"id":9630572}],"con":true,"img":false}]}
{"op":"mcm","clk":"1362440353","pt":1588451211251,"mc":[{"id":"1.170370564","rc":[{"trd":[[2.38,16.69]],"ltp":2.38,"tv":16.69,"id":9630572},{"atl":[[2.38,250.95]],"id":9630572}],"con":true,"img":false}]}
{"op":"mcm","clk":"1362440354","pt":1588451211759,"mc":[{"id":"1.170370564","rc":[{"trd":[[2.38,17]],"ltp":2.38,"tv":17.0,"id":9630572},{"atl":[[2.38,250.64]],"id":9630572},{"trd":[[1.72,12.44]],"ltp":1.72,"tv":12.44,"id":8509691}],"con":true,"img":false}]}
{"op":"mcm","clk":"1362440355","pt":1588451212064,"mc":[{"id":"1.170370564","rc":[{"trd":[[2.38,17.17]],"ltp":2.38,"tv":17.17,"id":9630572},{"atl":[[2.38,250.47]],"id":9630572},{"trd":[[1.72,12.68]],"ltp":1.72,"tv":12.68,"id":8509691}],"con":true,"img":false}]}
{"op":"mcm","clk":"1362440356","pt":1588451212724,"mc":[{"id":"1.170370564","rc":[{"trd":[[2.38,18.61]],"ltp":2.38,"tv":18.61,"id":9630572},{"atl":[[2.38,249.03]],"id":9630572},{"trd":[[1.72,14.68]],"ltp":1.72,"tv":14.68,"id":8509691}],"con":true,"img":false}]}
{"op":"mcm","clk":"1362440357","pt":1588451212926,"mc":[{"id":"1.170370564","rc":[{"trd":[[1.75,3.54]],"ltp":1.75,"tv":3.54,"id":8509691},{"atb":[[1.75,175.91]],"id":8509691},{"atl":[[1.75,0]],"id":8509691}],"con":true,"img":false}]}
{"op":"mcm","clk":"1362440360","pt":1588451214551,"mc":[{"id":"1.170370564","rc":[{"atb":[[1.75,0]],"id":8509691}],"con":true,"img":false}]}
{"op":"mcm","clk":"1362440361","pt":1588451214652,"mc":[{"id":"1.170370564","rc":[{"trd":[[2.3,100]],"ltp":2.3,"tv":100.0,"id":9630572},{"atb":[[2.3,0]],"id":9630572},{"trd":[[1.77,129.94]],"ltp":1.77,"tv":129.94,"id":8509691},{"atb":[[1.77,47.35]],"id":8509691}],"con":true,"img":false}]}
{"op":"mcm","clk":"1362440365","pt":1588451215516,"mc":[{"id":"1.170370564","rc":[{"atb":[[1.77,0]],"id":8509691}],"con":true,"img":false}]}
{"op":"mcm","clk":"1362440367","pt":1588451216328,"mc":[{"id":"1.170370564","rc":[{"trd":[[1.8,0.1]],"ltp":1.8,"tv":0.1,"id":8509691},{"atl":[[1.8,1.71]],"id":8509691}],"con":true,"img":false}]}
{"op":"mcm","clk":"1362440370","pt":1588451216633,"mc":[{"id":"1.170370564","rc":[{"atl":[[1.76,8.86]],"id":8509691}],"con":true,"img":false}]}
{"op":"mcm","clk":"1362440372","pt":1588451217141,"mc":[{"id":"1.170370564","rc":[{"trd":[[2.3,102.39]],"ltp":2.3,"tv":102.39,"id":9630572},{"trd":[[1.76,3.13]],"ltp":1.76,"tv":3.13,"id":8509691},{"atl":[[1.76,5.72]],"id":8509691}],"con":true,"img":false}]}
{"op":"mcm","clk":"1362440382","pt":1588451219832,"mc":[{"id":"1.170370564","rc":[{"atl":[[1.75,26.65]],"id":8509691}],"con":true,"img":false}]}
{"op":"mcm","clk":"1362440385","pt":1588451220136,"mc":[{"id":"1.170370567","rc":[{"atb":[[1.01,88.65]],"id":8509691}],"con":true,"img":false}]}
{"op":"mcm","clk":"1362440391","pt":1588451220543,"mc":[{"id":"1.170370564","rc":[{"atl":[[1.75,0]],"id":8509691}],"con":true,"img":false}]}
{"op":"mcm","clk":"1362440392","pt":1588451220644,"mc":[{"id":"1.170370567","rc":[{"atb":[[1.02,88.86]],"id":8509691}],"con":true,"img":false}]}
{"op":"mcm","clk":"1362440398","pt":1588451223145,"mc":[{"id":"1.170370564","rc":[{"trd":[[2.38,20.32]],"ltp":2.38,"tv":20.32,"id":9630572},{"atl":[[2.38,247.33]],"id":9630572},{"trd":[[1.72,17.03]],"ltp":1.72,"tv":17.03,"id":8509691}],"con":true,"img":false}]}
{"op":"mcm","clk":"1362440408","pt":1588451225544,"mc":[{"id":"1.170370564","rc":[{"trd":[[2.3,106.77]],"ltp":2.3,"tv":106.77,"id":9630572},{"atl":[[2.3,55.62]],"id":9630572},{"trd":[[1.76,8.86]],"ltp":1.76,"tv":8.86,"id":8509691},{"atl":[[1.76,0]],"id":8509691}],"con":true,"img":false}]}
{"op":"mcm","clk":"1362440414","pt":1588451226664,"mc":[{"id":"1.170370567","rc":[{"atb":[[1.02,88.86]],"id":9630572}],"con":true,"img":false}]}
{"op":"mcm","clk":"1362440424","pt":1588451227635,"mc":[{"id":"1.170370567","rc":[{"atb":[[1.03,88.65]],"id":9630572}],"con":true,"img":false}]}
{"op":"mcm","clk":"1362440427","pt":1588451227736,"mc":[{"id":"1.170370564","rc":[{"trd":[[2.3,117.29]],"ltp":2.3,"tv":117.29,"id":9630572},{"atl":[[2.3,50.36]],"id":9630572}],"con":true,"img":false}]}
{"op":"mcm","clk":"1362440429","pt":1588451228041,"mc":[{"id":"1.170370564","rc":[{"atb":[[1.44,0]],"id":8509691}],"con":true,"img":false}]}
{"op":"mcm","clk":"1362440465","pt":1588451233640,"mc":[{"id":"1.170370564","rc":[{"atl":[[1.79,0.42]],"id":8509691}],"con":true,"img":false}]}
{"op":"mcm","clk":"1362440485","pt":1588451238074,"mc":[{"id":"1.170370564","rc":[{"trd":[[2.3,117.94]],"ltp":2.3,"tv":117.94,"id":9630572},{"atl":[[2.3,49.71]],"id":9630572},{"trd":[[1.76,9.71]],"ltp":1.76,"tv":9.71,"id":8509691}],"con":true,"img":false}]}
{"op":"mcm","clk":"1362440486","pt":1588451238176,"mc":[{"id":"1.170370564","rc":[{"trd":[[2.3,118.29]],"ltp":2.3,"tv":118.29,"id":9630572},{"atl":[[2.3,49.36]],"id":9630572},{"trd":[[1.76,10.17]],"ltp":1.76,"tv":10.17,"id":8509691}],"con":true,"img":false}]}
{"op":"mcm","clk":"1362440494","pt":1588451240871,"mc":[{"id":"1.170370564","rc":[{"trd":[[2.38,65.28],[2.3,217.01]],"ltp":2.38,"tv":282.28,"id":9630572},{"atl":[[2.3,0],[2.38,224.84]],"id":9630572},{"atl":[[1.81,120]],"id":8509691}],"con":true,"img":false}]}
{"op":"mcm","clk":"1362440496","pt":1588451241176,"mc":[{"id":"1.170370564","rc":[{"trd":[[2.26,0.33]],"ltp":2.26,"tv":0.33,"id":9630572},{"atl":[[2.26,12.78]],"id":9630572},{"trd":[[1.79,0.42]],"ltp":1.79,"tv":0.42,"id":8509691},{"atl":[[1.79,0]],"id":8509691}],"con":true,"img":false}]}
{"op":"mcm","clk":"1362440501","pt":1588451242244,"mc":[{"id":"1.170370564","rc":[{"trd":[[2.26,3.84]],"ltp":2.26,"tv":3.84,"id":9630572},{"atl":[[2.26,9.27]],"id":9630572},{"trd":[[1.79,4.85]],"ltp":1.79,"tv":4.85,"id":8509691}],"con":true,"img":false}]}
{"op":"mcm","clk":"1362440506","pt":1588451242855,"mc":[{"id":"1.170370564","rc":[{"trd":[[2.38,86.86],[2.26,22.39]],"ltp":2.38,"tv":109.25,"id":9630572},{"atl":[[2.38,214.06],[2.26,0]],"id":9630572}],"con":true,"img":false}]}
{"op":"mcm","clk":"1362440524","pt":1588451245863,"mc":[{"id":"1.170370564","rc":[{"trd":[[2.24,1.38]],"ltp":2.24,"tv":1.38,"id":9630572},{"atl":[[2.24,6.05]],"id":9630572},{"trd":[[1.8,1.82]],"ltp":1.8,"tv":1.82,"id":8509691},{"atl":[[1.8,0]],"id":8509691}],"con":true,"img":false}]}
{"op":"mcm","clk":"1362440531","pt":1588451248963,"mc":[{"id":"1.170370564","rc":[{"trd":[[2.24,5.88]],"ltp":2.24,"tv":5.88,"id":9630572},{"atl":[[2.24,1.55]],"id":9630572},{"trd":[[1.8,7.42]],"ltp":1.8,"tv":7.42,"id":8509691}],"con":true,"img":false}]}
{"op":"mcm","clk":"1362440536","pt":1588451249471,"mc":[{"id":"1.170370564","rc":[{"trd":[[2.24,7.19]],"ltp":2.24,"tv":7.19,"id":9630572},{"atl":[[2.24,0.23]],"id":9630572},{"trd":[[1.8,9.06]],"ltp":1.8,"tv":9.06,"id":8509691}],"con":true,"img":false}]}
{"op":"mcm","clk":"1362440537","pt":1588451249776,"mc":[{"id":"1.170370564","rc":[{"atb":[[1.96,1000]],"id":9630572}],"con":true,"img":false}]}
{"op":"mcm","clk":"1362440539","pt":1588451250385,"mc":[{"id":"1.170370567","rc":[{"atb":[[1.05,79.98]],"id":9630572}],"con":true,"img":false}]}
{"op":"mcm","clk":"1362440546","pt":1588451251756,"mc":[{"id":"1.170370564","rc":[{"atl":[[2.38,0]],"id":9630572}],"con":true,"img":false}]}
{"op":"mcm","clk":"1362440552","pt":1588451252568,"mc":[{"id":"1.170370564","rc":[{"trd":[[2.24,7.67]],"ltp":2.24,"tv":7.67,"id":9630572},{"atb":[[2.38,2.34]],"id":9630572},{"atl":[[2.24,0]],"id":9630572}],"con":true,"img":false}]}
{"op":"mcm","clk":"1362440553","pt":1588451252873,"mc":[{"id":"1.170370564","rc":[{"trd":[[2.38,87.71]],"ltp":2.38,"tv":87.71,"id":9630572},{"atb":[[2.38,1.48]],"id":9630572},{"trd":[[1.73,1.17]],"ltp":1.73,"tv":1.17,"id":8509691}],"con":true,"img":false}]}
{"op":"mcm","clk":"1362440557","pt":1588451254041,"mc":[{"id":"1.170370564","rc":[{"atb":[[1.01,476.55]],"id":8509691}],"con":true,"img":false}]}
{"op":"mcm","clk":"1362440560","pt":1588451254347,"mc":[{"id":"1.170370564","rc":[{"atb":[[1.01,466.79]],"id":9630572}],"con":true,"img":false}]}
{"op":"mcm","clk":"1362440562","pt":1588451255159,"mc":[{"id":"1.170370564","rc":[{"atb":[[1.01,474.56]],"id":8509691}],"con":true,"img":false}]}
{"op":"mcm","clk":"1362440565","pt":1588451255363,"mc":[{"id":"1.170370564","rc":[{"atb":[[1.01,465]],"id":9630572}],"con":true,"img":false}]}
{"op":"mcm","clk":"1362440569","pt":1588451256276,"mc":[{"id":"1.170370564","rc":[{"atb":[[1.01,464.79]],"id":9630572},{"atb":[[1.01,474.55]],"id":8509691}],"con":true,"img":false}]}
{"op":"mcm","clk":"1362440578","pt":1588451257090,"mc":[{"id":"1.170370564","rc":[{"trd":[[2.22,12.33],[2.38,90.69]],"ltp":2.22,"tv":103.02,"id":9630572},{"atb":[[2.38,0]],"id":9630572},{"trd":[[1.81,15.12]],"ltp":1.81,"tv":15.12,"id":8509691},{"atl":[[1.81,104.88]],"id":8509691}],"con":true,"img":false}]}
{"op":"mcm","clk":"1362440579","pt":1588451257292,"mc":[{"id":"1.170370564","rc":[{"atl":[[1.9,4.17]],"id":8509691}],"con":true,"img":false}]}
{"op":"mcm","clk":"1362440594","pt":1588451261361,"mc":[{"id":"1.170370564","rc":[{"atb":[[2.24,0.21]],"id":9630572},{"trd":[[1.81,15.14]],"ltp":1.81,"tv":15.14,"id":8509691},{"atl":[[1.81,104.87]],"id":8509691}],"con":true,"img":false}]}
{"op":"mcm","clk":"1362440684","pt":1588451270463,"mc":[{"id":"1.170370564","rc":[{"trd":[[2.22,23.25],[2.24,8.09]],"ltp":2.22,"tv":31.34,"id":9630572},{"atb":[[2.24,0]],"id":9630572},{"trd":[[1.81,28.53]],"ltp":1.81,"tv":28.53,"id":8509691},{"atl":[[1.81,91.48]],"id":8509691}],"con":true,"img":false}]}
{"op":"mcm","clk":"1362440709","pt":1588451272904,"mc":[{"id":"1.170370564","rc":[{"atl":[[1.8,0.52]],"id":8509691}],"con":true,"img":false}]}
{"op":"mcm","clk":"1362440760","pt":1588451277276,"mc":[{"id":"1.170370564","rc":[{"atb":[[1.78,3]],"id":8509691}],"con":true,"img":false}]}
{"op":"mcm","clk":"1362440764","pt":1588451277683,"mc":[{"id":"1.170370564","rc":[{"atb":[[1.17,0]],"id":8509691}],"con":true,"img":false}]}
{"op":"mcm","clk":"1362440786","pt":1588451280274,"mc":[{"id":"1.170370566","rc":[{"atb":[[1.01,0]],"id":9630572},{"atb":[[1.01,0]],"id":8509691}],"con":true,"img":false}]}
{"op":"mcm","clk":"1362440787","pt":1588451280376,"mc":[{"id":"1.170370564","rc":[{"atb":[[1.4,4.43]],"id":8509691}],"con":true,"img":false}]}
{"op":"mcm","clk":"1362440792","pt":1588451281087,"mc":[{"id":"1.170370564","rc":[{"trd":[[3.6,3.29]],"ltp":3.6,"tv":3.29,"id":9630572},{"atl":[[3.6,56.71]],"id":9630572},{"trd":[[1.38,304],[1.4,188.13],[1.78,6]],"ltp":1.38,"tv":498.13,"id":8509691},{"atb":[[1.78,0],[1.4,0]],"id":8509691}],"con":true,"img":false}]}
{"op":"mcm","clk":"1362440793","pt":1588451281290,"mc":[{"id":"1.170370564","rc":[{"atl":[[1.9,1.77]],"id":8509691}],"con":true,"img":false}]}
{"op":"mcm","clk":"1362440800","pt":1588451283682,"mc":[{"id":"1.170370567","rc":[{"atb":[[1.01,0],[1.05,0]],"id":9630572}],"con":true,"img":false}]}
{"op":"mcm","clk":"1362440801","pt":1588451284091,"mc":[{"id":"1.170370564","rc":[{"atb":[[1.01,3124.37]],"id":9630572},{"atb":[[1.01,3134.12]],"id":8509691}],"con":true,"img":false}]}
{"op":"mcm","clk":"1362440804","pt":1588451285012,"mc":[{"id":"1.170370564","rc":[{"atl":[[1.8,121.67]],"id":8509691}],"con":true,"img":false}]}
{"op":"mcm","clk":"1362440829","pt":1588451287914,"mc":[{"id":"1.170370564","rc":[{"atl":[[1.78,0.28]],"id":8509691}],"con":true,"img":false}]}
{"op":"mcm","clk":"1362440832","pt":1588451288422,"mc":[{"id":"1.170370564","rc":[{"atl":[[1.78,3.78]],"id":8509691}],"con":true,"img":false}]}
{"op":"mcm","clk":"1362440844","pt":1588451290302,"mc":[{"id":"1.170370564","rc":[{"atl":[[1.78,7.26]],"id":8509691}],"con":true,"img":false}]}
{"op":"mcm","clk":"1362440856","pt":1588451291522,"mc":[{"id":"1.170370564","rc":[{"atl":[[4,100]],"id":9630572}],"con":true,"img":false}]}
{"op":"mcm","clk":"1362440858","pt":1588451291928,"mc":[{"id":"1.170370564","rc":[{"atl":[[1.78,3.78]],"id":8509691}],"con":true,"img":false}]}
{"op":"mcm","clk":"1362440859","pt":1588451292233,"mc":[{"id":"1.170370564","rc":[{"atb":[[1.41,9.39]],"id":8509691}],"con":true,"img":false}]}
{"op":"mcm","clk":"1362440860","pt":1588451292385,"mc":[{"id":"1.170370564","rc":[{"atl":[[1.78,5.78]],"id":8509691}],"con":true,"img":false}]}
{"op":"mcm","clk":"1362440870","pt":1588451294827,"mc":[{"id":"1.170370564","rc":[{"atl":[[1.81,0],[1.78,7.9]],"id":8509691}],"con":true,"img":false}]}
{"op":"mcm","clk":"1362440873","pt":1588451295336,"mc":[{"id":"1.170370566","rc":[{"atl":[[5,5]],"id":9630572}],"con":true,"img":false}]}
{"op":"mcm","clk":"1362440875","pt":1588451297219,"mc":[{"id":"1.170370564","rc":[{"atl":[[1.75,3.53]],"id":8509691}],"con":true,"img":false}]}
{"op":"mcm","clk":"1362440877","pt":1588451297422,"mc":[{"id":"1.170370564","rc":[{"atl":[[1.8,121.14]],"id":8509691}],"con":true,"img":false}]}
{"op":"mcm","clk":"1362440878","pt":1588451297525,"mc":[{"id":"1.170370564","rc":[{"atl":[[1.78,11.9]],"id":8509691}],"con":true,"img":false}]}
{"op":"mcm","clk":"1362440879","pt":1588451297627,"mc":[{"id":"1.170370564","rc":[{"atl":[[4,0]],"id":9630572}],"con":true,"img":false}]}
{"op":"mcm","clk":"1362440886","pt":1588451299611,"mc":[{"id":"1.170370564","rc":[{"atl":[[1.78,13.66]],"id":8509691}],"con":true,"img":false}]}
{"op":"mcm","clk":"1362440887","pt":1588451299916,"mc":[{"id":"1.170370564","rc":[{"atl":[[1.76,91.48]],"id":8509691}],"con":true,"img":false}]}
{"op":"mcm","clk":"1362440895","pt":1588451303826,"mc":[{"id":"1.170370566","rc":[{"atl":[[5,0]],"id":9630572}],"con":true,"img":false}]}
{"op":"mcm","clk":"1362440896","pt":1588451305199,"mc":[{"id":"1.170370564","rc":[{"atl":[[1.78,9.66]],"id":8509691}],"con":true,"img":false}]}
{"op":"mcm","clk":"1362440899","pt":1588451308910,"mc":[{"id":"1.170370566","rc":[{"atl":[[7,5]],"id":9630572}],"con":true,"img":false}]}
{"op":"mcm","clk":"1362440901","pt":1588451309113,"mc":[{"id":"1.170370564","rc":[{"atl":[[1.74,177.3]],"id":8509691}],"con":true,"img":false}]}
{"op":"mcm","clk":"1362440902","pt":1588451309317,"mc":[{"id":"1.170370564","rc":[{"atl":[[1.75,0]],"id":8509691}],"con":true,"img":false}]}
{"op":"mcm","clk":"1362440905","pt":1588451310333,"mc":[{"id":"1.170370564","rc":[{"atl":[[1.67,4]],"id":8509691}],"con":true,"img":false}]}
{"op":"mcm","clk":"1362440913","pt":1588451314651,"mc":[{"id":"1.170370564","rc":[{"atl":[[1.72,0.52],[1.65,3.75]],"id":8509691}],"con":true,"img":false}]}
{"op":"mcm","clk":"1362440924","pt":1588451318411,"mc":[{"id":"1.170370564","rc":[{"atl":[[3.6,0]],"id":9630572}],"con":true,"img":false}]}
{"op":"mcm","clk":"1362440932","pt":1588451321157,"mc":[{"id":"1.170370564","rc":[{"atl":[[1.8,0]],"id":8509691}],"con":true,"img":false}]}
{"op":"mcm","clk":"1362440936","pt":1588451322325,"mc":[{"id":"1.170370564","rc":[{"atl":[[1.74,0]],"id":8509691}],"con":true,"img":false}]}
{"op":"mcm","clk":"1362440937","pt":1588451322528,"mc":[{"id":"1.170370564","rc":[{"trd":[[1.41,30.17]],"ltp":1.41,"tv":30.17,"id":8509691},{"atb":[[1.41,0.63]],"id":8509691}],"con":true,"img":false}]}
{"op":"mcm","clk":"1362440945","pt":1588451325530,"mc":[{"id":"1.170370564","rc":[{"atb":[[1.43,2]],"id":8509691}],"con":true,"img":false}]}
{"op":"mcm","clk":"1362440946","pt":1588451325937,"mc":[{"id":"1.170370564","rc":[{"atl":[[1.78,9.38]],"id":8509691}],"con":true,"img":false}]}
{"op":"mcm","clk":"1362440947","pt":1588451326343,"mc":[{"id":"1.170370564","rc":[{"atl":[[1.65,124.89]],"id":8509691}],"con":true,"img":false}]}
{"op":"mcm","clk":"1362440949","pt":1588451327257,"mc":[{"id":"1.170370564","rc":[{"atb":[[1.43,0]],"id":8509691}],"con":true,"img":false}]}
{"op":"mcm","clk":"1362440952","pt":1588451328121,"mc":[{"id":"1.170370564","rc":[{"atb":[[1.96,0]],"id":9630572}],"con":true,"img":false}]}
{"op":"mcm","clk":"1362440954","pt":1588451328628,"mc":[{"id":"1.170370564","rc":[{"atl":[[2.54,5]],"id":9630572}],"con":true,"img":false}]}
{"op":"mcm","clk":"1362440956","pt":1588451329034,"mc":[{"id":"1.170370564","rc":[{"atl":[[1.76,0]],"id":8509691}],"con":true,"img":false}]}
{"op":"mcm","clk":"1362440963","pt":1588451331169,"mc":[{"id":"1.170370564","rc":[{"atl":[[1.65,121.14]],"id":8509691}],"con":true,"img":false}]}
{"op":"mcm","clk":"1362440968","pt":1588451333760,"mc":[{"id":"1.170370564","rc":[{"atl":[[1.78,7.38]],"id":8509691}],"con":true,"img":false}]}
{"op":"mcm","clk":"1362440969","pt":1588451334167,"mc":[{"id":"1.170370564","rc":[{"atl":[[1.66,91.48]],"id":8509691}],"con":true,"img":false}]}
{"op":"mcm","clk":"1362440988","pt":1588451335438,"mc":[{"id":"1.170370564","rc":[{"trd":[[2.54,5]],"ltp":2.54,"tv":5.0,"id":9630572},{"atl":[[2.54,0]],"id":9630572},{"trd":[[1.64,7.74]],"ltp":1.64,"tv":7.74,"id":8509691},{"atl":[[1.64,169.55]],"id":8509691}],"con":true,"img":false}]}
{"op":"mcm","clk":"1362440992","pt":1588451336353,"mc":[{"id":"1.170370564","rc":[{"atl":[[1.64,173.33]],"id":8509691}],"con":true,"img":false}]}
{"op":"mcm","clk":"1362441004","pt":1588451337526,"mc":[{"id":"1.170370564","rc":[{"trd":[[1.28,6762.07],[1.41,31.44]],"ltp":1.28,"tv":6793.5,"id":8509691},{"atb":[[1.28,62.8],[1.41,0]],"id":8509691}],"con":true,"img":false}]}
{"op":"mcm","clk":"1362441006","pt":1588451338134,"mc":[{"id":"1.170370564","rc":[{"atl":[[1.72,0]],"id":8509691}],"con":true,"img":false}]}
{"op":"mcm","clk":"1362441010","pt":1588451339760,"mc":[{"id":"1.170370564","rc":[{"atl":[[1.64,169.55]],"id":8509691}],"con":true,"img":false}]}
{"op":"mcm","clk":"1362441011","pt":1588451340471,"mc":[{"id":"1.170370564","rc":[{"atl":[[1.66,0]],"id":8509691}],"con":true,"img":false}]}
{"op":"mcm","clk":"1362441012","pt":1588451340675,"mc":[{"id":"1.170370564","rc":[{"atl":[[1.65,130.16]],"id":8509691}],"con":true,"img":false}]}
{"op":"mcm","clk":"1362441014","pt":1588451341031,"mc":[{"id":"1.170370564","rc":[{"atb":[[2.44,5.2]],"id":9630572}],"con":true,"img":false}]}
{"op":"mcm","clk":"1362441015","pt":1588451341540,"mc":[{"id":"1.170370564","rc":[{"atl":[[1.63,19.99]],"id":8509691}],"con":true,"img":false}]}
{"op":"mcm","clk":"1362441016","pt":1588451341744,"mc":[{"id":"1.170370564","rc":[{"atl":[[1.64,0.28],[1.78,5.62]],"id":8509691}],"con":true,"img":false}]}
{"op":"mcm","clk":"1362441025","pt":1588451344243,"mc":[{"id":"1.170370564","rc":[{"atl":[[1.64,0.56]],"id":8509691}],"con":true,"img":false}]}
{"op":"mcm","clk":"1362441027","pt":1588451344958,"mc":[{"id":"1.170370564","rc":[{"atl":[[1.56,3.96]],"id":8509691}],"con":true,"img":false}]}
{"op":"mcm","clk":"1362441028","pt":1588451345365,"mc":[{"id":"1.170370564","rc":[{"atl":[[1.6,0.24]],"id":8509691}],"con":true,"img":false}]}
{"op":"mcm","clk":"1362441030","pt":1588451345569,"mc":[{"id":"1.170370564","rc":[{"atl":[[1.63,111.47]],"id":8509691}],"con":true,"img":false}]}
{"op":"mcm","clk":"1362441033","pt":1588451345874,"mc":[{"id":"1.170370564","rc":[{"atl":[[1.64,2.2]],"id":8509691}],"con":true,"img":false}]}
{"op":"mcm","clk":"1362441035","pt":1588451347044,"mc":[{"id":"1.170370564","rc":[{"atl":[[1.65,9.01]],"id":8509691}],"con":true,"img":false}]}
{"op":"mcm","clk":"1362441037","pt":1588451347857,"mc":[{"id":"1.170370564","rc":[{"atl":[[1.65,0]],"id":8509691}],"con":true,"img":false}]}
{"op":"mcm","clk":"1362441039","pt":1588451349381,"mc":[{"id":"1.170370564","rc":[{"atl":[[1.63,91.48]],"id":8509691}],"con":true,"img":false}]}
{"op":"mcm","clk":"1362441044","pt":1588451351869,"mc":[{"id":"1.170370564","rc":[{"atl":[[1.64,3.21]],"id":8509691}],"con":true,"img":false}]}
{"op":"mcm","clk":"1362441052","pt":1588451352280,"mc":[{"id":"1.170370564","rc":[{"atl":[[1.59,125.95]],"id":8509691}],"con":true,"img":false}]}
{"op":"mcm","clk":"1362441061","pt":1588451352942,"mc":[{"id":"1.170370564","rc":[{"atl":[[1.62,9.01]],"id":8509691}],"con":true,"img":false}]}
{"op":"mcm","clk":"1362441097","pt":1588451356147,"mc":[{"id":"1.170370564","rc":[{"atb":[[1.3,8.86]],"id":8509691}],"con":true,"img":false}]}
{"op":"mcm","clk":"1362441101","pt":1588451357063,"mc":[{"id":"1.170370564","rc":[{"atl":[[1.63,101.48]],"id":8509691}],"con":true,"img":false}]}
{"op":"mcm","clk":"1362441846","pt":1588451362259,"mc":[{"id":"1.170370564","rc":[{"atl":[[3,3.54]],"id":9630572}],"con":true,"img":false}]}
{"op":"mcm","clk":"1362441859","pt":1588451365057,"mc":[{"id":"1.170370564","rc":[{"atl":[[1.56,0]],"id":8509691}],"con":true,"img":false}]}
{"op":"mcm","clk":"1362441864","pt":1588451366482,"mc":[{"id":"1.170370564","rc":[{"atl":[[1.63,10]],"id":8509691}],"con":true,"img":false}]}
{"op":"mcm","clk":"1362441870","pt":1588451370293,"mc":[{"id":"1.170370564","rc":[{"trd":[[3,15.4]],"ltp":3.0,"tv":15.4,"id":9630572},{"atl":[[3,1.48]],"id":9630572},{"trd":[[1.5,30.81]],"ltp":1.5,"tv":30.81,"id":8509691}],"con":true,"img":false}]}
{"op":"mcm","clk":"1362441872","pt":1588451371563,"mc":[{"id":"1.170370564","rc":[{"atl":[[1.55,91.48]],"id":8509691}],"con":true,"img":false}]}
{"op":"mcm","clk":"1362441873","pt":1588451371868,"mc":[{"id":"1.170370564","rc":[{"trd":[[3,16.88]],"ltp":3.0,"tv":16.88,"id":9630572},{"atl":[[3,0]],"id":9630572},{"trd":[[1.5,33.77]],"ltp":1.5,"tv":33.77,"id":8509691},{"atl":[[1.5,1.04]],"id":8509691}],"con":true,"img":false}]}
{"op":"mcm","clk":"1362441875","pt":1588451373394,"mc":[{"id":"1.170370564","rc":[{"atl":[[1.6,0]],"id":8509691}],"con":true,"img":false}]}
{"op":"mcm","clk":"1362441880","pt":1588451374562,"mc":[{"id":"1.170370564","rc":[{"atl":[[1.5,3.04]],"id":8509691}],"con":true,"img":false}]}
{"op":"mcm","clk":"1362441881","pt":1588451375069,"mc":[{"id":"1.170370564","rc":[{"atl":[[1.59,0]],"id":8509691}],"con":true,"img":false}]}
{"op":"mcm","clk":"1362441883","pt":1588451375375,"mc":[{"id":"1.170370564","rc":[{"atl":[[1.62,0]],"id":8509691}],"con":true,"img":false}]}
{"op":"mcm","clk":"1362441886","pt":1588451376087,"mc":[{"id":"1.170370564","rc":[{"atl":[[1.63,0]],"id":8509691}],"con":true,"img":false}]}
{"op":"mcm","clk":"1362441889","pt":1588451376899,"mc":[{"id":"1.170370566","rc":[{"atb":[[2,88.65]],"id":8509691}],"con":true,"img":false}]}
{"op":"mcm","clk":"1362441891","pt":1588451378677,"mc":[{"id":"1.170370564","rc":[{"atb":[[1.32,4.43]],"id":8509691}],"con":true,"img":false}]}
{"op":"mcm","clk":"1362441894","pt":1588451379897,"mc":[{"id":"1.170370564","rc":[{"atb":[[1.17,5.59]],"id":8509691}],"con":true,"img":false}]}
{"op":"mcm","clk":"1362441895","pt":1588451380201,"mc":[{"id":"1.170370564","rc":[{"atl":[[1.53,130.76]],"id":8509691}],"con":true,"img":false}]}
{"op":"mcm","clk":"1362441897","pt":1588451380506,"mc":[{"id":"1.170370564","rc":[{"atl":[[1.5,12.05]],"id":8509691}],"con":true,"img":false}]}
{"op":"mcm","clk":"1362441900","pt":1588451381166,"mc":[{"id":"1.170370564","rc":[{"atl":[[1.58,10]],"id":8509691}],"con":true,"img":false}]}
{"op":"mcm","clk":"1362441909","pt":1588451382896,"mc":[{"id":"1.170370564","rc":[{"atl":[[1.5,17.65]],"id":8509691}],"con":true,"img":false}]}
{"op":"mcm","clk":"1362441927","pt":1588451387014,"mc":[{"id":"1.170370564","rc":[{"atl":[[1.58,0]],"id":8509691}],"con":true,"img":false}]}
{"op":"mcm","clk":"1362441931","pt":1588451387421,"mc":[{"id":"1.170370564","rc":[{"atl":[[1.49,5.59]],"id":8509691}],"con":true,"img":false}]}
{"op":"mcm","clk":"1362441962","pt":1588451390826,"mc":[{"id":"1.170370564","rc":[{"atl":[[1.64,12.07]],"id":8509691}],"con":true,"img":false}]}
{"op":"mcm","clk":"1362441971","pt":1588451392810,"mc":[{"id":"1.170370564","rc":[{"atl":[[1.5,27.65]],"id":8509691}],"con":true,"img":false}]}
{"op":"mcm","clk":"1362441976","pt":1588451393116,"mc":[{"id":"1.170370564","rc":[{"atb":[[1.2,2627.67]],"id":8509691}],"con":true,"img":false}]}
{"op":"mcm","clk":"1362441984","pt":1588451393826,"mc":[{"id":"1.170370564","rc":[{"atl":[[1.49,11.19]],"id":8509691}],"con":true,"img":false}]}
{"op":"mcm","clk":"1362441995","pt":1588451394945,"mc":[{"id":"1.170370564","rc":[{"atl":[[1.65,1.99]],"id":8509691}],"con":true,"img":false}]}
{"op":"mcm","clk":"1362442000","pt":1588451395354,"mc":[{"id":"1.170370564","rc":[{"atl":[[1.52,26.39]],"id":8509691}],"con":true,"img":false}]}
{"op":"mcm","clk":"1362442006","pt":1588451396626,"mc":[{"id":"1.170370564","rc":[{"atl":[[1.64,3.21]],"id":8509691}],"con":true,"img":false}]}
{"op":"mcm","clk":"1362442008","pt":1588451398052,"mc":[{"id":"1.170370564","rc":[{"atl":[[1.5,27.91]],"id":8509691}],"con":true,"img":false}]}
{"op":"mcm","clk":"1362442011","pt":1588451398306,"mc":[{"id":"1.170370564","rc":[{"atb":[[3,10]],"id":9630572}],"con":true,"img":false}]}
{"op":"mcm","clk":"1362442035","pt":1588451404260,"mc":[{"id":"1.170370564","rc":[{"atl":[[1.53,0]],"id":8509691}],"con":true,"img":false}]}
{"op":"mcm","clk":"1362442038","pt":1588451405524,"mc":[{"id":"1.170370564","rc":[{"atl":[[1.44,0.24]],"id":8509691}],"con":true,"img":false}]}
{"op":"mcm","clk":"1362442045","pt":1588451409443,"mc":[{"id":"1.170370564","rc":[{"atl":[[1.49,155.08]],"id":8509691}],"con":true,"img":false}]}
{"op":"mcm","clk":"1362442046","pt":1588451409951,"mc":[{"id":"1.170370564","rc":[{"atl":[[1.62,0.87]],"id":8509691}],"con":true,"img":false}]}
{"op":"mcm","clk":"1362442055","pt":1588451412140,"mc":[{"id":"1.170370564","rc":[{"atl":[[1.5,18.89]],"id":8509691}],"con":true,"img":false}]}
{"op":"mcm","clk":"1362442060","pt":1588451412445,"mc":[{"id":"1.170370564","rc":[{"atl":[[1.5,16.89]],"id":8509691}],"con":true,"img":false}]}
{"op":"mcm","clk":"1362442082","pt":1588451416161,"mc":[{"id":"1.170370564","rc":[{"atl":[[1.55,0]],"id":8509691}],"con":true,"img":false}]}
{"op":"mcm","clk":"1362442088","pt":1588451417233,"mc":[{"id":"1.170370564","rc":[{"atl":[[1.47,9.01]],"id":8509691}],"con":true,"img":false}]}
{"op":"mcm","clk":"1362442093","pt":1588451417844,"mc":[{"id":"1.170370564","rc":[{"atb":[[1.17,0]],"id":8509691}],"con":true,"img":false}]}
{"op":"mcm","clk":"1362442102","pt":1588451420038,"mc":[{"id":"1.170370564","rc":[{"atl":[[1.49,143.88]],"id":8509691}],"con":true,"img":false}]}
{"op":"mcm","clk":"1362442103","pt":1588451420345,"mc":[{"id":"1.170370564","rc":[{"atl":[[1.5,11.29]],"id":8509691}],"con":true,"img":false}]}
{"op":"mcm","clk":"1362442112","pt":1588451421263,"mc":[{"id":"1.170370564","rc":[{"atl":[[1.45,91.48]],"id":8509691}],"con":true,"img":false}]}
{"op":"mcm","clk":"1362442117","pt":1588451421827,"mc":[{"id":"1.170370564","rc":[{"atb":[[1.21,5.59]],"id":8509691}],"con":true,"img":false}]}
{"op":"mcm","clk":"1362442152","pt":1588451426158,"mc":[{"id":"1.170370564","rc":[{"trd":[[1.32,1393.5]],"ltp":1.32,"tv":1393.5,"id":8509691},{"atb":[[1.32,1.38]],"id":8509691}],"con":true,"img":false}]}
{"op":"mcm","clk":"1362442172","pt":1588451429980,"mc":[{"id":"1.170370564","rc":[{"atl":[[1.47,0]],"id":8509691}],"con":true,"img":false}]}
{"op":"mcm","clk":"1362442173","pt":1588451430033,"mc":[{"id":"1.170370564","rc":[{"atl":[[1.43,88.65]],"id":8509691}],"con":true,"img":false}]}
{"op":"mcm","clk":"1362442185","pt":1588451435078,"mc":[{"id":"1.170370564","rc":[{"atl":[[1.42,9.01]],"id":8509691}],"con":true,"img":false}]}
{"op":"mcm","clk":"1362442187","pt":1588451435281,"mc":[{"id":"1.170370564","rc":[{"trd":[[1.42,12.26]],"ltp":1.42,"tv":12.26,"id":8509691},{"atl":[[1.42,2.88]],"id":8509691}],"con":true,"img":false}]}
{"op":"mcm","clk":"1362442188","pt":1588451435434,"mc":[{"id":"1.170370564","rc":[{"atl":[[4,100]],"id":9630572}],"con":true,"img":false}]}
{"op":"mcm","clk":"1362442203","pt":1588451440372,"mc":[{"id":"1.170370564","rc":[{"atl":[[1.41,31.7]],"id":8509691}],"con":true,"img":false}]}
{"op":"mcm","clk":"1362442205","pt":1588451440677,"mc":[{"id":"1.170370564","rc":[{"atb":[[1.32,0]],"id":8509691}],"con":true,"img":false}]}
{"op":"mcm","clk":"1362442209","pt":1588451441949,"mc":[{"id":"1.170370564","rc":[{"atb":[[1.3,0]],"id":8509691}],"con":true,"img":false}]}
{"op":"mcm","clk":"1362442213","pt":1588451442559,"mc":[{"id":"1.170370564","rc":[{"atl":[[1.45,0]],"id":8509691}],"con":true,"img":false}]}
{"op":"mcm","clk":"1362442215","pt":1588451442865,"mc":[{"id":"1.170370564","rc":[{"atb":[[1.35,88.65]],"id":8509691}],"con":true,"img":false}]}
{"op":"mcm","clk":"1362442217","pt":1588451443271,"mc":[{"id":"1.170370564","rc":[{"atl":[[1.49,0]],"id":8509691}],"con":true,"img":false}]}
{"op":"mcm","clk":"1362442229","pt":1588451445662,"mc":[{"id":"1.170370564","rc":[{"atl":[[1.43,0]],"id":8509691}],"con":true,"img":false}]}
{"op":"mcm","clk":"1362442232","pt":1588451445865,"mc":[{"id":"1.170370564","rc":[{"atl":[[1.4,2.87]],"id":8509691}],"con":true,"img":false}]}
{"op":"mcm","clk":"1362442237","pt":1588451446985,"mc":[{"id":"1.170370564","rc":[{"atl":[[1.52,0]],"id":8509691}],"con":true,"img":false}]}
{"op":"mcm","clk":"1362442239","pt":1588451447087,"mc":[{"id":"1.170370564","rc":[{"atb":[[1.34,8.86]],"id":8509691}],"con":true,"img":false}]}
{"op":"mcm","clk":"1362442244","pt":1588451447645,"mc":[{"id":"1.170370564","rc":[{"atl":[[1.42,94.36]],"id":8509691}],"con":true,"img":false}]}
{"op":"mcm","clk":"1362442248","pt":1588451448562,"mc":[{"id":"1.170370564","rc":[{"atl":[[1.5,1.29]],"id":8509691}],"con":true,"img":false}]}
{"op":"mcm","clk":"1362442267","pt":1588451451262,"mc":[{"id":"1.170370564","rc":[{"atb":[[1.34,0]],"id":8509691}],"con":true,"img":false}]}
{"op":"mcm","clk":"1362442307","pt":1588451455181,"mc":[{"id":"1.170370564","rc":[{"trd":[[1.35,1073.85]],"ltp":1.35,"tv":1073.85,"id":8509691},{"atb":[[1.35,0]],"id":8509691},{"atl":[[1.35,8.44]],"id":8509691}],"con":true,"img":false}]}
{"op":"mcm","clk":"1362442309","pt":1588451455283,"mc":[{"id":"1.170370565","rc":[{"atb":[[1.82,16.61]],"id":11269555}],"con":true,"img":false}]}
{"op":"mcm","clk":"1362442314","pt":1588451455487,"mc":[{"id":"1.170370564","rc":[{"atb":[[1.34,9.01]],"id":8509691}],"con":true,"img":false}]}
{"op":"mcm","clk":"1362442318","pt":1588451456351,"mc":[{"id":"1.170370564","rc":[{"trd":[[1.35,1090.73]],"ltp":1.35,"tv":1090.73,"id":8509691},{"atb":[[1.36,0.42]],"id":8509691},{"atl":[[1.35,0]],"id":8509691}],"con":true,"img":false}]}
{"op":"mcm","clk":"1362442327","pt":1588451457978,"mc":[{"id":"1.170370564","rc":[{"trd":[[1.36,47.98]],"ltp":1.36,"tv":47.98,"id":8509691},{"atb":[[1.36,0]],"id":8509691},{"atl":[[1.35,3.57]],"id":8509691}],"con":true,"img":false}]}
{"op":"mcm","clk":"1362442343","pt":1588451459199,"mc":[{"id":"1.170370564","rc":[{"trd":[[1.4,193.35],[1.35,1097.87]],"ltp":1.4,"tv":1291.21,"id":8509691},{"atl":[[1.35,0],[1.4,0.26]],"id":8509691}],"con":true,"img":false}]}
{"op":"mcm","clk":"1362442363","pt":1588451461588,"mc":[{"id":"1.170370567","rc":[{"atb":[[1.05,79.98]],"id":9630572}],"con":true,"img":false}]}
{"op":"mcm","clk":"1362442402","pt":1588451467411,"mc":[{"id":"1.170370564","rc":[{"atl":[[1.4,0]],"id":8509691}],"con":true,"img":false}]}
{"op":"mcm","clk":"1362442424","pt":1588451470107,"mc":[{"id":"1.170370564","rc":[{"trd":[[1.34,157.92]],"ltp":1.34,"tv":157.92,"id":8509691},{"atb":[[1.2,0],[1.34,5.01]],"id":8509691}],"con":true,"img":false}]}
{"op":"mcm","clk":"1362442427","pt":1588451470208,"mc":[{"id":"1.170370564","rc":[{"atl":[[1.78,2.11]],"id":8509691}],"con":true,"img":false}]}
{"op":"mcm","clk":"1362442440","pt":1588451471988,"mc":[{"id":"1.170370564","rc":[{"trd":[[4,70.22]],"ltp":4.0,"tv":70.22,"id":9630572},{"atl":[[4,92.5]],"id":9630572},{"trd":[[1.33,770.6],[1.34,167.96]],"ltp":1.33,"tv":938.56,"id":8509691},{"atb":[[1.34,0]],"id":8509691}],"con":true,"img":false}]}
{"op":"mcm","clk":"1362442442","pt":1588451472090,"mc":[{"id":"1.170370564","rc":[{"trd":[[1.41,36.57]],"ltp":1.41,"tv":36.57,"id":8509691},{"atl":[[1.41,29.14]],"id":8509691}],"con":true,"img":false}]}
{"op":"mcm","clk":"1362442445","pt":1588451472598,"mc":[{"id":"1.170370564","rc":[{"atl":[[1000,1.77]],"id":8509691}],"con":true,"img":false}]}
{"op":"mcm","clk":"1362442446","pt":1588451472801,"mc":[{"id":"1.170370566","rc":[{"atb":[[1.01,79.98]],"id":9630572}],"con":true,"img":false}]}
{"op":"mcm","clk":"1362442449","pt":1588451473004,"mc":[{"id":"1.170370564","rc":[{"atl":[[1000,0.27]],"id":8509691}],"con":true,"img":false}]}
{"op":"mcm","clk":"1362442451","pt":1588451473310,"mc":[{"id":"1.170370564","rc":[{"atl":[[1000,0]],"id":8509691}],"con":true,"img":false}]}
{"op":"mcm","clk":"1362442460","pt":1588451474581,"mc":[{"id":"1.170370564","rc":[{"atb":[[1.21,0]],"id":8509691}],"con":true,"img":false}]}
{"op":"mcm","clk":"1362442466","pt":1588451475395,"mc":[{"id":"1.170370564","rc":[{"atb":[[1.28,0]],"id":8509691}],"con":true,"img":false}]}
{"op":"mcm","clk":"1362442468","pt":1588451475599,"mc":[{"id":"1.170370564","rc":[{"atb":[[1.35,72.69]],"id":8509691}],"con":true,"img":false}]}
{"op":"mcm","clk":"1362442473","pt":1588451476515,"mc":[{"id":"1.170370564","rc":[{"trd":[[1.41,36.77],[1.35,1146.33]],"ltp":1.41,"tv":1183.1,"id":8509691},{"atb":[[1.35,48.46]],"id":8509691},{"atl":[[1.41,29.04]],"id":8509691}],"con":true,"img":false}]}
{"op":"mcm","clk":"1362442493","pt":1588451478399,"mc":[{"id":"1.170370564","rc":[{"trd":[[1.35,1146.88]],"ltp":1.35,"tv":1146.88,"id":8509691},{"atb":[[1.35,48.19]],"id":8509691}],"con":true,"img":false}]}
{"op":"mcm","clk":"1362442509","pt":1588451480487,"mc":[{"id":"1.170370564","rc":[{"trd":[[1.41,37.02]],"ltp":1.41,"tv":37.02,"id":8509691},{"atl":[[1.41,28.91]],"id":8509691}],"con":true,"img":false}]}
{"op":"mcm","clk":"1362442510","pt":1588451480793,"mc":[{"id":"1.170370564","rc":[{"trd":[[1.41,37.06]],"ltp":1.41,"tv":37.06,"id":8509691},{"atl":[[1.41,28.89]],"id":8509691}],"con":true,"img":false}]}
{"op":"mcm","clk":"1362442520","pt":1588451482015,"mc":[{"id":"1.170370564","rc":[{"atl":[[1.42,91.48]],"id":8509691}],"con":true,"img":false}]}
{"op":"mcm","clk":"1362442524","pt":1588451482219,"mc":[{"id":"1.170370564","rc":[{"atl":[[1.41,0]],"id":8509691}],"con":true,"img":false}]}
{"op":"mcm","clk":"1362442527","pt":1588451482780,"mc":[{"id":"1.170370564","rc":[{"atb":[[1.39,3]],"id":8509691}],"con":true,"img":false}]}
{"op":"mcm","clk":"1362442531","pt":1588451483288,"mc":[{"id":"1.170370564","rc":[{"atl":[[1.4,5.59]],"id":8509691}],"con":true,"img":false}]}
{"op":"mcm","clk":"1362442540","pt":1588451484406,"mc":[{"id":"1.170370564","rc":[{"trd":[[1.4,201.82]],"ltp":1.4,"tv":201.82,"id":8509691},{"atl":[[1.4,1.35]],"id":8509691}],"con":true,"img":false}]}
{"op":"mcm","clk":"1362442542","pt":1588451484609,"mc":[{"id":"1.170370564","rc":[{"trd":[[1.4,204.18]],"ltp":1.4,"tv":204.18,"id":8509691},{"atl":[[1.4,0.18]],"id":8509691}],"con":true,"img":false}]}
{"op":"mcm","clk":"1362442546","pt":1588451485220,"mc":[{"id":"1.170370564","rc":[{"atb":[[1.37,7.09]],"id":8509691}],"con":true,"img":false}]}
{"op":"mcm","clk":"1362442557","pt":1588451486492,"mc":[{"id":"1.170370564","rc":[{"atl":[[1.4,5.78]],"id":8509691}],"con":true,"img":false}]}
{"op":"mcm","clk":"1362442563","pt":1588451487104,"mc":[{"id":"1.170370564","rc":[{"atl":[[1.4,8.67]],"id":8509691}],"con":true,"img":false}]}
{"op":"mcm","clk":"1362442564","pt":1588451487308,"mc":[{"id":"1.170370564","rc":[{"atl":[[1.4,2.88]],"id":8509691}],"con":true,"img":false}]}
{"op":"mcm","clk":"1362442568","pt":1588451487919,"mc":[{"id":"1.170370564","rc":[{"atl":[[1.4,8.48]],"id":8509691}],"con":true,"img":false}]}
{"op":"mcm","clk":"1362442584","pt":1588451490310,"mc":[{"id":"1.170370564","rc":[{"atl":[[1.4,2.88]],"id":8509691}],"con":true,"img":false}]}
{"op":"mcm","clk":"1362442586","pt":1588451490615,"mc":[{"id":"1.170370564","rc":[{"atl":[[1.42,0]],"id":8509691}],"con":true,"img":false}]}
{"op":"mcm","clk":"1362442607","pt":1588451494125,"mc":[{"id":"1.170370564","rc":[{"atl":[[1.44,0]],"id":8509691}],"con":true,"img":false}]}
{"op":"mcm","clk":"1362442618","pt":1588451495699,"mc":[{"id":"1.170370564","rc":[{"trd":[[1.39,50.33]],"ltp":1.39,"tv":50.33,"id":8509691},{"atb":[[1.39,0]],"id":8509691},{"atl":[[1.39,88.48]],"id":8509691}],"con":true,"img":false}]}
{"op":"mcm","clk":"1362442623","pt":1588451496412,"mc":[{"id":"1.170370564","rc":[{"trd":[[3,37.53],[3.5,44.96],[3.55,51.99]],"ltp":3.0,"tv":134.48,"id":9630572},{"atb":[[3,0]],"id":9630572},{"atl":[[3,840.07]],"id":9630572},{"trd":[[1.5,35.06],[1.4,207.07],[1.39,138.81]],"ltp":1.5,"tv":380.94,"id":8509691},{"atl":[[1.39,0],[1.4,0],[1.5,0]],"id":8509691}],"con":true,"img":false}]}
{"op":"mcm","clk":"1362442659","pt":1588451502520,"mc":[{"id":"1.170370564","rc":[{"atl":[[2.88,213.65]],"id":9630572}],"con":true,"img":false}]}
{"op":"mcm","clk":"1362442661","pt":1588451502927,"mc":[{"id":"1.170370564","rc":[{"atb":[[1.51,88.65]],"id":8509691}],"con":true,"img":false}]}
{"op":"mcm","clk":"1362442666","pt":1588451503334,"mc":[{"id":"1.170370565","rc":[{"atb":[[1.82,0]],"id":11269555}],"con":true,"img":false}]}
{"op":"mcm","clk":"1362442668","pt":1588451503539,"mc":[{"id":"1.170370564","rc":[{"atb":[[1.52,88.65]],"id":8509691}],"con":true,"img":false}]}
{"op":"mcm","clk":"1362442682","pt":1588451505015,"mc":[{"id":"1.170370564","rc":[{"atb":[[1.4,0.23]],"id":8509691}],"con":true,"img":false}]}
{"op":"mcm","clk":"1362442690","pt":1588451506440,"mc":[{"id":"1.170370564","rc":[{"atb":[[1.51,0]],"id":8509691}],"con":true,"img":false}]}
{"op":"mcm","clk":"1362442702","pt":1588451507508,"mc":[{"id":"1.170370564","rc":[{"atb":[[1.52,0]],"id":8509691}],"con":true,"img":false}]}
{"op":"mcm","clk":"1362442708","pt":1588451508726,"mc":[{"id":"1.170370564","rc":[{"atb":[[1.54,88.65]],"id":8509691}],"con":true,"img":false}]}
{"op":"mcm","clk":"1362442711","pt":1588451509234,"mc":[{"id":"1.170370564","rc":[{"atl":[[2.88,0]],"id":9630572},{"atb":[[1.55,88.65]],"id":8509691}],"con":true,"img":false}]}
{"op":"mcm","clk":"1362442716","pt":1588451509842,"mc":[{"id":"1.170370564","rc":[{"atb":[[1.56,88.65]],"id":8509691}],"con":true,"img":false}]}
{"op":"mcm","clk":"1362442723","pt":1588451510808,"mc":[{"id":"1.170370564","rc":[{"atb":[[1.4,0]],"id":8509691}],"con":true,"img":false}]}
{"op":"mcm","clk":"1362442730","pt":1588451511318,"mc":[{"id":"1.170370564","rc":[{"atb":[[1.35,0]],"id":8509691}],"con":true,"img":false}]}
{"op":"mcm","clk":"1362442733","pt":1588451511419,"mc":[{"id":"1.170370564","rc":[{"atb":[[1.54,0]],"id":8509691}],"con":true,"img":false}]}
{"op":"mcm","clk":"1362442737","pt":1588451511724,"mc":[{"id":"1.170370564","rc":[{"atl":[[1.61,9.01]],"id":8509691}],"con":true,"img":false}]}
{"op":"mcm","clk":"1362442745","pt":1588451512945,"mc":[{"id":"1.170370564","rc":[{"atb":[[2.56,10]],"id":9630572}],"con":true,"img":false}]}
{"op":"mcm","clk":"1362442752","pt":1588451514318,"mc":[{"id":"1.170370564","rc":[{"trd":[[2.44,10.4],[2.48,6.05],[2.56,22.05],[2.6,0.54],[2.52,1.31],[2.62,5.54]],"ltp":2.44,"tv":45.89,"id":9630572},{"atb":[[2.56,0],[2.44,0]],"id":9630572},{"atl":[[2.42,186.3]],"id":9630572},{"trd":[[1.67,25.72],[1.65,23.27],[1.61,9.01],[1.62,0.87],[1.64,10.96]],"ltp":1.67,"tv":69.83,"id":8509691},{"atl":[[1.64,0],[1.67,0],[1.62,0],[1.65,0],[1.61,0]],"id":8509691}],"con":true,"img":false}]}
{"op":"mcm","clk":"1362442761","pt":1588451515639,"mc":[{"id":"1.170370564","rc":[{"trd":[[2.42,5.24]],"ltp":2.42,"tv":5.24,"id":9630572},{"atl":[[2.42,184.29]],"id":9630572}],"con":true,"img":false}]}
{"op":"mcm","clk":"1362442776","pt":1588451517931,"mc":[{"id":"1.170370564","rc":[{"trd":[[2.42,5.42]],"ltp":2.42,"tv":5.42,"id":9630572},{"atl":[[2.42,184.12]],"id":9630572},{"trd":[[1.7,2.01]],"ltp":1.7,"tv":2.01,"id":8509691}],"con":true,"img":false}]}
{"op":"mcm","clk":"1362442783","pt":1588451518948,"mc":[{"id":"1.170370566","rc":[{"atb":[[1.01,0]],"id":9630572}],"con":true,"img":false}]}
{"op":"mcm","clk":"1362442786","pt":1588451519356,"mc":[{"id":"1.170370564","rc":[{"atl":[[1.85,0],[1.9,0]],"id":8509691}],"con":true,"img":false}]}
{"op":"mcm","clk":"1362442801","pt":1588451521749,"mc":[{"id":"1.170370567","rc":[{"atb":[[1.05,0]],"id":9630572}],"con":true,"img":false}]}
{"op":"mcm","clk":"1362442814","pt":1588451524460,"mc":[{"id":"1.170370564","rc":[{"trd":[[2.42,57.45]],"ltp":2.42,"tv":57.45,"id":9630572},{"atl":[[2.42,132.09]],"id":9630572},{"trd":[[1.7,76.08]],"ltp":1.7,"tv":76.08,"id":8509691}],"con":true,"img":false}]}
{"op":"mcm","clk":"1362442816","pt":1588451524562,"mc":[{"id":"1.170370564","rc":[{"trd":[[2.42,64.47]],"ltp":2.42,"tv":64.47,"id":9630572},{"atl":[[2.42,125.07]],"id":9630572},{"trd":[[1.7,86.08]],"ltp":1.7,"tv":86.08,"id":8509691}],"con":true,"img":false}]}
{"op":"mcm","clk":"1362442825","pt":1588451525941,"mc":[{"id":"1.170370564","rc":[{"trd":[[2.42,66.22]],"ltp":2.42,"tv":66.22,"id":9630572},{"atl":[[2.42,123.31]],"id":9630572},{"trd":[[1.7,88.58]],"ltp":1.7,"tv":88.58,"id":8509691}],"con":true,"img":false}]}
{"op":"mcm","clk":"1362442833","pt":1588451526960,"mc":[{"id":"1.170370564","rc":[{"atb":[[1.57,40.78]],"id":8509691}],"con":true,"img":false}]}
{"op":"mcm","clk":"1362442835","pt":1588451527165,"mc":[{"id":"1.170370564","rc":[{"trd":[[2.42,69.2]],"ltp":2.42,"tv":69.2,"id":9630572},{"atl":[[2.42,120.33]],"id":9630572},{"trd":[[1.7,92.82]],"ltp":1.7,"tv":92.82,"id":8509691}],"con":true,"img":false}]}
{"op":"mcm","clk":"1362442841","pt":1588451527928,"mc":[{"id":"1.170370564","rc":[{"trd":[[2.42,73.14]],"ltp":2.42,"tv":73.14,"id":9630572},{"atl":[[2.42,116.4]],"id":9630572},{"trd":[[1.7,98.42]],"ltp":1.7,"tv":98.42,"id":8509691}],"con":true,"img":false}]}
{"op":"mcm","clk":"1362442848","pt":1588451528335,"mc":[{"id":"1.170370564","rc":[{"trd":[[2.42,73.21]],"ltp":2.42,"tv":73.21,"id":9630572},{"atl":[[2.42,116.32]],"id":9630572},{"trd":[[1.7,98.52]],"ltp":1.7,"tv":98.52,"id":8509691}],"con":true,"img":false}]}
{"op":"mcm","clk":"1362442855","pt":1588451528844,"mc":[{"id":"1.170370564","rc":[{"atb":[[2,5]],"id":9630572}],"con":true,"img":false}]}
{"op":"mcm","clk":"1362442864","pt":1588451530420,"mc":[{"id":"1.170370564","rc":[{"trd":[[2.42,73.58]],"ltp":2.42,"tv":73.58,"id":9630572},{"atl":[[2.42,115.95]],"id":9630572},{"trd":[[1.7,99.05]],"ltp":1.7,"tv":99.05,"id":8509691}],"con":true,"img":false}]}
{"op":"mcm","clk":"1362442870","pt":1588451531438,"mc":[{"id":"1.170370564","rc":[{"trd":[[2.42,84.12]],"ltp":2.42,"tv":84.12,"id":9630572},{"atl":[[2.42,105.41]],"id":9630572},{"trd":[[1.7,114.05]],"ltp":1.7,"tv":114.05,"id":8509691}],"con":true,"img":false}]}
{"op":"mcm","clk":"1362442877","pt":1588451531947,"mc":[{"id":"1.170370564","rc":[{"trd":[[2.42,115.46]],"ltp":2.42,"tv":115.46,"id":9630572},{"atl":[[2.42,74.07]],"id":9630572},{"trd":[[1.7,158.66]],"ltp":1.7,"tv":158.66,"id":8509691}],"con":true,"img":false}]}
{"op":"mcm","clk":"1362442878","pt":1588451532048,"mc":[{"id":"1.170370564","rc":[{"trd":[[1.88,6.13],[1.78,10.23]],"ltp":1.88,"tv":16.36,"id":8509691},{"atl":[[1.88,7.44],[1.78,0]],"id":8509691}],"con":true,"img":false}]}
{"op":"mcm","clk":"1362442883","pt":1588451532353,"mc":[{"id":"1.170370566","rc":[{"atl":[[1000,1.77]],"id":8509691}],"con":true,"img":false}]}
{"op":"mcm","clk":"1362442886","pt":1588451532659,"mc":[{"id":"1.170370566","rc":[{"atl":[[1000,0.88]],"id":8509691}],"con":true,"img":false}]}
{"op":"mcm","clk":"1362442887","pt":1588451532863,"mc":[{"id":"1.170370564","rc":[{"trd":[[2.42,118.18]],"ltp":2.42,"tv":118.18,"id":9630572},{"atl":[[2.42,71.35]],"id":9630572},{"trd":[[1.7,162.53]],"ltp":1.7,"tv":162.53,"id":8509691}],"con":true,"img":false}]}
{"op":"mcm","clk":"1362442889","pt":1588451532965,"mc":[{"id":"1.170370566","rc":[{"atl":[[1000,0]],"id":8509691}],"con":true,"img":false}]}
{"op":"mcm","clk":"1362442912","pt":1588451535560,"mc":[{"id":"1.170370564","rc":[{"trd":[[1.88,6.17]],"ltp":1.88,"tv":6.17,"id":8509691},{"atl":[[1.88,7.42]],"id":8509691}],"con":true,"img":false}]}
{"op":"mcm","clk":"1362442931","pt":1588451538060,"mc":[{"id":"1.170370566","rc":[{"atl":[[200,0.88]],"id":8509691}],"con":true,"img":false}]}
{"op":"mcm","clk":"1362442945","pt":1588451539130,"mc":[{"id":"1.170370564","rc":[{"trd":[[2.42,173.68]],"ltp":2.42,"tv":173.68,"id":9630572},{"atl":[[2.42,15.85]],"id":9630572},{"trd":[[1.7,241.53]],"ltp":1.7,"tv":241.53,"id":8509691}],"con":true,"img":false}]}
{"op":"mcm","clk":"1362442948","pt":1588451539436,"mc":[{"id":"1.170370564","rc":[{"trd":[[2.42,173.82]],"ltp":2.42,"tv":173.82,"id":9630572},{"atl":[[2.42,15.71]],"id":9630572},{"trd":[[1.7,241.73]],"ltp":1.7,"tv":241.73,"id":8509691}],"con":true,"img":false}]}
{"op":"mcm","clk":"1362442963","pt":1588451541730,"mc":[{"id":"1.170370564","rc":[{"atb":[[2,8]],"id":9630572}],"con":true,"img":false}]}
{"op":"mcm","clk":"1362442991","pt":1588451545250,"mc":[{"id":"1.170370564","rc":[{"trd":[[2.42,180.04]],"ltp":2.42,"tv":180.04,"id":9630572},{"atl":[[2.42,9.49]],"id":9630572},{"trd":[[1.7,250.6]],"ltp":1.7,"tv":250.6,"id":8509691}],"con":true,"img":false}]}
{"op":"mcm","clk":"1362443004","pt":1588451547286,"mc":[{"id":"1.170370564","rc":[{"atl":[[1.84,5.59]],"id":8509691}],"con":true,"img":false}]}
{"op":"mcm","clk":"1362443018","pt":1588451549477,"mc":[{"id":"1.170370564","rc":[{"atl":[[1.84,0]],"id":8509691}],"con":true,"img":false}]}
{"op":"mcm","clk":"1362443046","pt":1588451554771,"mc":[{"id":"1.170370564","rc":[{"atb":[[1.56,0]],"id":8509691}],"con":true,"img":false}]}
{"op":"mcm","clk":"1362443062","pt":1588451556763,"mc":[{"id":"1.170370564","rc":[{"atl":[[1.82,5.59]],"id":8509691}],"con":true,"img":false}]}
{"op":"mcm","clk":"1362443076","pt":1588451558953,"mc":[{"id":"1.170370564","rc":[{"atb":[[1.58,88.65]],"id":8509691}],"con":true,"img":false}]}
{"op":"mcm","clk":"1362443107","pt":1588451564192,"mc":[{"id":"1.170370564","rc":[{"atl":[[1.8,0.42]],"id":8509691}],"con":true,"img":false}]}
{"op":"mcm","clk":"1362443113","pt":1588451565158,"mc":[{"id":"1.170370564","rc":[{"trd":[[2.42,180.86]],"ltp":2.42,"tv":180.86,"id":9630572},{"atl":[[2.42,9.08]],"id":9630572}],"con":true,"img":false}]}
{"op":"mcm","clk":"1362443118","pt":1588451566178,"mc":[{"id":"1.170370564","rc":[{"trd":[[2.42,189.95]],"ltp":2.42,"tv":189.95,"id":9630572},{"atl":[[2.42,0]],"id":9630572},{"trd":[[1.7,263.53]],"ltp":1.7,"tv":263.53,"id":8509691},{"atl":[[1.7,164.37]],"id":8509691}],"con":true,"img":false}]}
{"op":"mcm","clk":"1362443122","pt":1588451566891,"mc":[{"id":"1.170370564","rc":[{"atb":[[1.57,0]],"id":8509691}],"con":true,"img":false}]}
{"op":"mcm","clk":"1362443126","pt":1588451567657,"mc":[{"id":"1.170370564","rc":[{"atl":[[1.7,165.92]],"id":8509691}],"con":true,"img":false}]}
{"op":"mcm","clk":"1362443129","pt":1588451568266,"mc":[{"id":"1.170370564","rc":[{"atb":[[1.58,0]],"id":8509691}],"con":true,"img":false}]}
{"op":"mcm","clk":"1362443135","pt":1588451569387,"mc":[{"id":"1.170370564","rc":[{"atl":[[1.82,0]],"id":8509691}],"con":true,"img":false}]}
{"op":"mcm","clk":"1362443138","pt":1588451569897,"mc":[{"id":"1.170370564","rc":[{"trd":[[2.42,230.75]],"ltp":2.42,"tv":230.75,"id":9630572},{"trd":[[1.7,321.61]],"ltp":1.7,"tv":321.61,"id":8509691},{"atl":[[1.7,107.84]],"id":8509691}],"con":true,"img":false}]}
{"op":"mcm","clk":"1362443142","pt":1588451570458,"mc":[{"id":"1.170370565","rc":[{"atb":[[2,88.65]],"id":11269555}],"con":true,"img":false}]}
{"op":"mcm","clk":"1362443156","pt":1588451571576,"mc":[{"id":"1.170370564","rc":[{"atl":[[1.8,2.42]],"id":8509691}],"con":true,"img":false}]}
{"op":"mcm","clk":"1362443158","pt":1588451571983,"mc":[{"id":"1.170370564","rc":[{"atb":[[1.59,40.78]],"id":8509691}],"con":true,"img":false}]}
{"op":"mcm","clk":"1362443182","pt":1588451574376,"mc":[{"id":"1.170370564","rc":[{"trd":[[2.42,246.74]],"ltp":2.42,"tv":246.74,"id":9630572},{"trd":[[1.7,344.39]],"ltp":1.7,"tv":344.39,"id":8509691},{"atl":[[1.7,85.06]],"id":8509691}],"con":true,"img":false}]}
{"op":"mcm","clk":"1362443184","pt":1588451574477,"mc":[{"id":"1.170370564","rc":[{"atl":[[1.69,5.59]],"id":8509691}],"con":true,"img":false}]}
{"op":"mcm","clk":"1362443186","pt":1588451574680,"mc":[{"id":"1.170370564","rc":[{"atl":[[3,0]],"id":9630572}],"con":true,"img":false}]}
{"op":"mcm","clk":"1362443187","pt":1588451574986,"mc":[{"id":"1.170370564","rc":[{"atb":[[1.59,0]],"id":8509691}],"con":true,"img":false},{"id":"1.170370566","rc":[{"atl":[[1.3,119.98]],"id":9630572}],"con":true,"img":false}]}
{"op":"mcm","clk":"1362443200","pt":1588451576108,"mc":[{"id":"1.170370564","rc":[{"atb":[[1.55,0]],"id":8509691}],"con":true,"img":false}]}
{"op":"mcm","clk":"1362443225","pt":1588451580077,"mc":[{"id":"1.170370564","rc":[{"atb":[[1.56,40.78]],"id":8509691}],"con":true,"img":false}]}
{"op":"mcm","clk":"1362443239","pt":1588451582115,"mc":[{"id":"1.170370564","rc":[{"trd":[[2.42,246.86],[2.44,14.28]],"ltp":2.42,"tv":261.14,"id":9630572},{"trd":[[1.7,344.55],[1.69,5.59]],"ltp":1.7,"tv":350.14,"id":8509691},{"atl":[[1.7,84.9],[1.69,0]],"id":8509691}],"con":true,"img":false}]}
{"op":"mcm","clk":"1362443240","pt":1588451582169,"mc":[{"id":"1.170370564","rc":[{"atb":[[1.56,0]],"id":8509691}],"con":true,"img":false}]}
{"op":"mcm","clk":"1362443256","pt":1588451584885,"mc":[{"id":"1.170370564","rc":[{"atl":[[1.7,86.31]],"id":8509691}],"con":true,"img":false}]}
{"op":"mcm","clk":"1362443264","pt":1588451586568,"mc":[{"id":"1.170370564","rc":[{"atb":[[1.35,5.59]],"id":8509691}],"con":true,"img":false}]}
{"op":"mcm","clk":"1362443292","pt":1588451590279,"mc":[{"id":"1.170370564","rc":[{"atb":[[1.35,11.19]],"id":8509691}],"con":true,"img":false}]}
{"op":"mcm","clk":"1362443316","pt":1588451593690,"mc":[{"id":"1.170370564","rc":[{"atb":[[1.39,88.65],[1.35,59.07]],"id":8509691}],"con":true,"img":false}]}
{"op":"mcm","clk":"1362443334","pt":1588451596687,"mc":[{"id":"1.170370564","rc":[{"atb":[[1.37,94.68]],"id":8509691}],"con":true,"img":false}]}
{"op":"mcm","clk":"1362443336","pt":1588451597095,"mc":[{"id":"1.170370564","rc":[{"atb":[[1.34,9.01]],"id":8509691}],"con":true,"img":false}]}
{"op":"mcm","clk":"1362443343","pt":1588451597707,"mc":[{"id":"1.170370564","rc":[{"atl":[[1.56,6.35]],"id":8509691}],"con":true,"img":false}]}
{"op":"mcm","clk":"1362443346","pt":1588451597911,"mc":[{"id":"1.170370564","rc":[{"atl":[[1.8,0.42]],"id":8509691}],"con":true,"img":false}]}
{"op":"mcm","clk":"1362443363","pt":1588451600710,"mc":[{"id":"1.170370564","rc":[{"atb":[[1.35,11.19]],"id":8509691}],"con":true,"img":false}]}
{"op":"mcm","clk":"1362443378","pt":1588451603004,"mc":[{"id":"1.170370564","rc":[{"atl":[[1.69,2]],"id":8509691}],"con":true,"img":false}]}
{"op":"mcm","clk":"1362443387","pt":1588451604993,"mc":[{"id":"1.170370564","rc":[{"trd":[[1.56,5.99]],"ltp":1.56,"tv":5.99,"id":8509691},{"atl":[[1.56,3.35]],"id":8509691}],"con":true,"img":false}]}
{"op":"mcm","clk":"1362443390","pt":1588451605094,"mc":[{"id":"1.170370564","rc":[{"atb":[[1.34,0]],"id":8509691}],"con":true,"img":false}]}
{"op":"mcm","clk":"1362443396","pt":1588451605705,"mc":[{"id":"1.170370564","rc":[{"atb":[[2,5]],"id":9630572}],"con":true,"img":false}]}
{"op":"mcm","clk":"1362443413","pt":1588451609119,"mc":[{"id":"1.170370564","rc":[{"atb":[[1.41,44.32]],"id":8509691}],"con":true,"img":false}]}
{"op":"mcm","clk":"1362443419","pt":1588451610192,"mc":[{"id":"1.170370564","rc":[{"atb":[[1.4,9.01]],"id":8509691}],"con":true,"img":false}]}
{"op":"mcm","clk":"1362443426","pt":1588451610801,"mc":[{"id":"1.170370564","rc":[{"atb":[[2.8,3]],"id":9630572}],"con":true,"img":false}]}
{"op":"mcm","clk":"1362443431","pt":1588451611815,"mc":[{"id":"1.170370564","rc":[{"atb":[[1.35,0]],"id":8509691}],"con":true,"img":false}]}
{"op":"mcm","clk":"1362443433","pt":1588451611917,"mc":[{"id":"1.170370564","rc":[{"atb":[[1.4,184.19]],"id":8509691}],"con":true,"img":false}]}
{"op":"mcm","clk":"1362443445","pt":1588451614106,"mc":[{"id":"1.170370564","rc":[{"atb":[[2.8,0]],"id":9630572}],"con":true,"img":false}]}
{"op":"mcm","clk":"1362443453","pt":1588451615528,"mc":[{"id":"1.170370564","rc":[{"atl":[[1.56,3.12]],"id":8509691}],"con":true,"img":false}]}
{"op":"mcm","clk":"1362443466","pt":1588451616907,"mc":[{"id":"1.170370564","rc":[{"atb":[[1.27,11.19]],"id":8509691}],"con":true,"img":false}]}
{"op":"mcm","clk":"1362443469","pt":1588451617212,"mc":[{"id":"1.170370564","rc":[{"atb":[[1.42,88.65]],"id":8509691}],"con":true,"img":false}]}
{"op":"mcm","clk":"1362443476","pt":1588451617920,"mc":[{"id":"1.170370564","rc":[{"atb":[[1.27,16.79]],"id":8509691}],"con":true,"img":false}]}
{"op":"mcm","clk":"1362443477","pt":1588451618330,"mc":[{"id":"1.170370564","rc":[{"atb":[[1.28,5.59],[1.43,88.65]],"id":8509691}],"con":true,"img":false}]}
{"op":"mcm","clk":"1362443481","pt":1588451618838,"mc":[{"id":"1.170370564","rc":[{"atb":[[1.39,0]],"id":8509691}],"con":true,"img":false}]}
{"op":"mcm","clk":"1362443485","pt":1588451619502,"mc":[{"id":"1.170370564","rc":[{"atl":[[1.44,3]],"id":8509691}],"con":true,"img":false}]}
{"op":"mcm","clk":"1362443487","pt":1588451619704,"mc":[{"id":"1.170370566","rc":[{"atl":[[7,0]],"id":9630572}],"con":true,"img":false}]}
{"op":"mcm","clk":"1362443497","pt":1588451621635,"mc":[{"id":"1.170370564","rc":[{"atb":[[1.42,0]],"id":8509691}],"con":true,"img":false}]}
{"op":"mcm","clk":"1362443511","pt":1588451623830,"mc":[{"id":"1.170370566","rc":[{"atb":[[2,0]],"id":8509691}],"con":true,"img":false}]}
{"op":"mcm","clk":"1362443525","pt":1588451625722,"mc":[{"id":"1.170370564","rc":[{"trd":[[1.44,49.08]],"ltp":1.44,"tv":49.08,"id":8509691},{"atb":[[1.44,85.65]],"id":8509691},{"atl":[[1.44,0]],"id":8509691}],"con":true,"img":false}]}
{"op":"mcm","clk":"1362443526","pt":1588451625825,"mc":[{"id":"1.170370564","rc":[{"atb":[[1.4,175.17]],"id":8509691}],"con":true,"img":false}]}
{"op":"mcm","clk":"1362443538","pt":1588451628217,"mc":[{"id":"1.170370564","rc":[{"atb":[[1.44,173.24],[1.41,0]],"id":8509691}],"con":true,"img":false}]}
{"op":"mcm","clk":"1362443541","pt":1588451628421,"mc":[{"id":"1.170370564","rc":[{"atb":[[2.5,7]],"id":9630572}],"con":true,"img":false}]}
{"op":"mcm","clk":"1362443555","pt":1588451630759,"mc":[{"id":"1.170370566","rc":[{"trd":[[1.3,13.22]],"ltp":1.3,"tv":13.22,"id":9630572},{"atl":[[1.3,106.75]],"id":9630572},{"trd":[[4.3,4]],"ltp":4.3,"tv":4.0,"id":8509691}],"con":true,"img":false}]}
{"op":"mcm","clk":"1362443556","pt":1588451630915,"mc":[{"id":"1.170370564","rc":[{"atb":[[1.45,9.01]],"id":8509691}],"con":true,"img":false},{"id":"1.170370565","rc":[{"atb":[[2.06,45.79]],"id":11269555}],"con":true,"img":false}]}
{"op":"mcm","clk":"1362443567","pt":1588451632337,"mc":[{"id":"1.170370564","rc":[{"atb":[[1.44,173.67]],"id":8509691}],"con":true,"img":false}]}
{"op":"mcm","clk":"1362443574","pt":1588451633356,"mc":[{"id":"1.170370564","rc":[{"atb":[[1.45,53.34]],"id":8509691}],"con":true,"img":false}]}
{"op":"mcm","clk":"1362443604","pt":1588451638144,"mc":[{"id":"1.170370564","rc":[{"atb":[[2,16.99]],"id":9630572}],"con":true,"img":false}]}
{"op":"mcm","clk":"1362443607","pt":1588451638753,"mc":[{"id":"1.170370565","rc":[{"atb":[[2,0]],"id":11269555}],"con":true,"img":false}]}
{"op":"mcm","clk":"1362443617","pt":1588451640536,"mc":[{"id":"1.170370564","rc":[{"atb":[[1.4,0]],"id":8509691}],"con":true,"img":false}]}
{"op":"mcm","clk":"1362443620","pt":1588451640637,"mc":[{"id":"1.170370564","rc":[{"atb":[[1.44,86.08],[1.37,7.09]],"id":8509691}],"con":true,"img":false}]}
{"op":"mcm","clk":"1362443625","pt":1588451641754,"mc":[{"id":"1.170370564","rc":[{"atb":[[1.44,0.42]],"id":8509691}],"con":true,"img":false}]}
{"op":"mcm","clk":"1362443628","pt":1588451642161,"mc":[{"id":"1.170370564","rc":[{"atb":[[1.43,0]],"id":8509691}],"con":true,"img":false}]}
{"op":"mcm","clk":"1362443675","pt":1588451647941,"mc":[{"id":"1.170370564","rc":[{"trd":[[2.5,5.44],[2.78,1.75]],"ltp":2.5,"tv":7.19,"id":9630572},{"atb":[[2.5,6.35]],"id":9630572},{"trd":[[1.56,9.12]],"ltp":1.56,"tv":9.12,"id":8509691},{"atl":[[1.56,0]],"id":8509691}],"con":true,"img":false}]}
{"op":"mcm","clk":"1362443680","pt":1588451648550,"mc":[{"id":"1.170370564","rc":[{"atl":[[1.47,3]],"id":8509691}],"con":true,"img":false}]}
{"op":"mcm","clk":"1362443698","pt":1588451652571,"mc":[{"id":"1.170370564","rc":[{"atb":[[1.45,9.01]],"id":8509691}],"con":true,"img":false}]}
{"op":"mcm","clk":"1362443728","pt":1588451655978,"mc":[{"id":"1.170370564","rc":[{"trd":[[1.47,25.5]],"ltp":1.47,"tv":25.5,"id":8509691},{"atb":[[1.47,85.65]],"id":8509691},{"atl":[[1.47,0]],"id":8509691}],"con":true,"img":false}]}
{"op":"mcm","clk":"1362443733","pt":1588451656588,"mc":[{"id":"1.170370566","rc":[{"trd":[[1.3,36.42]],"ltp":1.3,"tv":36.42,"id":9630572},{"atl":[[1.3,83.55]],"id":9630572},{"trd":[[4.3,11.01]],"ltp":4.3,"tv":11.01,"id":8509691}],"con":true,"img":false}]}
{"op":"mcm","clk":"1362443734","pt":1588451656691,"mc":[{"id":"1.170370564","rc":[{"atb":[[1.47,0]],"id":8509691}],"con":true,"img":false}]}
{"op":"mcm","clk":"1362443739","pt":1588451657252,"mc":[{"id":"1.170370564","rc":[{"atl":[[1.55,0.1]],"id":8509691}],"con":true,"img":false}]}
{"op":"mcm","clk":"1362443742","pt":1588451657659,"mc":[{"id":"1.170370564","rc":[{"atb":[[1.4,44.32]],"id":8509691}],"con":true,"img":false}]}
{"op":"mcm","clk":"1362443749","pt":1588451658572,"mc":[{"id":"1.170370564","rc":[{"atb":[[1.47,87.58]],"id":8509691}],"con":true,"img":false}]}
{"op":"mcm","clk":"1362443759","pt":1588451660558,"mc":[{"id":"1.170370564","rc":[{"atb":[[2,5]],"id":9630572}],"con":true,"img":false}]}
{"op":"mcm","clk":"1362443761","pt":1588451660763,"mc":[{"id":"1.170370564","rc":[{"atl":[[1.55,0]],"id":8509691}],"con":true,"img":false}]}
{"op":"mcm","clk":"1362443800","pt":1588451668403,"mc":[{"id":"1.170370564","rc":[{"atb":[[1.44,0]],"id":8509691}],"con":true,"img":false}]}
{"op":"mcm","clk":"1362443824","pt":1588451671867,"mc":[{"id":"1.170370566","rc":[{"atl":[[1.3,0]],"id":9630572}],"con":true,"img":false}]}
{"op":"mcm","clk":"1362443856","pt":1588451677105,"mc":[{"id":"1.170370566","rc":[{"atl":[[1.7,83.55]],"id":9630572}],"con":true,"img":false}]}
{"op":"mcm","clk":"1362443862","pt":1588451677973,"mc":[{"id":"1.170370564","rc":[{"trd":[[1.47,34.24]],"ltp":1.47,"tv":34.24,"id":8509691},{"atb":[[1.47,83.21]],"id":8509691}],"con":true,"img":false}]}
{"op":"mcm","clk":"1362443887","pt":1588451681790,"mc":[{"id":"1.170370564","rc":[{"atl":[[1.67,12.26]],"id":8509691}],"con":true,"img":false}]}
{"op":"mcm","clk":"1362443904","pt":1588451684793,"mc":[{"id":"1.170370564","rc":[{"atl":[[1.65,0.1]],"id":8509691}],"con":true,"img":false}]}
{"op":"mcm","clk":"1362443935","pt":1588451690082,"mc":[{"id":"1.170370566","rc":[{"atl":[[1.65,177.57]],"id":9630572}],"con":true,"img":false}]}
{"op":"mcm","clk":"1362443994","pt":1588451697718,"mc":[{"id":"1.170370566","rc":[{"atl":[[1.7,0]],"id":9630572}],"con":true,"img":false}]}
{"op":"mcm","clk":"1362443995","pt":1588451697921,"mc":[{"id":"1.170370567","rc":[{"atb":[[1.15,79.98]],"id":8509691}],"con":true,"img":false}]}
{"op":"mcm","clk":"1362444017","pt":1588451702406,"mc":[{"id":"1.170370564","rc":[{"atb":[[1.47,127.01]],"id":8509691}],"con":true,"img":false}]}
{"op":"mcm","clk":"1362444020","pt":1588451702818,"mc":[{"id":"1.170370566","rc":[{"atl":[[1.62,83.55]],"id":9630572}],"con":true,"img":false}]}
{"op":"mcm","clk":"1362444030","pt":1588451704552,"mc":[{"id":"1.170370564","rc":[{"atl":[[1.66,4.43]],"id":8509691}],"con":true,"img":false}]}
{"op":"mcm","clk":"1362444043","pt":1588451706742,"mc":[{"id":"1.170370564","rc":[{"atl":[[3.05,2.57]],"id":9630572}],"con":true,"img":false}]}
{"op":"mcm","clk":"1362444044","pt":1588451706946,"mc":[{"id":"1.170370566","rc":[{"atb":[[2.54,18.17]],"id":8509691}],"con":true,"img":false}]}
{"op":"mcm","clk":"1362444101","pt":1588451714229,"mc":[{"id":"1.170370564","rc":[{"atb":[[1.5,88.65]],"id":8509691}],"con":true,"img":false},{"id":"1.170370566","rc":[{"atb":[[2.54,0]],"id":8509691}],"con":true,"img":false}]}
{"op":"mcm","clk":"1362444131","pt":1588451716522,"mc":[{"id":"1.170370564","rc":[{"trd":[[1.5,51.31]],"ltp":1.5,"tv":51.31,"id":8509691},{"atb":[[1.5,80.52]],"id":8509691}],"con":true,"img":false}]}
{"op":"mcm","clk":"1362444148","pt":1588451718354,"mc":[{"id":"1.170370564","rc":[{"trd":[[3,39.93]],"ltp":3.0,"tv":39.93,"id":9630572},{"trd":[[1.5,56.11]],"ltp":1.5,"tv":56.11,"id":8509691},{"atb":[[1.5,75.72]],"id":8509691}],"con":true,"img":false}]}
{"op":"mcm","clk":"1362444159","pt":1588451719424,"mc":[{"id":"1.170370566","rc":[{"atb":[[2.62,17.27]],"id":8509691}],"con":true,"img":false}]}
{"op":"mcm","clk":"1362444160","pt":1588451719629,"mc":[{"id":"1.170370564","rc":[{"trd":[[1.66,8.65],[1.65,23.48]],"ltp":1.66,"tv":32.13,"id":8509691},{"atl":[[1.65,0],[1.66,0.1]],"id":8509691}],"con":true,"img":false}]}
{"op":"mcm","clk":"1362444187","pt":1588451722230,"mc":[{"id":"1.170370566","rc":[{"atl":[[1.6,79.98]],"id":9630572}],"con":true,"img":false}]}
{"op":"mcm","clk":"1362444193","pt":1588451722942,"mc":[{"id":"1.170370564","rc":[{"trd":[[1.5,66.11]],"ltp":1.5,"tv":66.11,"id":8509691},{"atb":[[1.5,70.72]],"id":8509691}],"con":true,"img":false}]}
{"op":"mcm","clk":"1362444198","pt":1588451723455,"mc":[{"id":"1.170370564","rc":[{"atl":[[1.66,8.86]],"id":8509691}],"con":true,"img":false}]}
{"op":"mcm","clk":"1362444224","pt":1588451725450,"mc":[{"id":"1.170370564","rc":[{"atl":[[2.96,11.99]],"id":9630572}],"con":true,"img":false}]}
{"op":"mcm","clk":"1362444231","pt":1588451726423,"mc":[{"id":"1.170370564","rc":[{"atb":[[1.51,4.43]],"id":8509691}],"con":true,"img":false}]}
{"op":"mcm","clk":"1362444233","pt":1588451726626,"mc":[{"id":"1.170370564","rc":[{"atl":[[2.96,23.99]],"id":9630572}],"con":true,"img":false}]}
{"op":"mcm","clk":"1362444240","pt":1588451727035,"mc":[{"id":"1.170370564","rc":[{"atl":[[1.66,14.46]],"id":8509691}],"con":true,"img":false}]}
{"op":"mcm","clk":"1362444244","pt":1588451727545,"mc":[{"id":"1.170370564","rc":[{"atl":[[3.05,0]],"id":9630572}],"con":true,"img":false}]}
{"op":"mcm","clk":"1362444249","pt":1588451727950,"mc":[{"id":"1.170370564","rc":[{"atl":[[1.66,20.06]],"id":8509691}],"con":true,"img":false}]}
{"op":"mcm","clk":"1362444250","pt":1588451728153,"mc":[{"id":"1.170370564","rc":[{"atl":[[2.96,35.99]],"id":9630572}],"con":true,"img":false}]}
{"op":"mcm","clk":"1362444251","pt":1588451728256,"mc":[{"id":"1.170370564","rc":[{"atb":[[1.51,0]],"id":8509691}],"con":true,"img":false}]}
{"op":"mcm","clk":"1362444253","pt":1588451728460,"mc":[{"id":"1.170370564","rc":[{"atl":[[1.66,25.66]],"id":8509691}],"con":true,"img":false}]}
{"op":"mcm","clk":"1362444260","pt":1588451729329,"mc":[{"id":"1.170370566","rc":[{"atb":[[1.2,984.64]],"id":8509691}],"con":true,"img":false}]}
{"op":"mcm","clk":"1362444263","pt":1588451729533,"mc":[{"id":"1.170370564","rc":[{"atl":[[2.96,47.99]],"id":9630572}],"con":true,"img":false}]}
{"op":"mcm","clk":"1362444271","pt":1588451730446,"mc":[{"id":"1.170370564","rc":[{"atl":[[1.66,8.86]],"id":8509691}],"con":true,"img":false}]}
{"op":"mcm","clk":"1362444278","pt":1588451731873,"mc":[{"id":"1.170370566","rc":[{"atl":[[1.62,0]],"id":9630572}],"con":true,"img":false}]}
{"op":"mcm","clk":"1362444280","pt":1588451732034,"mc":[{"id":"1.170370564","rc":[{"atb":[[1.5,0]],"id":8509691}],"con":true,"img":false}]}
{"op":"mcm","clk":"1362444281","pt":1588451732336,"mc":[{"id":"1.170370564","rc":[{"atb":[[1.53,88.65]],"id":8509691}],"con":true,"img":false}]}
{"op":"mcm","clk":"1362444290","pt":1588451733151,"mc":[{"id":"1.170370564","rc":[{"atb":[[1.52,88.65]],"id":8509691}],"con":true,"img":false}]}
{"op":"mcm","clk":"1362444296","pt":1588451733964,"mc":[{"id":"1.170370564","rc":[{"atb":[[1.52,93.08]],"id":8509691}],"con":true,"img":false}]}
{"op":"mcm","clk":"1362444302","pt":1588451734934,"mc":[{"id":"1.170370564","rc":[{"atl":[[1.65,15.99]],"id":8509691}],"con":true,"img":false}]}
{"op":"mcm","clk":"1362444304","pt":1588451735136,"mc":[{"id":"1.170370564","rc":[{"atb":[[1.52,88.65]],"id":8509691}],"con":true,"img":false}]}
{"op":"mcm","clk":"1362444322","pt":1588451736968,"mc":[{"id":"1.170370566","rc":[{"atl":[[1.53,83.55]],"id":9630572}],"con":true,"img":false}]}
{"op":"mcm","clk":"1362444327","pt":1588451737680,"mc":[{"id":"1.170370564","rc":[{"atb":[[1.52,106.17]],"id":8509691}],"con":true,"img":false}]}
{"op":"mcm","clk":"1362444330","pt":1588451737935,"mc":[{"id":"1.170370564","rc":[{"atl":[[4.4,16]],"id":8509691}],"con":true,"img":false}]}
{"op":"mcm","clk":"1362444349","pt":1588451740884,"mc":[{"id":"1.170370564","rc":[{"atb":[[1.4,0],[1.54,4.43]],"id":8509691}],"con":true,"img":false}]}
{"op":"mcm","clk":"1362444353","pt":1588451741447,"mc":[{"id":"1.170370564","rc":[{"atl":[[2.96,0]],"id":9630572}],"con":true,"img":false}]}
{"op":"mcm","clk":"1362444362","pt":1588451742971,"mc":[{"id":"1.170370564","rc":[{"atb":[[1.53,0]],"id":8509691}],"con":true,"img":false}]}
{"op":"mcm","clk":"1362444370","pt":1588451743684,"mc":[{"id":"1.170370564","rc":[{"atb":[[1.52,17.51]],"id":8509691}],"con":true,"img":false}]}
{"op":"mcm","clk":"1362444377","pt":1588451744961,"mc":[{"id":"1.170370564","rc":[{"trd":[[1.54,5.28]],"ltp":1.54,"tv":5.28,"id":8509691},{"atb":[[1.54,1.79]],"id":8509691}],"con":true,"img":false}]}
{"op":"mcm","clk":"1362444390","pt":1588451747660,"mc":[{"id":"1.170370564","rc":[{"atl":[[1.69,0]],"id":8509691}],"con":true,"img":false}]}
{"op":"mcm","clk":"1362444393","pt":1588451747761,"mc":[{"id":"1.170370564","rc":[{"atb":[[1.55,4.43]],"id":8509691}],"con":true,"img":false}]}
{"op":"mcm","clk":"1362444420","pt":1588451751374,"mc":[{"id":"1.170370564","rc":[{"atb":[[1.54,0]],"id":8509691}],"con":true,"img":false}]}
{"op":"mcm","clk":"1362444425","pt":1588451752286,"mc":[{"id":"1.170370564","rc":[{"atl":[[1.65,24.75]],"id":8509691}],"con":true,"img":false}]}
{"op":"mcm","clk":"1362444438","pt":1588451754374,"mc":[{"id":"1.170370564","rc":[{"atb":[[1.55,46.09]],"id":8509691}],"con":true,"img":false}]}
{"op":"mcm","clk":"1362444443","pt":1588451755085,"mc":[{"id":"1.170370565","rc":[{"atb":[[2.06,0]],"id":11269555}],"con":true,"img":false}]}
{"op":"mcm","clk":"1362444457","pt":1588451756664,"mc":[{"id":"1.170370564","rc":[{"atl":[[1.64,2.48]],"id":8509691}],"con":true,"img":false}]}
{"op":"mcm","clk":"1362444464","pt":1588451757984,"mc":[{"id":"1.170370566","rc":[{"atl":[[1.5,79.98]],"id":9630572}],"con":true,"img":false}]}
{"op":"mcm","clk":"1362444473","pt":1588451758956,"mc":[{"id":"1.170370567","rc":[{"atb":[[1.15,0]],"id":8509691}],"con":true,"img":false}]}
{"op":"mcm","clk":"1362444482","pt":1588451760283,"mc":[{"id":"1.170370565","rc":[{"atb":[[1.83,54.41]],"id":11269555}],"con":true,"img":false}]}
{"op":"mcm","clk":"1362444502","pt":1588451763397,"mc":[{"id":"1.170370564","rc":[{"atb":[[1.55,4.43]],"id":8509691}],"con":true,"img":false}]}
{"op":"mcm","clk":"1362444518","pt":1588451765396,"mc":[{"id":"1.170370564","rc":[{"atb":[[1.55,21.95]],"id":8509691}],"con":true,"img":false}]}
{"op":"mcm","clk":"1362444529","pt":1588451766371,"mc":[{"id":"1.170370566","rc":[{"trd":[[1.5,17.73]],"ltp":1.5,"tv":17.73,"id":9630572},{"atl":[[1.5,62.25]],"id":9630572},{"trd":[[3,8.86]],"ltp":3.0,"tv":8.86,"id":8509691}],"con":true,"img":false}]}
{"op":"mcm","clk":"1362444548","pt":1588451768459,"mc":[{"id":"1.170370564","rc":[{"atb":[[1.5,41.66]],"id":8509691}],"con":true,"img":false}]}
{"op":"mcm","clk":"1362444557","pt":1588451769884,"mc":[{"id":"1.170370564","rc":[{"trd":[[1.65,27.19],[1.64,15.92]],"ltp":1.65,"tv":43.11,"id":8509691},{"atl":[[1.64,0],[1.65,22.9]],"id":8509691}],"con":true,"img":false}]}
{"op":"mcm","clk":"1362444575","pt":1588451773397,"mc":[{"id":"1.170370566","rc":[{"atl":[[1.53,0]],"id":9630572}],"con":true,"img":false}]}
{"op":"mcm","clk":"1362444589","pt":1588451775080,"mc":[{"id":"1.170370566","rc":[{"atb":[[2.62,0]],"id":8509691}],"con":true,"img":false}]}
{"op":"mcm","clk":"1362444616","pt":1588451778188,"mc":[{"id":"1.170370564","rc":[{"trd":[[1.55,25.03]],"ltp":1.55,"tv":25.03,"id":8509691},{"atb":[[1.55,19.49]],"id":8509691}],"con":true,"img":false}]}
{"op":"mcm","clk":"1362444617","pt":1588451778290,"mc":[{"id":"1.170370564","rc":[{"trd":[[1.65,27.27]],"ltp":1.65,"tv":27.27,"id":8509691},{"atl":[[1.65,22.86]],"id":8509691}],"con":true,"img":false}]}
{"op":"mcm","clk":"1362444620","pt":1588451778490,"mc":[{"id":"1.170370566","rc":[{"atl":[[1.48,83.55]],"id":9630572}],"con":true,"img":false}]}
{"op":"mcm","clk":"1362444621","pt":1588451778596,"mc":[{"id":"1.170370564","rc":[{"atb":[[1.56,4.43]],"id":8509691}],"con":true,"img":false}]}
{"op":"mcm","clk":"1362444632","pt":1588451780172,"mc":[{"id":"1.170370566","rc":[{"atb":[[3.05,13.65]],"id":8509691}],"con":true,"img":false}]}
{"op":"mcm","clk":"1362444642","pt":1588451780785,"mc":[{"id":"1.170370564","rc":[{"atl":[[1.65,31.61]],"id":8509691}],"con":true,"img":false}]}
{"op":"mcm","clk":"1362444655","pt":1588451782114,"mc":[{"id":"1.170370566","rc":[{"atl":[[1.5,0]],"id":9630572}],"con":true,"img":false}]}
{"op":"mcm","clk":"1362444678","pt":1588451785383,"mc":[{"id":"1.170370566","rc":[{"atl":[[1.6,0]],"id":9630572}],"con":true,"img":false}]}
{"op":"mcm","clk":"1362444702","pt":1588451787119,"mc":[{"id":"1.170370566","rc":[{"atl":[[1.65,0]],"id":9630572}],"con":true,"img":false}]}
{"op":"mcm","clk":"1362444705","pt":1588451787219,"mc":[{"id":"1.170370566","rc":[{"atl":[[1.47,62.25]],"id":9630572}],"con":true,"img":false}]}
{"op":"mcm","clk":"1362444764","pt":1588451792993,"mc":[{"id":"1.170370566","rc":[{"atl":[[1.48,0]],"id":9630572}],"con":true,"img":false}]}
{"op":"mcm","clk":"1362444770","pt":1588451793709,"mc":[{"id":"1.170370564","rc":[{"trd":[[1.65,32.44]],"ltp":1.65,"tv":32.44,"id":8509691},{"atl":[[1.65,29.03]],"id":8509691}],"con":true,"img":false}]}
{"op":"mcm","clk":"1362444780","pt":1588451795292,"mc":[{"id":"1.170370564","rc":[{"atb":[[2.5,8.74]],"id":9630572}],"con":true,"img":false}]}
{"op":"mcm","clk":"1362444790","pt":1588451797285,"mc":[{"id":"1.170370566","rc":[{"atl":[[1.47,0]],"id":9630572}],"con":true,"img":false}]}
{"op":"mcm","clk":"1362444793","pt":1588451797593,"mc":[{"id":"1.170370564","rc":[{"atb":[[1.56,21.95]],"id":8509691}],"con":true,"img":false}]}
{"op":"mcm","clk":"1362444797","pt":1588451798105,"mc":[{"id":"1.170370566","rc":[{"atl":[[1.44,83.55]],"id":9630572}],"con":true,"img":false}]}
{"op":"mcm","clk":"1362444813","pt":1588451799582,"mc":[{"id":"1.170370564","rc":[{"atb":[[1.56,104.47]],"id":8509691}],"con":true,"img":false}]}
{"op":"mcm","clk":"1362444817","pt":1588451799787,"mc":[{"id":"1.170370564","rc":[{"atl":[[4,0]],"id":9630572}],"con":true,"img":false}]}
{"op":"mcm","clk":"1362444833","pt":1588451802029,"mc":[{"id":"1.170370566","rc":[{"atb":[[1.2,98.38]],"id":8509691}],"con":true,"img":false}]}
{"op":"mcm","clk":"1362444837","pt":1588451802386,"mc":[{"id":"1.170370566","rc":[{"atl":[[1.45,62.25]],"id":9630572}],"con":true,"img":false}]}
{"op":"mcm","clk":"1362444840","pt":1588451802795,"mc":[{"id":"1.170370564","rc":[{"atb":[[1.55,17.51]],"id":8509691}],"con":true,"img":false}]}
{"op":"mcm","clk":"1362444843","pt":1588451803510,"mc":[{"id":"1.170370564","rc":[{"atl":[[1.64,3.19]],"id":8509691}],"con":true,"img":false}]}
{"op":"mcm","clk":"1362444846","pt":1588451803917,"mc":[{"id":"1.170370564","rc":[{"atl":[[1.62,3.19]],"id":8509691}],"con":true,"img":false}]}
{"op":"mcm","clk":"1362444849","pt":1588451804427,"mc":[{"id":"1.170370564","rc":[{"atl":[[1.61,3.19]],"id":8509691}],"con":true,"img":false}]}
{"op":"mcm","clk":"1362444851","pt":1588451804631,"mc":[{"id":"1.170370566","rc":[{"atl":[[1.45,0]],"id":9630572}],"con":true,"img":false}]}
{"op":"mcm","clk":"1362444853","pt":1588451804887,"mc":[{"id":"1.170370564","rc":[{"atl":[[1.6,3.19]],"id":8509691}],"con":true,"img":false}]}
{"op":"mcm","clk":"1362444858","pt":1588451805908,"mc":[{"id":"1.170370564","rc":[{"atl":[[1.59,3.19],[1.58,3.19]],"id":8509691}],"con":true,"img":false}]}
{"op":"mcm","clk":"1362444860","pt":1588451806113,"mc":[{"id":"1.170370564","rc":[{"atb":[[2.5,6.35]],"id":9630572}],"con":true,"img":false}]}
{"op":"mcm","clk":"1362444863","pt":1588451806316,"mc":[{"id":"1.170370564","rc":[{"atl":[[1.58,6.39]],"id":8509691}],"con":true,"img":false}]}
{"op":"mcm","clk":"1362444864","pt":1588451806418,"mc":[{"id":"1.170370564","rc":[{"atb":[[1.01,3137.32]],"id":8509691}],"con":true,"img":false}]}
{"op":"mcm","clk":"1362444865","pt":1588451806623,"mc":[{"id":"1.170370564","rc":[{"trd":[[1.56,9.33]],"ltp":1.56,"tv":9.33,"id":8509691},{"atb":[[1.56,104.37]],"id":8509691}],"con":true,"img":false}]}
{"op":"mcm","clk":"1362444866","pt":1588451806725,"mc":[{"id":"1.170370564","rc":[{"atb":[[1.01,3136.59]],"id":8509691},{"atl":[[1.57,3.19]],"id":8509691}],"con":true,"img":false}]}
{"op":"mcm","clk":"1362444868","pt":1588451807031,"mc":[{"id":"1.170370564","rc":[{"atb":[[1.01,3134.12]],"id":8509691}],"con":true,"img":false}]}
{"op":"mcm","clk":"1362444877","pt":1588451807899,"mc":[{"id":"1.170370564","rc":[{"trd":[[1.57,3.95]],"ltp":1.57,"tv":3.95,"id":8509691},{"atl":[[1.57,1.22]],"id":8509691}],"con":true,"img":false}]}
{"op":"mcm","clk":"1362444880","pt":1588451808306,"mc":[{"id":"1.170370564","rc":[{"trd":[[1.56,129.31]],"ltp":1.56,"tv":129.31,"id":8509691},{"atb":[[1.56,44.38]],"id":8509691}],"con":true,"img":false}]}
{"op":"mcm","clk":"1362444882","pt":1588451808510,"mc":[{"id":"1.170370564","rc":[{"trd":[[1.56,218.07]],"ltp":1.56,"tv":218.07,"id":8509691},{"atb":[[1.56,0]],"id":8509691},{"atl":[[1.56,15.61]],"id":8509691}],"con":true,"img":false}]}
{"op":"mcm","clk":"1362444896","pt":1588451809733,"mc":[{"id":"1.170370566","rc":[{"atl":[[1.42,62.25]],"id":9630572}],"con":true,"img":false}]}
{"op":"mcm","clk":"1362444905","pt":1588451812027,"mc":[{"id":"1.170370564","rc":[{"atl":[[1.64,6.39]],"id":8509691}],"con":true,"img":false}]}
{"op":"mcm","clk":"1362444906","pt":1588451812130,"mc":[{"id":"1.170370564","rc":[{"trd":[[1.56,223.01]],"ltp":1.56,"tv":223.01,"id":8509691},{"atl":[[1.56,13.14]],"id":8509691}],"con":true,"img":false}]}
{"op":"mcm","clk":"1362444909","pt":1588451812537,"mc":[{"id":"1.170370564","rc":[{"atl":[[1.63,3.19]],"id":8509691}],"con":true,"img":false}]}
{"op":"mcm","clk":"1362444913","pt":1588451813099,"mc":[{"id":"1.170370564","rc":[{"atl":[[1.56,15.71]],"id":8509691}],"con":true,"img":false}]}
{"op":"mcm","clk":"1362444926","pt":1588451815597,"mc":[{"id":"1.170370566","rc":[{"atl":[[1.44,0]],"id":9630572}],"con":true,"img":false}]}
{"op":"mcm","clk":"1362444927","pt":1588451815699,"mc":[{"id":"1.170370564","rc":[{"atl":[[1.57,4.42]],"id":8509691}],"con":true,"img":false}]}
{"op":"mcm","clk":"1362444930","pt":1588451816107,"mc":[{"id":"1.170370566","rc":[{"atb":[[3.05,0]],"id":8509691}],"con":true,"img":false}]}
{"op":"mcm","clk":"1362444934","pt":1588451816414,"mc":[{"id":"1.170370564","rc":[{"atl":[[1.61,11.95]],"id":8509691}],"con":true,"img":false}]}
{"op":"mcm","clk":"1362444943","pt":1588451818097,"mc":[{"id":"1.170370564","rc":[{"atl":[[1.65,17.51]],"id":8509691}],"con":true,"img":false}]}
{"op":"mcm","clk":"1362444947","pt":1588451818607,"mc":[{"id":"1.170370564","rc":[{"atl":[[1.7,84.9]],"id":8509691}],"con":true,"img":false}]}
{"op":"mcm","clk":"1362444952","pt":1588451819218,"mc":[{"id":"1.170370564","rc":[{"trd":[[1.55,33.95]],"ltp":1.55,"tv":33.95,"id":8509691},{"atb":[[1.55,13.05]],"id":8509691}],"con":true,"img":false}]}
{"op":"mcm","clk":"1362444954","pt":1588451819320,"mc":[{"id":"1.170370564","rc":[{"atl":[[1.65,8.75],[1.61,3.19]],"id":8509691}],"con":true,"img":false}]}
{"op":"mcm","clk":"1362444956","pt":1588451819422,"mc":[{"id":"1.170370564","rc":[{"atl":[[1.66,0.1]],"id":8509691}],"con":true,"img":false}]}
{"op":"mcm","clk":"1362444958","pt":1588451819626,"mc":[{"id":"1.170370564","rc":[{"atb":[[1.55,0]],"id":8509691},{"atl":[[1.65,0]],"id":8509691}],"con":true,"img":false}]}
{"op":"mcm","clk":"1362444959","pt":1588451819728,"mc":[{"id":"1.170370564","rc":[{"atb":[[1.52,0]],"id":8509691}],"con":true,"img":false}]}
{"op":"mcm","clk":"1362444962","pt":1588451820135,"mc":[{"id":"1.170370564","rc":[{"atl":[[1.67,0]],"id":8509691}],"con":true,"img":false}]}
{"op":"mcm","clk":"1362444964","pt":1588451820237,"mc":[{"id":"1.170370564","rc":[{"atb":[[1.47,0]],"id":8509691}],"con":true,"img":false}]}
{"op":"mcm","clk":"1362444966","pt":1588451820339,"mc":[{"id":"1.170370564","rc":[{"atl":[[1.56,13.14]],"id":8509691}],"con":true,"img":false}]}
{"op":"mcm","clk":"1362444968","pt":1588451820697,"mc":[{"id":"1.170370566","rc":[{"atl":[[1.4,83.55]],"id":9630572}],"con":true,"img":false}]}
{"op":"mcm","clk":"1362444971","pt":1588451821207,"mc":[{"id":"1.170370566","rc":[{"atb":[[3.4,12.21]],"id":8509691}],"con":true,"img":false}]}
{"op":"mcm","clk":"1362444980","pt":1588451822636,"mc":[{"id":"1.170370566","rc":[{"atl":[[1.42,0]],"id":9630572}],"con":true,"img":false}]}
{"op":"mcm","clk":"1362444987","pt":1588451823405,"mc":[{"id":"1.170370564","rc":[{"atb":[[1.5,0]],"id":8509691}],"con":true,"img":false}]}
{"op":"mcm","clk":"1362444993","pt":1588451824430,"mc":[{"id":"1.170370564","rc":[{"atb":[[1.45,0]],"id":8509691}],"con":true,"img":false}]}
{"op":"mcm","clk":"1362444995","pt":1588451824532,"mc":[{"id":"1.170370564","rc":[{"trd":[[1.56,223.39]],"ltp":1.56,"tv":223.39,"id":8509691},{"atl":[[1.56,12.94]],"id":8509691}],"con":true,"img":false}]}
{"op":"mcm","clk":"1362444999","pt":1588451825400,"mc":[{"id":"1.170370564","rc":[{"atl":[[1.55,2.57]],"id":8509691}],"con":true,"img":false}]}
{"op":"mcm","clk":"1362445013","pt":1588451826624,"mc":[{"id":"1.170370564","rc":[{"trd":[[1.55,37.39]],"ltp":1.55,"tv":37.39,"id":8509691},{"atl":[[1.55,0.85]],"id":8509691}],"con":true,"img":false}]}
{"op":"mcm","clk":"1362445020","pt":1588451827747,"mc":[{"id":"1.170370566","rc":[{"atl":[[1.38,62.25]],"id":9630572}],"con":true,"img":false}]}
{"op":"mcm","clk":"1362445033","pt":1588451829531,"mc":[{"id":"1.170370564","rc":[{"atb":[[1.51,9.01]],"id":8509691}],"con":true,"img":false}]}
{"op":"mcm","clk":"1362445063","pt":1588451832644,"mc":[{"id":"1.170370564","rc":[{"atl":[[1.55,0]],"id":8509691}],"con":true,"img":false}]}
{"op":"mcm","clk":"1362445065","pt":1588451832746,"mc":[{"id":"1.170370564","rc":[{"atb":[[2,0]],"id":9630572}],"con":true,"img":false}]}
{"op":"mcm","clk":"1362445067","pt":1588451832949,"mc":[{"id":"1.170370566","rc":[{"atl":[[1.4,0]],"id":9630572}],"con":true,"img":false}]}
{"op":"mcm","clk":"1362445071","pt":1588451833255,"mc":[{"id":"1.170370564","rc":[{"atb":[[1.3,4.43]],"id":8509691}],"con":true,"img":false}]}
{"op":"mcm","clk":"1362445080","pt":1588451834222,"mc":[{"id":"1.170370566","rc":[{"atl":[[1.35,17.59]],"id":9630572}],"con":true,"img":false}]}
{"op":"mcm","clk":"1362445093","pt":1588451835343,"mc":[{"id":"1.170370564","rc":[{"atb":[[1.3,54.07]],"id":8509691}],"con":true,"img":false}]}
{"op":"mcm","clk":"1362445107","pt":1588451837433,"mc":[{"id":"1.170370564","rc":[{"atb":[[1.51,0]],"id":8509691}],"con":true,"img":false}]}
{"op":"mcm","clk":"1362445111","pt":1588451837738,"mc":[{"id":"1.170370564","rc":[{"atl":[[1.51,15.99]],"id":8509691}],"con":true,"img":false}]}
{"op":"mcm","clk":"1362445112","pt":1588451837840,"mc":[{"id":"1.170370564","rc":[{"atb":[[2.8,5]],"id":9630572}],"con":true,"img":false}]}
{"op":"mcm","clk":"1362445119","pt":1588451839214,"mc":[{"id":"1.170370564","rc":[{"atb":[[1.38,0.1]],"id":8509691}],"con":true,"img":false}]}
{"op":"mcm","clk":"1362445139","pt":1588451843037,"mc":[{"id":"1.170370564","rc":[{"atl":[[1.51,0]],"id":8509691}],"con":true,"img":false}]}
{"op":"mcm","clk":"1362445148","pt":1588451844568,"mc":[{"id":"1.170370564","rc":[{"atb":[[1.3,49.64]],"id":8509691}],"con":true,"img":false}]}
{"op":"mcm","clk":"1362445162","pt":1588451847067,"mc":[{"id":"1.170370566","rc":[{"atb":[[3.4,0]],"id":8509691}],"con":true,"img":false}]}
{"op":"mcm","clk":"1362445172","pt":1588451848753,"mc":[{"id":"1.170370564","rc":[{"atb":[[1.39,4.43]],"id":8509691}],"con":true,"img":false}]}
{"op":"mcm","clk":"1362445177","pt":1588451849262,"mc":[{"id":"1.170370564","rc":[{"atl":[[1.55,2]],"id":8509691}],"con":true,"img":false}]}
{"op":"mcm","clk":"1362445191","pt":1588451852169,"mc":[{"id":"1.170370566","rc":[{"atb":[[3.9,10.1]],"id":8509691}],"con":true,"img":false}]}
{"op":"mcm","clk":"1362445192","pt":1588451852271,"mc":[{"id":"1.170370564","rc":[{"atb":[[1.45,9.01]],"id":8509691}],"con":true,"img":false}]}
{"op":"mcm","clk":"1362445193","pt":1588451852475,"mc":[{"id":"1.170370564","rc":[{"atb":[[1.39,7.63]],"id":8509691}],"con":true,"img":false}]}
{"op":"mcm","clk":"1362445197","pt":1588451852934,"mc":[{"id":"1.170370564","rc":[{"atb":[[1.41,3.19]],"id":8509691}],"con":true,"img":false}]}
{"op":"mcm","clk":"1362445201","pt":1588451853851,"mc":[{"id":"1.170370564","rc":[{"atb":[[1.45,12.21]],"id":8509691}],"con":true,"img":false}]}
{"op":"mcm","clk":"1362445203","pt":1588451854259,"mc":[{"id":"1.170370564","rc":[{"atb":[[1.47,3.19]],"id":8509691}],"con":true,"img":false},{"id":"1.170370566","rc":[{"atl":[[1.35,0]],"id":9630572}],"con":true,"img":false}]}
{"op":"mcm","clk":"1362445205","pt":1588451854664,"mc":[{"id":"1.170370564","rc":[{"atb":[[1.49,3.19]],"id":8509691}],"con":true,"img":false}]}
{"op":"mcm","clk":"1362445207","pt":1588451854970,"mc":[{"id":"1.170370564","rc":[{"atb":[[1.5,3.19]],"id":8509691}],"con":true,"img":false}]}
{"op":"mcm","clk":"1362445209","pt":1588451855175,"mc":[{"id":"1.170370564","rc":[{"atb":[[1.53,3.19]],"id":8509691}],"con":true,"img":false}]}
{"op":"mcm","clk":"1362445212","pt":1588451855378,"mc":[{"id":"1.170370564","rc":[{"atb":[[1.53,6.39]],"id":8509691}],"con":true,"img":false}]}
{"op":"mcm","clk":"1362445214","pt":1588451855735,"mc":[{"id":"1.170370564","rc":[{"trd":[[1.55,41.39]],"ltp":1.55,"tv":41.39,"id":8509691},{"atb":[[1.55,1.19]],"id":8509691},{"atl":[[1.55,0]],"id":8509691}],"con":true,"img":false}]}
{"op":"mcm","clk":"1362445216","pt":1588451856038,"mc":[{"id":"1.170370566","rc":[{"atl":[[1.38,0]],"id":9630572}],"con":true,"img":false}]}
{"op":"mcm","clk":"1362445217","pt":1588451856140,"mc":[{"id":"1.170370564","rc":[{"atb":[[1.28,93.18]],"id":8509691}],"con":true,"img":false}]}
{"op":"mcm","clk":"1362445225","pt":1588451857667,"mc":[{"id":"1.170370564","rc":[{"atl":[[1.64,0],[1.59,0],[1.6,0],[1.58,0],[1.62,0],[1.56,0],[1.63,0],[1.57,0],[1.61,0]],"id":8509691}],"con":true,"img":false}]}
{"op":"mcm","clk":"1362445236","pt":1588451859345,"mc":[{"id":"1.170370566","rc":[{"atl":[[1.34,17.59]],"id":9630572}],"con":true,"img":false}]}
{"op":"mcm","clk":"1362445267","pt":1588451864285,"mc":[{"id":"1.170370564","rc":[{"atb":[[2.2,10.79]],"id":9630572}],"con":true,"img":false}]}
{"op":"mcm","clk":"1362445276","pt":1588451866068,"mc":[{"id":"1.170370564","rc":[{"trd":[[2.8,1.78]],"ltp":2.8,"tv":1.78,"id":9630572},{"atb":[[2.8,3.22]],"id":9630572},{"trd":[[1.56,226.59]],"ltp":1.56,"tv":226.59,"id":8509691}],"con":true,"img":false}]}
{"op":"mcm","clk":"1362445279","pt":1588451866678,"mc":[{"id":"1.170370564","rc":[{"atb":[[1.55,4.39]],"id":8509691}],"con":true,"img":false}]}
{"op":"mcm","clk":"1362445281","pt":1588451866883,"mc":[{"id":"1.170370564","rc":[{"trd":[[2.8,3.56]],"ltp":2.8,"tv":3.56,"id":9630572},{"atb":[[2.8,1.44]],"id":9630572},{"trd":[[1.56,229.79]],"ltp":1.56,"tv":229.79,"id":8509691}],"con":true,"img":false}]}
{"op":"mcm","clk":"1362445285","pt":1588451867444,"mc":[{"id":"1.170370564","rc":[{"trd":[[2.8,5]],"ltp":2.8,"tv":5.0,"id":9630572},{"atb":[[2.8,0]],"id":9630572},{"trd":[[1.56,232.38]],"ltp":1.56,"tv":232.38,"id":8509691},{"atb":[[1.56,0.61]],"id":8509691}],"con":true,"img":false}]}
{"op":"mcm","clk":"1362445287","pt":1588451867851,"mc":[{"id":"1.170370564","rc":[{"atb":[[1.55,7.59]],"id":8509691}],"con":true,"img":false}]}
{"op":"mcm","clk":"1362445290","pt":1588451868259,"mc":[{"id":"1.170370564","rc":[{"atb":[[1.53,9.59]],"id":8509691}],"con":true,"img":false},{"id":"1.170370566","rc":[{"atb":[[1.05,25.33]],"id":9630572}],"con":true,"img":false}]}
{"op":"mcm","clk":"1362445299","pt":1588451869276,"mc":[{"id":"1.170370564","rc":[{"atb":[[1.52,3.19]],"id":8509691}],"con":true,"img":false}]}
{"op":"mcm","clk":"1362445303","pt":1588451869786,"mc":[{"id":"1.170370564","rc":[{"atb":[[1.51,3.19]],"id":8509691}],"con":true,"img":false}]}
{"op":"mcm","clk":"1362445313","pt":1588451870953,"mc":[{"id":"1.170370564","rc":[{"atb":[[1.56,3.81]],"id":8509691}],"con":true,"img":false}]}
{"op":"mcm","clk":"1362445324","pt":1588451871869,"mc":[{"id":"1.170370564","rc":[{"atb":[[1.38,0]],"id":8509691}],"con":true,"img":false}]}
{"op":"mcm","clk":"1362445355","pt":1588451876651,"mc":[{"id":"1.170370564","rc":[{"atb":[[1.54,3.19]],"id":8509691}],"con":true,"img":false}]}
{"op":"mcm","clk":"1362445359","pt":1588451876957,"mc":[{"id":"1.170370564","rc":[{"atb":[[1.56,7.01]],"id":8509691}],"con":true,"img":false}]}
{"op":"mcm","clk":"1362445361","pt":1588451877364,"mc":[{"id":"1.170370564","rc":[{"trd":[[1.55,43.36],[1.56,246.41]],"ltp":1.55,"tv":289.77,"id":8509691},{"atb":[[1.56,0],[1.55,6.61]],"id":8509691}],"con":true,"img":false}]}
{"op":"mcm","clk":"1362445386","pt":1588451880163,"mc":[{"id":"1.170370564","rc":[{"trd":[[1.55,45.25]],"ltp":1.55,"tv":45.25,"id":8509691},{"atb":[[1.55,5.67]],"id":8509691}],"con":true,"img":false}]}
{"op":"mcm","clk":"1362445403","pt":1588451882766,"mc":[{"id":"1.170370564","rc":[{"atl":[[1.67,3.5]],"id":8509691}],"con":true,"img":false}]}
{"op":"mcm","clk":"1362445433","pt":1588451885068,"mc":[{"id":"1.170370564","rc":[{"atb":[[2.8,100]],"id":9630572}],"con":true,"img":false}]}
{"op":"mcm","clk":"1362445449","pt":1588451887162,"mc":[{"id":"1.170370564","rc":[{"atl":[[1.65,117.89]],"id":8509691}],"con":true,"img":false}]}
{"op":"mcm","clk":"1362445454","pt":1588451888081,"mc":[{"id":"1.170370566","rc":[{"atb":[[3.9,0]],"id":8509691}],"con":true,"img":false}]}
{"op":"mcm","clk":"1362445463","pt":1588451889403,"mc":[{"id":"1.170370564","rc":[{"trd":[[2.8,6.78]],"ltp":2.8,"tv":6.78,"id":9630572},{"atb":[[2.8,98.22]],"id":9630572},{"trd":[[1.56,249.61]],"ltp":1.56,"tv":249.61,"id":8509691}],"con":true,"img":false}]}
{"op":"mcm","clk":"1362445475","pt":1588451890268,"mc":[{"id":"1.170370564","rc":[{"trd":[[2.8,8.56]],"ltp":2.8,"tv":8.56,"id":9630572},{"atb":[[2.8,96.44]],"id":9630572},{"trd":[[1.56,252.81]],"ltp":1.56,"tv":252.81,"id":8509691}],"con":true,"img":false}]}
{"op":"mcm","clk":"1362445476","pt":1588451890370,"mc":[{"id":"1.170370564","rc":[{"atb":[[1.45,3.19]],"id":8509691}],"con":true,"img":false}]}
{"op":"mcm","clk":"1362445482","pt":1588451890676,"mc":[{"id":"1.170370564","rc":[{"trd":[[2.8,10.34]],"ltp":2.8,"tv":10.34,"id":9630572},{"atb":[[2.8,94.66]],"id":9630572},{"trd":[[1.56,256.01]],"ltp":1.56,"tv":256.01,"id":8509691}],"con":true,"img":false}]}
{"op":"mcm","clk":"1362445493","pt":1588451892000,"mc":[{"id":"1.170370564","rc":[{"trd":[[1.55,56.59]],"ltp":1.55,"tv":56.59,"id":8509691},{"atb":[[1.55,0]],"id":8509691},{"atl":[[1.55,4.9]],"id":8509691}],"con":true,"img":false}]}
{"op":"mcm","clk":"1362445518","pt":1588451895408,"mc":[{"id":"1.170370564","rc":[{"atb":[[1.4,3]],"id":8509691}],"con":true,"img":false}]}
{"op":"mcm","clk":"1362445550","pt":1588451898768,"mc":[{"id":"1.170370564","rc":[{"atb":[[1.52,11.95]],"id":8509691}],"con":true,"img":false}]}
{"op":"mcm","clk":"1362445555","pt":1588451898972,"mc":[{"id":"1.170370566","rc":[{"trd":[[1.05,50.66]],"ltp":1.05,"tv":50.66,"id":9630572},{"atb":[[1.05,0]],"id":9630572},{"atl":[[1.05,3.53]],"id":9630572}],"con":true,"img":false}]}
{"op":"mcm","clk":"1362445561","pt":1588451899888,"mc":[{"id":"1.170370564","rc":[{"trd":[[1.55,56.8]],"ltp":1.55,"tv":56.8,"id":8509691},{"atl":[[1.55,4.8]],"id":8509691}],"con":true,"img":false}]}
{"op":"mcm","clk":"1362445579","pt":1588451903197,"mc":[{"id":"1.170370566","rc":[{"atl":[[1.05,0]],"id":9630572}],"con":true,"img":false}]}
{"op":"mcm","clk":"1362445587","pt":1588451904216,"mc":[{"id":"1.170370564","rc":[{"atb":[[1.39,3.19]],"id":8509691}],"con":true,"img":false}]}
{"op":"mcm","clk":"1362445589","pt":1588451904420,"mc":[{"id":"1.170370564","rc":[{"trd":[[2.8,48.34]],"ltp":2.8,"tv":48.34,"id":9630572},{"atb":[[2.8,75.66]],"id":9630572}],"con":true,"img":false}]}
{"op":"mcm","clk":"1362445601","pt":1588451907224,"mc":[{"id":"1.170370566","rc":[{"atb":[[1.05,45.09]],"id":9630572}],"con":true,"img":false}]}
{"op":"mcm","clk":"1362445608","pt":1588451908397,"mc":[{"id":"1.170370564","rc":[{"atl":[[1.65,0]],"id":8509691}],"con":true,"img":false}]}
{"op":"mcm","clk":"1362445618","pt":1588451909112,"mc":[{"id":"1.170370564","rc":[{"atl":[[1.55,0]],"id":8509691}],"con":true,"img":false}]}
{"op":"mcm","clk":"1362445621","pt":1588451909214,"mc":[{"id":"1.170370564","rc":[{"atl":[[1.55,0.1]],"id":8509691}],"con":true,"img":false}]}
{"op":"mcm","clk":"1362445628","pt":1588451910285,"mc":[{"id":"1.170370564","rc":[{"trd":[[1.55,57.01]],"ltp":1.55,"tv":57.01,"id":8509691},{"atb":[[1.55,8.91]],"id":8509691},{"atl":[[1.55,0]],"id":8509691}],"con":true,"img":false}]}
{"op":"mcm","clk":"1362445635","pt":1588451911304,"mc":[{"id":"1.170370564","rc":[{"atb":[[1.4,0]],"id":8509691}],"con":true,"img":false}]}
{"op":"mcm","clk":"1362445653","pt":1588451913902,"mc":[{"id":"1.170370566","rc":[{"atb":[[1.05,0]],"id":9630572}],"con":true,"img":false}]}
{"op":"mcm","clk":"1362445658","pt":1588451915124,"mc":[{"id":"1.170370564","rc":[{"atl":[[1.65,8.75]],"id":8509691}],"con":true,"img":false}]}
{"op":"mcm","clk":"1362445662","pt":1588451915429,"mc":[{"id":"1.170370566","rc":[{"atl":[[1.3,43.99]],"id":9630572}],"con":true,"img":false}]}
{"op":"mcm","clk":"1362445669","pt":1588451916398,"mc":[{"id":"1.170370564","rc":[{"atb":[[1.38,3]],"id":8509691}],"con":true,"img":false}]}
{"op":"mcm","clk":"1362445688","pt":1588451919044,"mc":[{"id":"1.170370566","rc":[{"atb":[[1.03,45.09]],"id":9630572}],"con":true,"img":false}]}
{"op":"mcm","clk":"1362445729","pt":1588451925826,"mc":[{"id":"1.170370564","rc":[{"atl":[[1.65,8.86]],"id":8509691}],"con":true,"img":false}]}
{"op":"mcm","clk":"1362445734","pt":1588451926438,"mc":[{"id":"1.170370564","rc":[{"atb":[[1.21,1.18]],"id":8509691}],"con":true,"img":false}]}
{"op":"mcm","clk":"1362445737","pt":1588451926641,"mc":[{"id":"1.170370564","rc":[{"atl":[[1.65,126.75]],"id":8509691}],"con":true,"img":false}]}
{"op":"mcm","clk":"1362445767","pt":1588451929239,"mc":[{"id":"1.170370564","rc":[{"atb":[[1.5,20.71]],"id":8509691}],"con":true,"img":false}]}
{"op":"mcm","clk":"1362445796","pt":1588451931935,"mc":[{"id":"1.170370566","rc":[{"trd":[[1.03,12.24]],"ltp":1.03,"tv":12.24,"id":9630572},{"atb":[[1.03,38.97]],"id":9630572}],"con":true,"img":false}]}
{"op":"mcm","clk":"1362445797","pt":1588451932037,"mc":[{"id":"1.170370564","rc":[{"atl":[[1.65,117.99]],"id":8509691}],"con":true,"img":false}]}
{"op":"mcm","clk":"1362445799","pt":1588451932140,"mc":[{"id":"1.170370564","rc":[{"atl":[[1.67,0]],"id":8509691}],"con":true,"img":false}]}
{"op":"mcm","clk":"1362445802","pt":1588451932343,"mc":[{"id":"1.170370564","rc":[{"atb":[[1.52,3.19],[1.5,3.19]],"id":8509691}],"con":true,"img":false}]}
{"op":"mcm","clk":"1362445803","pt":1588451932547,"mc":[{"id":"1.170370564","rc":[{"atb":[[1.28,5.59]],"id":8509691}],"con":true,"img":false}]}
{"op":"mcm","clk":"1362445808","pt":1588451933158,"mc":[{"id":"1.170370564","rc":[{"trd":[[2.8,97.73]],"ltp":2.8,"tv":97.73,"id":9630572},{"atb":[[2.8,26.27]],"id":9630572},{"trd":[[1.56,344.66]],"ltp":1.56,"tv":344.66,"id":8509691}],"con":true,"img":false}]}
{"op":"mcm","clk":"1362445811","pt":1588451933463,"mc":[{"id":"1.170370566","rc":[{"atl":[[1.34,0]],"id":9630572}],"con":true,"img":false}]}
{"op":"mcm","clk":"1362445819","pt":1588451934939,"mc":[{"id":"1.170370566","rc":[{"atl":[[1.3,0]],"id":9630572}],"con":true,"img":false}]}
{"op":"mcm","clk":"1362445835","pt":1588451936263,"mc":[{"id":"1.170370564","rc":[{"trd":[[2.8,122.43]],"ltp":2.8,"tv":122.43,"id":9630572},{"atb":[[2.8,1.57]],"id":9630572},{"trd":[[1.56,388.98]],"ltp":1.56,"tv":388.98,"id":8509691}],"con":true,"img":false}]}
{"op":"mcm","clk":"1362445842","pt":1588451937028,"mc":[{"id":"1.170370564","rc":[{"trd":[[2.8,122.51]],"ltp":2.8,"tv":122.51,"id":9630572},{"atb":[[2.8,1.49]],"id":9630572},{"trd":[[1.56,389.12]],"ltp":1.56,"tv":389.12,"id":8509691}],"con":true,"img":false}]}
