{"op":"mcm","clk":"1361153586","pt":1588396379827,"mc":[{"id":"1.170370557","marketDefinition":{"bspMarket":false,"turnInPlayEnabled":true,"persistenceEnabled":true,"marketBaseRate":5.0,"eventId":"29788106","eventTypeId":"2","numberOfWinners":1,"bettingType":"ODDS","marketType":"MATCH_ODDS","marketTime":"2020-05-02T09:40:00.000Z","suspendTime":"2020-05-02T09:40:00.000Z","bspReconciled":false,"complete":true,"inPlay":false,"crossMatching":false,"runnersVoidable":false,"numberOfActiveRunners":2,"betDelay":0,"status":"OPEN","runners":[{"status":"ACTIVE","sortPriority":1,"id":9624350,"name":"Y Hanfmann"},{"status":"ACTIVE","sortPriority":2,"id":9622734,"name":"D Brown"}],"regulators":["MR_INT"],"countryCode":"GB","discountAllowed":false,"timezone":"GMT","openDate":"2020-05-02T09:40:00.000Z","version":3237452693,"name":"Match Odds","eventName":"Y Hanfmann v D Brown"},"rc":[],"con":true,"img":false}]}
{"op":"mcm","clk":"1361153664","pt":1588396381826,"mc":[{"id":"1.170370557","marketDefinition":{"bspMarket":false,"turnInPlayEnabled":true,"persistenceEnabled":true,"marketBaseRate":5.0,"eventId":"29788106","eventTypeId":"2","numberOfWinners":1,"bettingType":"ODDS","marketType":"MATCH_ODDS","marketTime":"2020-05-02T09:40:00.000Z","suspendTime":"2020-05-02T09:40:00.000Z","bspReconciled":false,"complete":true,"inPlay":false,"crossMatching":false,"runnersVoidable":false,"numberOfActiveRunners":2,"betDelay":0,"status":"OPEN","runners":[{"status":"ACTIVE","sortPriority":1,"id":9624350,"name":"Y Hanfmann"},{"status":"ACTIVE","sortPriority":2,"id":9622734,"name":"D Brown"}],"regulators":["MR_INT"],"countryCode":"GB","discountAllowed":true,"timezone":"GMT","openDate":"2020-05-02T09:40:00.000Z","version":3237452693,"name":"Match Odds","eventName":"Y Hanfmann v D Brown"},"rc":[],"con":true,"img":false}]}
{"op":"mcm","clk":"1361157514","pt":1588396467442,"mc":[{"id":"1.170370557","rc":[{"atb":[[1.96,62.13]],"id":9622734},{"atb":[[1.35,108.67]],"id":9624350}],"con":true,"img":false}]}
{"op":"mcm","clk":"1361158890","pt":1588396513116,"mc":[{"id":"1.170370557","rc":[{"atb":[[1.36,35.19]],"id":9624350}],"con":true,"img":false}]}
{"op":"mcm","clk":"1361158893","pt":1588396513322,"mc":[{"id":"1.170370557","rc":[{"atb":[[1.35,0]],"id":9624350}],"con":true,"img":false}]}
{"op":"mcm","clk":"1361158898","pt":1588396513427,"mc":[{"id":"1.170370557","rc":[{"atb":[[1.42,103.13]],"id":9624350}],"con":true,"img":false}]}
{"op":"mcm","clk":"1361158903","pt":1588396513530,"mc":[{"id":"1.170370557","rc":[{"atb":[[2.18,22.39]],"id":9622734}],"con":true,"img":false}]}
{"op":"mcm","clk":"1361158905","pt":1588396513630,"mc":[{"id":"1.170370557","rc":[{"atb":[[1.96,0]],"id":9622734}],"con":true,"img":false}]}
{"op":"mcm","clk":"1361158910","pt":1588396513732,"mc":[{"id":"1.170370557","rc":[{"atb":[[2.2,55.12]],"id":9622734}],"con":true,"img":false}]}
{"op":"mcm","clk":"1361164145","pt":1588396679881,"mc":[{"id":"1.170370557","rc":[{"atb":[[1.36,20.79]],"id":9624350}],"con":true,"img":false}]}
{"op":"mcm","clk":"1361164157","pt":1588396680288,"mc":[{"id":"1.170370557","rc":[{"atb":[[2.18,13.59]],"id":9622734}],"con":true,"img":false}]}
{"op":"mcm","clk":"1361167278","pt":1588396778726,"mc":[{"id":"1.170370557","rc":[{"atl":[[990,1.59]],"id":9622734},{"atl":[[990,1.59]],"id":9624350}],"con":true,"img":false}]}
{"op":"mcm","clk":"1361169320","pt":1588396840181,"mc":[{"id":"1.170370557","rc":[{"atb":[[1.53,86.87]],"id":9624350}],"con":true,"img":false}]}
{"op":"mcm","clk":"1361169329","pt":1588396840447,"mc":[{"id":"1.170370557","rc":[{"atb":[[1.42,0]],"id":9624350}],"con":true,"img":false}]}
{"op":"mcm","clk":"1361170113","pt":1588396862497,"mc":[{"id":"1.170370557","rc":[{"atb":[[1.36,0]],"id":9624350}],"con":true,"img":false}]}
{"op":"mcm","clk":"1361170125","pt":1588396862810,"mc":[{"id":"1.170370557","rc":[{"atb":[[1.36,35.19]],"id":9624350}],"con":true,"img":false}]}
{"op":"mcm","clk":"1361170139","pt":1588396863068,"mc":[{"id":"1.170370557","rc":[{"atb":[[2.18,0]],"id":9622734}],"con":true,"img":false}]}
{"op":"mcm","clk":"1361170148","pt":1588396863278,"mc":[{"id":"1.170370557","rc":[{"atb":[[2.18,22.39]],"id":9622734}],"con":true,"img":false}]}
{"op":"mcm","clk":"1361170317","pt":1588396868434,"mc":[{"id":"1.170370557","marketDefinition":{"bspMarket":false,"turnInPlayEnabled":true,"persistenceEnabled":true,"marketBaseRate":5.0,"eventId":"29788106","eventTypeId":"2","numberOfWinners":1,"bettingType":"ODDS","marketType":"MATCH_ODDS","marketTime":"2020-05-02T09:40:00.000Z","suspendTime":"2020-05-02T09:40:00.000Z","bspReconciled":false,"complete":true,"inPlay":false,"crossMatching":true,"runnersVoidable":false,"numberOfActiveRunners":2,"betDelay":0,"status":"OPEN","runners":[{"status":"ACTIVE","sortPriority":1,"id":9624350,"name":"Y Hanfmann"},{"status":"ACTIVE","sortPriority":2,"id":9622734,"name":"D Brown"}],"regulators":["MR_INT"],"countryCode":"GB","discountAllowed":true,"timezone":"GMT","openDate":"2020-05-02T09:40:00.000Z","version":3237452693,"name":"Match Odds","eventName":"Y Hanfmann v D Brown"},"rc":[],"con":true,"img":false}]}
{"op":"mcm","clk":"1361176324","pt":1588397049063,"mc":[{"id":"1.170370557","rc":[{"atb":[[1.36,0]],"id":9624350}],"con":true,"img":false}]}
{"op":"mcm","clk":"1361176334","pt":1588397049270,"mc":[{"id":"1.170370557","rc":[{"atb":[[1.36,79.18]],"id":9624350}],"con":true,"img":false}]}
{"op":"mcm","clk":"1361176344","pt":1588397049578,"mc":[{"id":"1.170370557","rc":[{"atb":[[2.18,0]],"id":9622734}],"con":true,"img":false}]}
{"op":"mcm","clk":"1361176354","pt":1588397049887,"mc":[{"id":"1.170370557","rc":[{"atb":[[2.18,49.59]],"id":9622734}],"con":true,"img":false}]}
{"op":"mcm","clk":"1361176584","pt":1588397056270,"mc":[{"id":"1.170370557","rc":[{"atb":[[2.18,0]],"id":9622734},{"atb":[[1.36,0]],"id":9624350}],"con":true,"img":false}]}
{"op":"mcm","clk":"1361176588","pt":1588397056373,"mc":[{"id":"1.170370557","rc":[{"atb":[[2.2,104.71]],"id":9622734},{"atb":[[1.37,79.18]],"id":9624350}],"con":true,"img":false}]}
{"op":"mcm","clk":"1361181985","pt":1588397234341,"mc":[{"id":"1.170370557","rc":[{"atb":[[1.37,47.19]],"id":9624350}],"con":true,"img":false}]}
{"op":"mcm","clk":"1361181997","pt":1588397234600,"mc":[{"id":"1.170370557","rc":[{"atb":[[2.2,84.71]],"id":9622734}],"con":true,"img":false}]}
{"op":"mcm","clk":"1361182399","pt":1588397248754,"mc":[{"id":"1.170370557","rc":[{"atb":[[2.62,27.25]],"id":9622734},{"atb":[[1.44,100.33]],"id":9624350}],"con":true,"img":false}]}
{"op":"mcm","clk":"1361182408","pt":1588397249064,"mc":[{"id":"1.170370557","rc":[{"atb":[[2.2,29.59]],"id":9622734}],"con":true,"img":false}]}
{"op":"mcm","clk":"1361209411","pt":1588398140018,"mc":[{"id":"1.170370557","rc":[{"atb":[[1.37,0]],"id":9624350}],"con":true,"img":false}]}
{"op":"mcm","clk":"1361209416","pt":1588398140222,"mc":[{"id":"1.170370557","rc":[{"atb":[[1.37,78.38]],"id":9624350}],"con":true,"img":false}]}
{"op":"mcm","clk":"1361209423","pt":1588398140531,"mc":[{"id":"1.170370557","rc":[{"atb":[[2.2,0]],"id":9622734}],"con":true,"img":false}]}
{"op":"mcm","clk":"1361209427","pt":1588398140730,"mc":[{"id":"1.170370557","rc":[{"atb":[[2.2,49.59]],"id":9622734}],"con":true,"img":false}]}
{"op":"mcm","clk":"1361214694","pt":1588398290726,"mc":[{"id":"1.170370557","rc":[{"atb":[[1.1,121.58]],"id":9622734},{"atb":[[1.1,121.58]],"id":9624350}],"con":true,"img":false}]}
{"op":"mcm","clk":"1361235276","pt":1588399041135,"mc":[{"id":"1.170370557","rc":[{"atb":[[1.37,47.19]],"id":9624350}],"con":true,"img":false}]}
{"op":"mcm","clk":"1361235291","pt":1588399041396,"mc":[{"id":"1.170370557","rc":[{"atb":[[2.2,29.59]],"id":9622734}],"con":true,"img":false}]}
{"op":"mcm","clk":"1361240390","pt":1588399209163,"mc":[{"id":"1.170370557","rc":[{"atb":[[2.2,0]],"id":9622734},{"atb":[[1.37,0]],"id":9624350}],"con":true,"img":false}]}
{"op":"mcm","clk":"1361240392","pt":1588399209264,"mc":[{"id":"1.170370557","rc":[{"atb":[[2.16,29.59]],"id":9622734},{"atb":[[1.38,47.19]],"id":9624350}],"con":true,"img":false}]}
{"op":"mcm","clk":"1361263777","pt":1588399930874,"mc":[{"id":"1.170370557","rc":[{"atb":[[2.56,3.91]],"id":9622734}],"con":true,"img":false}]}
{"op":"mcm","clk":"1361263924","pt":1588399934878,"mc":[{"id":"1.170370557","rc":[{"atl":[[990,3.79]],"id":9622734},{"atl":[[990,3.79]],"id":9624350}],"con":true,"img":false}]}
{"op":"mcm","clk":"1361264323","pt":1588399945993,"mc":[{"id":"1.170370557","rc":[{"atb":[[1.38,0]],"id":9624350}],"con":true,"img":false}]}
{"op":"mcm","clk":"1361264330","pt":1588399946199,"mc":[{"id":"1.170370557","rc":[{"atb":[[1.38,78.38]],"id":9624350}],"con":true,"img":false}]}
{"op":"mcm","clk":"1361264338","pt":1588399946456,"mc":[{"id":"1.170370557","rc":[{"atb":[[2.16,0]],"id":9622734}],"con":true,"img":false}]}
{"op":"mcm","clk":"1361264346","pt":1588399946661,"mc":[{"id":"1.170370557","rc":[{"atb":[[2.16,50.39]],"id":9622734}],"con":true,"img":false}]}
{"op":"mcm","clk":"1361271173","pt":1588400127527,"mc":[{"id":"1.170370557","rc":[{"atb":[[1.38,47.19]],"id":9624350}],"con":true,"img":false}]}
{"op":"mcm","clk":"1361271184","pt":1588400127836,"mc":[{"id":"1.170370557","rc":[{"atb":[[2.16,30.39]],"id":9622734}],"con":true,"img":false}]}
{"op":"mcm","clk":"1361281861","pt":1588400489097,"mc":[{"id":"1.170370557","rc":[{"atb":[[1.38,0]],"id":9624350}],"con":true,"img":false}]}
{"op":"mcm","clk":"1361281871","pt":1588400489305,"mc":[{"id":"1.170370557","rc":[{"atb":[[1.38,78.38]],"id":9624350}],"con":true,"img":false}]}
{"op":"mcm","clk":"1361281883","pt":1588400489616,"mc":[{"id":"1.170370557","rc":[{"atb":[[2.16,0]],"id":9622734}],"con":true,"img":false}]}
{"op":"mcm","clk":"1361281894","pt":1588400489821,"mc":[{"id":"1.170370557","rc":[{"atb":[[2.16,50.39]],"id":9622734}],"con":true,"img":false}]}
{"op":"mcm","clk":"1361286907","pt":1588400670757,"mc":[{"id":"1.170370557","rc":[{"atb":[[1.38,47.19]],"id":9624350}],"con":true,"img":false}]}
{"op":"mcm","clk":"1361286912","pt":1588400671068,"mc":[{"id":"1.170370557","rc":[{"atb":[[2.16,30.39]],"id":9622734}],"con":true,"img":false}]}
{"op":"mcm","clk":"1361297047","pt":1588401032321,"mc":[{"id":"1.170370557","rc":[{"atb":[[1.38,0]],"id":9624350}],"con":true,"img":false}]}
{"op":"mcm","clk":"1361297053","pt":1588401032477,"mc":[{"id":"1.170370557","rc":[{"atb":[[1.38,78.38]],"id":9624350}],"con":true,"img":false}]}
{"op":"mcm","clk":"1361300852","pt":1588401177798,"mc":[{"id":"1.170370557","rc":[{"atb":[[2.56,0]],"id":9622734}],"con":true,"img":false}]}
{"op":"mcm","clk":"1361300857","pt":1588401177901,"mc":[{"id":"1.170370557","rc":[{"atb":[[2.64,3.91]],"id":9622734}],"con":true,"img":false}]}
{"op":"mcm","clk":"1361301760","pt":1588401213862,"mc":[{"id":"1.170370557","rc":[{"atb":[[2.16,0]],"id":9622734}],"con":true,"img":false}]}
{"op":"mcm","clk":"1361301766","pt":1588401214068,"mc":[{"id":"1.170370557","rc":[{"atb":[[2.16,50.39]],"id":9622734}],"con":true,"img":false}]}
{"op":"mcm","clk":"1361308027","pt":1588401574943,"mc":[{"id":"1.170370557","rc":[{"atb":[[1.38,47.19]],"id":9624350}],"con":true,"img":false}]}
{"op":"mcm","clk":"1361308033","pt":1588401575251,"mc":[{"id":"1.170370557","rc":[{"atb":[[2.16,30.39]],"id":9622734}],"con":true,"img":false}]}
{"op":"mcm","clk":"1361309049","pt":1588401636923,"mc":[{"id":"1.170370557","rc":[{"atl":[[990,2.2]],"id":9622734},{"atl":[[990,2.2]],"id":9624350}],"con":true,"img":false}]}
{"op":"mcm","clk":"1361315406","pt":1588401935562,"mc":[{"id":"1.170370557","rc":[{"atb":[[1.38,0]],"id":9624350}],"con":true,"img":false}]}
{"op":"mcm","clk":"1361315410","pt":1588401935770,"mc":[{"id":"1.170370557","rc":[{"atb":[[1.38,78.38]],"id":9624350}],"con":true,"img":false}]}
{"op":"mcm","clk":"1361315413","pt":1588401936074,"mc":[{"id":"1.170370557","rc":[{"atb":[[2.16,0]],"id":9622734}],"con":true,"img":false}]}
{"op":"mcm","clk":"1361315416","pt":1588401936236,"mc":[{"id":"1.170370557","rc":[{"atb":[[2.16,50.39]],"id":9622734}],"con":true,"img":false}]}
{"op":"mcm","clk":"1361319348","pt":1588402116504,"mc":[{"id":"1.170370557","rc":[{"atb":[[1.38,47.19]],"id":9624350}],"con":true,"img":false}]}
{"op":"mcm","clk":"1361319360","pt":1588402116810,"mc":[{"id":"1.170370557","rc":[{"atb":[[2.16,30.39]],"id":9622734}],"con":true,"img":false}]}
{"op":"mcm","clk":"1361327643","pt":1588402404504,"mc":[{"id":"1.170370557","rc":[{"atb":[[1.11,31.99]],"id":9622734},{"atb":[[1.11,31.99]],"id":9624350}],"con":true,"img":false}]}
{"op":"mcm","clk":"1361328108","pt":1588402418188,"mc":[{"id":"1.170370557","rc":[{"atb":[[1.25,12.79]],"id":9624350},{"atl":[[2.1,3.19]],"id":9624350}],"con":true,"img":false}]}
{"op":"mcm","clk":"1361329443","pt":1588402461886,"mc":[{"id":"1.170370557","rc":[{"atb":[[1.01,4.79]],"id":9622734},{"atb":[[1.01,4.79]],"id":9624350}],"con":true,"img":false}]}
{"op":"mcm","clk":"1361359173","pt":1588403198689,"mc":[{"id":"1.170370557","rc":[{"atb":[[1.38,0]],"id":9624350}],"con":true,"img":false}]}
{"op":"mcm","clk":"1361359180","pt":1588403198894,"mc":[{"id":"1.170370557","rc":[{"atb":[[1.38,78.38]],"id":9624350}],"con":true,"img":false}]}
{"op":"mcm","clk":"1361359188","pt":1588403199097,"mc":[{"id":"1.170370557","rc":[{"atb":[[2.16,0]],"id":9622734}],"con":true,"img":false}]}
{"op":"mcm","clk":"1361359195","pt":1588403199301,"mc":[{"id":"1.170370557","rc":[{"atb":[[2.16,50.39]],"id":9622734}],"con":true,"img":false}]}
{"op":"mcm","clk":"1361365681","pt":1588403380163,"mc":[{"id":"1.170370557","rc":[{"atb":[[1.38,47.19]],"id":9624350}],"con":true,"img":false}]}
{"op":"mcm","clk":"1361365693","pt":1588403380421,"mc":[{"id":"1.170370557","rc":[{"atb":[[2.16,30.39]],"id":9622734}],"con":true,"img":false}]}
{"op":"mcm","clk":"1361368387","pt":1588403463880,"mc":[{"id":"1.170370557","rc":[{"trd":[[2.64,7.09]],"ltp":2.64,"tv":7.09,"id":9622734},{"atb":[[2.64,0.36]],"id":9622734}],"con":true,"img":false}]}
{"op":"mcm","clk":"1361368707","pt":1588403473199,"mc":[{"id":"1.170370557","rc":[{"trd":[[2.62,27.64],[2.64,7.81]],"ltp":2.62,"tv":35.45,"id":9622734},{"atb":[[2.64,0],[2.62,13.43]],"id":9622734}],"con":true,"img":false}]}
{"op":"mcm","clk":"1361368747","pt":1588403474595,"mc":[{"id":"1.170370557","rc":[{"atb":[[2.62,40.68]],"id":9622734}],"con":true,"img":false}]}
{"op":"mcm","clk":"1361368753","pt":1588403474697,"mc":[{"id":"1.170370557","rc":[{"atb":[[2.62,27.25]],"id":9622734}],"con":true,"img":false}]}
{"op":"mcm","clk":"1361431714","pt":1588405087656,"mc":[{"id":"1.170370557","marketDefinition":{"bspMarket":false,"turnInPlayEnabled":true,"persistenceEnabled":true,"marketBaseRate":5.0,"eventId":"29788106","eventTypeId":"2","numberOfWinners":1,"bettingType":"ODDS","marketType":"MATCH_ODDS","marketTime":"2020-05-02T11:00:00.000Z","suspendTime":"2020-05-02T11:00:00.000Z","bspReconciled":false,"complete":true,"inPlay":false,"crossMatching":true,"runnersVoidable":false,"numberOfActiveRunners":2,"betDelay":0,"status":"OPEN","runners":[{"status":"ACTIVE","sortPriority":1,"id":9624350,"name":"Y Hanfmann"},{"status":"ACTIVE","sortPriority":2,"id":9622734,"name":"D Brown"}],"regulators":["MR_INT"],"countryCode":"GB","discountAllowed":true,"timezone":"GMT","openDate":"2020-05-02T09:40:00.000Z","version":3237462492,"name":"Match Odds","eventName":"Y Hanfmann v D Brown"},"rc":[],"con":true,"img":false}]}
{"op":"mcm","clk":"1361431877","pt":1588405091654,"mc":[{"id":"1.170370557","marketDefinition":{"bspMarket":false,"turnInPlayEnabled":true,"persistenceEnabled":true,"marketBaseRate":5.0,"eventId":"29788106","eventTypeId":"2","numberOfWinners":1,"bettingType":"ODDS","marketType":"MATCH_ODDS","marketTime":"2020-05-02T11:00:00.000Z","suspendTime":"2020-05-02T11:00:00.000Z","bspReconciled":false,"complete":true,"inPlay":false,"crossMatching":true,"runnersVoidable":false,"numberOfActiveRunners":2,"betDelay":0,"status":"OPEN","runners":[{"status":"ACTIVE","sortPriority":1,"id":9624350,"name":"Y Hanfmann"},{"status":"ACTIVE","sortPriority":2,"id":9622734,"name":"D Brown"}],"regulators":["MR_INT"],"countryCode":"GB","discountAllowed":true,"timezone":"GMT","openDate":"2020-05-02T11:00:00.000Z","version":3237462492,"name":"Match Odds","eventName":"Y Hanfmann v D Brown"},"rc":[],"con":true,"img":false}]}
{"op":"mcm","clk":"1361435317","pt":1588405173357,"mc":[{"id":"1.170370557","rc":[{"atb":[[2.16,0]],"id":9622734},{"atb":[[1.38,0]],"id":9624350}],"con":true,"img":false}]}
{"op":"mcm","clk":"1361461654","pt":1588405817783,"mc":[{"id":"1.170370557","rc":[{"atl":[[2.8,1.77]],"id":9622734}],"con":true,"img":false}]}
{"op":"mcm","clk":"1361480805","pt":1588406340430,"mc":[{"id":"1.170370557","rc":[{"trd":[[2.8,1.77]],"ltp":2.8,"tv":1.77,"id":9622734},{"atl":[[2.8,0]],"id":9622734},{"trd":[[1.55,3.19]],"ltp":1.55,"tv":3.19,"id":9624350},{"atl":[[1.55,5.59]],"id":9624350}],"con":true,"img":false}]}
{"op":"mcm","clk":"1361483622","pt":1588406383678,"mc":[{"id":"1.170370557","rc":[{"atl":[[1.54,8.79]],"id":9624350}],"con":true,"img":false}]}
{"op":"mcm","clk":"1361484794","pt":1588406410920,"mc":[{"id":"1.170370557","rc":[{"atb":[[2.72,1.82]],"id":9622734}],"con":true,"img":false}]}
{"op":"mcm","clk":"1361485140","pt":1588406421024,"mc":[{"id":"1.170370557","rc":[{"trd":[[1.53,87.98]],"ltp":1.53,"tv":87.98,"id":9624350},{"atb":[[1.53,42.89]],"id":9624350}],"con":true,"img":false}]}
{"op":"mcm","clk":"1361485965","pt":1588406441146,"mc":[{"id":"1.170370557","rc":[{"trd":[[1.53,173.76]],"ltp":1.53,"tv":173.76,"id":9624350},{"atb":[[1.53,0]],"id":9624350},{"atl":[[1.53,1.1]],"id":9624350}],"con":true,"img":false}]}
{"op":"mcm","clk":"1361485976","pt":1588406441460,"mc":[{"id":"1.170370557","rc":[{"atb":[[1.47,105.01]],"id":9624350}],"con":true,"img":false}]}
{"op":"mcm","clk":"1361486586","pt":1588406454962,"mc":[{"id":"1.170370557","rc":[{"atb":[[1.48,35.19]],"id":9624350}],"con":true,"img":false}]}
{"op":"mcm","clk":"1361486596","pt":1588406455168,"mc":[{"id":"1.170370557","rc":[{"atb":[[1.47,0]],"id":9624350}],"con":true,"img":false}]}
{"op":"mcm","clk":"1361486600","pt":1588406455265,"mc":[{"id":"1.170370557","rc":[{"atb":[[1.48,139.7]],"id":9624350}],"con":true,"img":false}]}
{"op":"mcm","clk":"1361487338","pt":1588406471567,"mc":[{"id":"1.170370557","rc":[{"atb":[[1.47,26.39]],"id":9624350}],"con":true,"img":false}]}
{"op":"mcm","clk":"1361487605","pt":1588406477198,"mc":[{"id":"1.170370557","rc":[{"atb":[[1.26,61.52]],"id":9624350}],"con":true,"img":false}]}
{"op":"mcm","clk":"1361487618","pt":1588406477397,"mc":[{"id":"1.170370557","rc":[{"atb":[[1.26,123.05]],"id":9624350}],"con":true,"img":false}]}
{"op":"mcm","clk":"1361487631","pt":1588406477602,"mc":[{"id":"1.170370557","rc":[{"atb":[[1.26,184.57]],"id":9624350}],"con":true,"img":false}]}
{"op":"mcm","clk":"1361487644","pt":1588406477802,"mc":[{"id":"1.170370557","rc":[{"atb":[[1.26,246.1]],"id":9624350}],"con":true,"img":false}]}
{"op":"mcm","clk":"1361487874","pt":1588406482509,"mc":[{"id":"1.170370557","rc":[{"atb":[[1.4,99.98]],"id":9622734}],"con":true,"img":false}]}
{"op":"mcm","clk":"1361487881","pt":1588406482714,"mc":[{"id":"1.170370557","rc":[{"atb":[[1.4,199.96]],"id":9622734}],"con":true,"img":false}]}
{"op":"mcm","clk":"1361487946","pt":1588406484215,"mc":[{"id":"1.170370557","rc":[{"atb":[[1.4,299.95]],"id":9622734}],"con":true,"img":false}]}
{"op":"mcm","clk":"1361488143","pt":1588406489523,"mc":[{"id":"1.170370557","rc":[{"atb":[[1.47,106.38]],"id":9624350}],"con":true,"img":false}]}
{"op":"mcm","clk":"1361488151","pt":1588406489728,"mc":[{"id":"1.170370557","rc":[{"atb":[[2.38,79.98]],"id":9622734}],"con":true,"img":false}]}
{"op":"mcm","clk":"1361494870","pt":1588406680829,"mc":[{"id":"1.170370557","rc":[{"atb":[[1.48,35.19]],"id":9624350}],"con":true,"img":false}]}
{"op":"mcm","clk":"1361495068","pt":1588406685908,"mc":[{"id":"1.170370557","rc":[{"atb":[[1.47,26.39]],"id":9624350}],"con":true,"img":false}]}
{"op":"mcm","clk":"1361495088","pt":1588406686424,"mc":[{"id":"1.170370557","rc":[{"atb":[[2.38,0]],"id":9622734}],"con":true,"img":false}]}
{"op":"mcm","clk":"1361495093","pt":1588406686526,"mc":[{"id":"1.170370557","rc":[{"atb":[[2.4,79.98]],"id":9622734}],"con":true,"img":false}]}
{"op":"mcm","clk":"1361495143","pt":1588406687718,"mc":[{"id":"1.170370557","rc":[{"atb":[[1.45,39.99]],"id":9624350}],"con":true,"img":false}]}
{"op":"mcm","clk":"1361500184","pt":1588406804521,"mc":[{"id":"1.170370557","rc":[{"atb":[[2.4,39.99]],"id":9622734}],"con":true,"img":false}]}
{"op":"mcm","clk":"1361573134","pt":1588408504888,"mc":[{"id":"1.170370557","rc":[{"atb":[[1.45,0]],"id":9624350}],"con":true,"img":false}]}
{"op":"mcm","clk":"1361590403","pt":1588408868539,"mc":[{"id":"1.170370557","rc":[{"atb":[[1.01,6.57]],"id":9622734},{"atb":[[1.01,6.57]],"id":9624350}],"con":true,"img":false}]}
{"op":"mcm","clk":"1361590412","pt":1588408868746,"mc":[{"id":"1.170370557","rc":[{"atb":[[1.01,5.01]],"id":9622734},{"atb":[[1.01,5.01]],"id":9624350}],"con":true,"img":false}]}
{"op":"mcm","clk":"1361590420","pt":1588408868951,"mc":[{"id":"1.170370557","rc":[{"atb":[[1.01,4.79]],"id":9622734},{"atb":[[1.01,4.79]],"id":9624350}],"con":true,"img":false}]}
{"op":"mcm","clk":"1361590426","pt":1588408869054,"mc":[{"id":"1.170370557","rc":[{"atb":[[1.02,0.21]],"id":9622734},{"atb":[[1.02,0.21]],"id":9624350}],"con":true,"img":false}]}
{"op":"mcm","clk":"1361610967","pt":1588409408060,"mc":[{"id":"1.170370557","marketDefinition":{"bspMarket":false,"turnInPlayEnabled":true,"persistenceEnabled":true,"marketBaseRate":5.0,"eventId":"29788106","eventTypeId":"2","numberOfWinners":1,"bettingType":"ODDS","marketType":"MATCH_ODDS","marketTime":"2020-05-02T11:40:00.000Z","suspendTime":"2020-05-02T11:40:00.000Z","bspReconciled":false,"complete":true,"inPlay":false,"crossMatching":true,"runnersVoidable":false,"numberOfActiveRunners":2,"betDelay":0,"status":"OPEN","runners":[{"status":"ACTIVE","sortPriority":1,"id":9624350,"name":"Y Hanfmann"},{"status":"ACTIVE","sortPriority":2,"id":9622734,"name":"D Brown"}],"regulators":["MR_INT"],"countryCode":"GB","discountAllowed":true,"timezone":"GMT","openDate":"2020-05-02T11:00:00.000Z","version":3237467758,"name":"Match Odds","eventName":"Y Hanfmann v D Brown"},"rc":[],"con":true,"img":false}]}
{"op":"mcm","clk":"1361611055","pt":1588409412064,"mc":[{"id":"1.170370557","marketDefinition":{"bspMarket":false,"turnInPlayEnabled":true,"persistenceEnabled":true,"marketBaseRate":5.0,"eventId":"29788106","eventTypeId":"2","numberOfWinners":1,"bettingType":"ODDS","marketType":"MATCH_ODDS","marketTime":"2020-05-02T11:40:00.000Z","suspendTime":"2020-05-02T11:40:00.000Z","bspReconciled":false,"complete":true,"inPlay":false,"crossMatching":true,"runnersVoidable":false,"numberOfActiveRunners":2,"betDelay":0,"status":"OPEN","runners":[{"status":"ACTIVE","sortPriority":1,"id":9624350,"name":"Y Hanfmann"},{"status":"ACTIVE","sortPriority":2,"id":9622734,"name":"D Brown"}],"regulators":["MR_INT"],"countryCode":"GB","discountAllowed":true,"timezone":"GMT","openDate":"2020-05-02T11:40:00.000Z","version":3237467758,"name":"Match Odds","eventName":"Y Hanfmann v D Brown"},"rc":[],"con":true,"img":false}]}
{"op":"mcm","clk":"1361611115","pt":1588409414632,"mc":[{"id":"1.170370557","rc":[{"atb":[[2.4,0]],"id":9622734}],"con":true,"img":false}]}
{"op":"mcm","clk":"1361613692","pt":1588409523949,"mc":[{"id":"1.170370557","rc":[{"trd":[[2.84,2.69],[2.88,0.58]],"ltp":2.84,"tv":3.27,"id":9622734},{"trd":[[1.54,4.96],[1.53,174.86]],"ltp":1.54,"tv":179.82,"id":9624350},{"atl":[[1.54,3.83],[1.53,0]],"id":9624350}],"con":true,"img":false}]}
{"op":"mcm","clk":"1361627319","pt":1588409896817,"mc":[{"id":"1.170370557","rc":[{"atb":[[1.45,6.99]],"id":9624350}],"con":true,"img":false}]}
{"op":"mcm","clk":"1361635040","pt":1588410030821,"mc":[{"id":"1.170370557","rc":[{"atb":[[1.44,140.32]],"id":9624350}],"con":true,"img":false}]}
{"op":"mcm","clk":"1361635052","pt":1588410031029,"mc":[{"id":"1.170370557","rc":[{"atb":[[2.46,39.99]],"id":9622734}],"con":true,"img":false}]}
{"op":"mcm","clk":"1361646136","pt":1588410247622,"mc":[{"id":"1.170370557","rc":[{"trd":[[1.54,12.62]],"ltp":1.54,"tv":12.62,"id":9624350},{"atb":[[1.54,40.05]],"id":9624350},{"atl":[[1.54,0]],"id":9624350}],"con":true,"img":false}]}
{"op":"mcm","clk":"1361646418","pt":1588410252924,"mc":[{"id":"1.170370557","rc":[{"atb":[[1.54,0]],"id":9624350}],"con":true,"img":false}]}
{"op":"mcm","clk":"1361646421","pt":1588410253028,"mc":[{"id":"1.170370557","rc":[{"trd":[[1.55,14.4]],"ltp":1.55,"tv":14.4,"id":9624350},{"atb":[[1.55,34.45]],"id":9624350},{"atl":[[1.55,0]],"id":9624350}],"con":true,"img":false}]}
{"op":"mcm","clk":"1361646669","pt":1588410257418,"mc":[{"id":"1.170370557","rc":[{"atb":[[1.55,0]],"id":9624350}],"con":true,"img":false}]}
{"op":"mcm","clk":"1361646673","pt":1588410257522,"mc":[{"id":"1.170370557","rc":[{"trd":[[2.72,1.82]],"ltp":2.72,"tv":1.82,"id":9622734},{"atb":[[2.72,0]],"id":9622734},{"trd":[[1.59,3.12]],"ltp":1.59,"tv":3.12,"id":9624350},{"atb":[[1.59,31.32]],"id":9624350}],"con":true,"img":false}]}
{"op":"mcm","clk":"1361646893","pt":1588410261855,"mc":[{"id":"1.170370557","rc":[{"atb":[[1.59,0]],"id":9624350}],"con":true,"img":false}]}
{"op":"mcm","clk":"1361646898","pt":1588410261960,"mc":[{"id":"1.170370557","rc":[{"trd":[[2.62,47.01]],"ltp":2.62,"tv":47.01,"id":9622734},{"atb":[[2.62,7.88]],"id":9622734},{"trd":[[1.62,31.32]],"ltp":1.62,"tv":31.32,"id":9624350}],"con":true,"img":false}]}
{"op":"mcm","clk":"1361647048","pt":1588410264869,"mc":[{"id":"1.170370557","rc":[{"atb":[[2.46,70.22],[2.62,0]],"id":9622734}],"con":true,"img":false}]}
{"op":"mcm","clk":"1361647058","pt":1588410265074,"mc":[{"id":"1.170370557","rc":[{"atb":[[2.48,53.01]],"id":9622734}],"con":true,"img":false}]}
{"op":"mcm","clk":"1361652487","pt":1588410363478,"mc":[{"id":"1.170370557","rc":[{"trd":[[1.48,3.99]],"ltp":1.48,"tv":3.99,"id":9624350},{"atb":[[1.48,33.19]],"id":9624350}],"con":true,"img":false}]}
{"op":"mcm","clk":"1361652984","pt":1588410374515,"mc":[{"id":"1.170370557","rc":[{"atl":[[2.8,1.77]],"id":9622734}],"con":true,"img":false}]}
{"op":"mcm","clk":"1361653739","pt":1588410392934,"mc":[{"id":"1.170370557","rc":[{"atb":[[1.45,42.54]],"id":9624350}],"con":true,"img":false}]}
{"op":"mcm","clk":"1361654814","pt":1588410418110,"mc":[{"id":"1.170370557","rc":[{"atb":[[2.5,3.53]],"id":9622734}],"con":true,"img":false}]}
{"op":"mcm","clk":"1361654826","pt":1588410418315,"mc":[{"id":"1.170370557","rc":[{"atb":[[2.48,0]],"id":9622734}],"con":true,"img":false}]}
{"op":"mcm","clk":"1361654830","pt":1588410418418,"mc":[{"id":"1.170370557","rc":[{"atb":[[2.5,56.25]],"id":9622734}],"con":true,"img":false}]}
{"op":"mcm","clk":"1361654841","pt":1588410418675,"mc":[{"id":"1.170370557","rc":[{"atb":[[1.9,44.44]],"id":9622734}],"con":true,"img":false}]}
{"op":"mcm","clk":"1361659611","pt":1588410539027,"mc":[{"id":"1.170370557","rc":[{"atb":[[1.45,35.54]],"id":9624350}],"con":true,"img":false}]}
{"op":"mcm","clk":"1361663165","pt":1588410637754,"mc":[{"id":"1.170370557","rc":[{"atb":[[2.5,52.72]],"id":9622734}],"con":true,"img":false}]}
{"op":"mcm","clk":"1361663169","pt":1588410637854,"mc":[{"id":"1.170370557","rc":[{"atb":[[2.48,3.53]],"id":9622734}],"con":true,"img":false}]}
{"op":"mcm","clk":"1361667359","pt":1588410811408,"mc":[{"id":"1.170370557","rc":[{"atb":[[2.48,0]],"id":9622734}],"con":true,"img":false}]}
{"op":"mcm","clk":"1361676827","pt":1588411147662,"mc":[{"id":"1.170370557","rc":[{"atl":[[1.58,2]],"id":9624350}],"con":true,"img":false}]}
{"op":"mcm","clk":"1361677268","pt":1588411160759,"mc":[{"id":"1.170370557","rc":[{"atl":[[1.58,0]],"id":9624350}],"con":true,"img":false}]}
{"op":"mcm","clk":"1361677421","pt":1588411165462,"mc":[{"id":"1.170370557","rc":[{"atb":[[1.65,2]],"id":9624350}],"con":true,"img":false}]}
{"op":"mcm","clk":"1361677425","pt":1588411165566,"mc":[{"id":"1.170370557","rc":[{"trd":[[1.65,4]],"ltp":1.65,"tv":4.0,"id":9624350},{"atb":[[1.65,0]],"id":9624350}],"con":true,"img":false}]}
{"op":"mcm","clk":"1361677784","pt":1588411176191,"mc":[{"id":"1.170370557","rc":[{"atb":[[1.63,2]],"id":9624350}],"con":true,"img":false}]}
{"op":"mcm","clk":"1361678445","pt":1588411195409,"mc":[{"id":"1.170370557","rc":[{"atb":[[2.46,30.23]],"id":9622734}],"con":true,"img":false}]}
{"op":"mcm","clk":"1361678461","pt":1588411195925,"mc":[{"id":"1.170370557","rc":[{"atb":[[1.63,0]],"id":9624350}],"con":true,"img":false}]}
{"op":"mcm","clk":"1361678650","pt":1588411201627,"mc":[{"id":"1.170370557","rc":[{"atl":[[1.56,2]],"id":9624350}],"con":true,"img":false}]}
{"op":"mcm","clk":"1361679009","pt":1588411210139,"mc":[{"id":"1.170370557","rc":[{"trd":[[2.8,3.2]],"ltp":2.8,"tv":3.2,"id":9622734},{"atl":[[2.8,0.33]],"id":9622734},{"trd":[[1.55,16.98]],"ltp":1.55,"tv":16.98,"id":9624350},{"atb":[[1.54,2.6]],"id":9624350}],"con":true,"img":false}]}
{"op":"mcm","clk":"1361679285","pt":1588411216652,"mc":[{"id":"1.170370557","rc":[{"atl":[[1.56,0]],"id":9624350}],"con":true,"img":false}]}
{"op":"mcm","clk":"1361679518","pt":1588411222564,"mc":[{"id":"1.170370557","rc":[{"atb":[[1.64,2]],"id":9624350}],"con":true,"img":false}]}
{"op":"mcm","clk":"1361680145","pt":1588411238740,"mc":[{"id":"1.170370557","rc":[{"atb":[[1.64,0]],"id":9624350}],"con":true,"img":false}]}
{"op":"mcm","clk":"1361680441","pt":1588411246696,"mc":[{"id":"1.170370557","rc":[{"atl":[[1.56,2]],"id":9624350}],"con":true,"img":false}]}
{"op":"mcm","clk":"1361681042","pt":1588411263024,"mc":[{"id":"1.170370557","rc":[{"atl":[[1.56,0]],"id":9624350}],"con":true,"img":false}]}
{"op":"mcm","clk":"1361681348","pt":1588411271300,"mc":[{"id":"1.170370557","rc":[{"atb":[[1.64,2]],"id":9624350}],"con":true,"img":false}]}
{"op":"mcm","clk":"1361682004","pt":1588411288752,"mc":[{"id":"1.170370557","rc":[{"atb":[[1.64,0]],"id":9624350}],"con":true,"img":false}]}
{"op":"mcm","clk":"1361682242","pt":1588411295854,"mc":[{"id":"1.170370557","rc":[{"atl":[[1.56,2]],"id":9624350}],"con":true,"img":false}]}
{"op":"mcm","clk":"1361682794","pt":1588411309762,"mc":[{"id":"1.170370557","rc":[{"atl":[[1.56,0]],"id":9624350}],"con":true,"img":false}]}
{"op":"mcm","clk":"1361683094","pt":1588411317755,"mc":[{"id":"1.170370557","rc":[{"atb":[[1.64,2]],"id":9624350}],"con":true,"img":false}]}
{"op":"mcm","clk":"1361683940","pt":1588411336590,"mc":[{"id":"1.170370557","rc":[{"atb":[[1.64,0]],"id":9624350}],"con":true,"img":false}]}
{"op":"mcm","clk":"1361684152","pt":1588411341795,"mc":[{"id":"1.170370557","rc":[{"atl":[[1.56,2]],"id":9624350}],"con":true,"img":false}]}
{"op":"mcm","clk":"1361684807","pt":1588411356600,"mc":[{"id":"1.170370557","rc":[{"atl":[[1.56,0]],"id":9624350}],"con":true,"img":false}]}
{"op":"mcm","clk":"1361685088","pt":1588411362826,"mc":[{"id":"1.170370557","rc":[{"atb":[[1.64,2]],"id":9624350}],"con":true,"img":false}]}
{"op":"mcm","clk":"1361685577","pt":1588411373729,"mc":[{"id":"1.170370557","rc":[{"atb":[[1.64,0]],"id":9624350}],"con":true,"img":false}]}
{"op":"mcm","clk":"1361685931","pt":1588411380833,"mc":[{"id":"1.170370557","rc":[{"trd":[[2.8,3.88]],"ltp":2.8,"tv":3.88,"id":9622734},{"atb":[[2.8,3.19]],"id":9622734},{"atl":[[2.8,0]],"id":9622734}],"con":true,"img":false}]}
{"op":"mcm","clk":"1361685935","pt":1588411380936,"mc":[{"id":"1.170370557","rc":[{"atb":[[2.5,0]],"id":9622734}],"con":true,"img":false}]}
{"op":"mcm","clk":"1361685949","pt":1588411381142,"mc":[{"id":"1.170370557","rc":[{"atl":[[1.56,2]],"id":9624350}],"con":true,"img":false}]}
{"op":"mcm","clk":"1361686227","pt":1588411386529,"mc":[{"id":"1.170370557","rc":[{"atb":[[2.8,0]],"id":9622734}],"con":true,"img":false}]}
{"op":"mcm","clk":"1361686238","pt":1588411386737,"mc":[{"id":"1.170370557","rc":[{"atb":[[2.46,82.61]],"id":9622734}],"con":true,"img":false}]}
{"op":"mcm","clk":"1361686418","pt":1588411390253,"mc":[{"id":"1.170370557","rc":[{"atl":[[1.56,0]],"id":9624350}],"con":true,"img":false}]}
{"op":"mcm","clk":"1361687470","pt":1588411413069,"mc":[{"id":"1.170370557","rc":[{"atb":[[2.48,3.53]],"id":9622734}],"con":true,"img":false}]}
{"op":"mcm","clk":"1361687475","pt":1588411413172,"mc":[{"id":"1.170370557","rc":[{"atb":[[2.46,30.23]],"id":9622734}],"con":true,"img":false}]}
{"op":"mcm","clk":"1361691912","pt":1588411507086,"mc":[{"id":"1.170370557","rc":[{"atb":[[1.64,2]],"id":9624350}],"con":true,"img":false}]}
{"op":"mcm","clk":"1361692260","pt":1588411515507,"mc":[{"id":"1.170370557","rc":[{"atb":[[1.64,0]],"id":9624350}],"con":true,"img":false}]}
{"op":"mcm","clk":"1361693247","pt":1588411536031,"mc":[{"id":"1.170370557","rc":[{"atl":[[1.56,2]],"id":9624350}],"con":true,"img":false}]}
{"op":"mcm","clk":"1361693844","pt":1588411549056,"mc":[{"id":"1.170370557","rc":[{"atl":[[1.56,0]],"id":9624350}],"con":true,"img":false}]}
{"op":"mcm","clk":"1361694200","pt":1588411556253,"mc":[{"id":"1.170370557","rc":[{"atb":[[1.64,2]],"id":9624350}],"con":true,"img":false}]}
{"op":"mcm","clk":"1361694799","pt":1588411568298,"mc":[{"id":"1.170370557","rc":[{"atb":[[1.64,0]],"id":9624350}],"con":true,"img":false}]}
{"op":"mcm","clk":"1361695210","pt":1588411576194,"mc":[{"id":"1.170370557","rc":[{"atl":[[1.56,2]],"id":9624350}],"con":true,"img":false}]}
{"op":"mcm","clk":"1361695747","pt":1588411587695,"mc":[{"id":"1.170370557","rc":[{"atl":[[1.56,0]],"id":9624350}],"con":true,"img":false}]}
{"op":"mcm","clk":"1361696174","pt":1588411595627,"mc":[{"id":"1.170370557","rc":[{"atb":[[1.64,2]],"id":9624350}],"con":true,"img":false}]}
{"op":"mcm","clk":"1361697040","pt":1588411612552,"mc":[{"id":"1.170370557","rc":[{"atb":[[1.64,0]],"id":9624350}],"con":true,"img":false}]}
{"op":"mcm","clk":"1361697298","pt":1588411618548,"mc":[{"id":"1.170370557","rc":[{"atl":[[1.56,2]],"id":9624350}],"con":true,"img":false}]}
{"op":"mcm","clk":"1361697801","pt":1588411628862,"mc":[{"id":"1.170370557","rc":[{"atl":[[1.56,0]],"id":9624350}],"con":true,"img":false}]}
{"op":"mcm","clk":"1361698080","pt":1588411634292,"mc":[{"id":"1.170370557","rc":[{"atb":[[1.64,2]],"id":9624350}],"con":true,"img":false}]}
{"op":"mcm","clk":"1361698514","pt":1588411642301,"mc":[{"id":"1.170370557","rc":[{"atb":[[1.64,0]],"id":9624350}],"con":true,"img":false}]}
{"op":"mcm","clk":"1361699032","pt":1588411651866,"mc":[{"id":"1.170370557","rc":[{"atb":[[1.64,2]],"id":9624350}],"con":true,"img":false}]}
{"op":"mcm","clk":"1361699459","pt":1588411660281,"mc":[{"id":"1.170370557","rc":[{"atb":[[1.64,0]],"id":9624350}],"con":true,"img":false}]}
{"op":"mcm","clk":"1361699858","pt":1588411667404,"mc":[{"id":"1.170370557","rc":[{"atb":[[1.64,2]],"id":9624350}],"con":true,"img":false}]}
{"op":"mcm","clk":"1361700447","pt":1588411678714,"mc":[{"id":"1.170370557","rc":[{"atb":[[1.64,0]],"id":9624350}],"con":true,"img":false}]}
{"op":"mcm","clk":"1361701064","pt":1588411691644,"mc":[{"id":"1.170370557","rc":[{"atl":[[1.56,2]],"id":9624350}],"con":true,"img":false}]}
{"op":"mcm","clk":"1361701637","pt":1588411703271,"mc":[{"id":"1.170370557","rc":[{"atl":[[1.56,0]],"id":9624350}],"con":true,"img":false}]}
{"op":"mcm","clk":"1361701939","pt":1588411709845,"mc":[{"id":"1.170370557","rc":[{"atb":[[1.64,2]],"id":9624350}],"con":true,"img":false}]}
{"op":"mcm","clk":"1361702707","pt":1588411726492,"mc":[{"id":"1.170370557","rc":[{"atb":[[1.64,0]],"id":9624350}],"con":true,"img":false}]}
{"op":"mcm","clk":"1361703067","pt":1588411733906,"mc":[{"id":"1.170370557","rc":[{"atl":[[1.56,2]],"id":9624350}],"con":true,"img":false}]}
{"op":"mcm","clk":"1361703122","pt":1588411735192,"mc":[{"id":"1.170370557","rc":[{"atb":[[1.5,1.77]],"id":9624350}],"con":true,"img":false}]}
{"op":"mcm","clk":"1361703259","pt":1588411738283,"mc":[{"id":"1.170370557","rc":[{"atb":[[1.41,1.77]],"id":9624350}],"con":true,"img":false}]}
{"op":"mcm","clk":"1361703291","pt":1588411739105,"mc":[{"id":"1.170370557","rc":[{"atb":[[1.35,1.77]],"id":9624350}],"con":true,"img":false}]}
{"op":"mcm","clk":"1361703704","pt":1588411747110,"mc":[{"id":"1.170370557","rc":[{"atl":[[1.56,0]],"id":9624350}],"con":true,"img":false}]}
{"op":"mcm","clk":"1361704099","pt":1588411755896,"mc":[{"id":"1.170370557","rc":[{"atb":[[1.64,2]],"id":9624350}],"con":true,"img":false}]}
{"op":"mcm","clk":"1361705227","pt":1588411760937,"mc":[{"id":"1.170370557","rc":[{"atl":[[1.65,2.62]],"id":9624350}],"con":true,"img":false}]}
{"op":"mcm","clk":"1361705476","pt":1588411766036,"mc":[{"id":"1.170370557","rc":[{"atl":[[1.65,0]],"id":9624350}],"con":true,"img":false}]}
{"op":"mcm","clk":"1361705483","pt":1588411766241,"mc":[{"id":"1.170370557","rc":[{"atl":[[1.67,2.62]],"id":9624350}],"con":true,"img":false}]}
{"op":"mcm","clk":"1361707012","pt":1588411801467,"mc":[{"id":"1.170370557","rc":[{"atb":[[1.64,0]],"id":9624350}],"con":true,"img":false}]}
{"op":"mcm","clk":"1361707557","pt":1588411813770,"mc":[{"id":"1.170370557","rc":[{"atl":[[1.56,2]],"id":9624350}],"con":true,"img":false}]}
{"op":"mcm","clk":"1361708238","pt":1588411829399,"mc":[{"id":"1.170370557","rc":[{"atl":[[1.56,0]],"id":9624350}],"con":true,"img":false}]}
{"op":"mcm","clk":"1361708456","pt":1588411834091,"mc":[{"id":"1.170370557","rc":[{"atb":[[1.64,2]],"id":9624350}],"con":true,"img":false}]}
{"op":"mcm","clk":"1361708894","pt":1588411843014,"mc":[{"id":"1.170370557","rc":[{"atb":[[2.5,8.74]],"id":9622734}],"con":true,"img":false}]}
{"op":"mcm","clk":"1361709598","pt":1588411857142,"mc":[{"id":"1.170370557","rc":[{"atb":[[1.64,0]],"id":9624350}],"con":true,"img":false}]}
{"op":"mcm","clk":"1361709883","pt":1588411862472,"mc":[{"id":"1.170370557","rc":[{"atl":[[1.56,2]],"id":9624350}],"con":true,"img":false}]}
{"op":"mcm","clk":"1361710902","pt":1588411882882,"mc":[{"id":"1.170370557","rc":[{"atl":[[1.56,0]],"id":9624350}],"con":true,"img":false}]}
{"op":"mcm","clk":"1361711252","pt":1588411889963,"mc":[{"id":"1.170370557","rc":[{"atb":[[1.64,2]],"id":9624350}],"con":true,"img":false}]}
{"op":"mcm","clk":"1361712256","pt":1588411913219,"mc":[{"id":"1.170370557","rc":[{"atb":[[1.64,0]],"id":9624350}],"con":true,"img":false}]}
{"op":"mcm","clk":"1361712464","pt":1588411918703,"mc":[{"id":"1.170370557","rc":[{"atl":[[1.56,2]],"id":9624350}],"con":true,"img":false}]}
{"op":"mcm","clk":"1361712898","pt":1588411929619,"mc":[{"id":"1.170370557","rc":[{"atl":[[1.56,0]],"id":9624350}],"con":true,"img":false}]}
{"op":"mcm","clk":"1361712982","pt":1588411931927,"mc":[{"id":"1.170370557","rc":[{"atb":[[2.5,10.73]],"id":9622734}],"con":true,"img":false}]}
{"op":"mcm","clk":"1361713165","pt":1588411938015,"mc":[{"id":"1.170370557","rc":[{"atb":[[1.64,2]],"id":9624350}],"con":true,"img":false}]}
{"op":"mcm","clk":"1361713704","pt":1588411955751,"mc":[{"id":"1.170370557","rc":[{"atb":[[1.64,0]],"id":9624350}],"con":true,"img":false}]}
{"op":"mcm","clk":"1361713995","pt":1588411962888,"mc":[{"id":"1.170370557","rc":[{"atl":[[1.56,2]],"id":9624350}],"con":true,"img":false}]}
{"op":"mcm","clk":"1361714575","pt":1588411976675,"mc":[{"id":"1.170370557","rc":[{"atl":[[1.56,0]],"id":9624350}],"con":true,"img":false}]}
{"op":"mcm","clk":"1361714833","pt":1588411984010,"mc":[{"id":"1.170370557","rc":[{"atb":[[1.64,2]],"id":9624350}],"con":true,"img":false}]}
{"op":"mcm","clk":"1361715247","pt":1588411996243,"mc":[{"id":"1.170370557","rc":[{"atb":[[1.64,0]],"id":9624350}],"con":true,"img":false}]}
{"op":"mcm","clk":"1361715455","pt":1588412003037,"mc":[{"id":"1.170370557","rc":[{"atl":[[1.56,2]],"id":9624350}],"con":true,"img":false}]}
{"op":"mcm","clk":"1361715797","pt":1588412014454,"mc":[{"id":"1.170370557","rc":[{"atl":[[1.56,0]],"id":9624350}],"con":true,"img":false}]}
{"op":"mcm","clk":"1361715915","pt":1588412018748,"mc":[{"id":"1.170370557","rc":[{"atb":[[1.64,2]],"id":9624350}],"con":true,"img":false}]}
{"op":"mcm","clk":"1361716452","pt":1588412032371,"mc":[{"id":"1.170370557","rc":[{"atb":[[1.64,0]],"id":9624350}],"con":true,"img":false}]}
{"op":"mcm","clk":"1361716649","pt":1588412037663,"mc":[{"id":"1.170370557","rc":[{"atl":[[1.56,2]],"id":9624350}],"con":true,"img":false}]}
{"op":"mcm","clk":"1361717200","pt":1588412051781,"mc":[{"id":"1.170370557","rc":[{"atl":[[1.56,0]],"id":9624350}],"con":true,"img":false}]}
{"op":"mcm","clk":"1361717399","pt":1588412058008,"mc":[{"id":"1.170370557","rc":[{"atb":[[1.64,2]],"id":9624350}],"con":true,"img":false}]}
{"op":"mcm","clk":"1361717924","pt":1588412073798,"mc":[{"id":"1.170370557","rc":[{"atb":[[1.64,0]],"id":9624350}],"con":true,"img":false}]}
{"op":"mcm","clk":"1361718294","pt":1588412085413,"mc":[{"id":"1.170370557","rc":[{"atl":[[1.56,2]],"id":9624350}],"con":true,"img":false}]}
{"op":"mcm","clk":"1361718985","pt":1588412104877,"mc":[{"id":"1.170370557","rc":[{"atl":[[1.56,0]],"id":9624350}],"con":true,"img":false}]}
{"op":"mcm","clk":"1361719869","pt":1588412128698,"mc":[{"id":"1.170370557","rc":[{"atb":[[1.64,2]],"id":9624350}],"con":true,"img":false}]}
{"op":"mcm","clk":"1361720524","pt":1588412145102,"mc":[{"id":"1.170370557","rc":[{"atb":[[1.64,0]],"id":9624350}],"con":true,"img":false}]}
{"op":"mcm","clk":"1361720811","pt":1588412152614,"mc":[{"id":"1.170370557","rc":[{"atl":[[1.56,2]],"id":9624350}],"con":true,"img":false}]}
{"op":"mcm","clk":"1361721372","pt":1588412168444,"mc":[{"id":"1.170370557","rc":[{"atl":[[1.56,0]],"id":9624350}],"con":true,"img":false}]}
{"op":"mcm","clk":"1361721577","pt":1588412172764,"mc":[{"id":"1.170370557","rc":[{"atb":[[1.64,2]],"id":9624350}],"con":true,"img":false}]}
{"op":"mcm","clk":"1361721992","pt":1588412183782,"mc":[{"id":"1.170370557","rc":[{"atb":[[1.64,0]],"id":9624350}],"con":true,"img":false}]}
{"op":"mcm","clk":"1361722258","pt":1588412190083,"mc":[{"id":"1.170370557","rc":[{"atl":[[1.56,2]],"id":9624350}],"con":true,"img":false}]}
{"op":"mcm","clk":"1361722649","pt":1588412200401,"mc":[{"id":"1.170370557","rc":[{"atl":[[1.56,0]],"id":9624350}],"con":true,"img":false}]}
{"op":"mcm","clk":"1361722789","pt":1588412203505,"mc":[{"id":"1.170370557","rc":[{"trd":[[1.54,16.9]],"ltp":1.54,"tv":16.9,"id":9624350},{"atb":[[1.54,0.46]],"id":9624350}],"con":true,"img":false}]}
{"op":"mcm","clk":"1361730895","pt":1588412404187,"mc":[{"id":"1.170370557","rc":[{"atb":[[2.46,40.31]],"id":9622734},{"atb":[[1.44,173.76]],"id":9624350}],"con":true,"img":false}]}
{"op":"mcm","clk":"1361732167","pt":1588412435129,"mc":[{"id":"1.170370557","rc":[{"trd":[[2.5,3.97]],"ltp":2.5,"tv":3.97,"id":9622734},{"atb":[[2.5,0]],"id":9622734},{"atl":[[2.5,6.76]],"id":9622734}],"con":true,"img":false}]}
{"op":"mcm","clk":"1361732660","pt":1588412448181,"mc":[{"id":"1.170370557","rc":[{"atl":[[2.5,0]],"id":9622734}],"con":true,"img":false}]}
{"op":"mcm","clk":"1361732674","pt":1588412448390,"mc":[{"id":"1.170370557","rc":[{"trd":[[2.48,8.82]],"ltp":2.48,"tv":8.82,"id":9622734},{"atb":[[2.48,0]],"id":9622734},{"atl":[[2.48,1.46]],"id":9622734},{"trd":[[1.67,2.62]],"ltp":1.67,"tv":2.62,"id":9624350},{"atl":[[1.67,0]],"id":9624350}],"con":true,"img":false}]}
{"op":"mcm","clk":"1361746102","pt":1588412739931,"mc":[{"id":"1.170370557","rc":[{"atb":[[2.38,42.65],[2.46,0]],"id":9622734},{"atb":[[1.44,39.99],[1.53,111.05]],"id":9624350}],"con":true,"img":false}]}
{"op":"mcm","clk":"1361746427","pt":1588412749890,"mc":[{"id":"1.170370557","rc":[{"atb":[[2.24,47.46],[2.38,0]],"id":9622734},{"atb":[[1.53,0],[1.57,103.26]],"id":9624350}],"con":true,"img":false}]}
{"op":"mcm","clk":"1361747057","pt":1588412767119,"mc":[{"id":"1.170370557","rc":[{"atb":[[2.26,12.69]],"id":9622734}],"con":true,"img":false}]}
{"op":"mcm","clk":"1361747411","pt":1588412777475,"mc":[{"id":"1.170370557","rc":[{"atl":[[2.44,1.77]],"id":9622734}],"con":true,"img":false}]}
{"op":"mcm","clk":"1361752948","pt":1588412938274,"mc":[{"id":"1.170370557","rc":[{"atl":[[2.28,7.99]],"id":9622734}],"con":true,"img":false}]}
{"op":"mcm","clk":"1361752953","pt":1588412938477,"mc":[{"id":"1.170370557","rc":[{"trd":[[2.28,15.82]],"ltp":2.28,"tv":15.82,"id":9622734},{"atl":[[2.28,0.08]],"id":9622734}],"con":true,"img":false}]}
{"op":"mcm","clk":"1361752986","pt":1588412939501,"mc":[{"id":"1.170370557","rc":[{"trd":[[2.48,11.62],[2.28,15.99],[2.44,3.54]],"ltp":2.48,"tv":31.15,"id":9622734},{"atl":[[2.28,0],[2.44,0],[2.48,0.06]],"id":9622734}],"con":true,"img":false}]}
{"op":"mcm","clk":"1361752990","pt":1588412939604,"mc":[{"id":"1.170370557","rc":[{"atb":[[2.28,56.66]],"id":9622734}],"con":true,"img":false}]}
{"op":"mcm","clk":"1361753156","pt":1588412944818,"mc":[{"id":"1.170370557","rc":[{"atb":[[2.3,12.3]],"id":9622734}],"con":true,"img":false}]}
{"op":"mcm","clk":"1361753164","pt":1588412945024,"mc":[{"id":"1.170370557","rc":[{"atb":[[2.28,0]],"id":9622734}],"con":true,"img":false}]}
{"op":"mcm","clk":"1361753169","pt":1588412945078,"mc":[{"id":"1.170370557","rc":[{"atb":[[2.38,54.17]],"id":9622734}],"con":true,"img":false}]}
{"op":"mcm","clk":"1361753208","pt":1588412946779,"mc":[{"id":"1.170370557","rc":[{"atb":[[2.3,0]],"id":9622734}],"con":true,"img":false}]}
{"op":"mcm","clk":"1361755424","pt":1588413014197,"mc":[{"id":"1.170370557","rc":[{"atb":[[2.38,55.98]],"id":9622734}],"con":true,"img":false}]}
{"op":"mcm","clk":"1361755450","pt":1588413015021,"mc":[{"id":"1.170370557","rc":[{"atb":[[1.58,43.99]],"id":9624350}],"con":true,"img":false}]}
{"op":"mcm","clk":"1361755524","pt":1588413017394,"mc":[{"id":"1.170370557","rc":[{"trd":[[2.38,40]],"ltp":2.38,"tv":40.0,"id":9622734},{"atb":[[2.38,35.98]],"id":9622734}],"con":true,"img":false}]}
{"op":"mcm","clk":"1361755530","pt":1588413017598,"mc":[{"id":"1.170370557","rc":[{"atb":[[2.38,1.81]],"id":9622734}],"con":true,"img":false}]}
{"op":"mcm","clk":"1361755539","pt":1588413018008,"mc":[{"id":"1.170370557","rc":[{"atb":[[2.4,52.56]],"id":9622734}],"con":true,"img":false}]}
{"op":"mcm","clk":"1361759134","pt":1588413130261,"mc":[{"id":"1.170370557","rc":[{"atb":[[2.38,0]],"id":9622734}],"con":true,"img":false}]}
{"op":"mcm","clk":"1361759417","pt":1588413139187,"mc":[{"id":"1.170370557","rc":[{"atb":[[2.4,54.35]],"id":9622734}],"con":true,"img":false}]}
{"op":"mcm","clk":"1361766979","pt":1588413379443,"mc":[{"id":"1.170370557","rc":[{"trd":[[2.4,4]],"ltp":2.4,"tv":4.0,"id":9622734},{"atb":[[2.4,52.35]],"id":9622734}],"con":true,"img":false}]}
{"op":"mcm","clk":"1361766990","pt":1588413379704,"mc":[{"id":"1.170370557","rc":[{"atb":[[2.4,1.79]],"id":9622734}],"con":true,"img":false}]}
{"op":"mcm","clk":"1361779673","pt":1588413647099,"mc":[{"id":"1.170370557","rc":[{"atb":[[1.44,0]],"id":9624350}],"con":true,"img":false}]}
{"op":"mcm","clk":"1361779678","pt":1588413647203,"mc":[{"id":"1.170370557","rc":[{"atb":[[1.47,66.38]],"id":9624350}],"con":true,"img":false}]}
{"op":"mcm","clk":"1361779693","pt":1588413647406,"mc":[{"id":"1.170370557","rc":[{"atb":[[2.36,39.99]],"id":9622734}],"con":true,"img":false}]}
{"op":"mcm","clk":"1361793653","pt":1588413868658,"mc":[{"id":"1.170370557","rc":[{"atl":[[2.1,0]],"id":9624350}],"con":true,"img":false}]}
{"op":"mcm","clk":"1361793661","pt":1588413868762,"mc":[{"id":"1.170370557","rc":[{"atl":[[2.24,3.19]],"id":9624350}],"con":true,"img":false}]}
{"op":"mcm","clk":"1361794163","pt":1588413876776,"mc":[{"id":"1.170370557","rc":[{"atb":[[1.25,0]],"id":9624350}],"con":true,"img":false}]}
{"op":"mcm","clk":"1361794173","pt":1588413876879,"mc":[{"id":"1.170370557","rc":[{"atb":[[1.27,12.79]],"id":9624350}],"con":true,"img":false}]}
{"op":"mcm","clk":"1361802089","pt":1588414001956,"mc":[{"id":"1.170370557","rc":[{"atb":[[1.59,62.97]],"id":9624350}],"con":true,"img":false}]}
{"op":"mcm","clk":"1361808732","pt":1588414135972,"mc":[{"id":"1.170370557","rc":[{"atb":[[1.59,0]],"id":9624350}],"con":true,"img":false}]}
{"op":"mcm","clk":"1361823897","pt":1588414525917,"mc":[{"id":"1.170370557","rc":[{"atb":[[1.11,0]],"id":9624350}],"con":true,"img":false}]}
{"op":"mcm","clk":"1361824085","pt":1588414533546,"mc":[{"id":"1.170370557","rc":[{"atb":[[1.3,10.39]],"id":9624350}],"con":true,"img":false}]}
{"op":"mcm","clk":"1361824295","pt":1588414541260,"mc":[{"id":"1.170370557","rc":[{"atb":[[1.11,0]],"id":9622734}],"con":true,"img":false}]}
{"op":"mcm","clk":"1361824447","pt":1588414547350,"mc":[{"id":"1.170370557","rc":[{"atb":[[1.42,7.99]],"id":9622734}],"con":true,"img":false}]}
{"op":"mcm","clk":"1361825361","pt":1588414584481,"mc":[{"id":"1.170370557","rc":[{"trd":[[2.48,11.69]],"ltp":2.48,"tv":11.69,"id":9622734},{"atl":[[2.48,0]],"id":9622734},{"trd":[[1.67,2.72]],"ltp":1.67,"tv":2.72,"id":9624350},{"atl":[[1.64,44.22]],"id":9624350}],"con":true,"img":false}]}
{"op":"mcm","clk":"1361825686","pt":1588414597921,"mc":[{"id":"1.170370557","rc":[{"atl":[[1.64,0]],"id":9624350}],"con":true,"img":false}]}
{"op":"mcm","clk":"1361825692","pt":1588414598126,"mc":[{"id":"1.170370557","rc":[{"atl":[[1.66,44.22]],"id":9624350}],"con":true,"img":false}]}
{"op":"mcm","clk":"1361825847","pt":1588414603846,"mc":[{"id":"1.170370557","rc":[{"atl":[[1.59,2]],"id":9624350}],"con":true,"img":false}]}
{"op":"mcm","clk":"1361826030","pt":1588414610347,"mc":[{"id":"1.170370557","rc":[{"atb":[[1.45,0]],"id":9624350}],"con":true,"img":false}]}
{"op":"mcm","clk":"1361826059","pt":1588414611427,"mc":[{"id":"1.170370557","rc":[{"atl":[[1.59,0]],"id":9624350}],"con":true,"img":false}]}
{"op":"mcm","clk":"1361826062","pt":1588414611529,"mc":[{"id":"1.170370557","rc":[{"atb":[[1.35,47.47]],"id":9624350}],"con":true,"img":false}]}
{"op":"mcm","clk":"1361826064","pt":1588414611633,"mc":[{"id":"1.170370557","rc":[{"atb":[[1.35,93.18]],"id":9624350}],"con":true,"img":false}]}
{"op":"mcm","clk":"1361826069","pt":1588414611838,"mc":[{"id":"1.170370557","rc":[{"atb":[[1.35,138.88]],"id":9624350}],"con":true,"img":false}]}
{"op":"mcm","clk":"1361826192","pt":1588414618132,"mc":[{"id":"1.170370557","rc":[{"atb":[[1.6,62.97]],"id":9624350}],"con":true,"img":false}]}
{"op":"mcm","clk":"1361826218","pt":1588414619635,"mc":[{"id":"1.170370557","rc":[{"atb":[[1.65,2]],"id":9624350}],"con":true,"img":false}]}
{"op":"mcm","clk":"1361826280","pt":1588414621855,"mc":[{"id":"1.170370557","rc":[{"atl":[[1.66,0]],"id":9624350}],"con":true,"img":false}]}
{"op":"mcm","clk":"1361826440","pt":1588414627771,"mc":[{"id":"1.170370557","rc":[{"atb":[[1.65,0]],"id":9624350}],"con":true,"img":false}]}
{"op":"mcm","clk":"1361826709","pt":1588414637840,"mc":[{"id":"1.170370557","rc":[{"atl":[[1.66,64.51]],"id":9624350}],"con":true,"img":false}]}
{"op":"mcm","clk":"1361827695","pt":1588414671416,"mc":[{"id":"1.170370557","rc":[{"atl":[[1.61,2]],"id":9624350}],"con":true,"img":false}]}
{"op":"mcm","clk":"1361827926","pt":1588414680053,"mc":[{"id":"1.170370557","rc":[{"atb":[[1.6,0]],"id":9624350}],"con":true,"img":false}]}
{"op":"mcm","clk":"1361827933","pt":1588414680242,"mc":[{"id":"1.170370557","rc":[{"trd":[[1.61,4]],"ltp":1.61,"tv":4.0,"id":9624350},{"atb":[[1.61,60.97]],"id":9624350},{"atl":[[1.61,0]],"id":9624350}],"con":true,"img":false}]}
{"op":"mcm","clk":"1361828115","pt":1588414686658,"mc":[{"id":"1.170370557","rc":[{"atb":[[1.65,2]],"id":9624350}],"con":true,"img":false}]}
{"op":"mcm","clk":"1361828358","pt":1588414694957,"mc":[{"id":"1.170370557","rc":[{"atb":[[2.4,0]],"id":9622734}],"con":true,"img":false}]}
{"op":"mcm","clk":"1361828360","pt":1588414695063,"mc":[{"id":"1.170370557","rc":[{"atb":[[1.65,0]],"id":9624350}],"con":true,"img":false}]}
{"op":"mcm","clk":"1361828636","pt":1588414704415,"mc":[{"id":"1.170370557","rc":[{"trd":[[1.66,3.86]],"ltp":1.66,"tv":3.86,"id":9624350},{"atl":[[1.66,62.57]],"id":9624350}],"con":true,"img":false}]}
{"op":"mcm","clk":"1361833054","pt":1588414843881,"mc":[{"id":"1.170370557","rc":[{"atb":[[1.01,9.79]],"id":9622734},{"atb":[[1.01,9.79]],"id":9624350}],"con":true,"img":false}]}
{"op":"mcm","clk":"1361847548","pt":1588415200428,"mc":[{"id":"1.170370557","rc":[{"atb":[[2.36,92.67]],"id":9622734}],"con":true,"img":false}]}
{"op":"mcm","clk":"1361847659","pt":1588415202698,"mc":[{"id":"1.170370557","rc":[{"atb":[[2.36,52.68]],"id":9622734}],"con":true,"img":false}]}
{"op":"mcm","clk":"1361847679","pt":1588415203131,"mc":[{"id":"1.170370557","rc":[{"atb":[[1.47,26.39]],"id":9624350}],"con":true,"img":false}]}
{"op":"mcm","clk":"1361847685","pt":1588415203213,"mc":[{"id":"1.170370557","rc":[{"atb":[[1.49,39.99]],"id":9624350}],"con":true,"img":false}]}
{"op":"mcm","clk":"1361847806","pt":1588415205942,"mc":[{"id":"1.170370557","rc":[{"atb":[[1.49,0]],"id":9624350}],"con":true,"img":false}]}
{"op":"mcm","clk":"1361847814","pt":1588415206049,"mc":[{"id":"1.170370557","rc":[{"atb":[[1.48,73.18]],"id":9624350}],"con":true,"img":false}]}
{"op":"mcm","clk":"1361847823","pt":1588415206208,"mc":[{"id":"1.170370557","rc":[{"atb":[[2.34,39.99]],"id":9622734}],"con":true,"img":false}]}
{"op":"mcm","clk":"1361848069","pt":1588415211533,"mc":[{"id":"1.170370557","rc":[{"atb":[[1.48,33.19]],"id":9624350}],"con":true,"img":false}]}
{"op":"mcm","clk":"1361848073","pt":1588415211634,"mc":[{"id":"1.170370557","rc":[{"atb":[[1.49,39.99]],"id":9624350}],"con":true,"img":false}]}
{"op":"mcm","clk":"1361848305","pt":1588415217062,"mc":[{"id":"1.170370557","rc":[{"atb":[[1.49,0]],"id":9624350}],"con":true,"img":false}]}
{"op":"mcm","clk":"1361848310","pt":1588415217165,"mc":[{"id":"1.170370557","rc":[{"atb":[[1.48,73.18]],"id":9624350}],"con":true,"img":false}]}
{"op":"mcm","clk":"1361848507","pt":1588415221776,"mc":[{"id":"1.170370557","rc":[{"atb":[[1.48,33.19]],"id":9624350}],"con":true,"img":false}]}
{"op":"mcm","clk":"1361848513","pt":1588415221832,"mc":[{"id":"1.170370557","rc":[{"atb":[[1.49,39.99]],"id":9624350}],"con":true,"img":false}]}
{"op":"mcm","clk":"1361848754","pt":1588415226871,"mc":[{"id":"1.170370557","rc":[{"atb":[[1.49,0]],"id":9624350}],"con":true,"img":false}]}
{"op":"mcm","clk":"1361848760","pt":1588415226974,"mc":[{"id":"1.170370557","rc":[{"atb":[[1.48,73.18]],"id":9624350}],"con":true,"img":false}]}
{"op":"mcm","clk":"1361848975","pt":1588415231663,"mc":[{"id":"1.170370557","rc":[{"atb":[[1.48,33.19]],"id":9624350}],"con":true,"img":false}]}
{"op":"mcm","clk":"1361848981","pt":1588415231767,"mc":[{"id":"1.170370557","rc":[{"atb":[[1.49,39.99]],"id":9624350}],"con":true,"img":false}]}
{"op":"mcm","clk":"1361849184","pt":1588415236368,"mc":[{"id":"1.170370557","rc":[{"atb":[[1.49,0]],"id":9624350}],"con":true,"img":false}]}
{"op":"mcm","clk":"1361849189","pt":1588415236472,"mc":[{"id":"1.170370557","rc":[{"atb":[[1.48,73.18]],"id":9624350}],"con":true,"img":false}]}
{"op":"mcm","clk":"1361849432","pt":1588415241285,"mc":[{"id":"1.170370557","rc":[{"atb":[[1.48,33.19]],"id":9624350}],"con":true,"img":false}]}
{"op":"mcm","clk":"1361849440","pt":1588415241388,"mc":[{"id":"1.170370557","rc":[{"atb":[[1.49,39.99]],"id":9624350}],"con":true,"img":false}]}
{"op":"mcm","clk":"1361849660","pt":1588415245888,"mc":[{"id":"1.170370557","rc":[{"atb":[[1.49,0]],"id":9624350}],"con":true,"img":false}]}
{"op":"mcm","clk":"1361849665","pt":1588415245993,"mc":[{"id":"1.170370557","rc":[{"atb":[[1.48,73.18]],"id":9624350}],"con":true,"img":false}]}
{"op":"mcm","clk":"1361849749","pt":1588415247696,"mc":[{"id":"1.170370557","rc":[{"atb":[[2.36,0]],"id":9622734}],"con":true,"img":false}]}
{"op":"mcm","clk":"1361849929","pt":1588415251495,"mc":[{"id":"1.170370557","rc":[{"atb":[[2.34,0]],"id":9622734}],"con":true,"img":false}]}
{"op":"mcm","clk":"1361849938","pt":1588415251700,"mc":[{"id":"1.170370557","rc":[{"atb":[[2.28,53.91]],"id":9622734}],"con":true,"img":false}]}
{"op":"mcm","clk":"1361849946","pt":1588415251908,"mc":[{"id":"1.170370557","rc":[{"atb":[[1.48,33.19]],"id":9624350}],"con":true,"img":false}]}
{"op":"mcm","clk":"1361849951","pt":1588415252012,"mc":[{"id":"1.170370557","rc":[{"atb":[[1.49,39.99]],"id":9624350}],"con":true,"img":false}]}
{"op":"mcm","clk":"1361849974","pt":1588415252484,"mc":[{"id":"1.170370557","rc":[{"atb":[[2.3,39.99]],"id":9622734}],"con":true,"img":false}]}
{"op":"mcm","clk":"1361849979","pt":1588415252589,"mc":[{"id":"1.170370557","rc":[{"atb":[[2.28,0]],"id":9622734}],"con":true,"img":false}]}
{"op":"mcm","clk":"1361849983","pt":1588415252691,"mc":[{"id":"1.170370557","rc":[{"atb":[[2.32,52.89]],"id":9622734}],"con":true,"img":false}]}
{"op":"mcm","clk":"1361882282","pt":1588416002236,"mc":[{"id":"1.170370557","rc":[{"atb":[[2.44,18.46]],"id":9622734},{"atb":[[1.58,89.84]],"id":9624350}],"con":true,"img":false}]}
{"op":"mcm","clk":"1361882293","pt":1588416002505,"mc":[{"id":"1.170370557","rc":[{"atb":[[2.32,0]],"id":9622734}],"con":true,"img":false}]}
{"op":"mcm","clk":"1361882629","pt":1588416010028,"mc":[{"id":"1.170370557","rc":[{"atb":[[1.01,11.79]],"id":9622734},{"atl":[[1000,2]],"id":9622734},{"atl":[[1000,2]],"id":9624350}],"con":true,"img":false}]}
{"op":"mcm","clk":"1361882640","pt":1588416010349,"mc":[{"id":"1.170370557","rc":[{"atb":[[1.01,11.17]],"id":9622734},{"atl":[[1000,0.16]],"id":9622734},{"atl":[[1000,1.95]],"id":9624350}],"con":true,"img":false}]}
{"op":"mcm","clk":"1361882651","pt":1588416010648,"mc":[{"id":"1.170370557","rc":[{"atb":[[1.01,9.79]],"id":9622734},{"atl":[[1000,0]],"id":9622734},{"atl":[[1000,0]],"id":9624350}],"con":true,"img":false}]}
{"op":"mcm","clk":"1361882655","pt":1588416010707,"mc":[{"id":"1.170370557","rc":[{"atb":[[1.89,1.38]],"id":9622734},{"atl":[[2.78,0.16]],"id":9622734},{"atl":[[2.84,1.95]],"id":9624350}],"con":true,"img":false}]}
{"op":"mcm","clk":"1361882659","pt":1588416010809,"mc":[{"id":"1.170370557","rc":[{"atb":[[1.29,3.51]],"id":9624350}],"con":true,"img":false}]}
{"op":"mcm","clk":"1361883948","pt":1588416039982,"mc":[{"id":"1.170370557","rc":[{"atb":[[2.3,0]],"id":9622734},{"atb":[[1.49,0]],"id":9624350}],"con":true,"img":false}]}
{"op":"mcm","clk":"1361891348","pt":1588416238924,"mc":[{"id":"1.170370557","rc":[{"atl":[[2.6,10]],"id":9622734}],"con":true,"img":false}]}
{"op":"mcm","clk":"1361891978","pt":1588416256269,"mc":[{"id":"1.170370557","rc":[{"atl":[[2.6,20]],"id":9622734}],"con":true,"img":false}]}
{"op":"mcm","clk":"1361893441","pt":1588416272880,"mc":[{"id":"1.170370557","rc":[{"atl":[[2.6,10]],"id":9622734}],"con":true,"img":false}]}
{"op":"mcm","clk":"1361893445","pt":1588416272983,"mc":[{"id":"1.170370557","rc":[{"atl":[[2.72,10]],"id":9622734}],"con":true,"img":false}]}
{"op":"mcm","clk":"1361894305","pt":1588416295104,"mc":[{"id":"1.170370557","rc":[{"atl":[[2.82,10]],"id":9622734}],"con":true,"img":false}]}
{"op":"mcm","clk":"1361902121","pt":1588416509043,"mc":[{"id":"1.170370557","rc":[{"atb":[[1.61,0]],"id":9624350}],"con":true,"img":false}]}
{"op":"mcm","clk":"1361902131","pt":1588416509250,"mc":[{"id":"1.170370557","rc":[{"atb":[[1.62,60.97]],"id":9624350}],"con":true,"img":false}]}
{"op":"mcm","clk":"1361902134","pt":1588416509308,"mc":[{"id":"1.170370557","rc":[{"atb":[[2.48,17.96]],"id":9622734},{"atb":[[1.58,43.99],[1.56,47.49]],"id":9624350}],"con":true,"img":false}]}
{"op":"mcm","clk":"1361902173","pt":1588416510337,"mc":[{"id":"1.170370557","rc":[{"atb":[[2.48,0]],"id":9622734},{"atb":[[1.58,89.84]],"id":9624350}],"con":true,"img":false}]}
{"op":"mcm","clk":"1361905362","pt":1588416597918,"mc":[{"id":"1.170370557","rc":[{"atl":[[1.65,125.88]],"id":9624350}],"con":true,"img":false}]}
{"op":"mcm","clk":"1361915214","pt":1588417056002,"mc":[{"id":"1.170370557","rc":[{"trd":[[2.6,8.74]],"ltp":2.6,"tv":8.74,"id":9622734},{"atl":[[2.6,5.63]],"id":9622734}],"con":true,"img":false}]}
{"op":"mcm","clk":"1361933061","pt":1588417585966,"mc":[{"id":"1.170370557","rc":[{"atb":[[1.63,2.91]],"id":9624350}],"con":true,"img":false}]}
{"op":"mcm","clk":"1361934249","pt":1588417613799,"mc":[{"id":"1.170370557","rc":[{"atl":[[1.64,23.99]],"id":9624350}],"con":true,"img":false}]}
{"op":"mcm","clk":"1361934282","pt":1588417614580,"mc":[{"id":"1.170370557","rc":[{"atb":[[2.48,17.96]],"id":9622734},{"atb":[[1.57,149.91]],"id":9624350}],"con":true,"img":false}]}
{"op":"mcm","clk":"1361934287","pt":1588417614685,"mc":[{"id":"1.170370557","rc":[{"atb":[[1.58,43.99]],"id":9624350}],"con":true,"img":false}]}
{"op":"mcm","clk":"1361934780","pt":1588417626706,"mc":[{"id":"1.170370557","rc":[{"trd":[[1.64,5.99]],"ltp":1.64,"tv":5.99,"id":9624350},{"atl":[[1.64,20.99]],"id":9624350}],"con":true,"img":false}]}
{"op":"mcm","clk":"1361935071","pt":1588417635011,"mc":[{"id":"1.170370557","rc":[{"trd":[[1.64,9.99]],"ltp":1.64,"tv":9.99,"id":9624350},{"atl":[[1.64,18.99]],"id":9624350}],"con":true,"img":false}]}
{"op":"mcm","clk":"1361940313","pt":1588417778939,"mc":[{"id":"1.170370557","rc":[{"atb":[[1.63,0]],"id":9624350}],"con":true,"img":false}]}
{"op":"mcm","clk":"1361940318","pt":1588417779043,"mc":[{"id":"1.170370557","rc":[{"trd":[[1.64,15.74]],"ltp":1.64,"tv":15.74,"id":9624350},{"atl":[[1.64,16.12]],"id":9624350}],"con":true,"img":false}]}
{"op":"mcm","clk":"1361940338","pt":1588417779657,"mc":[{"id":"1.170370557","rc":[{"atb":[[2.48,0]],"id":9622734}],"con":true,"img":false}]}
{"op":"mcm","clk":"1361940342","pt":1588417779763,"mc":[{"id":"1.170370557","rc":[{"atb":[[1.58,89.84]],"id":9624350}],"con":true,"img":false}]}
{"op":"mcm","clk":"1361947100","pt":1588418025817,"mc":[{"id":"1.170370557","rc":[{"atb":[[1.63,70.34]],"id":9624350}],"con":true,"img":false}]}
{"op":"mcm","clk":"1361947121","pt":1588418026799,"mc":[{"id":"1.170370557","rc":[{"atb":[[1.58,43.99]],"id":9624350}],"con":true,"img":false}]}
{"op":"mcm","clk":"1361950207","pt":1588418160209,"mc":[{"id":"1.170370557","rc":[{"atl":[[1.65,0]],"id":9624350}],"con":true,"img":false}]}
{"op":"mcm","clk":"1361950211","pt":1588418160311,"mc":[{"id":"1.170370557","rc":[{"trd":[[1.63,140.69]],"ltp":1.63,"tv":140.69,"id":9624350},{"atb":[[1.63,0]],"id":9624350},{"atl":[[1.63,55.54]],"id":9624350}],"con":true,"img":false}]}
{"op":"mcm","clk":"1361950220","pt":1588418160783,"mc":[{"id":"1.170370557","rc":[{"atb":[[2.48,17.96]],"id":9622734}],"con":true,"img":false}]}
{"op":"mcm","clk":"1361950254","pt":1588418162865,"mc":[{"id":"1.170370557","marketDefinition":{"bspMarket":false,"turnInPlayEnabled":true,"persistenceEnabled":true,"marketBaseRate":5.0,"eventId":"29788106","eventTypeId":"2","numberOfWinners":1,"bettingType":"ODDS","marketType":"MATCH_ODDS","marketTime":"2020-05-02T11:45:00.000Z","suspendTime":"2020-05-02T11:45:00.000Z","bspReconciled":false,"complete":true,"inPlay":false,"crossMatching":true,"runnersVoidable":false,"numberOfActiveRunners":2,"betDelay":0,"status":"OPEN","runners":[{"status":"ACTIVE","sortPriority":1,"id":9624350,"name":"Y Hanfmann"},{"status":"ACTIVE","sortPriority":2,"id":9622734,"name":"D Brown"}],"regulators":["MR_INT"],"countryCode":"GB","discountAllowed":true,"timezone":"GMT","openDate":"2020-05-02T11:40:00.000Z","version":3237511885,"name":"Match Odds","eventName":"Y Hanfmann v D Brown"},"rc":[],"con":true,"img":false}]}
{"op":"mcm","clk":"1361950289","pt":1588418164868,"mc":[{"id":"1.170370557","marketDefinition":{"bspMarket":false,"turnInPlayEnabled":true,"persistenceEnabled":true,"marketBaseRate":5.0,"eventId":"29788106","eventTypeId":"2","numberOfWinners":1,"bettingType":"ODDS","marketType":"MATCH_ODDS","marketTime":"2020-05-02T11:45:00.000Z","suspendTime":"2020-05-02T11:45:00.000Z","bspReconciled":false,"complete":true,"inPlay":false,"crossMatching":true,"runnersVoidable":false,"numberOfActiveRunners":2,"betDelay":0,"status":"OPEN","runners":[{"status":"ACTIVE","sortPriority":1,"id":9624350,"name":"Y Hanfmann"},{"status":"ACTIVE","sortPriority":2,"id":9622734,"name":"D Brown"}],"regulators":["MR_INT"],"countryCode":"GB","discountAllowed":true,"timezone":"GMT","openDate":"2020-05-02T11:45:00.000Z","version":3237511885,"name":"Match Odds","eventName":"Y Hanfmann v D Brown"},"rc":[],"con":true,"img":false}]}
{"op":"mcm","clk":"1361950504","pt":1588418176544,"mc":[{"id":"1.170370557","rc":[{"atl":[[1.63,0]],"id":9624350}],"con":true,"img":false}]}
{"op":"mcm","clk":"1361950509","pt":1588418176807,"mc":[{"id":"1.170370557","rc":[{"atb":[[2.48,0]],"id":9622734},{"atb":[[1.57,103.26]],"id":9624350}],"con":true,"img":false}]}
{"op":"mcm","clk":"1361950613","pt":1588418181413,"mc":[{"id":"1.170370557","rc":[{"trd":[[1.62,141.25]],"ltp":1.62,"tv":141.25,"id":9624350},{"atb":[[1.62,6.01]],"id":9624350}],"con":true,"img":false}]}
{"op":"mcm","clk":"1361950619","pt":1588418181826,"mc":[{"id":"1.170370557","rc":[{"atb":[[2.48,17.96]],"id":9622734}],"con":true,"img":false}]}
{"op":"mcm","clk":"1361952463","pt":1588418280429,"mc":[{"id":"1.170370557","rc":[{"atl":[[1000,2]],"id":9622734}],"con":true,"img":false}]}
{"op":"mcm","clk":"1361952468","pt":1588418280634,"mc":[{"id":"1.170370557","rc":[{"atl":[[1000,1]],"id":9622734}],"con":true,"img":false}]}
{"op":"mcm","clk":"1361952473","pt":1588418280839,"mc":[{"id":"1.170370557","rc":[{"atl":[[1000,0]],"id":9622734}],"con":true,"img":false}]}
{"op":"mcm","clk":"1361952476","pt":1588418280940,"mc":[{"id":"1.170370557","rc":[{"atl":[[2.6,6.63]],"id":9622734}],"con":true,"img":false}]}
{"op":"mcm","clk":"1361954136","pt":1588418370205,"mc":[{"id":"1.170370557","rc":[{"atl":[[2.6,5.63]],"id":9622734}],"con":true,"img":false}]}
{"op":"mcm","clk":"1361954142","pt":1588418370308,"mc":[{"id":"1.170370557","rc":[{"atl":[[2.58,1]],"id":9622734}],"con":true,"img":false}]}
{"op":"mcm","clk":"1361954152","pt":1588418370924,"mc":[{"id":"1.170370557","rc":[{"atb":[[2.46,18.21],[2.48,0]],"id":9622734}],"con":true,"img":false}]}
{"op":"mcm","clk":"1361954623","pt":1588418396354,"mc":[{"id":"1.170370557","rc":[{"atl":[[2.58,0]],"id":9622734}],"con":true,"img":false}]}
{"op":"mcm","clk":"1361954626","pt":1588418396412,"mc":[{"id":"1.170370557","rc":[{"trd":[[2.56,1]],"ltp":2.56,"tv":1.0,"id":9622734},{"trd":[[1.64,17.3]],"ltp":1.64,"tv":17.3,"id":9624350},{"atl":[[1.64,14.56]],"id":9624350}],"con":true,"img":false}]}
{"op":"mcm","clk":"1361954637","pt":1588418396824,"mc":[{"id":"1.170370557","rc":[{"atb":[[2.48,17.96]],"id":9622734}],"con":true,"img":false}]}
{"op":"mcm","clk":"1361958611","pt":1588418613745,"mc":[{"id":"1.170370557","rc":[{"trd":[[2.6,19.38]],"ltp":2.6,"tv":19.38,"id":9622734},{"atl":[[2.6,0.31]],"id":9622734}],"con":true,"img":false}]}
{"op":"mcm","clk":"1361958931","pt":1588418630894,"mc":[{"id":"1.170370557","rc":[{"trd":[[1.62,151.89]],"ltp":1.62,"tv":151.89,"id":9624350},{"atb":[[1.62,0.69]],"id":9624350}],"con":true,"img":false}]}
{"op":"mcm","clk":"1361959182","pt":1588418643490,"mc":[{"id":"1.170370557","marketDefinition":{"bspMarket":false,"turnInPlayEnabled":true,"persistenceEnabled":true,"marketBaseRate":5.0,"eventId":"29788106","eventTypeId":"2","numberOfWinners":1,"bettingType":"ODDS","marketType":"MATCH_ODDS","marketTime":"2020-05-02T11:55:00.000Z","suspendTime":"2020-05-02T11:55:00.000Z","bspReconciled":false,"complete":true,"inPlay":false,"crossMatching":true,"runnersVoidable":false,"numberOfActiveRunners":2,"betDelay":0,"status":"OPEN","runners":[{"status":"ACTIVE","sortPriority":1,"id":9624350,"name":"Y Hanfmann"},{"status":"ACTIVE","sortPriority":2,"id":9622734,"name":"D Brown"}],"regulators":["MR_INT"],"countryCode":"GB","discountAllowed":true,"timezone":"GMT","openDate":"2020-05-02T11:45:00.000Z","version":3237513407,"name":"Match Odds","eventName":"Y Hanfmann v D Brown"},"rc":[],"con":true,"img":false}]}
{"op":"mcm","clk":"1361959238","pt":1588418646493,"mc":[{"id":"1.170370557","marketDefinition":{"bspMarket":false,"turnInPlayEnabled":true,"persistenceEnabled":true,"marketBaseRate":5.0,"eventId":"29788106","eventTypeId":"2","numberOfWinners":1,"bettingType":"ODDS","marketType":"MATCH_ODDS","marketTime":"2020-05-02T11:55:00.000Z","suspendTime":"2020-05-02T11:55:00.000Z","bspReconciled":false,"complete":true,"inPlay":false,"crossMatching":true,"runnersVoidable":false,"numberOfActiveRunners":2,"betDelay":0,"status":"OPEN","runners":[{"status":"ACTIVE","sortPriority":1,"id":9624350,"name":"Y Hanfmann"},{"status":"ACTIVE","sortPriority":2,"id":9622734,"name":"D Brown"}],"regulators":["MR_INT"],"countryCode":"GB","discountAllowed":true,"timezone":"GMT","openDate":"2020-05-02T11:55:00.000Z","version":3237513407,"name":"Match Odds","eventName":"Y Hanfmann v D Brown"},"rc":[],"con":true,"img":false}]}
{"op":"mcm","clk":"1361963753","pt":1588418903838,"mc":[{"id":"1.170370557","rc":[{"atl":[[2.66,2.12]],"id":9622734}],"con":true,"img":false}]}
{"op":"mcm","clk":"1361964245","pt":1588418930182,"mc":[{"id":"1.170370557","rc":[{"atl":[[4,3.19]],"id":9624350}],"con":true,"img":false}]}
{"op":"mcm","clk":"1361964335","pt":1588418934291,"mc":[{"id":"1.170370557","rc":[{"atl":[[4,3.59]],"id":9624350}],"con":true,"img":false}]}
{"op":"mcm","clk":"1361964410","pt":1588418938560,"mc":[{"id":"1.170370557","rc":[{"atl":[[4,0]],"id":9624350}],"con":true,"img":false}]}
{"op":"mcm","clk":"1361964412","pt":1588418938662,"mc":[{"id":"1.170370557","rc":[{"trd":[[1.62,152.69]],"ltp":1.62,"tv":152.69,"id":9624350},{"atb":[[1.62,0.29]],"id":9624350}],"con":true,"img":false}]}
{"op":"mcm","clk":"1361967986","pt":1588419095340,"mc":[{"id":"1.170370557","rc":[{"trd":[[2.56,10.33]],"ltp":2.56,"tv":10.33,"id":9622734},{"atl":[[2.56,3.46]],"id":9622734},{"trd":[[1.64,31.86]],"ltp":1.64,"tv":31.86,"id":9624350},{"atl":[[1.64,0]],"id":9624350}],"con":true,"img":false}]}
{"op":"mcm","clk":"1361968005","pt":1588419096056,"mc":[{"id":"1.170370557","rc":[{"atb":[[2.4,18.99]],"id":9622734}],"con":true,"img":false}]}
{"op":"mcm","clk":"1361968009","pt":1588419096262,"mc":[{"id":"1.170370557","rc":[{"atb":[[2.44,0],[2.48,0],[2.46,0]],"id":9622734}],"con":true,"img":false}]}
{"op":"mcm","clk":"1361968880","pt":1588419134800,"mc":[{"id":"1.170370557","rc":[{"atl":[[2.56,0]],"id":9622734}],"con":true,"img":false}]}
{"op":"mcm","clk":"1361968884","pt":1588419134903,"mc":[{"id":"1.170370557","rc":[{"trd":[[2.5,7.43]],"ltp":2.5,"tv":7.43,"id":9622734},{"trd":[[1.66,9.07]],"ltp":1.66,"tv":9.07,"id":9624350},{"atl":[[1.66,57.36]],"id":9624350}],"con":true,"img":false}]}
{"op":"mcm","clk":"1361968888","pt":1588419135109,"mc":[{"id":"1.170370557","rc":[{"atb":[[2.48,17.96]],"id":9622734}],"con":true,"img":false}]}
{"op":"mcm","clk":"1361969123","pt":1588419145211,"mc":[{"id":"1.170370557","rc":[{"atb":[[1.61,35.19]],"id":9624350}],"con":true,"img":false}]}
{"op":"mcm","clk":"1361969144","pt":1588419146239,"mc":[{"id":"1.170370557","rc":[{"atb":[[2.44,18.46],[2.48,0]],"id":9622734},{"atb":[[1.58,89.84]],"id":9624350}],"con":true,"img":false}]}
{"op":"mcm","clk":"1361969596","pt":1588419167365,"mc":[{"id":"1.170370557","rc":[{"trd":[[2.5,15.43]],"ltp":2.5,"tv":15.43,"id":9622734},{"trd":[[1.66,21.12]],"ltp":1.66,"tv":21.12,"id":9624350},{"atl":[[1.66,45.31]],"id":9624350}],"con":true,"img":false}]}
{"op":"mcm","clk":"1361969802","pt":1588419177461,"mc":[{"id":"1.170370557","rc":[{"atb":[[1.6,43.99]],"id":9624350}],"con":true,"img":false}]}
{"op":"mcm","clk":"1361971802","pt":1588419286944,"mc":[{"id":"1.170370557","rc":[{"atb":[[1.5,7.19]],"id":9624350}],"con":true,"img":false}]}
{"op":"mcm","clk":"1361972517","pt":1588419323918,"mc":[{"id":"1.170370557","rc":[{"trd":[[1.66,31.43]],"ltp":1.66,"tv":31.43,"id":9624350},{"atl":[[1.66,40.15]],"id":9624350}],"con":true,"img":false}]}
{"op":"mcm","clk":"1361973404","pt":1588419368403,"mc":[{"id":"1.170370557","marketDefinition":{"bspMarket":false,"turnInPlayEnabled":true,"persistenceEnabled":true,"marketBaseRate":5.0,"eventId":"29788106","eventTypeId":"2","numberOfWinners":1,"bettingType":"ODDS","marketType":"MATCH_ODDS","marketTime":"2020-05-02T12:05:00.000Z","suspendTime":"2020-05-02T12:05:00.000Z","bspReconciled":false,"complete":true,"inPlay":false,"crossMatching":true,"runnersVoidable":false,"numberOfActiveRunners":2,"betDelay":0,"status":"OPEN","runners":[{"status":"ACTIVE","sortPriority":1,"id":9624350,"name":"Y Hanfmann"},{"status":"ACTIVE","sortPriority":2,"id":9622734,"name":"D Brown"}],"regulators":["MR_INT"],"countryCode":"GB","discountAllowed":true,"timezone":"GMT","openDate":"2020-05-02T11:55:00.000Z","version":3237516246,"name":"Match Odds","eventName":"Y Hanfmann v D Brown"},"rc":[],"con":true,"img":false}]}
{"op":"mcm","clk":"1361973448","pt":1588419370422,"mc":[{"id":"1.170370557","marketDefinition":{"bspMarket":false,"turnInPlayEnabled":true,"persistenceEnabled":true,"marketBaseRate":5.0,"eventId":"29788106","eventTypeId":"2","numberOfWinners":1,"bettingType":"ODDS","marketType":"MATCH_ODDS","marketTime":"2020-05-02T12:05:00.000Z","suspendTime":"2020-05-02T12:05:00.000Z","bspReconciled":false,"complete":true,"inPlay":false,"crossMatching":true,"runnersVoidable":false,"numberOfActiveRunners":2,"betDelay":0,"status":"OPEN","runners":[{"status":"ACTIVE","sortPriority":1,"id":9624350,"name":"Y Hanfmann"},{"status":"ACTIVE","sortPriority":2,"id":9622734,"name":"D Brown"}],"regulators":["MR_INT"],"countryCode":"GB","discountAllowed":true,"timezone":"GMT","openDate":"2020-05-02T12:05:00.000Z","version":3237516246,"name":"Match Odds","eventName":"Y Hanfmann v D Brown"},"rc":[],"con":true,"img":false}]}
{"op":"mcm","clk":"1361980881","pt":1588419717001,"mc":[{"id":"1.170370557","rc":[{"trd":[[2.6,19.69]],"ltp":2.6,"tv":19.69,"id":9622734},{"atl":[[2.6,0]],"id":9622734},{"trd":[[1.61,33.03],[1.62,153.19]],"ltp":1.61,"tv":186.22,"id":9624350},{"atb":[[1.62,0],[1.61,20.67]],"id":9624350}],"con":true,"img":false}]}
{"op":"mcm","clk":"1361980887","pt":1588419717306,"mc":[{"id":"1.170370557","rc":[{"atb":[[2.46,18.21]],"id":9622734},{"atb":[[1.57,149.91]],"id":9624350}],"con":true,"img":false}]}
{"op":"mcm","clk":"1361980889","pt":1588419717409,"mc":[{"id":"1.170370557","rc":[{"atb":[[1.58,43.99]],"id":9624350}],"con":true,"img":false}]}
{"op":"mcm","clk":"1361981928","pt":1588419765977,"mc":[{"id":"1.170370557","rc":[{"trd":[[1.66,32.85]],"ltp":1.66,"tv":32.85,"id":9624350},{"atl":[[1.66,39.45]],"id":9624350}],"con":true,"img":false}]}
{"op":"mcm","clk":"1361986318","pt":1588419928279,"mc":[{"id":"1.170370557","rc":[{"trd":[[2.64,20.42]],"ltp":2.64,"tv":20.42,"id":9622734},{"atb":[[2.64,87.39]],"id":9622734},{"trd":[[1.61,53.71]],"ltp":1.61,"tv":53.71,"id":9624350},{"atb":[[1.61,0]],"id":9624350}],"con":true,"img":false}]}
{"op":"mcm","clk":"1361986340","pt":1588419929469,"mc":[{"id":"1.170370557","rc":[{"atb":[[2.54,17.26]],"id":9622734},{"atb":[[1.56,0],[1.57,103.26],[1.54,49.71]],"id":9624350}],"con":true,"img":false}]}
{"op":"mcm","clk":"1361986359","pt":1588419930497,"mc":[{"id":"1.170370557","rc":[{"atb":[[2.24,0]],"id":9622734},{"atb":[[1.57,0]],"id":9624350}],"con":true,"img":false}]}
{"op":"mcm","clk":"1361986368","pt":1588419930759,"mc":[{"id":"1.170370557","rc":[{"trd":[[2.66,4.25]],"ltp":2.66,"tv":4.25,"id":9622734},{"atb":[[2.66,0]],"id":9622734},{"atl":[[2.66,0]],"id":9622734}],"con":true,"img":false}]}
{"op":"mcm","clk":"1361986376","pt":1588419931070,"mc":[{"id":"1.170370557","rc":[{"atb":[[2.66,0]],"id":9622734}],"con":true,"img":false}]}
{"op":"mcm","clk":"1361987893","pt":1588420004892,"mc":[{"id":"1.170370557","rc":[{"atl":[[1000,2]],"id":9622734}],"con":true,"img":false}]}
{"op":"mcm","clk":"1361987901","pt":1588420005099,"mc":[{"id":"1.170370557","rc":[{"atl":[[1000,1]],"id":9622734}],"con":true,"img":false}]}
{"op":"mcm","clk":"1361987909","pt":1588420005306,"mc":[{"id":"1.170370557","rc":[{"atl":[[1000,0]],"id":9622734}],"con":true,"img":false}]}
{"op":"mcm","clk":"1361987912","pt":1588420005410,"mc":[{"id":"1.170370557","rc":[{"trd":[[2.64,22.42]],"ltp":2.64,"tv":22.42,"id":9622734},{"atb":[[2.64,86.39]],"id":9622734}],"con":true,"img":false}]}
{"op":"mcm","clk":"1361989018","pt":1588420064928,"mc":[{"id":"1.170370557","rc":[{"trd":[[1.6,2.91]],"ltp":1.6,"tv":2.91,"id":9624350},{"atb":[[1.6,42.53]],"id":9624350}],"con":true,"img":false}]}
{"op":"mcm","clk":"1361989469","pt":1588420084948,"mc":[{"id":"1.170370557","rc":[{"trd":[[2.64,38.14]],"ltp":2.64,"tv":38.14,"id":9622734},{"atb":[[2.64,70.67]],"id":9622734},{"trd":[[1.61,79.48]],"ltp":1.61,"tv":79.48,"id":9624350}],"con":true,"img":false}]}
{"op":"mcm","clk":"1361990692","pt":1588420141332,"mc":[{"id":"1.170370557","rc":[{"trd":[[2.64,59.6]],"ltp":2.64,"tv":59.6,"id":9622734},{"atb":[[2.64,49.21]],"id":9622734},{"trd":[[1.61,114.68]],"ltp":1.61,"tv":114.68,"id":9624350}],"con":true,"img":false}]}
{"op":"mcm","clk":"1361991001","pt":1588420155853,"mc":[{"id":"1.170370557","rc":[{"atb":[[1.6,0],[1.58,0],[1.48,0],[1.47,0]],"id":9624350}],"con":true,"img":false}]}
{"op":"mcm","clk":"1361991013","pt":1588420156468,"mc":[{"id":"1.170370557","rc":[{"atb":[[1.52,51.14]],"id":9624350}],"con":true,"img":false}]}
{"op":"mcm","clk":"1361991018","pt":1588420156570,"mc":[{"id":"1.170370557","rc":[{"atb":[[2.4,0]],"id":9622734},{"atb":[[1.54,0.46]],"id":9624350}],"con":true,"img":false}]}
{"op":"mcm","clk":"1361991038","pt":1588420157445,"mc":[{"id":"1.170370557","rc":[{"atb":[[2.6,16.62]],"id":9622734}],"con":true,"img":false}]}
{"op":"mcm","clk":"1361991119","pt":1588420160767,"mc":[{"id":"1.170370557","rc":[{"atb":[[2.24,47.46]],"id":9622734},{"atb":[[1.57,103.26]],"id":9624350}],"con":true,"img":false}]}
{"op":"mcm","clk":"1361991131","pt":1588420161483,"mc":[{"id":"1.170370557","rc":[{"atb":[[2.6,0],[2.56,17.04]],"id":9622734},{"atb":[[1.53,50.17]],"id":9624350}],"con":true,"img":false}]}
{"op":"mcm","clk":"1361991996","pt":1588420205655,"mc":[{"id":"1.170370557","rc":[{"trd":[[2.64,75.96]],"ltp":2.64,"tv":75.96,"id":9622734},{"atb":[[2.64,32.85]],"id":9622734},{"trd":[[1.61,141.51]],"ltp":1.61,"tv":141.51,"id":9624350}],"con":true,"img":false}]}
{"op":"mcm","clk":"1361992218","pt":1588420218486,"mc":[{"id":"1.170370557","rc":[{"atl":[[1000,4.41]],"id":9624350}],"con":true,"img":false}]}
{"op":"mcm","clk":"1361992225","pt":1588420218693,"mc":[{"id":"1.170370557","rc":[{"atl":[[1000,0.88]],"id":9624350}],"con":true,"img":false}]}
{"op":"mcm","clk":"1361992232","pt":1588420218951,"mc":[{"id":"1.170370557","rc":[{"atl":[[1000,0]],"id":9624350}],"con":true,"img":false}]}
{"op":"mcm","clk":"1361992236","pt":1588420219055,"mc":[{"id":"1.170370557","rc":[{"trd":[[2.72,2.33]],"ltp":2.72,"tv":2.33,"id":9622734},{"atl":[[2.72,9.49]],"id":9622734},{"trd":[[1.58,0.88]],"ltp":1.58,"tv":0.88,"id":9624350}],"con":true,"img":false}]}
{"op":"mcm","clk":"1361992782","pt":1588420240504,"mc":[{"id":"1.170370557","rc":[{"trd":[[2.64,87.67]],"ltp":2.64,"tv":87.67,"id":9622734},{"atb":[[2.64,27]],"id":9622734}],"con":true,"img":false}]}
{"op":"mcm","clk":"1361993862","pt":1588420310295,"mc":[{"id":"1.170370557","rc":[{"trd":[[2.64,90.66]],"ltp":2.64,"tv":90.66,"id":9622734},{"atb":[[2.64,24.01]],"id":9622734},{"trd":[[1.61,146.41]],"ltp":1.61,"tv":146.41,"id":9624350}],"con":true,"img":false}]}
{"op":"mcm","clk":"1361994582","pt":1588420375458,"mc":[{"id":"1.170370557","rc":[{"trd":[[2.72,7.36]],"ltp":2.72,"tv":7.36,"id":9622734},{"atl":[[2.72,4.46]],"id":9622734},{"trd":[[1.58,9.54]],"ltp":1.58,"tv":9.54,"id":9624350}],"con":true,"img":false}]}
{"op":"mcm","clk":"1361995451","pt":1588420458941,"mc":[{"id":"1.170370557","rc":[{"atb":[[2.64,27.79]],"id":9622734}],"con":true,"img":false}]}
{"op":"mcm","clk":"1361996498","pt":1588420568065,"mc":[{"id":"1.170370557","marketDefinition":{"bspMarket":false,"turnInPlayEnabled":true,"persistenceEnabled":true,"marketBaseRate":5.0,"eventId":"29788106","eventTypeId":"2","numberOfWinners":1,"bettingType":"ODDS","marketType":"MATCH_ODDS","marketTime":"2020-05-02T12:20:00.000Z","suspendTime":"2020-05-02T12:20:00.000Z","bspReconciled":false,"complete":true,"inPlay":false,"crossMatching":true,"runnersVoidable":false,"numberOfActiveRunners":2,"betDelay":0,"status":"OPEN","runners":[{"status":"ACTIVE","sortPriority":1,"id":9624350,"name":"Y Hanfmann"},{"status":"ACTIVE","sortPriority":2,"id":9622734,"name":"D Brown"}],"regulators":["MR_INT"],"countryCode":"GB","discountAllowed":true,"timezone":"GMT","openDate":"2020-05-02T12:05:00.000Z","version":3237523862,"name":"Match Odds","eventName":"Y Hanfmann v D Brown"},"rc":[],"con":true,"img":false}]}
{"op":"mcm","clk":"1361996638","pt":1588420584087,"mc":[{"id":"1.170370557","marketDefinition":{"bspMarket":false,"turnInPlayEnabled":true,"persistenceEnabled":true,"marketBaseRate":5.0,"eventId":"29788106","eventTypeId":"2","numberOfWinners":1,"bettingType":"ODDS","marketType":"MATCH_ODDS","marketTime":"2020-05-02T12:20:00.000Z","suspendTime":"2020-05-02T12:20:00.000Z","bspReconciled":false,"complete":true,"inPlay":false,"crossMatching":true,"runnersVoidable":false,"numberOfActiveRunners":2,"betDelay":0,"status":"OPEN","runners":[{"status":"ACTIVE","sortPriority":1,"id":9624350,"name":"Y Hanfmann"},{"status":"ACTIVE","sortPriority":2,"id":9622734,"name":"D Brown"}],"regulators":["MR_INT"],"countryCode":"GB","discountAllowed":true,"timezone":"GMT","openDate":"2020-05-02T12:20:00.000Z","version":3237523862,"name":"Match Odds","eventName":"Y Hanfmann v D Brown"},"rc":[],"con":true,"img":false}]}
{"op":"mcm","clk":"1361996646","pt":1588420585483,"mc":[{"id":"1.170370557","rc":[{"trd":[[2.64,91.07]],"ltp":2.64,"tv":91.07,"id":9622734},{"atb":[[2.64,27.58]],"id":9622734}],"con":true,"img":false}]}
{"op":"mcm","clk":"1361996709","pt":1588420591730,"mc":[{"id":"1.170370557","rc":[{"trd":[[2.72,11.82]],"ltp":2.72,"tv":11.82,"id":9622734},{"atl":[[2.72,0]],"id":9622734},{"trd":[[1.57,84.64],[1.58,17.22]],"ltp":1.57,"tv":101.86,"id":9624350},{"atb":[[1.57,60.94]],"id":9624350}],"con":true,"img":false}]}
{"op":"mcm","clk":"1361996772","pt":1588420596696,"mc":[{"id":"1.170370557","rc":[{"atb":[[1.57,164.2]],"id":9624350}],"con":true,"img":false}]}
{"op":"mcm","clk":"1361996774","pt":1588420596799,"mc":[{"id":"1.170370557","rc":[{"atb":[[1.57,103.26]],"id":9624350}],"con":true,"img":false}]}
{"op":"mcm","clk":"1361997694","pt":1588420685390,"mc":[{"id":"1.170370557","rc":[{"atb":[[1.1,124.78]],"id":9622734}],"con":true,"img":false}]}
{"op":"mcm","clk":"1361997787","pt":1588420694437,"mc":[{"id":"1.170370557","rc":[{"atb":[[1.1,125.57]],"id":9622734}],"con":true,"img":false}]}
{"op":"mcm","clk":"1361997830","pt":1588420697942,"mc":[{"id":"1.170370557","rc":[{"trd":[[1.57,95.13]],"ltp":1.57,"tv":95.13,"id":9624350},{"atb":[[1.57,98.01]],"id":9624350}],"con":true,"img":false}]}
{"op":"mcm","clk":"1361997868","pt":1588420701904,"mc":[{"id":"1.170370557","rc":[{"atb":[[1.57,201.27]],"id":9624350}],"con":true,"img":false}]}
{"op":"mcm","clk":"1361997869","pt":1588420702007,"mc":[{"id":"1.170370557","rc":[{"atb":[[1.57,103.26]],"id":9624350}],"con":true,"img":false}]}
{"op":"mcm","clk":"1361997893","pt":1588420703807,"mc":[{"id":"1.170370557","rc":[{"atb":[[1.1,122.38]],"id":9622734}],"con":true,"img":false}]}
{"op":"mcm","clk":"1361999998","pt":1588420826066,"mc":[{"id":"1.170370557","rc":[{"trd":[[1.57,106.79]],"ltp":1.57,"tv":106.79,"id":9624350},{"atb":[[1.57,97.43]],"id":9624350}],"con":true,"img":false}]}
{"op":"mcm","clk":"1362000012","pt":1588420827193,"mc":[{"id":"1.170370557","rc":[{"atb":[[1.57,103.26]],"id":9624350}],"con":true,"img":false}]}
{"op":"mcm","clk":"1362000106","pt":1588420836195,"mc":[{"id":"1.170370557","rc":[{"atb":[[2.6,2.04],[2.58,2.06]],"id":9622734},{"atl":[[2.82,12.25],[2.8,2.02]],"id":9622734},{"atb":[[1.55,2],[1.54,2.58]],"id":9624350},{"atl":[[1.64,2.04],[1.63,2.04]],"id":9624350}],"con":true,"img":false}]}
{"op":"mcm","clk":"1362000142","pt":1588420838510,"mc":[{"id":"1.170370557","rc":[{"atb":[[1.01,11.79]],"id":9624350}],"con":true,"img":false}]}
{"op":"mcm","clk":"1362000149","pt":1588420838920,"mc":[{"id":"1.170370557","rc":[{"atb":[[1.01,10.14]],"id":9624350}],"con":true,"img":false}]}
{"op":"mcm","clk":"1362000154","pt":1588420839184,"mc":[{"id":"1.170370557","rc":[{"atb":[[1.01,9.79]],"id":9624350}],"con":true,"img":false}]}
{"op":"mcm","clk":"1362000157","pt":1588420839286,"mc":[{"id":"1.170370557","rc":[{"trd":[[2.64,91.28]],"ltp":2.64,"tv":91.28,"id":9622734},{"atb":[[2.64,27.37]],"id":9622734},{"trd":[[1.61,146.76]],"ltp":1.61,"tv":146.76,"id":9624350}],"con":true,"img":false}]}
{"op":"mcm","clk":"1362001352","pt":1588420956135,"mc":[{"id":"1.170370557","rc":[{"atl":[[1.6,0.1]],"id":9624350}],"con":true,"img":false}]}
{"op":"mcm","clk":"1362001357","pt":1588420956508,"mc":[{"id":"1.170370557","rc":[{"atb":[[2.58,0]],"id":9622734},{"atl":[[2.82,10]],"id":9622734},{"atb":[[1.54,0.46]],"id":9624350},{"atl":[[1.64,0]],"id":9624350}],"con":true,"img":false}]}
{"op":"mcm","clk":"1362001361","pt":1588420956707,"mc":[{"id":"1.170370557","rc":[{"atb":[[2.58,2.06]],"id":9622734},{"atl":[[2.82,12.25]],"id":9622734},{"atb":[[1.54,2.48]],"id":9624350},{"atl":[[1.64,2.04]],"id":9624350}],"con":true,"img":false}]}
{"op":"mcm","clk":"1362001384","pt":1588420958515,"mc":[{"id":"1.170370557","rc":[{"atl":[[1.6,0]],"id":9624350}],"con":true,"img":false}]}
{"op":"mcm","clk":"1362001622","pt":1588420978225,"mc":[{"id":"1.170370557","rc":[{"atb":[[1.58,2.36]],"id":9624350}],"con":true,"img":false}]}
{"op":"mcm","clk":"1362001626","pt":1588420978535,"mc":[{"id":"1.170370557","rc":[{"atb":[[2.58,0]],"id":9622734},{"atl":[[2.82,10]],"id":9622734},{"atb":[[1.54,0.46]],"id":9624350},{"atl":[[1.64,0]],"id":9624350}],"con":true,"img":false}]}
{"op":"mcm","clk":"1362001628","pt":1588420978738,"mc":[{"id":"1.170370557","rc":[{"atb":[[2.58,2.06]],"id":9622734},{"atl":[[2.82,12.02]],"id":9622734},{"atb":[[1.54,2.56]],"id":9624350},{"atl":[[1.64,2.04]],"id":9624350}],"con":true,"img":false}]}
{"op":"mcm","clk":"1362001630","pt":1588420978944,"mc":[{"id":"1.170370557","rc":[{"trd":[[1.58,21.96]],"ltp":1.58,"tv":21.96,"id":9624350},{"atb":[[1.58,0]],"id":9624350},{"atl":[[1.58,0.63]],"id":9624350}],"con":true,"img":false}]}
{"op":"mcm","clk":"1362001661","pt":1588420981834,"mc":[{"id":"1.170370557","rc":[{"atl":[[1.58,0]],"id":9624350}],"con":true,"img":false}]}
{"op":"mcm","clk":"1362001731","pt":1588420989074,"mc":[{"id":"1.170370557","rc":[{"atb":[[1.5,1.77]],"id":9624350}],"con":true,"img":false}]}
{"op":"mcm","clk":"1362001737","pt":1588420989451,"mc":[{"id":"1.170370557","rc":[{"atb":[[2.58,0]],"id":9622734},{"atl":[[2.82,10]],"id":9622734},{"atb":[[1.54,0.46]],"id":9624350},{"atl":[[1.64,0]],"id":9624350}],"con":true,"img":false}]}
{"op":"mcm","clk":"1362001740","pt":1588420989650,"mc":[{"id":"1.170370557","rc":[{"atb":[[2.58,2.06]],"id":9622734},{"atl":[[2.82,12.08]],"id":9622734},{"atb":[[1.54,2.56]],"id":9624350},{"atl":[[1.64,2.18]],"id":9624350}],"con":true,"img":false}]}
{"op":"mcm","clk":"1362001791","pt":1588420993454,"mc":[{"id":"1.170370557","rc":[{"atb":[[1.6,2]],"id":9624350}],"con":true,"img":false}]}
{"op":"mcm","clk":"1362001793","pt":1588420993659,"mc":[{"id":"1.170370557","rc":[{"atb":[[1.58,2],[1.57,105.32]],"id":9624350}],"con":true,"img":false}]}
{"op":"mcm","clk":"1362001796","pt":1588420993764,"mc":[{"id":"1.170370557","rc":[{"atb":[[2.52,17.5]],"id":9622734}],"con":true,"img":false}]}
{"op":"mcm","clk":"1362001798","pt":1588420993866,"mc":[{"id":"1.170370557","rc":[{"atb":[[2.54,0],[2.56,0]],"id":9622734}],"con":true,"img":false}]}
{"op":"mcm","clk":"1362001801","pt":1588420993968,"mc":[{"id":"1.170370557","rc":[{"atb":[[1.55,0]],"id":9624350}],"con":true,"img":false}]}
{"op":"mcm","clk":"1362001830","pt":1588420996757,"mc":[{"id":"1.170370557","rc":[{"trd":[[1.6,6.91]],"ltp":1.6,"tv":6.91,"id":9624350},{"atb":[[1.6,0]],"id":9624350},{"atl":[[1.6,0.36]],"id":9624350}],"con":true,"img":false}]}
{"op":"mcm","clk":"1362001832","pt":1588420996961,"mc":[{"id":"1.170370557","rc":[{"atb":[[1.56,2.08],[1.55,2.19]],"id":9624350}],"con":true,"img":false}]}
{"op":"mcm","clk":"1362001835","pt":1588420997062,"mc":[{"id":"1.170370557","rc":[{"atl":[[1.64,0]],"id":9624350}],"con":true,"img":false}]}
{"op":"mcm","clk":"1362001837","pt":1588420997167,"mc":[{"id":"1.170370557","rc":[{"atb":[[2.58,0]],"id":9622734},{"atl":[[2.82,10]],"id":9622734},{"atb":[[1.58,0]],"id":9624350}],"con":true,"img":false}]}
{"op":"mcm","clk":"1362001840","pt":1588420997270,"mc":[{"id":"1.170370557","rc":[{"atb":[[1.57,103.26]],"id":9624350}],"con":true,"img":false}]}
{"op":"mcm","clk":"1362001843","pt":1588420997474,"mc":[{"id":"1.170370557","rc":[{"atb":[[2.58,2.06]],"id":9622734},{"atl":[[2.82,12.25]],"id":9622734},{"atb":[[1.56,0],[1.54,0.46]],"id":9624350},{"atl":[[1.64,2.04]],"id":9624350}],"con":true,"img":false}]}
{"op":"mcm","clk":"1362001848","pt":1588420997679,"mc":[{"id":"1.170370557","rc":[{"atb":[[1.54,2.56]],"id":9624350}],"con":true,"img":false}]}
{"op":"mcm","clk":"1362001850","pt":1588420997782,"mc":[{"id":"1.170370557","rc":[{"atb":[[2.56,17.04]],"id":9622734}],"con":true,"img":false}]}
{"op":"mcm","clk":"1362001919","pt":1588421003471,"mc":[{"id":"1.170370557","rc":[{"trd":[[1.6,7.65]],"ltp":1.6,"tv":7.65,"id":9624350},{"atb":[[1.6,1.63]],"id":9624350},{"atl":[[1.6,0]],"id":9624350}],"con":true,"img":false}]}
{"op":"mcm","clk":"1362001924","pt":1588421003884,"mc":[{"id":"1.170370557","rc":[{"atb":[[2.58,0]],"id":9622734},{"atl":[[2.82,10]],"id":9622734},{"atb":[[1.54,0.46]],"id":9624350},{"atl":[[1.64,0]],"id":9624350}],"con":true,"img":false}]}
{"op":"mcm","clk":"1362001927","pt":1588421004089,"mc":[{"id":"1.170370557","rc":[{"atb":[[2.58,2.06]],"id":9622734},{"atl":[[2.82,12.08]],"id":9622734},{"atb":[[1.54,2.54]],"id":9624350},{"atl":[[1.64,2.04]],"id":9624350}],"con":true,"img":false}]}
{"op":"mcm","clk":"1362001959","pt":1588421005585,"mc":[{"id":"1.170370557","rc":[{"atb":[[1.6,0]],"id":9624350}],"con":true,"img":false}]}
{"op":"mcm","clk":"1362002173","pt":1588421024898,"mc":[{"id":"1.170370557","rc":[{"atl":[[1.58,3]],"id":9624350}],"con":true,"img":false}]}
{"op":"mcm","clk":"1362002175","pt":1588421025107,"mc":[{"id":"1.170370557","rc":[{"atl":[[1.6,2.01],[1.61,2.14]],"id":9624350}],"con":true,"img":false}]}
{"op":"mcm","clk":"1362002178","pt":1588421025207,"mc":[{"id":"1.170370557","rc":[{"atl":[[2.82,10]],"id":9622734},{"atl":[[1.64,0]],"id":9624350}],"con":true,"img":false}]}
{"op":"mcm","clk":"1362002182","pt":1588421025310,"mc":[{"id":"1.170370557","rc":[{"atb":[[2.58,0]],"id":9622734},{"atb":[[1.54,0.46]],"id":9624350}],"con":true,"img":false}]}
{"op":"mcm","clk":"1362002184","pt":1588421025412,"mc":[{"id":"1.170370557","rc":[{"atl":[[2.82,12.25]],"id":9622734},{"atl":[[1.63,0]],"id":9624350}],"con":true,"img":false}]}
{"op":"mcm","clk":"1362002188","pt":1588421025513,"mc":[{"id":"1.170370557","rc":[{"atb":[[2.58,2.06]],"id":9622734},{"atb":[[1.54,2.54]],"id":9624350}],"con":true,"img":false}]}
{"op":"mcm","clk":"1362002194","pt":1588421025776,"mc":[{"id":"1.170370557","rc":[{"atb":[[1.51,52.14],[1.53,0],[1.52,0]],"id":9624350}],"con":true,"img":false}]}
{"op":"mcm","clk":"1362002214","pt":1588421027374,"mc":[{"id":"1.170370557","rc":[{"trd":[[1.58,26.7]],"ltp":1.58,"tv":26.7,"id":9624350},{"atl":[[1.58,0.63]],"id":9624350}],"con":true,"img":false}]}
{"op":"mcm","clk":"1362002219","pt":1588421027577,"mc":[{"id":"1.170370557","rc":[{"atl":[[1.63,2.04],[1.62,2.17]],"id":9624350}],"con":true,"img":false}]}
{"op":"mcm","clk":"1362002222","pt":1588421027680,"mc":[{"id":"1.170370557","rc":[{"atb":[[1.53,50.17]],"id":9624350},{"atl":[[1.6,0],[1.61,0]],"id":9624350}],"con":true,"img":false}]}
{"op":"mcm","clk":"1362002225","pt":1588421027882,"mc":[{"id":"1.170370557","rc":[{"atl":[[1.64,2.04]],"id":9624350}],"con":true,"img":false}]}
{"op":"mcm","clk":"1362002226","pt":1588421027984,"mc":[{"id":"1.170370557","rc":[{"atl":[[1.62,0]],"id":9624350}],"con":true,"img":false}]}
{"op":"mcm","clk":"1362002245","pt":1588421029985,"mc":[{"id":"1.170370557","rc":[{"atl":[[1.58,0]],"id":9624350}],"con":true,"img":false}]}
{"op":"mcm","clk":"1362002515","pt":1588421057707,"mc":[{"id":"1.170370557","rc":[{"atb":[[1.6,3]],"id":9624350}],"con":true,"img":false}]}
{"op":"mcm","clk":"1362002519","pt":1588421057910,"mc":[{"id":"1.170370557","rc":[{"atb":[[1.58,2.06],[1.57,105.32]],"id":9624350}],"con":true,"img":false}]}
{"op":"mcm","clk":"1362002521","pt":1588421058016,"mc":[{"id":"1.170370557","rc":[{"atb":[[2.58,0]],"id":9622734},{"atl":[[2.82,10]],"id":9622734},{"atb":[[1.54,0.46]],"id":9624350},{"atl":[[1.64,0]],"id":9624350}],"con":true,"img":false}]}
{"op":"mcm","clk":"1362002523","pt":1588421058320,"mc":[{"id":"1.170370557","rc":[{"atb":[[1.55,0]],"id":9624350}],"con":true,"img":false}]}
{"op":"mcm","clk":"1362002525","pt":1588421058526,"mc":[{"id":"1.170370557","rc":[{"atb":[[2.58,2.06]],"id":9622734},{"atl":[[2.82,12.08]],"id":9622734},{"atl":[[1.64,2.18]],"id":9624350}],"con":true,"img":false}]}
{"op":"mcm","clk":"1362002527","pt":1588421058938,"mc":[{"id":"1.170370557","rc":[{"atb":[[2.56,0]],"id":9622734}],"con":true,"img":false}]}
{"op":"mcm","clk":"1362002543","pt":1588421060119,"mc":[{"id":"1.170370557","rc":[{"trd":[[1.6,13.65]],"ltp":1.6,"tv":13.65,"id":9624350},{"atb":[[1.6,0]],"id":9624350},{"atl":[[1.6,1.02]],"id":9624350}],"con":true,"img":false}]}
{"op":"mcm","clk":"1362002546","pt":1588421060323,"mc":[{"id":"1.170370557","rc":[{"atb":[[1.56,2.06],[1.55,2.19]],"id":9624350}],"con":true,"img":false}]}
{"op":"mcm","clk":"1362002549","pt":1588421060425,"mc":[{"id":"1.170370557","rc":[{"atb":[[1.58,0],[1.57,103.26]],"id":9624350}],"con":true,"img":false}]}
{"op":"mcm","clk":"1362002551","pt":1588421060632,"mc":[{"id":"1.170370557","rc":[{"atb":[[1.54,2.52]],"id":9624350}],"con":true,"img":false}]}
{"op":"mcm","clk":"1362002553","pt":1588421060735,"mc":[{"id":"1.170370557","rc":[{"atb":[[1.56,0]],"id":9624350}],"con":true,"img":false}]}
{"op":"mcm","clk":"1362002555","pt":1588421060835,"mc":[{"id":"1.170370557","rc":[{"atb":[[2.56,17.04]],"id":9622734}],"con":true,"img":false}]}
{"op":"mcm","clk":"1362002613","pt":1588421067060,"mc":[{"id":"1.170370557","rc":[{"trd":[[1.6,15.7]],"ltp":1.6,"tv":15.7,"id":9624350},{"atb":[[1.6,0.97]],"id":9624350},{"atl":[[1.6,0]],"id":9624350}],"con":true,"img":false}]}
{"op":"mcm","clk":"1362002621","pt":1588421067324,"mc":[{"id":"1.170370557","rc":[{"atl":[[2.82,10]],"id":9622734},{"atl":[[1.64,0]],"id":9624350}],"con":true,"img":false}]}
{"op":"mcm","clk":"1362002622","pt":1588421067425,"mc":[{"id":"1.170370557","rc":[{"atb":[[2.58,0]],"id":9622734},{"atb":[[1.54,0.46]],"id":9624350}],"con":true,"img":false}]}
{"op":"mcm","clk":"1362002625","pt":1588421067528,"mc":[{"id":"1.170370557","rc":[{"atl":[[2.82,12.25]],"id":9622734},{"atl":[[1.64,2.04]],"id":9624350}],"con":true,"img":false}]}
{"op":"mcm","clk":"1362002627","pt":1588421067629,"mc":[{"id":"1.170370557","rc":[{"atb":[[2.58,2.06]],"id":9622734},{"atb":[[1.54,2.58]],"id":9624350}],"con":true,"img":false}]}
{"op":"mcm","clk":"1362002636","pt":1588421068756,"mc":[{"id":"1.170370557","rc":[{"atb":[[1.6,0]],"id":9624350}],"con":true,"img":false}]}
{"op":"mcm","clk":"1362003298","pt":1588421128924,"mc":[{"id":"1.170370557","rc":[{"atl":[[1.58,3]],"id":9624350}],"con":true,"img":false}]}
{"op":"mcm","clk":"1362003300","pt":1588421129130,"mc":[{"id":"1.170370557","rc":[{"atl":[[1.6,2.01],[1.61,2.01]],"id":9624350}],"con":true,"img":false}]}
{"op":"mcm","clk":"1362003303","pt":1588421129288,"mc":[{"id":"1.170370557","rc":[{"atb":[[2.58,0]],"id":9622734},{"atl":[[2.82,10]],"id":9622734},{"atb":[[1.54,0.46]],"id":9624350},{"atl":[[1.64,0]],"id":9624350}],"con":true,"img":false}]}
{"op":"mcm","clk":"1362003307","pt":1588421129594,"mc":[{"id":"1.170370557","rc":[{"atl":[[1.63,0]],"id":9624350}],"con":true,"img":false}]}
{"op":"mcm","clk":"1362003309","pt":1588421129799,"mc":[{"id":"1.170370557","rc":[{"atb":[[2.58,2.06]],"id":9622734},{"atl":[[2.82,12.08]],"id":9622734},{"atb":[[1.53,0],[1.54,2.58]],"id":9624350}],"con":true,"img":false}]}
{"op":"mcm","clk":"1362003322","pt":1588421131399,"mc":[{"id":"1.170370557","rc":[{"trd":[[1.58,32.7]],"ltp":1.58,"tv":32.7,"id":9624350},{"atb":[[1.58,1.14]],"id":9624350},{"atl":[[1.58,0]],"id":9624350}],"con":true,"img":false}]}
{"op":"mcm","clk":"1362003323","pt":1588421131602,"mc":[{"id":"1.170370557","rc":[{"atl":[[1.63,2.04],[1.62,2.17]],"id":9624350}],"con":true,"img":false}]}
{"op":"mcm","clk":"1362003324","pt":1588421131705,"mc":[{"id":"1.170370557","rc":[{"atl":[[1.6,0],[1.61,0]],"id":9624350}],"con":true,"img":false}]}
{"op":"mcm","clk":"1362003325","pt":1588421131809,"mc":[{"id":"1.170370557","rc":[{"atb":[[1.53,50.17]],"id":9624350}],"con":true,"img":false}]}
{"op":"mcm","clk":"1362003328","pt":1588421131912,"mc":[{"id":"1.170370557","rc":[{"atl":[[1.64,2.18],[1.65,2.1]],"id":9624350}],"con":true,"img":false}]}
{"op":"mcm","clk":"1362003330","pt":1588421132016,"mc":[{"id":"1.170370557","rc":[{"atl":[[1.63,0],[1.62,0]],"id":9624350}],"con":true,"img":false}]}
{"op":"mcm","clk":"1362003332","pt":1588421132220,"mc":[{"id":"1.170370557","rc":[{"atl":[[1.63,2.04]],"id":9624350}],"con":true,"img":false}]}
{"op":"mcm","clk":"1362003412","pt":1588421139141,"mc":[{"id":"1.170370557","rc":[{"trd":[[1.58,34.99]],"ltp":1.58,"tv":34.99,"id":9624350},{"atb":[[1.58,0]],"id":9624350},{"atl":[[1.58,0.85]],"id":9624350}],"con":true,"img":false}]}
{"op":"mcm","clk":"1362003422","pt":1588421139505,"mc":[{"id":"1.170370557","rc":[{"atb":[[2.58,0]],"id":9622734},{"atl":[[2.82,10]],"id":9622734},{"atb":[[1.54,0.46]],"id":9624350},{"atl":[[1.64,0],[1.65,0]],"id":9624350}],"con":true,"img":false}]}
{"op":"mcm","clk":"1362003425","pt":1588421139709,"mc":[{"id":"1.170370557","rc":[{"atb":[[2.58,2.02]],"id":9622734},{"atl":[[2.82,12.08]],"id":9622734},{"atb":[[1.54,2.58]],"id":9624350},{"atl":[[1.64,2.18]],"id":9624350}],"con":true,"img":false}]}
{"op":"mcm","clk":"1362003450","pt":1588421141005,"mc":[{"id":"1.170370557","rc":[{"atl":[[1.58,0]],"id":9624350}],"con":true,"img":false}]}
{"op":"mcm","clk":"1362003638","pt":1588421160532,"mc":[{"id":"1.170370557","rc":[{"atb":[[1.6,3]],"id":9624350}],"con":true,"img":false}]}
{"op":"mcm","clk":"1362003643","pt":1588421160738,"mc":[{"id":"1.170370557","rc":[{"atb":[[1.58,2.06],[1.57,105.3]],"id":9624350}],"con":true,"img":false}]}
{"op":"mcm","clk":"1362003647","pt":1588421160845,"mc":[{"id":"1.170370557","rc":[{"atb":[[2.58,0]],"id":9622734},{"atl":[[2.82,10]],"id":9622734},{"atb":[[1.54,0.46]],"id":9624350},{"atl":[[1.64,0]],"id":9624350}],"con":true,"img":false}]}
{"op":"mcm","clk":"1362003649","pt":1588421161156,"mc":[{"id":"1.170370557","rc":[{"atb":[[1.55,0]],"id":9624350}],"con":true,"img":false}]}
{"op":"mcm","clk":"1362003653","pt":1588421161320,"mc":[{"id":"1.170370557","rc":[{"atb":[[2.58,2.06]],"id":9622734},{"atl":[[2.82,12.08]],"id":9622734},{"atl":[[1.64,2.18]],"id":9624350}],"con":true,"img":false}]}
{"op":"mcm","clk":"1362003659","pt":1588421161941,"mc":[{"id":"1.170370557","rc":[{"atb":[[2.56,0]],"id":9622734}],"con":true,"img":false}]}
{"op":"mcm","clk":"1362003663","pt":1588421162923,"mc":[{"id":"1.170370557","rc":[{"trd":[[1.6,21.7]],"ltp":1.6,"tv":21.7,"id":9624350},{"atb":[[1.6,0]],"id":9624350},{"atl":[[1.6,1.14]],"id":9624350}],"con":true,"img":false}]}
{"op":"mcm","clk":"1362003666","pt":1588421163132,"mc":[{"id":"1.170370557","rc":[{"atb":[[1.56,2.04],[1.55,2.19]],"id":9624350}],"con":true,"img":false}]}
{"op":"mcm","clk":"1362003668","pt":1588421163239,"mc":[{"id":"1.170370557","rc":[{"atb":[[1.58,0],[1.57,103.26]],"id":9624350}],"con":true,"img":false}]}
{"op":"mcm","clk":"1362003670","pt":1588421163444,"mc":[{"id":"1.170370557","rc":[{"atb":[[1.54,2.58]],"id":9624350}],"con":true,"img":false}]}
{"op":"mcm","clk":"1362003672","pt":1588421163544,"mc":[{"id":"1.170370557","rc":[{"atb":[[1.56,0]],"id":9624350}],"con":true,"img":false}]}
{"op":"mcm","clk":"1362003675","pt":1588421163750,"mc":[{"id":"1.170370557","rc":[{"atb":[[2.56,17.04]],"id":9622734}],"con":true,"img":false}]}
{"op":"mcm","clk":"1362003711","pt":1588421168463,"mc":[{"id":"1.170370557","rc":[{"trd":[[1.6,24]],"ltp":1.6,"tv":24.0,"id":9624350},{"atb":[[1.6,0.85]],"id":9624350},{"atl":[[1.6,0]],"id":9624350}],"con":true,"img":false}]}
{"op":"mcm","clk":"1362003714","pt":1588421168725,"mc":[{"id":"1.170370557","rc":[{"atb":[[2.58,0]],"id":9622734},{"atl":[[2.82,10]],"id":9622734},{"atl":[[1.64,0]],"id":9624350}],"con":true,"img":false}]}
{"op":"mcm","clk":"1362003716","pt":1588421168929,"mc":[{"id":"1.170370557","rc":[{"atb":[[2.58,2.06]],"id":9622734},{"atl":[[2.82,12]],"id":9622734},{"atl":[[1.64,2.04]],"id":9624350}],"con":true,"img":false}]}
{"op":"mcm","clk":"1362003731","pt":1588421170328,"mc":[{"id":"1.170370557","rc":[{"atb":[[1.6,0]],"id":9624350}],"con":true,"img":false}]}
{"op":"mcm","clk":"1362003736","pt":1588421170634,"mc":[{"id":"1.170370557","rc":[{"atb":[[1.54,0.46]],"id":9624350}],"con":true,"img":false}]}
{"op":"mcm","clk":"1362003740","pt":1588421170839,"mc":[{"id":"1.170370557","rc":[{"atb":[[1.54,2.58]],"id":9624350}],"con":true,"img":false}]}
{"op":"mcm","clk":"1362004097","pt":1588421203467,"mc":[{"id":"1.170370557","rc":[{"atb":[[1.58,4.73]],"id":9624350}],"con":true,"img":false}]}
{"op":"mcm","clk":"1362004099","pt":1588421203675,"mc":[{"id":"1.170370557","rc":[{"atb":[[2.58,0]],"id":9622734},{"atl":[[2.82,10]],"id":9622734},{"atb":[[1.56,2.08],[1.54,0.46]],"id":9624350},{"atl":[[1.64,0]],"id":9624350}],"con":true,"img":false}]}
{"op":"mcm","clk":"1362004101","pt":1588421203897,"mc":[{"id":"1.170370557","rc":[{"atb":[[2.58,2]],"id":9622734},{"atl":[[2.78,2.41]],"id":9622734},{"atl":[[1.64,2.18]],"id":9624350}],"con":true,"img":false}]}
{"op":"mcm","clk":"1362004102","pt":1588421203983,"mc":[{"id":"1.170370557","rc":[{"atb":[[1.55,0]],"id":9624350}],"con":true,"img":false}]}
{"op":"mcm","clk":"1362004105","pt":1588421204187,"mc":[{"id":"1.170370557","rc":[{"atl":[[2.8,0]],"id":9622734}],"con":true,"img":false}]}
{"op":"mcm","clk":"1362004109","pt":1588421204397,"mc":[{"id":"1.170370557","rc":[{"atl":[[2.8,2.02]],"id":9622734},{"atb":[[1.55,2.08]],"id":9624350}],"con":true,"img":false}]}
{"op":"mcm","clk":"1362004122","pt":1588421205278,"mc":[{"id":"1.170370557","rc":[{"trd":[[1.58,42.99]],"ltp":1.58,"tv":42.99,"id":9624350},{"atb":[[1.58,0.73]],"id":9624350}],"con":true,"img":false}]}
{"op":"mcm","clk":"1362004126","pt":1588421205480,"mc":[{"id":"1.170370557","rc":[{"atb":[[1.54,2.48]],"id":9624350}],"con":true,"img":false}]}
{"op":"mcm","clk":"1362004127","pt":1588421205582,"mc":[{"id":"1.170370557","rc":[{"atb":[[1.56,0]],"id":9624350}],"con":true,"img":false}]}
{"op":"mcm","clk":"1362004131","pt":1588421205788,"mc":[{"id":"1.170370557","rc":[{"atl":[[2.82,12.25]],"id":9622734}],"con":true,"img":false}]}
{"op":"mcm","clk":"1362004132","pt":1588421205892,"mc":[{"id":"1.170370557","rc":[{"atl":[[2.78,0.16]],"id":9622734}],"con":true,"img":false}]}
{"op":"mcm","clk":"1362004208","pt":1588421213287,"mc":[{"id":"1.170370557","rc":[{"trd":[[1.58,44.47]],"ltp":1.58,"tv":44.47,"id":9624350},{"atb":[[1.58,0]],"id":9624350},{"atl":[[1.58,1.26]],"id":9624350}],"con":true,"img":false}]}
{"op":"mcm","clk":"1362004213","pt":1588421213591,"mc":[{"id":"1.170370557","rc":[{"atb":[[2.58,0]],"id":9622734},{"atl":[[2.82,10]],"id":9622734},{"atb":[[1.54,0.46]],"id":9624350},{"atl":[[1.64,0]],"id":9624350}],"con":true,"img":false}]}
{"op":"mcm","clk":"1362004214","pt":1588421213799,"mc":[{"id":"1.170370557","rc":[{"atb":[[2.58,2.06]],"id":9622734},{"atl":[[2.82,12.25]],"id":9622734},{"atb":[[1.54,2.58]],"id":9624350},{"atl":[[1.64,2.18]],"id":9624350}],"con":true,"img":false}]}
{"op":"mcm","clk":"1362004215","pt":1588421213899,"mc":[{"id":"1.170370557","rc":[{"atb":[[1.53,0]],"id":9624350}],"con":true,"img":false}]}
{"op":"mcm","clk":"1362004222","pt":1588421215030,"mc":[{"id":"1.170370557","rc":[{"atl":[[1.58,0]],"id":9624350}],"con":true,"img":false}]}
{"op":"mcm","clk":"1362004224","pt":1588421215866,"mc":[{"id":"1.170370557","rc":[{"atb":[[1.53,50.17]],"id":9624350}],"con":true,"img":false}]}
{"op":"mcm","clk":"1362004511","pt":1588421246156,"mc":[{"id":"1.170370557","rc":[{"atb":[[2.26,101.34]],"id":9622734}],"con":true,"img":false}]}
{"op":"mcm","clk":"1362004512","pt":1588421246463,"mc":[{"id":"1.170370557","rc":[{"atb":[[2.58,0]],"id":9622734},{"atb":[[1.54,0.46]],"id":9624350},{"atl":[[1.64,0]],"id":9624350}],"con":true,"img":false}]}
{"op":"mcm","clk":"1362004514","pt":1588421246565,"mc":[{"id":"1.170370557","rc":[{"atl":[[2.82,10]],"id":9622734}],"con":true,"img":false}]}
{"op":"mcm","clk":"1362004519","pt":1588421246770,"mc":[{"id":"1.170370557","rc":[{"atb":[[2.58,2.06]],"id":9622734},{"atl":[[2.82,12.25]],"id":9622734},{"atb":[[1.54,2.58]],"id":9624350},{"atl":[[1.64,2.01]],"id":9624350}],"con":true,"img":false}]}
{"op":"mcm","clk":"1362004822","pt":1588421276386,"mc":[{"id":"1.170370557","rc":[{"atb":[[1.6,4]],"id":9624350}],"con":true,"img":false}]}
{"op":"mcm","clk":"1362004826","pt":1588421276584,"mc":[{"id":"1.170370557","rc":[{"atb":[[1.58,2.06],[1.57,105.32]],"id":9624350}],"con":true,"img":false}]}
{"op":"mcm","clk":"1362004827","pt":1588421276686,"mc":[{"id":"1.170370557","rc":[{"atb":[[2.58,0]],"id":9622734},{"atl":[[2.82,10]],"id":9622734},{"atb":[[1.54,0.46]],"id":9624350},{"atl":[[1.64,0]],"id":9624350}],"con":true,"img":false}]}
{"op":"mcm","clk":"1362004828","pt":1588421276790,"mc":[{"id":"1.170370557","rc":[{"atl":[[2.72,2.16],[2.74,2.21]],"id":9622734}],"con":true,"img":false}]}
{"op":"mcm","clk":"1362004829","pt":1588421276994,"mc":[{"id":"1.170370557","rc":[{"atb":[[2.56,0]],"id":9622734},{"atb":[[1.55,0]],"id":9624350}],"con":true,"img":false}]}
{"op":"mcm","clk":"1362004830","pt":1588421277096,"mc":[{"id":"1.170370557","rc":[{"atb":[[2.58,2.06]],"id":9622734},{"atl":[[1.64,2.04]],"id":9624350}],"con":true,"img":false}]}
{"op":"mcm","clk":"1362004831","pt":1588421277198,"mc":[{"id":"1.170370557","rc":[{"atl":[[2.8,0]],"id":9622734}],"con":true,"img":false}]}
{"op":"mcm","clk":"1362004834","pt":1588421277302,"mc":[{"id":"1.170370557","rc":[{"trd":[[1.6,32]],"ltp":1.6,"tv":32.0,"id":9624350},{"atb":[[1.6,0]],"id":9624350},{"atl":[[1.6,0.73]],"id":9624350}],"con":true,"img":false}]}
{"op":"mcm","clk":"1362004836","pt":1588421277508,"mc":[{"id":"1.170370557","rc":[{"atb":[[1.56,2.08],[1.55,2.19]],"id":9624350}],"con":true,"img":false}]}
{"op":"mcm","clk":"1362004838","pt":1588421277610,"mc":[{"id":"1.170370557","rc":[{"atb":[[1.58,0],[1.57,103.26]],"id":9624350}],"con":true,"img":false}]}
{"op":"mcm","clk":"1362004840","pt":1588421277815,"mc":[{"id":"1.170370557","rc":[{"atb":[[2.56,17.04]],"id":9622734},{"atl":[[2.72,0],[2.74,0],[2.78,2.18],[2.76,2.02]],"id":9622734}],"con":true,"img":false}]}
{"op":"mcm","clk":"1362004842","pt":1588421277974,"mc":[{"id":"1.170370557","rc":[{"atl":[[2.82,12.08],[2.8,2.02]],"id":9622734}],"con":true,"img":false}]}
{"op":"mcm","clk":"1362004843","pt":1588421278076,"mc":[{"id":"1.170370557","rc":[{"atl":[[2.78,0.16],[2.76,0]],"id":9622734}],"con":true,"img":false}]}
{"op":"mcm","clk":"1362004845","pt":1588421278280,"mc":[{"id":"1.170370557","rc":[{"atl":[[2.86,2.01],[2.84,2.03]],"id":9622734},{"atb":[[1.54,2.54]],"id":9624350}],"con":true,"img":false}]}
{"op":"mcm","clk":"1362004846","pt":1588421278383,"mc":[{"id":"1.170370557","rc":[{"atl":[[2.8,0],[2.82,10]],"id":9622734},{"atb":[[1.56,0]],"id":9624350}],"con":true,"img":false}]}
{"op":"mcm","clk":"1362004849","pt":1588421278589,"mc":[{"id":"1.170370557","rc":[{"atl":[[2.82,12.25],[2.8,2.02]],"id":9622734}],"con":true,"img":false}]}
{"op":"mcm","clk":"1362004904","pt":1588421282983,"mc":[{"id":"1.170370557","rc":[{"trd":[[1.6,33.48]],"ltp":1.6,"tv":33.48,"id":9624350},{"atb":[[1.6,1.26]],"id":9624350},{"atl":[[1.6,0]],"id":9624350}],"con":true,"img":false}]}
{"op":"mcm","clk":"1362004905","pt":1588421283075,"mc":[{"id":"1.170370557","marketDefinition":{"bspMarket":false,"turnInPlayEnabled":true,"persistenceEnabled":true,"marketBaseRate":5.0,"eventId":"29788106","eventTypeId":"2","numberOfWinners":1,"bettingType":"ODDS","marketType":"MATCH_ODDS","marketTime":"2020-05-02T12:30:00.000Z","suspendTime":"2020-05-02T12:30:00.000Z","bspReconciled":false,"complete":true,"inPlay":false,"crossMatching":true,"runnersVoidable":false,"numberOfActiveRunners":2,"betDelay":0,"status":"OPEN","runners":[{"status":"ACTIVE","sortPriority":1,"id":9624350,"name":"Y Hanfmann"},{"status":"ACTIVE","sortPriority":2,"id":9622734,"name":"D Brown"}],"regulators":["MR_INT"],"countryCode":"GB","discountAllowed":true,"timezone":"GMT","openDate":"2020-05-02T12:20:00.000Z","version":3237528715,"name":"Match Odds","eventName":"Y Hanfmann v D Brown"},"rc":[],"con":true,"img":false}]}
{"op":"mcm","clk":"1362004918","pt":1588421284482,"mc":[{"id":"1.170370557","rc":[{"atb":[[1.6,0]],"id":9624350}],"con":true,"img":false}]}
{"op":"mcm","clk":"1362004924","pt":1588421284893,"mc":[{"id":"1.170370557","rc":[{"atb":[[2.58,0]],"id":9622734},{"atl":[[2.86,0],[2.84,0]],"id":9622734},{"atb":[[1.54,0.46]],"id":9624350},{"atl":[[1.64,0]],"id":9624350}],"con":true,"img":false}]}
{"op":"mcm","clk":"1362004926","pt":1588421284996,"mc":[{"id":"1.170370557","rc":[{"atl":[[2.82,10]],"id":9622734}],"con":true,"img":false}]}
{"op":"mcm","clk":"1362004927","pt":1588421285201,"mc":[{"id":"1.170370557","rc":[{"atb":[[2.58,2.06]],"id":9622734},{"atl":[[2.82,12]],"id":9622734},{"atb":[[1.54,2.58]],"id":9624350},{"atl":[[1.64,2.01]],"id":9624350}],"con":true,"img":false}]}
{"op":"mcm","clk":"1362004939","pt":1588421286079,"mc":[{"id":"1.170370557","marketDefinition":{"bspMarket":false,"turnInPlayEnabled":true,"persistenceEnabled":true,"marketBaseRate":5.0,"eventId":"29788106","eventTypeId":"2","numberOfWinners":1,"bettingType":"ODDS","marketType":"MATCH_ODDS","marketTime":"2020-05-02T12:30:00.000Z","suspendTime":"2020-05-02T12:30:00.000Z","bspReconciled":false,"complete":true,"inPlay":false,"crossMatching":true,"runnersVoidable":false,"numberOfActiveRunners":2,"betDelay":0,"status":"OPEN","runners":[{"status":"ACTIVE","sortPriority":1,"id":9624350,"name":"Y Hanfmann"},{"status":"ACTIVE","sortPriority":2,"id":9622734,"name":"D Brown"}],"regulators":["MR_INT"],"countryCode":"GB","discountAllowed":true,"timezone":"GMT","openDate":"2020-05-02T12:30:00.000Z","version":3237528715,"name":"Match Odds","eventName":"Y Hanfmann v D Brown"},"rc":[],"con":true,"img":false}]}
{"op":"mcm","clk":"1362005184","pt":1588421307314,"mc":[{"id":"1.170370557","rc":[{"atl":[[1.58,5]],"id":9624350}],"con":true,"img":false}]}
{"op":"mcm","clk":"1362005186","pt":1588421307513,"mc":[{"id":"1.170370557","rc":[{"atl":[[1.6,2],[1.61,2.01]],"id":9624350}],"con":true,"img":false}]}
{"op":"mcm","clk":"1362005189","pt":1588421307721,"mc":[{"id":"1.170370557","rc":[{"atb":[[2.58,0]],"id":9622734},{"atl":[[2.82,10]],"id":9622734},{"atb":[[1.54,0.46]],"id":9624350},{"atl":[[1.64,0]],"id":9624350}],"con":true,"img":false}]}
{"op":"mcm","clk":"1362005191","pt":1588421307925,"mc":[{"id":"1.170370557","rc":[{"atb":[[2.66,2.28],[2.68,2.11]],"id":9622734},{"atb":[[1.53,0]],"id":9624350}],"con":true,"img":false}]}
{"op":"mcm","clk":"1362005192","pt":1588421308028,"mc":[{"id":"1.170370557","rc":[{"atl":[[1.63,0]],"id":9624350}],"con":true,"img":false}]}
{"op":"mcm","clk":"1362005194","pt":1588421308233,"mc":[{"id":"1.170370557","rc":[{"atl":[[2.82,12.08]],"id":9622734},{"atb":[[1.54,2.48]],"id":9624350}],"con":true,"img":false}]}
{"op":"mcm","clk":"1362005195","pt":1588421308336,"mc":[{"id":"1.170370557","rc":[{"atb":[[2.6,0]],"id":9622734},{"trd":[[1.58,53.95]],"ltp":1.58,"tv":53.95,"id":9624350},{"atl":[[1.58,0.26]],"id":9624350}],"con":true,"img":false}]}
{"op":"mcm","clk":"1362005198","pt":1588421308497,"mc":[{"id":"1.170370557","rc":[{"atl":[[1.63,2.04],[1.62,2.17]],"id":9624350}],"con":true,"img":false}]}
{"op":"mcm","clk":"1362005199","pt":1588421308600,"mc":[{"id":"1.170370557","rc":[{"atl":[[1.6,0],[1.61,0]],"id":9624350}],"con":true,"img":false}]}
{"op":"mcm","clk":"1362005201","pt":1588421308701,"mc":[{"id":"1.170370557","rc":[{"atb":[[2.64,29.44],[2.62,2.04]],"id":9622734}],"con":true,"img":false}]}
{"op":"mcm","clk":"1362005207","pt":1588421308903,"mc":[{"id":"1.170370557","rc":[{"atb":[[2.66,0],[2.68,0]],"id":9622734},{"atb":[[1.53,50.17]],"id":9624350}],"con":true,"img":false}]}
{"op":"mcm","clk":"1362005212","pt":1588421309109,"mc":[{"id":"1.170370557","rc":[{"atb":[[2.6,2.04],[2.58,2.06]],"id":9622734}],"con":true,"img":false}]}
{"op":"mcm","clk":"1362005214","pt":1588421309213,"mc":[{"id":"1.170370557","rc":[{"atb":[[2.64,27.37],[2.62,0]],"id":9622734}],"con":true,"img":false}]}
{"op":"mcm","clk":"1362005219","pt":1588421309419,"mc":[{"id":"1.170370557","rc":[{"atl":[[1.64,2.04]],"id":9624350}],"con":true,"img":false}]}
{"op":"mcm","clk":"1362005221","pt":1588421309518,"mc":[{"id":"1.170370557","rc":[{"atl":[[1.62,0]],"id":9624350}],"con":true,"img":false}]}
{"op":"mcm","clk":"1362005262","pt":1588421312141,"mc":[{"id":"1.170370557","rc":[{"atl":[[1.58,0]],"id":9624350}],"con":true,"img":false}]}
{"op":"mcm","clk":"1362005418","pt":1588421322442,"mc":[{"id":"1.170370557","rc":[{"atb":[[1.6,6]],"id":9624350}],"con":true,"img":false}]}
{"op":"mcm","clk":"1362005420","pt":1588421322649,"mc":[{"id":"1.170370557","rc":[{"atb":[[1.58,2.06],[1.57,105.32]],"id":9624350}],"con":true,"img":false}]}
{"op":"mcm","clk":"1362005422","pt":1588421322854,"mc":[{"id":"1.170370557","rc":[{"atb":[[2.58,0]],"id":9622734},{"atl":[[2.82,10]],"id":9622734},{"atb":[[1.54,0.46]],"id":9624350},{"atl":[[1.64,0]],"id":9624350}],"con":true,"img":false}]}
{"op":"mcm","clk":"1362005425","pt":1588421323058,"mc":[{"id":"1.170370557","rc":[{"atb":[[2.56,0]],"id":9622734},{"atl":[[2.72,2],[2.74,2.25]],"id":9622734},{"atb":[[1.55,0]],"id":9624350}],"con":true,"img":false}]}
{"op":"mcm","clk":"1362005428","pt":1588421323160,"mc":[{"id":"1.170370557","rc":[{"atb":[[2.58,2.06]],"id":9622734},{"atl":[[1.64,2.18]],"id":9624350}],"con":true,"img":false}]}
{"op":"mcm","clk":"1362005431","pt":1588421323318,"mc":[{"id":"1.170370557","rc":[{"atl":[[2.8,0]],"id":9622734}],"con":true,"img":false}]}
{"op":"mcm","clk":"1362005437","pt":1588421323631,"mc":[{"id":"1.170370557","rc":[{"trd":[[1.6,42.96]],"ltp":1.6,"tv":42.96,"id":9624350},{"atb":[[1.6,1.26]],"id":9624350}],"con":true,"img":false}]}
{"op":"mcm","clk":"1362005442","pt":1588421323847,"mc":[{"id":"1.170370557","rc":[{"atb":[[1.56,2.02],[1.55,2.19]],"id":9624350}],"con":true,"img":false}]}
{"op":"mcm","clk":"1362005444","pt":1588421323948,"mc":[{"id":"1.170370557","rc":[{"atb":[[1.58,0],[1.57,103.26]],"id":9624350}],"con":true,"img":false}]}
{"op":"mcm","clk":"1362005447","pt":1588421324152,"mc":[{"id":"1.170370557","rc":[{"atl":[[2.78,2.18],[2.76,2.02]],"id":9622734}],"con":true,"img":false}]}
{"op":"mcm","clk":"1362005450","pt":1588421324256,"mc":[{"id":"1.170370557","rc":[{"atl":[[2.72,0],[2.74,0]],"id":9622734}],"con":true,"img":false}]}
{"op":"mcm","clk":"1362005454","pt":1588421324461,"mc":[{"id":"1.170370557","rc":[{"atl":[[2.82,12.02],[2.8,2.02]],"id":9622734}],"con":true,"img":false}]}
{"op":"mcm","clk":"1362005456","pt":1588421324516,"mc":[{"id":"1.170370557","rc":[{"atl":[[2.78,0.16],[2.76,0]],"id":9622734}],"con":true,"img":false}]}
{"op":"mcm","clk":"1362005459","pt":1588421324829,"mc":[{"id":"1.170370557","rc":[{"atb":[[2.56,17.04]],"id":9622734}],"con":true,"img":false}]}
{"op":"mcm","clk":"1362005467","pt":1588421325442,"mc":[{"id":"1.170370557","rc":[{"atb":[[1.6,0]],"id":9624350}],"con":true,"img":false}]}
{"op":"mcm","clk":"1362005471","pt":1588421325749,"mc":[{"id":"1.170370557","rc":[{"atb":[[1.54,2.58]],"id":9624350}],"con":true,"img":false}]}
{"op":"mcm","clk":"1362005476","pt":1588421325853,"mc":[{"id":"1.170370557","rc":[{"atb":[[1.56,0]],"id":9624350}],"con":true,"img":false}]}
{"op":"mcm","clk":"1362005580","pt":1588421332863,"mc":[{"id":"1.170370557","rc":[{"atb":[[1.58,13.78]],"id":9624350}],"con":true,"img":false}]}
{"op":"mcm","clk":"1362005582","pt":1588421333028,"mc":[{"id":"1.170370557","rc":[{"atb":[[1.56,2.08]],"id":9624350}],"con":true,"img":false}]}
{"op":"mcm","clk":"1362005583","pt":1588421333127,"mc":[{"id":"1.170370557","rc":[{"atl":[[2.82,10]],"id":9622734},{"atl":[[1.64,0]],"id":9624350}],"con":true,"img":false}]}
{"op":"mcm","clk":"1362005584","pt":1588421333231,"mc":[{"id":"1.170370557","rc":[{"atb":[[2.58,0]],"id":9622734},{"atb":[[1.54,0.46]],"id":9624350}],"con":true,"img":false}]}
{"op":"mcm","clk":"1362005587","pt":1588421333332,"mc":[{"id":"1.170370557","rc":[{"atl":[[2.78,2.18]],"id":9622734},{"atl":[[1.64,2.01]],"id":9624350}],"con":true,"img":false}]}
{"op":"mcm","clk":"1362005590","pt":1588421333438,"mc":[{"id":"1.170370557","rc":[{"atb":[[1.55,0]],"id":9624350}],"con":true,"img":false}]}
{"op":"mcm","clk":"1362005591","pt":1588421333539,"mc":[{"id":"1.170370557","rc":[{"atb":[[2.58,2.06]],"id":9622734},{"atl":[[2.8,0]],"id":9622734}],"con":true,"img":false}]}
{"op":"mcm","clk":"1362005595","pt":1588421333651,"mc":[{"id":"1.170370557","rc":[{"atb":[[1.55,2.19]],"id":9624350}],"con":true,"img":false}]}
{"op":"mcm","clk":"1362005597","pt":1588421333743,"mc":[{"id":"1.170370557","rc":[{"atl":[[2.8,2.02]],"id":9622734}],"con":true,"img":false}]}
{"op":"mcm","clk":"1362005662","pt":1588421341645,"mc":[{"id":"1.170370557","rc":[{"atb":[[1.41,21.28]],"id":9624350}],"con":true,"img":false}]}
{"op":"mcm","clk":"1362005668","pt":1588421341848,"mc":[{"id":"1.170370557","rc":[{"atb":[[1.41,40.79]],"id":9624350}],"con":true,"img":false}]}
{"op":"mcm","clk":"1362005669","pt":1588421341951,"mc":[{"id":"1.170370557","rc":[{"atb":[[2.58,0]],"id":9622734},{"atl":[[2.8,0]],"id":9622734},{"atb":[[1.55,0]],"id":9624350},{"atl":[[1.64,0]],"id":9624350}],"con":true,"img":false}]}
{"op":"mcm","clk":"1362005670","pt":1588421342055,"mc":[{"id":"1.170370557","rc":[{"atb":[[1.41,60.29]],"id":9624350}],"con":true,"img":false}]}
{"op":"mcm","clk":"1362005672","pt":1588421342153,"mc":[{"id":"1.170370557","rc":[{"atb":[[2.58,2.06]],"id":9622734},{"atl":[[2.8,2]],"id":9622734},{"atb":[[1.55,2]],"id":9624350},{"atl":[[1.64,2.18]],"id":9624350}],"con":true,"img":false}]}
{"op":"mcm","clk":"1362005680","pt":1588421342938,"mc":[{"id":"1.170370557","rc":[{"atb":[[1.52,15.38]],"id":9624350}],"con":true,"img":false}]}
{"op":"mcm","clk":"1362005825","pt":1588421357850,"mc":[{"id":"1.170370557","rc":[{"atl":[[1.59,4]],"id":9624350}],"con":true,"img":false}]}
{"op":"mcm","clk":"1362005829","pt":1588421358062,"mc":[{"id":"1.170370557","rc":[{"atb":[[2.64,29.44],[2.62,2.04]],"id":9622734},{"atl":[[1.62,2.25],[1.61,2.14]],"id":9624350}],"con":true,"img":false}]}
{"op":"mcm","clk":"1362005831","pt":1588421358161,"mc":[{"id":"1.170370557","rc":[{"atb":[[2.58,0]],"id":9622734},{"atl":[[2.8,0]],"id":9622734},{"atb":[[1.55,0]],"id":9624350},{"atl":[[1.64,0]],"id":9624350}],"con":true,"img":false}]}
{"op":"mcm","clk":"1362005834","pt":1588421358471,"mc":[{"id":"1.170370557","rc":[{"atb":[[2.6,0]],"id":9622734},{"atl":[[1.63,0]],"id":9624350}],"con":true,"img":false}]}
{"op":"mcm","clk":"1362005836","pt":1588421358675,"mc":[{"id":"1.170370557","rc":[{"atl":[[2.8,2.02]],"id":9622734},{"atb":[[1.55,2.19]],"id":9624350}],"con":true,"img":false}]}
{"op":"mcm","clk":"1362005856","pt":1588421360478,"mc":[{"id":"1.170370557","rc":[{"trd":[[1.59,6.9]],"ltp":1.59,"tv":6.9,"id":9624350},{"atl":[[1.59,2.11]],"id":9624350}],"con":true,"img":false}]}
{"op":"mcm","clk":"1362005861","pt":1588421360681,"mc":[{"id":"1.170370557","rc":[{"atb":[[2.64,27.37],[2.6,2.04],[2.58,2.02],[2.62,0]],"id":9622734}],"con":true,"img":false}]}
{"op":"mcm","clk":"1362005877","pt":1588421362854,"mc":[{"id":"1.170370557","rc":[{"atl":[[1.59,0]],"id":9624350}],"con":true,"img":false}]}
{"op":"mcm","clk":"1362005880","pt":1588421363067,"mc":[{"id":"1.170370557","rc":[{"atl":[[1.64,2.18],[1.63,2.04],[1.62,0],[1.61,0]],"id":9624350}],"con":true,"img":false}]}
{"op":"mcm","clk":"1362005882","pt":1588421363273,"mc":[{"id":"1.170370557","rc":[{"atl":[[1.66,41.64],[1.65,2.07]],"id":9624350}],"con":true,"img":false}]}
{"op":"mcm","clk":"1362005909","pt":1588421365180,"mc":[{"id":"1.170370557","rc":[{"atb":[[1.58,0]],"id":9624350}],"con":true,"img":false}]}
{"op":"mcm","clk":"1362005911","pt":1588421365383,"mc":[{"id":"1.170370557","rc":[{"atb":[[1.58,7.99],[1.54,2.58]],"id":9624350}],"con":true,"img":false}]}
{"op":"mcm","clk":"1362005913","pt":1588421365496,"mc":[{"id":"1.170370557","rc":[{"atl":[[2.8,0]],"id":9622734},{"atb":[[1.56,0]],"id":9624350}],"con":true,"img":false}]}
{"op":"mcm","clk":"1362005915","pt":1588421365703,"mc":[{"id":"1.170370557","rc":[{"atb":[[1.55,0]],"id":9624350}],"con":true,"img":false}]}
{"op":"mcm","clk":"1362005917","pt":1588421365794,"mc":[{"id":"1.170370557","rc":[{"atl":[[2.8,2.02]],"id":9622734},{"atb":[[1.56,2.08]],"id":9624350}],"con":true,"img":false}]}
{"op":"mcm","clk":"1362005920","pt":1588421365852,"mc":[{"id":"1.170370557","rc":[{"atb":[[1.55,2.08]],"id":9624350}],"con":true,"img":false}]}
{"op":"mcm","clk":"1362005957","pt":1588421368580,"mc":[{"id":"1.170370557","rc":[{"atb":[[1.54,10.58]],"id":9624350}],"con":true,"img":false}]}
{"op":"mcm","clk":"1362005960","pt":1588421368888,"mc":[{"id":"1.170370557","rc":[{"atb":[[2.58,0]],"id":9622734},{"atl":[[1.64,0]],"id":9624350}],"con":true,"img":false}]}
{"op":"mcm","clk":"1362005964","pt":1588421369091,"mc":[{"id":"1.170370557","rc":[{"atb":[[2.58,2.06]],"id":9622734},{"atl":[[1.64,2.04]],"id":9624350}],"con":true,"img":false}]}
{"op":"mcm","clk":"1362007864","pt":1588421528770,"mc":[{"id":"1.170370557","rc":[{"atb":[[1.42,39.99]],"id":9624350}],"con":true,"img":false}]}
{"op":"mcm","clk":"1362007866","pt":1588421528978,"mc":[{"id":"1.170370557","rc":[{"atb":[[2.1,39.99]],"id":9622734}],"con":true,"img":false}]}
{"op":"mcm","clk":"1362007868","pt":1588421529182,"mc":[{"id":"1.170370557","rc":[{"atb":[[2.58,0]],"id":9622734},{"atb":[[1.55,0],[1.54,8.46]],"id":9624350},{"atl":[[1.64,0],[1.65,0],[1.66,39.45]],"id":9624350}],"con":true,"img":false}]}
{"op":"mcm","clk":"1362007871","pt":1588421529285,"mc":[{"id":"1.170370557","rc":[{"atl":[[2.8,0]],"id":9622734}],"con":true,"img":false}]}
{"op":"mcm","clk":"1362007874","pt":1588421529490,"mc":[{"id":"1.170370557","rc":[{"atb":[[2.58,2.06]],"id":9622734},{"atl":[[2.8,2.02]],"id":9622734},{"atb":[[1.55,2.08]],"id":9624350},{"atl":[[1.64,2.01]],"id":9624350}],"con":true,"img":false}]}
{"op":"mcm","clk":"1362008446","pt":1588421583318,"mc":[{"id":"1.170370557","rc":[{"atb":[[2.1,0]],"id":9622734},{"atb":[[1.42,0]],"id":9624350}],"con":true,"img":false}]}
{"op":"mcm","clk":"1362008449","pt":1588421583628,"mc":[{"id":"1.170370557","rc":[{"atb":[[2.58,0]],"id":9622734},{"atl":[[2.8,0]],"id":9622734},{"atb":[[1.55,0]],"id":9624350},{"atl":[[1.64,0]],"id":9624350}],"con":true,"img":false}]}
{"op":"mcm","clk":"1362008451","pt":1588421583834,"mc":[{"id":"1.170370557","rc":[{"atb":[[2.58,2.06]],"id":9622734},{"atl":[[2.8,2.02]],"id":9622734},{"atb":[[1.55,2.19]],"id":9624350},{"atl":[[1.64,2.18]],"id":9624350}],"con":true,"img":false}]}
{"op":"mcm","clk":"1362008541","pt":1588421591333,"mc":[{"id":"1.170370557","rc":[{"atb":[[1.49,39.99]],"id":9624350}],"con":true,"img":false}]}
{"op":"mcm","clk":"1362008543","pt":1588421591540,"mc":[{"id":"1.170370557","rc":[{"atb":[[2.3,39.99]],"id":9622734}],"con":true,"img":false}]}
{"op":"mcm","clk":"1362008545","pt":1588421591643,"mc":[{"id":"1.170370557","rc":[{"atb":[[2.58,0]],"id":9622734},{"atl":[[2.8,0]],"id":9622734},{"atb":[[1.55,0]],"id":9624350},{"atl":[[1.64,0]],"id":9624350}],"con":true,"img":false}]}
{"op":"mcm","clk":"1362008548","pt":1588421591848,"mc":[{"id":"1.170370557","rc":[{"atb":[[2.58,2.06]],"id":9622734},{"atl":[[2.8,2.02]],"id":9622734},{"atb":[[1.55,2]],"id":9624350},{"atl":[[1.64,2.04]],"id":9624350}],"con":true,"img":false}]}
{"op":"mcm","clk":"1362009023","pt":1588421643851,"mc":[{"id":"1.170370557","rc":[{"atb":[[2.3,0]],"id":9622734},{"atb":[[1.49,0]],"id":9624350}],"con":true,"img":false}]}
{"op":"mcm","clk":"1362009027","pt":1588421644160,"mc":[{"id":"1.170370557","rc":[{"atb":[[2.58,0]],"id":9622734},{"atl":[[2.8,0]],"id":9622734},{"atb":[[1.55,0]],"id":9624350},{"atl":[[1.64,0]],"id":9624350}],"con":true,"img":false}]}
{"op":"mcm","clk":"1362009029","pt":1588421644366,"mc":[{"id":"1.170370557","rc":[{"atb":[[2.58,2.06]],"id":9622734},{"atl":[[2.8,2.02]],"id":9622734},{"atb":[[1.55,2.08]],"id":9624350},{"atl":[[1.64,2.18]],"id":9624350}],"con":true,"img":false}]}
{"op":"mcm","clk":"1362009084","pt":1588421651052,"mc":[{"id":"1.170370557","rc":[{"atb":[[1.49,39.99]],"id":9624350}],"con":true,"img":false}]}
{"op":"mcm","clk":"1362009085","pt":1588421651257,"mc":[{"id":"1.170370557","rc":[{"atb":[[2.3,39.99],[2.58,0]],"id":9622734},{"atl":[[2.8,0]],"id":9622734},{"atb":[[1.55,0]],"id":9624350},{"atl":[[1.64,0]],"id":9624350}],"con":true,"img":false}]}
{"op":"mcm","clk":"1362009086","pt":1588421651462,"mc":[{"id":"1.170370557","rc":[{"atb":[[2.58,2]],"id":9622734},{"atl":[[2.8,2.02]],"id":9622734},{"atb":[[1.55,2.19]],"id":9624350},{"atl":[[1.64,2.18]],"id":9624350}],"con":true,"img":false}]}
{"op":"mcm","clk":"1362010331","pt":1588421704546,"mc":[{"id":"1.170370557","rc":[{"atb":[[2.3,0]],"id":9622734},{"atb":[[1.49,0]],"id":9624350}],"con":true,"img":false}]}
{"op":"mcm","clk":"1362010334","pt":1588421704854,"mc":[{"id":"1.170370557","rc":[{"atb":[[2.58,0]],"id":9622734},{"atl":[[2.8,0]],"id":9622734},{"atb":[[1.55,0]],"id":9624350},{"atl":[[1.64,0]],"id":9624350}],"con":true,"img":false}]}
{"op":"mcm","clk":"1362010335","pt":1588421705060,"mc":[{"id":"1.170370557","rc":[{"atb":[[2.58,2.06]],"id":9622734},{"atl":[[2.8,2.02]],"id":9622734},{"atb":[[1.55,2.19]],"id":9624350},{"atl":[[1.64,2.18]],"id":9624350}],"con":true,"img":false}]}
{"op":"mcm","clk":"1362010406","pt":1588421713460,"mc":[{"id":"1.170370557","rc":[{"atb":[[1.49,39.99]],"id":9624350}],"con":true,"img":false}]}
{"op":"mcm","clk":"1362010407","pt":1588421713667,"mc":[{"id":"1.170370557","rc":[{"atb":[[2.3,39.99]],"id":9622734}],"con":true,"img":false}]}
{"op":"mcm","clk":"1362010409","pt":1588421713770,"mc":[{"id":"1.170370557","rc":[{"atb":[[2.58,0]],"id":9622734},{"atl":[[2.8,0]],"id":9622734},{"atb":[[1.55,0]],"id":9624350},{"atl":[[1.64,0]],"id":9624350}],"con":true,"img":false}]}
{"op":"mcm","clk":"1362010411","pt":1588421713930,"mc":[{"id":"1.170370557","rc":[{"atb":[[2.58,2.06]],"id":9622734},{"atl":[[2.8,2.02]],"id":9622734},{"atb":[[1.55,2.19]],"id":9624350},{"atl":[[1.64,2.18]],"id":9624350}],"con":true,"img":false}]}
{"op":"mcm","clk":"1362010990","pt":1588421765211,"mc":[{"id":"1.170370557","rc":[{"atb":[[2.3,0]],"id":9622734},{"atb":[[1.49,0]],"id":9624350}],"con":true,"img":false}]}
{"op":"mcm","clk":"1362010993","pt":1588421765521,"mc":[{"id":"1.170370557","rc":[{"atb":[[2.58,0]],"id":9622734},{"atl":[[2.8,0]],"id":9622734},{"atb":[[1.55,0]],"id":9624350},{"atl":[[1.64,0]],"id":9624350}],"con":true,"img":false}]}
{"op":"mcm","clk":"1362010994","pt":1588421765728,"mc":[{"id":"1.170370557","rc":[{"atb":[[2.58,2.06]],"id":9622734},{"atl":[[2.8,2.02]],"id":9622734},{"atb":[[1.55,2.19]],"id":9624350},{"atl":[[1.64,2.18]],"id":9624350}],"con":true,"img":false}]}
{"op":"mcm","clk":"1362011086","pt":1588421773708,"mc":[{"id":"1.170370557","rc":[{"atb":[[1.49,39.99]],"id":9624350}],"con":true,"img":false}]}
{"op":"mcm","clk":"1362011088","pt":1588421773899,"mc":[{"id":"1.170370557","rc":[{"atb":[[2.3,39.99]],"id":9622734}],"con":true,"img":false}]}
{"op":"mcm","clk":"1362011090","pt":1588421774012,"mc":[{"id":"1.170370557","rc":[{"atb":[[2.58,0]],"id":9622734},{"atl":[[2.8,0]],"id":9622734},{"atb":[[1.6,127.17],[1.55,0]],"id":9624350},{"atl":[[1.64,0]],"id":9624350}],"con":true,"img":false}]}
{"op":"mcm","clk":"1362011092","pt":1588421774205,"mc":[{"id":"1.170370557","rc":[{"atb":[[2.58,2.06]],"id":9622734},{"atl":[[2.8,2.02],[2.72,2.05],[2.74,2.01]],"id":9622734},{"atb":[[1.58,10.05],[1.57,105.3]],"id":9624350},{"atl":[[1.64,2.04]],"id":9624350}],"con":true,"img":false}]}
{"op":"mcm","clk":"1362011098","pt":1588421774412,"mc":[{"id":"1.170370557","rc":[{"atl":[[2.78,0.16]],"id":9622734},{"atb":[[1.56,0]],"id":9624350}],"con":true,"img":false}]}
{"op":"mcm","clk":"1362011108","pt":1588421775026,"mc":[{"id":"1.170370557","rc":[{"atb":[[2.54,17.26]],"id":9622734},{"atb":[[1.54,57.71]],"id":9624350}],"con":true,"img":false}]}
{"op":"mcm","clk":"1362011110","pt":1588421775128,"mc":[{"id":"1.170370557","rc":[{"atb":[[2.56,0]],"id":9622734}],"con":true,"img":false}]}
{"op":"mcm","clk":"1362011147","pt":1588421779102,"mc":[{"id":"1.170370557","rc":[{"atb":[[2.24,0]],"id":9622734},{"atb":[[1.57,2.04]],"id":9624350}],"con":true,"img":false}]}
{"op":"mcm","clk":"1362011574","pt":1588421824156,"mc":[{"id":"1.170370557","rc":[{"atb":[[1.6,0]],"id":9624350}],"con":true,"img":false}]}
{"op":"mcm","clk":"1362011576","pt":1588421824361,"mc":[{"id":"1.170370557","rc":[{"atb":[[1.56,2.08],[1.55,2.19]],"id":9624350}],"con":true,"img":false}]}
{"op":"mcm","clk":"1362011579","pt":1588421824571,"mc":[{"id":"1.170370557","rc":[{"atb":[[2.58,0]],"id":9622734},{"atl":[[2.8,0],[2.74,0]],"id":9622734},{"atb":[[1.58,7.99],[1.57,0]],"id":9624350},{"atl":[[1.64,0]],"id":9624350}],"con":true,"img":false}]}
{"op":"mcm","clk":"1362011580","pt":1588421824669,"mc":[{"id":"1.170370557","rc":[{"atl":[[2.78,2.18],[2.76,2.02]],"id":9622734}],"con":true,"img":false}]}
{"op":"mcm","clk":"1362011583","pt":1588421824773,"mc":[{"id":"1.170370557","rc":[{"atl":[[2.72,0]],"id":9622734}],"con":true,"img":false}]}
{"op":"mcm","clk":"1362011585","pt":1588421824875,"mc":[{"id":"1.170370557","rc":[{"atb":[[2.58,2.06]],"id":9622734},{"atl":[[1.64,2.04]],"id":9624350}],"con":true,"img":false}]}
{"op":"mcm","clk":"1362011586","pt":1588421824977,"mc":[{"id":"1.170370557","rc":[{"atl":[[2.8,2.02],[2.76,0]],"id":9622734},{"atb":[[1.52,66.52]],"id":9624350}],"con":true,"img":false}]}
{"op":"mcm","clk":"1362011591","pt":1588421825181,"mc":[{"id":"1.170370557","rc":[{"atb":[[2.44,0]],"id":9622734},{"atb":[[1.53,0],[1.54,8.46]],"id":9624350}],"con":true,"img":false}]}
{"op":"mcm","clk":"1362011599","pt":1588421825854,"mc":[{"id":"1.170370557","rc":[{"atb":[[2.3,0]],"id":9622734},{"atb":[[1.49,0]],"id":9624350}],"con":true,"img":false}]}
{"op":"mcm","clk":"1362011600","pt":1588421826162,"mc":[{"id":"1.170370557","rc":[{"atb":[[2.46,0]],"id":9622734}],"con":true,"img":false}]}
{"op":"mcm","clk":"1362011602","pt":1588421827087,"mc":[{"id":"1.170370557","rc":[{"atb":[[2.6,18.66]],"id":9622734}],"con":true,"img":false}]}
{"op":"mcm","clk":"1362011617","pt":1588421829187,"mc":[{"id":"1.170370557","rc":[{"atb":[[2.24,47.46]],"id":9622734},{"atb":[[1.57,103.26]],"id":9624350}],"con":true,"img":false}]}
{"op":"mcm","clk":"1362011628","pt":1588421830060,"mc":[{"id":"1.170370557","rc":[{"atb":[[2.6,2.04],[2.56,17.04]],"id":9622734},{"atb":[[1.53,50.17]],"id":9624350}],"con":true,"img":false}]}
{"op":"mcm","clk":"1362011669","pt":1588421835396,"mc":[{"id":"1.170370557","rc":[{"atb":[[1.49,39.99]],"id":9624350}],"con":true,"img":false}]}
{"op":"mcm","clk":"1362011674","pt":1588421835568,"mc":[{"id":"1.170370557","rc":[{"atb":[[2.3,39.99]],"id":9622734}],"con":true,"img":false}]}
{"op":"mcm","clk":"1362011676","pt":1588421835775,"mc":[{"id":"1.170370557","rc":[{"atb":[[2.58,0]],"id":9622734},{"atl":[[2.8,0]],"id":9622734},{"atb":[[1.55,0]],"id":9624350},{"atl":[[1.64,0]],"id":9624350}],"con":true,"img":false}]}
{"op":"mcm","clk":"1362011678","pt":1588421835968,"mc":[{"id":"1.170370557","rc":[{"atb":[[2.58,2.06]],"id":9622734},{"atl":[[2.8,2.02]],"id":9622734},{"atb":[[1.55,2.06]],"id":9624350},{"atl":[[1.64,2.18]],"id":9624350}],"con":true,"img":false}]}
{"op":"mcm","clk":"1362011844","pt":1588421853112,"mc":[{"id":"1.170370557","rc":[{"atb":[[1.1,121.58]],"id":9622734}],"con":true,"img":false}]}
{"op":"mcm","clk":"1362011847","pt":1588421853267,"mc":[{"id":"1.170370557","rc":[{"atb":[[2.58,0]],"id":9622734},{"atl":[[2.8,0]],"id":9622734},{"atl":[[1.64,0]],"id":9624350}],"con":true,"img":false}]}
{"op":"mcm","clk":"1362011849","pt":1588421853371,"mc":[{"id":"1.170370557","rc":[{"atb":[[1.55,0]],"id":9624350}],"con":true,"img":false}]}
{"op":"mcm","clk":"1362011850","pt":1588421853474,"mc":[{"id":"1.170370557","rc":[{"atb":[[2.58,2.06]],"id":9622734},{"atl":[[2.8,2.02]],"id":9622734},{"atl":[[1.64,2.18]],"id":9624350}],"con":true,"img":false}]}
{"op":"mcm","clk":"1362011852","pt":1588421853576,"mc":[{"id":"1.170370557","rc":[{"atb":[[1.55,2.08]],"id":9624350}],"con":true,"img":false}]}
{"op":"mcm","clk":"1362012233","pt":1588421886351,"mc":[{"id":"1.170370557","rc":[{"atb":[[2.3,0]],"id":9622734},{"atb":[[1.49,0]],"id":9624350}],"con":true,"img":false}]}
{"op":"mcm","clk":"1362012244","pt":1588421886822,"mc":[{"id":"1.170370557","rc":[{"atb":[[2.58,0]],"id":9622734},{"atl":[[2.8,0]],"id":9622734},{"atb":[[1.55,0]],"id":9624350},{"atl":[[1.64,0]],"id":9624350}],"con":true,"img":false}]}
{"op":"mcm","clk":"1362012247","pt":1588421887026,"mc":[{"id":"1.170370557","rc":[{"atb":[[2.58,2.06]],"id":9622734},{"atl":[[2.8,2.02]],"id":9622734},{"atb":[[1.55,2.19]],"id":9624350},{"atl":[[1.64,2.18]],"id":9624350}],"con":true,"img":false}]}
{"op":"mcm","clk":"1362012335","pt":1588421894145,"mc":[{"id":"1.170370557","rc":[{"atb":[[1.49,39.99]],"id":9624350}],"con":true,"img":false}]}
{"op":"mcm","clk":"1362012336","pt":1588421894352,"mc":[{"id":"1.170370557","rc":[{"atb":[[2.3,39.99]],"id":9622734}],"con":true,"img":false}]}
{"op":"mcm","clk":"1362012338","pt":1588421894455,"mc":[{"id":"1.170370557","rc":[{"atb":[[2.58,0]],"id":9622734},{"atl":[[2.8,0]],"id":9622734},{"atb":[[1.55,0]],"id":9624350},{"atl":[[1.64,0]],"id":9624350}],"con":true,"img":false}]}
{"op":"mcm","clk":"1362012342","pt":1588421894661,"mc":[{"id":"1.170370557","rc":[{"atb":[[2.58,2.06]],"id":9622734},{"atl":[[2.8,2.02]],"id":9622734},{"atb":[[1.55,2.08]],"id":9624350},{"atl":[[1.64,2.18]],"id":9624350}],"con":true,"img":false}]}
{"op":"mcm","clk":"1362012570","pt":1588421916881,"mc":[{"id":"1.170370557","rc":[{"atb":[[1.1,124.78]],"id":9622734}],"con":true,"img":false}]}
{"op":"mcm","clk":"1362012575","pt":1588421917248,"mc":[{"id":"1.170370557","rc":[{"atb":[[2.58,0]],"id":9622734},{"atl":[[2.8,0]],"id":9622734},{"atb":[[1.55,0]],"id":9624350},{"atl":[[1.64,0]],"id":9624350}],"con":true,"img":false}]}
{"op":"mcm","clk":"1362012578","pt":1588421917455,"mc":[{"id":"1.170370557","rc":[{"atb":[[2.58,2.06]],"id":9622734},{"atl":[[2.8,2.02]],"id":9622734},{"atb":[[1.55,2.19]],"id":9624350},{"atl":[[1.64,2.18]],"id":9624350}],"con":true,"img":false}]}
{"op":"mcm","clk":"1362012794","pt":1588421937392,"mc":[{"id":"1.170370557","rc":[{"atb":[[1.1,125.73]],"id":9622734}],"con":true,"img":false}]}
{"op":"mcm","clk":"1362012798","pt":1588421937701,"mc":[{"id":"1.170370557","rc":[{"atb":[[2.58,0]],"id":9622734},{"atl":[[2.8,0]],"id":9622734},{"atb":[[1.55,0]],"id":9624350},{"atl":[[1.64,0]],"id":9624350}],"con":true,"img":false}]}
{"op":"mcm","clk":"1362012800","pt":1588421937907,"mc":[{"id":"1.170370557","rc":[{"atb":[[2.58,2.06]],"id":9622734},{"atl":[[2.8,2.02]],"id":9622734},{"atb":[[1.55,2.08]],"id":9624350},{"atl":[[1.64,2.04]],"id":9624350}],"con":true,"img":false}]}
{"op":"mcm","clk":"1362012836","pt":1588421942205,"mc":[{"id":"1.170370557","rc":[{"atb":[[1.1,122.54]],"id":9622734}],"con":true,"img":false}]}
{"op":"mcm","clk":"1362012889","pt":1588421946883,"mc":[{"id":"1.170370557","rc":[{"atb":[[2.3,0]],"id":9622734},{"atb":[[1.49,0]],"id":9624350}],"con":true,"img":false}]}
{"op":"mcm","clk":"1362012895","pt":1588421947191,"mc":[{"id":"1.170370557","rc":[{"atb":[[2.58,0]],"id":9622734},{"atl":[[2.8,0]],"id":9622734},{"atb":[[1.55,0]],"id":9624350},{"atl":[[1.64,0]],"id":9624350}],"con":true,"img":false}]}
{"op":"mcm","clk":"1362012899","pt":1588421947390,"mc":[{"id":"1.170370557","rc":[{"atb":[[2.58,2.04]],"id":9622734},{"atl":[[2.8,2.02]],"id":9622734},{"atb":[[1.55,2.19]],"id":9624350},{"atl":[[1.64,2.18]],"id":9624350}],"con":true,"img":false}]}
{"op":"mcm","clk":"1362012936","pt":1588421950081,"mc":[{"id":"1.170370557","rc":[{"atb":[[1.49,39.99]],"id":9624350}],"con":true,"img":false}]}
{"op":"mcm","clk":"1362012938","pt":1588421950291,"mc":[{"id":"1.170370557","rc":[{"atb":[[2.3,39.99]],"id":9622734}],"con":true,"img":false}]}
{"op":"mcm","clk":"1362013452","pt":1588422007484,"mc":[{"id":"1.170370557","rc":[{"atb":[[2.3,0]],"id":9622734},{"atb":[[1.49,0]],"id":9624350}],"con":true,"img":false}]}
{"op":"mcm","clk":"1362013455","pt":1588422007745,"mc":[{"id":"1.170370557","rc":[{"atb":[[1.55,0]],"id":9624350}],"con":true,"img":false}]}
{"op":"mcm","clk":"1362013458","pt":1588422007851,"mc":[{"id":"1.170370557","rc":[{"atb":[[2.58,0]],"id":9622734},{"atl":[[2.8,0]],"id":9622734},{"atl":[[1.64,0]],"id":9624350}],"con":true,"img":false}]}
{"op":"mcm","clk":"1362013460","pt":1588422007957,"mc":[{"id":"1.170370557","rc":[{"atb":[[1.55,2.19]],"id":9624350}],"con":true,"img":false}]}
{"op":"mcm","clk":"1362013462","pt":1588422008057,"mc":[{"id":"1.170370557","rc":[{"atb":[[2.58,2.06]],"id":9622734},{"atl":[[2.8,2.02]],"id":9622734},{"atl":[[1.64,2.18]],"id":9624350}],"con":true,"img":false}]}
{"op":"mcm","clk":"1362013476","pt":1588422010273,"mc":[{"id":"1.170370557","rc":[{"atb":[[1.49,39.99]],"id":9624350}],"con":true,"img":false}]}
{"op":"mcm","clk":"1362013483","pt":1588422010476,"mc":[{"id":"1.170370557","rc":[{"atb":[[2.3,39.99]],"id":9622734}],"con":true,"img":false}]}
{"op":"mcm","clk":"1362013516","pt":1588422012955,"mc":[{"id":"1.170370557","rc":[{"atb":[[1.01,11.74],[1.02,1.67]],"id":9622734},{"atl":[[1000,1.48]],"id":9622734},{"atb":[[1.02,1.67]],"id":9624350},{"atl":[[1000,1.47]],"id":9624350}],"con":true,"img":false}]}
{"op":"mcm","clk":"1362013517","pt":1588422013067,"mc":[{"id":"1.170370557","rc":[{"atb":[[1.01,11.74]],"id":9624350}],"con":true,"img":false}]}
{"op":"mcm","clk":"1362013523","pt":1588422013680,"mc":[{"id":"1.170370557","rc":[{"atl":[[1000,0.01]],"id":9624350}],"con":true,"img":false}]}
{"op":"mcm","clk":"1362013525","pt":1588422013778,"mc":[{"id":"1.170370557","rc":[{"atb":[[1.01,10.28]],"id":9622734},{"atl":[[1000,0.02]],"id":9622734},{"atb":[[1.01,10.28]],"id":9624350}],"con":true,"img":false}]}
{"op":"mcm","clk":"1362013526","pt":1588422013988,"mc":[{"id":"1.170370557","rc":[{"atb":[[2.58,0]],"id":9622734},{"atb":[[1.55,0]],"id":9624350},{"atl":[[1.64,0]],"id":9624350}],"con":true,"img":false}]}
{"op":"mcm","clk":"1362013527","pt":1588422014092,"mc":[{"id":"1.170370557","rc":[{"atl":[[2.8,0]],"id":9622734}],"con":true,"img":false}]}
{"op":"mcm","clk":"1362013528","pt":1588422014253,"mc":[{"id":"1.170370557","rc":[{"atb":[[2.58,2.06]],"id":9622734},{"atl":[[2.8,2.02]],"id":9622734},{"atb":[[1.55,2.04]],"id":9624350},{"atl":[[1.64,2.01]],"id":9624350}],"con":true,"img":false}]}
{"op":"mcm","clk":"1362013530","pt":1588422014352,"mc":[{"id":"1.170370557","rc":[{"atl":[[1000,0]],"id":9624350}],"con":true,"img":false}]}
{"op":"mcm","clk":"1362013533","pt":1588422014458,"mc":[{"id":"1.170370557","rc":[{"atb":[[1.01,9.79]],"id":9622734},{"atl":[[1000,0]],"id":9622734},{"atb":[[1.01,9.79]],"id":9624350},{"atl":[[20,0.01]],"id":9624350}],"con":true,"img":false}]}
{"op":"mcm","clk":"1362013534","pt":1588422014560,"mc":[{"id":"1.170370557","rc":[{"atb":[[1.03,0.48]],"id":9622734},{"atl":[[10,0.02]],"id":9622734},{"atb":[[1.03,0.48]],"id":9624350}],"con":true,"img":false}]}
{"op":"mcm","clk":"1362014126","pt":1588422068237,"mc":[{"id":"1.170370557","rc":[{"atb":[[2.3,0]],"id":9622734},{"atb":[[1.49,0]],"id":9624350}],"con":true,"img":false}]}
{"op":"mcm","clk":"1362014130","pt":1588422068549,"mc":[{"id":"1.170370557","rc":[{"atb":[[2.58,0]],"id":9622734},{"atl":[[2.8,0]],"id":9622734},{"atb":[[1.55,0]],"id":9624350},{"atl":[[1.64,0]],"id":9624350}],"con":true,"img":false}]}
{"op":"mcm","clk":"1362014133","pt":1588422068756,"mc":[{"id":"1.170370557","rc":[{"atb":[[2.58,2.06]],"id":9622734},{"atl":[[2.8,2.02]],"id":9622734},{"atb":[[1.55,2.08]],"id":9624350},{"atl":[[1.64,2.18]],"id":9624350}],"con":true,"img":false}]}
{"op":"mcm","clk":"1362014145","pt":1588422069636,"mc":[{"id":"1.170370557","rc":[{"atb":[[1.49,39.99]],"id":9624350}],"con":true,"img":false}]}
{"op":"mcm","clk":"1362014146","pt":1588422069842,"mc":[{"id":"1.170370557","rc":[{"atb":[[2.3,39.99]],"id":9622734}],"con":true,"img":false}]}
{"op":"mcm","clk":"1362014700","pt":1588422128814,"mc":[{"id":"1.170370557","rc":[{"atb":[[2.3,0]],"id":9622734},{"atb":[[1.49,0]],"id":9624350}],"con":true,"img":false}]}
{"op":"mcm","clk":"1362014704","pt":1588422129226,"mc":[{"id":"1.170370557","rc":[{"atb":[[2.58,0]],"id":9622734},{"atl":[[2.8,0]],"id":9622734},{"atb":[[1.55,0]],"id":9624350},{"atl":[[1.64,0]],"id":9624350}],"con":true,"img":false}]}
{"op":"mcm","clk":"1362014707","pt":1588422129384,"mc":[{"id":"1.170370557","rc":[{"atb":[[2.58,2.06]],"id":9622734},{"atl":[[2.8,2.02]],"id":9622734},{"atb":[[1.55,2.06]],"id":9624350},{"atl":[[1.64,2.04]],"id":9624350}],"con":true,"img":false}]}
{"op":"mcm","clk":"1362014717","pt":1588422130308,"mc":[{"id":"1.170370557","rc":[{"atb":[[1.49,39.99]],"id":9624350}],"con":true,"img":false}]}
{"op":"mcm","clk":"1362014722","pt":1588422130516,"mc":[{"id":"1.170370557","rc":[{"atb":[[2.3,39.99]],"id":9622734}],"con":true,"img":false}]}
{"op":"mcm","clk":"1362014747","pt":1588422133593,"mc":[{"id":"1.170370557","rc":[{"atb":[[1.6,127.17]],"id":9624350}],"con":true,"img":false}]}
{"op":"mcm","clk":"1362014748","pt":1588422133695,"mc":[{"id":"1.170370557","rc":[{"atb":[[1.58,10.05],[1.57,105.32]],"id":9624350}],"con":true,"img":false}]}
{"op":"mcm","clk":"1362014752","pt":1588422134003,"mc":[{"id":"1.170370557","rc":[{"atb":[[1.56,0]],"id":9624350}],"con":true,"img":false}]}
{"op":"mcm","clk":"1362014754","pt":1588422134107,"mc":[{"id":"1.170370557","rc":[{"atb":[[1.54,57.71]],"id":9624350}],"con":true,"img":false}]}
{"op":"mcm","clk":"1362014756","pt":1588422134211,"mc":[{"id":"1.170370557","rc":[{"atl":[[2.72,2.16],[2.74,2.25]],"id":9622734}],"con":true,"img":false}]}
{"op":"mcm","clk":"1362014757","pt":1588422134311,"mc":[{"id":"1.170370557","rc":[{"atb":[[2.56,0]],"id":9622734}],"con":true,"img":false}]}
{"op":"mcm","clk":"1362014760","pt":1588422134522,"mc":[{"id":"1.170370557","rc":[{"atl":[[2.78,0.16]],"id":9622734}],"con":true,"img":false}]}
{"op":"mcm","clk":"1362014772","pt":1588422135237,"mc":[{"id":"1.170370557","rc":[{"atb":[[2.24,0]],"id":9622734},{"atb":[[1.57,2.06]],"id":9624350}],"con":true,"img":false}]}
{"op":"mcm","clk":"1362014776","pt":1588422135499,"mc":[{"id":"1.170370557","rc":[{"atl":[[2.8,0]],"id":9622734},{"atb":[[1.55,0]],"id":9624350}],"con":true,"img":false}]}
{"op":"mcm","clk":"1362014778","pt":1588422135600,"mc":[{"id":"1.170370557","rc":[{"atb":[[2.58,0]],"id":9622734},{"atl":[[1.64,0]],"id":9624350}],"con":true,"img":false}]}
{"op":"mcm","clk":"1362014781","pt":1588422135808,"mc":[{"id":"1.170370557","rc":[{"atb":[[2.58,2.06]],"id":9622734},{"atl":[[1.64,2.04]],"id":9624350}],"con":true,"img":false}]}
{"op":"mcm","clk":"1362014807","pt":1588422137399,"mc":[{"id":"1.170370557","rc":[{"atb":[[1.6,0]],"id":9624350}],"con":true,"img":false}]}
{"op":"mcm","clk":"1362014810","pt":1588422137501,"mc":[{"id":"1.170370557","rc":[{"atb":[[1.56,2.02],[1.55,2.19]],"id":9624350}],"con":true,"img":false}]}
{"op":"mcm","clk":"1362014812","pt":1588422137604,"mc":[{"id":"1.170370557","rc":[{"atb":[[1.58,7.99],[1.57,0]],"id":9624350}],"con":true,"img":false}]}
{"op":"mcm","clk":"1362014816","pt":1588422137810,"mc":[{"id":"1.170370557","rc":[{"atl":[[2.78,2.18],[2.76,2.02]],"id":9622734}],"con":true,"img":false}]}
{"op":"mcm","clk":"1362014818","pt":1588422137916,"mc":[{"id":"1.170370557","rc":[{"atl":[[2.72,0],[2.74,0]],"id":9622734}],"con":true,"img":false}]}
{"op":"mcm","clk":"1362014822","pt":1588422138119,"mc":[{"id":"1.170370557","rc":[{"atb":[[2.6,18.66]],"id":9622734},{"atl":[[2.82,12.25],[2.8,2.02],[2.78,0.16],[2.76,0]],"id":9622734},{"atb":[[1.53,0],[1.54,8.46]],"id":9624350}],"con":true,"img":false}]}
{"op":"mcm","clk":"1362014826","pt":1588422138328,"mc":[{"id":"1.170370557","rc":[{"atl":[[2.78,2.18]],"id":9622734}],"con":true,"img":false}]}
{"op":"mcm","clk":"1362014856","pt":1588422139718,"mc":[{"id":"1.170370557","rc":[{"trd":[[1.58,69.94]],"ltp":1.58,"tv":69.94,"id":9624350},{"atb":[[1.58,0]],"id":9624350},{"atl":[[1.58,48.03]],"id":9624350}],"con":true,"img":false}]}
{"op":"mcm","clk":"1362014860","pt":1588422139923,"mc":[{"id":"1.170370557","rc":[{"atb":[[1.54,10.58]],"id":9624350},{"atl":[[1.6,2.01],[1.61,2.14]],"id":9624350}],"con":true,"img":false}]}
{"op":"mcm","clk":"1362014862","pt":1588422140028,"mc":[{"id":"1.170370557","rc":[{"atb":[[1.56,0]],"id":9624350}],"con":true,"img":false}]}
{"op":"mcm","clk":"1362014865","pt":1588422140131,"mc":[{"id":"1.170370557","rc":[{"atb":[[2.64,43.59],[2.24,47.46]],"id":9622734},{"atb":[[1.57,103.26]],"id":9624350}],"con":true,"img":false}]}
{"op":"mcm","clk":"1362014866","pt":1588422140235,"mc":[{"id":"1.170370557","rc":[{"atb":[[2.66,2.02],[2.68,2.11]],"id":9622734},{"atl":[[2.84,2.03]],"id":9622734},{"atb":[[1.53,2.16],[1.52,17.46]],"id":9624350}],"con":true,"img":false}]}
{"op":"mcm","clk":"1362014869","pt":1588422140335,"mc":[{"id":"1.170370557","rc":[{"atl":[[2.8,0],[2.78,0.16]],"id":9622734},{"atb":[[1.55,0],[1.54,8.46]],"id":9624350},{"atl":[[1.63,0]],"id":9624350}],"con":true,"img":false}]}
{"op":"mcm","clk":"1362014877","pt":1588422140494,"mc":[{"id":"1.170370557","rc":[{"atb":[[2.6,16.62]],"id":9622734}],"con":true,"img":false}]}
{"op":"mcm","clk":"1362014880","pt":1588422140596,"mc":[{"id":"1.170370557","rc":[{"atl":[[2.8,2.02]],"id":9622734},{"atb":[[1.55,2],[1.54,10.54]],"id":9624350}],"con":true,"img":false}]}
{"op":"mcm","clk":"1362014889","pt":1588422141106,"mc":[{"id":"1.170370557","rc":[{"atb":[[2.62,16.41]],"id":9622734},{"atb":[[1.52,68.6]],"id":9624350}],"con":true,"img":false}]}
{"op":"mcm","clk":"1362014892","pt":1588422141314,"mc":[{"id":"1.170370557","rc":[{"atb":[[2.64,27.37]],"id":9622734}],"con":true,"img":false}]}
{"op":"mcm","clk":"1362014896","pt":1588422141621,"mc":[{"id":"1.170370557","rc":[{"atb":[[2.58,0]],"id":9622734},{"atl":[[1.64,0]],"id":9624350}],"con":true,"img":false}]}
{"op":"mcm","clk":"1362015099","pt":1588422161448,"mc":[{"id":"1.170370557","rc":[{"atl":[[1.6,9.91]],"id":9624350}],"con":true,"img":false}]}
{"op":"mcm","clk":"1362015104","pt":1588422161858,"mc":[{"id":"1.170370557","rc":[{"atb":[[2.66,0]],"id":9622734},{"atl":[[2.82,10],[2.84,0]],"id":9622734},{"atb":[[1.53,0],[1.54,8.46],[1.52,66.52]],"id":9624350},{"atl":[[1.61,0]],"id":9624350}],"con":true,"img":false}]}
{"op":"mcm","clk":"1362015107","pt":1588422162060,"mc":[{"id":"1.170370557","rc":[{"atb":[[2.66,2.02]],"id":9622734},{"atl":[[2.82,12.25]],"id":9622734},{"atb":[[1.54,10.58]],"id":9624350},{"atl":[[1.61,2.01]],"id":9624350}],"con":true,"img":false}]}
{"op":"mcm","clk":"1362015337","pt":1588422189515,"mc":[{"id":"1.170370557","rc":[{"atb":[[2.3,0]],"id":9622734},{"atb":[[1.49,0]],"id":9624350}],"con":true,"img":false}]}
{"op":"mcm","clk":"1362015344","pt":1588422189824,"mc":[{"id":"1.170370557","rc":[{"atb":[[2.66,0]],"id":9622734},{"atl":[[2.82,10]],"id":9622734},{"atb":[[1.54,8.46]],"id":9624350},{"atl":[[1.61,0]],"id":9624350}],"con":true,"img":false}]}
{"op":"mcm","clk":"1362015350","pt":1588422189979,"mc":[{"id":"1.170370557","rc":[{"atb":[[2.66,2.28]],"id":9622734},{"atl":[[2.82,12.08]],"id":9622734},{"atb":[[1.54,10.46]],"id":9624350},{"atl":[[1.61,2.01]],"id":9624350}],"con":true,"img":false}]}
{"op":"mcm","clk":"1362015406","pt":1588422197520,"mc":[{"id":"1.170370557","rc":[{"atb":[[1.49,39.99]],"id":9624350}],"con":true,"img":false}]}
{"op":"mcm","clk":"1362015409","pt":1588422197724,"mc":[{"id":"1.170370557","rc":[{"atb":[[2.3,39.99],[2.66,0]],"id":9622734},{"atl":[[2.82,10]],"id":9622734},{"atl":[[1.61,0]],"id":9624350}],"con":true,"img":false}]}
{"op":"mcm","clk":"1362015410","pt":1588422197826,"mc":[{"id":"1.170370557","rc":[{"atb":[[1.54,8.46]],"id":9624350}],"con":true,"img":false}]}
{"op":"mcm","clk":"1362015411","pt":1588422197928,"mc":[{"id":"1.170370557","rc":[{"atb":[[2.66,2.02]],"id":9622734},{"atl":[[2.82,12.08]],"id":9622734},{"atl":[[1.61,2.14]],"id":9624350}],"con":true,"img":false}]}
{"op":"mcm","clk":"1362015413","pt":1588422198030,"mc":[{"id":"1.170370557","rc":[{"atb":[[1.54,10.58]],"id":9624350}],"con":true,"img":false}]}
{"op":"mcm","clk":"1362015734","pt":1588422229270,"mc":[{"id":"1.170370557","rc":[{"atb":[[1.35,1.77]],"id":9624350}],"con":true,"img":false}]}
{"op":"mcm","clk":"1362015736","pt":1588422229374,"mc":[{"id":"1.170370557","rc":[{"atb":[[1.31,137.11]],"id":9624350}],"con":true,"img":false}]}
{"op":"mcm","clk":"1362015739","pt":1588422229579,"mc":[{"id":"1.170370557","rc":[{"atb":[[2.66,0]],"id":9622734},{"atl":[[2.82,10]],"id":9622734},{"atb":[[1.54,8.46]],"id":9624350},{"atl":[[1.61,0]],"id":9624350}],"con":true,"img":false}]}
{"op":"mcm","clk":"1362015745","pt":1588422229786,"mc":[{"id":"1.170370557","rc":[{"atb":[[2.66,2]],"id":9622734},{"atl":[[2.82,12.02]],"id":9622734},{"atb":[[1.54,10.58]],"id":9624350},{"atl":[[1.61,2.01]],"id":9624350}],"con":true,"img":false}]}
{"op":"mcm","clk":"1362015949","pt":1588422248329,"mc":[{"id":"1.170370557","marketDefinition":{"bspMarket":false,"turnInPlayEnabled":true,"persistenceEnabled":true,"marketBaseRate":5.0,"eventId":"29788106","eventTypeId":"2","numberOfWinners":1,"bettingType":"ODDS","marketType":"MATCH_ODDS","marketTime":"2020-05-02T12:40:00.000Z","suspendTime":"2020-05-02T12:40:00.000Z","bspReconciled":false,"complete":true,"inPlay":false,"crossMatching":true,"runnersVoidable":false,"numberOfActiveRunners":2,"betDelay":0,"status":"OPEN","runners":[{"status":"ACTIVE","sortPriority":1,"id":9624350,"name":"Y Hanfmann"},{"status":"ACTIVE","sortPriority":2,"id":9622734,"name":"D Brown"}],"regulators":["MR_INT"],"countryCode":"GB","discountAllowed":true,"timezone":"GMT","openDate":"2020-05-02T12:30:00.000Z","version":3237534183,"name":"Match Odds","eventName":"Y Hanfmann v D Brown"},"rc":[],"con":true,"img":false}]}
{"op":"mcm","clk":"1362015968","pt":1588422250076,"mc":[{"id":"1.170370557","rc":[{"atb":[[2.3,0]],"id":9622734},{"atb":[[1.49,0]],"id":9624350}],"con":true,"img":false}]}
{"op":"mcm","clk":"1362015971","pt":1588422250331,"mc":[{"id":"1.170370557","marketDefinition":{"bspMarket":false,"turnInPlayEnabled":true,"persistenceEnabled":true,"marketBaseRate":5.0,"eventId":"29788106","eventTypeId":"2","numberOfWinners":1,"bettingType":"ODDS","marketType":"MATCH_ODDS","marketTime":"2020-05-02T12:40:00.000Z","suspendTime":"2020-05-02T12:40:00.000Z","bspReconciled":false,"complete":true,"inPlay":false,"crossMatching":true,"runnersVoidable":false,"numberOfActiveRunners":2,"betDelay":0,"status":"OPEN","runners":[{"status":"ACTIVE","sortPriority":1,"id":9624350,"name":"Y Hanfmann"},{"status":"ACTIVE","sortPriority":2,"id":9622734,"name":"D Brown"}],"regulators":["MR_INT"],"countryCode":"GB","discountAllowed":true,"timezone":"GMT","openDate":"2020-05-02T12:40:00.000Z","version":3237534183,"name":"Match Odds","eventName":"Y Hanfmann v D Brown"},"rc":[],"con":true,"img":false}]}
{"op":"mcm","clk":"1362015975","pt":1588422250383,"mc":[{"id":"1.170370557","rc":[{"atb":[[2.66,0]],"id":9622734},{"atl":[[2.82,10]],"id":9622734},{"atb":[[1.54,8.46]],"id":9624350},{"atl":[[1.61,0]],"id":9624350}],"con":true,"img":false}]}
{"op":"mcm","clk":"1362015977","pt":1588422250588,"mc":[{"id":"1.170370557","rc":[{"atb":[[2.66,2.02]],"id":9622734},{"atl":[[2.82,12.25]],"id":9622734},{"atb":[[1.54,10.48]],"id":9624350},{"atl":[[1.61,2.14]],"id":9624350}],"con":true,"img":false}]}
{"op":"mcm","clk":"1362016014","pt":1588422254085,"mc":[{"id":"1.170370557","rc":[{"atb":[[2.64,23.59]],"id":9622734}],"con":true,"img":false}]}
{"op":"mcm","clk":"1362016025","pt":1588422255676,"mc":[{"id":"1.170370557","rc":[{"atb":[[1.49,39.99]],"id":9624350}],"con":true,"img":false}]}
{"op":"mcm","clk":"1362016027","pt":1588422255881,"mc":[{"id":"1.170370557","rc":[{"atb":[[2.3,39.99]],"id":9622734}],"con":true,"img":false}]}
{"op":"mcm","clk":"1362016144","pt":1588422268899,"mc":[{"id":"1.170370557","rc":[{"atb":[[2.68,5.83]],"id":9622734}],"con":true,"img":false}]}
{"op":"mcm","clk":"1362016147","pt":1588422269210,"mc":[{"id":"1.170370557","rc":[{"atb":[[2.66,0]],"id":9622734},{"atl":[[2.82,10]],"id":9622734},{"atb":[[1.54,8.46]],"id":9624350},{"atl":[[1.61,0]],"id":9624350}],"con":true,"img":false}]}
{"op":"mcm","clk":"1362016148","pt":1588422269415,"mc":[{"id":"1.170370557","rc":[{"atb":[[2.66,2.28]],"id":9622734},{"atl":[[2.82,12.02]],"id":9622734},{"atb":[[1.54,10.58]],"id":9624350},{"atl":[[1.61,2.14]],"id":9624350}],"con":true,"img":false}]}
{"op":"mcm","clk":"1362016326","pt":1588422286333,"mc":[{"id":"1.170370557","rc":[{"atb":[[2.3,0]],"id":9622734}],"con":true,"img":false}]}
{"op":"mcm","clk":"1362016332","pt":1588422286640,"mc":[{"id":"1.170370557","rc":[{"atb":[[2.66,0]],"id":9622734},{"atl":[[2.82,10]],"id":9622734},{"atb":[[1.54,8.46]],"id":9624350},{"atl":[[1.61,0]],"id":9624350}],"con":true,"img":false}]}
{"op":"mcm","clk":"1362016337","pt":1588422286845,"mc":[{"id":"1.170370557","rc":[{"atb":[[2.66,2.02]],"id":9622734},{"atl":[[2.82,12.08]],"id":9622734},{"atb":[[1.54,10.58],[1.49,0]],"id":9624350},{"atl":[[1.61,2]],"id":9624350}],"con":true,"img":false}]}
{"op":"mcm","clk":"1362016338","pt":1588422286948,"mc":[{"id":"1.170370557","rc":[{"atb":[[1.53,39.99]],"id":9624350}],"con":true,"img":false}]}
{"op":"mcm","clk":"1362016364","pt":1588422290345,"mc":[{"id":"1.170370557","rc":[{"atb":[[2.22,39.99]],"id":9622734}],"con":true,"img":false}]}
{"op":"mcm","clk":"1362016612","pt":1588422310653,"mc":[{"id":"1.170370557","rc":[{"atb":[[2.22,0]],"id":9622734},{"atb":[[1.53,0]],"id":9624350}],"con":true,"img":false}]}
{"op":"mcm","clk":"1362016615","pt":1588422310859,"mc":[{"id":"1.170370557","rc":[{"atb":[[2.66,0]],"id":9622734},{"atl":[[2.82,10]],"id":9622734},{"atb":[[1.54,8.46]],"id":9624350},{"atl":[[1.61,0]],"id":9624350}],"con":true,"img":false}]}
{"op":"mcm","clk":"1362016620","pt":1588422311063,"mc":[{"id":"1.170370557","rc":[{"atb":[[2.66,2.02]],"id":9622734},{"atl":[[2.82,12]],"id":9622734},{"atb":[[1.54,10.58]],"id":9624350},{"atl":[[1.61,2.01]],"id":9624350}],"con":true,"img":false}]}
{"op":"mcm","clk":"1362016720","pt":1588422318370,"mc":[{"id":"1.170370557","rc":[{"atb":[[1.53,39.99]],"id":9624350}],"con":true,"img":false}]}
{"op":"mcm","clk":"1362016723","pt":1588422318575,"mc":[{"id":"1.170370557","rc":[{"atb":[[2.22,39.99]],"id":9622734}],"con":true,"img":false}]}
{"op":"mcm","clk":"1362016725","pt":1588422318679,"mc":[{"id":"1.170370557","rc":[{"atb":[[2.66,0]],"id":9622734},{"atl":[[2.82,10]],"id":9622734},{"atb":[[1.54,8.46]],"id":9624350},{"atl":[[1.61,0]],"id":9624350}],"con":true,"img":false}]}
{"op":"mcm","clk":"1362016727","pt":1588422318883,"mc":[{"id":"1.170370557","rc":[{"atb":[[2.66,2.02]],"id":9622734},{"atl":[[2.82,12.08]],"id":9622734},{"atb":[[1.54,10.58]],"id":9624350},{"atl":[[1.61,2.14]],"id":9624350}],"con":true,"img":false}]}
{"op":"mcm","clk":"1362016862","pt":1588422332594,"mc":[{"id":"1.170370557","rc":[{"trd":[[2.72,39.66]],"ltp":2.72,"tv":39.66,"id":9622734},{"trd":[[1.58,117.87]],"ltp":1.58,"tv":117.87,"id":9624350},{"atl":[[1.58,0.1]],"id":9624350}],"con":true,"img":false}]}
{"op":"mcm","clk":"1362016869","pt":1588422332803,"mc":[{"id":"1.170370557","rc":[{"atl":[[1.63,2.04],[1.62,2.25]],"id":9624350}],"con":true,"img":false}]}
{"op":"mcm","clk":"1362016872","pt":1588422333011,"mc":[{"id":"1.170370557","rc":[{"atb":[[2.66,0]],"id":9622734},{"atl":[[2.82,10]],"id":9622734},{"atb":[[1.54,8.46]],"id":9624350},{"atl":[[1.6,7.9],[1.61,0]],"id":9624350}],"con":true,"img":false}]}
{"op":"mcm","clk":"1362016876","pt":1588422333218,"mc":[{"id":"1.170370557","rc":[{"atb":[[2.64,25.66],[2.6,0],[2.58,16.83],[2.62,2.04],[2.68,3.72]],"id":9622734},{"atl":[[2.82,12.25]],"id":9622734},{"atb":[[1.53,90.17],[1.54,10.58]],"id":9624350}],"con":true,"img":false}]}
{"op":"mcm","clk":"1362016889","pt":1588422334198,"mc":[{"id":"1.170370557","rc":[{"atb":[[2.58,0],[2.56,17.04]],"id":9622734}],"con":true,"img":false}]}
{"op":"mcm","clk":"1362017221","pt":1588422366139,"mc":[{"id":"1.170370557","rc":[{"trd":[[1.58,118.08]],"ltp":1.58,"tv":118.08,"id":9624350},{"atb":[[1.58,127.07]],"id":9624350},{"atl":[[1.58,0]],"id":9624350}],"con":true,"img":false}]}
{"op":"mcm","clk":"1362017223","pt":1588422366346,"mc":[{"id":"1.170370557","rc":[{"atb":[[1.56,2.08]],"id":9624350}],"con":true,"img":false}]}
{"op":"mcm","clk":"1362017225","pt":1588422366447,"mc":[{"id":"1.170370557","rc":[{"atb":[[2.62,0]],"id":9622734},{"atl":[[2.82,10]],"id":9622734},{"atb":[[1.54,8.46]],"id":9624350},{"atl":[[1.63,0]],"id":9624350}],"con":true,"img":false}]}
{"op":"mcm","clk":"1362017228","pt":1588422366652,"mc":[{"id":"1.170370557","rc":[{"atb":[[2.62,2.04]],"id":9622734},{"atl":[[2.78,2.41]],"id":9622734},{"atb":[[1.55,0]],"id":9624350},{"atl":[[1.63,2.04]],"id":9624350}],"con":true,"img":false}]}
{"op":"mcm","clk":"1362017233","pt":1588422366854,"mc":[{"id":"1.170370557","rc":[{"atb":[[1.55,2]],"id":9624350}],"con":true,"img":false}]}
{"op":"mcm","clk":"1362017235","pt":1588422366958,"mc":[{"id":"1.170370557","rc":[{"atl":[[2.8,0]],"id":9622734}],"con":true,"img":false}]}
{"op":"mcm","clk":"1362017238","pt":1588422367112,"mc":[{"id":"1.170370557","rc":[{"atl":[[2.8,2]],"id":9622734}],"con":true,"img":false}]}
{"op":"mcm","clk":"1362017272","pt":1588422371220,"mc":[{"id":"1.170370557","rc":[{"atb":[[2.22,0]],"id":9622734},{"atb":[[1.53,50.17]],"id":9624350}],"con":true,"img":false}]}
{"op":"mcm","clk":"1362017300","pt":1588422373518,"mc":[{"id":"1.170370557","rc":[{"atb":[[1.53,90.17]],"id":9624350}],"con":true,"img":false}]}
{"op":"mcm","clk":"1362017302","pt":1588422373726,"mc":[{"id":"1.170370557","rc":[{"atb":[[2.22,39.99],[2.62,0]],"id":9622734},{"atl":[[2.8,0]],"id":9622734},{"atb":[[1.55,0]],"id":9624350},{"atl":[[1.63,0]],"id":9624350}],"con":true,"img":false}]}
{"op":"mcm","clk":"1362017304","pt":1588422373930,"mc":[{"id":"1.170370557","rc":[{"atb":[[2.62,2.04]],"id":9622734},{"atl":[[2.8,2.02]],"id":9622734},{"atb":[[1.55,2.08]],"id":9624350},{"atl":[[1.63,2.01]],"id":9624350}],"con":true,"img":false}]}
{"op":"mcm","clk":"1362017322","pt":1588422376235,"mc":[{"id":"1.170370557","rc":[{"atl":[[1.6,0]],"id":9624350}],"con":true,"img":false}]}
{"op":"mcm","clk":"1362017323","pt":1588422376337,"mc":[{"id":"1.170370557","rc":[{"atl":[[1.64,2.04]],"id":9624350}],"con":true,"img":false}]}
{"op":"mcm","clk":"1362017326","pt":1588422376541,"mc":[{"id":"1.170370557","rc":[{"atl":[[1.62,0]],"id":9624350}],"con":true,"img":false}]}
{"op":"mcm","clk":"1362017329","pt":1588422376745,"mc":[{"id":"1.170370557","rc":[{"atl":[[1.62,2.09]],"id":9624350}],"con":true,"img":false}]}
{"op":"mcm","clk":"1362017397","pt":1588422380748,"mc":[{"id":"1.170370557","rc":[{"atl":[[1.64,9.74]],"id":9624350}],"con":true,"img":false}]}
{"op":"mcm","clk":"1362017404","pt":1588422381057,"mc":[{"id":"1.170370557","rc":[{"atb":[[2.62,0]],"id":9622734},{"atl":[[2.8,0]],"id":9622734},{"atb":[[1.55,0]],"id":9624350},{"atl":[[1.63,0]],"id":9624350}],"con":true,"img":false}]}
{"op":"mcm","clk":"1362017409","pt":1588422381264,"mc":[{"id":"1.170370557","rc":[{"atb":[[2.62,2.04]],"id":9622734},{"atl":[[2.8,2.02]],"id":9622734},{"atb":[[1.55,2.19]],"id":9624350},{"atl":[[1.63,2.04]],"id":9624350}],"con":true,"img":false}]}
{"op":"mcm","clk":"1362017614","pt":1588422397679,"mc":[{"id":"1.170370557","rc":[{"atb":[[1.58,0]],"id":9624350}],"con":true,"img":false}]}
{"op":"mcm","clk":"1362017619","pt":1588422397881,"mc":[{"id":"1.170370557","rc":[{"atb":[[1.54,10.58]],"id":9624350}],"con":true,"img":false}]}
{"op":"mcm","clk":"1362017621","pt":1588422397987,"mc":[{"id":"1.170370557","rc":[{"atb":[[2.62,0]],"id":9622734},{"atl":[[2.8,0]],"id":9622734},{"atb":[[1.56,0]],"id":9624350},{"atl":[[1.64,7.7],[1.63,0]],"id":9624350}],"con":true,"img":false}]}
{"op":"mcm","clk":"1362017624","pt":1588422398189,"mc":[{"id":"1.170370557","rc":[{"atl":[[2.82,12.08]],"id":9622734}],"con":true,"img":false}]}
{"op":"mcm","clk":"1362017628","pt":1588422398290,"mc":[{"id":"1.170370557","rc":[{"atl":[[2.78,0.16]],"id":9622734}],"con":true,"img":false}]}
{"op":"mcm","clk":"1362017630","pt":1588422398494,"mc":[{"id":"1.170370557","rc":[{"atb":[[2.62,2.04]],"id":9622734},{"atl":[[2.8,2.02]],"id":9622734},{"atl":[[1.63,2.04]],"id":9624350}],"con":true,"img":false}]}
{"op":"mcm","clk":"1362017708","pt":1588422405165,"mc":[{"id":"1.170370557","rc":[{"atl":[[1.64,0]],"id":9624350}],"con":true,"img":false}]}
{"op":"mcm","clk":"1362017712","pt":1588422405474,"mc":[{"id":"1.170370557","rc":[{"atb":[[2.62,0]],"id":9622734},{"atl":[[2.82,10]],"id":9622734},{"atb":[[1.54,8.46]],"id":9624350},{"atl":[[1.63,0]],"id":9624350}],"con":true,"img":false}]}
{"op":"mcm","clk":"1362017714","pt":1588422405680,"mc":[{"id":"1.170370557","rc":[{"atb":[[2.62,2]],"id":9622734},{"atl":[[2.82,12.08]],"id":9622734},{"atb":[[1.54,10.58]],"id":9624350},{"atl":[[1.63,2.04]],"id":9624350}],"con":true,"img":false}]}
{"op":"mcm","clk":"1362017729","pt":1588422406674,"mc":[{"id":"1.170370557","rc":[{"atl":[[1.6,7.9]],"id":9624350}],"con":true,"img":false}]}
{"op":"mcm","clk":"1362017786","pt":1588422412005,"mc":[{"id":"1.170370557","rc":[{"atb":[[1.58,127.17]],"id":9624350}],"con":true,"img":false}]}
{"op":"mcm","clk":"1362017788","pt":1588422412209,"mc":[{"id":"1.170370557","rc":[{"atb":[[1.56,2.08]],"id":9624350}],"con":true,"img":false}]}
{"op":"mcm","clk":"1362017790","pt":1588422412415,"mc":[{"id":"1.170370557","rc":[{"atb":[[2.62,0]],"id":9622734},{"atl":[[2.82,10]],"id":9622734},{"atb":[[1.54,8.46]],"id":9624350},{"atl":[[1.63,0]],"id":9624350}],"con":true,"img":false}]}
{"op":"mcm","clk":"1362017791","pt":1588422412516,"mc":[{"id":"1.170370557","rc":[{"atl":[[2.78,2.41]],"id":9622734}],"con":true,"img":false}]}
{"op":"mcm","clk":"1362017794","pt":1588422412616,"mc":[{"id":"1.170370557","rc":[{"atb":[[1.55,0]],"id":9624350}],"con":true,"img":false}]}
{"op":"mcm","clk":"1362017797","pt":1588422412719,"mc":[{"id":"1.170370557","rc":[{"atb":[[2.62,2.04]],"id":9622734},{"atl":[[1.63,2.04]],"id":9624350}],"con":true,"img":false}]}
{"op":"mcm","clk":"1362017799","pt":1588422412774,"mc":[{"id":"1.170370557","rc":[{"atl":[[2.8,0]],"id":9622734}],"con":true,"img":false}]}
{"op":"mcm","clk":"1362017802","pt":1588422412982,"mc":[{"id":"1.170370557","rc":[{"atl":[[2.8,2.02]],"id":9622734},{"atb":[[1.55,2.19]],"id":9624350}],"con":true,"img":false}]}
{"op":"mcm","clk":"1362018003","pt":1588422431832,"mc":[{"id":"1.170370557","rc":[{"atb":[[2.22,0]],"id":9622734},{"atb":[[1.53,50.17]],"id":9624350}],"con":true,"img":false}]}
{"op":"mcm","clk":"1362018006","pt":1588422432242,"mc":[{"id":"1.170370557","rc":[{"atb":[[2.62,0]],"id":9622734},{"atl":[[2.8,0]],"id":9622734},{"atb":[[1.55,0]],"id":9624350},{"atl":[[1.63,0]],"id":9624350}],"con":true,"img":false}]}
{"op":"mcm","clk":"1362018009","pt":1588422432399,"mc":[{"id":"1.170370557","rc":[{"atb":[[2.62,2.04]],"id":9622734},{"atl":[[2.8,2.02]],"id":9622734},{"atb":[[1.55,2.08]],"id":9624350},{"atl":[[1.63,2.04]],"id":9624350}],"con":true,"img":false}]}
{"op":"mcm","clk":"1362018038","pt":1588422435624,"mc":[{"id":"1.170370557","rc":[{"atb":[[1.53,90.17]],"id":9624350}],"con":true,"img":false}]}
{"op":"mcm","clk":"1362018041","pt":1588422435832,"mc":[{"id":"1.170370557","rc":[{"atb":[[2.22,39.99]],"id":9622734}],"con":true,"img":false}]}
{"op":"mcm","clk":"1362018415","pt":1588422474001,"mc":[{"id":"1.170370557","rc":[{"trd":[[2.74,0.1]],"ltp":2.74,"tv":0.1,"id":9622734},{"trd":[[1.58,118.26]],"ltp":1.58,"tv":118.26,"id":9624350},{"atb":[[1.58,127]],"id":9624350}],"con":true,"img":false}]}
{"op":"mcm","clk":"1362018420","pt":1588422474206,"mc":[{"id":"1.170370557","rc":[{"atb":[[1.58,0]],"id":9624350}],"con":true,"img":false}]}
{"op":"mcm","clk":"1362018421","pt":1588422474309,"mc":[{"id":"1.170370557","rc":[{"atb":[[2.62,0]],"id":9622734},{"atl":[[2.8,0]],"id":9622734},{"atb":[[1.55,0]],"id":9624350},{"atl":[[1.63,0]],"id":9624350}],"con":true,"img":false}]}
{"op":"mcm","clk":"1362018424","pt":1588422474467,"mc":[{"id":"1.170370557","rc":[{"atl":[[2.82,12.02]],"id":9622734},{"atb":[[1.54,10.58]],"id":9624350}],"con":true,"img":false}]}
{"op":"mcm","clk":"1362018428","pt":1588422474572,"mc":[{"id":"1.170370557","rc":[{"atl":[[2.78,0.16]],"id":9622734},{"atb":[[1.56,0]],"id":9624350}],"con":true,"img":false}]}
{"op":"mcm","clk":"1362018429","pt":1588422474775,"mc":[{"id":"1.170370557","rc":[{"atb":[[2.62,2.02]],"id":9622734},{"atl":[[2.8,2.02]],"id":9622734},{"atb":[[1.55,2.08]],"id":9624350},{"atl":[[1.63,2.04]],"id":9624350}],"con":true,"img":false}]}
{"op":"mcm","clk":"1362018544","pt":1588422488115,"mc":[{"id":"1.170370557","rc":[{"atb":[[1.58,127.17]],"id":9624350}],"con":true,"img":false}]}
{"op":"mcm","clk":"1362018547","pt":1588422488321,"mc":[{"id":"1.170370557","rc":[{"atb":[[1.56,2.08]],"id":9624350}],"con":true,"img":false}]}
{"op":"mcm","clk":"1362018548","pt":1588422488423,"mc":[{"id":"1.170370557","rc":[{"atb":[[2.62,0]],"id":9622734},{"atl":[[2.82,10]],"id":9622734},{"atb":[[1.54,8.46]],"id":9624350},{"atl":[[1.63,0]],"id":9624350}],"con":true,"img":false}]}
{"op":"mcm","clk":"1362018551","pt":1588422488580,"mc":[{"id":"1.170370557","rc":[{"atl":[[2.78,2.18]],"id":9622734},{"atb":[[1.55,0]],"id":9624350}],"con":true,"img":false}]}
{"op":"mcm","clk":"1362018552","pt":1588422488682,"mc":[{"id":"1.170370557","rc":[{"atb":[[2.62,2.04]],"id":9622734},{"atl":[[1.63,2.04]],"id":9624350}],"con":true,"img":false}]}
{"op":"mcm","clk":"1362018554","pt":1588422488782,"mc":[{"id":"1.170370557","rc":[{"atb":[[1.55,2.08]],"id":9624350}],"con":true,"img":false}]}
{"op":"mcm","clk":"1362018555","pt":1588422488886,"mc":[{"id":"1.170370557","rc":[{"atl":[[2.8,0]],"id":9622734}],"con":true,"img":false}]}
{"op":"mcm","clk":"1362018558","pt":1588422489091,"mc":[{"id":"1.170370557","rc":[{"atl":[[2.8,2.02]],"id":9622734}],"con":true,"img":false}]}
{"op":"mcm","clk":"1362018583","pt":1588422492518,"mc":[{"id":"1.170370557","rc":[{"atb":[[2.22,0]],"id":9622734},{"atb":[[1.53,50.17]],"id":9624350}],"con":true,"img":false}]}
{"op":"mcm","clk":"1362018623","pt":1588422496431,"mc":[{"id":"1.170370557","rc":[{"atb":[[1.53,90.17]],"id":9624350}],"con":true,"img":false}]}
{"op":"mcm","clk":"1362018627","pt":1588422496636,"mc":[{"id":"1.170370557","rc":[{"atb":[[2.22,39.99]],"id":9622734}],"con":true,"img":false}]}
{"op":"mcm","clk":"1362018629","pt":1588422496738,"mc":[{"id":"1.170370557","rc":[{"atb":[[2.62,0]],"id":9622734},{"atl":[[2.8,0]],"id":9622734}],"con":true,"img":false}]}
{"op":"mcm","clk":"1362018631","pt":1588422496795,"mc":[{"id":"1.170370557","rc":[{"atb":[[1.55,0]],"id":9624350},{"atl":[[1.63,0]],"id":9624350}],"con":true,"img":false}]}
{"op":"mcm","clk":"1362018632","pt":1588422497003,"mc":[{"id":"1.170370557","rc":[{"atb":[[2.62,2.04]],"id":9622734},{"atl":[[2.8,2.02]],"id":9622734},{"atb":[[1.55,2.08]],"id":9624350},{"atl":[[1.63,2.04]],"id":9624350}],"con":true,"img":false}]}
{"op":"mcm","clk":"1362019168","pt":1588422553083,"mc":[{"id":"1.170370557","rc":[{"atb":[[2.22,0]],"id":9622734},{"atb":[[1.53,50.17]],"id":9624350}],"con":true,"img":false}]}
{"op":"mcm","clk":"1362019172","pt":1588422553391,"mc":[{"id":"1.170370557","rc":[{"atl":[[2.8,0]],"id":9622734},{"atb":[[1.55,0]],"id":9624350},{"atl":[[1.63,0]],"id":9624350}],"con":true,"img":false}]}
{"op":"mcm","clk":"1362019173","pt":1588422553493,"mc":[{"id":"1.170370557","rc":[{"atb":[[2.62,0]],"id":9622734}],"con":true,"img":false}]}
{"op":"mcm","clk":"1362019176","pt":1588422553700,"mc":[{"id":"1.170370557","rc":[{"atb":[[2.62,2.04]],"id":9622734},{"atl":[[2.8,2]],"id":9622734},{"atb":[[1.55,2.08]],"id":9624350},{"atl":[[1.63,2.04]],"id":9624350}],"con":true,"img":false}]}
{"op":"mcm","clk":"1362019189","pt":1588422554673,"mc":[{"id":"1.170370557","rc":[{"atb":[[1.53,90.17]],"id":9624350}],"con":true,"img":false}]}
{"op":"mcm","clk":"1362019194","pt":1588422554876,"mc":[{"id":"1.170370557","rc":[{"atb":[[2.22,39.99]],"id":9622734}],"con":true,"img":false}]}
{"op":"mcm","clk":"1362020422","pt":1588422596073,"mc":[{"id":"1.170370557","rc":[{"atb":[[1.59,52.58]],"id":9624350}],"con":true,"img":false}]}
{"op":"mcm","clk":"1362020424","pt":1588422596278,"mc":[{"id":"1.170370557","rc":[{"atb":[[1.57,105.32]],"id":9624350}],"con":true,"img":false}]}
{"op":"mcm","clk":"1362020426","pt":1588422596381,"mc":[{"id":"1.170370557","rc":[{"trd":[[2.68,4.2]],"ltp":2.68,"tv":4.2,"id":9622734},{"atb":[[2.68,1.62]],"id":9622734},{"atl":[[2.8,0]],"id":9622734},{"atb":[[1.55,0]],"id":9624350},{"atl":[[1.63,0]],"id":9624350}],"con":true,"img":false}]}
{"op":"mcm","clk":"1362020428","pt":1588422596483,"mc":[{"id":"1.170370557","rc":[{"atb":[[2.62,0]],"id":9622734}],"con":true,"img":false}]}
{"op":"mcm","clk":"1362020430","pt":1588422596642,"mc":[{"id":"1.170370557","rc":[{"atb":[[2.6,2.04]],"id":9622734},{"atl":[[2.74,2.17],[2.76,2.02]],"id":9622734},{"atl":[[1.63,2.04]],"id":9624350}],"con":true,"img":false}]}
{"op":"mcm","clk":"1362020431","pt":1588422596742,"mc":[{"id":"1.170370557","rc":[{"atb":[[2.64,23.59]],"id":9622734},{"atb":[[1.56,0]],"id":9624350}],"con":true,"img":false}]}
{"op":"mcm","clk":"1362020434","pt":1588422596951,"mc":[{"id":"1.170370557","rc":[{"atb":[[2.62,2.04]],"id":9622734},{"atl":[[2.78,0.16]],"id":9622734}],"con":true,"img":false}]}
{"op":"mcm","clk":"1362020435","pt":1588422597052,"mc":[{"id":"1.170370557","rc":[{"atb":[[1.56,2.08]],"id":9624350}],"con":true,"img":false}]}
{"op":"mcm","clk":"1362020438","pt":1588422597257,"mc":[{"id":"1.170370557","rc":[{"atb":[[1.56,4.16],[1.54,57.71]],"id":9624350}],"con":true,"img":false}]}
{"op":"mcm","clk":"1362020439","pt":1588422597463,"mc":[{"id":"1.170370557","rc":[{"atb":[[2.56,0]],"id":9622734}],"con":true,"img":false}]}
{"op":"mcm","clk":"1362020481","pt":1588422601180,"mc":[{"id":"1.170370557","rc":[{"atb":[[2.24,0]],"id":9622734},{"atb":[[1.57,2.06]],"id":9624350}],"con":true,"img":false}]}
{"op":"mcm","clk":"1362020503","pt":1588422603452,"mc":[{"id":"1.170370557","rc":[{"atl":[[1.6,0]],"id":9624350}],"con":true,"img":false}]}
{"op":"mcm","clk":"1362020508","pt":1588422603662,"mc":[{"id":"1.170370557","rc":[{"atb":[[2.6,0]],"id":9622734},{"atl":[[2.76,0]],"id":9622734},{"atb":[[1.56,2.08]],"id":9624350},{"atl":[[1.64,2.04],[1.62,0]],"id":9624350}],"con":true,"img":false}]}
{"op":"mcm","clk":"1362020510","pt":1588422603765,"mc":[{"id":"1.170370557","rc":[{"atb":[[1.56,0]],"id":9624350}],"con":true,"img":false}]}
{"op":"mcm","clk":"1362020514","pt":1588422603967,"mc":[{"id":"1.170370557","rc":[{"atb":[[2.6,2.04]],"id":9622734},{"atl":[[2.76,2]],"id":9622734},{"atb":[[1.56,2.08]],"id":9624350},{"atl":[[1.62,2.09]],"id":9624350}],"con":true,"img":false}]}
{"op":"mcm","clk":"1362020519","pt":1588422604283,"mc":[{"id":"1.170370557","rc":[{"atl":[[1.63,0]],"id":9624350}],"con":true,"img":false}]}
{"op":"mcm","clk":"1362020524","pt":1588422604489,"mc":[{"id":"1.170370557","rc":[{"atl":[[1.63,2.04]],"id":9624350}],"con":true,"img":false}]}
{"op":"mcm","clk":"1362020527","pt":1588422604588,"mc":[{"id":"1.170370557","rc":[{"atl":[[1.64,9.74]],"id":9624350}],"con":true,"img":false}]}
{"op":"mcm","clk":"1362020622","pt":1588422613696,"mc":[{"id":"1.170370557","rc":[{"atb":[[2.22,0]],"id":9622734},{"atb":[[1.53,50.17]],"id":9624350}],"con":true,"img":false}]}
{"op":"mcm","clk":"1362020626","pt":1588422614005,"mc":[{"id":"1.170370557","rc":[{"atb":[[2.6,0]],"id":9622734},{"atl":[[2.76,0]],"id":9622734},{"atb":[[1.56,0]],"id":9624350},{"atl":[[1.64,7.7],[1.63,0]],"id":9624350}],"con":true,"img":false}]}
{"op":"mcm","clk":"1362020628","pt":1588422614206,"mc":[{"id":"1.170370557","rc":[{"atb":[[2.6,2.04]],"id":9622734},{"atl":[[2.76,2.02]],"id":9622734},{"atb":[[1.56,2.08]],"id":9624350},{"atl":[[1.63,2.04]],"id":9624350}],"con":true,"img":false}]}
{"op":"mcm","clk":"1362020653","pt":1588422616681,"mc":[{"id":"1.170370557","rc":[{"atl":[[1.6,88.65]],"id":9624350}],"con":true,"img":false}]}
{"op":"mcm","clk":"1362020661","pt":1588422617092,"mc":[{"id":"1.170370557","rc":[{"atb":[[1.53,90.17]],"id":9624350}],"con":true,"img":false}]}
{"op":"mcm","clk":"1362020664","pt":1588422617297,"mc":[{"id":"1.170370557","rc":[{"atb":[[2.22,39.99],[2.56,17.04]],"id":9622734}],"con":true,"img":false}]}
{"op":"mcm","clk":"1362020685","pt":1588422619609,"mc":[{"id":"1.170370557","rc":[{"atb":[[1.58,0]],"id":9624350}],"con":true,"img":false}]}
{"op":"mcm","clk":"1362020686","pt":1588422619713,"mc":[{"id":"1.170370557","rc":[{"atb":[[1.59,179.76]],"id":9624350}],"con":true,"img":false}]}
{"op":"mcm","clk":"1362020757","pt":1588422625421,"mc":[{"id":"1.170370557","rc":[{"atl":[[1.61,88.65]],"id":9624350}],"con":true,"img":false}]}
{"op":"mcm","clk":"1362020764","pt":1588422625729,"mc":[{"id":"1.170370557","rc":[{"atb":[[2.6,0]],"id":9622734},{"atl":[[2.76,0]],"id":9622734},{"atb":[[1.56,0]],"id":9624350},{"atl":[[1.63,0]],"id":9624350}],"con":true,"img":false}]}
{"op":"mcm","clk":"1362020767","pt":1588422625892,"mc":[{"id":"1.170370557","rc":[{"atb":[[2.6,2.04]],"id":9622734},{"atl":[[2.76,2.02]],"id":9622734},{"atb":[[1.56,2.08]],"id":9624350},{"atl":[[1.63,2.01]],"id":9624350}],"con":true,"img":false}]}
{"op":"mcm","clk":"1362020804","pt":1588422629023,"mc":[{"id":"1.170370557","rc":[{"trd":[[1.59,22.8]],"ltp":1.59,"tv":22.8,"id":9624350},{"atb":[[1.59,171.81]],"id":9624350}],"con":true,"img":false}]}
{"op":"mcm","clk":"1362020815","pt":1588422630515,"mc":[{"id":"1.170370557","rc":[{"atl":[[1.64,0]],"id":9624350}],"con":true,"img":false}]}
{"op":"mcm","clk":"1362020860","pt":1588422633706,"mc":[{"id":"1.170370557","rc":[{"atl":[[1.62,96.94]],"id":9624350}],"con":true,"img":false}]}
{"op":"mcm","clk":"1362020864","pt":1588422634015,"mc":[{"id":"1.170370557","rc":[{"atb":[[2.6,0]],"id":9622734},{"atl":[[2.76,0]],"id":9622734},{"atb":[[1.56,0]],"id":9624350},{"atl":[[1.63,0]],"id":9624350}],"con":true,"img":false}]}
{"op":"mcm","clk":"1362020865","pt":1588422634220,"mc":[{"id":"1.170370557","rc":[{"atb":[[2.6,2.02]],"id":9622734},{"atl":[[2.76,2.02]],"id":9622734},{"atb":[[1.56,2.08]],"id":9624350},{"atl":[[1.63,2.04]],"id":9624350}],"con":true,"img":false}]}
{"op":"mcm","clk":"1362020949","pt":1588422645223,"mc":[{"id":"1.170370557","rc":[{"atb":[[1.59,44.63]],"id":9624350}],"con":true,"img":false}]}
{"op":"mcm","clk":"1362020950","pt":1588422645325,"mc":[{"id":"1.170370557","rc":[{"trd":[[2.68,5.82]],"ltp":2.68,"tv":5.82,"id":9622734},{"atb":[[2.68,0]],"id":9622734},{"trd":[[1.6,222.98]],"ltp":1.6,"tv":222.98,"id":9624350},{"atb":[[1.6,35.81]],"id":9624350},{"atl":[[1.6,0]],"id":9624350}],"con":true,"img":false}]}
{"op":"mcm","clk":"1362020952","pt":1588422645527,"mc":[{"id":"1.170370557","rc":[{"atb":[[2.6,0]],"id":9622734},{"atl":[[2.76,0]],"id":9622734},{"atb":[[1.56,0]],"id":9624350},{"atl":[[1.63,0]],"id":9624350}],"con":true,"img":false}]}
{"op":"mcm","clk":"1362020953","pt":1588422645635,"mc":[{"id":"1.170370557","rc":[{"atb":[[2.58,2.06]],"id":9622734},{"atl":[[2.72,2.05]],"id":9622734},{"atb":[[1.58,2.06]],"id":9624350},{"atl":[[1.64,2.04]],"id":9624350}],"con":true,"img":false}]}
{"op":"mcm","clk":"1362020956","pt":1588422645734,"mc":[{"id":"1.170370557","rc":[{"atb":[[2.62,0]],"id":9622734},{"atl":[[1.62,94.85]],"id":9624350}],"con":true,"img":false}]}
{"op":"mcm","clk":"1362020959","pt":1588422645838,"mc":[{"id":"1.170370557","rc":[{"atb":[[2.6,2.04]],"id":9622734},{"atl":[[1.63,2.04]],"id":9624350}],"con":true,"img":false}]}
{"op":"mcm","clk":"1362020961","pt":1588422646039,"mc":[{"id":"1.170370557","rc":[{"atl":[[2.74,0]],"id":9622734},{"atb":[[1.57,0]],"id":9624350}],"con":true,"img":false}]}
{"op":"mcm","clk":"1362020962","pt":1588422646243,"mc":[{"id":"1.170370557","rc":[{"atl":[[2.74,2.17]],"id":9622734},{"atb":[[1.57,2.06]],"id":9624350}],"con":true,"img":false}]}
{"op":"mcm","clk":"1362020963","pt":1588422646346,"mc":[{"id":"1.170370557","rc":[{"atb":[[2.56,0]],"id":9622734}],"con":true,"img":false}]}
{"op":"mcm","clk":"1362020964","pt":1588422646451,"mc":[{"id":"1.170370557","rc":[{"atl":[[2.74,4.42]],"id":9622734},{"atb":[[1.57,4.12]],"id":9624350}],"con":true,"img":false}]}
{"op":"mcm","clk":"1362021024","pt":1588422652669,"mc":[{"id":"1.170370557","rc":[{"trd":[[1.6,294.59]],"ltp":1.6,"tv":294.59,"id":9624350},{"atb":[[1.6,0]],"id":9624350},{"atl":[[1.6,8.51]],"id":9624350}],"con":true,"img":false}]}
{"op":"mcm","clk":"1362021027","pt":1588422652873,"mc":[{"id":"1.170370557","rc":[{"atb":[[1.56,2]],"id":9624350},{"atl":[[1.62,97.02]],"id":9624350}],"con":true,"img":false}]}
{"op":"mcm","clk":"1362021028","pt":1588422653078,"mc":[{"id":"1.170370557","rc":[{"atb":[[2.58,0]],"id":9622734},{"atl":[[2.74,0]],"id":9622734},{"atb":[[1.58,0],[1.57,2.06]],"id":9624350},{"atl":[[1.64,0]],"id":9624350}],"con":true,"img":false}]}
{"op":"mcm","clk":"1362021030","pt":1588422653236,"mc":[{"id":"1.170370557","rc":[{"atb":[[2.62,2.04]],"id":9622734},{"atl":[[2.76,2.02]],"id":9622734}],"con":true,"img":false}]}
{"op":"mcm","clk":"1362021034","pt":1588422653337,"mc":[{"id":"1.170370557","rc":[{"atl":[[2.72,0]],"id":9622734},{"atl":[[1.63,0]],"id":9624350}],"con":true,"img":false}]}
{"op":"mcm","clk":"1362021036","pt":1588422653542,"mc":[{"id":"1.170370557","rc":[{"atl":[[2.74,2.25]],"id":9622734}],"con":true,"img":false}]}
{"op":"mcm","clk":"1362021037","pt":1588422653645,"mc":[{"id":"1.170370557","rc":[{"atb":[[2.6,0]],"id":9622734}],"con":true,"img":false}]}
{"op":"mcm","clk":"1362021038","pt":1588422653849,"mc":[{"id":"1.170370557","rc":[{"atb":[[2.6,2.02]],"id":9622734},{"atl":[[1.63,2.04]],"id":9624350}],"con":true,"img":false}]}
{"op":"mcm","clk":"1362021039","pt":1588422654054,"mc":[{"id":"1.170370557","rc":[{"atb":[[2.6,4.06]],"id":9622734},{"atl":[[1.63,4.08]],"id":9624350}],"con":true,"img":false}]}
{"op":"mcm","clk":"1362021233","pt":1588422674294,"mc":[{"id":"1.170370557","rc":[{"atb":[[2.22,0]],"id":9622734},{"atb":[[1.53,50.17]],"id":9624350}],"con":true,"img":false}]}
{"op":"mcm","clk":"1362021236","pt":1588422674703,"mc":[{"id":"1.170370557","rc":[{"atb":[[2.6,0]],"id":9622734},{"atl":[[2.76,0]],"id":9622734},{"atb":[[1.56,0]],"id":9624350},{"atl":[[1.63,0]],"id":9624350}],"con":true,"img":false}]}
{"op":"mcm","clk":"1362021239","pt":1588422674908,"mc":[{"id":"1.170370557","rc":[{"atb":[[2.6,2.04]],"id":9622734},{"atl":[[2.76,2.02]],"id":9622734},{"atb":[[1.56,2.08]],"id":9624350},{"atl":[[1.63,2.01]],"id":9624350}],"con":true,"img":false}]}
{"op":"mcm","clk":"1362021295","pt":1588422680814,"mc":[{"id":"1.170370557","rc":[{"atb":[[1.53,90.17]],"id":9624350}],"con":true,"img":false}]}
{"op":"mcm","clk":"1362021298","pt":1588422681014,"mc":[{"id":"1.170370557","rc":[{"atb":[[2.22,39.99]],"id":9622734}],"con":true,"img":false}]}
{"op":"mcm","clk":"1362021302","pt":1588422681322,"mc":[{"id":"1.170370557","rc":[{"atb":[[2.6,0]],"id":9622734},{"atl":[[2.76,0]],"id":9622734},{"atb":[[1.56,0]],"id":9624350},{"atl":[[1.63,0]],"id":9624350}],"con":true,"img":false}]}
{"op":"mcm","clk":"1362021306","pt":1588422681526,"mc":[{"id":"1.170370557","rc":[{"atb":[[2.6,2.04]],"id":9622734},{"atl":[[2.76,2.02]],"id":9622734},{"atb":[[1.56,2.08]],"id":9624350},{"atl":[[1.63,2.04]],"id":9624350}],"con":true,"img":false}]}
{"op":"mcm","clk":"1362021310","pt":1588422681683,"mc":[{"id":"1.170370557","rc":[{"atb":[[2.6,4.08]],"id":9622734},{"atl":[[2.76,4.04]],"id":9622734},{"atb":[[1.56,4.12]],"id":9624350},{"atl":[[1.63,4.08]],"id":9624350}],"con":true,"img":false}]}
{"op":"mcm","clk":"1362021667","pt":1588422719958,"mc":[{"id":"1.170370557","rc":[{"atb":[[2.64,33.21]],"id":9622734}],"con":true,"img":false}]}
{"op":"mcm","clk":"1362021674","pt":1588422720369,"mc":[{"id":"1.170370557","rc":[{"atb":[[2.6,0]],"id":9622734},{"atl":[[2.76,2.02]],"id":9622734},{"atb":[[1.56,0]],"id":9624350},{"atl":[[1.63,0]],"id":9624350}],"con":true,"img":false}]}
{"op":"mcm","clk":"1362021675","pt":1588422720472,"mc":[{"id":"1.170370557","rc":[{"atl":[[2.76,0]],"id":9622734}],"con":true,"img":false}]}
{"op":"mcm","clk":"1362021677","pt":1588422720570,"mc":[{"id":"1.170370557","rc":[{"atb":[[2.6,2.04]],"id":9622734},{"atb":[[1.56,2]],"id":9624350},{"atl":[[1.63,2.04]],"id":9624350}],"con":true,"img":false}]}
{"op":"mcm","clk":"1362021679","pt":1588422720674,"mc":[{"id":"1.170370557","rc":[{"atl":[[2.76,2.02]],"id":9622734}],"con":true,"img":false}]}
{"op":"mcm","clk":"1362021729","pt":1588422724458,"mc":[{"id":"1.170370557","rc":[{"atb":[[2.22,0]],"id":9622734}],"con":true,"img":false}]}
{"op":"mcm","clk":"1362021731","pt":1588422724559,"mc":[{"id":"1.170370557","rc":[{"atb":[[2.24,39.99]],"id":9622734}],"con":true,"img":false}]}
{"op":"mcm","clk":"1362021780","pt":1588422728979,"mc":[{"id":"1.170370557","rc":[{"atb":[[2.24,0]],"id":9622734}],"con":true,"img":false}]}
{"op":"mcm","clk":"1362021783","pt":1588422729084,"mc":[{"id":"1.170370557","rc":[{"atb":[[2.22,39.99]],"id":9622734}],"con":true,"img":false}]}
{"op":"mcm","clk":"1362021784","pt":1588422729290,"mc":[{"id":"1.170370557","rc":[{"atb":[[2.6,0]],"id":9622734},{"atl":[[2.76,0]],"id":9622734},{"atb":[[1.56,0]],"id":9624350},{"atl":[[1.63,0]],"id":9624350}],"con":true,"img":false}]}
{"op":"mcm","clk":"1362021788","pt":1588422729513,"mc":[{"id":"1.170370557","rc":[{"atb":[[2.6,2.04]],"id":9622734},{"atl":[[2.76,2.02]],"id":9622734},{"atb":[[1.56,2.06]],"id":9624350},{"atl":[[1.63,2.04]],"id":9624350}],"con":true,"img":false}]}
{"op":"mcm","clk":"1362021801","pt":1588422730695,"mc":[{"id":"1.170370557","rc":[{"atb":[[1.58,89.53]],"id":9624350}],"con":true,"img":false}]}
{"op":"mcm","clk":"1362021826","pt":1588422733313,"mc":[{"id":"1.170370557","rc":[{"atb":[[2.22,0]],"id":9622734}],"con":true,"img":false}]}
{"op":"mcm","clk":"1362021827","pt":1588422733366,"mc":[{"id":"1.170370557","rc":[{"atb":[[2.24,39.99]],"id":9622734}],"con":true,"img":false}]}
{"op":"mcm","clk":"1362021841","pt":1588422734802,"mc":[{"id":"1.170370557","rc":[{"atb":[[2.24,0]],"id":9622734},{"atb":[[1.58,89.8],[1.53,50.17]],"id":9624350}],"con":true,"img":false}]}
{"op":"mcm","clk":"1362021908","pt":1588422742200,"mc":[{"id":"1.170370557","rc":[{"atb":[[1.53,90.17]],"id":9624350}],"con":true,"img":false}]}
{"op":"mcm","clk":"1362021913","pt":1588422742404,"mc":[{"id":"1.170370557","rc":[{"atb":[[2.24,39.99]],"id":9622734}],"con":true,"img":false}]}
{"op":"mcm","clk":"1362021916","pt":1588422742508,"mc":[{"id":"1.170370557","rc":[{"atb":[[2.6,0]],"id":9622734},{"atl":[[2.76,0]],"id":9622734},{"atb":[[1.56,0]],"id":9624350},{"atl":[[1.63,0]],"id":9624350}],"con":true,"img":false}]}
{"op":"mcm","clk":"1362021921","pt":1588422742711,"mc":[{"id":"1.170370557","rc":[{"atb":[[2.6,2.04]],"id":9622734},{"atl":[[2.76,2.02]],"id":9622734},{"atb":[[1.56,2.08]],"id":9624350},{"atl":[[1.63,2.04]],"id":9624350}],"con":true,"img":false}]}
{"op":"mcm","clk":"1362021953","pt":1588422746823,"mc":[{"id":"1.170370557","rc":[{"atb":[[2.24,0]],"id":9622734}],"con":true,"img":false}]}
{"op":"mcm","clk":"1362021955","pt":1588422746926,"mc":[{"id":"1.170370557","rc":[{"atb":[[2.22,39.99]],"id":9622734}],"con":true,"img":false}]}
{"op":"mcm","clk":"1362022007","pt":1588422751103,"mc":[{"id":"1.170370557","rc":[{"atb":[[2.22,0]],"id":9622734}],"con":true,"img":false}]}
{"op":"mcm","clk":"1362022010","pt":1588422751205,"mc":[{"id":"1.170370557","rc":[{"atb":[[2.24,39.99]],"id":9622734}],"con":true,"img":false}]}
{"op":"mcm","clk":"1362022013","pt":1588422751412,"mc":[{"id":"1.170370557","rc":[{"atb":[[2.6,0]],"id":9622734},{"atl":[[2.76,0]],"id":9622734},{"atb":[[1.56,0]],"id":9624350},{"atl":[[1.63,0]],"id":9624350}],"con":true,"img":false}]}
{"op":"mcm","clk":"1362022017","pt":1588422751618,"mc":[{"id":"1.170370557","rc":[{"atb":[[2.6,2.04]],"id":9622734},{"atl":[[2.76,2.02]],"id":9622734},{"atb":[[1.56,2.08]],"id":9624350},{"atl":[[1.63,2.04]],"id":9624350}],"con":true,"img":false}]}
{"op":"mcm","clk":"1362022019","pt":1588422751717,"mc":[{"id":"1.170370557","rc":[{"atl":[[2.72,2.12]],"id":9622734}],"con":true,"img":false}]}
{"op":"mcm","clk":"1362022054","pt":1588422755426,"mc":[{"id":"1.170370557","rc":[{"atb":[[2.24,0]],"id":9622734}],"con":true,"img":false}]}
{"op":"mcm","clk":"1362022057","pt":1588422755530,"mc":[{"id":"1.170370557","rc":[{"atb":[[2.22,39.99]],"id":9622734}],"con":true,"img":false}]}
{"op":"mcm","clk":"1362022089","pt":1588422758726,"mc":[{"id":"1.170370557","rc":[{"atl":[[1.7,119.98]],"id":9624350}],"con":true,"img":false}]}
{"op":"mcm","clk":"1362022092","pt":1588422759036,"mc":[{"id":"1.170370557","rc":[{"atb":[[2.6,0]],"id":9622734},{"atl":[[2.76,0]],"id":9622734},{"atl":[[1.63,0]],"id":9624350}],"con":true,"img":false}]}
{"op":"mcm","clk":"1362022093","pt":1588422759134,"mc":[{"id":"1.170370557","rc":[{"atb":[[1.56,0]],"id":9624350}],"con":true,"img":false}]}
{"op":"mcm","clk":"1362022095","pt":1588422759237,"mc":[{"id":"1.170370557","rc":[{"atb":[[2.6,2.04]],"id":9622734},{"atl":[[2.76,2]],"id":9622734},{"atl":[[1.63,2.01]],"id":9624350}],"con":true,"img":false}]}
{"op":"mcm","clk":"1362022098","pt":1588422759298,"mc":[{"id":"1.170370557","rc":[{"atb":[[1.56,2.08]],"id":9624350}],"con":true,"img":false}]}
{"op":"mcm","clk":"1362022108","pt":1588422760018,"mc":[{"id":"1.170370557","rc":[{"atb":[[2.22,0]],"id":9622734}],"con":true,"img":false}]}
{"op":"mcm","clk":"1362022110","pt":1588422760122,"mc":[{"id":"1.170370557","rc":[{"atb":[[2.24,39.99]],"id":9622734}],"con":true,"img":false}]}
{"op":"mcm","clk":"1362022161","pt":1588422764333,"mc":[{"id":"1.170370557","rc":[{"atb":[[2.24,0]],"id":9622734}],"con":true,"img":false}]}
{"op":"mcm","clk":"1362022164","pt":1588422764436,"mc":[{"id":"1.170370557","rc":[{"atb":[[2.22,39.99]],"id":9622734}],"con":true,"img":false}]}
{"op":"mcm","clk":"1362022201","pt":1588422768450,"mc":[{"id":"1.170370557","rc":[{"atb":[[2.22,0]],"id":9622734}],"con":true,"img":false}]}
{"op":"mcm","clk":"1362022204","pt":1588422768509,"mc":[{"id":"1.170370557","rc":[{"atb":[[2.24,39.99]],"id":9622734}],"con":true,"img":false}]}
{"op":"mcm","clk":"1362022207","pt":1588422768715,"mc":[{"id":"1.170370557","rc":[{"atl":[[2.76,0]],"id":9622734},{"atb":[[1.56,0]],"id":9624350}],"con":true,"img":false}]}
{"op":"mcm","clk":"1362022210","pt":1588422768818,"mc":[{"id":"1.170370557","rc":[{"atb":[[2.6,0]],"id":9622734},{"atl":[[1.63,0]],"id":9624350}],"con":true,"img":false}]}
{"op":"mcm","clk":"1362022214","pt":1588422769023,"mc":[{"id":"1.170370557","rc":[{"atb":[[2.6,2.04]],"id":9622734},{"atl":[[2.76,2.02]],"id":9622734},{"atb":[[1.56,2.08]],"id":9624350},{"atl":[[1.63,2.04]],"id":9624350}],"con":true,"img":false}]}
{"op":"mcm","clk":"1362022269","pt":1588422773147,"mc":[{"id":"1.170370557","rc":[{"atb":[[2.24,0]],"id":9622734}],"con":true,"img":false}]}
{"op":"mcm","clk":"1362022270","pt":1588422773248,"mc":[{"id":"1.170370557","rc":[{"atb":[[2.22,39.99]],"id":9622734}],"con":true,"img":false}]}
{"op":"mcm","clk":"1362022314","pt":1588422777562,"mc":[{"id":"1.170370557","rc":[{"atb":[[2.22,0]],"id":9622734}],"con":true,"img":false}]}
{"op":"mcm","clk":"1362022315","pt":1588422777664,"mc":[{"id":"1.170370557","rc":[{"atb":[[2.24,39.99]],"id":9622734}],"con":true,"img":false}]}
{"op":"mcm","clk":"1362022317","pt":1588422777825,"mc":[{"id":"1.170370557","rc":[{"atb":[[2.6,0]],"id":9622734},{"atl":[[2.76,0]],"id":9622734},{"atb":[[1.56,0]],"id":9624350},{"atl":[[1.63,0]],"id":9624350}],"con":true,"img":false}]}
{"op":"mcm","clk":"1362022319","pt":1588422778031,"mc":[{"id":"1.170370557","rc":[{"atb":[[2.6,2.04]],"id":9622734},{"atl":[[2.76,2.02]],"id":9622734},{"atb":[[1.56,2.08]],"id":9624350},{"atl":[[1.63,2.04]],"id":9624350}],"con":true,"img":false}]}
{"op":"mcm","clk":"1362022360","pt":1588422782355,"mc":[{"id":"1.170370557","rc":[{"atb":[[2.24,0]],"id":9622734}],"con":true,"img":false}]}
{"op":"mcm","clk":"1362022362","pt":1588422782462,"mc":[{"id":"1.170370557","rc":[{"atb":[[2.22,39.99]],"id":9622734}],"con":true,"img":false}]}
{"op":"mcm","clk":"1362022406","pt":1588422786535,"mc":[{"id":"1.170370557","rc":[{"atb":[[2.22,0]],"id":9622734}],"con":true,"img":false}]}
{"op":"mcm","clk":"1362022408","pt":1588422786638,"mc":[{"id":"1.170370557","rc":[{"atb":[[2.24,39.99]],"id":9622734}],"con":true,"img":false}]}
{"op":"mcm","clk":"1362022411","pt":1588422786846,"mc":[{"id":"1.170370557","rc":[{"atl":[[2.76,0]],"id":9622734},{"atb":[[1.56,0]],"id":9624350}],"con":true,"img":false}]}
{"op":"mcm","clk":"1362022413","pt":1588422786950,"mc":[{"id":"1.170370557","rc":[{"atb":[[2.6,0]],"id":9622734},{"atl":[[1.63,0]],"id":9624350}],"con":true,"img":false}]}
{"op":"mcm","clk":"1362022415","pt":1588422787049,"mc":[{"id":"1.170370557","rc":[{"atl":[[2.76,2.02]],"id":9622734},{"atb":[[1.56,2.02]],"id":9624350}],"con":true,"img":false}]}
{"op":"mcm","clk":"1362022416","pt":1588422787152,"mc":[{"id":"1.170370557","rc":[{"atb":[[2.6,2.04]],"id":9622734},{"atl":[[1.63,2.04]],"id":9624350}],"con":true,"img":false}]}
{"op":"mcm","clk":"1362022420","pt":1588422787356,"mc":[{"id":"1.170370557","rc":[{"atb":[[2.6,4.08]],"id":9622734},{"atl":[[1.63,4.08]],"id":9624350}],"con":true,"img":false}]}
{"op":"mcm","clk":"1362022454","pt":1588422791161,"mc":[{"id":"1.170370557","rc":[{"atb":[[2.24,0]],"id":9622734}],"con":true,"img":false}]}
{"op":"mcm","clk":"1362022456","pt":1588422791264,"mc":[{"id":"1.170370557","rc":[{"atb":[[2.22,39.99]],"id":9622734}],"con":true,"img":false}]}
{"op":"mcm","clk":"1362022503","pt":1588422795590,"mc":[{"id":"1.170370557","rc":[{"atb":[[2.22,0]],"id":9622734},{"atb":[[1.53,50.17]],"id":9624350}],"con":true,"img":false}]}
{"op":"mcm","clk":"1362022507","pt":1588422795957,"mc":[{"id":"1.170370557","rc":[{"atb":[[2.6,0]],"id":9622734},{"atl":[[2.76,0]],"id":9622734},{"atb":[[1.56,0]],"id":9624350},{"atl":[[1.63,0]],"id":9624350}],"con":true,"img":false}]}
{"op":"mcm","clk":"1362022509","pt":1588422796058,"mc":[{"id":"1.170370557","rc":[{"atb":[[1.53,90.17]],"id":9624350}],"con":true,"img":false}]}
{"op":"mcm","clk":"1362022511","pt":1588422796157,"mc":[{"id":"1.170370557","rc":[{"atb":[[2.6,2.04]],"id":9622734},{"atl":[[2.76,2.02]],"id":9622734},{"atb":[[1.56,2.04]],"id":9624350},{"atl":[[1.63,2.04]],"id":9624350}],"con":true,"img":false}]}
{"op":"mcm","clk":"1362022513","pt":1588422796264,"mc":[{"id":"1.170370557","rc":[{"atb":[[2.24,39.99]],"id":9622734}],"con":true,"img":false}]}
{"op":"mcm","clk":"1362022564","pt":1588422800792,"mc":[{"id":"1.170370557","rc":[{"atb":[[2.24,0]],"id":9622734}],"con":true,"img":false}]}
{"op":"mcm","clk":"1362022566","pt":1588422800850,"mc":[{"id":"1.170370557","rc":[{"atb":[[2.22,39.99]],"id":9622734}],"con":true,"img":false}]}
{"op":"mcm","clk":"1362022618","pt":1588422805590,"mc":[{"id":"1.170370557","rc":[{"atb":[[2.22,0]],"id":9622734}],"con":true,"img":false}]}
{"op":"mcm","clk":"1362022621","pt":1588422805688,"mc":[{"id":"1.170370557","rc":[{"atb":[[2.24,39.99]],"id":9622734}],"con":true,"img":false}]}
{"op":"mcm","clk":"1362022625","pt":1588422805894,"mc":[{"id":"1.170370557","rc":[{"atb":[[2.6,0]],"id":9622734},{"atl":[[2.76,0]],"id":9622734},{"atb":[[1.56,0]],"id":9624350},{"atl":[[1.63,0]],"id":9624350}],"con":true,"img":false}]}
{"op":"mcm","clk":"1362022629","pt":1588422806099,"mc":[{"id":"1.170370557","rc":[{"atb":[[2.6,2.04]],"id":9622734},{"atl":[[2.76,2.02]],"id":9622734},{"atb":[[1.56,2.08]],"id":9624350},{"atl":[[1.63,2.04]],"id":9624350}],"con":true,"img":false}]}
{"op":"mcm","clk":"1362022675","pt":1588422809964,"mc":[{"id":"1.170370557","rc":[{"atb":[[2.24,0]],"id":9622734}],"con":true,"img":false}]}
{"op":"mcm","clk":"1362022677","pt":1588422810068,"mc":[{"id":"1.170370557","rc":[{"atb":[[2.22,39.99]],"id":9622734}],"con":true,"img":false}]}
{"op":"mcm","clk":"1362022728","pt":1588422815474,"mc":[{"id":"1.170370557","rc":[{"atb":[[2.22,0]],"id":9622734}],"con":true,"img":false}]}
{"op":"mcm","clk":"1362022731","pt":1588422815579,"mc":[{"id":"1.170370557","rc":[{"atb":[[2.24,39.99]],"id":9622734}],"con":true,"img":false}]}
{"op":"mcm","clk":"1362022734","pt":1588422815787,"mc":[{"id":"1.170370557","rc":[{"atb":[[2.6,0]],"id":9622734},{"atl":[[2.76,0]],"id":9622734},{"atb":[[1.56,0]],"id":9624350},{"atl":[[1.63,0]],"id":9624350}],"con":true,"img":false}]}
{"op":"mcm","clk":"1362022736","pt":1588422815993,"mc":[{"id":"1.170370557","rc":[{"atb":[[2.6,2.04]],"id":9622734},{"atl":[[2.76,2.02]],"id":9622734},{"atb":[[1.56,2.06]],"id":9624350},{"atl":[[1.63,2.04]],"id":9624350}],"con":true,"img":false}]}
{"op":"mcm","clk":"1362022777","pt":1588422819811,"mc":[{"id":"1.170370557","rc":[{"atb":[[2.24,0]],"id":9622734}],"con":true,"img":false}]}
{"op":"mcm","clk":"1362022778","pt":1588422819914,"mc":[{"id":"1.170370557","rc":[{"atb":[[2.22,39.99]],"id":9622734}],"con":true,"img":false}]}
{"op":"mcm","clk":"1362022814","pt":1588422824093,"mc":[{"id":"1.170370557","rc":[{"atb":[[2.22,0]],"id":9622734}],"con":true,"img":false}]}
{"op":"mcm","clk":"1362022816","pt":1588422824193,"mc":[{"id":"1.170370557","rc":[{"atb":[[2.24,39.99]],"id":9622734}],"con":true,"img":false}]}
{"op":"mcm","clk":"1362022821","pt":1588422824400,"mc":[{"id":"1.170370557","rc":[{"atb":[[2.6,0]],"id":9622734},{"atl":[[2.76,0]],"id":9622734},{"atb":[[1.56,0]],"id":9624350},{"atl":[[1.63,0]],"id":9624350}],"con":true,"img":false}]}
{"op":"mcm","clk":"1362022824","pt":1588422824606,"mc":[{"id":"1.170370557","rc":[{"atb":[[2.6,2.04]],"id":9622734},{"atl":[[2.76,2.02]],"id":9622734},{"atb":[[1.56,2.08]],"id":9624350},{"atl":[[1.63,2.04]],"id":9624350}],"con":true,"img":false}]}
{"op":"mcm","clk":"1362022867","pt":1588422828387,"mc":[{"id":"1.170370557","rc":[{"atb":[[2.24,0]],"id":9622734}],"con":true,"img":false}]}
{"op":"mcm","clk":"1362022868","pt":1588422828490,"mc":[{"id":"1.170370557","rc":[{"atb":[[2.22,39.99]],"id":9622734}],"con":true,"img":false}]}
{"op":"mcm","clk":"1362022913","pt":1588422832820,"mc":[{"id":"1.170370557","rc":[{"atb":[[2.22,0]],"id":9622734}],"con":true,"img":false}]}
{"op":"mcm","clk":"1362022914","pt":1588422832924,"mc":[{"id":"1.170370557","rc":[{"atb":[[2.24,39.99]],"id":9622734}],"con":true,"img":false}]}
{"op":"mcm","clk":"1362022915","pt":1588422833127,"mc":[{"id":"1.170370557","rc":[{"atb":[[2.6,0]],"id":9622734},{"atl":[[2.76,0]],"id":9622734},{"atb":[[1.56,0]],"id":9624350},{"atl":[[1.63,0]],"id":9624350}],"con":true,"img":false}]}
{"op":"mcm","clk":"1362022917","pt":1588422833285,"mc":[{"id":"1.170370557","rc":[{"atb":[[2.6,2]],"id":9622734},{"atl":[[2.76,2.02]],"id":9622734},{"atb":[[1.56,2.08]],"id":9624350},{"atl":[[1.63,2.04]],"id":9624350}],"con":true,"img":false}]}
{"op":"mcm","clk":"1362022956","pt":1588422837406,"mc":[{"id":"1.170370557","rc":[{"atb":[[2.24,0]],"id":9622734}],"con":true,"img":false}]}
{"op":"mcm","clk":"1362022958","pt":1588422837509,"mc":[{"id":"1.170370557","rc":[{"atb":[[2.22,39.99]],"id":9622734}],"con":true,"img":false}]}
{"op":"mcm","clk":"1362023005","pt":1588422841796,"mc":[{"id":"1.170370557","rc":[{"atb":[[2.22,0]],"id":9622734}],"con":true,"img":false}]}
{"op":"mcm","clk":"1362023007","pt":1588422841901,"mc":[{"id":"1.170370557","rc":[{"atb":[[2.24,39.99]],"id":9622734}],"con":true,"img":false}]}
{"op":"mcm","clk":"1362023012","pt":1588422842111,"mc":[{"id":"1.170370557","rc":[{"atb":[[2.6,0]],"id":9622734},{"atl":[[2.76,0]],"id":9622734},{"atb":[[1.56,0]],"id":9624350},{"atl":[[1.63,0]],"id":9624350}],"con":true,"img":false}]}
{"op":"mcm","clk":"1362023015","pt":1588422842320,"mc":[{"id":"1.170370557","rc":[{"atb":[[2.6,2.02]],"id":9622734},{"atl":[[2.76,2.02]],"id":9622734},{"atb":[[1.56,2.08]],"id":9624350},{"atl":[[1.63,2.04]],"id":9624350}],"con":true,"img":false}]}
{"op":"mcm","clk":"1362023059","pt":1588422846134,"mc":[{"id":"1.170370557","rc":[{"atb":[[2.24,0]],"id":9622734}],"con":true,"img":false}]}
{"op":"mcm","clk":"1362023060","pt":1588422846235,"mc":[{"id":"1.170370557","rc":[{"atb":[[2.22,39.99]],"id":9622734}],"con":true,"img":false}]}
{"op":"mcm","clk":"1362023114","pt":1588422850616,"mc":[{"id":"1.170370557","rc":[{"atb":[[2.22,0]],"id":9622734}],"con":true,"img":false}]}
{"op":"mcm","clk":"1362023117","pt":1588422850722,"mc":[{"id":"1.170370557","rc":[{"atb":[[2.24,39.99]],"id":9622734}],"con":true,"img":false}]}
{"op":"mcm","clk":"1362023120","pt":1588422850928,"mc":[{"id":"1.170370557","rc":[{"atb":[[2.6,0]],"id":9622734},{"atl":[[2.76,0]],"id":9622734},{"atb":[[1.56,0]],"id":9624350},{"atl":[[1.63,0]],"id":9624350}],"con":true,"img":false}]}
{"op":"mcm","clk":"1362023123","pt":1588422851134,"mc":[{"id":"1.170370557","rc":[{"atb":[[2.6,2],[2.24,0]],"id":9622734},{"atl":[[2.76,2.02]],"id":9622734},{"atb":[[1.56,2.08]],"id":9624350},{"atl":[[1.63,2.04]],"id":9624350}],"con":true,"img":false}]}
{"op":"mcm","clk":"1362023126","pt":1588422851544,"mc":[{"id":"1.170370557","rc":[{"atb":[[1.53,50.17]],"id":9624350}],"con":true,"img":false}]}
{"op":"mcm","clk":"1362023127","pt":1588422851647,"mc":[{"id":"1.170370557","rc":[{"atb":[[1.57,42.05]],"id":9624350}],"con":true,"img":false}]}
{"op":"mcm","clk":"1362023177","pt":1588422856226,"mc":[{"id":"1.170370557","rc":[{"atb":[[1.57,2.06]],"id":9624350}],"con":true,"img":false}]}
{"op":"mcm","clk":"1362023209","pt":1588422859314,"mc":[{"id":"1.170370557","rc":[{"atb":[[1.48,39.99]],"id":9624350}],"con":true,"img":false}]}
{"op":"mcm","clk":"1362023213","pt":1588422859559,"mc":[{"id":"1.170370557","rc":[{"atb":[[2.14,39.99]],"id":9622734}],"con":true,"img":false}]}
{"op":"mcm","clk":"1362023216","pt":1588422859620,"mc":[{"id":"1.170370557","rc":[{"atb":[[2.6,0]],"id":9622734},{"atl":[[2.76,0]],"id":9622734},{"atb":[[1.56,0]],"id":9624350},{"atl":[[1.63,0]],"id":9624350}],"con":true,"img":false}]}
{"op":"mcm","clk":"1362023219","pt":1588422859827,"mc":[{"id":"1.170370557","rc":[{"atb":[[2.6,2.04]],"id":9622734},{"atl":[[2.76,2.02]],"id":9622734},{"atb":[[1.56,2.08]],"id":9624350},{"atl":[[1.63,2]],"id":9624350}],"con":true,"img":false}]}
{"op":"mcm","clk":"1362023261","pt":1588422863944,"mc":[{"id":"1.170370557","rc":[{"atb":[[1.48,0]],"id":9624350}],"con":true,"img":false}]}
{"op":"mcm","clk":"1362023262","pt":1588422864047,"mc":[{"id":"1.170370557","rc":[{"atb":[[1.57,42.05]],"id":9624350}],"con":true,"img":false}]}
{"op":"mcm","clk":"1362023750","pt":1588422917287,"mc":[{"id":"1.170370557","rc":[{"atb":[[2.14,0]],"id":9622734},{"atb":[[1.57,2.06]],"id":9624350}],"con":true,"img":false}]}
{"op":"mcm","clk":"1362023755","pt":1588422917593,"mc":[{"id":"1.170370557","rc":[{"atb":[[2.6,0]],"id":9622734},{"atl":[[2.76,0]],"id":9622734},{"atb":[[1.56,0]],"id":9624350},{"atl":[[1.63,0]],"id":9624350}],"con":true,"img":false}]}
{"op":"mcm","clk":"1362023757","pt":1588422917798,"mc":[{"id":"1.170370557","rc":[{"atb":[[2.6,2.04]],"id":9622734},{"atl":[[2.76,2.02]],"id":9622734},{"atb":[[1.56,2.08]],"id":9624350},{"atl":[[1.63,2.04]],"id":9624350}],"con":true,"img":false}]}
{"op":"mcm","clk":"1362023816","pt":1588422923507,"mc":[{"id":"1.170370557","rc":[{"atb":[[1.48,39.99]],"id":9624350}],"con":true,"img":false}]}
{"op":"mcm","clk":"1362023819","pt":1588422923712,"mc":[{"id":"1.170370557","rc":[{"atb":[[2.14,39.99]],"id":9622734}],"con":true,"img":false}]}
{"op":"mcm","clk":"1362023820","pt":1588422923817,"mc":[{"id":"1.170370557","rc":[{"atb":[[2.6,0]],"id":9622734},{"atl":[[2.76,0]],"id":9622734},{"atb":[[1.56,0]],"id":9624350},{"atl":[[1.63,0]],"id":9624350}],"con":true,"img":false}]}
{"op":"mcm","clk":"1362023821","pt":1588422924023,"mc":[{"id":"1.170370557","rc":[{"atb":[[2.6,2]],"id":9622734},{"atl":[[2.76,2.02]],"id":9622734},{"atb":[[1.56,2.08]],"id":9624350},{"atl":[[1.63,2.04]],"id":9624350}],"con":true,"img":false}]}
{"op":"mcm","clk":"1362023856","pt":1588422928493,"mc":[{"id":"1.170370557","rc":[{"atb":[[1.48,0]],"id":9624350}],"con":true,"img":false}]}
{"op":"mcm","clk":"1362023857","pt":1588422928596,"mc":[{"id":"1.170370557","rc":[{"atb":[[1.57,42.05]],"id":9624350}],"con":true,"img":false}]}
{"op":"mcm","clk":"1362024337","pt":1588422977882,"mc":[{"id":"1.170370557","rc":[{"atb":[[2.14,0]],"id":9622734},{"atb":[[1.57,2.06]],"id":9624350}],"con":true,"img":false}]}
{"op":"mcm","clk":"1362024346","pt":1588422978195,"mc":[{"id":"1.170370557","rc":[{"atb":[[2.6,0]],"id":9622734},{"atb":[[1.56,0]],"id":9624350},{"atl":[[1.63,0]],"id":9624350}],"con":true,"img":false}]}
{"op":"mcm","clk":"1362024350","pt":1588422978400,"mc":[{"id":"1.170370557","rc":[{"atl":[[2.76,0]],"id":9622734}],"con":true,"img":false}]}
