{"op":"mcm","clk":"1362094001","pt":1588427080049,"mc":[{"id":"1.170370557","rc":[{"atl":[[1.73,170]],"id":9624350}],"con":true,"img":false}]}
{"op":"mcm","clk":"1362094058","pt":1588427083162,"mc":[{"id":"1.170370557","rc":[{"trd":[[1.52,670.34]],"ltp":1.52,"tv":670.34,"id":9624350},{"atb":[[1.52,45.95]],"id":9624350}],"con":true,"img":false}]}
{"op":"mcm","clk":"1362094068","pt":1588427083570,"mc":[{"id":"1.170370557","rc":[{"trd":[[1.52,762.26]],"ltp":1.52,"tv":762.26,"id":9624350},{"atb":[[1.52,0]],"id":9624350},{"atl":[[1.52,154.04]],"id":9624350}],"con":true,"img":false}]}
{"op":"mcm","clk":"1362094073","pt":1588427083874,"mc":[{"id":"1.170370557","rc":[{"atb":[[2.82,14.6]],"id":9622734},{"atb":[[1.46,57.81]],"id":9624350}],"con":true,"img":false}]}
{"op":"mcm","clk":"1362094077","pt":1588427084078,"mc":[{"id":"1.170370557","rc":[{"atb":[[1.48,0],[1.47,0]],"id":9624350}],"con":true,"img":false}]}
{"op":"mcm","clk":"1362094128","pt":1588427087546,"mc":[{"id":"1.170370557","rc":[{"atl":[[1.54,177.3]],"id":9624350}],"con":true,"img":false}]}
{"op":"mcm","clk":"1362094140","pt":1588427088361,"mc":[{"id":"1.170370557","rc":[{"atl":[[1.54,354.6]],"id":9624350}],"con":true,"img":false}]}
{"op":"mcm","clk":"1362094153","pt":1588427089077,"mc":[{"id":"1.170370557","rc":[{"atl":[[1.55,0]],"id":9624350}],"con":true,"img":false}]}
{"op":"mcm","clk":"1362094175","pt":1588427090353,"mc":[{"id":"1.170370557","rc":[{"trd":[[2.92,13.61]],"ltp":2.92,"tv":13.61,"id":9622734},{"trd":[[1.52,784.45]],"ltp":1.52,"tv":784.45,"id":9624350},{"atb":[[1.31,0]],"id":9624350},{"atl":[[1.52,131.85]],"id":9624350}],"con":true,"img":false}]}
{"op":"mcm","clk":"1362094176","pt":1588427090455,"mc":[{"id":"1.170370557","rc":[{"trd":[[2.92,76.42]],"ltp":2.92,"tv":76.42,"id":9622734},{"trd":[[1.52,905.11]],"ltp":1.52,"tv":905.11,"id":9624350},{"atl":[[1.52,11.19]],"id":9624350}],"con":true,"img":false}]}
{"op":"mcm","clk":"1362094190","pt":1588427090969,"mc":[{"id":"1.170370557","rc":[{"atb":[[2.82,0],[2.76,15.11]],"id":9622734},{"atb":[[1.46,0],[1.45,236.4]],"id":9624350}],"con":true,"img":false}]}
{"op":"mcm","clk":"1362094294","pt":1588427095052,"mc":[{"id":"1.170370557","rc":[{"trd":[[1.52,913.97]],"ltp":1.52,"tv":913.97,"id":9624350},{"atl":[[1.52,6.76]],"id":9624350}],"con":true,"img":false}]}
{"op":"mcm","clk":"1362094311","pt":1588427095666,"mc":[{"id":"1.170370557","rc":[{"atl":[[1.59,0]],"id":9624350}],"con":true,"img":false}]}
{"op":"mcm","clk":"1362094334","pt":1588427096686,"mc":[{"id":"1.170370557","rc":[{"atl":[[3,0.28]],"id":9622734}],"con":true,"img":false}]}
{"op":"mcm","clk":"1362094338","pt":1588427096788,"mc":[{"id":"1.170370557","rc":[{"trd":[[2.92,79.93]],"ltp":2.92,"tv":79.93,"id":9622734},{"atl":[[2.9,577.21]],"id":9622734},{"trd":[[1.52,920.73]],"ltp":1.52,"tv":920.73,"id":9624350},{"atl":[[1.52,0]],"id":9624350}],"con":true,"img":false}]}
{"op":"mcm","clk":"1362094362","pt":1588427097964,"mc":[{"id":"1.170370557","rc":[{"atb":[[2.76,0],[2.74,15.28]],"id":9622734},{"atb":[[1.48,55.4]],"id":9624350}],"con":true,"img":false}]}
{"op":"mcm","clk":"1362094404","pt":1588427100665,"mc":[{"id":"1.170370557","rc":[{"trd":[[2.9,2.72]],"ltp":2.9,"tv":2.72,"id":9622734},{"atl":[[2.9,576.87]],"id":9622734}],"con":true,"img":false}]}
{"op":"mcm","clk":"1362094429","pt":1588427101894,"mc":[{"id":"1.170370557","rc":[{"trd":[[2.9,7.31]],"ltp":2.9,"tv":7.31,"id":9622734},{"atl":[[2.9,572.28]],"id":9622734},{"trd":[[1.52,929.49]],"ltp":1.52,"tv":929.49,"id":9624350}],"con":true,"img":false}]}
{"op":"mcm","clk":"1362094568","pt":1588427108260,"mc":[{"id":"1.170370557","rc":[{"atl":[[1.55,177.3]],"id":9624350}],"con":true,"img":false}]}
{"op":"mcm","clk":"1362094579","pt":1588427108871,"mc":[{"id":"1.170370557","rc":[{"atl":[[1.54,0]],"id":9624350}],"con":true,"img":false}]}
{"op":"mcm","clk":"1362094589","pt":1588427109585,"mc":[{"id":"1.170370557","rc":[{"atl":[[1.55,354.6]],"id":9624350}],"con":true,"img":false}]}
{"op":"mcm","clk":"1362094598","pt":1588427109991,"mc":[{"id":"1.170370557","rc":[{"atb":[[2.74,0]],"id":9622734}],"con":true,"img":false}]}
{"op":"mcm","clk":"1362094744","pt":1588427118109,"mc":[{"id":"1.170370557","rc":[{"atb":[[1.53,100]],"id":9624350}],"con":true,"img":false}]}
{"op":"mcm","clk":"1362094893","pt":1588427125615,"mc":[{"id":"1.170370557","rc":[{"atb":[[1.53,122]],"id":9624350}],"con":true,"img":false}]}
{"op":"mcm","clk":"1362094903","pt":1588427126074,"mc":[{"id":"1.170370557","rc":[{"atl":[[1.56,0]],"id":9624350}],"con":true,"img":false}]}
{"op":"mcm","clk":"1362094908","pt":1588427126279,"mc":[{"id":"1.170370557","rc":[{"trd":[[1.53,1596.39]],"ltp":1.53,"tv":1596.39,"id":9624350},{"atb":[[1.53,110.29]],"id":9624350}],"con":true,"img":false}]}
{"op":"mcm","clk":"1362094918","pt":1588427126891,"mc":[{"id":"1.170370557","rc":[{"atl":[[1000,3.49]],"id":9624350}],"con":true,"img":false}]}
{"op":"mcm","clk":"1362094965","pt":1588427129802,"mc":[{"id":"1.170370557","rc":[{"atb":[[1.26,0]],"id":9624350}],"con":true,"img":false}]}
{"op":"mcm","clk":"1362095078","pt":1588427137919,"mc":[{"id":"1.170370557","rc":[{"trd":[[1.55,1000.65]],"ltp":1.55,"tv":1000.65,"id":9624350},{"atl":[[1.55,352.98]],"id":9624350}],"con":true,"img":false}]}
{"op":"mcm","clk":"1362095091","pt":1588427139040,"mc":[{"id":"1.170370557","rc":[{"trd":[[2.9,80.54]],"ltp":2.9,"tv":80.54,"id":9622734},{"atl":[[2.9,499.06]],"id":9622734},{"trd":[[1.52,1069.2],[1.53,1816.97]],"ltp":1.52,"tv":2886.17,"id":9624350},{"atb":[[1.53,0]],"id":9624350}],"con":true,"img":false}]}
{"op":"mcm","clk":"1362095131","pt":1588427141537,"mc":[{"id":"1.170370557","rc":[{"atl":[[1000,1.45]],"id":9624350}],"con":true,"img":false}]}
{"op":"mcm","clk":"1362095134","pt":1588427141640,"mc":[{"id":"1.170370557","rc":[{"atl":[[1.53,0.58]],"id":9624350}],"con":true,"img":false}]}
{"op":"mcm","clk":"1362095152","pt":1588427143009,"mc":[{"id":"1.170370557","marketDefinition":{"bspMarket":false,"turnInPlayEnabled":true,"persistenceEnabled":true,"marketBaseRate":5.0,"eventId":"29788106","eventTypeId":"2","numberOfWinners":1,"bettingType":"ODDS","marketType":"MATCH_ODDS","marketTime":"2020-05-02T13:35:00.000Z","suspendTime":"2020-05-02T13:35:00.000Z","bspReconciled":false,"complete":true,"inPlay":false,"crossMatching":true,"runnersVoidable":false,"numberOfActiveRunners":2,"betDelay":0,"status":"SUSPENDED","runners":[{"status":"ACTIVE","sortPriority":1,"id":9624350,"name":"Y Hanfmann"},{"status":"ACTIVE","sortPriority":2,"id":9622734,"name":"D Brown"}],"regulators":["MR_INT"],"countryCode":"GB","discountAllowed":true,"timezone":"GMT","openDate":"2020-05-02T13:35:00.000Z","version":3237570454,"name":"Match Odds","eventName":"Y Hanfmann v D Brown"},"rc":[],"con":true,"img":false}]}
{"op":"mcm","clk":"1362095155","pt":1588427143228,"mc":[{"id":"1.170370557","marketDefinition":{"bspMarket":false,"turnInPlayEnabled":true,"persistenceEnabled":true,"marketBaseRate":5.0,"eventId":"29788106","eventTypeId":"2","numberOfWinners":1,"bettingType":"ODDS","marketType":"MATCH_ODDS","marketTime":"2020-05-02T13:35:00.000Z","suspendTime":"2020-05-02T13:35:00.000Z","bspReconciled":false,"complete":true,"inPlay":true,"crossMatching":true,"runnersVoidable":false,"numberOfActiveRunners":2,"betDelay":5,"status":"OPEN","runners":[{"status":"ACTIVE","sortPriority":1,"id":9624350,"name":"Y Hanfmann"},{"status":"ACTIVE","sortPriority":2,"id":9622734,"name":"D Brown"}],"regulators":["MR_INT"],"countryCode":"GB","discountAllowed":true,"timezone":"GMT","openDate":"2020-05-02T13:35:00.000Z","version":3237570460,"name":"Match Odds","eventName":"Y Hanfmann v D Brown"},"rc":[],"con":true,"img":false},{"id":"1.170370557","rc":[{"atb":[[2.72,0],[1.89,0],[2.64,0],[2.26,0],[2.62,0],[2.24,0],[1.4,0],[2.02,0],[1.25,319.94],[1.02,1181.95],[1.9,0],[1.42,0]],"id":9622734},{"atl":[[2.9,0],[990,0],[1000,0]],"id":9622734},{"atb":[[1.45,0],[1.43,0],[1.1,1199.8],[1.48,0],[1.35,0],[1.41,0],[1.27,0],[1.02,1378.75],[1.3,0],[1.29,0]],"id":9624350},{"atl":[[1.73,0],[1.6,0],[1.62,0],[2.84,0],[1.53,0],[990,0],[1000,0],[2.24,0],[1.63,0],[1.55,0]],"id":9624350}],"con":true,"img":false}]}
{"op":"mcm","clk":"1362095228","pt":1588427149017,"mc":[{"id":"1.170370557","marketDefinition":{"bspMarket":false,"turnInPlayEnabled":true,"persistenceEnabled":true,"marketBaseRate":5.0,"eventId":"29788106","eventTypeId":"2","numberOfWinners":1,"bettingType":"ODDS","marketType":"MATCH_ODDS","marketTime":"2020-05-02T13:45:47.000Z","suspendTime":"2020-05-02T13:45:47.000Z","bspReconciled":false,"complete":true,"inPlay":true,"crossMatching":true,"runnersVoidable":false,"numberOfActiveRunners":2,"betDelay":5,"status":"OPEN","runners":[{"status":"ACTIVE","sortPriority":1,"id":9624350,"name":"Y Hanfmann"},{"status":"ACTIVE","sortPriority":2,"id":9622734,"name":"D Brown"}],"regulators":["MR_INT"],"countryCode":"GB","discountAllowed":true,"timezone":"GMT","openDate":"2020-05-02T13:35:00.000Z","version":3237570466,"name":"Match Odds","eventName":"Y Hanfmann v D Brown"},"rc":[],"con":true,"img":false}]}
{"op":"mcm","clk":"1362095245","pt":1588427150023,"mc":[{"id":"1.170370557","marketDefinition":{"bspMarket":false,"turnInPlayEnabled":true,"persistenceEnabled":true,"marketBaseRate":5.0,"eventId":"29788106","eventTypeId":"2","numberOfWinners":1,"bettingType":"ODDS","marketType":"MATCH_ODDS","marketTime":"2020-05-02T13:45:48.000Z","suspendTime":"2020-05-02T13:45:48.000Z","bspReconciled":false,"complete":true,"inPlay":true,"crossMatching":true,"runnersVoidable":false,"numberOfActiveRunners":2,"betDelay":5,"status":"OPEN","runners":[{"status":"ACTIVE","sortPriority":1,"id":9624350,"name":"Y Hanfmann"},{"status":"ACTIVE","sortPriority":2,"id":9622734,"name":"D Brown"}],"regulators":["MR_INT"],"countryCode":"GB","discountAllowed":true,"timezone":"GMT","openDate":"2020-05-02T13:35:00.000Z","version":3237570468,"name":"Match Odds","eventName":"Y Hanfmann v D Brown"},"rc":[],"con":true,"img":false}]}
{"op":"mcm","clk":"1362095265","pt":1588427151019,"mc":[{"id":"1.170370557","marketDefinition":{"bspMarket":false,"turnInPlayEnabled":true,"persistenceEnabled":true,"marketBaseRate":5.0,"eventId":"29788106","eventTypeId":"2","numberOfWinners":1,"bettingType":"ODDS","marketType":"MATCH_ODDS","marketTime":"2020-05-02T13:45:48.000Z","suspendTime":"2020-05-02T13:45:48.000Z","bspReconciled":false,"complete":true,"inPlay":true,"crossMatching":true,"runnersVoidable":false,"numberOfActiveRunners":2,"betDelay":5,"status":"OPEN","runners":[{"status":"ACTIVE","sortPriority":1,"id":9624350,"name":"Y Hanfmann"},{"status":"ACTIVE","sortPriority":2,"id":9622734,"name":"D Brown"}],"regulators":["MR_INT"],"countryCode":"GB","discountAllowed":true,"timezone":"GMT","openDate":"2020-05-02T13:45:47.000Z","version":3237570468,"name":"Match Odds","eventName":"Y Hanfmann v D Brown"},"rc":[],"con":true,"img":false}]}
{"op":"mcm","clk":"1362095360","pt":1588427155026,"mc":[{"id":"1.170370557","marketDefinition":{"bspMarket":false,"turnInPlayEnabled":true,"persistenceEnabled":true,"marketBaseRate":5.0,"eventId":"29788106","eventTypeId":"2","numberOfWinners":1,"bettingType":"ODDS","marketType":"MATCH_ODDS","marketTime":"2020-05-02T13:45:48.000Z","suspendTime":"2020-05-02T13:45:48.000Z","bspReconciled":false,"complete":true,"inPlay":true,"crossMatching":true,"runnersVoidable":false,"numberOfActiveRunners":2,"betDelay":5,"status":"OPEN","runners":[{"status":"ACTIVE","sortPriority":1,"id":9624350,"name":"Y Hanfmann"},{"status":"ACTIVE","sortPriority":2,"id":9622734,"name":"D Brown"}],"regulators":["MR_INT"],"countryCode":"GB","discountAllowed":true,"timezone":"GMT","openDate":"2020-05-02T13:45:48.000Z","version":3237570468,"name":"Match Odds","eventName":"Y Hanfmann v D Brown"},"rc":[],"con":true,"img":false}]}
{"op":"mcm","clk":"1362095365","pt":1588427155221,"mc":[{"id":"1.170370557","rc":[{"atl":[[1.65,4]],"id":9624350}],"con":true,"img":false}]}
{"op":"mcm","clk":"1362095441","pt":1588427158955,"mc":[{"id":"1.170370557","rc":[{"atl":[[1.65,4.86]],"id":9624350}],"con":true,"img":false}]}
{"op":"mcm","clk":"1362095531","pt":1588427163758,"mc":[{"id":"1.170370557","rc":[{"atb":[[1.25,479.92]],"id":9622734}],"con":true,"img":false}]}
{"op":"mcm","clk":"1362095536","pt":1588427164116,"mc":[{"id":"1.170370557","rc":[{"atl":[[1.66,134.45]],"id":9624350}],"con":true,"img":false}]}
{"op":"mcm","clk":"1362095552","pt":1588427165253,"mc":[{"id":"1.170370557","rc":[{"trd":[[2.96,90.45]],"ltp":2.96,"tv":90.45,"id":9622734},{"atl":[[2.96,12.66]],"id":9622734},{"trd":[[1.51,197.7]],"ltp":1.51,"tv":197.7,"id":9624350},{"atl":[[1.54,295.21]],"id":9624350}],"con":true,"img":false}]}
{"op":"mcm","clk":"1362095563","pt":1588427165858,"mc":[{"id":"1.170370557","rc":[{"trd":[[3,86.85],[2.96,103.11]],"ltp":3.0,"tv":189.95,"id":9622734},{"atl":[[3,0],[2.96,0]],"id":9622734},{"trd":[[1.5,1093.91],[1.51,222.52]],"ltp":1.5,"tv":1316.43,"id":9624350},{"atl":[[1.5,151.91]],"id":9624350}],"con":true,"img":false}]}
{"op":"mcm","clk":"1362095592","pt":1588427167342,"mc":[{"id":"1.170370557","rc":[{"atl":[[1.61,72.65]],"id":9624350}],"con":true,"img":false}]}
{"op":"mcm","clk":"1362095595","pt":1588427167445,"mc":[{"id":"1.170370557","rc":[{"atl":[[1.54,0]],"id":9624350}],"con":true,"img":false}]}
{"op":"mcm","clk":"1362095598","pt":1588427167548,"mc":[{"id":"1.170370557","rc":[{"atl":[[1.62,199.96]],"id":9624350}],"con":true,"img":false}]}
{"op":"mcm","clk":"1362095608","pt":1588427168162,"mc":[{"id":"1.170370557","rc":[{"atl":[[1.62,322.59]],"id":9624350}],"con":true,"img":false}]}
{"op":"mcm","clk":"1362095647","pt":1588427170770,"mc":[{"id":"1.170370557","rc":[{"trd":[[3,87.3]],"ltp":3.0,"tv":87.3,"id":9622734},{"trd":[[1.5,1094.82]],"ltp":1.5,"tv":1094.82,"id":9624350},{"atl":[[1.5,151.01]],"id":9624350}],"con":true,"img":false}]}
{"op":"mcm","clk":"1362095669","pt":1588427172561,"mc":[{"id":"1.170370557","rc":[{"atb":[[1.44,177.3]],"id":9624350}],"con":true,"img":false}]}
{"op":"mcm","clk":"1362095687","pt":1588427173942,"mc":[{"id":"1.170370557","rc":[{"atb":[[1.3,300]],"id":9624350}],"con":true,"img":false}]}
{"op":"mcm","clk":"1362095693","pt":1588427174248,"mc":[{"id":"1.170370557","rc":[{"atb":[[1.37,177.3]],"id":9624350}],"con":true,"img":false}]}
{"op":"mcm","clk":"1362095701","pt":1588427174860,"mc":[{"id":"1.170370557","rc":[{"atb":[[1.38,116.64]],"id":9624350}],"con":true,"img":false}]}
{"op":"mcm","clk":"1362095754","pt":1588427177668,"mc":[{"id":"1.170370557","rc":[{"atb":[[1.44,0]],"id":9624350}],"con":true,"img":false}]}
{"op":"mcm","clk":"1362095791","pt":1588427180172,"mc":[{"id":"1.170370557","rc":[{"atl":[[1.63,443.26],[1.66,39.45]],"id":9624350}],"con":true,"img":false}]}
{"op":"mcm","clk":"1362095816","pt":1588427181966,"mc":[{"id":"1.170370557","rc":[{"atb":[[1.33,69.97]],"id":9624350}],"con":true,"img":false}]}
{"op":"mcm","clk":"1362095819","pt":1588427182169,"mc":[{"id":"1.170370557","rc":[{"atb":[[1.33,513.23],[1.4,777]],"id":9624350}],"con":true,"img":false}]}
{"op":"mcm","clk":"1362095836","pt":1588427182942,"mc":[{"id":"1.170370557","rc":[{"atl":[[1.45,177.3]],"id":9624350}],"con":true,"img":false}]}
{"op":"mcm","clk":"1362095843","pt":1588427183450,"mc":[{"id":"1.170370557","rc":[{"atl":[[1.6,14.11]],"id":9624350}],"con":true,"img":false}]}
{"op":"mcm","clk":"1362095847","pt":1588427183652,"mc":[{"id":"1.170370557","rc":[{"atl":[[1.46,443.26]],"id":9624350}],"con":true,"img":false}]}
{"op":"mcm","clk":"1362095867","pt":1588427184677,"mc":[{"id":"1.170370557","rc":[{"atl":[[1.65,0.86]],"id":9624350}],"con":true,"img":false}]}
{"op":"mcm","clk":"1362095878","pt":1588427185244,"mc":[{"id":"1.170370557","rc":[{"atl":[[1.64,95]],"id":9624350}],"con":true,"img":false}]}
{"op":"mcm","clk":"1362095929","pt":1588427187237,"mc":[{"id":"1.170370557","rc":[{"atb":[[1.39,177.3]],"id":9624350}],"con":true,"img":false}]}
{"op":"mcm","clk":"1362095943","pt":1588427187752,"mc":[{"id":"1.170370557","rc":[{"trd":[[1.45,211.52]],"ltp":1.45,"tv":211.52,"id":9624350},{"atl":[[1.45,174.82]],"id":9624350}],"con":true,"img":false}]}
{"op":"mcm","clk":"1362095961","pt":1588427188562,"mc":[{"id":"1.170370557","rc":[{"atl":[[1.63,0]],"id":9624350}],"con":true,"img":false}]}
{"op":"mcm","clk":"1362095974","pt":1588427189174,"mc":[{"id":"1.170370557","rc":[{"trd":[[1.45,261.52]],"ltp":1.45,"tv":261.52,"id":9624350},{"atl":[[1.45,149.82]],"id":9624350}],"con":true,"img":false}]}
{"op":"mcm","clk":"1362095998","pt":1588427190454,"mc":[{"id":"1.170370557","rc":[{"atb":[[1.41,177.3]],"id":9624350}],"con":true,"img":false}]}
{"op":"mcm","clk":"1362096023","pt":1588427191473,"mc":[{"id":"1.170370557","rc":[{"trd":[[3.2,2.48]],"ltp":3.2,"tv":2.48,"id":9622734},{"trd":[[1.45,266.99]],"ltp":1.45,"tv":266.99,"id":9624350},{"atl":[[1.45,144.35]],"id":9624350}],"con":true,"img":false}]}
{"op":"mcm","clk":"1362096038","pt":1588427192085,"mc":[{"id":"1.170370557","rc":[{"atl":[[1.53,443.26]],"id":9624350}],"con":true,"img":false}]}
{"op":"mcm","clk":"1362096057","pt":1588427193162,"mc":[{"id":"1.170370557","rc":[{"atl":[[1000,1.45]],"id":9622734},{"atb":[[1.33,69.97]],"id":9624350},{"atl":[[1.65,0]],"id":9624350}],"con":true,"img":false}]}
{"op":"mcm","clk":"1362096065","pt":1588427193464,"mc":[{"id":"1.170370557","rc":[{"atl":[[1.7,2.47]],"id":9624350}],"con":true,"img":false}]}
{"op":"mcm","clk":"1362096108","pt":1588427195261,"mc":[{"id":"1.170370557","rc":[{"trd":[[1.4,1554],[1.41,354.61]],"ltp":1.4,"tv":1908.61,"id":9624350},{"atb":[[1.41,0],[1.4,0]],"id":9624350},{"atl":[[1.4,271.94]],"id":9624350}],"con":true,"img":false}]}
{"op":"mcm","clk":"1362096116","pt":1588427195461,"mc":[{"id":"1.170370557","rc":[{"trd":[[3.5,5.25]],"ltp":3.5,"tv":5.25,"id":9622734},{"trd":[[1.4,1567.13]],"ltp":1.4,"tv":1567.13,"id":9624350},{"atl":[[1.4,258.8]],"id":9624350}],"con":true,"img":false}]}
{"op":"mcm","clk":"1362096154","pt":1588427196890,"mc":[{"id":"1.170370557","rc":[{"atb":[[1.39,0]],"id":9624350}],"con":true,"img":false}]}
{"op":"mcm","clk":"1362096157","pt":1588427196991,"mc":[{"id":"1.170370557","rc":[{"atb":[[2.6,2.86]],"id":9622734}],"con":true,"img":false}]}
{"op":"mcm","clk":"1362096172","pt":1588427197658,"mc":[{"id":"1.170370557","rc":[{"atb":[[1.13,0.23]],"id":9624350}],"con":true,"img":false}]}
{"op":"mcm","clk":"1362096180","pt":1588427198075,"mc":[{"id":"1.170370557","rc":[{"atb":[[1.3,0]],"id":9624350}],"con":true,"img":false}]}
{"op":"mcm","clk":"1362096188","pt":1588427198268,"mc":[{"id":"1.170370557","rc":[{"atb":[[1.34,443.26]],"id":9624350}],"con":true,"img":false}]}
{"op":"mcm","clk":"1362096198","pt":1588427198879,"mc":[{"id":"1.170370557","rc":[{"atb":[[1.38,0]],"id":9624350},{"atl":[[1.61,0]],"id":9624350}],"con":true,"img":false}]}
{"op":"mcm","clk":"1362096201","pt":1588427198981,"mc":[{"id":"1.170370557","rc":[{"atb":[[1.39,69.97]],"id":9624350},{"atl":[[1.6,0]],"id":9624350}],"con":true,"img":false}]}
{"op":"mcm","clk":"1362096223","pt":1588427199955,"mc":[{"id":"1.170370557","rc":[{"atl":[[1.4,0]],"id":9624350}],"con":true,"img":false}]}
{"op":"mcm","clk":"1362096230","pt":1588427200167,"mc":[{"id":"1.170370557","rc":[{"atl":[[1.62,122.62]],"id":9624350}],"con":true,"img":false}]}
{"op":"mcm","clk":"1362096233","pt":1588427200262,"mc":[{"id":"1.170370557","rc":[{"atl":[[1.44,443.26]],"id":9624350}],"con":true,"img":false}]}
{"op":"mcm","clk":"1362096255","pt":1588427201179,"mc":[{"id":"1.170370557","rc":[{"atl":[[1000,3.45]],"id":9622734}],"con":true,"img":false}]}
{"op":"mcm","clk":"1362096260","pt":1588427201382,"mc":[{"id":"1.170370557","rc":[{"atl":[[1000,2.45]],"id":9622734}],"con":true,"img":false}]}
{"op":"mcm","clk":"1362096265","pt":1588427201586,"mc":[{"id":"1.170370557","rc":[{"atl":[[1000,1.45]],"id":9622734}],"con":true,"img":false}]}
{"op":"mcm","clk":"1362096269","pt":1588427201791,"mc":[{"id":"1.170370557","rc":[{"atl":[[1.62,0]],"id":9624350}],"con":true,"img":false}]}
{"op":"mcm","clk":"1362096325","pt":1588427204293,"mc":[{"id":"1.170370557","rc":[{"atl":[[1.44,643.26]],"id":9624350}],"con":true,"img":false}]}
{"op":"mcm","clk":"1362096332","pt":1588427204599,"mc":[{"id":"1.170370557","rc":[{"trd":[[1.44,407.99]],"ltp":1.44,"tv":407.99,"id":9624350},{"atl":[[1.44,439.26]],"id":9624350}],"con":true,"img":false}]}
{"op":"mcm","clk":"1362096337","pt":1588427204755,"mc":[{"id":"1.170370557","rc":[{"atl":[[1.43,177.3]],"id":9624350}],"con":true,"img":false}]}
{"op":"mcm","clk":"1362096342","pt":1588427205060,"mc":[{"id":"1.170370557","rc":[{"atb":[[1.36,123.12]],"id":9624350}],"con":true,"img":false}]}
{"op":"mcm","clk":"1362096373","pt":1588427206692,"mc":[{"id":"1.170370557","rc":[{"atl":[[3.4,1]],"id":9622734}],"con":true,"img":false}]}
{"op":"mcm","clk":"1362096381","pt":1588427206997,"mc":[{"id":"1.170370557","rc":[{"atl":[[1.42,177.3]],"id":9624350}],"con":true,"img":false}]}
{"op":"mcm","clk":"1362096386","pt":1588427207257,"mc":[{"id":"1.170370557","rc":[{"atb":[[1.38,116.64]],"id":9624350}],"con":true,"img":false}]}
{"op":"mcm","clk":"1362096394","pt":1588427207668,"mc":[{"id":"1.170370557","rc":[{"atb":[[1.35,200]],"id":9624350}],"con":true,"img":false}]}
{"op":"mcm","clk":"1362096396","pt":1588427207766,"mc":[{"id":"1.170370557","rc":[{"atb":[[1.38,416.64]],"id":9624350}],"con":true,"img":false}]}
{"op":"mcm","clk":"1362096402","pt":1588427208075,"mc":[{"id":"1.170370557","rc":[{"atb":[[1.39,0],[1.35,400]],"id":9624350}],"con":true,"img":false}]}
{"op":"mcm","clk":"1362096404","pt":1588427208174,"mc":[{"id":"1.170370557","rc":[{"atb":[[1.36,423.12]],"id":9624350}],"con":true,"img":false}]}
{"op":"mcm","clk":"1362096408","pt":1588427208380,"mc":[{"id":"1.170370557","rc":[{"atb":[[1.35,700]],"id":9624350}],"con":true,"img":false}]}
{"op":"mcm","clk":"1362096411","pt":1588427208585,"mc":[{"id":"1.170370557","rc":[{"atb":[[1.36,623.12]],"id":9624350}],"con":true,"img":false}]}
{"op":"mcm","clk":"1362096416","pt":1588427208988,"mc":[{"id":"1.170370557","rc":[{"atb":[[1.36,823.12]],"id":9624350}],"con":true,"img":false}]}
{"op":"mcm","clk":"1362096423","pt":1588427209600,"mc":[{"id":"1.170370557","rc":[{"atl":[[3.4,0]],"id":9622734}],"con":true,"img":false}]}
{"op":"mcm","clk":"1362096431","pt":1588427209961,"mc":[{"id":"1.170370557","rc":[{"atb":[[1.36,700]],"id":9624350}],"con":true,"img":false}]}
{"op":"mcm","clk":"1362096459","pt":1588427211293,"mc":[{"id":"1.170370557","rc":[{"atb":[[1.36,877.3]],"id":9624350}],"con":true,"img":false}]}
{"op":"mcm","clk":"1362096466","pt":1588427211697,"mc":[{"id":"1.170370557","rc":[{"trd":[[1.44,1286.52],[1.43,354.6],[1.42,354.6]],"ltp":1.44,"tv":1995.72,"id":9624350},{"atb":[[1.44,154.14],[1.41,208.34]],"id":9624350},{"atl":[[1.44,0],[1.43,0],[1.42,0]],"id":9624350}],"con":true,"img":false}]}
{"op":"mcm","clk":"1362096485","pt":1588427212772,"mc":[{"id":"1.170370557","rc":[{"atb":[[1.35,2078.54]],"id":9624350}],"con":true,"img":false}]}
{"op":"mcm","clk":"1362096496","pt":1588427213279,"mc":[{"id":"1.170370557","rc":[{"atb":[[1.38,486.61]],"id":9624350}],"con":true,"img":false}]}
{"op":"mcm","clk":"1362096505","pt":1588427213587,"mc":[{"id":"1.170370557","rc":[{"atl":[[1000,2.47]],"id":9622734}],"con":true,"img":false}]}
{"op":"mcm","clk":"1362096519","pt":1588427214403,"mc":[{"id":"1.170370557","rc":[{"atb":[[1.44,154.59]],"id":9624350}],"con":true,"img":false}]}
{"op":"mcm","clk":"1362096525","pt":1588427214606,"mc":[{"id":"1.170370557","rc":[{"trd":[[1.44,1291.67]],"ltp":1.44,"tv":1291.67,"id":9624350},{"atb":[[1.44,152.01]],"id":9624350}],"con":true,"img":false}]}
{"op":"mcm","clk":"1362096555","pt":1588427216295,"mc":[{"id":"1.170370557","rc":[{"atb":[[1.38,416.64]],"id":9624350}],"con":true,"img":false}]}
{"op":"mcm","clk":"1362096573","pt":1588427217878,"mc":[{"id":"1.170370557","rc":[{"atb":[[1.39,300]],"id":9624350}],"con":true,"img":false}]}
{"op":"mcm","clk":"1362096588","pt":1588427218492,"mc":[{"id":"1.170370557","rc":[{"atb":[[1.41,408.34]],"id":9624350}],"con":true,"img":false}]}
{"op":"mcm","clk":"1362096592","pt":1588427218696,"mc":[{"id":"1.170370557","rc":[{"trd":[[1.44,1595.7]],"ltp":1.44,"tv":1595.7,"id":9624350},{"atb":[[1.44,0]],"id":9624350},{"atl":[[1.44,158.27]],"id":9624350}],"con":true,"img":false}]}
{"op":"mcm","clk":"1362096606","pt":1588427219303,"mc":[{"id":"1.170370557","rc":[{"atb":[[1.41,608.34]],"id":9624350}],"con":true,"img":false}]}
{"op":"mcm","clk":"1362096626","pt":1588427220278,"mc":[{"id":"1.170370557","rc":[{"atl":[[1.44,335.57]],"id":9624350}],"con":true,"img":false}]}
{"op":"mcm","clk":"1362096636","pt":1588427220993,"mc":[{"id":"1.170370557","rc":[{"atl":[[1.44,510.75]],"id":9624350}],"con":true,"img":false}]}
{"op":"mcm","clk":"1362096652","pt":1588427222116,"mc":[{"id":"1.170370557","rc":[{"atl":[[1.44,518.19]],"id":9624350}],"con":true,"img":false}]}
{"op":"mcm","clk":"1362096664","pt":1588427222888,"mc":[{"id":"1.170370557","rc":[{"atl":[[1.44,520.81]],"id":9624350}],"con":true,"img":false}]}
{"op":"mcm","clk":"1362096671","pt":1588427223297,"mc":[{"id":"1.170370557","rc":[{"atb":[[1.42,177.3]],"id":9624350}],"con":true,"img":false}]}
{"op":"mcm","clk":"1362096676","pt":1588427223706,"mc":[{"id":"1.170370557","rc":[{"atb":[[1.41,408.34]],"id":9624350}],"con":true,"img":false}]}
{"op":"mcm","clk":"1362096678","pt":1588427223807,"mc":[{"id":"1.170370557","rc":[{"atl":[[1.44,521.01]],"id":9624350}],"con":true,"img":false}]}
{"op":"mcm","clk":"1362096684","pt":1588427224318,"mc":[{"id":"1.170370557","rc":[{"atb":[[1.42,377.3]],"id":9624350}],"con":true,"img":false}]}
{"op":"mcm","clk":"1362096687","pt":1588427224373,"mc":[{"id":"1.170370557","rc":[{"atb":[[1.42,554.6]],"id":9624350}],"con":true,"img":false}]}
{"op":"mcm","clk":"1362096709","pt":1588427225903,"mc":[{"id":"1.170370557","rc":[{"atb":[[1.38,116.64]],"id":9624350}],"con":true,"img":false}]}
{"op":"mcm","clk":"1362096718","pt":1588427226314,"mc":[{"id":"1.170370557","rc":[{"atb":[[1.36,577.3]],"id":9624350}],"con":true,"img":false}]}
{"op":"mcm","clk":"1362096729","pt":1588427227081,"mc":[{"id":"1.170370557","rc":[{"atb":[[1.35,1778.54]],"id":9624350}],"con":true,"img":false}]}
{"op":"mcm","clk":"1362096733","pt":1588427227288,"mc":[{"id":"1.170370557","rc":[{"atb":[[1.42,909.6]],"id":9624350}],"con":true,"img":false}]}
{"op":"mcm","clk":"1362096742","pt":1588427227897,"mc":[{"id":"1.170370557","rc":[{"atl":[[1.43,25.35]],"id":9624350}],"con":true,"img":false}]}
{"op":"mcm","clk":"1362096760","pt":1588427229016,"mc":[{"id":"1.170370557","rc":[{"trd":[[1.43,356.96]],"ltp":1.43,"tv":356.96,"id":9624350},{"atl":[[1.43,24.17]],"id":9624350}],"con":true,"img":false}]}
{"op":"mcm","clk":"1362096770","pt":1588427229784,"mc":[{"id":"1.170370557","rc":[{"trd":[[1.43,405.3]],"ltp":1.43,"tv":405.3,"id":9624350},{"atb":[[1.43,175.83]],"id":9624350},{"atl":[[1.43,0]],"id":9624350}],"con":true,"img":false}]}
{"op":"mcm","clk":"1362096783","pt":1588427230499,"mc":[{"id":"1.170370557","rc":[{"atb":[[1.41,208.34]],"id":9624350}],"con":true,"img":false}]}
{"op":"mcm","clk":"1362096789","pt":1588427230803,"mc":[{"id":"1.170370557","rc":[{"atb":[[1.43,273.34]],"id":9624350},{"atl":[[1.44,343.7]],"id":9624350}],"con":true,"img":false}]}
{"op":"mcm","clk":"1362096802","pt":1588427231819,"mc":[{"id":"1.170370557","rc":[{"atb":[[1.4,177.3]],"id":9624350}],"con":true,"img":false}]}
{"op":"mcm","clk":"1362096815","pt":1588427232691,"mc":[{"id":"1.170370557","rc":[{"trd":[[3.25,2.18]],"ltp":3.25,"tv":2.18,"id":9622734},{"trd":[[1.44,1600.63]],"ltp":1.44,"tv":1600.63,"id":9624350},{"atl":[[1.44,338.77]],"id":9624350}],"con":true,"img":false}]}
{"op":"mcm","clk":"1362096826","pt":1588427233607,"mc":[{"id":"1.170370557","rc":[{"atb":[[1.41,0]],"id":9624350},{"atl":[[1.44,185.43]],"id":9624350}],"con":true,"img":false}]}
{"op":"mcm","clk":"1362096834","pt":1588427234115,"mc":[{"id":"1.170370557","rc":[{"trd":[[3.35,5.57]],"ltp":3.35,"tv":5.57,"id":9622734},{"trd":[[1.43,418.35]],"ltp":1.43,"tv":418.35,"id":9624350},{"atb":[[1.43,260.29]],"id":9624350}],"con":true,"img":false}]}
{"op":"mcm","clk":"1362096837","pt":1588427234217,"mc":[{"id":"1.170370557","rc":[{"atb":[[1.39,0]],"id":9624350}],"con":true,"img":false}]}
{"op":"mcm","clk":"1362096842","pt":1588427234521,"mc":[{"id":"1.170370557","rc":[{"atb":[[1.37,0]],"id":9624350}],"con":true,"img":false}]}
{"op":"mcm","clk":"1362096846","pt":1588427234826,"mc":[{"id":"1.170370557","rc":[{"atb":[[1.42,912.45]],"id":9624350}],"con":true,"img":false}]}
{"op":"mcm","clk":"1362096848","pt":1588427234928,"mc":[{"id":"1.170370557","rc":[{"atl":[[1.44,10.25]],"id":9624350}],"con":true,"img":false}]}
{"op":"mcm","clk":"1362096855","pt":1588427235288,"mc":[{"id":"1.170370557","rc":[{"trd":[[1.44,1621.16]],"ltp":1.44,"tv":1621.16,"id":9624350},{"atb":[[1.44,417.73]],"id":9624350},{"atl":[[1.44,0]],"id":9624350}],"con":true,"img":false}]}
{"op":"mcm","clk":"1362096866","pt":1588427235797,"mc":[{"id":"1.170370557","rc":[{"trd":[[1.44,1631.16]],"ltp":1.44,"tv":1631.16,"id":9624350},{"atb":[[1.44,412.73]],"id":9624350}],"con":true,"img":false}]}
{"op":"mcm","clk":"1362096871","pt":1588427236103,"mc":[{"id":"1.170370557","rc":[{"atb":[[1.33,0]],"id":9624350}],"con":true,"img":false}]}
{"op":"mcm","clk":"1362096876","pt":1588427236511,"mc":[{"id":"1.170370557","rc":[{"atb":[[1.42,712.45]],"id":9624350}],"con":true,"img":false}]}
{"op":"mcm","clk":"1362096890","pt":1588427237427,"mc":[{"id":"1.170370557","rc":[{"atb":[[1.38,0]],"id":9624350}],"con":true,"img":false}]}
{"op":"mcm","clk":"1362096892","pt":1588427237529,"mc":[{"id":"1.170370557","rc":[{"trd":[[1.44,1791.14]],"ltp":1.44,"tv":1791.14,"id":9624350},{"atb":[[1.44,332.74]],"id":9624350}],"con":true,"img":false}]}
{"op":"mcm","clk":"1362096901","pt":1588427237892,"mc":[{"id":"1.170370557","rc":[{"atb":[[1.43,348.95]],"id":9624350}],"con":true,"img":false}]}
{"op":"mcm","clk":"1362096908","pt":1588427238297,"mc":[{"id":"1.170370557","rc":[{"atb":[[1.44,335.09],[1.42,357.45]],"id":9624350}],"con":true,"img":false}]}
{"op":"mcm","clk":"1362096920","pt":1588427239414,"mc":[{"id":"1.170370557","rc":[{"atb":[[1.44,385.59]],"id":9624350}],"con":true,"img":false}]}
{"op":"mcm","clk":"1362096922","pt":1588427239517,"mc":[{"id":"1.170370557","rc":[{"atb":[[1.44,542.54]],"id":9624350}],"con":true,"img":false}]}
{"op":"mcm","clk":"1362096945","pt":1588427241201,"mc":[{"id":"1.170370557","rc":[{"atb":[[1.44,542.81]],"id":9624350}],"con":true,"img":false}]}
{"op":"mcm","clk":"1362096978","pt":1588427243399,"mc":[{"id":"1.170370557","rc":[{"atb":[[1.43,703.95]],"id":9624350},{"atl":[[1.46,0]],"id":9624350}],"con":true,"img":false}]}
{"op":"mcm","clk":"1362096991","pt":1588427244014,"mc":[{"id":"1.170370557","rc":[{"atb":[[1.44,540.45]],"id":9624350}],"con":true,"img":false}]}
{"op":"mcm","clk":"1362097000","pt":1588427244520,"mc":[{"id":"1.170370557","rc":[{"trd":[[1.45,444.3]],"ltp":1.45,"tv":444.3,"id":9624350},{"atl":[[1.45,55.7]],"id":9624350}],"con":true,"img":false}]}
{"op":"mcm","clk":"1362097008","pt":1588427245030,"mc":[{"id":"1.170370557","rc":[{"trd":[[1.45,555.7]],"ltp":1.45,"tv":555.7,"id":9624350},{"atb":[[1.45,32.95]],"id":9624350},{"atl":[[1.45,0]],"id":9624350}],"con":true,"img":false}]}
{"op":"mcm","clk":"1362097024","pt":1588427245796,"mc":[{"id":"1.170370557","rc":[{"atb":[[1.44,540.19]],"id":9624350}],"con":true,"img":false}]}
{"op":"mcm","clk":"1362097027","pt":1588427246009,"mc":[{"id":"1.170370557","rc":[{"atl":[[1.53,0]],"id":9624350}],"con":true,"img":false}]}
{"op":"mcm","clk":"1362097055","pt":1588427247639,"mc":[{"id":"1.170370557","rc":[{"trd":[[1.44,1823.98],[1.45,621.6]],"ltp":1.44,"tv":2445.58,"id":9624350},{"atb":[[1.44,523.77],[1.45,0]],"id":9624350}],"con":true,"img":false}]}
{"op":"mcm","clk":"1362097070","pt":1588427248509,"mc":[{"id":"1.170370557","rc":[{"atl":[[1.48,443.26]],"id":9624350}],"con":true,"img":false}]}
{"op":"mcm","clk":"1362097085","pt":1588427249529,"mc":[{"id":"1.170370557","rc":[{"atb":[[1.43,541.17],[1.35,0],[1.36,177.3]],"id":9624350}],"con":true,"img":false}]}
{"op":"mcm","clk":"1362097090","pt":1588427249832,"mc":[{"id":"1.170370557","rc":[{"atl":[[1.49,175]],"id":9624350}],"con":true,"img":false}]}
{"op":"mcm","clk":"1362097099","pt":1588427250138,"mc":[{"id":"1.170370557","rc":[{"atl":[[1.49,350]],"id":9624350}],"con":true,"img":false}]}
{"op":"mcm","clk":"1362097101","pt":1588427250240,"mc":[{"id":"1.170370557","rc":[{"atb":[[1.44,473.27]],"id":9624350}],"con":true,"img":false}]}
{"op":"mcm","clk":"1362097104","pt":1588427250342,"mc":[{"id":"1.170370557","rc":[{"trd":[[1.44,2063.94]],"ltp":1.44,"tv":2063.94,"id":9624350},{"atb":[[1.44,353.29]],"id":9624350}],"con":true,"img":false}]}
{"op":"mcm","clk":"1362097114","pt":1588427250803,"mc":[{"id":"1.170370557","rc":[{"atl":[[1.52,175]],"id":9624350}],"con":true,"img":false}]}
{"op":"mcm","clk":"1362097117","pt":1588427251007,"mc":[{"id":"1.170370557","rc":[{"trd":[[1.43,1500.69],[1.44,2770.52]],"ltp":1.43,"tv":4271.21,"id":9624350},{"atb":[[1.44,0],[1.43,0]],"id":9624350},{"atl":[[1.43,69.01]],"id":9624350}],"con":true,"img":false}]}
{"op":"mcm","clk":"1362097122","pt":1588427251158,"mc":[{"id":"1.170370557","rc":[{"atl":[[1.52,350]],"id":9624350}],"con":true,"img":false}]}
{"op":"mcm","clk":"1362097140","pt":1588427252027,"mc":[{"id":"1.170370557","rc":[{"atl":[[1.44,39.99]],"id":9624350}],"con":true,"img":false}]}
{"op":"mcm","clk":"1362097170","pt":1588427253812,"mc":[{"id":"1.170370557","rc":[{"atl":[[1.43,0]],"id":9624350}],"con":true,"img":false}]}
{"op":"mcm","clk":"1362097171","pt":1588427253913,"mc":[{"id":"1.170370557","rc":[{"atb":[[1.42,180.14]],"id":9624350}],"con":true,"img":false}]}
{"op":"mcm","clk":"1362097174","pt":1588427254015,"mc":[{"id":"1.170370557","rc":[{"atl":[[1.54,443.26]],"id":9624350}],"con":true,"img":false}]}
{"op":"mcm","clk":"1362097186","pt":1588427254729,"mc":[{"id":"1.170370557","rc":[{"trd":[[1.44,2850.5]],"ltp":1.44,"tv":2850.5,"id":9624350},{"atb":[[1.45,121.92]],"id":9624350},{"atl":[[1.44,0]],"id":9624350}],"con":true,"img":false}]}
{"op":"mcm","clk":"1362097195","pt":1588427255339,"mc":[{"id":"1.170370557","rc":[{"atb":[[1.46,50.5]],"id":9624350}],"con":true,"img":false}]}
{"op":"mcm","clk":"1362097209","pt":1588427256154,"mc":[{"id":"1.170370557","rc":[{"trd":[[1.48,193.73]],"ltp":1.48,"tv":193.73,"id":9624350},{"atl":[[1.48,442.99]],"id":9624350}],"con":true,"img":false}]}
{"op":"mcm","clk":"1362097228","pt":1588427256923,"mc":[{"id":"1.170370557","rc":[{"trd":[[1.46,205]],"ltp":1.46,"tv":205.0,"id":9624350},{"atb":[[1.46,0]],"id":9624350},{"atl":[[1.46,773.89]],"id":9624350}],"con":true,"img":false}]}
{"op":"mcm","clk":"1362097280","pt":1588427257436,"mc":[{"id":"1.170370557","rc":[{"trd":[[1.46,208.44]],"ltp":1.46,"tv":208.44,"id":9624350},{"atl":[[1.46,772.17]],"id":9624350}],"con":true,"img":false}]}
{"op":"mcm","clk":"1362097287","pt":1588427257943,"mc":[{"id":"1.170370557","rc":[{"atb":[[1.43,221.63]],"id":9624350}],"con":true,"img":false}]}
{"op":"mcm","clk":"1362097290","pt":1588427258249,"mc":[{"id":"1.170370557","rc":[{"atb":[[1.43,399.55]],"id":9624350}],"con":true,"img":false}]}
{"op":"mcm","clk":"1362097296","pt":1588427258657,"mc":[{"id":"1.170370557","rc":[{"atb":[[1.43,177.92]],"id":9624350}],"con":true,"img":false}]}
{"op":"mcm","clk":"1362097301","pt":1588427259119,"mc":[{"id":"1.170370557","rc":[{"atl":[[1.48,0]],"id":9624350}],"con":true,"img":false}]}
{"op":"mcm","clk":"1362097304","pt":1588427259320,"mc":[{"id":"1.170370557","rc":[{"atl":[[3.3,4]],"id":9622734}],"con":true,"img":false}]}
{"op":"mcm","clk":"1362097312","pt":1588427259936,"mc":[{"id":"1.170370557","rc":[{"atb":[[1.45,130.66]],"id":9624350}],"con":true,"img":false}]}
{"op":"mcm","clk":"1362097316","pt":1588427260242,"mc":[{"id":"1.170370557","rc":[{"atl":[[3.2,9.35]],"id":9622734}],"con":true,"img":false}]}
{"op":"mcm","clk":"1362097319","pt":1588427260445,"mc":[{"id":"1.170370557","rc":[{"atb":[[1.45,130.92]],"id":9624350}],"con":true,"img":false}]}
{"op":"mcm","clk":"1362097321","pt":1588427260547,"mc":[{"id":"1.170370557","rc":[{"atl":[[3.3,0]],"id":9622734}],"con":true,"img":false}]}
{"op":"mcm","clk":"1362097342","pt":1588427261830,"mc":[{"id":"1.170370557","rc":[{"trd":[[3.15,4]],"ltp":3.15,"tv":4.0,"id":9622734},{"trd":[[1.46,217.07]],"ltp":1.46,"tv":217.07,"id":9624350},{"atl":[[1.46,763.54]],"id":9624350}],"con":true,"img":false}]}
{"op":"mcm","clk":"1362097347","pt":1588427262239,"mc":[{"id":"1.170370557","rc":[{"atl":[[1.47,94.3]],"id":9624350}],"con":true,"img":false}]}
{"op":"mcm","clk":"1362097359","pt":1588427263051,"mc":[{"id":"1.170370557","rc":[{"atl":[[1.47,0]],"id":9624350}],"con":true,"img":false}]}
{"op":"mcm","clk":"1362097362","pt":1588427263256,"mc":[{"id":"1.170370557","rc":[{"trd":[[1.46,234.8]],"ltp":1.46,"tv":234.8,"id":9624350},{"atl":[[1.46,754.67]],"id":9624350}],"con":true,"img":false}]}
{"op":"mcm","clk":"1362097371","pt":1588427263820,"mc":[{"id":"1.170370557","rc":[{"atl":[[1.46,831.67]],"id":9624350}],"con":true,"img":false}]}
{"op":"mcm","clk":"1362097375","pt":1588427264025,"mc":[{"id":"1.170370557","rc":[{"atb":[[1.45,122.17]],"id":9624350}],"con":true,"img":false}]}
{"op":"mcm","clk":"1362097381","pt":1588427264434,"mc":[{"id":"1.170370557","rc":[{"atb":[[1.42,2.84]],"id":9624350}],"con":true,"img":false}]}
{"op":"mcm","clk":"1362097385","pt":1588427264743,"mc":[{"id":"1.170370557","rc":[{"trd":[[1.46,286.51]],"ltp":1.46,"tv":286.51,"id":9624350},{"atl":[[1.46,805.82]],"id":9624350}],"con":true,"img":false}]}
{"op":"mcm","clk":"1362097388","pt":1588427264944,"mc":[{"id":"1.170370557","rc":[{"atl":[[3.3,0.46]],"id":9622734}],"con":true,"img":false}]}
{"op":"mcm","clk":"1362097395","pt":1588427265554,"mc":[{"id":"1.170370557","rc":[{"trd":[[1.45,752.81]],"ltp":1.45,"tv":752.81,"id":9624350},{"atb":[[1.45,56.57]],"id":9624350}],"con":true,"img":false}]}
{"op":"mcm","clk":"1362097398","pt":1588427265759,"mc":[{"id":"1.170370557","rc":[{"atl":[[1.49,0]],"id":9624350}],"con":true,"img":false}]}
{"op":"mcm","clk":"1362097419","pt":1588427267140,"mc":[{"id":"1.170370557","rc":[{"atb":[[1.43,0]],"id":9624350}],"con":true,"img":false}]}
{"op":"mcm","clk":"1362097432","pt":1588427268160,"mc":[{"id":"1.170370557","rc":[{"atl":[[1.46,728.82]],"id":9624350}],"con":true,"img":false}]}
{"op":"mcm","clk":"1362097444","pt":1588427268730,"mc":[{"id":"1.170370557","rc":[{"trd":[[1.46,291]],"ltp":1.46,"tv":291.0,"id":9624350},{"atl":[[1.46,726.57]],"id":9624350}],"con":true,"img":false}]}
{"op":"mcm","clk":"1362097451","pt":1588427269236,"mc":[{"id":"1.170370557","rc":[{"trd":[[1.46,308.49]],"ltp":1.46,"tv":308.49,"id":9624350},{"atl":[[1.46,717.82]],"id":9624350}],"con":true,"img":false}]}
{"op":"mcm","clk":"1362097459","pt":1588427269848,"mc":[{"id":"1.170370557","rc":[{"atb":[[1.44,2.57]],"id":9624350}],"con":true,"img":false}]}
{"op":"mcm","clk":"1362097467","pt":1588427270663,"mc":[{"id":"1.170370557","rc":[{"trd":[[1.45,802.81]],"ltp":1.45,"tv":802.81,"id":9624350},{"atb":[[1.45,31.57]],"id":9624350}],"con":true,"img":false}]}
{"op":"mcm","clk":"1362097475","pt":1588427271273,"mc":[{"id":"1.170370557","rc":[{"trd":[[1.46,322.51]],"ltp":1.46,"tv":322.51,"id":9624350},{"atl":[[1.46,710.82]],"id":9624350}],"con":true,"img":false}]}
{"op":"mcm","clk":"1362097496","pt":1588427272855,"mc":[{"id":"1.170370557","rc":[{"atb":[[1.45,0.25]],"id":9624350}],"con":true,"img":false}]}
{"op":"mcm","clk":"1362097502","pt":1588427273264,"mc":[{"id":"1.170370557","rc":[{"trd":[[3.2,11.83]],"ltp":3.2,"tv":11.83,"id":9622734},{"atl":[[3.2,0]],"id":9622734},{"trd":[[1.44,2855.66],[1.45,823.94]],"ltp":1.44,"tv":3679.6,"id":9624350},{"atb":[[1.44,0],[1.45,0]],"id":9624350},{"atl":[[1.44,53.54]],"id":9624350}],"con":true,"img":false}]}
{"op":"mcm","clk":"1362097524","pt":1588427275048,"mc":[{"id":"1.170370557","rc":[{"atb":[[1.4,0]],"id":9624350}],"con":true,"img":false}]}
{"op":"mcm","clk":"1362097542","pt":1588427276070,"mc":[{"id":"1.170370557","rc":[{"atl":[[3.3,0]],"id":9622734},{"atb":[[1.36,0]],"id":9624350}],"con":true,"img":false}]}
{"op":"mcm","clk":"1362097550","pt":1588427276428,"mc":[{"id":"1.170370557","rc":[{"atl":[[1.52,0]],"id":9624350}],"con":true,"img":false}]}
{"op":"mcm","clk":"1362097560","pt":1588427277046,"mc":[{"id":"1.170370557","rc":[{"trd":[[1.42,360.28]],"ltp":1.42,"tv":360.28,"id":9624350},{"atb":[[1.42,0]],"id":9624350},{"atl":[[1.4,330.16]],"id":9624350}],"con":true,"img":false}]}
{"op":"mcm","clk":"1362097561","pt":1588427277145,"mc":[{"id":"1.170370557","rc":[{"atl":[[1.41,492.02]],"id":9624350}],"con":true,"img":false}]}
{"op":"mcm","clk":"1362097565","pt":1588427277251,"mc":[{"id":"1.170370557","rc":[{"atb":[[1.09,0.31]],"id":9624350}],"con":true,"img":false}]}
{"op":"mcm","clk":"1362097577","pt":1588427278063,"mc":[{"id":"1.170370557","rc":[{"atl":[[1.43,310.28]],"id":9624350}],"con":true,"img":false}]}
{"op":"mcm","clk":"1362097585","pt":1588427278570,"mc":[{"id":"1.170370557","rc":[{"atl":[[1.43,485.28]],"id":9624350}],"con":true,"img":false}]}
{"op":"mcm","clk":"1362097590","pt":1588427278875,"mc":[{"id":"1.170370557","rc":[{"atl":[[1.43,660.28]],"id":9624350}],"con":true,"img":false}]}
{"op":"mcm","clk":"1362097592","pt":1588427278977,"mc":[{"id":"1.170370557","rc":[{"atl":[[1.43,350]],"id":9624350}],"con":true,"img":false}]}
{"op":"mcm","clk":"1362097595","pt":1588427279181,"mc":[{"id":"1.170370557","rc":[{"atl":[[1.44,496.8]],"id":9624350}],"con":true,"img":false}]}
{"op":"mcm","clk":"1362097602","pt":1588427279439,"mc":[{"id":"1.170370557","rc":[{"trd":[[1.4,1570.65]],"ltp":1.4,"tv":1570.65,"id":9624350},{"atl":[[1.4,328.4]],"id":9624350}],"con":true,"img":false}]}
{"op":"mcm","clk":"1362097628","pt":1588427280660,"mc":[{"id":"1.170370557","rc":[{"atl":[[1.54,0]],"id":9624350}],"con":true,"img":false}]}
{"op":"mcm","clk":"1362097642","pt":1588427281276,"mc":[{"id":"1.170370557","rc":[{"atb":[[1.39,183.32]],"id":9624350}],"con":true,"img":false}]}
{"op":"mcm","clk":"1362097647","pt":1588427281582,"mc":[{"id":"1.170370557","rc":[{"atb":[[1.39,216.28]],"id":9624350}],"con":true,"img":false}]}
{"op":"mcm","clk":"1362097651","pt":1588427281838,"mc":[{"id":"1.170370557","rc":[{"atb":[[1.35,221.63]],"id":9624350}],"con":true,"img":false}]}
{"op":"mcm","clk":"1362097655","pt":1588427282043,"mc":[{"id":"1.170370557","rc":[{"atl":[[1.46,0]],"id":9624350}],"con":true,"img":false}]}
{"op":"mcm","clk":"1362097670","pt":1588427282764,"mc":[{"id":"1.170370557","rc":[{"atl":[[1.41,0]],"id":9624350}],"con":true,"img":false}]}
{"op":"mcm","clk":"1362097681","pt":1588427283273,"mc":[{"id":"1.170370557","rc":[{"atb":[[1.34,0]],"id":9624350}],"con":true,"img":false}]}
{"op":"mcm","clk":"1362097689","pt":1588427283685,"mc":[{"id":"1.170370557","rc":[{"trd":[[1.4,1574.53]],"ltp":1.4,"tv":1574.53,"id":9624350},{"atl":[[1.4,326.46]],"id":9624350}],"con":true,"img":false}]}
{"op":"mcm","clk":"1362097703","pt":1588427284458,"mc":[{"id":"1.170370557","rc":[{"atb":[[1.36,175]],"id":9624350}],"con":true,"img":false}]}
{"op":"mcm","clk":"1362097711","pt":1588427284764,"mc":[{"id":"1.170370557","rc":[{"trd":[[1.4,1582.43]],"ltp":1.4,"tv":1582.43,"id":9624350},{"atb":[[1.36,350]],"id":9624350},{"atl":[[1.4,322.51]],"id":9624350}],"con":true,"img":false}]}
{"op":"mcm","clk":"1362097727","pt":1588427285482,"mc":[{"id":"1.170370557","rc":[{"atb":[[1.35,396.63]],"id":9624350}],"con":true,"img":false}]}
{"op":"mcm","clk":"1362097732","pt":1588427285790,"mc":[{"id":"1.170370557","rc":[{"atb":[[1.35,571.63]],"id":9624350}],"con":true,"img":false}]}
{"op":"mcm","clk":"1362097736","pt":1588427285846,"mc":[{"id":"1.170370557","rc":[{"atl":[[1.44,53.54]],"id":9624350}],"con":true,"img":false}]}
{"op":"mcm","clk":"1362097744","pt":1588427286252,"mc":[{"id":"1.170370557","rc":[{"atb":[[1.35,771.63]],"id":9624350}],"con":true,"img":false}]}
{"op":"mcm","clk":"1362097747","pt":1588427286357,"mc":[{"id":"1.170370557","rc":[{"atb":[[1.35,898.27]],"id":9624350}],"con":true,"img":false}]}
{"op":"mcm","clk":"1362097760","pt":1588427286870,"mc":[{"id":"1.170370557","rc":[{"atb":[[1.28,221.63]],"id":9624350}],"con":true,"img":false}]}
{"op":"mcm","clk":"1362097764","pt":1588427286969,"mc":[{"id":"1.170370557","rc":[{"trd":[[1.4,1585.2]],"ltp":1.4,"tv":1585.2,"id":9624350},{"atl":[[1.4,321.13]],"id":9624350}],"con":true,"img":false}]}
{"op":"mcm","clk":"1362097767","pt":1588427287070,"mc":[{"id":"1.170370557","rc":[{"atb":[[1.35,698.27]],"id":9624350}],"con":true,"img":false}]}
{"op":"mcm","clk":"1362097787","pt":1588427288047,"mc":[{"id":"1.170370557","rc":[{"trd":[[3.5,9.25]],"ltp":3.5,"tv":9.25,"id":9622734},{"trd":[[1.4,1595.2]],"ltp":1.4,"tv":1595.2,"id":9624350},{"atl":[[1.4,311.13]],"id":9624350}],"con":true,"img":false}]}
{"op":"mcm","clk":"1362097792","pt":1588427288253,"mc":[{"id":"1.170370557","rc":[{"atl":[[1.4,0]],"id":9624350}],"con":true,"img":false}]}
{"op":"mcm","clk":"1362097794","pt":1588427288353,"mc":[{"id":"1.170370557","rc":[{"atb":[[1.29,443.26]],"id":9624350}],"con":true,"img":false}]}
{"op":"mcm","clk":"1362097797","pt":1588427288455,"mc":[{"id":"1.170370557","rc":[{"trd":[[1.39,432.57]],"ltp":1.39,"tv":432.57,"id":9624350},{"atb":[[1.39,0]],"id":9624350},{"atl":[[1.39,494.16]],"id":9624350}],"con":true,"img":false}]}
{"op":"mcm","clk":"1362097809","pt":1588427289070,"mc":[{"id":"1.170370557","rc":[{"atb":[[1.35,571.63]],"id":9624350}],"con":true,"img":false}]}
{"op":"mcm","clk":"1362097825","pt":1588427289884,"mc":[{"id":"1.170370557","rc":[{"trd":[[3.55,0.28]],"ltp":3.55,"tv":0.28,"id":9622734},{"trd":[[1.39,433.29]],"ltp":1.39,"tv":433.29,"id":9624350},{"atl":[[1.39,493.44]],"id":9624350}],"con":true,"img":false}]}
{"op":"mcm","clk":"1362097829","pt":1588427289986,"mc":[{"id":"1.170370557","rc":[{"trd":[[1.39,443.87]],"ltp":1.39,"tv":443.87,"id":9624350},{"atl":[[1.39,488.15]],"id":9624350}],"con":true,"img":false}]}
{"op":"mcm","clk":"1362097846","pt":1588427290959,"mc":[{"id":"1.170370557","rc":[{"atl":[[1.47,443.26]],"id":9624350}],"con":true,"img":false}]}
{"op":"mcm","clk":"1362097853","pt":1588427291367,"mc":[{"id":"1.170370557","rc":[{"atb":[[1.37,221.63]],"id":9624350}],"con":true,"img":false}]}
{"op":"mcm","clk":"1362097857","pt":1588427291672,"mc":[{"id":"1.170370557","rc":[{"atb":[[1.35,350]],"id":9624350}],"con":true,"img":false}]}
{"op":"mcm","clk":"1362097863","pt":1588427292081,"mc":[{"id":"1.170370557","rc":[{"trd":[[1.39,446.72]],"ltp":1.39,"tv":446.72,"id":9624350},{"atl":[[1.39,486.72]],"id":9624350}],"con":true,"img":false}]}
{"op":"mcm","clk":"1362097866","pt":1588427292183,"mc":[{"id":"1.170370557","rc":[{"trd":[[1.39,452.4]],"ltp":1.39,"tv":452.4,"id":9624350},{"atl":[[1.39,483.88]],"id":9624350}],"con":true,"img":false}]}
{"op":"mcm","clk":"1362097878","pt":1588427292854,"mc":[{"id":"1.170370557","rc":[{"trd":[[1.39,454.76]],"ltp":1.39,"tv":454.76,"id":9624350},{"atl":[[1.39,482.7]],"id":9624350}],"con":true,"img":false}]}
{"op":"mcm","clk":"1362097899","pt":1588427294079,"mc":[{"id":"1.170370557","rc":[{"trd":[[1.39,460.02]],"ltp":1.39,"tv":460.02,"id":9624350},{"atb":[[1.35,0],[1.36,0]],"id":9624350},{"atl":[[1.43,0],[1.39,480.07]],"id":9624350}],"con":true,"img":false}]}
{"op":"mcm","clk":"1362097908","pt":1588427294587,"mc":[{"id":"1.170370557","rc":[{"trd":[[1.39,504.16]],"ltp":1.39,"tv":504.16,"id":9624350},{"atl":[[1.39,458]],"id":9624350}],"con":true,"img":false}]}
{"op":"mcm","clk":"1362097929","pt":1588427295864,"mc":[{"id":"1.170370557","rc":[{"atb":[[1.37,0]],"id":9624350}],"con":true,"img":false}]}
{"op":"mcm","clk":"1362097944","pt":1588427297491,"mc":[{"id":"1.170370557","rc":[{"trd":[[1.39,752.76]],"ltp":1.39,"tv":752.76,"id":9624350},{"atl":[[1.39,333.7]],"id":9624350}],"con":true,"img":false}]}
{"op":"mcm","clk":"1362097947","pt":1588427297901,"mc":[{"id":"1.170370557","rc":[{"trd":[[3.55,1.62]],"ltp":3.55,"tv":1.62,"id":9622734},{"trd":[[1.39,756.18]],"ltp":1.39,"tv":756.18,"id":9624350},{"atl":[[1.42,310.28],[1.39,330.28]],"id":9624350}],"con":true,"img":false}]}
{"op":"mcm","clk":"1362097958","pt":1588427298466,"mc":[{"id":"1.170370557","rc":[{"atb":[[1.01,4101.75]],"id":9624350}],"con":true,"img":false}]}
{"op":"mcm","clk":"1362097988","pt":1588427300659,"mc":[{"id":"1.170370557","rc":[{"atl":[[1.46,175]],"id":9624350}],"con":true,"img":false}]}
{"op":"mcm","clk":"1362097993","pt":1588427300976,"mc":[{"id":"1.170370557","rc":[{"atl":[[1.46,350]],"id":9624350}],"con":true,"img":false}]}
{"op":"mcm","clk":"1362097997","pt":1588427301681,"mc":[{"id":"1.170370557","rc":[{"atl":[[1.45,175]],"id":9624350}],"con":true,"img":false}]}
{"op":"mcm","clk":"1362098001","pt":1588427301989,"mc":[{"id":"1.170370557","rc":[{"atl":[[1.46,0]],"id":9624350}],"con":true,"img":false}]}
{"op":"mcm","clk":"1362098005","pt":1588427302395,"mc":[{"id":"1.170370557","rc":[{"atb":[[1.3,221.63]],"id":9624350}],"con":true,"img":false}]}
{"op":"mcm","clk":"1362098012","pt":1588427302802,"mc":[{"id":"1.170370557","rc":[{"atl":[[1.34,333]],"id":9624350}],"con":true,"img":false}]}
{"op":"mcm","clk":"1362098025","pt":1588427303671,"mc":[{"id":"1.170370557","rc":[{"trd":[[1.34,0.56]],"ltp":1.34,"tv":0.56,"id":9624350},{"atl":[[1.34,332.72]],"id":9624350}],"con":true,"img":false}]}
{"op":"mcm","clk":"1362098027","pt":1588427303774,"mc":[{"id":"1.170370557","rc":[{"atl":[[1.45,0]],"id":9624350}],"con":true,"img":false}]}
{"op":"mcm","clk":"1362098029","pt":1588427303875,"mc":[{"id":"1.170370557","rc":[{"atb":[[1.28,0]],"id":9624350},{"atl":[[1.35,310.28]],"id":9624350}],"con":true,"img":false}]}
{"op":"mcm","clk":"1362098033","pt":1588427304182,"mc":[{"id":"1.170370557","rc":[{"atl":[[1.36,443.26],[1.38,175]],"id":9624350}],"con":true,"img":false}]}
{"op":"mcm","clk":"1362098037","pt":1588427304489,"mc":[{"id":"1.170370557","rc":[{"atl":[[1.38,350]],"id":9624350}],"con":true,"img":false}]}
{"op":"mcm","clk":"1362098039","pt":1588427304592,"mc":[{"id":"1.170370557","rc":[{"atl":[[1.35,0]],"id":9624350}],"con":true,"img":false}]}
{"op":"mcm","clk":"1362098049","pt":1588427305203,"mc":[{"id":"1.170370557","rc":[{"atb":[[1.02,3184.36]],"id":9624350}],"con":true,"img":false}]}
{"op":"mcm","clk":"1362098052","pt":1588427305407,"mc":[{"id":"1.170370557","rc":[{"atl":[[1.36,618.26]],"id":9624350}],"con":true,"img":false}]}
{"op":"mcm","clk":"1362098057","pt":1588427305665,"mc":[{"id":"1.170370557","rc":[{"atl":[[1.36,793.26]],"id":9624350}],"con":true,"img":false}]}
{"op":"mcm","clk":"1362098060","pt":1588427305869,"mc":[{"id":"1.170370557","rc":[{"atl":[[1.42,0]],"id":9624350}],"con":true,"img":false}]}
{"op":"mcm","clk":"1362098085","pt":1588427308010,"mc":[{"id":"1.170370557","rc":[{"atl":[[1.38,466.64]],"id":9624350}],"con":true,"img":false}]}
{"op":"mcm","clk":"1362098094","pt":1588427308369,"mc":[{"id":"1.170370557","rc":[{"atb":[[3,0.28]],"id":9622734}],"con":true,"img":false}]}
{"op":"mcm","clk":"1362098098","pt":1588427308573,"mc":[{"id":"1.170370557","rc":[{"atl":[[1.34,463.08]],"id":9624350}],"con":true,"img":false}]}
{"op":"mcm","clk":"1362098119","pt":1588427310203,"mc":[{"id":"1.170370557","rc":[{"atb":[[1.25,221.63]],"id":9624350}],"con":true,"img":false}]}
{"op":"mcm","clk":"1362098122","pt":1588427310306,"mc":[{"id":"1.170370557","rc":[{"atb":[[1.26,175]],"id":9624350}],"con":true,"img":false}]}
{"op":"mcm","clk":"1362098128","pt":1588427310611,"mc":[{"id":"1.170370557","rc":[{"atb":[[1.26,350]],"id":9624350}],"con":true,"img":false}]}
{"op":"mcm","clk":"1362098131","pt":1588427310814,"mc":[{"id":"1.170370557","rc":[{"atb":[[1.31,1.77]],"id":9624350}],"con":true,"img":false}]}
{"op":"mcm","clk":"1362098134","pt":1588427310916,"mc":[{"id":"1.170370557","rc":[{"atb":[[1.1,0]],"id":9624350}],"con":true,"img":false}]}
{"op":"mcm","clk":"1362098146","pt":1588427311377,"mc":[{"id":"1.170370557","rc":[{"atb":[[1.03,2284.35]],"id":9624350}],"con":true,"img":false}]}
{"op":"mcm","clk":"1362098149","pt":1588427311479,"mc":[{"id":"1.170370557","rc":[{"atb":[[1.24,175]],"id":9624350}],"con":true,"img":false}]}
{"op":"mcm","clk":"1362098155","pt":1588427311683,"mc":[{"id":"1.170370557","rc":[{"atl":[[1.34,332.72],[1.38,350]],"id":9624350}],"con":true,"img":false}]}
{"op":"mcm","clk":"1362098158","pt":1588427311787,"mc":[{"id":"1.170370557","rc":[{"atb":[[1.24,350]],"id":9624350}],"con":true,"img":false}]}
{"op":"mcm","clk":"1362098173","pt":1588427312502,"mc":[{"id":"1.170370557","rc":[{"atb":[[1.23,175]],"id":9624350}],"con":true,"img":false}]}
{"op":"mcm","clk":"1362098177","pt":1588427312704,"mc":[{"id":"1.170370557","rc":[{"atl":[[1.47,0]],"id":9624350}],"con":true,"img":false}]}
{"op":"mcm","clk":"1362098181","pt":1588427312907,"mc":[{"id":"1.170370557","rc":[{"atb":[[1.23,350]],"id":9624350}],"con":true,"img":false}]}
{"op":"mcm","clk":"1362098196","pt":1588427313780,"mc":[{"id":"1.170370557","rc":[{"trd":[[1.31,3.54]],"ltp":1.31,"tv":3.54,"id":9624350},{"atb":[[1.31,0]],"id":9624350},{"atl":[[1.31,20.39]],"id":9624350}],"con":true,"img":false}]}
{"op":"mcm","clk":"1362098201","pt":1588427313982,"mc":[{"id":"1.170370557","rc":[{"trd":[[1.3,258.58]],"ltp":1.3,"tv":258.58,"id":9624350},{"atb":[[1.3,92.34]],"id":9624350}],"con":true,"img":false}]}
{"op":"mcm","clk":"1362098204","pt":1588427314185,"mc":[{"id":"1.170370557","rc":[{"atb":[[1.29,0]],"id":9624350}],"con":true,"img":false}]}
{"op":"mcm","clk":"1362098207","pt":1588427314389,"mc":[{"id":"1.170370557","rc":[{"trd":[[1.34,159.78],[1.31,44.32]],"ltp":1.34,"tv":204.1,"id":9624350},{"atl":[[1.31,0],[1.34,253.11]],"id":9624350}],"con":true,"img":false}]}
{"op":"mcm","clk":"1362098209","pt":1588427314490,"mc":[{"id":"1.170370557","rc":[{"atl":[[1.33,22.16]],"id":9624350}],"con":true,"img":false}]}
{"op":"mcm","clk":"1362098226","pt":1588427315407,"mc":[{"id":"1.170370557","rc":[{"atl":[[1000,0]],"id":9622734}],"con":true,"img":false}]}
{"op":"mcm","clk":"1362098234","pt":1588427315970,"mc":[{"id":"1.170370557","rc":[{"atb":[[1.08,1199.8]],"id":9624350},{"atl":[[1.33,156.48]],"id":9624350}],"con":true,"img":false}]}
{"op":"mcm","clk":"1362098241","pt":1588427316378,"mc":[{"id":"1.170370557","rc":[{"atl":[[1.4,443.26]],"id":9624350}],"con":true,"img":false}]}
{"op":"mcm","clk":"1362098276","pt":1588427318671,"mc":[{"id":"1.170370557","rc":[{"atb":[[1.04,2363.41]],"id":9624350}],"con":true,"img":false}]}
{"op":"mcm","clk":"1362098301","pt":1588427319998,"mc":[{"id":"1.170370557","rc":[{"atb":[[1.2,443.26]],"id":9624350},{"atl":[[1.41,2.11]],"id":9624350}],"con":true,"img":false}]}
{"op":"mcm","clk":"1362098307","pt":1588427320404,"mc":[{"id":"1.170370557","rc":[{"atl":[[1.39,0]],"id":9624350}],"con":true,"img":false}]}
{"op":"mcm","clk":"1362098308","pt":1588427320506,"mc":[{"id":"1.170370557","rc":[{"trd":[[1.3,262.58]],"ltp":1.3,"tv":262.58,"id":9624350},{"atb":[[1.3,90.33]],"id":9624350},{"atl":[[1.36,350]],"id":9624350}],"con":true,"img":false}]}
{"op":"mcm","clk":"1362098320","pt":1588427321477,"mc":[{"id":"1.170370557","rc":[{"atb":[[1.31,0.11]],"id":9624350}],"con":true,"img":false}]}
{"op":"mcm","clk":"1362098329","pt":1588427321884,"mc":[{"id":"1.170370557","rc":[{"atl":[[4.2,2]],"id":9622734}],"con":true,"img":false}]}
{"op":"mcm","clk":"1362098334","pt":1588427322191,"mc":[{"id":"1.170370557","rc":[{"atb":[[1.15,1378.54]],"id":9624350}],"con":true,"img":false}]}
{"op":"mcm","clk":"1362098357","pt":1588427323677,"mc":[{"id":"1.170370557","rc":[{"atl":[[1000,2.05]],"id":9624350}],"con":true,"img":false}]}
{"op":"mcm","clk":"1362098373","pt":1588427324295,"mc":[{"id":"1.170370557","rc":[{"atl":[[1000,0.59]],"id":9624350}],"con":true,"img":false}]}
{"op":"mcm","clk":"1362098389","pt":1588427324908,"mc":[{"id":"1.170370557","rc":[{"atl":[[1.34,0]],"id":9624350}],"con":true,"img":false}]}
{"op":"mcm","clk":"1362098390","pt":1588427325009,"mc":[{"id":"1.170370557","rc":[{"atl":[[1000,0]],"id":9624350}],"con":true,"img":false}]}
{"op":"mcm","clk":"1362098396","pt":1588427325214,"mc":[{"id":"1.170370557","rc":[{"atl":[[1.36,0],[1.38,0]],"id":9624350}],"con":true,"img":false}]}
{"op":"mcm","clk":"1362098412","pt":1588427325879,"mc":[{"id":"1.170370557","rc":[{"atb":[[1.13,0]],"id":9624350},{"atl":[[1.33,22.16]],"id":9624350}],"con":true,"img":false}]}
{"op":"mcm","clk":"1362098416","pt":1588427325983,"mc":[{"id":"1.170370557","rc":[{"atb":[[1.16,1378.54]],"id":9624350}],"con":true,"img":false}]}
{"op":"mcm","clk":"1362098418","pt":1588427326083,"mc":[{"id":"1.170370557","rc":[{"atb":[[1.15,0]],"id":9624350}],"con":true,"img":false}]}
{"op":"mcm","clk":"1362098423","pt":1588427326186,"mc":[{"id":"1.170370557","rc":[{"atb":[[1.05,1986.13]],"id":9624350}],"con":true,"img":false}]}
{"op":"mcm","clk":"1362098428","pt":1588427326492,"mc":[{"id":"1.170370557","rc":[{"atl":[[1.33,0]],"id":9624350}],"con":true,"img":false}]}
{"op":"mcm","clk":"1362098434","pt":1588427326797,"mc":[{"id":"1.170370557","rc":[{"atb":[[1.16,0]],"id":9624350}],"con":true,"img":false}]}
{"op":"mcm","clk":"1362098481","pt":1588427329401,"mc":[{"id":"1.170370557","rc":[{"atb":[[1.35,492.02]],"id":9624350}],"con":true,"img":false}]}
{"op":"mcm","clk":"1362098487","pt":1588427329706,"mc":[{"id":"1.170370557","rc":[{"atl":[[4.2,0]],"id":9622734}],"con":true,"img":false}]}
{"op":"mcm","clk":"1362098494","pt":1588427330015,"mc":[{"id":"1.170370557","rc":[{"atl":[[4.2,0.42]],"id":9622734}],"con":true,"img":false}]}
{"op":"mcm","clk":"1362098498","pt":1588427330117,"mc":[{"id":"1.170370557","rc":[{"trd":[[1.35,1.19]],"ltp":1.35,"tv":1.19,"id":9624350},{"atb":[[1.35,491.42]],"id":9624350}],"con":true,"img":false}]}
{"op":"mcm","clk":"1362098500","pt":1588427330219,"mc":[{"id":"1.170370557","rc":[{"atb":[[1.34,443.26]],"id":9624350}],"con":true,"img":false}]}
{"op":"mcm","clk":"1362098509","pt":1588427330627,"mc":[{"id":"1.170370557","rc":[{"trd":[[1.35,72.11]],"ltp":1.35,"tv":72.11,"id":9624350},{"atb":[[1.35,455.96]],"id":9624350}],"con":true,"img":false}]}
{"op":"mcm","clk":"1362098517","pt":1588427331086,"mc":[{"id":"1.170370557","rc":[{"atb":[[1.33,2.57],[1.31,175.11]],"id":9624350}],"con":true,"img":false}]}
{"op":"mcm","clk":"1362098521","pt":1588427331189,"mc":[{"id":"1.170370557","rc":[{"atb":[[1.14,1378.54]],"id":9624350}],"con":true,"img":false}]}
{"op":"mcm","clk":"1362098523","pt":1588427331290,"mc":[{"id":"1.170370557","rc":[{"atb":[[1.36,78.71]],"id":9624350}],"con":true,"img":false}]}
{"op":"mcm","clk":"1362098526","pt":1588427331493,"mc":[{"id":"1.170370557","rc":[{"trd":[[1.35,76.27],[1.36,157.41]],"ltp":1.35,"tv":233.68,"id":9624350},{"atb":[[1.35,453.88],[1.36,0]],"id":9624350}],"con":true,"img":false}]}
{"op":"mcm","clk":"1362098528","pt":1588427331595,"mc":[{"id":"1.170370557","rc":[{"atb":[[1.31,350.11]],"id":9624350}],"con":true,"img":false}]}
{"op":"mcm","clk":"1362098532","pt":1588427331800,"mc":[{"id":"1.170370557","rc":[{"atb":[[1.34,664.89]],"id":9624350}],"con":true,"img":false}]}
{"op":"mcm","clk":"1362098541","pt":1588427332413,"mc":[{"id":"1.170370557","rc":[{"atb":[[1.35,675.51]],"id":9624350},{"atl":[[1.39,175]],"id":9624350}],"con":true,"img":false}]}
{"op":"mcm","clk":"1362098545","pt":1588427332719,"mc":[{"id":"1.170370557","rc":[{"atl":[[1.39,350]],"id":9624350}],"con":true,"img":false}]}
{"op":"mcm","clk":"1362098550","pt":1588427333024,"mc":[{"id":"1.170370557","rc":[{"atb":[[1.06,2068.2]],"id":9624350}],"con":true,"img":false}]}
{"op":"mcm","clk":"1362098554","pt":1588427333332,"mc":[{"id":"1.170370557","rc":[{"atb":[[1.34,221.63],[1.31,431.83]],"id":9624350}],"con":true,"img":false}]}
{"op":"mcm","clk":"1362098556","pt":1588427333589,"mc":[{"id":"1.170370557","rc":[{"atb":[[1.34,0]],"id":9624350}],"con":true,"img":false}]}
{"op":"mcm","clk":"1362098561","pt":1588427333997,"mc":[{"id":"1.170370557","rc":[{"atb":[[1.14,0]],"id":9624350}],"con":true,"img":false}]}
{"op":"mcm","clk":"1362098568","pt":1588427334608,"mc":[{"id":"1.170370557","rc":[{"atl":[[1.39,463.65]],"id":9624350}],"con":true,"img":false}]}
{"op":"mcm","clk":"1362098571","pt":1588427334710,"mc":[{"id":"1.170370557","rc":[{"atb":[[1.33,6.5]],"id":9624350}],"con":true,"img":false}]}
{"op":"mcm","clk":"1362098574","pt":1588427334812,"mc":[{"id":"1.170370557","rc":[{"atl":[[4,2]],"id":9622734},{"atb":[[1.35,221.63]],"id":9624350}],"con":true,"img":false}]}
{"op":"mcm","clk":"1362098579","pt":1588427335120,"mc":[{"id":"1.170370557","rc":[{"atb":[[1.31,350.11]],"id":9624350},{"atl":[[1.4,0]],"id":9624350}],"con":true,"img":false}]}
{"op":"mcm","clk":"1362098582","pt":1588427335322,"mc":[{"id":"1.170370557","rc":[{"atb":[[1.35,0]],"id":9624350},{"atl":[[1000,1.77]],"id":9624350}],"con":true,"img":false}]}
{"op":"mcm","clk":"1362098585","pt":1588427335526,"mc":[{"id":"1.170370557","rc":[{"atb":[[1.15,492.02]],"id":9624350},{"atl":[[1000,0.59]],"id":9624350}],"con":true,"img":false}]}
{"op":"mcm","clk":"1362098587","pt":1588427335628,"mc":[{"id":"1.170370557","rc":[{"atb":[[1.36,221.63]],"id":9624350},{"atl":[[1.4,330.28]],"id":9624350}],"con":true,"img":false}]}
{"op":"mcm","clk":"1362098589","pt":1588427335730,"mc":[{"id":"1.170370557","rc":[{"atl":[[1000,0]],"id":9624350}],"con":true,"img":false}]}
{"op":"mcm","clk":"1362098594","pt":1588427335988,"mc":[{"id":"1.170370557","rc":[{"trd":[[1.36,227.82]],"ltp":1.36,"tv":227.82,"id":9624350},{"atb":[[1.36,186.42]],"id":9624350}],"con":true,"img":false}]}
{"op":"mcm","clk":"1362098601","pt":1588427336396,"mc":[{"id":"1.170370557","rc":[{"atl":[[1.44,496.8]],"id":9624350}],"con":true,"img":false}]}
{"op":"mcm","clk":"1362098606","pt":1588427336801,"mc":[{"id":"1.170370557","rc":[{"trd":[[1.36,231.95]],"ltp":1.36,"tv":231.95,"id":9624350},{"atb":[[1.36,184.36]],"id":9624350}],"con":true,"img":false}]}
{"op":"mcm","clk":"1362098634","pt":1588427339199,"mc":[{"id":"1.170370557","rc":[{"atb":[[1.26,793.26]],"id":9624350}],"con":true,"img":false}]}
{"op":"mcm","clk":"1362098643","pt":1588427340013,"mc":[{"id":"1.170370557","rc":[{"atl":[[4,0]],"id":9622734}],"con":true,"img":false}]}
{"op":"mcm","clk":"1362098645","pt":1588427340114,"mc":[{"id":"1.170370557","rc":[{"trd":[[1.39,758]],"ltp":1.39,"tv":758.0,"id":9624350},{"atl":[[1.39,462.74]],"id":9624350}],"con":true,"img":false}]}
{"op":"mcm","clk":"1362098649","pt":1588427340420,"mc":[{"id":"1.170370557","rc":[{"atb":[[1.07,1986.13]],"id":9624350}],"con":true,"img":false}]}
{"op":"mcm","clk":"1362098656","pt":1588427340725,"mc":[{"id":"1.170370557","rc":[{"atb":[[1.14,492.02]],"id":9624350}],"con":true,"img":false}]}
{"op":"mcm","clk":"1362098657","pt":1588427340827,"mc":[{"id":"1.170370557","rc":[{"trd":[[1.36,233.14]],"ltp":1.36,"tv":233.14,"id":9624350},{"atb":[[1.36,183.76]],"id":9624350}],"con":true,"img":false}]}
{"op":"mcm","clk":"1362098677","pt":1588427341699,"mc":[{"id":"1.170370557","rc":[{"atl":[[3.9,4]],"id":9622734},{"atb":[[1.33,228.13]],"id":9624350}],"con":true,"img":false}]}
{"op":"mcm","clk":"1362098688","pt":1588427342519,"mc":[{"id":"1.170370557","rc":[{"atb":[[1.13,492.02]],"id":9624350}],"con":true,"img":false}]}
{"op":"mcm","clk":"1362098696","pt":1588427343136,"mc":[{"id":"1.170370557","rc":[{"atl":[[1.41,0]],"id":9624350}],"con":true,"img":false}]}
{"op":"mcm","clk":"1362098706","pt":1588427343807,"mc":[{"id":"1.170370557","rc":[{"atb":[[1.31,0.11]],"id":9624350}],"con":true,"img":false}]}
{"op":"mcm","clk":"1362098728","pt":1588427345595,"mc":[{"id":"1.170370557","rc":[{"atb":[[1.2,0]],"id":9624350}],"con":true,"img":false}]}
{"op":"mcm","clk":"1362098734","pt":1588427345902,"mc":[{"id":"1.170370557","rc":[{"atb":[[1.14,984.04]],"id":9624350}],"con":true,"img":false}]}
{"op":"mcm","clk":"1362098750","pt":1588427347125,"mc":[{"id":"1.170370557","rc":[{"atl":[[1.38,0.39]],"id":9624350}],"con":true,"img":false}]}
{"op":"mcm","clk":"1362098752","pt":1588427347329,"mc":[{"id":"1.170370557","rc":[{"atb":[[1.33,6.5]],"id":9624350}],"con":true,"img":false}]}
{"op":"mcm","clk":"1362098753","pt":1588427347430,"mc":[{"id":"1.170370557","rc":[{"atb":[[1.08,2184.67]],"id":9624350}],"con":true,"img":false}]}
{"op":"mcm","clk":"1362098776","pt":1588427349421,"mc":[{"id":"1.170370557","rc":[{"atl":[[1.39,113.65]],"id":9624350}],"con":true,"img":false}]}
{"op":"mcm","clk":"1362098801","pt":1588427350899,"mc":[{"id":"1.170370557","rc":[{"trd":[[1.39,835.93],[1.38,0.78]],"ltp":1.39,"tv":836.7,"id":9624350},{"atl":[[1.39,74.68],[1.38,0]],"id":9624350}],"con":true,"img":false}]}
{"op":"mcm","clk":"1362098835","pt":1588427353397,"mc":[{"id":"1.170370557","rc":[{"atb":[[1.36,0]],"id":9624350}],"con":true,"img":false}]}
{"op":"mcm","clk":"1362098847","pt":1588427354009,"mc":[{"id":"1.170370557","rc":[{"atl":[[1.44,53.54]],"id":9624350}],"con":true,"img":false}]}
{"op":"mcm","clk":"1362098850","pt":1588427354212,"mc":[{"id":"1.170370557","rc":[{"atl":[[1.36,0.25]],"id":9624350}],"con":true,"img":false}]}
{"op":"mcm","clk":"1362098861","pt":1588427354822,"mc":[{"id":"1.170370557","rc":[{"atb":[[1.3,0]],"id":9624350}],"con":true,"img":false}]}
{"op":"mcm","clk":"1362098865","pt":1588427355333,"mc":[{"id":"1.170370557","rc":[{"atl":[[1.4,0]],"id":9624350}],"con":true,"img":false}]}
{"op":"mcm","clk":"1362098867","pt":1588427355435,"mc":[{"id":"1.170370557","rc":[{"trd":[[1.39,845.53]],"ltp":1.39,"tv":845.53,"id":9624350},{"atl":[[1.36,0],[1.39,69.88]],"id":9624350}],"con":true,"img":false}]}
{"op":"mcm","clk":"1362098885","pt":1588427356812,"mc":[{"id":"1.170370557","rc":[{"atl":[[1.36,175]],"id":9624350}],"con":true,"img":false}]}
{"op":"mcm","clk":"1362098889","pt":1588427357118,"mc":[{"id":"1.170370557","rc":[{"atl":[[1.36,350]],"id":9624350}],"con":true,"img":false}]}
{"op":"mcm","clk":"1362098896","pt":1588427357425,"mc":[{"id":"1.170370557","rc":[{"trd":[[3.9,4]],"ltp":3.9,"tv":4.0,"id":9622734},{"atl":[[3.9,0]],"id":9622734},{"trd":[[1.33,13.01],[1.34,171.42]],"ltp":1.33,"tv":184.42,"id":9624350},{"atb":[[1.33,0]],"id":9624350},{"atl":[[1.32,425.11]],"id":9624350}],"con":true,"img":false}]}
{"op":"mcm","clk":"1362098913","pt":1588427358806,"mc":[{"id":"1.170370557","rc":[{"atb":[[3.4,5.53]],"id":9622734}],"con":true,"img":false}]}
{"op":"mcm","clk":"1362098917","pt":1588427359112,"mc":[{"id":"1.170370557","rc":[{"atl":[[1.32,646.74]],"id":9624350}],"con":true,"img":false}]}
{"op":"mcm","clk":"1362098926","pt":1588427360029,"mc":[{"id":"1.170370557","rc":[{"atl":[[1.36,467.7]],"id":9624350}],"con":true,"img":false}]}
{"op":"mcm","clk":"1362098933","pt":1588427360539,"mc":[{"id":"1.170370557","rc":[{"atl":[[1.33,134.31]],"id":9624350}],"con":true,"img":false}]}
{"op":"mcm","clk":"1362098934","pt":1588427360642,"mc":[{"id":"1.170370557","rc":[{"atl":[[1.34,20]],"id":9624350}],"con":true,"img":false}]}
{"op":"mcm","clk":"1362098937","pt":1588427360744,"mc":[{"id":"1.170370557","rc":[{"trd":[[4.2,0.42]],"ltp":4.2,"tv":0.42,"id":9622734},{"atl":[[4.2,0]],"id":9622734},{"trd":[[1.31,45.91]],"ltp":1.31,"tv":45.91,"id":9624350},{"atb":[[1.31,0]],"id":9624350},{"atl":[[1.31,220.15]],"id":9624350}],"con":true,"img":false}]}
{"op":"mcm","clk":"1362098941","pt":1588427361101,"mc":[{"id":"1.170370557","rc":[{"atl":[[1.33,464.6]],"id":9624350}],"con":true,"img":false}]}
{"op":"mcm","clk":"1362098943","pt":1588427361206,"mc":[{"id":"1.170370557","rc":[{"atl":[[1.3,147.74]],"id":9624350}],"con":true,"img":false}]}
{"op":"mcm","clk":"1362098947","pt":1588427361513,"mc":[{"id":"1.170370557","rc":[{"atl":[[1.33,484.6]],"id":9624350}],"con":true,"img":false}]}
{"op":"mcm","clk":"1362098960","pt":1588427362531,"mc":[{"id":"1.170370557","rc":[{"atl":[[1.33,350.28]],"id":9624350}],"con":true,"img":false}]}
{"op":"mcm","clk":"1362098970","pt":1588427363041,"mc":[{"id":"1.170370557","rc":[{"atl":[[1.34,0]],"id":9624350}],"con":true,"img":false}]}
{"op":"mcm","clk":"1362098980","pt":1588427363912,"mc":[{"id":"1.170370557","rc":[{"atb":[[1.26,443.26],[1.23,0],[1.24,0]],"id":9624350},{"atl":[[1.38,443.26]],"id":9624350}],"con":true,"img":false}]}
{"op":"mcm","clk":"1362098982","pt":1588427364015,"mc":[{"id":"1.170370557","rc":[{"atl":[[1.31,240.15]],"id":9624350}],"con":true,"img":false}]}
{"op":"mcm","clk":"1362098987","pt":1588427364425,"mc":[{"id":"1.170370557","rc":[{"atl":[[1.31,260.15]],"id":9624350}],"con":true,"img":false}]}
{"op":"mcm","clk":"1362098992","pt":1588427364933,"mc":[{"id":"1.170370557","rc":[{"atl":[[1.33,330.28]],"id":9624350}],"con":true,"img":false}]}
{"op":"mcm","clk":"1362098994","pt":1588427365137,"mc":[{"id":"1.170370557","rc":[{"atl":[[1.3,168.42]],"id":9624350}],"con":true,"img":false}]}
{"op":"mcm","clk":"1362099000","pt":1588427365605,"mc":[{"id":"1.170370557","rc":[{"atb":[[1.25,0]],"id":9624350}],"con":true,"img":false}]}
{"op":"mcm","clk":"1362099005","pt":1588427365911,"mc":[{"id":"1.170370557","rc":[{"atb":[[1.27,221.63]],"id":9624350}],"con":true,"img":false}]}
{"op":"mcm","clk":"1362099009","pt":1588427366114,"mc":[{"id":"1.170370557","rc":[{"atb":[[1.14,492.02]],"id":9624350}],"con":true,"img":false}]}
{"op":"mcm","clk":"1362099011","pt":1588427366228,"mc":[{"id":"1.170370557","rc":[{"atb":[[3.4,0]],"id":9622734}],"con":true,"img":false}]}
{"op":"mcm","clk":"1362099013","pt":1588427366317,"mc":[{"id":"1.170370557","rc":[{"atl":[[1.34,91.18],[1.36,471.96]],"id":9624350}],"con":true,"img":false}]}
{"op":"mcm","clk":"1362099015","pt":1588427366624,"mc":[{"id":"1.170370557","rc":[{"atl":[[1.31,220.15]],"id":9624350}],"con":true,"img":false}]}
{"op":"mcm","clk":"1362099029","pt":1588427367900,"mc":[{"id":"1.170370557","rc":[{"atl":[[1.28,43.73]],"id":9624350}],"con":true,"img":false}]}
{"op":"mcm","clk":"1362099032","pt":1588427368011,"mc":[{"id":"1.170370557","rc":[{"atb":[[1.27,421.63]],"id":9624350},{"atl":[[1.32,425.11]],"id":9624350}],"con":true,"img":false}]}
{"op":"mcm","clk":"1362099034","pt":1588427368119,"mc":[{"id":"1.170370557","rc":[{"atl":[[1.29,20]],"id":9624350}],"con":true,"img":false}]}
{"op":"mcm","clk":"1362099042","pt":1588427368820,"mc":[{"id":"1.170370557","rc":[{"atb":[[1.19,443.26]],"id":9624350},{"atl":[[1.39,0]],"id":9624350}],"con":true,"img":false}]}
{"op":"mcm","clk":"1362099047","pt":1588427369137,"mc":[{"id":"1.170370557","rc":[{"atb":[[1.26,643.26]],"id":9624350}],"con":true,"img":false}]}
{"op":"mcm","clk":"1362099055","pt":1588427369544,"mc":[{"id":"1.170370557","rc":[{"atb":[[1.25,200]],"id":9624350}],"con":true,"img":false}]}
{"op":"mcm","clk":"1362099058","pt":1588427369750,"mc":[{"id":"1.170370557","rc":[{"trd":[[4.8,1.34]],"ltp":4.8,"tv":1.34,"id":9622734},{"trd":[[1.27,5.08]],"ltp":1.27,"tv":5.08,"id":9624350},{"atb":[[1.23,200],[1.27,416.54]],"id":9624350}],"con":true,"img":false}]}
{"op":"mcm","clk":"1362099063","pt":1588427370043,"mc":[{"id":"1.170370557","rc":[{"atb":[[1.17,175]],"id":9624350},{"atl":[[1.29,40]],"id":9624350}],"con":true,"img":false}]}
{"op":"mcm","clk":"1362099067","pt":1588427370146,"mc":[{"id":"1.170370557","rc":[{"atb":[[1.27,216.54]],"id":9624350}],"con":true,"img":false}]}
{"op":"mcm","clk":"1362099071","pt":1588427370416,"mc":[{"id":"1.170370557","rc":[{"atb":[[1.17,350]],"id":9624350}],"con":true,"img":false}]}
{"op":"mcm","clk":"1362099081","pt":1588427370814,"mc":[{"id":"1.170370557","rc":[{"trd":[[4.5,3.81]],"ltp":4.5,"tv":3.81,"id":9622734},{"trd":[[1.28,18.54]],"ltp":1.28,"tv":18.54,"id":9624350},{"atl":[[1.28,27.76]],"id":9624350}],"con":true,"img":false}]}
{"op":"mcm","clk":"1362099084","pt":1588427370926,"mc":[{"id":"1.170370557","rc":[{"atb":[[1.16,175]],"id":9624350}],"con":true,"img":false}]}
{"op":"mcm","clk":"1362099088","pt":1588427371025,"mc":[{"id":"1.170370557","rc":[{"trd":[[1.28,23.69]],"ltp":1.28,"tv":23.69,"id":9624350},{"atl":[[1.28,25.18],[1.33,0]],"id":9624350}],"con":true,"img":false}]}
{"op":"mcm","clk":"1362099091","pt":1588427371131,"mc":[{"id":"1.170370557","rc":[{"atl":[[1.36,354.26]],"id":9624350}],"con":true,"img":false}]}
{"op":"mcm","clk":"1362099093","pt":1588427371220,"mc":[{"id":"1.170370557","rc":[{"trd":[[4.5,5.81]],"ltp":4.5,"tv":5.81,"id":9622734},{"trd":[[1.28,30.72]],"ltp":1.28,"tv":30.72,"id":9624350},{"atb":[[1.21,221.63]],"id":9624350},{"atl":[[1.28,18.15]],"id":9624350}],"con":true,"img":false}]}
{"op":"mcm","clk":"1362099096","pt":1588427371425,"mc":[{"id":"1.170370557","rc":[{"atb":[[1.16,350]],"id":9624350}],"con":true,"img":false}]}
{"op":"mcm","clk":"1362099102","pt":1588427371742,"mc":[{"id":"1.170370557","rc":[{"atl":[[1.29,80]],"id":9624350}],"con":true,"img":false}]}
{"op":"mcm","clk":"1362099114","pt":1588427372444,"mc":[{"id":"1.170370557","rc":[{"atb":[[1.26,443.26]],"id":9624350}],"con":true,"img":false}]}
{"op":"mcm","clk":"1362099120","pt":1588427372916,"mc":[{"id":"1.170370557","rc":[{"atb":[[1.25,0]],"id":9624350}],"con":true,"img":false}]}
{"op":"mcm","clk":"1362099126","pt":1588427373226,"mc":[{"id":"1.170370557","rc":[{"trd":[[1.27,136.77]],"ltp":1.27,"tv":136.77,"id":9624350},{"atb":[[1.26,0],[1.27,150.7],[1.24,200]],"id":9624350}],"con":true,"img":false}]}
{"op":"mcm","clk":"1362099136","pt":1588427373940,"mc":[{"id":"1.170370557","rc":[{"atb":[[1.27,0]],"id":9624350}],"con":true,"img":false}]}
{"op":"mcm","clk":"1362099145","pt":1588427374549,"mc":[{"id":"1.170370557","rc":[{"atl":[[1.3,147.74]],"id":9624350}],"con":true,"img":false}]}
{"op":"mcm","clk":"1362099151","pt":1588427374946,"mc":[{"id":"1.170370557","rc":[{"atb":[[1.24,0]],"id":9624350}],"con":true,"img":false}]}
{"op":"mcm","clk":"1362099155","pt":1588427375251,"mc":[{"id":"1.170370557","rc":[{"atb":[[1.21,0]],"id":9624350}],"con":true,"img":false}]}
{"op":"mcm","clk":"1362099179","pt":1588427376225,"mc":[{"id":"1.170370557","rc":[{"atb":[[1.23,0]],"id":9624350},{"atl":[[1.26,117.7]],"id":9624350}],"con":true,"img":false}]}
{"op":"mcm","clk":"1362099189","pt":1588427376733,"mc":[{"id":"1.170370557","rc":[{"atl":[[1.24,2.11]],"id":9624350}],"con":true,"img":false}]}
{"op":"mcm","clk":"1362099192","pt":1588427376836,"mc":[{"id":"1.170370557","rc":[{"atl":[[1.26,142.7]],"id":9624350}],"con":true,"img":false}]}
{"op":"mcm","clk":"1362099202","pt":1588427377446,"mc":[{"id":"1.170370557","rc":[{"atl":[[1.27,175]],"id":9624350}],"con":true,"img":false}]}
{"op":"mcm","clk":"1362099205","pt":1588427377549,"mc":[{"id":"1.170370557","rc":[{"atl":[[1.34,0]],"id":9624350}],"con":true,"img":false}]}
{"op":"mcm","clk":"1362099210","pt":1588427377754,"mc":[{"id":"1.170370557","rc":[{"atl":[[1.27,350],[1.25,444]],"id":9624350}],"con":true,"img":false}]}
{"op":"mcm","clk":"1362099215","pt":1588427378009,"mc":[{"id":"1.170370557","rc":[{"atl":[[1.28,0]],"id":9624350}],"con":true,"img":false}]}
{"op":"mcm","clk":"1362099218","pt":1588427378315,"mc":[{"id":"1.170370557","rc":[{"trd":[[1.24,3.32]],"ltp":1.24,"tv":3.32,"id":9624350},{"atl":[[1.24,0.45]],"id":9624350}],"con":true,"img":false}]}
{"op":"mcm","clk":"1362099221","pt":1588427378519,"mc":[{"id":"1.170370557","rc":[{"atl":[[1.3,0]],"id":9624350}],"con":true,"img":false}]}
{"op":"mcm","clk":"1362099223","pt":1588427378622,"mc":[{"id":"1.170370557","rc":[{"trd":[[1.25,4.41],[1.24,4.23]],"ltp":1.25,"tv":8.64,"id":9624350},{"atl":[[1.25,441.79],[1.24,0]],"id":9624350}],"con":true,"img":false}]}
{"op":"mcm","clk":"1362099233","pt":1588427379339,"mc":[{"id":"1.170370557","rc":[{"atb":[[1.22,200]],"id":9624350}],"con":true,"img":false}]}
{"op":"mcm","clk":"1362099236","pt":1588427379439,"mc":[{"id":"1.170370557","rc":[{"atb":[[3.4,5.81]],"id":9622734}],"con":true,"img":false}]}
{"op":"mcm","clk":"1362099242","pt":1588427379746,"mc":[{"id":"1.170370557","rc":[{"atl":[[1.26,585.96]],"id":9624350}],"con":true,"img":false}]}
{"op":"mcm","clk":"1362099244","pt":1588427379849,"mc":[{"id":"1.170370557","rc":[{"atb":[[1.12,492.02]],"id":9624350}],"con":true,"img":false}]}
{"op":"mcm","clk":"1362099254","pt":1588427380313,"mc":[{"id":"1.170370557","rc":[{"atl":[[1.27,350.68]],"id":9624350}],"con":true,"img":false}]}
{"op":"mcm","clk":"1362099262","pt":1588427380621,"mc":[{"id":"1.170370557","rc":[{"atb":[[1.16,0],[1.17,0]],"id":9624350},{"atl":[[1.26,560.96],[1.36,4.26],[1.27,0.68]],"id":9624350}],"con":true,"img":false}]}
{"op":"mcm","clk":"1362099268","pt":1588427380928,"mc":[{"id":"1.170370557","rc":[{"atl":[[1.23,221.63]],"id":9624350}],"con":true,"img":false}]}
{"op":"mcm","clk":"1362099275","pt":1588427381132,"mc":[{"id":"1.170370557","rc":[{"trd":[[5.3,0.95]],"ltp":5.3,"tv":0.95,"id":9622734},{"trd":[[1.23,4.1]],"ltp":1.23,"tv":4.1,"id":9624350},{"atl":[[1.23,217.52],[1.36,0]],"id":9624350}],"con":true,"img":false}]}
{"op":"mcm","clk":"1362099281","pt":1588427381439,"mc":[{"id":"1.170370557","rc":[{"atl":[[1.26,443.26]],"id":9624350}],"con":true,"img":false}]}
{"op":"mcm","clk":"1362099283","pt":1588427381540,"mc":[{"id":"1.170370557","rc":[{"atb":[[1.22,0]],"id":9624350}],"con":true,"img":false}]}
{"op":"mcm","clk":"1362099288","pt":1588427381846,"mc":[{"id":"1.170370557","rc":[{"atl":[[1.25,619.09],[1.38,0]],"id":9624350}],"con":true,"img":false}]}
{"op":"mcm","clk":"1362099290","pt":1588427381948,"mc":[{"id":"1.170370557","rc":[{"trd":[[1.23,7.27]],"ltp":1.23,"tv":7.27,"id":9624350},{"atl":[[1.23,215.93]],"id":9624350}],"con":true,"img":false}]}
{"op":"mcm","clk":"1362099293","pt":1588427382051,"mc":[{"id":"1.170370557","rc":[{"atl":[[1.24,221.63]],"id":9624350}],"con":true,"img":false}]}
{"op":"mcm","clk":"1362099299","pt":1588427382358,"mc":[{"id":"1.170370557","rc":[{"atl":[[1.22,201.48]],"id":9624350}],"con":true,"img":false}]}
{"op":"mcm","clk":"1362099302","pt":1588427382412,"mc":[{"id":"1.170370557","rc":[{"atl":[[1.31,0]],"id":9624350}],"con":true,"img":false}]}
{"op":"mcm","clk":"1362099304","pt":1588427382512,"mc":[{"id":"1.170370557","rc":[{"atb":[[1.2,200]],"id":9624350}],"con":true,"img":false}]}
{"op":"mcm","clk":"1362099309","pt":1588427382819,"mc":[{"id":"1.170370557","rc":[{"atb":[[1.2,400]],"id":9624350}],"con":true,"img":false}]}
{"op":"mcm","clk":"1362099314","pt":1588427383125,"mc":[{"id":"1.170370557","rc":[{"trd":[[1.22,0.23]],"ltp":1.22,"tv":0.23,"id":9624350},{"atl":[[1.22,201.36]],"id":9624350}],"con":true,"img":false}]}
{"op":"mcm","clk":"1362099326","pt":1588427383636,"mc":[{"id":"1.170370557","rc":[{"atb":[[1.08,984.87]],"id":9624350}],"con":true,"img":false}]}
{"op":"mcm","clk":"1362099333","pt":1588427383941,"mc":[{"id":"1.170370557","rc":[{"atl":[[1.27,0]],"id":9624350}],"con":true,"img":false}]}
{"op":"mcm","clk":"1362099337","pt":1588427384043,"mc":[{"id":"1.170370557","rc":[{"atb":[[1.21,200]],"id":9624350}],"con":true,"img":false}]}
{"op":"mcm","clk":"1362099340","pt":1588427384145,"mc":[{"id":"1.170370557","rc":[{"atb":[[1.2,621.63]],"id":9624350}],"con":true,"img":false}]}
{"op":"mcm","clk":"1362099346","pt":1588427384453,"mc":[{"id":"1.170370557","rc":[{"atb":[[1.25,0]],"id":9622734}],"con":true,"img":false}]}
{"op":"mcm","clk":"1362099349","pt":1588427384555,"mc":[{"id":"1.170370557","rc":[{"atl":[[1.24,664.89]],"id":9624350}],"con":true,"img":false}]}
{"op":"mcm","clk":"1362099352","pt":1588427384658,"mc":[{"id":"1.170370557","rc":[{"atb":[[1.21,0]],"id":9624350}],"con":true,"img":false}]}
{"op":"mcm","clk":"1362099354","pt":1588427384762,"mc":[{"id":"1.170370557","rc":[{"atl":[[1.44,0]],"id":9624350}],"con":true,"img":false}]}
{"op":"mcm","clk":"1362099356","pt":1588427384866,"mc":[{"id":"1.170370557","rc":[{"atb":[[1.01,14.79],[1.03,3],[1.09,0],[1.08,0],[1.02,0.21],[1.06,0],[1.07,0],[1.05,0],[1.04,0]],"id":9622734},{"atb":[[1.2,641.63]],"id":9624350}],"con":true,"img":false}]}
{"op":"mcm","clk":"1362099360","pt":1588427385123,"mc":[{"id":"1.170370557","rc":[{"trd":[[1.2,0.44]],"ltp":1.2,"tv":0.44,"id":9624350},{"atb":[[1.2,661.41]],"id":9624350}],"con":true,"img":false}]}
{"op":"mcm","clk":"1362099374","pt":1588427385838,"mc":[{"id":"1.170370557","rc":[{"atb":[[1.01,4103.75]],"id":9624350},{"atl":[[1.25,177.3]],"id":9624350}],"con":true,"img":false}]}
{"op":"mcm","clk":"1362099381","pt":1588427386145,"mc":[{"id":"1.170370557","rc":[{"atb":[[1.01,4102.78]],"id":9624350}],"con":true,"img":false}]}
{"op":"mcm","clk":"1362099384","pt":1588427386346,"mc":[{"id":"1.170370557","rc":[{"atb":[[1.01,4101.75]],"id":9624350}],"con":true,"img":false}]}
{"op":"mcm","clk":"1362099389","pt":1588427386550,"mc":[{"id":"1.170370557","rc":[{"trd":[[1.2,235.85]],"ltp":1.2,"tv":235.85,"id":9624350},{"atb":[[1.2,543.7]],"id":9624350}],"con":true,"img":false}]}
{"op":"mcm","clk":"1362099396","pt":1588427387163,"mc":[{"id":"1.170370557","rc":[{"trd":[[1.2,280.55]],"ltp":1.2,"tv":280.55,"id":9624350},{"atb":[[1.2,521.35]],"id":9624350}],"con":true,"img":false}]}
{"op":"mcm","clk":"1362099399","pt":1588427387317,"mc":[{"id":"1.170370557","rc":[{"atl":[[1.22,228.93]],"id":9624350}],"con":true,"img":false}]}
{"op":"mcm","clk":"1362099411","pt":1588427388437,"mc":[{"id":"1.170370557","rc":[{"atb":[[1.12,0],[1.16,175]],"id":9624350}],"con":true,"img":false}]}
{"op":"mcm","clk":"1362099415","pt":1588427388744,"mc":[{"id":"1.170370557","rc":[{"atb":[[1.14,935.28],[1.16,350]],"id":9624350}],"con":true,"img":false}]}
{"op":"mcm","clk":"1362099424","pt":1588427389255,"mc":[{"id":"1.170370557","rc":[{"atb":[[1.17,175]],"id":9624350}],"con":true,"img":false}]}
{"op":"mcm","clk":"1362099429","pt":1588427389460,"mc":[{"id":"1.170370557","rc":[{"atb":[[1.21,221.63]],"id":9624350}],"con":true,"img":false}]}
{"op":"mcm","clk":"1362099432","pt":1588427389562,"mc":[{"id":"1.170370557","rc":[{"atb":[[1.17,350]],"id":9624350}],"con":true,"img":false}]}
{"op":"mcm","clk":"1362099441","pt":1588427389921,"mc":[{"id":"1.170370557","rc":[{"atl":[[1.22,248.61]],"id":9624350}],"con":true,"img":false}]}
{"op":"mcm","clk":"1362099456","pt":1588427391043,"mc":[{"id":"1.170370557","rc":[{"atb":[[1.21,223.92]],"id":9624350},{"atl":[[1.22,47.25]],"id":9624350}],"con":true,"img":false}]}
{"op":"mcm","clk":"1362099462","pt":1588427391452,"mc":[{"id":"1.170370557","rc":[{"trd":[[1.22,2.29]],"ltp":1.22,"tv":2.29,"id":9624350},{"atl":[[1.22,46.21]],"id":9624350}],"con":true,"img":false}]}
{"op":"mcm","clk":"1362099468","pt":1588427391859,"mc":[{"id":"1.170370557","rc":[{"atb":[[1.17,794]],"id":9624350}],"con":true,"img":false}]}
{"op":"mcm","clk":"1362099472","pt":1588427392166,"mc":[{"id":"1.170370557","rc":[{"trd":[[1.21,225]],"ltp":1.21,"tv":225.0,"id":9624350},{"atb":[[1.21,111.42],[1.16,842.02]],"id":9624350},{"atl":[[1.24,696.88]],"id":9624350}],"con":true,"img":false}]}
{"op":"mcm","clk":"1362099473","pt":1588427392267,"mc":[{"id":"1.170370557","rc":[{"atb":[[1.16,1286.02]],"id":9624350}],"con":true,"img":false}]}
{"op":"mcm","clk":"1362099480","pt":1588427392829,"mc":[{"id":"1.170370557","rc":[{"atb":[[1.15,936.02]],"id":9624350}],"con":true,"img":false}]}
{"op":"mcm","clk":"1362099483","pt":1588427392930,"mc":[{"id":"1.170370557","rc":[{"trd":[[5.1,111.19],[5.5,54.61],[5.3,51.06]],"ltp":5.1,"tv":216.86,"id":9622734},{"trd":[[1.21,226.38],[1.24,461.56],[1.23,223.21],[1.22,248.51]],"ltp":1.21,"tv":1159.66,"id":9624350},{"atb":[[1.21,110.72]],"id":9624350},{"atl":[[1.23,0],[1.22,0],[1.24,239.55]],"id":9624350}],"con":true,"img":false}]}
{"op":"mcm","clk":"1362099490","pt":1588427393442,"mc":[{"id":"1.170370557","rc":[{"trd":[[1.24,462.64]],"ltp":1.24,"tv":462.64,"id":9624350},{"atl":[[1.24,239.01]],"id":9624350}],"con":true,"img":false}]}
{"op":"mcm","clk":"1362099501","pt":1588427394359,"mc":[{"id":"1.170370557","rc":[{"atb":[[1.22,333]],"id":9624350}],"con":true,"img":false}]}
{"op":"mcm","clk":"1362099511","pt":1588427395130,"mc":[{"id":"1.170370557","rc":[{"atb":[[1.16,936.02],[1.17,444]],"id":9624350}],"con":true,"img":false}]}
{"op":"mcm","clk":"1362099519","pt":1588427395639,"mc":[{"id":"1.170370557","rc":[{"atb":[[1.22,333.19]],"id":9624350}],"con":true,"img":false}]}
{"op":"mcm","clk":"1362099528","pt":1588427395945,"mc":[{"id":"1.170370557","rc":[{"trd":[[1.24,463.15]],"ltp":1.24,"tv":463.15,"id":9624350},{"atl":[[1.24,238.75]],"id":9624350}],"con":true,"img":false}]}
{"op":"mcm","clk":"1362099555","pt":1588427397270,"mc":[{"id":"1.170370557","rc":[{"atl":[[1.25,0]],"id":9624350}],"con":true,"img":false}]}
{"op":"mcm","clk":"1362099571","pt":1588427398654,"mc":[{"id":"1.170370557","rc":[{"atb":[[1.22,333.31]],"id":9624350}],"con":true,"img":false}]}
{"op":"mcm","clk":"1362099574","pt":1588427398857,"mc":[{"id":"1.170370557","rc":[{"trd":[[1.22,852.51]],"ltp":1.22,"tv":852.51,"id":9624350},{"atb":[[1.18,444],[1.22,31.31]],"id":9624350},{"atl":[[1.26,0]],"id":9624350}],"con":true,"img":false}]}
{"op":"mcm","clk":"1362099587","pt":1588427399676,"mc":[{"id":"1.170370557","rc":[{"atl":[[1.32,0]],"id":9624350}],"con":true,"img":false}]}
{"op":"mcm","clk":"1362099590","pt":1588427399733,"mc":[{"id":"1.170370557","rc":[{"trd":[[1.22,909.37]],"ltp":1.22,"tv":909.37,"id":9624350},{"atb":[[1.22,2.88]],"id":9624350}],"con":true,"img":false}]}
{"op":"mcm","clk":"1362099594","pt":1588427400037,"mc":[{"id":"1.170370557","rc":[{"atb":[[1.22,1179.93]],"id":9624350}],"con":true,"img":false}]}
{"op":"mcm","clk":"1362099602","pt":1588427400546,"mc":[{"id":"1.170370557","rc":[{"atl":[[1.24,31.99]],"id":9624350}],"con":true,"img":false}]}
{"op":"mcm","clk":"1362099607","pt":1588427400854,"mc":[{"id":"1.170370557","rc":[{"atb":[[1.22,1439.93]],"id":9624350}],"con":true,"img":false}]}
{"op":"mcm","clk":"1362099615","pt":1588427401362,"mc":[{"id":"1.170370557","rc":[{"atb":[[1.19,0]],"id":9624350}],"con":true,"img":false}]}
{"op":"mcm","clk":"1362099623","pt":1588427401772,"mc":[{"id":"1.170370557","rc":[{"trd":[[1.22,912.28]],"ltp":1.22,"tv":912.28,"id":9624350},{"atb":[[1.22,1438.47]],"id":9624350}],"con":true,"img":false}]}
{"op":"mcm","clk":"1362099628","pt":1588427402137,"mc":[{"id":"1.170370557","rc":[{"atb":[[1.12,984.87]],"id":9624350}],"con":true,"img":false}]}
{"op":"mcm","clk":"1362099632","pt":1588427402340,"mc":[{"id":"1.170370557","rc":[{"atb":[[1.21,108.43]],"id":9624350}],"con":true,"img":false}]}
{"op":"mcm","clk":"1362099637","pt":1588427402648,"mc":[{"id":"1.170370557","rc":[{"trd":[[1.24,469.08]],"ltp":1.24,"tv":469.08,"id":9624350},{"atl":[[1.24,29.02]],"id":9624350}],"con":true,"img":false}]}
{"op":"mcm","clk":"1362099640","pt":1588427402752,"mc":[{"id":"1.170370557","rc":[{"atb":[[1.22,1437.36]],"id":9624350}],"con":true,"img":false}]}
{"op":"mcm","clk":"1362099656","pt":1588427403734,"mc":[{"id":"1.170370557","rc":[{"atb":[[1.19,200]],"id":9624350}],"con":true,"img":false}]}
{"op":"mcm","clk":"1362099659","pt":1588427403936,"mc":[{"id":"1.170370557","rc":[{"atb":[[1.18,739.21]],"id":9624350},{"atl":[[1.3,443.26]],"id":9624350}],"con":true,"img":false}]}
{"op":"mcm","clk":"1362099660","pt":1588427404040,"mc":[{"id":"1.170370557","rc":[{"atb":[[1.18,939.21]],"id":9624350}],"con":true,"img":false}]}
{"op":"mcm","clk":"1362099667","pt":1588427404347,"mc":[{"id":"1.170370557","rc":[{"atb":[[1.16,1136.02]],"id":9624350}],"con":true,"img":false}]}
{"op":"mcm","clk":"1362099668","pt":1588427404450,"mc":[{"id":"1.170370557","rc":[{"atb":[[1.22,1437.16]],"id":9624350}],"con":true,"img":false}]}
{"op":"mcm","clk":"1362099684","pt":1588427405270,"mc":[{"id":"1.170370557","rc":[{"atb":[[1.22,1437.05]],"id":9624350}],"con":true,"img":false}]}
{"op":"mcm","clk":"1362099701","pt":1588427406138,"mc":[{"id":"1.170370557","rc":[{"atb":[[1.15,492.02]],"id":9624350}],"con":true,"img":false}]}
{"op":"mcm","clk":"1362099703","pt":1588427406241,"mc":[{"id":"1.170370557","rc":[{"trd":[[1.22,972.28]],"ltp":1.22,"tv":972.28,"id":9624350},{"atb":[[1.22,1407.31]],"id":9624350}],"con":true,"img":false}]}
{"op":"mcm","clk":"1362099716","pt":1588427407057,"mc":[{"id":"1.170370557","rc":[{"atb":[[1.21,129.53]],"id":9624350}],"con":true,"img":false}]}
{"op":"mcm","clk":"1362099725","pt":1588427407670,"mc":[{"id":"1.170370557","rc":[{"trd":[[1.24,488.83]],"ltp":1.24,"tv":488.83,"id":9624350},{"atl":[[1.24,19.15]],"id":9624350}],"con":true,"img":false}]}
{"op":"mcm","clk":"1362099735","pt":1588427408335,"mc":[{"id":"1.170370557","rc":[{"atb":[[1.19,466.81]],"id":9624350}],"con":true,"img":false}]}
{"op":"mcm","clk":"1362099743","pt":1588427408950,"mc":[{"id":"1.170370557","rc":[{"atb":[[1.23,16.82]],"id":9624350}],"con":true,"img":false}]}
{"op":"mcm","clk":"1362099771","pt":1588427410275,"mc":[{"id":"1.170370557","rc":[{"atb":[[1.22,1147.31]],"id":9624350}],"con":true,"img":false}]}
{"op":"mcm","clk":"1362099783","pt":1588427410943,"mc":[{"id":"1.170370557","rc":[{"trd":[[1.22,988.62],[1.23,256.87]],"ltp":1.22,"tv":1245.49,"id":9624350},{"atb":[[1.23,0],[1.22,1139.14]],"id":9624350}],"con":true,"img":false}]}
{"op":"mcm","clk":"1362099785","pt":1588427411046,"mc":[{"id":"1.170370557","rc":[{"atb":[[1.14,492.02]],"id":9624350}],"con":true,"img":false}]}
{"op":"mcm","clk":"1362099788","pt":1588427411146,"mc":[{"id":"1.170370557","rc":[{"trd":[[1.24,491.98]],"ltp":1.24,"tv":491.98,"id":9624350},{"atl":[[1.24,17.58]],"id":9624350}],"con":true,"img":false}]}
{"op":"mcm","clk":"1362099792","pt":1588427411351,"mc":[{"id":"1.170370557","rc":[{"trd":[[1.24,492.07]],"ltp":1.24,"tv":492.07,"id":9624350},{"atb":[[1.17,644]],"id":9624350},{"atl":[[1.24,17.53]],"id":9624350}],"con":true,"img":false}]}
{"op":"mcm","clk":"1362099796","pt":1588427411554,"mc":[{"id":"1.170370557","rc":[{"trd":[[1.22,1017.78]],"ltp":1.22,"tv":1017.78,"id":9624350},{"atb":[[1.22,1124.56]],"id":9624350}],"con":true,"img":false}]}
{"op":"mcm","clk":"1362099800","pt":1588427411862,"mc":[{"id":"1.170370557","rc":[{"trd":[[1.22,1056.78]],"ltp":1.22,"tv":1056.78,"id":9624350},{"atb":[[1.22,1105.06]],"id":9624350}],"con":true,"img":false}]}
{"op":"mcm","clk":"1362099803","pt":1588427411963,"mc":[{"id":"1.170370557","rc":[{"trd":[[1.24,492.6]],"ltp":1.24,"tv":492.6,"id":9624350},{"atl":[[1.24,17.26]],"id":9624350}],"con":true,"img":false}]}
{"op":"mcm","clk":"1362099812","pt":1588427412371,"mc":[{"id":"1.170370557","rc":[{"atb":[[1.23,48.75]],"id":9624350}],"con":true,"img":false}]}
{"op":"mcm","clk":"1362099815","pt":1588427412576,"mc":[{"id":"1.170370557","rc":[{"trd":[[1.23,262.03]],"ltp":1.23,"tv":262.03,"id":9624350},{"atb":[[1.23,46.17]],"id":9624350}],"con":true,"img":false}]}
{"op":"mcm","clk":"1362099820","pt":1588427413083,"mc":[{"id":"1.170370557","rc":[{"trd":[[1.24,527.14]],"ltp":1.24,"tv":527.14,"id":9624350},{"atb":[[1.24,440.76]],"id":9624350},{"atl":[[1.24,0]],"id":9624350}],"con":true,"img":false}]}
{"op":"mcm","clk":"1362099826","pt":1588427413237,"mc":[{"id":"1.170370557","rc":[{"atb":[[1.23,304.31]],"id":9624350}],"con":true,"img":false}]}
{"op":"mcm","clk":"1362099837","pt":1588427413952,"mc":[{"id":"1.170370557","rc":[{"atb":[[1.23,497.03]],"id":9624350}],"con":true,"img":false}]}
{"op":"mcm","clk":"1362099866","pt":1588427415740,"mc":[{"id":"1.170370557","rc":[{"trd":[[1.24,570.33]],"ltp":1.24,"tv":570.33,"id":9624350},{"atb":[[1.24,419.16]],"id":9624350}],"con":true,"img":false}]}
{"op":"mcm","clk":"1362099868","pt":1588427415839,"mc":[{"id":"1.170370557","rc":[{"atb":[[1.24,420.09]],"id":9624350}],"con":true,"img":false}]}
{"op":"mcm","clk":"1362099888","pt":1588427417061,"mc":[{"id":"1.170370557","rc":[{"atb":[[1.23,517.03]],"id":9624350}],"con":true,"img":false}]}
{"op":"mcm","clk":"1362099902","pt":1588427417878,"mc":[{"id":"1.170370557","rc":[{"atb":[[1.16,692.02]],"id":9624350}],"con":true,"img":false}]}
{"op":"mcm","clk":"1362099912","pt":1588427418341,"mc":[{"id":"1.170370557","rc":[{"atb":[[1.17,200]],"id":9624350}],"con":true,"img":false}]}
{"op":"mcm","clk":"1362099921","pt":1588427418746,"mc":[{"id":"1.170370557","rc":[{"atb":[[1.18,495.21]],"id":9624350}],"con":true,"img":false}]}
{"op":"mcm","clk":"1362099924","pt":1588427418951,"mc":[{"id":"1.170370557","rc":[{"atb":[[1.23,470.85]],"id":9624350}],"con":true,"img":false}]}
{"op":"mcm","clk":"1362099925","pt":1588427419155,"mc":[{"id":"1.170370557","rc":[{"trd":[[1.24,649.05]],"ltp":1.24,"tv":649.05,"id":9624350},{"atb":[[1.24,380.73]],"id":9624350}],"con":true,"img":false}]}
{"op":"mcm","clk":"1362099934","pt":1588427419766,"mc":[{"id":"1.170370557","rc":[{"atb":[[1.25,444]],"id":9624350}],"con":true,"img":false}]}
{"op":"mcm","clk":"1362099936","pt":1588427419868,"mc":[{"id":"1.170370557","rc":[{"atb":[[1.23,472.63]],"id":9624350}],"con":true,"img":false}]}
{"op":"mcm","clk":"1362099946","pt":1588427420684,"mc":[{"id":"1.170370557","rc":[{"atb":[[1.26,251.99]],"id":9624350}],"con":true,"img":false}]}
{"op":"mcm","clk":"1362099952","pt":1588427421144,"mc":[{"id":"1.170370557","rc":[{"atb":[[1.25,798.6]],"id":9624350}],"con":true,"img":false}]}
{"op":"mcm","clk":"1362099958","pt":1588427421654,"mc":[{"id":"1.170370557","rc":[{"atb":[[1.24,735.34]],"id":9624350}],"con":true,"img":false}]}
{"op":"mcm","clk":"1362099960","pt":1588427421959,"mc":[{"id":"1.170370557","rc":[{"atb":[[1.24,749.55]],"id":9624350}],"con":true,"img":false}]}
{"op":"mcm","clk":"1362099969","pt":1588427422469,"mc":[{"id":"1.170370557","rc":[{"atb":[[1.23,214.49]],"id":9624350}],"con":true,"img":false}]}
{"op":"mcm","clk":"1362099976","pt":1588427422775,"mc":[{"id":"1.170370557","rc":[{"atb":[[1.21,21.09]],"id":9624350}],"con":true,"img":false}]}
{"op":"mcm","clk":"1362099978","pt":1588427422877,"mc":[{"id":"1.170370557","rc":[{"atb":[[1.24,369.75]],"id":9624350}],"con":true,"img":false}]}
{"op":"mcm","clk":"1362099986","pt":1588427423438,"mc":[{"id":"1.170370557","rc":[{"atb":[[1.2,299.72]],"id":9624350}],"con":true,"img":false}]}
{"op":"mcm","clk":"1362099987","pt":1588427423643,"mc":[{"id":"1.170370557","rc":[{"atl":[[5,3.54]],"id":9622734}],"con":true,"img":false}]}
{"op":"mcm","clk":"1362099991","pt":1588427423949,"mc":[{"id":"1.170370557","rc":[{"atb":[[1.16,995.96]],"id":9624350}],"con":true,"img":false}]}
{"op":"mcm","clk":"1362099993","pt":1588427424050,"mc":[{"id":"1.170370557","rc":[{"atl":[[1.58,343.22]],"id":9624350}],"con":true,"img":false}]}
{"op":"mcm","clk":"1362100009","pt":1588427425478,"mc":[{"id":"1.170370557","rc":[{"atl":[[1.35,443.26]],"id":9624350}],"con":true,"img":false}]}
{"op":"mcm","clk":"1362100017","pt":1588427425989,"mc":[{"id":"1.170370557","rc":[{"atb":[[1.22,1104.8]],"id":9624350}],"con":true,"img":false}]}
{"op":"mcm","clk":"1362100020","pt":1588427426248,"mc":[{"id":"1.170370557","rc":[{"atb":[[1.26,606.6]],"id":9624350}],"con":true,"img":false}]}
{"op":"mcm","clk":"1362100050","pt":1588427428187,"mc":[{"id":"1.170370557","rc":[{"trd":[[1.29,0.46]],"ltp":1.29,"tv":0.46,"id":9624350},{"atb":[[1.22,0]],"id":9624350},{"atl":[[1.29,79.77]],"id":9624350}],"con":true,"img":false}]}
{"op":"mcm","clk":"1362100054","pt":1588427428444,"mc":[{"id":"1.170370557","rc":[{"atb":[[1.23,21.77]],"id":9624350}],"con":true,"img":false}]}
{"op":"mcm","clk":"1362100058","pt":1588427428751,"mc":[{"id":"1.170370557","rc":[{"trd":[[1.3,272.03],[1.29,159.99]],"ltp":1.3,"tv":432.02,"id":9624350},{"atl":[[1.3,438.53],[1.29,0]],"id":9624350}],"con":true,"img":false}]}
{"op":"mcm","clk":"1362100060","pt":1588427428851,"mc":[{"id":"1.170370557","rc":[{"atb":[[1.29,2.57]],"id":9624350}],"con":true,"img":false}]}
{"op":"mcm","clk":"1362100091","pt":1588427430381,"mc":[{"id":"1.170370557","rc":[{"trd":[[1.26,465.67],[1.29,165.14]],"ltp":1.26,"tv":630.81,"id":9624350},{"atb":[[1.26,373.76],[1.29,0]],"id":9624350}],"con":true,"img":false}]}
{"op":"mcm","clk":"1362100109","pt":1588427431257,"mc":[{"id":"1.170370557","rc":[{"atb":[[1.24,15.14]],"id":9624350}],"con":true,"img":false}]}
{"op":"mcm","clk":"1362100130","pt":1588427432483,"mc":[{"id":"1.170370557","rc":[{"atl":[[1.29,152.84]],"id":9624350}],"con":true,"img":false}]}
{"op":"mcm","clk":"1362100134","pt":1588427432789,"mc":[{"id":"1.170370557","rc":[{"atb":[[1.25,354.6]],"id":9624350}],"con":true,"img":false}]}
{"op":"mcm","clk":"1362100141","pt":1588427433258,"mc":[{"id":"1.170370557","rc":[{"atb":[[1.27,1104.8]],"id":9624350}],"con":true,"img":false}]}
{"op":"mcm","clk":"1362100142","pt":1588427433358,"mc":[{"id":"1.170370557","rc":[{"atb":[[1.21,0]],"id":9624350}],"con":true,"img":false}]}
{"op":"mcm","clk":"1362100151","pt":1588427434380,"mc":[{"id":"1.170370557","rc":[{"atl":[[5,0]],"id":9622734}],"con":true,"img":false}]}
{"op":"mcm","clk":"1362100157","pt":1588427435095,"mc":[{"id":"1.170370557","rc":[{"atb":[[1.19,200]],"id":9624350}],"con":true,"img":false}]}
{"op":"mcm","clk":"1362100160","pt":1588427435250,"mc":[{"id":"1.170370557","rc":[{"trd":[[1.3,557.35],[1.29,470.83]],"ltp":1.3,"tv":1028.18,"id":9624350},{"atl":[[1.3,295.87],[1.29,0]],"id":9624350}],"con":true,"img":false}]}
{"op":"mcm","clk":"1362100162","pt":1588427435454,"mc":[{"id":"1.170370557","rc":[{"atb":[[1.24,0.92]],"id":9624350}],"con":true,"img":false}]}
{"op":"mcm","clk":"1362100181","pt":1588427436880,"mc":[{"id":"1.170370557","rc":[{"trd":[[1.27,141.92]],"ltp":1.27,"tv":141.92,"id":9624350},{"atb":[[1.27,1102.22]],"id":9624350}],"con":true,"img":false}]}
{"op":"mcm","clk":"1362100186","pt":1588427437491,"mc":[{"id":"1.170370557","rc":[{"atb":[[1.26,817.03]],"id":9624350}],"con":true,"img":false}]}
{"op":"mcm","clk":"1362100199","pt":1588427438362,"mc":[{"id":"1.170370557","rc":[{"atb":[[1.26,354.6]],"id":9624350}],"con":true,"img":false}]}
{"op":"mcm","clk":"1362100205","pt":1588427438975,"mc":[{"id":"1.170370557","rc":[{"trd":[[1.3,558.58]],"ltp":1.3,"tv":558.58,"id":9624350},{"atl":[[1.3,295.26]],"id":9624350}],"con":true,"img":false}]}
{"op":"mcm","clk":"1362100212","pt":1588427439179,"mc":[{"id":"1.170370557","rc":[{"trd":[[1.27,143.81]],"ltp":1.27,"tv":143.81,"id":9624350},{"atb":[[1.27,1101.28]],"id":9624350}],"con":true,"img":false}]}
{"op":"mcm","clk":"1362100216","pt":1588427439282,"mc":[{"id":"1.170370557","rc":[{"atb":[[1.22,443.26]],"id":9624350}],"con":true,"img":false}]}
{"op":"mcm","clk":"1362100220","pt":1588427439485,"mc":[{"id":"1.170370557","rc":[{"atl":[[4.8,3.54]],"id":9622734}],"con":true,"img":false}]}
{"op":"mcm","clk":"1362100224","pt":1588427439689,"mc":[{"id":"1.170370557","rc":[{"atl":[[1.35,0]],"id":9624350}],"con":true,"img":false}]}
{"op":"mcm","clk":"1362100248","pt":1588427441374,"mc":[{"id":"1.170370557","rc":[{"atb":[[1.22,445.53]],"id":9624350}],"con":true,"img":false}]}
{"op":"mcm","clk":"1362100250","pt":1588427441578,"mc":[{"id":"1.170370557","rc":[{"atl":[[1.3,0]],"id":9624350}],"con":true,"img":false}]}
{"op":"mcm","clk":"1362100267","pt":1588427442703,"mc":[{"id":"1.170370557","rc":[{"atb":[[1.28,168.54]],"id":9624350}],"con":true,"img":false}]}
{"op":"mcm","clk":"1362100281","pt":1588427443266,"mc":[{"id":"1.170370557","rc":[{"atl":[[4.4,13.02]],"id":9622734}],"con":true,"img":false}]}
{"op":"mcm","clk":"1362100284","pt":1588427443371,"mc":[{"id":"1.170370557","rc":[{"atb":[[1.21,21.09],[1.26,0]],"id":9624350}],"con":true,"img":false}]}
{"op":"mcm","clk":"1362100294","pt":1588427443777,"mc":[{"id":"1.170370557","rc":[{"atb":[[1.28,0]],"id":9624350}],"con":true,"img":false}]}
{"op":"mcm","clk":"1362100301","pt":1588427443981,"mc":[{"id":"1.170370557","rc":[{"atb":[[1.28,94.98]],"id":9624350}],"con":true,"img":false}]}
{"op":"mcm","clk":"1362100303","pt":1588427444083,"mc":[{"id":"1.170370557","rc":[{"atb":[[1.25,0]],"id":9624350}],"con":true,"img":false}]}
{"op":"mcm","clk":"1362100307","pt":1588427444389,"mc":[{"id":"1.170370557","rc":[{"atb":[[1.01,4104.33]],"id":9624350}],"con":true,"img":false}]}
{"op":"mcm","clk":"1362100317","pt":1588427445105,"mc":[{"id":"1.170370557","rc":[{"atl":[[1.43,443.26]],"id":9624350}],"con":true,"img":false}]}
{"op":"mcm","clk":"1362100321","pt":1588427445411,"mc":[{"id":"1.170370557","rc":[{"atl":[[4.8,0]],"id":9622734}],"con":true,"img":false}]}
{"op":"mcm","clk":"1362100323","pt":1588427445615,"mc":[{"id":"1.170370557","rc":[{"atb":[[1.23,20]],"id":9624350}],"con":true,"img":false}]}
{"op":"mcm","clk":"1362100329","pt":1588427446177,"mc":[{"id":"1.170370557","rc":[{"atb":[[1.28,0]],"id":9624350}],"con":true,"img":false}]}
{"op":"mcm","clk":"1362100336","pt":1588427446687,"mc":[{"id":"1.170370557","rc":[{"trd":[[4.4,13.02]],"ltp":4.4,"tv":13.02,"id":9622734},{"atl":[[4.4,0]],"id":9622734},{"trd":[[1.28,925.88],[1.29,515.28]],"ltp":1.28,"tv":1441.15,"id":9624350},{"atb":[[1.28,52.42]],"id":9624350}],"con":true,"img":false}]}
{"op":"mcm","clk":"1362100340","pt":1588427446993,"mc":[{"id":"1.170370557","rc":[{"atb":[[1.2,399.72]],"id":9624350}],"con":true,"img":false}]}
{"op":"mcm","clk":"1362100342","pt":1588427447096,"mc":[{"id":"1.170370557","rc":[{"atb":[[1.28,0]],"id":9624350}],"con":true,"img":false}]}
{"op":"mcm","clk":"1362100345","pt":1588427447299,"mc":[{"id":"1.170370557","rc":[{"trd":[[1.27,764.37]],"ltp":1.27,"tv":764.37,"id":9624350},{"atb":[[1.27,790.99]],"id":9624350}],"con":true,"img":false}]}
{"op":"mcm","clk":"1362100395","pt":1588427449902,"mc":[{"id":"1.170370557","rc":[{"trd":[[1.27,1473.59]],"ltp":1.27,"tv":1473.59,"id":9624350},{"atb":[[1.27,436.38],[1.25,173.22]],"id":9624350}],"con":true,"img":false}]}
{"op":"mcm","clk":"1362100398","pt":1588427450106,"mc":[{"id":"1.170370557","rc":[{"atb":[[1.3,2.18]],"id":9624350}],"con":true,"img":false}]}
{"op":"mcm","clk":"1362100411","pt":1588427450772,"mc":[{"id":"1.170370557","rc":[{"trd":[[1.3,562.96]],"ltp":1.3,"tv":562.96,"id":9624350},{"atb":[[1.3,0]],"id":9624350},{"atl":[[1.28,441.07]],"id":9624350}],"con":true,"img":false}]}
{"op":"mcm","clk":"1362100421","pt":1588427451281,"mc":[{"id":"1.170370557","rc":[{"trd":[[1.28,927.74]],"ltp":1.28,"tv":927.74,"id":9624350},{"atl":[[1.28,440.14]],"id":9624350}],"con":true,"img":false}]}
{"op":"mcm","clk":"1362100426","pt":1588427451789,"mc":[{"id":"1.170370557","rc":[{"atl":[[1.3,91.18]],"id":9624350}],"con":true,"img":false}]}
{"op":"mcm","clk":"1362100429","pt":1588427451891,"mc":[{"id":"1.170370557","rc":[{"atb":[[1.25,669.18]],"id":9624350},{"atl":[[1.28,0]],"id":9624350}],"con":true,"img":false}]}
{"op":"mcm","clk":"1362100458","pt":1588427454799,"mc":[{"id":"1.170370557","rc":[{"atl":[[1.28,447.58]],"id":9624350}],"con":true,"img":false}]}
{"op":"mcm","clk":"1362100469","pt":1588427455208,"mc":[{"id":"1.170370557","rc":[{"atb":[[1.25,1023.79]],"id":9624350}],"con":true,"img":false}]}
{"op":"mcm","clk":"1362100471","pt":1588427455310,"mc":[{"id":"1.170370557","rc":[{"trd":[[1.27,1476.51]],"ltp":1.27,"tv":1476.51,"id":9624350},{"atb":[[1.27,434.93]],"id":9624350}],"con":true,"img":false}]}
{"op":"mcm","clk":"1362100476","pt":1588427455513,"mc":[{"id":"1.170370557","rc":[{"atb":[[1.25,1080.53]],"id":9624350}],"con":true,"img":false}]}
{"op":"mcm","clk":"1362100482","pt":1588427455820,"mc":[{"id":"1.170370557","rc":[{"atb":[[1.22,443.26]],"id":9624350}],"con":true,"img":false}]}
{"op":"mcm","clk":"1362100486","pt":1588427455978,"mc":[{"id":"1.170370557","rc":[{"atb":[[1.26,354.6]],"id":9624350}],"con":true,"img":false}]}
{"op":"mcm","clk":"1362100492","pt":1588427456485,"mc":[{"id":"1.170370557","rc":[{"atl":[[1.3,0]],"id":9624350}],"con":true,"img":false}]}
{"op":"mcm","clk":"1362100494","pt":1588427456585,"mc":[{"id":"1.170370557","rc":[{"atb":[[1.22,0]],"id":9624350}],"con":true,"img":false}]}
{"op":"mcm","clk":"1362100497","pt":1588427456688,"mc":[{"id":"1.170370557","rc":[{"atl":[[1.41,175]],"id":9624350}],"con":true,"img":false}]}
{"op":"mcm","clk":"1362100501","pt":1588427456994,"mc":[{"id":"1.170370557","rc":[{"atb":[[1.24,0]],"id":9624350},{"atl":[[1.41,350],[1.31,440.14]],"id":9624350}],"con":true,"img":false}]}
{"op":"mcm","clk":"1362100509","pt":1588427457708,"mc":[{"id":"1.170370557","rc":[{"atl":[[1.32,100],[1.39,175]],"id":9624350}],"con":true,"img":false}]}
{"op":"mcm","clk":"1362100514","pt":1588427458015,"mc":[{"id":"1.170370557","rc":[{"atl":[[1.39,350]],"id":9624350}],"con":true,"img":false}]}
{"op":"mcm","clk":"1362100526","pt":1588427458680,"mc":[{"id":"1.170370557","rc":[{"atl":[[1.38,175]],"id":9624350}],"con":true,"img":false}]}
{"op":"mcm","clk":"1362100529","pt":1588427458784,"mc":[{"id":"1.170370557","rc":[{"atb":[[1.25,584.57]],"id":9624350}],"con":true,"img":false}]}
{"op":"mcm","clk":"1362100536","pt":1588427459191,"mc":[{"id":"1.170370557","rc":[{"atl":[[1.38,350]],"id":9624350}],"con":true,"img":false}]}
{"op":"mcm","clk":"1362100539","pt":1588427459395,"mc":[{"id":"1.170370557","rc":[{"atb":[[1.25,527.83]],"id":9624350}],"con":true,"img":false}]}
{"op":"mcm","clk":"1362100555","pt":1588427460725,"mc":[{"id":"1.170370557","rc":[{"atb":[[1.27,0]],"id":9624350},{"atl":[[1.28,0]],"id":9624350}],"con":true,"img":false}]}
{"op":"mcm","clk":"1362100559","pt":1588427460984,"mc":[{"id":"1.170370557","rc":[{"atb":[[1.21,23.38]],"id":9624350}],"con":true,"img":false}]}
{"op":"mcm","clk":"1362100561","pt":1588427461088,"mc":[{"id":"1.170370557","rc":[{"atb":[[1.11,60]],"id":9624350}],"con":true,"img":false}]}
{"op":"mcm","clk":"1362100565","pt":1588427461291,"mc":[{"id":"1.170370557","rc":[{"atb":[[1.01,4101.75]],"id":9624350}],"con":true,"img":false}]}
{"op":"mcm","clk":"1362100569","pt":1588427461494,"mc":[{"id":"1.170370557","rc":[{"atb":[[1.25,354.6],[1.16,692.02]],"id":9624350}],"con":true,"img":false}]}
{"op":"mcm","clk":"1362100571","pt":1588427461802,"mc":[{"id":"1.170370557","rc":[{"atl":[[1.32,0]],"id":9624350}],"con":true,"img":false}]}
{"op":"mcm","clk":"1362100577","pt":1588427462213,"mc":[{"id":"1.170370557","rc":[{"atb":[[1.21,466.65]],"id":9624350}],"con":true,"img":false}]}
{"op":"mcm","clk":"1362100598","pt":1588427463601,"mc":[{"id":"1.170370557","rc":[{"atb":[[1.27,52.52]],"id":9624350}],"con":true,"img":false}]}
{"op":"mcm","clk":"1362100603","pt":1588427463909,"mc":[{"id":"1.170370557","rc":[{"atb":[[1.28,492.37]],"id":9624350}],"con":true,"img":false}]}
{"op":"mcm","clk":"1362100616","pt":1588427464529,"mc":[{"id":"1.170370557","rc":[{"atb":[[1.27,0],[1.26,0]],"id":9624350}],"con":true,"img":false}]}
{"op":"mcm","clk":"1362100617","pt":1588427464583,"mc":[{"id":"1.170370557","rc":[{"atb":[[1.28,0]],"id":9624350}],"con":true,"img":false}]}
{"op":"mcm","clk":"1362100621","pt":1588427464688,"mc":[{"id":"1.170370557","rc":[{"atl":[[1.26,492.02]],"id":9624350}],"con":true,"img":false}]}
{"op":"mcm","clk":"1362100624","pt":1588427464891,"mc":[{"id":"1.170370557","rc":[{"trd":[[1.25,713.63]],"ltp":1.25,"tv":713.63,"id":9624350},{"atb":[[1.25,0]],"id":9624350},{"atl":[[1.25,89.39]],"id":9624350}],"con":true,"img":false}]}
{"op":"mcm","clk":"1362100632","pt":1588427465403,"mc":[{"id":"1.170370557","rc":[{"atl":[[1.26,802.3]],"id":9624350}],"con":true,"img":false}]}
{"op":"mcm","clk":"1362100640","pt":1588427465813,"mc":[{"id":"1.170370557","rc":[{"trd":[[1.26,1156.75],[1.25,892.41]],"ltp":1.26,"tv":2049.16,"id":9624350},{"atl":[[1.26,456.76],[1.25,0]],"id":9624350}],"con":true,"img":false}]}
{"op":"mcm","clk":"1362100643","pt":1588427465915,"mc":[{"id":"1.170370557","rc":[{"atb":[[1.21,464.36]],"id":9624350},{"atl":[[1.25,300]],"id":9624350}],"con":true,"img":false}]}
{"op":"mcm","clk":"1362100654","pt":1588427466427,"mc":[{"id":"1.170370557","rc":[{"atb":[[1.21,553.01]],"id":9624350}],"con":true,"img":false}]}
{"op":"mcm","clk":"1362100657","pt":1588427466529,"mc":[{"id":"1.170370557","rc":[{"atl":[[1.26,756.76]],"id":9624350}],"con":true,"img":false}]}
{"op":"mcm","clk":"1362100660","pt":1588427466583,"mc":[{"id":"1.170370557","rc":[{"atl":[[1.25,758.32]],"id":9624350}],"con":true,"img":false}]}
{"op":"mcm","clk":"1362100662","pt":1588427466888,"mc":[{"id":"1.170370557","rc":[{"trd":[[1.25,895.19]],"ltp":1.25,"tv":895.19,"id":9624350},{"atl":[[1.25,756.93]],"id":9624350}],"con":true,"img":false}]}
{"op":"mcm","clk":"1362100664","pt":1588427466989,"mc":[{"id":"1.170370557","rc":[{"trd":[[1.25,992.71]],"ltp":1.25,"tv":992.71,"id":9624350},{"atb":[[1.13,824.37]],"id":9624350},{"atl":[[1.25,458.32]],"id":9624350}],"con":true,"img":false}]}
{"op":"mcm","clk":"1362100690","pt":1588427468316,"mc":[{"id":"1.170370557","rc":[{"atl":[[1.26,456.76],[1.39,0],[1.41,0],[1.38,0]],"id":9624350}],"con":true,"img":false}]}
{"op":"mcm","clk":"1362100691","pt":1588427468418,"mc":[{"id":"1.170370557","rc":[{"atl":[[1.27,100]],"id":9624350}],"con":true,"img":false}]}
{"op":"mcm","clk":"1362100693","pt":1588427468520,"mc":[{"id":"1.170370557","rc":[{"atb":[[1.21,1053.01]],"id":9624350},{"atl":[[1.27,200]],"id":9624350}],"con":true,"img":false}]}
{"op":"mcm","clk":"1362100701","pt":1588427469030,"mc":[{"id":"1.170370557","rc":[{"atl":[[1.27,0]],"id":9624350}],"con":true,"img":false}]}
{"op":"mcm","clk":"1362100719","pt":1588427470207,"mc":[{"id":"1.170370557","rc":[{"atl":[[1.26,146.48]],"id":9624350}],"con":true,"img":false}]}
{"op":"mcm","clk":"1362100724","pt":1588427470514,"mc":[{"id":"1.170370557","rc":[{"trd":[[1.25,1008.67]],"ltp":1.25,"tv":1008.67,"id":9624350},{"atl":[[1.25,450.34]],"id":9624350}],"con":true,"img":false}]}
{"op":"mcm","clk":"1362100728","pt":1588427470617,"mc":[{"id":"1.170370557","rc":[{"atl":[[1.7,2.19]],"id":9624350}],"con":true,"img":false}]}
{"op":"mcm","clk":"1362100735","pt":1588427470923,"mc":[{"id":"1.170370557","rc":[{"atl":[[1.26,589.74]],"id":9624350}],"con":true,"img":false}]}
{"op":"mcm","clk":"1362100741","pt":1588427471229,"mc":[{"id":"1.170370557","rc":[{"trd":[[1.25,1705.29]],"ltp":1.25,"tv":1705.29,"id":9624350},{"atl":[[1.25,102.03]],"id":9624350}],"con":true,"img":false}]}
{"op":"mcm","clk":"1362100748","pt":1588427471792,"mc":[{"id":"1.170370557","rc":[{"atb":[[1.21,1553.01],[1.23,473.47],[1.24,59.09]],"id":9624350}],"con":true,"img":false}]}
{"op":"mcm","clk":"1362100750","pt":1588427471895,"mc":[{"id":"1.170370557","rc":[{"trd":[[1.24,767.24]],"ltp":1.24,"tv":767.24,"id":9624350},{"atb":[[1.24,0]],"id":9624350},{"atl":[[1.24,295.51]],"id":9624350}],"con":true,"img":false}]}
{"op":"mcm","clk":"1362100754","pt":1588427472201,"mc":[{"id":"1.170370557","rc":[{"atb":[[1.23,20]],"id":9624350}],"con":true,"img":false}]}
{"op":"mcm","clk":"1362100763","pt":1588427472710,"mc":[{"id":"1.170370557","rc":[{"atb":[[1.21,1109.75],[1.23,199.32]],"id":9624350}],"con":true,"img":false}]}
{"op":"mcm","clk":"1362100765","pt":1588427472812,"mc":[{"id":"1.170370557","rc":[{"atb":[[1.22,62.02]],"id":9624350}],"con":true,"img":false}]}
{"op":"mcm","clk":"1362100775","pt":1588427473221,"mc":[{"id":"1.170370557","rc":[{"atl":[[1.26,443.26]],"id":9624350}],"con":true,"img":false}]}
{"op":"mcm","clk":"1362100780","pt":1588427473426,"mc":[{"id":"1.170370557","rc":[{"trd":[[1.24,868.38]],"ltp":1.24,"tv":868.38,"id":9624350},{"atl":[[1.24,244.94]],"id":9624350}],"con":true,"img":false}]}
{"op":"mcm","clk":"1362100788","pt":1588427473631,"mc":[{"id":"1.170370557","rc":[{"trd":[[1.24,1358.28]],"ltp":1.24,"tv":1358.28,"id":9624350},{"atb":[[1.24,204.86]],"id":9624350},{"atl":[[1.24,0]],"id":9624350}],"con":true,"img":false}]}
{"op":"mcm","clk":"1362100808","pt":1588427475315,"mc":[{"id":"1.170370557","rc":[{"atb":[[1.23,519.69]],"id":9624350}],"con":true,"img":false}]}
{"op":"mcm","clk":"1362100812","pt":1588427475723,"mc":[{"id":"1.170370557","rc":[{"trd":[[1.25,1708.05]],"ltp":1.25,"tv":1708.05,"id":9624350},{"atl":[[1.25,100.65]],"id":9624350}],"con":true,"img":false}]}
{"op":"mcm","clk":"1362100814","pt":1588427475825,"mc":[{"id":"1.170370557","rc":[{"trd":[[1.25,1740.05]],"ltp":1.25,"tv":1740.05,"id":9624350},{"atl":[[1.25,84.65]],"id":9624350}],"con":true,"img":false}]}
{"op":"mcm","clk":"1362100819","pt":1588427476028,"mc":[{"id":"1.170370557","rc":[{"atl":[[1.25,0]],"id":9624350}],"con":true,"img":false}]}
{"op":"mcm","clk":"1362100823","pt":1588427476233,"mc":[{"id":"1.170370557","rc":[{"atl":[[1.31,0]],"id":9624350}],"con":true,"img":false}]}
{"op":"mcm","clk":"1362100825","pt":1588427476335,"mc":[{"id":"1.170370557","rc":[{"atl":[[1.27,79.98]],"id":9624350}],"con":true,"img":false}]}
{"op":"mcm","clk":"1362100829","pt":1588427476538,"mc":[{"id":"1.170370557","rc":[{"atb":[[1.22,416.62]],"id":9624350}],"con":true,"img":false}]}
{"op":"mcm","clk":"1362100835","pt":1588427476899,"mc":[{"id":"1.170370557","rc":[{"atb":[[4.8,11]],"id":9622734},{"atb":[[1.25,0.92]],"id":9624350}],"con":true,"img":false}]}
{"op":"mcm","clk":"1362100837","pt":1588427477002,"mc":[{"id":"1.170370557","rc":[{"atb":[[1.25,1.04]],"id":9624350}],"con":true,"img":false}]}
{"op":"mcm","clk":"1362100842","pt":1588427477813,"mc":[{"id":"1.170370557","rc":[{"atb":[[1.18,938.47]],"id":9624350}],"con":true,"img":false}]}
{"op":"mcm","clk":"1362100846","pt":1588427478223,"mc":[{"id":"1.170370557","rc":[{"atl":[[1.27,0]],"id":9624350}],"con":true,"img":false}]}
{"op":"mcm","clk":"1362100848","pt":1588427478326,"mc":[{"id":"1.170370557","rc":[{"atb":[[1.24,713.11]],"id":9624350}],"con":true,"img":false}]}
{"op":"mcm","clk":"1362100849","pt":1588427478428,"mc":[{"id":"1.170370557","rc":[{"atb":[[1.25,21.04]],"id":9624350}],"con":true,"img":false}]}
{"op":"mcm","clk":"1362100864","pt":1588427479502,"mc":[{"id":"1.170370557","rc":[{"atb":[[1.2,754.32]],"id":9624350}],"con":true,"img":false}]}
{"op":"mcm","clk":"1362100867","pt":1588427479605,"mc":[{"id":"1.170370557","rc":[{"atb":[[1.24,204.86]],"id":9624350}],"con":true,"img":false}]}
{"op":"mcm","clk":"1362100869","pt":1588427479810,"mc":[{"id":"1.170370557","rc":[{"trd":[[1.26,1604.51]],"ltp":1.26,"tv":1604.51,"id":9624350},{"atb":[[1.23,1019.69]],"id":9624350},{"atl":[[1.26,219.37]],"id":9624350}],"con":true,"img":false}]}
{"op":"mcm","clk":"1362100892","pt":1588427481239,"mc":[{"id":"1.170370557","rc":[{"atb":[[1.24,0]],"id":9624350}],"con":true,"img":false}]}
{"op":"mcm","clk":"1362100896","pt":1588427481499,"mc":[{"id":"1.170370557","rc":[{"atb":[[1.11,62.57]],"id":9624350}],"con":true,"img":false}]}
{"op":"mcm","clk":"1362100898","pt":1588427481602,"mc":[{"id":"1.170370557","rc":[{"atb":[[1.25,525.23],[1.22,456.92]],"id":9624350},{"atl":[[1000,3.03]],"id":9624350}],"con":true,"img":false}]}
{"op":"mcm","clk":"1362100900","pt":1588427481702,"mc":[{"id":"1.170370557","rc":[{"atl":[[1.32,443.26]],"id":9624350}],"con":true,"img":false}]}
{"op":"mcm","clk":"1362100905","pt":1588427482009,"mc":[{"id":"1.170370557","rc":[{"atb":[[1.23,699.32]],"id":9624350}],"con":true,"img":false}]}
{"op":"mcm","clk":"1362100914","pt":1588427482517,"mc":[{"id":"1.170370557","rc":[{"atl":[[1000,0.45]],"id":9624350}],"con":true,"img":false}]}
{"op":"mcm","clk":"1362100915","pt":1588427482619,"mc":[{"id":"1.170370557","rc":[{"atb":[[1.25,21.04]],"id":9624350}],"con":true,"img":false}]}
{"op":"mcm","clk":"1362100918","pt":1588427482824,"mc":[{"id":"1.170370557","rc":[{"atb":[[1.23,520]],"id":9624350}],"con":true,"img":false}]}
{"op":"mcm","clk":"1362100921","pt":1588427482926,"mc":[{"id":"1.170370557","rc":[{"atb":[[1.21,109.75],[1.23,20]],"id":9624350}],"con":true,"img":false}]}
{"op":"mcm","clk":"1362100926","pt":1588427483439,"mc":[{"id":"1.170370557","rc":[{"atl":[[1000,0]],"id":9624350}],"con":true,"img":false}]}
{"op":"mcm","clk":"1362100927","pt":1588427483642,"mc":[{"id":"1.170370557","rc":[{"atb":[[1.13,492.02]],"id":9624350},{"atl":[[1.58,0]],"id":9624350}],"con":true,"img":false}]}
{"op":"mcm","clk":"1362100938","pt":1588427484514,"mc":[{"id":"1.170370557","rc":[{"atb":[[1.22,102.31]],"id":9624350}],"con":true,"img":false}]}
{"op":"mcm","clk":"1362100940","pt":1588427484615,"mc":[{"id":"1.170370557","rc":[{"atb":[[1.21,21.09]],"id":9624350}],"con":true,"img":false}]}
{"op":"mcm","clk":"1362100946","pt":1588427485020,"mc":[{"id":"1.170370557","rc":[{"atb":[[1.2,1049.54]],"id":9624350}],"con":true,"img":false}]}
{"op":"mcm","clk":"1362100952","pt":1588427485430,"mc":[{"id":"1.170370557","rc":[{"atb":[[1.22,40.29]],"id":9624350}],"con":true,"img":false}]}
{"op":"mcm","clk":"1362100962","pt":1588427485839,"mc":[{"id":"1.170370557","rc":[{"atb":[[1.25,22.81]],"id":9624350}],"con":true,"img":false}]}
{"op":"mcm","clk":"1362100964","pt":1588427485942,"mc":[{"id":"1.170370557","rc":[{"trd":[[1.25,1747.17]],"ltp":1.25,"tv":1747.17,"id":9624350},{"atb":[[1.25,18.21],[1.22,0]],"id":9624350}],"con":true,"img":false}]}
{"op":"mcm","clk":"1362100968","pt":1588427486146,"mc":[{"id":"1.170370557","rc":[{"trd":[[1.25,1783.59]],"ltp":1.25,"tv":1783.59,"id":9624350},{"atb":[[1.25,0]],"id":9624350},{"atl":[[1.24,473.81]],"id":9624350}],"con":true,"img":false}]}
{"op":"mcm","clk":"1362100982","pt":1588427486711,"mc":[{"id":"1.170370557","rc":[{"atl":[[1.24,917.81]],"id":9624350}],"con":true,"img":false}]}
{"op":"mcm","clk":"1362100987","pt":1588427486914,"mc":[{"id":"1.170370557","rc":[{"atb":[[1.23,428.67]],"id":9624350}],"con":true,"img":false}]}
{"op":"mcm","clk":"1362100998","pt":1588427487321,"mc":[{"id":"1.170370557","rc":[{"atb":[[1.23,20]],"id":9624350}],"con":true,"img":false}]}
{"op":"mcm","clk":"1362101003","pt":1588427487423,"mc":[{"id":"1.170370557","rc":[{"atl":[[1.25,300]],"id":9624350}],"con":true,"img":false}]}
{"op":"mcm","clk":"1362101015","pt":1588427487933,"mc":[{"id":"1.170370557","rc":[{"atl":[[1.25,600]],"id":9624350}],"con":true,"img":false}]}
{"op":"mcm","clk":"1362101020","pt":1588427488240,"mc":[{"id":"1.170370557","rc":[{"atl":[[1.24,921.25]],"id":9624350}],"con":true,"img":false}]}
{"op":"mcm","clk":"1362101025","pt":1588427488546,"mc":[{"id":"1.170370557","rc":[{"atl":[[1.24,921.7]],"id":9624350}],"con":true,"img":false}]}
{"op":"mcm","clk":"1362101028","pt":1588427488750,"mc":[{"id":"1.170370557","rc":[{"atb":[[1.18,495.21]],"id":9624350},{"atl":[[1.43,0],[1.26,0],[1.32,0],[1.24,477.7]],"id":9624350}],"con":true,"img":false}]}
{"op":"mcm","clk":"1362101031","pt":1588427488909,"mc":[{"id":"1.170370557","rc":[{"atb":[[1.22,516.58]],"id":9624350}],"con":true,"img":false}]}
{"op":"mcm","clk":"1362101033","pt":1588427489009,"mc":[{"id":"1.170370557","rc":[{"atb":[[1.21,231.03]],"id":9624350}],"con":true,"img":false}]}
{"op":"mcm","clk":"1362101037","pt":1588427489113,"mc":[{"id":"1.170370557","rc":[{"atb":[[1.11,423.6]],"id":9624350},{"atl":[[1.49,401.83],[1.24,777.7]],"id":9624350}],"con":true,"img":false}]}
{"op":"mcm","clk":"1362101043","pt":1588427489520,"mc":[{"id":"1.170370557","rc":[{"atb":[[1.2,1261.23]],"id":9624350}],"con":true,"img":false}]}
{"op":"mcm","clk":"1362101056","pt":1588427490337,"mc":[{"id":"1.170370557","rc":[{"atl":[[1.25,653.98]],"id":9624350}],"con":true,"img":false}]}
{"op":"mcm","clk":"1362101059","pt":1588427490439,"mc":[{"id":"1.170370557","rc":[{"atl":[[1.24,477.7]],"id":9624350}],"con":true,"img":false}]}
{"op":"mcm","clk":"1362101070","pt":1588427491007,"mc":[{"id":"1.170370557","rc":[{"trd":[[1.24,1371.35]],"ltp":1.24,"tv":1371.35,"id":9624350},{"atb":[[1.14,510.63]],"id":9624350},{"atl":[[1.24,471.17]],"id":9624350}],"con":true,"img":false}]}
{"op":"mcm","clk":"1362101077","pt":1588427491314,"mc":[{"id":"1.170370557","rc":[{"atb":[[1.23,38.35]],"id":9624350}],"con":true,"img":false}]}
{"op":"mcm","clk":"1362101080","pt":1588427491417,"mc":[{"id":"1.170370557","rc":[{"atb":[[1.21,585.64]],"id":9624350}],"con":true,"img":false}]}
{"op":"mcm","clk":"1362101088","pt":1588427491726,"mc":[{"id":"1.170370557","rc":[{"atb":[[1.21,627.85]],"id":9624350}],"con":true,"img":false}]}
{"op":"mcm","clk":"1362101102","pt":1588427492335,"mc":[{"id":"1.170370557","rc":[{"trd":[[1.23,275.83]],"ltp":1.23,"tv":275.83,"id":9624350},{"atb":[[1.23,31.45]],"id":9624350}],"con":true,"img":false}]}
{"op":"mcm","clk":"1362101112","pt":1588427492743,"mc":[{"id":"1.170370557","rc":[{"atl":[[1.24,551.15]],"id":9624350}],"con":true,"img":false}]}
{"op":"mcm","clk":"1362101116","pt":1588427493051,"mc":[{"id":"1.170370557","rc":[{"atl":[[1.6,0.28]],"id":9624350}],"con":true,"img":false}]}
{"op":"mcm","clk":"1362101120","pt":1588427493256,"mc":[{"id":"1.170370557","rc":[{"trd":[[1.24,1403.07]],"ltp":1.24,"tv":1403.07,"id":9624350},{"atl":[[1.24,535.29]],"id":9624350}],"con":true,"img":false}]}
{"op":"mcm","clk":"1362101123","pt":1588427493309,"mc":[{"id":"1.170370557","rc":[{"atb":[[1.22,928.6]],"id":9624350}],"con":true,"img":false}]}
{"op":"mcm","clk":"1362101126","pt":1588427493411,"mc":[{"id":"1.170370557","rc":[{"atb":[[1.22,1251.6]],"id":9624350}],"con":true,"img":false}]}
{"op":"mcm","clk":"1362101133","pt":1588427493718,"mc":[{"id":"1.170370557","rc":[{"atl":[[1.25,659.66]],"id":9624350}],"con":true,"img":false}]}
{"op":"mcm","clk":"1362101139","pt":1588427494025,"mc":[{"id":"1.170370557","rc":[{"atb":[[1.11,421.02]],"id":9624350}],"con":true,"img":false}]}
{"op":"mcm","clk":"1362101141","pt":1588427494124,"mc":[{"id":"1.170370557","rc":[{"atb":[[1.21,690.38]],"id":9624350}],"con":true,"img":false}]}
{"op":"mcm","clk":"1362101149","pt":1588427494532,"mc":[{"id":"1.170370557","rc":[{"atb":[[1.22,928.6]],"id":9624350}],"con":true,"img":false}]}
{"op":"mcm","clk":"1362101153","pt":1588427494637,"mc":[{"id":"1.170370557","rc":[{"atl":[[1.29,443.26]],"id":9624350}],"con":true,"img":false}]}
{"op":"mcm","clk":"1362101165","pt":1588427495247,"mc":[{"id":"1.170370557","rc":[{"atl":[[1.24,83.88]],"id":9624350}],"con":true,"img":false}]}
{"op":"mcm","clk":"1362101168","pt":1588427495350,"mc":[{"id":"1.170370557","rc":[{"atl":[[1.24,3.89]],"id":9624350}],"con":true,"img":false}]}
{"op":"mcm","clk":"1362101172","pt":1588427495453,"mc":[{"id":"1.170370557","rc":[{"atb":[[1.18,583.86]],"id":9624350}],"con":true,"img":false}]}
{"op":"mcm","clk":"1362101197","pt":1588427496531,"mc":[{"id":"1.170370557","rc":[{"atb":[[1.23,38.04]],"id":9624350}],"con":true,"img":false}]}
{"op":"mcm","clk":"1362101207","pt":1588427497243,"mc":[{"id":"1.170370557","rc":[{"atb":[[1.2,1704.49]],"id":9624350}],"con":true,"img":false}]}
{"op":"mcm","clk":"1362101217","pt":1588427497855,"mc":[{"id":"1.170370557","rc":[{"atb":[[1.2,1492.8]],"id":9624350}],"con":true,"img":false}]}
{"op":"mcm","clk":"1362101234","pt":1588427498726,"mc":[{"id":"1.170370557","rc":[{"atb":[[1.23,54.03]],"id":9624350}],"con":true,"img":false}]}
{"op":"mcm","clk":"1362101240","pt":1588427499132,"mc":[{"id":"1.170370557","rc":[{"atb":[[1.21,1190.38]],"id":9624350}],"con":true,"img":false}]}
{"op":"mcm","clk":"1362101248","pt":1588427499642,"mc":[{"id":"1.170370557","rc":[{"atb":[[1.23,374.41],[1.22,1128.6]],"id":9624350}],"con":true,"img":false}]}
{"op":"mcm","clk":"1362101256","pt":1588427500255,"mc":[{"id":"1.170370557","rc":[{"atb":[[1.21,1390.38],[1.22,1628.6]],"id":9624350},{"atl":[[1000,3.19]],"id":9624350}],"con":true,"img":false}]}
{"op":"mcm","clk":"1362101259","pt":1588427500357,"mc":[{"id":"1.170370557","rc":[{"atb":[[1.23,333.47],[1.22,1112.02]],"id":9624350}],"con":true,"img":false}]}
{"op":"mcm","clk":"1362101261","pt":1588427500460,"mc":[{"id":"1.170370557","rc":[{"atl":[[1000,0.87]],"id":9624350}],"con":true,"img":false}]}
{"op":"mcm","clk":"1362101266","pt":1588427500718,"mc":[{"id":"1.170370557","rc":[{"atl":[[1000,0]],"id":9624350}],"con":true,"img":false}]}
{"op":"mcm","clk":"1362101271","pt":1588427501024,"mc":[{"id":"1.170370557","rc":[{"atb":[[1.22,700]],"id":9624350}],"con":true,"img":false}]}
{"op":"mcm","clk":"1362101280","pt":1588427501840,"mc":[{"id":"1.170370557","rc":[{"atb":[[1.21,1348.17]],"id":9624350}],"con":true,"img":false}]}
{"op":"mcm","clk":"1362101287","pt":1588427502455,"mc":[{"id":"1.170370557","rc":[{"trd":[[1.23,285.03]],"ltp":1.23,"tv":285.03,"id":9624350},{"atb":[[1.23,328.87]],"id":9624350}],"con":true,"img":false}]}
{"op":"mcm","clk":"1362101289","pt":1588427502659,"mc":[{"id":"1.170370557","rc":[{"atb":[[1.23,506.17]],"id":9624350}],"con":true,"img":false}]}
{"op":"mcm","clk":"1362101292","pt":1588427502863,"mc":[{"id":"1.170370557","rc":[{"atl":[[1.28,295.21]],"id":9624350}],"con":true,"img":false}]}
{"op":"mcm","clk":"1362101308","pt":1588427504041,"mc":[{"id":"1.170370557","rc":[{"atl":[[1.25,59.66]],"id":9624350}],"con":true,"img":false}]}
{"op":"mcm","clk":"1362101336","pt":1588427505421,"mc":[{"id":"1.170370557","rc":[{"trd":[[1.24,1410.85]],"ltp":1.24,"tv":1410.85,"id":9624350},{"atb":[[1.24,545.11]],"id":9624350},{"atl":[[1.24,0]],"id":9624350}],"con":true,"img":false}]}
{"op":"mcm","clk":"1362101348","pt":1588427505829,"mc":[{"id":"1.170370557","rc":[{"trd":[[1.24,1412.61]],"ltp":1.24,"tv":1412.61,"id":9624350},{"atb":[[1.24,544.23]],"id":9624350}],"con":true,"img":false}]}
{"op":"mcm","clk":"1362101353","pt":1588427506137,"mc":[{"id":"1.170370557","rc":[{"atb":[[1.23,544.71]],"id":9624350}],"con":true,"img":false}]}
{"op":"mcm","clk":"1362101379","pt":1588427507462,"mc":[{"id":"1.170370557","rc":[{"trd":[[1.24,1428.96]],"ltp":1.24,"tv":1428.96,"id":9624350},{"atb":[[1.24,536.06]],"id":9624350}],"con":true,"img":false}]}
{"op":"mcm","clk":"1362101407","pt":1588427508542,"mc":[{"id":"1.170370557","rc":[{"trd":[[1.24,1462.7]],"ltp":1.24,"tv":1462.7,"id":9624350},{"atb":[[1.24,519.19]],"id":9624350}],"con":true,"img":false}]}
{"op":"mcm","clk":"1362101412","pt":1588427508640,"mc":[{"id":"1.170370557","rc":[{"atb":[[1.24,519.45]],"id":9624350}],"con":true,"img":false}]}
{"op":"mcm","clk":"1362101448","pt":1588427510838,"mc":[{"id":"1.170370557","rc":[{"atb":[[1.24,519.63]],"id":9624350}],"con":true,"img":false}]}
{"op":"mcm","clk":"1362101526","pt":1588427514832,"mc":[{"id":"1.170370557","rc":[{"atb":[[1.21,1327.07]],"id":9624350}],"con":true,"img":false}]}
{"op":"mcm","clk":"1362101527","pt":1588427514930,"mc":[{"id":"1.170370557","rc":[{"atb":[[4.8,0]],"id":9622734}],"con":true,"img":false}]}
{"op":"mcm","clk":"1362101529","pt":1588427515035,"mc":[{"id":"1.170370557","rc":[{"atb":[[1.23,367.4]],"id":9624350}],"con":true,"img":false}]}
{"op":"mcm","clk":"1362101540","pt":1588427515749,"mc":[{"id":"1.170370557","rc":[{"trd":[[1.25,1783.84]],"ltp":1.25,"tv":1783.84,"id":9624350},{"atl":[[1.25,59.54]],"id":9624350}],"con":true,"img":false}]}
{"op":"mcm","clk":"1362101568","pt":1588427517636,"mc":[{"id":"1.170370557","rc":[{"trd":[[1.25,1902.92]],"ltp":1.25,"tv":1902.92,"id":9624350},{"atb":[[1.25,73.43]],"id":9624350},{"atl":[[1.25,0]],"id":9624350}],"con":true,"img":false}]}
{"op":"mcm","clk":"1362101591","pt":1588427519371,"mc":[{"id":"1.170370557","rc":[{"atb":[[1.25,74.61]],"id":9624350}],"con":true,"img":false}]}
{"op":"mcm","clk":"1362101600","pt":1588427520036,"mc":[{"id":"1.170370557","rc":[{"trd":[[1.25,1912.13]],"ltp":1.25,"tv":1912.13,"id":9624350},{"atb":[[1.25,70.01]],"id":9624350}],"con":true,"img":false}]}
{"op":"mcm","clk":"1362101615","pt":1588427520853,"mc":[{"id":"1.170370557","rc":[{"trd":[[1.25,2012.13]],"ltp":1.25,"tv":2012.13,"id":9624350},{"atb":[[1.25,20.01]],"id":9624350}],"con":true,"img":false}]}
{"op":"mcm","clk":"1362101634","pt":1588427521775,"mc":[{"id":"1.170370557","rc":[{"atb":[[1.25,20.19]],"id":9624350}],"con":true,"img":false}]}
{"op":"mcm","clk":"1362101657","pt":1588427522859,"mc":[{"id":"1.170370557","rc":[{"atb":[[1.23,47.03]],"id":9624350}],"con":true,"img":false}]}
{"op":"mcm","clk":"1362101666","pt":1588427523164,"mc":[{"id":"1.170370557","rc":[{"trd":[[1.25,2038.73]],"ltp":1.25,"tv":2038.73,"id":9624350},{"atb":[[1.25,6.89]],"id":9624350}],"con":true,"img":false}]}
{"op":"mcm","clk":"1362101668","pt":1588427523266,"mc":[{"id":"1.170370557","rc":[{"atb":[[1.25,1.35]],"id":9624350}],"con":true,"img":false}]}
{"op":"mcm","clk":"1362101686","pt":1588427524145,"mc":[{"id":"1.170370557","rc":[{"atb":[[1.22,200]],"id":9624350}],"con":true,"img":false}]}
{"op":"mcm","clk":"1362101696","pt":1588427524657,"mc":[{"id":"1.170370557","rc":[{"atb":[[1.11,60]],"id":9624350}],"con":true,"img":false}]}
{"op":"mcm","clk":"1362101698","pt":1588427524764,"mc":[{"id":"1.170370557","rc":[{"atb":[[1.21,827.07]],"id":9624350}],"con":true,"img":false}]}
{"op":"mcm","clk":"1362101707","pt":1588427525373,"mc":[{"id":"1.170370557","rc":[{"atb":[[1.24,519.45]],"id":9624350}],"con":true,"img":false}]}
{"op":"mcm","clk":"1362101714","pt":1588427526087,"mc":[{"id":"1.170370557","rc":[{"atb":[[1.25,1.17]],"id":9624350}],"con":true,"img":false}]}
{"op":"mcm","clk":"1362101727","pt":1588427527058,"mc":[{"id":"1.170370557","rc":[{"trd":[[1.25,2041.08]],"ltp":1.25,"tv":2041.08,"id":9624350},{"atb":[[1.25,0]],"id":9624350},{"atl":[[1.25,490.84]],"id":9624350}],"con":true,"img":false}]}
{"op":"mcm","clk":"1362101729","pt":1588427527159,"mc":[{"id":"1.170370557","rc":[{"trd":[[1.24,1493.69]],"ltp":1.24,"tv":1493.69,"id":9624350},{"atb":[[1.24,503.95]],"id":9624350}],"con":true,"img":false}]}
{"op":"mcm","clk":"1362101731","pt":1588427527260,"mc":[{"id":"1.170370557","rc":[{"atb":[[1.23,8.5]],"id":9624350}],"con":true,"img":false}]}
{"op":"mcm","clk":"1362101736","pt":1588427527668,"mc":[{"id":"1.170370557","rc":[{"atb":[[1.2,1049.54]],"id":9624350}],"con":true,"img":false}]}
{"op":"mcm","clk":"1362101741","pt":1588427527972,"mc":[{"id":"1.170370557","rc":[{"atl":[[1.25,934.84]],"id":9624350}],"con":true,"img":false}]}
{"op":"mcm","clk":"1362101743","pt":1588427528074,"mc":[{"id":"1.170370557","rc":[{"trd":[[5,0.23]],"ltp":5.0,"tv":0.23,"id":9622734},{"trd":[[1.25,2042.01]],"ltp":1.25,"tv":2042.01,"id":9624350},{"atl":[[1.25,933.91]],"id":9624350}],"con":true,"img":false}]}
{"op":"mcm","clk":"1362101757","pt":1588427528889,"mc":[{"id":"1.170370557","rc":[{"atb":[[1.23,287.65]],"id":9624350}],"con":true,"img":false}]}
{"op":"mcm","clk":"1362101761","pt":1588427529044,"mc":[{"id":"1.170370557","rc":[{"atl":[[1.25,934.02]],"id":9624350}],"con":true,"img":false}]}
{"op":"mcm","clk":"1362101770","pt":1588427529657,"mc":[{"id":"1.170370557","rc":[{"atl":[[1.27,300]],"id":9624350}],"con":true,"img":false}]}
{"op":"mcm","clk":"1362101775","pt":1588427529960,"mc":[{"id":"1.170370557","rc":[{"atl":[[1.27,600],[1.25,1377.29]],"id":9624350}],"con":true,"img":false}]}
{"op":"mcm","clk":"1362101776","pt":1588427530062,"mc":[{"id":"1.170370557","rc":[{"atl":[[1.25,1390.58]],"id":9624350}],"con":true,"img":false}]}
{"op":"mcm","clk":"1362101778","pt":1588427530165,"mc":[{"id":"1.170370557","rc":[{"atb":[[1.09,411.32]],"id":9624350}],"con":true,"img":false}]}
{"op":"mcm","clk":"1362101781","pt":1588427530369,"mc":[{"id":"1.170370557","rc":[{"atl":[[1.25,1410.09]],"id":9624350}],"con":true,"img":false}]}
{"op":"mcm","clk":"1362101787","pt":1588427530978,"mc":[{"id":"1.170370557","rc":[{"trd":[[1.24,1582.34]],"ltp":1.24,"tv":1582.34,"id":9624350},{"atb":[[1.24,459.63]],"id":9624350},{"atl":[[1.28,0],[1.25,1429.59]],"id":9624350}],"con":true,"img":false}]}
{"op":"mcm","clk":"1362101790","pt":1588427531182,"mc":[{"id":"1.170370557","rc":[{"atb":[[1.21,1127.07]],"id":9624350}],"con":true,"img":false}]}
{"op":"mcm","clk":"1362101792","pt":1588427531284,"mc":[{"id":"1.170370557","rc":[{"atl":[[1.25,1435.8]],"id":9624350}],"con":true,"img":false}]}
{"op":"mcm","clk":"1362101794","pt":1588427531386,"mc":[{"id":"1.170370557","rc":[{"atl":[[1.25,1422.5]],"id":9624350}],"con":true,"img":false}]}
{"op":"mcm","clk":"1362101796","pt":1588427531489,"mc":[{"id":"1.170370557","rc":[{"trd":[[1.25,2070.01]],"ltp":1.25,"tv":2070.01,"id":9624350},{"atb":[[1.21,1427.07]],"id":9624350},{"atl":[[1.25,1408.5]],"id":9624350}],"con":true,"img":false}]}
{"op":"mcm","clk":"1362101798","pt":1588427531544,"mc":[{"id":"1.170370557","rc":[{"atl":[[1.25,1428]],"id":9624350}],"con":true,"img":false}]}
{"op":"mcm","clk":"1362101801","pt":1588427531645,"mc":[{"id":"1.170370557","rc":[{"trd":[[1.24,1671]],"ltp":1.24,"tv":1671.0,"id":9624350},{"atb":[[1.24,415.3]],"id":9624350},{"atl":[[1.25,1408.5]],"id":9624350}],"con":true,"img":false}]}
{"op":"mcm","clk":"1362101806","pt":1588427531950,"mc":[{"id":"1.170370557","rc":[{"atb":[[1.22,500]],"id":9624350}],"con":true,"img":false}]}
{"op":"mcm","clk":"1362101809","pt":1588427532058,"mc":[{"id":"1.170370557","rc":[{"trd":[[1.24,1759.65]],"ltp":1.24,"tv":1759.65,"id":9624350},{"atb":[[1.24,370.98]],"id":9624350}],"con":true,"img":false}]}
{"op":"mcm","clk":"1362101812","pt":1588427532160,"mc":[{"id":"1.170370557","rc":[{"atl":[[1.25,1389]],"id":9624350}],"con":true,"img":false}]}
{"op":"mcm","clk":"1362101815","pt":1588427532261,"mc":[{"id":"1.170370557","rc":[{"atb":[[1.01,4103.53],[1.22,800]],"id":9624350}],"con":true,"img":false}]}
{"op":"mcm","clk":"1362101817","pt":1588427532363,"mc":[{"id":"1.170370557","rc":[{"trd":[[1.24,1866.03]],"ltp":1.24,"tv":1866.03,"id":9624350},{"atb":[[1.24,317.78]],"id":9624350}],"con":true,"img":false}]}
{"op":"mcm","clk":"1362101819","pt":1588427532465,"mc":[{"id":"1.170370557","rc":[{"atb":[[1.01,4102.94]],"id":9624350},{"atl":[[1.25,1382.79]],"id":9624350}],"con":true,"img":false}]}
{"op":"mcm","clk":"1362101822","pt":1588427532670,"mc":[{"id":"1.170370557","rc":[{"atb":[[1.01,4101.75]],"id":9624350}],"con":true,"img":false}]}
{"op":"mcm","clk":"1362101825","pt":1588427532774,"mc":[{"id":"1.170370557","rc":[{"trd":[[1.24,1954.68]],"ltp":1.24,"tv":1954.68,"id":9624350},{"atb":[[1.24,273.46]],"id":9624350}],"con":true,"img":false}]}
{"op":"mcm","clk":"1362101828","pt":1588427532975,"mc":[{"id":"1.170370557","rc":[{"atl":[[1.25,1363.29]],"id":9624350}],"con":true,"img":false}]}
{"op":"mcm","clk":"1362101831","pt":1588427533077,"mc":[{"id":"1.170370557","rc":[{"trd":[[1.24,2033.76]],"ltp":1.24,"tv":2033.76,"id":9624350},{"atb":[[1.24,233.92]],"id":9624350}],"con":true,"img":false}]}
{"op":"mcm","clk":"1362101839","pt":1588427533381,"mc":[{"id":"1.170370557","rc":[{"trd":[[1.24,2081.76]],"ltp":1.24,"tv":2081.76,"id":9624350},{"atb":[[1.01,4103.53],[1.24,209.92]],"id":9624350}],"con":true,"img":false}]}
{"op":"mcm","clk":"1362101840","pt":1588427533483,"mc":[{"id":"1.170370557","rc":[{"trd":[[1.24,2197.01]],"ltp":1.24,"tv":2197.01,"id":9624350},{"atb":[[1.18,495.21],[1.24,152.3]],"id":9624350}],"con":true,"img":false}]}
{"op":"mcm","clk":"1362101842","pt":1588427533585,"mc":[{"id":"1.170370557","rc":[{"trd":[[1.24,2285.66]],"ltp":1.24,"tv":2285.66,"id":9624350},{"atb":[[1.01,4102.69],[1.24,107.97]],"id":9624350}],"con":true,"img":false}]}
{"op":"mcm","clk":"1362101849","pt":1588427533891,"mc":[{"id":"1.170370557","rc":[{"atb":[[1.01,4101.75]],"id":9624350}],"con":true,"img":false}]}
{"op":"mcm","clk":"1362101851","pt":1588427534045,"mc":[{"id":"1.170370557","rc":[{"trd":[[5.2,10.54]],"ltp":5.2,"tv":10.54,"id":9622734},{"trd":[[1.24,2329.9]],"ltp":1.24,"tv":2329.9,"id":9624350},{"atb":[[1.24,63.73]],"id":9624350}],"con":true,"img":false}]}
{"op":"mcm","clk":"1362101858","pt":1588427534353,"mc":[{"id":"1.170370557","rc":[{"trd":[[5.2,21.09]],"ltp":5.2,"tv":21.09,"id":9622734},{"trd":[[1.24,2374.13]],"ltp":1.24,"tv":2374.13,"id":9624350},{"atb":[[1.24,19.5]],"id":9624350}],"con":true,"img":false}]}
{"op":"mcm","clk":"1362101860","pt":1588427534455,"mc":[{"id":"1.170370557","rc":[{"trd":[[1.24,2413.14]],"ltp":1.24,"tv":2413.14,"id":9624350},{"atb":[[1.24,0]],"id":9624350},{"atl":[[1.24,24.82]],"id":9624350}],"con":true,"img":false}]}
{"op":"mcm","clk":"1362101863","pt":1588427534567,"mc":[{"id":"1.170370557","rc":[{"atl":[[1.27,610.2]],"id":9624350}],"con":true,"img":false}]}
{"op":"mcm","clk":"1362101870","pt":1588427535071,"mc":[{"id":"1.170370557","rc":[{"atl":[[1.24,48.81]],"id":9624350}],"con":true,"img":false}]}
{"op":"mcm","clk":"1362101873","pt":1588427535172,"mc":[{"id":"1.170370557","rc":[{"atl":[[1.24,75.41]],"id":9624350}],"con":true,"img":false}]}
{"op":"mcm","clk":"1362101875","pt":1588427535273,"mc":[{"id":"1.170370557","rc":[{"trd":[[5.4,8.3]],"ltp":5.4,"tv":8.3,"id":9622734},{"trd":[[1.23,321.51]],"ltp":1.23,"tv":321.51,"id":9624350},{"atb":[[1.23,251.17]],"id":9624350},{"atl":[[1.24,99.41]],"id":9624350}],"con":true,"img":false}]}
{"op":"mcm","clk":"1362101884","pt":1588427535781,"mc":[{"id":"1.170370557","rc":[{"atl":[[1.24,74.58]],"id":9624350}],"con":true,"img":false}]}
{"op":"mcm","clk":"1362101886","pt":1588427536087,"mc":[{"id":"1.170370557","rc":[{"atb":[[1.23,451.17]],"id":9624350},{"atl":[[1.24,47.99]],"id":9624350}],"con":true,"img":false}]}
{"op":"mcm","clk":"1362101890","pt":1588427536189,"mc":[{"id":"1.170370557","rc":[{"atl":[[1.24,23.99]],"id":9624350}],"con":true,"img":false}]}
{"op":"mcm","clk":"1362101900","pt":1588427536650,"mc":[{"id":"1.170370557","rc":[{"atl":[[1.24,0]],"id":9624350}],"con":true,"img":false}]}
{"op":"mcm","clk":"1362101902","pt":1588427536753,"mc":[{"id":"1.170370557","rc":[{"atb":[[1.24,14.11]],"id":9624350}],"con":true,"img":false}]}
{"op":"mcm","clk":"1362101911","pt":1588427537466,"mc":[{"id":"1.170370557","rc":[{"trd":[[5,4.23]],"ltp":5.0,"tv":4.23,"id":9622734},{"trd":[[1.25,2086.01]],"ltp":1.25,"tv":2086.01,"id":9624350},{"atl":[[1.25,1347.29]],"id":9624350}],"con":true,"img":false}]}
{"op":"mcm","clk":"1362101916","pt":1588427537675,"mc":[{"id":"1.170370557","rc":[{"trd":[[1.24,2441.36]],"ltp":1.24,"tv":2441.36,"id":9624350},{"atb":[[1.24,0]],"id":9624350},{"atl":[[1.24,1.88]],"id":9624350}],"con":true,"img":false}]}
{"op":"mcm","clk":"1362101918","pt":1588427537775,"mc":[{"id":"1.170370557","rc":[{"atb":[[5.2,11]],"id":9622734},{"trd":[[1.24,2443.74]],"ltp":1.24,"tv":2443.74,"id":9624350},{"atl":[[1.24,0.69]],"id":9624350}],"con":true,"img":false}]}
{"op":"mcm","clk":"1362101925","pt":1588427538182,"mc":[{"id":"1.170370557","rc":[{"atb":[[1.23,771.55]],"id":9624350}],"con":true,"img":false}]}
{"op":"mcm","clk":"1362101929","pt":1588427538384,"mc":[{"id":"1.170370557","rc":[{"atl":[[1.25,1347.17]],"id":9624350}],"con":true,"img":false}]}
{"op":"mcm","clk":"1362101933","pt":1588427538588,"mc":[{"id":"1.170370557","rc":[{"atb":[[1.22,888.65]],"id":9624350}],"con":true,"img":false}]}
{"op":"mcm","clk":"1362101938","pt":1588427538996,"mc":[{"id":"1.170370557","rc":[{"trd":[[5.2,21.15]],"ltp":5.2,"tv":21.15,"id":9622734},{"atb":[[5.2,10.94]],"id":9622734},{"trd":[[1.24,2445.38]],"ltp":1.24,"tv":2445.38,"id":9624350},{"atl":[[1.24,0]],"id":9624350}],"con":true,"img":false}]}
{"op":"mcm","clk":"1362101946","pt":1588427539561,"mc":[{"id":"1.170370557","rc":[{"atl":[[1.24,13.29]],"id":9624350}],"con":true,"img":false}]}
{"op":"mcm","clk":"1362101951","pt":1588427539969,"mc":[{"id":"1.170370557","rc":[{"atl":[[1.24,57.62]],"id":9624350}],"con":true,"img":false}]}
{"op":"mcm","clk":"1362101955","pt":1588427540275,"mc":[{"id":"1.170370557","rc":[{"trd":[[1.24,2519.24]],"ltp":1.24,"tv":2519.24,"id":9624350},{"atl":[[1.24,20.69]],"id":9624350}],"con":true,"img":false}]}
{"op":"mcm","clk":"1362101958","pt":1588427540378,"mc":[{"id":"1.170370557","rc":[{"atl":[[1.24,65.01]],"id":9624350}],"con":true,"img":false}]}
{"op":"mcm","clk":"1362101960","pt":1588427540479,"mc":[{"id":"1.170370557","rc":[{"atl":[[1.24,165.01]],"id":9624350}],"con":true,"img":false}]}
{"op":"mcm","clk":"1362101963","pt":1588427540583,"mc":[{"id":"1.170370557","rc":[{"atl":[[1.24,209.34]],"id":9624350}],"con":true,"img":false}]}
{"op":"mcm","clk":"1362101971","pt":1588427540891,"mc":[{"id":"1.170370557","rc":[{"atb":[[5.2,14.74]],"id":9622734}],"con":true,"img":false}]}
{"op":"mcm","clk":"1362101980","pt":1588427541197,"mc":[{"id":"1.170370557","rc":[{"atl":[[1.24,253.67]],"id":9624350}],"con":true,"img":false}]}
{"op":"mcm","clk":"1362101982","pt":1588427541299,"mc":[{"id":"1.170370557","rc":[{"atl":[[1.24,232.97]],"id":9624350}],"con":true,"img":false}]}
{"op":"mcm","clk":"1362101989","pt":1588427541606,"mc":[{"id":"1.170370557","rc":[{"atb":[[5.2,10.94]],"id":9622734}],"con":true,"img":false}]}
{"op":"mcm","clk":"1362101993","pt":1588427541660,"mc":[{"id":"1.170370557","rc":[{"atl":[[1.24,188.65]],"id":9624350}],"con":true,"img":false}]}
{"op":"mcm","clk":"1362101996","pt":1588427541864,"mc":[{"id":"1.170370557","rc":[{"atl":[[1.24,144.32]],"id":9624350}],"con":true,"img":false}]}
{"op":"mcm","clk":"1362102000","pt":1588427541965,"mc":[{"id":"1.170370557","rc":[{"atb":[[5.2,14.74]],"id":9622734}],"con":true,"img":false}]}
{"op":"mcm","clk":"1362102013","pt":1588427542579,"mc":[{"id":"1.170370557","rc":[{"atl":[[1.24,100]],"id":9624350}],"con":true,"img":false}]}
{"op":"mcm","clk":"1362102016","pt":1588427542683,"mc":[{"id":"1.170370557","rc":[{"trd":[[1.24,2551.51]],"ltp":1.24,"tv":2551.51,"id":9624350},{"atl":[[1.24,86.44]],"id":9624350}],"con":true,"img":false}]}
{"op":"mcm","clk":"1362102025","pt":1588427543193,"mc":[{"id":"1.170370557","rc":[{"trd":[[5.4,13.75]],"ltp":5.4,"tv":13.75,"id":9622734},{"trd":[[1.23,345.43]],"ltp":1.23,"tv":345.43,"id":9624350},{"atb":[[1.23,747.63]],"id":9624350}],"con":true,"img":false}]}
{"op":"mcm","clk":"1362102031","pt":1588427543598,"mc":[{"id":"1.170370557","rc":[{"atb":[[5.2,10.94]],"id":9622734}],"con":true,"img":false}]}
{"op":"mcm","clk":"1362102035","pt":1588427543803,"mc":[{"id":"1.170370557","rc":[{"atl":[[1.24,126.43]],"id":9624350}],"con":true,"img":false}]}
{"op":"mcm","clk":"1362102040","pt":1588427544007,"mc":[{"id":"1.170370557","rc":[{"atb":[[5.2,21.48]],"id":9622734},{"atl":[[1.24,211.22]],"id":9624350}],"con":true,"img":false}]}
{"op":"mcm","clk":"1362102042","pt":1588427544163,"mc":[{"id":"1.170370557","rc":[{"trd":[[5.4,19.2]],"ltp":5.4,"tv":19.2,"id":9622734},{"trd":[[1.23,369.35]],"ltp":1.23,"tv":369.35,"id":9624350},{"atb":[[1.23,723.71]],"id":9624350}],"con":true,"img":false}]}
{"op":"mcm","clk":"1362102045","pt":1588427544469,"mc":[{"id":"1.170370557","rc":[{"trd":[[1.23,387.08]],"ltp":1.23,"tv":387.08,"id":9624350},{"atb":[[1.23,714.84]],"id":9624350}],"con":true,"img":false}]}
{"op":"mcm","clk":"1362102048","pt":1588427544673,"mc":[{"id":"1.170370557","rc":[{"atl":[[1.24,171.23]],"id":9624350}],"con":true,"img":false}]}
{"op":"mcm","clk":"1362102050","pt":1588427544776,"mc":[{"id":"1.170370557","rc":[{"trd":[[1.23,440.27]],"ltp":1.23,"tv":440.27,"id":9624350},{"atb":[[1.23,688.25]],"id":9624350}],"con":true,"img":false}]}
{"op":"mcm","clk":"1362102056","pt":1588427544981,"mc":[{"id":"1.170370557","rc":[{"atb":[[5.2,27.02]],"id":9622734},{"trd":[[1.23,536.26]],"ltp":1.23,"tv":536.26,"id":9624350},{"atb":[[1.21,827.07],[1.23,640.25],[1.22,288.65]],"id":9624350}],"con":true,"img":false}]}
{"op":"mcm","clk":"1362102062","pt":1588427545489,"mc":[{"id":"1.170370557","rc":[{"atb":[[5.2,16.47]],"id":9622734}],"con":true,"img":false}]}
{"op":"mcm","clk":"1362102073","pt":1588427546098,"mc":[{"id":"1.170370557","rc":[{"trd":[[5.4,22.83]],"ltp":5.4,"tv":22.83,"id":9622734},{"trd":[[1.23,552.2]],"ltp":1.23,"tv":552.2,"id":9624350},{"atb":[[1.23,624.31]],"id":9624350}],"con":true,"img":false}]}
{"op":"mcm","clk":"1362102084","pt":1588427546764,"mc":[{"id":"1.170370557","rc":[{"atb":[[1.19,643.26]],"id":9624350}],"con":true,"img":false}]}
{"op":"mcm","clk":"1362102086","pt":1588427546866,"mc":[{"id":"1.170370557","rc":[{"atb":[[5.2,19.67]],"id":9622734},{"trd":[[1.23,569.93]],"ltp":1.23,"tv":569.93,"id":9624350},{"atb":[[1.23,615.45]],"id":9624350}],"con":true,"img":false}]}
{"op":"mcm","clk":"1362102089","pt":1588427546968,"mc":[{"id":"1.170370557","rc":[{"trd":[[5.4,36.68]],"ltp":5.4,"tv":36.68,"id":9622734},{"trd":[[1.23,630.73]],"ltp":1.23,"tv":630.73,"id":9624350},{"atb":[[1.23,554.65]],"id":9624350}],"con":true,"img":false}]}
{"op":"mcm","clk":"1362102093","pt":1588427547070,"mc":[{"id":"1.170370557","rc":[{"trd":[[1.24,2552.07]],"ltp":1.24,"tv":2552.07,"id":9624350},{"atl":[[1.24,170.95]],"id":9624350}],"con":true,"img":false}]}
{"op":"mcm","clk":"1362102097","pt":1588427547379,"mc":[{"id":"1.170370557","rc":[{"atb":[[5.2,14.13]],"id":9622734},{"atl":[[1.27,10.2]],"id":9624350}],"con":true,"img":false}]}
{"op":"mcm","clk":"1362102111","pt":1588427548495,"mc":[{"id":"1.170370557","rc":[{"atb":[[5.2,10.94]],"id":9622734}],"con":true,"img":false}]}
{"op":"mcm","clk":"1362102115","pt":1588427549004,"mc":[{"id":"1.170370557","rc":[{"trd":[[5.4,58.84]],"ltp":5.4,"tv":58.84,"id":9622734},{"trd":[[1.23,728.03]],"ltp":1.23,"tv":728.03,"id":9624350},{"atb":[[1.23,457.35]],"id":9624350}],"con":true,"img":false}]}
{"op":"mcm","clk":"1362102117","pt":1588427549106,"mc":[{"id":"1.170370557","rc":[{"atb":[[1.01,4104.95]],"id":9624350}],"con":true,"img":false}]}
{"op":"mcm","clk":"1362102125","pt":1588427549412,"mc":[{"id":"1.170370557","rc":[{"atb":[[1.01,4102.67]],"id":9624350}],"con":true,"img":false}]}
{"op":"mcm","clk":"1362102128","pt":1588427549571,"mc":[{"id":"1.170370557","rc":[{"trd":[[1.24,2552.77]],"ltp":1.24,"tv":2552.77,"id":9624350},{"atl":[[1.24,170.6]],"id":9624350}],"con":true,"img":false}]}
{"op":"mcm","clk":"1362102130","pt":1588427549673,"mc":[{"id":"1.170370557","rc":[{"atb":[[1.01,4101.75]],"id":9624350}],"con":true,"img":false}]}
{"op":"mcm","clk":"1362102133","pt":1588427549875,"mc":[{"id":"1.170370557","rc":[{"trd":[[1.23,816.69]],"ltp":1.23,"tv":816.69,"id":9624350},{"atb":[[1.23,413.02]],"id":9624350}],"con":true,"img":false}]}
{"op":"mcm","clk":"1362102135","pt":1588427549976,"mc":[{"id":"1.170370557","rc":[{"atb":[[5.2,0]],"id":9622734}],"con":true,"img":false}]}
{"op":"mcm","clk":"1362102136","pt":1588427550079,"mc":[{"id":"1.170370557","rc":[{"trd":[[1.23,905.34]],"ltp":1.23,"tv":905.34,"id":9624350},{"atb":[[1.23,368.69]],"id":9624350}],"con":true,"img":false}]}
{"op":"mcm","clk":"1362102150","pt":1588427550897,"mc":[{"id":"1.170370557","rc":[{"trd":[[1.23,994]],"ltp":1.23,"tv":994.0,"id":9624350},{"atb":[[1.23,320.37]],"id":9624350}],"con":true,"img":false}]}
{"op":"mcm","clk":"1362102161","pt":1588427551715,"mc":[{"id":"1.170370557","rc":[{"trd":[[1.23,1020.59]],"ltp":1.23,"tv":1020.59,"id":9624350},{"atb":[[1.23,307.07]],"id":9624350},{"atl":[[1.25,903.17]],"id":9624350}],"con":true,"img":false}]}
{"op":"mcm","clk":"1362102164","pt":1588427552179,"mc":[{"id":"1.170370557","rc":[{"trd":[[5.4,62.47]],"ltp":5.4,"tv":62.47,"id":9622734},{"trd":[[1.23,1036.53]],"ltp":1.23,"tv":1036.53,"id":9624350},{"atb":[[1.23,291.13]],"id":9624350}],"con":true,"img":false}]}
{"op":"mcm","clk":"1362102167","pt":1588427552484,"mc":[{"id":"1.170370557","rc":[{"trd":[[1.24,2567.77]],"ltp":1.24,"tv":2567.77,"id":9624350},{"atl":[[1.24,163.1]],"id":9624350}],"con":true,"img":false}]}
{"op":"mcm","clk":"1362102172","pt":1588427552792,"mc":[{"id":"1.170370557","rc":[{"atl":[[1.41,300]],"id":9624350}],"con":true,"img":false}]}
{"op":"mcm","clk":"1362102173","pt":1588427552892,"mc":[{"id":"1.170370557","rc":[{"atl":[[1.24,78.31]],"id":9624350}],"con":true,"img":false}]}
{"op":"mcm","clk":"1362102176","pt":1588427553197,"mc":[{"id":"1.170370557","rc":[{"trd":[[1.23,1116.52]],"ltp":1.23,"tv":1116.52,"id":9624350},{"atb":[[1.23,251.14]],"id":9624350}],"con":true,"img":false}]}
{"op":"mcm","clk":"1362102180","pt":1588427553503,"mc":[{"id":"1.170370557","rc":[{"atl":[[1.44,300]],"id":9624350}],"con":true,"img":false}]}
{"op":"mcm","clk":"1362102184","pt":1588427554115,"mc":[{"id":"1.170370557","rc":[{"trd":[[5.4,72.54]],"ltp":5.4,"tv":72.54,"id":9622734},{"trd":[[1.23,1160.69]],"ltp":1.23,"tv":1160.69,"id":9624350},{"atb":[[1.23,206.96]],"id":9624350}],"con":true,"img":false}]}
{"op":"mcm","clk":"1362102187","pt":1588427554578,"mc":[{"id":"1.170370557","rc":[{"atl":[[1.46,300]],"id":9624350}],"con":true,"img":false}]}
{"op":"mcm","clk":"1362102189","pt":1588427554679,"mc":[{"id":"1.170370557","rc":[{"trd":[[1.23,1178.42]],"ltp":1.23,"tv":1178.42,"id":9624350},{"atb":[[1.23,198.1]],"id":9624350}],"con":true,"img":false}]}
{"op":"mcm","clk":"1362102190","pt":1588427554780,"mc":[{"id":"1.170370557","rc":[{"atb":[[1.2,1050.46]],"id":9624350}],"con":true,"img":false}]}
{"op":"mcm","clk":"1362102195","pt":1588427555088,"mc":[{"id":"1.170370557","rc":[{"atb":[[5.3,10.94]],"id":9622734}],"con":true,"img":false}]}
{"op":"mcm","clk":"1362102197","pt":1588427555189,"mc":[{"id":"1.170370557","rc":[{"trd":[[1.23,1191.22]],"ltp":1.23,"tv":1191.22,"id":9624350},{"atb":[[1.23,191.7]],"id":9624350}],"con":true,"img":false}]}
{"op":"mcm","clk":"1362102199","pt":1588427555496,"mc":[{"id":"1.170370557","rc":[{"atl":[[1.24,2.57]],"id":9624350}],"con":true,"img":false}]}
{"op":"mcm","clk":"1362102202","pt":1588427555902,"mc":[{"id":"1.170370557","rc":[{"trd":[[1.23,1208.95]],"ltp":1.23,"tv":1208.95,"id":9624350},{"atb":[[1.23,182.83]],"id":9624350}],"con":true,"img":false}]}
{"op":"mcm","clk":"1362102208","pt":1588427556515,"mc":[{"id":"1.170370557","rc":[{"atl":[[1.24,202.57]],"id":9624350}],"con":true,"img":false}]}
{"op":"mcm","clk":"1362102214","pt":1588427556977,"mc":[{"id":"1.170370557","rc":[{"trd":[[1.23,1240.95]],"ltp":1.23,"tv":1240.95,"id":9624350},{"atb":[[1.23,166.83]],"id":9624350}],"con":true,"img":false}]}
{"op":"mcm","clk":"1362102216","pt":1588427557080,"mc":[{"id":"1.170370557","rc":[{"trd":[[1.24,2578.26]],"ltp":1.24,"tv":2578.26,"id":9624350},{"atl":[[1.24,197.33]],"id":9624350}],"con":true,"img":false}]}
{"op":"mcm","clk":"1362102221","pt":1588427557287,"mc":[{"id":"1.170370557","rc":[{"trd":[[5.4,76.17]],"ltp":5.4,"tv":76.17,"id":9622734},{"trd":[[1.23,1256.89]],"ltp":1.23,"tv":1256.89,"id":9624350},{"atb":[[1.23,150.89]],"id":9624350}],"con":true,"img":false}]}
{"op":"mcm","clk":"1362102229","pt":1588427557901,"mc":[{"id":"1.170370557","rc":[{"trd":[[1.23,1263.29]],"ltp":1.23,"tv":1263.29,"id":9624350},{"atb":[[1.23,147.69]],"id":9624350}],"con":true,"img":false}]}
{"op":"mcm","clk":"1362102231","pt":1588427558002,"mc":[{"id":"1.170370557","rc":[{"trd":[[1.23,1432.87]],"ltp":1.23,"tv":1432.87,"id":9624350},{"atb":[[1.23,62.9]],"id":9624350}],"con":true,"img":false}]}
{"op":"mcm","clk":"1362102238","pt":1588427558409,"mc":[{"id":"1.170370557","rc":[{"trd":[[5.4,84.48]],"ltp":5.4,"tv":84.48,"id":9622734},{"trd":[[1.23,1469.35]],"ltp":1.23,"tv":1469.35,"id":9624350},{"atb":[[1.23,26.42]],"id":9624350}],"con":true,"img":false}]}
{"op":"mcm","clk":"1362102255","pt":1588427559688,"mc":[{"id":"1.170370557","rc":[{"trd":[[5.4,90.5]],"ltp":5.4,"tv":90.5,"id":9622734},{"atb":[[5.4,2.84]],"id":9622734},{"trd":[[1.23,1495.78]],"ltp":1.23,"tv":1495.78,"id":9624350},{"atb":[[1.23,0]],"id":9624350}],"con":true,"img":false}]}
{"op":"mcm","clk":"1362102258","pt":1588427559891,"mc":[{"id":"1.170370557","rc":[{"atl":[[1.23,35.46]],"id":9624350}],"con":true,"img":false}]}
{"op":"mcm","clk":"1362102260","pt":1588427559995,"mc":[{"id":"1.170370557","rc":[{"atb":[[5.2,2.42]],"id":9622734}],"con":true,"img":false}]}
{"op":"mcm","clk":"1362102271","pt":1588427560817,"mc":[{"id":"1.170370557","rc":[{"atb":[[5.4,6.39]],"id":9622734}],"con":true,"img":false}]}
{"op":"mcm","clk":"1362102274","pt":1588427561016,"mc":[{"id":"1.170370557","rc":[{"atb":[[1.22,488.65]],"id":9624350}],"con":true,"img":false}]}
{"op":"mcm","clk":"1362102278","pt":1588427561219,"mc":[{"id":"1.170370557","rc":[{"atl":[[1.23,0]],"id":9624350}],"con":true,"img":false}]}
{"op":"mcm","clk":"1362102282","pt":1588427561322,"mc":[{"id":"1.170370557","rc":[{"atl":[[1.23,13.29]],"id":9624350}],"con":true,"img":false}]}
{"op":"mcm","clk":"1362102295","pt":1588427562400,"mc":[{"id":"1.170370557","rc":[{"atl":[[1.23,29.29]],"id":9624350}],"con":true,"img":false}]}
{"op":"mcm","clk":"1362102298","pt":1588427562604,"mc":[{"id":"1.170370557","rc":[{"atl":[[1.23,15.99]],"id":9624350}],"con":true,"img":false}]}
{"op":"mcm","clk":"1362102314","pt":1588427563980,"mc":[{"id":"1.170370557","rc":[{"atb":[[1.21,617.13]],"id":9624350},{"atl":[[1.24,357.3]],"id":9624350}],"con":true,"img":false}]}
{"op":"mcm","clk":"1362102316","pt":1588427564084,"mc":[{"id":"1.170370557","rc":[{"atl":[[1.23,0]],"id":9624350}],"con":true,"img":false}]}
{"op":"mcm","clk":"1362102322","pt":1588427564491,"mc":[{"id":"1.170370557","rc":[{"atl":[[1.25,1063.14]],"id":9624350}],"con":true,"img":false}]}
{"op":"mcm","clk":"1362102337","pt":1588427565619,"mc":[{"id":"1.170370557","rc":[{"atb":[[1.22,88.65]],"id":9624350}],"con":true,"img":false}]}
{"op":"mcm","clk":"1362102352","pt":1588427566801,"mc":[{"id":"1.170370557","rc":[{"atl":[[1.24,557.3]],"id":9624350}],"con":true,"img":false}]}
{"op":"mcm","clk":"1362102368","pt":1588427567729,"mc":[{"id":"1.170370557","rc":[{"trd":[[5.4,96.89]],"ltp":5.4,"tv":96.89,"id":9622734},{"atb":[[5.4,0]],"id":9622734},{"trd":[[1.24,2580.44],[1.23,1523.84]],"ltp":1.24,"tv":4104.28,"id":9624350},{"atl":[[1.24,556.21]],"id":9624350}],"con":true,"img":false}]}
{"op":"mcm","clk":"1362102374","pt":1588427568181,"mc":[{"id":"1.170370557","rc":[{"atl":[[1.23,7.1]],"id":9624350}],"con":true,"img":false}]}
{"op":"mcm","clk":"1362102382","pt":1588427568793,"mc":[{"id":"1.170370557","rc":[{"atb":[[5.4,12]],"id":9622734}],"con":true,"img":false}]}
{"op":"mcm","clk":"1362102388","pt":1588427569203,"mc":[{"id":"1.170370557","rc":[{"trd":[[5.4,108.89]],"ltp":5.4,"tv":108.89,"id":9622734},{"atb":[[5.4,0]],"id":9622734},{"trd":[[1.23,1590.73]],"ltp":1.23,"tv":1590.73,"id":9624350},{"atb":[[1.23,146.74]],"id":9624350},{"atl":[[1.23,0]],"id":9624350}],"con":true,"img":false}]}
{"op":"mcm","clk":"1362102392","pt":1588427569918,"mc":[{"id":"1.170370557","rc":[{"trd":[[1.23,1661.65]],"ltp":1.23,"tv":1661.65,"id":9624350},{"atb":[[1.23,111.28]],"id":9624350}],"con":true,"img":false}]}
{"op":"mcm","clk":"1362102401","pt":1588427570327,"mc":[{"id":"1.170370557","rc":[{"atb":[[1.23,0]],"id":9624350}],"con":true,"img":false}]}
{"op":"mcm","clk":"1362102404","pt":1588427570531,"mc":[{"id":"1.170370557","rc":[{"trd":[[5.6,19.31]],"ltp":5.6,"tv":19.31,"id":9622734},{"atb":[[5.6,26.33]],"id":9622734},{"trd":[[1.22,1145.44]],"ltp":1.22,"tv":1145.44,"id":9624350},{"atb":[[1.22,0]],"id":9624350}],"con":true,"img":false}]}
{"op":"mcm","clk":"1362102407","pt":1588427570685,"mc":[{"id":"1.170370557","rc":[{"atl":[[1.22,13.29]],"id":9624350}],"con":true,"img":false}]}
{"op":"mcm","clk":"1362102410","pt":1588427570889,"mc":[{"id":"1.170370557","rc":[{"atb":[[5.6,92.82]],"id":9622734}],"con":true,"img":false}]}
{"op":"mcm","clk":"1362102422","pt":1588427572013,"mc":[{"id":"1.170370557","rc":[{"atl":[[1.22,0]],"id":9624350}],"con":true,"img":false}]}
{"op":"mcm","clk":"1362102431","pt":1588427572627,"mc":[{"id":"1.170370557","rc":[{"atl":[[1.23,15]],"id":9624350}],"con":true,"img":false}]}
{"op":"mcm","clk":"1362102442","pt":1588427573087,"mc":[{"id":"1.170370557","rc":[{"atb":[[5.6,95.04]],"id":9622734},{"atl":[[1.25,619.88]],"id":9624350}],"con":true,"img":false}]}
{"op":"mcm","clk":"1362102444","pt":1588427573189,"mc":[{"id":"1.170370557","rc":[{"atl":[[1.22,15.99]],"id":9624350}],"con":true,"img":false}]}
{"op":"mcm","clk":"1362102456","pt":1588427573906,"mc":[{"id":"1.170370557","rc":[{"atl":[[1.3,17.49]],"id":9624350}],"con":true,"img":false}]}
{"op":"mcm","clk":"1362102459","pt":1588427574215,"mc":[{"id":"1.170370557","rc":[{"atb":[[5.2,0]],"id":9622734}],"con":true,"img":false}]}
{"op":"mcm","clk":"1362102462","pt":1588427574524,"mc":[{"id":"1.170370557","rc":[{"atl":[[1.22,24.86]],"id":9624350}],"con":true,"img":false}]}
{"op":"mcm","clk":"1362102466","pt":1588427574932,"mc":[{"id":"1.170370557","rc":[{"atl":[[1.22,8.86]],"id":9624350}],"con":true,"img":false}]}
{"op":"mcm","clk":"1362102472","pt":1588427575392,"mc":[{"id":"1.170370557","rc":[{"atb":[[5.6,115.04]],"id":9622734}],"con":true,"img":false}]}
{"op":"mcm","clk":"1362102474","pt":1588427575495,"mc":[{"id":"1.170370557","rc":[{"trd":[[5.6,41.82]],"ltp":5.6,"tv":41.82,"id":9622734},{"atb":[[5.6,92.53]],"id":9622734},{"trd":[[1.22,1266.49]],"ltp":1.22,"tv":1266.49,"id":9624350},{"atl":[[1.22,0]],"id":9624350}],"con":true,"img":false}]}
{"op":"mcm","clk":"1362102477","pt":1588427575699,"mc":[{"id":"1.170370557","rc":[{"atb":[[1.14,492.02]],"id":9624350}],"con":true,"img":false}]}
{"op":"mcm","clk":"1362102480","pt":1588427575801,"mc":[{"id":"1.170370557","rc":[{"atb":[[1.2,910.46]],"id":9624350}],"con":true,"img":false}]}
{"op":"mcm","clk":"1362102485","pt":1588427576211,"mc":[{"id":"1.170370557","rc":[{"atl":[[1.29,0]],"id":9624350}],"con":true,"img":false}]}
{"op":"mcm","clk":"1362102500","pt":1588427576927,"mc":[{"id":"1.170370557","rc":[{"trd":[[5.6,54.75]],"ltp":5.6,"tv":54.75,"id":9622734},{"atb":[[5.6,79.61]],"id":9622734},{"trd":[[1.22,1325.83]],"ltp":1.22,"tv":1325.83,"id":9624350}],"con":true,"img":false}]}
{"op":"mcm","clk":"1362102506","pt":1588427577233,"mc":[{"id":"1.170370557","rc":[{"trd":[[5.6,132]],"ltp":5.6,"tv":132.0,"id":9622734},{"atb":[[5.6,2.36]],"id":9622734},{"trd":[[1.22,1680.44]],"ltp":1.22,"tv":1680.44,"id":9624350}],"con":true,"img":false}]}
{"op":"mcm","clk":"1362102509","pt":1588427577388,"mc":[{"id":"1.170370557","rc":[{"atl":[[1.23,102.93]],"id":9624350}],"con":true,"img":false}]}
{"op":"mcm","clk":"1362102513","pt":1588427577590,"mc":[{"id":"1.170370557","rc":[{"atl":[[1.23,87.93]],"id":9624350}],"con":true,"img":false}]}
{"op":"mcm","clk":"1362102547","pt":1588427580394,"mc":[{"id":"1.170370557","rc":[{"atl":[[1.27,453.46]],"id":9624350}],"con":true,"img":false}]}
{"op":"mcm","clk":"1362102559","pt":1588427581520,"mc":[{"id":"1.170370557","rc":[{"atl":[[1.27,443.26]],"id":9624350}],"con":true,"img":false}]}
{"op":"mcm","clk":"1362102562","pt":1588427581724,"mc":[{"id":"1.170370557","rc":[{"atb":[[5.3,0]],"id":9622734}],"con":true,"img":false}]}
{"op":"mcm","clk":"1362102568","pt":1588427582293,"mc":[{"id":"1.170370557","rc":[{"trd":[[1.21,236.89]],"ltp":1.21,"tv":236.89,"id":9624350},{"atb":[[1.21,611.88]],"id":9624350}],"con":true,"img":false}]}
{"op":"mcm","clk":"1362102572","pt":1588427582498,"mc":[{"id":"1.170370557","rc":[{"atl":[[1.23,442.54]],"id":9624350}],"con":true,"img":false}]}
{"op":"mcm","clk":"1362102576","pt":1588427582701,"mc":[{"id":"1.170370557","rc":[{"trd":[[1.21,266.89]],"ltp":1.21,"tv":266.89,"id":9624350},{"atb":[[1.21,596.88]],"id":9624350}],"con":true,"img":false}]}
{"op":"mcm","clk":"1362102601","pt":1588427584295,"mc":[{"id":"1.170370557","rc":[{"atb":[[5.6,0]],"id":9622734}],"con":true,"img":false}]}
{"op":"mcm","clk":"1362102618","pt":1588427585417,"mc":[{"id":"1.170370557","rc":[{"atl":[[1.25,159.97]],"id":9624350}],"con":true,"img":false}]}
{"op":"mcm","clk":"1362102637","pt":1588427586797,"mc":[{"id":"1.170370557","rc":[{"atb":[[5.7,10.94]],"id":9622734}],"con":true,"img":false}]}
{"op":"mcm","clk":"1362102661","pt":1588427588837,"mc":[{"id":"1.170370557","rc":[{"trd":[[5.7,0.15]],"ltp":5.7,"tv":0.15,"id":9622734},{"atb":[[5.7,10.79]],"id":9622734},{"trd":[[1.22,1681.13]],"ltp":1.22,"tv":1681.13,"id":9624350}],"con":true,"img":false}]}
{"op":"mcm","clk":"1362102665","pt":1588427588941,"mc":[{"id":"1.170370557","rc":[{"trd":[[5.7,10.85]],"ltp":5.7,"tv":10.85,"id":9622734},{"atb":[[5.7,0.09]],"id":9622734},{"trd":[[1.22,1731.13]],"ltp":1.22,"tv":1731.13,"id":9624350}],"con":true,"img":false}]}
{"op":"mcm","clk":"1362102668","pt":1588427589145,"mc":[{"id":"1.170370557","rc":[{"trd":[[5.7,10.94]],"ltp":5.7,"tv":10.94,"id":9622734},{"atb":[[5.7,0]],"id":9622734},{"atl":[[7.2,1.72]],"id":9622734},{"trd":[[1.22,1731.78]],"ltp":1.22,"tv":1731.78,"id":9624350},{"atb":[[1.2,615.24],[1.22,1.24]],"id":9624350}],"con":true,"img":false}]}
{"op":"mcm","clk":"1362102681","pt":1588427589910,"mc":[{"id":"1.170370557","rc":[{"trd":[[1.21,288.02],[1.22,1734.26]],"ltp":1.21,"tv":2022.28,"id":9624350},{"atb":[[1.21,586.31],[1.22,0]],"id":9624350}],"con":true,"img":false}]}
{"op":"mcm","clk":"1362102685","pt":1588427590317,"mc":[{"id":"1.170370557","rc":[{"atb":[[1.19,200]],"id":9624350}],"con":true,"img":false}]}
{"op":"mcm","clk":"1362102740","pt":1588427593935,"mc":[{"id":"1.170370557","rc":[{"atb":[[1.22,16.2]],"id":9624350}],"con":true,"img":false}]}
{"op":"mcm","clk":"1362102758","pt":1588427595313,"mc":[{"id":"1.170370557","rc":[{"atb":[[5.5,17.73]],"id":9622734}],"con":true,"img":false}]}
{"op":"mcm","clk":"1362102761","pt":1588427595415,"mc":[{"id":"1.170370557","rc":[{"atb":[[1.18,938.47]],"id":9624350}],"con":true,"img":false}]}
{"op":"mcm","clk":"1362102781","pt":1588427597050,"mc":[{"id":"1.170370557","rc":[{"atb":[[1.22,18.77]],"id":9624350}],"con":true,"img":false}]}
{"op":"mcm","clk":"1362102802","pt":1588427599039,"mc":[{"id":"1.170370557","rc":[{"atl":[[1.24,396.24]],"id":9624350}],"con":true,"img":false}]}
{"op":"mcm","clk":"1362102805","pt":1588427599447,"mc":[{"id":"1.170370557","rc":[{"atl":[[1.25,0]],"id":9624350}],"con":true,"img":false}]}
{"op":"mcm","clk":"1362102819","pt":1588427601137,"mc":[{"id":"1.170370557","rc":[{"atb":[[1.21,323.78]],"id":9624350}],"con":true,"img":false}]}
{"op":"mcm","clk":"1362102827","pt":1588427601746,"mc":[{"id":"1.170370557","rc":[{"atl":[[1.24,0]],"id":9624350}],"con":true,"img":false}]}
{"op":"mcm","clk":"1362102836","pt":1588427602308,"mc":[{"id":"1.170370557","rc":[{"atb":[[1.2,355.52]],"id":9624350}],"con":true,"img":false}]}
{"op":"mcm","clk":"1362102841","pt":1588427602717,"mc":[{"id":"1.170370557","rc":[{"trd":[[1.22,1737.09]],"ltp":1.22,"tv":1737.09,"id":9624350},{"atb":[[1.22,17.36]],"id":9624350}],"con":true,"img":false}]}
{"op":"mcm","clk":"1362102843","pt":1588427602820,"mc":[{"id":"1.170370557","rc":[{"trd":[[5.8,67.55],[5.6,135.78]],"ltp":5.8,"tv":203.32,"id":9622734},{"atb":[[5.8,28.67]],"id":9622734},{"trd":[[1.21,611.81],[1.22,1754.46]],"ltp":1.21,"tv":2366.27,"id":9624350},{"atb":[[1.21,0],[1.22,0]],"id":9624350}],"con":true,"img":false}]}
{"op":"mcm","clk":"1362102848","pt":1588427603125,"mc":[{"id":"1.170370557","rc":[{"atl":[[1.23,87.93]],"id":9624350}],"con":true,"img":false}]}
{"op":"mcm","clk":"1362102855","pt":1588427603635,"mc":[{"id":"1.170370557","rc":[{"atb":[[1.18,738.47],[1.19,0],[1.16,492.02],[1.17,0]],"id":9624350}],"con":true,"img":false}]}
{"op":"mcm","clk":"1362102877","pt":1588427605014,"mc":[{"id":"1.170370557","rc":[{"atb":[[1.2,0.91]],"id":9624350}],"con":true,"img":false}]}
{"op":"mcm","clk":"1362102885","pt":1588427605321,"mc":[{"id":"1.170370557","rc":[{"atl":[[8.4,3.99]],"id":9622734}],"con":true,"img":false}]}
{"op":"mcm","clk":"1362102891","pt":1588427605931,"mc":[{"id":"1.170370557","rc":[{"atl":[[1.26,48.41]],"id":9624350}],"con":true,"img":false}]}
{"op":"mcm","clk":"1362102900","pt":1588427606747,"mc":[{"id":"1.170370557","rc":[{"atb":[[1.09,0.31]],"id":9624350}],"con":true,"img":false}]}
{"op":"mcm","clk":"1362102909","pt":1588427607358,"mc":[{"id":"1.170370557","rc":[{"atb":[[1.18,443.26]],"id":9624350}],"con":true,"img":false}]}
{"op":"mcm","clk":"1362102932","pt":1588427609245,"mc":[{"id":"1.170370557","rc":[{"trd":[[5.8,96.22]],"ltp":5.8,"tv":96.22,"id":9622734},{"atb":[[5.8,0]],"id":9622734},{"trd":[[1.21,749.24]],"ltp":1.21,"tv":749.24,"id":9624350},{"atb":[[1.21,84.2]],"id":9624350}],"con":true,"img":false}]}
{"op":"mcm","clk":"1362102952","pt":1588427610419,"mc":[{"id":"1.170370557","rc":[{"atb":[[1.17,118.86]],"id":9624350},{"atl":[[1.22,131.78]],"id":9624350}],"con":true,"img":false}]}
{"op":"mcm","clk":"1362102955","pt":1588427610622,"mc":[{"id":"1.170370557","rc":[{"atb":[[1.21,0]],"id":9624350}],"con":true,"img":false}]}
{"op":"mcm","clk":"1362102977","pt":1588427612358,"mc":[{"id":"1.170370557","rc":[{"atb":[[1.11,421.02]],"id":9624350}],"con":true,"img":false}]}
{"op":"mcm","clk":"1362102984","pt":1588427613126,"mc":[{"id":"1.170370557","rc":[{"atl":[[1.22,132.62]],"id":9624350}],"con":true,"img":false}]}
{"op":"mcm","clk":"1362102988","pt":1588427613228,"mc":[{"id":"1.170370557","rc":[{"atb":[[1.16,935.28]],"id":9624350}],"con":true,"img":false}]}
{"op":"mcm","clk":"1362102999","pt":1588427613942,"mc":[{"id":"1.170370557","rc":[{"trd":[[5.5,56.1]],"ltp":5.5,"tv":56.1,"id":9622734},{"atb":[[5.5,16.98]],"id":9622734}],"con":true,"img":false}]}
{"op":"mcm","clk":"1362103010","pt":1588427614654,"mc":[{"id":"1.170370557","rc":[{"atl":[[1.22,354.25]],"id":9624350}],"con":true,"img":false}]}
{"op":"mcm","clk":"1362103028","pt":1588427616444,"mc":[{"id":"1.170370557","rc":[{"atl":[[1.25,221.63]],"id":9624350}],"con":true,"img":false}]}
{"op":"mcm","clk":"1362103082","pt":1588427620271,"mc":[{"id":"1.170370557","rc":[{"trd":[[1.18,20.47],[1.2,282.39]],"ltp":1.18,"tv":302.86,"id":9624350},{"atb":[[1.2,0],[1.18,433.02]],"id":9624350}],"con":true,"img":false}]}
{"op":"mcm","clk":"1362103110","pt":1588427622571,"mc":[{"id":"1.170370557","rc":[{"trd":[[1.18,25.28]],"ltp":1.18,"tv":25.28,"id":9624350},{"atb":[[1.18,430.62]],"id":9624350}],"con":true,"img":false}]}
{"op":"mcm","clk":"1362103120","pt":1588427623747,"mc":[{"id":"1.170370557","rc":[{"atl":[[1.29,221.63]],"id":9624350}],"con":true,"img":false}]}
{"op":"mcm","clk":"1362103143","pt":1588427625483,"mc":[{"id":"1.170370557","rc":[{"atl":[[1.22,353.41]],"id":9624350}],"con":true,"img":false}]}
{"op":"mcm","clk":"1362103161","pt":1588427626556,"mc":[{"id":"1.170370557","rc":[{"atb":[[1.19,200]],"id":9624350}],"con":true,"img":false}]}
{"op":"mcm","clk":"1362103167","pt":1588427626871,"mc":[{"id":"1.170370557","rc":[{"atb":[[1.17,318.86]],"id":9624350}],"con":true,"img":false}]}
{"op":"mcm","clk":"1362103171","pt":1588427627069,"mc":[{"id":"1.170370557","rc":[{"atb":[[1.17,518.86]],"id":9624350}],"con":true,"img":false}]}
{"op":"mcm","clk":"1362103186","pt":1588427628141,"mc":[{"id":"1.170370557","rc":[{"atb":[[1.16,1135.28]],"id":9624350}],"con":true,"img":false}]}
{"op":"mcm","clk":"1362103188","pt":1588427628242,"mc":[{"id":"1.170370557","rc":[{"atb":[[1.19,243.79]],"id":9624350}],"con":true,"img":false}]}
{"op":"mcm","clk":"1362103191","pt":1588427628448,"mc":[{"id":"1.170370557","rc":[{"atb":[[1.16,1335.28]],"id":9624350}],"con":true,"img":false}]}
{"op":"mcm","clk":"1362103196","pt":1588427628957,"mc":[{"id":"1.170370557","rc":[{"atb":[[1.17,718.86]],"id":9624350}],"con":true,"img":false}]}
{"op":"mcm","clk":"1362103214","pt":1588427630283,"mc":[{"id":"1.170370557","rc":[{"atb":[[1.2,0.67],[1.16,1535.28]],"id":9624350}],"con":true,"img":false}]}
{"op":"mcm","clk":"1362103216","pt":1588427630487,"mc":[{"id":"1.170370557","rc":[{"atl":[[1.21,66.48]],"id":9624350}],"con":true,"img":false}]}
{"op":"mcm","clk":"1362103220","pt":1588427630641,"mc":[{"id":"1.170370557","rc":[{"atl":[[1.21,132.97]],"id":9624350}],"con":true,"img":false}]}
{"op":"mcm","clk":"1362103222","pt":1588427630744,"mc":[{"id":"1.170370557","rc":[{"trd":[[1.19,7.17],[1.2,283.75]],"ltp":1.19,"tv":290.92,"id":9624350},{"atb":[[1.2,0],[1.19,240.2]],"id":9624350}],"con":true,"img":false}]}
{"op":"mcm","clk":"1362103234","pt":1588427631457,"mc":[{"id":"1.170370557","rc":[{"atl":[[1.23,0]],"id":9624350}],"con":true,"img":false}]}
{"op":"mcm","clk":"1362103240","pt":1588427632069,"mc":[{"id":"1.170370557","rc":[{"atl":[[7.2,0]],"id":9622734}],"con":true,"img":false}]}
{"op":"mcm","clk":"1362103264","pt":1588427633292,"mc":[{"id":"1.170370557","rc":[{"trd":[[1.21,751.3]],"ltp":1.21,"tv":751.3,"id":9624350},{"atl":[[1.21,131.95]],"id":9624350}],"con":true,"img":false}]}
{"op":"mcm","clk":"1362103273","pt":1588427633650,"mc":[{"id":"1.170370557","rc":[{"atb":[[1.18,0]],"id":9624350}],"con":true,"img":false}]}
{"op":"mcm","clk":"1362103284","pt":1588427634568,"mc":[{"id":"1.170370557","rc":[{"atl":[[1.22,221.63]],"id":9624350}],"con":true,"img":false}]}
{"op":"mcm","clk":"1362103292","pt":1588427635383,"mc":[{"id":"1.170370557","rc":[{"atb":[[1.19,43.79]],"id":9624350}],"con":true,"img":false}]}
{"op":"mcm","clk":"1362103314","pt":1588427637476,"mc":[{"id":"1.170370557","rc":[{"atl":[[6.2,2]],"id":9622734},{"atl":[[1.21,221.33]],"id":9624350}],"con":true,"img":false}]}
{"op":"mcm","clk":"1362103325","pt":1588427638598,"mc":[{"id":"1.170370557","rc":[{"trd":[[1.19,11.17]],"ltp":1.19,"tv":11.17,"id":9624350},{"atb":[[1.19,41.79]],"id":9624350}],"con":true,"img":false}]}
{"op":"mcm","clk":"1362103340","pt":1588427639976,"mc":[{"id":"1.170370557","rc":[{"trd":[[1.19,18.25]],"ltp":1.19,"tv":18.25,"id":9624350},{"atb":[[1.19,38.25]],"id":9624350}],"con":true,"img":false}]}
{"op":"mcm","clk":"1362103349","pt":1588427640487,"mc":[{"id":"1.170370557","rc":[{"trd":[[1.21,851.3]],"ltp":1.21,"tv":851.3,"id":9624350},{"atl":[[1.21,171.33]],"id":9624350}],"con":true,"img":false}]}
{"op":"mcm","clk":"1362103398","pt":1588427643403,"mc":[{"id":"1.170370557","rc":[{"atl":[[1.21,188.85]],"id":9624350}],"con":true,"img":false}]}
{"op":"mcm","clk":"1362103401","pt":1588427643505,"mc":[{"id":"1.170370557","rc":[{"atl":[[1.24,133.1]],"id":9624350}],"con":true,"img":false}]}
{"op":"mcm","clk":"1362103415","pt":1588427644481,"mc":[{"id":"1.170370557","rc":[{"atl":[[6.2,0]],"id":9622734},{"atb":[[1.17,768.86]],"id":9624350}],"con":true,"img":false}]}
{"op":"mcm","clk":"1362103478","pt":1588427649185,"mc":[{"id":"1.170370557","rc":[{"atl":[[1.21,106.9]],"id":9624350}],"con":true,"img":false}]}
{"op":"mcm","clk":"1362103501","pt":1588427650205,"mc":[{"id":"1.170370557","rc":[{"atb":[[1.2,66.48]],"id":9624350}],"con":true,"img":false}]}
{"op":"mcm","clk":"1362103509","pt":1588427650409,"mc":[{"id":"1.170370557","rc":[{"atl":[[7.2,1.72]],"id":9622734}],"con":true,"img":false}]}
{"op":"mcm","clk":"1362103532","pt":1588427651581,"mc":[{"id":"1.170370557","rc":[{"atl":[[1.22,0]],"id":9624350}],"con":true,"img":false}]}
{"op":"mcm","clk":"1362103543","pt":1588427652091,"mc":[{"id":"1.170370557","rc":[{"atl":[[1.21,17.51]],"id":9624350}],"con":true,"img":false}]}
{"op":"mcm","clk":"1362103559","pt":1588427653516,"mc":[{"id":"1.170370557","rc":[{"atb":[[1.18,0.1]],"id":9624350}],"con":true,"img":false}]}
{"op":"mcm","clk":"1362103563","pt":1588427653720,"mc":[{"id":"1.170370557","rc":[{"trd":[[1.21,859.3]],"ltp":1.21,"tv":859.3,"id":9624350},{"atl":[[1.21,13.51]],"id":9624350}],"con":true,"img":false}]}
{"op":"mcm","clk":"1362103568","pt":1588427653976,"mc":[{"id":"1.170370557","rc":[{"trd":[[1.2,325.2]],"ltp":1.2,"tv":325.2,"id":9624350},{"atb":[[1.2,45.76]],"id":9624350}],"con":true,"img":false}]}
{"op":"mcm","clk":"1362103575","pt":1588427654385,"mc":[{"id":"1.170370557","rc":[{"trd":[[1.21,886.33]],"ltp":1.21,"tv":886.33,"id":9624350},{"atb":[[1.21,52.96]],"id":9624350},{"atl":[[1.21,0]],"id":9624350}],"con":true,"img":false}]}
{"op":"mcm","clk":"1362103582","pt":1588427654793,"mc":[{"id":"1.170370557","rc":[{"atb":[[1.21,119.45]],"id":9624350}],"con":true,"img":false}]}
{"op":"mcm","clk":"1362103585","pt":1588427654894,"mc":[{"id":"1.170370557","rc":[{"atb":[[1.18,43.89]],"id":9624350}],"con":true,"img":false}]}
{"op":"mcm","clk":"1362103587","pt":1588427654996,"mc":[{"id":"1.170370557","rc":[{"atb":[[1.21,185.94]],"id":9624350}],"con":true,"img":false}]}
{"op":"mcm","clk":"1362103600","pt":1588427655404,"mc":[{"id":"1.170370557","rc":[{"atb":[[1.21,252.43]],"id":9624350}],"con":true,"img":false}]}
{"op":"mcm","clk":"1362103658","pt":1588427658922,"mc":[{"id":"1.170370557","rc":[{"atb":[[1.2,489.02]],"id":9624350}],"con":true,"img":false}]}
{"op":"mcm","clk":"1362103665","pt":1588427659227,"mc":[{"id":"1.170370557","rc":[{"atl":[[1.23,87.93]],"id":9624350}],"con":true,"img":false}]}
{"op":"mcm","clk":"1362103684","pt":1588427660912,"mc":[{"id":"1.170370557","rc":[{"atb":[[1.19,44.07]],"id":9624350}],"con":true,"img":false}]}
{"op":"mcm","clk":"1362103691","pt":1588427661319,"mc":[{"id":"1.170370557","rc":[{"atb":[[1.16,1092.02]],"id":9624350}],"con":true,"img":false}]}
{"op":"mcm","clk":"1362103695","pt":1588427661727,"mc":[{"id":"1.170370557","rc":[{"trd":[[1.21,888.03]],"ltp":1.21,"tv":888.03,"id":9624350},{"atb":[[1.21,251.58]],"id":9624350}],"con":true,"img":false}]}
{"op":"mcm","clk":"1362103711","pt":1588427663414,"mc":[{"id":"1.170370557","rc":[{"atl":[[1.27,0]],"id":9624350}],"con":true,"img":false}]}
{"op":"mcm","clk":"1362103717","pt":1588427663823,"mc":[{"id":"1.170370557","rc":[{"atl":[[1.25,0]],"id":9624350}],"con":true,"img":false}]}
{"op":"mcm","clk":"1362103733","pt":1588427665307,"mc":[{"id":"1.170370557","rc":[{"atl":[[1.24,354.73]],"id":9624350}],"con":true,"img":false}]}
{"op":"mcm","clk":"1362103738","pt":1588427665716,"mc":[{"id":"1.170370557","rc":[{"atl":[[1.23,154.42]],"id":9624350}],"con":true,"img":false}]}
{"op":"mcm","clk":"1362103742","pt":1588427665920,"mc":[{"id":"1.170370557","rc":[{"atl":[[1.23,220.91]],"id":9624350}],"con":true,"img":false}]}
{"op":"mcm","clk":"1362103745","pt":1588427666127,"mc":[{"id":"1.170370557","rc":[{"atl":[[1.23,287.4]],"id":9624350}],"con":true,"img":false}]}
{"op":"mcm","clk":"1362103749","pt":1588427666431,"mc":[{"id":"1.170370557","rc":[{"atb":[[1.17,1212.12]],"id":9624350}],"con":true,"img":false}]}
{"op":"mcm","clk":"1362103766","pt":1588427667605,"mc":[{"id":"1.170370557","rc":[{"atl":[[7.8,11.19]],"id":9622734},{"atl":[[1.26,270.04]],"id":9624350}],"con":true,"img":false}]}
{"op":"mcm","clk":"1362103773","pt":1588427668321,"mc":[{"id":"1.170370557","rc":[{"atl":[[1.23,87.93]],"id":9624350}],"con":true,"img":false}]}
{"op":"mcm","clk":"1362103777","pt":1588427668524,"mc":[{"id":"1.170370557","rc":[{"atl":[[1.3,460.75]],"id":9624350}],"con":true,"img":false}]}
{"op":"mcm","clk":"1362103780","pt":1588427668933,"mc":[{"id":"1.170370557","rc":[{"atb":[[1.11,60]],"id":9624350}],"con":true,"img":false}]}
{"op":"mcm","clk":"1362103783","pt":1588427669137,"mc":[{"id":"1.170370557","rc":[{"atl":[[1.23,0]],"id":9624350}],"con":true,"img":false}]}
{"op":"mcm","clk":"1362103795","pt":1588427670208,"mc":[{"id":"1.170370557","rc":[{"atl":[[1.24,133.1]],"id":9624350}],"con":true,"img":false}]}
{"op":"mcm","clk":"1362103797","pt":1588427670309,"mc":[{"id":"1.170370557","rc":[{"atl":[[1.25,17.51]],"id":9624350}],"con":true,"img":false}]}
{"op":"mcm","clk":"1362103800","pt":1588427670514,"mc":[{"id":"1.170370557","rc":[{"atl":[[1.22,30.14]],"id":9624350}],"con":true,"img":false}]}
{"op":"mcm","clk":"1362103802","pt":1588427670616,"mc":[{"id":"1.170370557","rc":[{"atb":[[1.17,768.86]],"id":9624350},{"atl":[[1.3,17.49]],"id":9624350}],"con":true,"img":false}]}
{"op":"mcm","clk":"1362103805","pt":1588427670718,"mc":[{"id":"1.170370557","rc":[{"atb":[[1.2,45.76]],"id":9624350}],"con":true,"img":false}]}
{"op":"mcm","clk":"1362103836","pt":1588427673529,"mc":[{"id":"1.170370557","rc":[{"trd":[[5.5,64.23]],"ltp":5.5,"tv":64.23,"id":9622734},{"atb":[[5.5,8.85]],"id":9622734},{"trd":[[1.23,1698],[1.22,1814.74]],"ltp":1.23,"tv":3512.74,"id":9624350},{"atl":[[1.22,0]],"id":9624350}],"con":true,"img":false}]}
{"op":"mcm","clk":"1362103845","pt":1588427674038,"mc":[{"id":"1.170370557","rc":[{"atb":[[1.22,66.48]],"id":9624350}],"con":true,"img":false}]}
{"op":"mcm","clk":"1362103847","pt":1588427674140,"mc":[{"id":"1.170370557","rc":[{"atb":[[1.17,650]],"id":9624350}],"con":true,"img":false}]}
{"op":"mcm","clk":"1362103851","pt":1588427674241,"mc":[{"id":"1.170370557","rc":[{"atb":[[1.22,132.97]],"id":9624350}],"con":true,"img":false}]}
{"op":"mcm","clk":"1362103854","pt":1588427674445,"mc":[{"id":"1.170370557","rc":[{"atb":[[1.22,199.46],[1.13,824.37]],"id":9624350}],"con":true,"img":false}]}
{"op":"mcm","clk":"1362103857","pt":1588427674598,"mc":[{"id":"1.170370557","rc":[{"atl":[[7.8,0]],"id":9622734},{"atb":[[1.22,265.95]],"id":9624350}],"con":true,"img":false}]}
{"op":"mcm","clk":"1362103873","pt":1588427675514,"mc":[{"id":"1.170370557","rc":[{"atl":[[1.25,104.04]],"id":9624350}],"con":true,"img":false}]}
{"op":"mcm","clk":"1362103890","pt":1588427676943,"mc":[{"id":"1.170370557","rc":[{"atl":[[1.25,547.3]],"id":9624350}],"con":true,"img":false}]}
{"op":"mcm","clk":"1362103909","pt":1588427678219,"mc":[{"id":"1.170370557","rc":[{"atb":[[1.22,487.58]],"id":9624350}],"con":true,"img":false}]}
{"op":"mcm","clk":"1362103925","pt":1588427679136,"mc":[{"id":"1.170370557","rc":[{"atb":[[1.2,489.02]],"id":9624350}],"con":true,"img":false}]}
{"op":"mcm","clk":"1362103932","pt":1588427679646,"mc":[{"id":"1.170370557","rc":[{"atb":[[1.21,473.21]],"id":9624350},{"atl":[[1.23,66.48]],"id":9624350}],"con":true,"img":false}]}
{"op":"mcm","clk":"1362103935","pt":1588427679849,"mc":[{"id":"1.170370557","rc":[{"atl":[[1.23,132.97]],"id":9624350}],"con":true,"img":false}]}
{"op":"mcm","clk":"1362103943","pt":1588427680512,"mc":[{"id":"1.170370557","rc":[{"atl":[[1.23,145.1]],"id":9624350}],"con":true,"img":false}]}
{"op":"mcm","clk":"1362103955","pt":1588427681838,"mc":[{"id":"1.170370557","rc":[{"atl":[[1.24,354.73]],"id":9624350}],"con":true,"img":false}]}
{"op":"mcm","clk":"1362103964","pt":1588427682708,"mc":[{"id":"1.170370557","rc":[{"atb":[[1.17,600]],"id":9624350}],"con":true,"img":false}]}
{"op":"mcm","clk":"1362103971","pt":1588427683626,"mc":[{"id":"1.170370557","rc":[{"trd":[[1.23,1708.64]],"ltp":1.23,"tv":1708.64,"id":9624350},{"atl":[[1.23,139.78]],"id":9624350}],"con":true,"img":false}]}
{"op":"mcm","clk":"1362103985","pt":1588427684957,"mc":[{"id":"1.170370557","rc":[{"atl":[[1.24,355.08]],"id":9624350}],"con":true,"img":false}]}
{"op":"mcm","clk":"1362104017","pt":1588427687920,"mc":[{"id":"1.170370557","rc":[{"trd":[[1.22,1823.61]],"ltp":1.22,"tv":1823.61,"id":9624350},{"atb":[[1.22,483.15]],"id":9624350}],"con":true,"img":false}]}
{"op":"mcm","clk":"1362104023","pt":1588427688532,"mc":[{"id":"1.170370557","rc":[{"atb":[[1.22,221.63]],"id":9624350}],"con":true,"img":false}]}
{"op":"mcm","clk":"1362104030","pt":1588427689042,"mc":[{"id":"1.170370557","rc":[{"atl":[[1.3,0]],"id":9624350}],"con":true,"img":false}]}
{"op":"mcm","clk":"1362104044","pt":1588427689962,"mc":[{"id":"1.170370557","rc":[{"atb":[[1.13,492.02]],"id":9624350}],"con":true,"img":false}]}
{"op":"mcm","clk":"1362104046","pt":1588427690216,"mc":[{"id":"1.170370557","rc":[{"atl":[[1.25,460.78]],"id":9624350}],"con":true,"img":false}]}
{"op":"mcm","clk":"1362104052","pt":1588427690534,"mc":[{"id":"1.170370557","rc":[{"trd":[[1.23,1744.1]],"ltp":1.23,"tv":1744.1,"id":9624350},{"atl":[[1.23,122.05]],"id":9624350}],"con":true,"img":false}]}
{"op":"mcm","clk":"1362104055","pt":1588427690740,"mc":[{"id":"1.170370557","rc":[{"atb":[[1.22,0]],"id":9624350}],"con":true,"img":false}]}
{"op":"mcm","clk":"1362104059","pt":1588427691149,"mc":[{"id":"1.170370557","rc":[{"trd":[[1.23,1792.63]],"ltp":1.23,"tv":1792.63,"id":9624350},{"atb":[[1.18,161.75]],"id":9624350},{"atl":[[1.23,97.79]],"id":9624350}],"con":true,"img":false}]}
{"op":"mcm","clk":"1362104067","pt":1588427692015,"mc":[{"id":"1.170370557","rc":[{"atb":[[1.2,532.81]],"id":9624350}],"con":true,"img":false}]}
{"op":"mcm","clk":"1362104074","pt":1588427692424,"mc":[{"id":"1.170370557","rc":[{"atl":[[1.23,164.28]],"id":9624350}],"con":true,"img":false}]}
{"op":"mcm","clk":"1362104078","pt":1588427692629,"mc":[{"id":"1.170370557","rc":[{"atl":[[1.23,230.77]],"id":9624350}],"con":true,"img":false}]}
{"op":"mcm","clk":"1362104082","pt":1588427692833,"mc":[{"id":"1.170370557","rc":[{"atl":[[1.22,29.59]],"id":9624350}],"con":true,"img":false}]}
{"op":"mcm","clk":"1362104083","pt":1588427692934,"mc":[{"id":"1.170370557","rc":[{"atl":[[1.22,96.08]],"id":9624350}],"con":true,"img":false}]}
{"op":"mcm","clk":"1362104084","pt":1588427693036,"mc":[{"id":"1.170370557","rc":[{"atb":[[1.21,251.58]],"id":9624350}],"con":true,"img":false}]}
{"op":"mcm","clk":"1362104086","pt":1588427693138,"mc":[{"id":"1.170370557","rc":[{"trd":[[1.22,1826.37]],"ltp":1.22,"tv":1826.37,"id":9624350},{"atb":[[1.18,456.96]],"id":9624350},{"atl":[[1.22,94.7]],"id":9624350}],"con":true,"img":false}]}
{"op":"mcm","clk":"1362104089","pt":1588427693242,"mc":[{"id":"1.170370557","rc":[{"atl":[[1.22,161.19]],"id":9624350}],"con":true,"img":false}]}
{"op":"mcm","clk":"1362104092","pt":1588427693344,"mc":[{"id":"1.170370557","rc":[{"atl":[[1.22,172.71]],"id":9624350}],"con":true,"img":false}]}
{"op":"mcm","clk":"1362104109","pt":1588427694263,"mc":[{"id":"1.170370557","rc":[{"atl":[[1.25,478.27]],"id":9624350}],"con":true,"img":false}]}
{"op":"mcm","clk":"1362104114","pt":1588427694568,"mc":[{"id":"1.170370557","rc":[{"trd":[[5.5,80.22]],"ltp":5.5,"tv":80.22,"id":9622734},{"atb":[[5.5,0.85]],"id":9622734}],"con":true,"img":false}]}
{"op":"mcm","clk":"1362104120","pt":1588427695026,"mc":[{"id":"1.170370557","rc":[{"atl":[[1.22,615.97]],"id":9624350}],"con":true,"img":false}]}
{"op":"mcm","clk":"1362104125","pt":1588427695432,"mc":[{"id":"1.170370557","rc":[{"atb":[[1.11,421.02]],"id":9624350}],"con":true,"img":false}]}
{"op":"mcm","clk":"1362104134","pt":1588427696044,"mc":[{"id":"1.170370557","rc":[{"atl":[[1.22,704.62]],"id":9624350}],"con":true,"img":false}]}
{"op":"mcm","clk":"1362104148","pt":1588427697265,"mc":[{"id":"1.170370557","rc":[{"atl":[[1.22,926.26]],"id":9624350}],"con":true,"img":false}]}
{"op":"mcm","clk":"1362104155","pt":1588427697672,"mc":[{"id":"1.170370557","rc":[{"atl":[[1.22,914.73]],"id":9624350}],"con":true,"img":false}]}
{"op":"mcm","clk":"1362104191","pt":1588427700836,"mc":[{"id":"1.170370557","rc":[{"atb":[[1.17,1043.26]],"id":9624350}],"con":true,"img":false}]}
{"op":"mcm","clk":"1362104211","pt":1588427701960,"mc":[{"id":"1.170370557","rc":[{"atb":[[1.21,301.58]],"id":9624350}],"con":true,"img":false}]}
{"op":"mcm","clk":"1362104226","pt":1588427702728,"mc":[{"id":"1.170370557","rc":[{"trd":[[1.21,911.08]],"ltp":1.21,"tv":911.08,"id":9624350},{"atb":[[1.21,290.06]],"id":9624350}],"con":true,"img":false}]}
{"op":"mcm","clk":"1362104234","pt":1588427703237,"mc":[{"id":"1.170370557","rc":[{"atb":[[1.2,754.45]],"id":9624350}],"con":true,"img":false}]}
{"op":"mcm","clk":"1362104236","pt":1588427703339,"mc":[{"id":"1.170370557","rc":[{"atb":[[1.18,161.75]],"id":9624350}],"con":true,"img":false}]}
{"op":"mcm","clk":"1362104241","pt":1588427703646,"mc":[{"id":"1.170370557","rc":[{"atl":[[1.29,0]],"id":9624350}],"con":true,"img":false}]}
{"op":"mcm","clk":"1362104274","pt":1588427705035,"mc":[{"id":"1.170370557","rc":[{"atb":[[1.18,383.38]],"id":9624350}],"con":true,"img":false}]}
{"op":"mcm","clk":"1362104298","pt":1588427706365,"mc":[{"id":"1.170370557","rc":[{"atl":[[1.22,471.47]],"id":9624350}],"con":true,"img":false}]}
{"op":"mcm","clk":"1362104308","pt":1588427707336,"mc":[{"id":"1.170370557","rc":[{"atb":[[1.2,311.18]],"id":9624350}],"con":true,"img":false}]}
{"op":"mcm","clk":"1362104313","pt":1588427707745,"mc":[{"id":"1.170370557","rc":[{"atl":[[1.24,372.59]],"id":9624350}],"con":true,"img":false}]}
{"op":"mcm","clk":"1362104316","pt":1588427708052,"mc":[{"id":"1.170370557","rc":[{"trd":[[5.5,132.64]],"ltp":5.5,"tv":132.64,"id":9622734},{"atb":[[5.5,0]],"id":9622734},{"trd":[[1.22,2054.92]],"ltp":1.22,"tv":2054.92,"id":9624350},{"atl":[[1.22,242.92]],"id":9624350}],"con":true,"img":false}]}
{"op":"mcm","clk":"1362104328","pt":1588427708975,"mc":[{"id":"1.170370557","rc":[{"atb":[[1.21,240.06]],"id":9624350}],"con":true,"img":false}]}
{"op":"mcm","clk":"1362104371","pt":1588427712142,"mc":[{"id":"1.170370557","rc":[{"atl":[[1.26,221.63]],"id":9624350}],"con":true,"img":false}]}
{"op":"mcm","clk":"1362104378","pt":1588427712653,"mc":[{"id":"1.170370557","rc":[{"atb":[[1.21,173.57]],"id":9624350}],"con":true,"img":false}]}
{"op":"mcm","clk":"1362104410","pt":1588427715359,"mc":[{"id":"1.170370557","rc":[{"trd":[[1.21,962.22]],"ltp":1.21,"tv":962.22,"id":9624350},{"atb":[[1.21,81.51]],"id":9624350}],"con":true,"img":false}]}
{"op":"mcm","clk":"1362104430","pt":1588427717248,"mc":[{"id":"1.170370557","rc":[{"trd":[[1.21,1059.03]],"ltp":1.21,"tv":1059.03,"id":9624350},{"atb":[[1.21,33.11]],"id":9624350}],"con":true,"img":false}]}
{"op":"mcm","clk":"1362104437","pt":1588427718062,"mc":[{"id":"1.170370557","rc":[{"trd":[[1.21,1125.26]],"ltp":1.21,"tv":1125.26,"id":9624350},{"atb":[[1.21,0]],"id":9624350},{"atl":[[1.21,16.89]],"id":9624350}],"con":true,"img":false}]}
{"op":"mcm","clk":"1362104447","pt":1588427718878,"mc":[{"id":"1.170370557","rc":[{"atb":[[1.19,87.87]],"id":9624350}],"con":true,"img":false}]}
{"op":"mcm","clk":"1362104479","pt":1588427721989,"mc":[{"id":"1.170370557","rc":[{"atl":[[1.21,0]],"id":9624350}],"con":true,"img":false}]}
{"op":"mcm","clk":"1362104507","pt":1588427723781,"mc":[{"id":"1.170370557","rc":[{"atl":[[1.22,309.41]],"id":9624350}],"con":true,"img":false}]}
{"op":"mcm","clk":"1362104514","pt":1588427723985,"mc":[{"id":"1.170370557","rc":[{"atl":[[1.22,375.9]],"id":9624350}],"con":true,"img":false}]}
{"op":"mcm","clk":"1362104519","pt":1588427724189,"mc":[{"id":"1.170370557","rc":[{"atl":[[1.22,442.39]],"id":9624350}],"con":true,"img":false}]}
{"op":"mcm","clk":"1362104605","pt":1588427729711,"mc":[{"id":"1.170370557","rc":[{"trd":[[1.22,2055.39]],"ltp":1.22,"tv":2055.39,"id":9624350},{"atl":[[1.22,442.16]],"id":9624350}],"con":true,"img":false}]}
{"op":"mcm","clk":"1362104617","pt":1588427730883,"mc":[{"id":"1.170370557","rc":[{"atb":[[1.2,265.42]],"id":9624350}],"con":true,"img":false}]}
{"op":"mcm","clk":"1362104618","pt":1588427730984,"mc":[{"id":"1.170370557","rc":[{"atb":[[1.11,60]],"id":9624350}],"con":true,"img":false}]}
{"op":"mcm","clk":"1362104620","pt":1588427731188,"mc":[{"id":"1.170370557","rc":[{"atb":[[1.2,43.79]],"id":9624350}],"con":true,"img":false}]}
{"op":"mcm","clk":"1362104633","pt":1588427732311,"mc":[{"id":"1.170370557","rc":[{"atb":[[1.18,161.75]],"id":9624350}],"con":true,"img":false}]}
{"op":"mcm","clk":"1362104638","pt":1588427732776,"mc":[{"id":"1.170370557","rc":[{"atl":[[1.24,390.11]],"id":9624350}],"con":true,"img":false}]}
{"op":"mcm","clk":"1362104659","pt":1588427734407,"mc":[{"id":"1.170370557","rc":[{"atb":[[1.21,1.65]],"id":9624350}],"con":true,"img":false}]}
{"op":"mcm","clk":"1362104662","pt":1588427734612,"mc":[{"id":"1.170370557","rc":[{"atl":[[5.9,50]],"id":9622734}],"con":true,"img":false}]}
{"op":"mcm","clk":"1362104664","pt":1588427734713,"mc":[{"id":"1.170370557","rc":[{"trd":[[1.21,1128.55]],"ltp":1.21,"tv":1128.55,"id":9624350},{"atb":[[1.21,0]],"id":9624350},{"atl":[[1.21,64.84]],"id":9624350}],"con":true,"img":false}]}
{"op":"mcm","clk":"1362104669","pt":1588427735019,"mc":[{"id":"1.170370557","rc":[{"trd":[[5.9,4.62]],"ltp":5.9,"tv":4.62,"id":9622734},{"atl":[[5.9,45.38]],"id":9622734},{"trd":[[1.2,435.49]],"ltp":1.2,"tv":435.49,"id":9624350},{"atb":[[1.2,0]],"id":9624350}],"con":true,"img":false}]}
{"op":"mcm","clk":"1362104673","pt":1588427735172,"mc":[{"id":"1.170370557","rc":[{"trd":[[5.9,50]],"ltp":5.9,"tv":50.0,"id":9622734},{"atl":[[5.9,0]],"id":9622734},{"trd":[[1.2,658.61]],"ltp":1.2,"tv":658.61,"id":9624350},{"atl":[[1.2,286.63]],"id":9624350}],"con":true,"img":false}]}
{"op":"mcm","clk":"1362104679","pt":1588427735378,"mc":[{"id":"1.170370557","rc":[{"atl":[[1.2,353.12]],"id":9624350}],"con":true,"img":false}]}
{"op":"mcm","clk":"1362104688","pt":1588427736195,"mc":[{"id":"1.170370557","rc":[{"atl":[[1.2,419.6]],"id":9624350}],"con":true,"img":false}]}
{"op":"mcm","clk":"1362104691","pt":1588427736603,"mc":[{"id":"1.170370557","rc":[{"atb":[[1.09,411.32]],"id":9624350}],"con":true,"img":false}]}
{"op":"mcm","clk":"1362104694","pt":1588427736706,"mc":[{"id":"1.170370557","rc":[{"trd":[[1.19,193.98]],"ltp":1.19,"tv":193.98,"id":9624350},{"atb":[[1.19,0]],"id":9624350},{"atl":[[1.19,133.76]],"id":9624350}],"con":true,"img":false}]}
{"op":"mcm","clk":"1362104697","pt":1588427736910,"mc":[{"id":"1.170370557","rc":[{"atl":[[1.22,421.09]],"id":9624350}],"con":true,"img":false}]}
{"op":"mcm","clk":"1362104700","pt":1588427737114,"mc":[{"id":"1.170370557","rc":[{"atl":[[1.2,824.96]],"id":9624350}],"con":true,"img":false}]}
{"op":"mcm","clk":"1362104745","pt":1588427740082,"mc":[{"id":"1.170370557","rc":[{"atl":[[1.2,829.96]],"id":9624350}],"con":true,"img":false}]}
{"op":"mcm","clk":"1362104748","pt":1588427740179,"mc":[{"id":"1.170370557","rc":[{"atb":[[1.18,43.89]],"id":9624350}],"con":true,"img":false}]}
{"op":"mcm","clk":"1362104762","pt":1588427741709,"mc":[{"id":"1.170370557","rc":[{"trd":[[1.19,461.51]],"ltp":1.19,"tv":461.51,"id":9624350},{"atb":[[1.19,309.49]],"id":9624350},{"atl":[[1.19,0]],"id":9624350}],"con":true,"img":false}]}
{"op":"mcm","clk":"1362104766","pt":1588427742015,"mc":[{"id":"1.170370557","rc":[{"atl":[[1.2,824.96]],"id":9624350}],"con":true,"img":false}]}
{"op":"mcm","clk":"1362104771","pt":1588427742628,"mc":[{"id":"1.170370557","rc":[{"atb":[[1.19,0]],"id":9624350}],"con":true,"img":false}]}
{"op":"mcm","clk":"1362104774","pt":1588427742886,"mc":[{"id":"1.170370557","rc":[{"atb":[[1.18,265.52],[1.13,935.28]],"id":9624350}],"con":true,"img":false}]}
{"op":"mcm","clk":"1362104784","pt":1588427743496,"mc":[{"id":"1.170370557","rc":[{"atl":[[1.2,419.6]],"id":9624350}],"con":true,"img":false}]}
{"op":"mcm","clk":"1362104786","pt":1588427743802,"mc":[{"id":"1.170370557","rc":[{"atb":[[1.18,354.18]],"id":9624350}],"con":true,"img":false}]}
{"op":"mcm","clk":"1362104787","pt":1588427743904,"mc":[{"id":"1.170370557","rc":[{"atb":[[1.18,386.08]],"id":9624350}],"con":true,"img":false}]}
{"op":"mcm","clk":"1362104800","pt":1588427744621,"mc":[{"id":"1.170370557","rc":[{"atb":[[1.17,600]],"id":9624350}],"con":true,"img":false}]}
{"op":"mcm","clk":"1362104826","pt":1588427746309,"mc":[{"id":"1.170370557","rc":[{"atb":[[1.17,718.86]],"id":9624350}],"con":true,"img":false}]}
{"op":"mcm","clk":"1362104834","pt":1588427747083,"mc":[{"id":"1.170370557","rc":[{"atb":[[1.16,1135.81]],"id":9624350}],"con":true,"img":false}]}
{"op":"mcm","clk":"1362104842","pt":1588427747899,"mc":[{"id":"1.170370557","rc":[{"trd":[[6.2,3.19]],"ltp":6.2,"tv":3.19,"id":9622734},{"trd":[[1.18,44.42],[1.19,478.18]],"ltp":1.18,"tv":522.6,"id":9624350},{"atb":[[1.18,376.5]],"id":9624350}],"con":true,"img":false}]}
{"op":"mcm","clk":"1362104847","pt":1588427748102,"mc":[{"id":"1.170370557","rc":[{"atb":[[1.17,118.86]],"id":9624350}],"con":true,"img":false}]}
{"op":"mcm","clk":"1362104850","pt":1588427748204,"mc":[{"id":"1.170370557","rc":[{"atl":[[1.2,441.02]],"id":9624350}],"con":true,"img":false}]}
{"op":"mcm","clk":"1362104852","pt":1588427748411,"mc":[{"id":"1.170370557","rc":[{"atb":[[1.18,455.87]],"id":9624350}],"con":true,"img":false}]}
{"op":"mcm","clk":"1362104855","pt":1588427748615,"mc":[{"id":"1.170370557","rc":[{"atb":[[1.16,535.81]],"id":9624350}],"con":true,"img":false}]}
{"op":"mcm","clk":"1362104862","pt":1588427749432,"mc":[{"id":"1.170370557","rc":[{"atb":[[1.17,0]],"id":9624350}],"con":true,"img":false}]}
{"op":"mcm","clk":"1362104865","pt":1588427749689,"mc":[{"id":"1.170370557","rc":[{"atl":[[1.24,257.01]],"id":9624350}],"con":true,"img":false}]}
{"op":"mcm","clk":"1362104883","pt":1588427750609,"mc":[{"id":"1.170370557","rc":[{"atb":[[1.19,66.48]],"id":9624350}],"con":true,"img":false}]}
{"op":"mcm","clk":"1362104905","pt":1588427751992,"mc":[{"id":"1.170370557","rc":[{"trd":[[1.19,611.16]],"ltp":1.19,"tv":611.16,"id":9624350},{"atb":[[1.19,0]],"id":9624350},{"atl":[[1.19,72.2]],"id":9624350}],"con":true,"img":false}]}
{"op":"mcm","clk":"1362104910","pt":1588427752399,"mc":[{"id":"1.170370557","rc":[{"trd":[[1.18,56.83]],"ltp":1.18,"tv":56.83,"id":9624350},{"atb":[[1.18,449.66]],"id":9624350}],"con":true,"img":false}]}
{"op":"mcm","clk":"1362104911","pt":1588427752707,"mc":[{"id":"1.170370557","rc":[{"atl":[[1.23,12.12],[1000,2.63]],"id":9624350}],"con":true,"img":false}]}
{"op":"mcm","clk":"1362104921","pt":1588427753319,"mc":[{"id":"1.170370557","rc":[{"trd":[[1.18,66.83]],"ltp":1.18,"tv":66.83,"id":9624350},{"atb":[[1.18,444.66]],"id":9624350}],"con":true,"img":false}]}
{"op":"mcm","clk":"1362104924","pt":1588427753523,"mc":[{"id":"1.170370557","rc":[{"atb":[[1.18,498.84]],"id":9624350}],"con":true,"img":false}]}
{"op":"mcm","clk":"1362104926","pt":1588427753626,"mc":[{"id":"1.170370557","rc":[{"atl":[[1000,0.06]],"id":9624350}],"con":true,"img":false}]}
{"op":"mcm","clk":"1362104934","pt":1588427754395,"mc":[{"id":"1.170370557","rc":[{"atb":[[1.16,43.79]],"id":9624350}],"con":true,"img":false}]}
{"op":"mcm","clk":"1362104938","pt":1588427754497,"mc":[{"id":"1.170370557","rc":[{"atl":[[1000,0]],"id":9624350}],"con":true,"img":false}]}
{"op":"mcm","clk":"1362104943","pt":1588427754802,"mc":[{"id":"1.170370557","rc":[{"atb":[[1.18,444.66]],"id":9624350}],"con":true,"img":false}]}
{"op":"mcm","clk":"1362104952","pt":1588427755315,"mc":[{"id":"1.170370557","rc":[{"trd":[[1.18,877.56]],"ltp":1.18,"tv":877.56,"id":9624350},{"atb":[[1.18,39.29]],"id":9624350}],"con":true,"img":false}]}
{"op":"mcm","clk":"1362104958","pt":1588427755721,"mc":[{"id":"1.170370557","rc":[{"atl":[[1.2,220.88]],"id":9624350}],"con":true,"img":false}]}
{"op":"mcm","clk":"1362104975","pt":1588427756999,"mc":[{"id":"1.170370557","rc":[{"atb":[[1.09,0.31]],"id":9624350}],"con":true,"img":false}]}
{"op":"mcm","clk":"1362104983","pt":1588427757409,"mc":[{"id":"1.170370557","rc":[{"atl":[[1.22,199.46]],"id":9624350}],"con":true,"img":false}]}
{"op":"mcm","clk":"1362104985","pt":1588427757614,"mc":[{"id":"1.170370557","rc":[{"atl":[[1.2,21.41],[1.21,0],[1.22,0]],"id":9624350}],"con":true,"img":false}]}
{"op":"mcm","clk":"1362105000","pt":1588427758537,"mc":[{"id":"1.170370557","rc":[{"atl":[[1.19,0]],"id":9624350}],"con":true,"img":false}]}
{"op":"mcm","clk":"1362105005","pt":1588427758692,"mc":[{"id":"1.170370557","rc":[{"atl":[[1.2,0]],"id":9624350}],"con":true,"img":false}]}
{"op":"mcm","clk":"1362105015","pt":1588427759406,"mc":[{"id":"1.170370557","rc":[{"atb":[[1.2,0.58]],"id":9624350}],"con":true,"img":false}]}
{"op":"mcm","clk":"1362105019","pt":1588427759611,"mc":[{"id":"1.170370557","rc":[{"trd":[[1.2,658.73]],"ltp":1.2,"tv":658.73,"id":9624350},{"atb":[[1.2,4.52]],"id":9624350}],"con":true,"img":false}]}
{"op":"mcm","clk":"1362105021","pt":1588427759714,"mc":[{"id":"1.170370557","rc":[{"atb":[[1.19,492.02]],"id":9624350}],"con":true,"img":false}]}
{"op":"mcm","clk":"1362105037","pt":1588427761093,"mc":[{"id":"1.170370557","rc":[{"atb":[[1.2,8.08]],"id":9624350}],"con":true,"img":false}]}
{"op":"mcm","clk":"1362105046","pt":1588427762114,"mc":[{"id":"1.170370557","rc":[{"atb":[[1.2,46.72]],"id":9624350}],"con":true,"img":false}]}
{"op":"mcm","clk":"1362105049","pt":1588427762318,"mc":[{"id":"1.170370557","rc":[{"atl":[[1.22,17.51]],"id":9624350}],"con":true,"img":false}]}
{"op":"mcm","clk":"1362105054","pt":1588427762523,"mc":[{"id":"1.170370557","rc":[{"atb":[[1.17,57.35]],"id":9624350}],"con":true,"img":false}]}
{"op":"mcm","clk":"1362105055","pt":1588427762624,"mc":[{"id":"1.170370557","rc":[{"atb":[[1.11,421.02]],"id":9624350}],"con":true,"img":false}]}
{"op":"mcm","clk":"1362105058","pt":1588427762934,"mc":[{"id":"1.170370557","rc":[{"trd":[[1.22,2075.33]],"ltp":1.22,"tv":2075.33,"id":9624350},{"atl":[[1.22,7.54]],"id":9624350}],"con":true,"img":false}]}
{"op":"mcm","clk":"1362105062","pt":1588427763037,"mc":[{"id":"1.170370557","rc":[{"atb":[[1.19,542.02]],"id":9624350}],"con":true,"img":false}]}
{"op":"mcm","clk":"1362105067","pt":1588427763344,"mc":[{"id":"1.170370557","rc":[{"atb":[[1.2,46.19]],"id":9624350}],"con":true,"img":false}]}
{"op":"mcm","clk":"1362105072","pt":1588427763805,"mc":[{"id":"1.170370557","rc":[{"atb":[[1.2,267.82],[1.18,0]],"id":9624350}],"con":true,"img":false}]}
{"op":"mcm","clk":"1362105077","pt":1588427764318,"mc":[{"id":"1.170370557","rc":[{"atb":[[1.2,366.58]],"id":9624350}],"con":true,"img":false}]}
{"op":"mcm","clk":"1362105087","pt":1588427764933,"mc":[{"id":"1.170370557","rc":[{"atb":[[1.17,0]],"id":9624350},{"atl":[[1.22,114.35]],"id":9624350}],"con":true,"img":false}]}
{"op":"mcm","clk":"1362105091","pt":1588427765343,"mc":[{"id":"1.170370557","rc":[{"atl":[[1.22,558.35]],"id":9624350}],"con":true,"img":false}]}
{"op":"mcm","clk":"1362105101","pt":1588427766011,"mc":[{"id":"1.170370557","rc":[{"atb":[[1.19,544.59]],"id":9624350}],"con":true,"img":false}]}
{"op":"mcm","clk":"1362105103","pt":1588427766113,"mc":[{"id":"1.170370557","rc":[{"atl":[[1.22,779.98]],"id":9624350}],"con":true,"img":false}]}
{"op":"mcm","clk":"1362105114","pt":1588427766524,"mc":[{"id":"1.170370557","rc":[{"atl":[[1.23,81.97]],"id":9624350}],"con":true,"img":false}]}
{"op":"mcm","clk":"1362105127","pt":1588427767338,"mc":[{"id":"1.170370557","rc":[{"atb":[[1.19,52.57]],"id":9624350}],"con":true,"img":false}]}
{"op":"mcm","clk":"1362105142","pt":1588427768211,"mc":[{"id":"1.170370557","rc":[{"atb":[[1.16,535.81]],"id":9624350}],"con":true,"img":false}]}
{"op":"mcm","clk":"1362105150","pt":1588427768924,"mc":[{"id":"1.170370557","rc":[{"atl":[[1.23,69.85]],"id":9624350}],"con":true,"img":false}]}
{"op":"mcm","clk":"1362105157","pt":1588427769432,"mc":[{"id":"1.170370557","rc":[{"atb":[[1.15,935.28]],"id":9624350},{"atl":[[1.22,850.4]],"id":9624350}],"con":true,"img":false}]}
{"op":"mcm","clk":"1362105164","pt":1588427769840,"mc":[{"id":"1.170370557","rc":[{"atb":[[1.19,53.63]],"id":9624350}],"con":true,"img":false}]}
{"op":"mcm","clk":"1362105170","pt":1588427770711,"mc":[{"id":"1.170370557","rc":[{"atb":[[1.2,327.94]],"id":9624350}],"con":true,"img":false}]}
{"op":"mcm","clk":"1362105182","pt":1588427771729,"mc":[{"id":"1.170370557","rc":[{"atb":[[1.19,51.05]],"id":9624350}],"con":true,"img":false}]}
{"op":"mcm","clk":"1362105191","pt":1588427772854,"mc":[{"id":"1.170370557","rc":[{"trd":[[1.22,2075.69]],"ltp":1.22,"tv":2075.69,"id":9624350},{"atl":[[1.22,850.22]],"id":9624350}],"con":true,"img":false}]}
{"op":"mcm","clk":"1362105200","pt":1588427773520,"mc":[{"id":"1.170370557","rc":[{"atb":[[1.2,277.94],[1.19,50]],"id":9624350}],"con":true,"img":false}]}
{"op":"mcm","clk":"1362105207","pt":1588427773926,"mc":[{"id":"1.170370557","rc":[{"atb":[[1.17,43.79]],"id":9624350}],"con":true,"img":false}]}
{"op":"mcm","clk":"1362105218","pt":1588427774536,"mc":[{"id":"1.170370557","rc":[{"atb":[[1.2,229.18]],"id":9624350}],"con":true,"img":false}]}
{"op":"mcm","clk":"1362105219","pt":1588427774638,"mc":[{"id":"1.170370557","rc":[{"trd":[[1.22,2076.87]],"ltp":1.22,"tv":2076.87,"id":9624350},{"atb":[[1.19,0]],"id":9624350},{"atl":[[1.22,849.63]],"id":9624350}],"con":true,"img":false}]}
{"op":"mcm","clk":"1362105246","pt":1588427776730,"mc":[{"id":"1.170370557","rc":[{"atb":[[1.2,7.55]],"id":9624350}],"con":true,"img":false}]}
{"op":"mcm","clk":"1362105248","pt":1588427776931,"mc":[{"id":"1.170370557","rc":[{"atl":[[1.22,845.7]],"id":9624350}],"con":true,"img":false}]}
{"op":"mcm","clk":"1362105250","pt":1588427777037,"mc":[{"id":"1.170370557","rc":[{"atb":[[1.11,60]],"id":9624350},{"atl":[[1.22,912.19]],"id":9624350}],"con":true,"img":false}]}
{"op":"mcm","clk":"1362105253","pt":1588427777238,"mc":[{"id":"1.170370557","rc":[{"atl":[[1.22,978.68]],"id":9624350}],"con":true,"img":false}]}
{"op":"mcm","clk":"1362105256","pt":1588427777443,"mc":[{"id":"1.170370557","rc":[{"atl":[[1.23,0]],"id":9624350}],"con":true,"img":false}]}
{"op":"mcm","clk":"1362105265","pt":1588427778361,"mc":[{"id":"1.170370557","rc":[{"trd":[[1.2,673.84]],"ltp":1.2,"tv":673.84,"id":9624350},{"atb":[[1.2,0]],"id":9624350},{"atl":[[1.19,484.46]],"id":9624350}],"con":true,"img":false}]}
{"op":"mcm","clk":"1362105269","pt":1588427778721,"mc":[{"id":"1.170370557","rc":[{"atl":[[1.19,928.46]],"id":9624350}],"con":true,"img":false}]}
{"op":"mcm","clk":"1362105287","pt":1588427780247,"mc":[{"id":"1.170370557","rc":[{"trd":[[1.19,646.62]],"ltp":1.19,"tv":646.62,"id":9624350},{"atl":[[1.19,910.73]],"id":9624350}],"con":true,"img":false}]}
{"op":"mcm","clk":"1362105294","pt":1588427780860,"mc":[{"id":"1.170370557","rc":[{"atb":[[1.18,54.17]],"id":9624350}],"con":true,"img":false}]}
{"op":"mcm","clk":"1362105299","pt":1588427781321,"mc":[{"id":"1.170370557","rc":[{"atl":[[1.2,66.48]],"id":9624350}],"con":true,"img":false}]}
{"op":"mcm","clk":"1362105300","pt":1588427781424,"mc":[{"id":"1.170370557","rc":[{"atl":[[1.2,132.97]],"id":9624350}],"con":true,"img":false}]}
{"op":"mcm","clk":"1362105303","pt":1588427781626,"mc":[{"id":"1.170370557","rc":[{"atb":[[1.18,0]],"id":9624350}],"con":true,"img":false}]}
{"op":"mcm","clk":"1362105306","pt":1588427781833,"mc":[{"id":"1.170370557","rc":[{"atl":[[1.2,199.46]],"id":9624350}],"con":true,"img":false}]}
{"op":"mcm","clk":"1362105307","pt":1588427781935,"mc":[{"id":"1.170370557","rc":[{"atl":[[1.22,871.87]],"id":9624350}],"con":true,"img":false}]}
{"op":"mcm","clk":"1362105309","pt":1588427782135,"mc":[{"id":"1.170370557","rc":[{"atl":[[1.19,665.63]],"id":9624350}],"con":true,"img":false}]}
{"op":"mcm","clk":"1362105315","pt":1588427782645,"mc":[{"id":"1.170370557","rc":[{"trd":[[1.19,651.78]],"ltp":1.19,"tv":651.78,"id":9624350},{"atb":[[1.09,411.32]],"id":9624350},{"atl":[[1.19,663.05],[1.24,35.38]],"id":9624350}],"con":true,"img":false}]}
{"op":"mcm","clk":"1362105317","pt":1588427782747,"mc":[{"id":"1.170370557","rc":[{"atl":[[1.2,265.95]],"id":9624350}],"con":true,"img":false}]}
{"op":"mcm","clk":"1362105318","pt":1588427782849,"mc":[{"id":"1.170370557","rc":[{"atl":[[1.2,332.44],[1.18,50]],"id":9624350}],"con":true,"img":false}]}
{"op":"mcm","clk":"1362105320","pt":1588427782951,"mc":[{"id":"1.170370557","rc":[{"atl":[[1.21,71]],"id":9624350}],"con":true,"img":false}]}
{"op":"mcm","clk":"1362105326","pt":1588427783665,"mc":[{"id":"1.170370557","rc":[{"trd":[[1.18,892.79]],"ltp":1.18,"tv":892.79,"id":9624350},{"atl":[[1.18,42.38]],"id":9624350}],"con":true,"img":false}]}
{"op":"mcm","clk":"1362105328","pt":1588427784127,"mc":[{"id":"1.170370557","rc":[{"atb":[[1.16,547.86]],"id":9624350}],"con":true,"img":false}]}
{"op":"mcm","clk":"1362105333","pt":1588427784945,"mc":[{"id":"1.170370557","rc":[{"atl":[[1.22,672.4]],"id":9624350}],"con":true,"img":false}]}
