{"op":"mcm","clk":"1362414340","pt":1588448987154,"mc":[{"id":"1.170370564","rc":[{"trd":[[1.27,4100.49]],"ltp":1.27,"tv":4100.49,"id":8509691},{"atb":[[1.14,2.31],[1.27,228.35]],"id":8509691},{"atl":[[1.27,0]],"id":8509691}],"con":true,"img":false},{"id":"1.170370566","rc":[{"atb":[[1.18,0]],"id":8509691}],"con":true,"img":false}]}
{"op":"mcm","clk":"1362414345","pt":1588448987863,"mc":[{"id":"1.170370564","rc":[{"atb":[[1.27,0]],"id":8509691}],"con":true,"img":false}]}
{"op":"mcm","clk":"1362414346","pt":1588448988372,"mc":[{"id":"1.170370564","rc":[{"atb":[[1.12,610.46]],"id":8509691}],"con":true,"img":false}]}
{"op":"mcm","clk":"1362414348","pt":1588448988576,"mc":[{"id":"1.170370564","rc":[{"atl":[[1.3,259]],"id":8509691}],"con":true,"img":false}]}
{"op":"mcm","clk":"1362414350","pt":1588448989136,"mc":[{"id":"1.170370564","rc":[{"atl":[[1.56,0]],"id":8509691}],"con":true,"img":false},{"id":"1.170370566","rc":[{"atb":[[2.62,0]],"id":9630572}],"con":true,"img":false}]}
{"op":"mcm","clk":"1362414354","pt":1588448989339,"mc":[{"id":"1.170370564","rc":[{"atl":[[1.32,272.64]],"id":8509691}],"con":true,"img":false}]}
{"op":"mcm","clk":"1362414355","pt":1588448989440,"mc":[{"id":"1.170370564","rc":[{"atl":[[1.26,177.3]],"id":8509691}],"con":true,"img":false}]}
{"op":"mcm","clk":"1362414362","pt":1588448990256,"mc":[{"id":"1.170370564","rc":[{"atl":[[1.26,354.6]],"id":8509691}],"con":true,"img":false}]}
{"op":"mcm","clk":"1362414365","pt":1588448990664,"mc":[{"id":"1.170370564","rc":[{"atl":[[1.26,0]],"id":8509691}],"con":true,"img":false}]}
{"op":"mcm","clk":"1362414371","pt":1588448992340,"mc":[{"id":"1.170370564","rc":[{"atb":[[1.16,303.94]],"id":8509691}],"con":true,"img":false},{"id":"1.170370566","rc":[{"atb":[[1.22,275.91]],"id":8509691}],"con":true,"img":false}]}
{"op":"mcm","clk":"1362414373","pt":1588448992440,"mc":[{"id":"1.170370564","rc":[{"atb":[[1.22,10]],"id":8509691}],"con":true,"img":false}]}
{"op":"mcm","clk":"1362414377","pt":1588448993150,"mc":[{"id":"1.170370564","rc":[{"atb":[[1.16,0]],"id":8509691}],"con":true,"img":false},{"id":"1.170370566","rc":[{"atb":[[1.22,0]],"id":8509691}],"con":true,"img":false}]}
{"op":"mcm","clk":"1362414379","pt":1588448993455,"mc":[{"id":"1.170370564","rc":[{"atl":[[1.35,5.31]],"id":8509691}],"con":true,"img":false}]}
{"op":"mcm","clk":"1362414396","pt":1588448995848,"mc":[{"id":"1.170370564","rc":[{"atb":[[1.19,10]],"id":8509691}],"con":true,"img":false}]}
{"op":"mcm","clk":"1362414403","pt":1588448996457,"mc":[{"id":"1.170370564","rc":[{"atb":[[1.14,0]],"id":8509691}],"con":true,"img":false}]}
{"op":"mcm","clk":"1362414406","pt":1588448996762,"mc":[{"id":"1.170370564","rc":[{"atb":[[1.24,119.13]],"id":8509691}],"con":true,"img":false}]}
{"op":"mcm","clk":"1362414415","pt":1588448997884,"mc":[{"id":"1.170370564","rc":[{"atl":[[1.5,24.57]],"id":8509691}],"con":true,"img":false}]}
{"op":"mcm","clk":"1362414425","pt":1588448999075,"mc":[{"id":"1.170370565","rc":[{"atl":[[24,0]],"id":11269555}],"con":true,"img":false}]}
{"op":"mcm","clk":"1362414430","pt":1588448999281,"mc":[{"id":"1.170370564","rc":[{"atb":[[1.23,0.68]],"id":8509691},{"atl":[[1.28,175.56]],"id":8509691}],"con":true,"img":false}]}
{"op":"mcm","clk":"1362414438","pt":1588449000399,"mc":[{"id":"1.170370564","rc":[{"atb":[[1.27,100]],"id":8509691}],"con":true,"img":false},{"id":"1.170370565","rc":[{"atl":[[1.05,55]],"id":11340560}],"con":true,"img":false}]}
{"op":"mcm","clk":"1362414439","pt":1588449000453,"mc":[{"id":"1.170370564","rc":[{"atl":[[1.29,177.3]],"id":8509691}],"con":true,"img":false}]}
{"op":"mcm","clk":"1362414444","pt":1588449001065,"mc":[{"id":"1.170370564","rc":[{"atl":[[1.29,238.89]],"id":8509691}],"con":true,"img":false}]}
{"op":"mcm","clk":"1362414455","pt":1588449003674,"mc":[{"id":"1.170370564","rc":[{"atl":[[1.3,19],[1.32,32.64]],"id":8509691}],"con":true,"img":false}]}
{"op":"mcm","clk":"1362414464","pt":1588449004187,"mc":[{"id":"1.170370564","rc":[{"atb":[[1.27,0]],"id":8509691}],"con":true,"img":false}]}
{"op":"mcm","clk":"1362414469","pt":1588449004492,"mc":[{"id":"1.170370565","rc":[{"atl":[[1.05,0]],"id":11340560}],"con":true,"img":false}]}
{"op":"mcm","clk":"1362414486","pt":1588449006173,"mc":[{"id":"1.170370564","rc":[{"trd":[[1.22,730.24],[1.24,1707.01],[1.23,405.06]],"ltp":1.22,"tv":2842.31,"id":8509691},{"atb":[[1.23,0],[1.22,0],[1.24,0]],"id":8509691},{"atl":[[1.22,870.18]],"id":8509691}],"con":true,"img":false}]}
{"op":"mcm","clk":"1362414499","pt":1588449008872,"mc":[{"id":"1.170370564","rc":[{"atl":[[1.27,87.58]],"id":8509691}],"con":true,"img":false}]}
{"op":"mcm","clk":"1362414501","pt":1588449009072,"mc":[{"id":"1.170370564","rc":[{"trd":[[1.22,760.24]],"ltp":1.22,"tv":760.24,"id":8509691},{"atl":[[1.22,855.18]],"id":8509691}],"con":true,"img":false}]}
{"op":"mcm","clk":"1362414504","pt":1588449009278,"mc":[{"id":"1.170370564","rc":[{"trd":[[1.22,960.24]],"ltp":1.22,"tv":960.24,"id":8509691},{"atl":[[1.22,755.18]],"id":8509691}],"con":true,"img":false}]}
{"op":"mcm","clk":"1362414511","pt":1588449009890,"mc":[{"id":"1.170370565","rc":[{"atb":[[1.05,98.4]],"id":11340560}],"con":true,"img":false}]}
{"op":"mcm","clk":"1362414519","pt":1588449010502,"mc":[{"id":"1.170370564","rc":[{"atb":[[1.21,60]],"id":8509691}],"con":true,"img":false}]}
{"op":"mcm","clk":"1362414522","pt":1588449010804,"mc":[{"id":"1.170370564","rc":[{"atl":[[1.27,91.54]],"id":8509691}],"con":true,"img":false}]}
{"op":"mcm","clk":"1362414527","pt":1588449011313,"mc":[{"id":"1.170370564","rc":[{"atl":[[1.22,755.67]],"id":8509691}],"con":true,"img":false}]}
{"op":"mcm","clk":"1362414530","pt":1588449011824,"mc":[{"id":"1.170370564","rc":[{"atl":[[1.27,3.96]],"id":8509691}],"con":true,"img":false}]}
{"op":"mcm","clk":"1362414537","pt":1588449012386,"mc":[{"id":"1.170370564","rc":[{"trd":[[5.5,10.11]],"ltp":5.5,"tv":10.11,"id":9630572},{"trd":[[1.22,971.85]],"ltp":1.22,"tv":971.85,"id":8509691},{"atl":[[1.22,744.06]],"id":8509691}],"con":true,"img":false}]}
{"op":"mcm","clk":"1362414541","pt":1588449012487,"mc":[{"id":"1.170370564","rc":[{"trd":[[1.22,987.85]],"ltp":1.22,"tv":987.85,"id":8509691},{"atl":[[1.22,736.06]],"id":8509691}],"con":true,"img":false}]}
{"op":"mcm","clk":"1362414546","pt":1588449012896,"mc":[{"id":"1.170370564","rc":[{"atl":[[1.26,41.66]],"id":8509691}],"con":true,"img":false}]}
{"op":"mcm","clk":"1362414550","pt":1588449013203,"mc":[{"id":"1.170370564","rc":[{"atl":[[1.27,243.96]],"id":8509691}],"con":true,"img":false}]}
{"op":"mcm","clk":"1362414558","pt":1588449014219,"mc":[{"id":"1.170370564","rc":[{"trd":[[1.22,993.17]],"ltp":1.22,"tv":993.17,"id":8509691},{"atl":[[1.22,733.4]],"id":8509691}],"con":true,"img":false}]}
{"op":"mcm","clk":"1362414564","pt":1588449015082,"mc":[{"id":"1.170370564","rc":[{"atb":[[1.21,10]],"id":8509691}],"con":true,"img":false}]}
{"op":"mcm","clk":"1362414570","pt":1588449016206,"mc":[{"id":"1.170370564","rc":[{"atl":[[1.31,3]],"id":8509691}],"con":true,"img":false}]}
{"op":"mcm","clk":"1362414571","pt":1588449016409,"mc":[{"id":"1.170370566","rc":[{"atl":[[1.3,63.98]],"id":8509691}],"con":true,"img":false}]}
{"op":"mcm","clk":"1362414575","pt":1588449017016,"mc":[{"id":"1.170370564","rc":[{"atl":[[1.22,732.91]],"id":8509691}],"con":true,"img":false}]}
{"op":"mcm","clk":"1362414584","pt":1588449017524,"mc":[{"id":"1.170370564","rc":[{"trd":[[1.21,629.4]],"ltp":1.21,"tv":629.4,"id":8509691},{"atb":[[1.21,2.78]],"id":8509691}],"con":true,"img":false}]}
{"op":"mcm","clk":"1362414589","pt":1588449018235,"mc":[{"id":"1.170370564","rc":[{"trd":[[1.22,1013.17]],"ltp":1.22,"tv":1013.17,"id":8509691},{"atl":[[1.22,722.91]],"id":8509691}],"con":true,"img":false}]}
{"op":"mcm","clk":"1362414603","pt":1588449020217,"mc":[{"id":"1.170370564","rc":[{"trd":[[1.22,1113.17]],"ltp":1.22,"tv":1113.17,"id":8509691},{"atl":[[1.22,672.91]],"id":8509691}],"con":true,"img":false}]}
{"op":"mcm","clk":"1362414607","pt":1588449020931,"mc":[{"id":"1.170370564","rc":[{"atl":[[1.22,0]],"id":8509691}],"con":true,"img":false}]}
{"op":"mcm","clk":"1362414611","pt":1588449021338,"mc":[{"id":"1.170370564","rc":[{"atl":[[1.27,290.96]],"id":8509691}],"con":true,"img":false}]}
{"op":"mcm","clk":"1362414613","pt":1588449021440,"mc":[{"id":"1.170370564","rc":[{"atl":[[5.5,1000]],"id":9630572}],"con":true,"img":false}]}
{"op":"mcm","clk":"1362414617","pt":1588449022005,"mc":[{"id":"1.170370564","rc":[{"atb":[[1.1,594.79]],"id":8509691}],"con":true,"img":false}]}
{"op":"mcm","clk":"1362414632","pt":1588449023226,"mc":[{"id":"1.170370566","rc":[{"atl":[[1.3,0]],"id":8509691}],"con":true,"img":false}]}
{"op":"mcm","clk":"1362414635","pt":1588449023532,"mc":[{"id":"1.170370564","rc":[{"atl":[[5.5,1010]],"id":9630572}],"con":true,"img":false}]}
{"op":"mcm","clk":"1362414639","pt":1588449024143,"mc":[{"id":"1.170370567","rc":[{"atb":[[2.5,0]],"id":9630572}],"con":true,"img":false}]}
{"op":"mcm","clk":"1362414643","pt":1588449024707,"mc":[{"id":"1.170370564","rc":[{"atb":[[1.18,55]],"id":8509691}],"con":true,"img":false},{"id":"1.170370565","rc":[{"atl":[[10,19.5]],"id":11269555}],"con":true,"img":false}]}
{"op":"mcm","clk":"1362414645","pt":1588449024912,"mc":[{"id":"1.170370564","rc":[{"atl":[[5.5,1021.84]],"id":9630572}],"con":true,"img":false}]}
{"op":"mcm","clk":"1362414658","pt":1588449026233,"mc":[{"id":"1.170370564","rc":[{"atl":[[1.55,8.86]],"id":8509691}],"con":true,"img":false}]}
{"op":"mcm","clk":"1362414689","pt":1588449031525,"mc":[{"id":"1.170370564","rc":[{"atl":[[1.27,243.96]],"id":8509691}],"con":true,"img":false}]}
{"op":"mcm","clk":"1362414691","pt":1588449031932,"mc":[{"id":"1.170370565","rc":[{"atl":[[10,0]],"id":11269555}],"con":true,"img":false}]}
{"op":"mcm","clk":"1362414697","pt":1588449032644,"mc":[{"id":"1.170370564","rc":[{"atl":[[1.26,42.35]],"id":8509691}],"con":true,"img":false}]}
{"op":"mcm","clk":"1362414700","pt":1588449032848,"mc":[{"id":"1.170370564","rc":[{"atl":[[5.5,1010]],"id":9630572}],"con":true,"img":false}]}
{"op":"mcm","clk":"1362414710","pt":1588449033763,"mc":[{"id":"1.170370564","rc":[{"trd":[[1.26,2509.63]],"ltp":1.26,"tv":2509.63,"id":8509691},{"atb":[[1.26,7.64]],"id":8509691},{"atl":[[1.26,0]],"id":8509691}],"con":true,"img":false}]}
{"op":"mcm","clk":"1362414723","pt":1588449036455,"mc":[{"id":"1.170370565","rc":[{"atb":[[1.05,0]],"id":11340560}],"con":true,"img":false}]}
{"op":"mcm","clk":"1362414726","pt":1588449037065,"mc":[{"id":"1.170370564","rc":[{"atl":[[1.31,0]],"id":8509691}],"con":true,"img":false}]}
{"op":"mcm","clk":"1362414741","pt":1588449038950,"mc":[{"id":"1.170370564","rc":[{"atl":[[1.29,239.38]],"id":8509691}],"con":true,"img":false}]}
{"op":"mcm","clk":"1362414743","pt":1588449039153,"mc":[{"id":"1.170370564","rc":[{"atl":[[1.27,3.96]],"id":8509691}],"con":true,"img":false}]}
{"op":"mcm","clk":"1362414757","pt":1588449040328,"mc":[{"id":"1.170370564","rc":[{"atl":[[1.29,62.08]],"id":8509691}],"con":true,"img":false}]}
{"op":"mcm","clk":"1362414776","pt":1588449043336,"mc":[{"id":"1.170370564","rc":[{"atb":[[1.26,302.85]],"id":8509691}],"con":true,"img":false}]}
{"op":"mcm","clk":"1362414786","pt":1588449043942,"mc":[{"id":"1.170370564","rc":[{"trd":[[4.9,20.49]],"ltp":4.9,"tv":20.49,"id":9630572},{"trd":[[1.26,2529.08]],"ltp":1.26,"tv":2529.08,"id":8509691},{"atb":[[1.26,283.4]],"id":8509691}],"con":true,"img":false}]}
{"op":"mcm","clk":"1362414788","pt":1588449044046,"mc":[{"id":"1.170370564","rc":[{"atb":[[1.26,578.61]],"id":8509691}],"con":true,"img":false}]}
{"op":"mcm","clk":"1362414799","pt":1588449044962,"mc":[{"id":"1.170370564","rc":[{"atb":[[1.26,873.82]],"id":8509691}],"con":true,"img":false}]}
{"op":"mcm","clk":"1362414801","pt":1588449045369,"mc":[{"id":"1.170370564","rc":[{"atb":[[1.23,240]],"id":8509691}],"con":true,"img":false}]}
{"op":"mcm","clk":"1362414807","pt":1588449045878,"mc":[{"id":"1.170370564","rc":[{"atb":[[1.25,240]],"id":8509691}],"con":true,"img":false}]}
{"op":"mcm","clk":"1362414810","pt":1588449046337,"mc":[{"id":"1.170370564","rc":[{"atl":[[1.28,0]],"id":8509691}],"con":true,"img":false}]}
{"op":"mcm","clk":"1362414811","pt":1588449046439,"mc":[{"id":"1.170370565","rc":[{"atb":[[9.4,7]],"id":11269555}],"con":true,"img":false}]}
{"op":"mcm","clk":"1362414813","pt":1588449046745,"mc":[{"id":"1.170370564","rc":[{"atl":[[1.31,177.3]],"id":8509691}],"con":true,"img":false}]}
{"op":"mcm","clk":"1362414820","pt":1588449047352,"mc":[{"id":"1.170370564","rc":[{"trd":[[4.7,277.24]],"ltp":4.7,"tv":277.24,"id":9630572},{"atl":[[4.7,10.77]],"id":9630572},{"trd":[[1.27,4104.45]],"ltp":1.27,"tv":4104.45,"id":8509691},{"atl":[[1.27,0]],"id":8509691}],"con":true,"img":false}]}
{"op":"mcm","clk":"1362414821","pt":1588449047963,"mc":[{"id":"1.170370564","rc":[{"trd":[[4.7,277.95]],"ltp":4.7,"tv":277.95,"id":9630572},{"atl":[[4.7,10.06]],"id":9630572},{"trd":[[1.27,4107.08]],"ltp":1.27,"tv":4107.08,"id":8509691}],"con":true,"img":false}]}
{"op":"mcm","clk":"1362414827","pt":1588449048674,"mc":[{"id":"1.170370564","rc":[{"atb":[[1.28,240]],"id":8509691}],"con":true,"img":false}]}
{"op":"mcm","clk":"1362414828","pt":1588449048776,"mc":[{"id":"1.170370564","rc":[{"atb":[[3,2.43]],"id":9630572}],"con":true,"img":false}]}
{"op":"mcm","clk":"1362414830","pt":1588449048878,"mc":[{"id":"1.170370564","rc":[{"atl":[[1.6,9.75]],"id":8509691}],"con":true,"img":false}]}
{"op":"mcm","clk":"1362414835","pt":1588449049284,"mc":[{"id":"1.170370564","rc":[{"atl":[[4.7,0]],"id":9630572},{"trd":[[1.28,4473.9]],"ltp":1.28,"tv":4473.9,"id":8509691},{"atb":[[1.28,190]],"id":8509691}],"con":true,"img":false}]}
{"op":"mcm","clk":"1362414838","pt":1588449049338,"mc":[{"id":"1.170370564","rc":[{"trd":[[1.28,4497.34]],"ltp":1.28,"tv":4497.34,"id":8509691},{"atb":[[1.28,178.28]],"id":8509691}],"con":true,"img":false}]}
{"op":"mcm","clk":"1362414851","pt":1588449050760,"mc":[{"id":"1.170370565","rc":[{"atb":[[9.4,0]],"id":11269555}],"con":true,"img":false}]}
{"op":"mcm","clk":"1362414852","pt":1588449050862,"mc":[{"id":"1.170370564","rc":[{"atb":[[1.15,124.53]],"id":8509691}],"con":true,"img":false}]}
{"op":"mcm","clk":"1362414856","pt":1588449051371,"mc":[{"id":"1.170370564","rc":[{"atb":[[1.22,0.68]],"id":8509691}],"con":true,"img":false}]}
{"op":"mcm","clk":"1362414868","pt":1588449053052,"mc":[{"id":"1.170370564","rc":[{"atb":[[1.27,177.3]],"id":8509691}],"con":true,"img":false}]}
{"op":"mcm","clk":"1362414870","pt":1588449053255,"mc":[{"id":"1.170370567","rc":[{"atb":[[2.3,0]],"id":9630572}],"con":true,"img":false}]}
{"op":"mcm","clk":"1362414884","pt":1588449055594,"mc":[{"id":"1.170370565","rc":[{"atl":[[9.4,7.09]],"id":11269555}],"con":true,"img":false}]}
{"op":"mcm","clk":"1362414888","pt":1588449055952,"mc":[{"id":"1.170370565","rc":[{"atl":[[9.4,16.71]],"id":11269555}],"con":true,"img":false}]}
{"op":"mcm","clk":"1362414889","pt":1588449056054,"mc":[{"id":"1.170370564","rc":[{"atl":[[5.5,1000]],"id":9630572},{"atl":[[1.3,259]],"id":8509691}],"con":true,"img":false}]}
{"op":"mcm","clk":"1362414901","pt":1588449057578,"mc":[{"id":"1.170370564","rc":[{"trd":[[1.28,4853.9]],"ltp":1.28,"tv":4853.9,"id":8509691},{"atb":[[1.28,0]],"id":8509691},{"atl":[[1.28,321.72]],"id":8509691}],"con":true,"img":false}]}
{"op":"mcm","clk":"1362414907","pt":1588449058698,"mc":[{"id":"1.170370564","rc":[{"atb":[[1.27,417.3]],"id":8509691}],"con":true,"img":false}]}
{"op":"mcm","clk":"1362414909","pt":1588449059058,"mc":[{"id":"1.170370565","rc":[{"atl":[[9.4,7.09]],"id":11269555}],"con":true,"img":false}]}
{"op":"mcm","clk":"1362414911","pt":1588449059868,"mc":[{"id":"1.170370565","rc":[{"atl":[[9.4,0]],"id":11269555}],"con":true,"img":false}]}
{"op":"mcm","clk":"1362414912","pt":1588449059970,"mc":[{"id":"1.170370564","rc":[{"atb":[[1.23,0],[1.27,177.3],[1.25,0]],"id":8509691}],"con":true,"img":false}]}
{"op":"mcm","clk":"1362414917","pt":1588449061089,"mc":[{"id":"1.170370564","rc":[{"atl":[[5.1,5]],"id":9630572}],"con":true,"img":false}]}
{"op":"mcm","clk":"1362414918","pt":1588449061191,"mc":[{"id":"1.170370564","rc":[{"trd":[[1.26,3019.68],[1.27,4461.68]],"ltp":1.26,"tv":7481.36,"id":8509691},{"atb":[[1.26,628.52],[1.27,0]],"id":8509691}],"con":true,"img":false}]}
{"op":"mcm","clk":"1362414919","pt":1588449061496,"mc":[{"id":"1.170370564","rc":[{"atb":[[1.26,0]],"id":8509691}],"con":true,"img":false}]}
{"op":"mcm","clk":"1362414924","pt":1588449062668,"mc":[{"id":"1.170370564","rc":[{"atl":[[1.36,295.21]],"id":8509691}],"con":true,"img":false}]}
{"op":"mcm","clk":"1362414926","pt":1588449062772,"mc":[{"id":"1.170370564","rc":[{"atl":[[5.5,0]],"id":9630572}],"con":true,"img":false}]}
{"op":"mcm","clk":"1362414927","pt":1588449062872,"mc":[{"id":"1.170370564","rc":[{"atl":[[1.3,19]],"id":8509691}],"con":true,"img":false}]}
{"op":"mcm","clk":"1362414937","pt":1588449063992,"mc":[{"id":"1.170370564","rc":[{"atl":[[1.26,5]],"id":8509691}],"con":true,"img":false}]}
{"op":"mcm","clk":"1362414941","pt":1588449064503,"mc":[{"id":"1.170370564","rc":[{"atl":[[1.29,302.08]],"id":8509691}],"con":true,"img":false}]}
{"op":"mcm","clk":"1362414946","pt":1588449065781,"mc":[{"id":"1.170370564","rc":[{"trd":[[1.26,3029.68]],"ltp":1.26,"tv":3029.68,"id":8509691},{"atl":[[1.26,0]],"id":8509691}],"con":true,"img":false}]}
{"op":"mcm","clk":"1362414947","pt":1588449065883,"mc":[{"id":"1.170370564","rc":[{"atl":[[1.65,10.63]],"id":8509691}],"con":true,"img":false}]}
{"op":"mcm","clk":"1362414949","pt":1588449066394,"mc":[{"id":"1.170370564","rc":[{"atl":[[1.27,243.36]],"id":8509691}],"con":true,"img":false}]}
{"op":"mcm","clk":"1362414952","pt":1588449066802,"mc":[{"id":"1.170370564","rc":[{"atl":[[1.29,650.84]],"id":8509691}],"con":true,"img":false}]}
{"op":"mcm","clk":"1362414954","pt":1588449067006,"mc":[{"id":"1.170370564","rc":[{"atl":[[1.32,16.64]],"id":8509691}],"con":true,"img":false}]}
{"op":"mcm","clk":"1362414955","pt":1588449067108,"mc":[{"id":"1.170370564","rc":[{"atl":[[1.27,0]],"id":8509691}],"con":true,"img":false}]}
{"op":"mcm","clk":"1362414961","pt":1588449068583,"mc":[{"id":"1.170370564","rc":[{"atl":[[1.27,41.38]],"id":8509691}],"con":true,"img":false}]}
{"op":"mcm","clk":"1362414976","pt":1588449070514,"mc":[{"id":"1.170370565","rc":[{"atl":[[7,19.5]],"id":11269555}],"con":true,"img":false}]}
{"op":"mcm","clk":"1362414982","pt":1588449070819,"mc":[{"id":"1.170370564","rc":[{"atl":[[1.27,43.17]],"id":8509691}],"con":true,"img":false}]}
{"op":"mcm","clk":"1362414990","pt":1588449072093,"mc":[{"id":"1.170370564","rc":[{"atl":[[1.28,337.71]],"id":8509691}],"con":true,"img":false}]}
{"op":"mcm","clk":"1362414992","pt":1588449072295,"mc":[{"id":"1.170370564","rc":[{"atl":[[1.27,286.3]],"id":8509691}],"con":true,"img":false}]}
{"op":"mcm","clk":"1362414994","pt":1588449073108,"mc":[{"id":"1.170370564","rc":[{"trd":[[4.7,282.95]],"ltp":4.7,"tv":282.95,"id":9630572},{"trd":[[1.27,4480.18]],"ltp":1.27,"tv":4480.18,"id":8509691},{"atl":[[1.27,267.8]],"id":8509691}],"con":true,"img":false}]}
{"op":"mcm","clk":"1362415007","pt":1588449074786,"mc":[{"id":"1.170370564","rc":[{"atb":[[1.18,54]],"id":8509691}],"con":true,"img":false}]}
{"op":"mcm","clk":"1362415012","pt":1588449075598,"mc":[{"id":"1.170370565","rc":[{"atb":[[2,0]],"id":11340557}],"con":true,"img":false}]}
{"op":"mcm","clk":"1362415025","pt":1588449077629,"mc":[{"id":"1.170370564","rc":[{"atl":[[1.36,0]],"id":8509691}],"con":true,"img":false}]}
{"op":"mcm","clk":"1362415030","pt":1588449078594,"mc":[{"id":"1.170370564","rc":[{"trd":[[4.7,355.32]],"ltp":4.7,"tv":355.32,"id":9630572},{"atl":[[4.7,927.63]],"id":9630572},{"trd":[[1.27,4747.99]],"ltp":1.27,"tv":4747.99,"id":8509691},{"atl":[[1.27,0]],"id":8509691}],"con":true,"img":false}]}
{"op":"mcm","clk":"1362415031","pt":1588449079000,"mc":[{"id":"1.170370564","rc":[{"atl":[[1.29,650.34]],"id":8509691}],"con":true,"img":false}]}
{"op":"mcm","clk":"1362415033","pt":1588449079101,"mc":[{"id":"1.170370564","rc":[{"atb":[[1.25,295.21]],"id":8509691},{"atl":[[1.35,23.04]],"id":8509691}],"con":true,"img":false}]}
{"op":"mcm","clk":"1362415035","pt":1588449079203,"mc":[{"id":"1.170370564","rc":[{"atb":[[1.22,0]],"id":8509691}],"con":true,"img":false}]}
{"op":"mcm","clk":"1362415042","pt":1588449080624,"mc":[{"id":"1.170370564","rc":[{"atb":[[1.25,0]],"id":8509691}],"con":true,"img":false}]}
{"op":"mcm","clk":"1362415052","pt":1588449082403,"mc":[{"id":"1.170370564","rc":[{"atl":[[1.29,410.34]],"id":8509691}],"con":true,"img":false}]}
{"op":"mcm","clk":"1362415061","pt":1588449084740,"mc":[{"id":"1.170370565","rc":[{"atl":[[1.21,66]],"id":11340560}],"con":true,"img":false}]}
{"op":"mcm","clk":"1362415065","pt":1588449085045,"mc":[{"id":"1.170370564","rc":[{"atb":[[1.21,297.99]],"id":8509691}],"con":true,"img":false}]}
{"op":"mcm","clk":"1362415070","pt":1588449085655,"mc":[{"id":"1.170370564","rc":[{"atb":[[1.23,295.21]],"id":8509691}],"con":true,"img":false}]}
{"op":"mcm","clk":"1362415083","pt":1588449088043,"mc":[{"id":"1.170370565","rc":[{"atl":[[1.21,0]],"id":11340560}],"con":true,"img":false}]}
{"op":"mcm","clk":"1362415088","pt":1588449088857,"mc":[{"id":"1.170370564","rc":[{"atb":[[1.23,345.21]],"id":8509691}],"con":true,"img":false}]}
{"op":"mcm","clk":"1362415089","pt":1588449088911,"mc":[{"id":"1.170370564","rc":[{"atl":[[1.28,577.71]],"id":8509691}],"con":true,"img":false}]}
{"op":"mcm","clk":"1362415097","pt":1588449090230,"mc":[{"id":"1.170370564","rc":[{"atb":[[1.22,295.21]],"id":8509691}],"con":true,"img":false}]}
{"op":"mcm","clk":"1362415107","pt":1588449092923,"mc":[{"id":"1.170370565","rc":[{"atl":[[5.7,10.63]],"id":11269555}],"con":true,"img":false},{"id":"1.170370566","rc":[{"trd":[[4.1,29.22],[4.2,0.81]],"ltp":4.1,"tv":30.02,"id":9630572},{"atl":[[4.1,0]],"id":9630572},{"trd":[[1.32,90.79],[1.31,10.62]],"ltp":1.32,"tv":101.41,"id":8509691},{"atl":[[1.32,0],[1.31,0]],"id":8509691}],"con":true,"img":false}]}
{"op":"mcm","clk":"1362415108","pt":1588449093228,"mc":[{"id":"1.170370566","rc":[{"atl":[[4.1,0]],"id":9630572}],"con":true,"img":false}]}
{"op":"mcm","clk":"1362415110","pt":1588449093635,"mc":[{"id":"1.170370564","rc":[{"trd":[[4.5,536.16]],"ltp":4.5,"tv":536.16,"id":9630572},{"atb":[[4.5,0]],"id":9630572},{"trd":[[1.28,4876.23]],"ltp":1.28,"tv":4876.23,"id":8509691},{"atl":[[1.28,555.38]],"id":8509691}],"con":true,"img":false}]}
{"op":"mcm","clk":"1362415111","pt":1588449093736,"mc":[{"id":"1.170370564","rc":[{"trd":[[4.7,359.14]],"ltp":4.7,"tv":359.14,"id":9630572},{"atl":[[4.7,925.72]],"id":9630572}],"con":true,"img":false}]}
{"op":"mcm","clk":"1362415116","pt":1588449094346,"mc":[{"id":"1.170370564","rc":[{"atl":[[1.31,0]],"id":8509691}],"con":true,"img":false}]}
{"op":"mcm","clk":"1362415118","pt":1588449094956,"mc":[{"id":"1.170370564","rc":[{"atl":[[1.32,20]],"id":8509691}],"con":true,"img":false}]}
{"op":"mcm","clk":"1362415120","pt":1588449095159,"mc":[{"id":"1.170370564","rc":[{"trd":[[4.7,359.68]],"ltp":4.7,"tv":359.68,"id":9630572},{"atl":[[4.7,925.18]],"id":9630572},{"trd":[[1.27,4749.99]],"ltp":1.27,"tv":4749.99,"id":8509691}],"con":true,"img":false}]}
{"op":"mcm","clk":"1362415137","pt":1588449098361,"mc":[{"id":"1.170370564","rc":[{"trd":[[1.28,4886.87]],"ltp":1.28,"tv":4886.87,"id":8509691},{"atl":[[1.28,550.06]],"id":8509691}],"con":true,"img":false}]}
{"op":"mcm","clk":"1362415140","pt":1588449099071,"mc":[{"id":"1.170370565","rc":[{"atl":[[5.7,0],[7,0]],"id":11269555}],"con":true,"img":false}]}
{"op":"mcm","clk":"1362415148","pt":1588449100240,"mc":[{"id":"1.170370564","rc":[{"atl":[[4.7,0]],"id":9630572},{"atl":[[1.33,243.79]],"id":8509691}],"con":true,"img":false}]}
{"op":"mcm","clk":"1362415153","pt":1588449100953,"mc":[{"id":"1.170370564","rc":[{"trd":[[4.5,636.16]],"ltp":4.5,"tv":636.16,"id":9630572},{"trd":[[1.28,5239.36]],"ltp":1.28,"tv":5239.36,"id":8509691},{"atl":[[1.28,198.04]],"id":8509691}],"con":true,"img":false}]}
{"op":"mcm","clk":"1362415154","pt":1588449101055,"mc":[{"id":"1.170370564","rc":[{"trd":[[1.28,5339.36]],"ltp":1.28,"tv":5339.36,"id":8509691},{"atl":[[1.28,148.04]],"id":8509691}],"con":true,"img":false}]}
{"op":"mcm","clk":"1362415157","pt":1588449101566,"mc":[{"id":"1.170370564","rc":[{"trd":[[1.28,5352.2]],"ltp":1.28,"tv":5352.2,"id":8509691},{"atl":[[1.28,141.62]],"id":8509691}],"con":true,"img":false}]}
{"op":"mcm","clk":"1362415159","pt":1588449101770,"mc":[{"id":"1.170370564","rc":[{"atl":[[1.27,1.45]],"id":8509691}],"con":true,"img":false}]}
{"op":"mcm","clk":"1362415161","pt":1588449102177,"mc":[{"id":"1.170370564","rc":[{"trd":[[4.5,676.44],[4.7,360.07]],"ltp":4.5,"tv":1036.51,"id":9630572},{"atl":[[4.5,59.33]],"id":9630572},{"trd":[[1.28,5493.82],[1.27,4751.45]],"ltp":1.28,"tv":10245.27,"id":8509691},{"atl":[[1.28,0],[1.27,0]],"id":8509691}],"con":true,"img":false}]}
{"op":"mcm","clk":"1362415166","pt":1588449103042,"mc":[{"id":"1.170370564","rc":[{"atl":[[4.5,61.95]],"id":9630572}],"con":true,"img":false}]}
{"op":"mcm","clk":"1362415176","pt":1588449104874,"mc":[{"id":"1.170370564","rc":[{"trd":[[4.5,683.41]],"ltp":4.5,"tv":683.41,"id":9630572},{"atl":[[4.5,54.98]],"id":9630572},{"trd":[[1.28,5518.31]],"ltp":1.28,"tv":5518.31,"id":8509691}],"con":true,"img":false}]}
{"op":"mcm","clk":"1362415186","pt":1588449106146,"mc":[{"id":"1.170370564","rc":[{"trd":[[4.5,686.33]],"ltp":4.5,"tv":686.33,"id":9630572},{"atl":[[4.5,53.52]],"id":9630572}],"con":true,"img":false}]}
{"op":"mcm","clk":"1362415195","pt":1588449107670,"mc":[{"id":"1.170370564","rc":[{"atl":[[1.29,61.59]],"id":8509691}],"con":true,"img":false}]}
{"op":"mcm","clk":"1362415204","pt":1588449108789,"mc":[{"id":"1.170370564","rc":[{"atb":[[1.25,240]],"id":8509691}],"con":true,"img":false}]}
{"op":"mcm","clk":"1362415207","pt":1588449109195,"mc":[{"id":"1.170370564","rc":[{"trd":[[4.5,690.06]],"ltp":4.5,"tv":690.06,"id":9630572},{"atl":[[4.5,49.79]],"id":9630572},{"trd":[[1.28,5531.43]],"ltp":1.28,"tv":5531.43,"id":8509691}],"con":true,"img":false}]}
{"op":"mcm","clk":"1362415209","pt":1588449109398,"mc":[{"id":"1.170370564","rc":[{"atb":[[1.22,535.21]],"id":8509691}],"con":true,"img":false}]}
{"op":"mcm","clk":"1362415212","pt":1588449109957,"mc":[{"id":"1.170370564","rc":[{"atl":[[4.5,47.17]],"id":9630572}],"con":true,"img":false}]}
{"op":"mcm","clk":"1362415218","pt":1588449110566,"mc":[{"id":"1.170370564","rc":[{"trd":[[1.29,21913.29]],"ltp":1.29,"tv":21913.29,"id":8509691},{"atl":[[1.29,56.59]],"id":8509691}],"con":true,"img":false}]}
{"op":"mcm","clk":"1362415222","pt":1588449111278,"mc":[{"id":"1.170370564","rc":[{"trd":[[4.5,737.23]],"ltp":4.5,"tv":737.23,"id":9630572},{"atl":[[4.5,0]],"id":9630572},{"trd":[[1.28,5697.26]],"ltp":1.28,"tv":5697.26,"id":8509691},{"atl":[[1.28,185.65]],"id":8509691}],"con":true,"img":false}]}
{"op":"mcm","clk":"1362415228","pt":1588449111583,"mc":[{"id":"1.170370566","rc":[{"atl":[[1.8,0]],"id":8509691}],"con":true,"img":false}]}
{"op":"mcm","clk":"1362415229","pt":1588449111786,"mc":[{"id":"1.170370564","rc":[{"atl":[[1.28,194.69]],"id":8509691}],"con":true,"img":false}]}
{"op":"mcm","clk":"1362415236","pt":1588449112396,"mc":[{"id":"1.170370564","rc":[{"atb":[[1.2,12]],"id":8509691}],"con":true,"img":false}]}
{"op":"mcm","clk":"1362415240","pt":1588449113007,"mc":[{"id":"1.170370564","rc":[{"atl":[[1000,2]],"id":8509691}],"con":true,"img":false}]}
{"op":"mcm","clk":"1362415241","pt":1588449113058,"mc":[{"id":"1.170370565","rc":[{"atl":[[4,48.75]],"id":11269555}],"con":true,"img":false}]}
{"op":"mcm","clk":"1362415243","pt":1588449113363,"mc":[{"id":"1.170370564","rc":[{"atl":[[1000,0.2]],"id":8509691}],"con":true,"img":false}]}
{"op":"mcm","clk":"1362415244","pt":1588449113566,"mc":[{"id":"1.170370566","rc":[{"atl":[[1.9,0]],"id":8509691}],"con":true,"img":false}]}
{"op":"mcm","clk":"1362415246","pt":1588449113668,"mc":[{"id":"1.170370564","rc":[{"atl":[[1000,0]],"id":8509691}],"con":true,"img":false}]}
{"op":"mcm","clk":"1362415249","pt":1588449113973,"mc":[{"id":"1.170370564","rc":[{"trd":[[4.5,762.23]],"ltp":4.5,"tv":762.23,"id":9630572},{"trd":[[1.28,5785.15]],"ltp":1.28,"tv":5785.15,"id":8509691},{"atl":[[1.28,106.8]],"id":8509691}],"con":true,"img":false}]}
{"op":"mcm","clk":"1362415250","pt":1588449114074,"mc":[{"id":"1.170370564","rc":[{"trd":[[1.28,5785.25]],"ltp":1.28,"tv":5785.25,"id":8509691},{"atl":[[1.28,106.75]],"id":8509691}],"con":true,"img":false}]}
{"op":"mcm","clk":"1362415253","pt":1588449114786,"mc":[{"id":"1.170370564","rc":[{"atb":[[1.26,177.3]],"id":8509691},{"atl":[[1.28,281.93]],"id":8509691}],"con":true,"img":false}]}
{"op":"mcm","clk":"1362415256","pt":1588449115599,"mc":[{"id":"1.170370567","rc":[{"atb":[[1.51,0]],"id":9630572}],"con":true,"img":false}]}
{"op":"mcm","clk":"1362415266","pt":1588449117478,"mc":[{"id":"1.170370564","rc":[{"atb":[[4.1,100]],"id":9630572}],"con":true,"img":false}]}
{"op":"mcm","clk":"1362415269","pt":1588449118189,"mc":[{"id":"1.170370565","rc":[{"atl":[[4,0]],"id":11269555}],"con":true,"img":false}]}
{"op":"mcm","clk":"1362415270","pt":1588449118290,"mc":[{"id":"1.170370564","rc":[{"atl":[[1.31,6.39]],"id":8509691}],"con":true,"img":false}]}
{"op":"mcm","clk":"1362415271","pt":1588449118493,"mc":[{"id":"1.170370564","rc":[{"atb":[[1.25,0]],"id":8509691}],"con":true,"img":false}]}
{"op":"mcm","clk":"1362415274","pt":1588449118798,"mc":[{"id":"1.170370564","rc":[{"atl":[[1.53,0.2]],"id":8509691}],"con":true,"img":false}]}
{"op":"mcm","clk":"1362415278","pt":1588449119306,"mc":[{"id":"1.170370564","rc":[{"atl":[[1.28,106.75]],"id":8509691}],"con":true,"img":false}]}
{"op":"mcm","clk":"1362415295","pt":1588449121695,"mc":[{"id":"1.170370564","rc":[{"atb":[[1.27,240]],"id":8509691}],"con":true,"img":false}]}
{"op":"mcm","clk":"1362415296","pt":1588449121797,"mc":[{"id":"1.170370564","rc":[{"trd":[[4.8,178.64]],"ltp":4.8,"tv":178.64,"id":9630572},{"trd":[[1.27,4752.02]],"ltp":1.27,"tv":4752.02,"id":8509691},{"atb":[[1.27,239.43]],"id":8509691}],"con":true,"img":false}]}
{"op":"mcm","clk":"1362415298","pt":1588449122000,"mc":[{"id":"1.170370567","rc":[{"atb":[[1.2,0]],"id":9630572}],"con":true,"img":false}]}
{"op":"mcm","clk":"1362415300","pt":1588449122512,"mc":[{"id":"1.170370566","rc":[{"atl":[[2,8.86]],"id":8509691}],"con":true,"img":false}]}
{"op":"mcm","clk":"1362415303","pt":1588449123328,"mc":[{"id":"1.170370564","rc":[{"atl":[[1.7,1.77]],"id":8509691}],"con":true,"img":false},{"id":"1.170370565","rc":[{"atl":[[3.5,48.75]],"id":11269555}],"con":true,"img":false}]}
{"op":"mcm","clk":"1362415304","pt":1588449123430,"mc":[{"id":"1.170370564","rc":[{"atb":[[1.27,0],[1.22,295.21]],"id":8509691}],"con":true,"img":false}]}
{"op":"mcm","clk":"1362415329","pt":1588449127099,"mc":[{"id":"1.170370567","rc":[{"atb":[[1.12,523.11]],"id":9630572}],"con":true,"img":false}]}
{"op":"mcm","clk":"1362415336","pt":1588449127813,"mc":[{"id":"1.170370564","rc":[{"atl":[[1.28,9.03]],"id":8509691}],"con":true,"img":false}]}
{"op":"mcm","clk":"1362415341","pt":1588449128524,"mc":[{"id":"1.170370564","rc":[{"trd":[[4.5,764.8]],"ltp":4.5,"tv":764.8,"id":9630572},{"atl":[[4.5,0.05]],"id":9630572},{"trd":[[1.28,5794.28]],"ltp":1.28,"tv":5794.28,"id":8509691},{"atl":[[1.28,0]],"id":8509691}],"con":true,"img":false}]}
{"op":"mcm","clk":"1362415343","pt":1588449128626,"mc":[{"id":"1.170370564","rc":[{"trd":[[4.5,764.85]],"ltp":4.5,"tv":764.85,"id":9630572},{"atl":[[4.5,0]],"id":9630572},{"trd":[[1.28,5794.48]],"ltp":1.28,"tv":5794.48,"id":8509691},{"atl":[[1.27,1.8]],"id":8509691}],"con":true,"img":false}]}
{"op":"mcm","clk":"1362415346","pt":1588449128727,"mc":[{"id":"1.170370564","rc":[{"atl":[[1.33,0]],"id":8509691}],"con":true,"img":false}]}
{"op":"mcm","clk":"1362415350","pt":1588449129235,"mc":[{"id":"1.170370564","rc":[{"atl":[[1.28,3]],"id":8509691}],"con":true,"img":false}]}
{"op":"mcm","clk":"1362415354","pt":1588449129540,"mc":[{"id":"1.170370564","rc":[{"atb":[[4,0]],"id":9630572}],"con":true,"img":false}]}
{"op":"mcm","clk":"1362415355","pt":1588449129642,"mc":[{"id":"1.170370564","rc":[{"atb":[[1.23,585.21]],"id":8509691}],"con":true,"img":false}]}
{"op":"mcm","clk":"1362415356","pt":1588449130099,"mc":[{"id":"1.170370566","rc":[{"atb":[[1.05,88.65]],"id":8509691},{"atl":[[2.96,0]],"id":8509691}],"con":true,"img":false}]}
{"op":"mcm","clk":"1362415359","pt":1588449130607,"mc":[{"id":"1.170370564","rc":[{"atl":[[1.37,0]],"id":8509691}],"con":true,"img":false}]}
{"op":"mcm","clk":"1362415362","pt":1588449131216,"mc":[{"id":"1.170370564","rc":[{"atb":[[1.21,537.99]],"id":8509691}],"con":true,"img":false}]}
{"op":"mcm","clk":"1362415364","pt":1588449131317,"mc":[{"id":"1.170370564","rc":[{"atb":[[1.23,345.21]],"id":8509691}],"con":true,"img":false}]}
{"op":"mcm","clk":"1362415367","pt":1588449132334,"mc":[{"id":"1.170370564","rc":[{"atl":[[1.32,16.64]],"id":8509691}],"con":true,"img":false}]}
{"op":"mcm","clk":"1362415371","pt":1588449132944,"mc":[{"id":"1.170370564","rc":[{"atb":[[1.04,2996.78]],"id":8509691}],"con":true,"img":false}]}
{"op":"mcm","clk":"1362415378","pt":1588449133606,"mc":[{"id":"1.170370564","rc":[{"trd":[[4.5,765.71],[4.7,360.56]],"ltp":4.5,"tv":1126.27,"id":9630572},{"atl":[[4.5,0.4]],"id":9630572},{"trd":[[1.28,5797.48],[1.27,4753.82]],"ltp":1.28,"tv":10551.3,"id":8509691},{"atl":[[1.28,0],[1.27,0]],"id":8509691}],"con":true,"img":false}]}
{"op":"mcm","clk":"1362415382","pt":1588449133910,"mc":[{"id":"1.170370564","rc":[{"atb":[[1.28,7.93]],"id":8509691}],"con":true,"img":false}]}
{"op":"mcm","clk":"1362415385","pt":1588449134418,"mc":[{"id":"1.170370564","rc":[{"atb":[[1.2,307.21],[1.24,240]],"id":8509691}],"con":true,"img":false}]}
{"op":"mcm","clk":"1362415387","pt":1588449134621,"mc":[{"id":"1.170370564","rc":[{"trd":[[4.5,766.44]],"ltp":4.5,"tv":766.44,"id":9630572},{"atl":[[4.5,0.04]],"id":9630572}],"con":true,"img":false}]}
{"op":"mcm","clk":"1362415395","pt":1588449136908,"mc":[{"id":"1.170370564","rc":[{"atb":[[1.26,0]],"id":8509691}],"con":true,"img":false}]}
{"op":"mcm","clk":"1362415399","pt":1588449137619,"mc":[{"id":"1.170370564","rc":[{"atl":[[1.31,9.78]],"id":8509691}],"con":true,"img":false}]}
{"op":"mcm","clk":"1362415403","pt":1588449138534,"mc":[{"id":"1.170370564","rc":[{"atl":[[1.75,1.77]],"id":8509691}],"con":true,"img":false}]}
{"op":"mcm","clk":"1362415409","pt":1588449139448,"mc":[{"id":"1.170370564","rc":[{"atl":[[1.31,3.38]],"id":8509691}],"con":true,"img":false}]}
{"op":"mcm","clk":"1362415415","pt":1588449139957,"mc":[{"id":"1.170370565","rc":[{"atl":[[3.5,0]],"id":11269555}],"con":true,"img":false}]}
{"op":"mcm","clk":"1362415421","pt":1588449140822,"mc":[{"id":"1.170370564","rc":[{"trd":[[4.5,766.48]],"ltp":4.5,"tv":766.48,"id":9630572},{"atl":[[4.5,0]],"id":9630572},{"trd":[[1.28,5813.5]],"ltp":1.28,"tv":5813.5,"id":8509691},{"atb":[[1.28,0]],"id":8509691},{"atl":[[1.26,167.09]],"id":8509691}],"con":true,"img":false}]}
{"op":"mcm","clk":"1362415423","pt":1588449140924,"mc":[{"id":"1.170370564","rc":[{"trd":[[1.26,3082.87]],"ltp":1.26,"tv":3082.87,"id":8509691},{"atl":[[1.26,140.49]],"id":8509691}],"con":true,"img":false}]}
{"op":"mcm","clk":"1362415430","pt":1588449142450,"mc":[{"id":"1.170370564","rc":[{"atl":[[1.26,317.8]],"id":8509691}],"con":true,"img":false}]}
{"op":"mcm","clk":"1362415434","pt":1588449142962,"mc":[{"id":"1.170370564","rc":[{"atl":[[1.27,177.3]],"id":8509691}],"con":true,"img":false}]}
{"op":"mcm","clk":"1362415440","pt":1588449143930,"mc":[{"id":"1.170370564","rc":[{"trd":[[5.1,11.41]],"ltp":5.1,"tv":11.41,"id":9630572},{"atl":[[5.1,4.57]],"id":9630572}],"con":true,"img":false}]}
{"op":"mcm","clk":"1362415443","pt":1588449144134,"mc":[{"id":"1.170370564","rc":[{"atl":[[1.26,177.3]],"id":8509691}],"con":true,"img":false}]}
{"op":"mcm","clk":"1362415446","pt":1588449144540,"mc":[{"id":"1.170370564","rc":[{"atl":[[1.33,6.39]],"id":8509691}],"con":true,"img":false}]}
{"op":"mcm","clk":"1362415454","pt":1588449146270,"mc":[{"id":"1.170370564","rc":[{"trd":[[5.1,11.49]],"ltp":5.1,"tv":11.49,"id":9630572},{"atl":[[5.1,4.53]],"id":9630572}],"con":true,"img":false}]}
{"op":"mcm","clk":"1362415462","pt":1588449148051,"mc":[{"id":"1.170370564","rc":[{"atl":[[1.32,345.44]],"id":8509691}],"con":true,"img":false}]}
{"op":"mcm","clk":"1362415483","pt":1588449151254,"mc":[{"id":"1.170370565","rc":[{"atb":[[3,0]],"id":11340557}],"con":true,"img":false}]}
{"op":"mcm","clk":"1362415485","pt":1588449151559,"mc":[{"id":"1.170370564","rc":[{"trd":[[1.26,3083.08]],"ltp":1.26,"tv":3083.08,"id":8509691},{"atl":[[1.26,177.19]],"id":8509691}],"con":true,"img":false}]}
{"op":"mcm","clk":"1362415494","pt":1588449152475,"mc":[{"id":"1.170370564","rc":[{"atl":[[1.8,1.77]],"id":8509691}],"con":true,"img":false}]}
{"op":"mcm","clk":"1362415524","pt":1588449157256,"mc":[{"id":"1.170370564","rc":[{"atb":[[1.06,2474.9]],"id":8509691}],"con":true,"img":false}]}
{"op":"mcm","clk":"1362415536","pt":1588449159290,"mc":[{"id":"1.170370565","rc":[{"atl":[[1.51,55]],"id":11340560}],"con":true,"img":false}]}
{"op":"mcm","clk":"1362415541","pt":1588449160410,"mc":[{"id":"1.170370564","rc":[{"atb":[[1.12,590.46]],"id":8509691}],"con":true,"img":false}]}
{"op":"mcm","clk":"1362415552","pt":1588449163108,"mc":[{"id":"1.170370565","rc":[{"atl":[[1.51,0]],"id":11340560}],"con":true,"img":false}]}
{"op":"mcm","clk":"1362415555","pt":1588449163210,"mc":[{"id":"1.170370564","rc":[{"atl":[[1000,3.19]],"id":9630572}],"con":true,"img":false}]}
{"op":"mcm","clk":"1362415557","pt":1588449163414,"mc":[{"id":"1.170370564","rc":[{"atb":[[1.11,200.62]],"id":8509691}],"con":true,"img":false}]}
{"op":"mcm","clk":"1362415561","pt":1588449163718,"mc":[{"id":"1.170370564","rc":[{"atb":[[1.23,50]],"id":8509691}],"con":true,"img":false}]}
{"op":"mcm","clk":"1362415565","pt":1588449163973,"mc":[{"id":"1.170370564","rc":[{"atl":[[1.25,3.19]],"id":8509691}],"con":true,"img":false}]}
{"op":"mcm","clk":"1362415572","pt":1588449164686,"mc":[{"id":"1.170370564","rc":[{"trd":[[1.26,3103.27],[1.25,3264.95]],"ltp":1.26,"tv":6368.21,"id":8509691},{"atl":[[1.26,167.1],[1.25,0]],"id":8509691}],"con":true,"img":false}]}
{"op":"mcm","clk":"1362415588","pt":1588449166317,"mc":[{"id":"1.170370564","rc":[{"atb":[[1.15,26.13]],"id":8509691}],"con":true,"img":false}]}
{"op":"mcm","clk":"1362415592","pt":1588449167486,"mc":[{"id":"1.170370564","rc":[{"atb":[[1.21,297.99],[1.24,0]],"id":8509691}],"con":true,"img":false}]}
{"op":"mcm","clk":"1362415595","pt":1588449167996,"mc":[{"id":"1.170370564","rc":[{"trd":[[5.1,12.45]],"ltp":5.1,"tv":12.45,"id":9630572},{"atl":[[5.1,3.57]],"id":9630572},{"trd":[[1.24,1710.95]],"ltp":1.24,"tv":1710.95,"id":8509691}],"con":true,"img":false},{"id":"1.170370565","rc":[{"atl":[[2.5,48.75]],"id":11269555}],"con":true,"img":false}]}
{"op":"mcm","clk":"1362415597","pt":1588449168301,"mc":[{"id":"1.170370564","rc":[{"atl":[[1.26,0]],"id":8509691}],"con":true,"img":false}]}
{"op":"mcm","clk":"1362415601","pt":1588449168910,"mc":[{"id":"1.170370564","rc":[{"trd":[[1.27,4754.1]],"ltp":1.27,"tv":4754.1,"id":8509691},{"atl":[[1.27,177.16]],"id":8509691}],"con":true,"img":false}]}
{"op":"mcm","clk":"1362415606","pt":1588449169214,"mc":[{"id":"1.170370564","rc":[{"atl":[[1.27,0]],"id":8509691}],"con":true,"img":false}]}
{"op":"mcm","clk":"1362415608","pt":1588449169316,"mc":[{"id":"1.170370564","rc":[{"atl":[[5.1,0]],"id":9630572}],"con":true,"img":false},{"id":"1.170370565","rc":[{"atl":[[2.5,0]],"id":11269555}],"con":true,"img":false}]}
{"op":"mcm","clk":"1362415611","pt":1588449169723,"mc":[{"id":"1.170370564","rc":[{"atl":[[1.85,1.77]],"id":8509691}],"con":true,"img":false}]}
{"op":"mcm","clk":"1362415613","pt":1588449170028,"mc":[{"id":"1.170370565","rc":[{"atb":[[1.51,91.63]],"id":11340560}],"con":true,"img":false}]}
{"op":"mcm","clk":"1362415638","pt":1588449173485,"mc":[{"id":"1.170370564","rc":[{"atl":[[1000,3.43]],"id":9630572}],"con":true,"img":false}]}
{"op":"mcm","clk":"1362415645","pt":1588449174298,"mc":[{"id":"1.170370564","rc":[{"atl":[[1000,2]],"id":8509691}],"con":true,"img":false}]}
{"op":"mcm","clk":"1362415649","pt":1588449174603,"mc":[{"id":"1.170370564","rc":[{"atl":[[1000,0.59]],"id":8509691}],"con":true,"img":false}]}
{"op":"mcm","clk":"1362415651","pt":1588449174909,"mc":[{"id":"1.170370564","rc":[{"atl":[[1000,0]],"id":8509691}],"con":true,"img":false}]}
{"op":"mcm","clk":"1362415652","pt":1588449175112,"mc":[{"id":"1.170370565","rc":[{"atb":[[1.51,0]],"id":11340560}],"con":true,"img":false}]}
{"op":"mcm","clk":"1362415670","pt":1588449178217,"mc":[{"id":"1.170370564","rc":[{"atb":[[1.19,305.21]],"id":8509691}],"con":true,"img":false}]}
{"op":"mcm","clk":"1362415677","pt":1588449179034,"mc":[{"id":"1.170370565","rc":[{"atb":[[1.6,132.97]],"id":11340560}],"con":true,"img":false}]}
{"op":"mcm","clk":"1362415681","pt":1588449180051,"mc":[{"id":"1.170370564","rc":[{"trd":[[1.23,406.24]],"ltp":1.23,"tv":406.24,"id":8509691},{"atb":[[1.23,49.41]],"id":8509691}],"con":true,"img":false}]}
{"op":"mcm","clk":"1362415684","pt":1588449180610,"mc":[{"id":"1.170370564","rc":[{"trd":[[1.29,21919.28]],"ltp":1.29,"tv":21919.28,"id":8509691},{"atl":[[1.29,53.59]],"id":8509691}],"con":true,"img":false}]}
{"op":"mcm","clk":"1362415692","pt":1588449181832,"mc":[{"id":"1.170370564","rc":[{"atl":[[1.24,4]],"id":8509691}],"con":true,"img":false}]}
{"op":"mcm","clk":"1362415694","pt":1588449182137,"mc":[{"id":"1.170370564","rc":[{"atb":[[1.04,2984.53]],"id":8509691}],"con":true,"img":false}]}
{"op":"mcm","clk":"1362415707","pt":1588449184844,"mc":[{"id":"1.170370564","rc":[{"atl":[[1.28,295.21]],"id":8509691}],"con":true,"img":false}]}
{"op":"mcm","clk":"1362415712","pt":1588449185815,"mc":[{"id":"1.170370564","rc":[{"atl":[[5.2,3.57]],"id":9630572}],"con":true,"img":false}]}
{"op":"mcm","clk":"1362415721","pt":1588449187850,"mc":[{"id":"1.170370565","rc":[{"atb":[[1.6,0]],"id":11340560}],"con":true,"img":false}]}
{"op":"mcm","clk":"1362415736","pt":1588449191355,"mc":[{"id":"1.170370564","rc":[{"atb":[[1.18,4],[1.23,0]],"id":8509691}],"con":true,"img":false}]}
{"op":"mcm","clk":"1362415738","pt":1588449191559,"mc":[{"id":"1.170370564","rc":[{"trd":[[1.24,1718.95]],"ltp":1.24,"tv":1718.95,"id":8509691},{"atb":[[1.24,173.3]],"id":8509691},{"atl":[[1.24,0]],"id":8509691}],"con":true,"img":false}]}
{"op":"mcm","clk":"1362415742","pt":1588449192068,"mc":[{"id":"1.170370564","rc":[{"atb":[[1.24,0]],"id":8509691}],"con":true,"img":false}]}
{"op":"mcm","clk":"1362415745","pt":1588449193339,"mc":[{"id":"1.170370566","rc":[{"atb":[[1.06,355.14]],"id":8509691}],"con":true,"img":false}]}
{"op":"mcm","clk":"1362415748","pt":1588449193747,"mc":[{"id":"1.170370564","rc":[{"trd":[[5.2,3.57]],"ltp":5.2,"tv":3.57,"id":9630572},{"atl":[[5.2,0]],"id":9630572},{"trd":[[1.23,421.33]],"ltp":1.23,"tv":421.33,"id":8509691},{"atl":[[1.23,162.21]],"id":8509691}],"con":true,"img":false}]}
{"op":"mcm","clk":"1362415753","pt":1588449194867,"mc":[{"id":"1.170370564","rc":[{"atl":[[1.23,0]],"id":8509691}],"con":true,"img":false}]}
{"op":"mcm","clk":"1362415760","pt":1588449196140,"mc":[{"id":"1.170370565","rc":[{"atl":[[2.6,68.26]],"id":11269555}],"con":true,"img":false}]}
{"op":"mcm","clk":"1362415762","pt":1588449196445,"mc":[{"id":"1.170370564","rc":[{"atl":[[1.9,1.77]],"id":8509691}],"con":true,"img":false}]}
{"op":"mcm","clk":"1362415772","pt":1588449198375,"mc":[{"id":"1.170370564","rc":[{"atl":[[1.25,177.3]],"id":8509691}],"con":true,"img":false}]}
{"op":"mcm","clk":"1362415777","pt":1588449199949,"mc":[{"id":"1.170370564","rc":[{"atl":[[1.23,87.58]],"id":8509691}],"con":true,"img":false}]}
{"op":"mcm","clk":"1362415786","pt":1588449200968,"mc":[{"id":"1.170370564","rc":[{"atl":[[1.27,177.3]],"id":8509691}],"con":true,"img":false}]}
{"op":"mcm","clk":"1362415792","pt":1588449202188,"mc":[{"id":"1.170370564","rc":[{"atb":[[1.22,0]],"id":8509691}],"con":true,"img":false}]}
{"op":"mcm","clk":"1362415803","pt":1588449206102,"mc":[{"id":"1.170370565","rc":[{"atl":[[2.6,0]],"id":11269555}],"con":true,"img":false}]}
{"op":"mcm","clk":"1362415817","pt":1588449208900,"mc":[{"id":"1.170370564","rc":[{"atl":[[1.23,102.58]],"id":8509691}],"con":true,"img":false}]}
{"op":"mcm","clk":"1362415821","pt":1588449209612,"mc":[{"id":"1.170370564","rc":[{"atb":[[1.21,2.78]],"id":8509691}],"con":true,"img":false}]}
{"op":"mcm","clk":"1362415828","pt":1588449210680,"mc":[{"id":"1.170370564","rc":[{"atl":[[1.23,87.58]],"id":8509691}],"con":true,"img":false}]}
{"op":"mcm","clk":"1362415831","pt":1588449211189,"mc":[{"id":"1.170370564","rc":[{"atl":[[1.22,15.99]],"id":8509691}],"con":true,"img":false}]}
{"op":"mcm","clk":"1362415839","pt":1588449212207,"mc":[{"id":"1.170370564","rc":[{"atl":[[1.28,0]],"id":8509691}],"con":true,"img":false},{"id":"1.170370566","rc":[{"atb":[[1.06,0]],"id":8509691}],"con":true,"img":false}]}
{"op":"mcm","clk":"1362415844","pt":1588449213275,"mc":[{"id":"1.170370564","rc":[{"trd":[[5.5,10.94]],"ltp":5.5,"tv":10.94,"id":9630572},{"trd":[[1.22,1116.91]],"ltp":1.22,"tv":1116.91,"id":8509691},{"atl":[[1.22,12.25]],"id":8509691}],"con":true,"img":false}]}
{"op":"mcm","clk":"1362415845","pt":1588449213377,"mc":[{"id":"1.170370564","rc":[{"atl":[[1.22,27.25]],"id":8509691}],"con":true,"img":false}]}
{"op":"mcm","clk":"1362415846","pt":1588449213476,"mc":[{"id":"1.170370564","rc":[{"trd":[[1.21,634.96]],"ltp":1.21,"tv":634.96,"id":8509691},{"atb":[[1.21,0]],"id":8509691},{"atl":[[1.21,873.11]],"id":8509691}],"con":true,"img":false}]}
{"op":"mcm","clk":"1362415847","pt":1588449213682,"mc":[{"id":"1.170370564","rc":[{"atl":[[1.53,0]],"id":8509691}],"con":true,"img":false}]}
{"op":"mcm","clk":"1362415854","pt":1588449214596,"mc":[{"id":"1.170370564","rc":[{"trd":[[1.21,641.47]],"ltp":1.21,"tv":641.47,"id":8509691},{"atl":[[1.21,869.85]],"id":8509691}],"con":true,"img":false}]}
{"op":"mcm","clk":"1362415860","pt":1588449215710,"mc":[{"id":"1.170370564","rc":[{"atb":[[1.2,12]],"id":8509691}],"con":true,"img":false}]}
{"op":"mcm","clk":"1362415863","pt":1588449216018,"mc":[{"id":"1.170370564","rc":[{"atl":[[1.24,295.21]],"id":8509691}],"con":true,"img":false}]}
{"op":"mcm","clk":"1362415865","pt":1588449216220,"mc":[{"id":"1.170370564","rc":[{"atb":[[1.19,10]],"id":8509691}],"con":true,"img":false}]}
{"op":"mcm","clk":"1362415868","pt":1588449216422,"mc":[{"id":"1.170370564","rc":[{"trd":[[5.7,10.51]],"ltp":5.7,"tv":10.51,"id":9630572},{"trd":[[1.21,688.58]],"ltp":1.21,"tv":688.58,"id":8509691},{"atl":[[1.21,822.74]],"id":8509691}],"con":true,"img":false}]}
{"op":"mcm","clk":"1362415869","pt":1588449216524,"mc":[{"id":"1.170370564","rc":[{"atl":[[1.22,204.55]],"id":8509691}],"con":true,"img":false}]}
{"op":"mcm","clk":"1362415870","pt":1588449216625,"mc":[{"id":"1.170370564","rc":[{"atl":[[1.22,189.55]],"id":8509691}],"con":true,"img":false}]}
{"op":"mcm","clk":"1362415875","pt":1588449217085,"mc":[{"id":"1.170370564","rc":[{"atb":[[1.13,0]],"id":8509691}],"con":true,"img":false}]}
{"op":"mcm","clk":"1362415881","pt":1588449218406,"mc":[{"id":"1.170370564","rc":[{"atb":[[1.12,0.03]],"id":8509691}],"con":true,"img":false}]}
{"op":"mcm","clk":"1362415883","pt":1588449218713,"mc":[{"id":"1.170370564","rc":[{"trd":[[1.21,692.3]],"ltp":1.21,"tv":692.3,"id":8509691},{"atl":[[1.21,820.88]],"id":8509691}],"con":true,"img":false}]}
{"op":"mcm","clk":"1362415886","pt":1588449219729,"mc":[{"id":"1.170370564","rc":[{"atl":[[1.22,12.25]],"id":8509691}],"con":true,"img":false}]}
{"op":"mcm","clk":"1362415887","pt":1588449219933,"mc":[{"id":"1.170370567","rc":[{"atl":[[9.2,15.74]],"id":8509691}],"con":true,"img":false}]}
{"op":"mcm","clk":"1362415889","pt":1588449220133,"mc":[{"id":"1.170370564","rc":[{"atl":[[1.24,0]],"id":8509691}],"con":true,"img":false}]}
{"op":"mcm","clk":"1362415892","pt":1588449220493,"mc":[{"id":"1.170370564","rc":[{"atl":[[1.22,0]],"id":8509691}],"con":true,"img":false}]}
{"op":"mcm","clk":"1362415898","pt":1588449222528,"mc":[{"id":"1.170370564","rc":[{"trd":[[1.2,811.66]],"ltp":1.2,"tv":811.66,"id":8509691},{"atb":[[1.2,0]],"id":8509691},{"atl":[[1.2,165.3]],"id":8509691}],"con":true,"img":false},{"id":"1.170370565","rc":[{"atl":[[2.5,68.26]],"id":11269555}],"con":true,"img":false}]}
{"op":"mcm","clk":"1362415900","pt":1588449223137,"mc":[{"id":"1.170370564","rc":[{"atl":[[1.2,342.6]],"id":8509691}],"con":true,"img":false}]}
{"op":"mcm","clk":"1362415903","pt":1588449223900,"mc":[{"id":"1.170370564","rc":[{"trd":[[1.2,816.91]],"ltp":1.2,"tv":816.91,"id":8509691},{"atl":[[1.2,339.98]],"id":8509691}],"con":true,"img":false}]}
{"op":"mcm","clk":"1362415906","pt":1588449224308,"mc":[{"id":"1.170370564","rc":[{"atl":[[1.36,13.5]],"id":8509691}],"con":true,"img":false}]}
{"op":"mcm","clk":"1362415912","pt":1588449225629,"mc":[{"id":"1.170370564","rc":[{"atl":[[1.21,833.14]],"id":8509691}],"con":true,"img":false}]}
{"op":"mcm","clk":"1362415915","pt":1588449226137,"mc":[{"id":"1.170370564","rc":[{"atb":[[1.16,11.56]],"id":8509691}],"con":true,"img":false}]}
{"op":"mcm","clk":"1362415916","pt":1588449226444,"mc":[{"id":"1.170370564","rc":[{"atb":[[1.17,177.3]],"id":8509691}],"con":true,"img":false}]}
{"op":"mcm","clk":"1362415918","pt":1588449227002,"mc":[{"id":"1.170370564","rc":[{"atb":[[1.16,188.87]],"id":8509691}],"con":true,"img":false}]}
{"op":"mcm","clk":"1362415920","pt":1588449227408,"mc":[{"id":"1.170370564","rc":[{"trd":[[1.19,34]],"ltp":1.19,"tv":34.0,"id":8509691},{"atb":[[1.19,4.28]],"id":8509691}],"con":true,"img":false}]}
{"op":"mcm","clk":"1362415925","pt":1588449228832,"mc":[{"id":"1.170370564","rc":[{"atl":[[1.21,12.25]],"id":8509691}],"con":true,"img":false}]}
{"op":"mcm","clk":"1362415931","pt":1588449230047,"mc":[{"id":"1.170370564","rc":[{"atb":[[4.8,10]],"id":9630572}],"con":true,"img":false}]}
{"op":"mcm","clk":"1362415933","pt":1588449230404,"mc":[{"id":"1.170370564","rc":[{"atl":[[1.23,0]],"id":8509691}],"con":true,"img":false}]}
{"op":"mcm","clk":"1362415937","pt":1588449230813,"mc":[{"id":"1.170370564","rc":[{"atl":[[1.21,0]],"id":8509691}],"con":true,"img":false}]}
{"op":"mcm","clk":"1362415946","pt":1588449231220,"mc":[{"id":"1.170370564","rc":[{"trd":[[1.2,879.59]],"ltp":1.2,"tv":879.59,"id":8509691},{"atl":[[1.2,308.64]],"id":8509691}],"con":true,"img":false}]}
{"op":"mcm","clk":"1362415974","pt":1588449235947,"mc":[{"id":"1.170370564","rc":[{"trd":[[1.19,42.56]],"ltp":1.19,"tv":42.56,"id":8509691},{"atb":[[1.19,0]],"id":8509691},{"atl":[[1.19,7.97]],"id":8509691}],"con":true,"img":false}]}
{"op":"mcm","clk":"1362415982","pt":1588449237219,"mc":[{"id":"1.170370564","rc":[{"atl":[[1.47,2]],"id":8509691}],"con":true,"img":false}]}
{"op":"mcm","clk":"1362415989","pt":1588449237828,"mc":[{"id":"1.170370564","rc":[{"atl":[[6.4,1.45]],"id":9630572}],"con":true,"img":false}]}
{"op":"mcm","clk":"1362415994","pt":1588449238743,"mc":[{"id":"1.170370564","rc":[{"atl":[[1.19,15.97]],"id":8509691}],"con":true,"img":false}]}
{"op":"mcm","clk":"1362416000","pt":1588449239556,"mc":[{"id":"1.170370564","rc":[{"atb":[[1.16,177.3]],"id":8509691}],"con":true,"img":false}]}
{"op":"mcm","clk":"1362416004","pt":1588449240062,"mc":[{"id":"1.170370564","rc":[{"trd":[[1.19,49.75]],"ltp":1.19,"tv":49.75,"id":8509691},{"atl":[[1.19,12.38]],"id":8509691}],"con":true,"img":false}]}
{"op":"mcm","clk":"1362416008","pt":1588449240622,"mc":[{"id":"1.170370564","rc":[{"trd":[[6.2,1.04]],"ltp":6.2,"tv":1.04,"id":9630572},{"trd":[[1.19,50.28]],"ltp":1.19,"tv":50.28,"id":8509691},{"atl":[[1.19,11.84]],"id":8509691}],"con":true,"img":false}]}
{"op":"mcm","clk":"1362416012","pt":1588449241844,"mc":[{"id":"1.170370565","rc":[{"atb":[[1.3,11.99]],"id":11269555}],"con":true,"img":false}]}
{"op":"mcm","clk":"1362416024","pt":1588449243836,"mc":[{"id":"1.170370564","rc":[{"atb":[[1.17,0]],"id":8509691}],"con":true,"img":false}]}
{"op":"mcm","clk":"1362416029","pt":1588449244758,"mc":[{"id":"1.170370565","rc":[{"atb":[[32,3]],"id":11269557}],"con":true,"img":false}]}
{"op":"mcm","clk":"1362416032","pt":1588449244962,"mc":[{"id":"1.170370564","rc":[{"trd":[[1.19,72.84]],"ltp":1.19,"tv":72.84,"id":8509691},{"atl":[[1.19,0.57]],"id":8509691}],"con":true,"img":false}]}
{"op":"mcm","clk":"1362416036","pt":1588449245266,"mc":[{"id":"1.170370565","rc":[{"atl":[[2.5,0]],"id":11269555}],"con":true,"img":false}]}
{"op":"mcm","clk":"1362416037","pt":1588449245368,"mc":[{"id":"1.170370564","rc":[{"trd":[[1.19,73.98]],"ltp":1.19,"tv":73.98,"id":8509691},{"atb":[[1.19,199.43]],"id":8509691},{"atl":[[1.19,0]],"id":8509691}],"con":true,"img":false}]}
{"op":"mcm","clk":"1362416051","pt":1588449246238,"mc":[{"id":"1.170370564","rc":[{"trd":[[6,0.88]],"ltp":6.0,"tv":0.88,"id":9630572},{"trd":[[1.2,884.03]],"ltp":1.2,"tv":884.03,"id":8509691},{"atl":[[1.2,304.2]],"id":8509691}],"con":true,"img":false}]}
{"op":"mcm","clk":"1362416057","pt":1588449246645,"mc":[{"id":"1.170370564","rc":[{"atl":[[1.54,4]],"id":8509691}],"con":true,"img":false}]}
{"op":"mcm","clk":"1362416060","pt":1588449246949,"mc":[{"id":"1.170370564","rc":[{"atb":[[1.19,205.82]],"id":8509691}],"con":true,"img":false}]}
{"op":"mcm","clk":"1362416065","pt":1588449247559,"mc":[{"id":"1.170370565","rc":[{"atb":[[32,0]],"id":11269557}],"con":true,"img":false}]}
{"op":"mcm","clk":"1362416068","pt":1588449248373,"mc":[{"id":"1.170370564","rc":[{"trd":[[1.19,74.68]],"ltp":1.19,"tv":74.68,"id":8509691},{"atb":[[1.19,205.47]],"id":8509691}],"con":true,"img":false}]}
{"op":"mcm","clk":"1362416080","pt":1588449249847,"mc":[{"id":"1.170370564","rc":[{"atl":[[1.2,0]],"id":8509691}],"con":true,"img":false}]}
{"op":"mcm","clk":"1362416090","pt":1588449251471,"mc":[{"id":"1.170370564","rc":[{"atb":[[1.11,495.83]],"id":8509691}],"con":true,"img":false}]}
{"op":"mcm","clk":"1362416095","pt":1588449252892,"mc":[{"id":"1.170370564","rc":[{"atb":[[1.11,200.62]],"id":8509691}],"con":true,"img":false}]}
{"op":"mcm","clk":"1362416105","pt":1588449253756,"mc":[{"id":"1.170370564","rc":[{"atl":[[1.3,178.98]],"id":8509691}],"con":true,"img":false}]}
{"op":"mcm","clk":"1362416108","pt":1588449254267,"mc":[{"id":"1.170370565","rc":[{"atl":[[32,3.54]],"id":11269557}],"con":true,"img":false}]}
{"op":"mcm","clk":"1362416112","pt":1588449255178,"mc":[{"id":"1.170370565","rc":[{"atl":[[32,0]],"id":11269557}],"con":true,"img":false}]}
{"op":"mcm","clk":"1362416116","pt":1588449255787,"mc":[{"id":"1.170370564","rc":[{"atl":[[1.22,177.3]],"id":8509691}],"con":true,"img":false}]}
{"op":"mcm","clk":"1362416119","pt":1588449256395,"mc":[{"id":"1.170370564","rc":[{"atb":[[1.19,207.47]],"id":8509691}],"con":true,"img":false}]}
{"op":"mcm","clk":"1362416126","pt":1588449257767,"mc":[{"id":"1.170370564","rc":[{"atl":[[6.4,101.45]],"id":9630572}],"con":true,"img":false}]}
{"op":"mcm","clk":"1362416136","pt":1588449259190,"mc":[{"id":"1.170370564","rc":[{"atb":[[1.2,0.46]],"id":8509691}],"con":true,"img":false}]}
{"op":"mcm","clk":"1362416153","pt":1588449262495,"mc":[{"id":"1.170370564","rc":[{"trd":[[1.19,459.15],[1.2,884.95]],"ltp":1.19,"tv":1344.1,"id":8509691},{"atb":[[1.2,0],[1.19,15.24]],"id":8509691}],"con":true,"img":false}]}
{"op":"mcm","clk":"1362416183","pt":1588449268603,"mc":[{"id":"1.170370566","rc":[{"atb":[[1.05,0]],"id":8509691}],"con":true,"img":false}]}
{"op":"mcm","clk":"1362416220","pt":1588449275920,"mc":[{"id":"1.170370567","rc":[{"atb":[[2.5,88.65]],"id":9630572}],"con":true,"img":false}]}
{"op":"mcm","clk":"1362416261","pt":1588449283045,"mc":[{"id":"1.170370564","rc":[{"trd":[[1.19,489.64]],"ltp":1.19,"tv":489.64,"id":8509691},{"atb":[[1.19,0]],"id":8509691},{"atl":[[1.19,84.75]],"id":8509691}],"con":true,"img":false}]}
{"op":"mcm","clk":"1362416262","pt":1588449283147,"mc":[{"id":"1.170370564","rc":[{"atl":[[8.8,3]],"id":9630572}],"con":true,"img":false}]}
{"op":"mcm","clk":"1362416329","pt":1588449294786,"mc":[{"id":"1.170370564","rc":[{"trd":[[1.19,620.28]],"ltp":1.19,"tv":620.28,"id":8509691},{"atl":[[1.19,19.43]],"id":8509691}],"con":true,"img":false}]}
{"op":"mcm","clk":"1362416334","pt":1588449295956,"mc":[{"id":"1.170370564","rc":[{"trd":[[1.19,630.28]],"ltp":1.19,"tv":630.28,"id":8509691},{"atl":[[1.19,14.43]],"id":8509691}],"con":true,"img":false}]}
{"op":"mcm","clk":"1362416336","pt":1588449296564,"mc":[{"id":"1.170370564","rc":[{"trd":[[6.4,1.52]],"ltp":6.4,"tv":1.52,"id":9630572},{"atl":[[6.4,99.93]],"id":9630572},{"trd":[[1.18,325.34]],"ltp":1.18,"tv":325.34,"id":8509691},{"atb":[[1.18,0]],"id":8509691}],"con":true,"img":false}]}
{"op":"mcm","clk":"1362416338","pt":1588449297172,"mc":[{"id":"1.170370564","rc":[{"atb":[[1.17,191.96]],"id":8509691}],"con":true,"img":false}]}
{"op":"mcm","clk":"1362416343","pt":1588449298086,"mc":[{"id":"1.170370564","rc":[{"trd":[[6.4,3.13]],"ltp":6.4,"tv":3.13,"id":9630572},{"atl":[[6.4,98.32]],"id":9630572},{"trd":[[1.18,334.1]],"ltp":1.18,"tv":334.1,"id":8509691}],"con":true,"img":false}]}
{"op":"mcm","clk":"1362416344","pt":1588449298187,"mc":[{"id":"1.170370566","rc":[{"atb":[[1.03,79.98]],"id":8509691}],"con":true,"img":false}]}
{"op":"mcm","clk":"1362416345","pt":1588449298290,"mc":[{"id":"1.170370564","rc":[{"trd":[[1.19,659.14]],"ltp":1.19,"tv":659.14,"id":8509691},{"atb":[[1.19,50.89]],"id":8509691},{"atl":[[1.19,0]],"id":8509691}],"con":true,"img":false}]}
{"op":"mcm","clk":"1362416355","pt":1588449299865,"mc":[{"id":"1.170370564","rc":[{"atb":[[1.17,0]],"id":8509691}],"con":true,"img":false}]}
{"op":"mcm","clk":"1362416369","pt":1588449301191,"mc":[{"id":"1.170370564","rc":[{"atl":[[1000,0]],"id":9630572}],"con":true,"img":false}]}
{"op":"mcm","clk":"1362416373","pt":1588449301599,"mc":[{"id":"1.170370564","rc":[{"trd":[[1.19,668.06]],"ltp":1.19,"tv":668.06,"id":8509691},{"atb":[[1.19,46.43]],"id":8509691}],"con":true,"img":false}]}
{"op":"mcm","clk":"1362416397","pt":1588449304001,"mc":[{"id":"1.170370564","rc":[{"trd":[[6.4,101.45]],"ltp":6.4,"tv":101.45,"id":9630572},{"atl":[[6.4,0]],"id":9630572},{"trd":[[1.18,867.36],[1.19,760.92]],"ltp":1.18,"tv":1628.28,"id":8509691},{"atb":[[1.19,0]],"id":8509691},{"atl":[[1.18,33.43]],"id":8509691}],"con":true,"img":false}]}
{"op":"mcm","clk":"1362416404","pt":1588449305277,"mc":[{"id":"1.170370566","rc":[{"atb":[[2.02,79.98]],"id":9630572}],"con":true,"img":false}]}
{"op":"mcm","clk":"1362416412","pt":1588449306297,"mc":[{"id":"1.170370564","rc":[{"trd":[[6.4,101.69]],"ltp":6.4,"tv":101.69,"id":9630572},{"trd":[[1.18,868.66]],"ltp":1.18,"tv":868.66,"id":8509691},{"atl":[[1.18,32.13]],"id":8509691}],"con":true,"img":false}]}
{"op":"mcm","clk":"1362416416","pt":1588449307009,"mc":[{"id":"1.170370564","rc":[{"trd":[[1.18,932.92]],"ltp":1.18,"tv":932.92,"id":8509691},{"atb":[[1.19,2046.77]],"id":8509691},{"atl":[[1.18,0]],"id":8509691}],"con":true,"img":false}]}
{"op":"mcm","clk":"1362416422","pt":1588449307672,"mc":[{"id":"1.170370564","rc":[{"atb":[[1.19,2057.79]],"id":8509691}],"con":true,"img":false}]}
{"op":"mcm","clk":"1362416425","pt":1588449308282,"mc":[{"id":"1.170370564","rc":[{"atl":[[6.2,0.7]],"id":9630572}],"con":true,"img":false}]}
{"op":"mcm","clk":"1362416437","pt":1588449310008,"mc":[{"id":"1.170370564","rc":[{"atl":[[6.2,9.57]],"id":9630572},{"trd":[[1.22,1117.36]],"ltp":1.22,"tv":1117.36,"id":8509691},{"atl":[[1.22,177.08]],"id":8509691}],"con":true,"img":false}]}
{"op":"mcm","clk":"1362416438","pt":1588449310109,"mc":[{"id":"1.170370564","rc":[{"atl":[[1.25,227.3]],"id":8509691}],"con":true,"img":false}]}
{"op":"mcm","clk":"1362416440","pt":1588449310516,"mc":[{"id":"1.170370566","rc":[{"atb":[[1.04,88.65]],"id":8509691}],"con":true,"img":false}]}
{"op":"mcm","clk":"1362416463","pt":1588449313212,"mc":[{"id":"1.170370564","rc":[{"atl":[[6.2,8.86]],"id":9630572}],"con":true,"img":false}]}
{"op":"mcm","clk":"1362416464","pt":1588449313314,"mc":[{"id":"1.170370564","rc":[{"atb":[[1.2,11.52]],"id":8509691}],"con":true,"img":false}]}
{"op":"mcm","clk":"1362416471","pt":1588449314025,"mc":[{"id":"1.170370564","rc":[{"atl":[[1.22,225.98]],"id":8509691}],"con":true,"img":false}]}
{"op":"mcm","clk":"1362416480","pt":1588449315705,"mc":[{"id":"1.170370564","rc":[{"atb":[[1.19,2083.79]],"id":8509691}],"con":true,"img":false}]}
{"op":"mcm","clk":"1362416482","pt":1588449315909,"mc":[{"id":"1.170370564","rc":[{"atb":[[1.18,25.19]],"id":8509691}],"con":true,"img":false}]}
{"op":"mcm","clk":"1362416489","pt":1588449317696,"mc":[{"id":"1.170370565","rc":[{"atl":[[1.03,44]],"id":11340560}],"con":true,"img":false}]}
{"op":"mcm","clk":"1362416490","pt":1588449317798,"mc":[{"id":"1.170370564","rc":[{"atb":[[1.18,38.48]],"id":8509691}],"con":true,"img":false}]}
{"op":"mcm","clk":"1362416500","pt":1588449319425,"mc":[{"id":"1.170370564","rc":[{"atl":[[1.25,50]],"id":8509691}],"con":true,"img":false}]}
{"op":"mcm","clk":"1362416501","pt":1588449319526,"mc":[{"id":"1.170370564","rc":[{"atb":[[1.19,37.02]],"id":8509691}],"con":true,"img":false}]}
{"op":"mcm","clk":"1362416502","pt":1588449319933,"mc":[{"id":"1.170370564","rc":[{"atb":[[1.2,0]],"id":8509691}],"con":true,"img":false}]}
{"op":"mcm","clk":"1362416507","pt":1588449321051,"mc":[{"id":"1.170370565","rc":[{"atl":[[1.03,0]],"id":11340560}],"con":true,"img":false}]}
{"op":"mcm","clk":"1362416510","pt":1588449321511,"mc":[{"id":"1.170370564","rc":[{"atl":[[1.25,0]],"id":8509691}],"con":true,"img":false}]}
{"op":"mcm","clk":"1362416511","pt":1588449321716,"mc":[{"id":"1.170370564","rc":[{"atb":[[1.01,467.99]],"id":9630572}],"con":true,"img":false}]}
{"op":"mcm","clk":"1362416520","pt":1588449322734,"mc":[{"id":"1.170370564","rc":[{"atb":[[1.18,13.29]],"id":8509691}],"con":true,"img":false}]}
{"op":"mcm","clk":"1362416527","pt":1588449323345,"mc":[{"id":"1.170370564","rc":[{"atb":[[1.16,0]],"id":8509691}],"con":true,"img":false}]}
{"op":"mcm","clk":"1362416541","pt":1588449324616,"mc":[{"id":"1.170370564","rc":[{"atb":[[1.21,2046.77]],"id":8509691}],"con":true,"img":false}]}
{"op":"mcm","clk":"1362416543","pt":1588449325024,"mc":[{"id":"1.170370564","rc":[{"atb":[[1.18,24.82]],"id":8509691}],"con":true,"img":false}]}
{"op":"mcm","clk":"1362416554","pt":1588449326244,"mc":[{"id":"1.170370564","rc":[{"trd":[[1.21,2444.08]],"ltp":1.21,"tv":2444.08,"id":8509691},{"atb":[[1.21,1170.88]],"id":8509691}],"con":true,"img":false}]}
{"op":"mcm","clk":"1362416558","pt":1588449326651,"mc":[{"id":"1.170370564","rc":[{"atl":[[1.3,228.98]],"id":8509691}],"con":true,"img":false}]}
{"op":"mcm","clk":"1362416564","pt":1588449326957,"mc":[{"id":"1.170370564","rc":[{"atl":[[1.22,48.9]],"id":8509691}],"con":true,"img":false}]}
{"op":"mcm","clk":"1362416572","pt":1588449327822,"mc":[{"id":"1.170370564","rc":[{"trd":[[1.22,1166.08]],"ltp":1.22,"tv":1166.08,"id":8509691},{"atl":[[1.22,24.53]],"id":8509691}],"con":true,"img":false}]}
{"op":"mcm","clk":"1362416573","pt":1588449328025,"mc":[{"id":"1.170370564","rc":[{"trd":[[5.8,100]],"ltp":5.8,"tv":100.0,"id":9630572},{"trd":[[1.21,2923.41]],"ltp":1.21,"tv":2923.41,"id":8509691},{"atb":[[1.21,691.55]],"id":8509691}],"con":true,"img":false}]}
{"op":"mcm","clk":"1362416574","pt":1588449328228,"mc":[{"id":"1.170370564","rc":[{"trd":[[1.22,1215.16]],"ltp":1.22,"tv":1215.16,"id":8509691},{"atb":[[1.22,0.46]],"id":8509691},{"atl":[[1.22,0]],"id":8509691}],"con":true,"img":false}]}
{"op":"mcm","clk":"1362416580","pt":1588449329548,"mc":[{"id":"1.170370564","rc":[{"atl":[[6.2,0]],"id":9630572}],"con":true,"img":false}]}
{"op":"mcm","clk":"1362416588","pt":1588449331072,"mc":[{"id":"1.170370564","rc":[{"atb":[[1.18,13.29]],"id":8509691}],"con":true,"img":false}]}
{"op":"mcm","clk":"1362416589","pt":1588449331224,"mc":[{"id":"1.170370564","rc":[{"atb":[[1.2,77]],"id":8509691}],"con":true,"img":false}]}
{"op":"mcm","clk":"1362416601","pt":1588449332544,"mc":[{"id":"1.170370564","rc":[{"atb":[[1.01,468.23]],"id":9630572}],"con":true,"img":false}]}
{"op":"mcm","clk":"1362416603","pt":1588449332748,"mc":[{"id":"1.170370564","rc":[{"atb":[[1.21,0]],"id":8509691}],"con":true,"img":false}]}
{"op":"mcm","clk":"1362416612","pt":1588449333765,"mc":[{"id":"1.170370564","rc":[{"trd":[[1.22,1216.08]],"ltp":1.22,"tv":1216.08,"id":8509691},{"atb":[[1.22,0]],"id":8509691},{"atl":[[1.21,176.84]],"id":8509691}],"con":true,"img":false}]}
{"op":"mcm","clk":"1362416628","pt":1588449336157,"mc":[{"id":"1.170370564","rc":[{"trd":[[1.21,2946.46]],"ltp":1.21,"tv":2946.46,"id":8509691},{"atl":[[1.21,165.31]],"id":8509691}],"con":true,"img":false}]}
{"op":"mcm","clk":"1362416640","pt":1588449337172,"mc":[{"id":"1.170370565","rc":[{"atb":[[1.1,106.38]],"id":11340560}],"con":true,"img":false}]}
{"op":"mcm","clk":"1362416646","pt":1588449337477,"mc":[{"id":"1.170370564","rc":[{"atl":[[1.21,174.62]],"id":8509691}],"con":true,"img":false}]}
{"op":"mcm","clk":"1362416652","pt":1588449337985,"mc":[{"id":"1.170370564","rc":[{"trd":[[1.2,899.53]],"ltp":1.2,"tv":899.53,"id":8509691},{"atb":[[1.2,69.71]],"id":8509691}],"con":true,"img":false}]}
{"op":"mcm","clk":"1362416656","pt":1588449339055,"mc":[{"id":"1.170370565","rc":[{"atb":[[3.05,0]],"id":11340557}],"con":true,"img":false}]}
{"op":"mcm","clk":"1362416660","pt":1588449339666,"mc":[{"id":"1.170370564","rc":[{"atl":[[1.3,178.98]],"id":8509691}],"con":true,"img":false}]}
{"op":"mcm","clk":"1362416663","pt":1588449339972,"mc":[{"id":"1.170370564","rc":[{"atl":[[1.21,245.42]],"id":8509691}],"con":true,"img":false}]}
{"op":"mcm","clk":"1362416695","pt":1588449343284,"mc":[{"id":"1.170370564","rc":[{"atl":[[1.21,236.11]],"id":8509691}],"con":true,"img":false}]}
{"op":"mcm","clk":"1362416704","pt":1588449344303,"mc":[{"id":"1.170370564","rc":[{"atl":[[1.26,240]],"id":8509691}],"con":true,"img":false}]}
{"op":"mcm","clk":"1362416710","pt":1588449344762,"mc":[{"id":"1.170370564","rc":[{"atl":[[1.28,290]],"id":8509691}],"con":true,"img":false}]}
{"op":"mcm","clk":"1362416712","pt":1588449344863,"mc":[{"id":"1.170370566","rc":[{"atb":[[1.03,0]],"id":8509691}],"con":true,"img":false}]}
{"op":"mcm","clk":"1362416714","pt":1588449345067,"mc":[{"id":"1.170370564","rc":[{"atb":[[1.19,11.02]],"id":8509691}],"con":true,"img":false}]}
{"op":"mcm","clk":"1362416719","pt":1588449345576,"mc":[{"id":"1.170370564","rc":[{"atl":[[1.25,2]],"id":8509691}],"con":true,"img":false}]}
{"op":"mcm","clk":"1362416722","pt":1588449345779,"mc":[{"id":"1.170370565","rc":[{"atb":[[1.1,0]],"id":11340560}],"con":true,"img":false}]}
{"op":"mcm","clk":"1362416725","pt":1588449346084,"mc":[{"id":"1.170370564","rc":[{"atb":[[1.01,464.79]],"id":9630572}],"con":true,"img":false}]}
{"op":"mcm","clk":"1362416732","pt":1588449346796,"mc":[{"id":"1.170370564","rc":[{"trd":[[1.21,2996.46]],"ltp":1.21,"tv":2996.46,"id":8509691},{"atl":[[1.21,211.11]],"id":8509691}],"con":true,"img":false}]}
{"op":"mcm","clk":"1362416735","pt":1588449347101,"mc":[{"id":"1.170370564","rc":[{"atb":[[1.19,0]],"id":8509691}],"con":true,"img":false}]}
{"op":"mcm","clk":"1362416736","pt":1588449347203,"mc":[{"id":"1.170370564","rc":[{"atl":[[1.21,140.31]],"id":8509691}],"con":true,"img":false}]}
{"op":"mcm","clk":"1362416743","pt":1588449347965,"mc":[{"id":"1.170370564","rc":[{"atl":[[1.27,0]],"id":8509691}],"con":true,"img":false}]}
{"op":"mcm","clk":"1362416752","pt":1588449348881,"mc":[{"id":"1.170370564","rc":[{"trd":[[1.21,3000.47]],"ltp":1.21,"tv":3000.47,"id":8509691},{"atl":[[1.21,138.31]],"id":8509691}],"con":true,"img":false}]}
{"op":"mcm","clk":"1362416765","pt":1588449349999,"mc":[{"id":"1.170370566","rc":[{"atb":[[1.05,79.98]],"id":8509691}],"con":true,"img":false}]}
{"op":"mcm","clk":"1362416769","pt":1588449350202,"mc":[{"id":"1.170370564","rc":[{"trd":[[1.21,3052.47]],"ltp":1.21,"tv":3052.47,"id":8509691},{"atl":[[1.21,112.31]],"id":8509691}],"con":true,"img":false}]}
{"op":"mcm","clk":"1362416775","pt":1588449350863,"mc":[{"id":"1.170370565","rc":[{"atb":[[1.12,106.38]],"id":11340560}],"con":true,"img":false}]}
{"op":"mcm","clk":"1362416777","pt":1588449351168,"mc":[{"id":"1.170370564","rc":[{"atb":[[4.8,10.23]],"id":9630572}],"con":true,"img":false}]}
{"op":"mcm","clk":"1362416785","pt":1588449351778,"mc":[{"id":"1.170370564","rc":[{"atl":[[1.25,179.3]],"id":8509691}],"con":true,"img":false}]}
{"op":"mcm","clk":"1362416789","pt":1588449352185,"mc":[{"id":"1.170370564","rc":[{"trd":[[1.21,3074.15]],"ltp":1.21,"tv":3074.15,"id":8509691},{"atl":[[1.21,101.47]],"id":8509691}],"con":true,"img":false}]}
{"op":"mcm","clk":"1362416792","pt":1588449352287,"mc":[{"id":"1.170370564","rc":[{"trd":[[1.2,1038.95]],"ltp":1.2,"tv":1038.95,"id":8509691},{"atb":[[1.2,0]],"id":8509691},{"atl":[[1.2,1.09]],"id":8509691}],"con":true,"img":false}]}
{"op":"mcm","clk":"1362416796","pt":1588449352795,"mc":[{"id":"1.170370564","rc":[{"trd":[[5.7,19.15],[6,1.1]],"ltp":5.7,"tv":20.25,"id":9630572},{"trd":[[1.21,3114.87],[1.2,1040.04]],"ltp":1.21,"tv":4154.91,"id":8509691},{"atl":[[1.2,0],[1.21,60.75]],"id":8509691}],"con":true,"img":false}]}
{"op":"mcm","clk":"1362416804","pt":1588449353507,"mc":[{"id":"1.170370564","rc":[{"atl":[[1.2,87.58]],"id":8509691}],"con":true,"img":false}]}
{"op":"mcm","clk":"1362416818","pt":1588449354575,"mc":[{"id":"1.170370565","rc":[{"atb":[[1.12,0]],"id":11340560}],"con":true,"img":false}]}
{"op":"mcm","clk":"1362416833","pt":1588449355795,"mc":[{"id":"1.170370566","rc":[{"atl":[[2,0]],"id":8509691}],"con":true,"img":false}]}
{"op":"mcm","clk":"1362416835","pt":1588449355897,"mc":[{"id":"1.170370564","rc":[{"atl":[[1.2,91.58]],"id":8509691}],"con":true,"img":false}]}
{"op":"mcm","clk":"1362416873","pt":1588449359707,"mc":[{"id":"1.170370565","rc":[{"atb":[[1.11,106.38]],"id":11340560}],"con":true,"img":false}]}
{"op":"mcm","clk":"1362416887","pt":1588449360928,"mc":[{"id":"1.170370566","rc":[{"atl":[[1.98,8.86]],"id":8509691}],"con":true,"img":false}]}
{"op":"mcm","clk":"1362416898","pt":1588449362006,"mc":[{"id":"1.170370564","rc":[{"atl":[[1.28,50],[1.26,0]],"id":8509691}],"con":true,"img":false}]}
{"op":"mcm","clk":"1362416904","pt":1588449362311,"mc":[{"id":"1.170370564","rc":[{"atl":[[1.2,4]],"id":8509691}],"con":true,"img":false}]}
{"op":"mcm","clk":"1362416915","pt":1588449363487,"mc":[{"id":"1.170370564","rc":[{"atb":[[1.17,177.3]],"id":8509691}],"con":true,"img":false}]}
{"op":"mcm","clk":"1362416932","pt":1588449364619,"mc":[{"id":"1.170370565","rc":[{"atb":[[1.5,177.3]],"id":11340560}],"con":true,"img":false}]}
{"op":"mcm","clk":"1362416938","pt":1588449365232,"mc":[{"id":"1.170370565","rc":[{"atb":[[1.11,0]],"id":11340560}],"con":true,"img":false}]}
{"op":"mcm","clk":"1362416960","pt":1588449366608,"mc":[{"id":"1.170370564","rc":[{"trd":[[1.2,1048.04]],"ltp":1.2,"tv":1048.04,"id":8509691},{"atb":[[1.2,21]],"id":8509691},{"atl":[[1.2,0]],"id":8509691}],"con":true,"img":false}]}
{"op":"mcm","clk":"1362416976","pt":1588449367932,"mc":[{"id":"1.170370566","rc":[{"atb":[[1.36,8.39]],"id":8509691}],"con":true,"img":false}]}
{"op":"mcm","clk":"1362417003","pt":1588449369915,"mc":[{"id":"1.170370564","rc":[{"atl":[[1.21,0]],"id":8509691}],"con":true,"img":false}]}
{"op":"mcm","clk":"1362417009","pt":1588449370322,"mc":[{"id":"1.170370565","rc":[{"atb":[[1.1,106.38]],"id":11340560}],"con":true,"img":false}]}
{"op":"mcm","clk":"1362417031","pt":1588449372818,"mc":[{"id":"1.170370565","rc":[{"atb":[[1.5,0]],"id":11340560}],"con":true,"img":false}]}
{"op":"mcm","clk":"1362417065","pt":1588449375514,"mc":[{"id":"1.170370564","rc":[{"atl":[[1.24,177.3]],"id":8509691}],"con":true,"img":false}]}
{"op":"mcm","clk":"1362417105","pt":1588449379007,"mc":[{"id":"1.170370564","rc":[{"atb":[[1.21,25]],"id":8509691}],"con":true,"img":false}]}
{"op":"mcm","clk":"1362417194","pt":1588449385439,"mc":[{"id":"1.170370564","rc":[{"trd":[[1.24,1758.95]],"ltp":1.24,"tv":1758.95,"id":8509691},{"atl":[[1.24,157.3]],"id":8509691}],"con":true,"img":false}]}
{"op":"mcm","clk":"1362417206","pt":1588449386456,"mc":[{"id":"1.170370564","rc":[{"atl":[[5.7,100]],"id":9630572}],"con":true,"img":false}]}
{"op":"mcm","clk":"1362417227","pt":1588449388442,"mc":[{"id":"1.170370564","rc":[{"trd":[[5.7,21.49]],"ltp":5.7,"tv":21.49,"id":9630572},{"atl":[[5.7,97.66]],"id":9630572},{"trd":[[1.21,3175.87]],"ltp":1.21,"tv":3175.87,"id":8509691},{"atb":[[1.21,0]],"id":8509691}],"con":true,"img":false}]}
{"op":"mcm","clk":"1362417229","pt":1588449388748,"mc":[{"id":"1.170370565","rc":[{"atb":[[1.3,132.97]],"id":11340560}],"con":true,"img":false}]}
{"op":"mcm","clk":"1362417233","pt":1588449388951,"mc":[{"id":"1.170370564","rc":[{"trd":[[5.1,50.7]],"ltp":5.1,"tv":50.7,"id":9630572},{"atl":[[5.1,20.6]],"id":9630572},{"trd":[[1.24,1916.25]],"ltp":1.24,"tv":1916.25,"id":8509691},{"atl":[[1.24,0]],"id":8509691}],"con":true,"img":false}]}
{"op":"mcm","clk":"1362417242","pt":1588449389257,"mc":[{"id":"1.170370564","rc":[{"trd":[[5.1,70.7]],"ltp":5.1,"tv":70.7,"id":9630572},{"atl":[[5.1,10.6]],"id":9630572}],"con":true,"img":false}]}
{"op":"mcm","clk":"1362417251","pt":1588449390274,"mc":[{"id":"1.170370564","rc":[{"trd":[[5.1,71.18]],"ltp":5.1,"tv":71.18,"id":9630572},{"atl":[[5.1,10.12]],"id":9630572},{"trd":[[1.24,1918.23]],"ltp":1.24,"tv":1918.23,"id":8509691}],"con":true,"img":false}]}
{"op":"mcm","clk":"1362417264","pt":1588449391038,"mc":[{"id":"1.170370566","rc":[{"atb":[[1.36,0]],"id":8509691}],"con":true,"img":false}]}
{"op":"mcm","clk":"1362417265","pt":1588449391343,"mc":[{"id":"1.170370564","rc":[{"atb":[[1.17,0]],"id":8509691}],"con":true,"img":false}]}
{"op":"mcm","clk":"1362417294","pt":1588449393073,"mc":[{"id":"1.170370564","rc":[{"atb":[[1.12,0]],"id":8509691}],"con":true,"img":false}]}
{"op":"mcm","clk":"1362417318","pt":1588449395157,"mc":[{"id":"1.170370564","rc":[{"atl":[[1.25,2]],"id":8509691}],"con":true,"img":false}]}
{"op":"mcm","clk":"1362417332","pt":1588449395869,"mc":[{"id":"1.170370564","rc":[{"atl":[[5.7,0]],"id":9630572}],"con":true,"img":false}]}
{"op":"mcm","clk":"1362417337","pt":1588449396275,"mc":[{"id":"1.170370566","rc":[{"atb":[[2.02,0]],"id":9630572}],"con":true,"img":false}]}
{"op":"mcm","clk":"1362417350","pt":1588449396885,"mc":[{"id":"1.170370565","rc":[{"atb":[[1.3,0]],"id":11340560}],"con":true,"img":false}]}
{"op":"mcm","clk":"1362417365","pt":1588449398055,"mc":[{"id":"1.170370564","rc":[{"trd":[[5.1,81.31]],"ltp":5.1,"tv":81.31,"id":9630572},{"atl":[[5.1,0]],"id":9630572},{"trd":[[1.24,1959.87]],"ltp":1.24,"tv":1959.87,"id":8509691},{"atl":[[1.24,135.66]],"id":8509691}],"con":true,"img":false}]}
{"op":"mcm","clk":"1362417374","pt":1588449398970,"mc":[{"id":"1.170370564","rc":[{"trd":[[5.1,114.3]],"ltp":5.1,"tv":114.3,"id":9630572},{"atl":[[5.1,67.01]],"id":9630572},{"trd":[[1.24,2095.54]],"ltp":1.24,"tv":2095.54,"id":8509691},{"atl":[[1.24,0]],"id":8509691}],"con":true,"img":false}]}
{"op":"mcm","clk":"1362417377","pt":1588449399275,"mc":[{"id":"1.170370564","rc":[{"atb":[[1.22,295.21]],"id":8509691}],"con":true,"img":false}]}
{"op":"mcm","clk":"1362417384","pt":1588449399783,"mc":[{"id":"1.170370564","rc":[{"trd":[[5.1,114.5]],"ltp":5.1,"tv":114.5,"id":9630572},{"atl":[[5.1,66.91]],"id":9630572}],"con":true,"img":false}]}
{"op":"mcm","clk":"1362417388","pt":1588449399885,"mc":[{"id":"1.170370564","rc":[{"trd":[[5.1,117.48]],"ltp":5.1,"tv":117.48,"id":9630572},{"atl":[[5.1,63.93]],"id":9630572},{"trd":[[1.24,2107.8]],"ltp":1.24,"tv":2107.8,"id":8509691}],"con":true,"img":false}]}
{"op":"mcm","clk":"1362417400","pt":1588449400851,"mc":[{"id":"1.170370564","rc":[{"atb":[[1.22,177.3]],"id":8509691}],"con":true,"img":false}]}
{"op":"mcm","clk":"1362417402","pt":1588449400953,"mc":[{"id":"1.170370564","rc":[{"trd":[[5.1,122.34]],"ltp":5.1,"tv":122.34,"id":9630572},{"atl":[[5.1,59.07]],"id":9630572},{"trd":[[1.24,2127.8]],"ltp":1.24,"tv":2127.8,"id":8509691}],"con":true,"img":false}]}
{"op":"mcm","clk":"1362417449","pt":1588449404364,"mc":[{"id":"1.170370564","rc":[{"atl":[[1.28,0]],"id":8509691}],"con":true,"img":false}]}
{"op":"mcm","clk":"1362417477","pt":1588449406095,"mc":[{"id":"1.170370564","rc":[{"trd":[[5.1,134.5]],"ltp":5.1,"tv":134.5,"id":9630572},{"atl":[[5.1,46.91]],"id":9630572},{"trd":[[1.24,2177.8]],"ltp":1.24,"tv":2177.8,"id":8509691}],"con":true,"img":false}]}
{"op":"mcm","clk":"1362417498","pt":1588449407977,"mc":[{"id":"1.170370565","rc":[{"atl":[[2.5,48.75]],"id":11269555}],"con":true,"img":false}]}
{"op":"mcm","clk":"1362417510","pt":1588449408790,"mc":[{"id":"1.170370564","rc":[{"trd":[[1.25,3265.07]],"ltp":1.25,"tv":3265.07,"id":8509691},{"atl":[[1.25,1.94]],"id":8509691}],"con":true,"img":false}]}
{"op":"mcm","clk":"1362417521","pt":1588449409503,"mc":[{"id":"1.170370564","rc":[{"atl":[[1.3,228.98]],"id":8509691}],"con":true,"img":false}]}
{"op":"mcm","clk":"1362417541","pt":1588449411179,"mc":[{"id":"1.170370564","rc":[{"atb":[[1.22,0]],"id":8509691}],"con":true,"img":false}]}
{"op":"mcm","clk":"1362417551","pt":1588449411892,"mc":[{"id":"1.170370564","rc":[{"trd":[[5.1,181.41]],"ltp":5.1,"tv":181.41,"id":9630572},{"atl":[[5.1,0]],"id":9630572},{"trd":[[1.24,2370.74]],"ltp":1.24,"tv":2370.74,"id":8509691},{"atl":[[1.24,17.27]],"id":8509691}],"con":true,"img":false}]}
{"op":"mcm","clk":"1362417553","pt":1588449411994,"mc":[{"id":"1.170370565","rc":[{"atl":[[2.5,0]],"id":11269555}],"con":true,"img":false}]}
{"op":"mcm","clk":"1362417556","pt":1588449412299,"mc":[{"id":"1.170370564","rc":[{"atb":[[1.22,10]],"id":8509691}],"con":true,"img":false}]}
{"op":"mcm","clk":"1362417626","pt":1588449418303,"mc":[{"id":"1.170370564","rc":[{"atl":[[1.24,0]],"id":8509691}],"con":true,"img":false}]}
{"op":"mcm","clk":"1362417650","pt":1588449420234,"mc":[{"id":"1.170370564","rc":[{"trd":[[1.25,3268.95]],"ltp":1.25,"tv":3268.95,"id":8509691},{"atb":[[1.25,18.06]],"id":8509691},{"atl":[[1.33,0],[1.25,0]],"id":8509691}],"con":true,"img":false}]}
{"op":"mcm","clk":"1362417655","pt":1588449420693,"mc":[{"id":"1.170370564","rc":[{"atb":[[1.25,313.27]],"id":8509691}],"con":true,"img":false}]}
{"op":"mcm","clk":"1362417657","pt":1588449420795,"mc":[{"id":"1.170370564","rc":[{"trd":[[4.8,199.12]],"ltp":4.8,"tv":199.12,"id":9630572},{"atb":[[4.8,0]],"id":9630572},{"atl":[[4.8,3.35]],"id":9630572}],"con":true,"img":false}]}
{"op":"mcm","clk":"1362417678","pt":1588449422531,"mc":[{"id":"1.170370564","rc":[{"atb":[[1.25,18.06]],"id":8509691}],"con":true,"img":false}]}
{"op":"mcm","clk":"1362417683","pt":1588449422941,"mc":[{"id":"1.170370564","rc":[{"atb":[[1.24,20]],"id":8509691}],"con":true,"img":false}]}
{"op":"mcm","clk":"1362417690","pt":1588449423298,"mc":[{"id":"1.170370566","rc":[{"atb":[[1.04,0]],"id":8509691}],"con":true,"img":false}]}
{"op":"mcm","clk":"1362417694","pt":1588449423502,"mc":[{"id":"1.170370564","rc":[{"atb":[[1.21,10]],"id":8509691}],"con":true,"img":false}]}
{"op":"mcm","clk":"1362417711","pt":1588449424626,"mc":[{"id":"1.170370565","rc":[{"atl":[[3,29.25]],"id":11269555}],"con":true,"img":false}]}
{"op":"mcm","clk":"1362417716","pt":1588449424831,"mc":[{"id":"1.170370564","rc":[{"atb":[[1.24,105.17]],"id":8509691}],"con":true,"img":false}]}
{"op":"mcm","clk":"1362417720","pt":1588449425035,"mc":[{"id":"1.170370564","rc":[{"atb":[[1.24,20]],"id":8509691}],"con":true,"img":false}]}
{"op":"mcm","clk":"1362417724","pt":1588449425341,"mc":[{"id":"1.170370564","rc":[{"atl":[[1.3,235.38]],"id":8509691}],"con":true,"img":false}]}
{"op":"mcm","clk":"1362417740","pt":1588449426106,"mc":[{"id":"1.170370564","rc":[{"atl":[[4.8,0]],"id":9630572}],"con":true,"img":false}]}
{"op":"mcm","clk":"1362417748","pt":1588449427026,"mc":[{"id":"1.170370564","rc":[{"atl":[[1000,1.89]],"id":8509691}],"con":true,"img":false}]}
{"op":"mcm","clk":"1362417763","pt":1588449427637,"mc":[{"id":"1.170370564","rc":[{"atl":[[1000,0.43]],"id":8509691}],"con":true,"img":false}]}
{"op":"mcm","clk":"1362417772","pt":1588449428199,"mc":[{"id":"1.170370564","rc":[{"atl":[[1000,0]],"id":8509691}],"con":true,"img":false}]}
{"op":"mcm","clk":"1362417782","pt":1588449428911,"mc":[{"id":"1.170370565","rc":[{"atl":[[3,0]],"id":11269555}],"con":true,"img":false}]}
{"op":"mcm","clk":"1362417793","pt":1588449429929,"mc":[{"id":"1.170370564","rc":[{"atl":[[1.31,0]],"id":8509691}],"con":true,"img":false}]}
{"op":"mcm","clk":"1362417804","pt":1588449430744,"mc":[{"id":"1.170370565","rc":[{"atb":[[1.1,0]],"id":11340560}],"con":true,"img":false}]}
{"op":"mcm","clk":"1362417811","pt":1588449431304,"mc":[{"id":"1.170370564","rc":[{"atb":[[4.8,100]],"id":9630572}],"con":true,"img":false}]}
{"op":"mcm","clk":"1362417839","pt":1588449433135,"mc":[{"id":"1.170370564","rc":[{"atb":[[4.8,0]],"id":9630572}],"con":true,"img":false}]}
{"op":"mcm","clk":"1362417845","pt":1588449433339,"mc":[{"id":"1.170370564","rc":[{"atl":[[1.26,0.43]],"id":8509691}],"con":true,"img":false}]}
{"op":"mcm","clk":"1362417854","pt":1588449433646,"mc":[{"id":"1.170370564","rc":[{"atb":[[4.8,3]],"id":9630572}],"con":true,"img":false}]}
{"op":"mcm","clk":"1362417879","pt":1588449435224,"mc":[{"id":"1.170370564","rc":[{"atl":[[1.39,3.19]],"id":8509691}],"con":true,"img":false}]}
{"op":"mcm","clk":"1362417917","pt":1588449438174,"mc":[{"id":"1.170370564","rc":[{"atb":[[1.23,50]],"id":8509691}],"con":true,"img":false}]}
{"op":"mcm","clk":"1362417922","pt":1588449438582,"mc":[{"id":"1.170370564","rc":[{"trd":[[1.25,3269.59]],"ltp":1.25,"tv":3269.59,"id":8509691},{"atb":[[1.25,17.74]],"id":8509691}],"con":true,"img":false}]}
{"op":"mcm","clk":"1362417959","pt":1588449441478,"mc":[{"id":"1.170370564","rc":[{"atb":[[1.24,211.96]],"id":8509691}],"con":true,"img":false}]}
{"op":"mcm","clk":"1362417962","pt":1588449441987,"mc":[{"id":"1.170370566","rc":[{"atb":[[1.06,2.62]],"id":8509691}],"con":true,"img":false}]}
{"op":"mcm","clk":"1362417964","pt":1588449442089,"mc":[{"id":"1.170370564","rc":[{"trd":[[4.8,202.12]],"ltp":4.8,"tv":202.12,"id":9630572},{"atb":[[4.8,0]],"id":9630572},{"trd":[[1.29,21959.71],[1.27,4765.45],[1.26,3104.15]],"ltp":1.29,"tv":29829.3,"id":8509691},{"atl":[[1.26,0],[1.29,33.37]],"id":8509691}],"con":true,"img":false}]}
{"op":"mcm","clk":"1362418031","pt":1588449446820,"mc":[{"id":"1.170370564","rc":[{"atb":[[4.4,100]],"id":9630572}],"con":true,"img":false}]}
{"op":"mcm","clk":"1362418039","pt":1588449447176,"mc":[{"id":"1.170370564","rc":[{"atb":[[1.27,20]],"id":8509691}],"con":true,"img":false}]}
{"op":"mcm","clk":"1362418106","pt":1588449451805,"mc":[{"id":"1.170370566","rc":[{"atb":[[1.05,0]],"id":8509691}],"con":true,"img":false}]}
{"op":"mcm","clk":"1362418114","pt":1588449452311,"mc":[{"id":"1.170370564","rc":[{"atb":[[1.24,20]],"id":8509691}],"con":true,"img":false}]}
{"op":"mcm","clk":"1362418120","pt":1588449452720,"mc":[{"id":"1.170370564","rc":[{"trd":[[5,5.97],[4.8,207.41]],"ltp":5.0,"tv":213.38,"id":9630572},{"trd":[[1.25,3283.88],[1.27,4785.45]],"ltp":1.25,"tv":8069.33,"id":8509691},{"atb":[[1.27,0],[1.25,3.44]],"id":8509691}],"con":true,"img":false}]}
{"op":"mcm","clk":"1362418160","pt":1588449456026,"mc":[{"id":"1.170370564","rc":[{"atb":[[1.27,295.21]],"id":8509691}],"con":true,"img":false}]}
{"op":"mcm","clk":"1362418179","pt":1588449457404,"mc":[{"id":"1.170370564","rc":[{"atb":[[1.22,201.96]],"id":8509691}],"con":true,"img":false}]}
{"op":"mcm","clk":"1362418187","pt":1588449457913,"mc":[{"id":"1.170370564","rc":[{"trd":[[1.27,4809.97]],"ltp":1.27,"tv":4809.97,"id":8509691},{"atb":[[1.27,282.95]],"id":8509691}],"con":true,"img":false}]}
{"op":"mcm","clk":"1362418194","pt":1588449458321,"mc":[{"id":"1.170370564","rc":[{"atb":[[1.27,0]],"id":8509691}],"con":true,"img":false}]}
{"op":"mcm","clk":"1362418198","pt":1588449458627,"mc":[{"id":"1.170370564","rc":[{"atl":[[5,3]],"id":9630572}],"con":true,"img":false}]}
{"op":"mcm","clk":"1362418240","pt":1588449461218,"mc":[{"id":"1.170370564","rc":[{"trd":[[1.29,21960.64]],"ltp":1.29,"tv":21960.64,"id":8509691},{"atl":[[1.29,32.91]],"id":8509691}],"con":true,"img":false}]}
{"op":"mcm","clk":"1362418243","pt":1588449461524,"mc":[{"id":"1.170370564","rc":[{"atb":[[1.23,0]],"id":8509691}],"con":true,"img":false}]}
{"op":"mcm","clk":"1362418251","pt":1588449462235,"mc":[{"id":"1.170370564","rc":[{"atl":[[1.27,7]],"id":8509691}],"con":true,"img":false}]}
{"op":"mcm","clk":"1362418264","pt":1588449462998,"mc":[{"id":"1.170370564","rc":[{"trd":[[1.25,3289.88]],"ltp":1.25,"tv":3289.88,"id":8509691},{"atb":[[1.25,0.44]],"id":8509691}],"con":true,"img":false}]}
{"op":"mcm","clk":"1362418272","pt":1588449463405,"mc":[{"id":"1.170370564","rc":[{"atl":[[1.28,12.16]],"id":8509691}],"con":true,"img":false}]}
{"op":"mcm","clk":"1362418313","pt":1588449467224,"mc":[{"id":"1.170370566","rc":[{"atb":[[1.06,0]],"id":8509691}],"con":true,"img":false}]}
{"op":"mcm","clk":"1362418380","pt":1588449472413,"mc":[{"id":"1.170370566","rc":[{"atb":[[1.22,2.62]],"id":8509691}],"con":true,"img":false}]}
{"op":"mcm","clk":"1362418382","pt":1588449472515,"mc":[{"id":"1.170370564","rc":[{"trd":[[1.27,4823.97]],"ltp":1.27,"tv":4823.97,"id":8509691},{"atb":[[1.27,43]],"id":8509691},{"atl":[[1.27,0]],"id":8509691}],"con":true,"img":false}]}
{"op":"mcm","clk":"1362418434","pt":1588449476839,"mc":[{"id":"1.170370564","rc":[{"atb":[[1.22,10]],"id":8509691}],"con":true,"img":false}]}
{"op":"mcm","clk":"1362418440","pt":1588449477347,"mc":[{"id":"1.170370564","rc":[{"atb":[[1.25,3.95]],"id":8509691}],"con":true,"img":false}]}
{"op":"mcm","clk":"1362418494","pt":1588449481060,"mc":[{"id":"1.170370564","rc":[{"atb":[[1.26,295.21]],"id":8509691}],"con":true,"img":false}]}
{"op":"mcm","clk":"1362418533","pt":1588449483920,"mc":[{"id":"1.170370564","rc":[{"atb":[[1.26,0]],"id":8509691}],"con":true,"img":false}]}
{"op":"mcm","clk":"1362418539","pt":1588449484432,"mc":[{"id":"1.170370564","rc":[{"trd":[[1.28,5821.5]],"ltp":1.28,"tv":5821.5,"id":8509691},{"atl":[[1.28,8.16]],"id":8509691}],"con":true,"img":false}]}
{"op":"mcm","clk":"1362418546","pt":1588449484741,"mc":[{"id":"1.170370564","rc":[{"trd":[[1.28,5837.83]],"ltp":1.28,"tv":5837.83,"id":8509691},{"atb":[[1.28,64.84]],"id":8509691},{"atl":[[1.28,0]],"id":8509691}],"con":true,"img":false}]}
{"op":"mcm","clk":"1362418552","pt":1588449484945,"mc":[{"id":"1.170370564","rc":[{"atb":[[1.28,0]],"id":8509691}],"con":true,"img":false}]}
{"op":"mcm","clk":"1362418637","pt":1588449491154,"mc":[{"id":"1.170370564","rc":[{"trd":[[1.29,22026.47]],"ltp":1.29,"tv":22026.47,"id":8509691},{"atb":[[1.29,33.57]],"id":8509691},{"atl":[[1.29,0]],"id":8509691}],"con":true,"img":false}]}
{"op":"mcm","clk":"1362418643","pt":1588449491357,"mc":[{"id":"1.170370564","rc":[{"atb":[[1.29,0]],"id":8509691}],"con":true,"img":false}]}
{"op":"mcm","clk":"1362418651","pt":1588449491967,"mc":[{"id":"1.170370564","rc":[{"atb":[[4.2,0]],"id":9630572},{"trd":[[1.27,4824.67]],"ltp":1.27,"tv":4824.67,"id":8509691},{"atb":[[1.27,42.65]],"id":8509691}],"con":true,"img":false}]}
{"op":"mcm","clk":"1362418675","pt":1588449493849,"mc":[{"id":"1.170370564","rc":[{"atb":[[1.27,219.95]],"id":8509691}],"con":true,"img":false}]}
{"op":"mcm","clk":"1362418685","pt":1588449494763,"mc":[{"id":"1.170370564","rc":[{"trd":[[1.27,4828.91]],"ltp":1.27,"tv":4828.91,"id":8509691},{"atb":[[1.27,217.83]],"id":8509691}],"con":true,"img":false}]}
{"op":"mcm","clk":"1362418703","pt":1588449496186,"mc":[{"id":"1.170370564","rc":[{"atb":[[3,0]],"id":9630572}],"con":true,"img":false}]}
{"op":"mcm","clk":"1362418721","pt":1588449497662,"mc":[{"id":"1.170370564","rc":[{"atb":[[1.28,177.3]],"id":8509691}],"con":true,"img":false}]}
{"op":"mcm","clk":"1362418725","pt":1588449498170,"mc":[{"id":"1.170370564","rc":[{"atl":[[1.3,228.98]],"id":8509691}],"con":true,"img":false}]}
{"op":"mcm","clk":"1362418749","pt":1588449499897,"mc":[{"id":"1.170370564","rc":[{"atb":[[1.29,20]],"id":8509691}],"con":true,"img":false}]}
{"op":"mcm","clk":"1362418769","pt":1588449501270,"mc":[{"id":"1.170370564","rc":[{"atb":[[3.2,5.79]],"id":9630572}],"con":true,"img":false}]}
{"op":"mcm","clk":"1362418802","pt":1588449503866,"mc":[{"id":"1.170370564","rc":[{"trd":[[1.29,22048.43]],"ltp":1.29,"tv":22048.43,"id":8509691},{"atb":[[1.29,9.02]],"id":8509691}],"con":true,"img":false}]}
{"op":"mcm","clk":"1362418840","pt":1588449506866,"mc":[{"id":"1.170370564","rc":[{"trd":[[1.28,6011.9],[1.29,22066.47]],"ltp":1.28,"tv":28078.37,"id":8509691},{"atb":[[1.28,90.26],[1.29,0]],"id":8509691}],"con":true,"img":false}]}
{"op":"mcm","clk":"1362418843","pt":1588449506967,"mc":[{"id":"1.170370564","rc":[{"trd":[[4.6,111.5]],"ltp":4.6,"tv":111.5,"id":9630572},{"trd":[[1.28,6017.14]],"ltp":1.28,"tv":6017.14,"id":8509691},{"atb":[[1.28,85.02]],"id":8509691}],"con":true,"img":false}]}
{"op":"mcm","clk":"1362418916","pt":1588449511394,"mc":[{"id":"1.170370564","rc":[{"atb":[[1.26,177.3]],"id":8509691}],"con":true,"img":false}]}
{"op":"mcm","clk":"1362418928","pt":1588449512310,"mc":[{"id":"1.170370564","rc":[{"trd":[[1.28,6063.53]],"ltp":1.28,"tv":6063.53,"id":8509691},{"atb":[[1.28,61.83]],"id":8509691}],"con":true,"img":false}]}
{"op":"mcm","clk":"1362418958","pt":1588449514399,"mc":[{"id":"1.170370564","rc":[{"atb":[[3.2,3.36]],"id":9630572}],"con":true,"img":false}]}
{"op":"mcm","clk":"1362418962","pt":1588449514805,"mc":[{"id":"1.170370564","rc":[{"atl":[[1.39,0]],"id":8509691}],"con":true,"img":false}]}
{"op":"mcm","clk":"1362418985","pt":1588449516485,"mc":[{"id":"1.170370564","rc":[{"trd":[[1.3,3906.5]],"ltp":1.3,"tv":3906.5,"id":8509691},{"atl":[[1.3,228.19]],"id":8509691}],"con":true,"img":false}]}
{"op":"mcm","clk":"1362418992","pt":1588449516893,"mc":[{"id":"1.170370564","rc":[{"trd":[[1.3,4009.61]],"ltp":1.3,"tv":4009.61,"id":8509691},{"atl":[[1.3,176.63]],"id":8509691}],"con":true,"img":false}]}
{"op":"mcm","clk":"1362419009","pt":1588449518519,"mc":[{"id":"1.170370564","rc":[{"trd":[[1.3,4027.34]],"ltp":1.3,"tv":4027.34,"id":8509691},{"atl":[[1.3,167.77]],"id":8509691}],"con":true,"img":false}]}
{"op":"mcm","clk":"1362419020","pt":1588449519486,"mc":[{"id":"1.170370564","rc":[{"atb":[[3,2.43]],"id":9630572}],"con":true,"img":false}]}
{"op":"mcm","clk":"1362419023","pt":1588449519588,"mc":[{"id":"1.170370564","rc":[{"atb":[[1.26,0]],"id":8509691}],"con":true,"img":false}]}
{"op":"mcm","clk":"1362419035","pt":1588449520098,"mc":[{"id":"1.170370564","rc":[{"atl":[[1.29,3.43]],"id":8509691}],"con":true,"img":false}]}
{"op":"mcm","clk":"1362419049","pt":1588449520912,"mc":[{"id":"1.170370564","rc":[{"atb":[[1.28,0]],"id":8509691}],"con":true,"img":false}]}
{"op":"mcm","clk":"1362419062","pt":1588449521624,"mc":[{"id":"1.170370564","rc":[{"trd":[[1.29,22067.51]],"ltp":1.29,"tv":22067.51,"id":8509691},{"atl":[[1.29,2.91]],"id":8509691}],"con":true,"img":false}]}
{"op":"mcm","clk":"1362419076","pt":1588449522795,"mc":[{"id":"1.170370564","rc":[{"atl":[[1.29,6.46]],"id":8509691}],"con":true,"img":false}]}
{"op":"mcm","clk":"1362419100","pt":1588449524524,"mc":[{"id":"1.170370564","rc":[{"trd":[[1.27,4833.05]],"ltp":1.27,"tv":4833.05,"id":8509691},{"atb":[[1.27,215.76]],"id":8509691}],"con":true,"img":false}]}
{"op":"mcm","clk":"1362419131","pt":1588449526817,"mc":[{"id":"1.170370564","rc":[{"atl":[[1.3,169.77]],"id":8509691}],"con":true,"img":false}]}
{"op":"mcm","clk":"1362419143","pt":1588449527631,"mc":[{"id":"1.170370564","rc":[{"atb":[[1.25,3.5]],"id":8509691}],"con":true,"img":false}]}
{"op":"mcm","clk":"1362419152","pt":1588449528038,"mc":[{"id":"1.170370564","rc":[{"trd":[[1.3,4054.41],[1.29,22080.44]],"ltp":1.3,"tv":26134.85,"id":8509691},{"atl":[[1.3,156.23],[1.29,0]],"id":8509691}],"con":true,"img":false}]}
{"op":"mcm","clk":"1362419211","pt":1588449532219,"mc":[{"id":"1.170370564","rc":[{"atl":[[1.28,44]],"id":8509691}],"con":true,"img":false}]}
{"op":"mcm","clk":"1362419251","pt":1588449534208,"mc":[{"id":"1.170370564","rc":[{"atl":[[1.3,154.23]],"id":8509691}],"con":true,"img":false}]}
{"op":"mcm","clk":"1362419361","pt":1588449541641,"mc":[{"id":"1.170370564","rc":[{"trd":[[1.28,6151.52]],"ltp":1.28,"tv":6151.52,"id":8509691},{"atb":[[1.28,0.32]],"id":8509691},{"atl":[[1.28,0]],"id":8509691}],"con":true,"img":false}]}
{"op":"mcm","clk":"1362419375","pt":1588449542587,"mc":[{"id":"1.170370564","rc":[{"atb":[[1.28,0]],"id":8509691}],"con":true,"img":false}]}
{"op":"mcm","clk":"1362419381","pt":1588449543019,"mc":[{"id":"1.170370564","rc":[{"atl":[[4.5,9.89]],"id":9630572}],"con":true,"img":false}]}
{"op":"mcm","clk":"1362419400","pt":1588449544136,"mc":[{"id":"1.170370564","rc":[{"atb":[[1.27,38.46]],"id":8509691}],"con":true,"img":false}]}
{"op":"mcm","clk":"1362419441","pt":1588449546934,"mc":[{"id":"1.170370564","rc":[{"trd":[[4.5,771.53]],"ltp":4.5,"tv":771.53,"id":9630572},{"atl":[[4.5,4.85]],"id":9630572},{"trd":[[1.28,6169.25]],"ltp":1.28,"tv":6169.25,"id":8509691}],"con":true,"img":false}]}
{"op":"mcm","clk":"1362419475","pt":1588449549333,"mc":[{"id":"1.170370564","rc":[{"trd":[[4.5,776.38]],"ltp":4.5,"tv":776.38,"id":9630572},{"atl":[[4.5,0]],"id":9630572},{"trd":[[1.27,4864.93],[1.28,6186.31]],"ltp":1.27,"tv":11051.24,"id":8509691},{"atb":[[1.27,22.52]],"id":8509691}],"con":true,"img":false}]}
{"op":"mcm","clk":"1362420319","pt":1588449560768,"mc":[{"id":"1.170370564","rc":[{"atb":[[1.28,295.21]],"id":8509691}],"con":true,"img":false}]}
{"op":"mcm","clk":"1362420331","pt":1588449561885,"mc":[{"id":"1.170370564","rc":[{"atb":[[1.28,0]],"id":8509691}],"con":true,"img":false}]}
{"op":"mcm","clk":"1362420382","pt":1588449566160,"mc":[{"id":"1.170370566","rc":[{"trd":[[1.22,5.24]],"ltp":1.22,"tv":5.24,"id":8509691},{"atb":[[1.22,0]],"id":8509691},{"atl":[[1.22,6.97]],"id":8509691}],"con":true,"img":false}]}
{"op":"mcm","clk":"1362420435","pt":1588449571298,"mc":[{"id":"1.170370564","rc":[{"trd":[[1.27,4909.97]],"ltp":1.27,"tv":4909.97,"id":8509691},{"atb":[[1.27,0]],"id":8509691},{"atl":[[1.27,154.78]],"id":8509691}],"con":true,"img":false}]}
{"op":"mcm","clk":"1362420446","pt":1588449572467,"mc":[{"id":"1.170370564","rc":[{"trd":[[1.27,4929.97]],"ltp":1.27,"tv":4929.97,"id":8509691},{"atl":[[1.27,144.78]],"id":8509691}],"con":true,"img":false}]}
{"op":"mcm","clk":"1362420455","pt":1588449573382,"mc":[{"id":"1.170370564","rc":[{"trd":[[5,8.97]],"ltp":5.0,"tv":8.97,"id":9630572},{"atl":[[5,0]],"id":9630572},{"trd":[[1.25,3308.89]],"ltp":1.25,"tv":3308.89,"id":8509691},{"atb":[[1.25,0]],"id":8509691},{"atl":[[1.25,161.79]],"id":8509691}],"con":true,"img":false}]}
{"op":"mcm","clk":"1362420457","pt":1588449573891,"mc":[{"id":"1.170370564","rc":[{"atl":[[1.27,0]],"id":8509691}],"con":true,"img":false}]}
{"op":"mcm","clk":"1362420462","pt":1588449574298,"mc":[{"id":"1.170370566","rc":[{"atl":[[1.22,0]],"id":8509691}],"con":true,"img":false}]}
{"op":"mcm","clk":"1362420463","pt":1588449574402,"mc":[{"id":"1.170370564","rc":[{"trd":[[1.24,2410.74]],"ltp":1.24,"tv":2410.74,"id":8509691},{"atb":[[1.24,0]],"id":8509691},{"atl":[[1.24,157.3],[1.25,0]],"id":8509691}],"con":true,"img":false}]}
{"op":"mcm","clk":"1362420472","pt":1588449575162,"mc":[{"id":"1.170370564","rc":[{"atl":[[1.24,0]],"id":8509691}],"con":true,"img":false}]}
{"op":"mcm","clk":"1362420497","pt":1588449576993,"mc":[{"id":"1.170370564","rc":[{"trd":[[4.4,282.24]],"ltp":4.4,"tv":282.24,"id":9630572},{"atb":[[4.4,95.57]],"id":9630572}],"con":true,"img":false}]}
{"op":"mcm","clk":"1362420525","pt":1588449579892,"mc":[{"id":"1.170370564","rc":[{"atb":[[1.01,467.99]],"id":9630572}],"con":true,"img":false}]}
{"op":"mcm","clk":"1362420533","pt":1588449580806,"mc":[{"id":"1.170370564","rc":[{"atb":[[1.01,464.82]],"id":9630572}],"con":true,"img":false}]}
{"op":"mcm","clk":"1362420537","pt":1588449580907,"mc":[{"id":"1.170370564","rc":[{"atb":[[1.25,177.3]],"id":8509691}],"con":true,"img":false}]}
{"op":"mcm","clk":"1362420551","pt":1588449581671,"mc":[{"id":"1.170370564","rc":[{"atb":[[1.01,464.79]],"id":9630572}],"con":true,"img":false}]}
{"op":"mcm","clk":"1362420555","pt":1588449581976,"mc":[{"id":"1.170370564","rc":[{"atb":[[1.26,177.3]],"id":8509691}],"con":true,"img":false}]}
{"op":"mcm","clk":"1362420564","pt":1588449582689,"mc":[{"id":"1.170370564","rc":[{"atb":[[1.25,0]],"id":8509691}],"con":true,"img":false}]}
{"op":"mcm","clk":"1362420627","pt":1588449586815,"mc":[{"id":"1.170370564","rc":[{"atb":[[4.7,0.02]],"id":9630572}],"con":true,"img":false}]}
{"op":"mcm","clk":"1362420646","pt":1588449588191,"mc":[{"id":"1.170370564","rc":[{"atb":[[1.26,0]],"id":8509691}],"con":true,"img":false}]}
{"op":"mcm","clk":"1362420657","pt":1588449588903,"mc":[{"id":"1.170370564","rc":[{"trd":[[4.4,291.06],[4.7,360.61]],"ltp":4.4,"tv":651.67,"id":9630572},{"atb":[[4.4,91.16],[4.7,0]],"id":9630572}],"con":true,"img":false}]}
{"op":"mcm","clk":"1362420678","pt":1588449590428,"mc":[{"id":"1.170370564","rc":[{"atl":[[1.44,0]],"id":8509691}],"con":true,"img":false}]}
{"op":"mcm","clk":"1362420735","pt":1588449593888,"mc":[{"id":"1.170370564","rc":[{"atl":[[1.26,262.41]],"id":8509691}],"con":true,"img":false}]}
{"op":"mcm","clk":"1362420779","pt":1588449596130,"mc":[{"id":"1.170370564","rc":[{"atl":[[1.26,0]],"id":8509691}],"con":true,"img":false}]}
{"op":"mcm","clk":"1362420853","pt":1588449600103,"mc":[{"id":"1.170370564","rc":[{"atb":[[1.27,295.21]],"id":8509691}],"con":true,"img":false}]}
{"op":"mcm","clk":"1362420864","pt":1588449600720,"mc":[{"id":"1.170370564","rc":[{"atl":[[1.29,8.86]],"id":8509691}],"con":true,"img":false}]}
{"op":"mcm","clk":"1362420908","pt":1588449604101,"mc":[{"id":"1.170370564","rc":[{"atb":[[1.27,0]],"id":8509691}],"con":true,"img":false}]}
{"op":"mcm","clk":"1362420930","pt":1588449605636,"mc":[{"id":"1.170370564","rc":[{"atl":[[1.26,55.12]],"id":8509691}],"con":true,"img":false}]}
{"op":"mcm","clk":"1362420938","pt":1588449606145,"mc":[{"id":"1.170370564","rc":[{"trd":[[1.3,4281.04],[1.26,3214.4],[1.29,22098.17]],"ltp":1.3,"tv":29593.61,"id":8509691},{"atl":[[1.26,0],[1.3,40.92],[1.29,0]],"id":8509691}],"con":true,"img":false}]}
{"op":"mcm","clk":"1362420943","pt":1588449606551,"mc":[{"id":"1.170370564","rc":[{"trd":[[4.4,331.35]],"ltp":4.4,"tv":331.35,"id":9630572},{"atb":[[4.4,50.87]],"id":9630572},{"trd":[[1.3,4499.27]],"ltp":1.3,"tv":4499.27,"id":8509691},{"atb":[[1.29,31.97]],"id":8509691},{"atl":[[1.3,0]],"id":8509691}],"con":true,"img":false}]}
{"op":"mcm","clk":"1362420947","pt":1588449606755,"mc":[{"id":"1.170370564","rc":[{"atb":[[1.29,0]],"id":8509691}],"con":true,"img":false}]}
{"op":"mcm","clk":"1362420975","pt":1588449608943,"mc":[{"id":"1.170370564","rc":[{"atl":[[1.27,262.41]],"id":8509691}],"con":true,"img":false}]}
{"op":"mcm","clk":"1362421008","pt":1588449610523,"mc":[{"id":"1.170370566","rc":[{"atl":[[1.98,0]],"id":8509691}],"con":true,"img":false}]}
{"op":"mcm","clk":"1362421015","pt":1588449611033,"mc":[{"id":"1.170370564","rc":[{"atl":[[1.27,0]],"id":8509691}],"con":true,"img":false}]}
{"op":"mcm","clk":"1362421066","pt":1588449614136,"mc":[{"id":"1.170370564","rc":[{"trd":[[4.4,341.35]],"ltp":4.4,"tv":341.35,"id":9630572},{"atb":[[4.4,45.87]],"id":9630572}],"con":true,"img":false}]}
{"op":"mcm","clk":"1362421070","pt":1588449614340,"mc":[{"id":"1.170370564","rc":[{"atb":[[1.27,34.34]],"id":8509691}],"con":true,"img":false}]}
{"op":"mcm","clk":"1362421074","pt":1588449614544,"mc":[{"id":"1.170370564","rc":[{"atb":[[1.27,0]],"id":8509691}],"con":true,"img":false}]}
{"op":"mcm","clk":"1362421103","pt":1588449616427,"mc":[{"id":"1.170370564","rc":[{"trd":[[4.4,341.38]],"ltp":4.4,"tv":341.38,"id":9630572},{"atb":[[4.4,45.84]],"id":9630572},{"trd":[[1.3,4499.35]],"ltp":1.3,"tv":4499.35,"id":8509691},{"atb":[[1.26,43.79]],"id":8509691}],"con":true,"img":false}]}
{"op":"mcm","clk":"1362421140","pt":1588449619837,"mc":[{"id":"1.170370564","rc":[{"atb":[[1.26,0]],"id":8509691}],"con":true,"img":false}]}
{"op":"mcm","clk":"1362421152","pt":1588449620346,"mc":[{"id":"1.170370564","rc":[{"trd":[[1.22,1222.08]],"ltp":1.22,"tv":1222.08,"id":8509691},{"atb":[[1.22,7]],"id":8509691}],"con":true,"img":false}]}
{"op":"mcm","clk":"1362421154","pt":1588449620549,"mc":[{"id":"1.170370564","rc":[{"atb":[[1.25,50]],"id":8509691}],"con":true,"img":false}]}
{"op":"mcm","clk":"1362421175","pt":1588449622279,"mc":[{"id":"1.170370564","rc":[{"trd":[[4.4,387.22]],"ltp":4.4,"tv":387.22,"id":9630572},{"atb":[[4.4,0]],"id":9630572},{"trd":[[1.3,4654.5]],"ltp":1.3,"tv":4654.5,"id":8509691},{"atb":[[1.3,730.48]],"id":8509691}],"con":true,"img":false}]}
{"op":"mcm","clk":"1362421179","pt":1588449622584,"mc":[{"id":"1.170370566","rc":[{"atl":[[3.05,8.86]],"id":8509691}],"con":true,"img":false}]}
{"op":"mcm","clk":"1362421193","pt":1588449623552,"mc":[{"id":"1.170370564","rc":[{"atb":[[1.29,7.99]],"id":8509691}],"con":true,"img":false}]}
{"op":"mcm","clk":"1362421241","pt":1588449627883,"mc":[{"id":"1.170370564","rc":[{"atb":[[1.3,0]],"id":8509691}],"con":true,"img":false}]}
{"op":"mcm","clk":"1362421251","pt":1588449628341,"mc":[{"id":"1.170370564","rc":[{"atl":[[1.3,2.57]],"id":8509691}],"con":true,"img":false}]}
{"op":"mcm","clk":"1362421280","pt":1588449630481,"mc":[{"id":"1.170370564","rc":[{"atl":[[4.4,5]],"id":9630572}],"con":true,"img":false}]}
{"op":"mcm","clk":"1362421308","pt":1588449632795,"mc":[{"id":"1.170370564","rc":[{"atb":[[1.1,694.79]],"id":8509691}],"con":true,"img":false}]}
{"op":"mcm","clk":"1362421310","pt":1588449632999,"mc":[{"id":"1.170370564","rc":[{"atl":[[1.3,0]],"id":8509691}],"con":true,"img":false}]}
{"op":"mcm","clk":"1362421313","pt":1588449633051,"mc":[{"id":"1.170370564","rc":[{"atb":[[1.29,0]],"id":8509691}],"con":true,"img":false}]}
{"op":"mcm","clk":"1362421346","pt":1588449636208,"mc":[{"id":"1.170370564","rc":[{"atl":[[1.3,8]],"id":8509691}],"con":true,"img":false}]}
{"op":"mcm","clk":"1362421367","pt":1588449638195,"mc":[{"id":"1.170370564","rc":[{"trd":[[1.3,4670.5]],"ltp":1.3,"tv":4670.5,"id":8509691},{"atl":[[1.3,0]],"id":8509691}],"con":true,"img":false}]}
{"op":"mcm","clk":"1362421398","pt":1588449641195,"mc":[{"id":"1.170370564","rc":[{"trd":[[4.4,392.22]],"ltp":4.4,"tv":392.22,"id":9630572},{"atl":[[4.4,0]],"id":9630572},{"trd":[[1.29,22115.23]],"ltp":1.29,"tv":22115.23,"id":8509691},{"atl":[[1.29,278.15]],"id":8509691}],"con":true,"img":false}]}
{"op":"mcm","clk":"1362421412","pt":1588449642367,"mc":[{"id":"1.170370564","rc":[{"atl":[[1.29,0]],"id":8509691}],"con":true,"img":false}]}
{"op":"mcm","clk":"1362421429","pt":1588449643691,"mc":[{"id":"1.170370564","rc":[{"trd":[[1.32,362.26]],"ltp":1.32,"tv":362.26,"id":8509691},{"atl":[[1.32,328.5]],"id":8509691}],"con":true,"img":false}]}
{"op":"mcm","clk":"1362421432","pt":1588449643893,"mc":[{"id":"1.170370564","rc":[{"atl":[[1.29,0.1]],"id":8509691}],"con":true,"img":false}]}
{"op":"mcm","clk":"1362421459","pt":1588449645981,"mc":[{"id":"1.170370564","rc":[{"trd":[[1.29,22115.43]],"ltp":1.29,"tv":22115.43,"id":8509691},{"atb":[[1.3,4.9]],"id":8509691},{"atl":[[1.29,0]],"id":8509691}],"con":true,"img":false}]}
{"op":"mcm","clk":"1362421462","pt":1588449646389,"mc":[{"id":"1.170370564","rc":[{"atb":[[1.28,17.18]],"id":8509691}],"con":true,"img":false}]}
{"op":"mcm","clk":"1362421582","pt":1588449657140,"mc":[{"id":"1.170370564","rc":[{"trd":[[1.28,6211.97],[1.3,4680.31]],"ltp":1.28,"tv":10892.28,"id":8509691},{"atb":[[1.28,4.36],[1.3,0]],"id":8509691}],"con":true,"img":false}]}
{"op":"mcm","clk":"1362421591","pt":1588449657699,"mc":[{"id":"1.170370564","rc":[{"trd":[[1.32,516.26]],"ltp":1.32,"tv":516.26,"id":8509691},{"atl":[[1.32,251.5]],"id":8509691}],"con":true,"img":false}]}
{"op":"mcm","clk":"1362421604","pt":1588449658618,"mc":[{"id":"1.170370564","rc":[{"atl":[[1.3,8.75]],"id":8509691}],"con":true,"img":false}]}
{"op":"mcm","clk":"1362421665","pt":1588449661935,"mc":[{"id":"1.170370564","rc":[{"atl":[[1.3,10.55]],"id":8509691}],"con":true,"img":false}]}
{"op":"mcm","clk":"1362421668","pt":1588449662139,"mc":[{"id":"1.170370564","rc":[{"atl":[[1.3,1.79]],"id":8509691}],"con":true,"img":false}]}
{"op":"mcm","clk":"1362421672","pt":1588449662344,"mc":[{"id":"1.170370564","rc":[{"atl":[[5,1.45]],"id":9630572}],"con":true,"img":false}]}
{"op":"mcm","clk":"1362421689","pt":1588449663420,"mc":[{"id":"1.170370564","rc":[{"atl":[[1.3,179.1]],"id":8509691}],"con":true,"img":false}]}
{"op":"mcm","clk":"1362421710","pt":1588449664645,"mc":[{"id":"1.170370564","rc":[{"atl":[[1.3,197.1]],"id":8509691}],"con":true,"img":false}]}
{"op":"mcm","clk":"1362421743","pt":1588449666836,"mc":[{"id":"1.170370564","rc":[{"atl":[[1.3,19.79]],"id":8509691}],"con":true,"img":false}]}
{"op":"mcm","clk":"1362421765","pt":1588449668314,"mc":[{"id":"1.170370564","rc":[{"trd":[[4.1,119.69]],"ltp":4.1,"tv":119.69,"id":9630572},{"atb":[[4.1,90.69]],"id":9630572},{"trd":[[1.33,28.7],[1.3,4719.9],[1.32,1019.26]],"ltp":1.33,"tv":5767.86,"id":8509691},{"atl":[[1.3,0],[1.32,0]],"id":8509691}],"con":true,"img":false}]}
{"op":"mcm","clk":"1362421773","pt":1588449668727,"mc":[{"id":"1.170370564","rc":[{"trd":[[4.1,210.38]],"ltp":4.1,"tv":210.38,"id":9630572},{"atb":[[4.1,0]],"id":9630572},{"trd":[[1.33,308.27]],"ltp":1.33,"tv":308.27,"id":8509691},{"atb":[[1.33,20.43]],"id":8509691}],"con":true,"img":false}]}
{"op":"mcm","clk":"1362421811","pt":1588449670761,"mc":[{"id":"1.170370564","rc":[{"atl":[[4.3,130.51]],"id":9630572}],"con":true,"img":false}]}
{"op":"mcm","clk":"1362421815","pt":1588449670957,"mc":[{"id":"1.170370564","rc":[{"atl":[[4.3,0]],"id":9630572}],"con":true,"img":false}]}
{"op":"mcm","clk":"1362421817","pt":1588449671010,"mc":[{"id":"1.170370564","rc":[{"trd":[[1.33,349.13]],"ltp":1.33,"tv":349.13,"id":8509691},{"atb":[[1.33,0]],"id":8509691},{"atl":[[1.33,31.12]],"id":8509691}],"con":true,"img":false}]}
{"op":"mcm","clk":"1362421861","pt":1588449673351,"mc":[{"id":"1.170370564","rc":[{"atl":[[4.3,5]],"id":9630572}],"con":true,"img":false}]}
{"op":"mcm","clk":"1362421864","pt":1588449673556,"mc":[{"id":"1.170370564","rc":[{"atb":[[1.32,177.3]],"id":8509691}],"con":true,"img":false}]}
{"op":"mcm","clk":"1362421871","pt":1588449673962,"mc":[{"id":"1.170370564","rc":[{"trd":[[4,9.27]],"ltp":4.0,"tv":9.27,"id":9630572},{"trd":[[1.33,377.01]],"ltp":1.33,"tv":377.01,"id":8509691},{"atl":[[1.33,3.24]],"id":8509691}],"con":true,"img":false}]}
{"op":"mcm","clk":"1362421875","pt":1588449674321,"mc":[{"id":"1.170370564","rc":[{"trd":[[1.33,383.5]],"ltp":1.33,"tv":383.5,"id":8509691},{"atb":[[1.33,174.06]],"id":8509691},{"atl":[[1.33,0]],"id":8509691}],"con":true,"img":false}]}
{"op":"mcm","clk":"1362421931","pt":1588449678141,"mc":[{"id":"1.170370564","rc":[{"atb":[[1.1,594.79]],"id":8509691}],"con":true,"img":false}]}
{"op":"mcm","clk":"1362421941","pt":1588449679058,"mc":[{"id":"1.170370564","rc":[{"trd":[[1.33,478.94]],"ltp":1.33,"tv":478.94,"id":8509691},{"atb":[[1.33,126.33]],"id":8509691}],"con":true,"img":false}]}
{"op":"mcm","clk":"1362421946","pt":1588449679262,"mc":[{"id":"1.170370566","rc":[{"atb":[[1.05,523.11]],"id":8509691}],"con":true,"img":false}]}
{"op":"mcm","clk":"1362421950","pt":1588449679468,"mc":[{"id":"1.170370564","rc":[{"trd":[[1.4,66.98],[1.36,29.4],[1.35,53.09]],"ltp":1.4,"tv":149.47,"id":8509691},{"atb":[[1.41,2.32]],"id":8509691},{"atl":[[1.35,0],[1.4,0],[1.36,0]],"id":8509691}],"con":true,"img":false}]}
{"op":"mcm","clk":"1362421952","pt":1588449679567,"mc":[{"id":"1.170370564","rc":[{"atb":[[1.01,467.42]],"id":9630572}],"con":true,"img":false},{"id":"1.170370566","rc":[{"atl":[[3.05,0]],"id":8509691}],"con":true,"img":false}]}
{"op":"mcm","clk":"1362421965","pt":1588449680331,"mc":[{"id":"1.170370564","rc":[{"atb":[[1.01,464.85]],"id":9630572}],"con":true,"img":false}]}
{"op":"mcm","clk":"1362421978","pt":1588449681248,"mc":[{"id":"1.170370564","rc":[{"atb":[[1.01,464.79]],"id":9630572}],"con":true,"img":false}]}
{"op":"mcm","clk":"1362421988","pt":1588449682065,"mc":[{"id":"1.170370564","rc":[{"trd":[[1.33,485.71],[1.41,4.65]],"ltp":1.33,"tv":490.35,"id":8509691},{"atb":[[1.33,122.95],[1.41,0]],"id":8509691}],"con":true,"img":false}]}
{"op":"mcm","clk":"1362422022","pt":1588449684663,"mc":[{"id":"1.170370566","rc":[{"atl":[[4,8.86]],"id":8509691}],"con":true,"img":false}]}
{"op":"mcm","clk":"1362422025","pt":1588449685071,"mc":[{"id":"1.170370564","rc":[{"atb":[[1.35,11.75]],"id":8509691}],"con":true,"img":false}]}
{"op":"mcm","clk":"1362422032","pt":1588449685478,"mc":[{"id":"1.170370564","rc":[{"atb":[[1.35,9.63]],"id":8509691}],"con":true,"img":false}]}
{"op":"mcm","clk":"1362422034","pt":1588449685631,"mc":[{"id":"1.170370564","rc":[{"trd":[[1.33,488.98]],"ltp":1.33,"tv":488.98,"id":8509691},{"atb":[[1.33,121.32],[1.35,0]],"id":8509691}],"con":true,"img":false}]}
{"op":"mcm","clk":"1362422042","pt":1588449685933,"mc":[{"id":"1.170370564","rc":[{"atb":[[1.35,100]],"id":8509691},{"atl":[[1.4,300]],"id":8509691}],"con":true,"img":false}]}
{"op":"mcm","clk":"1362422046","pt":1588449686239,"mc":[{"id":"1.170370564","rc":[{"atl":[[1.41,44.32]],"id":8509691}],"con":true,"img":false}]}
{"op":"mcm","clk":"1362422048","pt":1588449686342,"mc":[{"id":"1.170370564","rc":[{"trd":[[3.9,0.05]],"ltp":3.9,"tv":0.05,"id":9630572},{"trd":[[1.35,53.24]],"ltp":1.35,"tv":53.24,"id":8509691},{"atb":[[1.35,99.85]],"id":8509691}],"con":true,"img":false}]}
{"op":"mcm","clk":"1362422069","pt":1588449687461,"mc":[{"id":"1.170370564","rc":[{"atl":[[1.44,44.32]],"id":8509691}],"con":true,"img":false}]}
{"op":"mcm","clk":"1362422081","pt":1588449688276,"mc":[{"id":"1.170370564","rc":[{"trd":[[1.4,67.62]],"ltp":1.4,"tv":67.62,"id":8509691},{"atl":[[1.4,299.68]],"id":8509691}],"con":true,"img":false}]}
{"op":"mcm","clk":"1362422085","pt":1588449688531,"mc":[{"id":"1.170370564","rc":[{"trd":[[1.35,64]],"ltp":1.35,"tv":64.0,"id":8509691},{"atb":[[1.35,94.47]],"id":8509691}],"con":true,"img":false}]}
{"op":"mcm","clk":"1362422095","pt":1588449689550,"mc":[{"id":"1.170370564","rc":[{"atl":[[1.41,49.32]],"id":8509691}],"con":true,"img":false}]}
{"op":"mcm","clk":"1362422107","pt":1588449690364,"mc":[{"id":"1.170370564","rc":[{"trd":[[1.4,69.74]],"ltp":1.4,"tv":69.74,"id":8509691},{"atl":[[1.4,298.62]],"id":8509691}],"con":true,"img":false}]}
{"op":"mcm","clk":"1362422112","pt":1588449690873,"mc":[{"id":"1.170370564","rc":[{"atl":[[1.41,57.32]],"id":8509691}],"con":true,"img":false}]}
{"op":"mcm","clk":"1362422113","pt":1588449690974,"mc":[{"id":"1.170370564","rc":[{"trd":[[3.5,20]],"ltp":3.5,"tv":20.0,"id":9630572},{"trd":[[1.4,119.74]],"ltp":1.4,"tv":119.74,"id":8509691},{"atl":[[1.4,248.62]],"id":8509691}],"con":true,"img":false}]}
{"op":"mcm","clk":"1362422137","pt":1588449693061,"mc":[{"id":"1.170370564","rc":[{"atl":[[1.39,44.32]],"id":8509691}],"con":true,"img":false}]}
{"op":"mcm","clk":"1362422165","pt":1588449695657,"mc":[{"id":"1.170370564","rc":[{"trd":[[1.39,0.01]],"ltp":1.39,"tv":0.01,"id":8509691},{"atl":[[1.39,44.31]],"id":8509691}],"con":true,"img":false}]}
{"op":"mcm","clk":"1362422176","pt":1588449696572,"mc":[{"id":"1.170370564","rc":[{"trd":[[1.35,252.94]],"ltp":1.35,"tv":252.94,"id":8509691},{"atb":[[1.35,0]],"id":8509691},{"atl":[[1.35,205.53]],"id":8509691}],"con":true,"img":false}]}
{"op":"mcm","clk":"1362422197","pt":1588449698455,"mc":[{"id":"1.170370564","rc":[{"trd":[[1.35,279.36]],"ltp":1.35,"tv":279.36,"id":8509691},{"atl":[[1.35,192.32]],"id":8509691}],"con":true,"img":false}]}
{"op":"mcm","clk":"1362422203","pt":1588449698865,"mc":[{"id":"1.170370564","rc":[{"trd":[[1.35,282.92]],"ltp":1.35,"tv":282.92,"id":8509691},{"atl":[[1.35,190.54]],"id":8509691}],"con":true,"img":false}]}
{"op":"mcm","clk":"1362422215","pt":1588449700290,"mc":[{"id":"1.170370564","rc":[{"trd":[[1.35,328.38]],"ltp":1.35,"tv":328.38,"id":8509691},{"atl":[[1.35,167.81]],"id":8509691}],"con":true,"img":false}]}
{"op":"mcm","clk":"1362422224","pt":1588449700901,"mc":[{"id":"1.170370564","rc":[{"trd":[[3.5,43.81],[3.85,58.84],[3.55,17.35]],"ltp":3.5,"tv":120.0,"id":9630572},{"trd":[[1.4,179.27],[1.39,44.33],[1.35,496.19]],"ltp":1.4,"tv":719.79,"id":8509691},{"atl":[[1.39,0],[1.35,0],[1.4,189.09]],"id":8509691}],"con":true,"img":false}]}
{"op":"mcm","clk":"1362422236","pt":1588449702581,"mc":[{"id":"1.170370564","rc":[{"atl":[[5,0]],"id":9630572}],"con":true,"img":false}]}
{"op":"mcm","clk":"1362422241","pt":1588449703192,"mc":[{"id":"1.170370564","rc":[{"atl":[[1.35,2.11]],"id":8509691}],"con":true,"img":false}]}
{"op":"mcm","clk":"1362422246","pt":1588449703497,"mc":[{"id":"1.170370564","rc":[{"atb":[[1.32,0]],"id":8509691}],"con":true,"img":false}]}
{"op":"mcm","clk":"1362422248","pt":1588449703700,"mc":[{"id":"1.170370564","rc":[{"atl":[[1.38,6.39]],"id":8509691}],"con":true,"img":false}]}
{"op":"mcm","clk":"1362422254","pt":1588449703904,"mc":[{"id":"1.170370564","rc":[{"atl":[[1.35,9.11]],"id":8509691}],"con":true,"img":false}]}
{"op":"mcm","clk":"1362422279","pt":1588449705688,"mc":[{"id":"1.170370564","rc":[{"trd":[[1.35,497.15]],"ltp":1.35,"tv":497.15,"id":8509691},{"atl":[[1.35,8.63]],"id":8509691}],"con":true,"img":false}]}
{"op":"mcm","clk":"1362422281","pt":1588449705792,"mc":[{"id":"1.170370564","rc":[{"trd":[[1.33,586.56]],"ltp":1.33,"tv":586.56,"id":8509691},{"atb":[[1.33,72.52]],"id":8509691}],"con":true,"img":false}]}
{"op":"mcm","clk":"1362422308","pt":1588449707675,"mc":[{"id":"1.170370564","rc":[{"atl":[[4,1.45]],"id":9630572}],"con":true,"img":false}]}
{"op":"mcm","clk":"1362422351","pt":1588449711296,"mc":[{"id":"1.170370564","rc":[{"trd":[[4,10.72]],"ltp":4.0,"tv":10.72,"id":9630572},{"atl":[[4,0]],"id":9630572},{"trd":[[1.33,736]],"ltp":1.33,"tv":736.0,"id":8509691},{"atb":[[1.33,0]],"id":8509691},{"atl":[[1.33,223.09],[1.35,23.21]],"id":8509691}],"con":true,"img":false}]}
{"op":"mcm","clk":"1362422359","pt":1588449711806,"mc":[{"id":"1.170370564","rc":[{"atl":[[1.32,300]],"id":8509691}],"con":true,"img":false}]}
{"op":"mcm","clk":"1362422364","pt":1588449712417,"mc":[{"id":"1.170370564","rc":[{"atl":[[1.32,0]],"id":8509691}],"con":true,"img":false}]}
{"op":"mcm","clk":"1362422381","pt":1588449713589,"mc":[{"id":"1.170370564","rc":[{"trd":[[1.33,736.03]],"ltp":1.33,"tv":736.03,"id":8509691},{"atl":[[1.33,223.07]],"id":8509691}],"con":true,"img":false}]}
{"op":"mcm","clk":"1362422403","pt":1588449715777,"mc":[{"id":"1.170370564","rc":[{"trd":[[4,12.72]],"ltp":4.0,"tv":12.72,"id":9630572},{"trd":[[1.33,742.05]],"ltp":1.33,"tv":742.05,"id":8509691},{"atl":[[1.33,217.05]],"id":8509691}],"con":true,"img":false}]}
{"op":"mcm","clk":"1362422443","pt":1588449718984,"mc":[{"id":"1.170370564","rc":[{"atl":[[1.33,220.05]],"id":8509691}],"con":true,"img":false}]}
{"op":"mcm","clk":"1362422452","pt":1588449719698,"mc":[{"id":"1.170370564","rc":[{"atl":[[1.33,3],[1.4,0]],"id":8509691}],"con":true,"img":false}]}
{"op":"mcm","clk":"1362422458","pt":1588449720408,"mc":[{"id":"1.170370564","rc":[{"trd":[[1.35,513.9],[1.33,748.05]],"ltp":1.35,"tv":1261.94,"id":8509691},{"atl":[[1.33,0],[1.35,14.83]],"id":8509691}],"con":true,"img":false}]}
{"op":"mcm","clk":"1362422468","pt":1588449721121,"mc":[{"id":"1.170370564","rc":[{"atb":[[1.01,8552.56]],"id":8509691},{"atl":[[1.38,6.89]],"id":8509691}],"con":true,"img":false}]}
{"op":"mcm","clk":"1362422473","pt":1588449721784,"mc":[{"id":"1.170370564","rc":[{"atb":[[3,0]],"id":9630572}],"con":true,"img":false}]}
{"op":"mcm","clk":"1362422489","pt":1588449722709,"mc":[{"id":"1.170370564","rc":[{"trd":[[4.3,262.27]],"ltp":4.3,"tv":262.27,"id":9630572},{"atl":[[4.3,0]],"id":9630572},{"trd":[[1.3,4736.44]],"ltp":1.3,"tv":4736.44,"id":8509691},{"atl":[[1.3,28.26]],"id":8509691}],"con":true,"img":false}]}
{"op":"mcm","clk":"1362422510","pt":1588449724194,"mc":[{"id":"1.170370564","rc":[{"atb":[[2.9,100]],"id":9630572}],"con":true,"img":false}]}
{"op":"mcm","clk":"1362422512","pt":1588449724297,"mc":[{"id":"1.170370564","rc":[{"atl":[[1.41,13]],"id":8509691}],"con":true,"img":false}]}
{"op":"mcm","clk":"1362422524","pt":1588449725520,"mc":[{"id":"1.170370564","rc":[{"atl":[[1.35,0.26]],"id":8509691}],"con":true,"img":false}]}
{"op":"mcm","clk":"1362422527","pt":1588449725724,"mc":[{"id":"1.170370564","rc":[{"atl":[[1.44,0]],"id":8509691}],"con":true,"img":false}]}
{"op":"mcm","clk":"1362422533","pt":1588449726131,"mc":[{"id":"1.170370564","rc":[{"atl":[[1.3,205.56]],"id":8509691}],"con":true,"img":false}]}
{"op":"mcm","clk":"1362422540","pt":1588449726589,"mc":[{"id":"1.170370564","rc":[{"atl":[[1.29,177.3]],"id":8509691}],"con":true,"img":false}]}
{"op":"mcm","clk":"1362422541","pt":1588449726691,"mc":[{"id":"1.170370564","rc":[{"trd":[[1.29,22315.43]],"ltp":1.29,"tv":22315.43,"id":8509691},{"atl":[[1.29,77.3]],"id":8509691}],"con":true,"img":false}]}
{"op":"mcm","clk":"1362422543","pt":1588449726794,"mc":[{"id":"1.170370564","rc":[{"atl":[[1.33,93.45]],"id":8509691}],"con":true,"img":false}]}
{"op":"mcm","clk":"1362422545","pt":1588449726895,"mc":[{"id":"1.170370564","rc":[{"atb":[[2.9,102.43]],"id":9630572}],"con":true,"img":false}]}
{"op":"mcm","clk":"1362422551","pt":1588449727201,"mc":[{"id":"1.170370564","rc":[{"trd":[[1.28,6220.69]],"ltp":1.28,"tv":6220.69,"id":8509691},{"atb":[[1.28,0]],"id":8509691},{"atl":[[1.28,172.94]],"id":8509691}],"con":true,"img":false}]}
{"op":"mcm","clk":"1362422554","pt":1588449727505,"mc":[{"id":"1.170370564","rc":[{"atl":[[1.3,205.67]],"id":8509691}],"con":true,"img":false}]}
{"op":"mcm","clk":"1362422555","pt":1588449727608,"mc":[{"id":"1.170370564","rc":[{"atl":[[1.33,0]],"id":8509691}],"con":true,"img":false}]}
{"op":"mcm","clk":"1362422559","pt":1588449728218,"mc":[{"id":"1.170370564","rc":[{"trd":[[4.5,776.4]],"ltp":4.5,"tv":776.4,"id":9630572},{"trd":[[1.28,6220.76]],"ltp":1.28,"tv":6220.76,"id":8509691},{"atl":[[1.28,172.88]],"id":8509691}],"con":true,"img":false}]}
{"op":"mcm","clk":"1362422588","pt":1588449731319,"mc":[{"id":"1.170370564","rc":[{"atb":[[1.1,598.79]],"id":8509691}],"con":true,"img":false}]}
{"op":"mcm","clk":"1362422603","pt":1588449732793,"mc":[{"id":"1.170370564","rc":[{"atl":[[1.29,173.65]],"id":8509691}],"con":true,"img":false}]}
{"op":"mcm","clk":"1362422604","pt":1588449732895,"mc":[{"id":"1.170370564","rc":[{"atl":[[1.54,0],[1.47,0]],"id":8509691}],"con":true,"img":false}]}
{"op":"mcm","clk":"1362422622","pt":1588449734318,"mc":[{"id":"1.170370564","rc":[{"trd":[[1.28,6223.59]],"ltp":1.28,"tv":6223.59,"id":8509691},{"atl":[[1.28,171.46]],"id":8509691}],"con":true,"img":false}]}
{"op":"mcm","clk":"1362422624","pt":1588449734419,"mc":[{"id":"1.170370564","rc":[{"atl":[[1.28,215.46]],"id":8509691}],"con":true,"img":false}]}
{"op":"mcm","clk":"1362422625","pt":1588449734521,"mc":[{"id":"1.170370564","rc":[{"atl":[[1.3,205.56],[1.29,96.35]],"id":8509691}],"con":true,"img":false}]}
{"op":"mcm","clk":"1362422630","pt":1588449734928,"mc":[{"id":"1.170370564","rc":[{"atl":[[1.28,223.46]],"id":8509691}],"con":true,"img":false}]}
{"op":"mcm","clk":"1362422638","pt":1588449735741,"mc":[{"id":"1.170370564","rc":[{"trd":[[4.5,826.4]],"ltp":4.5,"tv":826.4,"id":9630572},{"trd":[[1.28,6399.38]],"ltp":1.28,"tv":6399.38,"id":8509691},{"atb":[[1.23,191.96]],"id":8509691},{"atl":[[1.28,47.68]],"id":8509691}],"con":true,"img":false}]}
{"op":"mcm","clk":"1362422640","pt":1588449735843,"mc":[{"id":"1.170370564","rc":[{"atl":[[1.29,0]],"id":8509691}],"con":true,"img":false}]}
{"op":"mcm","clk":"1362422649","pt":1588449736505,"mc":[{"id":"1.170370564","rc":[{"atl":[[1.38,0.49]],"id":8509691}],"con":true,"img":false}]}
{"op":"mcm","clk":"1362422655","pt":1588449737216,"mc":[{"id":"1.170370564","rc":[{"atb":[[1.25,0]],"id":8509691},{"atl":[[1.3,28.26]],"id":8509691}],"con":true,"img":false}]}
{"op":"mcm","clk":"1362422689","pt":1588449740629,"mc":[{"id":"1.170370564","rc":[{"atb":[[1.01,8553.29]],"id":8509691}],"con":true,"img":false}]}
{"op":"mcm","clk":"1362422694","pt":1588449741035,"mc":[{"id":"1.170370564","rc":[{"atl":[[1.27,97.87]],"id":8509691}],"con":true,"img":false}]}
{"op":"mcm","clk":"1362422696","pt":1588449741137,"mc":[{"id":"1.170370564","rc":[{"atb":[[1.23,0]],"id":8509691}],"con":true,"img":false}]}
{"op":"mcm","clk":"1362422701","pt":1588449741646,"mc":[{"id":"1.170370564","rc":[{"trd":[[1.27,4949.97]],"ltp":1.27,"tv":4949.97,"id":8509691},{"atl":[[1.27,87.87]],"id":8509691}],"con":true,"img":false}]}
{"op":"mcm","clk":"1362422704","pt":1588449741900,"mc":[{"id":"1.170370564","rc":[{"atl":[[1.4,1.74]],"id":8509691}],"con":true,"img":false}]}
{"op":"mcm","clk":"1362422712","pt":1588449742410,"mc":[{"id":"1.170370564","rc":[{"trd":[[1.28,6494.74],[1.27,5125.71]],"ltp":1.28,"tv":11620.45,"id":8509691},{"atb":[[1.29,644.45]],"id":8509691},{"atl":[[1.28,0],[1.27,0]],"id":8509691}],"con":true,"img":false}]}
{"op":"mcm","clk":"1362422733","pt":1588449744446,"mc":[{"id":"1.170370564","rc":[{"trd":[[1.29,22403.43]],"ltp":1.29,"tv":22403.43,"id":8509691},{"atb":[[1.29,600.45]],"id":8509691}],"con":true,"img":false}]}
{"op":"mcm","clk":"1362422797","pt":1588449751421,"mc":[{"id":"1.170370564","rc":[{"atb":[[4,50]],"id":9630572}],"con":true,"img":false}]}
{"op":"mcm","clk":"1362422828","pt":1588449754422,"mc":[{"id":"1.170370564","rc":[{"atb":[[1.24,61.59]],"id":8509691}],"con":true,"img":false}]}
{"op":"mcm","clk":"1362422831","pt":1588449754625,"mc":[{"id":"1.170370564","rc":[{"trd":[[1.29,22407.02]],"ltp":1.29,"tv":22407.02,"id":8509691},{"atb":[[1.29,598.66]],"id":8509691}],"con":true,"img":false}]}
{"op":"mcm","clk":"1362422839","pt":1588449755744,"mc":[{"id":"1.170370564","rc":[{"trd":[[1.29,22411.02]],"ltp":1.29,"tv":22411.02,"id":8509691},{"atb":[[1.29,596.66]],"id":8509691}],"con":true,"img":false}]}
{"op":"mcm","clk":"1362422849","pt":1588449756760,"mc":[{"id":"1.170370564","rc":[{"atb":[[1.27,2.57]],"id":8509691}],"con":true,"img":false}]}
{"op":"mcm","clk":"1362422852","pt":1588449756862,"mc":[{"id":"1.170370564","rc":[{"trd":[[1.29,22427.01]],"ltp":1.29,"tv":22427.01,"id":8509691},{"atb":[[1.29,588.66]],"id":8509691}],"con":true,"img":false}]}
{"op":"mcm","clk":"1362422867","pt":1588449758344,"mc":[{"id":"1.170370564","rc":[{"trd":[[1.29,22427.22]],"ltp":1.29,"tv":22427.22,"id":8509691},{"atb":[[1.29,588.56]],"id":8509691}],"con":true,"img":false}]}
{"op":"mcm","clk":"1362422870","pt":1588449758956,"mc":[{"id":"1.170370564","rc":[{"atl":[[1.3,27.74]],"id":8509691}],"con":true,"img":false}]}
{"op":"mcm","clk":"1362422880","pt":1588449759872,"mc":[{"id":"1.170370564","rc":[{"atl":[[1.4,16.32]],"id":8509691}],"con":true,"img":false}]}
{"op":"mcm","clk":"1362422893","pt":1588449761043,"mc":[{"id":"1.170370564","rc":[{"atb":[[1.01,8552.56]],"id":8509691}],"con":true,"img":false}]}
{"op":"mcm","clk":"1362422936","pt":1588449764867,"mc":[{"id":"1.170370564","rc":[{"trd":[[1.29,22525.24]],"ltp":1.29,"tv":22525.24,"id":8509691},{"atb":[[1.29,539.55]],"id":8509691}],"con":true,"img":false}]}
{"op":"mcm","clk":"1362422942","pt":1588449765477,"mc":[{"id":"1.170370564","rc":[{"trd":[[4.3,265.47]],"ltp":4.3,"tv":265.47,"id":9630572},{"trd":[[1.3,4747.03]],"ltp":1.3,"tv":4747.03,"id":8509691},{"atl":[[1.3,17.15]],"id":8509691}],"con":true,"img":false}]}
{"op":"mcm","clk":"1362422950","pt":1588449766138,"mc":[{"id":"1.170370564","rc":[{"trd":[[1.3,4748.48]],"ltp":1.3,"tv":4748.48,"id":8509691},{"atl":[[1.3,16.42]],"id":8509691}],"con":true,"img":false}]}
{"op":"mcm","clk":"1362422960","pt":1588449766959,"mc":[{"id":"1.170370564","rc":[{"trd":[[1.3,4758.48]],"ltp":1.3,"tv":4758.48,"id":8509691},{"atl":[[1.3,11.42]],"id":8509691}],"con":true,"img":false}]}
{"op":"mcm","clk":"1362422962","pt":1588449767061,"mc":[{"id":"1.170370564","rc":[{"atb":[[1.27,0]],"id":8509691}],"con":true,"img":false}]}
{"op":"mcm","clk":"1362422969","pt":1588449767570,"mc":[{"id":"1.170370564","rc":[{"atl":[[1.35,1.68]],"id":8509691}],"con":true,"img":false}]}
{"op":"mcm","clk":"1362422973","pt":1588449767977,"mc":[{"id":"1.170370564","rc":[{"trd":[[1.29,22541.24]],"ltp":1.29,"tv":22541.24,"id":8509691},{"atb":[[1.29,531.55]],"id":8509691}],"con":true,"img":false}]}
{"op":"mcm","clk":"1362422977","pt":1588449768385,"mc":[{"id":"1.170370564","rc":[{"trd":[[1.3,4781.34]],"ltp":1.3,"tv":4781.34,"id":8509691},{"atb":[[1.3,284.69]],"id":8509691},{"atl":[[1.3,0]],"id":8509691}],"con":true,"img":false}]}
{"op":"mcm","clk":"1362423003","pt":1588449770680,"mc":[{"id":"1.170370564","rc":[{"trd":[[1.3,5135.95]],"ltp":1.3,"tv":5135.95,"id":8509691},{"atb":[[1.3,107.38]],"id":8509691}],"con":true,"img":false}]}
{"op":"mcm","clk":"1362423033","pt":1588449773175,"mc":[{"id":"1.170370564","rc":[{"trd":[[4,13.33]],"ltp":4.0,"tv":13.33,"id":9630572},{"atb":[[4,49.39]],"id":9630572},{"trd":[[1.34,1.82]],"ltp":1.34,"tv":1.82,"id":8509691}],"con":true,"img":false}]}
{"op":"mcm","clk":"1362423035","pt":1588449773277,"mc":[{"id":"1.170370564","rc":[{"trd":[[1.29,22926.46],[1.3,5350.73]],"ltp":1.29,"tv":28277.19,"id":8509691},{"atb":[[1.3,0],[1.29,338.94]],"id":8509691}],"con":true,"img":false}]}
{"op":"mcm","clk":"1362423037","pt":1588449773584,"mc":[{"id":"1.170370564","rc":[{"trd":[[1.29,23526.46]],"ltp":1.29,"tv":23526.46,"id":8509691},{"atb":[[1.29,38.94]],"id":8509691}],"con":true,"img":false}]}
{"op":"mcm","clk":"1362423052","pt":1588449775058,"mc":[{"id":"1.170370564","rc":[{"trd":[[1.29,23604.34]],"ltp":1.29,"tv":23604.34,"id":8509691},{"atb":[[1.29,0]],"id":8509691},{"atl":[[1.28,261.06]],"id":8509691}],"con":true,"img":false}]}
{"op":"mcm","clk":"1362423099","pt":1588449779178,"mc":[{"id":"1.170370564","rc":[{"atl":[[1.28,0]],"id":8509691}],"con":true,"img":false}]}
{"op":"mcm","clk":"1362423119","pt":1588449781368,"mc":[{"id":"1.170370564","rc":[{"atb":[[1.25,177.3]],"id":8509691}],"con":true,"img":false}]}
{"op":"mcm","clk":"1362423121","pt":1588449781469,"mc":[{"id":"1.170370564","rc":[{"atl":[[1.26,41.35]],"id":8509691}],"con":true,"img":false}]}
{"op":"mcm","clk":"1362423132","pt":1588449782692,"mc":[{"id":"1.170370564","rc":[{"atb":[[1.25,179.3]],"id":8509691}],"con":true,"img":false}]}
{"op":"mcm","clk":"1362423135","pt":1588449782896,"mc":[{"id":"1.170370564","rc":[{"atb":[[1.23,300]],"id":8509691}],"con":true,"img":false}]}
{"op":"mcm","clk":"1362423144","pt":1588449783887,"mc":[{"id":"1.170370564","rc":[{"atb":[[1.25,2]],"id":8509691}],"con":true,"img":false}]}
{"op":"mcm","clk":"1362423170","pt":1588449786291,"mc":[{"id":"1.170370564","rc":[{"atl":[[1.3,4]],"id":8509691}],"con":true,"img":false}]}
{"op":"mcm","clk":"1362423178","pt":1588449787310,"mc":[{"id":"1.170370564","rc":[{"trd":[[1.24,2446.74],[1.25,3312.89]],"ltp":1.24,"tv":5759.62,"id":8509691},{"atb":[[1.25,0],[1.24,43.59]],"id":8509691}],"con":true,"img":false}]}
{"op":"mcm","clk":"1362423185","pt":1588449788126,"mc":[{"id":"1.170370564","rc":[{"trd":[[1.26,3297.1]],"ltp":1.26,"tv":3297.1,"id":8509691},{"atb":[[1.26,258.65]],"id":8509691},{"atl":[[1.26,0]],"id":8509691}],"con":true,"img":false}]}
{"op":"mcm","clk":"1362423186","pt":1588449788178,"mc":[{"id":"1.170370564","rc":[{"atb":[[1.26,435.95]],"id":8509691}],"con":true,"img":false}]}
{"op":"mcm","clk":"1362423198","pt":1588449789298,"mc":[{"id":"1.170370564","rc":[{"trd":[[1.26,3313.6]],"ltp":1.26,"tv":3313.6,"id":8509691},{"atb":[[1.26,427.7]],"id":8509691}],"con":true,"img":false}]}
{"op":"mcm","clk":"1362423218","pt":1588449791185,"mc":[{"id":"1.170370566","rc":[{"atb":[[1.05,0]],"id":8509691}],"con":true,"img":false}]}
{"op":"mcm","clk":"1362423230","pt":1588449792305,"mc":[{"id":"1.170370564","rc":[{"atl":[[1.38,0]],"id":8509691}],"con":true,"img":false}]}
{"op":"mcm","clk":"1362423231","pt":1588449792407,"mc":[{"id":"1.170370564","rc":[{"trd":[[1.26,3349.06]],"ltp":1.26,"tv":3349.06,"id":8509691},{"atb":[[1.26,409.97]],"id":8509691}],"con":true,"img":false}]}
{"op":"mcm","clk":"1362423251","pt":1588449793885,"mc":[{"id":"1.170370564","rc":[{"atl":[[1.29,11.99]],"id":8509691}],"con":true,"img":false}]}
{"op":"mcm","clk":"1362423255","pt":1588449794088,"mc":[{"id":"1.170370564","rc":[{"atl":[[4.8,10]],"id":9630572}],"con":true,"img":false}]}
{"op":"mcm","clk":"1362423272","pt":1588449796024,"mc":[{"id":"1.170370564","rc":[{"atl":[[1.29,0]],"id":8509691}],"con":true,"img":false}]}
{"op":"mcm","clk":"1362423276","pt":1588449796330,"mc":[{"id":"1.170370564","rc":[{"atl":[[1.31,2]],"id":8509691}],"con":true,"img":false}]}
{"op":"mcm","clk":"1362423294","pt":1588449798215,"mc":[{"id":"1.170370564","rc":[{"trd":[[1.26,3510.5]],"ltp":1.26,"tv":3510.5,"id":8509691},{"atb":[[1.26,329.25]],"id":8509691}],"con":true,"img":false}]}
{"op":"mcm","clk":"1362423307","pt":1588449799538,"mc":[{"id":"1.170370564","rc":[{"atb":[[1.01,8551.11]],"id":8509691}],"con":true,"img":false}]}
{"op":"mcm","clk":"1362423312","pt":1588449799894,"mc":[{"id":"1.170370564","rc":[{"trd":[[1.26,3528.24]],"ltp":1.26,"tv":3528.24,"id":8509691},{"atb":[[1.26,320.38]],"id":8509691}],"con":true,"img":false}]}
{"op":"mcm","clk":"1362423315","pt":1588449800099,"mc":[{"id":"1.170370564","rc":[{"atb":[[1.27,8.75]],"id":8509691}],"con":true,"img":false}]}
{"op":"mcm","clk":"1362423335","pt":1588449801531,"mc":[{"id":"1.170370564","rc":[{"atb":[[1.26,322.96]],"id":8509691}],"con":true,"img":false}]}
{"op":"mcm","clk":"1362423367","pt":1588449804444,"mc":[{"id":"1.170370564","rc":[{"atl":[[1.31,0]],"id":8509691}],"con":true,"img":false}]}
{"op":"mcm","clk":"1362423378","pt":1588449805618,"mc":[{"id":"1.170370564","rc":[{"atb":[[1.26,179.88],[1.23,0]],"id":8509691}],"con":true,"img":false}]}
{"op":"mcm","clk":"1362423385","pt":1588449806330,"mc":[{"id":"1.170370564","rc":[{"atl":[[1.29,2.57]],"id":8509691}],"con":true,"img":false}]}
{"op":"mcm","clk":"1362423389","pt":1588449806635,"mc":[{"id":"1.170370564","rc":[{"trd":[[1.29,23607.92]],"ltp":1.29,"tv":23607.92,"id":8509691},{"atl":[[1.29,0.78]],"id":8509691}],"con":true,"img":false}]}
{"op":"mcm","clk":"1362423397","pt":1588449807246,"mc":[{"id":"1.170370564","rc":[{"trd":[[1.3,5358.73],[1.29,23609.49]],"ltp":1.3,"tv":28968.22,"id":8509691},{"atb":[[1.3,0.21]],"id":8509691},{"atl":[[1.3,0],[1.29,0]],"id":8509691}],"con":true,"img":false}]}
{"op":"mcm","clk":"1362423444","pt":1588449811019,"mc":[{"id":"1.170370564","rc":[{"atl":[[1000,2]],"id":8509691}],"con":true,"img":false}]}
{"op":"mcm","clk":"1362423447","pt":1588449811121,"mc":[{"id":"1.170370564","rc":[{"atb":[[1.26,2.57]],"id":8509691}],"con":true,"img":false}]}
{"op":"mcm","clk":"1362423450","pt":1588449811324,"mc":[{"id":"1.170370564","rc":[{"trd":[[4.8,217.41]],"ltp":4.8,"tv":217.41,"id":9630572},{"atl":[[4.8,0]],"id":9630572},{"trd":[[1.26,3571.49],[1.27,5143.23],[1.3,5359.15]],"ltp":1.26,"tv":14073.86,"id":8509691},{"atb":[[1.26,0],[1.27,0],[1.3,0]],"id":8509691},{"atl":[[1.26,245.56]],"id":8509691}],"con":true,"img":false}]}
{"op":"mcm","clk":"1362423453","pt":1588449811630,"mc":[{"id":"1.170370564","rc":[{"atl":[[1000,1.97]],"id":8509691}],"con":true,"img":false},{"id":"1.170370566","rc":[{"atb":[[1.03,19]],"id":8509691}],"con":true,"img":false}]}
{"op":"mcm","clk":"1362423455","pt":1588449811732,"mc":[{"id":"1.170370564","rc":[{"atl":[[1.29,300]],"id":8509691}],"con":true,"img":false}]}
{"op":"mcm","clk":"1362423466","pt":1588449812751,"mc":[{"id":"1.170370564","rc":[{"atl":[[1.57,0]],"id":8509691}],"con":true,"img":false}]}
{"op":"mcm","clk":"1362423468","pt":1588449812853,"mc":[{"id":"1.170370564","rc":[{"atl":[[1.26,485.56],[1000,0]],"id":8509691}],"con":true,"img":false}]}
{"op":"mcm","clk":"1362423483","pt":1588449814229,"mc":[{"id":"1.170370564","rc":[{"trd":[[1.26,3571.63]],"ltp":1.26,"tv":3571.63,"id":8509691},{"atl":[[1.26,485.49]],"id":8509691}],"con":true,"img":false}]}
{"op":"mcm","clk":"1362423489","pt":1588449814636,"mc":[{"id":"1.170370564","rc":[{"atb":[[1.23,510.23]],"id":8509691}],"con":true,"img":false}]}
{"op":"mcm","clk":"1362423490","pt":1588449814839,"mc":[{"id":"1.170370564","rc":[{"atb":[[4.8,52.64]],"id":9630572},{"atl":[[1.26,240]],"id":8509691}],"con":true,"img":false}]}
{"op":"mcm","clk":"1362423493","pt":1588449815043,"mc":[{"id":"1.170370564","rc":[{"atb":[[4.8,0]],"id":9630572}],"con":true,"img":false}]}
{"op":"mcm","clk":"1362423497","pt":1588449815348,"mc":[{"id":"1.170370564","rc":[{"atb":[[1.23,0]],"id":8509691}],"con":true,"img":false}]}
{"op":"mcm","clk":"1362423512","pt":1588449816619,"mc":[{"id":"1.170370564","rc":[{"atb":[[1.25,50.04]],"id":8509691}],"con":true,"img":false}]}
{"op":"mcm","clk":"1362423523","pt":1588449817537,"mc":[{"id":"1.170370564","rc":[{"trd":[[1.24,2533.92],[1.25,3412.98]],"ltp":1.24,"tv":5946.9,"id":8509691},{"atb":[[1.25,0],[1.24,0]],"id":8509691},{"atl":[[1.24,146.37]],"id":8509691}],"con":true,"img":false}]}
{"op":"mcm","clk":"1362423528","pt":1588449817949,"mc":[{"id":"1.170370564","rc":[{"atl":[[1.27,1.97]],"id":8509691}],"con":true,"img":false}]}
{"op":"mcm","clk":"1362423536","pt":1588449818967,"mc":[{"id":"1.170370564","rc":[{"atl":[[1.24,0]],"id":8509691}],"con":true,"img":false},{"id":"1.170370566","rc":[{"atl":[[3.95,17.93]],"id":8509691}],"con":true,"img":false}]}
{"op":"mcm","clk":"1362423541","pt":1588449819324,"mc":[{"id":"1.170370564","rc":[{"atl":[[1.26,359.98]],"id":8509691}],"con":true,"img":false}]}
{"op":"mcm","clk":"1362423544","pt":1588449819526,"mc":[{"id":"1.170370564","rc":[{"atb":[[1.01,8552.88]],"id":8509691}],"con":true,"img":false}]}
{"op":"mcm","clk":"1362423547","pt":1588449819933,"mc":[{"id":"1.170370564","rc":[{"atb":[[1.01,8551.18]],"id":8509691}],"con":true,"img":false}]}
{"op":"mcm","clk":"1362423551","pt":1588449820239,"mc":[{"id":"1.170370564","rc":[{"atb":[[1.01,8551.11]],"id":8509691}],"con":true,"img":false}]}
{"op":"mcm","clk":"1362423554","pt":1588449820543,"mc":[{"id":"1.170370564","rc":[{"trd":[[1.26,3660.28]],"ltp":1.26,"tv":3660.28,"id":8509691},{"atl":[[1.26,315.65]],"id":8509691}],"con":true,"img":false}]}
{"op":"mcm","clk":"1362423559","pt":1588449820849,"mc":[{"id":"1.170370564","rc":[{"atl":[[1.27,19.46],[1.24,11.99]],"id":8509691}],"con":true,"img":false}]}
{"op":"mcm","clk":"1362423560","pt":1588449820951,"mc":[{"id":"1.170370565","rc":[{"atb":[[1.3,0]],"id":11269555}],"con":true,"img":false}]}
{"op":"mcm","clk":"1362423564","pt":1588449821460,"mc":[{"id":"1.170370564","rc":[{"atl":[[1.26,195.67]],"id":8509691}],"con":true,"img":false}]}
{"op":"mcm","clk":"1362423571","pt":1588449821969,"mc":[{"id":"1.170370564","rc":[{"trd":[[1.24,2533.94]],"ltp":1.24,"tv":2533.94,"id":8509691},{"atl":[[1.26,0],[1.24,11.99]],"id":8509691}],"con":true,"img":false}]}
{"op":"mcm","clk":"1362423582","pt":1588449823037,"mc":[{"id":"1.170370564","rc":[{"atl":[[1.23,11.99]],"id":8509691}],"con":true,"img":false}]}
{"op":"mcm","clk":"1362423596","pt":1588449824054,"mc":[{"id":"1.170370564","rc":[{"trd":[[1.23,426.48]],"ltp":1.23,"tv":426.48,"id":8509691},{"atl":[[1.23,9.42],[1.24,23.98]],"id":8509691}],"con":true,"img":false}]}
{"op":"mcm","clk":"1362423613","pt":1588449825377,"mc":[{"id":"1.170370564","rc":[{"trd":[[1.23,426.62]],"ltp":1.23,"tv":426.62,"id":8509691},{"atl":[[1.23,9.35]],"id":8509691}],"con":true,"img":false}]}
{"op":"mcm","clk":"1362423621","pt":1588449826040,"mc":[{"id":"1.170370565","rc":[{"atb":[[1.2,11.99]],"id":11269555}],"con":true,"img":false}]}
{"op":"mcm","clk":"1362423629","pt":1588449826955,"mc":[{"id":"1.170370564","rc":[{"trd":[[5.6,1.52]],"ltp":5.6,"tv":1.52,"id":9630572},{"atb":[[5.6,8.97]],"id":9630572},{"trd":[[1.22,1229.08]],"ltp":1.22,"tv":1229.08,"id":8509691},{"atb":[[1.22,0]],"id":8509691},{"atl":[[1.24,11.99]],"id":8509691}],"con":true,"img":false}]}
{"op":"mcm","clk":"1362423632","pt":1588449827362,"mc":[{"id":"1.170370564","rc":[{"atl":[[1.35,43.78]],"id":8509691}],"con":true,"img":false}]}
{"op":"mcm","clk":"1362423637","pt":1588449827566,"mc":[{"id":"1.170370564","rc":[{"trd":[[5.6,10.49]],"ltp":5.6,"tv":10.49,"id":9630572},{"atb":[[5.6,0]],"id":9630572},{"trd":[[1.22,1270.26]],"ltp":1.22,"tv":1270.26,"id":8509691},{"atb":[[1.22,108.82]],"id":8509691}],"con":true,"img":false}]}
{"op":"mcm","clk":"1362423655","pt":1588449829457,"mc":[{"id":"1.170370564","rc":[{"trd":[[1.22,1358.91]],"ltp":1.22,"tv":1358.91,"id":8509691},{"atb":[[1.22,64.49]],"id":8509691}],"con":true,"img":false}]}
{"op":"mcm","clk":"1362423660","pt":1588449829864,"mc":[{"id":"1.170370564","rc":[{"atb":[[1.18,159.44]],"id":8509691}],"con":true,"img":false}]}
{"op":"mcm","clk":"1362423661","pt":1588449829966,"mc":[{"id":"1.170370564","rc":[{"trd":[[1.22,1447.57]],"ltp":1.22,"tv":1447.57,"id":8509691},{"atb":[[1.22,20.16]],"id":8509691}],"con":true,"img":false}]}
{"op":"mcm","clk":"1362423668","pt":1588449830783,"mc":[{"id":"1.170370564","rc":[{"atb":[[2.9,100]],"id":9630572}],"con":true,"img":false}]}
{"op":"mcm","clk":"1362423673","pt":1588449831396,"mc":[{"id":"1.170370564","rc":[{"trd":[[1.23,445.32],[1.2,1076.37],[1.21,3195.87],[1.22,1487.89]],"ltp":1.23,"tv":6205.45,"id":8509691},{"atb":[[1.2,6.83],[1.21,0],[1.23,140.65],[1.22,0]],"id":8509691},{"atl":[[1.23,0]],"id":8509691}],"con":true,"img":false}]}
{"op":"mcm","clk":"1362423684","pt":1588449832264,"mc":[{"id":"1.170370564","rc":[{"trd":[[1.23,533.98]],"ltp":1.23,"tv":533.98,"id":8509691},{"atb":[[1.23,96.32]],"id":8509691},{"atl":[[1.41,8]],"id":8509691}],"con":true,"img":false}]}
{"op":"mcm","clk":"1362423686","pt":1588449832366,"mc":[{"id":"1.170370564","rc":[{"trd":[[1.23,544.74]],"ltp":1.23,"tv":544.74,"id":8509691},{"atb":[[1.23,90.94]],"id":8509691}],"con":true,"img":false}]}
{"op":"mcm","clk":"1362423690","pt":1588449832673,"mc":[{"id":"1.170370564","rc":[{"atb":[[1.23,0]],"id":8509691}],"con":true,"img":false}]}
{"op":"mcm","clk":"1362423712","pt":1588449835681,"mc":[{"id":"1.170370564","rc":[{"trd":[[1.18,988.8],[1.2,1090.03]],"ltp":1.18,"tv":2078.83,"id":8509691},{"atb":[[1.2,0],[1.18,131.51]],"id":8509691}],"con":true,"img":false}]}
{"op":"mcm","clk":"1362423714","pt":1588449835884,"mc":[{"id":"1.170370566","rc":[{"atb":[[1.35,79.98]],"id":9630572}],"con":true,"img":false}]}
{"op":"mcm","clk":"1362423718","pt":1588449836395,"mc":[{"id":"1.170370564","rc":[{"atl":[[5.3,20]],"id":9630572}],"con":true,"img":false}]}
{"op":"mcm","clk":"1362423732","pt":1588449837670,"mc":[{"id":"1.170370566","rc":[{"atl":[[4,0]],"id":8509691}],"con":true,"img":false}]}
{"op":"mcm","clk":"1362423744","pt":1588449838894,"mc":[{"id":"1.170370564","rc":[{"trd":[[5.3,10.29]],"ltp":5.3,"tv":10.29,"id":9630572},{"atl":[[5.3,9.71]],"id":9630572},{"trd":[[1.23,589.06]],"ltp":1.23,"tv":589.06,"id":8509691}],"con":true,"img":false}]}
{"op":"mcm","clk":"1362423746","pt":1588449839096,"mc":[{"id":"1.170370564","rc":[{"atb":[[1.23,3.5]],"id":8509691}],"con":true,"img":false}]}
{"op":"mcm","clk":"1362423790","pt":1588449841603,"mc":[{"id":"1.170370564","rc":[{"atb":[[1.22,7]],"id":8509691}],"con":true,"img":false}]}
{"op":"mcm","clk":"1362423798","pt":1588449842167,"mc":[{"id":"1.170370564","rc":[{"atl":[[5.6,4]],"id":9630572}],"con":true,"img":false}]}
{"op":"mcm","clk":"1362423800","pt":1588449842372,"mc":[{"id":"1.170370564","rc":[{"atb":[[1.19,44.32]],"id":8509691}],"con":true,"img":false}]}
{"op":"mcm","clk":"1362423805","pt":1588449842782,"mc":[{"id":"1.170370566","rc":[{"atl":[[3.85,8.86]],"id":8509691}],"con":true,"img":false}]}
{"op":"mcm","clk":"1362423809","pt":1588449842989,"mc":[{"id":"1.170370564","rc":[{"atb":[[1.19,88.65]],"id":8509691}],"con":true,"img":false}]}
{"op":"mcm","clk":"1362423811","pt":1588449843091,"mc":[{"id":"1.170370564","rc":[{"atb":[[1.23,0]],"id":8509691}],"con":true,"img":false}]}
{"op":"mcm","clk":"1362423815","pt":1588449843502,"mc":[{"id":"1.170370564","rc":[{"atl":[[5.3,0]],"id":9630572}],"con":true,"img":false}]}
{"op":"mcm","clk":"1362423822","pt":1588449844117,"mc":[{"id":"1.170370564","rc":[{"atl":[[1.23,200]],"id":8509691}],"con":true,"img":false}]}
{"op":"mcm","clk":"1362423824","pt":1588449844168,"mc":[{"id":"1.170370564","rc":[{"atl":[[1.29,0]],"id":8509691}],"con":true,"img":false}]}
{"op":"mcm","clk":"1362423836","pt":1588449845294,"mc":[{"id":"1.170370564","rc":[{"trd":[[5.6,13.69]],"ltp":5.6,"tv":13.69,"id":9630572},{"atl":[[5.6,0.8]],"id":9630572},{"trd":[[1.21,3210.7],[1.22,1501.9]],"ltp":1.21,"tv":4712.6,"id":8509691},{"atb":[[1.22,0]],"id":8509691},{"atl":[[1.22,37.32]],"id":8509691}],"con":true,"img":false}]}
{"op":"mcm","clk":"1362423839","pt":1588449845396,"mc":[{"id":"1.170370564","rc":[{"trd":[[5.6,14.49]],"ltp":5.6,"tv":14.49,"id":9630572},{"atl":[[5.6,0]],"id":9630572},{"trd":[[1.19,768.8],[1.21,3214.4]],"ltp":1.19,"tv":3983.19,"id":8509691},{"atb":[[1.19,84.71]],"id":8509691}],"con":true,"img":false}]}
{"op":"mcm","clk":"1362423847","pt":1588449845907,"mc":[{"id":"1.170370564","rc":[{"atl":[[1.23,214.39]],"id":8509691}],"con":true,"img":false}]}
{"op":"mcm","clk":"1362423850","pt":1588449846008,"mc":[{"id":"1.170370564","rc":[{"atl":[[1.23,238.39]],"id":8509691}],"con":true,"img":false}]}
{"op":"mcm","clk":"1362423856","pt":1588449846517,"mc":[{"id":"1.170370564","rc":[{"trd":[[1.23,614.42],[1.22,1576.54]],"ltp":1.23,"tv":2190.96,"id":8509691},{"atl":[[1.23,225.71],[1.22,0]],"id":8509691}],"con":true,"img":false}]}
{"op":"mcm","clk":"1362423864","pt":1588449846978,"mc":[{"id":"1.170370564","rc":[{"atb":[[1.01,8560.86]],"id":8509691}],"con":true,"img":false}]}
{"op":"mcm","clk":"1362423885","pt":1588449848405,"mc":[{"id":"1.170370564","rc":[{"atb":[[1.21,44.32]],"id":8509691}],"con":true,"img":false}]}
{"op":"mcm","clk":"1362423887","pt":1588449848608,"mc":[{"id":"1.170370564","rc":[{"trd":[[1.23,614.98]],"ltp":1.23,"tv":614.98,"id":8509691},{"atl":[[1.23,225.43]],"id":8509691}],"con":true,"img":false}]}
{"op":"mcm","clk":"1362423889","pt":1588449848710,"mc":[{"id":"1.170370564","rc":[{"trd":[[1.24,2557.92],[1.23,1065.86]],"ltp":1.24,"tv":3623.77,"id":8509691},{"atb":[[1.25,2.57]],"id":8509691},{"atl":[[1.23,0],[1.24,0]],"id":8509691}],"con":true,"img":false}]}
{"op":"mcm","clk":"1362423893","pt":1588449848914,"mc":[{"id":"1.170370564","rc":[{"atb":[[1.21,88.65]],"id":8509691}],"con":true,"img":false}]}
{"op":"mcm","clk":"1362423902","pt":1588449849645,"mc":[{"id":"1.170370564","rc":[{"trd":[[1.27,5187.31],[1.25,3413.12]],"ltp":1.27,"tv":8600.43,"id":8509691},{"atb":[[1.27,127.96],[1.25,2.5]],"id":8509691},{"atl":[[1.27,0]],"id":8509691}],"con":true,"img":false}]}
{"op":"mcm","clk":"1362423906","pt":1588449849900,"mc":[{"id":"1.170370564","rc":[{"atb":[[1.27,277.96]],"id":8509691}],"con":true,"img":false}]}
{"op":"mcm","clk":"1362423908","pt":1588449850002,"mc":[{"id":"1.170370564","rc":[{"atb":[[1.18,0],[1.25,0]],"id":8509691}],"con":true,"img":false}]}
{"op":"mcm","clk":"1362423913","pt":1588449850613,"mc":[{"id":"1.170370564","rc":[{"atb":[[1.24,150]],"id":8509691}],"con":true,"img":false}]}
{"op":"mcm","clk":"1362423917","pt":1588449851021,"mc":[{"id":"1.170370564","rc":[{"atb":[[1.24,300]],"id":8509691}],"con":true,"img":false}]}
{"op":"mcm","clk":"1362423924","pt":1588449851631,"mc":[{"id":"1.170370564","rc":[{"trd":[[1.27,5189.67]],"ltp":1.27,"tv":5189.67,"id":8509691},{"atb":[[1.27,276.78]],"id":8509691}],"con":true,"img":false}]}
{"op":"mcm","clk":"1362423927","pt":1588449851886,"mc":[{"id":"1.170370566","rc":[{"atb":[[1.03,0]],"id":8509691}],"con":true,"img":false}]}
{"op":"mcm","clk":"1362423930","pt":1588449852090,"mc":[{"id":"1.170370564","rc":[{"trd":[[1.27,5196.76]],"ltp":1.27,"tv":5196.76,"id":8509691},{"atb":[[1.27,273.23]],"id":8509691}],"con":true,"img":false}]}
{"op":"mcm","clk":"1362423935","pt":1588449852600,"mc":[{"id":"1.170370564","rc":[{"atb":[[1.15,10]],"id":8509691}],"con":true,"img":false}]}
{"op":"mcm","clk":"1362423941","pt":1588449853110,"mc":[{"id":"1.170370566","rc":[{"atb":[[1.35,0]],"id":9630572}],"con":true,"img":false}]}
{"op":"mcm","clk":"1362423948","pt":1588449853825,"mc":[{"id":"1.170370564","rc":[{"atb":[[1.2,295.21]],"id":8509691}],"con":true,"img":false}]}
{"op":"mcm","clk":"1362423957","pt":1588449854690,"mc":[{"id":"1.170370564","rc":[{"atb":[[1.22,3.5]],"id":8509691}],"con":true,"img":false}]}
{"op":"mcm","clk":"1362423962","pt":1588449854996,"mc":[{"id":"1.170370564","rc":[{"atb":[[1.23,44.32]],"id":8509691}],"con":true,"img":false}]}
{"op":"mcm","clk":"1362423968","pt":1588449855606,"mc":[{"id":"1.170370564","rc":[{"atb":[[1.24,344.32]],"id":8509691}],"con":true,"img":false}]}
{"op":"mcm","clk":"1362423974","pt":1588449856115,"mc":[{"id":"1.170370564","rc":[{"atb":[[1.2,0]],"id":8509691},{"atl":[[1.32,103.84]],"id":8509691}],"con":true,"img":false}]}
{"op":"mcm","clk":"1362423977","pt":1588449856419,"mc":[{"id":"1.170370564","rc":[{"atl":[[1.33,150]],"id":8509691}],"con":true,"img":false}]}
{"op":"mcm","clk":"1362423984","pt":1588449857032,"mc":[{"id":"1.170370564","rc":[{"atl":[[1.33,300]],"id":8509691}],"con":true,"img":false}]}
{"op":"mcm","clk":"1362424007","pt":1588449859121,"mc":[{"id":"1.170370566","rc":[{"atl":[[3.95,0]],"id":8509691}],"con":true,"img":false}]}
{"op":"mcm","clk":"1362424011","pt":1588449859325,"mc":[{"id":"1.170370564","rc":[{"trd":[[1.32,1019.48]],"ltp":1.32,"tv":1019.48,"id":8509691},{"atl":[[1.32,103.73]],"id":8509691}],"con":true,"img":false}]}
{"op":"mcm","clk":"1362424017","pt":1588449859732,"mc":[{"id":"1.170370564","rc":[{"trd":[[1.27,5197.13]],"ltp":1.27,"tv":5197.13,"id":8509691},{"atb":[[1.27,273.05]],"id":8509691}],"con":true,"img":false}]}
{"op":"mcm","clk":"1362424019","pt":1588449859834,"mc":[{"id":"1.170370564","rc":[{"atb":[[1.25,177.3]],"id":8509691}],"con":true,"img":false}]}
{"op":"mcm","clk":"1362424027","pt":1588449860700,"mc":[{"id":"1.170370564","rc":[{"atb":[[1.22,0]],"id":8509691}],"con":true,"img":false}]}
{"op":"mcm","clk":"1362424036","pt":1588449861310,"mc":[{"id":"1.170370565","rc":[{"atb":[[1.2,0]],"id":11269555}],"con":true,"img":false}]}
{"op":"mcm","clk":"1362424038","pt":1588449861412,"mc":[{"id":"1.170370564","rc":[{"trd":[[1.27,5229.13]],"ltp":1.27,"tv":5229.13,"id":8509691},{"atb":[[1.27,257.05]],"id":8509691}],"con":true,"img":false}]}
{"op":"mcm","clk":"1362424051","pt":1588449862432,"mc":[{"id":"1.170370564","rc":[{"atb":[[1.23,0]],"id":8509691}],"con":true,"img":false}]}
{"op":"mcm","clk":"1362424053","pt":1588449862534,"mc":[{"id":"1.170370564","rc":[{"trd":[[1.27,5233.13]],"ltp":1.27,"tv":5233.13,"id":8509691},{"atb":[[1.27,255.05]],"id":8509691}],"con":true,"img":false}]}
{"op":"mcm","clk":"1362424056","pt":1588449862738,"mc":[{"id":"1.170370564","rc":[{"atb":[[1.24,44.32]],"id":8509691}],"con":true,"img":false}]}
{"op":"mcm","clk":"1362424062","pt":1588449863044,"mc":[{"id":"1.170370564","rc":[{"atb":[[1.24,0]],"id":8509691}],"con":true,"img":false}]}
{"op":"mcm","clk":"1362424066","pt":1588449863451,"mc":[{"id":"1.170370564","rc":[{"atb":[[1.11,495.83]],"id":8509691}],"con":true,"img":false}]}
{"op":"mcm","clk":"1362424071","pt":1588449863809,"mc":[{"id":"1.170370564","rc":[{"atb":[[1.21,0]],"id":8509691}],"con":true,"img":false}]}
{"op":"mcm","clk":"1362424073","pt":1588449864013,"mc":[{"id":"1.170370564","rc":[{"atb":[[1.12,295.21]],"id":8509691}],"con":true,"img":false}]}
{"op":"mcm","clk":"1362424076","pt":1588449864216,"mc":[{"id":"1.170370566","rc":[{"atl":[[3.8,17.93]],"id":8509691}],"con":true,"img":false}]}
{"op":"mcm","clk":"1362424080","pt":1588449864726,"mc":[{"id":"1.170370564","rc":[{"atb":[[1.26,177.3]],"id":8509691}],"con":true,"img":false}]}
{"op":"mcm","clk":"1362424086","pt":1588449865440,"mc":[{"id":"1.170370564","rc":[{"atb":[[1.26,0],[1.19,0],[1.25,0]],"id":8509691}],"con":true,"img":false}]}
{"op":"mcm","clk":"1362424089","pt":1588449865642,"mc":[{"id":"1.170370564","rc":[{"atl":[[1.31,2]],"id":8509691}],"con":true,"img":false}]}
{"op":"mcm","clk":"1362424100","pt":1588449866457,"mc":[{"id":"1.170370565","rc":[{"atb":[[1.32,11.99]],"id":11269555}],"con":true,"img":false}]}
{"op":"mcm","clk":"1362424146","pt":1588449871655,"mc":[{"id":"1.170370564","rc":[{"atb":[[1.28,177.3]],"id":8509691}],"con":true,"img":false}]}
{"op":"mcm","clk":"1362424149","pt":1588449871860,"mc":[{"id":"1.170370564","rc":[{"trd":[[4.1,243.78],[4.2,88.47]],"ltp":4.1,"tv":332.25,"id":9630572},{"atl":[[4.1,65.98]],"id":9630572},{"trd":[[1.32,1123.21],[1.31,733.42]],"ltp":1.32,"tv":1856.63,"id":8509691},{"atl":[[1.32,0],[1.31,0]],"id":8509691}],"con":true,"img":false}]}
{"op":"mcm","clk":"1362424162","pt":1588449873036,"mc":[{"id":"1.170370564","rc":[{"atl":[[1.33,0]],"id":8509691}],"con":true,"img":false}]}
{"op":"mcm","clk":"1362424215","pt":1588449878235,"mc":[{"id":"1.170370566","rc":[{"atl":[[3.85,0]],"id":8509691}],"con":true,"img":false}]}
{"op":"mcm","clk":"1362424226","pt":1588449879254,"mc":[{"id":"1.170370564","rc":[{"trd":[[4.1,244.92]],"ltp":4.1,"tv":244.92,"id":9630572},{"atl":[[4.1,64.84]],"id":9630572},{"trd":[[1.32,1126.75]],"ltp":1.32,"tv":1126.75,"id":8509691}],"con":true,"img":false}]}
{"op":"mcm","clk":"1362424236","pt":1588449880477,"mc":[{"id":"1.170370564","rc":[{"trd":[[4,13.36]],"ltp":4.0,"tv":13.36,"id":9630572},{"atb":[[4,49.36]],"id":9630572},{"trd":[[1.34,1.91]],"ltp":1.34,"tv":1.91,"id":8509691}],"con":true,"img":false}]}
{"op":"mcm","clk":"1362424260","pt":1588449883332,"mc":[{"id":"1.170370566","rc":[{"atl":[[3.75,8.86]],"id":8509691}],"con":true,"img":false}]}
{"op":"mcm","clk":"1362424265","pt":1588449883740,"mc":[{"id":"1.170370564","rc":[{"atl":[[1.35,42.36]],"id":8509691}],"con":true,"img":false}]}
{"op":"mcm","clk":"1362424281","pt":1588449885166,"mc":[{"id":"1.170370564","rc":[{"atb":[[1.2,2]],"id":8509691}],"con":true,"img":false}]}
{"op":"mcm","clk":"1362424358","pt":1588449891078,"mc":[{"id":"1.170370566","rc":[{"atl":[[3.8,0]],"id":8509691}],"con":true,"img":false}]}
{"op":"mcm","clk":"1362424361","pt":1588449891180,"mc":[{"id":"1.170370564","rc":[{"trd":[[4.1,245.38]],"ltp":4.1,"tv":245.38,"id":9630572},{"atl":[[4.1,64.38]],"id":9630572},{"trd":[[1.32,1128.17]],"ltp":1.32,"tv":1128.17,"id":8509691}],"con":true,"img":false}]}
{"op":"mcm","clk":"1362424401","pt":1588449893890,"mc":[{"id":"1.170370564","rc":[{"trd":[[4.1,277.06]],"ltp":4.1,"tv":277.06,"id":9630572},{"atl":[[4.1,32.7]],"id":9630572},{"trd":[[1.32,1226.58]],"ltp":1.32,"tv":1226.58,"id":8509691}],"con":true,"img":false}]}
{"op":"mcm","clk":"1362424437","pt":1588449895375,"mc":[{"id":"1.170370564","rc":[{"trd":[[4.1,285.11]],"ltp":4.1,"tv":285.11,"id":9630572},{"atl":[[4.1,24.65]],"id":9630572},{"trd":[[1.32,1251.58]],"ltp":1.32,"tv":1251.58,"id":8509691}],"con":true,"img":false}]}
{"op":"mcm","clk":"1362424454","pt":1588449896193,"mc":[{"id":"1.170370566","rc":[{"atl":[[3.7,17.93]],"id":8509691}],"con":true,"img":false}]}
{"op":"mcm","clk":"1362424466","pt":1588449896958,"mc":[{"id":"1.170370564","rc":[{"trd":[[4.1,285.88]],"ltp":4.1,"tv":285.88,"id":9630572},{"atl":[[4.1,23.88]],"id":9630572},{"trd":[[1.32,1253.98]],"ltp":1.32,"tv":1253.98,"id":8509691}],"con":true,"img":false}]}
{"op":"mcm","clk":"1362424478","pt":1588449897876,"mc":[{"id":"1.170370564","rc":[{"trd":[[4.1,286.52]],"ltp":4.1,"tv":286.52,"id":9630572},{"atl":[[4.1,23.24]],"id":9630572},{"trd":[[1.32,1255.98]],"ltp":1.32,"tv":1255.98,"id":8509691}],"con":true,"img":false}]}
{"op":"mcm","clk":"1362424495","pt":1588449899673,"mc":[{"id":"1.170370564","rc":[{"trd":[[4.1,286.72]],"ltp":4.1,"tv":286.72,"id":9630572},{"atl":[[4.1,23.14]],"id":9630572}],"con":true,"img":false}]}
{"op":"mcm","clk":"1362424512","pt":1588449901503,"mc":[{"id":"1.170370564","rc":[{"atl":[[1.44,2]],"id":8509691}],"con":true,"img":false}]}
{"op":"mcm","clk":"1362424537","pt":1588449903499,"mc":[{"id":"1.170370564","rc":[{"trd":[[4.1,287.55]],"ltp":4.1,"tv":287.55,"id":9630572},{"atl":[[4.1,22.31]],"id":9630572},{"trd":[[1.32,1258.55]],"ltp":1.32,"tv":1258.55,"id":8509691}],"con":true,"img":false}]}
{"op":"mcm","clk":"1362424574","pt":1588449905805,"mc":[{"id":"1.170370564","rc":[{"atb":[[1.27,0]],"id":8509691}],"con":true,"img":false}]}
{"op":"mcm","clk":"1362424595","pt":1588449907692,"mc":[{"id":"1.170370564","rc":[{"atb":[[1.28,0]],"id":8509691}],"con":true,"img":false}]}
{"op":"mcm","clk":"1362424626","pt":1588449910088,"mc":[{"id":"1.170370564","rc":[{"trd":[[4.1,309.86]],"ltp":4.1,"tv":309.86,"id":9630572},{"atl":[[4.1,0]],"id":9630572},{"trd":[[1.32,1327.85]],"ltp":1.32,"tv":1327.85,"id":8509691},{"atl":[[1.28,225.91]],"id":8509691}],"con":true,"img":false}]}
{"op":"mcm","clk":"1362424638","pt":1588449911004,"mc":[{"id":"1.170370564","rc":[{"atl":[[1.28,425.91]],"id":8509691}],"con":true,"img":false}]}
{"op":"mcm","clk":"1362424682","pt":1588449913808,"mc":[{"id":"1.170370564","rc":[{"atl":[[1.29,240]],"id":8509691}],"con":true,"img":false}]}
{"op":"mcm","clk":"1362424685","pt":1588449914011,"mc":[{"id":"1.170370564","rc":[{"atl":[[1.25,147.16]],"id":8509691}],"con":true,"img":false}]}
{"op":"mcm","clk":"1362424694","pt":1588449914724,"mc":[{"id":"1.170370564","rc":[{"atb":[[4.1,64.52]],"id":9630572}],"con":true,"img":false}]}
{"op":"mcm","clk":"1362424697","pt":1588449914929,"mc":[{"id":"1.170370564","rc":[{"atb":[[4.1,0]],"id":9630572}],"con":true,"img":false}]}
{"op":"mcm","clk":"1362424702","pt":1588449915286,"mc":[{"id":"1.170370564","rc":[{"trd":[[1.25,3552.82]],"ltp":1.25,"tv":3552.82,"id":8509691},{"atl":[[1.25,77.31]],"id":8509691}],"con":true,"img":false}]}
{"op":"mcm","clk":"1362424706","pt":1588449915799,"mc":[{"id":"1.170370564","rc":[{"trd":[[5,15.47]],"ltp":5.0,"tv":15.47,"id":9630572},{"trd":[[1.25,3578.82]],"ltp":1.25,"tv":3578.82,"id":8509691},{"atl":[[1.25,51.31]],"id":8509691}],"con":true,"img":false}]}
{"op":"mcm","clk":"1362424718","pt":1588449916613,"mc":[{"id":"1.170370564","rc":[{"atl":[[1.26,240]],"id":8509691}],"con":true,"img":false}]}
{"op":"mcm","clk":"1362424721","pt":1588449916919,"mc":[{"id":"1.170370564","rc":[{"atl":[[1.25,0]],"id":8509691}],"con":true,"img":false}]}
{"op":"mcm","clk":"1362424729","pt":1588449917632,"mc":[{"id":"1.170370564","rc":[{"atl":[[1.29,0]],"id":8509691}],"con":true,"img":false}]}
{"op":"mcm","clk":"1362424738","pt":1588449918193,"mc":[{"id":"1.170370564","rc":[{"atb":[[1.18,200]],"id":8509691}],"con":true,"img":false}]}
{"op":"mcm","clk":"1362424744","pt":1588449918805,"mc":[{"id":"1.170370564","rc":[{"atl":[[1.32,11.75]],"id":8509691}],"con":true,"img":false},{"id":"1.170370566","rc":[{"trd":[[1.02,60.28]],"ltp":1.02,"tv":60.28,"id":8509691},{"atb":[[1.02,58.72]],"id":8509691}],"con":true,"img":false}]}
{"op":"mcm","clk":"1362424747","pt":1588449918906,"mc":[{"id":"1.170370564","rc":[{"atb":[[1.22,2.57]],"id":8509691}],"con":true,"img":false}]}
{"op":"mcm","clk":"1362424771","pt":1588449921099,"mc":[{"id":"1.170370566","rc":[{"atl":[[3.75,0]],"id":8509691}],"con":true,"img":false}]}
{"op":"mcm","clk":"1362424774","pt":1588449921303,"mc":[{"id":"1.170370564","rc":[{"atl":[[1.28,200]],"id":8509691}],"con":true,"img":false}]}
{"op":"mcm","clk":"1362424779","pt":1588449921609,"mc":[{"id":"1.170370564","rc":[{"atl":[[1.24,132.97]],"id":8509691}],"con":true,"img":false}]}
{"op":"mcm","clk":"1362424794","pt":1588449923036,"mc":[{"id":"1.170370564","rc":[{"atl":[[1.44,0]],"id":8509691}],"con":true,"img":false}]}
{"op":"mcm","clk":"1362424804","pt":1588449923698,"mc":[{"id":"1.170370564","rc":[{"atb":[[1.22,100.82]],"id":8509691}],"con":true,"img":false}]}
{"op":"mcm","clk":"1362424809","pt":1588449924719,"mc":[{"id":"1.170370564","rc":[{"atl":[[1.26,0]],"id":8509691}],"con":true,"img":false}]}
{"op":"mcm","clk":"1362424835","pt":1588449926502,"mc":[{"id":"1.170370564","rc":[{"atl":[[1.28,0]],"id":8509691}],"con":true,"img":false}]}
{"op":"mcm","clk":"1362424841","pt":1588449926910,"mc":[{"id":"1.170370564","rc":[{"trd":[[5.6,21.49]],"ltp":5.6,"tv":21.49,"id":9630572},{"trd":[[1.22,1608.67]],"ltp":1.22,"tv":1608.67,"id":8509691},{"atb":[[1.22,68.69]],"id":8509691}],"con":true,"img":false}]}
{"op":"mcm","clk":"1362424842","pt":1588449927013,"mc":[{"id":"1.170370564","rc":[{"trd":[[1.24,2558.27]],"ltp":1.24,"tv":2558.27,"id":8509691},{"atl":[[1.24,132.8]],"id":8509691}],"con":true,"img":false}]}
{"op":"mcm","clk":"1362424848","pt":1588449927627,"mc":[{"id":"1.170370565","rc":[{"atb":[[1.32,0]],"id":11269555}],"con":true,"img":false}]}
{"op":"mcm","clk":"1362424851","pt":1588449927728,"mc":[{"id":"1.170370564","rc":[{"atb":[[1.21,177.3]],"id":8509691}],"con":true,"img":false}]}
{"op":"mcm","clk":"1362424859","pt":1588449928339,"mc":[{"id":"1.170370564","rc":[{"atb":[[1.21,0]],"id":8509691}],"con":true,"img":false}]}
{"op":"mcm","clk":"1362424864","pt":1588449928746,"mc":[{"id":"1.170370564","rc":[{"trd":[[1.22,1618.67]],"ltp":1.22,"tv":1618.67,"id":8509691},{"atb":[[1.22,63.69]],"id":8509691}],"con":true,"img":false}]}
{"op":"mcm","clk":"1362424877","pt":1588449930123,"mc":[{"id":"1.170370564","rc":[{"atb":[[1.2,10.79]],"id":8509691}],"con":true,"img":false}]}
{"op":"mcm","clk":"1362424890","pt":1588449931040,"mc":[{"id":"1.170370564","rc":[{"atl":[[1.32,0]],"id":8509691}],"con":true,"img":false}]}
{"op":"mcm","clk":"1362424918","pt":1588449932723,"mc":[{"id":"1.170370565","rc":[{"atb":[[1.22,11.99]],"id":11269555}],"con":true,"img":false}]}
{"op":"mcm","clk":"1362424941","pt":1588449934253,"mc":[{"id":"1.170370564","rc":[{"trd":[[1.22,1677.18]],"ltp":1.22,"tv":1677.18,"id":8509691},{"atb":[[1.22,34.44]],"id":8509691}],"con":true,"img":false}]}
{"op":"mcm","clk":"1362424991","pt":1588449937054,"mc":[{"id":"1.170370566","rc":[{"atb":[[1.02,0]],"id":8509691}],"con":true,"img":false}]}
{"op":"mcm","clk":"1362424994","pt":1588449937156,"mc":[{"id":"1.170370564","rc":[{"trd":[[1.22,1678.87]],"ltp":1.22,"tv":1678.87,"id":8509691},{"atb":[[1.22,33.59]],"id":8509691}],"con":true,"img":false}]}
{"op":"mcm","clk":"1362425002","pt":1588449937565,"mc":[{"id":"1.170370566","rc":[{"atb":[[1.01,0]],"id":8509691}],"con":true,"img":false}]}
{"op":"mcm","clk":"1362425006","pt":1588449937820,"mc":[{"id":"1.170370564","rc":[{"atl":[[1.24,0]],"id":8509691}],"con":true,"img":false}]}
{"op":"mcm","clk":"1362425025","pt":1588449938941,"mc":[{"id":"1.170370564","rc":[{"trd":[[1.22,1685.88]],"ltp":1.22,"tv":1685.88,"id":8509691},{"atb":[[1.22,30.08]],"id":8509691}],"con":true,"img":false}]}
{"op":"mcm","clk":"1362425035","pt":1588449939857,"mc":[{"id":"1.170370564","rc":[{"trd":[[1.22,1705.38]],"ltp":1.22,"tv":1705.38,"id":8509691},{"atb":[[1.22,20.33]],"id":8509691}],"con":true,"img":false}]}
{"op":"mcm","clk":"1362425069","pt":1588449942965,"mc":[{"id":"1.170370564","rc":[{"atl":[[1.28,132.8]],"id":8509691}],"con":true,"img":false}]}
{"op":"mcm","clk":"1362425090","pt":1588449945668,"mc":[{"id":"1.170370564","rc":[{"trd":[[1.22,1706.42]],"ltp":1.22,"tv":1706.42,"id":8509691},{"atb":[[1.22,19.81]],"id":8509691}],"con":true,"img":false}]}
{"op":"mcm","clk":"1362425102","pt":1588449947247,"mc":[{"id":"1.170370564","rc":[{"atb":[[1.17,17.75]],"id":8509691}],"con":true,"img":false}]}
{"op":"mcm","clk":"1362425117","pt":1588449948470,"mc":[{"id":"1.170370564","rc":[{"atl":[[1.31,240]],"id":8509691}],"con":true,"img":false}]}
{"op":"mcm","clk":"1362425126","pt":1588449949438,"mc":[{"id":"1.170370564","rc":[{"trd":[[1.22,1746.05]],"ltp":1.22,"tv":1746.05,"id":8509691},{"atb":[[1.22,0]],"id":8509691},{"atl":[[1.22,20.19]],"id":8509691}],"con":true,"img":false}]}
{"op":"mcm","clk":"1362425131","pt":1588449950050,"mc":[{"id":"1.170370564","rc":[{"atl":[[1.27,240]],"id":8509691}],"con":true,"img":false}]}
{"op":"mcm","clk":"1362425177","pt":1588449954954,"mc":[{"id":"1.170370566","rc":[{"atb":[[1.4,79.98]],"id":9630572}],"con":true,"img":false}]}
{"op":"mcm","clk":"1362425187","pt":1588449956077,"mc":[{"id":"1.170370564","rc":[{"trd":[[1.22,1786.43]],"ltp":1.22,"tv":1786.43,"id":8509691},{"atb":[[1.23,21.81]],"id":8509691},{"atl":[[1.22,0]],"id":8509691}],"con":true,"img":false}]}
{"op":"mcm","clk":"1362425201","pt":1588449957096,"mc":[{"id":"1.170370564","rc":[{"atb":[[1.2,2]],"id":8509691}],"con":true,"img":false}]}
{"op":"mcm","clk":"1362425243","pt":1588449961382,"mc":[{"id":"1.170370564","rc":[{"atl":[[1.25,76]],"id":8509691}],"con":true,"img":false}]}
{"op":"mcm","clk":"1362425247","pt":1588449961586,"mc":[{"id":"1.170370564","rc":[{"trd":[[1.23,1100.89]],"ltp":1.23,"tv":1100.89,"id":8509691},{"atb":[[1.23,4.29]],"id":8509691}],"con":true,"img":false}]}
{"op":"mcm","clk":"1362425253","pt":1588449961994,"mc":[{"id":"1.170370565","rc":[{"atb":[[2.08,42.11]],"id":11340557}],"con":true,"img":false}]}
{"op":"mcm","clk":"1362425255","pt":1588449962198,"mc":[{"id":"1.170370564","rc":[{"atb":[[1.19,8.79]],"id":8509691},{"atl":[[1.28,0]],"id":8509691}],"con":true,"img":false}]}
{"op":"mcm","clk":"1362425285","pt":1588449964963,"mc":[{"id":"1.170370564","rc":[{"atl":[[1.27,0],[1.31,0]],"id":8509691}],"con":true,"img":false}]}
{"op":"mcm","clk":"1362425319","pt":1588449967773,"mc":[{"id":"1.170370564","rc":[{"atb":[[1.17,0]],"id":8509691}],"con":true,"img":false}]}
{"op":"mcm","clk":"1362425334","pt":1588449969299,"mc":[{"id":"1.170370566","rc":[{"atl":[[3.7,0]],"id":8509691}],"con":true,"img":false}]}
{"op":"mcm","clk":"1362425347","pt":1588449971082,"mc":[{"id":"1.170370564","rc":[{"trd":[[1.25,3730.82]],"ltp":1.25,"tv":3730.82,"id":8509691},{"atb":[[1.25,49]],"id":8509691},{"atl":[[1.25,0]],"id":8509691}],"con":true,"img":false}]}
{"op":"mcm","clk":"1362425360","pt":1588449971794,"mc":[{"id":"1.170370564","rc":[{"atb":[[1.25,174]],"id":8509691}],"con":true,"img":false}]}
{"op":"mcm","clk":"1362425370","pt":1588449972506,"mc":[{"id":"1.170370564","rc":[{"atb":[[1.25,0]],"id":8509691}],"con":true,"img":false}]}
{"op":"mcm","clk":"1362425378","pt":1588449972914,"mc":[{"id":"1.170370564","rc":[{"atb":[[1.16,17.75]],"id":8509691}],"con":true,"img":false}]}
{"op":"mcm","clk":"1362425382","pt":1588449973220,"mc":[{"id":"1.170370564","rc":[{"atb":[[1.27,3.35]],"id":8509691}],"con":true,"img":false}]}
{"op":"mcm","clk":"1362425396","pt":1588449974493,"mc":[{"id":"1.170370566","rc":[{"atl":[[3.45,17.93]],"id":8509691}],"con":true,"img":false}]}
{"op":"mcm","clk":"1362425403","pt":1588449975409,"mc":[{"id":"1.170370564","rc":[{"atl":[[1.33,125]],"id":8509691}],"con":true,"img":false}]}
{"op":"mcm","clk":"1362425408","pt":1588449975816,"mc":[{"id":"1.170370564","rc":[{"atl":[[1.33,250]],"id":8509691}],"con":true,"img":false}]}
{"op":"mcm","clk":"1362425422","pt":1588449976784,"mc":[{"id":"1.170370564","rc":[{"atb":[[1.25,3.54]],"id":8509691}],"con":true,"img":false}]}
{"op":"mcm","clk":"1362425435","pt":1588449978108,"mc":[{"id":"1.170370564","rc":[{"atl":[[1.3,2.84]],"id":8509691}],"con":true,"img":false}]}
{"op":"mcm","clk":"1362425441","pt":1588449978619,"mc":[{"id":"1.170370564","rc":[{"atb":[[1.25,0]],"id":8509691}],"con":true,"img":false}]}
{"op":"mcm","clk":"1362425443","pt":1588449978720,"mc":[{"id":"1.170370564","rc":[{"atl":[[1.32,125]],"id":8509691}],"con":true,"img":false}]}
{"op":"mcm","clk":"1362425447","pt":1588449979025,"mc":[{"id":"1.170370564","rc":[{"atl":[[1.32,250]],"id":8509691}],"con":true,"img":false}]}
{"op":"mcm","clk":"1362425491","pt":1588449983510,"mc":[{"id":"1.170370564","rc":[{"trd":[[1.27,5239.85]],"ltp":1.27,"tv":5239.85,"id":8509691},{"atb":[[1.27,0]],"id":8509691},{"atl":[[1.25,8.39]],"id":8509691}],"con":true,"img":false}]}
{"op":"mcm","clk":"1362425494","pt":1588449983816,"mc":[{"id":"1.170370564","rc":[{"trd":[[1.25,3747.61]],"ltp":1.25,"tv":3747.61,"id":8509691},{"atb":[[1.25,168.9]],"id":8509691},{"atl":[[1.25,0]],"id":8509691}],"con":true,"img":false}]}
{"op":"mcm","clk":"1362425502","pt":1588449984734,"mc":[{"id":"1.170370564","rc":[{"atb":[[1.15,12.26]],"id":8509691}],"con":true,"img":false},{"id":"1.170370566","rc":[{"atb":[[1.4,0]],"id":9630572}],"con":true,"img":false}]}
{"op":"mcm","clk":"1362425511","pt":1588449985296,"mc":[{"id":"1.170370566","rc":[{"atb":[[2,88.65]],"id":9630572}],"con":true,"img":false}]}
{"op":"mcm","clk":"1362425516","pt":1588449985908,"mc":[{"id":"1.170370564","rc":[{"atb":[[1.21,177.3]],"id":8509691}],"con":true,"img":false}]}
{"op":"mcm","clk":"1362425522","pt":1588449986621,"mc":[{"id":"1.170370564","rc":[{"atb":[[1.21,0]],"id":8509691}],"con":true,"img":false}]}
{"op":"mcm","clk":"1362425529","pt":1588449987233,"mc":[{"id":"1.170370564","rc":[{"atl":[[1.27,8.86]],"id":8509691}],"con":true,"img":false}]}
{"op":"mcm","clk":"1362425535","pt":1588449987692,"mc":[{"id":"1.170370564","rc":[{"atb":[[1.18,0]],"id":8509691},{"atl":[[1.33,0],[1.32,0]],"id":8509691}],"con":true,"img":false}]}
{"op":"mcm","clk":"1362425543","pt":1588449988517,"mc":[{"id":"1.170370566","rc":[{"atb":[[1.01,88.65]],"id":8509691}],"con":true,"img":false}]}
{"op":"mcm","clk":"1362425544","pt":1588449988714,"mc":[{"id":"1.170370564","rc":[{"trd":[[1.25,3885.18]],"ltp":1.25,"tv":3885.18,"id":8509691},{"atb":[[1.25,100.12]],"id":8509691}],"con":true,"img":false}]}
{"op":"mcm","clk":"1362425548","pt":1588449989223,"mc":[{"id":"1.170370564","rc":[{"atl":[[1.27,0]],"id":8509691}],"con":true,"img":false}]}
{"op":"mcm","clk":"1362425554","pt":1588449989835,"mc":[{"id":"1.170370566","rc":[{"atb":[[1.41,79.98]],"id":9630572}],"con":true,"img":false}]}
{"op":"mcm","clk":"1362425561","pt":1588449990396,"mc":[{"id":"1.170370564","rc":[{"atb":[[1.25,0]],"id":8509691}],"con":true,"img":false}]}
{"op":"mcm","clk":"1362425567","pt":1588449991007,"mc":[{"id":"1.170370564","rc":[{"atl":[[1.3,0]],"id":8509691}],"con":true,"img":false}]}
{"op":"mcm","clk":"1362425577","pt":1588449992432,"mc":[{"id":"1.170370564","rc":[{"atl":[[1.27,22]],"id":8509691}],"con":true,"img":false}]}
{"op":"mcm","clk":"1362425589","pt":1588449993908,"mc":[{"id":"1.170370564","rc":[{"atl":[[1.25,200]],"id":8509691}],"con":true,"img":false}]}
{"op":"mcm","clk":"1362425600","pt":1588449994925,"mc":[{"id":"1.170370567","rc":[{"atl":[[1.65,2.62]],"id":8509691}],"con":true,"img":false}]}
{"op":"mcm","clk":"1362425615","pt":1588449996046,"mc":[{"id":"1.170370564","rc":[{"atb":[[1.14,192.86]],"id":8509691}],"con":true,"img":false}]}
{"op":"mcm","clk":"1362425628","pt":1588449997217,"mc":[{"id":"1.170370567","rc":[{"atb":[[1.07,0]],"id":8509691}],"con":true,"img":false}]}
{"op":"mcm","clk":"1362425644","pt":1588449998235,"mc":[{"id":"1.170370567","rc":[{"atl":[[1.65,0]],"id":8509691}],"con":true,"img":false}]}
{"op":"mcm","clk":"1362425652","pt":1588449999048,"mc":[{"id":"1.170370565","rc":[{"atb":[[1.5,106.38]],"id":11340560}],"con":true,"img":false}]}
{"op":"mcm","clk":"1362425658","pt":1588449999609,"mc":[{"id":"1.170370564","rc":[{"atl":[[1.27,0]],"id":8509691}],"con":true,"img":false}]}
{"op":"mcm","clk":"1362425684","pt":1588450001342,"mc":[{"id":"1.170370564","rc":[{"atl":[[1.25,0]],"id":8509691}],"con":true,"img":false}]}
{"op":"mcm","clk":"1362425696","pt":1588450002311,"mc":[{"id":"1.170370567","rc":[{"atb":[[1.01,800.67]],"id":8509691}],"con":true,"img":false}]}
{"op":"mcm","clk":"1362425718","pt":1588450004454,"mc":[{"id":"1.170370564","rc":[{"atl":[[1.32,0.1]],"id":8509691}],"con":true,"img":false}]}
{"op":"mcm","clk":"1362425733","pt":1588450005422,"mc":[{"id":"1.170370564","rc":[{"atb":[[1.25,1.42]],"id":8509691}],"con":true,"img":false}]}
{"op":"mcm","clk":"1362425737","pt":1588450005728,"mc":[{"id":"1.170370564","rc":[{"atb":[[1.26,44.32],[1.25,3.9]],"id":8509691}],"con":true,"img":false}]}
{"op":"mcm","clk":"1362425790","pt":1588450010365,"mc":[{"id":"1.170370564","rc":[{"trd":[[4,15.5]],"ltp":4.0,"tv":15.5,"id":9630572},{"atb":[[4,47.22]],"id":9630572},{"trd":[[1.34,8.29],[1.32,1328.06]],"ltp":1.34,"tv":1336.35,"id":8509691},{"atl":[[1.32,0]],"id":8509691}],"con":true,"img":false}]}
{"op":"mcm","clk":"1362425792","pt":1588450010567,"mc":[{"id":"1.170370564","rc":[{"atb":[[1.15,10]],"id":8509691}],"con":true,"img":false}]}
{"op":"mcm","clk":"1362425824","pt":1588450013932,"mc":[{"id":"1.170370564","rc":[{"atb":[[1.25,1.42]],"id":8509691}],"con":true,"img":false},{"id":"1.170370567","rc":[{"atb":[[1.12,2.62]],"id":8509691}],"con":true,"img":false}]}
{"op":"mcm","clk":"1362425856","pt":1588450016430,"mc":[{"id":"1.170370564","rc":[{"trd":[[4,62.72]],"ltp":4.0,"tv":62.72,"id":9630572},{"atb":[[4,0]],"id":9630572},{"trd":[[1.34,149.25]],"ltp":1.34,"tv":149.25,"id":8509691},{"atb":[[1.28,240],[1.34,34.04]],"id":8509691}],"con":true,"img":false}]}
{"op":"mcm","clk":"1362425865","pt":1588450016939,"mc":[{"id":"1.170370564","rc":[{"atb":[[1.26,284.32]],"id":8509691}],"con":true,"img":false},{"id":"1.170370566","rc":[{"atb":[[1.06,902.8]],"id":8509691}],"con":true,"img":false}]}
{"op":"mcm","clk":"1362425872","pt":1588450017754,"mc":[{"id":"1.170370564","rc":[{"trd":[[1.35,598.64]],"ltp":1.35,"tv":598.64,"id":8509691},{"atb":[[1.35,132.63]],"id":8509691},{"atl":[[1.35,0]],"id":8509691}],"con":true,"img":false}]}
{"op":"mcm","clk":"1362425875","pt":1588450018059,"mc":[{"id":"1.170370566","rc":[{"atl":[[3.45,0]],"id":8509691}],"con":true,"img":false}]}
{"op":"mcm","clk":"1362425877","pt":1588450018161,"mc":[{"id":"1.170370564","rc":[{"atb":[[1.31,98.67]],"id":8509691}],"con":true,"img":false}]}
{"op":"mcm","clk":"1362425884","pt":1588450018772,"mc":[{"id":"1.170370564","rc":[{"atb":[[1.26,240]],"id":8509691}],"con":true,"img":false}]}
{"op":"mcm","clk":"1362425888","pt":1588450018976,"mc":[{"id":"1.170370564","rc":[{"atb":[[1.29,196.8]],"id":8509691}],"con":true,"img":false}]}
{"op":"mcm","clk":"1362425890","pt":1588450019079,"mc":[{"id":"1.170370564","rc":[{"atb":[[1.2,4.48]],"id":8509691}],"con":true,"img":false}]}
{"op":"mcm","clk":"1362425892","pt":1588450019130,"mc":[{"id":"1.170370564","rc":[{"atb":[[1.14,0],[1.34,0],[1.35,0]],"id":8509691}],"con":true,"img":false}]}
{"op":"mcm","clk":"1362425923","pt":1588450022443,"mc":[{"id":"1.170370564","rc":[{"trd":[[1.31,735.18]],"ltp":1.31,"tv":735.18,"id":8509691},{"atb":[[1.31,97.79]],"id":8509691}],"con":true,"img":false}]}
{"op":"mcm","clk":"1362425927","pt":1588450023054,"mc":[{"id":"1.170370564","rc":[{"atb":[[1.29,0]],"id":8509691}],"con":true,"img":false}]}
{"op":"mcm","clk":"1362425929","pt":1588450023258,"mc":[{"id":"1.170370566","rc":[{"atl":[[3.4,17.93]],"id":8509691}],"con":true,"img":false}]}
{"op":"mcm","clk":"1362425931","pt":1588450023463,"mc":[{"id":"1.170370564","rc":[{"atb":[[1.28,0]],"id":8509691}],"con":true,"img":false}]}
{"op":"mcm","clk":"1362425937","pt":1588450023872,"mc":[{"id":"1.170370564","rc":[{"atl":[[1000,2.91]],"id":8509691}],"con":true,"img":false}]}
{"op":"mcm","clk":"1362425946","pt":1588450024387,"mc":[{"id":"1.170370564","rc":[{"atl":[[1.39,2]],"id":8509691}],"con":true,"img":false}]}
{"op":"mcm","clk":"1362425952","pt":1588450024745,"mc":[{"id":"1.170370564","rc":[{"atl":[[1000,0.33]],"id":8509691}],"con":true,"img":false}]}
{"op":"mcm","clk":"1362425960","pt":1588450025155,"mc":[{"id":"1.170370564","rc":[{"atl":[[1.38,19.01]],"id":8509691}],"con":true,"img":false}]}
{"op":"mcm","clk":"1362425965","pt":1588450025464,"mc":[{"id":"1.170370566","rc":[{"atb":[[1.41,0]],"id":9630572}],"con":true,"img":false}]}
{"op":"mcm","clk":"1362425968","pt":1588450025672,"mc":[{"id":"1.170370564","rc":[{"atl":[[1000,0]],"id":8509691}],"con":true,"img":false}]}
{"op":"mcm","clk":"1362425974","pt":1588450026080,"mc":[{"id":"1.170370565","rc":[{"atb":[[2.08,0]],"id":11340557}],"con":true,"img":false}]}
{"op":"mcm","clk":"1362425982","pt":1588450026487,"mc":[{"id":"1.170370564","rc":[{"atb":[[1.32,240]],"id":8509691}],"con":true,"img":false}]}
{"op":"mcm","clk":"1362426000","pt":1588450027665,"mc":[{"id":"1.170370564","rc":[{"trd":[[1.32,1383.4]],"ltp":1.32,"tv":1383.4,"id":8509691},{"atb":[[1.32,212.33]],"id":8509691}],"con":true,"img":false}]}
{"op":"mcm","clk":"1362426005","pt":1588450028176,"mc":[{"id":"1.170370564","rc":[{"trd":[[1.38,5.64]],"ltp":1.38,"tv":5.64,"id":8509691},{"atl":[[1.38,16.19]],"id":8509691}],"con":true,"img":false}]}
{"op":"mcm","clk":"1362426010","pt":1588450028483,"mc":[{"id":"1.170370564","rc":[{"trd":[[1.38,5.74]],"ltp":1.38,"tv":5.74,"id":8509691},{"atl":[[1.38,16.14]],"id":8509691}],"con":true,"img":false}]}
{"op":"mcm","clk":"1362426017","pt":1588450029196,"mc":[{"id":"1.170370564","rc":[{"atb":[[1.23,0]],"id":8509691}],"con":true,"img":false}]}
{"op":"mcm","clk":"1362426030","pt":1588450030062,"mc":[{"id":"1.170370566","rc":[{"atl":[[3.4,0]],"id":8509691}],"con":true,"img":false}]}
{"op":"mcm","clk":"1362426038","pt":1588450030776,"mc":[{"id":"1.170370564","rc":[{"atl":[[1.34,0.33]],"id":8509691}],"con":true,"img":false}]}
{"op":"mcm","clk":"1362426060","pt":1588450032662,"mc":[{"id":"1.170370564","rc":[{"atl":[[1.39,0]],"id":8509691}],"con":true,"img":false}]}
{"op":"mcm","clk":"1362426069","pt":1588450033071,"mc":[{"id":"1.170370564","rc":[{"atb":[[1.31,0]],"id":8509691}],"con":true,"img":false}]}
{"op":"mcm","clk":"1362426077","pt":1588450033580,"mc":[{"id":"1.170370564","rc":[{"atl":[[1.36,8.86]],"id":8509691}],"con":true,"img":false}]}
{"op":"mcm","clk":"1362426084","pt":1588450034292,"mc":[{"id":"1.170370564","rc":[{"trd":[[1.36,37.82],[1.34,149.92]],"ltp":1.36,"tv":187.73,"id":8509691},{"atl":[[1.34,0],[1.36,4.65]],"id":8509691}],"con":true,"img":false}]}
{"op":"mcm","clk":"1362426085","pt":1588450034393,"mc":[{"id":"1.170370564","rc":[{"atb":[[1.26,0],[1.32,0]],"id":8509691},{"atl":[[1.37,26.66]],"id":8509691}],"con":true,"img":false}]}
{"op":"mcm","clk":"1362426090","pt":1588450034800,"mc":[{"id":"1.170370566","rc":[{"atb":[[1.01,0]],"id":8509691}],"con":true,"img":false}]}
{"op":"mcm","clk":"1362426093","pt":1588450034903,"mc":[{"id":"1.170370564","rc":[{"atb":[[1.2,2.48]],"id":8509691}],"con":true,"img":false}]}
{"op":"mcm","clk":"1362426099","pt":1588450035361,"mc":[{"id":"1.170370564","rc":[{"atb":[[1.35,98.4]],"id":8509691}],"con":true,"img":false}]}
{"op":"mcm","clk":"1362426101","pt":1588450035565,"mc":[{"id":"1.170370567","rc":[{"atb":[[1.12,0]],"id":9630572}],"con":true,"img":false}]}
{"op":"mcm","clk":"1362426102","pt":1588450035667,"mc":[{"id":"1.170370564","rc":[{"trd":[[1.35,602.64]],"ltp":1.35,"tv":602.64,"id":8509691},{"atb":[[1.35,96.4]],"id":8509691}],"con":true,"img":false}]}
{"op":"mcm","clk":"1362426109","pt":1588450036074,"mc":[{"id":"1.170370564","rc":[{"trd":[[1.36,38.97]],"ltp":1.36,"tv":38.97,"id":8509691},{"atl":[[1.36,4.07]],"id":8509691}],"con":true,"img":false}]}
{"op":"mcm","clk":"1362426137","pt":1588450037957,"mc":[{"id":"1.170370564","rc":[{"atb":[[1.34,177.3]],"id":8509691}],"con":true,"img":false}]}
{"op":"mcm","clk":"1362426138","pt":1588450038059,"mc":[{"id":"1.170370564","rc":[{"trd":[[1.35,603.21]],"ltp":1.35,"tv":603.21,"id":8509691},{"atb":[[1.35,96.11]],"id":8509691}],"con":true,"img":false}]}
{"op":"mcm","clk":"1362426142","pt":1588450038466,"mc":[{"id":"1.170370564","rc":[{"atb":[[1.35,273.42]],"id":8509691}],"con":true,"img":false}]}
{"op":"mcm","clk":"1362426147","pt":1588450038771,"mc":[{"id":"1.170370564","rc":[{"atb":[[1.34,0]],"id":8509691}],"con":true,"img":false}]}
{"op":"mcm","clk":"1362426156","pt":1588450039484,"mc":[{"id":"1.170370564","rc":[{"atb":[[1.35,96.11]],"id":8509691}],"con":true,"img":false}]}
{"op":"mcm","clk":"1362426160","pt":1588450039999,"mc":[{"id":"1.170370564","rc":[{"trd":[[1.36,47.13]],"ltp":1.36,"tv":47.13,"id":8509691},{"atb":[[1.36,173.22],[1.3,2]],"id":8509691},{"atl":[[1.36,0]],"id":8509691}],"con":true,"img":false}]}
{"op":"mcm","clk":"1362426167","pt":1588450040711,"mc":[{"id":"1.170370566","rc":[{"atb":[[2,0]],"id":9630572},{"atb":[[1.07,88.65]],"id":8509691}],"con":true,"img":false},{"id":"1.170370567","rc":[{"atb":[[1.13,523.11]],"id":9630572}],"con":true,"img":false}]}
{"op":"mcm","clk":"1362426179","pt":1588450041881,"mc":[{"id":"1.170370564","rc":[{"atb":[[1.26,240]],"id":8509691}],"con":true,"img":false}]}
{"op":"mcm","clk":"1362426189","pt":1588450042697,"mc":[{"id":"1.170370564","rc":[{"trd":[[1.37,62.59]],"ltp":1.37,"tv":62.59,"id":8509691},{"atb":[[1.2,242.48],[1.37,150.64]],"id":8509691},{"atl":[[1.37,0]],"id":8509691}],"con":true,"img":false}]}
{"op":"mcm","clk":"1362426201","pt":1588450043716,"mc":[{"id":"1.170370564","rc":[{"atb":[[1.36,0]],"id":8509691}],"con":true,"img":false}]}
{"op":"mcm","clk":"1362426211","pt":1588450044378,"mc":[{"id":"1.170370564","rc":[{"trd":[[3.75,3.52]],"ltp":3.75,"tv":3.52,"id":9630572},{"trd":[[1.37,72.25]],"ltp":1.37,"tv":72.25,"id":8509691},{"atb":[[1.37,140.99]],"id":8509691}],"con":true,"img":false}]}
{"op":"mcm","clk":"1362426214","pt":1588450044684,"mc":[{"id":"1.170370564","rc":[{"atb":[[1.35,0]],"id":8509691}],"con":true,"img":false}]}
{"op":"mcm","clk":"1362426233","pt":1588450046312,"mc":[{"id":"1.170370564","rc":[{"trd":[[1.38,6]],"ltp":1.38,"tv":6.0,"id":8509691},{"atl":[[1.38,16.01]],"id":8509691}],"con":true,"img":false}]}
{"op":"mcm","clk":"1362426234","pt":1588450046414,"mc":[{"id":"1.170370566","rc":[{"atb":[[1.06,0]],"id":8509691}],"con":true,"img":false}]}
{"op":"mcm","clk":"1362426241","pt":1588450046975,"mc":[{"id":"1.170370564","rc":[{"atb":[[1.24,5.06]],"id":8509691}],"con":true,"img":false}]}
{"op":"mcm","clk":"1362426250","pt":1588450047484,"mc":[{"id":"1.170370564","rc":[{"trd":[[1.38,38.02],[1.37,78.38]],"ltp":1.38,"tv":116.4,"id":8509691},{"atb":[[1.37,137.92],[1.38,161.29]],"id":8509691},{"atl":[[1.38,0]],"id":8509691}],"con":true,"img":false}]}
{"op":"mcm","clk":"1362426254","pt":1588450047688,"mc":[{"id":"1.170370564","rc":[{"atb":[[1.25,0]],"id":8509691}],"con":true,"img":false}]}
{"op":"mcm","clk":"1362426256","pt":1588450047790,"mc":[{"id":"1.170370564","rc":[{"trd":[[3.65,60.98]],"ltp":3.65,"tv":60.98,"id":9630572},{"atb":[[3.65,39.02]],"id":9630572},{"trd":[[1.38,199.31]],"ltp":1.38,"tv":199.31,"id":8509691},{"atb":[[1.38,0]],"id":8509691}],"con":true,"img":false}]}
{"op":"mcm","clk":"1362426259","pt":1588450047994,"mc":[{"id":"1.170370564","rc":[{"trd":[[3.75,3.63]],"ltp":3.75,"tv":3.63,"id":9630572},{"trd":[[1.37,78.66]],"ltp":1.37,"tv":78.66,"id":8509691},{"atb":[[1.37,137.64]],"id":8509691}],"con":true,"img":false}]}
{"op":"mcm","clk":"1362426268","pt":1588450048505,"mc":[{"id":"1.170370564","rc":[{"atb":[[1.37,0]],"id":8509691}],"con":true,"img":false}]}
{"op":"mcm","clk":"1362426280","pt":1588450049778,"mc":[{"id":"1.170370564","rc":[{"trd":[[3.65,97.32]],"ltp":3.65,"tv":97.32,"id":9630572},{"atb":[[3.65,2.68]],"id":9630572},{"trd":[[1.38,295.43]],"ltp":1.38,"tv":295.43,"id":8509691}],"con":true,"img":false}]}
{"op":"mcm","clk":"1362426286","pt":1588450050288,"mc":[{"id":"1.170370564","rc":[{"atl":[[1.35,23]],"id":8509691}],"con":true,"img":false}]}
{"op":"mcm","clk":"1362426314","pt":1588450052480,"mc":[{"id":"1.170370564","rc":[{"atb":[[1.01,467.99]],"id":9630572}],"con":true,"img":false}]}
{"op":"mcm","clk":"1362426320","pt":1588450053093,"mc":[{"id":"1.170370564","rc":[{"atb":[[1.01,464.94]],"id":9630572}],"con":true,"img":false},{"id":"1.170370566","rc":[{"atb":[[1.07,0]],"id":8509691}],"con":true,"img":false}]}
{"op":"mcm","clk":"1362426326","pt":1588450053807,"mc":[{"id":"1.170370564","rc":[{"atb":[[1.01,464.79]],"id":9630572}],"con":true,"img":false}]}
{"op":"mcm","clk":"1362426349","pt":1588450055183,"mc":[{"id":"1.170370564","rc":[{"atl":[[1.37,11.81]],"id":8509691}],"con":true,"img":false}]}
{"op":"mcm","clk":"1362426372","pt":1588450057119,"mc":[{"id":"1.170370564","rc":[{"trd":[[1.35,606.99]],"ltp":1.35,"tv":606.99,"id":8509691},{"atl":[[1.35,21.11]],"id":8509691}],"con":true,"img":false}]}
{"op":"mcm","clk":"1362426380","pt":1588450058187,"mc":[{"id":"1.170370566","rc":[{"atb":[[1.01,79.98]],"id":8509691}],"con":true,"img":false}]}
{"op":"mcm","clk":"1362426391","pt":1588450058899,"mc":[{"id":"1.170370564","rc":[{"atb":[[3.75,0.14]],"id":9630572}],"con":true,"img":false}]}
{"op":"mcm","clk":"1362426397","pt":1588450059103,"mc":[{"id":"1.170370564","rc":[{"atb":[[3.75,0]],"id":9630572}],"con":true,"img":false}]}
{"op":"mcm","clk":"1362426411","pt":1588450060732,"mc":[{"id":"1.170370566","rc":[{"atb":[[1.01,168.63]],"id":9630572}],"con":true,"img":false}]}
{"op":"mcm","clk":"1362426413","pt":1588450060834,"mc":[{"id":"1.170370566","rc":[{"atb":[[1.02,88.65]],"id":8509691}],"con":true,"img":false}]}
{"op":"mcm","clk":"1362426417","pt":1588450061037,"mc":[{"id":"1.170370564","rc":[{"atl":[[1.37,10.75]],"id":8509691}],"con":true,"img":false}]}
{"op":"mcm","clk":"1362426446","pt":1588450063735,"mc":[{"id":"1.170370564","rc":[{"atb":[[1.3,4.5]],"id":8509691}],"con":true,"img":false}]}
{"op":"mcm","clk":"1362426461","pt":1588450065008,"mc":[{"id":"1.170370564","rc":[{"trd":[[1.35,626.99]],"ltp":1.35,"tv":626.99,"id":8509691},{"atl":[[1.35,11.11]],"id":8509691}],"con":true,"img":false}]}
{"op":"mcm","clk":"1362426463","pt":1588450065110,"mc":[{"id":"1.170370564","rc":[{"atb":[[1.01,467.99]],"id":9630572}],"con":true,"img":false}]}
{"op":"mcm","clk":"1362426470","pt":1588450065726,"mc":[{"id":"1.170370564","rc":[{"atb":[[1.01,464.91]],"id":9630572}],"con":true,"img":false}]}
{"op":"mcm","clk":"1362426477","pt":1588450066337,"mc":[{"id":"1.170370564","rc":[{"atb":[[1.01,464.79]],"id":9630572}],"con":true,"img":false}]}
{"op":"mcm","clk":"1362426481","pt":1588450066745,"mc":[{"id":"1.170370564","rc":[{"atl":[[1.37,12.75]],"id":8509691}],"con":true,"img":false}]}
{"op":"mcm","clk":"1362426494","pt":1588450067815,"mc":[{"id":"1.170370564","rc":[{"trd":[[1.35,633.99]],"ltp":1.35,"tv":633.99,"id":8509691},{"atl":[[1.35,7.61]],"id":8509691}],"con":true,"img":false}]}
{"op":"mcm","clk":"1362426497","pt":1588450068325,"mc":[{"id":"1.170370564","rc":[{"trd":[[1.26,3678.65],[1.3,5368.16]],"ltp":1.26,"tv":9046.81,"id":8509691},{"atb":[[1.26,230.82],[1.3,0]],"id":8509691}],"con":true,"img":false}]}
{"op":"mcm","clk":"1362426539","pt":1588450071433,"mc":[{"id":"1.170370564","rc":[{"atb":[[4.4,0.11]],"id":9630572}],"con":true,"img":false}]}
{"op":"mcm","clk":"1362426560","pt":1588450072553,"mc":[{"id":"1.170370566","rc":[{"atb":[[1.06,902.8]],"id":8509691}],"con":true,"img":false}]}
{"op":"mcm","clk":"1362426571","pt":1588450073317,"mc":[{"id":"1.170370564","rc":[{"atb":[[4.4,0]],"id":9630572}],"con":true,"img":false}]}
{"op":"mcm","clk":"1362426584","pt":1588450074247,"mc":[{"id":"1.170370564","rc":[{"trd":[[3.85,61.34]],"ltp":3.85,"tv":61.34,"id":9630572},{"trd":[[1.35,641.12]],"ltp":1.35,"tv":641.12,"id":8509691},{"atl":[[1.35,0.48]],"id":8509691}],"con":true,"img":false}]}
{"op":"mcm","clk":"1362426601","pt":1588450076021,"mc":[{"id":"1.170370564","rc":[{"atl":[[1.37,10.75]],"id":8509691}],"con":true,"img":false},{"id":"1.170370567","rc":[{"atl":[[9.2,0]],"id":8509691}],"con":true,"img":false}]}
{"op":"mcm","clk":"1362426616","pt":1588450077346,"mc":[{"id":"1.170370564","rc":[{"trd":[[1.35,642.08]],"ltp":1.35,"tv":642.08,"id":8509691},{"atb":[[1.35,11.27]],"id":8509691},{"atl":[[1.35,0]],"id":8509691}],"con":true,"img":false}]}
{"op":"mcm","clk":"1362426633","pt":1588450079342,"mc":[{"id":"1.170370564","rc":[{"atb":[[1.01,467.99]],"id":9630572}],"con":true,"img":false}]}
{"op":"mcm","clk":"1362426639","pt":1588450079954,"mc":[{"id":"1.170370564","rc":[{"atb":[[1.01,464.91]],"id":9630572}],"con":true,"img":false}]}
{"op":"mcm","clk":"1362426646","pt":1588450080416,"mc":[{"id":"1.170370564","rc":[{"atb":[[1.2,240]],"id":8509691}],"con":true,"img":false}]}
{"op":"mcm","clk":"1362426648","pt":1588450080516,"mc":[{"id":"1.170370564","rc":[{"atb":[[1.01,464.79]],"id":9630572}],"con":true,"img":false}]}
{"op":"mcm","clk":"1362426656","pt":1588450081330,"mc":[{"id":"1.170370567","rc":[{"atl":[[8.6,15.74]],"id":8509691}],"con":true,"img":false}]}
{"op":"mcm","clk":"1362426665","pt":1588450081844,"mc":[{"id":"1.170370564","rc":[{"atb":[[1.2,0],[1.26,0]],"id":8509691}],"con":true,"img":false}]}
{"op":"mcm","clk":"1362426688","pt":1588450083842,"mc":[{"id":"1.170370566","rc":[{"atb":[[1.06,0]],"id":8509691}],"con":true,"img":false}]}
{"op":"mcm","clk":"1362426693","pt":1588450084354,"mc":[{"id":"1.170370564","rc":[{"atb":[[1.27,0.1]],"id":8509691}],"con":true,"img":false}]}
{"op":"mcm","clk":"1362426696","pt":1588450084558,"mc":[{"id":"1.170370564","rc":[{"atl":[[1.36,8.5]],"id":8509691}],"con":true,"img":false}]}
{"op":"mcm","clk":"1362426708","pt":1588450085531,"mc":[{"id":"1.170370564","rc":[{"atb":[[1.25,2.48]],"id":8509691}],"con":true,"img":false}]}
{"op":"mcm","clk":"1362426710","pt":1588450085633,"mc":[{"id":"1.170370564","rc":[{"trd":[[3.9,0.16]],"ltp":3.9,"tv":0.16,"id":9630572},{"trd":[[1.35,642.4]],"ltp":1.35,"tv":642.4,"id":8509691},{"atb":[[1.35,10.94]],"id":8509691}],"con":true,"img":false}]}
{"op":"mcm","clk":"1362426718","pt":1588450086143,"mc":[{"id":"1.170370564","rc":[{"trd":[[1.35,664.3]],"ltp":1.35,"tv":664.3,"id":8509691},{"atb":[[1.35,0]],"id":8509691},{"atl":[[1.3,284.26]],"id":8509691}],"con":true,"img":false}]}
{"op":"mcm","clk":"1362426721","pt":1588450086346,"mc":[{"id":"1.170370566","rc":[{"atb":[[1.03,256.75]],"id":9630572}],"con":true,"img":false}]}
{"op":"mcm","clk":"1362426725","pt":1588450086856,"mc":[{"id":"1.170370566","rc":[{"atb":[[1.05,88.78]],"id":9630572}],"con":true,"img":false}]}
{"op":"mcm","clk":"1362426728","pt":1588450087264,"mc":[{"id":"1.170370564","rc":[{"atl":[[1.34,175]],"id":8509691}],"con":true,"img":false}]}
{"op":"mcm","clk":"1362426731","pt":1588450087365,"mc":[{"id":"1.170370564","rc":[{"atl":[[1.32,240]],"id":8509691}],"con":true,"img":false}]}
{"op":"mcm","clk":"1362426738","pt":1588450087772,"mc":[{"id":"1.170370564","rc":[{"atl":[[1.3,0]],"id":8509691}],"con":true,"img":false}]}
{"op":"mcm","clk":"1362426756","pt":1588450089146,"mc":[{"id":"1.170370564","rc":[{"atl":[[1.35,0.17]],"id":8509691}],"con":true,"img":false}]}
{"op":"mcm","clk":"1362426762","pt":1588450089655,"mc":[{"id":"1.170370564","rc":[{"atl":[[1.34,0]],"id":8509691}],"con":true,"img":false}]}
{"op":"mcm","clk":"1362426800","pt":1588450091385,"mc":[{"id":"1.170370564","rc":[{"atb":[[1.29,11.03]],"id":8509691}],"con":true,"img":false}]}
{"op":"mcm","clk":"1362426803","pt":1588450091487,"mc":[{"id":"1.170370566","rc":[{"atb":[[1.03,0]],"id":9630572}],"con":true,"img":false}]}
{"op":"mcm","clk":"1362426810","pt":1588450091691,"mc":[{"id":"1.170370564","rc":[{"trd":[[1.29,23631.57]],"ltp":1.29,"tv":23631.57,"id":8509691},{"atb":[[1.29,0]],"id":8509691},{"atl":[[1.29,121.94]],"id":8509691}],"con":true,"img":false}]}
{"op":"mcm","clk":"1362426833","pt":1588450092609,"mc":[{"id":"1.170370564","rc":[{"atb":[[3.85,100]],"id":9630572}],"con":true,"img":false}]}
{"op":"mcm","clk":"1362426854","pt":1588450093374,"mc":[{"id":"1.170370564","rc":[{"atl":[[1.29,361.94]],"id":8509691}],"con":true,"img":false}]}
{"op":"mcm","clk":"1362426863","pt":1588450093684,"mc":[{"id":"1.170370564","rc":[{"trd":[[4.4,395.32]],"ltp":4.4,"tv":395.32,"id":9630572},{"trd":[[1.29,23642.15]],"ltp":1.29,"tv":23642.15,"id":8509691},{"atl":[[1.35,0],[1.29,351.35]],"id":8509691}],"con":true,"img":false}]}
{"op":"mcm","clk":"1362426884","pt":1588450094601,"mc":[{"id":"1.170370564","rc":[{"atb":[[3.85,0]],"id":9630572}],"con":true,"img":false}]}
{"op":"mcm","clk":"1362426901","pt":1588450095313,"mc":[{"id":"1.170370564","rc":[{"atb":[[1.01,467.99]],"id":9630572}],"con":true,"img":false}]}
{"op":"mcm","clk":"1362426906","pt":1588450095415,"mc":[{"id":"1.170370566","rc":[{"atb":[[1.11,984.87]],"id":9630572}],"con":true,"img":false}]}
{"op":"mcm","clk":"1362426920","pt":1588450095976,"mc":[{"id":"1.170370564","rc":[{"atb":[[1.01,464.81]],"id":9630572}],"con":true,"img":false}]}
{"op":"mcm","clk":"1362426932","pt":1588450096581,"mc":[{"id":"1.170370566","rc":[{"atb":[[1.08,256.75]],"id":9630572}],"con":true,"img":false}]}
{"op":"mcm","clk":"1362426938","pt":1588450096789,"mc":[{"id":"1.170370564","rc":[{"atb":[[1.01,464.79]],"id":9630572}],"con":true,"img":false}]}
{"op":"mcm","clk":"1362426977","pt":1588450098618,"mc":[{"id":"1.170370564","rc":[{"atb":[[1.19,0],[1.16,0]],"id":8509691}],"con":true,"img":false}]}
{"op":"mcm","clk":"1362426982","pt":1588450098772,"mc":[{"id":"1.170370564","rc":[{"atb":[[1.27,0]],"id":8509691}],"con":true,"img":false}]}
{"op":"mcm","clk":"1362426988","pt":1588450099077,"mc":[{"id":"1.170370564","rc":[{"trd":[[1.29,23649.24]],"ltp":1.29,"tv":23649.24,"id":8509691},{"atl":[[1.29,347.81]],"id":8509691}],"con":true,"img":false}]}
{"op":"mcm","clk":"1362427012","pt":1588450100503,"mc":[{"id":"1.170370564","rc":[{"trd":[[1.25,3889.18]],"ltp":1.25,"tv":3889.18,"id":8509691},{"atb":[[1.25,0.48]],"id":8509691}],"con":true,"img":false}]}
{"op":"mcm","clk":"1362427024","pt":1588450101222,"mc":[{"id":"1.170370566","rc":[{"atb":[[1.01,0]],"id":8509691}],"con":true,"img":false}]}
{"op":"mcm","clk":"1362427045","pt":1588450101883,"mc":[{"id":"1.170370564","rc":[{"atb":[[4.8,0.01]],"id":9630572}],"con":true,"img":false}]}
{"op":"mcm","clk":"1362427048","pt":1588450101982,"mc":[{"id":"1.170370564","rc":[{"trd":[[4.8,217.43]],"ltp":4.8,"tv":217.43,"id":9630572},{"atb":[[4.8,0]],"id":9630572},{"trd":[[1.29,23656.13],[1.27,5239.91]],"ltp":1.29,"tv":28896.04,"id":8509691},{"atl":[[1.29,344.37]],"id":8509691}],"con":true,"img":false}]}
{"op":"mcm","clk":"1362427055","pt":1588450102495,"mc":[{"id":"1.170370564","rc":[{"trd":[[1.25,3890.15]],"ltp":1.25,"tv":3890.15,"id":8509691},{"atb":[[1.25,0]],"id":8509691},{"atl":[[1.25,19.01]],"id":8509691}],"con":true,"img":false}]}
{"op":"mcm","clk":"1362427060","pt":1588450102801,"mc":[{"id":"1.170370564","rc":[{"trd":[[1.24,2562.27]],"ltp":1.24,"tv":2562.27,"id":8509691},{"atb":[[1.24,3.06]],"id":8509691}],"con":true,"img":false},{"id":"1.170370566","rc":[{"atb":[[1.05,0]],"id":9630572}],"con":true,"img":false}]}
{"op":"mcm","clk":"1362427068","pt":1588450103208,"mc":[{"id":"1.170370564","rc":[{"trd":[[1.24,2566.27]],"ltp":1.24,"tv":2566.27,"id":8509691},{"atb":[[1.24,1.06]],"id":8509691}],"con":true,"img":false}]}
{"op":"mcm","clk":"1362427069","pt":1588450103309,"mc":[{"id":"1.170370564","rc":[{"trd":[[1.25,3891.25]],"ltp":1.25,"tv":3891.25,"id":8509691},{"atl":[[1.25,18.46]],"id":8509691}],"con":true,"img":false}]}
{"op":"mcm","clk":"1362427075","pt":1588450103713,"mc":[{"id":"1.170370564","rc":[{"atb":[[1.18,8.79],[1.15,27.75]],"id":8509691}],"con":true,"img":false}]}
{"op":"mcm","clk":"1362427082","pt":1588450104222,"mc":[{"id":"1.170370564","rc":[{"atb":[[1.12,0]],"id":8509691}],"con":true,"img":false}]}
{"op":"mcm","clk":"1362427126","pt":1588450106411,"mc":[{"id":"1.170370564","rc":[{"atl":[[1.32,0]],"id":8509691}],"con":true,"img":false}]}
{"op":"mcm","clk":"1362427136","pt":1588450107327,"mc":[{"id":"1.170370564","rc":[{"atl":[[1.25,0]],"id":8509691}],"con":true,"img":false}]}
{"op":"mcm","clk":"1362427146","pt":1588450107887,"mc":[{"id":"1.170370566","rc":[{"atb":[[1.2,88.78]],"id":9630572}],"con":true,"img":false}]}
{"op":"mcm","clk":"1362427151","pt":1588450108195,"mc":[{"id":"1.170370564","rc":[{"atl":[[1.29,104.37]],"id":8509691}],"con":true,"img":false}]}
{"op":"mcm","clk":"1362427168","pt":1588450109216,"mc":[{"id":"1.170370564","rc":[{"atl":[[1.36,0]],"id":8509691}],"con":true,"img":false}]}
{"op":"mcm","clk":"1362427184","pt":1588450110387,"mc":[{"id":"1.170370564","rc":[{"trd":[[1.18,990.68],[1.24,2568.39]],"ltp":1.18,"tv":3559.06,"id":8509691},{"atb":[[1.18,7.85],[1.24,0]],"id":8509691}],"con":true,"img":false}]}
{"op":"mcm","clk":"1362427189","pt":1588450110896,"mc":[{"id":"1.170370566","rc":[{"atb":[[1.2,611.9]],"id":9630572}],"con":true,"img":false}]}
{"op":"mcm","clk":"1362427190","pt":1588450110998,"mc":[{"id":"1.170370564","rc":[{"trd":[[1.29,23656.2]],"ltp":1.29,"tv":23656.2,"id":8509691},{"atl":[[1.29,104.33]],"id":8509691}],"con":true,"img":false}]}
{"op":"mcm","clk":"1362427209","pt":1588450112935,"mc":[{"id":"1.170370564","rc":[{"atl":[[1.25,1.66]],"id":8509691}],"con":true,"img":false}]}
{"op":"mcm","clk":"1362427216","pt":1588450113801,"mc":[{"id":"1.170370564","rc":[{"atb":[[1.2,0.1]],"id":8509691}],"con":true,"img":false}]}
{"op":"mcm","clk":"1362427226","pt":1588450114821,"mc":[{"id":"1.170370564","rc":[{"atl":[[1.33,8.7]],"id":8509691}],"con":true,"img":false}]}
{"op":"mcm","clk":"1362427248","pt":1588450116605,"mc":[{"id":"1.170370566","rc":[{"atb":[[1.11,0]],"id":9630572}],"con":true,"img":false}]}
{"op":"mcm","clk":"1362427250","pt":1588450116707,"mc":[{"id":"1.170370564","rc":[{"atb":[[1.19,8.75]],"id":8509691}],"con":true,"img":false}]}
{"op":"mcm","clk":"1362427270","pt":1588450118999,"mc":[{"id":"1.170370564","rc":[{"atl":[[1.28,240]],"id":8509691}],"con":true,"img":false}]}
{"op":"mcm","clk":"1362427281","pt":1588450119713,"mc":[{"id":"1.170370566","rc":[{"atb":[[1.3,256.75]],"id":9630572}],"con":true,"img":false}]}
{"op":"mcm","clk":"1362427288","pt":1588450119917,"mc":[{"id":"1.170370564","rc":[{"atb":[[1.22,11.99]],"id":8509691}],"con":true,"img":false}]}
{"op":"mcm","clk":"1362427305","pt":1588450121904,"mc":[{"id":"1.170370566","rc":[{"atl":[[5.7,18.36]],"id":8509691}],"con":true,"img":false}]}
{"op":"mcm","clk":"1362427324","pt":1588450123534,"mc":[{"id":"1.170370566","rc":[{"atb":[[1.2,523.11]],"id":9630572}],"con":true,"img":false}]}
{"op":"mcm","clk":"1362427328","pt":1588450123840,"mc":[{"id":"1.170370566","rc":[{"atb":[[2,88.65]],"id":9630572}],"con":true,"img":false}]}
{"op":"mcm","clk":"1362427347","pt":1588450125627,"mc":[{"id":"1.170370564","rc":[{"atl":[[1.27,177.3]],"id":8509691}],"con":true,"img":false}]}
{"op":"mcm","clk":"1362427352","pt":1588450126542,"mc":[{"id":"1.170370564","rc":[{"atl":[[1.29,0]],"id":8509691}],"con":true,"img":false}]}
{"op":"mcm","clk":"1362427367","pt":1588450127512,"mc":[{"id":"1.170370564","rc":[{"atl":[[1.28,0],[1.33,0]],"id":8509691}],"con":true,"img":false}]}
{"op":"mcm","clk":"1362427380","pt":1588450128841,"mc":[{"id":"1.170370564","rc":[{"atl":[[1.27,0]],"id":8509691}],"con":true,"img":false}]}
{"op":"mcm","clk":"1362427386","pt":1588450129251,"mc":[{"id":"1.170370564","rc":[{"atl":[[1.23,3.5]],"id":8509691}],"con":true,"img":false}]}
{"op":"mcm","clk":"1362427413","pt":1588450131652,"mc":[{"id":"1.170370564","rc":[{"atl":[[1.26,104.33]],"id":8509691}],"con":true,"img":false}]}
{"op":"mcm","clk":"1362427421","pt":1588450132055,"mc":[{"id":"1.170370564","rc":[{"atb":[[1.15,10]],"id":8509691}],"con":true,"img":false}]}
{"op":"mcm","clk":"1362427429","pt":1588450133335,"mc":[{"id":"1.170370564","rc":[{"atb":[[1.2,0]],"id":8509691}],"con":true,"img":false}]}
{"op":"mcm","clk":"1362427436","pt":1588450133945,"mc":[{"id":"1.170370566","rc":[{"atb":[[1.02,0]],"id":8509691}],"con":true,"img":false}]}
{"op":"mcm","clk":"1362427442","pt":1588450134253,"mc":[{"id":"1.170370564","rc":[{"trd":[[4.8,244.82],[5,15.89],[5.3,11.1]],"ltp":4.8,"tv":271.81,"id":9630572},{"atl":[[4.5,71.38]],"id":9630572},{"trd":[[1.26,3782.98],[1.23,1104.4],[1.25,3892.92]],"ltp":1.26,"tv":8780.3,"id":8509691},{"atl":[[1.26,0],[1.23,0],[1.25,0]],"id":8509691}],"con":true,"img":false}]}
{"op":"mcm","clk":"1362427477","pt":1588450136957,"mc":[{"id":"1.170370564","rc":[{"atb":[[1.22,0]],"id":8509691}],"con":true,"img":false}]}
{"op":"mcm","clk":"1362427481","pt":1588450137160,"mc":[{"id":"1.170370564","rc":[{"atb":[[1.14,17.75]],"id":8509691}],"con":true,"img":false}]}
{"op":"mcm","clk":"1362427514","pt":1588450139663,"mc":[{"id":"1.170370564","rc":[{"atb":[[1.27,295.21]],"id":8509691}],"con":true,"img":false}]}
{"op":"mcm","clk":"1362427537","pt":1588450141346,"mc":[{"id":"1.170370564","rc":[{"atb":[[1.23,0.1]],"id":8509691}],"con":true,"img":false}]}
{"op":"mcm","clk":"1362427539","pt":1588450141651,"mc":[{"id":"1.170370566","rc":[{"atb":[[1.2,0],[1.01,88.65],[1.3,0],[1.08,0]],"id":9630572}],"con":true,"img":false}]}
{"op":"mcm","clk":"1362427548","pt":1588450142673,"mc":[{"id":"1.170370564","rc":[{"atb":[[1.27,0]],"id":8509691}],"con":true,"img":false}]}
{"op":"mcm","clk":"1362427575","pt":1588450144669,"mc":[{"id":"1.170370564","rc":[{"atb":[[1.15,18.75]],"id":8509691}],"con":true,"img":false}]}
{"op":"mcm","clk":"1362427599","pt":1588450146454,"mc":[{"id":"1.170370566","rc":[{"atb":[[2,0]],"id":9630572}],"con":true,"img":false}]}
{"op":"mcm","clk":"1362427600","pt":1588450146552,"mc":[{"id":"1.170370566","rc":[{"atb":[[1.07,902.8]],"id":8509691}],"con":true,"img":false}]}
{"op":"mcm","clk":"1362427605","pt":1588450147064,"mc":[{"id":"1.170370566","rc":[{"atl":[[5.7,0]],"id":8509691}],"con":true,"img":false}]}
{"op":"mcm","clk":"1362427613","pt":1588450147983,"mc":[{"id":"1.170370564","rc":[{"atb":[[1.35,115.24]],"id":8509691}],"con":true,"img":false}]}
{"op":"mcm","clk":"1362427633","pt":1588450148751,"mc":[{"id":"1.170370564","rc":[{"atb":[[1.29,177.3]],"id":8509691}],"con":true,"img":false}]}
{"op":"mcm","clk":"1362427644","pt":1588450150078,"mc":[{"id":"1.170370564","rc":[{"atb":[[1.3,177.3]],"id":8509691}],"con":true,"img":false},{"id":"1.170370566","rc":[{"atb":[[1.02,88.65]],"id":8509691}],"con":true,"img":false}]}
{"op":"mcm","clk":"1362427648","pt":1588450150286,"mc":[{"id":"1.170370564","rc":[{"atb":[[1.23,1.52]],"id":8509691}],"con":true,"img":false}]}
{"op":"mcm","clk":"1362427659","pt":1588450151252,"mc":[{"id":"1.170370566","rc":[{"atb":[[1.01,799.87]],"id":8509691}],"con":true,"img":false}]}
{"op":"mcm","clk":"1362427672","pt":1588450153088,"mc":[{"id":"1.170370564","rc":[{"atb":[[1.3,0]],"id":8509691}],"con":true,"img":false},{"id":"1.170370566","rc":[{"atb":[[1.08,88.65]],"id":8509691}],"con":true,"img":false}]}
{"op":"mcm","clk":"1362427689","pt":1588450154770,"mc":[{"id":"1.170370564","rc":[{"atb":[[1.3,240]],"id":8509691}],"con":true,"img":false}]}
{"op":"mcm","clk":"1362427691","pt":1588450155075,"mc":[{"id":"1.170370564","rc":[{"trd":[[3.7,3.72]],"ltp":3.7,"tv":3.72,"id":9630572},{"trd":[[1.37,79.45]],"ltp":1.37,"tv":79.45,"id":8509691},{"atl":[[1.37,9.97]],"id":8509691}],"con":true,"img":false}]}
{"op":"mcm","clk":"1362427696","pt":1588450155379,"mc":[{"id":"1.170370564","rc":[{"atb":[[1.23,241.52]],"id":8509691}],"con":true,"img":false}]}
{"op":"mcm","clk":"1362427712","pt":1588450156293,"mc":[{"id":"1.170370564","rc":[{"trd":[[4.5,897.78]],"ltp":4.5,"tv":897.78,"id":9630572},{"atl":[[4.5,0]],"id":9630572},{"trd":[[1.28,6745.69],[1.35,894.8],[1.3,5848.16],[1.29,24010.81]],"ltp":1.28,"tv":37499.45,"id":8509691},{"atb":[[1.35,0],[1.3,0],[1.29,0]],"id":8509691},{"atl":[[1.28,103.02]],"id":8509691}],"con":true,"img":false}]}
{"op":"mcm","clk":"1362427715","pt":1588450156550,"mc":[{"id":"1.170370566","rc":[{"atb":[[1.05,799.87]],"id":9630572}],"con":true,"img":false}]}
{"op":"mcm","clk":"1362427721","pt":1588450157261,"mc":[{"id":"1.170370564","rc":[{"atl":[[1.35,177.3]],"id":8509691}],"con":true,"img":false}]}
{"op":"mcm","clk":"1362427731","pt":1588450158081,"mc":[{"id":"1.170370564","rc":[{"atl":[[1.4,14.57]],"id":8509691}],"con":true,"img":false}]}
{"op":"mcm","clk":"1362427740","pt":1588450158488,"mc":[{"id":"1.170370564","rc":[{"atb":[[1.23,1.52]],"id":8509691}],"con":true,"img":false}]}
{"op":"mcm","clk":"1362427749","pt":1588450159302,"mc":[{"id":"1.170370564","rc":[{"atl":[[1.35,177.48]],"id":8509691}],"con":true,"img":false}]}
{"op":"mcm","clk":"1362427752","pt":1588450159963,"mc":[{"id":"1.170370564","rc":[{"atl":[[1.28,0]],"id":8509691}],"con":true,"img":false}]}
{"op":"mcm","clk":"1362427782","pt":1588450161390,"mc":[{"id":"1.170370564","rc":[{"atb":[[1.31,177.3]],"id":8509691}],"con":true,"img":false},{"id":"1.170370566","rc":[{"atb":[[1.08,0]],"id":8509691}],"con":true,"img":false}]}
{"op":"mcm","clk":"1362427783","pt":1588450161593,"mc":[{"id":"1.170370564","rc":[{"atl":[[1.35,189.48]],"id":8509691}],"con":true,"img":false}]}
{"op":"mcm","clk":"1362427785","pt":1588450161899,"mc":[{"id":"1.170370564","rc":[{"atb":[[1.31,0]],"id":8509691}],"con":true,"img":false}]}
{"op":"mcm","clk":"1362427801","pt":1588450162868,"mc":[{"id":"1.170370564","rc":[{"atl":[[1.36,237.92]],"id":8509691}],"con":true,"img":false}]}
{"op":"mcm","clk":"1362427810","pt":1588450163275,"mc":[{"id":"1.170370564","rc":[{"atb":[[1.25,0]],"id":9630572}],"con":true,"img":false}]}
{"op":"mcm","clk":"1362427812","pt":1588450163376,"mc":[{"id":"1.170370564","rc":[{"atl":[[1.35,191.23]],"id":8509691}],"con":true,"img":false}]}
{"op":"mcm","clk":"1362427817","pt":1588450163579,"mc":[{"id":"1.170370564","rc":[{"atl":[[1.36,0]],"id":8509691}],"con":true,"img":false}]}
{"op":"mcm","clk":"1362427820","pt":1588450163783,"mc":[{"id":"1.170370564","rc":[{"atl":[[1.38,8]],"id":8509691}],"con":true,"img":false},{"id":"1.170370566","rc":[{"atb":[[1.1,97.58]],"id":9630572}],"con":true,"img":false}]}
{"op":"mcm","clk":"1362427824","pt":1588450164091,"mc":[{"id":"1.170370564","rc":[{"atb":[[1.28,29.25]],"id":8509691}],"con":true,"img":false}]}
{"op":"mcm","clk":"1362427828","pt":1588450164903,"mc":[{"id":"1.170370564","rc":[{"atb":[[1.28,0]],"id":8509691}],"con":true,"img":false}]}
{"op":"mcm","clk":"1362427835","pt":1588450165307,"mc":[{"id":"1.170370564","rc":[{"atl":[[1.35,191.43]],"id":8509691}],"con":true,"img":false}]}
{"op":"mcm","clk":"1362427852","pt":1588450166299,"mc":[{"id":"1.170370564","rc":[{"atl":[[1.31,240]],"id":8509691}],"con":true,"img":false}]}
{"op":"mcm","clk":"1362427893","pt":1588450169188,"mc":[{"id":"1.170370564","rc":[{"atl":[[1.35,179.43]],"id":8509691}],"con":true,"img":false}]}
{"op":"mcm","clk":"1362427925","pt":1588450171592,"mc":[{"id":"1.170370566","rc":[{"atb":[[1.05,0]],"id":9630572},{"atb":[[1.01,0]],"id":8509691}],"con":true,"img":false}]}
