{"op":"mcm","clk":"1350002330","pt":1588415167277,"mc":[{"id":"1.170370562","rc":[{"atb":[[1.01,1102.13]],"id":9631798}],"con":true,"img":false}]}
{"op":"mcm","clk":"1350002333","pt":1588415167382,"mc":[{"id":"1.170370562","rc":[{"atb":[[1.01,1100.14]],"id":9631798}],"con":true,"img":false}]}
{"op":"mcm","clk":"1350002338","pt":1588415167485,"mc":[{"id":"1.170370562","rc":[{"atb":[[1.44,224.56]],"id":9625043}],"con":true,"img":false}]}
{"op":"mcm","clk":"1350002344","pt":1588415167591,"mc":[{"id":"1.170370562","rc":[{"atb":[[1.01,1100.13]],"id":9631798}],"con":true,"img":false}]}
{"op":"mcm","clk":"1350002394","pt":1588415168892,"mc":[{"id":"1.170370562","rc":[{"atb":[[1.42,0]],"id":9625043}],"con":true,"img":false}]}
{"op":"mcm","clk":"1350002399","pt":1588415169049,"mc":[{"id":"1.170370562","rc":[{"atl":[[1.48,55.61]],"id":9625043}],"con":true,"img":false}]}
{"op":"mcm","clk":"1350002414","pt":1588415169463,"mc":[{"id":"1.170370562","rc":[{"trd":[[1.48,565.01]],"ltp":1.48,"tv":565.01,"id":9625043},{"atb":[[1.5,33.97]],"id":9625043},{"atl":[[1.48,0]],"id":9625043}],"con":true,"img":false}]}
{"op":"mcm","clk":"1350002427","pt":1588415169668,"mc":[{"id":"1.170370562","rc":[{"atl":[[1.65,177.3]],"id":9625043}],"con":true,"img":false}]}
{"op":"mcm","clk":"1350002449","pt":1588415170187,"mc":[{"id":"1.170370562","rc":[{"atb":[[1.39,240]],"id":9625043}],"con":true,"img":false}]}
{"op":"mcm","clk":"1350002461","pt":1588415170446,"mc":[{"id":"1.170370562","rc":[{"atl":[[1.79,265.95]],"id":9625043}],"con":true,"img":false}]}
{"op":"mcm","clk":"1350002506","pt":1588415172051,"mc":[{"id":"1.170370562","rc":[{"atb":[[2.94,0.01]],"id":9631798}],"con":true,"img":false}]}
{"op":"mcm","clk":"1350002510","pt":1588415172160,"mc":[{"id":"1.170370562","rc":[{"atl":[[1.53,0]],"id":9625043}],"con":true,"img":false}]}
{"op":"mcm","clk":"1350002532","pt":1588415172675,"mc":[{"id":"1.170370562","rc":[{"atb":[[2.9,0.01]],"id":9631798}],"con":true,"img":false}]}
{"op":"mcm","clk":"1350002553","pt":1588415173454,"mc":[{"id":"1.170370562","rc":[{"trd":[[1.5,911.72]],"ltp":1.5,"tv":911.72,"id":9625043},{"atb":[[1.5,21.71],[1.38,265.95]],"id":9625043}],"con":true,"img":false}]}
{"op":"mcm","clk":"1350002581","pt":1588415174387,"mc":[{"id":"1.170370562","rc":[{"trd":[[1.5,914.85]],"ltp":1.5,"tv":914.85,"id":9625043},{"atb":[[1.5,20.15]],"id":9625043}],"con":true,"img":false}]}
{"op":"mcm","clk":"1350002640","pt":1588415176260,"mc":[{"id":"1.170370562","rc":[{"trd":[[1.5,955.15]],"ltp":1.5,"tv":955.15,"id":9625043},{"atb":[[1.5,0]],"id":9625043},{"atl":[[1.5,157.15]],"id":9625043}],"con":true,"img":false}]}
{"op":"mcm","clk":"1350002665","pt":1588415177085,"mc":[{"id":"1.170370562","rc":[{"trd":[[1.5,1043.8]],"ltp":1.5,"tv":1043.8,"id":9625043},{"atl":[[1.5,112.82]],"id":9625043}],"con":true,"img":false}]}
{"op":"mcm","clk":"1350002668","pt":1588415177187,"mc":[{"id":"1.170370562","rc":[{"atb":[[3,17.73]],"id":9631798}],"con":true,"img":false}]}
{"op":"mcm","clk":"1350002679","pt":1588415177495,"mc":[{"id":"1.170370562","rc":[{"trd":[[1.46,1007.45]],"ltp":1.46,"tv":1007.45,"id":9625043},{"atb":[[1.46,186.53]],"id":9625043}],"con":true,"img":false}]}
{"op":"mcm","clk":"1350002711","pt":1588415178374,"mc":[{"id":"1.170370562","rc":[{"atl":[[1000,2.65]],"id":9625043}],"con":true,"img":false}]}
{"op":"mcm","clk":"1350002727","pt":1588415178995,"mc":[{"id":"1.170370562","rc":[{"atl":[[1.5,156.82]],"id":9625043},{"atl":[[3.3,34.98]],"id":9631798}],"con":true,"img":false}]}
{"op":"mcm","clk":"1350002735","pt":1588415179256,"mc":[{"id":"1.170370562","rc":[{"atl":[[1000,0.07]],"id":9625043}],"con":true,"img":false}]}
{"op":"mcm","clk":"1350002752","pt":1588415179977,"mc":[{"id":"1.170370562","rc":[{"trd":[[1.5,1148.76]],"ltp":1.5,"tv":1148.76,"id":9625043},{"atl":[[1.5,104.34]],"id":9625043}],"con":true,"img":false}]}
{"op":"mcm","clk":"1350002755","pt":1588415180084,"mc":[{"id":"1.170370562","rc":[{"atl":[[1000,0.05]],"id":9625043}],"con":true,"img":false}]}
{"op":"mcm","clk":"1350002778","pt":1588415180962,"mc":[{"id":"1.170370562","rc":[{"atl":[[1.5,191.93]],"id":9625043}],"con":true,"img":false}]}
{"op":"mcm","clk":"1350002843","pt":1588415182883,"mc":[{"id":"1.170370562","rc":[{"atl":[[1.48,55]],"id":9625043}],"con":true,"img":false}]}
{"op":"mcm","clk":"1350002862","pt":1588415183353,"mc":[{"id":"1.170370562","rc":[{"atl":[[1.5,192.05]],"id":9625043}],"con":true,"img":false}]}
{"op":"mcm","clk":"1350002875","pt":1588415183869,"mc":[{"id":"1.170370562","rc":[{"atl":[[1.5,194.62]],"id":9625043}],"con":true,"img":false}]}
{"op":"mcm","clk":"1350002888","pt":1588415184387,"mc":[{"id":"1.170370562","rc":[{"atl":[[1.5,107.03]],"id":9625043}],"con":true,"img":false}]}
{"op":"mcm","clk":"1350002893","pt":1588415184594,"mc":[{"id":"1.170370562","rc":[{"atb":[[1.46,0]],"id":9625043}],"con":true,"img":false}]}
{"op":"mcm","clk":"1350002910","pt":1588415185063,"mc":[{"id":"1.170370562","rc":[{"atb":[[1.2,4.39],[1.18,0],[1.39,0],[1.35,0],[1.27,0],[1.16,0]],"id":9625043}],"con":true,"img":false}]}
{"op":"mcm","clk":"1350002916","pt":1588415185167,"mc":[{"id":"1.170370562","rc":[{"atl":[[1.5,107.06]],"id":9625043}],"con":true,"img":false}]}
{"op":"mcm","clk":"1350002925","pt":1588415185479,"mc":[{"id":"1.170370562","rc":[{"atl":[[1.48,805]],"id":9625043}],"con":true,"img":false}]}
{"op":"mcm","clk":"1350002934","pt":1588415185790,"mc":[{"id":"1.170370562","rc":[{"atl":[[1.48,55]],"id":9625043}],"con":true,"img":false}]}
{"op":"mcm","clk":"1350002941","pt":1588415186104,"mc":[{"id":"1.170370562","rc":[{"trd":[[1.44,6167.98]],"ltp":1.44,"tv":6167.98,"id":9625043},{"atb":[[1.44,0]],"id":9625043},{"atl":[[1.44,916.64],[1.48,105]],"id":9625043},{"trd":[[3.25,188.95]],"ltp":3.25,"tv":188.95,"id":9631798},{"atl":[[3.25,0]],"id":9631798}],"con":true,"img":false}]}
{"op":"mcm","clk":"1350002966","pt":1588415187091,"mc":[{"id":"1.170370562","rc":[{"atl":[[1.47,492.02]],"id":9625043}],"con":true,"img":false}]}
{"op":"mcm","clk":"1350002976","pt":1588415187503,"mc":[{"id":"1.170370562","rc":[{"atl":[[1.44,0]],"id":9625043}],"con":true,"img":false}]}
{"op":"mcm","clk":"1350002980","pt":1588415187713,"mc":[{"id":"1.170370562","rc":[{"atl":[[1.5,106.94]],"id":9625043}],"con":true,"img":false}]}
{"op":"mcm","clk":"1350002984","pt":1588415187865,"mc":[{"id":"1.170370562","rc":[{"atl":[[1.46,177.3]],"id":9625043}],"con":true,"img":false}]}
{"op":"mcm","clk":"1350003000","pt":1588415188385,"mc":[{"id":"1.170370562","rc":[{"atl":[[1.51,0],[1.48,50]],"id":9625043}],"con":true,"img":false}]}
{"op":"mcm","clk":"1350003029","pt":1588415189669,"mc":[{"id":"1.170370562","rc":[{"atl":[[1.47,0]],"id":9625043}],"con":true,"img":false}]}
{"op":"mcm","clk":"1350003036","pt":1588415189874,"mc":[{"id":"1.170370562","rc":[{"atl":[[1.45,66.48]],"id":9625043}],"con":true,"img":false}]}
{"op":"mcm","clk":"1350003040","pt":1588415189979,"mc":[{"id":"1.170370562","rc":[{"trd":[[1.45,806.85]],"ltp":1.45,"tv":806.85,"id":9625043},{"atl":[[1.44,62.8],[1.45,17.57]],"id":9625043},{"trd":[[3.2,22.17]],"ltp":3.2,"tv":22.17,"id":9631798}],"con":true,"img":false}]}
{"op":"mcm","clk":"1350003061","pt":1588415190597,"mc":[{"id":"1.170370562","rc":[{"atb":[[1.43,143.94]],"id":9625043},{"atl":[[1.45,84.06]],"id":9625043}],"con":true,"img":false}]}
{"op":"mcm","clk":"1350003076","pt":1588415191373,"mc":[{"id":"1.170370562","rc":[{"atb":[[1.28,500]],"id":9625043}],"con":true,"img":false}]}
{"op":"mcm","clk":"1350003080","pt":1588415191477,"mc":[{"id":"1.170370562","rc":[{"atb":[[1.33,240]],"id":9625043}],"con":true,"img":false}]}
{"op":"mcm","clk":"1350003086","pt":1588415191683,"mc":[{"id":"1.170370562","rc":[{"atl":[[1.54,265.95]],"id":9625043}],"con":true,"img":false}]}
{"op":"mcm","clk":"1350003088","pt":1588415191786,"mc":[{"id":"1.170370562","rc":[{"trd":[[1.43,795.24]],"ltp":1.43,"tv":795.24,"id":9625043},{"atb":[[1.43,79.8]],"id":9625043}],"con":true,"img":false}]}
{"op":"mcm","clk":"1350003097","pt":1588415191997,"mc":[{"id":"1.170370562","rc":[{"trd":[[1.44,6168.45]],"ltp":1.44,"tv":6168.45,"id":9625043},{"atb":[[1.24,500]],"id":9625043},{"atl":[[1.44,62.56]],"id":9625043}],"con":true,"img":false}]}
{"op":"mcm","clk":"1350003109","pt":1588415192306,"mc":[{"id":"1.170370562","rc":[{"trd":[[1.44,6186.19]],"ltp":1.44,"tv":6186.19,"id":9625043},{"atl":[[1.44,53.69]],"id":9625043}],"con":true,"img":false}]}
{"op":"mcm","clk":"1350003128","pt":1588415192772,"mc":[{"id":"1.170370562","rc":[{"trd":[[1.43,1035.59]],"ltp":1.43,"tv":1035.59,"id":9625043},{"atb":[[1.43,0]],"id":9625043},{"atl":[[1.44,0],[1.43,2.77]],"id":9625043},{"trd":[[3.3,85.65]],"ltp":3.3,"tv":85.65,"id":9631798},{"atl":[[3.3,0]],"id":9631798}],"con":true,"img":false}]}
{"op":"mcm","clk":"1350003136","pt":1588415192977,"mc":[{"id":"1.170370562","rc":[{"atb":[[1.23,240]],"id":9625043},{"atl":[[1.43,180.07]],"id":9625043}],"con":true,"img":false}]}
{"op":"mcm","clk":"1350003168","pt":1588415194013,"mc":[{"id":"1.170370562","rc":[{"atl":[[1.5,62.94]],"id":9625043}],"con":true,"img":false}]}
{"op":"mcm","clk":"1350003177","pt":1588415194174,"mc":[{"id":"1.170370562","rc":[{"atb":[[1.18,240]],"id":9625043},{"atb":[[3,0]],"id":9631798}],"con":true,"img":false}]}
{"op":"mcm","clk":"1350003196","pt":1588415194787,"mc":[{"id":"1.170370562","rc":[{"atb":[[1.21,240]],"id":9625043}],"con":true,"img":false}]}
{"op":"mcm","clk":"1350003218","pt":1588415195507,"mc":[{"id":"1.170370562","rc":[{"atl":[[1.5,60.37]],"id":9625043}],"con":true,"img":false}]}
{"op":"mcm","clk":"1350003288","pt":1588415197782,"mc":[{"id":"1.170370562","rc":[{"trd":[[1.43,1168.57]],"ltp":1.43,"tv":1168.57,"id":9625043},{"atl":[[1.43,113.58]],"id":9625043}],"con":true,"img":false}]}
{"op":"mcm","clk":"1350003309","pt":1588415198507,"mc":[{"id":"1.170370562","rc":[{"atb":[[1.4,185.24]],"id":9625043}],"con":true,"img":false}]}
{"op":"mcm","clk":"1350003322","pt":1588415198869,"mc":[{"id":"1.170370562","rc":[{"atb":[[1.38,0]],"id":9625043}],"con":true,"img":false}]}
{"op":"mcm","clk":"1350003325","pt":1588415198974,"mc":[{"id":"1.170370562","rc":[{"atb":[[1.42,10.14]],"id":9625043}],"con":true,"img":false}]}
{"op":"mcm","clk":"1350003334","pt":1588415199179,"mc":[{"id":"1.170370562","rc":[{"atl":[[1.43,236.2],[1.45,0]],"id":9625043}],"con":true,"img":false}]}
{"op":"mcm","clk":"1350003353","pt":1588415199800,"mc":[{"id":"1.170370562","rc":[{"atb":[[1.12,240]],"id":9625043}],"con":true,"img":false}]}
{"op":"mcm","clk":"1350003357","pt":1588415199904,"mc":[{"id":"1.170370562","rc":[{"trd":[[1.43,1279.36]],"ltp":1.43,"tv":1279.36,"id":9625043},{"atl":[[1.43,180.8]],"id":9625043}],"con":true,"img":false}]}
{"op":"mcm","clk":"1350003361","pt":1588415200006,"mc":[{"id":"1.170370562","rc":[{"atb":[[1.4,7.93]],"id":9625043}],"con":true,"img":false}]}
{"op":"mcm","clk":"1350003369","pt":1588415200213,"mc":[{"id":"1.170370562","rc":[{"atb":[[1.13,240]],"id":9625043}],"con":true,"img":false}]}
{"op":"mcm","clk":"1350003372","pt":1588415200316,"mc":[{"id":"1.170370562","rc":[{"atb":[[1.34,500]],"id":9625043}],"con":true,"img":false}]}
{"op":"mcm","clk":"1350003382","pt":1588415200678,"mc":[{"id":"1.170370562","rc":[{"atb":[[1.34,1000]],"id":9625043}],"con":true,"img":false}]}
{"op":"mcm","clk":"1350003385","pt":1588415200783,"mc":[{"id":"1.170370562","rc":[{"trd":[[1.43,1279.59]],"ltp":1.43,"tv":1279.59,"id":9625043},{"atl":[[1.43,180.69]],"id":9625043}],"con":true,"img":false}]}
{"op":"mcm","clk":"1350003389","pt":1588415200884,"mc":[{"id":"1.170370562","rc":[{"atb":[[1.09,240]],"id":9625043}],"con":true,"img":false}]}
{"op":"mcm","clk":"1350003412","pt":1588415201710,"mc":[{"id":"1.170370562","rc":[{"trd":[[1.4,5319.39],[1.42,1577.99]],"ltp":1.4,"tv":6897.38,"id":9625043},{"atb":[[1.4,0],[1.42,0]],"id":9625043},{"atl":[[1.4,1237.44]],"id":9625043},{"trd":[[3.5,1030.33]],"ltp":3.5,"tv":1030.33,"id":9631798},{"atl":[[3.5,0]],"id":9631798}],"con":true,"img":false}]}
{"op":"mcm","clk":"1350003417","pt":1588415201916,"mc":[{"id":"1.170370562","rc":[{"atb":[[1.21,740]],"id":9625043}],"con":true,"img":false}]}
{"op":"mcm","clk":"1350003432","pt":1588415202177,"mc":[{"id":"1.170370562","rc":[{"atb":[[1.21,1240]],"id":9625043}],"con":true,"img":false}]}
{"op":"mcm","clk":"1350003448","pt":1588415202795,"mc":[{"id":"1.170370562","rc":[{"atl":[[1.54,0]],"id":9625043}],"con":true,"img":false}]}
{"op":"mcm","clk":"1350003456","pt":1588415203006,"mc":[{"id":"1.170370562","rc":[{"atl":[[1.44,239.96]],"id":9625043}],"con":true,"img":false}]}
{"op":"mcm","clk":"1350003476","pt":1588415203516,"mc":[{"id":"1.170370562","rc":[{"trd":[[1.4,5870.79]],"ltp":1.4,"tv":5870.79,"id":9625043},{"atl":[[1.4,961.74]],"id":9625043}],"con":true,"img":false}]}
{"op":"mcm","clk":"1350003492","pt":1588415203879,"mc":[{"id":"1.170370562","rc":[{"atb":[[1.34,0]],"id":9625043}],"con":true,"img":false}]}
{"op":"mcm","clk":"1350003497","pt":1588415203982,"mc":[{"id":"1.170370562","rc":[{"atb":[[1.34,265.95]],"id":9625043}],"con":true,"img":false}]}
{"op":"mcm","clk":"1350003515","pt":1588415204393,"mc":[{"id":"1.170370562","rc":[{"atb":[[1.33,0],[1.31,265.95]],"id":9625043},{"atl":[[1.42,17.01]],"id":9625043}],"con":true,"img":false}]}
{"op":"mcm","clk":"1350003520","pt":1588415204599,"mc":[{"id":"1.170370562","rc":[{"trd":[[1.37,1902.93]],"ltp":1.37,"tv":1902.93,"id":9625043},{"atl":[[1.37,7.65]],"id":9625043},{"trd":[[3.7,104.37]],"ltp":3.7,"tv":104.37,"id":9631798},{"atl":[[3.7,0]],"id":9631798}],"con":true,"img":false}]}
{"op":"mcm","clk":"1350003539","pt":1588415205011,"mc":[{"id":"1.170370562","rc":[{"atl":[[1.42,509.03]],"id":9625043}],"con":true,"img":false}]}
{"op":"mcm","clk":"1350003555","pt":1588415205475,"mc":[{"id":"1.170370562","rc":[{"atl":[[1.37,0]],"id":9625043}],"con":true,"img":false}]}
{"op":"mcm","clk":"1350003561","pt":1588415205785,"mc":[{"id":"1.170370562","rc":[{"trd":[[1.4,5928.4]],"ltp":1.4,"tv":5928.4,"id":9625043},{"atl":[[1.4,932.93]],"id":9625043}],"con":true,"img":false}]}
{"op":"mcm","clk":"1350003576","pt":1588415206408,"mc":[{"id":"1.170370562","rc":[{"atb":[[1.86,0]],"id":9631798}],"con":true,"img":false}]}
{"op":"mcm","clk":"1350003595","pt":1588415206821,"mc":[{"id":"1.170370562","rc":[{"trd":[[1.4,5931.23]],"ltp":1.4,"tv":5931.23,"id":9625043},{"atl":[[1.4,931.52]],"id":9625043}],"con":true,"img":false}]}
{"op":"mcm","clk":"1350003597","pt":1588415206873,"mc":[{"id":"1.170370562","rc":[{"atb":[[1.35,240]],"id":9625043}],"con":true,"img":false}]}
{"op":"mcm","clk":"1350003599","pt":1588415206976,"mc":[{"id":"1.170370562","rc":[{"atl":[[1.44,242.58]],"id":9625043}],"con":true,"img":false}]}
{"op":"mcm","clk":"1350003609","pt":1588415207390,"mc":[{"id":"1.170370562","rc":[{"atl":[[1.46,0],[1.43,122.62],[1.5,0.02],[1.65,0]],"id":9625043}],"con":true,"img":false}]}
{"op":"mcm","clk":"1350003615","pt":1588415207596,"mc":[{"id":"1.170370562","rc":[{"atb":[[1.35,0]],"id":9625043},{"atl":[[1.48,0]],"id":9625043}],"con":true,"img":false}]}
{"op":"mcm","clk":"1350003623","pt":1588415207905,"mc":[{"id":"1.170370562","rc":[{"atl":[[1.61,265.95]],"id":9625043}],"con":true,"img":false}]}
{"op":"mcm","clk":"1350003635","pt":1588415208317,"mc":[{"id":"1.170370562","rc":[{"atl":[[1.44,2.62]],"id":9625043}],"con":true,"img":false}]}
{"op":"mcm","clk":"1350003639","pt":1588415208421,"mc":[{"id":"1.170370562","rc":[{"atl":[[1.39,66.48]],"id":9625043}],"con":true,"img":false}]}
{"op":"mcm","clk":"1350003642","pt":1588415208524,"mc":[{"id":"1.170370562","rc":[{"atl":[[1.42,17.01]],"id":9625043}],"con":true,"img":false}]}
{"op":"mcm","clk":"1350003647","pt":1588415208577,"mc":[{"id":"1.170370562","rc":[{"atl":[[1.39,132.97]],"id":9625043}],"con":true,"img":false}]}
{"op":"mcm","clk":"1350003654","pt":1588415208885,"mc":[{"id":"1.170370562","rc":[{"atl":[[1.39,199.46]],"id":9625043}],"con":true,"img":false}]}
{"op":"mcm","clk":"1350003668","pt":1588415209404,"mc":[{"id":"1.170370562","rc":[{"atl":[[1.42,282.96]],"id":9625043}],"con":true,"img":false}]}
{"op":"mcm","clk":"1350003670","pt":1588415209507,"mc":[{"id":"1.170370562","rc":[{"atb":[[1.33,1.17]],"id":9625043}],"con":true,"img":false}]}
{"op":"mcm","clk":"1350003686","pt":1588415209979,"mc":[{"id":"1.170370562","rc":[{"trd":[[1.39,3936.16]],"ltp":1.39,"tv":3936.16,"id":9625043},{"atb":[[1.35,177.3]],"id":9625043},{"atl":[[1.39,195.96]],"id":9625043}],"con":true,"img":false}]}
{"op":"mcm","clk":"1350003703","pt":1588415210704,"mc":[{"id":"1.170370562","rc":[{"atb":[[1.26,500]],"id":9625043}],"con":true,"img":false}]}
{"op":"mcm","clk":"1350003710","pt":1588415211013,"mc":[{"id":"1.170370562","rc":[{"trd":[[1.39,3940.17]],"ltp":1.39,"tv":3940.17,"id":9625043},{"atl":[[1.39,193.96]],"id":9625043}],"con":true,"img":false}]}
{"op":"mcm","clk":"1350003713","pt":1588415211115,"mc":[{"id":"1.170370562","rc":[{"atl":[[1.39,371.26]],"id":9625043}],"con":true,"img":false}]}
{"op":"mcm","clk":"1350003724","pt":1588415211579,"mc":[{"id":"1.170370562","rc":[{"atb":[[1.97,379.17]],"id":9631798}],"con":true,"img":false}]}
{"op":"mcm","clk":"1350003756","pt":1588415212616,"mc":[{"id":"1.170370562","rc":[{"atl":[[1.42,265.95]],"id":9625043}],"con":true,"img":false}]}
{"op":"mcm","clk":"1350003760","pt":1588415212718,"mc":[{"id":"1.170370562","rc":[{"atl":[[1.46,50]],"id":9625043}],"con":true,"img":false}]}
{"op":"mcm","clk":"1350003763","pt":1588415212822,"mc":[{"id":"1.170370562","rc":[{"trd":[[1.39,3962.33]],"ltp":1.39,"tv":3962.33,"id":9625043},{"atl":[[1.39,360.18]],"id":9625043}],"con":true,"img":false}]}
{"op":"mcm","clk":"1350003774","pt":1588415213185,"mc":[{"id":"1.170370562","rc":[{"atb":[[1.36,73.58]],"id":9625043}],"con":true,"img":false}]}
{"op":"mcm","clk":"1350003791","pt":1588415213599,"mc":[{"id":"1.170370562","rc":[{"atb":[[1.36,140.07],[1.32,240]],"id":9625043}],"con":true,"img":false}]}
{"op":"mcm","clk":"1350003806","pt":1588415214013,"mc":[{"id":"1.170370562","rc":[{"trd":[[1.39,3962.82]],"ltp":1.39,"tv":3962.82,"id":9625043},{"atl":[[1.39,359.93]],"id":9625043}],"con":true,"img":false}]}
{"op":"mcm","clk":"1350003815","pt":1588415214323,"mc":[{"id":"1.170370562","rc":[{"atb":[[1.35,243.79]],"id":9625043}],"con":true,"img":false}]}
{"op":"mcm","clk":"1350003820","pt":1588415214426,"mc":[{"id":"1.170370562","rc":[{"atb":[[1.26,740]],"id":9625043}],"con":true,"img":false}]}
{"op":"mcm","clk":"1350003822","pt":1588415214529,"mc":[{"id":"1.170370562","rc":[{"atb":[[1.35,310.28]],"id":9625043}],"con":true,"img":false}]}
{"op":"mcm","clk":"1350003842","pt":1588415215097,"mc":[{"id":"1.170370562","rc":[{"atb":[[1.27,240]],"id":9625043}],"con":true,"img":false}]}
{"op":"mcm","clk":"1350003889","pt":1588415217111,"mc":[{"id":"1.170370562","rc":[{"trd":[[1.39,4190.03]],"ltp":1.39,"tv":4190.03,"id":9625043},{"atl":[[1.39,246.32]],"id":9625043}],"con":true,"img":false}]}
{"op":"mcm","clk":"1350003891","pt":1588415217213,"mc":[{"id":"1.170370562","rc":[{"atl":[[1.46,227.3]],"id":9625043}],"con":true,"img":false}]}
{"op":"mcm","clk":"1350003897","pt":1588415217524,"mc":[{"id":"1.170370562","rc":[{"atb":[[1.28,0]],"id":9625043}],"con":true,"img":false}]}
{"op":"mcm","clk":"1350003938","pt":1588415218815,"mc":[{"id":"1.170370562","rc":[{"trd":[[1.39,4278.68]],"ltp":1.39,"tv":4278.68,"id":9625043},{"atl":[[1.39,202]],"id":9625043}],"con":true,"img":false}]}
{"op":"mcm","clk":"1350003940","pt":1588415218918,"mc":[{"id":"1.170370562","rc":[{"trd":[[1.39,4283.4]],"ltp":1.39,"tv":4283.4,"id":9625043},{"atl":[[1.39,199.64]],"id":9625043}],"con":true,"img":false}]}
{"op":"mcm","clk":"1350003941","pt":1588415219022,"mc":[{"id":"1.170370562","rc":[{"trd":[[1.36,571.91]],"ltp":1.36,"tv":571.91,"id":9625043},{"atb":[[1.36,120.07]],"id":9625043}],"con":true,"img":false}]}
{"op":"mcm","clk":"1350003991","pt":1588415220635,"mc":[{"id":"1.170370562","rc":[{"atl":[[1.4,0]],"id":9625043}],"con":true,"img":false}]}
{"op":"mcm","clk":"1350004001","pt":1588415220998,"mc":[{"id":"1.170370562","rc":[{"trd":[[1.39,4284.39]],"ltp":1.39,"tv":4284.39,"id":9625043},{"atl":[[1.39,199.14]],"id":9625043}],"con":true,"img":false}]}
{"op":"mcm","clk":"1350004018","pt":1588415221515,"mc":[{"id":"1.170370562","rc":[{"trd":[[1.39,4285.11]],"ltp":1.39,"tv":4285.11,"id":9625043},{"atl":[[1.39,198.42]],"id":9625043},{"trd":[[3.55,13.03]],"ltp":3.55,"tv":13.03,"id":9631798}],"con":true,"img":false}]}
{"op":"mcm","clk":"1350004032","pt":1588415222135,"mc":[{"id":"1.170370562","rc":[{"atl":[[1.39,21.11]],"id":9625043}],"con":true,"img":false}]}
{"op":"mcm","clk":"1350004062","pt":1588415223537,"mc":[{"id":"1.170370562","rc":[{"atb":[[1.36,112.97]],"id":9625043}],"con":true,"img":false}]}
{"op":"mcm","clk":"1350004069","pt":1588415223692,"mc":[{"id":"1.170370562","rc":[{"atb":[[1.35,177.3]],"id":9625043}],"con":true,"img":false}]}
{"op":"mcm","clk":"1350004072","pt":1588415223797,"mc":[{"id":"1.170370562","rc":[{"atb":[[1.28,177.3]],"id":9625043}],"con":true,"img":false}]}
{"op":"mcm","clk":"1350004089","pt":1588415224322,"mc":[{"id":"1.170370562","rc":[{"atb":[[1.38,66.48]],"id":9625043}],"con":true,"img":false}]}
{"op":"mcm","clk":"1350004097","pt":1588415224525,"mc":[{"id":"1.170370562","rc":[{"atb":[[1.17,500],[1.38,132.97]],"id":9625043}],"con":true,"img":false}]}
{"op":"mcm","clk":"1350004121","pt":1588415225300,"mc":[{"id":"1.170370562","rc":[{"atb":[[1.28,677.3]],"id":9625043}],"con":true,"img":false}]}
{"op":"mcm","clk":"1350004126","pt":1588415225507,"mc":[{"id":"1.170370562","rc":[{"trd":[[1.39,4327.35]],"ltp":1.39,"tv":4327.35,"id":9625043},{"atb":[[1.4,34.27]],"id":9625043},{"atl":[[1.39,0]],"id":9625043}],"con":true,"img":false}]}
{"op":"mcm","clk":"1350004128","pt":1588415225610,"mc":[{"id":"1.170370562","rc":[{"atb":[[1.29,333]],"id":9625043}],"con":true,"img":false}]}
{"op":"mcm","clk":"1350004135","pt":1588415225922,"mc":[{"id":"1.170370562","rc":[{"atb":[[1.28,1010.3]],"id":9625043}],"con":true,"img":false}]}
{"op":"mcm","clk":"1350004167","pt":1588415227127,"mc":[{"id":"1.170370562","rc":[{"atb":[[1.36,0]],"id":9625043}],"con":true,"img":false}]}
{"op":"mcm","clk":"1350004186","pt":1588415227709,"mc":[{"id":"1.170370562","rc":[{"atl":[[1.41,177.3]],"id":9625043}],"con":true,"img":false}]}
{"op":"mcm","clk":"1350004233","pt":1588415229220,"mc":[{"id":"1.170370562","rc":[{"atb":[[1.39,7.09]],"id":9625043}],"con":true,"img":false}]}
{"op":"mcm","clk":"1350004280","pt":1588415230826,"mc":[{"id":"1.170370562","rc":[{"atl":[[1.42,0]],"id":9625043}],"con":true,"img":false}]}
{"op":"mcm","clk":"1350004333","pt":1588415232228,"mc":[{"id":"1.170370562","rc":[{"trd":[[1.4,5999.79]],"ltp":1.4,"tv":5999.79,"id":9625043},{"atb":[[1.4,0]],"id":9625043},{"atl":[[1.4,143.02]],"id":9625043}],"con":true,"img":false}]}
{"op":"mcm","clk":"1350004359","pt":1588415232850,"mc":[{"id":"1.170370562","rc":[{"atl":[[1.61,0]],"id":9625043}],"con":true,"img":false}]}
{"op":"mcm","clk":"1350004377","pt":1588415233419,"mc":[{"id":"1.170370562","rc":[{"atl":[[1.41,0]],"id":9625043}],"con":true,"img":false}]}
{"op":"mcm","clk":"1350004396","pt":1588415233934,"mc":[{"id":"1.170370562","rc":[{"atb":[[1.37,3.5]],"id":9625043}],"con":true,"img":false}]}
{"op":"mcm","clk":"1350004408","pt":1588415234247,"mc":[{"id":"1.170370562","rc":[{"atl":[[1.79,0]],"id":9625043}],"con":true,"img":false}]}
{"op":"mcm","clk":"1350004468","pt":1588415235945,"mc":[{"id":"1.170370562","rc":[{"atl":[[1.49,265.95]],"id":9625043}],"con":true,"img":false}]}
{"op":"mcm","clk":"1350004511","pt":1588415237454,"mc":[{"id":"1.170370562","rc":[{"atb":[[1.35,0]],"id":9625043}],"con":true,"img":false}]}
{"op":"mcm","clk":"1350004559","pt":1588415239212,"mc":[{"id":"1.170370562","rc":[{"atb":[[1.28,677.3]],"id":9625043}],"con":true,"img":false}]}
{"op":"mcm","clk":"1350004567","pt":1588415239520,"mc":[{"id":"1.170370562","rc":[{"atl":[[1.4,145.59]],"id":9625043}],"con":true,"img":false}]}
{"op":"mcm","clk":"1350004596","pt":1588415240661,"mc":[{"id":"1.170370562","rc":[{"trd":[[1.37,1909.93],[1.39,4341.53],[1.38,702.95]],"ltp":1.37,"tv":6954.41,"id":9625043},{"atb":[[1.38,0],[1.37,0],[1.39,0]],"id":9625043},{"atl":[[1.37,1115.42]],"id":9625043}],"con":true,"img":false}]}
{"op":"mcm","clk":"1350004613","pt":1588415241231,"mc":[{"id":"1.170370562","rc":[{"atl":[[1.37,0]],"id":9625043}],"con":true,"img":false}]}
{"op":"mcm","clk":"1350004624","pt":1588415241645,"mc":[{"id":"1.170370562","rc":[{"trd":[[1.4,6055.2]],"ltp":1.4,"tv":6055.2,"id":9625043},{"atl":[[1.4,90.19],[1.38,492.02]],"id":9625043},{"trd":[[3.5,1052.5]],"ltp":3.5,"tv":1052.5,"id":9631798}],"con":true,"img":false}]}
{"op":"mcm","clk":"1350004638","pt":1588415242323,"mc":[{"id":"1.170370562","rc":[{"atl":[[3.25,0]],"id":9625043}],"con":true,"img":false}]}
{"op":"mcm","clk":"1350004645","pt":1588415242529,"mc":[{"id":"1.170370562","rc":[{"atl":[[1.38,0]],"id":9625043}],"con":true,"img":false}]}
{"op":"mcm","clk":"1350004648","pt":1588415242633,"mc":[{"id":"1.170370562","rc":[{"atb":[[1.28,177.3]],"id":9625043}],"con":true,"img":false}]}
{"op":"mcm","clk":"1350004652","pt":1588415242736,"mc":[{"id":"1.170370562","rc":[{"atb":[[1.3,333]],"id":9625043}],"con":true,"img":false}]}
{"op":"mcm","clk":"1350004656","pt":1588415242942,"mc":[{"id":"1.170370562","rc":[{"atl":[[3.55,129.45]],"id":9631798}],"con":true,"img":false}]}
{"op":"mcm","clk":"1350004672","pt":1588415243561,"mc":[{"id":"1.170370562","rc":[{"trd":[[1.39,4518.84]],"ltp":1.39,"tv":4518.84,"id":9625043},{"trd":[[3.55,82.45]],"ltp":3.55,"tv":82.45,"id":9631798},{"atl":[[3.55,60.03]],"id":9631798}],"con":true,"img":false}]}
{"op":"mcm","clk":"1350004681","pt":1588415243923,"mc":[{"id":"1.170370562","rc":[{"atl":[[1.75,10.57]],"id":9625043}],"con":true,"img":false}]}
{"op":"mcm","clk":"1350004707","pt":1588415244642,"mc":[{"id":"1.170370562","rc":[{"atb":[[1.26,240]],"id":9625043}],"con":true,"img":false}]}
{"op":"mcm","clk":"1350004734","pt":1588415245728,"mc":[{"id":"1.170370562","rc":[{"atb":[[1.24,0]],"id":9625043}],"con":true,"img":false}]}
{"op":"mcm","clk":"1350004806","pt":1588415247848,"mc":[{"id":"1.170370562","rc":[{"atb":[[1.35,31.4]],"id":9625043}],"con":true,"img":false}]}
{"op":"mcm","clk":"1350004856","pt":1588415248954,"mc":[{"id":"1.170370562","rc":[{"atb":[[1.35,208.7]],"id":9625043}],"con":true,"img":false}]}
{"op":"mcm","clk":"1350004875","pt":1588415249731,"mc":[{"id":"1.170370562","rc":[{"trd":[[1.4,6235.59]],"ltp":1.4,"tv":6235.59,"id":9625043},{"atb":[[1.4,9.8]],"id":9625043},{"atl":[[1.4,0]],"id":9625043}],"con":true,"img":false}]}
{"op":"mcm","clk":"1350004898","pt":1588415250867,"mc":[{"id":"1.170370562","rc":[{"trd":[[1.39,4575.53],[1.4,6255.18]],"ltp":1.39,"tv":10830.71,"id":9625043},{"atb":[[1.4,0]],"id":9625043},{"trd":[[3.55,104.65]],"ltp":3.55,"tv":104.65,"id":9631798},{"atl":[[3.55,37.83]],"id":9631798}],"con":true,"img":false}]}
{"op":"mcm","clk":"1350004900","pt":1588415250972,"mc":[{"id":"1.170370562","rc":[{"trd":[[1.39,4642.02]],"ltp":1.39,"tv":4642.02,"id":9625043},{"trd":[[3.55,130.68]],"ltp":3.55,"tv":130.68,"id":9631798},{"atl":[[3.55,11.8]],"id":9631798}],"con":true,"img":false}]}
{"op":"mcm","clk":"1350004907","pt":1588415251128,"mc":[{"id":"1.170370562","rc":[{"trd":[[1.39,4672.16]],"ltp":1.39,"tv":4672.16,"id":9625043},{"atl":[[1.38,36.34]],"id":9625043},{"trd":[[3.55,142.48]],"ltp":3.55,"tv":142.48,"id":9631798},{"atl":[[3.55,0]],"id":9631798}],"con":true,"img":false}]}
{"op":"mcm","clk":"1350004915","pt":1588415251336,"mc":[{"id":"1.170370562","rc":[{"atl":[[1.38,102.83]],"id":9625043}],"con":true,"img":false}]}
{"op":"mcm","clk":"1350004921","pt":1588415251440,"mc":[{"id":"1.170370562","rc":[{"atl":[[1.38,169.32]],"id":9625043}],"con":true,"img":false}]}
{"op":"mcm","clk":"1350004940","pt":1588415252063,"mc":[{"id":"1.170370562","rc":[{"atb":[[1.35,448.7]],"id":9625043}],"con":true,"img":false}]}
{"op":"mcm","clk":"1350004956","pt":1588415252326,"mc":[{"id":"1.170370562","rc":[{"atb":[[1.35,208.7]],"id":9625043}],"con":true,"img":false}]}
{"op":"mcm","clk":"1350005012","pt":1588415254343,"mc":[{"id":"1.170370562","rc":[{"atb":[[1.32,0]],"id":9625043}],"con":true,"img":false}]}
{"op":"mcm","clk":"1350005031","pt":1588415254967,"mc":[{"id":"1.170370562","rc":[{"atl":[[1.49,0]],"id":9625043}],"con":true,"img":false}]}
{"op":"mcm","clk":"1350005064","pt":1588415255955,"mc":[{"id":"1.170370562","rc":[{"atl":[[1.38,235.81]],"id":9625043}],"con":true,"img":false}]}
{"op":"mcm","clk":"1350005071","pt":1588415256058,"mc":[{"id":"1.170370562","rc":[{"atb":[[1.3,0]],"id":9625043},{"atl":[[1.39,0.1]],"id":9625043}],"con":true,"img":false}]}
{"op":"mcm","clk":"1350005079","pt":1588415256268,"mc":[{"id":"1.170370562","rc":[{"atl":[[1.38,302.3]],"id":9625043}],"con":true,"img":false}]}
{"op":"mcm","clk":"1350005091","pt":1588415256529,"mc":[{"id":"1.170370562","rc":[{"atl":[[1.38,794.32]],"id":9625043}],"con":true,"img":false}]}
{"op":"mcm","clk":"1350005094","pt":1588415256636,"mc":[{"id":"1.170370562","rc":[{"atl":[[1.38,860.81]],"id":9625043},{"atb":[[3.35,7.23]],"id":9631798}],"con":true,"img":false}]}
{"op":"mcm","clk":"1350005123","pt":1588415257934,"mc":[{"id":"1.170370562","rc":[{"atb":[[3.35,0]],"id":9631798}],"con":true,"img":false}]}
{"op":"mcm","clk":"1350005124","pt":1588415258036,"mc":[{"id":"1.170370562","rc":[{"atb":[[1.37,66.48]],"id":9625043},{"atl":[[1.42,177.3]],"id":9625043}],"con":true,"img":false}]}
{"op":"mcm","clk":"1350005137","pt":1588415258349,"mc":[{"id":"1.170370562","rc":[{"atb":[[1.37,132.97]],"id":9625043}],"con":true,"img":false}]}
{"op":"mcm","clk":"1350005144","pt":1588415258555,"mc":[{"id":"1.170370562","rc":[{"atb":[[1.27,0],[1.29,0]],"id":9625043}],"con":true,"img":false}]}
{"op":"mcm","clk":"1350005157","pt":1588415258967,"mc":[{"id":"1.170370562","rc":[{"atl":[[1.42,443.26]],"id":9625043}],"con":true,"img":false}]}
{"op":"mcm","clk":"1350005162","pt":1588415259073,"mc":[{"id":"1.170370562","rc":[{"trd":[[1.37,1925.7]],"ltp":1.37,"tv":1925.7,"id":9625043},{"atb":[[1.37,125.09]],"id":9625043}],"con":true,"img":false}]}
{"op":"mcm","clk":"1350005167","pt":1588415259177,"mc":[{"id":"1.170370562","rc":[{"atl":[[1.5,87.61]],"id":9625043}],"con":true,"img":false}]}
{"op":"mcm","clk":"1350005171","pt":1588415259280,"mc":[{"id":"1.170370562","rc":[{"trd":[[1.38,2102.94]],"ltp":1.38,"tv":2102.94,"id":9625043},{"atl":[[1.38,160.82]],"id":9625043}],"con":true,"img":false}]}
{"op":"mcm","clk":"1350005214","pt":1588415260677,"mc":[{"id":"1.170370562","rc":[{"atb":[[1.24,240]],"id":9625043}],"con":true,"img":false}]}
{"op":"mcm","clk":"1350005233","pt":1588415261142,"mc":[{"id":"1.170370562","rc":[{"trd":[[1.38,2108.6]],"ltp":1.38,"tv":2108.6,"id":9625043},{"atb":[[1.24,740]],"id":9625043},{"atl":[[1.38,157.99]],"id":9625043}],"con":true,"img":false}]}
{"op":"mcm","clk":"1350005241","pt":1588415261453,"mc":[{"id":"1.170370562","rc":[{"atb":[[1.24,1240]],"id":9625043}],"con":true,"img":false}]}
{"op":"mcm","clk":"1350005250","pt":1588415261661,"mc":[{"id":"1.170370562","rc":[{"atb":[[1.18,480]],"id":9625043}],"con":true,"img":false}]}
{"op":"mcm","clk":"1350005270","pt":1588415262173,"mc":[{"id":"1.170370562","rc":[{"atb":[[1.19,240]],"id":9625043}],"con":true,"img":false}]}
{"op":"mcm","clk":"1350005321","pt":1588415263667,"mc":[{"id":"1.170370562","rc":[{"atb":[[1.35,275.19]],"id":9625043}],"con":true,"img":false}]}
{"op":"mcm","clk":"1350005330","pt":1588415264184,"mc":[{"id":"1.170370562","rc":[{"trd":[[1.38,2119.18]],"ltp":1.38,"tv":2119.18,"id":9625043},{"atb":[[1.3,893.4]],"id":9625043},{"atl":[[1.38,152.7]],"id":9625043}],"con":true,"img":false}]}
{"op":"mcm","clk":"1350005353","pt":1588415264752,"mc":[{"id":"1.170370562","rc":[{"atb":[[1.37,525.68]],"id":9625043}],"con":true,"img":false}]}
{"op":"mcm","clk":"1350005354","pt":1588415264855,"mc":[{"id":"1.170370562","rc":[{"trd":[[1.38,2360.89]],"ltp":1.38,"tv":2360.89,"id":9625043},{"atb":[[1.25,333]],"id":9625043},{"atl":[[1.38,31.85]],"id":9625043}],"con":true,"img":false}]}
{"op":"mcm","clk":"1350005370","pt":1588415265371,"mc":[{"id":"1.170370562","rc":[{"atb":[[1.23,573]],"id":9625043}],"con":true,"img":false}]}
{"op":"mcm","clk":"1350005388","pt":1588415265944,"mc":[{"id":"1.170370562","rc":[{"atb":[[1.36,66.48]],"id":9625043}],"con":true,"img":false}]}
{"op":"mcm","clk":"1350005398","pt":1588415266358,"mc":[{"id":"1.170370562","rc":[{"atb":[[1.21,1573]],"id":9625043}],"con":true,"img":false}]}
{"op":"mcm","clk":"1350005406","pt":1588415266564,"mc":[{"id":"1.170370562","rc":[{"atb":[[1.37,528.52]],"id":9625043}],"con":true,"img":false}]}
{"op":"mcm","clk":"1350005422","pt":1588415267240,"mc":[{"id":"1.170370562","rc":[{"trd":[[1.37,2029.33]],"ltp":1.37,"tv":2029.33,"id":9625043},{"atb":[[1.37,476.71]],"id":9625043}],"con":true,"img":false}]}
{"op":"mcm","clk":"1350005432","pt":1588415267651,"mc":[{"id":"1.170370562","rc":[{"atb":[[1.37,543.2]],"id":9625043}],"con":true,"img":false}]}
{"op":"mcm","clk":"1350005444","pt":1588415267857,"mc":[{"id":"1.170370562","rc":[{"atb":[[1.37,609.68]],"id":9625043}],"con":true,"img":false}]}
{"op":"mcm","clk":"1350005451","pt":1588415268063,"mc":[{"id":"1.170370562","rc":[{"atb":[[1.37,676.17]],"id":9625043}],"con":true,"img":false}]}
{"op":"mcm","clk":"1350005456","pt":1588415268270,"mc":[{"id":"1.170370562","rc":[{"atb":[[1.37,742.66]],"id":9625043}],"con":true,"img":false}]}
{"op":"mcm","clk":"1350005466","pt":1588415268581,"mc":[{"id":"1.170370562","rc":[{"trd":[[1.38,2366.05]],"ltp":1.38,"tv":2366.05,"id":9625043},{"atb":[[1.37,809.15]],"id":9625043},{"atl":[[1.38,29.27]],"id":9625043}],"con":true,"img":false}]}
{"op":"mcm","clk":"1350005474","pt":1588415268787,"mc":[{"id":"1.170370562","rc":[{"atb":[[1.37,875.64]],"id":9625043}],"con":true,"img":false}]}
{"op":"mcm","clk":"1350005480","pt":1588415269043,"mc":[{"id":"1.170370562","rc":[{"trd":[[1.37,2034.49]],"ltp":1.37,"tv":2034.49,"id":9625043},{"atb":[[1.37,873.06]],"id":9625043}],"con":true,"img":false}]}
{"op":"mcm","clk":"1350005487","pt":1588415269560,"mc":[{"id":"1.170370562","rc":[{"atb":[[1.37,878.39]],"id":9625043}],"con":true,"img":false}]}
{"op":"mcm","clk":"1350005495","pt":1588415269977,"mc":[{"id":"1.170370562","rc":[{"atb":[[1.37,965.23]],"id":9625043}],"con":true,"img":false}]}
{"op":"mcm","clk":"1350005510","pt":1588415270342,"mc":[{"id":"1.170370562","rc":[{"atb":[[1.27,177.3]],"id":9625043}],"con":true,"img":false}]}
{"op":"mcm","clk":"1350005531","pt":1588415271167,"mc":[{"id":"1.170370562","rc":[{"trd":[[1.38,2366.28]],"ltp":1.38,"tv":2366.28,"id":9625043},{"atl":[[1.38,29.15]],"id":9625043}],"con":true,"img":false}]}
{"op":"mcm","clk":"1350005536","pt":1588415271268,"mc":[{"id":"1.170370562","rc":[{"atl":[[1.44,90.21]],"id":9625043}],"con":true,"img":false}]}
{"op":"mcm","clk":"1350005554","pt":1588415272049,"mc":[{"id":"1.170370562","rc":[{"atb":[[1.36,0]],"id":9625043}],"con":true,"img":false}]}
{"op":"mcm","clk":"1350005599","pt":1588415273654,"mc":[{"id":"1.170370562","rc":[{"trd":[[1.38,2416.28]],"ltp":1.38,"tv":2416.28,"id":9625043},{"atl":[[1.38,4.15]],"id":9625043}],"con":true,"img":false}]}
{"op":"mcm","clk":"1350005610","pt":1588415273860,"mc":[{"id":"1.170370562","rc":[{"trd":[[1.38,2417.7]],"ltp":1.38,"tv":2417.7,"id":9625043},{"atl":[[1.38,3.44]],"id":9625043}],"con":true,"img":false}]}
{"op":"mcm","clk":"1350005622","pt":1588415274275,"mc":[{"id":"1.170370562","rc":[{"atl":[[1.42,683.26]],"id":9625043}],"con":true,"img":false}]}
{"op":"mcm","clk":"1350005629","pt":1588415274377,"mc":[{"id":"1.170370562","rc":[{"atb":[[1.01,1102.13]],"id":9631798}],"con":true,"img":false}]}
{"op":"mcm","clk":"1350005637","pt":1588415274585,"mc":[{"id":"1.170370562","rc":[{"atl":[[1.41,240]],"id":9625043},{"atb":[[1.01,1100.14]],"id":9631798}],"con":true,"img":false}]}
{"op":"mcm","clk":"1350005642","pt":1588415274790,"mc":[{"id":"1.170370562","rc":[{"atb":[[1.01,1100.13]],"id":9631798}],"con":true,"img":false}]}
{"op":"mcm","clk":"1350005664","pt":1588415275465,"mc":[{"id":"1.170370562","rc":[{"trd":[[1.38,2422.85]],"ltp":1.38,"tv":2422.85,"id":9625043},{"atl":[[1.41,480],[1.38,0.86]],"id":9625043}],"con":true,"img":false}]}
{"op":"mcm","clk":"1350005669","pt":1588415275570,"mc":[{"id":"1.170370562","rc":[{"atl":[[1.42,443.26]],"id":9625043}],"con":true,"img":false}]}
{"op":"mcm","clk":"1350005677","pt":1588415275774,"mc":[{"id":"1.170370562","rc":[{"trd":[[1.38,2424.59]],"ltp":1.38,"tv":2424.59,"id":9625043},{"atb":[[1.38,272.34]],"id":9625043},{"atl":[[1.38,0]],"id":9625043}],"con":true,"img":false}]}
{"op":"mcm","clk":"1350005683","pt":1588415275981,"mc":[{"id":"1.170370562","rc":[{"atl":[[1.41,480.34]],"id":9625043}],"con":true,"img":false}]}
{"op":"mcm","clk":"1350005716","pt":1588415276861,"mc":[{"id":"1.170370562","rc":[{"trd":[[1.42,1617.11],[1.39,4672.37],[1.41,1642.4]],"ltp":1.42,"tv":7931.87,"id":9625043},{"atl":[[1.39,0],[1.41,0],[1.42,423.7]],"id":9625043}],"con":true,"img":false}]}
{"op":"mcm","clk":"1350005728","pt":1588415277170,"mc":[{"id":"1.170370562","rc":[{"atb":[[1.38,273.37]],"id":9625043}],"con":true,"img":false}]}
{"op":"mcm","clk":"1350005795","pt":1588415279448,"mc":[{"id":"1.170370562","rc":[{"atl":[[3.6,0.23]],"id":9631798}],"con":true,"img":false}]}
{"op":"mcm","clk":"1350005804","pt":1588415279860,"mc":[{"id":"1.170370562","rc":[{"atb":[[3.45,0.01]],"id":9631798}],"con":true,"img":false}]}
{"op":"mcm","clk":"1350005835","pt":1588415280998,"mc":[{"id":"1.170370562","rc":[{"atb":[[1.38,339.86]],"id":9625043}],"con":true,"img":false}]}
{"op":"mcm","clk":"1350005839","pt":1588415281163,"mc":[{"id":"1.170370562","rc":[{"atb":[[1.38,406.35]],"id":9625043}],"con":true,"img":false}]}
{"op":"mcm","clk":"1350005845","pt":1588415281368,"mc":[{"id":"1.170370562","rc":[{"atb":[[1.38,472.84]],"id":9625043}],"con":true,"img":false}]}
{"op":"mcm","clk":"1350005851","pt":1588415281573,"mc":[{"id":"1.170370562","rc":[{"atb":[[1.38,539.33]],"id":9625043}],"con":true,"img":false}]}
{"op":"mcm","clk":"1350005856","pt":1588415281779,"mc":[{"id":"1.170370562","rc":[{"atb":[[1.38,605.82]],"id":9625043}],"con":true,"img":false}]}
{"op":"mcm","clk":"1350005859","pt":1588415281984,"mc":[{"id":"1.170370562","rc":[{"atb":[[1.38,672.31]],"id":9625043}],"con":true,"img":false}]}
{"op":"mcm","clk":"1350005866","pt":1588415282293,"mc":[{"id":"1.170370562","rc":[{"atb":[[1.38,738.8]],"id":9625043}],"con":true,"img":false}]}
{"op":"mcm","clk":"1350005872","pt":1588415282397,"mc":[{"id":"1.170370562","rc":[{"trd":[[1.38,3902.81]],"ltp":1.38,"tv":3902.81,"id":9625043},{"atb":[[1.38,0]],"id":9625043},{"atl":[[1.38,10.59]],"id":9625043},{"trd":[[3.6,0.23]],"ltp":3.6,"tv":0.23,"id":9631798},{"atl":[[3.6,0]],"id":9631798}],"con":true,"img":false}]}
{"op":"mcm","clk":"1350005881","pt":1588415282660,"mc":[{"id":"1.170370562","rc":[{"atb":[[1.31,0]],"id":9625043},{"atl":[[1.38,0]],"id":9625043}],"con":true,"img":false}]}
{"op":"mcm","clk":"1350005882","pt":1588415282764,"mc":[{"id":"1.170370562","rc":[{"atl":[[1.4,492.02]],"id":9625043}],"con":true,"img":false}]}
{"op":"mcm","clk":"1350005887","pt":1588415282971,"mc":[{"id":"1.170370562","rc":[{"atb":[[1.37,495.6]],"id":9625043}],"con":true,"img":false}]}
{"op":"mcm","clk":"1350005892","pt":1588415283284,"mc":[{"id":"1.170370562","rc":[{"atb":[[1.38,66.48]],"id":9625043}],"con":true,"img":false}]}
{"op":"mcm","clk":"1350005895","pt":1588415283391,"mc":[{"id":"1.170370562","rc":[{"atb":[[1.39,240]],"id":9625043}],"con":true,"img":false}]}
{"op":"mcm","clk":"1350005910","pt":1588415283865,"mc":[{"id":"1.170370562","rc":[{"atl":[[1.41,66.48]],"id":9625043}],"con":true,"img":false}]}
{"op":"mcm","clk":"1350005918","pt":1588415284083,"mc":[{"id":"1.170370562","rc":[{"atl":[[1.41,132.97]],"id":9625043}],"con":true,"img":false}]}
{"op":"mcm","clk":"1350005933","pt":1588415284415,"mc":[{"id":"1.170370562","rc":[{"atb":[[1.39,0]],"id":9625043},{"atl":[[1.41,199.46]],"id":9625043}],"con":true,"img":false}]}
{"op":"mcm","clk":"1350005939","pt":1588415284592,"mc":[{"id":"1.170370562","rc":[{"atb":[[1.38,0]],"id":9625043},{"atb":[[1.97,0]],"id":9631798}],"con":true,"img":false}]}
{"op":"mcm","clk":"1350005942","pt":1588415284697,"mc":[{"id":"1.170370562","rc":[{"atl":[[1.41,332.44]],"id":9625043}],"con":true,"img":false}]}
{"op":"mcm","clk":"1350005950","pt":1588415284899,"mc":[{"id":"1.170370562","rc":[{"atl":[[1.41,398.93]],"id":9625043}],"con":true,"img":false}]}
{"op":"mcm","clk":"1350005961","pt":1588415285366,"mc":[{"id":"1.170370562","rc":[{"atl":[[1.45,265.95]],"id":9625043}],"con":true,"img":false}]}
{"op":"mcm","clk":"1350005989","pt":1588415286291,"mc":[{"id":"1.170370562","rc":[{"atl":[[1.44,134.01]],"id":9625043}],"con":true,"img":false}]}
{"op":"mcm","clk":"1350006007","pt":1588415286806,"mc":[{"id":"1.170370562","rc":[{"atb":[[1.27,510.3]],"id":9625043}],"con":true,"img":false}]}
{"op":"mcm","clk":"1350006021","pt":1588415287370,"mc":[{"id":"1.170370562","rc":[{"atl":[[1.45,0]],"id":9625043}],"con":true,"img":false}]}
{"op":"mcm","clk":"1350006059","pt":1588415288763,"mc":[{"id":"1.170370562","rc":[{"trd":[[1.37,2090.48]],"ltp":1.37,"tv":2090.48,"id":9625043},{"atb":[[1.37,467.6]],"id":9625043}],"con":true,"img":false}]}
{"op":"mcm","clk":"1350006066","pt":1588415289072,"mc":[{"id":"1.170370562","rc":[{"atb":[[1.01,1102.13]],"id":9631798}],"con":true,"img":false}]}
{"op":"mcm","clk":"1350006072","pt":1588415289276,"mc":[{"id":"1.170370562","rc":[{"atb":[[1.01,1100.14]],"id":9631798}],"con":true,"img":false}]}
{"op":"mcm","clk":"1350006080","pt":1588415289483,"mc":[{"id":"1.170370562","rc":[{"atb":[[1.01,1100.13]],"id":9631798}],"con":true,"img":false}]}
{"op":"mcm","clk":"1350006086","pt":1588415289790,"mc":[{"id":"1.170370562","rc":[{"atb":[[2.12,363.96]],"id":9631798}],"con":true,"img":false}]}
{"op":"mcm","clk":"1350006092","pt":1588415289997,"mc":[{"id":"1.170370562","rc":[{"trd":[[1.4,7239.22]],"ltp":1.4,"tv":7239.22,"id":9625043},{"atb":[[1.4,237.06]],"id":9625043},{"atl":[[1.4,0]],"id":9625043}],"con":true,"img":false}]}
{"op":"mcm","clk":"1350006099","pt":1588415290203,"mc":[{"id":"1.170370562","rc":[{"atl":[[3.6,0.26]],"id":9631798}],"con":true,"img":false}]}
{"op":"mcm","clk":"1350006114","pt":1588415290769,"mc":[{"id":"1.170370562","rc":[{"atb":[[1.4,0]],"id":9625043}],"con":true,"img":false}]}
{"op":"mcm","clk":"1350006127","pt":1588415291281,"mc":[{"id":"1.170370562","rc":[{"atb":[[1.01,1102.13]],"id":9631798}],"con":true,"img":false}]}
{"op":"mcm","clk":"1350006134","pt":1588415291487,"mc":[{"id":"1.170370562","rc":[{"atb":[[1.27,750.3]],"id":9625043}],"con":true,"img":false}]}
{"op":"mcm","clk":"1350006139","pt":1588415291594,"mc":[{"id":"1.170370562","rc":[{"atb":[[1.01,1100.14]],"id":9631798}],"con":true,"img":false}]}
{"op":"mcm","clk":"1350006143","pt":1588415291697,"mc":[{"id":"1.170370562","rc":[{"atb":[[1.01,1100.13]],"id":9631798}],"con":true,"img":false}]}
{"op":"mcm","clk":"1350006175","pt":1588415292565,"mc":[{"id":"1.170370562","rc":[{"atb":[[1.27,990.3]],"id":9625043}],"con":true,"img":false}]}
{"op":"mcm","clk":"1350006228","pt":1588415294589,"mc":[{"id":"1.170370562","rc":[{"trd":[[3.6,0.25]],"ltp":3.6,"tv":0.25,"id":9631798},{"atl":[[3.6,0.25]],"id":9631798}],"con":true,"img":false}]}
{"op":"mcm","clk":"1350006234","pt":1588415294792,"mc":[{"id":"1.170370562","rc":[{"atb":[[1.01,1102.13]],"id":9631798}],"con":true,"img":false}]}
{"op":"mcm","clk":"1350006242","pt":1588415294998,"mc":[{"id":"1.170370562","rc":[{"atb":[[1.01,1100.14]],"id":9631798}],"con":true,"img":false}]}
{"op":"mcm","clk":"1350006253","pt":1588415295212,"mc":[{"id":"1.170370562","rc":[{"atb":[[1.39,495.55]],"id":9625043},{"atb":[[1.01,1100.13]],"id":9631798}],"con":true,"img":false}]}
{"op":"mcm","clk":"1350006265","pt":1588415295880,"mc":[{"id":"1.170370562","rc":[{"atb":[[1.01,1102.13]],"id":9631798}],"con":true,"img":false}]}
{"op":"mcm","clk":"1350006271","pt":1588415296087,"mc":[{"id":"1.170370562","rc":[{"atb":[[1.01,1100.14]],"id":9631798}],"con":true,"img":false}]}
{"op":"mcm","clk":"1350006274","pt":1588415296187,"mc":[{"id":"1.170370562","rc":[{"atl":[[1.4,177.3]],"id":9625043}],"con":true,"img":false}]}
{"op":"mcm","clk":"1350006276","pt":1588415296293,"mc":[{"id":"1.170370562","rc":[{"atb":[[1.24,240]],"id":9625043},{"atb":[[1.01,1100.13]],"id":9631798}],"con":true,"img":false}]}
{"op":"mcm","clk":"1350006283","pt":1588415296499,"mc":[{"id":"1.170370562","rc":[{"atb":[[1.01,1102.13]],"id":9631798}],"con":true,"img":false}]}
{"op":"mcm","clk":"1350006289","pt":1588415296704,"mc":[{"id":"1.170370562","rc":[{"atb":[[1.27,657.3]],"id":9625043},{"atb":[[1.01,1100.14]],"id":9631798}],"con":true,"img":false}]}
{"op":"mcm","clk":"1350006296","pt":1588415296806,"mc":[{"id":"1.170370562","rc":[{"trd":[[3.6,0.27]],"ltp":3.6,"tv":0.27,"id":9631798},{"atl":[[3.6,0.24]],"id":9631798}],"con":true,"img":false}]}
{"op":"mcm","clk":"1350006298","pt":1588415296905,"mc":[{"id":"1.170370562","rc":[{"atb":[[1.01,1100.13]],"id":9631798}],"con":true,"img":false}]}
{"op":"mcm","clk":"1350006300","pt":1588415297007,"mc":[{"id":"1.170370562","rc":[{"trd":[[1.4,7294.62]],"ltp":1.4,"tv":7294.62,"id":9625043},{"atl":[[1.4,149.6]],"id":9625043}],"con":true,"img":false}]}
{"op":"mcm","clk":"1350006304","pt":1588415297109,"mc":[{"id":"1.170370562","rc":[{"atb":[[1.21,573]],"id":9625043}],"con":true,"img":false}]}
{"op":"mcm","clk":"1350006314","pt":1588415297518,"mc":[{"id":"1.170370562","rc":[{"atl":[[1.4,649.6]],"id":9625043}],"con":true,"img":false}]}
{"op":"mcm","clk":"1350006318","pt":1588415297573,"mc":[{"id":"1.170370562","rc":[{"atb":[[1.38,240]],"id":9625043}],"con":true,"img":false}]}
{"op":"mcm","clk":"1350006327","pt":1588415297981,"mc":[{"id":"1.170370562","rc":[{"trd":[[1.39,5026.98]],"ltp":1.39,"tv":5026.98,"id":9625043},{"atb":[[1.39,318.25]],"id":9625043}],"con":true,"img":false}]}
{"op":"mcm","clk":"1350006336","pt":1588415298492,"mc":[{"id":"1.170370562","rc":[{"atb":[[1.01,1102.13]],"id":9631798}],"con":true,"img":false}]}
{"op":"mcm","clk":"1350006340","pt":1588415298599,"mc":[{"id":"1.170370562","rc":[{"trd":[[1.4,7765.36]],"ltp":1.4,"tv":7765.36,"id":9625043},{"atl":[[1.4,414.24]],"id":9625043}],"con":true,"img":false}]}
{"op":"mcm","clk":"1350006346","pt":1588415298698,"mc":[{"id":"1.170370562","rc":[{"atb":[[1.01,1100.14]],"id":9631798}],"con":true,"img":false}]}
{"op":"mcm","clk":"1350006350","pt":1588415298904,"mc":[{"id":"1.170370562","rc":[{"atb":[[1.01,1100.13]],"id":9631798}],"con":true,"img":false}]}
{"op":"mcm","clk":"1350006354","pt":1588415299112,"mc":[{"id":"1.170370562","rc":[{"trd":[[1.4,8097.75]],"ltp":1.4,"tv":8097.75,"id":9625043},{"atl":[[1.4,81.85]],"id":9625043},{"trd":[[3.5,1185.45]],"ltp":3.5,"tv":1185.45,"id":9631798}],"con":true,"img":false}]}
{"op":"mcm","clk":"1350006360","pt":1588415299315,"mc":[{"id":"1.170370562","rc":[{"atl":[[1.4,0]],"id":9625043}],"con":true,"img":false}]}
{"op":"mcm","clk":"1350006368","pt":1588415299522,"mc":[{"id":"1.170370562","rc":[{"atl":[[3.5,10.87]],"id":9631798}],"con":true,"img":false}]}
{"op":"mcm","clk":"1350006373","pt":1588415299576,"mc":[{"id":"1.170370562","rc":[{"atl":[[1.42,157.74]],"id":9625043}],"con":true,"img":false}]}
{"op":"mcm","clk":"1350006393","pt":1588415300298,"mc":[{"id":"1.170370562","rc":[{"trd":[[3.5,1185.47]],"ltp":3.5,"tv":1185.47,"id":9631798},{"atl":[[3.5,10.87]],"id":9631798}],"con":true,"img":false}]}
{"op":"mcm","clk":"1350006405","pt":1588415300603,"mc":[{"id":"1.170370562","rc":[{"atl":[[1.5,131.4]],"id":9625043}],"con":true,"img":false}]}
{"op":"mcm","clk":"1350006413","pt":1588415300807,"mc":[{"id":"1.170370562","rc":[{"trd":[[1.4,8097.86]],"ltp":1.4,"tv":8097.86,"id":9625043},{"trd":[[3.5,1185.52]],"ltp":3.5,"tv":1185.52,"id":9631798},{"atl":[[3.5,10.82]],"id":9631798}],"con":true,"img":false}]}
{"op":"mcm","clk":"1350006422","pt":1588415301117,"mc":[{"id":"1.170370562","rc":[{"atl":[[3.5,28.55]],"id":9631798}],"con":true,"img":false}]}
{"op":"mcm","clk":"1350006431","pt":1588415301419,"mc":[{"id":"1.170370562","rc":[{"atb":[[1.01,1102.13],[3.3,0.01]],"id":9631798},{"atl":[[3.5,46.28]],"id":9631798}],"con":true,"img":false}]}
{"op":"mcm","clk":"1350006432","pt":1588415301521,"mc":[{"id":"1.170370562","rc":[{"trd":[[1.4,8099.64]],"ltp":1.4,"tv":8099.64,"id":9625043},{"trd":[[3.5,1186.23]],"ltp":3.5,"tv":1186.23,"id":9631798},{"atl":[[3.5,45.57]],"id":9631798}],"con":true,"img":false}]}
{"op":"mcm","clk":"1350006435","pt":1588415301726,"mc":[{"id":"1.170370562","rc":[{"atb":[[1.01,1100.14]],"id":9631798}],"con":true,"img":false}]}
{"op":"mcm","clk":"1350006438","pt":1588415301783,"mc":[{"id":"1.170370562","rc":[{"atb":[[1.38,0],[1.34,0]],"id":9625043}],"con":true,"img":false}]}
{"op":"mcm","clk":"1350006440","pt":1588415301886,"mc":[{"id":"1.170370562","rc":[{"atb":[[1.01,1100.13]],"id":9631798}],"con":true,"img":false}]}
{"op":"mcm","clk":"1350006444","pt":1588415301989,"mc":[{"id":"1.170370562","rc":[{"atb":[[3.15,0.01]],"id":9631798}],"con":true,"img":false}]}
{"op":"mcm","clk":"1350006489","pt":1588415303993,"mc":[{"id":"1.170370562","rc":[{"trd":[[1.41,1644.61]],"ltp":1.41,"tv":1644.61,"id":9625043},{"atl":[[1.41,396.72]],"id":9625043},{"trd":[[3.5,1186.25],[3.4,100.94],[3.45,0.03]],"ltp":3.5,"tv":1287.22,"id":9631798},{"atb":[[3.45,0]],"id":9631798},{"atl":[[3.5,45.56]],"id":9631798}],"con":true,"img":false}]}
{"op":"mcm","clk":"1350006498","pt":1588415304195,"mc":[{"id":"1.170370562","rc":[{"trd":[[1.4,8199.64]],"ltp":1.4,"tv":8199.64,"id":9625043},{"trd":[[3.5,1226.24]],"ltp":3.5,"tv":1226.24,"id":9631798},{"atl":[[3.5,5.56]],"id":9631798}],"con":true,"img":false}]}
{"op":"mcm","clk":"1350006504","pt":1588415304403,"mc":[{"id":"1.170370562","rc":[{"atl":[[3.5,23.29]],"id":9631798}],"con":true,"img":false}]}
{"op":"mcm","clk":"1350006517","pt":1588415304713,"mc":[{"id":"1.170370562","rc":[{"atl":[[1.47,265.95]],"id":9625043}],"con":true,"img":false}]}
{"op":"mcm","clk":"1350006529","pt":1588415305224,"mc":[{"id":"1.170370562","rc":[{"atb":[[1.27,177.3]],"id":9625043}],"con":true,"img":false}]}
{"op":"mcm","clk":"1350006537","pt":1588415305588,"mc":[{"id":"1.170370562","rc":[{"atb":[[1.4,240]],"id":9625043}],"con":true,"img":false}]}
{"op":"mcm","clk":"1350006559","pt":1588415306306,"mc":[{"id":"1.170370562","rc":[{"atb":[[1.4,241.17]],"id":9625043}],"con":true,"img":false}]}
{"op":"mcm","clk":"1350006572","pt":1588415306720,"mc":[{"id":"1.170370562","rc":[{"atb":[[1.4,243.02]],"id":9625043}],"con":true,"img":false}]}
{"op":"mcm","clk":"1350006575","pt":1588415306819,"mc":[{"id":"1.170370562","rc":[{"atl":[[1.41,330.23]],"id":9625043}],"con":true,"img":false}]}
{"op":"mcm","clk":"1350006578","pt":1588415306924,"mc":[{"id":"1.170370562","rc":[{"atb":[[1.29,265.95]],"id":9625043}],"con":true,"img":false}]}
{"op":"mcm","clk":"1350006581","pt":1588415307025,"mc":[{"id":"1.170370562","rc":[{"atb":[[2.88,0.01]],"id":9631798}],"con":true,"img":false}]}
{"op":"mcm","clk":"1350006593","pt":1588415307389,"mc":[{"id":"1.170370562","rc":[{"atl":[[1.41,263.75]],"id":9625043}],"con":true,"img":false}]}
{"op":"mcm","clk":"1350006604","pt":1588415307694,"mc":[{"id":"1.170370562","rc":[{"atb":[[1.4,443.02]],"id":9625043}],"con":true,"img":false}]}
{"op":"mcm","clk":"1350006609","pt":1588415307800,"mc":[{"id":"1.170370562","rc":[{"atl":[[1.41,197.26]],"id":9625043}],"con":true,"img":false}]}
{"op":"mcm","clk":"1350006674","pt":1588415309589,"mc":[{"id":"1.170370562","rc":[{"atb":[[1.28,0],[1.27,0],[1.35,97.89]],"id":9625043},{"atl":[[1.46,50],[1.42,0]],"id":9625043}],"con":true,"img":false}]}
{"op":"mcm","clk":"1350006682","pt":1588415309895,"mc":[{"id":"1.170370562","rc":[{"trd":[[1.41,1654.61]],"ltp":1.41,"tv":1654.61,"id":9625043},{"atl":[[1.41,192.26]],"id":9625043}],"con":true,"img":false}]}
{"op":"mcm","clk":"1350006711","pt":1588415310918,"mc":[{"id":"1.170370562","rc":[{"atl":[[1000,2.05]],"id":9631798}],"con":true,"img":false}]}
{"op":"mcm","clk":"1350006718","pt":1588415311124,"mc":[{"id":"1.170370562","rc":[{"atl":[[1000,0.06]],"id":9631798}],"con":true,"img":false}]}
{"op":"mcm","clk":"1350006728","pt":1588415311327,"mc":[{"id":"1.170370562","rc":[{"atl":[[1000,0.05]],"id":9631798}],"con":true,"img":false}]}
{"op":"mcm","clk":"1350006733","pt":1588415311430,"mc":[{"id":"1.170370562","rc":[{"atl":[[1000,2.05]],"id":9631798}],"con":true,"img":false}]}
{"op":"mcm","clk":"1350006738","pt":1588415311633,"mc":[{"id":"1.170370562","rc":[{"atl":[[1000,0.06]],"id":9631798}],"con":true,"img":false}]}
{"op":"mcm","clk":"1350006744","pt":1588415311895,"mc":[{"id":"1.170370562","rc":[{"atl":[[1000,0.05]],"id":9631798}],"con":true,"img":false}]}
{"op":"mcm","clk":"1350006749","pt":1588415312100,"mc":[{"id":"1.170370562","rc":[{"atl":[[1000,2.05]],"id":9631798}],"con":true,"img":false}]}
{"op":"mcm","clk":"1350006752","pt":1588415312206,"mc":[{"id":"1.170370562","rc":[{"atb":[[1.4,203.02]],"id":9625043}],"con":true,"img":false}]}
{"op":"mcm","clk":"1350006756","pt":1588415312308,"mc":[{"id":"1.170370562","rc":[{"atl":[[1000,0.06]],"id":9631798}],"con":true,"img":false}]}
{"op":"mcm","clk":"1350006760","pt":1588415312512,"mc":[{"id":"1.170370562","rc":[{"atl":[[1000,0.05]],"id":9631798}],"con":true,"img":false}]}
{"op":"mcm","clk":"1350006767","pt":1588415312616,"mc":[{"id":"1.170370562","rc":[{"atb":[[1.39,0]],"id":9625043}],"con":true,"img":false}]}
{"op":"mcm","clk":"1350006770","pt":1588415312818,"mc":[{"id":"1.170370562","rc":[{"atb":[[1.3,0]],"id":9625043},{"atl":[[1000,2.05]],"id":9631798}],"con":true,"img":false}]}
{"op":"mcm","clk":"1350006774","pt":1588415313025,"mc":[{"id":"1.170370562","rc":[{"atl":[[1000,0.06]],"id":9631798}],"con":true,"img":false}]}
{"op":"mcm","clk":"1350006782","pt":1588415313228,"mc":[{"id":"1.170370562","rc":[{"atl":[[1000,0.05]],"id":9631798}],"con":true,"img":false}]}
{"op":"mcm","clk":"1350006786","pt":1588415313432,"mc":[{"id":"1.170370562","rc":[{"atb":[[1.37,0]],"id":9625043}],"con":true,"img":false}]}
{"op":"mcm","clk":"1350006790","pt":1588415313533,"mc":[{"id":"1.170370562","rc":[{"atl":[[1000,2.05]],"id":9631798}],"con":true,"img":false}]}
{"op":"mcm","clk":"1350006799","pt":1588415313738,"mc":[{"id":"1.170370562","rc":[{"atl":[[1000,0.06]],"id":9631798}],"con":true,"img":false}]}
{"op":"mcm","clk":"1350006801","pt":1588415313841,"mc":[{"id":"1.170370562","rc":[{"atl":[[1000,0.05]],"id":9631798}],"con":true,"img":false}]}
{"op":"mcm","clk":"1350006814","pt":1588415314000,"mc":[{"id":"1.170370562","rc":[{"atl":[[1000,2.05]],"id":9631798}],"con":true,"img":false}]}
{"op":"mcm","clk":"1350006818","pt":1588415314103,"mc":[{"id":"1.170370562","rc":[{"atb":[[1.4,201.85]],"id":9625043},{"atl":[[1000,0.06]],"id":9631798}],"con":true,"img":false}]}
{"op":"mcm","clk":"1350006827","pt":1588415314309,"mc":[{"id":"1.170370562","rc":[{"atl":[[1000,0.05]],"id":9631798}],"con":true,"img":false}]}
{"op":"mcm","clk":"1350006841","pt":1588415314615,"mc":[{"id":"1.170370562","rc":[{"atl":[[1000,2.05]],"id":9631798}],"con":true,"img":false}]}
{"op":"mcm","clk":"1350006855","pt":1588415314820,"mc":[{"id":"1.170370562","rc":[{"atl":[[1.41,0]],"id":9625043},{"atl":[[1000,0.06]],"id":9631798}],"con":true,"img":false}]}
{"op":"mcm","clk":"1350006863","pt":1588415314927,"mc":[{"id":"1.170370562","rc":[{"atb":[[1.4,1.85],[1.17,0]],"id":9625043}],"con":true,"img":false}]}
{"op":"mcm","clk":"1350006867","pt":1588415315025,"mc":[{"id":"1.170370562","rc":[{"atl":[[1000,0.05]],"id":9631798}],"con":true,"img":false}]}
{"op":"mcm","clk":"1350006880","pt":1588415315331,"mc":[{"id":"1.170370562","rc":[{"trd":[[1.38,3903.44],[1.4,8261.58]],"ltp":1.38,"tv":12165.02,"id":9625043},{"atb":[[1.4,0]],"id":9625043},{"atl":[[1.37,689.28]],"id":9625043},{"trd":[[3.6,0.51],[3.5,1249.54]],"ltp":3.6,"tv":1250.05,"id":9631798},{"atl":[[3.6,0],[3.5,0]],"id":9631798}],"con":true,"img":false}]}
{"op":"mcm","clk":"1350006886","pt":1588415315433,"mc":[{"id":"1.170370562","rc":[{"atl":[[1.4,1.77]],"id":9625043}],"con":true,"img":false}]}
{"op":"mcm","clk":"1350006896","pt":1588415315637,"mc":[{"id":"1.170370562","rc":[{"atb":[[1.18,0],[1.12,0],[1.21,333],[1.26,0],[1.19,0],[1.23,333],[1.09,0],[1.13,0],[1.24,0]],"id":9625043},{"atl":[[1.37,1439.28]],"id":9625043}],"con":true,"img":false}]}
{"op":"mcm","clk":"1350006910","pt":1588415315898,"mc":[{"id":"1.170370562","rc":[{"trd":[[1.33,440.09],[1.35,1275.83]],"ltp":1.33,"tv":1715.91,"id":9625043},{"atb":[[1.33,0],[1.35,0]],"id":9625043},{"atl":[[1.33,868.78]],"id":9625043}],"con":true,"img":false}]}
{"op":"mcm","clk":"1350006918","pt":1588415316205,"mc":[{"id":"1.170370562","rc":[{"atl":[[1.35,492.02]],"id":9625043}],"con":true,"img":false}]}
{"op":"mcm","clk":"1350006931","pt":1588415316411,"mc":[{"id":"1.170370562","rc":[{"trd":[[1.33,920.09]],"ltp":1.33,"tv":920.09,"id":9625043},{"atl":[[1.33,628.77]],"id":9625043},{"atl":[[4.8,0.01]],"id":9631798}],"con":true,"img":false}]}
{"op":"mcm","clk":"1350006935","pt":1588415316514,"mc":[{"id":"1.170370562","rc":[{"trd":[[1.33,971.11]],"ltp":1.33,"tv":971.11,"id":9625043},{"atl":[[1.33,603.27]],"id":9625043}],"con":true,"img":false}]}
{"op":"mcm","clk":"1350006940","pt":1588415316618,"mc":[{"id":"1.170370562","rc":[{"atb":[[1.21,0],[1.23,0],[1.25,0]],"id":9625043}],"con":true,"img":false}]}
{"op":"mcm","clk":"1350006955","pt":1588415317024,"mc":[{"id":"1.170370562","rc":[{"atl":[[1.37,0]],"id":9625043},{"atl":[[4.6,0.01]],"id":9631798}],"con":true,"img":false}]}
{"op":"mcm","clk":"1350006975","pt":1588415317538,"mc":[{"id":"1.170370562","rc":[{"atb":[[2.12,0]],"id":9631798}],"con":true,"img":false}]}
{"op":"mcm","clk":"1350006979","pt":1588415317640,"mc":[{"id":"1.170370562","rc":[{"atl":[[4.4,0.01]],"id":9631798}],"con":true,"img":false}]}
{"op":"mcm","clk":"1350006982","pt":1588415317695,"mc":[{"id":"1.170370562","rc":[{"atl":[[1.38,177.3]],"id":9625043}],"con":true,"img":false}]}
{"op":"mcm","clk":"1350006989","pt":1588415317902,"mc":[{"id":"1.170370562","rc":[{"trd":[[1.33,975.06]],"ltp":1.33,"tv":975.06,"id":9625043},{"atl":[[1.33,599.32]],"id":9625043},{"trd":[[4,33.4]],"ltp":4.0,"tv":33.4,"id":9631798}],"con":true,"img":false}]}
{"op":"mcm","clk":"1350007007","pt":1588415318314,"mc":[{"id":"1.170370562","rc":[{"trd":[[1.33,975.09]],"ltp":1.33,"tv":975.09,"id":9625043},{"atl":[[1.33,599.29]],"id":9625043},{"trd":[[4,33.41]],"ltp":4.0,"tv":33.41,"id":9631798}],"con":true,"img":false}]}
{"op":"mcm","clk":"1350007031","pt":1588415318929,"mc":[{"id":"1.170370562","rc":[{"trd":[[1.33,975.12]],"ltp":1.33,"tv":975.12,"id":9625043},{"atl":[[1.33,599.26]],"id":9625043},{"trd":[[4,33.42]],"ltp":4.0,"tv":33.42,"id":9631798}],"con":true,"img":false}]}
{"op":"mcm","clk":"1350007043","pt":1588415319435,"mc":[{"id":"1.170370562","rc":[{"trd":[[1.33,975.15]],"ltp":1.33,"tv":975.15,"id":9625043},{"atl":[[1.33,599.23],[1.47,0]],"id":9625043},{"trd":[[4,33.43]],"ltp":4.0,"tv":33.43,"id":9631798}],"con":true,"img":false}]}
{"op":"mcm","clk":"1350007049","pt":1588415319539,"mc":[{"id":"1.170370562","rc":[{"trd":[[1.33,2173.61]],"ltp":1.33,"tv":2173.61,"id":9625043},{"atb":[[1.33,215.07]],"id":9625043},{"atl":[[1.33,0]],"id":9625043}],"con":true,"img":false}]}
{"op":"mcm","clk":"1350007077","pt":1588415320106,"mc":[{"id":"1.170370562","rc":[{"trd":[[1.35,1275.86]],"ltp":1.35,"tv":1275.86,"id":9625043},{"atl":[[1.35,491.99]],"id":9625043},{"trd":[[3.85,25.02]],"ltp":3.85,"tv":25.02,"id":9631798}],"con":true,"img":false}]}
{"op":"mcm","clk":"1350007083","pt":1588415320316,"mc":[{"id":"1.170370562","rc":[{"atb":[[3.7,6.29]],"id":9631798}],"con":true,"img":false}]}
{"op":"mcm","clk":"1350007089","pt":1588415320418,"mc":[{"id":"1.170370562","rc":[{"atl":[[1.36,66.48]],"id":9625043}],"con":true,"img":false}]}
{"op":"mcm","clk":"1350007099","pt":1588415320623,"mc":[{"id":"1.170370562","rc":[{"atl":[[1.36,132.97]],"id":9625043}],"con":true,"img":false}]}
{"op":"mcm","clk":"1350007114","pt":1588415320930,"mc":[{"id":"1.170370562","rc":[{"atb":[[3.5,100]],"id":9631798}],"con":true,"img":false}]}
{"op":"mcm","clk":"1350007121","pt":1588415321035,"mc":[{"id":"1.170370562","rc":[{"atl":[[1.35,824.99]],"id":9625043}],"con":true,"img":false}]}
{"op":"mcm","clk":"1350007141","pt":1588415321442,"mc":[{"id":"1.170370562","rc":[{"atb":[[3.7,0]],"id":9631798}],"con":true,"img":false}]}
{"op":"mcm","clk":"1350007164","pt":1588415322014,"mc":[{"id":"1.170370562","rc":[{"atl":[[1.35,491.99]],"id":9625043}],"con":true,"img":false}]}
{"op":"mcm","clk":"1350007201","pt":1588415322836,"mc":[{"id":"1.170370562","rc":[{"trd":[[1.33,2282.67]],"ltp":1.33,"tv":2282.67,"id":9625043},{"atb":[[1.33,160.54]],"id":9625043},{"atl":[[1.34,265.95]],"id":9625043}],"con":true,"img":false}]}
{"op":"mcm","clk":"1350007203","pt":1588415322937,"mc":[{"id":"1.170370562","rc":[{"atb":[[2.38,343.94]],"id":9631798}],"con":true,"img":false}]}
{"op":"mcm","clk":"1350007220","pt":1588415323346,"mc":[{"id":"1.170370562","rc":[{"atl":[[1.35,0]],"id":9625043}],"con":true,"img":false}]}
{"op":"mcm","clk":"1350007237","pt":1588415323630,"mc":[{"id":"1.170370562","rc":[{"atl":[[1.42,265.95]],"id":9625043}],"con":true,"img":false}]}
{"op":"mcm","clk":"1350007250","pt":1588415323812,"mc":[{"id":"1.170370562","rc":[{"atl":[[1.41,240]],"id":9625043}],"con":true,"img":false}]}
{"op":"mcm","clk":"1350007264","pt":1588415324184,"mc":[{"id":"1.170370562","rc":[{"atb":[[1.31,967.84]],"id":9625043},{"atl":[[1.7,87.58]],"id":9625043}],"con":true,"img":false}]}
{"op":"mcm","clk":"1350007271","pt":1588415324220,"mc":[{"id":"1.170370562","rc":[{"atl":[[1.46,290]],"id":9625043}],"con":true,"img":false}]}
{"op":"mcm","clk":"1350007278","pt":1588415324328,"mc":[{"id":"1.170370562","rc":[{"trd":[[1.33,2603.77]],"ltp":1.33,"tv":2603.77,"id":9625043},{"atb":[[1.33,0]],"id":9625043},{"atl":[[1.32,172.45]],"id":9625043}],"con":true,"img":false}]}
{"op":"mcm","clk":"1350007303","pt":1588415324839,"mc":[{"id":"1.170370562","rc":[{"atl":[[1.32,0]],"id":9625043}],"con":true,"img":false}]}
{"op":"mcm","clk":"1350007318","pt":1588415325147,"mc":[{"id":"1.170370562","rc":[{"atb":[[1.3,55]],"id":9625043}],"con":true,"img":false}]}
{"op":"mcm","clk":"1350007326","pt":1588415325354,"mc":[{"id":"1.170370562","rc":[{"atb":[[1.01,1003.5]],"id":9625043}],"con":true,"img":false}]}
{"op":"mcm","clk":"1350007330","pt":1588415325455,"mc":[{"id":"1.170370562","rc":[{"atl":[[1.33,35.69]],"id":9625043}],"con":true,"img":false}]}
{"op":"mcm","clk":"1350007337","pt":1588415325536,"mc":[{"id":"1.170370562","rc":[{"atl":[[1.33,212.99]],"id":9625043}],"con":true,"img":false}]}
{"op":"mcm","clk":"1350007346","pt":1588415325730,"mc":[{"id":"1.170370562","rc":[{"atb":[[1.01,1001.75]],"id":9625043}],"con":true,"img":false}]}
{"op":"mcm","clk":"1350007360","pt":1588415326038,"mc":[{"id":"1.170370562","rc":[{"atb":[[1.32,55]],"id":9625043}],"con":true,"img":false}]}
{"op":"mcm","clk":"1350007365","pt":1588415326129,"mc":[{"id":"1.170370562","rc":[{"atb":[[1.01,1001.72]],"id":9625043}],"con":true,"img":false}]}
{"op":"mcm","clk":"1350007382","pt":1588415326537,"mc":[{"id":"1.170370562","rc":[{"trd":[[1.33,2604.72]],"ltp":1.33,"tv":2604.72,"id":9625043},{"atb":[[1.3,232.3]],"id":9625043},{"atl":[[1.33,212.52]],"id":9625043}],"con":true,"img":false}]}
{"op":"mcm","clk":"1350007406","pt":1588415327150,"mc":[{"id":"1.170370562","rc":[{"atl":[[1.34,332.44]],"id":9625043}],"con":true,"img":false}]}
{"op":"mcm","clk":"1350007411","pt":1588415327253,"mc":[{"id":"1.170370562","rc":[{"trd":[[1.33,2734.13]],"ltp":1.33,"tv":2734.13,"id":9625043},{"atl":[[1.33,147.81]],"id":9625043}],"con":true,"img":false}]}
{"op":"mcm","clk":"1350007417","pt":1588415327355,"mc":[{"id":"1.170370562","rc":[{"atl":[[1.34,398.93]],"id":9625043}],"con":true,"img":false}]}
{"op":"mcm","clk":"1350007432","pt":1588415327723,"mc":[{"id":"1.170370562","rc":[{"trd":[[1.33,2739.29]],"ltp":1.33,"tv":2739.29,"id":9625043},{"atl":[[1.33,145.23]],"id":9625043}],"con":true,"img":false}]}
{"op":"mcm","clk":"1350007442","pt":1588415327930,"mc":[{"id":"1.170370562","rc":[{"atb":[[1.24,177.3]],"id":9625043}],"con":true,"img":false}]}
{"op":"mcm","clk":"1350007498","pt":1588415329340,"mc":[{"id":"1.170370562","rc":[{"trd":[[1.33,2792.61]],"ltp":1.33,"tv":2792.61,"id":9625043},{"atl":[[1.33,91.91]],"id":9625043},{"trd":[[4,51.16]],"ltp":4.0,"tv":51.16,"id":9631798}],"con":true,"img":false}]}
{"op":"mcm","clk":"1350007510","pt":1588415329552,"mc":[{"id":"1.170370562","rc":[{"trd":[[1.33,2845.94]],"ltp":1.33,"tv":2845.94,"id":9625043},{"atl":[[1.33,38.59]],"id":9625043},{"trd":[[4,68.89]],"ltp":4.0,"tv":68.89,"id":9631798}],"con":true,"img":false}]}
{"op":"mcm","clk":"1350007518","pt":1588415329654,"mc":[{"id":"1.170370562","rc":[{"trd":[[1.34,252.91],[1.33,2923.12]],"ltp":1.34,"tv":3176.02,"id":9625043},{"atl":[[1.33,0],[1.34,382.52]],"id":9625043}],"con":true,"img":false}]}
{"op":"mcm","clk":"1350007523","pt":1588415329755,"mc":[{"id":"1.170370562","rc":[{"trd":[[1.34,259.91]],"ltp":1.34,"tv":259.91,"id":9625043},{"atl":[[1.34,379.02]],"id":9625043}],"con":true,"img":false}]}
{"op":"mcm","clk":"1350007529","pt":1588415329858,"mc":[{"id":"1.170370562","rc":[{"trd":[[1.34,421.52]],"ltp":1.34,"tv":421.52,"id":9625043},{"atl":[[1.34,272.42]],"id":9625043},{"trd":[[3.9,19.14]],"ltp":3.9,"tv":19.14,"id":9631798}],"con":true,"img":false}]}
{"op":"mcm","clk":"1350007538","pt":1588415330022,"mc":[{"id":"1.170370562","rc":[{"atl":[[1000,2.05]],"id":9631798}],"con":true,"img":false}]}
{"op":"mcm","clk":"1350007550","pt":1588415330224,"mc":[{"id":"1.170370562","rc":[{"atl":[[1000,0.06]],"id":9631798}],"con":true,"img":false}]}
{"op":"mcm","clk":"1350007561","pt":1588415330429,"mc":[{"id":"1.170370562","rc":[{"atl":[[1000,0.05]],"id":9631798}],"con":true,"img":false}]}
{"op":"mcm","clk":"1350007566","pt":1588415330532,"mc":[{"id":"1.170370562","rc":[{"atl":[[1000,2.05]],"id":9631798}],"con":true,"img":false}]}
{"op":"mcm","clk":"1350007577","pt":1588415330736,"mc":[{"id":"1.170370562","rc":[{"atl":[[1000,0.06]],"id":9631798}],"con":true,"img":false}]}
{"op":"mcm","clk":"1350007583","pt":1588415330838,"mc":[{"id":"1.170370562","rc":[{"atl":[[1000,2.06]],"id":9631798}],"con":true,"img":false}]}
{"op":"mcm","clk":"1350007586","pt":1588415330942,"mc":[{"id":"1.170370562","rc":[{"atl":[[1000,2.05]],"id":9631798}],"con":true,"img":false}]}
{"op":"mcm","clk":"1350007590","pt":1588415331049,"mc":[{"id":"1.170370562","rc":[{"atl":[[1000,0.06]],"id":9631798}],"con":true,"img":false}]}
{"op":"mcm","clk":"1350007596","pt":1588415331148,"mc":[{"id":"1.170370562","rc":[{"trd":[[1.34,421.75]],"ltp":1.34,"tv":421.75,"id":9625043},{"atl":[[1.34,272.3]],"id":9625043}],"con":true,"img":false}]}
{"op":"mcm","clk":"1350007601","pt":1588415331247,"mc":[{"id":"1.170370562","rc":[{"trd":[[1.34,421.8]],"ltp":1.34,"tv":421.8,"id":9625043},{"atb":[[1.29,0]],"id":9625043},{"atl":[[1.34,272.27]],"id":9625043},{"atl":[[1000,0.05]],"id":9631798}],"con":true,"img":false}]}
{"op":"mcm","clk":"1350007604","pt":1588415331352,"mc":[{"id":"1.170370562","rc":[{"atb":[[1.25,170.83]],"id":9625043}],"con":true,"img":false}]}
{"op":"mcm","clk":"1350007621","pt":1588415331927,"mc":[{"id":"1.170370562","rc":[{"atb":[[1.18,265.95]],"id":9625043}],"con":true,"img":false}]}
{"op":"mcm","clk":"1350007625","pt":1588415332019,"mc":[{"id":"1.170370562","rc":[{"atl":[[1.34,139.29]],"id":9625043}],"con":true,"img":false}]}
{"op":"mcm","clk":"1350007630","pt":1588415332123,"mc":[{"id":"1.170370562","rc":[{"atb":[[1.19,179.44]],"id":9625043}],"con":true,"img":false}]}
{"op":"mcm","clk":"1350007645","pt":1588415332737,"mc":[{"id":"1.170370562","rc":[{"atl":[[1.44,131.38]],"id":9625043}],"con":true,"img":false}]}
{"op":"mcm","clk":"1350007654","pt":1588415332948,"mc":[{"id":"1.170370562","rc":[{"trd":[[1.34,439.32]],"ltp":1.34,"tv":439.32,"id":9625043},{"atl":[[1.34,0]],"id":9625043}],"con":true,"img":false}]}
{"op":"mcm","clk":"1350007703","pt":1588415334237,"mc":[{"id":"1.170370562","rc":[{"atb":[[1.33,5]],"id":9625043}],"con":true,"img":false}]}
{"op":"mcm","clk":"1350007720","pt":1588415334649,"mc":[{"id":"1.170370562","rc":[{"atb":[[1.33,149.77]],"id":9625043}],"con":true,"img":false}]}
{"op":"mcm","clk":"1350007732","pt":1588415334954,"mc":[{"id":"1.170370562","rc":[{"atb":[[1.32,123.69]],"id":9625043},{"atl":[[3.85,2.64]],"id":9631798}],"con":true,"img":false}]}
{"op":"mcm","clk":"1350007739","pt":1588415335160,"mc":[{"id":"1.170370562","rc":[{"trd":[[1.35,1278.43]],"ltp":1.35,"tv":1278.43,"id":9625043},{"trd":[[3.85,25.92]],"ltp":3.85,"tv":25.92,"id":9631798},{"atl":[[3.85,1.74]],"id":9631798}],"con":true,"img":false}]}
{"op":"mcm","clk":"1350007750","pt":1588415335422,"mc":[{"id":"1.170370562","rc":[{"trd":[[1.36,777.85]],"ltp":1.36,"tv":777.85,"id":9625043},{"atl":[[1.36,30]],"id":9625043}],"con":true,"img":false}]}
{"op":"mcm","clk":"1350007754","pt":1588415335526,"mc":[{"id":"1.170370562","rc":[{"atl":[[6.6,0.01]],"id":9631798}],"con":true,"img":false}]}
{"op":"mcm","clk":"1350007755","pt":1588415335634,"mc":[{"id":"1.170370562","rc":[{"atb":[[1.32,68.69]],"id":9625043}],"con":true,"img":false}]}
{"op":"mcm","clk":"1350007769","pt":1588415336037,"mc":[{"id":"1.170370562","rc":[{"atl":[[5.6,0.01]],"id":9631798}],"con":true,"img":false}]}
{"op":"mcm","clk":"1350007783","pt":1588415336344,"mc":[{"id":"1.170370562","rc":[{"atl":[[5.1,0.01]],"id":9631798}],"con":true,"img":false}]}
{"op":"mcm","clk":"1350007810","pt":1588415337057,"mc":[{"id":"1.170370562","rc":[{"atb":[[1.32,197.27]],"id":9625043}],"con":true,"img":false}]}
{"op":"mcm","clk":"1350007824","pt":1588415337366,"mc":[{"id":"1.170370562","rc":[{"atb":[[1.25,0]],"id":9625043}],"con":true,"img":false}]}
{"op":"mcm","clk":"1350007831","pt":1588415337524,"mc":[{"id":"1.170370562","rc":[{"atl":[[1.46,50],[1.41,0],[1.38,0]],"id":9625043}],"con":true,"img":false}]}
{"op":"mcm","clk":"1350007847","pt":1588415338040,"mc":[{"id":"1.170370562","rc":[{"atl":[[1.36,0]],"id":9625043}],"con":true,"img":false}]}
{"op":"mcm","clk":"1350007863","pt":1588415338553,"mc":[{"id":"1.170370562","rc":[{"atb":[[1.19,0]],"id":9625043}],"con":true,"img":false}]}
{"op":"mcm","clk":"1350007911","pt":1588415340144,"mc":[{"id":"1.170370562","rc":[{"atb":[[1.36,967.84],[1.32,128.58]],"id":9625043}],"con":true,"img":false}]}
{"op":"mcm","clk":"1350007915","pt":1588415340248,"mc":[{"id":"1.170370562","rc":[{"atb":[[1.31,0]],"id":9625043}],"con":true,"img":false}]}
{"op":"mcm","clk":"1350007923","pt":1588415340453,"mc":[{"id":"1.170370562","rc":[{"atb":[[1.34,750]],"id":9625043}],"con":true,"img":false}]}
{"op":"mcm","clk":"1350007952","pt":1588415341274,"mc":[{"id":"1.170370562","rc":[{"atb":[[1.34,751.17]],"id":9625043}],"con":true,"img":false}]}
{"op":"mcm","clk":"1350007974","pt":1588415341640,"mc":[{"id":"1.170370562","rc":[{"atb":[[1.3,177.3]],"id":9625043}],"con":true,"img":false}]}
{"op":"mcm","clk":"1350007986","pt":1588415341946,"mc":[{"id":"1.170370562","rc":[{"trd":[[1.36,791.86]],"ltp":1.36,"tv":791.86,"id":9625043},{"atb":[[1.36,960.83]],"id":9625043}],"con":true,"img":false}]}
{"op":"mcm","clk":"1350007990","pt":1588415342057,"mc":[{"id":"1.170370562","rc":[{"atb":[[1.35,66.48]],"id":9625043}],"con":true,"img":false}]}
{"op":"mcm","clk":"1350007995","pt":1588415342261,"mc":[{"id":"1.170370562","rc":[{"atb":[[1.34,1.17]],"id":9625043}],"con":true,"img":false}]}
{"op":"mcm","clk":"1350008001","pt":1588415342361,"mc":[{"id":"1.170370562","rc":[{"trd":[[1.36,967.04]],"ltp":1.36,"tv":967.04,"id":9625043},{"atb":[[1.36,873.25]],"id":9625043}],"con":true,"img":false}]}
{"op":"mcm","clk":"1350008012","pt":1588415342668,"mc":[{"id":"1.170370562","rc":[{"atb":[[1.3,0]],"id":9625043}],"con":true,"img":false}]}
{"op":"mcm","clk":"1350008022","pt":1588415342931,"mc":[{"id":"1.170370562","rc":[{"atb":[[1.38,177.3]],"id":9625043}],"con":true,"img":false}]}
{"op":"mcm","clk":"1350008035","pt":1588415343345,"mc":[{"id":"1.170370562","rc":[{"atb":[[1.38,243.79]],"id":9625043}],"con":true,"img":false}]}
{"op":"mcm","clk":"1350008037","pt":1588415343451,"mc":[{"id":"1.170370562","rc":[{"atl":[[3.95,21]],"id":9631798}],"con":true,"img":false}]}
{"op":"mcm","clk":"1350008039","pt":1588415343555,"mc":[{"id":"1.170370562","rc":[{"atb":[[1.38,504.65]],"id":9625043}],"con":true,"img":false}]}
{"op":"mcm","clk":"1350008046","pt":1588415343760,"mc":[{"id":"1.170370562","rc":[{"atb":[[1.36,1006.68],[1.32,0],[1.38,659.39]],"id":9625043}],"con":true,"img":false}]}
{"op":"mcm","clk":"1350008055","pt":1588415344377,"mc":[{"id":"1.170370562","rc":[{"atb":[[1.24,0]],"id":9625043},{"atl":[[3.95,0]],"id":9631798}],"con":true,"img":false}]}
{"op":"mcm","clk":"1350008057","pt":1588415344480,"mc":[{"id":"1.170370562","rc":[{"atb":[[1.32,0.11]],"id":9625043}],"con":true,"img":false}]}
{"op":"mcm","clk":"1350008059","pt":1588415344639,"mc":[{"id":"1.170370562","rc":[{"atb":[[1.34,157.67]],"id":9625043}],"con":true,"img":false}]}
{"op":"mcm","clk":"1350008067","pt":1588415344950,"mc":[{"id":"1.170370562","rc":[{"trd":[[1.38,3903.67]],"ltp":1.38,"tv":3903.67,"id":9625043},{"atb":[[1.38,659.27]],"id":9625043}],"con":true,"img":false}]}
{"op":"mcm","clk":"1350008076","pt":1588415345259,"mc":[{"id":"1.170370562","rc":[{"atb":[[1.34,314.17]],"id":9625043}],"con":true,"img":false}]}
{"op":"mcm","clk":"1350008088","pt":1588415345774,"mc":[{"id":"1.170370562","rc":[{"atb":[[1.34,470.66]],"id":9625043}],"con":true,"img":false}]}
{"op":"mcm","clk":"1350008103","pt":1588415346242,"mc":[{"id":"1.170370562","rc":[{"atl":[[1.41,500]],"id":9625043}],"con":true,"img":false}]}
{"op":"mcm","clk":"1350008121","pt":1588415346758,"mc":[{"id":"1.170370562","rc":[{"atb":[[1.38,504.53]],"id":9625043}],"con":true,"img":false}]}
{"op":"mcm","clk":"1350008137","pt":1588415347477,"mc":[{"id":"1.170370562","rc":[{"atb":[[1.37,132.45]],"id":9625043}],"con":true,"img":false}]}
{"op":"mcm","clk":"1350008141","pt":1588415347577,"mc":[{"id":"1.170370562","rc":[{"atb":[[1.33,144.77],[1.36,873.25]],"id":9625043}],"con":true,"img":false}]}
{"op":"mcm","clk":"1350008168","pt":1588415348665,"mc":[{"id":"1.170370562","rc":[{"atl":[[1.39,0.23]],"id":9625043}],"con":true,"img":false}]}
{"op":"mcm","clk":"1350008171","pt":1588415348766,"mc":[{"id":"1.170370562","rc":[{"atb":[[1.36,900.94]],"id":9625043}],"con":true,"img":false}]}
{"op":"mcm","clk":"1350008181","pt":1588415349279,"mc":[{"id":"1.170370562","rc":[{"atb":[[1.28,265.95]],"id":9625043}],"con":true,"img":false}]}
{"op":"mcm","clk":"1350008189","pt":1588415349544,"mc":[{"id":"1.170370562","rc":[{"trd":[[1.39,5027.45]],"ltp":1.39,"tv":5027.45,"id":9625043},{"atb":[[1.39,54.76]],"id":9625043},{"atl":[[1.39,0]],"id":9625043}],"con":true,"img":false}]}
{"op":"mcm","clk":"1350008192","pt":1588415349746,"mc":[{"id":"1.170370562","rc":[{"atb":[[1.39,109.76]],"id":9625043}],"con":true,"img":false}]}
{"op":"mcm","clk":"1350008200","pt":1588415350262,"mc":[{"id":"1.170370562","rc":[{"atb":[[1.37,309.76],[1.34,0]],"id":9625043}],"con":true,"img":false}]}
{"op":"mcm","clk":"1350008209","pt":1588415350772,"mc":[{"id":"1.170370562","rc":[{"atl":[[1.47,265.95]],"id":9625043}],"con":true,"img":false}]}
{"op":"mcm","clk":"1350008218","pt":1588415351440,"mc":[{"id":"1.170370562","rc":[{"trd":[[1.39,5056.68]],"ltp":1.39,"tv":5056.68,"id":9625043},{"atb":[[1.39,95.15]],"id":9625043}],"con":true,"img":false}]}
{"op":"mcm","clk":"1350008223","pt":1588415351952,"mc":[{"id":"1.170370562","rc":[{"atb":[[1.39,315.25]],"id":9625043},{"atl":[[1.42,0]],"id":9625043}],"con":true,"img":false}]}
{"op":"mcm","clk":"1350008247","pt":1588415353181,"mc":[{"id":"1.170370562","rc":[{"atl":[[1.41,0]],"id":9625043}],"con":true,"img":false}]}
{"op":"mcm","clk":"1350008260","pt":1588415354058,"mc":[{"id":"1.170370562","rc":[{"atb":[[1.35,0]],"id":9625043}],"con":true,"img":false}]}
{"op":"mcm","clk":"1350008264","pt":1588415354261,"mc":[{"id":"1.170370562","rc":[{"trd":[[1.39,5061.94]],"ltp":1.39,"tv":5061.94,"id":9625043},{"atb":[[1.39,312.62]],"id":9625043}],"con":true,"img":false}]}
{"op":"mcm","clk":"1350008281","pt":1588415354778,"mc":[{"id":"1.170370562","rc":[{"trd":[[1.4,8273.18]],"ltp":1.4,"tv":8273.18,"id":9625043},{"atl":[[1.4,0]],"id":9625043},{"trd":[[3.5,1252.76]],"ltp":3.5,"tv":1252.76,"id":9631798},{"atb":[[3.5,96.78]],"id":9631798}],"con":true,"img":false}]}
{"op":"mcm","clk":"1350008299","pt":1588415355388,"mc":[{"id":"1.170370562","rc":[{"trd":[[1.4,8274.24]],"ltp":1.4,"tv":8274.24,"id":9625043},{"trd":[[3.5,1253.18]],"ltp":3.5,"tv":1253.18,"id":9631798},{"atb":[[3.5,96.36]],"id":9631798}],"con":true,"img":false}]}
{"op":"mcm","clk":"1350008326","pt":1588415356479,"mc":[{"id":"1.170370562","rc":[{"trd":[[1.4,8348.5]],"ltp":1.4,"tv":8348.5,"id":9625043},{"atb":[[1.38,243.67]],"id":9625043},{"trd":[[3.5,1282.88]],"ltp":3.5,"tv":1282.88,"id":9631798},{"atb":[[3.5,0]],"id":9631798}],"con":true,"img":false}]}
{"op":"mcm","clk":"1350008355","pt":1588415357766,"mc":[{"id":"1.170370562","rc":[{"trd":[[1.39,5307.18]],"ltp":1.39,"tv":5307.18,"id":9625043},{"atb":[[1.39,190]],"id":9625043}],"con":true,"img":false}]}
{"op":"mcm","clk":"1350008414","pt":1588415360393,"mc":[{"id":"1.170370562","rc":[{"atb":[[1.4,3]],"id":9625043}],"con":true,"img":false}]}
{"op":"mcm","clk":"1350008449","pt":1588415361585,"mc":[{"id":"1.170370562","rc":[{"atb":[[1.37,132.45]],"id":9625043}],"con":true,"img":false}]}
{"op":"mcm","clk":"1350008461","pt":1588415362200,"mc":[{"id":"1.170370562","rc":[{"atb":[[1.4,4.77]],"id":9625043}],"con":true,"img":false}]}
{"op":"mcm","clk":"1350008466","pt":1588415362669,"mc":[{"id":"1.170370562","rc":[{"atb":[[1.38,177.18]],"id":9625043}],"con":true,"img":false}]}
{"op":"mcm","clk":"1350008470","pt":1588415362770,"mc":[{"id":"1.170370562","rc":[{"atl":[[1.43,122.86]],"id":9625043}],"con":true,"img":false}]}
{"op":"mcm","clk":"1350008533","pt":1588415365560,"mc":[{"id":"1.170370562","rc":[{"atb":[[1.39,66.48]],"id":9625043},{"atb":[[2.64,0],[3.3,0],[2.94,0],[2.88,0],[2.9,0],[2.74,0],[3.15,0]],"id":9631798}],"con":true,"img":false}]}
{"op":"mcm","clk":"1350008540","pt":1588415365766,"mc":[{"id":"1.170370562","rc":[{"atl":[[1.42,66.48]],"id":9625043}],"con":true,"img":false}]}
{"op":"mcm","clk":"1350008547","pt":1588415365971,"mc":[{"id":"1.170370562","rc":[{"atl":[[1.42,132.97]],"id":9625043}],"con":true,"img":false}]}
{"op":"mcm","clk":"1350008552","pt":1588415366073,"mc":[{"id":"1.170370562","rc":[{"atl":[[3.85,0]],"id":9631798}],"con":true,"img":false}]}
{"op":"mcm","clk":"1350008565","pt":1588415366585,"mc":[{"id":"1.170370562","rc":[{"atl":[[1.42,0]],"id":9625043}],"con":true,"img":false}]}
{"op":"mcm","clk":"1350008589","pt":1588415367477,"mc":[{"id":"1.170370562","rc":[{"trd":[[1.43,1525.32]],"ltp":1.43,"tv":1525.32,"id":9625043},{"atb":[[1.43,627.14]],"id":9625043},{"atl":[[1.43,0]],"id":9625043}],"con":true,"img":false}]}
{"op":"mcm","clk":"1350008593","pt":1588415367568,"mc":[{"id":"1.170370562","rc":[{"atb":[[2.38,0]],"id":9631798}],"con":true,"img":false}]}
{"op":"mcm","clk":"1350008605","pt":1588415367979,"mc":[{"id":"1.170370562","rc":[{"atb":[[1.43,0]],"id":9625043}],"con":true,"img":false}]}
{"op":"mcm","clk":"1350008614","pt":1588415368184,"mc":[{"id":"1.170370562","rc":[{"atb":[[1.42,967.84]],"id":9625043}],"con":true,"img":false}]}
{"op":"mcm","clk":"1350008620","pt":1588415368389,"mc":[{"id":"1.170370562","rc":[{"atb":[[1.36,27.69]],"id":9625043}],"con":true,"img":false}]}
{"op":"mcm","clk":"1350008654","pt":1588415369777,"mc":[{"id":"1.170370562","rc":[{"trd":[[1.44,6448.95]],"ltp":1.44,"tv":6448.95,"id":9625043},{"atb":[[1.45,108.62],[1.43,492.02]],"id":9625043},{"atl":[[1.44,0]],"id":9625043}],"con":true,"img":false}]}
{"op":"mcm","clk":"1350008665","pt":1588415370193,"mc":[{"id":"1.170370562","rc":[{"atb":[[1.42,1034.33]],"id":9625043}],"con":true,"img":false}]}
{"op":"mcm","clk":"1350008669","pt":1588415370296,"mc":[{"id":"1.170370562","rc":[{"atb":[[1.39,0],[1.42,1100.82]],"id":9625043}],"con":true,"img":false}]}
{"op":"mcm","clk":"1350008672","pt":1588415370498,"mc":[{"id":"1.170370562","rc":[{"atb":[[1.42,1167.31]],"id":9625043}],"con":true,"img":false}]}
{"op":"mcm","clk":"1350008680","pt":1588415370702,"mc":[{"id":"1.170370562","rc":[{"atb":[[1.45,0],[1.42,1233.8]],"id":9625043}],"con":true,"img":false}]}
{"op":"mcm","clk":"1350008681","pt":1588415370804,"mc":[{"id":"1.170370562","rc":[{"atb":[[1.45,118.41]],"id":9625043}],"con":true,"img":false}]}
{"op":"mcm","clk":"1350008691","pt":1588415371068,"mc":[{"id":"1.170370562","rc":[{"atl":[[3.5,21]],"id":9631798}],"con":true,"img":false}]}
{"op":"mcm","clk":"1350008697","pt":1588415371274,"mc":[{"id":"1.170370562","rc":[{"atb":[[1.45,0]],"id":9625043}],"con":true,"img":false}]}
{"op":"mcm","clk":"1350008704","pt":1588415371376,"mc":[{"id":"1.170370562","rc":[{"atb":[[1.42,1361.59]],"id":9625043}],"con":true,"img":false}]}
{"op":"mcm","clk":"1350008715","pt":1588415371794,"mc":[{"id":"1.170370562","rc":[{"atb":[[1.43,497.12]],"id":9625043}],"con":true,"img":false}]}
{"op":"mcm","clk":"1350008718","pt":1588415371895,"mc":[{"id":"1.170370562","rc":[{"atb":[[1.36,0]],"id":9625043}],"con":true,"img":false}]}
{"op":"mcm","clk":"1350008723","pt":1588415372003,"mc":[{"id":"1.170370562","rc":[{"trd":[[1.43,1578.51]],"ltp":1.43,"tv":1578.51,"id":9625043},{"atb":[[1.43,470.52]],"id":9625043}],"con":true,"img":false}]}
{"op":"mcm","clk":"1350008732","pt":1588415372205,"mc":[{"id":"1.170370562","rc":[{"atb":[[1.42,1538.9]],"id":9625043}],"con":true,"img":false}]}
{"op":"mcm","clk":"1350008736","pt":1588415372306,"mc":[{"id":"1.170370562","rc":[{"atl":[[3.5,0]],"id":9631798}],"con":true,"img":false}]}
{"op":"mcm","clk":"1350008739","pt":1588415372410,"mc":[{"id":"1.170370562","rc":[{"atb":[[1.43,5.1]],"id":9625043}],"con":true,"img":false}]}
{"op":"mcm","clk":"1350008759","pt":1588415372982,"mc":[{"id":"1.170370562","rc":[{"atb":[[1.4,1.77]],"id":9625043},{"atb":[[1.97,379.17]],"id":9631798}],"con":true,"img":false}]}
{"op":"mcm","clk":"1350008768","pt":1588415373287,"mc":[{"id":"1.170370562","rc":[{"atb":[[1.39,265.95]],"id":9625043}],"con":true,"img":false}]}
{"op":"mcm","clk":"1350008780","pt":1588415374163,"mc":[{"id":"1.170370562","rc":[{"atl":[[1.46,550]],"id":9625043}],"con":true,"img":false}]}
{"op":"mcm","clk":"1350008808","pt":1588415375192,"mc":[{"id":"1.170370562","rc":[{"trd":[[1.42,1694.5],[1.43,1588.71]],"ltp":1.42,"tv":3283.21,"id":9625043},{"atb":[[1.43,0],[1.42,1500.2]],"id":9625043}],"con":true,"img":false}]}
{"op":"mcm","clk":"1350008817","pt":1588415375704,"mc":[{"id":"1.170370562","rc":[{"atb":[[3.2,193.7]],"id":9631798}],"con":true,"img":false}]}
{"op":"mcm","clk":"1350008820","pt":1588415375808,"mc":[{"id":"1.170370562","rc":[{"atl":[[1.44,121.11]],"id":9625043}],"con":true,"img":false}]}
{"op":"mcm","clk":"1350008831","pt":1588415376068,"mc":[{"id":"1.170370562","rc":[{"trd":[[1.44,6537.61]],"ltp":1.44,"tv":6537.61,"id":9625043},{"atl":[[1.44,76.78]],"id":9625043}],"con":true,"img":false}]}
{"op":"mcm","clk":"1350008846","pt":1588415376482,"mc":[{"id":"1.170370562","rc":[{"trd":[[1.46,1089.09],[1.44,6691.17]],"ltp":1.46,"tv":7780.26,"id":9625043},{"atl":[[1.46,509.18],[1.44,0]],"id":9625043}],"con":true,"img":false}]}
{"op":"mcm","clk":"1350008852","pt":1588415376790,"mc":[{"id":"1.170370562","rc":[{"atb":[[1.44,118.61]],"id":9625043}],"con":true,"img":false}]}
{"op":"mcm","clk":"1350008858","pt":1588415377306,"mc":[{"id":"1.170370562","rc":[{"trd":[[1.44,6743.99]],"ltp":1.44,"tv":6743.99,"id":9625043},{"atb":[[1.44,92.2]],"id":9625043}],"con":true,"img":false}]}
{"op":"mcm","clk":"1350008879","pt":1588415378182,"mc":[{"id":"1.170370562","rc":[{"atl":[[1.54,240]],"id":9625043}],"con":true,"img":false}]}
{"op":"mcm","clk":"1350008886","pt":1588415378594,"mc":[{"id":"1.170370562","rc":[{"atb":[[1.33,0]],"id":9625043}],"con":true,"img":false}]}
{"op":"mcm","clk":"1350008889","pt":1588415378902,"mc":[{"id":"1.170370562","rc":[{"atb":[[1.45,44.32]],"id":9625043}],"con":true,"img":false}]}
{"op":"mcm","clk":"1350008900","pt":1588415379366,"mc":[{"id":"1.170370562","rc":[{"atl":[[1.59,240]],"id":9625043}],"con":true,"img":false}]}
{"op":"mcm","clk":"1350008905","pt":1588415379778,"mc":[{"id":"1.170370562","rc":[{"atb":[[1.42,1372.4]],"id":9625043}],"con":true,"img":false}]}
{"op":"mcm","clk":"1350008921","pt":1588415380911,"mc":[{"id":"1.170370562","rc":[{"trd":[[1.46,1094.41]],"ltp":1.46,"tv":1094.41,"id":9625043},{"atl":[[1.46,506.52]],"id":9625043}],"con":true,"img":false}]}
{"op":"mcm","clk":"1350008929","pt":1588415381482,"mc":[{"id":"1.170370562","rc":[{"atl":[[3.3,2.57]],"id":9631798}],"con":true,"img":false}]}
{"op":"mcm","clk":"1350008935","pt":1588415381689,"mc":[{"id":"1.170370562","rc":[{"atl":[[1.46,6.52]],"id":9625043}],"con":true,"img":false}]}
{"op":"mcm","clk":"1350008949","pt":1588415382412,"mc":[{"id":"1.170370562","rc":[{"atl":[[1.47,0]],"id":9625043},{"trd":[[3.2,118.48]],"ltp":3.2,"tv":118.48,"id":9631798},{"atb":[[3.2,145.54]],"id":9631798}],"con":true,"img":false}]}
{"op":"mcm","clk":"1350008951","pt":1588415382514,"mc":[{"id":"1.170370562","rc":[{"trd":[[1.46,1156.05]],"ltp":1.46,"tv":1156.05,"id":9625043},{"atl":[[1.46,0]],"id":9625043},{"trd":[[3.2,140.66]],"ltp":3.2,"tv":140.66,"id":9631798},{"atb":[[3.2,123.36]],"id":9631798}],"con":true,"img":false}]}
{"op":"mcm","clk":"1350008960","pt":1588415382981,"mc":[{"id":"1.170370562","rc":[{"trd":[[1.46,1211.18]],"ltp":1.46,"tv":1211.18,"id":9625043},{"trd":[[3.2,165.81]],"ltp":3.2,"tv":165.81,"id":9631798},{"atb":[[3.2,98.21]],"id":9631798}],"con":true,"img":false}]}
{"op":"mcm","clk":"1350008963","pt":1588415383089,"mc":[{"id":"1.170370562","rc":[{"trd":[[1.46,1216.21]],"ltp":1.46,"tv":1216.21,"id":9625043},{"trd":[[3.2,168.1]],"ltp":3.2,"tv":168.1,"id":9631798},{"atb":[[3.2,95.92]],"id":9631798}],"con":true,"img":false}]}
{"op":"mcm","clk":"1350008965","pt":1588415383190,"mc":[{"id":"1.170370562","rc":[{"trd":[[1.45,811.57]],"ltp":1.45,"tv":811.57,"id":9625043},{"atb":[[1.45,41.96]],"id":9625043}],"con":true,"img":false}]}
{"op":"mcm","clk":"1350008979","pt":1588415383708,"mc":[{"id":"1.170370562","rc":[{"atb":[[1.44,236.97]],"id":9625043}],"con":true,"img":false}]}
{"op":"mcm","clk":"1350008986","pt":1588415383912,"mc":[{"id":"1.170370562","rc":[{"atb":[[1.01,1003.72]],"id":9625043}],"con":true,"img":false}]}
{"op":"mcm","clk":"1350008994","pt":1588415384219,"mc":[{"id":"1.170370562","rc":[{"atb":[[1.44,296.82],[1.01,1002.79]],"id":9625043},{"atl":[[3.25,24.73]],"id":9631798}],"con":true,"img":false}]}
{"op":"mcm","clk":"1350008999","pt":1588415384475,"mc":[{"id":"1.170370562","rc":[{"atb":[[1.01,1001.72]],"id":9625043}],"con":true,"img":false}]}
{"op":"mcm","clk":"1350009002","pt":1588415384580,"mc":[{"id":"1.170370562","rc":[{"trd":[[3.2,222]],"ltp":3.2,"tv":222.0,"id":9631798},{"atb":[[3.2,68.97]],"id":9631798}],"con":true,"img":false}]}
{"op":"mcm","clk":"1350009019","pt":1588415385405,"mc":[{"id":"1.170370562","rc":[{"atb":[[1.42,443.26]],"id":9625043},{"atl":[[3.3,0]],"id":9631798}],"con":true,"img":false}]}
{"op":"mcm","clk":"1350009022","pt":1588415385510,"mc":[{"id":"1.170370562","rc":[{"atl":[[3.25,0]],"id":9631798}],"con":true,"img":false}]}
{"op":"mcm","clk":"1350009025","pt":1588415385613,"mc":[{"id":"1.170370562","rc":[{"atb":[[1.44,236.97]],"id":9625043},{"atl":[[1.52,354.6]],"id":9625043}],"con":true,"img":false}]}
{"op":"mcm","clk":"1350009055","pt":1588415387108,"mc":[{"id":"1.170370562","rc":[{"atb":[[1.42,265.95]],"id":9625043}],"con":true,"img":false}]}
{"op":"mcm","clk":"1350009062","pt":1588415387418,"mc":[{"id":"1.170370562","rc":[{"trd":[[1.45,811.8]],"ltp":1.45,"tv":811.8,"id":9625043},{"atb":[[1.45,41.85]],"id":9625043}],"con":true,"img":false}]}
{"op":"mcm","clk":"1350009070","pt":1588415387779,"mc":[{"id":"1.170370562","rc":[{"atb":[[1.44,92.2]],"id":9625043}],"con":true,"img":false}]}
{"op":"mcm","clk":"1350009103","pt":1588415389581,"mc":[{"id":"1.170370562","rc":[{"atb":[[1.44,93.27]],"id":9625043}],"con":true,"img":false}]}
{"op":"mcm","clk":"1350009117","pt":1588415390201,"mc":[{"id":"1.170370562","rc":[{"atb":[[1.44,92.2]],"id":9625043}],"con":true,"img":false}]}
{"op":"mcm","clk":"1350009134","pt":1588415390820,"mc":[{"id":"1.170370562","rc":[{"atl":[[1.5,218.99]],"id":9625043}],"con":true,"img":false}]}
{"op":"mcm","clk":"1350009168","pt":1588415392520,"mc":[{"id":"1.170370562","rc":[{"atb":[[1.42,0]],"id":9625043}],"con":true,"img":false}]}
{"op":"mcm","clk":"1350009172","pt":1588415392881,"mc":[{"id":"1.170370562","rc":[{"trd":[[1.46,1360.99]],"ltp":1.46,"tv":1360.99,"id":9625043},{"trd":[[3.2,288.06]],"ltp":3.2,"tv":288.06,"id":9631798},{"atb":[[3.2,2.91]],"id":9631798}],"con":true,"img":false}]}
{"op":"mcm","clk":"1350009182","pt":1588415393398,"mc":[{"id":"1.170370562","rc":[{"atb":[[1.39,0]],"id":9625043}],"con":true,"img":false}]}
{"op":"mcm","clk":"1350009192","pt":1588415393913,"mc":[{"id":"1.170370562","rc":[{"trd":[[3.2,290.17]],"ltp":3.2,"tv":290.17,"id":9631798},{"atb":[[3.2,1.86]],"id":9631798}],"con":true,"img":false}]}
{"op":"mcm","clk":"1350009195","pt":1588415394118,"mc":[{"id":"1.170370562","rc":[{"atb":[[1.37,0]],"id":9625043}],"con":true,"img":false}]}
{"op":"mcm","clk":"1350009198","pt":1588415394218,"mc":[{"id":"1.170370562","rc":[{"atb":[[1.44,0]],"id":9625043}],"con":true,"img":false}]}
{"op":"mcm","clk":"1350009205","pt":1588415394682,"mc":[{"id":"1.170370562","rc":[{"atb":[[1.97,0]],"id":9631798}],"con":true,"img":false}]}
{"op":"mcm","clk":"1350009208","pt":1588415394784,"mc":[{"id":"1.170370562","rc":[{"atb":[[1.45,0]],"id":9625043}],"con":true,"img":false}]}
{"op":"mcm","clk":"1350009234","pt":1588415395927,"mc":[{"id":"1.170370562","rc":[{"atl":[[1.45,66.48]],"id":9625043}],"con":true,"img":false}]}
{"op":"mcm","clk":"1350009236","pt":1588415396028,"mc":[{"id":"1.170370562","rc":[{"atl":[[1.45,132.97]],"id":9625043}],"con":true,"img":false}]}
{"op":"mcm","clk":"1350009238","pt":1588415396081,"mc":[{"id":"1.170370562","rc":[{"atl":[[1.45,134.52]],"id":9625043}],"con":true,"img":false}]}
{"op":"mcm","clk":"1350009240","pt":1588415396188,"mc":[{"id":"1.170370562","rc":[{"atl":[[1.45,201.01]],"id":9625043}],"con":true,"img":false}]}
{"op":"mcm","clk":"1350009244","pt":1588415396288,"mc":[{"id":"1.170370562","rc":[{"atb":[[1.38,0]],"id":9625043}],"con":true,"img":false}]}
{"op":"mcm","clk":"1350009253","pt":1588415396804,"mc":[{"id":"1.170370562","rc":[{"trd":[[1.45,816.95]],"ltp":1.45,"tv":816.95,"id":9625043},{"atl":[[1.45,198.43]],"id":9625043}],"con":true,"img":false}]}
{"op":"mcm","clk":"1350009270","pt":1588415397883,"mc":[{"id":"1.170370562","rc":[{"atb":[[1.43,98.68]],"id":9625043}],"con":true,"img":false}]}
{"op":"mcm","clk":"1350009272","pt":1588415397986,"mc":[{"id":"1.170370562","rc":[{"atl":[[1.45,198.98]],"id":9625043}],"con":true,"img":false}]}
{"op":"mcm","clk":"1350009302","pt":1588415399228,"mc":[{"id":"1.170370562","rc":[{"atb":[[1.34,132.45]],"id":9625043}],"con":true,"img":false}]}
{"op":"mcm","clk":"1350009321","pt":1588415400000,"mc":[{"id":"1.170370562","rc":[{"atb":[[2.12,363.96]],"id":9631798}],"con":true,"img":false}]}
{"op":"mcm","clk":"1350009351","pt":1588415400998,"mc":[{"id":"1.170370562","rc":[{"trd":[[1.45,818.53]],"ltp":1.45,"tv":818.53,"id":9625043},{"atl":[[1.45,197.4]],"id":9625043},{"trd":[[3.2,294.61]],"ltp":3.2,"tv":294.61,"id":9631798},{"atb":[[3.2,0]],"id":9631798}],"con":true,"img":false}]}
{"op":"mcm","clk":"1350009466","pt":1588415404894,"mc":[{"id":"1.170370562","rc":[{"atb":[[1.43,0]],"id":9625043}],"con":true,"img":false}]}
{"op":"mcm","clk":"1350009546","pt":1588415407148,"mc":[{"id":"1.170370562","rc":[{"trd":[[1.45,833.23]],"ltp":1.45,"tv":833.23,"id":9625043},{"atl":[[1.45,190.05]],"id":9625043}],"con":true,"img":false}]}
{"op":"mcm","clk":"1350009553","pt":1588415407535,"mc":[{"id":"1.170370562","rc":[{"trd":[[1.45,835.59]],"ltp":1.45,"tv":835.59,"id":9625043},{"atl":[[1.45,188.87]],"id":9625043}],"con":true,"img":false}]}
{"op":"mcm","clk":"1350009556","pt":1588415407637,"mc":[{"id":"1.170370562","rc":[{"atl":[[1.43,87.58]],"id":9625043}],"con":true,"img":false}]}
{"op":"mcm","clk":"1350009595","pt":1588415409239,"mc":[{"id":"1.170370562","rc":[{"trd":[[1.43,1609.77]],"ltp":1.43,"tv":1609.77,"id":9625043},{"atl":[[1.43,77.05]],"id":9625043}],"con":true,"img":false}]}
{"op":"mcm","clk":"1350009599","pt":1588415409291,"mc":[{"id":"1.170370562","rc":[{"atl":[[1.43,827.05]],"id":9625043}],"con":true,"img":false}]}
{"op":"mcm","clk":"1350009626","pt":1588415410537,"mc":[{"id":"1.170370562","rc":[{"atl":[[1.41,492.02]],"id":9625043}],"con":true,"img":false}]}
{"op":"mcm","clk":"1350009647","pt":1588415411215,"mc":[{"id":"1.170370562","rc":[{"trd":[[1.4,8352.05]],"ltp":1.4,"tv":8352.05,"id":9625043},{"atb":[[1.4,0]],"id":9625043},{"atl":[[1.39,175.53]],"id":9625043}],"con":true,"img":false}]}
{"op":"mcm","clk":"1350009660","pt":1588415411942,"mc":[{"id":"1.170370562","rc":[{"trd":[[1.39,5324.68]],"ltp":1.39,"tv":5324.68,"id":9625043},{"atl":[[1.39,166.78]],"id":9625043}],"con":true,"img":false}]}
{"op":"mcm","clk":"1350009665","pt":1588415412197,"mc":[{"id":"1.170370562","rc":[{"atl":[[1.43,77.05]],"id":9625043}],"con":true,"img":false}]}
{"op":"mcm","clk":"1350009688","pt":1588415413026,"mc":[{"id":"1.170370562","rc":[{"atb":[[1.34,1100.3]],"id":9625043},{"atl":[[1.45,188.32]],"id":9625043}],"con":true,"img":false}]}
{"op":"mcm","clk":"1350009709","pt":1588415414011,"mc":[{"id":"1.170370562","rc":[{"atl":[[1.41,0]],"id":9625043}],"con":true,"img":false}]}
{"op":"mcm","clk":"1350009725","pt":1588415414527,"mc":[{"id":"1.170370562","rc":[{"atl":[[1.54,0]],"id":9625043}],"con":true,"img":false}]}
{"op":"mcm","clk":"1350009732","pt":1588415414734,"mc":[{"id":"1.170370562","rc":[{"atb":[[2.12,0]],"id":9631798}],"con":true,"img":false}]}
{"op":"mcm","clk":"1350009761","pt":1588415415712,"mc":[{"id":"1.170370562","rc":[{"atl":[[1.39,0]],"id":9625043}],"con":true,"img":false}]}
{"op":"mcm","clk":"1350009772","pt":1588415416229,"mc":[{"id":"1.170370562","rc":[{"atl":[[1.45,186.78]],"id":9625043}],"con":true,"img":false}]}
{"op":"mcm","clk":"1350009781","pt":1588415416437,"mc":[{"id":"1.170370562","rc":[{"atl":[[1.4,156.49]],"id":9625043}],"con":true,"img":false}]}
{"op":"mcm","clk":"1350009785","pt":1588415416595,"mc":[{"id":"1.170370562","rc":[{"atl":[[1.4,312.99],[1.38,500]],"id":9625043}],"con":true,"img":false}]}
{"op":"mcm","clk":"1350009795","pt":1588415417010,"mc":[{"id":"1.170370562","rc":[{"atl":[[1.38,656.49]],"id":9625043}],"con":true,"img":false}]}
{"op":"mcm","clk":"1350009799","pt":1588415417216,"mc":[{"id":"1.170370562","rc":[{"atl":[[1.41,354.6],[1.38,812.99]],"id":9625043}],"con":true,"img":false}]}
{"op":"mcm","clk":"1350009801","pt":1588415417421,"mc":[{"id":"1.170370562","rc":[{"trd":[[1.38,3904.93]],"ltp":1.38,"tv":3904.93,"id":9625043},{"atl":[[1.38,812.36]],"id":9625043}],"con":true,"img":false}]}
{"op":"mcm","clk":"1350009805","pt":1588415417527,"mc":[{"id":"1.170370562","rc":[{"atl":[[1.52,0]],"id":9625043}],"con":true,"img":false}]}
{"op":"mcm","clk":"1350009812","pt":1588415417736,"mc":[{"id":"1.170370562","rc":[{"atl":[[1.38,968.86]],"id":9625043}],"con":true,"img":false}]}
{"op":"mcm","clk":"1350009817","pt":1588415418044,"mc":[{"id":"1.170370562","rc":[{"atb":[[1.34,132.45]],"id":9625043},{"atl":[[1.38,1125.36]],"id":9625043}],"con":true,"img":false}]}
{"op":"mcm","clk":"1350009819","pt":1588415418144,"mc":[{"id":"1.170370562","rc":[{"atb":[[1.35,66.48]],"id":9625043}],"con":true,"img":false}]}
{"op":"mcm","clk":"1350009831","pt":1588415418820,"mc":[{"id":"1.170370562","rc":[{"atl":[[1.38,1191.85]],"id":9625043}],"con":true,"img":false}]}
{"op":"mcm","clk":"1350009836","pt":1588415419026,"mc":[{"id":"1.170370562","rc":[{"atl":[[1.38,1258.34]],"id":9625043}],"con":true,"img":false}]}
{"op":"mcm","clk":"1350009838","pt":1588415419129,"mc":[{"id":"1.170370562","rc":[{"atb":[[1.35,243.79]],"id":9625043}],"con":true,"img":false}]}
{"op":"mcm","clk":"1350009840","pt":1588415419231,"mc":[{"id":"1.170370562","rc":[{"atl":[[1.38,1324.83]],"id":9625043}],"con":true,"img":false}]}
{"op":"mcm","clk":"1350009842","pt":1588415419436,"mc":[{"id":"1.170370562","rc":[{"atl":[[1.38,1391.32]],"id":9625043}],"con":true,"img":false}]}
{"op":"mcm","clk":"1350009844","pt":1588415419540,"mc":[{"id":"1.170370562","rc":[{"atb":[[1.28,0]],"id":9625043}],"con":true,"img":false}]}
{"op":"mcm","clk":"1350009860","pt":1588415420004,"mc":[{"id":"1.170370562","rc":[{"atb":[[2.3,350.35]],"id":9631798}],"con":true,"img":false}]}
{"op":"mcm","clk":"1350009871","pt":1588415420417,"mc":[{"id":"1.170370562","rc":[{"atb":[[1.18,0]],"id":9625043}],"con":true,"img":false}]}
{"op":"mcm","clk":"1350009883","pt":1588415420624,"mc":[{"id":"1.170370562","rc":[{"atb":[[1.35,66.48]],"id":9625043}],"con":true,"img":false}]}
{"op":"mcm","clk":"1350009911","pt":1588415422017,"mc":[{"id":"1.170370562","rc":[{"atl":[[1.42,177.3]],"id":9625043}],"con":true,"img":false}]}
{"op":"mcm","clk":"1350009924","pt":1588415422639,"mc":[{"id":"1.170370562","rc":[{"atl":[[1.49,354.6]],"id":9625043}],"con":true,"img":false}]}
{"op":"mcm","clk":"1350009947","pt":1588415423417,"mc":[{"id":"1.170370562","rc":[{"atb":[[1.34,0]],"id":9625043}],"con":true,"img":false}]}
{"op":"mcm","clk":"1350009950","pt":1588415423623,"mc":[{"id":"1.170370562","rc":[{"atl":[[1.38,765.32]],"id":9625043}],"con":true,"img":false}]}
{"op":"mcm","clk":"1350009954","pt":1588415423728,"mc":[{"id":"1.170370562","rc":[{"atb":[[1.34,199.96]],"id":9625043}],"con":true,"img":false}]}
{"op":"mcm","clk":"1350009956","pt":1588415423932,"mc":[{"id":"1.170370562","rc":[{"atb":[[1.34,399.93]],"id":9625043}],"con":true,"img":false}]}
{"op":"mcm","clk":"1350009958","pt":1588415424036,"mc":[{"id":"1.170370562","rc":[{"atl":[[1.42,0]],"id":9625043}],"con":true,"img":false}]}
{"op":"mcm","clk":"1350009961","pt":1588415424245,"mc":[{"id":"1.170370562","rc":[{"atb":[[1.36,66.48]],"id":9625043}],"con":true,"img":false}]}
{"op":"mcm","clk":"1350009971","pt":1588415424655,"mc":[{"id":"1.170370562","rc":[{"atl":[[1.4,0]],"id":9625043}],"con":true,"img":false}]}
{"op":"mcm","clk":"1350009995","pt":1588415426433,"mc":[{"id":"1.170370562","rc":[{"atb":[[1.16,354.6]],"id":9625043},{"atl":[[1.37,177.3]],"id":9625043}],"con":true,"img":false}]}
{"op":"mcm","clk":"1350010005","pt":1588415427054,"mc":[{"id":"1.170370562","rc":[{"atl":[[1.37,0]],"id":9625043}],"con":true,"img":false}]}
{"op":"mcm","clk":"1350010042","pt":1588415428816,"mc":[{"id":"1.170370562","rc":[{"atb":[[1.33,85.75]],"id":9625043}],"con":true,"img":false}]}
{"op":"mcm","clk":"1350010061","pt":1588415429543,"mc":[{"id":"1.170370562","rc":[{"atl":[[1.5,175.2]],"id":9625043}],"con":true,"img":false}]}
{"op":"mcm","clk":"1350010080","pt":1588415430055,"mc":[{"id":"1.170370562","rc":[{"trd":[[1.38,3904.97]],"ltp":1.38,"tv":3904.97,"id":9625043},{"atl":[[1.38,765.3]],"id":9625043}],"con":true,"img":false}]}
{"op":"mcm","clk":"1350010098","pt":1588415430518,"mc":[{"id":"1.170370562","rc":[{"atb":[[1.33,0]],"id":9625043}],"con":true,"img":false}]}
{"op":"mcm","clk":"1350010101","pt":1588415430624,"mc":[{"id":"1.170370562","rc":[{"trd":[[1.36,987.04]],"ltp":1.36,"tv":987.04,"id":9625043},{"atb":[[1.36,56.48]],"id":9625043}],"con":true,"img":false}]}
{"op":"mcm","clk":"1350010104","pt":1588415430727,"mc":[{"id":"1.170370562","rc":[{"atb":[[2.3,0]],"id":9631798}],"con":true,"img":false}]}
{"op":"mcm","clk":"1350010110","pt":1588415430933,"mc":[{"id":"1.170370562","rc":[{"trd":[[1.38,3924.97]],"ltp":1.38,"tv":3924.97,"id":9625043},{"atl":[[1.38,755.3]],"id":9625043}],"con":true,"img":false}]}
{"op":"mcm","clk":"1350010144","pt":1588415432439,"mc":[{"id":"1.170370562","rc":[{"atb":[[1.37,22.16]],"id":9625043}],"con":true,"img":false}]}
{"op":"mcm","clk":"1350010149","pt":1588415432544,"mc":[{"id":"1.170370562","rc":[{"trd":[[1.37,2100.59]],"ltp":1.37,"tv":2100.59,"id":9625043},{"atb":[[1.37,17.1]],"id":9625043}],"con":true,"img":false}]}
{"op":"mcm","clk":"1350010162","pt":1588415433162,"mc":[{"id":"1.170370562","rc":[{"trd":[[1.35,1331.23],[1.37,2134.81],[1.36,1100.02]],"ltp":1.35,"tv":4566.05,"id":9625043},{"atb":[[1.37,0],[1.35,40.08],[1.36,0]],"id":9625043}],"con":true,"img":false}]}
{"op":"mcm","clk":"1350010173","pt":1588415433733,"mc":[{"id":"1.170370562","rc":[{"atl":[[1.41,0]],"id":9625043}],"con":true,"img":false}]}
{"op":"mcm","clk":"1350010179","pt":1588415433940,"mc":[{"id":"1.170370562","rc":[{"trd":[[1.38,5228.51]],"ltp":1.38,"tv":5228.51,"id":9625043},{"atl":[[1.38,103.53]],"id":9625043}],"con":true,"img":false}]}
{"op":"mcm","clk":"1350010185","pt":1588415434149,"mc":[{"id":"1.170370562","rc":[{"atl":[[1.37,44.32]],"id":9625043}],"con":true,"img":false}]}
{"op":"mcm","clk":"1350010198","pt":1588415434822,"mc":[{"id":"1.170370562","rc":[{"atl":[[1.37,88.65]],"id":9625043}],"con":true,"img":false}]}
{"op":"mcm","clk":"1350010227","pt":1588415435933,"mc":[{"id":"1.170370562","rc":[{"atb":[[1.33,44.32]],"id":9625043}],"con":true,"img":false}]}
{"op":"mcm","clk":"1350010236","pt":1588415436659,"mc":[{"id":"1.170370562","rc":[{"atb":[[1.32,44.44]],"id":9625043}],"con":true,"img":false}]}
{"op":"mcm","clk":"1350010239","pt":1588415436762,"mc":[{"id":"1.170370562","rc":[{"trd":[[1.37,2200.81]],"ltp":1.37,"tv":2200.81,"id":9625043},{"atl":[[1.37,55.65]],"id":9625043}],"con":true,"img":false}]}
{"op":"mcm","clk":"1350010243","pt":1588415436863,"mc":[{"id":"1.170370562","rc":[{"trd":[[1.35,1332.33]],"ltp":1.35,"tv":1332.33,"id":9625043},{"atb":[[1.35,39.53]],"id":9625043}],"con":true,"img":false}]}
{"op":"mcm","clk":"1350010257","pt":1588415437330,"mc":[{"id":"1.170370562","rc":[{"trd":[[1.35,1359.53]],"ltp":1.35,"tv":1359.53,"id":9625043},{"atb":[[1.35,25.93]],"id":9625043}],"con":true,"img":false}]}
{"op":"mcm","clk":"1350010281","pt":1588415438363,"mc":[{"id":"1.170370562","rc":[{"atb":[[1.34,0]],"id":9625043}],"con":true,"img":false}]}
{"op":"mcm","clk":"1350010320","pt":1588415440133,"mc":[{"id":"1.170370562","rc":[{"atl":[[1.37,0]],"id":9625043}],"con":true,"img":false}]}
{"op":"mcm","clk":"1350010328","pt":1588415440547,"mc":[{"id":"1.170370562","rc":[{"atb":[[1.37,66.48]],"id":9625043}],"con":true,"img":false}]}
{"op":"mcm","clk":"1350010349","pt":1588415441432,"mc":[{"id":"1.170370562","rc":[{"atb":[[1.33,0]],"id":9625043}],"con":true,"img":false}]}
{"op":"mcm","clk":"1350010353","pt":1588415441534,"mc":[{"id":"1.170370562","rc":[{"atb":[[1.37,132.97]],"id":9625043}],"con":true,"img":false}]}
{"op":"mcm","clk":"1350010361","pt":1588415441743,"mc":[{"id":"1.170370562","rc":[{"atb":[[1.32,0.11]],"id":9625043}],"con":true,"img":false}]}
{"op":"mcm","clk":"1350010366","pt":1588415441846,"mc":[{"id":"1.170370562","rc":[{"trd":[[1.29,692.84],[1.37,2466.77],[1.35,1411.41],[1.32,643.07]],"ltp":1.29,"tv":5214.09,"id":9625043},{"atb":[[1.37,0],[1.35,0],[1.32,0]],"id":9625043},{"atl":[[1.28,590.93]],"id":9625043},{"trd":[[4.4,7.15]],"ltp":4.4,"tv":7.15,"id":9631798},{"atl":[[4.4,0]],"id":9631798}],"con":true,"img":false}]}
{"op":"mcm","clk":"1350010378","pt":1588415442523,"mc":[{"id":"1.170370562","rc":[{"trd":[[1.28,110]],"ltp":1.28,"tv":110.0,"id":9625043},{"atl":[[1.28,535.93]],"id":9625043}],"con":true,"img":false}]}
{"op":"mcm","clk":"1350010381","pt":1588415442628,"mc":[{"id":"1.170370562","rc":[{"atb":[[1.16,370.31]],"id":9625043}],"con":true,"img":false}]}
{"op":"mcm","clk":"1350010383","pt":1588415442734,"mc":[{"id":"1.170370562","rc":[{"atl":[[1.28,0]],"id":9625043}],"con":true,"img":false}]}
{"op":"mcm","clk":"1350010386","pt":1588415442835,"mc":[{"id":"1.170370562","rc":[{"trd":[[1.27,16.3]],"ltp":1.27,"tv":16.3,"id":9625043},{"atl":[[1.27,491.98]],"id":9625043},{"trd":[[4.6,0.02]],"ltp":4.6,"tv":0.02,"id":9631798},{"atl":[[4.6,0]],"id":9631798}],"con":true,"img":false}]}
{"op":"mcm","clk":"1350010391","pt":1588415443048,"mc":[{"id":"1.170370562","rc":[{"trd":[[1.27,126.3]],"ltp":1.27,"tv":126.3,"id":9625043},{"atl":[[1.27,436.98]],"id":9625043}],"con":true,"img":false}]}
{"op":"mcm","clk":"1350010409","pt":1588415444135,"mc":[{"id":"1.170370562","rc":[{"trd":[[1.27,259.28]],"ltp":1.27,"tv":259.28,"id":9625043},{"atl":[[1.27,370.49]],"id":9625043}],"con":true,"img":false}]}
{"op":"mcm","clk":"1350010434","pt":1588415445429,"mc":[{"id":"1.170370562","rc":[{"trd":[[1.27,509.28]],"ltp":1.27,"tv":509.28,"id":9625043},{"atb":[[1.16,354.6]],"id":9625043},{"atl":[[1.27,245.49]],"id":9625043}],"con":true,"img":false}]}
{"op":"mcm","clk":"1350010477","pt":1588415446832,"mc":[{"id":"1.170370562","rc":[{"atb":[[1.2,1165.01]],"id":9625043}],"con":true,"img":false}]}
{"op":"mcm","clk":"1350010494","pt":1588415447452,"mc":[{"id":"1.170370562","rc":[{"atl":[[1.32,44.32]],"id":9625043}],"con":true,"img":false}]}
{"op":"mcm","clk":"1350010514","pt":1588415448176,"mc":[{"id":"1.170370562","rc":[{"atb":[[1.01,1003.5]],"id":9625043}],"con":true,"img":false}]}
{"op":"mcm","clk":"1350010518","pt":1588415448384,"mc":[{"id":"1.170370562","rc":[{"atb":[[1.01,1001.76]],"id":9625043}],"con":true,"img":false}]}
{"op":"mcm","clk":"1350010524","pt":1588415448436,"mc":[{"id":"1.170370562","rc":[{"atb":[[1.26,55.43]],"id":9625043}],"con":true,"img":false}]}
{"op":"mcm","clk":"1350010525","pt":1588415448542,"mc":[{"id":"1.170370562","rc":[{"atl":[[1.27,289.82]],"id":9625043}],"con":true,"img":false}]}
{"op":"mcm","clk":"1350010530","pt":1588415448658,"mc":[{"id":"1.170370562","rc":[{"atb":[[1.01,1001.72]],"id":9625043}],"con":true,"img":false}]}
{"op":"mcm","clk":"1350010553","pt":1588415449474,"mc":[{"id":"1.170370562","rc":[{"atl":[[1.33,66.48]],"id":9625043}],"con":true,"img":false}]}
{"op":"mcm","clk":"1350010555","pt":1588415449576,"mc":[{"id":"1.170370562","rc":[{"atb":[[1.26,122.45]],"id":9625043}],"con":true,"img":false}]}
{"op":"mcm","clk":"1350010569","pt":1588415450252,"mc":[{"id":"1.170370562","rc":[{"atl":[[1.33,132.97],[1.27,44.32]],"id":9625043}],"con":true,"img":false}]}
{"op":"mcm","clk":"1350010573","pt":1588415450457,"mc":[{"id":"1.170370562","rc":[{"atl":[[1.33,199.46]],"id":9625043}],"con":true,"img":false}]}
{"op":"mcm","clk":"1350010577","pt":1588415450562,"mc":[{"id":"1.170370562","rc":[{"atl":[[1.33,265.95]],"id":9625043}],"con":true,"img":false}]}
{"op":"mcm","clk":"1350010581","pt":1588415450663,"mc":[{"id":"1.170370562","rc":[{"atb":[[1.26,248.44]],"id":9625043}],"con":true,"img":false}]}
{"op":"mcm","clk":"1350010589","pt":1588415450971,"mc":[{"id":"1.170370562","rc":[{"atl":[[1.37,240]],"id":9625043}],"con":true,"img":false}]}
{"op":"mcm","clk":"1350010596","pt":1588415451284,"mc":[{"id":"1.170370562","rc":[{"trd":[[1.26,588.13]],"ltp":1.26,"tv":588.13,"id":9625043},{"atb":[[1.26,0]],"id":9625043},{"atl":[[1.26,106.12]],"id":9625043},{"trd":[[4.8,0.01]],"ltp":4.8,"tv":0.01,"id":9631798},{"atl":[[4.8,0]],"id":9631798}],"con":true,"img":false}]}
{"op":"mcm","clk":"1350010600","pt":1588415451337,"mc":[{"id":"1.170370562","rc":[{"atl":[[1.3,240]],"id":9625043}],"con":true,"img":false}]}
{"op":"mcm","clk":"1350010607","pt":1588415451544,"mc":[{"id":"1.170370562","rc":[{"atl":[[1.25,66.48]],"id":9625043}],"con":true,"img":false}]}
{"op":"mcm","clk":"1350010610","pt":1588415451649,"mc":[{"id":"1.170370562","rc":[{"atb":[[1.21,44.32]],"id":9625043}],"con":true,"img":false}]}
{"op":"mcm","clk":"1350010615","pt":1588415451752,"mc":[{"id":"1.170370562","rc":[{"atl":[[1.25,132.97]],"id":9625043}],"con":true,"img":false}]}
{"op":"mcm","clk":"1350010619","pt":1588415451959,"mc":[{"id":"1.170370562","rc":[{"atl":[[1.25,199.46]],"id":9625043}],"con":true,"img":false}]}
{"op":"mcm","clk":"1350010623","pt":1588415452060,"mc":[{"id":"1.170370562","rc":[{"atl":[[1.25,439.46]],"id":9625043}],"con":true,"img":false}]}
{"op":"mcm","clk":"1350010629","pt":1588415452372,"mc":[{"id":"1.170370562","rc":[{"atb":[[1.22,44.32]],"id":9625043}],"con":true,"img":false}]}
{"op":"mcm","clk":"1350010634","pt":1588415452576,"mc":[{"id":"1.170370562","rc":[{"atl":[[1.25,505.95]],"id":9625043}],"con":true,"img":false}]}
{"op":"mcm","clk":"1350010638","pt":1588415452679,"mc":[{"id":"1.170370562","rc":[{"atl":[[1.25,572.44]],"id":9625043}],"con":true,"img":false}]}
{"op":"mcm","clk":"1350010642","pt":1588415452782,"mc":[{"id":"1.170370562","rc":[{"trd":[[1.22,20.83],[1.24,0.03]],"ltp":1.22,"tv":20.86,"id":9625043},{"atb":[[1.22,41.96]],"id":9625043},{"trd":[[5.1,0.01]],"ltp":5.1,"tv":0.01,"id":9631798},{"atl":[[5.1,0]],"id":9631798}],"con":true,"img":false}]}
{"op":"mcm","clk":"1350010659","pt":1588415453455,"mc":[{"id":"1.170370562","rc":[{"trd":[[1.25,453.21]],"ltp":1.25,"tv":453.21,"id":9625043},{"atl":[[1.25,345.83]],"id":9625043},{"atb":[[2,4]],"id":9631798}],"con":true,"img":false}]}
{"op":"mcm","clk":"1350010663","pt":1588415453665,"mc":[{"id":"1.170370562","rc":[{"atb":[[1.23,0.47]],"id":9625043}],"con":true,"img":false}]}
{"op":"mcm","clk":"1350010666","pt":1588415453768,"mc":[{"id":"1.170370562","rc":[{"trd":[[1.25,453.29]],"ltp":1.25,"tv":453.29,"id":9625043},{"atl":[[1.25,345.79],[1.3,0]],"id":9625043}],"con":true,"img":false}]}
{"op":"mcm","clk":"1350010668","pt":1588415453873,"mc":[{"id":"1.170370562","rc":[{"atl":[[1.45,0]],"id":9625043}],"con":true,"img":false}]}
{"op":"mcm","clk":"1350010672","pt":1588415454078,"mc":[{"id":"1.170370562","rc":[{"atb":[[2.8,319.92]],"id":9631798},{"atl":[[7.8,2.08]],"id":9631798}],"con":true,"img":false}]}
{"op":"mcm","clk":"1350010675","pt":1588415454183,"mc":[{"id":"1.170370562","rc":[{"trd":[[1.2,306.51],[1.22,104.77],[1.21,88.7],[1.23,0.94]],"ltp":1.2,"tv":500.92,"id":9625043},{"atb":[[1.2,1151.83],[1.21,0],[1.23,0],[1.22,0]],"id":9625043},{"trd":[[5.6,0.01]],"ltp":5.6,"tv":0.01,"id":9631798},{"atl":[[5.6,0]],"id":9631798}],"con":true,"img":false}]}
{"op":"mcm","clk":"1350010676","pt":1588415454387,"mc":[{"id":"1.170370562","rc":[{"trd":[[1.25,494.47]],"ltp":1.25,"tv":494.47,"id":9625043},{"atb":[[1.24,55]],"id":9625043},{"atl":[[1.25,325.2]],"id":9625043}],"con":true,"img":false}]}
{"op":"mcm","clk":"1350010678","pt":1588415454545,"mc":[{"id":"1.170370562","rc":[{"atl":[[1.38,0]],"id":9625043}],"con":true,"img":false}]}
{"op":"mcm","clk":"1350010690","pt":1588415455373,"mc":[{"id":"1.170370562","rc":[{"trd":[[1.24,0.4]],"ltp":1.24,"tv":0.4,"id":9625043},{"atb":[[1.24,54.82]],"id":9625043}],"con":true,"img":false}]}
{"op":"mcm","clk":"1350010701","pt":1588415455888,"mc":[{"id":"1.170370562","rc":[{"atb":[[1.16,0]],"id":9625043}],"con":true,"img":false}]}
{"op":"mcm","clk":"1350010707","pt":1588415455941,"mc":[{"id":"1.170370562","rc":[{"trd":[[1.24,44.14]],"ltp":1.24,"tv":44.14,"id":9625043},{"atb":[[1.24,32.95]],"id":9625043}],"con":true,"img":false}]}
{"op":"mcm","clk":"1350010717","pt":1588415456355,"mc":[{"id":"1.170370562","rc":[{"trd":[[1.25,604.47]],"ltp":1.25,"tv":604.47,"id":9625043},{"atl":[[1.25,270.2]],"id":9625043}],"con":true,"img":false}]}
{"op":"mcm","clk":"1350010723","pt":1588415456566,"mc":[{"id":"1.170370562","rc":[{"trd":[[1.25,714.47]],"ltp":1.25,"tv":714.47,"id":9625043},{"atl":[[1.25,215.2]],"id":9625043}],"con":true,"img":false}]}
{"op":"mcm","clk":"1350010730","pt":1588415456773,"mc":[{"id":"1.170370562","rc":[{"atb":[[1.09,333]],"id":9625043},{"atb":[[2.8,0]],"id":9631798},{"atl":[[7.8,0]],"id":9631798}],"con":true,"img":false}]}
{"op":"mcm","clk":"1350010734","pt":1588415456875,"mc":[{"id":"1.170370562","rc":[{"trd":[[1.24,47.68]],"ltp":1.24,"tv":47.68,"id":9625043},{"atb":[[1.24,31.18]],"id":9625043},{"atl":[[1.31,44.32]],"id":9625043}],"con":true,"img":false}]}
{"op":"mcm","clk":"1350010736","pt":1588415456981,"mc":[{"id":"1.170370562","rc":[{"trd":[[1.2,433.18],[1.21,221.68],[1.24,110.04]],"ltp":1.2,"tv":764.9,"id":9625043},{"atb":[[1.2,1088.49],[1.24,0]],"id":9625043}],"con":true,"img":false}]}
{"op":"mcm","clk":"1350010740","pt":1588415457082,"mc":[{"id":"1.170370562","rc":[{"atb":[[1.08,1317.92]],"id":9625043}],"con":true,"img":false}]}
{"op":"mcm","clk":"1350010742","pt":1588415457185,"mc":[{"id":"1.170370562","rc":[{"atb":[[1.21,66.48]],"id":9625043}],"con":true,"img":false}]}
{"op":"mcm","clk":"1350010744","pt":1588415457288,"mc":[{"id":"1.170370562","rc":[{"atb":[[1.08,333]],"id":9625043}],"con":true,"img":false}]}
{"op":"mcm","clk":"1350010750","pt":1588415457390,"mc":[{"id":"1.170370562","rc":[{"atb":[[1.21,132.97],[1.07,1317.92]],"id":9625043}],"con":true,"img":false}]}
{"op":"mcm","clk":"1350010753","pt":1588415457493,"mc":[{"id":"1.170370562","rc":[{"atl":[[1.31,88.65]],"id":9625043}],"con":true,"img":false}]}
{"op":"mcm","clk":"1350010763","pt":1588415457752,"mc":[{"id":"1.170370562","rc":[{"atb":[[1.22,325.22],[1.07,333]],"id":9625043},{"atl":[[1.25,132.97]],"id":9625043}],"con":true,"img":false}]}
{"op":"mcm","clk":"1350010768","pt":1588415457856,"mc":[{"id":"1.170370562","rc":[{"trd":[[1.25,715.32]],"ltp":1.25,"tv":715.32,"id":9625043},{"atl":[[1.25,132.55]],"id":9625043}],"con":true,"img":false}]}
{"op":"mcm","clk":"1350010795","pt":1588415458784,"mc":[{"id":"1.170370562","rc":[{"trd":[[1.22,109.92]],"ltp":1.22,"tv":109.92,"id":9625043},{"atb":[[1.22,322.64]],"id":9625043}],"con":true,"img":false}]}
{"op":"mcm","clk":"1350010808","pt":1588415459147,"mc":[{"id":"1.170370562","rc":[{"atb":[[1.09,0]],"id":9625043},{"atl":[[1.49,0]],"id":9625043}],"con":true,"img":false}]}
{"op":"mcm","clk":"1350010815","pt":1588415459455,"mc":[{"id":"1.170370562","rc":[{"atb":[[1.04,1339.53]],"id":9625043}],"con":true,"img":false}]}
{"op":"mcm","clk":"1350010830","pt":1588415460179,"mc":[{"id":"1.170370562","rc":[{"atl":[[1.37,0]],"id":9625043}],"con":true,"img":false}]}
{"op":"mcm","clk":"1350010833","pt":1588415460385,"mc":[{"id":"1.170370562","rc":[{"atb":[[1.21,0]],"id":9625043}],"con":true,"img":false}]}
{"op":"mcm","clk":"1350010839","pt":1588415460593,"mc":[{"id":"1.170370562","rc":[{"atl":[[1.24,44.32]],"id":9625043}],"con":true,"img":false}]}
{"op":"mcm","clk":"1350010854","pt":1588415461060,"mc":[{"id":"1.170370562","rc":[{"atl":[[1.24,88.65]],"id":9625043}],"con":true,"img":false}]}
{"op":"mcm","clk":"1350010860","pt":1588415461268,"mc":[{"id":"1.170370562","rc":[{"atb":[[1.22,389.13]],"id":9625043}],"con":true,"img":false}]}
{"op":"mcm","clk":"1350010866","pt":1588415461371,"mc":[{"id":"1.170370562","rc":[{"atb":[[1.22,444.13]],"id":9625043}],"con":true,"img":false}]}
{"op":"mcm","clk":"1350010871","pt":1588415461474,"mc":[{"id":"1.170370562","rc":[{"trd":[[1.22,119.2]],"ltp":1.22,"tv":119.2,"id":9625043},{"atb":[[1.22,505.98]],"id":9625043}],"con":true,"img":false}]}
{"op":"mcm","clk":"1350010876","pt":1588415461578,"mc":[{"id":"1.170370562","rc":[{"atl":[[1.33,0]],"id":9625043}],"con":true,"img":false}]}
{"op":"mcm","clk":"1350010883","pt":1588415461786,"mc":[{"id":"1.170370562","rc":[{"trd":[[1.24,117.04]],"ltp":1.24,"tv":117.04,"id":9625043},{"atb":[[1.22,560.98]],"id":9625043},{"atl":[[1.24,85.15]],"id":9625043},{"atb":[[1.08,0]],"id":9631798}],"con":true,"img":false}]}
{"op":"mcm","clk":"1350010892","pt":1588415462095,"mc":[{"id":"1.170370562","rc":[{"atl":[[1000,2.67]],"id":9625043}],"con":true,"img":false}]}
{"op":"mcm","clk":"1350010904","pt":1588415462251,"mc":[{"id":"1.170370562","rc":[{"atb":[[1.07,0]],"id":9631798}],"con":true,"img":false}]}
{"op":"mcm","clk":"1350010909","pt":1588415462358,"mc":[{"id":"1.170370562","rc":[{"atl":[[1.26,0]],"id":9625043}],"con":true,"img":false}]}
{"op":"mcm","clk":"1350010916","pt":1588415462566,"mc":[{"id":"1.170370562","rc":[{"trd":[[1.22,124.35]],"ltp":1.22,"tv":124.35,"id":9625043},{"atb":[[1.22,558.4]],"id":9625043}],"con":true,"img":false}]}
{"op":"mcm","clk":"1350010930","pt":1588415462983,"mc":[{"id":"1.170370562","rc":[{"atl":[[1000,0.09]],"id":9625043}],"con":true,"img":false}]}
{"op":"mcm","clk":"1350010935","pt":1588415463088,"mc":[{"id":"1.170370562","rc":[{"atl":[[1.27,0],[1.32,0],[1.31,0],[1.24,0]],"id":9625043}],"con":true,"img":false}]}
{"op":"mcm","clk":"1350010945","pt":1588415463550,"mc":[{"id":"1.170370562","rc":[{"trd":[[1.25,980.42]],"ltp":1.25,"tv":980.42,"id":9625043},{"atb":[[1.29,617.45]],"id":9625043},{"atl":[[1.25,0]],"id":9625043},{"atl":[[1000,2.05]],"id":9631798}],"con":true,"img":false}]}
{"op":"mcm","clk":"1350010948","pt":1588415463655,"mc":[{"id":"1.170370562","rc":[{"atb":[[1.27,100]],"id":9625043}],"con":true,"img":false}]}
{"op":"mcm","clk":"1350010950","pt":1588415463758,"mc":[{"id":"1.170370562","rc":[{"atl":[[1000,0.06]],"id":9631798}],"con":true,"img":false}]}
{"op":"mcm","clk":"1350010954","pt":1588415463863,"mc":[{"id":"1.170370562","rc":[{"atb":[[1.29,1367.45]],"id":9625043},{"atl":[[1000,0.05]],"id":9625043}],"con":true,"img":false}]}
{"op":"mcm","clk":"1350010960","pt":1588415464072,"mc":[{"id":"1.170370562","rc":[{"atb":[[1.22,425.42]],"id":9625043},{"atl":[[1000,0.05]],"id":9631798}],"con":true,"img":false}]}
{"op":"mcm","clk":"1350010967","pt":1588415464280,"mc":[{"id":"1.170370562","rc":[{"atb":[[1.23,66.48],[1.29,0]],"id":9625043}],"con":true,"img":false}]}
{"op":"mcm","clk":"1350010977","pt":1588415464593,"mc":[{"id":"1.170370562","rc":[{"atl":[[1000,2.05]],"id":9631798}],"con":true,"img":false}]}
{"op":"mcm","clk":"1350010985","pt":1588415464800,"mc":[{"id":"1.170370562","rc":[{"atb":[[1.06,1317.92]],"id":9625043},{"atl":[[1000,0.06]],"id":9631798}],"con":true,"img":false}]}
{"op":"mcm","clk":"1350010988","pt":1588415464853,"mc":[{"id":"1.170370562","rc":[{"atb":[[1.27,1260.61]],"id":9625043}],"con":true,"img":false}]}
{"op":"mcm","clk":"1350010992","pt":1588415464960,"mc":[{"id":"1.170370562","rc":[{"atb":[[1.25,55]],"id":9625043},{"atl":[[1000,0.05]],"id":9631798}],"con":true,"img":false}]}
{"op":"mcm","clk":"1350010997","pt":1588415465065,"mc":[{"id":"1.170370562","rc":[{"atb":[[1.2,0]],"id":9625043}],"con":true,"img":false}]}
{"op":"mcm","clk":"1350011001","pt":1588415465165,"mc":[{"id":"1.170370562","rc":[{"trd":[[1.27,577.33]],"ltp":1.27,"tv":577.33,"id":9625043},{"atb":[[1.27,1226.59]],"id":9625043}],"con":true,"img":false}]}
{"op":"mcm","clk":"1350011010","pt":1588415465377,"mc":[{"id":"1.170370562","rc":[{"atb":[[1.23,0]],"id":9625043}],"con":true,"img":false}]}
{"op":"mcm","clk":"1350011016","pt":1588415465479,"mc":[{"id":"1.170370562","rc":[{"atb":[[1.25,55.41]],"id":9625043}],"con":true,"img":false}]}
{"op":"mcm","clk":"1350011022","pt":1588415465579,"mc":[{"id":"1.170370562","rc":[{"atl":[[1000,2.05]],"id":9631798}],"con":true,"img":false}]}
{"op":"mcm","clk":"1350011028","pt":1588415465684,"mc":[{"id":"1.170370562","rc":[{"atl":[[1000,0.06]],"id":9631798}],"con":true,"img":false}]}
{"op":"mcm","clk":"1350011037","pt":1588415465895,"mc":[{"id":"1.170370562","rc":[{"atl":[[1000,0.05]],"id":9631798}],"con":true,"img":false}]}
{"op":"mcm","clk":"1350011046","pt":1588415466000,"mc":[{"id":"1.170370562","rc":[{"trd":[[1.27,915.42]],"ltp":1.27,"tv":915.42,"id":9625043},{"atb":[[1.27,1057.55]],"id":9625043}],"con":true,"img":false}]}
{"op":"mcm","clk":"1350011075","pt":1588415466672,"mc":[{"id":"1.170370562","rc":[{"atb":[[1.25,55.64]],"id":9625043},{"atl":[[1000,2.05]],"id":9631798}],"con":true,"img":false}]}
{"op":"mcm","clk":"1350011079","pt":1588415466877,"mc":[{"id":"1.170370562","rc":[{"atl":[[1000,0.06]],"id":9631798}],"con":true,"img":false}]}
{"op":"mcm","clk":"1350011083","pt":1588415467083,"mc":[{"id":"1.170370562","rc":[{"trd":[[1.27,1075.39]],"ltp":1.27,"tv":1075.39,"id":9625043},{"atb":[[1.27,977.56]],"id":9625043},{"atl":[[1000,0.05]],"id":9631798}],"con":true,"img":false}]}
{"op":"mcm","clk":"1350011097","pt":1588415467393,"mc":[{"id":"1.170370562","rc":[{"atl":[[1.39,66.48]],"id":9625043}],"con":true,"img":false}]}
{"op":"mcm","clk":"1350011101","pt":1588415467498,"mc":[{"id":"1.170370562","rc":[{"trd":[[1.27,1175.39]],"ltp":1.27,"tv":1175.39,"id":9625043},{"atb":[[1.27,927.56]],"id":9625043}],"con":true,"img":false}]}
{"op":"mcm","clk":"1350011107","pt":1588415467600,"mc":[{"id":"1.170370562","rc":[{"atl":[[1.39,132.97]],"id":9625043}],"con":true,"img":false}]}
{"op":"mcm","clk":"1350011116","pt":1588415467757,"mc":[{"id":"1.170370562","rc":[{"atl":[[1.39,199.46]],"id":9625043}],"con":true,"img":false}]}
{"op":"mcm","clk":"1350011125","pt":1588415467964,"mc":[{"id":"1.170370562","rc":[{"trd":[[1.27,1186.64]],"ltp":1.27,"tv":1186.64,"id":9625043},{"atb":[[1.27,921.94]],"id":9625043}],"con":true,"img":false}]}
{"op":"mcm","clk":"1350011129","pt":1588415468069,"mc":[{"id":"1.170370562","rc":[{"trd":[[1.27,1188.26]],"ltp":1.27,"tv":1188.26,"id":9625043},{"atb":[[1.27,921.13]],"id":9625043}],"con":true,"img":false}]}
{"op":"mcm","clk":"1350011131","pt":1588415468177,"mc":[{"id":"1.170370562","rc":[{"atb":[[1.17,112]],"id":9625043}],"con":true,"img":false}]}
{"op":"mcm","clk":"1350011153","pt":1588415468892,"mc":[{"id":"1.170370562","rc":[{"atb":[[1.25,0.64],[1.22,315.42]],"id":9625043}],"con":true,"img":false}]}
{"op":"mcm","clk":"1350011157","pt":1588415468996,"mc":[{"id":"1.170370562","rc":[{"trd":[[1.27,1188.35]],"ltp":1.27,"tv":1188.35,"id":9625043},{"atb":[[1.12,112],[1.27,921.08]],"id":9625043}],"con":true,"img":false}]}
{"op":"mcm","clk":"1350011162","pt":1588415469201,"mc":[{"id":"1.170370562","rc":[{"atb":[[1.27,965.41]],"id":9625043},{"atl":[[7.6,0.01]],"id":9631798}],"con":true,"img":false}]}
{"op":"mcm","clk":"1350011184","pt":1588415469768,"mc":[{"id":"1.170370562","rc":[{"atb":[[1.25,5.89],[1.3,44.32]],"id":9625043}],"con":true,"img":false}]}
{"op":"mcm","clk":"1350011190","pt":1588415469873,"mc":[{"id":"1.170370562","rc":[{"trd":[[1.3,19055.15]],"ltp":1.3,"tv":19055.15,"id":9625043},{"atb":[[1.3,43.14]],"id":9625043}],"con":true,"img":false}]}
{"op":"mcm","clk":"1350011199","pt":1588415470076,"mc":[{"id":"1.170370562","rc":[{"atl":[[8.4,0.01]],"id":9631798}],"con":true,"img":false}]}
{"op":"mcm","clk":"1350011208","pt":1588415470592,"mc":[{"id":"1.170370562","rc":[{"atb":[[1.29,44.32]],"id":9625043}],"con":true,"img":false}]}
{"op":"mcm","clk":"1350011211","pt":1588415470692,"mc":[{"id":"1.170370562","rc":[{"atb":[[1.28,212.46]],"id":9625043}],"con":true,"img":false}]}
{"op":"mcm","clk":"1350011218","pt":1588415471009,"mc":[{"id":"1.170370562","rc":[{"atl":[[1.35,0.47]],"id":9625043},{"atl":[[6.4,0.01]],"id":9631798}],"con":true,"img":false}]}
{"op":"mcm","clk":"1350011233","pt":1588415471576,"mc":[{"id":"1.170370562","rc":[{"trd":[[1.28,460.58],[1.3,19141.45],[1.39,5326.43],[1.35,1412.36],[1.29,781.49]],"ltp":1.28,"tv":27122.31,"id":9625043},{"atb":[[1.28,37.17],[1.3,0],[1.29,0]],"id":9625043},{"atl":[[1.39,198.59],[1.35,0]],"id":9625043}],"con":true,"img":false}]}
{"op":"mcm","clk":"1350011256","pt":1588415472199,"mc":[{"id":"1.170370562","rc":[{"atl":[[5.8,0.01]],"id":9631798}],"con":true,"img":false}]}
{"op":"mcm","clk":"1350011287","pt":1588415473283,"mc":[{"id":"1.170370562","rc":[{"atb":[[1.25,8.47]],"id":9625043}],"con":true,"img":false}]}
{"op":"mcm","clk":"1350011295","pt":1588415473488,"mc":[{"id":"1.170370562","rc":[{"atb":[[1.27,44.32]],"id":9625043}],"con":true,"img":false}]}
{"op":"mcm","clk":"1350011296","pt":1588415473592,"mc":[{"id":"1.170370562","rc":[{"atb":[[1.3,200]],"id":9625043}],"con":true,"img":false}]}
{"op":"mcm","clk":"1350011304","pt":1588415474004,"mc":[{"id":"1.170370562","rc":[{"atb":[[1.3,496.01],[1.22,0]],"id":9625043}],"con":true,"img":false}]}
{"op":"mcm","clk":"1350011317","pt":1588415474573,"mc":[{"id":"1.170370562","rc":[{"atl":[[6.4,0],[5.8,0],[7.6,0],[6.6,0],[8.4,0]],"id":9631798}],"con":true,"img":false}]}
{"op":"mcm","clk":"1350011329","pt":1588415474987,"mc":[{"id":"1.170370562","rc":[{"trd":[[1.3,19395.23]],"ltp":1.3,"tv":19395.23,"id":9625043},{"atb":[[1.3,481.12]],"id":9625043}],"con":true,"img":false}]}
{"op":"mcm","clk":"1350011337","pt":1588415475298,"mc":[{"id":"1.170370562","rc":[{"atb":[[1.32,112]],"id":9625043}],"con":true,"img":false}]}
{"op":"mcm","clk":"1350011344","pt":1588415475709,"mc":[{"id":"1.170370562","rc":[{"atb":[[1.28,0]],"id":9625043}],"con":true,"img":false}]}
{"op":"mcm","clk":"1350011349","pt":1588415475813,"mc":[{"id":"1.170370562","rc":[{"atb":[[1.25,3.22]],"id":9625043}],"con":true,"img":false}]}
{"op":"mcm","clk":"1350011370","pt":1588415476283,"mc":[{"id":"1.170370562","rc":[{"trd":[[1.39,5328.45]],"ltp":1.39,"tv":5328.45,"id":9625043},{"atl":[[1.39,197.57]],"id":9625043}],"con":true,"img":false}]}
{"op":"mcm","clk":"1350011387","pt":1588415476795,"mc":[{"id":"1.170370562","rc":[{"atl":[[1.36,44.32]],"id":9625043}],"con":true,"img":false}]}
{"op":"mcm","clk":"1350011395","pt":1588415477205,"mc":[{"id":"1.170370562","rc":[{"atb":[[2.42,341.44]],"id":9631798}],"con":true,"img":false}]}
{"op":"mcm","clk":"1350011410","pt":1588415477775,"mc":[{"id":"1.170370562","rc":[{"atb":[[2.42,0]],"id":9631798}],"con":true,"img":false}]}
{"op":"mcm","clk":"1350011414","pt":1588415477879,"mc":[{"id":"1.170370562","rc":[{"atb":[[1.32,116.43],[1.3,1641.74]],"id":9625043},{"atl":[[1.36,88.65]],"id":9625043}],"con":true,"img":false}]}
{"op":"mcm","clk":"1350011420","pt":1588415478085,"mc":[{"id":"1.170370562","rc":[{"trd":[[1.36,1100.17]],"ltp":1.36,"tv":1100.17,"id":9625043},{"atl":[[1.36,88.5]],"id":9625043},{"trd":[[3.75,0.05]],"ltp":3.75,"tv":0.05,"id":9631798}],"con":true,"img":false}]}
{"op":"mcm","clk":"1350011424","pt":1588415478188,"mc":[{"id":"1.170370562","rc":[{"atb":[[1.3,1529.74]],"id":9625043}],"con":true,"img":false}]}
{"op":"mcm","clk":"1350011453","pt":1588415479275,"mc":[{"id":"1.170370562","rc":[{"atl":[[1.33,44.32]],"id":9625043}],"con":true,"img":false}]}
{"op":"mcm","clk":"1350011460","pt":1588415479686,"mc":[{"id":"1.170370562","rc":[{"atb":[[1.01,1102.13]],"id":9631798}],"con":true,"img":false}]}
{"op":"mcm","clk":"1350011464","pt":1588415479895,"mc":[{"id":"1.170370562","rc":[{"atl":[[1.33,88.65]],"id":9625043},{"atb":[[1.01,1100.17]],"id":9631798}],"con":true,"img":false}]}
{"op":"mcm","clk":"1350011469","pt":1588415480102,"mc":[{"id":"1.170370562","rc":[{"atb":[[1.3,1233.72]],"id":9625043},{"atl":[[1.33,0]],"id":9625043},{"atb":[[1.01,1100.13]],"id":9631798}],"con":true,"img":false}]}
{"op":"mcm","clk":"1350011478","pt":1588415480411,"mc":[{"id":"1.170370562","rc":[{"atb":[[1.3,1160.61]],"id":9625043}],"con":true,"img":false}]}
{"op":"mcm","clk":"1350011502","pt":1588415481088,"mc":[{"id":"1.170370562","rc":[{"atb":[[1.32,112]],"id":9625043}],"con":true,"img":false}]}
{"op":"mcm","clk":"1350011520","pt":1588415481601,"mc":[{"id":"1.170370562","rc":[{"atb":[[1.33,132.97]],"id":9625043}],"con":true,"img":false}]}
{"op":"mcm","clk":"1350011539","pt":1588415482220,"mc":[{"id":"1.170370562","rc":[{"atl":[[1000,2.05]],"id":9631798}],"con":true,"img":false}]}
{"op":"mcm","clk":"1350011543","pt":1588415482322,"mc":[{"id":"1.170370562","rc":[{"atl":[[1000,0.06]],"id":9631798}],"con":true,"img":false}]}
{"op":"mcm","clk":"1350011550","pt":1588415482580,"mc":[{"id":"1.170370562","rc":[{"atl":[[1000,0.05]],"id":9631798}],"con":true,"img":false}]}
{"op":"mcm","clk":"1350011563","pt":1588415482893,"mc":[{"id":"1.170370562","rc":[{"atb":[[1.31,22.81]],"id":9625043}],"con":true,"img":false}]}
{"op":"mcm","clk":"1350011588","pt":1588415484021,"mc":[{"id":"1.170370562","rc":[{"trd":[[1.36,1112.6]],"ltp":1.36,"tv":1112.6,"id":9625043},{"atl":[[1.36,82.28]],"id":9625043}],"con":true,"img":false}]}
{"op":"mcm","clk":"1350011603","pt":1588415484490,"mc":[{"id":"1.170370562","rc":[{"trd":[[1.33,2928.27]],"ltp":1.33,"tv":2928.27,"id":9625043},{"atb":[[1.33,130.39]],"id":9625043}],"con":true,"img":false}]}
{"op":"mcm","clk":"1350011606","pt":1588415484592,"mc":[{"id":"1.170370562","rc":[{"trd":[[1.33,2928.31]],"ltp":1.33,"tv":2928.31,"id":9625043},{"atb":[[1.33,130.38]],"id":9625043}],"con":true,"img":false}]}
{"op":"mcm","clk":"1350011609","pt":1588415484695,"mc":[{"id":"1.170370562","rc":[{"atb":[[1.3,0]],"id":9625043}],"con":true,"img":false}]}
{"op":"mcm","clk":"1350011611","pt":1588415484796,"mc":[{"id":"1.170370562","rc":[{"atb":[[1.32,0]],"id":9625043}],"con":true,"img":false}]}
{"op":"mcm","clk":"1350011614","pt":1588415484900,"mc":[{"id":"1.170370562","rc":[{"atl":[[1000,2.05]],"id":9631798}],"con":true,"img":false}]}
{"op":"mcm","clk":"1350011619","pt":1588415485107,"mc":[{"id":"1.170370562","rc":[{"trd":[[1.33,3040.26]],"ltp":1.33,"tv":3040.26,"id":9625043},{"atb":[[1.33,74.4]],"id":9625043},{"atl":[[1000,0.06]],"id":9631798}],"con":true,"img":false}]}
{"op":"mcm","clk":"1350011623","pt":1588415485211,"mc":[{"id":"1.170370562","rc":[{"trd":[[1.31,2428.15],[1.33,3189.07]],"ltp":1.31,"tv":5617.22,"id":9625043},{"atb":[[1.33,0],[1.31,0]],"id":9625043},{"atl":[[1.3,778.66]],"id":9625043},{"atb":[[3.5,0.04]],"id":9631798}],"con":true,"img":false}]}
{"op":"mcm","clk":"1350011626","pt":1588415485316,"mc":[{"id":"1.170370562","rc":[{"atl":[[1000,0.05]],"id":9631798}],"con":true,"img":false}]}
{"op":"mcm","clk":"1350011646","pt":1588415486283,"mc":[{"id":"1.170370562","rc":[{"trd":[[1.3,19619.23]],"ltp":1.3,"tv":19619.23,"id":9625043},{"atl":[[1.3,666.66]],"id":9625043}],"con":true,"img":false}]}
{"op":"mcm","clk":"1350011662","pt":1588415486606,"mc":[{"id":"1.170370562","rc":[{"atl":[[1.36,0]],"id":9625043}],"con":true,"img":false}]}
{"op":"mcm","clk":"1350011664","pt":1588415486709,"mc":[{"id":"1.170370562","rc":[{"trd":[[1.3,19628.09]],"ltp":1.3,"tv":19628.09,"id":9625043},{"atl":[[1.3,662.23]],"id":9625043}],"con":true,"img":false}]}
{"op":"mcm","clk":"1350011681","pt":1588415487328,"mc":[{"id":"1.170370562","rc":[{"trd":[[1.3,19629.21]],"ltp":1.3,"tv":19629.21,"id":9625043},{"atl":[[1.3,661.67]],"id":9625043}],"con":true,"img":false}]}
{"op":"mcm","clk":"1350011692","pt":1588415487686,"mc":[{"id":"1.170370562","rc":[{"atl":[[5.3,0.01]],"id":9631798}],"con":true,"img":false}]}
{"op":"mcm","clk":"1350011696","pt":1588415487788,"mc":[{"id":"1.170370562","rc":[{"atb":[[1.12,0],[1.17,0]],"id":9625043}],"con":true,"img":false}]}
{"op":"mcm","clk":"1350011703","pt":1588415488101,"mc":[{"id":"1.170370562","rc":[{"trd":[[1.3,19739.21]],"ltp":1.3,"tv":19739.21,"id":9625043},{"atl":[[1.3,606.67]],"id":9625043}],"con":true,"img":false}]}
{"op":"mcm","clk":"1350011711","pt":1588415488513,"mc":[{"id":"1.170370562","rc":[{"trd":[[1.39,5723.6],[1.3,20952.56]],"ltp":1.39,"tv":26676.16,"id":9625043},{"atb":[[1.39,545.6]],"id":9625043},{"atl":[[1.39,0],[1.3,0]],"id":9625043}],"con":true,"img":false}]}
{"op":"mcm","clk":"1350011731","pt":1588415489127,"mc":[{"id":"1.170370562","rc":[{"atl":[[1.58,266.07]],"id":9625043}],"con":true,"img":false}]}
{"op":"mcm","clk":"1350011737","pt":1588415489180,"mc":[{"id":"1.170370562","rc":[{"atb":[[1.39,0]],"id":9625043}],"con":true,"img":false}]}
{"op":"mcm","clk":"1350011742","pt":1588415489385,"mc":[{"id":"1.170370562","rc":[{"atb":[[1.08,0]],"id":9625043}],"con":true,"img":false}]}
{"op":"mcm","clk":"1350011759","pt":1588415490002,"mc":[{"id":"1.170370562","rc":[{"atl":[[1.39,9.62]],"id":9625043}],"con":true,"img":false}]}
{"op":"mcm","clk":"1350011774","pt":1588415490414,"mc":[{"id":"1.170370562","rc":[{"atl":[[4,0.01]],"id":9631798}],"con":true,"img":false}]}
{"op":"mcm","clk":"1350011778","pt":1588415490517,"mc":[{"id":"1.170370562","rc":[{"atl":[[1.35,66.48]],"id":9625043}],"con":true,"img":false}]}
{"op":"mcm","clk":"1350011781","pt":1588415490619,"mc":[{"id":"1.170370562","rc":[{"trd":[[1.35,1545.34]],"ltp":1.35,"tv":1545.34,"id":9625043},{"atb":[[1.36,45.51]],"id":9625043},{"atl":[[1.35,0]],"id":9625043}],"con":true,"img":false}]}
{"op":"mcm","clk":"1350011785","pt":1588415490722,"mc":[{"id":"1.170370562","rc":[{"trd":[[1.35,1550.59],[1.36,1203.62]],"ltp":1.35,"tv":2754.21,"id":9625043},{"atb":[[1.36,0]],"id":9625043},{"atl":[[1.35,18.35]],"id":9625043}],"con":true,"img":false}]}
{"op":"mcm","clk":"1350011788","pt":1588415490824,"mc":[{"id":"1.170370562","rc":[{"atb":[[1.01,16.79],[1.03,1],[1.02,0.21],[1.06,0],[1.05,0],[1.04,0]],"id":9631798}],"con":true,"img":false}]}
{"op":"mcm","clk":"1350011791","pt":1588415490927,"mc":[{"id":"1.170370562","rc":[{"atl":[[1.35,84.84]],"id":9625043}],"con":true,"img":false}]}
{"op":"mcm","clk":"1350011796","pt":1588415491133,"mc":[{"id":"1.170370562","rc":[{"trd":[[1.33,3189.09]],"ltp":1.33,"tv":3189.09,"id":9625043},{"atl":[[1.35,151.32],[1.32,4.4]],"id":9625043},{"trd":[[4,68.9]],"ltp":4.0,"tv":68.9,"id":9631798},{"atl":[[4,0]],"id":9631798}],"con":true,"img":false}]}
{"op":"mcm","clk":"1350011826","pt":1588415492213,"mc":[{"id":"1.170370562","rc":[{"trd":[[1.35,1554.59],[1.32,651.89]],"ltp":1.35,"tv":2206.48,"id":9625043},{"atl":[[1.35,149.32],[1.32,0]],"id":9625043}],"con":true,"img":false}]}
{"op":"mcm","clk":"1350011836","pt":1588415492521,"mc":[{"id":"1.170370562","rc":[{"atl":[[1.43,0]],"id":9625043}],"con":true,"img":false}]}
{"op":"mcm","clk":"1350011865","pt":1588415493707,"mc":[{"id":"1.170370562","rc":[{"trd":[[1.35,1555.05]],"ltp":1.35,"tv":1555.05,"id":9625043},{"atl":[[1.35,149.09]],"id":9625043}],"con":true,"img":false}]}
{"op":"mcm","clk":"1350011892","pt":1588415494732,"mc":[{"id":"1.170370562","rc":[{"atl":[[1.39,509.62]],"id":9625043}],"con":true,"img":false}]}
{"op":"mcm","clk":"1350011937","pt":1588415495915,"mc":[{"id":"1.170370562","rc":[{"atb":[[1.33,66.48]],"id":9625043}],"con":true,"img":false}]}
{"op":"mcm","clk":"1350011950","pt":1588415496327,"mc":[{"id":"1.170370562","rc":[{"atb":[[1.33,132.97]],"id":9625043}],"con":true,"img":false}]}
{"op":"mcm","clk":"1350011958","pt":1588415496530,"mc":[{"id":"1.170370562","rc":[{"atb":[[1.33,199.46]],"id":9625043}],"con":true,"img":false}]}
{"op":"mcm","clk":"1350011963","pt":1588415496632,"mc":[{"id":"1.170370562","rc":[{"atl":[[1.34,44.32]],"id":9625043}],"con":true,"img":false}]}
{"op":"mcm","clk":"1350011990","pt":1588415497200,"mc":[{"id":"1.170370562","rc":[{"atl":[[1.34,88.65]],"id":9625043}],"con":true,"img":false}]}
{"op":"mcm","clk":"1350012017","pt":1588415498238,"mc":[{"id":"1.170370562","rc":[{"atb":[[1.33,265.95]],"id":9625043}],"con":true,"img":false}]}
{"op":"mcm","clk":"1350012034","pt":1588415498903,"mc":[{"id":"1.170370562","rc":[{"atb":[[1.33,0]],"id":9625043}],"con":true,"img":false}]}
{"op":"mcm","clk":"1350012049","pt":1588415499625,"mc":[{"id":"1.170370562","rc":[{"trd":[[1.34,439.88]],"ltp":1.34,"tv":439.88,"id":9625043},{"atl":[[1.34,88.36]],"id":9625043}],"con":true,"img":false}]}
{"op":"mcm","clk":"1350012064","pt":1588415500091,"mc":[{"id":"1.170370562","rc":[{"atl":[[1.39,500]],"id":9625043}],"con":true,"img":false}]}
{"op":"mcm","clk":"1350012074","pt":1588415500502,"mc":[{"id":"1.170370562","rc":[{"atl":[[1.39,0]],"id":9625043}],"con":true,"img":false}]}
{"op":"mcm","clk":"1350012134","pt":1588415503184,"mc":[{"id":"1.170370562","rc":[{"trd":[[1.34,572.86]],"ltp":1.34,"tv":572.86,"id":9625043},{"atl":[[1.34,21.87]],"id":9625043}],"con":true,"img":false}]}
{"op":"mcm","clk":"1350012137","pt":1588415503290,"mc":[{"id":"1.170370562","rc":[{"atb":[[1.27,0]],"id":9625043}],"con":true,"img":false}]}
{"op":"mcm","clk":"1350012142","pt":1588415503442,"mc":[{"id":"1.170370562","rc":[{"trd":[[1.33,3244.49]],"ltp":1.33,"tv":3244.49,"id":9625043},{"atl":[[1.33,84.3]],"id":9625043}],"con":true,"img":false}]}
{"op":"mcm","clk":"1350012167","pt":1588415504365,"mc":[{"id":"1.170370562","rc":[{"trd":[[1.23,0.98],[1.25,986.86]],"ltp":1.23,"tv":987.84,"id":9625043},{"atb":[[1.25,0]],"id":9625043},{"atl":[[1.17,746.74]],"id":9625043},{"trd":[[5.3,0.01]],"ltp":5.3,"tv":0.01,"id":9631798},{"atl":[[5.3,0]],"id":9631798}],"con":true,"img":false}]}
{"op":"mcm","clk":"1350012177","pt":1588415504673,"mc":[{"id":"1.170370562","rc":[{"atl":[[1.17,1496.74]],"id":9625043}],"con":true,"img":false}]}
{"op":"mcm","clk":"1350012185","pt":1588415504984,"mc":[{"id":"1.170370562","rc":[{"atl":[[1.2,1160.61],[1.35,149.27],[1.16,492.02]],"id":9625043}],"con":true,"img":false}]}
{"op":"mcm","clk":"1350012197","pt":1588415505244,"mc":[{"id":"1.170370562","rc":[{"atl":[[1.38,8.74]],"id":9625043}],"con":true,"img":false}]}
{"op":"mcm","clk":"1350012235","pt":1588415506473,"mc":[{"id":"1.170370562","rc":[{"atl":[[1.17,0]],"id":9625043}],"con":true,"img":false}]}
{"op":"mcm","clk":"1350012256","pt":1588415507350,"mc":[{"id":"1.170370562","rc":[{"atb":[[1.07,0]],"id":9625043}],"con":true,"img":false}]}
{"op":"mcm","clk":"1350012269","pt":1588415507864,"mc":[{"id":"1.170370562","rc":[{"atl":[[1.35,149.09]],"id":9625043}],"con":true,"img":false}]}
{"op":"mcm","clk":"1350012293","pt":1588415508944,"mc":[{"id":"1.170370562","rc":[{"trd":[[1.16,132.97]],"ltp":1.16,"tv":132.97,"id":9625043},{"atl":[[1.16,425.53]],"id":9625043}],"con":true,"img":false}]}
{"op":"mcm","clk":"1350012303","pt":1588415509456,"mc":[{"id":"1.170370562","rc":[{"trd":[[1.16,203.77]],"ltp":1.16,"tv":203.77,"id":9625043},{"atl":[[1.16,390.13]],"id":9625043}],"con":true,"img":false}]}
{"op":"mcm","clk":"1350012329","pt":1588415510277,"mc":[{"id":"1.170370562","rc":[{"trd":[[1.16,204.25]],"ltp":1.16,"tv":204.25,"id":9625043},{"atl":[[1.16,389.89]],"id":9625043}],"con":true,"img":false}]}
{"op":"mcm","clk":"1350012354","pt":1588415511271,"mc":[{"id":"1.170370562","rc":[{"atl":[[1.13,333]],"id":9625043}],"con":true,"img":false}]}
{"op":"mcm","clk":"1350012364","pt":1588415511576,"mc":[{"id":"1.170370562","rc":[{"atl":[[1.15,79.78]],"id":9625043}],"con":true,"img":false}]}
{"op":"mcm","clk":"1350012366","pt":1588415511665,"mc":[{"id":"1.170370562","rc":[{"atl":[[1.15,159.57]],"id":9625043}],"con":true,"img":false}]}
{"op":"mcm","clk":"1350012369","pt":1588415511871,"mc":[{"id":"1.170370562","rc":[{"atl":[[1.15,239.36]],"id":9625043}],"con":true,"img":false}]}
{"op":"mcm","clk":"1350012379","pt":1588415512385,"mc":[{"id":"1.170370562","rc":[{"atl":[[1.15,1270.5]],"id":9625043}],"con":true,"img":false}]}
{"op":"mcm","clk":"1350012390","pt":1588415512849,"mc":[{"id":"1.170370562","rc":[{"atb":[[1.08,79.78]],"id":9625043}],"con":true,"img":false}]}
{"op":"mcm","clk":"1350012394","pt":1588415512953,"mc":[{"id":"1.170370562","rc":[{"atb":[[1.08,159.57]],"id":9625043}],"con":true,"img":false}]}
{"op":"mcm","clk":"1350012403","pt":1588415513157,"mc":[{"id":"1.170370562","rc":[{"atb":[[1.08,239.36]],"id":9625043}],"con":true,"img":false}]}
{"op":"mcm","clk":"1350012407","pt":1588415513260,"mc":[{"id":"1.170370562","rc":[{"atl":[[1.15,1314.82]],"id":9625043}],"con":true,"img":false}]}
{"op":"mcm","clk":"1350012414","pt":1588415513567,"mc":[{"id":"1.170370562","rc":[{"atl":[[1.15,1328.61]],"id":9625043}],"con":true,"img":false}]}
{"op":"mcm","clk":"1350012427","pt":1588415514079,"mc":[{"id":"1.170370562","rc":[{"atb":[[1.07,79.78]],"id":9625043}],"con":true,"img":false}]}
{"op":"mcm","clk":"1350012432","pt":1588415514285,"mc":[{"id":"1.170370562","rc":[{"trd":[[1.13,134.13]],"ltp":1.13,"tv":134.13,"id":9625043},{"atl":[[1.13,265.93]],"id":9625043}],"con":true,"img":false}]}
{"op":"mcm","clk":"1350012435","pt":1588415514387,"mc":[{"id":"1.170370562","rc":[{"atb":[[1.07,159.57]],"id":9625043}],"con":true,"img":false}]}
{"op":"mcm","clk":"1350012437","pt":1588415514488,"mc":[{"id":"1.170370562","rc":[{"atb":[[1.07,239.36]],"id":9625043},{"atl":[[1.15,1372.93],[1.13,377.93]],"id":9625043}],"con":true,"img":false}]}
{"op":"mcm","clk":"1350012441","pt":1588415514648,"mc":[{"id":"1.170370562","rc":[{"trd":[[1.13,205.55]],"ltp":1.13,"tv":205.55,"id":9625043},{"atl":[[1.13,342.22]],"id":9625043}],"con":true,"img":false}]}
{"op":"mcm","clk":"1350012443","pt":1588415514767,"mc":[{"id":"1.170370562","rc":[{"trd":[[1.13,206.49]],"ltp":1.13,"tv":206.49,"id":9625043},{"atl":[[1.13,341.75]],"id":9625043}],"con":true,"img":false}]}
{"op":"mcm","clk":"1350012445","pt":1588415514853,"mc":[{"id":"1.170370562","rc":[{"atl":[[1.15,1439.42]],"id":9625043}],"con":true,"img":false}]}
{"op":"mcm","clk":"1350012447","pt":1588415514954,"mc":[{"id":"1.170370562","rc":[{"atb":[[1.07,239.59]],"id":9625043},{"atl":[[1.19,362],[1.15,1505.91]],"id":9625043}],"con":true,"img":false}]}
{"op":"mcm","clk":"1350012451","pt":1588415515164,"mc":[{"id":"1.170370562","rc":[{"atl":[[1.35,0],[1.15,1572.4]],"id":9625043}],"con":true,"img":false}]}
{"op":"mcm","clk":"1350012455","pt":1588415515365,"mc":[{"id":"1.170370562","rc":[{"atb":[[1.01,1003.5]],"id":9625043},{"atl":[[1.19,612]],"id":9625043}],"con":true,"img":false}]}
{"op":"mcm","clk":"1350012460","pt":1588415515573,"mc":[{"id":"1.170370562","rc":[{"trd":[[1.11,32.23]],"ltp":1.11,"tv":32.23,"id":9625043},{"atb":[[1.11,0]],"id":9625043},{"atl":[[1.19,656.32],[1.11,249.84]],"id":9625043}],"con":true,"img":false}]}
{"op":"mcm","clk":"1350012464","pt":1588415515673,"mc":[{"id":"1.170370562","rc":[{"atb":[[1.01,1001.96]],"id":9625043},{"atl":[[1.14,333],[1.15,1684.4]],"id":9625043}],"con":true,"img":false}]}
{"op":"mcm","clk":"1350012471","pt":1588415515980,"mc":[{"id":"1.170370562","rc":[{"atb":[[1.01,1001.72]],"id":9625043},{"atl":[[1.15,480.39]],"id":9625043}],"con":true,"img":false}]}
{"op":"mcm","clk":"1350012475","pt":1588415516084,"mc":[{"id":"1.170370562","rc":[{"atl":[[1.19,700.65]],"id":9625043}],"con":true,"img":false}]}
{"op":"mcm","clk":"1350012481","pt":1588415516187,"mc":[{"id":"1.170370562","rc":[{"atl":[[1.15,546.88]],"id":9625043}],"con":true,"img":false}]}
{"op":"mcm","clk":"1350012487","pt":1588415516389,"mc":[{"id":"1.170370562","rc":[{"atl":[[1.19,744.97]],"id":9625043}],"con":true,"img":false}]}
{"op":"mcm","clk":"1350012496","pt":1588415516959,"mc":[{"id":"1.170370562","rc":[{"trd":[[1.11,34.59]],"ltp":1.11,"tv":34.59,"id":9625043},{"atb":[[1.08,0]],"id":9625043},{"atl":[[1.19,789.3],[1.15,796.88],[1.11,248.66]],"id":9625043}],"con":true,"img":false}]}
{"op":"mcm","clk":"1350012504","pt":1588415517267,"mc":[{"id":"1.170370562","rc":[{"trd":[[1.15,82.35],[1.14,333],[1.11,549.21],[1.13,548.24]],"ltp":1.15,"tv":1512.8,"id":9625043},{"atl":[[1.14,0],[1.15,714.52],[1.11,0],[1.13,0]],"id":9625043},{"trd":[[7.6,12.46],[8.6,44.9],[8,47.45],[10,57.12]],"ltp":7.6,"tv":161.93,"id":9631798},{"atb":[[3.7,292.14]],"id":9631798},{"atl":[[24,11.6]],"id":9631798}],"con":true,"img":false}]}
{"op":"mcm","clk":"1350012507","pt":1588415517367,"mc":[{"id":"1.170370562","rc":[{"atl":[[1.15,1259.73]],"id":9625043}],"con":true,"img":false}]}
{"op":"mcm","clk":"1350012508","pt":1588415517469,"mc":[{"id":"1.170370562","rc":[{"atb":[[1.09,66.48]],"id":9625043}],"con":true,"img":false}]}
{"op":"mcm","clk":"1350012512","pt":1588415517575,"mc":[{"id":"1.170370562","rc":[{"atl":[[1.14,310.28]],"id":9625043}],"con":true,"img":false}]}
{"op":"mcm","clk":"1350012517","pt":1588415517678,"mc":[{"id":"1.170370562","rc":[{"atb":[[1.09,132.97]],"id":9625043},{"atl":[[1.14,620.56]],"id":9625043}],"con":true,"img":false}]}
{"op":"mcm","clk":"1350012518","pt":1588415517781,"mc":[{"id":"1.170370562","rc":[{"trd":[[1.14,346.7]],"ltp":1.14,"tv":346.7,"id":9625043},{"atl":[[1.14,613.71]],"id":9625043}],"con":true,"img":false}]}
{"op":"mcm","clk":"1350012520","pt":1588415517881,"mc":[{"id":"1.170370562","rc":[{"atb":[[1.09,199.46]],"id":9625043},{"atl":[[1.14,923.99]],"id":9625043}],"con":true,"img":false}]}
{"op":"mcm","clk":"1350012527","pt":1588415518291,"mc":[{"id":"1.170370562","rc":[{"atl":[[1.14,1234.28]],"id":9625043}],"con":true,"img":false}]}
{"op":"mcm","clk":"1350012529","pt":1588415518393,"mc":[{"id":"1.170370562","rc":[{"atl":[[1.14,1544.56]],"id":9625043}],"con":true,"img":false}]}
{"op":"mcm","clk":"1350012533","pt":1588415518652,"mc":[{"id":"1.170370562","rc":[{"atb":[[1.1,44.82]],"id":9625043}],"con":true,"img":false}]}
{"op":"mcm","clk":"1350012534","pt":1588415518755,"mc":[{"id":"1.170370562","rc":[{"atl":[[1.14,1794.56]],"id":9625043},{"atl":[[20,5]],"id":9631798}],"con":true,"img":false}]}
{"op":"mcm","clk":"1350012537","pt":1588415518963,"mc":[{"id":"1.170370562","rc":[{"trd":[[1.14,347.16]],"ltp":1.14,"tv":347.16,"id":9625043},{"atb":[[1.06,1514.11]],"id":9625043},{"atl":[[1.14,1794.33]],"id":9625043}],"con":true,"img":false}]}
{"op":"mcm","clk":"1350012539","pt":1588415519067,"mc":[{"id":"1.170370562","rc":[{"atl":[[1.14,2044.33]],"id":9625043}],"con":true,"img":false}]}
{"op":"mcm","clk":"1350012542","pt":1588415519166,"mc":[{"id":"1.170370562","rc":[{"atb":[[1.1,89.15]],"id":9625043}],"con":true,"img":false}]}
{"op":"mcm","clk":"1350012555","pt":1588415519681,"mc":[{"id":"1.170370562","rc":[{"atl":[[1.11,3.44]],"id":9625043}],"con":true,"img":false}]}
{"op":"mcm","clk":"1350012557","pt":1588415519780,"mc":[{"id":"1.170370562","rc":[{"atl":[[1.15,759.73]],"id":9625043}],"con":true,"img":false}]}
{"op":"mcm","clk":"1350012562","pt":1588415520091,"mc":[{"id":"1.170370562","rc":[{"atb":[[1.07,489.59]],"id":9625043}],"con":true,"img":false}]}
{"op":"mcm","clk":"1350012567","pt":1588415520191,"mc":[{"id":"1.170370562","rc":[{"atl":[[1.15,464.52]],"id":9625043}],"con":true,"img":false}]}
{"op":"mcm","clk":"1350012569","pt":1588415520293,"mc":[{"id":"1.170370562","rc":[{"atb":[[1.06,1181.11],[1.07,739.59]],"id":9625043}],"con":true,"img":false}]}
{"op":"mcm","clk":"1350012573","pt":1588415520659,"mc":[{"id":"1.170370562","rc":[{"atl":[[25,5]],"id":9631798}],"con":true,"img":false}]}
{"op":"mcm","clk":"1350012577","pt":1588415520757,"mc":[{"id":"1.170370562","rc":[{"trd":[[1.11,556.1]],"ltp":1.11,"tv":556.1,"id":9625043},{"atb":[[1.11,40.87]],"id":9625043},{"atl":[[1.11,0]],"id":9625043}],"con":true,"img":false}]}
{"op":"mcm","clk":"1350012582","pt":1588415521066,"mc":[{"id":"1.170370562","rc":[{"trd":[[1.14,347.64]],"ltp":1.14,"tv":347.64,"id":9625043},{"atb":[[1.09,449.46],[1.13,2.57]],"id":9625043},{"atl":[[1.14,2283.45],[1.38,0]],"id":9625043}],"con":true,"img":false}]}
{"op":"mcm","clk":"1350012590","pt":1588415521374,"mc":[{"id":"1.170370562","rc":[{"atl":[[1.14,2395.45]],"id":9625043}],"con":true,"img":false}]}
{"op":"mcm","clk":"1350012591","pt":1588415521477,"mc":[{"id":"1.170370562","rc":[{"atb":[[1.09,699.46]],"id":9625043}],"con":true,"img":false}]}
{"op":"mcm","clk":"1350012594","pt":1588415521785,"mc":[{"id":"1.170370562","rc":[{"trd":[[1.13,553.4]],"ltp":1.13,"tv":553.4,"id":9625043},{"atb":[[1.13,0]],"id":9625043},{"atl":[[1.12,330.42]],"id":9625043}],"con":true,"img":false}]}
{"op":"mcm","clk":"1350012600","pt":1588415522300,"mc":[{"id":"1.170370562","rc":[{"atb":[[1.09,743.79]],"id":9625043}],"con":true,"img":false}]}
{"op":"mcm","clk":"1350012603","pt":1588415522405,"mc":[{"id":"1.170370562","rc":[{"atl":[[1.12,79.18],[1.13,112]],"id":9625043}],"con":true,"img":false}]}
{"op":"mcm","clk":"1350012606","pt":1588415522459,"mc":[{"id":"1.170370562","rc":[{"trd":[[1.11,637.86]],"ltp":1.11,"tv":637.86,"id":9625043},{"atb":[[1.11,0],[1.08,250]],"id":9625043},{"atl":[[1.11,84.12]],"id":9625043}],"con":true,"img":false}]}
{"op":"mcm","clk":"1350012608","pt":1588415522576,"mc":[{"id":"1.170370562","rc":[{"atl":[[1.14,2156.09]],"id":9625043},{"atl":[[32,5]],"id":9631798}],"con":true,"img":false}]}
{"op":"mcm","clk":"1350012611","pt":1588415522774,"mc":[{"id":"1.170370562","rc":[{"atb":[[1.08,500]],"id":9625043}],"con":true,"img":false}]}
{"op":"mcm","clk":"1350012612","pt":1588415522879,"mc":[{"id":"1.170370562","rc":[{"atl":[[1.11,196.12]],"id":9625043}],"con":true,"img":false}]}
{"op":"mcm","clk":"1350012614","pt":1588415522984,"mc":[{"id":"1.170370562","rc":[{"atl":[[1.11,274.84]],"id":9625043}],"con":true,"img":false}]}
{"op":"mcm","clk":"1350012617","pt":1588415523086,"mc":[{"id":"1.170370562","rc":[{"trd":[[1.11,639.76]],"ltp":1.11,"tv":639.76,"id":9625043},{"atl":[[1.11,273.89]],"id":9625043}],"con":true,"img":false}]}
{"op":"mcm","clk":"1350012622","pt":1588415523292,"mc":[{"id":"1.170370562","rc":[{"trd":[[1.11,653.59]],"ltp":1.11,"tv":653.59,"id":9625043},{"atb":[[1.07,819.38]],"id":9625043},{"atl":[[1.11,266.98]],"id":9625043}],"con":true,"img":false}]}
{"op":"mcm","clk":"1350012624","pt":1588415523397,"mc":[{"id":"1.170370562","rc":[{"atl":[[1.19,289.3]],"id":9625043}],"con":true,"img":false}]}
{"op":"mcm","clk":"1350012626","pt":1588415523499,"mc":[{"id":"1.170370562","rc":[{"atb":[[1.07,899.16]],"id":9625043}],"con":true,"img":false}]}
{"op":"mcm","clk":"1350012628","pt":1588415523602,"mc":[{"id":"1.170370562","rc":[{"atb":[[1.01,3710.14],[1.07,978.95]],"id":9625043},{"atl":[[1.11,154.98]],"id":9625043}],"con":true,"img":false}]}
{"op":"mcm","clk":"1350012630","pt":1588415523706,"mc":[{"id":"1.170370562","rc":[{"atb":[[1.07,1058.74]],"id":9625043},{"atl":[[1.2,0]],"id":9625043}],"con":true,"img":false}]}
{"op":"mcm","clk":"1350012633","pt":1588415523863,"mc":[{"id":"1.170370562","rc":[{"atb":[[1.04,984.92]],"id":9625043},{"atl":[[1.13,407.21]],"id":9625043}],"con":true,"img":false}]}
{"op":"mcm","clk":"1350012640","pt":1588415524383,"mc":[{"id":"1.170370562","rc":[{"atb":[[1.01,3711.91]],"id":9625043}],"con":true,"img":false}]}
{"op":"mcm","clk":"1350012646","pt":1588415524686,"mc":[{"id":"1.170370562","rc":[{"atb":[[1.01,3710.37]],"id":9625043}],"con":true,"img":false}]}
{"op":"mcm","clk":"1350012651","pt":1588415524893,"mc":[{"id":"1.170370562","rc":[{"atl":[[1.13,451.53]],"id":9625043}],"con":true,"img":false}]}
{"op":"mcm","clk":"1350012657","pt":1588415524999,"mc":[{"id":"1.170370562","rc":[{"atb":[[1.01,3710.14]],"id":9625043}],"con":true,"img":false}]}
{"op":"mcm","clk":"1350012662","pt":1588415525097,"mc":[{"id":"1.170370562","rc":[{"trd":[[1.11,763.59]],"ltp":1.11,"tv":763.59,"id":9625043},{"atl":[[1.11,99.98]],"id":9625043}],"con":true,"img":false}]}
{"op":"mcm","clk":"1350012665","pt":1588415525304,"mc":[{"id":"1.170370562","rc":[{"atl":[[1.13,701.53]],"id":9625043}],"con":true,"img":false}]}
{"op":"mcm","clk":"1350012669","pt":1588415525508,"mc":[{"id":"1.170370562","rc":[{"trd":[[1.09,221.68],[1.1,178.31]],"ltp":1.09,"tv":399.99,"id":9625043},{"atb":[[1.09,632.95],[1.1,0]],"id":9625043},{"atl":[[1.13,745.86]],"id":9625043}],"con":true,"img":false}]}
{"op":"mcm","clk":"1350012671","pt":1588415525567,"mc":[{"id":"1.170370562","rc":[{"atl":[[1.13,995.86]],"id":9625043}],"con":true,"img":false}]}
{"op":"mcm","clk":"1350012681","pt":1588415526180,"mc":[{"id":"1.170370562","rc":[{"trd":[[1.11,807.32]],"ltp":1.11,"tv":807.32,"id":9625043},{"atl":[[1.11,78.11]],"id":9625043}],"con":true,"img":false}]}
{"op":"mcm","clk":"1350012685","pt":1588415526285,"mc":[{"id":"1.170370562","rc":[{"trd":[[1.11,988.05]],"ltp":1.11,"tv":988.05,"id":9625043},{"atb":[[1.01,3711.91],[1.11,242.63]],"id":9625043},{"atl":[[1.11,0]],"id":9625043}],"con":true,"img":false}]}
{"op":"mcm","clk":"1350012690","pt":1588415526591,"mc":[{"id":"1.170370562","rc":[{"atb":[[1.01,3710.38]],"id":9625043}],"con":true,"img":false}]}
{"op":"mcm","clk":"1350012697","pt":1588415526902,"mc":[{"id":"1.170370562","rc":[{"atb":[[1.01,3710.14]],"id":9625043}],"con":true,"img":false}]}
{"op":"mcm","clk":"1350012707","pt":1588415527208,"mc":[{"id":"1.170370562","rc":[{"atb":[[1.11,44.32]],"id":9625043}],"con":true,"img":false}]}
{"op":"mcm","clk":"1350012712","pt":1588415527413,"mc":[{"id":"1.170370562","rc":[{"atb":[[1.08,1239.24]],"id":9625043}],"con":true,"img":false}]}
{"op":"mcm","clk":"1350012717","pt":1588415527576,"mc":[{"id":"1.170370562","rc":[{"trd":[[1.11,1015.53]],"ltp":1.11,"tv":1015.53,"id":9625043},{"atb":[[1.11,30.58]],"id":9625043}],"con":true,"img":false}]}
{"op":"mcm","clk":"1350012723","pt":1588415527781,"mc":[{"id":"1.170370562","rc":[{"atb":[[1.11,31.75]],"id":9625043}],"con":true,"img":false}]}
{"op":"mcm","clk":"1350012728","pt":1588415528089,"mc":[{"id":"1.170370562","rc":[{"atl":[[1.58,0.11]],"id":9625043}],"con":true,"img":false}]}
{"op":"mcm","clk":"1350012736","pt":1588415528293,"mc":[{"id":"1.170370562","rc":[{"atl":[[1.12,158.97]],"id":9625043}],"con":true,"img":false}]}
{"op":"mcm","clk":"1350012740","pt":1588415528397,"mc":[{"id":"1.170370562","rc":[{"atl":[[1.12,238.76]],"id":9625043}],"con":true,"img":false}]}
{"op":"mcm","clk":"1350012745","pt":1588415528600,"mc":[{"id":"1.170370562","rc":[{"atl":[[1.12,318.54]],"id":9625043}],"con":true,"img":false}]}
{"op":"mcm","clk":"1350012749","pt":1588415528705,"mc":[{"id":"1.170370562","rc":[{"atb":[[1.11,98.24],[1.09,677.27]],"id":9625043}],"con":true,"img":false}]}
{"op":"mcm","clk":"1350012757","pt":1588415528959,"mc":[{"id":"1.170370562","rc":[{"atb":[[1.11,164.73]],"id":9625043}],"con":true,"img":false}]}
{"op":"mcm","clk":"1350012760","pt":1588415529067,"mc":[{"id":"1.170370562","rc":[{"trd":[[1.11,1115.53]],"ltp":1.11,"tv":1115.53,"id":9625043},{"atb":[[1.11,114.74],[1.09,721.6]],"id":9625043}],"con":true,"img":false}]}
{"op":"mcm","clk":"1350012765","pt":1588415529267,"mc":[{"id":"1.170370562","rc":[{"atb":[[1.11,0],[1.1,333]],"id":9625043}],"con":true,"img":false}]}
{"op":"mcm","clk":"1350012773","pt":1588415529678,"mc":[{"id":"1.170370562","rc":[{"trd":[[1.1,195.83]],"ltp":1.1,"tv":195.83,"id":9625043},{"atb":[[1.1,324.24]],"id":9625043}],"con":true,"img":false}]}
{"op":"mcm","clk":"1350012774","pt":1588415529783,"mc":[{"id":"1.170370562","rc":[{"atl":[[1.12,430.54],[1.13,1005.16]],"id":9625043}],"con":true,"img":false}]}
{"op":"mcm","clk":"1350012777","pt":1588415529885,"mc":[{"id":"1.170370562","rc":[{"trd":[[1.1,295.83]],"ltp":1.1,"tv":295.83,"id":9625043},{"atb":[[1.1,274.24]],"id":9625043}],"con":true,"img":false}]}
{"op":"mcm","clk":"1350012779","pt":1588415529985,"mc":[{"id":"1.170370562","rc":[{"trd":[[1.12,28.77]],"ltp":1.12,"tv":28.77,"id":9625043},{"atb":[[1.11,92.28]],"id":9625043},{"atl":[[1.12,401.76]],"id":9625043},{"trd":[[9.2,3.5]],"ltp":9.2,"tv":3.5,"id":9631798}],"con":true,"img":false}]}
{"op":"mcm","clk":"1350012781","pt":1588415530093,"mc":[{"id":"1.170370562","rc":[{"trd":[[1.12,29.24]],"ltp":1.12,"tv":29.24,"id":9625043},{"atl":[[1.12,401.53]],"id":9625043}],"con":true,"img":false}]}
{"op":"mcm","clk":"1350012789","pt":1588415530497,"mc":[{"id":"1.170370562","rc":[{"trd":[[1.11,1119.08]],"ltp":1.11,"tv":1119.08,"id":9625043},{"atb":[[1.11,90.5]],"id":9625043}],"con":true,"img":false}]}
{"op":"mcm","clk":"1350012793","pt":1588415530701,"mc":[{"id":"1.170370562","rc":[{"atb":[[1.09,1054.6]],"id":9625043}],"con":true,"img":false}]}
{"op":"mcm","clk":"1350012795","pt":1588415530804,"mc":[{"id":"1.170370562","rc":[{"atl":[[1.12,513.53]],"id":9625043}],"con":true,"img":false}]}
{"op":"mcm","clk":"1350012801","pt":1588415531271,"mc":[{"id":"1.170370562","rc":[{"atl":[[1.12,557.86]],"id":9625043}],"con":true,"img":false}]}
{"op":"mcm","clk":"1350012809","pt":1588415531782,"mc":[{"id":"1.170370562","rc":[{"atl":[[1.12,853.07]],"id":9625043}],"con":true,"img":false}]}
{"op":"mcm","clk":"1350012811","pt":1588415531885,"mc":[{"id":"1.170370562","rc":[{"atl":[[1.12,897.4]],"id":9625043}],"con":true,"img":false}]}
{"op":"mcm","clk":"1350012814","pt":1588415531988,"mc":[{"id":"1.170370562","rc":[{"trd":[[1.12,29.72]],"ltp":1.12,"tv":29.72,"id":9625043},{"atl":[[1.12,897.16]],"id":9625043}],"con":true,"img":false}]}
{"op":"mcm","clk":"1350012826","pt":1588415532604,"mc":[{"id":"1.170370562","rc":[{"trd":[[1.11,1120.46]],"ltp":1.11,"tv":1120.46,"id":9625043},{"atb":[[1.11,89.81]],"id":9625043}],"con":true,"img":false}]}
{"op":"mcm","clk":"1350012831","pt":1588415532863,"mc":[{"id":"1.170370562","rc":[{"atb":[[1.11,92.39]],"id":9625043}],"con":true,"img":false}]}
{"op":"mcm","clk":"1350012835","pt":1588415532976,"mc":[{"id":"1.170370562","rc":[{"atl":[[1.12,963.65]],"id":9625043}],"con":true,"img":false}]}
{"op":"mcm","clk":"1350012846","pt":1588415533173,"mc":[{"id":"1.170370562","rc":[{"atl":[[1.12,1074.46]],"id":9625043}],"con":true,"img":false}]}
{"op":"mcm","clk":"1350012850","pt":1588415533276,"mc":[{"id":"1.170370562","rc":[{"atl":[[1.12,1140.95]],"id":9625043}],"con":true,"img":false}]}
{"op":"mcm","clk":"1350012859","pt":1588415533481,"mc":[{"id":"1.170370562","rc":[{"atb":[[1.11,94.96]],"id":9625043}],"con":true,"img":false}]}
{"op":"mcm","clk":"1350012863","pt":1588415533583,"mc":[{"id":"1.170370562","rc":[{"atl":[[1.12,1207.44]],"id":9625043}],"con":true,"img":false}]}
{"op":"mcm","clk":"1350012868","pt":1588415533688,"mc":[{"id":"1.170370562","rc":[{"atl":[[1.12,1273.93],[1.29,0.47],[1.13,893.16]],"id":9625043}],"con":true,"img":false}]}
{"op":"mcm","clk":"1350012881","pt":1588415533996,"mc":[{"id":"1.170370562","rc":[{"atb":[[1.11,97.54]],"id":9625043}],"con":true,"img":false}]}
{"op":"mcm","clk":"1350012896","pt":1588415534304,"mc":[{"id":"1.170370562","rc":[{"atl":[[1.12,1628.54]],"id":9625043}],"con":true,"img":false}]}
{"op":"mcm","clk":"1350012904","pt":1588415534471,"mc":[{"id":"1.170370562","rc":[{"atb":[[1.1,318.56]],"id":9625043}],"con":true,"img":false}]}
{"op":"mcm","clk":"1350012911","pt":1588415534774,"mc":[{"id":"1.170370562","rc":[{"trd":[[1.11,1121.4]],"ltp":1.11,"tv":1121.4,"id":9625043},{"atb":[[1.11,97.07]],"id":9625043}],"con":true,"img":false}]}
{"op":"mcm","clk":"1350012914","pt":1588415534878,"mc":[{"id":"1.170370562","rc":[{"trd":[[1.12,34.87]],"ltp":1.12,"tv":34.87,"id":9625043},{"atl":[[1.12,1625.97]],"id":9625043}],"con":true,"img":false}]}
{"op":"mcm","clk":"1350012921","pt":1588415534983,"mc":[{"id":"1.170370562","rc":[{"atb":[[1.1,362.89]],"id":9625043},{"atl":[[1000,4.7]],"id":9625043}],"con":true,"img":false}]}
{"op":"mcm","clk":"1350012928","pt":1588415535188,"mc":[{"id":"1.170370562","rc":[{"atb":[[1.11,99.64]],"id":9625043}],"con":true,"img":false}]}
{"op":"mcm","clk":"1350012938","pt":1588415535600,"mc":[{"id":"1.170370562","rc":[{"trd":[[1.1,296.49],[1.11,1320.72]],"ltp":1.1,"tv":1617.21,"id":9625043},{"atb":[[1.11,0],[1.1,362.56]],"id":9625043}],"con":true,"img":false}]}
{"op":"mcm","clk":"1350012944","pt":1588415535804,"mc":[{"id":"1.170370562","rc":[{"atl":[[1000,2.12]],"id":9625043}],"con":true,"img":false}]}
{"op":"mcm","clk":"1350012960","pt":1588415536579,"mc":[{"id":"1.170370562","rc":[{"atl":[[1.14,612]],"id":9625043}],"con":true,"img":false}]}
{"op":"mcm","clk":"1350012965","pt":1588415536683,"mc":[{"id":"1.170370562","rc":[{"atb":[[1.02,2790.75]],"id":9625043},{"atl":[[1000,0.05]],"id":9625043}],"con":true,"img":false}]}
{"op":"mcm","clk":"1350012969","pt":1588415536887,"mc":[{"id":"1.170370562","rc":[{"atb":[[1.1,442.34]],"id":9625043}],"con":true,"img":false}]}
{"op":"mcm","clk":"1350012971","pt":1588415536991,"mc":[{"id":"1.170370562","rc":[{"atb":[[1.09,1234.54],[1.1,522.13]],"id":9625043},{"atl":[[1.11,15.74]],"id":9625043}],"con":true,"img":false}]}
{"op":"mcm","clk":"1350012974","pt":1588415537093,"mc":[{"id":"1.170370562","rc":[{"atb":[[1.09,901.54]],"id":9625043}],"con":true,"img":false}]}
{"op":"mcm","clk":"1350012976","pt":1588415537196,"mc":[{"id":"1.170370562","rc":[{"atb":[[1.1,601.92]],"id":9625043}],"con":true,"img":false}]}
{"op":"mcm","clk":"1350012980","pt":1588415537709,"mc":[{"id":"1.170370562","rc":[{"atb":[[1.1,602.26]],"id":9625043}],"con":true,"img":false}]}
{"op":"mcm","clk":"1350012982","pt":1588415537865,"mc":[{"id":"1.170370562","rc":[{"atb":[[1.1,956.87]],"id":9625043},{"atl":[[1.11,18.83]],"id":9625043}],"con":true,"img":false}]}
{"op":"mcm","clk":"1350012985","pt":1588415537970,"mc":[{"id":"1.170370562","rc":[{"atb":[[1.1,717.51]],"id":9625043}],"con":true,"img":false}]}
{"op":"mcm","clk":"1350012993","pt":1588415538487,"mc":[{"id":"1.170370562","rc":[{"atl":[[1.2,239.96]],"id":9625043}],"con":true,"img":false}]}
{"op":"mcm","clk":"1350013006","pt":1588415539103,"mc":[{"id":"1.170370562","rc":[{"atl":[[1.13,597.95]],"id":9625043}],"con":true,"img":false}]}
{"op":"mcm","clk":"1350013014","pt":1588415539412,"mc":[{"id":"1.170370562","rc":[{"trd":[[1.1,297.49]],"ltp":1.1,"tv":297.49,"id":9625043},{"atb":[[1.1,717.01]],"id":9625043}],"con":true,"img":false}]}
{"op":"mcm","clk":"1350013018","pt":1588415539568,"mc":[{"id":"1.170370562","rc":[{"atl":[[1.11,18.99]],"id":9625043}],"con":true,"img":false}]}
{"op":"mcm","clk":"1350013028","pt":1588415539982,"mc":[{"id":"1.170370562","rc":[{"atl":[[1.14,656.32]],"id":9625043}],"con":true,"img":false}]}
{"op":"mcm","clk":"1350013050","pt":1588415540602,"mc":[{"id":"1.170370562","rc":[{"atl":[[1.14,700.65]],"id":9625043}],"con":true,"img":false}]}
{"op":"mcm","clk":"1350013055","pt":1588415540705,"mc":[{"id":"1.170370562","rc":[{"trd":[[1.11,1322.13]],"ltp":1.11,"tv":1322.13,"id":9625043},{"atl":[[1.11,18.28]],"id":9625043}],"con":true,"img":false}]}
{"op":"mcm","clk":"1350013061","pt":1588415540908,"mc":[{"id":"1.170370562","rc":[{"atl":[[1.11,21.37]],"id":9625043}],"con":true,"img":false}]}
{"op":"mcm","clk":"1350013063","pt":1588415541011,"mc":[{"id":"1.170370562","rc":[{"trd":[[1.11,1330.49]],"ltp":1.11,"tv":1330.49,"id":9625043},{"atl":[[1.11,17.19]],"id":9625043}],"con":true,"img":false}]}
{"op":"mcm","clk":"1350013065","pt":1588415541114,"mc":[{"id":"1.170370562","rc":[{"trd":[[1.1,299.07]],"ltp":1.1,"tv":299.07,"id":9625043},{"atb":[[1.1,716.22]],"id":9625043}],"con":true,"img":false}]}
{"op":"mcm","clk":"1350013077","pt":1588415541788,"mc":[{"id":"1.170370562","rc":[{"atl":[[1.11,19.6]],"id":9625043}],"con":true,"img":false}]}
{"op":"mcm","clk":"1350013083","pt":1588415541993,"mc":[{"id":"1.170370562","rc":[{"atl":[[1.11,36.84]],"id":9625043}],"con":true,"img":false}]}
{"op":"mcm","clk":"1350013090","pt":1588415542199,"mc":[{"id":"1.170370562","rc":[{"atb":[[1.1,1049.22]],"id":9625043}],"con":true,"img":false}]}
{"op":"mcm","clk":"1350013095","pt":1588415542405,"mc":[{"id":"1.170370562","rc":[{"trd":[[1.11,1331.44]],"ltp":1.11,"tv":1331.44,"id":9625043},{"atl":[[1.11,88.24]],"id":9625043}],"con":true,"img":false}]}
{"op":"mcm","clk":"1350013099","pt":1588415542866,"mc":[{"id":"1.170370562","rc":[{"atb":[[1.03,1888.73]],"id":9625043}],"con":true,"img":false}]}
{"op":"mcm","clk":"1350013101","pt":1588415542970,"mc":[{"id":"1.170370562","rc":[{"trd":[[1.11,1336.51]],"ltp":1.11,"tv":1336.51,"id":9625043},{"atl":[[1.11,85.7]],"id":9625043}],"con":true,"img":false}]}
{"op":"mcm","clk":"1350013114","pt":1588415543693,"mc":[{"id":"1.170370562","rc":[{"trd":[[1.1,310.27]],"ltp":1.1,"tv":310.27,"id":9625043},{"atb":[[1.1,1043.62]],"id":9625043}],"con":true,"img":false}]}
{"op":"mcm","clk":"1350013126","pt":1588415544311,"mc":[{"id":"1.170370562","rc":[{"atb":[[1.1,1123.41]],"id":9625043}],"con":true,"img":false}]}
{"op":"mcm","clk":"1350013127","pt":1588415544414,"mc":[{"id":"1.170370562","rc":[{"atb":[[1.1,1203.2]],"id":9625043}],"con":true,"img":false}]}
{"op":"mcm","clk":"1350013129","pt":1588415544571,"mc":[{"id":"1.170370562","rc":[{"atb":[[1.1,1282.98]],"id":9625043}],"con":true,"img":false}]}
{"op":"mcm","clk":"1350013133","pt":1588415544780,"mc":[{"id":"1.170370562","rc":[{"atb":[[1.1,1123.41]],"id":9625043}],"con":true,"img":false}]}
{"op":"mcm","clk":"1350013136","pt":1588415544885,"mc":[{"id":"1.170370562","rc":[{"trd":[[1.1,331.29],[1.11,1338.86]],"ltp":1.1,"tv":1670.14,"id":9625043},{"atb":[[1.1,1112.9]],"id":9625043},{"atl":[[1.11,84.53]],"id":9625043}],"con":true,"img":false}]}
{"op":"mcm","clk":"1350013139","pt":1588415544987,"mc":[{"id":"1.170370562","rc":[{"trd":[[1.11,1342.97]],"ltp":1.11,"tv":1342.97,"id":9625043},{"atl":[[1.11,82.47]],"id":9625043}],"con":true,"img":false}]}
{"op":"mcm","clk":"1350013143","pt":1588415545192,"mc":[{"id":"1.170370562","rc":[{"trd":[[1.1,391.29]],"ltp":1.1,"tv":391.29,"id":9625043},{"atb":[[1.1,1082.9]],"id":9625043}],"con":true,"img":false}]}
{"op":"mcm","clk":"1350013150","pt":1588415545502,"mc":[{"id":"1.170370562","rc":[{"atb":[[1.1,1003.11]],"id":9625043}],"con":true,"img":false}]}
{"op":"mcm","clk":"1350013164","pt":1588415546172,"mc":[{"id":"1.170370562","rc":[{"atl":[[1.11,92.47]],"id":9625043}],"con":true,"img":false}]}
{"op":"mcm","clk":"1350013166","pt":1588415546276,"mc":[{"id":"1.170370562","rc":[{"trd":[[1.1,391.91]],"ltp":1.1,"tv":391.91,"id":9625043},{"atb":[[1.1,1002.8]],"id":9625043}],"con":true,"img":false}]}
{"op":"mcm","clk":"1350013168","pt":1588415546381,"mc":[{"id":"1.170370562","rc":[{"trd":[[1.11,1343.82]],"ltp":1.11,"tv":1343.82,"id":9625043},{"atl":[[1.11,92.05]],"id":9625043}],"con":true,"img":false}]}
{"op":"mcm","clk":"1350013172","pt":1588415546592,"mc":[{"id":"1.170370562","rc":[{"atl":[[1.11,40.17]],"id":9625043}],"con":true,"img":false}]}
{"op":"mcm","clk":"1350013180","pt":1588415547005,"mc":[{"id":"1.170370562","rc":[{"trd":[[1.1,551.29]],"ltp":1.1,"tv":551.29,"id":9625043},{"atb":[[1.1,923.11]],"id":9625043}],"con":true,"img":false}]}
{"op":"mcm","clk":"1350013191","pt":1588415547676,"mc":[{"id":"1.170370562","rc":[{"trd":[[1.1,554.83]],"ltp":1.1,"tv":554.83,"id":9625043},{"atb":[[1.1,921.34]],"id":9625043}],"con":true,"img":false}]}
{"op":"mcm","clk":"1350013202","pt":1588415548395,"mc":[{"id":"1.170370562","rc":[{"trd":[[1.11,1424.17]],"ltp":1.11,"tv":1424.17,"id":9625043},{"atb":[[1.11,4.14]],"id":9625043},{"atl":[[1.11,0]],"id":9625043}],"con":true,"img":false}]}
{"op":"mcm","clk":"1350013204","pt":1588415548499,"mc":[{"id":"1.170370562","rc":[{"atb":[[9.2,189.2]],"id":9631798}],"con":true,"img":false}]}
{"op":"mcm","clk":"1350013227","pt":1588415549786,"mc":[{"id":"1.170370562","rc":[{"atb":[[1.1,588.34]],"id":9625043}],"con":true,"img":false}]}
{"op":"mcm","clk":"1350013233","pt":1588415550304,"mc":[{"id":"1.170370562","rc":[{"atb":[[1.11,16.94]],"id":9625043}],"con":true,"img":false}]}
{"op":"mcm","clk":"1350013242","pt":1588415550613,"mc":[{"id":"1.170370562","rc":[{"trd":[[1.1,720.95],[1.11,1458.05]],"ltp":1.1,"tv":2179.0,"id":9625043},{"atb":[[1.11,0],[1.1,505.28]],"id":9625043}],"con":true,"img":false}]}
{"op":"mcm","clk":"1350013271","pt":1588415552015,"mc":[{"id":"1.170370562","rc":[{"trd":[[1.1,762.93]],"ltp":1.1,"tv":762.93,"id":9625043},{"atb":[[1.11,1.05],[1.1,484.29]],"id":9625043}],"con":true,"img":false}]}
{"op":"mcm","clk":"1350013279","pt":1588415552215,"mc":[{"id":"1.170370562","rc":[{"atb":[[1.09,401.54],[1.08,739.24],[1.07,558.74]],"id":9625043},{"atl":[[1.14,200.65],[1.13,97.95]],"id":9625043}],"con":true,"img":false}]}
{"op":"mcm","clk":"1350013294","pt":1588415552729,"mc":[{"id":"1.170370562","rc":[{"atl":[[1.12,1401.97]],"id":9625043}],"con":true,"img":false}]}
{"op":"mcm","clk":"1350013328","pt":1588415554221,"mc":[{"id":"1.170370562","rc":[{"atb":[[1.06,984.92]],"id":9625043}],"con":true,"img":false}]}
{"op":"mcm","clk":"1350013338","pt":1588415554586,"mc":[{"id":"1.170370562","rc":[{"atb":[[1.08,0]],"id":9625043}],"con":true,"img":false}]}
{"op":"mcm","clk":"1350013347","pt":1588415554898,"mc":[{"id":"1.170370562","rc":[{"atb":[[1.11,334.05]],"id":9625043}],"con":true,"img":false}]}
{"op":"mcm","clk":"1350013364","pt":1588415555718,"mc":[{"id":"1.170370562","rc":[{"atb":[[1.07,0.23]],"id":9625043}],"con":true,"img":false}]}
{"op":"mcm","clk":"1350013386","pt":1588415556494,"mc":[{"id":"1.170370562","rc":[{"atb":[[1.1,483.95]],"id":9625043},{"atl":[[1.12,1162.6]],"id":9625043}],"con":true,"img":false}]}
{"op":"mcm","clk":"1350013389","pt":1588415556596,"mc":[{"id":"1.170370562","rc":[{"atb":[[1.11,378.38]],"id":9625043}],"con":true,"img":false}]}
{"op":"mcm","clk":"1350013402","pt":1588415557215,"mc":[{"id":"1.170370562","rc":[{"trd":[[1.11,1475.57]],"ltp":1.11,"tv":1475.57,"id":9625043},{"atb":[[1.11,369.62]],"id":9625043}],"con":true,"img":false}]}
{"op":"mcm","clk":"1350013415","pt":1588415558007,"mc":[{"id":"1.170370562","rc":[{"atb":[[1.09,756.15]],"id":9625043}],"con":true,"img":false}]}
{"op":"mcm","clk":"1350013419","pt":1588415558309,"mc":[{"id":"1.170370562","rc":[{"atl":[[1.12,1029.62]],"id":9625043}],"con":true,"img":false}]}
{"op":"mcm","clk":"1350013431","pt":1588415558821,"mc":[{"id":"1.170370562","rc":[{"atl":[[1.14,88.65]],"id":9625043}],"con":true,"img":false}]}
{"op":"mcm","clk":"1350013433","pt":1588415558925,"mc":[{"id":"1.170370562","rc":[{"trd":[[1.11,1510.56]],"ltp":1.11,"tv":1510.56,"id":9625043},{"atb":[[1.11,352.13]],"id":9625043}],"con":true,"img":false}]}
{"op":"mcm","clk":"1350013435","pt":1588415559023,"mc":[{"id":"1.170370562","rc":[{"trd":[[1.11,1610.56]],"ltp":1.11,"tv":1610.56,"id":9625043},{"atb":[[1.11,302.13]],"id":9625043}],"con":true,"img":false}]}
{"op":"mcm","clk":"1350013442","pt":1588415559228,"mc":[{"id":"1.170370562","rc":[{"trd":[[1.11,1615.71]],"ltp":1.11,"tv":1615.71,"id":9625043},{"atb":[[1.11,299.55]],"id":9625043}],"con":true,"img":false}]}
{"op":"mcm","clk":"1350013446","pt":1588415559693,"mc":[{"id":"1.170370562","rc":[{"atl":[[1.13,9.3]],"id":9625043}],"con":true,"img":false}]}
{"op":"mcm","clk":"1350013447","pt":1588415559795,"mc":[{"id":"1.170370562","rc":[{"atl":[[1.15,352.52]],"id":9625043}],"con":true,"img":false}]}
{"op":"mcm","clk":"1350013452","pt":1588415560420,"mc":[{"id":"1.170370562","rc":[{"atb":[[1.08,354.6]],"id":9625043}],"con":true,"img":false}]}
{"op":"mcm","clk":"1350013453","pt":1588415560630,"mc":[{"id":"1.170370562","rc":[{"atl":[[2.12,0]],"id":9625043}],"con":true,"img":false}]}
{"op":"mcm","clk":"1350013458","pt":1588415560835,"mc":[{"id":"1.170370562","rc":[{"trd":[[1.11,2054.47]],"ltp":1.11,"tv":2054.47,"id":9625043},{"atb":[[1.11,80.17]],"id":9625043}],"con":true,"img":false}]}
{"op":"mcm","clk":"1350013463","pt":1588415561094,"mc":[{"id":"1.170370562","rc":[{"atb":[[1.11,290.17],[1.09,401.54],[1.1,443.26]],"id":9625043}],"con":true,"img":false}]}
{"op":"mcm","clk":"1350013471","pt":1588415561302,"mc":[{"id":"1.170370562","rc":[{"atb":[[1.09,268.56]],"id":9625043},{"atl":[[1.19,177.3]],"id":9625043}],"con":true,"img":false}]}
{"op":"mcm","clk":"1350013484","pt":1588415561611,"mc":[{"id":"1.170370562","rc":[{"trd":[[1.11,2056.79]],"ltp":1.11,"tv":2056.79,"id":9625043},{"atb":[[1.11,289.01]],"id":9625043}],"con":true,"img":false}]}
{"op":"mcm","clk":"1350013504","pt":1588415562435,"mc":[{"id":"1.170370562","rc":[{"trd":[[1.12,35.81]],"ltp":1.12,"tv":35.81,"id":9625043},{"atl":[[1.12,1029.15]],"id":9625043}],"con":true,"img":false}]}
{"op":"mcm","clk":"1350013507","pt":1588415562532,"mc":[{"id":"1.170370562","rc":[{"trd":[[1.12,36.76]],"ltp":1.12,"tv":36.76,"id":9625043},{"atl":[[1.12,1028.68]],"id":9625043}],"con":true,"img":false}]}
{"op":"mcm","clk":"1350013530","pt":1588415563412,"mc":[{"id":"1.170370562","rc":[{"atb":[[1.11,289.48]],"id":9625043}],"con":true,"img":false}]}
{"op":"mcm","clk":"1350013531","pt":1588415563515,"mc":[{"id":"1.170370562","rc":[{"atl":[[1.33,0]],"id":9625043}],"con":true,"img":false}]}
{"op":"mcm","clk":"1350013533","pt":1588415563640,"mc":[{"id":"1.170370562","rc":[{"trd":[[1.1,1583.95],[1.11,2635.77]],"ltp":1.1,"tv":4219.72,"id":9625043},{"atb":[[1.11,0],[1.1,32.75]],"id":9625043}],"con":true,"img":false}]}
{"op":"mcm","clk":"1350013543","pt":1588415564029,"mc":[{"id":"1.170370562","rc":[{"atb":[[1.09,88.62]],"id":9625043}],"con":true,"img":false}]}
{"op":"mcm","clk":"1350013581","pt":1588415566198,"mc":[{"id":"1.170370562","rc":[{"trd":[[1.12,118.14]],"ltp":1.12,"tv":118.14,"id":9625043},{"atl":[[1.12,987.99]],"id":9625043}],"con":true,"img":false}]}
{"op":"mcm","clk":"1350013588","pt":1588415566820,"mc":[{"id":"1.170370562","rc":[{"atl":[[1000,2.05]],"id":9625043}],"con":true,"img":false}]}
{"op":"mcm","clk":"1350013593","pt":1588415567028,"mc":[{"id":"1.170370562","rc":[{"atl":[[1000,0.3]],"id":9625043}],"con":true,"img":false}]}
{"op":"mcm","clk":"1350013650","pt":1588415567813,"mc":[{"id":"1.170370562","rc":[{"atb":[[1.07,0]],"id":9625043}],"con":true,"img":false}]}
{"op":"mcm","clk":"1350013655","pt":1588415568008,"mc":[{"id":"1.170370562","rc":[{"trd":[[1.12,206.79]],"ltp":1.12,"tv":206.79,"id":9625043},{"atl":[[1.12,943.67]],"id":9625043}],"con":true,"img":false}]}
{"op":"mcm","clk":"1350013660","pt":1588415568213,"mc":[{"id":"1.170370562","rc":[{"atl":[[1000,0.05],[1.13,0]],"id":9625043}],"con":true,"img":false}]}
{"op":"mcm","clk":"1350013674","pt":1588415569140,"mc":[{"id":"1.170370562","rc":[{"atl":[[1.14,0]],"id":9625043}],"con":true,"img":false}]}
{"op":"mcm","clk":"1350013676","pt":1588415569191,"mc":[{"id":"1.170370562","rc":[{"atl":[[1.89,0]],"id":9625043}],"con":true,"img":false}]}
{"op":"mcm","clk":"1350013682","pt":1588415569607,"mc":[{"id":"1.170370562","rc":[{"atl":[[1.11,0.3]],"id":9625043}],"con":true,"img":false}]}
{"op":"mcm","clk":"1350013687","pt":1588415569812,"mc":[{"id":"1.170370562","rc":[{"atl":[[1.15,332.44]],"id":9625043}],"con":true,"img":false}]}
{"op":"mcm","clk":"1350013749","pt":1588415570840,"mc":[{"id":"1.170370562","rc":[{"atl":[[1.11,14.95]],"id":9625043}],"con":true,"img":false}]}
{"op":"mcm","clk":"1350013769","pt":1588415571411,"mc":[{"id":"1.170370562","rc":[{"atb":[[1.06,1169.95]],"id":9625043}],"con":true,"img":false}]}
{"op":"mcm","clk":"1350013782","pt":1588415572133,"mc":[{"id":"1.170370562","rc":[{"atl":[[1.11,36.82]],"id":9625043}],"con":true,"img":false}]}
{"op":"mcm","clk":"1350013788","pt":1588415572392,"mc":[{"id":"1.170370562","rc":[{"atl":[[1.11,105.91]],"id":9625043}],"con":true,"img":false}]}
{"op":"mcm","clk":"1350013810","pt":1588415573115,"mc":[{"id":"1.170370562","rc":[{"trd":[[1.11,2636.01]],"ltp":1.11,"tv":2636.01,"id":9625043},{"atl":[[1.11,105.48]],"id":9625043}],"con":true,"img":false}]}
{"op":"mcm","clk":"1350013813","pt":1588415573321,"mc":[{"id":"1.170370562","rc":[{"atl":[[2,0.25]],"id":9625043}],"con":true,"img":false}]}
{"op":"mcm","clk":"1350013837","pt":1588415574097,"mc":[{"id":"1.170370562","rc":[{"trd":[[1.1,1589.05]],"ltp":1.1,"tv":1589.05,"id":9625043},{"atb":[[1.1,30.2]],"id":9625043}],"con":true,"img":false}]}
{"op":"mcm","clk":"1350013855","pt":1588415574717,"mc":[{"id":"1.170370562","rc":[{"trd":[[1.11,2636.69]],"ltp":1.11,"tv":2636.69,"id":9625043},{"atl":[[1.11,105.14]],"id":9625043}],"con":true,"img":false}]}
{"op":"mcm","clk":"1350013914","pt":1588415575543,"mc":[{"id":"1.170370562","rc":[{"trd":[[1.1,1594.21]],"ltp":1.1,"tv":1594.21,"id":9625043},{"atb":[[1.1,27.62]],"id":9625043}],"con":true,"img":false}]}
{"op":"mcm","clk":"1350013930","pt":1588415576115,"mc":[{"id":"1.170370562","rc":[{"atl":[[1.11,83.28]],"id":9625043}],"con":true,"img":false}]}
{"op":"mcm","clk":"1350013935","pt":1588415576380,"mc":[{"id":"1.170370562","rc":[{"atb":[[1.1,82.62]],"id":9625043}],"con":true,"img":false}]}
{"op":"mcm","clk":"1350013942","pt":1588415576644,"mc":[{"id":"1.170370562","rc":[{"atl":[[1.12,687.05]],"id":9625043}],"con":true,"img":false}]}
{"op":"mcm","clk":"1350013945","pt":1588415576742,"mc":[{"id":"1.170370562","rc":[{"atb":[[1.05,1224.92]],"id":9625043}],"con":true,"img":false}]}
{"op":"mcm","clk":"1350013952","pt":1588415577003,"mc":[{"id":"1.170370562","rc":[{"atl":[[1.15,0]],"id":9625043}],"con":true,"img":false}]}
{"op":"mcm","clk":"1350013954","pt":1588415577107,"mc":[{"id":"1.170370562","rc":[{"trd":[[1.11,2643.7]],"ltp":1.11,"tv":2643.7,"id":9625043},{"atl":[[1.11,79.78]],"id":9625043}],"con":true,"img":false}]}
{"op":"mcm","clk":"1350013961","pt":1588415577316,"mc":[{"id":"1.170370562","rc":[{"trd":[[1.11,2723.7]],"ltp":1.11,"tv":2723.7,"id":9625043},{"atl":[[1.11,39.78]],"id":9625043}],"con":true,"img":false}]}
{"op":"mcm","clk":"1350013966","pt":1588415577524,"mc":[{"id":"1.170370562","rc":[{"atb":[[1.01,3950.14]],"id":9625043}],"con":true,"img":false}]}
{"op":"mcm","clk":"1350013972","pt":1588415577727,"mc":[{"id":"1.170370562","rc":[{"atb":[[1.1,121.63]],"id":9625043}],"con":true,"img":false}]}
{"op":"mcm","clk":"1350013991","pt":1588415578298,"mc":[{"id":"1.170370562","rc":[{"atb":[[1.06,185.03]],"id":9625043}],"con":true,"img":false}]}
{"op":"mcm","clk":"1350014015","pt":1588415578829,"mc":[{"id":"1.170370562","rc":[{"atb":[[1.05,240]],"id":9625043},{"atb":[[9.2,0]],"id":9631798}],"con":true,"img":false}]}
{"op":"mcm","clk":"1350014022","pt":1588415579038,"mc":[{"id":"1.170370562","rc":[{"trd":[[1.11,2803.25]],"ltp":1.11,"tv":2803.25,"id":9625043},{"atb":[[1.11,4.54]],"id":9625043},{"atl":[[1.11,0]],"id":9625043}],"con":true,"img":false}]}
{"op":"mcm","clk":"1350014033","pt":1588415579449,"mc":[{"id":"1.170370562","rc":[{"atb":[[1.11,0]],"id":9625043},{"atl":[[1.19,0],[1.34,0]],"id":9625043}],"con":true,"img":false}]}
{"op":"mcm","clk":"1350014045","pt":1588415579912,"mc":[{"id":"1.170370562","rc":[{"trd":[[1.1,1615.15]],"ltp":1.1,"tv":1615.15,"id":9625043},{"atb":[[1.1,111.16]],"id":9625043}],"con":true,"img":false}]}
{"op":"mcm","clk":"1350014053","pt":1588415580118,"mc":[{"id":"1.170370562","rc":[{"trd":[[1.1,1617.26]],"ltp":1.1,"tv":1617.26,"id":9625043},{"atb":[[1.1,110.1]],"id":9625043}],"con":true,"img":false}]}
{"op":"mcm","clk":"1350014068","pt":1588415580531,"mc":[{"id":"1.170370562","rc":[{"trd":[[1.12,243.2]],"ltp":1.12,"tv":243.2,"id":9625043},{"atl":[[1.12,650.64]],"id":9625043},{"trd":[[9.2,7.93]],"ltp":9.2,"tv":7.93,"id":9631798}],"con":true,"img":false}]}
{"op":"mcm","clk":"1350014070","pt":1588415580637,"mc":[{"id":"1.170370562","rc":[{"atb":[[1.06,0]],"id":9625043}],"con":true,"img":false}]}
{"op":"mcm","clk":"1350014098","pt":1588415581104,"mc":[{"id":"1.170370562","rc":[{"atb":[[1.11,6.2]],"id":9625043}],"con":true,"img":false}]}
{"op":"mcm","clk":"1350014110","pt":1588415581310,"mc":[{"id":"1.170370562","rc":[{"trd":[[1.1,1648.59],[1.11,2815.67]],"ltp":1.1,"tv":4464.26,"id":9625043},{"atb":[[1.11,0],[1.1,94.44]],"id":9625043}],"con":true,"img":false}]}
{"op":"mcm","clk":"1350014118","pt":1588415581518,"mc":[{"id":"1.170370562","rc":[{"trd":[[1.1,1715.25]],"ltp":1.1,"tv":1715.25,"id":9625043},{"atb":[[1.1,61.1]],"id":9625043}],"con":true,"img":false}]}
{"op":"mcm","clk":"1350014131","pt":1588415582046,"mc":[{"id":"1.170370562","rc":[{"atb":[[1.11,7.88]],"id":9625043}],"con":true,"img":false}]}
{"op":"mcm","clk":"1350014137","pt":1588415582143,"mc":[{"id":"1.170370562","rc":[{"trd":[[1.1,1837.47],[1.11,2831.43]],"ltp":1.1,"tv":4668.9,"id":9625043},{"atb":[[1.11,0],[1.1,0]],"id":9625043},{"atl":[[1.1,19.66]],"id":9625043}],"con":true,"img":false}]}
{"op":"mcm","clk":"1350014156","pt":1588415582720,"mc":[{"id":"1.170370562","rc":[{"trd":[[1.12,248.2],[1.1,1876.79]],"ltp":1.12,"tv":2124.99,"id":9625043},{"atl":[[1.12,648.14],[1.1,0]],"id":9625043}],"con":true,"img":false}]}
{"op":"mcm","clk":"1350014187","pt":1588415583766,"mc":[{"id":"1.170370562","rc":[{"atb":[[1.11,53.32]],"id":9625043}],"con":true,"img":false}]}
{"op":"mcm","clk":"1350014214","pt":1588415584557,"mc":[{"id":"1.170370562","rc":[{"atb":[[1.08,360.2]],"id":9625043}],"con":true,"img":false}]}
{"op":"mcm","clk":"1350014230","pt":1588415584970,"mc":[{"id":"1.170370562","rc":[{"trd":[[1.11,2938.08]],"ltp":1.11,"tv":2938.08,"id":9625043},{"atb":[[1.11,0]],"id":9625043},{"atl":[[1.1,30.11]],"id":9625043}],"con":true,"img":false}]}
{"op":"mcm","clk":"1350014309","pt":1588415587462,"mc":[{"id":"1.170370562","rc":[{"atb":[[1.05,573]],"id":9625043}],"con":true,"img":false}]}
{"op":"mcm","clk":"1350014317","pt":1588415587731,"mc":[{"id":"1.170370562","rc":[{"atb":[[1.04,1317.92]],"id":9625043}],"con":true,"img":false}]}
{"op":"mcm","clk":"1350014326","pt":1588415588042,"mc":[{"id":"1.170370562","rc":[{"trd":[[1.1,1877.91]],"ltp":1.1,"tv":1877.91,"id":9625043},{"atb":[[1.03,2221.73]],"id":9625043},{"atl":[[1.1,29.56]],"id":9625043}],"con":true,"img":false}]}
{"op":"mcm","clk":"1350014334","pt":1588415588353,"mc":[{"id":"1.170370562","rc":[{"atb":[[1.02,3123.75]],"id":9625043}],"con":true,"img":false}]}
{"op":"mcm","clk":"1350014343","pt":1588415588716,"mc":[{"id":"1.170370562","rc":[{"atb":[[1.01,4283.14]],"id":9625043}],"con":true,"img":false}]}
{"op":"mcm","clk":"1350014383","pt":1588415589963,"mc":[{"id":"1.170370562","rc":[{"trd":[[1.1,1922.24]],"ltp":1.1,"tv":1922.24,"id":9625043},{"atb":[[1.08,5.59]],"id":9625043},{"atl":[[1.1,7.39]],"id":9625043}],"con":true,"img":false}]}
{"op":"mcm","clk":"1350014494","pt":1588415593130,"mc":[{"id":"1.170370562","rc":[{"atl":[[1.19,354.6]],"id":9625043}],"con":true,"img":false}]}
{"op":"mcm","clk":"1350014499","pt":1588415593232,"mc":[{"id":"1.170370562","rc":[{"trd":[[1.1,1922.7]],"ltp":1.1,"tv":1922.7,"id":9625043},{"atl":[[1.1,7.16]],"id":9625043}],"con":true,"img":false}]}
{"op":"mcm","clk":"1350014544","pt":1588415595046,"mc":[{"id":"1.170370562","rc":[{"atl":[[1.16,0]],"id":9625043}],"con":true,"img":false}]}
{"op":"mcm","clk":"1350014552","pt":1588415595256,"mc":[{"id":"1.170370562","rc":[{"trd":[[1.09,222.67]],"ltp":1.09,"tv":222.67,"id":9625043},{"atb":[[1.09,88.12]],"id":9625043}],"con":true,"img":false}]}
{"op":"mcm","clk":"1350014557","pt":1588415595457,"mc":[{"id":"1.170370562","rc":[{"atb":[[1.08,383.66]],"id":9625043}],"con":true,"img":false}]}
{"op":"mcm","clk":"1350014561","pt":1588415595562,"mc":[{"id":"1.170370562","rc":[{"atb":[[1.07,98.47]],"id":9625043}],"con":true,"img":false}]}
{"op":"mcm","clk":"1350014587","pt":1588415596438,"mc":[{"id":"1.170370562","rc":[{"atb":[[1.03,2576.34]],"id":9625043}],"con":true,"img":false}]}
{"op":"mcm","clk":"1350014605","pt":1588415597066,"mc":[{"id":"1.170370562","rc":[{"atl":[[1.1,0]],"id":9625043}],"con":true,"img":false}]}
{"op":"mcm","clk":"1350014615","pt":1588415597431,"mc":[{"id":"1.170370562","rc":[{"atb":[[1.1,0.24]],"id":9625043}],"con":true,"img":false}]}
{"op":"mcm","clk":"1350014632","pt":1588415597949,"mc":[{"id":"1.170370562","rc":[{"atb":[[3.7,0]],"id":9631798},{"atl":[[24,0]],"id":9631798}],"con":true,"img":false}]}
{"op":"mcm","clk":"1350014645","pt":1588415598463,"mc":[{"id":"1.170370562","rc":[{"trd":[[1.09,402.47],[1.1,1923.2]],"ltp":1.09,"tv":2325.67,"id":9625043},{"atb":[[1.09,0],[1.1,0]],"id":9625043},{"atl":[[1.09,59.85]],"id":9625043}],"con":true,"img":false}]}
{"op":"mcm","clk":"1350014698","pt":1588415600178,"mc":[{"id":"1.170370562","rc":[{"trd":[[1.09,438.87]],"ltp":1.09,"tv":438.87,"id":9625043},{"atl":[[1.09,41.65]],"id":9625043}],"con":true,"img":false}]}
{"op":"mcm","clk":"1350014704","pt":1588415600227,"mc":[{"id":"1.170370562","rc":[{"atl":[[1.09,42.82]],"id":9625043}],"con":true,"img":false}]}
{"op":"mcm","clk":"1350014712","pt":1588415600435,"mc":[{"id":"1.170370562","rc":[{"trd":[[1.08,124.99]],"ltp":1.08,"tv":124.99,"id":9625043},{"atb":[[1.08,258.67]],"id":9625043},{"trd":[[13.5,10]],"ltp":13.5,"tv":10.0,"id":9631798}],"con":true,"img":false}]}
{"op":"mcm","clk":"1350014732","pt":1588415600954,"mc":[{"id":"1.170370562","rc":[{"trd":[[1.09,447.73]],"ltp":1.09,"tv":447.73,"id":9625043},{"atl":[[1.09,38.39]],"id":9625043}],"con":true,"img":false}]}
{"op":"mcm","clk":"1350014748","pt":1588415601475,"mc":[{"id":"1.170370562","rc":[{"atb":[[1.08,0]],"id":9625043}],"con":true,"img":false}]}
{"op":"mcm","clk":"1350014791","pt":1588415602460,"mc":[{"id":"1.170370562","rc":[{"trd":[[1.09,451.27]],"ltp":1.09,"tv":451.27,"id":9625043},{"atl":[[1.09,36.62]],"id":9625043}],"con":true,"img":false}]}
{"op":"mcm","clk":"1350014801","pt":1588415602773,"mc":[{"id":"1.170370562","rc":[{"atl":[[1.1,26.39]],"id":9625043}],"con":true,"img":false}]}
{"op":"mcm","clk":"1350014814","pt":1588415603081,"mc":[{"id":"1.170370562","rc":[{"trd":[[1.09,454.82]],"ltp":1.09,"tv":454.82,"id":9625043},{"atl":[[1.09,34.85]],"id":9625043}],"con":true,"img":false}]}
{"op":"mcm","clk":"1350014818","pt":1588415603139,"mc":[{"id":"1.170370562","rc":[{"atl":[[1.12,293.53]],"id":9625043}],"con":true,"img":false}]}
{"op":"mcm","clk":"1350014838","pt":1588415603962,"mc":[{"id":"1.170370562","rc":[{"atb":[[1.04,1335.72]],"id":9625043}],"con":true,"img":false}]}
{"op":"mcm","clk":"1350014865","pt":1588415604949,"mc":[{"id":"1.170370562","rc":[{"trd":[[1.09,524.53]],"ltp":1.09,"tv":524.53,"id":9625043},{"atb":[[1.09,9.46]],"id":9625043},{"atl":[[1.09,0]],"id":9625043}],"con":true,"img":false}]}
{"op":"mcm","clk":"1350014887","pt":1588415605567,"mc":[{"id":"1.170370562","rc":[{"atl":[[1.11,0.23]],"id":9625043}],"con":true,"img":false}]}
{"op":"mcm","clk":"1350014892","pt":1588415605727,"mc":[{"id":"1.170370562","rc":[{"trd":[[1.09,526.82]],"ltp":1.09,"tv":526.82,"id":9625043},{"atb":[[1.09,8.32]],"id":9625043}],"con":true,"img":false}]}
{"op":"mcm","clk":"1350014947","pt":1588415607335,"mc":[{"id":"1.170370562","rc":[{"atb":[[1.09,0]],"id":9625043}],"con":true,"img":false}]}
{"op":"mcm","clk":"1350014955","pt":1588415607645,"mc":[{"id":"1.170370562","rc":[{"atb":[[1.05,240]],"id":9625043}],"con":true,"img":false}]}
{"op":"mcm","clk":"1350014974","pt":1588415608162,"mc":[{"id":"1.170370562","rc":[{"atb":[[1.01,4043.14],[1.05,0]],"id":9625043}],"con":true,"img":false}]}
{"op":"mcm","clk":"1350014986","pt":1588415608476,"mc":[{"id":"1.170370562","rc":[{"trd":[[1.07,10]],"ltp":1.07,"tv":10.0,"id":9625043},{"atb":[[1.09,4.63],[1.07,93.47]],"id":9625043}],"con":true,"img":false}]}
{"op":"mcm","clk":"1350014991","pt":1588415608580,"mc":[{"id":"1.170370562","rc":[{"atl":[[20,0]],"id":9631798}],"con":true,"img":false}]}
{"op":"mcm","clk":"1350015025","pt":1588415609457,"mc":[{"id":"1.170370562","rc":[{"atl":[[25,0]],"id":9631798}],"con":true,"img":false}]}
{"op":"mcm","clk":"1350015034","pt":1588415609662,"mc":[{"id":"1.170370562","rc":[{"trd":[[1.09,536.09]],"ltp":1.09,"tv":536.09,"id":9625043},{"atb":[[1.09,0]],"id":9625043},{"atl":[[1.09,745.36]],"id":9625043}],"con":true,"img":false}]}
{"op":"mcm","clk":"1350015052","pt":1588415610177,"mc":[{"id":"1.170370562","rc":[{"atb":[[1.04,350.79]],"id":9625043}],"con":true,"img":false}]}
{"op":"mcm","clk":"1350015061","pt":1588415610334,"mc":[{"id":"1.170370562","rc":[{"trd":[[1.07,196.94]],"ltp":1.07,"tv":196.94,"id":9625043},{"atb":[[1.07,0]],"id":9625043},{"atl":[[1.07,1067.14]],"id":9625043}],"con":true,"img":false}]}
{"op":"mcm","clk":"1350015076","pt":1588415610647,"mc":[{"id":"1.170370562","rc":[{"atl":[[1.1,0]],"id":9625043}],"con":true,"img":false}]}
{"op":"mcm","clk":"1350015082","pt":1588415610752,"mc":[{"id":"1.170370562","rc":[{"trd":[[1.07,207.45]],"ltp":1.07,"tv":207.45,"id":9625043},{"atl":[[1.07,1061.88]],"id":9625043}],"con":true,"img":false}]}
{"op":"mcm","clk":"1350015086","pt":1588415610855,"mc":[{"id":"1.170370562","rc":[{"atl":[[1.07,2046.81]],"id":9625043}],"con":true,"img":false}]}
{"op":"mcm","clk":"1350015115","pt":1588415611581,"mc":[{"id":"1.170370562","rc":[{"trd":[[1.07,317.45]],"ltp":1.07,"tv":317.45,"id":9625043},{"atl":[[1.07,1992.24]],"id":9625043}],"con":true,"img":false}]}
{"op":"mcm","clk":"1350015120","pt":1588415611682,"mc":[{"id":"1.170370562","rc":[{"atl":[[1.09,0]],"id":9625043}],"con":true,"img":false}]}
{"op":"mcm","clk":"1350015147","pt":1588415612252,"mc":[{"id":"1.170370562","rc":[{"atl":[[1.12,0]],"id":9625043}],"con":true,"img":false}]}
{"op":"mcm","clk":"1350015191","pt":1588415613755,"mc":[{"id":"1.170370562","rc":[{"atl":[[1.09,239.96],[1.07,2058.73]],"id":9625043}],"con":true,"img":false}]}
{"op":"mcm","clk":"1350015198","pt":1588415613962,"mc":[{"id":"1.170370562","rc":[{"atl":[[1.08,354.6],[1.07,2125.22]],"id":9625043}],"con":true,"img":false}]}
{"op":"mcm","clk":"1350015207","pt":1588415614169,"mc":[{"id":"1.170370562","rc":[{"atl":[[1.07,2191.71]],"id":9625043}],"con":true,"img":false}]}
{"op":"mcm","clk":"1350015214","pt":1588415614377,"mc":[{"id":"1.170370562","rc":[{"atl":[[1.08,594.57],[1.07,2258.2]],"id":9625043}],"con":true,"img":false}]}
{"op":"mcm","clk":"1350015220","pt":1588415614481,"mc":[{"id":"1.170370562","rc":[{"atb":[[4.1,283.68]],"id":9631798},{"atl":[[65,15.21]],"id":9631798}],"con":true,"img":false}]}
{"op":"mcm","clk":"1350015233","pt":1588415614744,"mc":[{"id":"1.170370562","rc":[{"atl":[[1.08,597.14]],"id":9625043}],"con":true,"img":false}]}
{"op":"mcm","clk":"1350015255","pt":1588415615367,"mc":[{"id":"1.170370562","rc":[{"atl":[[1.11,240.23]],"id":9625043}],"con":true,"img":false}]}
{"op":"mcm","clk":"1350015267","pt":1588415615675,"mc":[{"id":"1.170370562","rc":[{"atb":[[1.05,228.68]],"id":9625043}],"con":true,"img":false}]}
{"op":"mcm","clk":"1350015274","pt":1588415615881,"mc":[{"id":"1.170370562","rc":[{"atl":[[1.19,0]],"id":9625043}],"con":true,"img":false}]}
{"op":"mcm","clk":"1350015279","pt":1588415615987,"mc":[{"id":"1.170370562","rc":[{"atl":[[1.09,0]],"id":9625043}],"con":true,"img":false}]}
{"op":"mcm","clk":"1350015292","pt":1588415616244,"mc":[{"id":"1.170370562","rc":[{"atl":[[1.19,240]],"id":9625043}],"con":true,"img":false}]}
{"op":"mcm","clk":"1350015307","pt":1588415616658,"mc":[{"id":"1.170370562","rc":[{"atl":[[1.07,2257.77]],"id":9625043}],"con":true,"img":false}]}
{"op":"mcm","clk":"1350015316","pt":1588415616868,"mc":[{"id":"1.170370562","rc":[{"atl":[[32,0]],"id":9631798}],"con":true,"img":false}]}
{"op":"mcm","clk":"1350015354","pt":1588415618174,"mc":[{"id":"1.170370562","rc":[{"atl":[[1.08,648.07]],"id":9625043}],"con":true,"img":false}]}
{"op":"mcm","clk":"1350015358","pt":1588415618279,"mc":[{"id":"1.170370562","rc":[{"trd":[[1.07,321]],"ltp":1.07,"tv":321.0,"id":9625043},{"atb":[[1.01,4056.28],[1.04,705.4]],"id":9625043},{"atl":[[1.07,2255.99]],"id":9625043}],"con":true,"img":false}]}
{"op":"mcm","clk":"1350015360","pt":1588415618383,"mc":[{"id":"1.170370562","rc":[{"atl":[[1.11,284.55]],"id":9625043}],"con":true,"img":false}]}
{"op":"mcm","clk":"1350015382","pt":1588415619156,"mc":[{"id":"1.170370562","rc":[{"trd":[[1.07,421]],"ltp":1.07,"tv":421.0,"id":9625043},{"atl":[[1.07,2205.99]],"id":9625043}],"con":true,"img":false}]}
{"op":"mcm","clk":"1350015395","pt":1588415619680,"mc":[{"id":"1.170370562","rc":[{"atl":[[1.11,284.32]],"id":9625043}],"con":true,"img":false}]}
{"op":"mcm","clk":"1350015404","pt":1588415619989,"mc":[{"id":"1.170370562","rc":[{"atb":[[15,110.81]],"id":9631798}],"con":true,"img":false}]}
{"op":"mcm","clk":"1350015415","pt":1588415620255,"mc":[{"id":"1.170370562","rc":[{"trd":[[1.05,143.97]],"ltp":1.05,"tv":143.97,"id":9625043},{"atb":[[1.05,156.7]],"id":9625043}],"con":true,"img":false}]}
{"op":"mcm","clk":"1350015422","pt":1588415620457,"mc":[{"id":"1.170370562","rc":[{"atb":[[1.05,359.27]],"id":9625043},{"atl":[[1.08,597.14]],"id":9625043}],"con":true,"img":false}]}
{"op":"mcm","clk":"1350015452","pt":1588415621492,"mc":[{"id":"1.170370562","rc":[{"atl":[[1.17,354.6]],"id":9625043}],"con":true,"img":false}]}
{"op":"mcm","clk":"1350015458","pt":1588415621598,"mc":[{"id":"1.170370562","rc":[{"atl":[[1.07,1221.06]],"id":9625043}],"con":true,"img":false}]}
{"op":"mcm","clk":"1350015490","pt":1588415622484,"mc":[{"id":"1.170370562","rc":[{"atb":[[1.03,3006.76]],"id":9625043},{"atl":[[34,5]],"id":9631798}],"con":true,"img":false}]}
{"op":"mcm","clk":"1350015507","pt":1588415622953,"mc":[{"id":"1.170370562","rc":[{"atb":[[1.03,2103.95]],"id":9625043}],"con":true,"img":false}]}
{"op":"mcm","clk":"1350015528","pt":1588415623573,"mc":[{"id":"1.170370562","rc":[{"atb":[[1.01,4296.28]],"id":9625043}],"con":true,"img":false}]}
{"op":"mcm","clk":"1350015548","pt":1588415624296,"mc":[{"id":"1.170370562","rc":[{"atl":[[50,5]],"id":9631798}],"con":true,"img":false}]}
{"op":"mcm","clk":"1350015560","pt":1588415624969,"mc":[{"id":"1.170370562","rc":[{"atb":[[1.04,372.4]],"id":9625043}],"con":true,"img":false}]}
{"op":"mcm","clk":"1350015567","pt":1588415625401,"mc":[{"id":"1.170370562","rc":[{"atb":[[1.04,17.79]],"id":9625043}],"con":true,"img":false}]}
{"op":"mcm","clk":"1350015587","pt":1588415626175,"mc":[{"id":"1.170370562","rc":[{"trd":[[1.07,421.84]],"ltp":1.07,"tv":421.84,"id":9625043},{"atb":[[1.03,1749.34]],"id":9625043},{"atl":[[1.07,1220.64]],"id":9625043}],"con":true,"img":false}]}
{"op":"mcm","clk":"1350015599","pt":1588415626486,"mc":[{"id":"1.170370562","rc":[{"trd":[[1.07,424.81]],"ltp":1.07,"tv":424.81,"id":9625043},{"atl":[[1.07,1219.16]],"id":9625043}],"con":true,"img":false}]}
{"op":"mcm","clk":"1350015610","pt":1588415626745,"mc":[{"id":"1.170370562","rc":[{"trd":[[1.05,145.24]],"ltp":1.05,"tv":145.24,"id":9625043},{"atb":[[1.05,358.63]],"id":9625043}],"con":true,"img":false}]}
{"op":"mcm","clk":"1350015627","pt":1588415627471,"mc":[{"id":"1.170370562","rc":[{"atb":[[15,0]],"id":9631798}],"con":true,"img":false}]}
{"op":"mcm","clk":"1350015630","pt":1588415627571,"mc":[{"id":"1.170370562","rc":[{"trd":[[1.05,147.6]],"ltp":1.05,"tv":147.6,"id":9625043},{"atb":[[1.05,357.45]],"id":9625043}],"con":true,"img":false}]}
{"op":"mcm","clk":"1350015633","pt":1588415627674,"mc":[{"id":"1.170370562","rc":[{"trd":[[1.07,429.96]],"ltp":1.07,"tv":429.96,"id":9625043},{"atl":[[1.07,1216.58]],"id":9625043}],"con":true,"img":false}]}
{"op":"mcm","clk":"1350015640","pt":1588415627984,"mc":[{"id":"1.170370562","rc":[{"atb":[[1.06,40]],"id":9625043}],"con":true,"img":false}]}
{"op":"mcm","clk":"1350015701","pt":1588415630163,"mc":[{"id":"1.170370562","rc":[{"atl":[[1.08,242.53]],"id":9625043}],"con":true,"img":false}]}
{"op":"mcm","clk":"1350015705","pt":1588415630265,"mc":[{"id":"1.170370562","rc":[{"atl":[[1000,2.83]],"id":9625043}],"con":true,"img":false}]}
{"op":"mcm","clk":"1350015729","pt":1588415630994,"mc":[{"id":"1.170370562","rc":[{"atl":[[1.11,44.32]],"id":9625043}],"con":true,"img":false}]}
{"op":"mcm","clk":"1350015733","pt":1588415631097,"mc":[{"id":"1.170370562","rc":[{"atl":[[1000,0.25]],"id":9625043}],"con":true,"img":false}]}
{"op":"mcm","clk":"1350015742","pt":1588415631302,"mc":[{"id":"1.170370562","rc":[{"trd":[[1.05,874.92],[1.06,80]],"ltp":1.05,"tv":954.92,"id":9625043},{"atb":[[1.02,3478.36],[1.06,0],[1.05,0]],"id":9625043},{"atl":[[1.05,140.34]],"id":9625043}],"con":true,"img":false}]}
{"op":"mcm","clk":"1350015757","pt":1588415631564,"mc":[{"id":"1.170370562","rc":[{"atl":[[34,0]],"id":9631798}],"con":true,"img":false}]}
{"op":"mcm","clk":"1350015765","pt":1588415631771,"mc":[{"id":"1.170370562","rc":[{"atl":[[1.07,1966.58]],"id":9625043}],"con":true,"img":false}]}
{"op":"mcm","clk":"1350015769","pt":1588415631876,"mc":[{"id":"1.170370562","rc":[{"trd":[[1.05,880.07]],"ltp":1.05,"tv":880.07,"id":9625043},{"atl":[[1000,0.05],[1.05,137.76]],"id":9625043}],"con":true,"img":false}]}
{"op":"mcm","clk":"1350015775","pt":1588415632077,"mc":[{"id":"1.170370562","rc":[{"atb":[[4.1,0]],"id":9631798},{"atl":[[65,0]],"id":9631798}],"con":true,"img":false}]}
{"op":"mcm","clk":"1350015786","pt":1588415632492,"mc":[{"id":"1.170370562","rc":[{"atl":[[1.09,3.53]],"id":9625043}],"con":true,"img":false}]}
{"op":"mcm","clk":"1350015791","pt":1588415632595,"mc":[{"id":"1.170370562","rc":[{"atl":[[1.07,1216.58]],"id":9625043}],"con":true,"img":false}]}
{"op":"mcm","clk":"1350015813","pt":1588415633375,"mc":[{"id":"1.170370562","rc":[{"trd":[[1.04,35.58]],"ltp":1.04,"tv":35.58,"id":9625043},{"atb":[[1.04,0]],"id":9625043},{"atl":[[1.04,302.15]],"id":9625043}],"con":true,"img":false}]}
{"op":"mcm","clk":"1350015825","pt":1588415633894,"mc":[{"id":"1.170370562","rc":[{"atl":[[1.04,0]],"id":9625043}],"con":true,"img":false}]}
{"op":"mcm","clk":"1350015836","pt":1588415634200,"mc":[{"id":"1.170370562","rc":[{"atl":[[1.05,537.76]],"id":9625043}],"con":true,"img":false}]}
{"op":"mcm","clk":"1350015840","pt":1588415634251,"mc":[{"id":"1.170370562","rc":[{"atl":[[1.05,538.19]],"id":9625043}],"con":true,"img":false}]}
{"op":"mcm","clk":"1350015853","pt":1588415634670,"mc":[{"id":"1.170370562","rc":[{"trd":[[1.05,887.49]],"ltp":1.05,"tv":887.49,"id":9625043},{"atl":[[1.05,534.48]],"id":9625043}],"con":true,"img":false}]}
{"op":"mcm","clk":"1350015871","pt":1588415635188,"mc":[{"id":"1.170370562","rc":[{"atb":[[1.02,3565.83]],"id":9625043}],"con":true,"img":false}]}
{"op":"mcm","clk":"1350015880","pt":1588415635499,"mc":[{"id":"1.170370562","rc":[{"atb":[[1.01,4283.14]],"id":9625043}],"con":true,"img":false}]}
{"op":"mcm","clk":"1350015899","pt":1588415636177,"mc":[{"id":"1.170370562","rc":[{"trd":[[1.05,961.65]],"ltp":1.05,"tv":961.65,"id":9625043},{"atl":[[1.05,497.4]],"id":9625043}],"con":true,"img":false}]}
{"op":"mcm","clk":"1350015904","pt":1588415636385,"mc":[{"id":"1.170370562","rc":[{"atl":[[1.05,549.27]],"id":9625043}],"con":true,"img":false}]}
{"op":"mcm","clk":"1350015925","pt":1588415636962,"mc":[{"id":"1.170370562","rc":[{"atl":[[1.05,549.48]],"id":9625043}],"con":true,"img":false}]}
{"op":"mcm","clk":"1350015930","pt":1588415637169,"mc":[{"id":"1.170370562","rc":[{"atl":[[34,2]],"id":9631798}],"con":true,"img":false}]}
{"op":"mcm","clk":"1350015938","pt":1588415637479,"mc":[{"id":"1.170370562","rc":[{"trd":[[1.05,962.58]],"ltp":1.05,"tv":962.58,"id":9625043},{"atl":[[1.05,549.02],[1.07,950.63]],"id":9625043}],"con":true,"img":false}]}
{"op":"mcm","clk":"1350015942","pt":1588415637687,"mc":[{"id":"1.170370562","rc":[{"atl":[[1.07,0]],"id":9625043}],"con":true,"img":false}]}
{"op":"mcm","clk":"1350015949","pt":1588415638051,"mc":[{"id":"1.170370562","rc":[{"atl":[[1.08,2.57]],"id":9625043}],"con":true,"img":false}]}
{"op":"mcm","clk":"1350015955","pt":1588415638465,"mc":[{"id":"1.170370562","rc":[{"atl":[[1.59,0],[1.19,0]],"id":9625043}],"con":true,"img":false}]}
{"op":"mcm","clk":"1350015959","pt":1588415638675,"mc":[{"id":"1.170370562","rc":[{"atb":[[1.03,764.42]],"id":9625043}],"con":true,"img":false}]}
{"op":"mcm","clk":"1350015986","pt":1588415639862,"mc":[{"id":"1.170370562","rc":[{"atb":[[1.04,66.48]],"id":9625043}],"con":true,"img":false}]}
{"op":"mcm","clk":"1350015989","pt":1588415639969,"mc":[{"id":"1.170370562","rc":[{"atb":[[1.04,132.97]],"id":9625043}],"con":true,"img":false}]}
{"op":"mcm","clk":"1350015994","pt":1588415640175,"mc":[{"id":"1.170370562","rc":[{"atb":[[1.04,199.46]],"id":9625043}],"con":true,"img":false}]}
{"op":"mcm","clk":"1350016000","pt":1588415640385,"mc":[{"id":"1.170370562","rc":[{"trd":[[1.05,1095.56]],"ltp":1.05,"tv":1095.56,"id":9625043},{"atl":[[1.05,482.53]],"id":9625043}],"con":true,"img":false}]}
{"op":"mcm","clk":"1350016003","pt":1588415640490,"mc":[{"id":"1.170370562","rc":[{"trd":[[1.05,2060.62]],"ltp":1.05,"tv":2060.62,"id":9625043},{"atb":[[1.06,267.47]],"id":9625043},{"atl":[[1.05,0]],"id":9625043}],"con":true,"img":false}]}
{"op":"mcm","clk":"1350016020","pt":1588415640955,"mc":[{"id":"1.170370562","rc":[{"atb":[[1.04,465.42]],"id":9625043}],"con":true,"img":false}]}
{"op":"mcm","clk":"1350016023","pt":1588415641060,"mc":[{"id":"1.170370562","rc":[{"atb":[[1.02,3478.36]],"id":9625043}],"con":true,"img":false}]}
{"op":"mcm","clk":"1350016032","pt":1588415641268,"mc":[{"id":"1.170370562","rc":[{"atb":[[1.06,1017.47],[1.04,531.91]],"id":9625043}],"con":true,"img":false}]}
{"op":"mcm","clk":"1350016041","pt":1588415641577,"mc":[{"id":"1.170370562","rc":[{"atb":[[1.06,1767.47],[1.04,598.4]],"id":9625043}],"con":true,"img":false}]}
{"op":"mcm","clk":"1350016051","pt":1588415642111,"mc":[{"id":"1.170370562","rc":[{"atb":[[1.06,2007.47]],"id":9625043}],"con":true,"img":false}]}
{"op":"mcm","clk":"1350016054","pt":1588415642216,"mc":[{"id":"1.170370562","rc":[{"atb":[[1.05,333]],"id":9625043}],"con":true,"img":false}]}
{"op":"mcm","clk":"1350016058","pt":1588415642320,"mc":[{"id":"1.170370562","rc":[{"atb":[[1.06,240]],"id":9625043}],"con":true,"img":false}]}
{"op":"mcm","clk":"1350016061","pt":1588415642425,"mc":[{"id":"1.170370562","rc":[{"trd":[[1.06,80.56]],"ltp":1.06,"tv":80.56,"id":9625043},{"atb":[[1.06,572.72]],"id":9625043}],"con":true,"img":false}]}
{"op":"mcm","clk":"1350016065","pt":1588415642633,"mc":[{"id":"1.170370562","rc":[{"atb":[[1.07,240]],"id":9625043}],"con":true,"img":false}]}
{"op":"mcm","clk":"1350016072","pt":1588415642898,"mc":[{"id":"1.170370562","rc":[{"atb":[[1.06,838.67],[1.05,399.48]],"id":9625043}],"con":true,"img":false}]}
{"op":"mcm","clk":"1350016076","pt":1588415643005,"mc":[{"id":"1.170370562","rc":[{"atb":[[1.05,1051.41]],"id":9625043}],"con":true,"img":false}]}
{"op":"mcm","clk":"1350016082","pt":1588415643216,"mc":[{"id":"1.170370562","rc":[{"atb":[[1.05,1117.9]],"id":9625043}],"con":true,"img":false}]}
{"op":"mcm","clk":"1350016086","pt":1588415643423,"mc":[{"id":"1.170370562","rc":[{"atb":[[1.07,1227.09],[1.05,1184.39]],"id":9625043}],"con":true,"img":false}]}
{"op":"mcm","clk":"1350016094","pt":1588415643632,"mc":[{"id":"1.170370562","rc":[{"trd":[[1.08,130.15]],"ltp":1.08,"tv":130.15,"id":9625043},{"atb":[[1.08,330.42]],"id":9625043},{"atl":[[1.08,0]],"id":9625043}],"con":true,"img":false}]}
{"op":"mcm","clk":"1350016108","pt":1588415644207,"mc":[{"id":"1.170370562","rc":[{"atb":[[1.05,449.46],[1.04,610.4]],"id":9625043}],"con":true,"img":false}]}
{"op":"mcm","clk":"1350016118","pt":1588415644517,"mc":[{"id":"1.170370562","rc":[{"atb":[[3.6,294.45]],"id":9631798},{"atl":[[21,10.62]],"id":9631798}],"con":true,"img":false}]}
{"op":"mcm","clk":"1350016120","pt":1588415644622,"mc":[{"id":"1.170370562","rc":[{"atb":[[1.05,699.46]],"id":9625043}],"con":true,"img":false}]}
{"op":"mcm","clk":"1350016131","pt":1588415644935,"mc":[{"id":"1.170370562","rc":[{"atb":[[1.04,943.4]],"id":9625043}],"con":true,"img":false}]}
{"op":"mcm","clk":"1350016135","pt":1588415645040,"mc":[{"id":"1.170370562","rc":[{"atb":[[3.6,0]],"id":9631798},{"atl":[[21,0]],"id":9631798}],"con":true,"img":false}]}
