{"op":"mcm","clk":"1362114266","pt":1588428343158,"mc":[{"id":"1.170370557","rc":[{"trd":[[1.51,476.11],[1.49,2304.41],[1.5,1112.05]],"ltp":1.51,"tv":3892.56,"id":9624350},{"atl":[[1.5,0],[1.49,0],[1.51,843.95]],"id":9624350}],"con":true,"img":false}]}
{"op":"mcm","clk":"1362114275","pt":1588428343769,"mc":[{"id":"1.170370557","rc":[{"atl":[[1.62,8.75]],"id":9624350}],"con":true,"img":false}]}
{"op":"mcm","clk":"1362114281","pt":1588428344076,"mc":[{"id":"1.170370557","rc":[{"atl":[[1.48,112]],"id":9624350}],"con":true,"img":false}]}
{"op":"mcm","clk":"1362114287","pt":1588428344337,"mc":[{"id":"1.170370557","rc":[{"atb":[[1.38,0]],"id":9624350}],"con":true,"img":false}]}
{"op":"mcm","clk":"1362114289","pt":1588428344436,"mc":[{"id":"1.170370557","rc":[{"atl":[[1.47,112]],"id":9624350}],"con":true,"img":false}]}
{"op":"mcm","clk":"1362114292","pt":1588428344539,"mc":[{"id":"1.170370557","rc":[{"atb":[[2.86,0]],"id":9622734}],"con":true,"img":false}]}
{"op":"mcm","clk":"1362114303","pt":1588428345049,"mc":[{"id":"1.170370557","rc":[{"atb":[[2.76,0]],"id":9622734}],"con":true,"img":false}]}
{"op":"mcm","clk":"1362114307","pt":1588428345256,"mc":[{"id":"1.170370557","rc":[{"atl":[[1.47,0]],"id":9624350}],"con":true,"img":false}]}
{"op":"mcm","clk":"1362114314","pt":1588428345558,"mc":[{"id":"1.170370557","rc":[{"atl":[[1.47,94.3],[1.71,443.26]],"id":9624350}],"con":true,"img":false}]}
{"op":"mcm","clk":"1362114319","pt":1588428345967,"mc":[{"id":"1.170370557","rc":[{"trd":[[1.47,722.65]],"ltp":1.47,"tv":722.65,"id":9624350},{"atl":[[1.47,5.65]],"id":9624350}],"con":true,"img":false}]}
{"op":"mcm","clk":"1362114323","pt":1588428346172,"mc":[{"id":"1.170370557","rc":[{"atl":[[1.62,0]],"id":9624350}],"con":true,"img":false}]}
{"op":"mcm","clk":"1362114326","pt":1588428346377,"mc":[{"id":"1.170370557","rc":[{"atl":[[1.47,0]],"id":9624350}],"con":true,"img":false}]}
{"op":"mcm","clk":"1362114331","pt":1588428346737,"mc":[{"id":"1.170370557","rc":[{"trd":[[1.48,206.27]],"ltp":1.48,"tv":206.27,"id":9624350},{"atl":[[1.48,105.73]],"id":9624350}],"con":true,"img":false}]}
{"op":"mcm","clk":"1362114336","pt":1588428347143,"mc":[{"id":"1.170370557","rc":[{"atb":[[1.46,281.91]],"id":9624350}],"con":true,"img":false}]}
{"op":"mcm","clk":"1362114341","pt":1588428347554,"mc":[{"id":"1.170370557","rc":[{"trd":[[1.46,996.03]],"ltp":1.46,"tv":996.03,"id":9624350},{"atb":[[1.46,281.25]],"id":9624350}],"con":true,"img":false}]}
{"op":"mcm","clk":"1362114345","pt":1588428347865,"mc":[{"id":"1.170370557","rc":[{"trd":[[3.05,49.95]],"ltp":3.05,"tv":49.95,"id":9622734},{"trd":[[1.48,297.62]],"ltp":1.48,"tv":297.62,"id":9624350},{"atl":[[1.48,14.38]],"id":9624350}],"con":true,"img":false}]}
{"op":"mcm","clk":"1362114348","pt":1588428348064,"mc":[{"id":"1.170370557","rc":[{"atb":[[1.41,654.6]],"id":9624350}],"con":true,"img":false}]}
{"op":"mcm","clk":"1362114350","pt":1588428348176,"mc":[{"id":"1.170370557","rc":[{"trd":[[3.05,56.93]],"ltp":3.05,"tv":56.93,"id":9622734},{"atl":[[3,37.34]],"id":9622734},{"trd":[[1.48,312]],"ltp":1.48,"tv":312.0,"id":9624350},{"atl":[[1.48,0]],"id":9624350}],"con":true,"img":false}]}
{"op":"mcm","clk":"1362114358","pt":1588428348577,"mc":[{"id":"1.170370557","rc":[{"atl":[[1.51,489.34]],"id":9624350}],"con":true,"img":false}]}
{"op":"mcm","clk":"1362114377","pt":1588428349650,"mc":[{"id":"1.170370557","rc":[{"trd":[[3.2,70.56],[3,164.92]],"ltp":3.2,"tv":235.48,"id":9622734},{"atl":[[3,0]],"id":9622734},{"trd":[[1.46,1025.66]],"ltp":1.46,"tv":1025.66,"id":9624350},{"atb":[[1.46,251.62]],"id":9624350}],"con":true,"img":false}]}
{"op":"mcm","clk":"1362114384","pt":1588428350165,"mc":[{"id":"1.170370557","rc":[{"trd":[[1.46,1071.71]],"ltp":1.46,"tv":1071.71,"id":9624350},{"atb":[[1.46,228.59],[1.49,2.35]],"id":9624350}],"con":true,"img":false}]}
{"op":"mcm","clk":"1362114388","pt":1588428350369,"mc":[{"id":"1.170370557","rc":[{"atb":[[1.45,0.23]],"id":9624350}],"con":true,"img":false}]}
{"op":"mcm","clk":"1362114445","pt":1588428351247,"mc":[{"id":"1.170370557","rc":[{"atl":[[1.5,112]],"id":9624350}],"con":true,"img":false}]}
{"op":"mcm","clk":"1362114448","pt":1588428351449,"mc":[{"id":"1.170370557","rc":[{"atb":[[1.31,443.26]],"id":9624350}],"con":true,"img":false}]}
{"op":"mcm","clk":"1362114451","pt":1588428351660,"mc":[{"id":"1.170370557","rc":[{"atl":[[1.5,0]],"id":9624350}],"con":true,"img":false}]}
{"op":"mcm","clk":"1362114457","pt":1588428352167,"mc":[{"id":"1.170370557","rc":[{"atb":[[1.46,415.51]],"id":9624350}],"con":true,"img":false}]}
{"op":"mcm","clk":"1362114462","pt":1588428352882,"mc":[{"id":"1.170370557","rc":[{"atb":[[1.46,228.59]],"id":9624350}],"con":true,"img":false}]}
{"op":"mcm","clk":"1362114468","pt":1588428353345,"mc":[{"id":"1.170370557","rc":[{"atb":[[1.48,92.34]],"id":9624350}],"con":true,"img":false}]}
{"op":"mcm","clk":"1362114471","pt":1588428353957,"mc":[{"id":"1.170370557","rc":[{"atb":[[1.29,500]],"id":9624350}],"con":true,"img":false}]}
{"op":"mcm","clk":"1362114472","pt":1588428354263,"mc":[{"id":"1.170370557","rc":[{"atb":[[1.41,354.6]],"id":9624350}],"con":true,"img":false}]}
{"op":"mcm","clk":"1362114473","pt":1588428354465,"mc":[{"id":"1.170370557","rc":[{"atb":[[1.41,0]],"id":9624350}],"con":true,"img":false}]}
{"op":"mcm","clk":"1362114474","pt":1588428354772,"mc":[{"id":"1.170370557","rc":[{"atb":[[1.4,0]],"id":9624350}],"con":true,"img":false}]}
{"op":"mcm","clk":"1362114475","pt":1588428354874,"mc":[{"id":"1.170370557","rc":[{"trd":[[1.48,315.28],[1.49,2309.12]],"ltp":1.48,"tv":2624.39,"id":9624350},{"atb":[[1.49,0],[1.48,90.7]],"id":9624350}],"con":true,"img":false}]}
{"op":"mcm","clk":"1362114482","pt":1588428356358,"mc":[{"id":"1.170370557","rc":[{"trd":[[1.51,478.03]],"ltp":1.51,"tv":478.03,"id":9624350},{"atl":[[1.51,488.38]],"id":9624350}],"con":true,"img":false}]}
{"op":"mcm","clk":"1362114495","pt":1588428357888,"mc":[{"id":"1.170370557","rc":[{"atb":[[1.47,112.77]],"id":9624350}],"con":true,"img":false}]}
{"op":"mcm","clk":"1362114514","pt":1588428358863,"mc":[{"id":"1.170370557","rc":[{"atl":[[1.5,402]],"id":9624350}],"con":true,"img":false}]}
{"op":"mcm","clk":"1362114515","pt":1588428358966,"mc":[{"id":"1.170370557","rc":[{"trd":[[1.48,365.28]],"ltp":1.48,"tv":365.28,"id":9624350},{"atb":[[1.48,65.7]],"id":9624350}],"con":true,"img":false}]}
{"op":"mcm","clk":"1362114553","pt":1588428361257,"mc":[{"id":"1.170370557","rc":[{"atl":[[1.51,354.6]],"id":9624350}],"con":true,"img":false}]}
{"op":"mcm","clk":"1362114566","pt":1588428363298,"mc":[{"id":"1.170370557","rc":[{"atb":[[1.39,500]],"id":9624350}],"con":true,"img":false}]}
{"op":"mcm","clk":"1362114569","pt":1588428363860,"mc":[{"id":"1.170370557","rc":[{"atl":[[1.51,0]],"id":9624350}],"con":true,"img":false}]}
{"op":"mcm","clk":"1362114570","pt":1588428363963,"mc":[{"id":"1.170370557","rc":[{"atb":[[2.48,0]],"id":9622734}],"con":true,"img":false}]}
{"op":"mcm","clk":"1362114572","pt":1588428364065,"mc":[{"id":"1.170370557","rc":[{"atl":[[1.5,0]],"id":9624350}],"con":true,"img":false}]}
{"op":"mcm","clk":"1362114573","pt":1588428364168,"mc":[{"id":"1.170370557","rc":[{"atl":[[1.52,0]],"id":9624350}],"con":true,"img":false}]}
{"op":"mcm","clk":"1362114576","pt":1588428364885,"mc":[{"id":"1.170370557","rc":[{"atb":[[1.25,0]],"id":9624350},{"atl":[[1.77,0]],"id":9624350}],"con":true,"img":false}]}
{"op":"mcm","clk":"1362114577","pt":1588428365089,"mc":[{"id":"1.170370557","rc":[{"atl":[[2.96,4.43]],"id":9622734}],"con":true,"img":false}]}
{"op":"mcm","clk":"1362114583","pt":1588428366876,"mc":[{"id":"1.170370557","rc":[{"atb":[[1.46,0],[1.48,0]],"id":9624350}],"con":true,"img":false}]}
{"op":"mcm","clk":"1362114590","pt":1588428367691,"mc":[{"id":"1.170370557","rc":[{"atb":[[1.55,112]],"id":9624350}],"con":true,"img":false}]}
{"op":"mcm","clk":"1362114595","pt":1588428367998,"mc":[{"id":"1.170370557","rc":[{"trd":[[1.55,1627.13]],"ltp":1.55,"tv":1627.13,"id":9624350},{"atb":[[1.55,102],[1.54,112]],"id":9624350}],"con":true,"img":false}]}
{"op":"mcm","clk":"1362114598","pt":1588428368202,"mc":[{"id":"1.170370557","rc":[{"atb":[[1.53,112]],"id":9624350}],"con":true,"img":false}]}
{"op":"mcm","clk":"1362114601","pt":1588428368305,"mc":[{"id":"1.170370557","rc":[{"atb":[[1.53,312],[1.51,112]],"id":9624350}],"con":true,"img":false}]}
{"op":"mcm","clk":"1362114606","pt":1588428368663,"mc":[{"id":"1.170370557","rc":[{"atb":[[1.53,512]],"id":9624350}],"con":true,"img":false}]}
{"op":"mcm","clk":"1362114612","pt":1588428369175,"mc":[{"id":"1.170370557","rc":[{"trd":[[1.53,2302.97],[1.55,1831.13],[1.54,4989.47]],"ltp":1.53,"tv":9123.57,"id":9624350},{"atb":[[1.53,324],[1.55,0],[1.54,0]],"id":9624350}],"con":true,"img":false}]}
{"op":"mcm","clk":"1362114617","pt":1588428369479,"mc":[{"id":"1.170370557","rc":[{"atb":[[1.57,200],[1.54,88.65],[1.5,21.59]],"id":9624350}],"con":true,"img":false}]}
{"op":"mcm","clk":"1362114622","pt":1588428369683,"mc":[{"id":"1.170370557","rc":[{"atb":[[1.55,88.65]],"id":9624350}],"con":true,"img":false}]}
{"op":"mcm","clk":"1362114625","pt":1588428369787,"mc":[{"id":"1.170370557","rc":[{"atb":[[1.57,400]],"id":9624350}],"con":true,"img":false}]}
{"op":"mcm","clk":"1362114627","pt":1588428369889,"mc":[{"id":"1.170370557","rc":[{"atb":[[1.55,177.3]],"id":9624350}],"con":true,"img":false}]}
{"op":"mcm","clk":"1362114631","pt":1588428369991,"mc":[{"id":"1.170370557","rc":[{"atb":[[1.55,265.95]],"id":9624350}],"con":true,"img":false}]}
{"op":"mcm","clk":"1362114636","pt":1588428370195,"mc":[{"id":"1.170370557","rc":[{"atb":[[1.55,354.6]],"id":9624350}],"con":true,"img":false}]}
{"op":"mcm","clk":"1362114644","pt":1588428370600,"mc":[{"id":"1.170370557","rc":[{"atl":[[2.9,1031.14]],"id":9622734}],"con":true,"img":false}]}
{"op":"mcm","clk":"1362114647","pt":1588428370805,"mc":[{"id":"1.170370557","rc":[{"atb":[[1.38,236.58]],"id":9624350},{"atl":[[2.04,202.06]],"id":9624350}],"con":true,"img":false}]}
{"op":"mcm","clk":"1362114654","pt":1588428371316,"mc":[{"id":"1.170370557","rc":[{"trd":[[1.57,1541.53]],"ltp":1.57,"tv":1541.53,"id":9624350},{"atb":[[1.53,374.17],[1.57,374]],"id":9624350}],"con":true,"img":false}]}
{"op":"mcm","clk":"1362114656","pt":1588428371371,"mc":[{"id":"1.170370557","rc":[{"atb":[[1.39,0]],"id":9624350}],"con":true,"img":false}]}
{"op":"mcm","clk":"1362114658","pt":1588428371476,"mc":[{"id":"1.170370557","rc":[{"atb":[[1.45,0]],"id":9624350}],"con":true,"img":false}]}
{"op":"mcm","clk":"1362114661","pt":1588428371579,"mc":[{"id":"1.170370557","rc":[{"atb":[[1.51,0],[1.47,0]],"id":9624350}],"con":true,"img":false}]}
{"op":"mcm","clk":"1362114666","pt":1588428371880,"mc":[{"id":"1.170370557","rc":[{"atl":[[3.05,0.41]],"id":9622734}],"con":true,"img":false}]}
{"op":"mcm","clk":"1362114672","pt":1588428372289,"mc":[{"id":"1.170370557","rc":[{"atb":[[1.29,0]],"id":9624350}],"con":true,"img":false}]}
{"op":"mcm","clk":"1362114676","pt":1588428372594,"mc":[{"id":"1.170370557","rc":[{"atl":[[1000,3.19]],"id":9624350}],"con":true,"img":false}]}
{"op":"mcm","clk":"1362114679","pt":1588428372798,"mc":[{"id":"1.170370557","rc":[{"atb":[[1.3,0]],"id":9624350},{"atl":[[1.69,88.87]],"id":9624350}],"con":true,"img":false}]}
{"op":"mcm","clk":"1362114682","pt":1588428372899,"mc":[{"id":"1.170370557","rc":[{"atb":[[1.43,0]],"id":9624350}],"con":true,"img":false}]}
{"op":"mcm","clk":"1362114689","pt":1588428373307,"mc":[{"id":"1.170370557","rc":[{"atb":[[1.53,324]],"id":9624350}],"con":true,"img":false}]}
{"op":"mcm","clk":"1362114693","pt":1588428373409,"mc":[{"id":"1.170370557","rc":[{"trd":[[1.6,602.49]],"ltp":1.6,"tv":602.49,"id":9624350},{"atb":[[1.62,37.59]],"id":9624350},{"atl":[[1.6,0]],"id":9624350}],"con":true,"img":false}]}
{"op":"mcm","clk":"1362114702","pt":1588428373817,"mc":[{"id":"1.170370557","rc":[{"atb":[[1.37,2.35]],"id":9624350}],"con":true,"img":false}]}
{"op":"mcm","clk":"1362114704","pt":1588428373870,"mc":[{"id":"1.170370557","rc":[{"atl":[[2.9,0]],"id":9622734}],"con":true,"img":false}]}
{"op":"mcm","clk":"1362114708","pt":1588428373972,"mc":[{"id":"1.170370557","rc":[{"atb":[[1.58,354.6]],"id":9624350}],"con":true,"img":false}]}
{"op":"mcm","clk":"1362114744","pt":1588428375402,"mc":[{"id":"1.170370557","rc":[{"atl":[[2.96,0]],"id":9622734}],"con":true,"img":false}]}
{"op":"mcm","clk":"1362114757","pt":1588428375809,"mc":[{"id":"1.170370557","rc":[{"atb":[[1.6,354.6]],"id":9624350}],"con":true,"img":false}]}
{"op":"mcm","clk":"1362114759","pt":1588428375912,"mc":[{"id":"1.170370557","rc":[{"atb":[[1.54,0]],"id":9624350}],"con":true,"img":false}]}
{"op":"mcm","clk":"1362114765","pt":1588428376218,"mc":[{"id":"1.170370557","rc":[{"trd":[[1.6,966.89],[1.62,277.18]],"ltp":1.6,"tv":1244.07,"id":9624350},{"atb":[[1.6,172.41],[1.62,0]],"id":9624350}],"con":true,"img":false}]}
{"op":"mcm","clk":"1362114769","pt":1588428376373,"mc":[{"id":"1.170370557","rc":[{"atb":[[1.58,797.87]],"id":9624350}],"con":true,"img":false}]}
{"op":"mcm","clk":"1362114772","pt":1588428376480,"mc":[{"id":"1.170370557","rc":[{"atb":[[1.58,443.26]],"id":9624350}],"con":true,"img":false}]}
{"op":"mcm","clk":"1362114794","pt":1588428377907,"mc":[{"id":"1.170370557","rc":[{"atb":[[1.6,0]],"id":9624350}],"con":true,"img":false}]}
{"op":"mcm","clk":"1362114809","pt":1588428378676,"mc":[{"id":"1.170370557","rc":[{"atb":[[1.55,265.95]],"id":9624350}],"con":true,"img":false}]}
{"op":"mcm","clk":"1362114830","pt":1588428380004,"mc":[{"id":"1.170370557","rc":[{"trd":[[1.58,876.46]],"ltp":1.58,"tv":876.46,"id":9624350},{"atb":[[1.58,443.08]],"id":9624350}],"con":true,"img":false}]}
{"op":"mcm","clk":"1362114837","pt":1588428380516,"mc":[{"id":"1.170370557","rc":[{"atl":[[2.54,4.43]],"id":9622734}],"con":true,"img":false}]}
{"op":"mcm","clk":"1362114845","pt":1588428380925,"mc":[{"id":"1.170370557","rc":[{"atl":[[1.69,0]],"id":9624350}],"con":true,"img":false}]}
{"op":"mcm","clk":"1362114856","pt":1588428381488,"mc":[{"id":"1.170370557","rc":[{"atl":[[1.67,75]],"id":9624350}],"con":true,"img":false}]}
{"op":"mcm","clk":"1362114860","pt":1588428381591,"mc":[{"id":"1.170370557","rc":[{"trd":[[2.54,57.62]],"ltp":2.54,"tv":57.62,"id":9622734},{"atl":[[2.54,4.28]],"id":9622734},{"trd":[[1.64,1237.74]],"ltp":1.64,"tv":1237.74,"id":9624350}],"con":true,"img":false}]}
{"op":"mcm","clk":"1362114867","pt":1588428381692,"mc":[{"id":"1.170370557","rc":[{"trd":[[2.54,59.69]],"ltp":2.54,"tv":59.69,"id":9622734},{"atl":[[2.54,2.2]],"id":9622734},{"trd":[[1.64,1240.95]],"ltp":1.64,"tv":1240.95,"id":9624350}],"con":true,"img":false}]}
{"op":"mcm","clk":"1362114876","pt":1588428382203,"mc":[{"id":"1.170370557","rc":[{"atl":[[1.65,75]],"id":9624350}],"con":true,"img":false}]}
{"op":"mcm","clk":"1362114897","pt":1588428383585,"mc":[{"id":"1.170370557","rc":[{"atl":[[1.65,0]],"id":9624350}],"con":true,"img":false}]}
{"op":"mcm","clk":"1362114918","pt":1588428384808,"mc":[{"id":"1.170370557","rc":[{"atb":[[1.53,0],[1.57,0]],"id":9624350}],"con":true,"img":false}]}
{"op":"mcm","clk":"1362114920","pt":1588428384911,"mc":[{"id":"1.170370557","rc":[{"atb":[[1.6,73.87]],"id":9624350}],"con":true,"img":false}]}
{"op":"mcm","clk":"1362114928","pt":1588428385420,"mc":[{"id":"1.170370557","rc":[{"atb":[[1.5,0]],"id":9624350}],"con":true,"img":false}]}
{"op":"mcm","clk":"1362114931","pt":1588428385625,"mc":[{"id":"1.170370557","rc":[{"trd":[[2.54,61.22]],"ltp":2.54,"tv":61.22,"id":9622734},{"atl":[[2.54,0.68]],"id":9622734},{"trd":[[1.64,1243.31]],"ltp":1.64,"tv":1243.31,"id":9624350}],"con":true,"img":false}]}
{"op":"mcm","clk":"1362114936","pt":1588428385829,"mc":[{"id":"1.170370557","rc":[{"atb":[[1.6,0]],"id":9624350}],"con":true,"img":false}]}
{"op":"mcm","clk":"1362114939","pt":1588428385932,"mc":[{"id":"1.170370557","rc":[{"atb":[[1.38,0]],"id":9624350}],"con":true,"img":false}]}
{"op":"mcm","clk":"1362114941","pt":1588428385985,"mc":[{"id":"1.170370557","rc":[{"atb":[[1.36,443.26]],"id":9624350}],"con":true,"img":false}]}
{"op":"mcm","clk":"1362114960","pt":1588428387008,"mc":[{"id":"1.170370557","rc":[{"atl":[[1.94,0]],"id":9624350}],"con":true,"img":false}]}
{"op":"mcm","clk":"1362114968","pt":1588428387315,"mc":[{"id":"1.170370557","rc":[{"atb":[[1.01,4103.75],[1.55,0]],"id":9624350}],"con":true,"img":false}]}
{"op":"mcm","clk":"1362114973","pt":1588428387518,"mc":[{"id":"1.170370557","rc":[{"atb":[[1.01,4101.79]],"id":9624350}],"con":true,"img":false}]}
{"op":"mcm","clk":"1362114979","pt":1588428387722,"mc":[{"id":"1.170370557","rc":[{"atb":[[1.01,4101.75]],"id":9624350}],"con":true,"img":false}]}
{"op":"mcm","clk":"1362114988","pt":1588428388334,"mc":[{"id":"1.170370557","rc":[{"trd":[[2.54,61.9]],"ltp":2.54,"tv":61.9,"id":9622734},{"atl":[[2.54,0]],"id":9622734},{"trd":[[1.58,1075.04],[1.64,1244.37]],"ltp":1.58,"tv":2319.41,"id":9624350},{"atb":[[1.58,343.79]],"id":9624350}],"con":true,"img":false}]}
{"op":"mcm","clk":"1362114992","pt":1588428388592,"mc":[{"id":"1.170370557","rc":[{"atb":[[1.58,0]],"id":9624350}],"con":true,"img":false}]}
{"op":"mcm","clk":"1362115010","pt":1588428389511,"mc":[{"id":"1.170370557","rc":[{"atl":[[1.64,2.57]],"id":9624350}],"con":true,"img":false}]}
{"op":"mcm","clk":"1362115016","pt":1588428389715,"mc":[{"id":"1.170370557","rc":[{"atb":[[1.6,88.65]],"id":9624350}],"con":true,"img":false}]}
{"op":"mcm","clk":"1362115018","pt":1588428389819,"mc":[{"id":"1.170370557","rc":[{"atl":[[1.71,0]],"id":9624350}],"con":true,"img":false}]}
{"op":"mcm","clk":"1362115020","pt":1588428389922,"mc":[{"id":"1.170370557","rc":[{"atb":[[1.6,177.3]],"id":9624350}],"con":true,"img":false}]}
{"op":"mcm","clk":"1362115023","pt":1588428390124,"mc":[{"id":"1.170370557","rc":[{"atb":[[1.6,265.95]],"id":9624350}],"con":true,"img":false}]}
{"op":"mcm","clk":"1362115026","pt":1588428390226,"mc":[{"id":"1.170370557","rc":[{"atb":[[1.45,2]],"id":9624350}],"con":true,"img":false}]}
{"op":"mcm","clk":"1362115029","pt":1588428390331,"mc":[{"id":"1.170370557","rc":[{"atb":[[1.6,354.6]],"id":9624350}],"con":true,"img":false}]}
{"op":"mcm","clk":"1362115032","pt":1588428390432,"mc":[{"id":"1.170370557","rc":[{"atb":[[1.45,10.52]],"id":9624350}],"con":true,"img":false}]}
{"op":"mcm","clk":"1362115042","pt":1588428390998,"mc":[{"id":"1.170370557","rc":[{"atb":[[1.6,0]],"id":9624350}],"con":true,"img":false}]}
{"op":"mcm","clk":"1362115048","pt":1588428391406,"mc":[{"id":"1.170370557","rc":[{"atb":[[1.59,20.37]],"id":9624350}],"con":true,"img":false}]}
{"op":"mcm","clk":"1362115053","pt":1588428391812,"mc":[{"id":"1.170370557","rc":[{"atb":[[1.4,237.93]],"id":9624350}],"con":true,"img":false}]}
{"op":"mcm","clk":"1362115057","pt":1588428392119,"mc":[{"id":"1.170370557","rc":[{"atl":[[2.06,443.26]],"id":9624350}],"con":true,"img":false}]}
{"op":"mcm","clk":"1362115066","pt":1588428392629,"mc":[{"id":"1.170370557","rc":[{"atb":[[2.5,7.2]],"id":9622734}],"con":true,"img":false}]}
{"op":"mcm","clk":"1362115069","pt":1588428392834,"mc":[{"id":"1.170370557","rc":[{"trd":[[1.64,1244.45]],"ltp":1.64,"tv":1244.45,"id":9624350},{"atl":[[1.64,2.53]],"id":9624350}],"con":true,"img":false}]}
{"op":"mcm","clk":"1362115079","pt":1588428393501,"mc":[{"id":"1.170370557","rc":[{"atb":[[1.6,221.63]],"id":9624350}],"con":true,"img":false}]}
{"op":"mcm","clk":"1362115086","pt":1588428393805,"mc":[{"id":"1.170370557","rc":[{"trd":[[1.6,967.46]],"ltp":1.6,"tv":967.46,"id":9624350},{"atb":[[1.6,221.34]],"id":9624350}],"con":true,"img":false}]}
{"op":"mcm","clk":"1362115093","pt":1588428394213,"mc":[{"id":"1.170370557","rc":[{"atb":[[1.6,0]],"id":9624350}],"con":true,"img":false}]}
{"op":"mcm","clk":"1362115095","pt":1588428394315,"mc":[{"id":"1.170370557","rc":[{"atl":[[1.64,3.46]],"id":9624350}],"con":true,"img":false}]}
{"op":"mcm","clk":"1362115106","pt":1588428394926,"mc":[{"id":"1.170370557","rc":[{"atb":[[1.4,355.14]],"id":9624350}],"con":true,"img":false}]}
{"op":"mcm","clk":"1362115140","pt":1588428397023,"mc":[{"id":"1.170370557","rc":[{"atb":[[1.49,88.65]],"id":9624350},{"atl":[[1.64,20.98]],"id":9624350}],"con":true,"img":false}]}
{"op":"mcm","clk":"1362115144","pt":1588428397224,"mc":[{"id":"1.170370557","rc":[{"atb":[[2.5,6.92]],"id":9622734},{"atb":[[1.49,177.3]],"id":9624350}],"con":true,"img":false}]}
{"op":"mcm","clk":"1362115149","pt":1588428397428,"mc":[{"id":"1.170370557","rc":[{"atb":[[1.49,265.95]],"id":9624350}],"con":true,"img":false}]}
{"op":"mcm","clk":"1362115151","pt":1588428397530,"mc":[{"id":"1.170370557","rc":[{"atb":[[1.59,0],[1.49,354.6]],"id":9624350}],"con":true,"img":false}]}
{"op":"mcm","clk":"1362115155","pt":1588428397734,"mc":[{"id":"1.170370557","rc":[{"atl":[[1.64,20.05]],"id":9624350}],"con":true,"img":false}]}
{"op":"mcm","clk":"1362115161","pt":1588428398143,"mc":[{"id":"1.170370557","rc":[{"atb":[[1.48,112]],"id":9624350}],"con":true,"img":false}]}
{"op":"mcm","clk":"1362115168","pt":1588428398450,"mc":[{"id":"1.170370557","rc":[{"atb":[[1.48,0]],"id":9624350}],"con":true,"img":false}]}
{"op":"mcm","clk":"1362115173","pt":1588428398705,"mc":[{"id":"1.170370557","rc":[{"atb":[[1.44,112],[1.49,0]],"id":9624350}],"con":true,"img":false}]}
{"op":"mcm","clk":"1362115180","pt":1588428399015,"mc":[{"id":"1.170370557","rc":[{"atb":[[1.44,0]],"id":9624350}],"con":true,"img":false}]}
{"op":"mcm","clk":"1362115193","pt":1588428399626,"mc":[{"id":"1.170370557","rc":[{"atl":[[1.64,2.53]],"id":9624350}],"con":true,"img":false}]}
{"op":"mcm","clk":"1362115198","pt":1588428399932,"mc":[{"id":"1.170370557","rc":[{"atb":[[1.4,117.2]],"id":9624350},{"atl":[[2.04,0]],"id":9624350}],"con":true,"img":false}]}
{"op":"mcm","clk":"1362115218","pt":1588428401211,"mc":[{"id":"1.170370557","rc":[{"atl":[[1.59,0.25]],"id":9624350}],"con":true,"img":false}]}
{"op":"mcm","clk":"1362115238","pt":1588428402125,"mc":[{"id":"1.170370557","rc":[{"atl":[[1.55,492.02]],"id":9624350}],"con":true,"img":false}]}
{"op":"mcm","clk":"1362115265","pt":1588428403813,"mc":[{"id":"1.170370557","rc":[{"atl":[[1.56,200]],"id":9624350}],"con":true,"img":false}]}
{"op":"mcm","clk":"1362115271","pt":1588428404120,"mc":[{"id":"1.170370557","rc":[{"atl":[[1.58,88.65]],"id":9624350}],"con":true,"img":false}]}
{"op":"mcm","clk":"1362115275","pt":1588428404324,"mc":[{"id":"1.170370557","rc":[{"atl":[[1.58,177.3]],"id":9624350}],"con":true,"img":false}]}
{"op":"mcm","clk":"1362115279","pt":1588428404426,"mc":[{"id":"1.170370557","rc":[{"atl":[[1.55,935.28]],"id":9624350}],"con":true,"img":false}]}
{"op":"mcm","clk":"1362115282","pt":1588428404528,"mc":[{"id":"1.170370557","rc":[{"atl":[[1.58,265.95]],"id":9624350}],"con":true,"img":false}]}
{"op":"mcm","clk":"1362115286","pt":1588428404732,"mc":[{"id":"1.170370557","rc":[{"atl":[[1.58,354.6],[1.57,112]],"id":9624350}],"con":true,"img":false}]}
{"op":"mcm","clk":"1362115292","pt":1588428405140,"mc":[{"id":"1.170370557","rc":[{"atl":[[1.62,112]],"id":9624350}],"con":true,"img":false}]}
{"op":"mcm","clk":"1362115296","pt":1588428405446,"mc":[{"id":"1.170370557","rc":[{"atl":[[1.67,0]],"id":9624350}],"con":true,"img":false}]}
{"op":"mcm","clk":"1362115297","pt":1588428405548,"mc":[{"id":"1.170370557","rc":[{"atl":[[1.53,221.63]],"id":9624350}],"con":true,"img":false}]}
{"op":"mcm","clk":"1362115301","pt":1588428405652,"mc":[{"id":"1.170370557","rc":[{"atl":[[1.57,0]],"id":9624350}],"con":true,"img":false}]}
{"op":"mcm","clk":"1362115305","pt":1588428405856,"mc":[{"id":"1.170370557","rc":[{"atb":[[1.31,695.17]],"id":9624350},{"atl":[[1.89,229.64]],"id":9624350}],"con":true,"img":false}]}
{"op":"mcm","clk":"1362115313","pt":1588428406316,"mc":[{"id":"1.170370557","rc":[{"atl":[[1.56,0],[1.58,0]],"id":9624350}],"con":true,"img":false}]}
{"op":"mcm","clk":"1362115327","pt":1588428407234,"mc":[{"id":"1.170370557","rc":[{"atb":[[1.4,0]],"id":9624350}],"con":true,"img":false}]}
{"op":"mcm","clk":"1362115332","pt":1588428407539,"mc":[{"id":"1.170370557","rc":[{"atb":[[1.46,22.18]],"id":9624350}],"con":true,"img":false}]}
{"op":"mcm","clk":"1362115337","pt":1588428407953,"mc":[{"id":"1.170370557","rc":[{"atl":[[1.55,443.26]],"id":9624350}],"con":true,"img":false}]}
{"op":"mcm","clk":"1362115340","pt":1588428408257,"mc":[{"id":"1.170370557","rc":[{"atl":[[1.54,88.65]],"id":9624350}],"con":true,"img":false}]}
{"op":"mcm","clk":"1362115343","pt":1588428408411,"mc":[{"id":"1.170370557","rc":[{"atl":[[1.54,177.3],[1.53,421.63],[1.52,112]],"id":9624350}],"con":true,"img":false}]}
{"op":"mcm","clk":"1362115347","pt":1588428408617,"mc":[{"id":"1.170370557","rc":[{"atl":[[1.54,265.95]],"id":9624350}],"con":true,"img":false}]}
{"op":"mcm","clk":"1362115350","pt":1588428408821,"mc":[{"id":"1.170370557","rc":[{"atl":[[1.54,354.6]],"id":9624350}],"con":true,"img":false}]}
{"op":"mcm","clk":"1362115354","pt":1588428409024,"mc":[{"id":"1.170370557","rc":[{"atl":[[1.54,466.6]],"id":9624350}],"con":true,"img":false}]}
{"op":"mcm","clk":"1362115356","pt":1588428409126,"mc":[{"id":"1.170370557","rc":[{"atl":[[1.52,333.63]],"id":9624350}],"con":true,"img":false}]}
{"op":"mcm","clk":"1362115368","pt":1588428410045,"mc":[{"id":"1.170370557","rc":[{"trd":[[3.05,57.34]],"ltp":3.05,"tv":57.34,"id":9622734},{"atl":[[3.05,0]],"id":9622734},{"trd":[[1.48,366.13]],"ltp":1.48,"tv":366.13,"id":9624350},{"atl":[[1.48,87.19]],"id":9624350}],"con":true,"img":false}]}
{"op":"mcm","clk":"1362115378","pt":1588428410862,"mc":[{"id":"1.170370557","rc":[{"atl":[[1.54,354.6]],"id":9624350}],"con":true,"img":false}]}
{"op":"mcm","clk":"1362115388","pt":1588428411322,"mc":[{"id":"1.170370557","rc":[{"atl":[[1.53,221.63]],"id":9624350}],"con":true,"img":false}]}
{"op":"mcm","clk":"1362115392","pt":1588428411526,"mc":[{"id":"1.170370557","rc":[{"atl":[[1.54,0]],"id":9624350}],"con":true,"img":false}]}
{"op":"mcm","clk":"1362115403","pt":1588428412037,"mc":[{"id":"1.170370557","rc":[{"atl":[[1.52,533.63]],"id":9624350}],"con":true,"img":false}]}
{"op":"mcm","clk":"1362115405","pt":1588428412140,"mc":[{"id":"1.170370557","rc":[{"atb":[[1.45,232.15]],"id":9624350}],"con":true,"img":false}]}
{"op":"mcm","clk":"1362115411","pt":1588428412344,"mc":[{"id":"1.170370557","rc":[{"trd":[[1.48,454.78]],"ltp":1.48,"tv":454.78,"id":9624350},{"atl":[[1.48,42.87]],"id":9624350}],"con":true,"img":false}]}
{"op":"mcm","clk":"1362115420","pt":1588428412957,"mc":[{"id":"1.170370557","rc":[{"atl":[[1.52,333.63]],"id":9624350}],"con":true,"img":false}]}
{"op":"mcm","clk":"1362115423","pt":1588428413163,"mc":[{"id":"1.170370557","rc":[{"atb":[[1.46,41.45]],"id":9624350}],"con":true,"img":false}]}
{"op":"mcm","clk":"1362115427","pt":1588428413366,"mc":[{"id":"1.170370557","rc":[{"atl":[[2.06,0]],"id":9624350}],"con":true,"img":false}]}
{"op":"mcm","clk":"1362115434","pt":1588428413828,"mc":[{"id":"1.170370557","rc":[{"atb":[[1.46,22.18]],"id":9624350}],"con":true,"img":false}]}
{"op":"mcm","clk":"1362115449","pt":1588428414543,"mc":[{"id":"1.170370557","rc":[{"trd":[[3.05,77.34]],"ltp":3.05,"tv":77.34,"id":9622734},{"trd":[[1.48,496]],"ltp":1.48,"tv":496.0,"id":9624350},{"atl":[[1.48,1.65]],"id":9624350}],"con":true,"img":false}]}
{"op":"mcm","clk":"1362115457","pt":1588428415155,"mc":[{"id":"1.170370557","rc":[{"atb":[[1.31,251.91]],"id":9624350}],"con":true,"img":false}]}
{"op":"mcm","clk":"1362115459","pt":1588428415259,"mc":[{"id":"1.170370557","rc":[{"atl":[[1.53,0]],"id":9624350}],"con":true,"img":false}]}
{"op":"mcm","clk":"1362115463","pt":1588428415566,"mc":[{"id":"1.170370557","rc":[{"atb":[[2.5,0]],"id":9622734}],"con":true,"img":false}]}
{"op":"mcm","clk":"1362115466","pt":1588428415770,"mc":[{"id":"1.170370557","rc":[{"atl":[[1.51,200]],"id":9624350}],"con":true,"img":false}]}
{"op":"mcm","clk":"1362115474","pt":1588428416237,"mc":[{"id":"1.170370557","rc":[{"trd":[[1.48,499.31]],"ltp":1.48,"tv":499.31,"id":9624350},{"atb":[[1.48,16.8]],"id":9624350},{"atl":[[1.48,0]],"id":9624350}],"con":true,"img":false}]}
{"op":"mcm","clk":"1362115476","pt":1588428416341,"mc":[{"id":"1.170370557","rc":[{"atl":[[1.74,443.26]],"id":9624350}],"con":true,"img":false}]}
{"op":"mcm","clk":"1362115481","pt":1588428416649,"mc":[{"id":"1.170370557","rc":[{"trd":[[1.51,546.73]],"ltp":1.51,"tv":546.73,"id":9624350},{"atl":[[1.51,520.25]],"id":9624350}],"con":true,"img":false}]}
{"op":"mcm","clk":"1362115489","pt":1588428417171,"mc":[{"id":"1.170370557","rc":[{"atl":[[1000,1.77]],"id":9622734}],"con":true,"img":false}]}
{"op":"mcm","clk":"1362115500","pt":1588428417925,"mc":[{"id":"1.170370557","rc":[{"atb":[[1.41,221.63]],"id":9624350}],"con":true,"img":false}]}
{"op":"mcm","clk":"1362115502","pt":1588428418029,"mc":[{"id":"1.170370557","rc":[{"atl":[[1.52,112]],"id":9624350}],"con":true,"img":false}]}
{"op":"mcm","clk":"1362115507","pt":1588428418233,"mc":[{"id":"1.170370557","rc":[{"atl":[[1000,1.56]],"id":9622734}],"con":true,"img":false}]}
{"op":"mcm","clk":"1362115516","pt":1588428418641,"mc":[{"id":"1.170370557","rc":[{"atl":[[1000,0]],"id":9622734}],"con":true,"img":false}]}
{"op":"mcm","clk":"1362115518","pt":1588428418844,"mc":[{"id":"1.170370557","rc":[{"atb":[[1.36,0]],"id":9624350}],"con":true,"img":false}]}
{"op":"mcm","clk":"1362115522","pt":1588428419151,"mc":[{"id":"1.170370557","rc":[{"atb":[[1.48,60.6]],"id":9624350}],"con":true,"img":false}]}
{"op":"mcm","clk":"1362115531","pt":1588428419563,"mc":[{"id":"1.170370557","rc":[{"atl":[[1.52,0]],"id":9624350}],"con":true,"img":false}]}
{"op":"mcm","clk":"1362115538","pt":1588428419971,"mc":[{"id":"1.170370557","rc":[{"atb":[[1.48,60.75]],"id":9624350}],"con":true,"img":false}]}
{"op":"mcm","clk":"1362115553","pt":1588428420944,"mc":[{"id":"1.170370557","rc":[{"atl":[[1.51,741.89]],"id":9624350}],"con":true,"img":false}]}
{"op":"mcm","clk":"1362115556","pt":1588428421046,"mc":[{"id":"1.170370557","rc":[{"atb":[[1.24,489.62]],"id":9624350}],"con":true,"img":false}]}
{"op":"mcm","clk":"1362115562","pt":1588428421459,"mc":[{"id":"1.170370557","rc":[{"atb":[[1.48,63.11]],"id":9624350}],"con":true,"img":false}]}
{"op":"mcm","clk":"1362115571","pt":1588428421769,"mc":[{"id":"1.170370557","rc":[{"atl":[[1.51,520.25]],"id":9624350}],"con":true,"img":false}]}
{"op":"mcm","clk":"1362115574","pt":1588428421871,"mc":[{"id":"1.170370557","rc":[{"atl":[[1.5,221.63]],"id":9624350}],"con":true,"img":false}]}
{"op":"mcm","clk":"1362115577","pt":1588428421974,"mc":[{"id":"1.170370557","rc":[{"trd":[[1.48,579.31]],"ltp":1.48,"tv":579.31,"id":9624350},{"atb":[[1.48,23.11]],"id":9624350}],"con":true,"img":false}]}
{"op":"mcm","clk":"1362115583","pt":1588428422282,"mc":[{"id":"1.170370557","rc":[{"atb":[[1.48,2.51]],"id":9624350}],"con":true,"img":false}]}
{"op":"mcm","clk":"1362115586","pt":1588428422355,"mc":[{"id":"1.170370557","rc":[{"atl":[[1.5,333.63]],"id":9624350}],"con":true,"img":false}]}
{"op":"mcm","clk":"1362115594","pt":1588428423058,"mc":[{"id":"1.170370557","rc":[{"atl":[[1.55,0]],"id":9624350}],"con":true,"img":false}]}
{"op":"mcm","clk":"1362115600","pt":1588428423368,"mc":[{"id":"1.170370557","rc":[{"atb":[[1.48,3.03]],"id":9624350}],"con":true,"img":false}]}
{"op":"mcm","clk":"1362115604","pt":1588428423573,"mc":[{"id":"1.170370557","rc":[{"atb":[[1.34,0.23]],"id":9624350}],"con":true,"img":false}]}
{"op":"mcm","clk":"1362115609","pt":1588428423777,"mc":[{"id":"1.170370557","rc":[{"trd":[[3,166.49]],"ltp":3.0,"tv":166.49,"id":9622734},{"trd":[[1.5,1115.18]],"ltp":1.5,"tv":1115.18,"id":9624350},{"atl":[[1.5,330.49]],"id":9624350}],"con":true,"img":false}]}
{"op":"mcm","clk":"1362115624","pt":1588428424959,"mc":[{"id":"1.170370557","rc":[{"atb":[[1.48,3.31]],"id":9624350}],"con":true,"img":false}]}
{"op":"mcm","clk":"1362115652","pt":1588428426246,"mc":[{"id":"1.170370557","rc":[{"atb":[[1.48,3.15]],"id":9624350}],"con":true,"img":false}]}
{"op":"mcm","clk":"1362115654","pt":1588428426350,"mc":[{"id":"1.170370557","rc":[{"atb":[[1.45,230.15]],"id":9624350}],"con":true,"img":false}]}
{"op":"mcm","clk":"1362115658","pt":1588428426658,"mc":[{"id":"1.170370557","rc":[{"atl":[[1.59,0]],"id":9624350}],"con":true,"img":false}]}
{"op":"mcm","clk":"1362115660","pt":1588428426760,"mc":[{"id":"1.170370557","rc":[{"trd":[[1.48,585.63]],"ltp":1.48,"tv":585.63,"id":9624350},{"atb":[[1.48,0]],"id":9624350},{"atl":[[1.48,21.84]],"id":9624350}],"con":true,"img":false}]}
{"op":"mcm","clk":"1362115665","pt":1588428427067,"mc":[{"id":"1.170370557","rc":[{"atl":[[1.62,0]],"id":9624350}],"con":true,"img":false}]}
{"op":"mcm","clk":"1362115682","pt":1588428428396,"mc":[{"id":"1.170370557","rc":[{"atb":[[1.45,8.52]],"id":9624350}],"con":true,"img":false}]}
{"op":"mcm","clk":"1362115696","pt":1588428429267,"mc":[{"id":"1.170370557","rc":[{"atl":[[1.48,36.84]],"id":9624350}],"con":true,"img":false}]}
{"op":"mcm","clk":"1362115698","pt":1588428429371,"mc":[{"id":"1.170370557","rc":[{"atb":[[1.46,0]],"id":9624350}],"con":true,"img":false}]}
{"op":"mcm","clk":"1362115703","pt":1588428429779,"mc":[{"id":"1.170370557","rc":[{"atl":[[1.58,112]],"id":9624350}],"con":true,"img":false}]}
{"op":"mcm","clk":"1362115714","pt":1588428430290,"mc":[{"id":"1.170370557","rc":[{"atb":[[1.45,0]],"id":9624350}],"con":true,"img":false}]}
{"op":"mcm","clk":"1362115726","pt":1588428431056,"mc":[{"id":"1.170370557","rc":[{"trd":[[1.48,586.55]],"ltp":1.48,"tv":586.55,"id":9624350},{"atl":[[1.48,36.38]],"id":9624350}],"con":true,"img":false}]}
{"op":"mcm","clk":"1362115735","pt":1588428431363,"mc":[{"id":"1.170370557","rc":[{"atl":[[1000,0.07]],"id":9624350}],"con":true,"img":false}]}
{"op":"mcm","clk":"1362115741","pt":1588428431671,"mc":[{"id":"1.170370557","rc":[{"atl":[[1.48,21.38]],"id":9624350}],"con":true,"img":false}]}
{"op":"mcm","clk":"1362115747","pt":1588428432079,"mc":[{"id":"1.170370557","rc":[{"atl":[[1.51,354.6]],"id":9624350}],"con":true,"img":false}]}
{"op":"mcm","clk":"1362115764","pt":1588428433562,"mc":[{"id":"1.170370557","rc":[{"atb":[[2.7,0.28]],"id":9622734}],"con":true,"img":false}]}
{"op":"mcm","clk":"1362115775","pt":1588428434073,"mc":[{"id":"1.170370557","rc":[{"atl":[[1.58,0],[1.5,218.49]],"id":9624350}],"con":true,"img":false}]}
{"op":"mcm","clk":"1362115796","pt":1588428435199,"mc":[{"id":"1.170370557","rc":[{"trd":[[1.41,2786.46]],"ltp":1.41,"tv":2786.46,"id":9624350},{"atb":[[1.41,211.63]],"id":9624350}],"con":true,"img":false}]}
{"op":"mcm","clk":"1362115810","pt":1588428435764,"mc":[{"id":"1.170370557","rc":[{"atb":[[1.4,23.13]],"id":9624350}],"con":true,"img":false}]}
{"op":"mcm","clk":"1362115820","pt":1588428436377,"mc":[{"id":"1.170370557","rc":[{"atb":[[1.41,0]],"id":9624350}],"con":true,"img":false}]}
{"op":"mcm","clk":"1362115824","pt":1588428436478,"mc":[{"id":"1.170370557","rc":[{"trd":[[1.5,1124.42],[1.48,629.31]],"ltp":1.5,"tv":1753.73,"id":9624350},{"atl":[[1.5,213.87],[1.48,0]],"id":9624350}],"con":true,"img":false}]}
{"op":"mcm","clk":"1362115835","pt":1588428437195,"mc":[{"id":"1.170370557","rc":[{"atl":[[1.51,0]],"id":9624350}],"con":true,"img":false}]}
{"op":"mcm","clk":"1362115849","pt":1588428438070,"mc":[{"id":"1.170370557","rc":[{"atl":[[1.5,0]],"id":9624350}],"con":true,"img":false}]}
{"op":"mcm","clk":"1362115864","pt":1588428438889,"mc":[{"id":"1.170370557","rc":[{"atb":[[1.31,0]],"id":9624350}],"con":true,"img":false}]}
{"op":"mcm","clk":"1362115918","pt":1588428441394,"mc":[{"id":"1.170370557","rc":[{"atb":[[1.54,255.95]],"id":9624350}],"con":true,"img":false}]}
{"op":"mcm","clk":"1362115922","pt":1588428441601,"mc":[{"id":"1.170370557","rc":[{"atb":[[1.5,200]],"id":9624350}],"con":true,"img":false}]}
{"op":"mcm","clk":"1362115927","pt":1588428441807,"mc":[{"id":"1.170370557","rc":[{"atl":[[1.58,112]],"id":9624350}],"con":true,"img":false}]}
{"op":"mcm","clk":"1362115928","pt":1588428441906,"mc":[{"id":"1.170370557","rc":[{"atb":[[1.5,400]],"id":9624350}],"con":true,"img":false}]}
{"op":"mcm","clk":"1362115934","pt":1588428442112,"mc":[{"id":"1.170370557","rc":[{"atl":[[1.58,0]],"id":9624350}],"con":true,"img":false}]}
{"op":"mcm","clk":"1362115939","pt":1588428442472,"mc":[{"id":"1.170370557","rc":[{"atb":[[1.5,488.65],[1.52,200]],"id":9624350}],"con":true,"img":false}]}
{"op":"mcm","clk":"1362115942","pt":1588428442680,"mc":[{"id":"1.170370557","rc":[{"atb":[[1.4,0],[1.5,577.3]],"id":9624350}],"con":true,"img":false}]}
{"op":"mcm","clk":"1362115944","pt":1588428442781,"mc":[{"id":"1.170370557","rc":[{"atb":[[1.51,88.65]],"id":9624350}],"con":true,"img":false}]}
{"op":"mcm","clk":"1362115946","pt":1588428442885,"mc":[{"id":"1.170370557","rc":[{"atb":[[1.52,643.26]],"id":9624350}],"con":true,"img":false}]}
{"op":"mcm","clk":"1362115948","pt":1588428442999,"mc":[{"id":"1.170370557","rc":[{"atb":[[1.51,289.3],[1.52,843.26]],"id":9624350}],"con":true,"img":false}]}
{"op":"mcm","clk":"1362115950","pt":1588428443100,"mc":[{"id":"1.170370557","rc":[{"atl":[[3.05,3.5]],"id":9622734}],"con":true,"img":false}]}
{"op":"mcm","clk":"1362115952","pt":1588428443193,"mc":[{"id":"1.170370557","rc":[{"atb":[[1.47,112]],"id":9624350}],"con":true,"img":false}]}
{"op":"mcm","clk":"1362115957","pt":1588428443394,"mc":[{"id":"1.170370557","rc":[{"trd":[[1.54,4990.86]],"ltp":1.54,"tv":4990.86,"id":9624350},{"atb":[[1.45,112],[1.54,255.26]],"id":9624350}],"con":true,"img":false}]}
{"op":"mcm","clk":"1362115960","pt":1588428443600,"mc":[{"id":"1.170370557","rc":[{"atb":[[1.52,443.26],[1.5,177.3]],"id":9624350}],"con":true,"img":false}]}
{"op":"mcm","clk":"1362115962","pt":1588428443701,"mc":[{"id":"1.170370557","rc":[{"trd":[[1.54,4996.01]],"ltp":1.54,"tv":4996.01,"id":9624350},{"atb":[[1.54,252.68]],"id":9624350}],"con":true,"img":false}]}
{"op":"mcm","clk":"1362115965","pt":1588428443804,"mc":[{"id":"1.170370557","rc":[{"trd":[[1.54,5001.16]],"ltp":1.54,"tv":5001.16,"id":9624350},{"atb":[[1.54,250.11]],"id":9624350}],"con":true,"img":false}]}
{"op":"mcm","clk":"1362115970","pt":1588428444008,"mc":[{"id":"1.170370557","rc":[{"atl":[[1000,1.45]],"id":9622734},{"atb":[[1.38,2]],"id":9624350}],"con":true,"img":false}]}
{"op":"mcm","clk":"1362115983","pt":1588428444467,"mc":[{"id":"1.170370557","rc":[{"atb":[[1.54,471.74]],"id":9624350}],"con":true,"img":false}]}
{"op":"mcm","clk":"1362115989","pt":1588428444877,"mc":[{"id":"1.170370557","rc":[{"atb":[[1.38,238.58]],"id":9624350}],"con":true,"img":false}]}
{"op":"mcm","clk":"1362116003","pt":1588428445694,"mc":[{"id":"1.170370557","rc":[{"atb":[[1.54,250.11]],"id":9624350}],"con":true,"img":false}]}
{"op":"mcm","clk":"1362116005","pt":1588428445797,"mc":[{"id":"1.170370557","rc":[{"atl":[[3.05,0]],"id":9622734}],"con":true,"img":false}]}
{"op":"mcm","clk":"1362116012","pt":1588428446006,"mc":[{"id":"1.170370557","rc":[{"trd":[[2.7,1.13]],"ltp":2.7,"tv":1.13,"id":9622734},{"atb":[[2.7,0]],"id":9622734},{"atl":[[2.66,1030.85]],"id":9622734}],"con":true,"img":false}]}
{"op":"mcm","clk":"1362116020","pt":1588428446407,"mc":[{"id":"1.170370557","rc":[{"atb":[[1.62,61.48]],"id":9624350}],"con":true,"img":false}]}
{"op":"mcm","clk":"1362116025","pt":1588428446714,"mc":[{"id":"1.170370557","rc":[{"atb":[[1.62,0]],"id":9624350}],"con":true,"img":false}]}
{"op":"mcm","clk":"1362116037","pt":1588428447586,"mc":[{"id":"1.170370557","rc":[{"atb":[[1.55,221.63]],"id":9624350}],"con":true,"img":false}]}
{"op":"mcm","clk":"1362116045","pt":1588428448099,"mc":[{"id":"1.170370557","rc":[{"atb":[[1.45,0],[1.51,177.3],[1.47,0]],"id":9624350}],"con":true,"img":false}]}
{"op":"mcm","clk":"1362116049","pt":1588428448406,"mc":[{"id":"1.170370557","rc":[{"atb":[[1.44,0.23]],"id":9624350}],"con":true,"img":false}]}
{"op":"mcm","clk":"1362116052","pt":1588428448609,"mc":[{"id":"1.170370557","rc":[{"atb":[[1.5,0]],"id":9624350}],"con":true,"img":false}]}
{"op":"mcm","clk":"1362116054","pt":1588428448710,"mc":[{"id":"1.170370557","rc":[{"atl":[[1.71,112]],"id":9624350}],"con":true,"img":false}]}
{"op":"mcm","clk":"1362116056","pt":1588428448812,"mc":[{"id":"1.170370557","rc":[{"atb":[[1.54,0]],"id":9624350},{"atl":[[1.62,157.67]],"id":9624350}],"con":true,"img":false}]}
{"op":"mcm","clk":"1362116060","pt":1588428449118,"mc":[{"id":"1.170370557","rc":[{"atb":[[1.51,0]],"id":9624350}],"con":true,"img":false}]}
{"op":"mcm","clk":"1362116065","pt":1588428449322,"mc":[{"id":"1.170370557","rc":[{"atl":[[1.62,0]],"id":9624350}],"con":true,"img":false}]}
{"op":"mcm","clk":"1362116075","pt":1588428449888,"mc":[{"id":"1.170370557","rc":[{"atb":[[1.55,242.53]],"id":9624350}],"con":true,"img":false}]}
{"op":"mcm","clk":"1362116081","pt":1588428450298,"mc":[{"id":"1.170370557","rc":[{"trd":[[2.66,61.45]],"ltp":2.66,"tv":61.45,"id":9622734},{"atl":[[2.66,1029.43]],"id":9622734},{"trd":[[1.6,969.81]],"ltp":1.6,"tv":969.81,"id":9624350}],"con":true,"img":false}]}
{"op":"mcm","clk":"1362116092","pt":1588428451118,"mc":[{"id":"1.170370557","rc":[{"atl":[[2.66,0]],"id":9622734}],"con":true,"img":false}]}
{"op":"mcm","clk":"1362116095","pt":1588428451221,"mc":[{"id":"1.170370557","rc":[{"atb":[[1.52,0]],"id":9624350}],"con":true,"img":false}]}
{"op":"mcm","clk":"1362116101","pt":1588428451627,"mc":[{"id":"1.170370557","rc":[{"atl":[[1000,0]],"id":9624350}],"con":true,"img":false}]}
{"op":"mcm","clk":"1362116120","pt":1588428452703,"mc":[{"id":"1.170370557","rc":[{"atb":[[1.56,68.06],[1.24,46.36]],"id":9624350},{"atl":[[1.74,0]],"id":9624350}],"con":true,"img":false}]}
{"op":"mcm","clk":"1362116122","pt":1588428452808,"mc":[{"id":"1.170370557","rc":[{"atb":[[2.66,50.87]],"id":9622734}],"con":true,"img":false}]}
{"op":"mcm","clk":"1362116130","pt":1588428453214,"mc":[{"id":"1.170370557","rc":[{"atb":[[1.56,0]],"id":9624350}],"con":true,"img":false}]}
{"op":"mcm","clk":"1362116136","pt":1588428453520,"mc":[{"id":"1.170370557","rc":[{"trd":[[1.55,1909.19]],"ltp":1.55,"tv":1909.19,"id":9624350},{"atb":[[1.55,203.5]],"id":9624350}],"con":true,"img":false}]}
{"op":"mcm","clk":"1362116163","pt":1588428455207,"mc":[{"id":"1.170370557","rc":[{"atl":[[1.67,152.95]],"id":9624350}],"con":true,"img":false}]}
{"op":"mcm","clk":"1362116166","pt":1588428455309,"mc":[{"id":"1.170370557","rc":[{"trd":[[2.66,72.18]],"ltp":2.66,"tv":72.18,"id":9622734},{"atb":[[2.66,40.14]],"id":9622734},{"trd":[[1.61,431.36]],"ltp":1.61,"tv":431.36,"id":9624350}],"con":true,"img":false}]}
{"op":"mcm","clk":"1362116173","pt":1588428455932,"mc":[{"id":"1.170370557","rc":[{"trd":[[2.66,72.27]],"ltp":2.66,"tv":72.27,"id":9622734},{"atb":[[2.66,40.05]],"id":9622734},{"trd":[[1.61,431.51]],"ltp":1.61,"tv":431.51,"id":9624350}],"con":true,"img":false}]}
{"op":"mcm","clk":"1362116189","pt":1588428457103,"mc":[{"id":"1.170370557","rc":[{"atl":[[1.62,2.12]],"id":9624350}],"con":true,"img":false}]}
{"op":"mcm","clk":"1362116193","pt":1588428457308,"mc":[{"id":"1.170370557","rc":[{"atl":[[1000,2.47]],"id":9622734}],"con":true,"img":false}]}
{"op":"mcm","clk":"1362116218","pt":1588428459098,"mc":[{"id":"1.170370557","rc":[{"atb":[[1.38,236.58]],"id":9624350}],"con":true,"img":false}]}
{"op":"mcm","clk":"1362116226","pt":1588428459713,"mc":[{"id":"1.170370557","rc":[{"atb":[[1.34,443.49]],"id":9624350}],"con":true,"img":false}]}
{"op":"mcm","clk":"1362116230","pt":1588428460023,"mc":[{"id":"1.170370557","rc":[{"atb":[[1.49,221.63],[1.38,0]],"id":9624350},{"atl":[[1.89,0]],"id":9624350}],"con":true,"img":false}]}
{"op":"mcm","clk":"1362116239","pt":1588428460889,"mc":[{"id":"1.170370557","rc":[{"atl":[[1.6,0.86]],"id":9624350}],"con":true,"img":false}]}
{"op":"mcm","clk":"1362116269","pt":1588428462120,"mc":[{"id":"1.170370557","rc":[{"trd":[[1.55,1920.89]],"ltp":1.55,"tv":1920.89,"id":9624350},{"atb":[[1.55,197.65]],"id":9624350}],"con":true,"img":false}]}
{"op":"mcm","clk":"1362116287","pt":1588428462834,"mc":[{"id":"1.170370557","rc":[{"atl":[[1.6,2.04]],"id":9624350}],"con":true,"img":false}]}
{"op":"mcm","clk":"1362116292","pt":1588428463037,"mc":[{"id":"1.170370557","rc":[{"atb":[[1.56,17.41]],"id":9624350}],"con":true,"img":false}]}
{"op":"mcm","clk":"1362116311","pt":1588428464218,"mc":[{"id":"1.170370557","rc":[{"atb":[[1.39,2]],"id":9624350}],"con":true,"img":false}]}
{"op":"mcm","clk":"1362116316","pt":1588428464524,"mc":[{"id":"1.170370557","rc":[{"atb":[[1.4,200]],"id":9624350}],"con":true,"img":false}]}
{"op":"mcm","clk":"1362116323","pt":1588428464936,"mc":[{"id":"1.170370557","rc":[{"atb":[[1.4,400]],"id":9624350}],"con":true,"img":false}]}
{"op":"mcm","clk":"1362116326","pt":1588428465036,"mc":[{"id":"1.170370557","rc":[{"atl":[[1.6,1.17]],"id":9624350}],"con":true,"img":false}]}
{"op":"mcm","clk":"1362116335","pt":1588428465704,"mc":[{"id":"1.170370557","rc":[{"atl":[[1.6,0.75]],"id":9624350}],"con":true,"img":false}]}
{"op":"mcm","clk":"1362116347","pt":1588428466418,"mc":[{"id":"1.170370557","rc":[{"trd":[[2.66,73.17]],"ltp":2.66,"tv":73.17,"id":9622734},{"atb":[[2.66,39.6]],"id":9622734}],"con":true,"img":false}]}
{"op":"mcm","clk":"1362116357","pt":1588428467036,"mc":[{"id":"1.170370557","rc":[{"trd":[[1.56,1704.45]],"ltp":1.56,"tv":1704.45,"id":9624350},{"atb":[[1.56,12.66]],"id":9624350}],"con":true,"img":false}]}
{"op":"mcm","clk":"1362116362","pt":1588428467395,"mc":[{"id":"1.170370557","rc":[{"atl":[[1.6,0]],"id":9624350}],"con":true,"img":false}]}
{"op":"mcm","clk":"1362116368","pt":1588428467904,"mc":[{"id":"1.170370557","rc":[{"atb":[[1.44,0]],"id":9624350}],"con":true,"img":false}]}
{"op":"mcm","clk":"1362116386","pt":1588428469440,"mc":[{"id":"1.170370557","rc":[{"atl":[[1.96,443.26]],"id":9624350}],"con":true,"img":false}]}
{"op":"mcm","clk":"1362116390","pt":1588428469699,"mc":[{"id":"1.170370557","rc":[{"atb":[[1.4,0]],"id":9624350},{"atl":[[1.67,0]],"id":9624350}],"con":true,"img":false}]}
{"op":"mcm","clk":"1362116439","pt":1588428473131,"mc":[{"id":"1.170370557","rc":[{"atl":[[1.6,221.63]],"id":9624350}],"con":true,"img":false}]}
{"op":"mcm","clk":"1362116456","pt":1588428474408,"mc":[{"id":"1.170370557","rc":[{"trd":[[1.56,1710.25]],"ltp":1.56,"tv":1710.25,"id":9624350},{"atb":[[1.56,9.76]],"id":9624350}],"con":true,"img":false}]}
{"op":"mcm","clk":"1362116458","pt":1588428474609,"mc":[{"id":"1.170370557","rc":[{"atl":[[1.62,0]],"id":9624350}],"con":true,"img":false}]}
{"op":"mcm","clk":"1362116461","pt":1588428474813,"mc":[{"id":"1.170370557","rc":[{"atl":[[1.6,381.27]],"id":9624350}],"con":true,"img":false}]}
{"op":"mcm","clk":"1362116464","pt":1588428475020,"mc":[{"id":"1.170370557","rc":[{"atb":[[1.48,2.35]],"id":9624350}],"con":true,"img":false}]}
{"op":"mcm","clk":"1362116479","pt":1588428476199,"mc":[{"id":"1.170370557","rc":[{"atl":[[1.6,159.64],[1.71,0]],"id":9624350}],"con":true,"img":false}]}
{"op":"mcm","clk":"1362116497","pt":1588428477634,"mc":[{"id":"1.170370557","rc":[{"atb":[[1.57,0.34]],"id":9624350}],"con":true,"img":false}]}
{"op":"mcm","clk":"1362116509","pt":1588428478146,"mc":[{"id":"1.170370557","rc":[{"atl":[[1.59,5]],"id":9624350}],"con":true,"img":false}]}
{"op":"mcm","clk":"1362116525","pt":1588428478610,"mc":[{"id":"1.170370557","rc":[{"atl":[[1.96,0]],"id":9624350}],"con":true,"img":false}]}
{"op":"mcm","clk":"1362116581","pt":1588428482251,"mc":[{"id":"1.170370557","rc":[{"trd":[[1.56,1711.29]],"ltp":1.56,"tv":1711.29,"id":9624350},{"atb":[[1.56,9.24],[1.57,0]],"id":9624350}],"con":true,"img":false}]}
{"op":"mcm","clk":"1362116598","pt":1588428483737,"mc":[{"id":"1.170370557","rc":[{"atl":[[2.14,443.26]],"id":9624350}],"con":true,"img":false}]}
{"op":"mcm","clk":"1362116617","pt":1588428485130,"mc":[{"id":"1.170370557","rc":[{"trd":[[1.56,1724.04]],"ltp":1.56,"tv":1724.04,"id":9624350},{"atb":[[1.56,2.87]],"id":9624350}],"con":true,"img":false}]}
{"op":"mcm","clk":"1362116622","pt":1588428485645,"mc":[{"id":"1.170370557","rc":[{"atb":[[1.39,0]],"id":9624350}],"con":true,"img":false}]}
{"op":"mcm","clk":"1362116624","pt":1588428485749,"mc":[{"id":"1.170370557","rc":[{"trd":[[1.56,1729.79]],"ltp":1.56,"tv":1729.79,"id":9624350},{"atb":[[1.56,0],[1.55,20.9]],"id":9624350},{"atl":[[1.56,168.22]],"id":9624350}],"con":true,"img":false}]}
{"op":"mcm","clk":"1362116626","pt":1588428485850,"mc":[{"id":"1.170370557","rc":[{"atb":[[1.55,0]],"id":9624350}],"con":true,"img":false}]}
{"op":"mcm","clk":"1362116636","pt":1588428486523,"mc":[{"id":"1.170370557","rc":[{"atb":[[1.49,0]],"id":9624350}],"con":true,"img":false}]}
{"op":"mcm","clk":"1362116648","pt":1588428487244,"mc":[{"id":"1.170370557","rc":[{"atl":[[1.55,5]],"id":9624350}],"con":true,"img":false}]}
{"op":"mcm","clk":"1362116662","pt":1588428488267,"mc":[{"id":"1.170370557","rc":[{"trd":[[1.55,1923.25]],"ltp":1.55,"tv":1923.25,"id":9624350},{"atb":[[1.34,0.23]],"id":9624350},{"atl":[[1.55,3.82],[2.14,0]],"id":9624350}],"con":true,"img":false}]}
{"op":"mcm","clk":"1362116678","pt":1588428489649,"mc":[{"id":"1.170370557","rc":[{"atl":[[1.55,0]],"id":9624350}],"con":true,"img":false}]}
{"op":"mcm","clk":"1362116680","pt":1588428489753,"mc":[{"id":"1.170370557","rc":[{"atb":[[2.5,6.92]],"id":9622734}],"con":true,"img":false}]}
{"op":"mcm","clk":"1362116694","pt":1588428490469,"mc":[{"id":"1.170370557","rc":[{"atl":[[1.52,492.02]],"id":9624350}],"con":true,"img":false}]}
{"op":"mcm","clk":"1362116697","pt":1588428490572,"mc":[{"id":"1.170370557","rc":[{"trd":[[1.48,634.03]],"ltp":1.48,"tv":634.03,"id":9624350},{"atb":[[1.48,0]],"id":9624350},{"atl":[[1.48,552.64]],"id":9624350}],"con":true,"img":false}]}
{"op":"mcm","clk":"1362116701","pt":1588428490729,"mc":[{"id":"1.170370557","rc":[{"trd":[[1.48,638.03]],"ltp":1.48,"tv":638.03,"id":9624350},{"atl":[[1.48,550.64]],"id":9624350}],"con":true,"img":false}]}
{"op":"mcm","clk":"1362116704","pt":1588428490933,"mc":[{"id":"1.170370557","rc":[{"atb":[[1.38,236.58]],"id":9624350},{"atl":[[2.04,202.06]],"id":9624350}],"con":true,"img":false}]}
{"op":"mcm","clk":"1362116711","pt":1588428491447,"mc":[{"id":"1.170370557","rc":[{"atl":[[1.46,279.95]],"id":9624350}],"con":true,"img":false}]}
{"op":"mcm","clk":"1362116714","pt":1588428491649,"mc":[{"id":"1.170370557","rc":[{"atl":[[1.6,0]],"id":9624350}],"con":true,"img":false}]}
{"op":"mcm","clk":"1362116718","pt":1588428491855,"mc":[{"id":"1.170370557","rc":[{"atl":[[1.57,112]],"id":9624350}],"con":true,"img":false}]}
{"op":"mcm","clk":"1362116721","pt":1588428492060,"mc":[{"id":"1.170370557","rc":[{"atb":[[1.38,0]],"id":9624350},{"atl":[[2.04,0],[1.52,604.02]],"id":9624350}],"con":true,"img":false}]}
{"op":"mcm","clk":"1362116723","pt":1588428492162,"mc":[{"id":"1.170370557","rc":[{"atb":[[2.5,0]],"id":9622734},{"atl":[[1.53,200]],"id":9624350}],"con":true,"img":false}]}
{"op":"mcm","clk":"1362116728","pt":1588428492468,"mc":[{"id":"1.170370557","rc":[{"atl":[[1.53,400]],"id":9624350}],"con":true,"img":false}]}
{"op":"mcm","clk":"1362116731","pt":1588428492571,"mc":[{"id":"1.170370557","rc":[{"trd":[[3.15,38]],"ltp":3.15,"tv":38.0,"id":9622734},{"trd":[[1.46,1145.07]],"ltp":1.46,"tv":1145.07,"id":9624350},{"atl":[[1.46,206.59],[1.5,112]],"id":9624350}],"con":true,"img":false}]}
{"op":"mcm","clk":"1362116738","pt":1588428493131,"mc":[{"id":"1.170370557","rc":[{"atb":[[1.26,279.95]],"id":9624350}],"con":true,"img":false}]}
{"op":"mcm","clk":"1362116741","pt":1588428493333,"mc":[{"id":"1.170370557","rc":[{"atl":[[1.48,0]],"id":9624350}],"con":true,"img":false}]}
{"op":"mcm","clk":"1362116743","pt":1588428493436,"mc":[{"id":"1.170370557","rc":[{"trd":[[1.46,1169.59]],"ltp":1.46,"tv":1169.59,"id":9624350},{"atl":[[1.41,88.65],[1.46,194.33]],"id":9624350}],"con":true,"img":false}]}
{"op":"mcm","clk":"1362116747","pt":1588428493642,"mc":[{"id":"1.170370557","rc":[{"atl":[[1.41,177.3]],"id":9624350}],"con":true,"img":false}]}
{"op":"mcm","clk":"1362116749","pt":1588428493845,"mc":[{"id":"1.170370557","rc":[{"atl":[[1.41,265.95]],"id":9624350}],"con":true,"img":false}]}
{"op":"mcm","clk":"1362116754","pt":1588428494052,"mc":[{"id":"1.170370557","rc":[{"atl":[[1.41,354.6]],"id":9624350}],"con":true,"img":false}]}
{"op":"mcm","clk":"1362116760","pt":1588428494359,"mc":[{"id":"1.170370557","rc":[{"atl":[[1.47,221.63]],"id":9624350}],"con":true,"img":false}]}
{"op":"mcm","clk":"1362116767","pt":1588428494666,"mc":[{"id":"1.170370557","rc":[{"atl":[[1.47,421.63]],"id":9624350}],"con":true,"img":false}]}
{"op":"mcm","clk":"1362116768","pt":1588428494768,"mc":[{"id":"1.170370557","rc":[{"atb":[[1.38,23.47]],"id":9624350}],"con":true,"img":false}]}
{"op":"mcm","clk":"1362116779","pt":1588428495538,"mc":[{"id":"1.170370557","rc":[{"atb":[[2.8,0.23]],"id":9622734}],"con":true,"img":false}]}
{"op":"mcm","clk":"1362116788","pt":1588428496256,"mc":[{"id":"1.170370557","rc":[{"atl":[[1.52,112]],"id":9624350}],"con":true,"img":false}]}
{"op":"mcm","clk":"1362116792","pt":1588428496465,"mc":[{"id":"1.170370557","rc":[{"atl":[[1.41,0]],"id":9624350}],"con":true,"img":false}]}
{"op":"mcm","clk":"1362116795","pt":1588428496569,"mc":[{"id":"1.170370557","rc":[{"atl":[[1.47,221.63]],"id":9624350}],"con":true,"img":false}]}
{"op":"mcm","clk":"1362116800","pt":1588428496872,"mc":[{"id":"1.170370557","rc":[{"atl":[[1.45,200]],"id":9624350}],"con":true,"img":false}]}
{"op":"mcm","clk":"1362116803","pt":1588428496976,"mc":[{"id":"1.170370557","rc":[{"atl":[[1.46,0]],"id":9624350}],"con":true,"img":false}]}
{"op":"mcm","clk":"1362116804","pt":1588428497076,"mc":[{"id":"1.170370557","rc":[{"atl":[[1.45,312]],"id":9624350}],"con":true,"img":false}]}
{"op":"mcm","clk":"1362116807","pt":1588428497232,"mc":[{"id":"1.170370557","rc":[{"atl":[[1.46,221.63]],"id":9624350}],"con":true,"img":false}]}
{"op":"mcm","clk":"1362116811","pt":1588428497538,"mc":[{"id":"1.170370557","rc":[{"atb":[[1.42,88.65]],"id":9624350}],"con":true,"img":false}]}
{"op":"mcm","clk":"1362116813","pt":1588428497640,"mc":[{"id":"1.170370557","rc":[{"atl":[[1.44,200]],"id":9624350}],"con":true,"img":false}]}
{"op":"mcm","clk":"1362116815","pt":1588428497743,"mc":[{"id":"1.170370557","rc":[{"atl":[[1.44,288.65],[1.45,533.63]],"id":9624350}],"con":true,"img":false}]}
{"op":"mcm","clk":"1362116820","pt":1588428497954,"mc":[{"id":"1.170370557","rc":[{"atl":[[1.44,489.3]],"id":9624350}],"con":true,"img":false}]}
{"op":"mcm","clk":"1362116827","pt":1588428498154,"mc":[{"id":"1.170370557","rc":[{"trd":[[1.42,1162.63]],"ltp":1.42,"tv":1162.63,"id":9624350},{"atb":[[1.42,0]],"id":9624350},{"atl":[[1.44,577.95],[1.41,354.6]],"id":9624350}],"con":true,"img":false}]}
{"op":"mcm","clk":"1362116832","pt":1588428498361,"mc":[{"id":"1.170370557","rc":[{"atl":[[1.44,666.6]],"id":9624350}],"con":true,"img":false}]}
{"op":"mcm","clk":"1362116840","pt":1588428498873,"mc":[{"id":"1.170370557","rc":[{"atl":[[1.41,0],[1.47,0]],"id":9624350}],"con":true,"img":false}]}
{"op":"mcm","clk":"1362116845","pt":1588428499233,"mc":[{"id":"1.170370557","rc":[{"atl":[[1.56,0]],"id":9624350}],"con":true,"img":false}]}
{"op":"mcm","clk":"1362116860","pt":1588428500157,"mc":[{"id":"1.170370557","rc":[{"atb":[[1.29,443.26]],"id":9624350}],"con":true,"img":false}]}
{"op":"mcm","clk":"1362116867","pt":1588428500466,"mc":[{"id":"1.170370557","rc":[{"atb":[[1.39,89.96]],"id":9624350}],"con":true,"img":false}]}
{"op":"mcm","clk":"1362116872","pt":1588428500672,"mc":[{"id":"1.170370557","rc":[{"atb":[[1.35,221.63]],"id":9624350},{"atl":[[1.45,421.63]],"id":9624350}],"con":true,"img":false}]}
{"op":"mcm","clk":"1362116874","pt":1588428500775,"mc":[{"id":"1.170370557","rc":[{"atl":[[1.45,221.63]],"id":9624350}],"con":true,"img":false}]}
{"op":"mcm","clk":"1362116877","pt":1588428500879,"mc":[{"id":"1.170370557","rc":[{"atl":[[1.46,0]],"id":9624350}],"con":true,"img":false}]}
{"op":"mcm","clk":"1362116881","pt":1588428501033,"mc":[{"id":"1.170370557","rc":[{"atb":[[1.3,112]],"id":9624350}],"con":true,"img":false}]}
{"op":"mcm","clk":"1362116885","pt":1588428501236,"mc":[{"id":"1.170370557","rc":[{"atb":[[1.27,112]],"id":9624350}],"con":true,"img":false}]}
{"op":"mcm","clk":"1362116890","pt":1588428501441,"mc":[{"id":"1.170370557","rc":[{"atl":[[1.44,554.6]],"id":9624350}],"con":true,"img":false}]}
{"op":"mcm","clk":"1362116896","pt":1588428501747,"mc":[{"id":"1.170370557","rc":[{"atb":[[1.29,555.26]],"id":9624350}],"con":true,"img":false}]}
{"op":"mcm","clk":"1362116909","pt":1588428502568,"mc":[{"id":"1.170370557","rc":[{"atb":[[1.26,0]],"id":9624350}],"con":true,"img":false}]}
{"op":"mcm","clk":"1362116912","pt":1588428502771,"mc":[{"id":"1.170370557","rc":[{"atl":[[1.44,643.26]],"id":9624350}],"con":true,"img":false}]}
{"op":"mcm","clk":"1362116916","pt":1588428502976,"mc":[{"id":"1.170370557","rc":[{"atl":[[1.44,731.91]],"id":9624350}],"con":true,"img":false}]}
{"op":"mcm","clk":"1362116920","pt":1588428503180,"mc":[{"id":"1.170370557","rc":[{"atl":[[1.44,820.56]],"id":9624350}],"con":true,"img":false}]}
{"op":"mcm","clk":"1362116924","pt":1588428503335,"mc":[{"id":"1.170370557","rc":[{"atl":[[1.45,0]],"id":9624350}],"con":true,"img":false}]}
{"op":"mcm","clk":"1362116936","pt":1588428504049,"mc":[{"id":"1.170370557","rc":[{"atb":[[1.3,116.97]],"id":9624350}],"con":true,"img":false}]}
{"op":"mcm","clk":"1362116943","pt":1588428504356,"mc":[{"id":"1.170370557","rc":[{"atl":[[1.44,1263.82]],"id":9624350}],"con":true,"img":false}]}
{"op":"mcm","clk":"1362116947","pt":1588428504669,"mc":[{"id":"1.170370557","rc":[{"atl":[[1.43,221.63]],"id":9624350}],"con":true,"img":false}]}
{"op":"mcm","clk":"1362116956","pt":1588428505436,"mc":[{"id":"1.170370557","rc":[{"atb":[[1.3,112]],"id":9624350}],"con":true,"img":false}]}
{"op":"mcm","clk":"1362116959","pt":1588428505642,"mc":[{"id":"1.170370557","rc":[{"atl":[[1.69,443.26]],"id":9624350}],"con":true,"img":false}]}
{"op":"mcm","clk":"1362116970","pt":1588428506465,"mc":[{"id":"1.170370557","rc":[{"atl":[[1.44,1175.17]],"id":9624350}],"con":true,"img":false}]}
{"op":"mcm","clk":"1362116976","pt":1588428506977,"mc":[{"id":"1.170370557","rc":[{"atl":[[1.44,1086.52]],"id":9624350}],"con":true,"img":false}]}
{"op":"mcm","clk":"1362116980","pt":1588428507239,"mc":[{"id":"1.170370557","rc":[{"atl":[[3.4,0.18]],"id":9622734}],"con":true,"img":false}]}
{"op":"mcm","clk":"1362116987","pt":1588428507753,"mc":[{"id":"1.170370557","rc":[{"atl":[[1.44,997.87]],"id":9624350}],"con":true,"img":false}]}
{"op":"mcm","clk":"1362116995","pt":1588428508165,"mc":[{"id":"1.170370557","rc":[{"atl":[[1.6,2.35]],"id":9624350}],"con":true,"img":false}]}
{"op":"mcm","clk":"1362116998","pt":1588428508268,"mc":[{"id":"1.170370557","rc":[{"atl":[[1.44,909.21]],"id":9624350}],"con":true,"img":false}]}
{"op":"mcm","clk":"1362117011","pt":1588428508853,"mc":[{"id":"1.170370557","rc":[{"atb":[[1.29,112]],"id":9624350},{"atl":[[1.48,221.63]],"id":9624350}],"con":true,"img":false}]}
{"op":"mcm","clk":"1362117059","pt":1588428509263,"mc":[{"id":"1.170370557","rc":[{"trd":[[1.43,3215.39]],"ltp":1.43,"tv":3215.39,"id":9624350},{"atl":[[1.43,218.12]],"id":9624350}],"con":true,"img":false}]}
{"op":"mcm","clk":"1362117068","pt":1588428509777,"mc":[{"id":"1.170370557","rc":[{"trd":[[3.4,6]],"ltp":3.4,"tv":6.0,"id":9622734},{"atl":[[3.4,0]],"id":9622734},{"trd":[[1.39,1185.58],[1.41,2786.91]],"ltp":1.39,"tv":3972.49,"id":9624350},{"atb":[[1.39,89.23]],"id":9624350}],"con":true,"img":false}]}
{"op":"mcm","clk":"1362117071","pt":1588428509879,"mc":[{"id":"1.170370557","rc":[{"trd":[[1.39,1186.01]],"ltp":1.39,"tv":1186.01,"id":9624350},{"atb":[[1.39,89.01]],"id":9624350}],"con":true,"img":false}]}
{"op":"mcm","clk":"1362117073","pt":1588428509981,"mc":[{"id":"1.170370557","rc":[{"atb":[[1.41,2.62]],"id":9624350}],"con":true,"img":false}]}
{"op":"mcm","clk":"1362117083","pt":1588428510644,"mc":[{"id":"1.170370557","rc":[{"atb":[[1.32,4.89]],"id":9624350}],"con":true,"img":false}]}
{"op":"mcm","clk":"1362117085","pt":1588428510747,"mc":[{"id":"1.170370557","rc":[{"trd":[[1.41,2787.6]],"ltp":1.41,"tv":2787.6,"id":9624350},{"atb":[[1.41,2.28]],"id":9624350}],"con":true,"img":false}]}
{"op":"mcm","clk":"1362117086","pt":1588428511054,"mc":[{"id":"1.170370557","rc":[{"atb":[[2.8,0]],"id":9622734}],"con":true,"img":false}]}
{"op":"mcm","clk":"1362117090","pt":1588428513149,"mc":[{"id":"1.170370557","rc":[{"atb":[[1.39,0]],"id":9624350}],"con":true,"img":false}]}
{"op":"mcm","clk":"1362117093","pt":1588428513556,"mc":[{"id":"1.170370557","rc":[{"trd":[[1.41,2792.15]],"ltp":1.41,"tv":2792.15,"id":9624350},{"atb":[[1.41,0]],"id":9624350},{"atl":[[1.39,165.27]],"id":9624350}],"con":true,"img":false}]}
{"op":"mcm","clk":"1362117134","pt":1588428513964,"mc":[{"id":"1.170370557","rc":[{"atb":[[1.26,443.26]],"id":9624350}],"con":true,"img":false}]}
{"op":"mcm","clk":"1362117146","pt":1588428514782,"mc":[{"id":"1.170370557","rc":[{"atl":[[1.39,465.27]],"id":9624350}],"con":true,"img":false}]}
{"op":"mcm","clk":"1362117154","pt":1588428515192,"mc":[{"id":"1.170370557","rc":[{"trd":[[1.38,58.25]],"ltp":1.38,"tv":58.25,"id":9624350},{"atb":[[1.38,18.47]],"id":9624350}],"con":true,"img":false}]}
{"op":"mcm","clk":"1362117164","pt":1588428516060,"mc":[{"id":"1.170370557","rc":[{"atb":[[1.2,120.19]],"id":9624350}],"con":true,"img":false}]}
{"op":"mcm","clk":"1362117169","pt":1588428516470,"mc":[{"id":"1.170370557","rc":[{"trd":[[1.39,1210.54]],"ltp":1.39,"tv":1210.54,"id":9624350},{"atl":[[1.44,709.21],[1.39,453.01],[1.53,0]],"id":9624350}],"con":true,"img":false}]}
{"op":"mcm","clk":"1362117172","pt":1588428516674,"mc":[{"id":"1.170370557","rc":[{"atb":[[1.35,0]],"id":9624350}],"con":true,"img":false}]}
{"op":"mcm","clk":"1362117180","pt":1588428517392,"mc":[{"id":"1.170370557","rc":[{"trd":[[1.39,1383.6]],"ltp":1.39,"tv":1383.6,"id":9624350},{"atl":[[1.39,366.48]],"id":9624350}],"con":true,"img":false}]}
{"op":"mcm","clk":"1362117190","pt":1588428518263,"mc":[{"id":"1.170370557","rc":[{"atb":[[1.12,0]],"id":9624350}],"con":true,"img":false}]}
{"op":"mcm","clk":"1362117193","pt":1588428518671,"mc":[{"id":"1.170370557","rc":[{"atb":[[1.13,0]],"id":9624350}],"con":true,"img":false}]}
{"op":"mcm","clk":"1362117195","pt":1588428518875,"mc":[{"id":"1.170370557","rc":[{"atl":[[1.39,426.48]],"id":9624350}],"con":true,"img":false}]}
{"op":"mcm","clk":"1362117202","pt":1588428519384,"mc":[{"id":"1.170370557","rc":[{"atl":[[1.44,265.95]],"id":9624350}],"con":true,"img":false}]}
{"op":"mcm","clk":"1362117204","pt":1588428519588,"mc":[{"id":"1.170370557","rc":[{"atb":[[1.38,0]],"id":9624350}],"con":true,"img":false}]}
{"op":"mcm","clk":"1362117206","pt":1588428519894,"mc":[{"id":"1.170370557","rc":[{"atb":[[1.27,0],[1.3,0],[1.29,0]],"id":9624350}],"con":true,"img":false}]}
{"op":"mcm","clk":"1362117208","pt":1588428519996,"mc":[{"id":"1.170370557","rc":[{"atb":[[1.32,0]],"id":9624350}],"con":true,"img":false}]}
{"op":"mcm","clk":"1362117214","pt":1588428520762,"mc":[{"id":"1.170370557","rc":[{"trd":[[1.39,1403.6]],"ltp":1.39,"tv":1403.6,"id":9624350},{"atl":[[1.39,416.48]],"id":9624350}],"con":true,"img":false}]}
{"op":"mcm","clk":"1362117225","pt":1588428521582,"mc":[{"id":"1.170370557","rc":[{"atl":[[1.39,421.53]],"id":9624350}],"con":true,"img":false}]}
{"op":"mcm","clk":"1362117231","pt":1588428521990,"mc":[{"id":"1.170370557","rc":[{"atl":[[1.43,0]],"id":9624350}],"con":true,"img":false}]}
{"op":"mcm","clk":"1362117236","pt":1588428523064,"mc":[{"id":"1.170370557","rc":[{"trd":[[1.37,636.81]],"ltp":1.37,"tv":636.81,"id":9624350},{"atb":[[1.37,0]],"id":9624350},{"atl":[[1.35,747.64]],"id":9624350}],"con":true,"img":false}]}
{"op":"mcm","clk":"1362117238","pt":1588428523166,"mc":[{"id":"1.170370557","rc":[{"atl":[[1.48,0]],"id":9624350}],"con":true,"img":false}]}
{"op":"mcm","clk":"1362117242","pt":1588428523373,"mc":[{"id":"1.170370557","rc":[{"atl":[[1.35,1497.64]],"id":9624350}],"con":true,"img":false}]}
{"op":"mcm","clk":"1362117245","pt":1588428523475,"mc":[{"id":"1.170370557","rc":[{"atl":[[1.39,361.53]],"id":9624350}],"con":true,"img":false}]}
{"op":"mcm","clk":"1362117257","pt":1588428524502,"mc":[{"id":"1.170370557","rc":[{"atb":[[1.17,492.02]],"id":9624350}],"con":true,"img":false}]}
{"op":"mcm","clk":"1362117259","pt":1588428524605,"mc":[{"id":"1.170370557","rc":[{"trd":[[1.34,174.48]],"ltp":1.34,"tv":174.48,"id":9624350},{"atb":[[1.34,0]],"id":9624350},{"atl":[[1.34,491.78]],"id":9624350}],"con":true,"img":false}]}
{"op":"mcm","clk":"1362117262","pt":1588428524809,"mc":[{"id":"1.170370557","rc":[{"atl":[[1.38,2]],"id":9624350}],"con":true,"img":false}]}
{"op":"mcm","clk":"1362117265","pt":1588428524962,"mc":[{"id":"1.170370557","rc":[{"trd":[[1.34,174.8]],"ltp":1.34,"tv":174.8,"id":9624350},{"atb":[[1.18,492.02]],"id":9624350},{"atl":[[1.34,491.62]],"id":9624350}],"con":true,"img":false}]}
{"op":"mcm","clk":"1362117271","pt":1588428525372,"mc":[{"id":"1.170370557","rc":[{"trd":[[3.9,7.5]],"ltp":3.9,"tv":7.5,"id":9622734},{"trd":[[1.34,185]],"ltp":1.34,"tv":185.0,"id":9624350},{"atl":[[1.34,481.42]],"id":9624350}],"con":true,"img":false}]}
{"op":"mcm","clk":"1362117282","pt":1588428525782,"mc":[{"id":"1.170370557","rc":[{"atl":[[1.33,112]],"id":9624350}],"con":true,"img":false}]}
{"op":"mcm","clk":"1362117288","pt":1588428526088,"mc":[{"id":"1.170370557","rc":[{"atb":[[1.2,400.26]],"id":9624350},{"atl":[[1.66,305.89]],"id":9624350}],"con":true,"img":false}]}
{"op":"mcm","clk":"1362117290","pt":1588428526191,"mc":[{"id":"1.170370557","rc":[{"atl":[[1.38,114]],"id":9624350}],"con":true,"img":false}]}
{"op":"mcm","clk":"1362117292","pt":1588428526293,"mc":[{"id":"1.170370557","rc":[{"atb":[[1.27,5.09]],"id":9624350},{"atl":[[1.34,1174.68]],"id":9624350}],"con":true,"img":false}]}
{"op":"mcm","clk":"1362117300","pt":1588428527009,"mc":[{"id":"1.170370557","rc":[{"atb":[[1.01,4104.95]],"id":9624350}],"con":true,"img":false}]}
{"op":"mcm","clk":"1362117306","pt":1588428527316,"mc":[{"id":"1.170370557","rc":[{"atl":[[1000,0]],"id":9622734},{"atb":[[1.01,4104.38]],"id":9624350}],"con":true,"img":false}]}
{"op":"mcm","clk":"1362117308","pt":1588428527367,"mc":[{"id":"1.170370557","rc":[{"atl":[[1.35,0]],"id":9624350}],"con":true,"img":false}]}
{"op":"mcm","clk":"1362117310","pt":1588428527469,"mc":[{"id":"1.170370557","rc":[{"trd":[[1.33,20.39]],"ltp":1.33,"tv":20.39,"id":9624350},{"atl":[[1.33,111.13]],"id":9624350}],"con":true,"img":false}]}
{"op":"mcm","clk":"1362117313","pt":1588428527674,"mc":[{"id":"1.170370557","rc":[{"atb":[[1.01,4101.75]],"id":9624350}],"con":true,"img":false}]}
{"op":"mcm","clk":"1362117323","pt":1588428528596,"mc":[{"id":"1.170370557","rc":[{"atb":[[1.28,19.92]],"id":9624350},{"atl":[[1.36,60]],"id":9624350}],"con":true,"img":false}]}
{"op":"mcm","clk":"1362117327","pt":1588428528903,"mc":[{"id":"1.170370557","rc":[{"atb":[[1.21,250]],"id":9624350}],"con":true,"img":false}]}
{"op":"mcm","clk":"1362117333","pt":1588428529314,"mc":[{"id":"1.170370557","rc":[{"trd":[[1.33,28.92]],"ltp":1.33,"tv":28.92,"id":9624350},{"atl":[[1.33,106.87]],"id":9624350}],"con":true,"img":false}]}
{"op":"mcm","clk":"1362117337","pt":1588428529518,"mc":[{"id":"1.170370557","rc":[{"atl":[[1.34,1396.32]],"id":9624350}],"con":true,"img":false}]}
{"op":"mcm","clk":"1362117340","pt":1588428529620,"mc":[{"id":"1.170370557","rc":[{"atl":[[1.39,61.53]],"id":9624350}],"con":true,"img":false}]}
{"op":"mcm","clk":"1362117345","pt":1588428529773,"mc":[{"id":"1.170370557","rc":[{"atb":[[1.01,4103.53]],"id":9624350}],"con":true,"img":false}]}
{"op":"mcm","clk":"1362117349","pt":1588428530081,"mc":[{"id":"1.170370557","rc":[{"atb":[[1.01,4101.99]],"id":9624350},{"atl":[[1.33,328.5]],"id":9624350}],"con":true,"img":false}]}
{"op":"mcm","clk":"1362117352","pt":1588428530285,"mc":[{"id":"1.170370557","rc":[{"atb":[[1.01,4103.77]],"id":9624350}],"con":true,"img":false}]}
{"op":"mcm","clk":"1362117354","pt":1588428530387,"mc":[{"id":"1.170370557","rc":[{"atb":[[1.01,4103.53]],"id":9624350}],"con":true,"img":false}]}
{"op":"mcm","clk":"1362117358","pt":1588428530593,"mc":[{"id":"1.170370557","rc":[{"trd":[[1.33,49.46]],"ltp":1.33,"tv":49.46,"id":9624350},{"atl":[[1.33,318.23],[1.32,250]],"id":9624350}],"con":true,"img":false}]}
{"op":"mcm","clk":"1362117360","pt":1588428530695,"mc":[{"id":"1.170370557","rc":[{"atb":[[1.01,4101.91]],"id":9624350}],"con":true,"img":false}]}
{"op":"mcm","clk":"1362117364","pt":1588428531001,"mc":[{"id":"1.170370557","rc":[{"atb":[[1.01,4101.75],[1.31,44.32]],"id":9624350}],"con":true,"img":false}]}
{"op":"mcm","clk":"1362117368","pt":1588428531309,"mc":[{"id":"1.170370557","rc":[{"atl":[[1.33,406.88]],"id":9624350}],"con":true,"img":false}]}
{"op":"mcm","clk":"1362117372","pt":1588428531514,"mc":[{"id":"1.170370557","rc":[{"atl":[[1.33,495.53]],"id":9624350}],"con":true,"img":false}]}
{"op":"mcm","clk":"1362117375","pt":1588428531616,"mc":[{"id":"1.170370557","rc":[{"atb":[[1.27,255.09]],"id":9624350}],"con":true,"img":false}]}
{"op":"mcm","clk":"1362117377","pt":1588428531718,"mc":[{"id":"1.170370557","rc":[{"atl":[[1.32,338.65]],"id":9624350}],"con":true,"img":false}]}
{"op":"mcm","clk":"1362117381","pt":1588428531923,"mc":[{"id":"1.170370557","rc":[{"atl":[[1.32,427.3]],"id":9624350}],"con":true,"img":false}]}
{"op":"mcm","clk":"1362117390","pt":1588428532280,"mc":[{"id":"1.170370557","rc":[{"atl":[[1.32,515.95]],"id":9624350}],"con":true,"img":false}]}
{"op":"mcm","clk":"1362117392","pt":1588428532382,"mc":[{"id":"1.170370557","rc":[{"trd":[[4.1,1.02]],"ltp":4.1,"tv":1.02,"id":9622734},{"trd":[[1.32,3.17]],"ltp":1.32,"tv":3.17,"id":9624350},{"atl":[[1.32,512.78]],"id":9624350}],"con":true,"img":false}]}
{"op":"mcm","clk":"1362117395","pt":1588428532486,"mc":[{"id":"1.170370557","rc":[{"atl":[[1.34,914.89],[1.32,734.41]],"id":9624350}],"con":true,"img":false}]}
{"op":"mcm","clk":"1362117400","pt":1588428532792,"mc":[{"id":"1.170370557","rc":[{"trd":[[1.32,8.41]],"ltp":1.32,"tv":8.41,"id":9624350},{"atl":[[1.39,5.05],[1.34,693.26],[1.32,731.79]],"id":9624350}],"con":true,"img":false}]}
{"op":"mcm","clk":"1362117402","pt":1588428532894,"mc":[{"id":"1.170370557","rc":[{"atb":[[1.27,367.09]],"id":9624350}],"con":true,"img":false}]}
{"op":"mcm","clk":"1362117406","pt":1588428533099,"mc":[{"id":"1.170370557","rc":[{"atb":[[1.28,269.92]],"id":9624350}],"con":true,"img":false}]}
{"op":"mcm","clk":"1362117411","pt":1588428533509,"mc":[{"id":"1.170370557","rc":[{"atb":[[1.24,0]],"id":9624350}],"con":true,"img":false}]}
{"op":"mcm","clk":"1362117413","pt":1588428533611,"mc":[{"id":"1.170370557","rc":[{"atb":[[1.28,381.92]],"id":9624350}],"con":true,"img":false}]}
{"op":"mcm","clk":"1362117415","pt":1588428533713,"mc":[{"id":"1.170370557","rc":[{"trd":[[1.32,8.45]],"ltp":1.32,"tv":8.45,"id":9624350},{"atl":[[1.32,731.77]],"id":9624350}],"con":true,"img":false}]}
{"op":"mcm","clk":"1362117417","pt":1588428533815,"mc":[{"id":"1.170370557","rc":[{"trd":[[1.32,13.41]],"ltp":1.32,"tv":13.41,"id":9624350},{"atl":[[1.32,729.29]],"id":9624350}],"con":true,"img":false}]}
{"op":"mcm","clk":"1362117421","pt":1588428534020,"mc":[{"id":"1.170370557","rc":[{"atb":[[1.27,588.72]],"id":9624350}],"con":true,"img":false}]}
{"op":"mcm","clk":"1362117426","pt":1588428534380,"mc":[{"id":"1.170370557","rc":[{"trd":[[1.32,17.41]],"ltp":1.32,"tv":17.41,"id":9624350},{"atb":[[1.19,443.26]],"id":9624350},{"atl":[[1.32,727.29]],"id":9624350}],"con":true,"img":false}]}
{"op":"mcm","clk":"1362117429","pt":1588428534585,"mc":[{"id":"1.170370557","rc":[{"atl":[[1.34,443.26]],"id":9624350}],"con":true,"img":false}]}
{"op":"mcm","clk":"1362117432","pt":1588428534790,"mc":[{"id":"1.170370557","rc":[{"atl":[[1.32,461.34]],"id":9624350}],"con":true,"img":false}]}
{"op":"mcm","clk":"1362117435","pt":1588428534893,"mc":[{"id":"1.170370557","rc":[{"atb":[[1.29,112]],"id":9624350}],"con":true,"img":false}]}
{"op":"mcm","clk":"1362117447","pt":1588428535506,"mc":[{"id":"1.170370557","rc":[{"trd":[[1.32,17.89]],"ltp":1.32,"tv":17.89,"id":9624350},{"atb":[[1.29,224]],"id":9624350},{"atl":[[1.44,0],[1.32,461.1]],"id":9624350}],"con":true,"img":false}]}
{"op":"mcm","clk":"1362117454","pt":1588428535812,"mc":[{"id":"1.170370557","rc":[{"atl":[[1.69,0]],"id":9624350}],"con":true,"img":false}]}
{"op":"mcm","clk":"1362117459","pt":1588428536119,"mc":[{"id":"1.170370557","rc":[{"trd":[[1.32,18.21]],"ltp":1.32,"tv":18.21,"id":9624350},{"atl":[[1.32,460.94]],"id":9624350}],"con":true,"img":false}]}
{"op":"mcm","clk":"1362117467","pt":1588428536785,"mc":[{"id":"1.170370557","rc":[{"trd":[[4.1,4.52]],"ltp":4.1,"tv":4.52,"id":9622734},{"trd":[[1.32,29.09]],"ltp":1.32,"tv":29.09,"id":9624350},{"atl":[[1.32,450.06]],"id":9624350}],"con":true,"img":false}]}
{"op":"mcm","clk":"1362117477","pt":1588428537501,"mc":[{"id":"1.170370557","rc":[{"atb":[[1.2,308.93]],"id":9624350}],"con":true,"img":false}]}
{"op":"mcm","clk":"1362117483","pt":1588428538013,"mc":[{"id":"1.170370557","rc":[{"atb":[[1.26,0]],"id":9624350},{"atl":[[1.32,228.43]],"id":9624350}],"con":true,"img":false}]}
{"op":"mcm","clk":"1362117489","pt":1588428538527,"mc":[{"id":"1.170370557","rc":[{"atb":[[1.29,312.65]],"id":9624350}],"con":true,"img":false}]}
{"op":"mcm","clk":"1362117491","pt":1588428538630,"mc":[{"id":"1.170370557","rc":[{"trd":[[1.31,167.55]],"ltp":1.31,"tv":167.55,"id":9624350},{"atb":[[1.31,0]],"id":9624350},{"atl":[[1.31,177.3]],"id":9624350}],"con":true,"img":false}]}
{"op":"mcm","clk":"1362117493","pt":1588428538732,"mc":[{"id":"1.170370557","rc":[{"atb":[[1.29,401.3]],"id":9624350}],"con":true,"img":false}]}
{"op":"mcm","clk":"1362117495","pt":1588428538784,"mc":[{"id":"1.170370557","rc":[{"atb":[[1.29,489.95]],"id":9624350},{"atl":[[1.47,443.26]],"id":9624350}],"con":true,"img":false}]}
{"op":"mcm","clk":"1362117498","pt":1588428538988,"mc":[{"id":"1.170370557","rc":[{"atb":[[1.29,578.6]],"id":9624350}],"con":true,"img":false}]}
{"op":"mcm","clk":"1362117530","pt":1588428541033,"mc":[{"id":"1.170370557","rc":[{"atl":[[1.31,477.3]],"id":9624350}],"con":true,"img":false}]}
{"op":"mcm","clk":"1362117532","pt":1588428541135,"mc":[{"id":"1.170370557","rc":[{"atb":[[1.28,131.92]],"id":9624350},{"atl":[[1.31,300]],"id":9624350}],"con":true,"img":false}]}
{"op":"mcm","clk":"1362117538","pt":1588428541493,"mc":[{"id":"1.170370557","rc":[{"atb":[[1.22,89.83]],"id":9624350}],"con":true,"img":false}]}
{"op":"mcm","clk":"1362117540","pt":1588428541596,"mc":[{"id":"1.170370557","rc":[{"atb":[[1.27,338.72]],"id":9624350}],"con":true,"img":false}]}
{"op":"mcm","clk":"1362117542","pt":1588428541699,"mc":[{"id":"1.170370557","rc":[{"atl":[[1.34,0]],"id":9624350}],"con":true,"img":false}]}
{"op":"mcm","clk":"1362117557","pt":1588428542930,"mc":[{"id":"1.170370557","rc":[{"trd":[[1.31,172.79]],"ltp":1.31,"tv":172.79,"id":9624350},{"atl":[[1.31,297.38]],"id":9624350}],"con":true,"img":false}]}
{"op":"mcm","clk":"1362117559","pt":1588428543032,"mc":[{"id":"1.170370557","rc":[{"atl":[[1.31,298.89]],"id":9624350}],"con":true,"img":false}]}
{"op":"mcm","clk":"1362117566","pt":1588428543596,"mc":[{"id":"1.170370557","rc":[{"atl":[[1.31,355.63]],"id":9624350}],"con":true,"img":false}]}
{"op":"mcm","clk":"1362117571","pt":1588428543904,"mc":[{"id":"1.170370557","rc":[{"atl":[[1.31,365.38]],"id":9624350}],"con":true,"img":false}]}
{"op":"mcm","clk":"1362117574","pt":1588428544007,"mc":[{"id":"1.170370557","rc":[{"atb":[[1.28,112]],"id":9624350}],"con":true,"img":false}]}
{"op":"mcm","clk":"1362117589","pt":1588428545240,"mc":[{"id":"1.170370557","rc":[{"atl":[[1.33,398.93]],"id":9624350}],"con":true,"img":false}]}
{"op":"mcm","clk":"1362117602","pt":1588428545803,"mc":[{"id":"1.170370557","rc":[{"trd":[[4.2,13.92]],"ltp":4.2,"tv":13.92,"id":9622734},{"trd":[[1.31,184.02]],"ltp":1.31,"tv":184.02,"id":9624350},{"atl":[[1.31,354.15]],"id":9624350}],"con":true,"img":false}]}
{"op":"mcm","clk":"1362117625","pt":1588428547440,"mc":[{"id":"1.170370557","rc":[{"atl":[[1.33,177.3]],"id":9624350}],"con":true,"img":false}]}
{"op":"mcm","clk":"1362117628","pt":1588428547643,"mc":[{"id":"1.170370557","rc":[{"trd":[[1.31,184.23]],"ltp":1.31,"tv":184.23,"id":9624350},{"atl":[[1.31,354.05]],"id":9624350}],"con":true,"img":false}]}
{"op":"mcm","clk":"1362117636","pt":1588428548105,"mc":[{"id":"1.170370557","rc":[{"trd":[[1.31,191.23]],"ltp":1.31,"tv":191.23,"id":9624350},{"atl":[[1.31,350.55]],"id":9624350}],"con":true,"img":false}]}
{"op":"mcm","clk":"1362117642","pt":1588428548411,"mc":[{"id":"1.170370557","rc":[{"atl":[[1.31,340.8]],"id":9624350}],"con":true,"img":false}]}
{"op":"mcm","clk":"1362117645","pt":1588428548513,"mc":[{"id":"1.170370557","rc":[{"atb":[[1.27,333.63]],"id":9624350}],"con":true,"img":false}]}
{"op":"mcm","clk":"1362117650","pt":1588428548922,"mc":[{"id":"1.170370557","rc":[{"atl":[[1.32,0]],"id":9624350}],"con":true,"img":false}]}
{"op":"mcm","clk":"1362117656","pt":1588428549533,"mc":[{"id":"1.170370557","rc":[{"atb":[[1.28,0],[1.27,221.63],[1.29,354.6]],"id":9624350}],"con":true,"img":false}]}
{"op":"mcm","clk":"1362117658","pt":1588428549635,"mc":[{"id":"1.170370557","rc":[{"atb":[[1.3,19.6]],"id":9624350}],"con":true,"img":false}]}
{"op":"mcm","clk":"1362117668","pt":1588428550249,"mc":[{"id":"1.170370557","rc":[{"atb":[[1.29,0]],"id":9624350},{"atl":[[1.36,0]],"id":9624350}],"con":true,"img":false}]}
{"op":"mcm","clk":"1362117672","pt":1588428550452,"mc":[{"id":"1.170370557","rc":[{"trd":[[1.31,192.62]],"ltp":1.31,"tv":192.62,"id":9624350},{"atb":[[1.3,0]],"id":9624350},{"atl":[[1.31,340.1]],"id":9624350}],"con":true,"img":false}]}
{"op":"mcm","clk":"1362117678","pt":1588428550708,"mc":[{"id":"1.170370557","rc":[{"atb":[[1.21,0]],"id":9624350}],"con":true,"img":false}]}
{"op":"mcm","clk":"1362117682","pt":1588428550912,"mc":[{"id":"1.170370557","rc":[{"atb":[[1.27,0]],"id":9624350}],"con":true,"img":false}]}
{"op":"mcm","clk":"1362117684","pt":1588428551014,"mc":[{"id":"1.170370557","rc":[{"trd":[[4.2,14.02]],"ltp":4.2,"tv":14.02,"id":9622734},{"trd":[[1.31,192.95]],"ltp":1.31,"tv":192.95,"id":9624350},{"atl":[[1.31,339.77]],"id":9624350}],"con":true,"img":false}]}
{"op":"mcm","clk":"1362117686","pt":1588428551117,"mc":[{"id":"1.170370557","rc":[{"atb":[[1.2,28.86]],"id":9624350},{"atl":[[1.66,0]],"id":9624350}],"con":true,"img":false}]}
{"op":"mcm","clk":"1362117688","pt":1588428551219,"mc":[{"id":"1.170370557","rc":[{"atl":[[1.29,25]],"id":9624350}],"con":true,"img":false}]}
{"op":"mcm","clk":"1362117693","pt":1588428551627,"mc":[{"id":"1.170370557","rc":[{"trd":[[1.29,550.55]],"ltp":1.29,"tv":550.55,"id":9624350},{"atl":[[1.29,24.88]],"id":9624350}],"con":true,"img":false}]}
{"op":"mcm","clk":"1362117695","pt":1588428551729,"mc":[{"id":"1.170370557","rc":[{"trd":[[1.29,551.11]],"ltp":1.29,"tv":551.11,"id":9624350},{"atl":[[1.29,24.6]],"id":9624350}],"con":true,"img":false}]}
{"op":"mcm","clk":"1362117702","pt":1588428552137,"mc":[{"id":"1.170370557","rc":[{"atb":[[1.22,0]],"id":9624350}],"con":true,"img":false}]}
{"op":"mcm","clk":"1362117713","pt":1588428552955,"mc":[{"id":"1.170370557","rc":[{"atl":[[1.3,79.18]],"id":9624350}],"con":true,"img":false}]}
{"op":"mcm","clk":"1362117719","pt":1588428553313,"mc":[{"id":"1.170370557","rc":[{"trd":[[1.3,758.08],[1.29,600.32]],"ltp":1.3,"tv":1358.4,"id":9624350},{"atl":[[1.3,15.13],[1.29,0]],"id":9624350}],"con":true,"img":false}]}
{"op":"mcm","clk":"1362117721","pt":1588428553517,"mc":[{"id":"1.170370557","rc":[{"trd":[[1.31,320.49],[1.3,788.34],[1.28,1267.4]],"ltp":1.31,"tv":2376.23,"id":9624350},{"atl":[[1.3,0],[1.31,276]],"id":9624350}],"con":true,"img":false}]}
{"op":"mcm","clk":"1362117725","pt":1588428553823,"mc":[{"id":"1.170370557","rc":[{"trd":[[1.31,497.79]],"ltp":1.31,"tv":497.79,"id":9624350},{"atl":[[1.31,187.35]],"id":9624350}],"con":true,"img":false}]}
{"op":"mcm","clk":"1362117727","pt":1588428553926,"mc":[{"id":"1.170370557","rc":[{"atl":[[1.28,492.02]],"id":9624350}],"con":true,"img":false}]}
{"op":"mcm","clk":"1362117733","pt":1588428554435,"mc":[{"id":"1.170370557","rc":[{"atl":[[1.27,444]],"id":9624350}],"con":true,"img":false}]}
{"op":"mcm","clk":"1362117739","pt":1588428554947,"mc":[{"id":"1.170370557","rc":[{"trd":[[4.7,3.5]],"ltp":4.7,"tv":3.5,"id":9622734},{"trd":[[1.27,1489.48]],"ltp":1.27,"tv":1489.48,"id":9624350},{"atl":[[1.27,431.03]],"id":9624350}],"con":true,"img":false}]}
{"op":"mcm","clk":"1362117742","pt":1588428555151,"mc":[{"id":"1.170370557","rc":[{"atl":[[1.26,443.26]],"id":9624350}],"con":true,"img":false}]}
{"op":"mcm","clk":"1362117744","pt":1588428555253,"mc":[{"id":"1.170370557","rc":[{"atl":[[1.28,742.02]],"id":9624350}],"con":true,"img":false}]}
{"op":"mcm","clk":"1362117746","pt":1588428555356,"mc":[{"id":"1.170370557","rc":[{"atl":[[1.25,60]],"id":9624350}],"con":true,"img":false}]}
{"op":"mcm","clk":"1362117749","pt":1588428555512,"mc":[{"id":"1.170370557","rc":[{"atl":[[1.3,112]],"id":9624350}],"con":true,"img":false}]}
{"op":"mcm","clk":"1362117753","pt":1588428555920,"mc":[{"id":"1.170370557","rc":[{"atl":[[1.29,112]],"id":9624350}],"con":true,"img":false}]}
{"op":"mcm","clk":"1362117761","pt":1588428556435,"mc":[{"id":"1.170370557","rc":[{"atl":[[1.29,334]],"id":9624350}],"con":true,"img":false}]}
{"op":"mcm","clk":"1362117766","pt":1588428556742,"mc":[{"id":"1.170370557","rc":[{"atl":[[1.33,0]],"id":9624350}],"con":true,"img":false}]}
{"op":"mcm","clk":"1362117790","pt":1588428556948,"mc":[{"id":"1.170370557","rc":[{"trd":[[1.25,2287.09]],"ltp":1.25,"tv":2287.09,"id":9624350},{"atl":[[1.25,59.46]],"id":9624350}],"con":true,"img":false}]}
{"op":"mcm","clk":"1362117810","pt":1588428557050,"mc":[{"id":"1.170370557","rc":[{"atb":[[1.14,823.29]],"id":9624350},{"atl":[[1.56,356.42]],"id":9624350}],"con":true,"img":false}]}
{"op":"mcm","clk":"1362117815","pt":1588428557359,"mc":[{"id":"1.170370557","rc":[{"atl":[[1.25,281.09]],"id":9624350}],"con":true,"img":false}]}
{"op":"mcm","clk":"1362117820","pt":1588428557513,"mc":[{"id":"1.170370557","rc":[{"atb":[[1.22,123.17]],"id":9624350}],"con":true,"img":false}]}
{"op":"mcm","clk":"1362117822","pt":1588428557616,"mc":[{"id":"1.170370557","rc":[{"atl":[[1.31,185.83]],"id":9624350}],"con":true,"img":false}]}
{"op":"mcm","clk":"1362117825","pt":1588428557820,"mc":[{"id":"1.170370557","rc":[{"atb":[[1.21,112]],"id":9624350}],"con":true,"img":false}]}
{"op":"mcm","clk":"1362117827","pt":1588428557923,"mc":[{"id":"1.170370557","rc":[{"atb":[[1.2,120.19]],"id":9624350}],"con":true,"img":false}]}
{"op":"mcm","clk":"1362117831","pt":1588428558229,"mc":[{"id":"1.170370557","rc":[{"atb":[[1.19,555.26]],"id":9624350}],"con":true,"img":false}]}
{"op":"mcm","clk":"1362117832","pt":1588428558638,"mc":[{"id":"1.170370557","rc":[{"atb":[[1.21,117.34]],"id":9624350}],"con":true,"img":false}]}
{"op":"mcm","clk":"1362117833","pt":1588428558741,"mc":[{"id":"1.170370557","rc":[{"atb":[[1.2,232.19]],"id":9624350}],"con":true,"img":false}]}
{"op":"mcm","clk":"1362117835","pt":1588428558844,"mc":[{"id":"1.170370557","rc":[{"atl":[[1.31,129.1]],"id":9624350}],"con":true,"img":false}]}
{"op":"mcm","clk":"1362117837","pt":1588428558946,"mc":[{"id":"1.170370557","rc":[{"atl":[[1.28,250]],"id":9624350}],"con":true,"img":false}]}
{"op":"mcm","clk":"1362117838","pt":1588428559049,"mc":[{"id":"1.170370557","rc":[{"atl":[[1.25,221.63],[1.29,112]],"id":9624350}],"con":true,"img":false}]}
{"op":"mcm","clk":"1362117841","pt":1588428559355,"mc":[{"id":"1.170370557","rc":[{"atb":[[1.19,112]],"id":9624350}],"con":true,"img":false}]}
{"op":"mcm","clk":"1362117842","pt":1588428559560,"mc":[{"id":"1.170370557","rc":[{"atb":[[1.21,127.34],[1.22,144.07]],"id":9624350}],"con":true,"img":false}]}
{"op":"mcm","clk":"1362117849","pt":1588428560019,"mc":[{"id":"1.170370557","rc":[{"atl":[[1.26,693.26]],"id":9624350}],"con":true,"img":false}]}
{"op":"mcm","clk":"1362117858","pt":1588428560324,"mc":[{"id":"1.170370557","rc":[{"atl":[[1.27,543.03]],"id":9624350}],"con":true,"img":false}]}
{"op":"mcm","clk":"1362117864","pt":1588428560938,"mc":[{"id":"1.170370557","rc":[{"atl":[[1.24,221.63]],"id":9624350}],"con":true,"img":false}]}
{"op":"mcm","clk":"1362117865","pt":1588428561040,"mc":[{"id":"1.170370557","rc":[{"atl":[[1.26,805.26]],"id":9624350}],"con":true,"img":false}]}
{"op":"mcm","clk":"1362117867","pt":1588428561245,"mc":[{"id":"1.170370557","rc":[{"atb":[[1.21,117.34]],"id":9624350}],"con":true,"img":false}]}
{"op":"mcm","clk":"1362117868","pt":1588428561348,"mc":[{"id":"1.170370557","rc":[{"atl":[[1.25,333.63]],"id":9624350}],"con":true,"img":false}]}
{"op":"mcm","clk":"1362117872","pt":1588428561858,"mc":[{"id":"1.170370557","rc":[{"atl":[[1.31,0]],"id":9624350}],"con":true,"img":false}]}
{"op":"mcm","clk":"1362117875","pt":1588428562065,"mc":[{"id":"1.170370557","rc":[{"atl":[[1.24,501.33]],"id":9624350}],"con":true,"img":false}]}
{"op":"mcm","clk":"1362117877","pt":1588428562371,"mc":[{"id":"1.170370557","rc":[{"trd":[[1.24,3065.91]],"ltp":1.24,"tv":3065.91,"id":9624350},{"atb":[[1.21,229.34]],"id":9624350},{"atl":[[1.24,500.81]],"id":9624350}],"con":true,"img":false}]}
{"op":"mcm","clk":"1362117879","pt":1588428562626,"mc":[{"id":"1.170370557","rc":[{"atb":[[1.21,445.63]],"id":9624350}],"con":true,"img":false}]}
{"op":"mcm","clk":"1362117881","pt":1588428562727,"mc":[{"id":"1.170370557","rc":[{"atb":[[1.2,482.19]],"id":9624350}],"con":true,"img":false}]}
{"op":"mcm","clk":"1362117884","pt":1588428563032,"mc":[{"id":"1.170370557","rc":[{"atb":[[1.2,732.19],[1.19,224]],"id":9624350}],"con":true,"img":false}]}
{"op":"mcm","clk":"1362117885","pt":1588428563241,"mc":[{"id":"1.170370557","rc":[{"atb":[[1.2,844.19],[1.14,1266.56]],"id":9624350}],"con":true,"img":false}]}
{"op":"mcm","clk":"1362117887","pt":1588428563547,"mc":[{"id":"1.170370557","rc":[{"atb":[[1.21,695.63]],"id":9624350}],"con":true,"img":false}]}
{"op":"mcm","clk":"1362117889","pt":1588428563854,"mc":[{"id":"1.170370557","rc":[{"atl":[[1.47,0]],"id":9624350}],"con":true,"img":false}]}
{"op":"mcm","clk":"1362117891","pt":1588428563956,"mc":[{"id":"1.170370557","rc":[{"atb":[[1.21,945.63]],"id":9624350}],"con":true,"img":false}]}
{"op":"mcm","clk":"1362117893","pt":1588428564058,"mc":[{"id":"1.170370557","rc":[{"atb":[[1.22,256.07]],"id":9624350}],"con":true,"img":false}]}
{"op":"mcm","clk":"1362117896","pt":1588428564263,"mc":[{"id":"1.170370557","rc":[{"trd":[[1.24,3075.91]],"ltp":1.24,"tv":3075.91,"id":9624350},{"atb":[[1.22,506.07]],"id":9624350},{"atl":[[1.24,495.81]],"id":9624350}],"con":true,"img":false}]}
{"op":"mcm","clk":"1362117900","pt":1588428564467,"mc":[{"id":"1.170370557","rc":[{"atb":[[1.22,618.07]],"id":9624350}],"con":true,"img":false}]}
{"op":"mcm","clk":"1362117905","pt":1588428564620,"mc":[{"id":"1.170370557","rc":[{"atb":[[1.22,868.07]],"id":9624350}],"con":true,"img":false}]}
{"op":"mcm","clk":"1362117907","pt":1588428564722,"mc":[{"id":"1.170370557","rc":[{"atl":[[1.27,112]],"id":9624350}],"con":true,"img":false}]}
{"op":"mcm","clk":"1362117910","pt":1588428564927,"mc":[{"id":"1.170370557","rc":[{"atb":[[1.21,1057.63]],"id":9624350}],"con":true,"img":false}]}
{"op":"mcm","clk":"1362117911","pt":1588428565030,"mc":[{"id":"1.170370557","rc":[{"trd":[[5.1,114.69]],"ltp":5.1,"tv":114.69,"id":9622734},{"trd":[[1.24,3090.31]],"ltp":1.24,"tv":3090.31,"id":9624350},{"atl":[[1.24,481.4]],"id":9624350}],"con":true,"img":false}]}
{"op":"mcm","clk":"1362117914","pt":1588428565541,"mc":[{"id":"1.170370557","rc":[{"atb":[[1.16,1546.85]],"id":9624350}],"con":true,"img":false}]}
{"op":"mcm","clk":"1362117916","pt":1588428566625,"mc":[{"id":"1.170370557","rc":[{"atb":[[1.23,48.75]],"id":9624350}],"con":true,"img":false}]}
{"op":"mcm","clk":"1362117918","pt":1588428566932,"mc":[{"id":"1.170370557","rc":[{"atb":[[1.22,1089.7]],"id":9624350}],"con":true,"img":false}]}
{"op":"mcm","clk":"1362117919","pt":1588428567034,"mc":[{"id":"1.170370557","rc":[{"atl":[[1.3,555.26]],"id":9624350}],"con":true,"img":false}]}
{"op":"mcm","clk":"1362117928","pt":1588428567749,"mc":[{"id":"1.170370557","rc":[{"atb":[[1.22,1589.7]],"id":9624350}],"con":true,"img":false}]}
{"op":"mcm","clk":"1362117934","pt":1588428568260,"mc":[{"id":"1.170370557","rc":[{"atb":[[1.14,823.29]],"id":9624350}],"con":true,"img":false}]}
{"op":"mcm","clk":"1362117936","pt":1588428568973,"mc":[{"id":"1.170370557","rc":[{"atb":[[1.22,2033.7]],"id":9624350}],"con":true,"img":false}]}
{"op":"mcm","clk":"1362117937","pt":1588428569075,"mc":[{"id":"1.170370557","rc":[{"trd":[[5.1,114.81]],"ltp":5.1,"tv":114.81,"id":9622734},{"trd":[[1.24,3090.8]],"ltp":1.24,"tv":3090.8,"id":9624350},{"atl":[[1.24,480.92]],"id":9624350}],"con":true,"img":false}]}
{"op":"mcm","clk":"1362117939","pt":1588428569227,"mc":[{"id":"1.170370557","rc":[{"trd":[[1.23,1949.54]],"ltp":1.23,"tv":1949.54,"id":9624350},{"atb":[[1.23,47.24]],"id":9624350}],"con":true,"img":false}]}
{"op":"mcm","clk":"1362117941","pt":1588428569838,"mc":[{"id":"1.170370557","rc":[{"trd":[[1.22,2671.28],[1.23,2044.03]],"ltp":1.22,"tv":4715.31,"id":9624350},{"atb":[[1.23,0],[1.22,2024.21]],"id":9624350}],"con":true,"img":false}]}
{"op":"mcm","clk":"1362117942","pt":1588428569940,"mc":[{"id":"1.170370557","rc":[{"atb":[[1.23,500]],"id":9624350}],"con":true,"img":false}]}
{"op":"mcm","clk":"1362117946","pt":1588428571067,"mc":[{"id":"1.170370557","rc":[{"trd":[[1.23,2266.03]],"ltp":1.23,"tv":2266.03,"id":9624350},{"atb":[[1.23,389]],"id":9624350}],"con":true,"img":false}]}
{"op":"mcm","clk":"1362117949","pt":1588428571733,"mc":[{"id":"1.170370557","rc":[{"atb":[[1.22,2136.21]],"id":9624350}],"con":true,"img":false}]}
{"op":"mcm","clk":"1362117995","pt":1588428572553,"mc":[{"id":"1.170370557","rc":[{"atl":[[1.26,362]],"id":9624350}],"con":true,"img":false}]}
{"op":"mcm","clk":"1362118007","pt":1588428573371,"mc":[{"id":"1.170370557","rc":[{"atb":[[1.15,935.28]],"id":9624350}],"con":true,"img":false}]}
{"op":"mcm","clk":"1362118010","pt":1588428573939,"mc":[{"id":"1.170370557","rc":[{"atb":[[1.23,0]],"id":9624350}],"con":true,"img":false}]}
{"op":"mcm","clk":"1362118017","pt":1588428574450,"mc":[{"id":"1.170370557","rc":[{"trd":[[1.24,3095.96]],"ltp":1.24,"tv":3095.96,"id":9624350},{"atl":[[1.24,478.34]],"id":9624350}],"con":true,"img":false}]}
{"op":"mcm","clk":"1362118019","pt":1588428574756,"mc":[{"id":"1.170370557","rc":[{"atl":[[1.29,0]],"id":9624350}],"con":true,"img":false}]}
{"op":"mcm","clk":"1362118023","pt":1588428575167,"mc":[{"id":"1.170370557","rc":[{"atl":[[1.3,443.26]],"id":9624350}],"con":true,"img":false}]}
{"op":"mcm","clk":"1362118037","pt":1588428576548,"mc":[{"id":"1.170370557","rc":[{"trd":[[5.1,118.31]],"ltp":5.1,"tv":118.31,"id":9622734},{"trd":[[1.24,3110.36]],"ltp":1.24,"tv":3110.36,"id":9624350},{"atl":[[1.24,463.93]],"id":9624350}],"con":true,"img":false}]}
{"op":"mcm","clk":"1362118039","pt":1588428577161,"mc":[{"id":"1.170370557","rc":[{"atl":[[1.25,445.63]],"id":9624350}],"con":true,"img":false}]}
{"op":"mcm","clk":"1362118046","pt":1588428577774,"mc":[{"id":"1.170370557","rc":[{"trd":[[1.22,2790.19]],"ltp":1.22,"tv":2790.19,"id":9624350},{"atb":[[1.22,2076.75]],"id":9624350}],"con":true,"img":false}]}
{"op":"mcm","clk":"1362118047","pt":1588428578185,"mc":[{"id":"1.170370557","rc":[{"atl":[[1.5,112.28]],"id":9624350}],"con":true,"img":false}]}
{"op":"mcm","clk":"1362118051","pt":1588428579154,"mc":[{"id":"1.170370557","rc":[{"atb":[[1.2,864.19],[1.22,2055.85]],"id":9624350}],"con":true,"img":false}]}
{"op":"mcm","clk":"1362118061","pt":1588428579767,"mc":[{"id":"1.170370557","rc":[{"atb":[[1.2,884.19]],"id":9624350}],"con":true,"img":false}]}
{"op":"mcm","clk":"1362118063","pt":1588428579972,"mc":[{"id":"1.170370557","rc":[{"atb":[[1.22,2001.63]],"id":9624350}],"con":true,"img":false}]}
{"op":"mcm","clk":"1362118077","pt":1588428581095,"mc":[{"id":"1.170370557","rc":[{"atb":[[1.22,1557.63]],"id":9624350}],"con":true,"img":false}]}
{"op":"mcm","clk":"1362118079","pt":1588428581197,"mc":[{"id":"1.170370557","rc":[{"trd":[[5.1,123.31]],"ltp":5.1,"tv":123.31,"id":9622734},{"trd":[[1.24,3130.93]],"ltp":1.24,"tv":3130.93,"id":9624350},{"atl":[[1.24,443.36]],"id":9624350}],"con":true,"img":false}]}
{"op":"mcm","clk":"1362118083","pt":1588428581351,"mc":[{"id":"1.170370557","rc":[{"trd":[[1.24,3134.93]],"ltp":1.24,"tv":3134.93,"id":9624350},{"atl":[[1.24,441.36]],"id":9624350}],"con":true,"img":false}]}
{"op":"mcm","clk":"1362118090","pt":1588428581862,"mc":[{"id":"1.170370557","rc":[{"trd":[[1.24,3135.98]],"ltp":1.24,"tv":3135.98,"id":9624350},{"atl":[[1.24,440.84]],"id":9624350}],"con":true,"img":false}]}
{"op":"mcm","clk":"1362118092","pt":1588428581963,"mc":[{"id":"1.170370557","rc":[{"trd":[[1.22,2807.93]],"ltp":1.22,"tv":2807.93,"id":9624350},{"atb":[[1.22,1548.76]],"id":9624350}],"con":true,"img":false}]}
{"op":"mcm","clk":"1362118101","pt":1588428582576,"mc":[{"id":"1.170370557","rc":[{"atb":[[1.2,930.55]],"id":9624350}],"con":true,"img":false}]}
{"op":"mcm","clk":"1362118104","pt":1588428582679,"mc":[{"id":"1.170370557","rc":[{"atl":[[1.23,88.65]],"id":9624350}],"con":true,"img":false}]}
{"op":"mcm","clk":"1362118107","pt":1588428582886,"mc":[{"id":"1.170370557","rc":[{"atl":[[1.23,177.3]],"id":9624350}],"con":true,"img":false}]}
{"op":"mcm","clk":"1362118110","pt":1588428583092,"mc":[{"id":"1.170370557","rc":[{"atb":[[1.21,1457.63]],"id":9624350},{"atl":[[1.23,265.95]],"id":9624350}],"con":true,"img":false}]}
{"op":"mcm","clk":"1362118114","pt":1588428583297,"mc":[{"id":"1.170370557","rc":[{"atl":[[1.23,354.6]],"id":9624350}],"con":true,"img":false}]}
{"op":"mcm","clk":"1362118116","pt":1588428583348,"mc":[{"id":"1.170370557","rc":[{"atb":[[1.19,624]],"id":9624350}],"con":true,"img":false}]}
{"op":"mcm","clk":"1362118118","pt":1588428583451,"mc":[{"id":"1.170370557","rc":[{"atb":[[1.17,892.02]],"id":9624350},{"atl":[[1.23,443.26]],"id":9624350}],"con":true,"img":false}]}
{"op":"mcm","clk":"1362118127","pt":1588428584068,"mc":[{"id":"1.170370557","rc":[{"trd":[[1.23,2276.03]],"ltp":1.23,"tv":2276.03,"id":9624350},{"atl":[[1.23,526.91]],"id":9624350}],"con":true,"img":false}]}
{"op":"mcm","clk":"1362118128","pt":1588428584169,"mc":[{"id":"1.170370557","rc":[{"atb":[[1.2,1330.55]],"id":9624350}],"con":true,"img":false}]}
{"op":"mcm","clk":"1362118134","pt":1588428584582,"mc":[{"id":"1.170370557","rc":[{"atb":[[1.18,892.02]],"id":9624350}],"con":true,"img":false}]}
{"op":"mcm","clk":"1362118139","pt":1588428584890,"mc":[{"id":"1.170370557","rc":[{"trd":[[1.23,2296.03]],"ltp":1.23,"tv":2296.03,"id":9624350},{"atl":[[1.23,516.91]],"id":9624350}],"con":true,"img":false}]}
{"op":"mcm","clk":"1362118141","pt":1588428584992,"mc":[{"id":"1.170370557","rc":[{"trd":[[1.23,2337.48]],"ltp":1.23,"tv":2337.48,"id":9624350},{"atb":[[1.22,1048.76]],"id":9624350},{"atl":[[1.23,496.18]],"id":9624350}],"con":true,"img":false}]}
{"op":"mcm","clk":"1362118153","pt":1588428585962,"mc":[{"id":"1.170370557","rc":[{"trd":[[1.22,3189.47]],"ltp":1.22,"tv":3189.47,"id":9624350},{"atb":[[1.22,857.99]],"id":9624350}],"con":true,"img":false}]}
{"op":"mcm","clk":"1362118158","pt":1588428586374,"mc":[{"id":"1.170370557","rc":[{"trd":[[1.23,2338.14]],"ltp":1.23,"tv":2338.14,"id":9624350},{"atl":[[1.23,495.85]],"id":9624350}],"con":true,"img":false}]}
{"op":"mcm","clk":"1362118169","pt":1588428586987,"mc":[{"id":"1.170370557","rc":[{"trd":[[1.23,2416.86]],"ltp":1.23,"tv":2416.86,"id":9624350},{"atl":[[1.23,456.49]],"id":9624350}],"con":true,"img":false}]}
{"op":"mcm","clk":"1362118183","pt":1588428587806,"mc":[{"id":"1.170370557","rc":[{"atb":[[1.2,830.55]],"id":9624350}],"con":true,"img":false}]}
{"op":"mcm","clk":"1362118199","pt":1588428588676,"mc":[{"id":"1.170370557","rc":[{"trd":[[1.22,3212.69]],"ltp":1.22,"tv":3212.69,"id":9624350},{"atb":[[1.22,721.63]],"id":9624350}],"con":true,"img":false}]}
{"op":"mcm","clk":"1362118243","pt":1588428592008,"mc":[{"id":"1.170370557","rc":[{"atb":[[1.21,1236]],"id":9624350}],"con":true,"img":false}]}
{"op":"mcm","clk":"1362118249","pt":1588428592468,"mc":[{"id":"1.170370557","rc":[{"atl":[[1.23,637.24]],"id":9624350}],"con":true,"img":false}]}
{"op":"mcm","clk":"1362118256","pt":1588428592981,"mc":[{"id":"1.170370557","rc":[{"atl":[[1.26,250],[1.23,456.49],[1.27,0],[1.25,221.63],[1.57,0],[1.5,0.28],[1.38,2],[1.52,0]],"id":9624350}],"con":true,"img":false}]}
{"op":"mcm","clk":"1362118258","pt":1588428593086,"mc":[{"id":"1.170370557","rc":[{"atl":[[1.24,279.7]],"id":9624350}],"con":true,"img":false}]}
{"op":"mcm","clk":"1362118262","pt":1588428593394,"mc":[{"id":"1.170370557","rc":[{"atl":[[1.23,0],[1.24,0]],"id":9624350}],"con":true,"img":false}]}
{"op":"mcm","clk":"1362118264","pt":1588428593497,"mc":[{"id":"1.170370557","rc":[{"atl":[[1.28,0],[1.26,0]],"id":9624350}],"con":true,"img":false}]}
{"op":"mcm","clk":"1362118274","pt":1588428594265,"mc":[{"id":"1.170370557","rc":[{"atl":[[1.25,0]],"id":9624350}],"con":true,"img":false}]}
{"op":"mcm","clk":"1362118279","pt":1588428594572,"mc":[{"id":"1.170370557","rc":[{"atb":[[1.22,1221.63]],"id":9624350}],"con":true,"img":false}]}
{"op":"mcm","clk":"1362118288","pt":1588428595193,"mc":[{"id":"1.170370557","rc":[{"atb":[[1.14,492.02]],"id":9624350}],"con":true,"img":false}]}
{"op":"mcm","clk":"1362118290","pt":1588428595296,"mc":[{"id":"1.170370557","rc":[{"trd":[[1.22,3281.38]],"ltp":1.22,"tv":3281.38,"id":9624350},{"atb":[[1.22,1187.28]],"id":9624350}],"con":true,"img":false}]}
{"op":"mcm","clk":"1362118326","pt":1588428597812,"mc":[{"id":"1.170370557","rc":[{"atb":[[1.25,279.95],[1.24,444]],"id":9624350}],"con":true,"img":false}]}
{"op":"mcm","clk":"1362118337","pt":1588428598375,"mc":[{"id":"1.170370557","rc":[{"atb":[[1.25,0]],"id":9624350}],"con":true,"img":false}]}
{"op":"mcm","clk":"1362118340","pt":1588428598581,"mc":[{"id":"1.170370557","rc":[{"trd":[[1.22,3377.43],[1.24,4023.98]],"ltp":1.22,"tv":7401.41,"id":9624350},{"atb":[[1.22,1139.26],[1.24,0]],"id":9624350}],"con":true,"img":false}]}
{"op":"mcm","clk":"1362118342","pt":1588428598684,"mc":[{"id":"1.170370557","rc":[{"atl":[[1.25,203.25]],"id":9624350}],"con":true,"img":false}]}
{"op":"mcm","clk":"1362118345","pt":1588428598787,"mc":[{"id":"1.170370557","rc":[{"atb":[[1.23,750]],"id":9624350}],"con":true,"img":false}]}
{"op":"mcm","clk":"1362118349","pt":1588428599094,"mc":[{"id":"1.170370557","rc":[{"atb":[[1.23,1000]],"id":9624350}],"con":true,"img":false}]}
{"op":"mcm","clk":"1362118351","pt":1588428599196,"mc":[{"id":"1.170370557","rc":[{"atb":[[1.23,1240]],"id":9624350}],"con":true,"img":false}]}
{"op":"mcm","clk":"1362118353","pt":1588428599299,"mc":[{"id":"1.170370557","rc":[{"atb":[[1.23,1240.86]],"id":9624350}],"con":true,"img":false}]}
{"op":"mcm","clk":"1362118359","pt":1588428599607,"mc":[{"id":"1.170370557","rc":[{"atb":[[1.24,443.26]],"id":9624350}],"con":true,"img":false}]}
{"op":"mcm","clk":"1362118361","pt":1588428599709,"mc":[{"id":"1.170370557","rc":[{"atb":[[1.23,1480.86]],"id":9624350}],"con":true,"img":false}]}
{"op":"mcm","clk":"1362118372","pt":1588428600275,"mc":[{"id":"1.170370557","rc":[{"trd":[[1.25,2693.6]],"ltp":1.25,"tv":2693.6,"id":9624350},{"atb":[[1.25,151.35]],"id":9624350},{"atl":[[1.25,0]],"id":9624350}],"con":true,"img":false}]}
{"op":"mcm","clk":"1362118374","pt":1588428600379,"mc":[{"id":"1.170370557","rc":[{"trd":[[1.24,4705.31],[1.25,2996.31]],"ltp":1.24,"tv":7701.62,"id":9624350},{"atb":[[1.25,0],[1.24,102.59]],"id":9624350}],"con":true,"img":false}]}
{"op":"mcm","clk":"1362118386","pt":1588428601100,"mc":[{"id":"1.170370557","rc":[{"atb":[[1.18,1182.03]],"id":9624350}],"con":true,"img":false}]}
{"op":"mcm","clk":"1362118389","pt":1588428601305,"mc":[{"id":"1.170370557","rc":[{"atb":[[1.24,112.01]],"id":9624350}],"con":true,"img":false}]}
{"op":"mcm","clk":"1362118391","pt":1588428601408,"mc":[{"id":"1.170370557","rc":[{"atb":[[1.21,736],[1.23,980.86],[1.27,888]],"id":9624350}],"con":true,"img":false}]}
{"op":"mcm","clk":"1362118395","pt":1588428601612,"mc":[{"id":"1.170370557","rc":[{"atb":[[1.2,821.69]],"id":9624350}],"con":true,"img":false}]}
{"op":"mcm","clk":"1362118400","pt":1588428602021,"mc":[{"id":"1.170370557","rc":[{"atb":[[1.23,480.86]],"id":9624350}],"con":true,"img":false}]}
{"op":"mcm","clk":"1362118407","pt":1588428602583,"mc":[{"id":"1.170370557","rc":[{"atb":[[1.22,139.26]],"id":9624350}],"con":true,"img":false}]}
{"op":"mcm","clk":"1362118417","pt":1588428603308,"mc":[{"id":"1.170370557","rc":[{"atb":[[1.24,466.62]],"id":9624350}],"con":true,"img":false}]}
{"op":"mcm","clk":"1362118426","pt":1588428603721,"mc":[{"id":"1.170370557","rc":[{"atb":[[1.27,0]],"id":9624350}],"con":true,"img":false}]}
{"op":"mcm","clk":"1362118429","pt":1588428603823,"mc":[{"id":"1.170370557","rc":[{"atb":[[1.2,1317.8]],"id":9624350}],"con":true,"img":false}]}
{"op":"mcm","clk":"1362118436","pt":1588428604286,"mc":[{"id":"1.170370557","rc":[{"trd":[[1.24,5229.75],[1.26,1639.98]],"ltp":1.24,"tv":6869.73,"id":9624350},{"atb":[[1.24,204.4]],"id":9624350}],"con":true,"img":false}]}
{"op":"mcm","clk":"1362118442","pt":1588428604801,"mc":[{"id":"1.170370557","rc":[{"trd":[[1.23,2567.96],[1.24,5638.57]],"ltp":1.23,"tv":8206.52,"id":9624350},{"atb":[[1.23,405.31],[1.24,0]],"id":9624350}],"con":true,"img":false}]}
{"op":"mcm","clk":"1362118448","pt":1588428605214,"mc":[{"id":"1.170370557","rc":[{"atb":[[1.18,892.02]],"id":9624350},{"atl":[[1.56,0]],"id":9624350}],"con":true,"img":false}]}
{"op":"mcm","clk":"1362118450","pt":1588428605318,"mc":[{"id":"1.170370557","rc":[{"atb":[[1.23,645.31]],"id":9624350}],"con":true,"img":false}]}
{"op":"mcm","clk":"1362118454","pt":1588428605577,"mc":[{"id":"1.170370557","rc":[{"atb":[[1.21,1232.09]],"id":9624350}],"con":true,"img":false}]}
{"op":"mcm","clk":"1362118457","pt":1588428605685,"mc":[{"id":"1.170370557","rc":[{"atb":[[1.24,240]],"id":9624350}],"con":true,"img":false}]}
{"op":"mcm","clk":"1362118465","pt":1588428606296,"mc":[{"id":"1.170370557","rc":[{"atb":[[1.24,480]],"id":9624350}],"con":true,"img":false}]}
{"op":"mcm","clk":"1362118468","pt":1588428606400,"mc":[{"id":"1.170370557","rc":[{"atb":[[1.24,880]],"id":9624350}],"con":true,"img":false}]}
{"op":"mcm","clk":"1362118472","pt":1588428606503,"mc":[{"id":"1.170370557","rc":[{"atb":[[1.25,17.73],[1.22,0]],"id":9624350}],"con":true,"img":false}]}
{"op":"mcm","clk":"1362118474","pt":1588428606607,"mc":[{"id":"1.170370557","rc":[{"atb":[[1.24,968.65]],"id":9624350}],"con":true,"img":false}]}
{"op":"mcm","clk":"1362118476","pt":1588428606711,"mc":[{"id":"1.170370557","rc":[{"atl":[[1.27,111]],"id":9624350}],"con":true,"img":false}]}
{"op":"mcm","clk":"1362118478","pt":1588428606813,"mc":[{"id":"1.170370557","rc":[{"atb":[[1.24,1057.3]],"id":9624350}],"con":true,"img":false}]}
{"op":"mcm","clk":"1362118481","pt":1588428607018,"mc":[{"id":"1.170370557","rc":[{"atb":[[1.24,1145.95]],"id":9624350}],"con":true,"img":false}]}
{"op":"mcm","clk":"1362118483","pt":1588428607121,"mc":[{"id":"1.170370557","rc":[{"trd":[[1.24,6103.11],[1.25,3031.77]],"ltp":1.24,"tv":9134.88,"id":9624350},{"atb":[[1.25,0],[1.24,1002.33]],"id":9624350},{"atl":[[1.27,465.6],[1.25,285.02],[1.29,111]],"id":9624350}],"con":true,"img":false}]}
{"op":"mcm","clk":"1362118486","pt":1588428607325,"mc":[{"id":"1.170370557","rc":[{"atb":[[1.24,1090.99]],"id":9624350}],"con":true,"img":false}]}
{"op":"mcm","clk":"1362118491","pt":1588428607529,"mc":[{"id":"1.170370557","rc":[{"atl":[[1.25,777.04]],"id":9624350}],"con":true,"img":false}]}
{"op":"mcm","clk":"1362118495","pt":1588428607631,"mc":[{"id":"1.170370557","rc":[{"atb":[[1.24,443.26]],"id":9624350},{"atl":[[1.29,294.32]],"id":9624350}],"con":true,"img":false}]}
{"op":"mcm","clk":"1362118504","pt":1588428608192,"mc":[{"id":"1.170370557","rc":[{"atl":[[1.26,250]],"id":9624350}],"con":true,"img":false}]}
{"op":"mcm","clk":"1362118510","pt":1588428608500,"mc":[{"id":"1.170370557","rc":[{"atb":[[1.2,1226.48]],"id":9624350}],"con":true,"img":false}]}
{"op":"mcm","clk":"1362118512","pt":1588428608603,"mc":[{"id":"1.170370557","rc":[{"atb":[[1.2,1002.48],[1.21,896.09],[1.19,400],[1.23,0.86]],"id":9624350},{"atl":[[1.25,285.02]],"id":9624350}],"con":true,"img":false}]}
{"op":"mcm","clk":"1362118515","pt":1588428608807,"mc":[{"id":"1.170370557","rc":[{"atl":[[1.26,500]],"id":9624350}],"con":true,"img":false}]}
{"op":"mcm","clk":"1362118519","pt":1588428609114,"mc":[{"id":"1.170370557","rc":[{"atl":[[1.29,648.92]],"id":9624350}],"con":true,"img":false}]}
{"op":"mcm","clk":"1362118528","pt":1588428609834,"mc":[{"id":"1.170370557","rc":[{"trd":[[1.25,3041.77]],"ltp":1.25,"tv":3041.77,"id":9624350},{"atl":[[1.25,280.02]],"id":9624350}],"con":true,"img":false}]}
{"op":"mcm","clk":"1362118531","pt":1588428609886,"mc":[{"id":"1.170370557","rc":[{"atl":[[1.27,629.77]],"id":9624350}],"con":true,"img":false}]}
{"op":"mcm","clk":"1362118535","pt":1588428610090,"mc":[{"id":"1.170370557","rc":[{"atl":[[1.3,0]],"id":9624350}],"con":true,"img":false}]}
{"op":"mcm","clk":"1362118537","pt":1588428610193,"mc":[{"id":"1.170370557","rc":[{"atl":[[1.27,879.77]],"id":9624350}],"con":true,"img":false}]}
{"op":"mcm","clk":"1362118540","pt":1588428610297,"mc":[{"id":"1.170370557","rc":[{"trd":[[1.25,3130.43]],"ltp":1.25,"tv":3130.43,"id":9624350},{"atl":[[1.25,235.7]],"id":9624350}],"con":true,"img":false}]}
{"op":"mcm","clk":"1362118542","pt":1588428610401,"mc":[{"id":"1.170370557","rc":[{"trd":[[1.24,6326.93]],"ltp":1.24,"tv":6326.93,"id":9624350},{"atb":[[1.24,0]],"id":9624350}],"con":true,"img":false}]}
{"op":"mcm","clk":"1362118545","pt":1588428610503,"mc":[{"id":"1.170370557","rc":[{"trd":[[1.23,2569.69]],"ltp":1.23,"tv":2569.69,"id":9624350},{"atb":[[1.23,0]],"id":9624350},{"atl":[[1.22,279.09]],"id":9624350}],"con":true,"img":false}]}
{"op":"mcm","clk":"1362118559","pt":1588428611530,"mc":[{"id":"1.170370557","rc":[{"atl":[[1.29,801.77]],"id":9624350}],"con":true,"img":false}]}
{"op":"mcm","clk":"1362118563","pt":1588428611735,"mc":[{"id":"1.170370557","rc":[{"atl":[[1.22,722.35]],"id":9624350}],"con":true,"img":false}]}
{"op":"mcm","clk":"1362118570","pt":1588428612198,"mc":[{"id":"1.170370557","rc":[{"trd":[[1.21,2015.08]],"ltp":1.21,"tv":2015.08,"id":9624350},{"atb":[[1.21,452.82]],"id":9624350},{"atl":[[1.26,779.95]],"id":9624350}],"con":true,"img":false}]}
{"op":"mcm","clk":"1362118573","pt":1588428612404,"mc":[{"id":"1.170370557","rc":[{"atl":[[1.29,648.92],[1.24,184.68]],"id":9624350}],"con":true,"img":false}]}
{"op":"mcm","clk":"1362118575","pt":1588428612507,"mc":[{"id":"1.170370557","rc":[{"trd":[[1.22,3378.37]],"ltp":1.22,"tv":3378.37,"id":9624350},{"atl":[[1.22,721.88]],"id":9624350}],"con":true,"img":false}]}
{"op":"mcm","clk":"1362118578","pt":1588428612711,"mc":[{"id":"1.170370557","rc":[{"atl":[[1.24,464.64]],"id":9624350}],"con":true,"img":false}]}
{"op":"mcm","clk":"1362118586","pt":1588428613227,"mc":[{"id":"1.170370557","rc":[{"atl":[[1.26,1134.56]],"id":9624350}],"con":true,"img":false}]}
{"op":"mcm","clk":"1362118590","pt":1588428613434,"mc":[{"id":"1.170370557","rc":[{"atl":[[1.27,893.79]],"id":9624350}],"con":true,"img":false}]}
{"op":"mcm","clk":"1362118592","pt":1588428613537,"mc":[{"id":"1.170370557","rc":[{"atl":[[1.27,782.79],[1.29,537.92]],"id":9624350}],"con":true,"img":false}]}
{"op":"mcm","clk":"1362118597","pt":1588428613692,"mc":[{"id":"1.170370557","rc":[{"atl":[[1.22,1221.88]],"id":9624350}],"con":true,"img":false}]}
{"op":"mcm","clk":"1362118606","pt":1588428614409,"mc":[{"id":"1.170370557","rc":[{"trd":[[1.22,3555.67]],"ltp":1.22,"tv":3555.67,"id":9624350},{"atl":[[1.27,428.18],[1.22,1133.23],[1.24,704.64]],"id":9624350}],"con":true,"img":false}]}
{"op":"mcm","clk":"1362118608","pt":1588428614515,"mc":[{"id":"1.170370557","rc":[{"atl":[[1.22,189.96],[1.24,954.64]],"id":9624350}],"con":true,"img":false}]}
{"op":"mcm","clk":"1362118610","pt":1588428614617,"mc":[{"id":"1.170370557","rc":[{"trd":[[1.22,3732.98]],"ltp":1.22,"tv":3732.98,"id":9624350},{"atl":[[1.22,101.31]],"id":9624350}],"con":true,"img":false}]}
{"op":"mcm","clk":"1362118613","pt":1588428614822,"mc":[{"id":"1.170370557","rc":[{"atl":[[1.24,1204.64]],"id":9624350}],"con":true,"img":false}]}
{"op":"mcm","clk":"1362118615","pt":1588428614924,"mc":[{"id":"1.170370557","rc":[{"atl":[[1.23,192.72]],"id":9624350}],"con":true,"img":false}]}
{"op":"mcm","clk":"1362118618","pt":1588428615128,"mc":[{"id":"1.170370557","rc":[{"atl":[[1.29,354.6]],"id":9624350}],"con":true,"img":false}]}
{"op":"mcm","clk":"1362118625","pt":1588428615592,"mc":[{"id":"1.170370557","rc":[{"atb":[[1.16,492.02]],"id":9624350}],"con":true,"img":false}]}
{"op":"mcm","clk":"1362118627","pt":1588428615703,"mc":[{"id":"1.170370557","rc":[{"atl":[[1.23,442.72]],"id":9624350}],"con":true,"img":false}]}
{"op":"mcm","clk":"1362118632","pt":1588428616009,"mc":[{"id":"1.170370557","rc":[{"atl":[[1.23,975.37]],"id":9624350}],"con":true,"img":false}]}
{"op":"mcm","clk":"1362118634","pt":1588428616111,"mc":[{"id":"1.170370557","rc":[{"atl":[[1.23,1215.37]],"id":9624350}],"con":true,"img":false}]}
{"op":"mcm","clk":"1362118636","pt":1588428616213,"mc":[{"id":"1.170370557","rc":[{"atl":[[1.23,1304.02]],"id":9624350}],"con":true,"img":false}]}
{"op":"mcm","clk":"1362118638","pt":1588428616326,"mc":[{"id":"1.170370557","rc":[{"atl":[[1.23,1392.67],[1.22,341.31]],"id":9624350}],"con":true,"img":false}]}
{"op":"mcm","clk":"1362118640","pt":1588428616423,"mc":[{"id":"1.170370557","rc":[{"atl":[[1.22,785.31]],"id":9624350}],"con":true,"img":false}]}
{"op":"mcm","clk":"1362118642","pt":1588428616525,"mc":[{"id":"1.170370557","rc":[{"atb":[[1.15,492.02]],"id":9624350},{"atl":[[1.22,873.97]],"id":9624350}],"con":true,"img":false}]}
{"op":"mcm","clk":"1362118646","pt":1588428616730,"mc":[{"id":"1.170370557","rc":[{"atl":[[1.27,178.18],[1.22,962.62]],"id":9624350}],"con":true,"img":false}]}
{"op":"mcm","clk":"1362118650","pt":1588428616935,"mc":[{"id":"1.170370557","rc":[{"atl":[[1.22,1051.27]],"id":9624350}],"con":true,"img":false}]}
{"op":"mcm","clk":"1362118655","pt":1588428617140,"mc":[{"id":"1.170370557","rc":[{"atl":[[1.22,1291.27]],"id":9624350}],"con":true,"img":false}]}
{"op":"mcm","clk":"1362118661","pt":1588428617499,"mc":[{"id":"1.170370557","rc":[{"atl":[[1.22,1379.92]],"id":9624350}],"con":true,"img":false}]}
{"op":"mcm","clk":"1362118666","pt":1588428617704,"mc":[{"id":"1.170370557","rc":[{"atl":[[1.22,1468.58]],"id":9624350}],"con":true,"img":false}]}
{"op":"mcm","clk":"1362118673","pt":1588428618115,"mc":[{"id":"1.170370557","rc":[{"atl":[[1.24,1604.64]],"id":9624350}],"con":true,"img":false}]}
{"op":"mcm","clk":"1362118676","pt":1588428618319,"mc":[{"id":"1.170370557","rc":[{"atb":[[1.2,1445.74]],"id":9624350}],"con":true,"img":false}]}
{"op":"mcm","clk":"1362118678","pt":1588428618421,"mc":[{"id":"1.170370557","rc":[{"trd":[[1.22,3815.22]],"ltp":1.22,"tv":3815.22,"id":9624350},{"atl":[[1.22,1427.46]],"id":9624350}],"con":true,"img":false}]}
{"op":"mcm","clk":"1362118683","pt":1588428618626,"mc":[{"id":"1.170370557","rc":[{"atl":[[1.24,1706.16]],"id":9624350}],"con":true,"img":false}]}
{"op":"mcm","clk":"1362118686","pt":1588428618729,"mc":[{"id":"1.170370557","rc":[{"atl":[[1.23,1792.67]],"id":9624350}],"con":true,"img":false}]}
{"op":"mcm","clk":"1362118689","pt":1588428618934,"mc":[{"id":"1.170370557","rc":[{"trd":[[1.21,2887.2]],"ltp":1.21,"tv":2887.2,"id":9624350},{"atb":[[1.21,16.76]],"id":9624350}],"con":true,"img":false}]}
{"op":"mcm","clk":"1362118694","pt":1588428619138,"mc":[{"id":"1.170370557","rc":[{"atl":[[1.26,779.95]],"id":9624350}],"con":true,"img":false}]}
{"op":"mcm","clk":"1362118701","pt":1588428619502,"mc":[{"id":"1.170370557","rc":[{"trd":[[1.22,3865.88]],"ltp":1.22,"tv":3865.88,"id":9624350},{"atl":[[1.22,1402.12]],"id":9624350}],"con":true,"img":false}]}
{"op":"mcm","clk":"1362118703","pt":1588428619605,"mc":[{"id":"1.170370557","rc":[{"atl":[[1.23,2235.94]],"id":9624350}],"con":true,"img":false}]}
{"op":"mcm","clk":"1362118706","pt":1588428619708,"mc":[{"id":"1.170370557","rc":[{"atl":[[1.25,635.7],[1.24,1604.64]],"id":9624350}],"con":true,"img":false}]}
{"op":"mcm","clk":"1362118712","pt":1588428620015,"mc":[{"id":"1.170370557","rc":[{"atl":[[1.29,0]],"id":9624350}],"con":true,"img":false}]}
{"op":"mcm","clk":"1362118714","pt":1588428620117,"mc":[{"id":"1.170370557","rc":[{"atl":[[1.23,1995.94]],"id":9624350}],"con":true,"img":false}]}
{"op":"mcm","clk":"1362118731","pt":1588428621299,"mc":[{"id":"1.170370557","rc":[{"atl":[[1.22,1490.78]],"id":9624350}],"con":true,"img":false}]}
{"op":"mcm","clk":"1362118733","pt":1588428621402,"mc":[{"id":"1.170370557","rc":[{"atl":[[1.22,1579.43]],"id":9624350}],"con":true,"img":false}]}
{"op":"mcm","clk":"1362118750","pt":1588428622326,"mc":[{"id":"1.170370557","rc":[{"atl":[[1.23,2487.96]],"id":9624350}],"con":true,"img":false}]}
{"op":"mcm","clk":"1362118758","pt":1588428622836,"mc":[{"id":"1.170370557","rc":[{"atl":[[1.26,279.95],[1.23,2237.96],[1.24,1104.64]],"id":9624350}],"con":true,"img":false}]}
{"op":"mcm","clk":"1362118762","pt":1588428623040,"mc":[{"id":"1.170370557","rc":[{"atl":[[1.23,1793.96],[1.22,1135.43]],"id":9624350}],"con":true,"img":false}]}
{"op":"mcm","clk":"1362118768","pt":1588428623403,"mc":[{"id":"1.170370557","rc":[{"atb":[[1.21,105.41]],"id":9624350}],"con":true,"img":false}]}
{"op":"mcm","clk":"1362118771","pt":1588428623605,"mc":[{"id":"1.170370557","rc":[{"atb":[[1.21,194.06]],"id":9624350}],"con":true,"img":false}]}
{"op":"mcm","clk":"1362118773","pt":1588428623707,"mc":[{"id":"1.170370557","rc":[{"atl":[[1.22,1535.43]],"id":9624350}],"con":true,"img":false}]}
{"op":"mcm","clk":"1362118775","pt":1588428623810,"mc":[{"id":"1.170370557","rc":[{"atb":[[1.21,282.72]],"id":9624350}],"con":true,"img":false}]}
{"op":"mcm","clk":"1362118778","pt":1588428624014,"mc":[{"id":"1.170370557","rc":[{"atb":[[1.21,371.37]],"id":9624350}],"con":true,"img":false}]}
{"op":"mcm","clk":"1362118781","pt":1588428624220,"mc":[{"id":"1.170370557","rc":[{"atl":[[1.22,2302.58]],"id":9624350}],"con":true,"img":false}]}
{"op":"mcm","clk":"1362118783","pt":1588428624322,"mc":[{"id":"1.170370557","rc":[{"trd":[[1.22,3953.47]],"ltp":1.22,"tv":3953.47,"id":9624350},{"atl":[[1.22,2258.78]],"id":9624350}],"con":true,"img":false}]}
{"op":"mcm","clk":"1362118787","pt":1588428624527,"mc":[{"id":"1.170370557","rc":[{"atb":[[1.21,460.02]],"id":9624350}],"con":true,"img":false}]}
{"op":"mcm","clk":"1362118791","pt":1588428624731,"mc":[{"id":"1.170370557","rc":[{"atb":[[1.21,548.67]],"id":9624350}],"con":true,"img":false}]}
{"op":"mcm","clk":"1362118793","pt":1588428624834,"mc":[{"id":"1.170370557","rc":[{"atb":[[1.21,637.33]],"id":9624350}],"con":true,"img":false}]}
{"op":"mcm","clk":"1362118804","pt":1588428625551,"mc":[{"id":"1.170370557","rc":[{"trd":[[1.21,3686.5]],"ltp":1.21,"tv":3686.5,"id":9624350},{"atb":[[1.21,237.67]],"id":9624350}],"con":true,"img":false}]}
{"op":"mcm","clk":"1362118822","pt":1588428626522,"mc":[{"id":"1.170370557","rc":[{"atl":[[1.23,1601.24],[1.27,14.01],[1.24,919.95]],"id":9624350}],"con":true,"img":false}]}
{"op":"mcm","clk":"1362118826","pt":1588428626830,"mc":[{"id":"1.170370557","rc":[{"trd":[[1.21,3754.28],[1.22,3959.15]],"ltp":1.21,"tv":7713.43,"id":9624350},{"atb":[[1.21,208.78]],"id":9624350},{"atl":[[1.22,2255.94]],"id":9624350}],"con":true,"img":false}]}
{"op":"mcm","clk":"1362118834","pt":1588428627555,"mc":[{"id":"1.170370557","rc":[{"trd":[[1.22,3960.49]],"ltp":1.22,"tv":3960.49,"id":9624350},{"atl":[[1.22,2255.27]],"id":9624350}],"con":true,"img":false}]}
{"op":"mcm","clk":"1362118839","pt":1588428627914,"mc":[{"id":"1.170370557","rc":[{"trd":[[1.22,3965.65]],"ltp":1.22,"tv":3965.65,"id":9624350},{"atb":[[1.21,277.56]],"id":9624350},{"atl":[[1.22,2252.69]],"id":9624350}],"con":true,"img":false}]}
{"op":"mcm","clk":"1362118849","pt":1588428628842,"mc":[{"id":"1.170370557","rc":[{"trd":[[1.22,4135.22]],"ltp":1.22,"tv":4135.22,"id":9624350},{"atl":[[1.22,2167.9]],"id":9624350}],"con":true,"img":false}]}
{"op":"mcm","clk":"1362118851","pt":1588428628944,"mc":[{"id":"1.170370557","rc":[{"atl":[[1.23,1335.28],[1.24,679.95]],"id":9624350}],"con":true,"img":false}]}
{"op":"mcm","clk":"1362118857","pt":1588428629353,"mc":[{"id":"1.170370557","rc":[{"trd":[[1.22,4207.88]],"ltp":1.22,"tv":4207.88,"id":9624350},{"atl":[[1.22,2131.57]],"id":9624350}],"con":true,"img":false}]}
{"op":"mcm","clk":"1362118859","pt":1588428629455,"mc":[{"id":"1.170370557","rc":[{"trd":[[1.22,4212.6]],"ltp":1.22,"tv":4212.6,"id":9624350},{"atl":[[1.22,2129.21]],"id":9624350}],"con":true,"img":false}]}
{"op":"mcm","clk":"1362118868","pt":1588428629916,"mc":[{"id":"1.170370557","rc":[{"trd":[[1.22,4213.42]],"ltp":1.22,"tv":4213.42,"id":9624350},{"atl":[[1.22,2128.8]],"id":9624350}],"con":true,"img":false}]}
{"op":"mcm","clk":"1362118881","pt":1588428630635,"mc":[{"id":"1.170370557","rc":[{"trd":[[1.21,4309.41]],"ltp":1.21,"tv":4309.41,"id":9624350},{"atb":[[1.21,0]],"id":9624350},{"atl":[[1.21,526.11]],"id":9624350}],"con":true,"img":false}]}
{"op":"mcm","clk":"1362118895","pt":1588428631247,"mc":[{"id":"1.170370557","rc":[{"atb":[[1.2,1002.48]],"id":9624350}],"con":true,"img":false}]}
{"op":"mcm","clk":"1362118899","pt":1588428631452,"mc":[{"id":"1.170370557","rc":[{"trd":[[1.21,4313.53]],"ltp":1.21,"tv":4313.53,"id":9624350},{"atl":[[1.21,524.05]],"id":9624350}],"con":true,"img":false}]}
{"op":"mcm","clk":"1362118903","pt":1588428631553,"mc":[{"id":"1.170370557","rc":[{"atl":[[1.21,0],[1.22,2174.22]],"id":9624350}],"con":true,"img":false}]}
{"op":"mcm","clk":"1362118908","pt":1588428631758,"mc":[{"id":"1.170370557","rc":[{"atb":[[1.21,79.18]],"id":9624350}],"con":true,"img":false}]}
{"op":"mcm","clk":"1362118913","pt":1588428631963,"mc":[{"id":"1.170370557","rc":[{"trd":[[1.22,4218.58]],"ltp":1.22,"tv":4218.58,"id":9624350},{"atl":[[1.22,2171.64]],"id":9624350}],"con":true,"img":false}]}
{"op":"mcm","clk":"1362118939","pt":1588428633651,"mc":[{"id":"1.170370557","rc":[{"trd":[[1.22,4236.31]],"ltp":1.22,"tv":4236.31,"id":9624350},{"atl":[[1.22,2162.77]],"id":9624350}],"con":true,"img":false}]}
{"op":"mcm","clk":"1362118942","pt":1588428633754,"mc":[{"id":"1.170370557","rc":[{"trd":[[1.21,4412.67]],"ltp":1.21,"tv":4412.67,"id":9624350},{"atb":[[1.21,29.61]],"id":9624350}],"con":true,"img":false}]}
{"op":"mcm","clk":"1362118960","pt":1588428634732,"mc":[{"id":"1.170370557","rc":[{"atb":[[1.21,105.78]],"id":9624350}],"con":true,"img":false}]}
{"op":"mcm","clk":"1362118962","pt":1588428634834,"mc":[{"id":"1.170370557","rc":[{"trd":[[1.22,4237.69]],"ltp":1.22,"tv":4237.69,"id":9624350},{"atl":[[1.22,2162.08]],"id":9624350}],"con":true,"img":false}]}
{"op":"mcm","clk":"1362118966","pt":1588428635141,"mc":[{"id":"1.170370557","rc":[{"trd":[[1.22,4237.71]],"ltp":1.22,"tv":4237.71,"id":9624350},{"atl":[[1.22,2162.07]],"id":9624350}],"con":true,"img":false}]}
{"op":"mcm","clk":"1362118969","pt":1588428635345,"mc":[{"id":"1.170370557","rc":[{"trd":[[5.5,612.23]],"ltp":5.5,"tv":612.23,"id":9622734},{"atl":[[5.5,261.33]],"id":9622734},{"trd":[[1.22,6399.79]],"ltp":1.22,"tv":6399.79,"id":9624350},{"atl":[[1.22,0]],"id":9624350}],"con":true,"img":false}]}
{"op":"mcm","clk":"1362118980","pt":1588428636063,"mc":[{"id":"1.170370557","rc":[{"atb":[[1.22,100]],"id":9624350}],"con":true,"img":false}]}
{"op":"mcm","clk":"1362118982","pt":1588428636165,"mc":[{"id":"1.170370557","rc":[{"atb":[[1.2,956.11]],"id":9624350}],"con":true,"img":false}]}
{"op":"mcm","clk":"1362118986","pt":1588428636323,"mc":[{"id":"1.170370557","rc":[{"atb":[[1.19,843.26]],"id":9624350}],"con":true,"img":false}]}
{"op":"mcm","clk":"1362118988","pt":1588428636425,"mc":[{"id":"1.170370557","rc":[{"atb":[[1.22,140]],"id":9624350}],"con":true,"img":false}]}
{"op":"mcm","clk":"1362119011","pt":1588428638265,"mc":[{"id":"1.170370557","rc":[{"atb":[[1.19,931.91]],"id":9624350}],"con":true,"img":false}]}
{"op":"mcm","clk":"1362119013","pt":1588428638367,"mc":[{"id":"1.170370557","rc":[{"atb":[[1.19,1020.56]],"id":9624350}],"con":true,"img":false}]}
{"op":"mcm","clk":"1362119017","pt":1588428638571,"mc":[{"id":"1.170370557","rc":[{"atb":[[1.19,1109.21]],"id":9624350}],"con":true,"img":false}]}
{"op":"mcm","clk":"1362119026","pt":1588428638933,"mc":[{"id":"1.170370557","rc":[{"atb":[[1.22,142.62]],"id":9624350}],"con":true,"img":false}]}
{"op":"mcm","clk":"1362119037","pt":1588428639546,"mc":[{"id":"1.170370557","rc":[{"trd":[[5.5,812.23]],"ltp":5.5,"tv":812.23,"id":9622734},{"atl":[[5.5,161.33]],"id":9622734}],"con":true,"img":false}]}
{"op":"mcm","clk":"1362119048","pt":1588428640468,"mc":[{"id":"1.170370557","rc":[{"atb":[[1.21,357.17]],"id":9624350}],"con":true,"img":false}]}
{"op":"mcm","clk":"1362119061","pt":1588428641545,"mc":[{"id":"1.170370557","rc":[{"trd":[[1.23,2571.07]],"ltp":1.23,"tv":2571.07,"id":9624350},{"atl":[[1.23,1334.59]],"id":9624350}],"con":true,"img":false}]}
{"op":"mcm","clk":"1362119066","pt":1588428641852,"mc":[{"id":"1.170370557","rc":[{"trd":[[1.23,2748.37]],"ltp":1.23,"tv":2748.37,"id":9624350},{"atl":[[1.23,1245.94]],"id":9624350}],"con":true,"img":false}]}
{"op":"mcm","clk":"1362119068","pt":1588428641954,"mc":[{"id":"1.170370557","rc":[{"trd":[[1.23,2925.67]],"ltp":1.23,"tv":2925.67,"id":9624350},{"atb":[[1.21,608.55]],"id":9624350},{"atl":[[1.23,1157.29]],"id":9624350}],"con":true,"img":false}]}
{"op":"mcm","clk":"1362119072","pt":1588428642160,"mc":[{"id":"1.170370557","rc":[{"trd":[[1.23,3102.98]],"ltp":1.23,"tv":3102.98,"id":9624350},{"atb":[[1.21,1008.55]],"id":9624350},{"atl":[[1.23,1068.64]],"id":9624350}],"con":true,"img":false}]}
{"op":"mcm","clk":"1362119075","pt":1588428642262,"mc":[{"id":"1.170370557","rc":[{"atb":[[1.22,145.56]],"id":9624350},{"atl":[[1.24,705.62]],"id":9624350}],"con":true,"img":false}]}
{"op":"mcm","clk":"1362119077","pt":1588428642365,"mc":[{"id":"1.170370557","rc":[{"atb":[[1.22,105.56]],"id":9624350}],"con":true,"img":false}]}
{"op":"mcm","clk":"1362119080","pt":1588428642467,"mc":[{"id":"1.170370557","rc":[{"trd":[[1.23,3280.28]],"ltp":1.23,"tv":3280.28,"id":9624350},{"atl":[[1.23,979.99]],"id":9624350}],"con":true,"img":false}]}
{"op":"mcm","clk":"1362119088","pt":1588428642774,"mc":[{"id":"1.170370557","rc":[{"trd":[[1.23,3634.89]],"ltp":1.23,"tv":3634.89,"id":9624350},{"atl":[[1.23,802.68]],"id":9624350}],"con":true,"img":false}]}
{"op":"mcm","clk":"1362119097","pt":1588428643336,"mc":[{"id":"1.170370557","rc":[{"atb":[[1.21,1259.94]],"id":9624350}],"con":true,"img":false}]}
{"op":"mcm","clk":"1362119112","pt":1588428644361,"mc":[{"id":"1.170370557","rc":[{"atb":[[5.4,64.6]],"id":9622734}],"con":true,"img":false}]}
{"op":"mcm","clk":"1362119134","pt":1588428645385,"mc":[{"id":"1.170370557","rc":[{"trd":[[1.23,3727.62]],"ltp":1.23,"tv":3727.62,"id":9624350},{"atl":[[1.23,756.32]],"id":9624350}],"con":true,"img":false}]}
{"op":"mcm","clk":"1362119141","pt":1588428645641,"mc":[{"id":"1.170370557","rc":[{"trd":[[1.23,3827.62]],"ltp":1.23,"tv":3827.62,"id":9624350},{"atb":[[1.19,843.26]],"id":9624350},{"atl":[[1.23,706.32]],"id":9624350}],"con":true,"img":false}]}
{"op":"mcm","clk":"1362119148","pt":1588428645951,"mc":[{"id":"1.170370557","rc":[{"atb":[[1.22,956.38]],"id":9624350}],"con":true,"img":false}]}
{"op":"mcm","clk":"1362119175","pt":1588428647285,"mc":[{"id":"1.170370557","rc":[{"atb":[[1.22,956.61]],"id":9624350}],"con":true,"img":false}]}
{"op":"mcm","clk":"1362119183","pt":1588428647644,"mc":[{"id":"1.170370557","rc":[{"atb":[[1.21,1348.59]],"id":9624350}],"con":true,"img":false}]}
{"op":"mcm","clk":"1362119185","pt":1588428647747,"mc":[{"id":"1.170370557","rc":[{"trd":[[1.23,3828.08]],"ltp":1.23,"tv":3828.08,"id":9624350},{"atl":[[1.23,706.09]],"id":9624350}],"con":true,"img":false}]}
{"op":"mcm","clk":"1362119187","pt":1588428647851,"mc":[{"id":"1.170370557","rc":[{"atb":[[1.21,1437.24]],"id":9624350}],"con":true,"img":false}]}
{"op":"mcm","clk":"1362119189","pt":1588428647953,"mc":[{"id":"1.170370557","rc":[{"atb":[[1.21,1525.89]],"id":9624350}],"con":true,"img":false}]}
{"op":"mcm","clk":"1362119193","pt":1588428648157,"mc":[{"id":"1.170370557","rc":[{"atb":[[1.22,1356.61]],"id":9624350}],"con":true,"img":false}]}
{"op":"mcm","clk":"1362119195","pt":1588428648260,"mc":[{"id":"1.170370557","rc":[{"atb":[[1.21,1614.55]],"id":9624350}],"con":true,"img":false}]}
{"op":"mcm","clk":"1362119201","pt":1588428648466,"mc":[{"id":"1.170370557","rc":[{"atb":[[1.2,916.11],[1.21,1703.2]],"id":9624350}],"con":true,"img":false}]}
{"op":"mcm","clk":"1362119203","pt":1588428648568,"mc":[{"id":"1.170370557","rc":[{"atb":[[1.21,1791.85]],"id":9624350}],"con":true,"img":false}]}
{"op":"mcm","clk":"1362119209","pt":1588428648875,"mc":[{"id":"1.170370557","rc":[{"atb":[[1.21,2043.23]],"id":9624350}],"con":true,"img":false}]}
{"op":"mcm","clk":"1362119214","pt":1588428649079,"mc":[{"id":"1.170370557","rc":[{"atl":[[5.5,0]],"id":9622734}],"con":true,"img":false}]}
{"op":"mcm","clk":"1362119220","pt":1588428649345,"mc":[{"id":"1.170370557","rc":[{"atb":[[1.22,1596.61]],"id":9624350}],"con":true,"img":false}]}
{"op":"mcm","clk":"1362119227","pt":1588428649652,"mc":[{"id":"1.170370557","rc":[{"trd":[[5.4,112.72]],"ltp":5.4,"tv":112.72,"id":9622734},{"atb":[[5.4,62.69]],"id":9622734},{"atb":[[1.21,2283.23]],"id":9624350}],"con":true,"img":false}]}
{"op":"mcm","clk":"1362119252","pt":1588428650984,"mc":[{"id":"1.170370557","rc":[{"atb":[[1.22,2039.87]],"id":9624350}],"con":true,"img":false}]}
{"op":"mcm","clk":"1362119279","pt":1588428652062,"mc":[{"id":"1.170370557","rc":[{"atb":[[1.22,2039.64]],"id":9624350}],"con":true,"img":false}]}
{"op":"mcm","clk":"1362119295","pt":1588428653085,"mc":[{"id":"1.170370557","rc":[{"atb":[[1.22,2037.02]],"id":9624350}],"con":true,"img":false}]}
{"op":"mcm","clk":"1362119300","pt":1588428653495,"mc":[{"id":"1.170370557","rc":[{"trd":[[1.23,3908.08]],"ltp":1.23,"tv":3908.08,"id":9624350},{"atl":[[1.23,666.09]],"id":9624350}],"con":true,"img":false}]}
{"op":"mcm","clk":"1362119305","pt":1588428653750,"mc":[{"id":"1.170370557","rc":[{"atb":[[1.22,2276.98]],"id":9624350}],"con":true,"img":false}]}
{"op":"mcm","clk":"1362119312","pt":1588428654160,"mc":[{"id":"1.170370557","rc":[{"trd":[[5.3,149.69],[5.4,238.11]],"ltp":5.3,"tv":387.8,"id":9622734},{"atb":[[5.4,0]],"id":9622734},{"trd":[[1.23,4333.07]],"ltp":1.23,"tv":4333.07,"id":9624350},{"atl":[[1.23,241.09]],"id":9624350}],"con":true,"img":false}]}
{"op":"mcm","clk":"1362119316","pt":1588428654364,"mc":[{"id":"1.170370557","rc":[{"trd":[[5.3,149.99]],"ltp":5.3,"tv":149.99,"id":9622734},{"trd":[[1.23,4334.34]],"ltp":1.23,"tv":4334.34,"id":9624350},{"atl":[[1.23,239.83]],"id":9624350}],"con":true,"img":false}]}
{"op":"mcm","clk":"1362119324","pt":1588428654670,"mc":[{"id":"1.170370557","rc":[{"atl":[[5.4,50]],"id":9622734}],"con":true,"img":false}]}
{"op":"mcm","clk":"1362119331","pt":1588428655079,"mc":[{"id":"1.170370557","rc":[{"atl":[[1.26,799.2]],"id":9624350}],"con":true,"img":false}]}
{"op":"mcm","clk":"1362119343","pt":1588428655692,"mc":[{"id":"1.170370557","rc":[{"atl":[[1.23,0]],"id":9624350}],"con":true,"img":false}]}
{"op":"mcm","clk":"1362119348","pt":1588428655897,"mc":[{"id":"1.170370557","rc":[{"atb":[[1.14,0]],"id":9624350}],"con":true,"img":false}]}
{"op":"mcm","clk":"1362119363","pt":1588428656565,"mc":[{"id":"1.170370557","rc":[{"atb":[[1.15,0]],"id":9624350}],"con":true,"img":false}]}
{"op":"mcm","clk":"1362119376","pt":1588428657180,"mc":[{"id":"1.170370557","rc":[{"atb":[[1.16,0],[1.22,2516.94]],"id":9624350}],"con":true,"img":false}]}
{"op":"mcm","clk":"1362119378","pt":1588428657282,"mc":[{"id":"1.170370557","rc":[{"atb":[[1.21,1751.32],[1.23,20]],"id":9624350}],"con":true,"img":false}]}
{"op":"mcm","clk":"1362119385","pt":1588428657692,"mc":[{"id":"1.170370557","rc":[{"trd":[[1.23,4334.58]],"ltp":1.23,"tv":4334.58,"id":9624350},{"atb":[[1.23,19.88],[1.17,400]],"id":9624350}],"con":true,"img":false}]}
{"op":"mcm","clk":"1362119393","pt":1588428658205,"mc":[{"id":"1.170370557","rc":[{"atb":[[1.18,400],[1.23,39.88]],"id":9624350}],"con":true,"img":false}]}
{"op":"mcm","clk":"1362119396","pt":1588428658307,"mc":[{"id":"1.170370557","rc":[{"atb":[[1.23,41.73]],"id":9624350}],"con":true,"img":false}]}
{"op":"mcm","clk":"1362119420","pt":1588428659491,"mc":[{"id":"1.170370557","rc":[{"atb":[[1.23,219.03],[1.22,2771.19]],"id":9624350}],"con":true,"img":false}]}
{"op":"mcm","clk":"1362119426","pt":1588428659696,"mc":[{"id":"1.170370557","rc":[{"atb":[[1.23,276.85]],"id":9624350}],"con":true,"img":false}]}
{"op":"mcm","clk":"1362119435","pt":1588428660209,"mc":[{"id":"1.170370557","rc":[{"atb":[[1.23,516.85]],"id":9624350}],"con":true,"img":false}]}
{"op":"mcm","clk":"1362119445","pt":1588428660670,"mc":[{"id":"1.170370557","rc":[{"trd":[[1.23,4342.72]],"ltp":1.23,"tv":4342.72,"id":9624350},{"atb":[[1.23,512.78]],"id":9624350}],"con":true,"img":false}]}
{"op":"mcm","clk":"1362119447","pt":1588428660772,"mc":[{"id":"1.170370557","rc":[{"atl":[[1.24,305.62]],"id":9624350}],"con":true,"img":false}]}
{"op":"mcm","clk":"1362119459","pt":1588428661387,"mc":[{"id":"1.170370557","rc":[{"atb":[[1.23,1756.69]],"id":9624350}],"con":true,"img":false}]}
{"op":"mcm","clk":"1362119470","pt":1588428662002,"mc":[{"id":"1.170370557","rc":[{"trd":[[1.23,4406.3]],"ltp":1.23,"tv":4406.3,"id":9624350},{"atb":[[1.23,1724.9]],"id":9624350}],"con":true,"img":false}]}
{"op":"mcm","clk":"1362119474","pt":1588428662207,"mc":[{"id":"1.170370557","rc":[{"atb":[[1.22,2859.85]],"id":9624350}],"con":true,"img":false}]}
{"op":"mcm","clk":"1362119477","pt":1588428662310,"mc":[{"id":"1.170370557","rc":[{"atb":[[1.23,1964.9]],"id":9624350}],"con":true,"img":false}]}
{"op":"mcm","clk":"1362119479","pt":1588428662413,"mc":[{"id":"1.170370557","rc":[{"atb":[[1.22,2948.5]],"id":9624350}],"con":true,"img":false}]}
{"op":"mcm","clk":"1362119483","pt":1588428662567,"mc":[{"id":"1.170370557","rc":[{"atb":[[1.22,3037.15]],"id":9624350}],"con":true,"img":false}]}
{"op":"mcm","clk":"1362119489","pt":1588428662772,"mc":[{"id":"1.170370557","rc":[{"atb":[[1.22,3125.8]],"id":9624350}],"con":true,"img":false}]}
{"op":"mcm","clk":"1362119494","pt":1588428662977,"mc":[{"id":"1.170370557","rc":[{"atb":[[1.23,1966.91],[1.22,3214.46]],"id":9624350}],"con":true,"img":false}]}
{"op":"mcm","clk":"1362119507","pt":1588428663802,"mc":[{"id":"1.170370557","rc":[{"atb":[[1.23,1967.1]],"id":9624350}],"con":true,"img":false}]}
{"op":"mcm","clk":"1362119509","pt":1588428663905,"mc":[{"id":"1.170370557","rc":[{"trd":[[1.23,4677.37]],"ltp":1.23,"tv":4677.37,"id":9624350},{"atb":[[1.23,1829.71]],"id":9624350}],"con":true,"img":false}]}
{"op":"mcm","clk":"1362119512","pt":1588428664111,"mc":[{"id":"1.170370557","rc":[{"atl":[[1.24,279.95]],"id":9624350}],"con":true,"img":false}]}
{"op":"mcm","clk":"1362119529","pt":1588428665599,"mc":[{"id":"1.170370557","rc":[{"atb":[[1.23,1827.7]],"id":9624350}],"con":true,"img":false}]}
{"op":"mcm","clk":"1362119536","pt":1588428665911,"mc":[{"id":"1.170370557","rc":[{"atb":[[1.23,1847.7]],"id":9624350}],"con":true,"img":false}]}
{"op":"mcm","clk":"1362119552","pt":1588428666884,"mc":[{"id":"1.170370557","rc":[{"atb":[[1.23,1847.93]],"id":9624350}],"con":true,"img":false}]}
{"op":"mcm","clk":"1362119562","pt":1588428667399,"mc":[{"id":"1.170370557","rc":[{"atl":[[1.24,299.95]],"id":9624350}],"con":true,"img":false}]}
{"op":"mcm","clk":"1362119583","pt":1588428668270,"mc":[{"id":"1.170370557","rc":[{"atl":[[1.24,319.95]],"id":9624350}],"con":true,"img":false}]}
{"op":"mcm","clk":"1362119614","pt":1588428669908,"mc":[{"id":"1.170370557","rc":[{"atb":[[1.22,3211.52]],"id":9624350}],"con":true,"img":false}]}
{"op":"mcm","clk":"1362119619","pt":1588428670214,"mc":[{"id":"1.170370557","rc":[{"trd":[[1.24,6346.93],[1.23,4804.32]],"ltp":1.24,"tv":11151.25,"id":9624350},{"atb":[[1.23,1784.27]],"id":9624350},{"atl":[[1.24,309.95]],"id":9624350}],"con":true,"img":false}]}
{"op":"mcm","clk":"1362119629","pt":1588428670778,"mc":[{"id":"1.170370557","rc":[{"atb":[[1.23,1784.04]],"id":9624350}],"con":true,"img":false}]}
{"op":"mcm","clk":"1362119635","pt":1588428671084,"mc":[{"id":"1.170370557","rc":[{"trd":[[1.24,6352.18]],"ltp":1.24,"tv":6352.18,"id":9624350},{"atl":[[1.24,307.33]],"id":9624350}],"con":true,"img":false}]}
{"op":"mcm","clk":"1362119645","pt":1588428671494,"mc":[{"id":"1.170370557","rc":[{"trd":[[1.24,6832.18]],"ltp":1.24,"tv":6832.18,"id":9624350},{"atl":[[1.24,67.33]],"id":9624350}],"con":true,"img":false}]}
{"op":"mcm","clk":"1362119648","pt":1588428671596,"mc":[{"id":"1.170370557","rc":[{"atl":[[1.24,87.33]],"id":9624350}],"con":true,"img":false}]}
{"op":"mcm","clk":"1362119683","pt":1588428672824,"mc":[{"id":"1.170370557","rc":[{"trd":[[1.24,6835.73]],"ltp":1.24,"tv":6835.73,"id":9624350},{"atl":[[1.24,85.55]],"id":9624350}],"con":true,"img":false}]}
{"op":"mcm","clk":"1362119713","pt":1588428674410,"mc":[{"id":"1.170370557","rc":[{"atl":[[1.24,25.55]],"id":9624350}],"con":true,"img":false}]}
{"op":"mcm","clk":"1362119717","pt":1588428674616,"mc":[{"id":"1.170370557","rc":[{"atl":[[1.25,235.7]],"id":9624350}],"con":true,"img":false}]}
{"op":"mcm","clk":"1362119736","pt":1588428675411,"mc":[{"id":"1.170370557","rc":[{"trd":[[1.23,4805.4]],"ltp":1.23,"tv":4805.4,"id":9624350},{"atb":[[1.23,1783.5]],"id":9624350}],"con":true,"img":false}]}
{"op":"mcm","clk":"1362119739","pt":1588428675515,"mc":[{"id":"1.170370557","rc":[{"trd":[[1.24,6839.75]],"ltp":1.24,"tv":6839.75,"id":9624350},{"atl":[[1.24,23.54]],"id":9624350}],"con":true,"img":false}]}
{"op":"mcm","clk":"1362119745","pt":1588428675825,"mc":[{"id":"1.170370557","rc":[{"trd":[[1.25,3368.92],[1.24,6886.84]],"ltp":1.25,"tv":10255.76,"id":9624350},{"atl":[[1.25,116.45],[1.24,0]],"id":9624350}],"con":true,"img":false}]}
{"op":"mcm","clk":"1362119774","pt":1588428677928,"mc":[{"id":"1.170370557","rc":[{"atl":[[5.1,2.09]],"id":9622734},{"atl":[[1.25,379.99]],"id":9624350}],"con":true,"img":false}]}
{"op":"mcm","clk":"1362119787","pt":1588428678695,"mc":[{"id":"1.170370557","rc":[{"atb":[[1.23,1763.5]],"id":9624350}],"con":true,"img":false}]}
{"op":"mcm","clk":"1362119790","pt":1588428678797,"mc":[{"id":"1.170370557","rc":[{"atb":[[1.21,1351.32]],"id":9624350}],"con":true,"img":false}]}
{"op":"mcm","clk":"1362119800","pt":1588428679206,"mc":[{"id":"1.170370557","rc":[{"trd":[[5.1,125.41]],"ltp":5.1,"tv":125.41,"id":9622734},{"atl":[[5.1,0]],"id":9622734},{"trd":[[1.23,4818.15],[1.24,6895.47]],"ltp":1.23,"tv":11713.61,"id":9624350},{"atb":[[1.23,1757.12]],"id":9624350}],"con":true,"img":false}]}
{"op":"mcm","clk":"1362119803","pt":1588428679309,"mc":[{"id":"1.170370557","rc":[{"atb":[[1.2,516.11]],"id":9624350}],"con":true,"img":false}]}
{"op":"mcm","clk":"1362119809","pt":1588428679615,"mc":[{"id":"1.170370557","rc":[{"atb":[[1.24,132.97]],"id":9624350}],"con":true,"img":false}]}
{"op":"mcm","clk":"1362119816","pt":1588428680024,"mc":[{"id":"1.170370557","rc":[{"trd":[[1.24,6895.95]],"ltp":1.24,"tv":6895.95,"id":9624350},{"atb":[[1.24,132.73]],"id":9624350}],"con":true,"img":false}]}
{"op":"mcm","clk":"1362119827","pt":1588428680484,"mc":[{"id":"1.170370557","rc":[{"atl":[[1.25,399.99]],"id":9624350}],"con":true,"img":false}]}
{"op":"mcm","clk":"1362119834","pt":1588428680996,"mc":[{"id":"1.170370557","rc":[{"atl":[[1.25,419.99]],"id":9624350}],"con":true,"img":false}]}
{"op":"mcm","clk":"1362119836","pt":1588428681200,"mc":[{"id":"1.170370557","rc":[{"atl":[[1.5,0]],"id":9624350}],"con":true,"img":false}]}
{"op":"mcm","clk":"1362119838","pt":1588428681303,"mc":[{"id":"1.170370557","rc":[{"atb":[[1.22,2768.26]],"id":9624350}],"con":true,"img":false}]}
{"op":"mcm","clk":"1362119845","pt":1588428681813,"mc":[{"id":"1.170370557","rc":[{"atb":[[1.21,1275.15]],"id":9624350}],"con":true,"img":false}]}
{"op":"mcm","clk":"1362119848","pt":1588428682021,"mc":[{"id":"1.170370557","rc":[{"atb":[[1.24,150.46]],"id":9624350}],"con":true,"img":false}]}
{"op":"mcm","clk":"1362119850","pt":1588428682123,"mc":[{"id":"1.170370557","rc":[{"atb":[[1.24,153.4]],"id":9624350}],"con":true,"img":false}]}
{"op":"mcm","clk":"1362119852","pt":1588428682226,"mc":[{"id":"1.170370557","rc":[{"atl":[[1.27,0]],"id":9624350}],"con":true,"img":false}]}
{"op":"mcm","clk":"1362119854","pt":1588428682328,"mc":[{"id":"1.170370557","rc":[{"atb":[[1.19,400]],"id":9624350}],"con":true,"img":false}]}
{"op":"mcm","clk":"1362119858","pt":1588428682635,"mc":[{"id":"1.170370557","rc":[{"atb":[[1.19,0]],"id":9624350}],"con":true,"img":false}]}
{"op":"mcm","clk":"1362119862","pt":1588428682896,"mc":[{"id":"1.170370557","rc":[{"atb":[[1.24,373.37]],"id":9624350}],"con":true,"img":false}]}
{"op":"mcm","clk":"1362119868","pt":1588428683199,"mc":[{"id":"1.170370557","rc":[{"atb":[[1.18,0]],"id":9624350}],"con":true,"img":false}]}
{"op":"mcm","clk":"1362119877","pt":1588428683612,"mc":[{"id":"1.170370557","rc":[{"atb":[[1.17,0]],"id":9624350}],"con":true,"img":false}]}
{"op":"mcm","clk":"1362119895","pt":1588428684597,"mc":[{"id":"1.170370557","rc":[{"atb":[[1.24,816.63]],"id":9624350}],"con":true,"img":false}]}
{"op":"mcm","clk":"1362119905","pt":1588428685109,"mc":[{"id":"1.170370557","rc":[{"atb":[[1.21,269.61]],"id":9624350}],"con":true,"img":false}]}
{"op":"mcm","clk":"1362119909","pt":1588428685313,"mc":[{"id":"1.170370557","rc":[{"atb":[[1.22,2528.26]],"id":9624350},{"atl":[[1.27,443.26]],"id":9624350}],"con":true,"img":false}]}
{"op":"mcm","clk":"1362119919","pt":1588428685828,"mc":[{"id":"1.170370557","rc":[{"atb":[[1.22,2048.33]],"id":9624350}],"con":true,"img":false}]}
{"op":"mcm","clk":"1362119923","pt":1588428686137,"mc":[{"id":"1.170370557","rc":[{"trd":[[1.24,6922.42]],"ltp":1.24,"tv":6922.42,"id":9624350},{"atb":[[1.24,803.39]],"id":9624350}],"con":true,"img":false}]}
{"op":"mcm","clk":"1362119942","pt":1588428687421,"mc":[{"id":"1.170370557","rc":[{"atb":[[1.24,803.63]],"id":9624350}],"con":true,"img":false}]}
{"op":"mcm","clk":"1362119949","pt":1588428687933,"mc":[{"id":"1.170370557","rc":[{"trd":[[1.24,6933.06]],"ltp":1.24,"tv":6933.06,"id":9624350},{"atb":[[1.24,798.31]],"id":9624350}],"con":true,"img":false}]}
{"op":"mcm","clk":"1362119954","pt":1588428688444,"mc":[{"id":"1.170370557","rc":[{"trd":[[1.25,3374.24]],"ltp":1.25,"tv":3374.24,"id":9624350},{"atl":[[1.25,417.33]],"id":9624350}],"con":true,"img":false}]}
{"op":"mcm","clk":"1362119958","pt":1588428688701,"mc":[{"id":"1.170370557","rc":[{"atl":[[5.1,0.31]],"id":9622734},{"atb":[[1.23,1782.12]],"id":9624350}],"con":true,"img":false}]}
{"op":"mcm","clk":"1362120029","pt":1588428692440,"mc":[{"id":"1.170370557","rc":[{"atl":[[5.1,0]],"id":9622734}],"con":true,"img":false}]}
{"op":"mcm","clk":"1362120049","pt":1588428693626,"mc":[{"id":"1.170370557","rc":[{"trd":[[1.24,6937.06]],"ltp":1.24,"tv":6937.06,"id":9624350},{"atb":[[1.24,796.3]],"id":9624350}],"con":true,"img":false}]}
{"op":"mcm","clk":"1362120059","pt":1588428694037,"mc":[{"id":"1.170370557","rc":[{"trd":[[5,58.23]],"ltp":5.0,"tv":58.23,"id":9622734},{"trd":[[1.25,3390.24]],"ltp":1.25,"tv":3390.24,"id":9624350},{"atl":[[1.25,401.33]],"id":9624350}],"con":true,"img":false}]}
{"op":"mcm","clk":"1362120073","pt":1588428694505,"mc":[{"id":"1.170370557","rc":[{"atb":[[1.23,1302.12]],"id":9624350}],"con":true,"img":false}]}
{"op":"mcm","clk":"1362120081","pt":1588428694817,"mc":[{"id":"1.170370557","rc":[{"trd":[[5,62.23]],"ltp":5.0,"tv":62.23,"id":9622734},{"trd":[[1.25,3406.24]],"ltp":1.25,"tv":3406.24,"id":9624350},{"atl":[[1.25,385.33]],"id":9624350}],"con":true,"img":false}]}
{"op":"mcm","clk":"1362120094","pt":1588428695330,"mc":[{"id":"1.170370557","rc":[{"trd":[[1.25,3406.81]],"ltp":1.25,"tv":3406.81,"id":9624350},{"atb":[[1.24,796.07]],"id":9624350},{"atl":[[1.25,385.04]],"id":9624350}],"con":true,"img":false}]}
{"op":"mcm","clk":"1362120098","pt":1588428695432,"mc":[{"id":"1.170370557","rc":[{"atb":[[1.2,519.79]],"id":9624350}],"con":true,"img":false}]}
{"op":"mcm","clk":"1362120107","pt":1588428695842,"mc":[{"id":"1.170370557","rc":[{"trd":[[1.25,3407.75]],"ltp":1.25,"tv":3407.75,"id":9624350},{"atl":[[1.25,384.57]],"id":9624350}],"con":true,"img":false}]}
{"op":"mcm","clk":"1362120114","pt":1588428696149,"mc":[{"id":"1.170370557","rc":[{"trd":[[1.25,3408.13]],"ltp":1.25,"tv":3408.13,"id":9624350},{"atb":[[1.21,29.61]],"id":9624350},{"atl":[[1.25,384.39]],"id":9624350}],"con":true,"img":false}]}
{"op":"mcm","clk":"1362120162","pt":1588428698717,"mc":[{"id":"1.170370557","rc":[{"atl":[[6,3.5]],"id":9622734}],"con":true,"img":false}]}
{"op":"mcm","clk":"1362120188","pt":1588428699640,"mc":[{"id":"1.170370557","rc":[{"trd":[[1.24,6946.48]],"ltp":1.24,"tv":6946.48,"id":9624350},{"atb":[[1.24,791.36]],"id":9624350}],"con":true,"img":false}]}
{"op":"mcm","clk":"1362120222","pt":1588428700924,"mc":[{"id":"1.170370557","rc":[{"trd":[[1.25,3418.71]],"ltp":1.25,"tv":3418.71,"id":9624350},{"atl":[[1.25,379.09]],"id":9624350}],"con":true,"img":false}]}
{"op":"mcm","clk":"1362120268","pt":1588428702812,"mc":[{"id":"1.170370557","rc":[{"trd":[[1.25,3425.71]],"ltp":1.25,"tv":3425.71,"id":9624350},{"atl":[[1.25,375.59]],"id":9624350}],"con":true,"img":false}]}
{"op":"mcm","clk":"1362120271","pt":1588428702917,"mc":[{"id":"1.170370557","rc":[{"trd":[[5,64.87]],"ltp":5.0,"tv":64.87,"id":9622734},{"trd":[[1.25,3436.29]],"ltp":1.25,"tv":3436.29,"id":9624350},{"atl":[[1.25,365.02]],"id":9624350}],"con":true,"img":false}]}
{"op":"mcm","clk":"1362120291","pt":1588428703941,"mc":[{"id":"1.170370557","rc":[{"trd":[[1.25,3436.66]],"ltp":1.25,"tv":3436.66,"id":9624350},{"atl":[[1.25,364.83]],"id":9624350}],"con":true,"img":false}]}
{"op":"mcm","clk":"1362120298","pt":1588428704353,"mc":[{"id":"1.170370557","rc":[{"trd":[[5,65.19]],"ltp":5.0,"tv":65.19,"id":9622734},{"trd":[[1.25,3437.92]],"ltp":1.25,"tv":3437.92,"id":9624350},{"atl":[[1.25,363.57]],"id":9624350}],"con":true,"img":false}]}
{"op":"mcm","clk":"1362120301","pt":1588428704456,"mc":[{"id":"1.170370557","rc":[{"atb":[[1.22,1948.33]],"id":9624350}],"con":true,"img":false}]}
{"op":"mcm","clk":"1362120310","pt":1588428704715,"mc":[{"id":"1.170370557","rc":[{"atl":[[1.26,279.95]],"id":9624350}],"con":true,"img":false}]}
{"op":"mcm","clk":"1362120330","pt":1588428705838,"mc":[{"id":"1.170370557","rc":[{"atb":[[1.24,1011.33]],"id":9624350}],"con":true,"img":false}]}
{"op":"mcm","clk":"1362120337","pt":1588428706144,"mc":[{"id":"1.170370557","rc":[{"trd":[[1.24,6951.64]],"ltp":1.24,"tv":6951.64,"id":9624350},{"atb":[[1.24,1008.75]],"id":9624350}],"con":true,"img":false}]}
{"op":"mcm","clk":"1362120340","pt":1588428706247,"mc":[{"id":"1.170370557","rc":[{"trd":[[5,67.54]],"ltp":5.0,"tv":67.54,"id":9622734},{"trd":[[1.25,3447.35]],"ltp":1.25,"tv":3447.35,"id":9624350},{"atl":[[1.25,354.14]],"id":9624350}],"con":true,"img":false}]}
{"op":"mcm","clk":"1362120384","pt":1588428708722,"mc":[{"id":"1.170370557","rc":[{"trd":[[1.24,6957.08]],"ltp":1.24,"tv":6957.08,"id":9624350},{"atb":[[1.24,1006.03]],"id":9624350}],"con":true,"img":false}]}
{"op":"mcm","clk":"1362120405","pt":1588428709955,"mc":[{"id":"1.170370557","rc":[{"trd":[[5,71.08]],"ltp":5.0,"tv":71.08,"id":9622734},{"trd":[[1.25,3461.51]],"ltp":1.25,"tv":3461.51,"id":9624350},{"atb":[[1.23,58.21]],"id":9624350},{"atl":[[1.25,339.98]],"id":9624350}],"con":true,"img":false}]}
{"op":"mcm","clk":"1362120411","pt":1588428710261,"mc":[{"id":"1.170370557","rc":[{"trd":[[1.25,3461.97]],"ltp":1.25,"tv":3461.97,"id":9624350},{"atl":[[1.25,339.75]],"id":9624350}],"con":true,"img":false}]}
{"op":"mcm","clk":"1362120414","pt":1588428710466,"mc":[{"id":"1.170370557","rc":[{"atl":[[1.25,863.15]],"id":9624350}],"con":true,"img":false}]}
{"op":"mcm","clk":"1362120417","pt":1588428710671,"mc":[{"id":"1.170370557","rc":[{"trd":[[1.24,6985.11]],"ltp":1.24,"tv":6985.11,"id":9624350},{"atb":[[1.24,992.01]],"id":9624350}],"con":true,"img":false}]}
{"op":"mcm","clk":"1362120455","pt":1588428713234,"mc":[{"id":"1.170370557","rc":[{"atl":[[7.2,3.5]],"id":9622734}],"con":true,"img":false}]}
{"op":"mcm","clk":"1362120477","pt":1588428714564,"mc":[{"id":"1.170370557","rc":[{"atl":[[1.5,0.56]],"id":9624350}],"con":true,"img":false}]}
{"op":"mcm","clk":"1362120487","pt":1588428715075,"mc":[{"id":"1.170370557","rc":[{"trd":[[1.25,3468.98]],"ltp":1.25,"tv":3468.98,"id":9624350},{"atl":[[1.25,859.65]],"id":9624350}],"con":true,"img":false}]}
{"op":"mcm","clk":"1362120490","pt":1588428715130,"mc":[{"id":"1.170370557","rc":[{"trd":[[5,76.37]],"ltp":5.0,"tv":76.37,"id":9622734},{"trd":[[1.25,3490.14]],"ltp":1.25,"tv":3490.14,"id":9624350},{"atl":[[1.25,838.49]],"id":9624350}],"con":true,"img":false}]}
{"op":"mcm","clk":"1362120510","pt":1588428716668,"mc":[{"id":"1.170370557","rc":[{"trd":[[1.25,3550.14]],"ltp":1.25,"tv":3550.14,"id":9624350},{"atl":[[1.25,808.49]],"id":9624350}],"con":true,"img":false}]}
{"op":"mcm","clk":"1362120551","pt":1588428719177,"mc":[{"id":"1.170370557","rc":[{"atl":[[1.3,0.18]],"id":9624350}],"con":true,"img":false}]}
{"op":"mcm","clk":"1362120554","pt":1588428719279,"mc":[{"id":"1.170370557","rc":[{"trd":[[1.25,3555.3]],"ltp":1.25,"tv":3555.3,"id":9624350},{"atl":[[1.25,805.91]],"id":9624350}],"con":true,"img":false}]}
{"op":"mcm","clk":"1362120557","pt":1588428719432,"mc":[{"id":"1.170370557","rc":[{"trd":[[1.25,3557.9]],"ltp":1.25,"tv":3557.9,"id":9624350},{"atl":[[1.25,804.61]],"id":9624350}],"con":true,"img":false}]}
{"op":"mcm","clk":"1362120572","pt":1588428720564,"mc":[{"id":"1.170370557","rc":[{"atb":[[1.16,1191.88]],"id":9624350}],"con":true,"img":false}]}
{"op":"mcm","clk":"1362120584","pt":1588428721077,"mc":[{"id":"1.170370557","rc":[{"trd":[[1.25,5111.9]],"ltp":1.25,"tv":5111.9,"id":9624350},{"atl":[[1.25,27.61]],"id":9624350}],"con":true,"img":false}]}
{"op":"mcm","clk":"1362120593","pt":1588428721387,"mc":[{"id":"1.170370557","rc":[{"trd":[[1.24,7001.1]],"ltp":1.24,"tv":7001.1,"id":9624350},{"atb":[[1.24,984.01]],"id":9624350}],"con":true,"img":false}]}
{"op":"mcm","clk":"1362120614","pt":1588428722980,"mc":[{"id":"1.170370557","rc":[{"trd":[[1.24,7064.69]],"ltp":1.24,"tv":7064.69,"id":9624350},{"atb":[[1.24,952.22]],"id":9624350}],"con":true,"img":false}]}
{"op":"mcm","clk":"1362120630","pt":1588428723957,"mc":[{"id":"1.170370557","rc":[{"atb":[[1.24,955.93]],"id":9624350}],"con":true,"img":false}]}
{"op":"mcm","clk":"1362120677","pt":1588428726790,"mc":[{"id":"1.170370557","rc":[{"trd":[[5,78.37]],"ltp":5.0,"tv":78.37,"id":9622734},{"trd":[[1.25,5119.89]],"ltp":1.25,"tv":5119.89,"id":9624350},{"atl":[[1.25,19.61]],"id":9624350}],"con":true,"img":false}]}
{"op":"mcm","clk":"1362120684","pt":1588428727252,"mc":[{"id":"1.170370557","rc":[{"atl":[[1.25,31.61]],"id":9624350}],"con":true,"img":false}]}
{"op":"mcm","clk":"1362120716","pt":1588428729194,"mc":[{"id":"1.170370557","rc":[{"trd":[[1.24,7074.1]],"ltp":1.24,"tv":7074.1,"id":9624350},{"atb":[[1.24,951.22]],"id":9624350}],"con":true,"img":false}]}
{"op":"mcm","clk":"1362120727","pt":1588428729761,"mc":[{"id":"1.170370557","rc":[{"atl":[[8.8,3.5]],"id":9622734}],"con":true,"img":false}]}
{"op":"mcm","clk":"1362120731","pt":1588428729966,"mc":[{"id":"1.170370557","rc":[{"trd":[[1.25,5183.13]],"ltp":1.25,"tv":5183.13,"id":9624350},{"atb":[[1.25,18.38]],"id":9624350},{"atl":[[1.25,0]],"id":9624350}],"con":true,"img":false}]}
{"op":"mcm","clk":"1362120748","pt":1588428731400,"mc":[{"id":"1.170370557","rc":[{"trd":[[1.26,1643.94]],"ltp":1.26,"tv":1643.94,"id":9624350},{"atl":[[1.26,277.97]],"id":9624350}],"con":true,"img":false}]}
{"op":"mcm","clk":"1362120773","pt":1588428732789,"mc":[{"id":"1.170370557","rc":[{"atb":[[1.25,71.57]],"id":9624350}],"con":true,"img":false}]}
{"op":"mcm","clk":"1362120776","pt":1588428732994,"mc":[{"id":"1.170370557","rc":[{"trd":[[1.24,7074.94],[1.25,5326.28]],"ltp":1.24,"tv":12401.22,"id":9624350},{"atb":[[1.25,0],[1.24,950.8]],"id":9624350}],"con":true,"img":false}]}
{"op":"mcm","clk":"1362120807","pt":1588428735193,"mc":[{"id":"1.170370557","rc":[{"atb":[[1.23,24.99]],"id":9624350}],"con":true,"img":false}]}
{"op":"mcm","clk":"1362120810","pt":1588428735398,"mc":[{"id":"1.170370557","rc":[{"atb":[[1.25,1.04]],"id":9624350}],"con":true,"img":false}]}
{"op":"mcm","clk":"1362120816","pt":1588428735866,"mc":[{"id":"1.170370557","rc":[{"atl":[[1.27,0]],"id":9624350}],"con":true,"img":false}]}
{"op":"mcm","clk":"1362120851","pt":1588428737811,"mc":[{"id":"1.170370557","rc":[{"atl":[[16.5,4]],"id":9624350}],"con":true,"img":false}]}
{"op":"mcm","clk":"1362120854","pt":1588428738071,"mc":[{"id":"1.170370557","rc":[{"atb":[[1.24,947.1]],"id":9624350}],"con":true,"img":false}]}
{"op":"mcm","clk":"1362120862","pt":1588428738785,"mc":[{"id":"1.170370557","rc":[{"trd":[[1.25,5328.37]],"ltp":1.25,"tv":5328.37,"id":9624350},{"atb":[[1.25,0]],"id":9624350},{"atl":[[1.36,250],[1.25,0.72]],"id":9624350}],"con":true,"img":false}]}
{"op":"mcm","clk":"1362120869","pt":1588428739196,"mc":[{"id":"1.170370557","rc":[{"atl":[[1.26,0]],"id":9624350}],"con":true,"img":false}]}
{"op":"mcm","clk":"1362120871","pt":1588428739298,"mc":[{"id":"1.170370557","rc":[{"atl":[[1.36,500]],"id":9624350}],"con":true,"img":false}]}
{"op":"mcm","clk":"1362120879","pt":1588428739810,"mc":[{"id":"1.170370557","rc":[{"atl":[[1.34,250]],"id":9624350}],"con":true,"img":false}]}
{"op":"mcm","clk":"1362120886","pt":1588428740119,"mc":[{"id":"1.170370557","rc":[{"atl":[[1.34,500]],"id":9624350}],"con":true,"img":false}]}
{"op":"mcm","clk":"1362120902","pt":1588428740683,"mc":[{"id":"1.170370557","rc":[{"atl":[[1.34,0]],"id":9624350}],"con":true,"img":false}]}
{"op":"mcm","clk":"1362120911","pt":1588428741195,"mc":[{"id":"1.170370557","rc":[{"atl":[[1.36,0]],"id":9624350}],"con":true,"img":false}]}
{"op":"mcm","clk":"1362120920","pt":1588428741503,"mc":[{"id":"1.170370557","rc":[{"atl":[[5.4,0]],"id":9622734}],"con":true,"img":false}]}
{"op":"mcm","clk":"1362120929","pt":1588428741912,"mc":[{"id":"1.170370557","rc":[{"atl":[[1.31,443.26]],"id":9624350}],"con":true,"img":false}]}
{"op":"mcm","clk":"1362121024","pt":1588428748174,"mc":[{"id":"1.170370557","rc":[{"atb":[[1.2,963.05]],"id":9624350}],"con":true,"img":false}]}
{"op":"mcm","clk":"1362121030","pt":1588428748480,"mc":[{"id":"1.170370557","rc":[{"atb":[[1.19,277.84]],"id":9624350}],"con":true,"img":false}]}
{"op":"mcm","clk":"1362121048","pt":1588428749199,"mc":[{"id":"1.170370557","rc":[{"atl":[[1.29,333]],"id":9624350}],"con":true,"img":false}]}
{"op":"mcm","clk":"1362121053","pt":1588428749404,"mc":[{"id":"1.170370557","rc":[{"atl":[[1.25,0]],"id":9624350}],"con":true,"img":false}]}
{"op":"mcm","clk":"1362121116","pt":1588428753312,"mc":[{"id":"1.170370557","rc":[{"atl":[[1.26,354.6]],"id":9624350}],"con":true,"img":false}]}
{"op":"mcm","clk":"1362121128","pt":1588428753980,"mc":[{"id":"1.170370557","rc":[{"trd":[[4.8,3.99]],"ltp":4.8,"tv":3.99,"id":9622734},{"trd":[[1.26,1654.02]],"ltp":1.26,"tv":1654.02,"id":9624350},{"atb":[[1.24,950.27]],"id":9624350},{"atl":[[1.26,344.53]],"id":9624350}],"con":true,"img":false}]}
{"op":"mcm","clk":"1362121138","pt":1588428754595,"mc":[{"id":"1.170370557","rc":[{"atl":[[1.3,1.04]],"id":9624350}],"con":true,"img":false}]}
{"op":"mcm","clk":"1362121160","pt":1588428756401,"mc":[{"id":"1.170370557","rc":[{"atl":[[1.28,279.95]],"id":9624350}],"con":true,"img":false}]}
{"op":"mcm","clk":"1362121163","pt":1588428756503,"mc":[{"id":"1.170370557","rc":[{"atl":[[1.33,354.6]],"id":9624350}],"con":true,"img":false}]}
{"op":"mcm","clk":"1362121169","pt":1588428756809,"mc":[{"id":"1.170370557","rc":[{"atl":[[1.28,438.26]],"id":9624350}],"con":true,"img":false}]}
{"op":"mcm","clk":"1362121197","pt":1588428758811,"mc":[{"id":"1.170370557","rc":[{"atb":[[1.25,100]],"id":9624350}],"con":true,"img":false}]}
{"op":"mcm","clk":"1362121238","pt":1588428760713,"mc":[{"id":"1.170370557","rc":[{"atl":[[1.59,0]],"id":9624350}],"con":true,"img":false}]}
{"op":"mcm","clk":"1362121252","pt":1588428761529,"mc":[{"id":"1.170370557","rc":[{"atb":[[1.25,187.58]],"id":9624350}],"con":true,"img":false}]}
{"op":"mcm","clk":"1362121267","pt":1588428762296,"mc":[{"id":"1.170370557","rc":[{"atb":[[1.24,446.04]],"id":9624350}],"con":true,"img":false}]}
{"op":"mcm","clk":"1362121281","pt":1588428763112,"mc":[{"id":"1.170370557","rc":[{"atb":[[1.2,963.79]],"id":9624350}],"con":true,"img":false}]}
{"op":"mcm","clk":"1362121298","pt":1588428764390,"mc":[{"id":"1.170370557","rc":[{"atb":[[1.2,520.53]],"id":9624350}],"con":true,"img":false}]}
{"op":"mcm","clk":"1362121306","pt":1588428764802,"mc":[{"id":"1.170370557","rc":[{"trd":[[1.24,7683.8],[1.25,5703.55]],"ltp":1.24,"tv":13387.35,"id":9624350},{"atb":[[1.25,0],[1.24,141.6]],"id":9624350}],"con":true,"img":false}]}
{"op":"mcm","clk":"1362121307","pt":1588428764900,"mc":[{"id":"1.170370557","rc":[{"atl":[[1.28,158.3]],"id":9624350}],"con":true,"img":false}]}
{"op":"mcm","clk":"1362121310","pt":1588428765004,"mc":[{"id":"1.170370557","rc":[{"trd":[[1.26,2083.19]],"ltp":1.26,"tv":2083.19,"id":9624350},{"atl":[[1.26,129.94],[1.29,0]],"id":9624350}],"con":true,"img":false}]}
{"op":"mcm","clk":"1362121320","pt":1588428765617,"mc":[{"id":"1.170370557","rc":[{"trd":[[1.23,4868.15],[1.24,7967.01]],"ltp":1.23,"tv":12835.16,"id":9624350},{"atb":[[1.23,0],[1.24,0]],"id":9624350},{"atl":[[1.23,277.4]],"id":9624350}],"con":true,"img":false}]}
{"op":"mcm","clk":"1362121327","pt":1588428765929,"mc":[{"id":"1.170370557","rc":[{"trd":[[5.3,150.73]],"ltp":5.3,"tv":150.73,"id":9622734},{"trd":[[1.23,4871.34]],"ltp":1.23,"tv":4871.34,"id":9624350},{"atl":[[1.23,274.21],[1.24,310.28]],"id":9624350}],"con":true,"img":false}]}
{"op":"mcm","clk":"1362121337","pt":1588428766404,"mc":[{"id":"1.170370557","rc":[{"atb":[[1.22,1505.07]],"id":9624350}],"con":true,"img":false}]}
{"op":"mcm","clk":"1362121345","pt":1588428766814,"mc":[{"id":"1.170370557","rc":[{"atl":[[1.25,250]],"id":9624350}],"con":true,"img":false}]}
{"op":"mcm","clk":"1362121347","pt":1588428766917,"mc":[{"id":"1.170370557","rc":[{"atl":[[1.26,0]],"id":9624350}],"con":true,"img":false}]}
{"op":"mcm","clk":"1362121352","pt":1588428767123,"mc":[{"id":"1.170370557","rc":[{"atb":[[1.22,254.25]],"id":9624350}],"con":true,"img":false}]}
{"op":"mcm","clk":"1362121363","pt":1588428767736,"mc":[{"id":"1.170370557","rc":[{"atl":[[1.25,356.38]],"id":9624350}],"con":true,"img":false}]}
{"op":"mcm","clk":"1362121365","pt":1588428767840,"mc":[{"id":"1.170370557","rc":[{"atl":[[1.23,628.81]],"id":9624350}],"con":true,"img":false}]}
{"op":"mcm","clk":"1362121370","pt":1588428768099,"mc":[{"id":"1.170370557","rc":[{"atl":[[1.25,250]],"id":9624350}],"con":true,"img":false}]}
{"op":"mcm","clk":"1362121379","pt":1588428768809,"mc":[{"id":"1.170370557","rc":[{"atb":[[1.21,472.88]],"id":9624350}],"con":true,"img":false}]}
{"op":"mcm","clk":"1362121382","pt":1588428769116,"mc":[{"id":"1.170370557","rc":[{"atl":[[1.33,0]],"id":9624350}],"con":true,"img":false}]}
{"op":"mcm","clk":"1362121385","pt":1588428769218,"mc":[{"id":"1.170370557","rc":[{"trd":[[1.23,5152.12]],"ltp":1.23,"tv":5152.12,"id":9624350},{"atl":[[1.23,488.42]],"id":9624350}],"con":true,"img":false}]}
{"op":"mcm","clk":"1362121397","pt":1588428770037,"mc":[{"id":"1.170370557","rc":[{"atb":[[1.19,0]],"id":9624350}],"con":true,"img":false}]}
{"op":"mcm","clk":"1362121401","pt":1588428770139,"mc":[{"id":"1.170370557","rc":[{"atb":[[1.22,750.31]],"id":9624350}],"con":true,"img":false}]}
{"op":"mcm","clk":"1362121404","pt":1588428770242,"mc":[{"id":"1.170370557","rc":[{"atl":[[1.23,354.6]],"id":9624350}],"con":true,"img":false}]}
{"op":"mcm","clk":"1362121425","pt":1588428771421,"mc":[{"id":"1.170370557","rc":[{"atl":[[1.31,0]],"id":9624350}],"con":true,"img":false}]}
{"op":"mcm","clk":"1362121438","pt":1588428772143,"mc":[{"id":"1.170370557","rc":[{"trd":[[1.22,6577.09]],"ltp":1.22,"tv":6577.09,"id":9624350},{"atb":[[1.22,661.65]],"id":9624350}],"con":true,"img":false}]}
{"op":"mcm","clk":"1362121441","pt":1588428772246,"mc":[{"id":"1.170370557","rc":[{"trd":[[1.23,5611.16]],"ltp":1.23,"tv":5611.16,"id":9624350},{"atl":[[1.23,125.08]],"id":9624350}],"con":true,"img":false}]}
{"op":"mcm","clk":"1362121444","pt":1588428772401,"mc":[{"id":"1.170370557","rc":[{"trd":[[1.22,6754.39]],"ltp":1.22,"tv":6754.39,"id":9624350},{"atb":[[1.22,573]],"id":9624350}],"con":true,"img":false}]}
{"op":"mcm","clk":"1362121446","pt":1588428772503,"mc":[{"id":"1.170370557","rc":[{"trd":[[1.22,7463.61]],"ltp":1.22,"tv":7463.61,"id":9624350},{"atb":[[1.22,218.39]],"id":9624350}],"con":true,"img":false}]}
{"op":"mcm","clk":"1362121448","pt":1588428772607,"mc":[{"id":"1.170370557","rc":[{"trd":[[1.23,5861.34]],"ltp":1.23,"tv":5861.34,"id":9624350},{"atb":[[1.23,1118.82]],"id":9624350},{"atl":[[1.23,0]],"id":9624350}],"con":true,"img":false}]}
{"op":"mcm","clk":"1362121455","pt":1588428773012,"mc":[{"id":"1.170370557","rc":[{"trd":[[1.23,6038.64]],"ltp":1.23,"tv":6038.64,"id":9624350},{"atb":[[1.23,1030.17]],"id":9624350}],"con":true,"img":false}]}
{"op":"mcm","clk":"1362121465","pt":1588428773422,"mc":[{"id":"1.170370557","rc":[{"trd":[[1.23,6215.94]],"ltp":1.23,"tv":6215.94,"id":9624350},{"atb":[[1.23,941.52]],"id":9624350}],"con":true,"img":false}]}
{"op":"mcm","clk":"1362121470","pt":1588428773627,"mc":[{"id":"1.170370557","rc":[{"trd":[[5.1,127.99]],"ltp":5.1,"tv":127.99,"id":9622734},{"trd":[[1.24,7977.6]],"ltp":1.24,"tv":7977.6,"id":9624350},{"atl":[[1.24,299.68]],"id":9624350}],"con":true,"img":false}]}
{"op":"mcm","clk":"1362121476","pt":1588428773832,"mc":[{"id":"1.170370557","rc":[{"trd":[[1.23,6393.25]],"ltp":1.23,"tv":6393.25,"id":9624350},{"atb":[[1.23,852.87]],"id":9624350},{"atl":[[1.5,0]],"id":9624350}],"con":true,"img":false}]}
{"op":"mcm","clk":"1362121483","pt":1588428774037,"mc":[{"id":"1.170370557","rc":[{"trd":[[1.23,6570.55]],"ltp":1.23,"tv":6570.55,"id":9624350},{"atb":[[1.23,764.22]],"id":9624350}],"con":true,"img":false}]}
{"op":"mcm","clk":"1362121506","pt":1588428775419,"mc":[{"id":"1.170370557","rc":[{"atb":[[1.09,411.32]],"id":9624350},{"atl":[[1.47,423.75]],"id":9624350}],"con":true,"img":false}]}
{"op":"mcm","clk":"1362121510","pt":1588428775727,"mc":[{"id":"1.170370557","rc":[{"atl":[[1.27,443.26]],"id":9624350}],"con":true,"img":false}]}
{"op":"mcm","clk":"1362121512","pt":1588428775830,"mc":[{"id":"1.170370557","rc":[{"atl":[[1.24,0]],"id":9624350}],"con":true,"img":false}]}
{"op":"mcm","clk":"1362121514","pt":1588428775932,"mc":[{"id":"1.170370557","rc":[{"atb":[[1.17,500]],"id":9624350}],"con":true,"img":false}]}
{"op":"mcm","clk":"1362121517","pt":1588428776138,"mc":[{"id":"1.170370557","rc":[{"atl":[[1.25,0]],"id":9624350}],"con":true,"img":false}]}
{"op":"mcm","clk":"1362121550","pt":1588428777830,"mc":[{"id":"1.170370557","rc":[{"atb":[[1.23,766.84]],"id":9624350}],"con":true,"img":false}]}
{"op":"mcm","clk":"1362121555","pt":1588428777933,"mc":[{"id":"1.170370557","rc":[{"atb":[[1.14,443.26]],"id":9624350}],"con":true,"img":false}]}
{"op":"mcm","clk":"1362121557","pt":1588428778035,"mc":[{"id":"1.170370557","rc":[{"atb":[[1.21,827.49]],"id":9624350}],"con":true,"img":false}]}
{"op":"mcm","clk":"1362121572","pt":1588428778857,"mc":[{"id":"1.170370557","rc":[{"atb":[[1.23,2.72]],"id":9624350}],"con":true,"img":false}]}
{"op":"mcm","clk":"1362121583","pt":1588428779317,"mc":[{"id":"1.170370557","rc":[{"atb":[[1.23,91.38]],"id":9624350}],"con":true,"img":false}]}
{"op":"mcm","clk":"1362121589","pt":1588428779726,"mc":[{"id":"1.170370557","rc":[{"atb":[[1.23,180.03]],"id":9624350}],"con":true,"img":false}]}
{"op":"mcm","clk":"1362121593","pt":1588428779831,"mc":[{"id":"1.170370557","rc":[{"atb":[[1.2,24.42],[1.22,0]],"id":9624350}],"con":true,"img":false}]}
{"op":"mcm","clk":"1362121595","pt":1588428779932,"mc":[{"id":"1.170370557","rc":[{"atb":[[1.23,268.68]],"id":9624350}],"con":true,"img":false}]}
{"op":"mcm","clk":"1362121598","pt":1588428780137,"mc":[{"id":"1.170370557","rc":[{"atb":[[1.23,357.33]],"id":9624350}],"con":true,"img":false}]}
{"op":"mcm","clk":"1362121602","pt":1588428780446,"mc":[{"id":"1.170370557","rc":[{"atb":[[1.17,854.6]],"id":9624350}],"con":true,"img":false}]}
{"op":"mcm","clk":"1362121604","pt":1588428780548,"mc":[{"id":"1.170370557","rc":[{"atb":[[1.23,445.99]],"id":9624350}],"con":true,"img":false}]}
{"op":"mcm","clk":"1362121608","pt":1588428780855,"mc":[{"id":"1.170370557","rc":[{"atb":[[1.23,91.38]],"id":9624350}],"con":true,"img":false}]}
{"op":"mcm","clk":"1362121611","pt":1588428780960,"mc":[{"id":"1.170370557","rc":[{"atb":[[1.16,0]],"id":9624350}],"con":true,"img":false}]}
{"op":"mcm","clk":"1362121615","pt":1588428781063,"mc":[{"id":"1.170370557","rc":[{"atb":[[1.23,2.72]],"id":9624350},{"atl":[[1.25,300]],"id":9624350}],"con":true,"img":false}]}
{"op":"mcm","clk":"1362121621","pt":1588428781629,"mc":[{"id":"1.170370557","rc":[{"atb":[[1.21,384.22]],"id":9624350}],"con":true,"img":false}]}
{"op":"mcm","clk":"1362121627","pt":1588428781835,"mc":[{"id":"1.170370557","rc":[{"atl":[[1.24,443.26]],"id":9624350}],"con":true,"img":false}]}
{"op":"mcm","clk":"1362121628","pt":1588428781938,"mc":[{"id":"1.170370557","rc":[{"atb":[[1.23,29.17],[1.17,354.6]],"id":9624350}],"con":true,"img":false}]}
{"op":"mcm","clk":"1362121638","pt":1588428782453,"mc":[{"id":"1.170370557","rc":[{"atb":[[1.09,0.31]],"id":9624350},{"atl":[[1.47,0]],"id":9624350}],"con":true,"img":false}]}
{"op":"mcm","clk":"1362121644","pt":1588428782865,"mc":[{"id":"1.170370557","rc":[{"atb":[[1.21,29.61]],"id":9624350}],"con":true,"img":false}]}
{"op":"mcm","clk":"1362121648","pt":1588428783129,"mc":[{"id":"1.170370557","rc":[{"trd":[[1.24,8864.13]],"ltp":1.24,"tv":8864.13,"id":9624350},{"atb":[[1.24,0.74]],"id":9624350},{"atl":[[1.24,0]],"id":9624350}],"con":true,"img":false}]}
{"op":"mcm","clk":"1362121658","pt":1588428783843,"mc":[{"id":"1.170370557","rc":[{"atb":[[1.17,0]],"id":9624350}],"con":true,"img":false}]}
{"op":"mcm","clk":"1362121661","pt":1588428784052,"mc":[{"id":"1.170370557","rc":[{"atl":[[1.27,0]],"id":9624350}],"con":true,"img":false}]}
{"op":"mcm","clk":"1362121667","pt":1588428784467,"mc":[{"id":"1.170370557","rc":[{"trd":[[6,3.78]],"ltp":6.0,"tv":3.78,"id":9622734},{"atl":[[6,0]],"id":9622734},{"trd":[[1.2,1129.45],[1.23,6628.91],[1.21,4471.91],[1.24,8865.61]],"ltp":1.2,"tv":21095.88,"id":9624350},{"atb":[[1.2,0],[1.21,0],[1.23,0],[1.24,0]],"id":9624350},{"atl":[[1.2,178.47]],"id":9624350}],"con":true,"img":false}]}
{"op":"mcm","clk":"1362121668","pt":1588428784567,"mc":[{"id":"1.170370557","rc":[{"atl":[[1.2,622.47]],"id":9624350}],"con":true,"img":false}]}
{"op":"mcm","clk":"1362121671","pt":1588428784670,"mc":[{"id":"1.170370557","rc":[{"atl":[[1.26,500]],"id":9624350}],"con":true,"img":false}]}
{"op":"mcm","clk":"1362121676","pt":1588428785032,"mc":[{"id":"1.170370557","rc":[{"atb":[[1.19,751.03]],"id":9624350}],"con":true,"img":false}]}
{"op":"mcm","clk":"1362121686","pt":1588428785447,"mc":[{"id":"1.170370557","rc":[{"atl":[[1.22,310.28]],"id":9624350}],"con":true,"img":false}]}
{"op":"mcm","clk":"1362121690","pt":1588428785655,"mc":[{"id":"1.170370557","rc":[{"atl":[[1.22,1087.28]],"id":9624350}],"con":true,"img":false}]}
{"op":"mcm","clk":"1362121694","pt":1588428785861,"mc":[{"id":"1.170370557","rc":[{"atl":[[1.23,500]],"id":9624350}],"con":true,"img":false}]}
{"op":"mcm","clk":"1362121697","pt":1588428786067,"mc":[{"id":"1.170370557","rc":[{"atl":[[6.4,18.9]],"id":9622734}],"con":true,"img":false}]}
{"op":"mcm","clk":"1362121700","pt":1588428786169,"mc":[{"id":"1.170370557","rc":[{"atl":[[1.21,777]],"id":9624350}],"con":true,"img":false}]}
{"op":"mcm","clk":"1362121707","pt":1588428786528,"mc":[{"id":"1.170370557","rc":[{"atl":[[1.21,1277]],"id":9624350}],"con":true,"img":false}]}
{"op":"mcm","clk":"1362121710","pt":1588428786630,"mc":[{"id":"1.170370557","rc":[{"atl":[[1.21,2054]],"id":9624350}],"con":true,"img":false}]}
{"op":"mcm","clk":"1362121717","pt":1588428786937,"mc":[{"id":"1.170370557","rc":[{"atb":[[1.18,102.19]],"id":9624350}],"con":true,"img":false}]}
{"op":"mcm","clk":"1362121720","pt":1588428787040,"mc":[{"id":"1.170370557","rc":[{"atl":[[1.22,1175.93]],"id":9624350}],"con":true,"img":false}]}
{"op":"mcm","clk":"1362121725","pt":1588428787245,"mc":[{"id":"1.170370557","rc":[{"atl":[[1.21,2142.65]],"id":9624350}],"con":true,"img":false}]}
{"op":"mcm","clk":"1362121733","pt":1588428787656,"mc":[{"id":"1.170370557","rc":[{"atl":[[1.23,529.17]],"id":9624350}],"con":true,"img":false}]}
{"op":"mcm","clk":"1362121739","pt":1588428787966,"mc":[{"id":"1.170370557","rc":[{"trd":[[1.2,1145.32]],"ltp":1.2,"tv":1145.32,"id":9624350},{"atl":[[1.2,614.54]],"id":9624350}],"con":true,"img":false}]}
{"op":"mcm","clk":"1362121740","pt":1588428788067,"mc":[{"id":"1.170370557","rc":[{"atl":[[1.28,0],[1.21,1642.65],[1.26,0],[1.23,29.17]],"id":9624350}],"con":true,"img":false}]}
{"op":"mcm","clk":"1362121742","pt":1588428788169,"mc":[{"id":"1.170370557","rc":[{"atl":[[1.23,73.5]],"id":9624350}],"con":true,"img":false}]}
{"op":"mcm","clk":"1362121744","pt":1588428788271,"mc":[{"id":"1.170370557","rc":[{"atl":[[1.23,44.32]],"id":9624350}],"con":true,"img":false}]}
{"op":"mcm","clk":"1362121747","pt":1588428788377,"mc":[{"id":"1.170370557","rc":[{"trd":[[1.2,1322.63]],"ltp":1.2,"tv":1322.63,"id":9624350},{"atb":[[1.06,2572.36]],"id":9624350},{"atl":[[1.2,525.89],[1.4,489.42]],"id":9624350}],"con":true,"img":false}]}
{"op":"mcm","clk":"1362121750","pt":1588428788477,"mc":[{"id":"1.170370557","rc":[{"atb":[[1.18,0]],"id":9624350}],"con":true,"img":false}]}
{"op":"mcm","clk":"1362121752","pt":1588428788528,"mc":[{"id":"1.170370557","rc":[{"atl":[[1.21,88.65]],"id":9624350}],"con":true,"img":false}]}
{"op":"mcm","clk":"1362121756","pt":1588428788836,"mc":[{"id":"1.170370557","rc":[{"trd":[[1.2,1499.93]],"ltp":1.2,"tv":1499.93,"id":9624350},{"atl":[[1.2,437.24]],"id":9624350}],"con":true,"img":false}]}
{"op":"mcm","clk":"1362121759","pt":1588428789060,"mc":[{"id":"1.170370557","rc":[{"atl":[[1.22,1667.95]],"id":9624350}],"con":true,"img":false}]}
{"op":"mcm","clk":"1362121761","pt":1588428789142,"mc":[{"id":"1.170370557","rc":[{"atl":[[1.21,531.91]],"id":9624350}],"con":true,"img":false}]}
{"op":"mcm","clk":"1362121765","pt":1588428789347,"mc":[{"id":"1.170370557","rc":[{"atb":[[1.17,88.65]],"id":9624350},{"atl":[[1.4,0]],"id":9624350}],"con":true,"img":false}]}
{"op":"mcm","clk":"1362121767","pt":1588428789448,"mc":[{"id":"1.170370557","rc":[{"atb":[[1.06,2068.2]],"id":9624350},{"atl":[[1.23,0]],"id":9624350}],"con":true,"img":false}]}
{"op":"mcm","clk":"1362121770","pt":1588428789553,"mc":[{"id":"1.170370557","rc":[{"atb":[[1.17,177.3]],"id":9624350}],"con":true,"img":false}]}
{"op":"mcm","clk":"1362121778","pt":1588428789959,"mc":[{"id":"1.170370557","rc":[{"atb":[[1.18,443.26]],"id":9624350}],"con":true,"img":false}]}
{"op":"mcm","clk":"1362121785","pt":1588428790470,"mc":[{"id":"1.170370557","rc":[{"atl":[[1.2,0]],"id":9624350}],"con":true,"img":false}]}
{"op":"mcm","clk":"1362121791","pt":1588428790777,"mc":[{"id":"1.170370557","rc":[{"atb":[[1.15,354.6]],"id":9624350}],"con":true,"img":false}]}
{"op":"mcm","clk":"1362121797","pt":1588428791034,"mc":[{"id":"1.170370557","rc":[{"atl":[[1.22,1357.67]],"id":9624350}],"con":true,"img":false}]}
{"op":"mcm","clk":"1362121799","pt":1588428791134,"mc":[{"id":"1.170370557","rc":[{"atb":[[1.2,783.32],[1.16,443.26]],"id":9624350}],"con":true,"img":false}]}
{"op":"mcm","clk":"1362121804","pt":1588428791544,"mc":[{"id":"1.170370557","rc":[{"atb":[[1.19,847.86]],"id":9624350}],"con":true,"img":false}]}
{"op":"mcm","clk":"1362121816","pt":1588428792258,"mc":[{"id":"1.170370557","rc":[{"trd":[[1.2,2499.93]],"ltp":1.2,"tv":2499.93,"id":9624350},{"atb":[[1.2,375.3]],"id":9624350}],"con":true,"img":false}]}
{"op":"mcm","clk":"1362121827","pt":1588428792871,"mc":[{"id":"1.170370557","rc":[{"atb":[[1.17,288.3]],"id":9624350}],"con":true,"img":false}]}
{"op":"mcm","clk":"1362121830","pt":1588428792974,"mc":[{"id":"1.170370557","rc":[{"atl":[[1.25,0]],"id":9624350}],"con":true,"img":false}]}
{"op":"mcm","clk":"1362121833","pt":1588428793176,"mc":[{"id":"1.170370557","rc":[{"trd":[[1.2,2526.53]],"ltp":1.2,"tv":2526.53,"id":9624350},{"atb":[[1.2,382]],"id":9624350},{"atl":[[1.23,2]],"id":9624350}],"con":true,"img":false}]}
{"op":"mcm","clk":"1362121841","pt":1588428793535,"mc":[{"id":"1.170370557","rc":[{"atb":[[1.15,465.6]],"id":9624350}],"con":true,"img":false}]}
{"op":"mcm","clk":"1362121869","pt":1588428794771,"mc":[{"id":"1.170370557","rc":[{"atb":[[1.19,751.03]],"id":9624350}],"con":true,"img":false}]}
{"op":"mcm","clk":"1362121874","pt":1588428794869,"mc":[{"id":"1.170370557","rc":[{"atb":[[1.19,839.68]],"id":9624350}],"con":true,"img":false}]}
{"op":"mcm","clk":"1362121886","pt":1588428795280,"mc":[{"id":"1.170370557","rc":[{"atb":[[1.19,928.34]],"id":9624350}],"con":true,"img":false}]}
{"op":"mcm","clk":"1362121889","pt":1588428795333,"mc":[{"id":"1.170370557","rc":[{"atb":[[1.13,111]],"id":9624350}],"con":true,"img":false}]}
{"op":"mcm","clk":"1362121895","pt":1588428795539,"mc":[{"id":"1.170370557","rc":[{"atb":[[1.19,1016.99],[1.17,111]],"id":9624350}],"con":true,"img":false}]}
{"op":"mcm","clk":"1362121900","pt":1588428795945,"mc":[{"id":"1.170370557","rc":[{"atb":[[1.13,888]],"id":9624350}],"con":true,"img":false}]}
{"op":"mcm","clk":"1362121905","pt":1588428796251,"mc":[{"id":"1.170370557","rc":[{"atb":[[1.13,1665]],"id":9624350}],"con":true,"img":false}]}
{"op":"mcm","clk":"1362121912","pt":1588428796763,"mc":[{"id":"1.170370557","rc":[{"atb":[[1.12,777]],"id":9624350},{"atl":[[1.21,1031.91]],"id":9624350}],"con":true,"img":false}]}
{"op":"mcm","clk":"1362121922","pt":1588428797173,"mc":[{"id":"1.170370557","rc":[{"trd":[[1.2,2574.52]],"ltp":1.2,"tv":2574.52,"id":9624350},{"atb":[[1.2,358],[1.12,1554]],"id":9624350}],"con":true,"img":false}]}
{"op":"mcm","clk":"1362121925","pt":1588428797378,"mc":[{"id":"1.170370557","rc":[{"atb":[[1.13,1554]],"id":9624350},{"atl":[[1.3,0.86]],"id":9624350}],"con":true,"img":false}]}
{"op":"mcm","clk":"1362121929","pt":1588428797684,"mc":[{"id":"1.170370557","rc":[{"trd":[[1.2,2663.18]],"ltp":1.2,"tv":2663.18,"id":9624350},{"atb":[[1.2,313.67]],"id":9624350}],"con":true,"img":false}]}
{"op":"mcm","clk":"1362121934","pt":1588428797941,"mc":[{"id":"1.170370557","rc":[{"atb":[[1.11,414.6]],"id":9624350}],"con":true,"img":false}]}
{"op":"mcm","clk":"1362121939","pt":1588428798045,"mc":[{"id":"1.170370557","rc":[{"trd":[[1.2,3263.17]],"ltp":1.2,"tv":3263.17,"id":9624350},{"atb":[[1.2,13.68],[1.08,0]],"id":9624350},{"atl":[[1.5,0.71]],"id":9624350}],"con":true,"img":false}]}
{"op":"mcm","clk":"1362121940","pt":1588428798150,"mc":[{"id":"1.170370557","rc":[{"trd":[[1.2,3279.17]],"ltp":1.2,"tv":3279.17,"id":9624350},{"atb":[[1.2,0]],"id":9624350}],"con":true,"img":false}]}
{"op":"mcm","clk":"1362121947","pt":1588428798452,"mc":[{"id":"1.170370557","rc":[{"trd":[[1.2,3463.15]],"ltp":1.2,"tv":3463.15,"id":9624350},{"atl":[[1.2,6.41]],"id":9624350}],"con":true,"img":false}]}
{"op":"mcm","clk":"1362121953","pt":1588428798759,"mc":[{"id":"1.170370557","rc":[{"trd":[[1.2,3475.98]],"ltp":1.2,"tv":3475.98,"id":9624350},{"atb":[[1.2,82.65]],"id":9624350},{"atl":[[1.2,0],[1.22,580.67]],"id":9624350}],"con":true,"img":false}]}
{"op":"mcm","clk":"1362121959","pt":1588428798963,"mc":[{"id":"1.170370557","rc":[{"atb":[[1.2,171.31]],"id":9624350}],"con":true,"img":false}]}
{"op":"mcm","clk":"1362121963","pt":1588428799168,"mc":[{"id":"1.170370557","rc":[{"trd":[[1.2,3563.45]],"ltp":1.2,"tv":3563.45,"id":9624350},{"atb":[[1.2,216.23]],"id":9624350},{"atl":[[1.21,588.65]],"id":9624350}],"con":true,"img":false}]}
{"op":"mcm","clk":"1362121971","pt":1588428799580,"mc":[{"id":"1.170370557","rc":[{"atb":[[1.07,1083.33]],"id":9624350}],"con":true,"img":false}]}
{"op":"mcm","clk":"1362121974","pt":1588428799788,"mc":[{"id":"1.170370557","rc":[{"trd":[[6,12.65]],"ltp":6.0,"tv":12.65,"id":9622734},{"trd":[[1.2,3607.78]],"ltp":1.2,"tv":3607.78,"id":9624350},{"atb":[[1.2,171.9]],"id":9624350}],"con":true,"img":false}]}
{"op":"mcm","clk":"1362121978","pt":1588428800051,"mc":[{"id":"1.170370557","rc":[{"atb":[[1.19,751.03]],"id":9624350}],"con":true,"img":false}]}
{"op":"mcm","clk":"1362121980","pt":1588428800150,"mc":[{"id":"1.170370557","rc":[{"trd":[[6,44.64]],"ltp":6.0,"tv":44.64,"id":9622734},{"trd":[[1.2,3767.75]],"ltp":1.2,"tv":3767.75,"id":9624350},{"atb":[[1.2,11.93],[1.16,0]],"id":9624350}],"con":true,"img":false}]}
{"op":"mcm","clk":"1362121986","pt":1588428800455,"mc":[{"id":"1.170370557","rc":[{"trd":[[6,47.03]],"ltp":6.0,"tv":47.03,"id":9622734},{"atb":[[6,13.61]],"id":9622734},{"trd":[[1.2,3779.68]],"ltp":1.2,"tv":3779.68,"id":9624350},{"atb":[[1.2,0]],"id":9624350}],"con":true,"img":false}]}
{"op":"mcm","clk":"1362121996","pt":1588428800765,"mc":[{"id":"1.170370557","rc":[{"atb":[[1.14,0]],"id":9624350},{"atl":[[1.2,0.18]],"id":9624350}],"con":true,"img":false}]}
{"op":"mcm","clk":"1362121997","pt":1588428800865,"mc":[{"id":"1.170370557","rc":[{"atl":[[1.2,0.87]],"id":9624350}],"con":true,"img":false}]}
{"op":"mcm","clk":"1362122004","pt":1588428801275,"mc":[{"id":"1.170370557","rc":[{"atb":[[6,16.27]],"id":9622734}],"con":true,"img":false}]}
{"op":"mcm","clk":"1362122009","pt":1588428801482,"mc":[{"id":"1.170370557","rc":[{"atb":[[6,8.27]],"id":9622734}],"con":true,"img":false}]}
{"op":"mcm","clk":"1362122012","pt":1588428801585,"mc":[{"id":"1.170370557","rc":[{"trd":[[6,63.3]],"ltp":6.0,"tv":63.3,"id":9622734},{"atb":[[6,0]],"id":9622734},{"trd":[[1.21,4482.64],[1.2,3862.79]],"ltp":1.21,"tv":8345.43,"id":9624350},{"atl":[[1.2,0],[1.21,583.28]],"id":9624350}],"con":true,"img":false}]}
{"op":"mcm","clk":"1362122017","pt":1588428801887,"mc":[{"id":"1.170370557","rc":[{"atb":[[6,7.99]],"id":9622734}],"con":true,"img":false}]}
{"op":"mcm","clk":"1362122025","pt":1588428802264,"mc":[{"id":"1.170370557","rc":[{"trd":[[1.2,3863.64]],"ltp":1.2,"tv":3863.64,"id":9624350},{"atl":[[1.2,43.9]],"id":9624350}],"con":true,"img":false}]}
{"op":"mcm","clk":"1362122028","pt":1588428802369,"mc":[{"id":"1.170370557","rc":[{"atl":[[1.2,57.19]],"id":9624350}],"con":true,"img":false}]}
{"op":"mcm","clk":"1362122030","pt":1588428802471,"mc":[{"id":"1.170370557","rc":[{"atb":[[1.19,862.03]],"id":9624350}],"con":true,"img":false}]}
{"op":"mcm","clk":"1362122036","pt":1588428802779,"mc":[{"id":"1.170370557","rc":[{"atb":[[6,0]],"id":9622734}],"con":true,"img":false}]}
{"op":"mcm","clk":"1362122044","pt":1588428803289,"mc":[{"id":"1.170370557","rc":[{"trd":[[1.2,3875.01]],"ltp":1.2,"tv":3875.01,"id":9624350},{"atl":[[1.2,51.51]],"id":9624350}],"con":true,"img":false}]}
{"op":"mcm","clk":"1362122052","pt":1588428803798,"mc":[{"id":"1.170370557","rc":[{"atl":[[1.2,38.21]],"id":9624350}],"con":true,"img":false}]}
{"op":"mcm","clk":"1362122057","pt":1588428804000,"mc":[{"id":"1.170370557","rc":[{"atb":[[1.18,0]],"id":9624350},{"atl":[[1.2,0]],"id":9624350}],"con":true,"img":false}]}
{"op":"mcm","clk":"1362122058","pt":1588428804102,"mc":[{"id":"1.170370557","rc":[{"atb":[[1.19,111]],"id":9624350}],"con":true,"img":false}]}
{"op":"mcm","clk":"1362122061","pt":1588428804161,"mc":[{"id":"1.170370557","rc":[{"atb":[[1.19,0],[1.15,354.6],[1.17,0]],"id":9624350}],"con":true,"img":false}]}
{"op":"mcm","clk":"1362122078","pt":1588428805899,"mc":[{"id":"1.170370557","rc":[{"atb":[[1.12,0],[1.13,0]],"id":9624350}],"con":true,"img":false}]}
{"op":"mcm","clk":"1362122081","pt":1588428806054,"mc":[{"id":"1.170370557","rc":[{"atl":[[1.3,0]],"id":9624350}],"con":true,"img":false}]}
{"op":"mcm","clk":"1362122090","pt":1588428806667,"mc":[{"id":"1.170370557","rc":[{"atb":[[1.11,680.56]],"id":9624350}],"con":true,"img":false}]}
{"op":"mcm","clk":"1362122093","pt":1588428806770,"mc":[{"id":"1.170370557","rc":[{"atb":[[1.15,0]],"id":9624350}],"con":true,"img":false}]}
{"op":"mcm","clk":"1362122095","pt":1588428806872,"mc":[{"id":"1.170370557","rc":[{"atl":[[1.19,8.74]],"id":9624350}],"con":true,"img":false}]}
{"op":"mcm","clk":"1362122102","pt":1588428807280,"mc":[{"id":"1.170370557","rc":[{"atl":[[1.22,88.65]],"id":9624350}],"con":true,"img":false}]}
{"op":"mcm","clk":"1362122111","pt":1588428808101,"mc":[{"id":"1.170370557","rc":[{"atb":[[1.11,325.95]],"id":9624350}],"con":true,"img":false}]}
{"op":"mcm","clk":"1362122123","pt":1588428809072,"mc":[{"id":"1.170370557","rc":[{"trd":[[1.19,662.72]],"ltp":1.19,"tv":662.72,"id":9624350},{"atl":[[1.19,7.27]],"id":9624350}],"con":true,"img":false}]}
{"op":"mcm","clk":"1362122130","pt":1588428809481,"mc":[{"id":"1.170370557","rc":[{"trd":[[6.4,23.9]],"ltp":6.4,"tv":23.9,"id":9622734},{"atl":[[6.4,0]],"id":9622734},{"trd":[[1.18,1325.24]],"ltp":1.18,"tv":1325.24,"id":9624350},{"atl":[[1.18,207.76]],"id":9624350}],"con":true,"img":false}]}
{"op":"mcm","clk":"1362122132","pt":1588428809583,"mc":[{"id":"1.170370557","rc":[{"atl":[[1.18,651.76]],"id":9624350}],"con":true,"img":false}]}
{"op":"mcm","clk":"1362122135","pt":1588428809788,"mc":[{"id":"1.170370557","rc":[{"atl":[[1.17,88.65]],"id":9624350}],"con":true,"img":false}]}
{"op":"mcm","clk":"1362122137","pt":1588428809891,"mc":[{"id":"1.170370557","rc":[{"atl":[[1.19,784.27]],"id":9624350}],"con":true,"img":false}]}
{"op":"mcm","clk":"1362122139","pt":1588428809993,"mc":[{"id":"1.170370557","rc":[{"atl":[[1.18,744.79]],"id":9624350}],"con":true,"img":false}]}
{"op":"mcm","clk":"1362122142","pt":1588428810197,"mc":[{"id":"1.170370557","rc":[{"atl":[[1.17,177.3]],"id":9624350}],"con":true,"img":false}]}
{"op":"mcm","clk":"1362122144","pt":1588428810300,"mc":[{"id":"1.170370557","rc":[{"atl":[[1.19,1561.27]],"id":9624350}],"con":true,"img":false}]}
{"op":"mcm","clk":"1362122146","pt":1588428810402,"mc":[{"id":"1.170370557","rc":[{"atl":[[1.19,2311.27],[1.17,265.95]],"id":9624350}],"con":true,"img":false}]}
{"op":"mcm","clk":"1362122150","pt":1588428810508,"mc":[{"id":"1.170370557","rc":[{"trd":[[7.2,5.22]],"ltp":7.2,"tv":5.22,"id":9622734},{"atl":[[7.2,0]],"id":9622734},{"trd":[[1.16,499.8]],"ltp":1.16,"tv":499.8,"id":9624350},{"atl":[[1.16,66.9],[1.17,531.91]],"id":9624350}],"con":true,"img":false}]}
{"op":"mcm","clk":"1362122151","pt":1588428810557,"mc":[{"id":"1.170370557","rc":[{"atb":[[6.4,37.04]],"id":9622734}],"con":true,"img":false}]}
{"op":"mcm","clk":"1362122154","pt":1588428810659,"mc":[{"id":"1.170370557","rc":[{"atl":[[1.23,179.3]],"id":9624350}],"con":true,"img":false}]}
{"op":"mcm","clk":"1362122156","pt":1588428810762,"mc":[{"id":"1.170370557","rc":[{"atb":[[6.4,18.89]],"id":9622734},{"atl":[[1.2,4]],"id":9624350}],"con":true,"img":false}]}
{"op":"mcm","clk":"1362122158","pt":1588428810864,"mc":[{"id":"1.170370557","rc":[{"atl":[[1.22,0]],"id":9624350}],"con":true,"img":false}]}
{"op":"mcm","clk":"1362122160","pt":1588428810965,"mc":[{"id":"1.170370557","rc":[{"atl":[[1.19,1561.27]],"id":9624350}],"con":true,"img":false}]}
{"op":"mcm","clk":"1362122166","pt":1588428811374,"mc":[{"id":"1.170370557","rc":[{"atb":[[6.4,0]],"id":9622734},{"atl":[[1.21,500]],"id":9624350}],"con":true,"img":false}]}
{"op":"mcm","clk":"1362122168","pt":1588428811476,"mc":[{"id":"1.170370557","rc":[{"atb":[[1.14,111]],"id":9624350}],"con":true,"img":false}]}
{"op":"mcm","clk":"1362122175","pt":1588428811986,"mc":[{"id":"1.170370557","rc":[{"atb":[[1.14,0]],"id":9624350}],"con":true,"img":false}]}
{"op":"mcm","clk":"1362122178","pt":1588428812089,"mc":[{"id":"1.170370557","rc":[{"atl":[[1.19,1574.57]],"id":9624350}],"con":true,"img":false}]}
{"op":"mcm","clk":"1362122180","pt":1588428812190,"mc":[{"id":"1.170370557","rc":[{"atb":[[1.12,111]],"id":9624350}],"con":true,"img":false}]}
{"op":"mcm","clk":"1362122183","pt":1588428812397,"mc":[{"id":"1.170370557","rc":[{"trd":[[1.17,1375.35],[1.16,633.62]],"ltp":1.17,"tv":2008.96,"id":9624350},{"atb":[[1.17,165.05]],"id":9624350},{"atl":[[1.16,0],[1.17,0]],"id":9624350}],"con":true,"img":false}]}
{"op":"mcm","clk":"1362122185","pt":1588428812500,"mc":[{"id":"1.170370557","rc":[{"atl":[[1.19,20.57]],"id":9624350}],"con":true,"img":false}]}
{"op":"mcm","clk":"1362122187","pt":1588428812603,"mc":[{"id":"1.170370557","rc":[{"atb":[[1.11,436.95]],"id":9624350}],"con":true,"img":false}]}
{"op":"mcm","clk":"1362122192","pt":1588428812862,"mc":[{"id":"1.170370557","rc":[{"atl":[[1.18,300.79]],"id":9624350}],"con":true,"img":false}]}
{"op":"mcm","clk":"1362122194","pt":1588428812966,"mc":[{"id":"1.170370557","rc":[{"atl":[[1.18,303.62],[1.23,2]],"id":9624350}],"con":true,"img":false}]}
{"op":"mcm","clk":"1362122201","pt":1588428813372,"mc":[{"id":"1.170370557","rc":[{"atl":[[1.19,7.27]],"id":9624350}],"con":true,"img":false}]}
{"op":"mcm","clk":"1362122206","pt":1588428813681,"mc":[{"id":"1.170370557","rc":[{"atb":[[1.09,354.92]],"id":9624350}],"con":true,"img":false}]}
{"op":"mcm","clk":"1362122208","pt":1588428813784,"mc":[{"id":"1.170370557","rc":[{"trd":[[1.17,1416.7]],"ltp":1.17,"tv":1416.7,"id":9624350},{"atb":[[1.17,144.37]],"id":9624350}],"con":true,"img":false}]}
{"op":"mcm","clk":"1362122213","pt":1588428814194,"mc":[{"id":"1.170370557","rc":[{"trd":[[1.18,1330.53]],"ltp":1.18,"tv":1330.53,"id":9624350},{"atl":[[1.18,300.98]],"id":9624350}],"con":true,"img":false}]}
{"op":"mcm","clk":"1362122215","pt":1588428814296,"mc":[{"id":"1.170370557","rc":[{"atl":[[1.18,298.14]],"id":9624350}],"con":true,"img":false}]}
{"op":"mcm","clk":"1362122223","pt":1588428814705,"mc":[{"id":"1.170370557","rc":[{"atl":[[1.2,18.57]],"id":9624350}],"con":true,"img":false}]}
{"op":"mcm","clk":"1362122228","pt":1588428814860,"mc":[{"id":"1.170370557","rc":[{"atb":[[1.13,49.21]],"id":9624350}],"con":true,"img":false}]}
{"op":"mcm","clk":"1362122235","pt":1588428815379,"mc":[{"id":"1.170370557","rc":[{"trd":[[1.17,1705.46]],"ltp":1.17,"tv":1705.46,"id":9624350},{"atb":[[1.17,0]],"id":9624350},{"atl":[[1.17,22.49]],"id":9624350}],"con":true,"img":false}]}
{"op":"mcm","clk":"1362122248","pt":1588428815990,"mc":[{"id":"1.170370557","rc":[{"trd":[[1.16,707.68]],"ltp":1.16,"tv":707.68,"id":9624350},{"atl":[[1.16,140.27]],"id":9624350}],"con":true,"img":false}]}
{"op":"mcm","clk":"1362122250","pt":1588428816093,"mc":[{"id":"1.170370557","rc":[{"atl":[[1.18,293.77]],"id":9624350}],"con":true,"img":false}]}
{"op":"mcm","clk":"1362122253","pt":1588428816195,"mc":[{"id":"1.170370557","rc":[{"atl":[[1.16,153.57]],"id":9624350}],"con":true,"img":false}]}
{"op":"mcm","clk":"1362122265","pt":1588428816707,"mc":[{"id":"1.170370557","rc":[{"atl":[[1.16,13.29]],"id":9624350}],"con":true,"img":false}]}
{"op":"mcm","clk":"1362122268","pt":1588428816810,"mc":[{"id":"1.170370557","rc":[{"atl":[[1.17,0]],"id":9624350}],"con":true,"img":false}]}
{"op":"mcm","clk":"1362122271","pt":1588428816863,"mc":[{"id":"1.170370557","rc":[{"atb":[[1.14,55]],"id":9624350}],"con":true,"img":false}]}
{"op":"mcm","clk":"1362122276","pt":1588428817069,"mc":[{"id":"1.170370557","rc":[{"atl":[[1.16,101.95]],"id":9624350}],"con":true,"img":false}]}
{"op":"mcm","clk":"1362122280","pt":1588428817273,"mc":[{"id":"1.170370557","rc":[{"atl":[[1.16,485.81]],"id":9624350}],"con":true,"img":false}]}
{"op":"mcm","clk":"1362122284","pt":1588428817475,"mc":[{"id":"1.170370557","rc":[{"atb":[[1.1,1565.66]],"id":9624350}],"con":true,"img":false}]}
{"op":"mcm","clk":"1362122287","pt":1588428817782,"mc":[{"id":"1.170370557","rc":[{"atb":[[1.13,104.21]],"id":9624350}],"con":true,"img":false}]}
{"op":"mcm","clk":"1362122291","pt":1588428817987,"mc":[{"id":"1.170370557","rc":[{"atb":[[1.07,1860.33]],"id":9624350}],"con":true,"img":false}]}
{"op":"mcm","clk":"1362122294","pt":1588428818090,"mc":[{"id":"1.170370557","rc":[{"atb":[[1.13,159.21]],"id":9624350}],"con":true,"img":false}]}
{"op":"mcm","clk":"1362122299","pt":1588428818294,"mc":[{"id":"1.170370557","rc":[{"atb":[[1.13,469.49],[1.07,2637.33]],"id":9624350},{"atl":[[1.17,444]],"id":9624350}],"con":true,"img":false}]}
{"op":"mcm","clk":"1362122306","pt":1588428818498,"mc":[{"id":"1.170370557","rc":[{"atl":[[1.3,95]],"id":9624350}],"con":true,"img":false}]}
{"op":"mcm","clk":"1362122310","pt":1588428818600,"mc":[{"id":"1.170370557","rc":[{"atl":[[1.17,557.66]],"id":9624350}],"con":true,"img":false}]}
{"op":"mcm","clk":"1362122315","pt":1588428818804,"mc":[{"id":"1.170370557","rc":[{"trd":[[1.16,734.27]],"ltp":1.16,"tv":734.27,"id":9624350},{"atl":[[1.16,397.16]],"id":9624350}],"con":true,"img":false}]}
{"op":"mcm","clk":"1362122318","pt":1588428818906,"mc":[{"id":"1.170370557","rc":[{"atb":[[1.14,100.7],[1.08,777]],"id":9624350},{"atl":[[1.16,751.77]],"id":9624350}],"con":true,"img":false}]}
{"op":"mcm","clk":"1362122321","pt":1588428819008,"mc":[{"id":"1.170370557","rc":[{"atb":[[1.15,88.65]],"id":9624350},{"atl":[[1.17,444]],"id":9624350}],"con":true,"img":false}]}
{"op":"mcm","clk":"1362122326","pt":1588428819212,"mc":[{"id":"1.170370557","rc":[{"atb":[[1.08,1554],[1.15,177.3]],"id":9624350}],"con":true,"img":false}]}
{"op":"mcm","clk":"1362122328","pt":1588428819314,"mc":[{"id":"1.170370557","rc":[{"atb":[[1.15,265.95]],"id":9624350}],"con":true,"img":false}]}
{"op":"mcm","clk":"1362122332","pt":1588428819518,"mc":[{"id":"1.170370557","rc":[{"atb":[[1.15,354.6]],"id":9624350}],"con":true,"img":false}]}
{"op":"mcm","clk":"1362122335","pt":1588428819671,"mc":[{"id":"1.170370557","rc":[{"atb":[[1.15,443.26]],"id":9624350}],"con":true,"img":false}]}
{"op":"mcm","clk":"1362122340","pt":1588428819980,"mc":[{"id":"1.170370557","rc":[{"atb":[[1.13,420.28]],"id":9624350},{"atl":[[1.16,456.56],[1.17,754.28]],"id":9624350}],"con":true,"img":false}]}
{"op":"mcm","clk":"1362122342","pt":1588428820081,"mc":[{"id":"1.170370557","rc":[{"atl":[[1.18,205.12]],"id":9624350}],"con":true,"img":false}]}
{"op":"mcm","clk":"1362122346","pt":1588428820285,"mc":[{"id":"1.170370557","rc":[{"atb":[[1.15,531.91]],"id":9624350}],"con":true,"img":false}]}
{"op":"mcm","clk":"1362122352","pt":1588428820696,"mc":[{"id":"1.170370557","rc":[{"atl":[[1.17,929.28]],"id":9624350}],"con":true,"img":false}]}
{"op":"mcm","clk":"1362122356","pt":1588428821004,"mc":[{"id":"1.170370557","rc":[{"atb":[[1.15,586.91]],"id":9624350},{"atl":[[1.18,380.12]],"id":9624350}],"con":true,"img":false}]}
{"op":"mcm","clk":"1362122358","pt":1588428821107,"mc":[{"id":"1.170370557","rc":[{"atl":[[1.23,0],[1.17,619]],"id":9624350}],"con":true,"img":false}]}
{"op":"mcm","clk":"1362122360","pt":1588428821208,"mc":[{"id":"1.170370557","rc":[{"atb":[[1.14,211.7]],"id":9624350}],"con":true,"img":false}]}
{"op":"mcm","clk":"1362122361","pt":1588428821310,"mc":[{"id":"1.170370557","rc":[{"atl":[[1.17,623.37]],"id":9624350}],"con":true,"img":false}]}
{"op":"mcm","clk":"1362122366","pt":1588428821615,"mc":[{"id":"1.170370557","rc":[{"atl":[[1.18,175]],"id":9624350}],"con":true,"img":false}]}
{"op":"mcm","clk":"1362122368","pt":1588428821718,"mc":[{"id":"1.170370557","rc":[{"trd":[[1.16,774.27]],"ltp":1.16,"tv":774.27,"id":9624350},{"atl":[[1.16,436.56],[1.17,836.67]],"id":9624350}],"con":true,"img":false}]}
{"op":"mcm","clk":"1362122373","pt":1588428822082,"mc":[{"id":"1.170370557","rc":[{"atb":[[1.14,166]],"id":9624350}],"con":true,"img":false}]}
{"op":"mcm","clk":"1362122379","pt":1588428822487,"mc":[{"id":"1.170370557","rc":[{"trd":[[1.15,27.83]],"ltp":1.15,"tv":27.83,"id":9624350},{"atb":[[1.15,572.99]],"id":9624350}],"con":true,"img":false}]}
{"op":"mcm","clk":"1362122383","pt":1588428822691,"mc":[{"id":"1.170370557","rc":[{"atb":[[1.11,171]],"id":9624350},{"atl":[[1.17,636.67]],"id":9624350}],"con":true,"img":false}]}
{"op":"mcm","clk":"1362122390","pt":1588428822999,"mc":[{"id":"1.170370557","rc":[{"trd":[[1.15,35.1]],"ltp":1.15,"tv":35.1,"id":9624350},{"atb":[[1.14,431.95],[1.15,569.36]],"id":9624350}],"con":true,"img":false}]}
{"op":"mcm","clk":"1362122393","pt":1588428823205,"mc":[{"id":"1.170370557","rc":[{"atl":[[1.2,14.57]],"id":9624350}],"con":true,"img":false}]}
{"op":"mcm","clk":"1362122395","pt":1588428823307,"mc":[{"id":"1.170370557","rc":[{"atl":[[1.17,623.37]],"id":9624350}],"con":true,"img":false}]}
{"op":"mcm","clk":"1362122399","pt":1588428823512,"mc":[{"id":"1.170370557","rc":[{"atb":[[1.13,110]],"id":9624350},{"atl":[[1.17,179.37]],"id":9624350}],"con":true,"img":false}]}
{"op":"mcm","clk":"1362122401","pt":1588428823615,"mc":[{"id":"1.170370557","rc":[{"atl":[[1.19,182.27]],"id":9624350}],"con":true,"img":false}]}
{"op":"mcm","clk":"1362122413","pt":1588428824186,"mc":[{"id":"1.170370557","rc":[{"atb":[[1.15,640.28]],"id":9624350}],"con":true,"img":false}]}
{"op":"mcm","clk":"1362122416","pt":1588428824282,"mc":[{"id":"1.170370557","rc":[{"atl":[[1.17,175]],"id":9624350}],"con":true,"img":false}]}
{"op":"mcm","clk":"1362122419","pt":1588428824384,"mc":[{"id":"1.170370557","rc":[{"atl":[[1.2,0]],"id":9624350}],"con":true,"img":false}]}
{"op":"mcm","clk":"1362122426","pt":1588428824794,"mc":[{"id":"1.170370557","rc":[{"trd":[[1.15,100.86]],"ltp":1.15,"tv":100.86,"id":9624350},{"atb":[[1.15,536.48]],"id":9624350}],"con":true,"img":false}]}
{"op":"mcm","clk":"1362122429","pt":1588428824898,"mc":[{"id":"1.170370557","rc":[{"atl":[[1.19,440.95]],"id":9624350}],"con":true,"img":false}]}
{"op":"mcm","clk":"1362122435","pt":1588428825205,"mc":[{"id":"1.170370557","rc":[{"trd":[[1.16,774.32]],"ltp":1.16,"tv":774.32,"id":9624350},{"atl":[[1.16,436.53]],"id":9624350}],"con":true,"img":false}]}
{"op":"mcm","clk":"1362122440","pt":1588428825513,"mc":[{"id":"1.170370557","rc":[{"trd":[[1.15,965.51]],"ltp":1.15,"tv":965.51,"id":9624350},{"atb":[[1.15,104.15]],"id":9624350}],"con":true,"img":false}]}
{"op":"mcm","clk":"1362122445","pt":1588428825820,"mc":[{"id":"1.170370557","rc":[{"trd":[[1.15,1141.04]],"ltp":1.15,"tv":1141.04,"id":9624350},{"atb":[[1.15,16.39]],"id":9624350}],"con":true,"img":false}]}
{"op":"mcm","clk":"1362122448","pt":1588428825922,"mc":[{"id":"1.170370557","rc":[{"atl":[[1.16,525.18]],"id":9624350}],"con":true,"img":false}]}
{"op":"mcm","clk":"1362122453","pt":1588428826282,"mc":[{"id":"1.170370557","rc":[{"trd":[[1.16,854.31]],"ltp":1.16,"tv":854.31,"id":9624350},{"atl":[[1.16,485.19]],"id":9624350}],"con":true,"img":false}]}
{"op":"mcm","clk":"1362122456","pt":1588428826487,"mc":[{"id":"1.170370557","rc":[{"atb":[[1.11,60]],"id":9624350},{"atl":[[1.17,175.3]],"id":9624350}],"con":true,"img":false}]}
{"op":"mcm","clk":"1362122469","pt":1588428827410,"mc":[{"id":"1.170370557","rc":[{"trd":[[1.15,1173.82]],"ltp":1.15,"tv":1173.82,"id":9624350},{"atb":[[1.15,0]],"id":9624350},{"atl":[[1.15,173.24]],"id":9624350}],"con":true,"img":false}]}
{"op":"mcm","clk":"1362122474","pt":1588428827616,"mc":[{"id":"1.170370557","rc":[{"trd":[[8.2,6.9]],"ltp":8.2,"tv":6.9,"id":9622734},{"trd":[[1.14,49.63]],"ltp":1.14,"tv":49.63,"id":9624350},{"atb":[[1.14,382.32]],"id":9624350}],"con":true,"img":false}]}
{"op":"mcm","clk":"1362122482","pt":1588428828126,"mc":[{"id":"1.170370557","rc":[{"atb":[[1.09,650.13]],"id":9624350}],"con":true,"img":false}]}
{"op":"mcm","clk":"1362122487","pt":1588428828330,"mc":[{"id":"1.170370557","rc":[{"trd":[[1.14,67.87]],"ltp":1.14,"tv":67.87,"id":9624350},{"atb":[[1.14,373.2]],"id":9624350}],"con":true,"img":false}]}
{"op":"mcm","clk":"1362122499","pt":1588428829198,"mc":[{"id":"1.170370557","rc":[{"trd":[[1.15,1186.61]],"ltp":1.15,"tv":1186.61,"id":9624350},{"atl":[[1.15,166.85]],"id":9624350}],"con":true,"img":false}]}
{"op":"mcm","clk":"1362122504","pt":1588428829507,"mc":[{"id":"1.170370557","rc":[{"atl":[[1.15,171.22]],"id":9624350}],"con":true,"img":false}]}
{"op":"mcm","clk":"1362122506","pt":1588428829609,"mc":[{"id":"1.170370557","rc":[{"atl":[[1.16,354.6]],"id":9624350}],"con":true,"img":false}]}
{"op":"mcm","clk":"1362122509","pt":1588428829816,"mc":[{"id":"1.170370557","rc":[{"atb":[[1.13,0]],"id":9624350}],"con":true,"img":false}]}
{"op":"mcm","clk":"1362122512","pt":1588428830021,"mc":[{"id":"1.170370557","rc":[{"trd":[[1.15,1187.05]],"ltp":1.15,"tv":1187.05,"id":9624350},{"atb":[[1.1,1831.61]],"id":9624350},{"atl":[[1.15,171],[1.17,7.57]],"id":9624350}],"con":true,"img":false}]}
{"op":"mcm","clk":"1362122517","pt":1588428830429,"mc":[{"id":"1.170370557","rc":[{"trd":[[1.15,1340.71]],"ltp":1.15,"tv":1340.71,"id":9624350},{"atl":[[1.15,94.17]],"id":9624350}],"con":true,"img":false}]}
{"op":"mcm","clk":"1362122523","pt":1588428830894,"mc":[{"id":"1.170370557","rc":[{"trd":[[1.15,1450.71]],"ltp":1.15,"tv":1450.71,"id":9624350},{"atl":[[1.15,39.17]],"id":9624350}],"con":true,"img":false}]}
{"op":"mcm","clk":"1362122536","pt":1588428831606,"mc":[{"id":"1.170370557","rc":[{"trd":[[1.14,68.6]],"ltp":1.14,"tv":68.6,"id":9624350},{"atb":[[1.14,372.83],[1.13,111]],"id":9624350}],"con":true,"img":false}]}
{"op":"mcm","clk":"1362122545","pt":1588428832015,"mc":[{"id":"1.170370557","rc":[{"atl":[[1.16,443.26]],"id":9624350}],"con":true,"img":false}]}
{"op":"mcm","clk":"1362122549","pt":1588428832117,"mc":[{"id":"1.170370557","rc":[{"atl":[[1.16,531.91]],"id":9624350}],"con":true,"img":false}]}
{"op":"mcm","clk":"1362122556","pt":1588428832424,"mc":[{"id":"1.170370557","rc":[{"atb":[[1.11,947.13]],"id":9624350},{"atl":[[1.16,620.56]],"id":9624350}],"con":true,"img":false}]}
{"op":"mcm","clk":"1362122559","pt":1588428832526,"mc":[{"id":"1.170370557","rc":[{"trd":[[1.15,1529.05]],"ltp":1.15,"tv":1529.05,"id":9624350},{"atb":[[1.15,15.83]],"id":9624350},{"atl":[[1.15,0]],"id":9624350}],"con":true,"img":false}]}
{"op":"mcm","clk":"1362122562","pt":1588428832628,"mc":[{"id":"1.170370557","rc":[{"atl":[[1.16,709.21],[1.17,8.05]],"id":9624350}],"con":true,"img":false}]}
{"op":"mcm","clk":"1362122564","pt":1588428832730,"mc":[{"id":"1.170370557","rc":[{"atl":[[1.16,531.91]],"id":9624350}],"con":true,"img":false}]}
{"op":"mcm","clk":"1362122567","pt":1588428832885,"mc":[{"id":"1.170370557","rc":[{"atb":[[1.1,2807.45]],"id":9624350},{"atl":[[1.16,443.26]],"id":9624350}],"con":true,"img":false}]}
{"op":"mcm","clk":"1362122572","pt":1588428833090,"mc":[{"id":"1.170370557","rc":[{"atb":[[1.04,3140.41]],"id":9624350},{"atl":[[1.16,0]],"id":9624350}],"con":true,"img":false}]}
{"op":"mcm","clk":"1362122576","pt":1588428833396,"mc":[{"id":"1.170370557","rc":[{"atb":[[1.12,376.95],[1.04,3917.41]],"id":9624350}],"con":true,"img":false}]}
{"op":"mcm","clk":"1362122578","pt":1588428833497,"mc":[{"id":"1.170370557","rc":[{"atb":[[1.09,1734.39]],"id":9624350}],"con":true,"img":false}]}
{"op":"mcm","clk":"1362122581","pt":1588428833600,"mc":[{"id":"1.170370557","rc":[{"trd":[[1.15,1560.71]],"ltp":1.15,"tv":1560.71,"id":9624350},{"atb":[[1.15,0]],"id":9624350},{"atl":[[1.15,365.17]],"id":9624350}],"con":true,"img":false}]}
{"op":"mcm","clk":"1362122585","pt":1588428833804,"mc":[{"id":"1.170370557","rc":[{"atl":[[1.18,0]],"id":9624350}],"con":true,"img":false}]}
{"op":"mcm","clk":"1362122588","pt":1588428834011,"mc":[{"id":"1.170370557","rc":[{"atb":[[1.03,3061.35],[1.08,2773.79]],"id":9624350}],"con":true,"img":false}]}
{"op":"mcm","clk":"1362122591","pt":1588428834218,"mc":[{"id":"1.170370557","rc":[{"trd":[[1.15,1797.31]],"ltp":1.15,"tv":1797.31,"id":9624350},{"atl":[[1.15,246.87]],"id":9624350}],"con":true,"img":false}]}
{"op":"mcm","clk":"1362122593","pt":1588428834323,"mc":[{"id":"1.170370557","rc":[{"atb":[[1.03,3838.35]],"id":9624350},{"atl":[[1.19,265.95]],"id":9624350}],"con":true,"img":false}]}
{"op":"mcm","clk":"1362122598","pt":1588428834734,"mc":[{"id":"1.170370557","rc":[{"atb":[[1.07,4031.39]],"id":9624350}],"con":true,"img":false}]}
{"op":"mcm","clk":"1362122602","pt":1588428834894,"mc":[{"id":"1.170370557","rc":[{"trd":[[1.15,2291.05]],"ltp":1.15,"tv":2291.05,"id":9624350},{"atb":[[1.16,107.73]],"id":9624350},{"atl":[[1.15,0]],"id":9624350}],"con":true,"img":false}]}
{"op":"mcm","clk":"1362122606","pt":1588428835096,"mc":[{"id":"1.170370557","rc":[{"atb":[[1.13,215.49]],"id":9624350}],"con":true,"img":false}]}
{"op":"mcm","clk":"1362122608","pt":1588428835198,"mc":[{"id":"1.170370557","rc":[{"atb":[[1.1,1241.79],[1.16,196.39]],"id":9624350}],"con":true,"img":false}]}
{"op":"mcm","clk":"1362122612","pt":1588428835402,"mc":[{"id":"1.170370557","rc":[{"atb":[[1.16,285.04]],"id":9624350}],"con":true,"img":false}]}
{"op":"mcm","clk":"1362122614","pt":1588428835504,"mc":[{"id":"1.170370557","rc":[{"atb":[[1.16,373.69]],"id":9624350}],"con":true,"img":false}]}
{"op":"mcm","clk":"1362122618","pt":1588428835708,"mc":[{"id":"1.170370557","rc":[{"atb":[[1.16,462.34]],"id":9624350}],"con":true,"img":false}]}
{"op":"mcm","clk":"1362122620","pt":1588428835811,"mc":[{"id":"1.170370557","rc":[{"atb":[[1.15,111]],"id":9624350}],"con":true,"img":false}]}
{"op":"mcm","clk":"1362122622","pt":1588428835921,"mc":[{"id":"1.170370557","rc":[{"trd":[[1.14,244.62],[1.15,2513.05],[1.16,1956.3]],"ltp":1.14,"tv":4713.97,"id":9624350},{"atb":[[1.14,284.82],[1.16,0],[1.15,0]],"id":9624350}],"con":true,"img":false}]}
{"op":"mcm","clk":"1362122626","pt":1588428836224,"mc":[{"id":"1.170370557","rc":[{"trd":[[1.14,814.28]],"ltp":1.14,"tv":814.28,"id":9624350},{"atb":[[1.14,0]],"id":9624350},{"atl":[[1.14,465.17]],"id":9624350}],"con":true,"img":false}]}
{"op":"mcm","clk":"1362122630","pt":1588428836531,"mc":[{"id":"1.170370557","rc":[{"trd":[[1.14,991.58]],"ltp":1.14,"tv":991.58,"id":9624350},{"atl":[[1.14,376.52]],"id":9624350}],"con":true,"img":false}]}
{"op":"mcm","clk":"1362122633","pt":1588428836687,"mc":[{"id":"1.170370557","rc":[{"trd":[[1.14,1168.89]],"ltp":1.14,"tv":1168.89,"id":9624350},{"atl":[[1.14,287.87]],"id":9624350}],"con":true,"img":false}]}
{"op":"mcm","clk":"1362122639","pt":1588428837096,"mc":[{"id":"1.170370557","rc":[{"trd":[[1.14,1346.19]],"ltp":1.14,"tv":1346.19,"id":9624350},{"atl":[[1.14,199.22]],"id":9624350}],"con":true,"img":false}]}
{"op":"mcm","clk":"1362122650","pt":1588428837710,"mc":[{"id":"1.170370557","rc":[{"atb":[[1.13,111]],"id":9624350}],"con":true,"img":false}]}
{"op":"mcm","clk":"1362122653","pt":1588428837813,"mc":[{"id":"1.170370557","rc":[{"atb":[[1.12,265.95],[1.13,0]],"id":9624350}],"con":true,"img":false}]}
{"op":"mcm","clk":"1362122657","pt":1588428838018,"mc":[{"id":"1.170370557","rc":[{"trd":[[1.14,1472.82]],"ltp":1.14,"tv":1472.82,"id":9624350},{"atl":[[1.14,135.9]],"id":9624350}],"con":true,"img":false}]}
{"op":"mcm","clk":"1362122678","pt":1588428839397,"mc":[{"id":"1.170370557","rc":[{"atl":[[1.14,150.47]],"id":9624350}],"con":true,"img":false}]}
{"op":"mcm","clk":"1362122688","pt":1588428840111,"mc":[{"id":"1.170370557","rc":[{"trd":[[1.16,2057.27],[1.14,1773.78]],"ltp":1.16,"tv":3831.05,"id":9624350},{"atl":[[1.21,0],[1.14,0],[1.16,38.16]],"id":9624350}],"con":true,"img":false}]}
{"op":"mcm","clk":"1362122692","pt":1588428840315,"mc":[{"id":"1.170370557","rc":[{"atb":[[8.2,6.32]],"id":9622734},{"atl":[[1.16,126.81]],"id":9624350}],"con":true,"img":false}]}
{"op":"mcm","clk":"1362122694","pt":1588428840417,"mc":[{"id":"1.170370557","rc":[{"atb":[[8.2,12.02]],"id":9622734}],"con":true,"img":false}]}
{"op":"mcm","clk":"1362122697","pt":1588428840519,"mc":[{"id":"1.170370557","rc":[{"atb":[[8.2,5.7]],"id":9622734}],"con":true,"img":false}]}
{"op":"mcm","clk":"1362122699","pt":1588428840621,"mc":[{"id":"1.170370557","rc":[{"atb":[[8.2,0]],"id":9622734}],"con":true,"img":false}]}
{"op":"mcm","clk":"1362122705","pt":1588428841032,"mc":[{"id":"1.170370557","rc":[{"atl":[[1.17,96.7]],"id":9624350}],"con":true,"img":false}]}
{"op":"mcm","clk":"1362122711","pt":1588428841291,"mc":[{"id":"1.170370557","rc":[{"atl":[[1.17,185.35]],"id":9624350}],"con":true,"img":false}]}
{"op":"mcm","clk":"1362122728","pt":1588428842110,"mc":[{"id":"1.170370557","rc":[{"trd":[[1.16,2167.28]],"ltp":1.16,"tv":2167.28,"id":9624350},{"atl":[[1.16,71.8]],"id":9624350}],"con":true,"img":false}]}
{"op":"mcm","clk":"1362122732","pt":1588428842212,"mc":[{"id":"1.170370557","rc":[{"atl":[[1.16,160.46]],"id":9624350}],"con":true,"img":false}]}
{"op":"mcm","clk":"1362122736","pt":1588428842315,"mc":[{"id":"1.170370557","rc":[{"atl":[[1.17,8.05]],"id":9624350}],"con":true,"img":false}]}
{"op":"mcm","clk":"1362122740","pt":1588428842418,"mc":[{"id":"1.170370557","rc":[{"atl":[[1.16,249.11]],"id":9624350}],"con":true,"img":false}]}
{"op":"mcm","clk":"1362122744","pt":1588428842724,"mc":[{"id":"1.170370557","rc":[{"atb":[[1.14,55]],"id":9624350},{"atl":[[1.16,337.76]],"id":9624350}],"con":true,"img":false}]}
{"op":"mcm","clk":"1362122749","pt":1588428843032,"mc":[{"id":"1.170370557","rc":[{"atb":[[1.14,175.06]],"id":9624350},{"atl":[[1.15,88.65]],"id":9624350}],"con":true,"img":false}]}
{"op":"mcm","clk":"1362122751","pt":1588428843136,"mc":[{"id":"1.170370557","rc":[{"atb":[[1.14,120.06]],"id":9624350}],"con":true,"img":false}]}
{"op":"mcm","clk":"1362122765","pt":1588428843342,"mc":[{"id":"1.170370557","rc":[{"trd":[[8.2,16.9]],"ltp":8.2,"tv":16.9,"id":9622734},{"trd":[[1.14,1845.71]],"ltp":1.14,"tv":1845.71,"id":9624350},{"atb":[[1.14,48.12]],"id":9624350},{"atl":[[1.15,177.3]],"id":9624350}],"con":true,"img":false}]}
