{"op":"mcm","clk":"1349943137","pt":1588413012602,"mc":[{"id":"1.170370562","rc":[{"atb":[[2.36,0]],"id":9625043}],"con":true,"img":false}]}
{"op":"mcm","clk":"1349943139","pt":1588413012703,"mc":[{"id":"1.170370562","rc":[{"atb":[[2.38,1.79]],"id":9625043}],"con":true,"img":false}]}
{"op":"mcm","clk":"1349943141","pt":1588413012808,"mc":[{"id":"1.170370562","rc":[{"atb":[[2.1,80.26]],"id":9625043}],"con":true,"img":false}]}
{"op":"mcm","clk":"1349943214","pt":1588413016777,"mc":[{"id":"1.170370562","rc":[{"atl":[[1.81,0]],"id":9631798}],"con":true,"img":false}]}
{"op":"mcm","clk":"1349943303","pt":1588413022188,"mc":[{"id":"1.170370562","rc":[{"atb":[[2.22,24.32]],"id":9625043}],"con":true,"img":false}]}
{"op":"mcm","clk":"1349943390","pt":1588413027908,"mc":[{"id":"1.170370562","rc":[{"atl":[[1.7,4.37]],"id":9631798}],"con":true,"img":false}]}
{"op":"mcm","clk":"1349943404","pt":1588413028833,"mc":[{"id":"1.170370562","rc":[{"atb":[[2.34,19.84]],"id":9625043}],"con":true,"img":false}]}
{"op":"mcm","clk":"1349943406","pt":1588413028936,"mc":[{"id":"1.170370562","rc":[{"atb":[[2.1,56.09]],"id":9625043}],"con":true,"img":false}]}
{"op":"mcm","clk":"1349943588","pt":1588413039049,"mc":[{"id":"1.170370562","rc":[{"trd":[[1.7,10.81],[1.68,5.53]],"ltp":1.7,"tv":16.34,"id":9631798},{"atl":[[1.68,0],[1.7,0.96]],"id":9631798}],"con":true,"img":false}]}
{"op":"mcm","clk":"1349943602","pt":1588413039927,"mc":[{"id":"1.170370562","rc":[{"atb":[[2.34,0]],"id":9625043}],"con":true,"img":false}]}
{"op":"mcm","clk":"1349943964","pt":1588413056154,"mc":[{"id":"1.170370562","rc":[{"trd":[[1.71,292.02],[1.7,12.74]],"ltp":1.71,"tv":304.76,"id":9631798},{"atl":[[1.7,0],[1.71,17.5]],"id":9631798}],"con":true,"img":false}]}
{"op":"mcm","clk":"1349943978","pt":1588413056972,"mc":[{"id":"1.170370562","rc":[{"atb":[[1.61,1.77]],"id":9631798}],"con":true,"img":false}]}
{"op":"mcm","clk":"1349943990","pt":1588413057894,"mc":[{"id":"1.170370562","rc":[{"atb":[[1.64,41.56]],"id":9631798}],"con":true,"img":false}]}
{"op":"mcm","clk":"1349944062","pt":1588413061694,"mc":[{"id":"1.170370562","rc":[{"trd":[[1.67,7.1]],"ltp":1.67,"tv":7.1,"id":9631798},{"atb":[[1.67,87.29]],"id":9631798}],"con":true,"img":false}]}
{"op":"mcm","clk":"1349944147","pt":1588413066186,"mc":[{"id":"1.170370562","rc":[{"atb":[[1.67,176.35]],"id":9631798}],"con":true,"img":false}]}
{"op":"mcm","clk":"1349944149","pt":1588413066289,"mc":[{"id":"1.170370562","rc":[{"atb":[[1.67,89.06]],"id":9631798}],"con":true,"img":false}]}
{"op":"mcm","clk":"1349944239","pt":1588413072392,"mc":[{"id":"1.170370562","rc":[{"trd":[[1.67,12.25]],"ltp":1.67,"tv":12.25,"id":9631798},{"atb":[[1.67,86.48]],"id":9631798}],"con":true,"img":false}]}
{"op":"mcm","clk":"1349944290","pt":1588413076290,"mc":[{"id":"1.170370562","rc":[{"atb":[[1.67,175.54]],"id":9631798}],"con":true,"img":false}]}
{"op":"mcm","clk":"1349944292","pt":1588413076393,"mc":[{"id":"1.170370562","rc":[{"atb":[[1.67,89.06]],"id":9631798}],"con":true,"img":false}]}
{"op":"mcm","clk":"1349944573","pt":1588413094669,"mc":[{"id":"1.170370562","rc":[{"trd":[[1.71,296.02]],"ltp":1.71,"tv":296.02,"id":9631798},{"atl":[[1.71,15.5]],"id":9631798}],"con":true,"img":false}]}
{"op":"mcm","clk":"1349944820","pt":1588413108204,"mc":[{"id":"1.170370562","rc":[{"atb":[[1.8,2]],"id":9625043}],"con":true,"img":false}]}
{"op":"mcm","clk":"1349944941","pt":1588413114901,"mc":[{"id":"1.170370562","rc":[{"trd":[[1.67,17.5]],"ltp":1.67,"tv":17.5,"id":9631798},{"atb":[[1.67,86.44]],"id":9631798}],"con":true,"img":false}]}
{"op":"mcm","clk":"1349944981","pt":1588413116296,"mc":[{"id":"1.170370562","rc":[{"atb":[[1.67,89.06]],"id":9631798}],"con":true,"img":false}]}
{"op":"mcm","clk":"1349945052","pt":1588413119520,"mc":[{"id":"1.170370562","marketDefinition":{"bspMarket":false,"turnInPlayEnabled":true,"persistenceEnabled":true,"marketBaseRate":5.0,"eventId":"29788105","eventTypeId":"2","numberOfWinners":1,"bettingType":"ODDS","marketType":"MATCH_ODDS","marketTime":"2020-05-02T09:50:00.000Z","suspendTime":"2020-05-02T09:50:00.000Z","bspReconciled":false,"complete":true,"inPlay":true,"crossMatching":true,"runnersVoidable":false,"numberOfActiveRunners":2,"betDelay":5,"status":"OPEN","runners":[{"status":"ACTIVE","sortPriority":1,"id":9631798,"name":"B Hassan"},{"status":"ACTIVE","sortPriority":2,"id":9625043,"name":"J Haerteis"}],"regulators":["MR_INT"],"countryCode":"GB","discountAllowed":true,"timezone":"GMT","openDate":"2020-05-02T09:50:00.000Z","version":3237483164,"name":"Match Odds","eventName":"B Hassan v J Haerteis"},"rc":[],"con":true,"img":false},{"id":"1.170370562","rc":[{"atb":[[2.32,0],[2.22,0],[1.1,0],[2.1,0],[1.71,0],[1.11,0],[2.38,0],[1.5,0],[2.18,0],[1.66,0]],"id":9625043},{"atb":[[1.64,0],[1.51,0],[1.1,0],[1.4,0],[1.63,0],[1.11,0],[1.67,0],[1.42,0],[1.66,0],[1.61,0]],"id":9631798},{"atl":[[1.73,0],[2.4,0],[1.82,0],[3.1,0],[1.88,0],[1.75,0]],"id":9631798}],"con":true,"img":false}]}
{"op":"mcm","clk":"1349945301","pt":1588413130150,"mc":[{"id":"1.170370562","rc":[{"atb":[[1.1,159.97]],"id":9631798}],"con":true,"img":false}]}
{"op":"mcm","clk":"1349945303","pt":1588413130256,"mc":[{"id":"1.170370562","rc":[{"atb":[[1.1,319.94]],"id":9631798}],"con":true,"img":false}]}
{"op":"mcm","clk":"1349945308","pt":1588413130461,"mc":[{"id":"1.170370562","rc":[{"atb":[[1.1,479.92]],"id":9631798}],"con":true,"img":false}]}
{"op":"mcm","clk":"1349945313","pt":1588413130666,"mc":[{"id":"1.170370562","rc":[{"atb":[[1.1,639.89]],"id":9631798}],"con":true,"img":false}]}
{"op":"mcm","clk":"1349945315","pt":1588413130717,"mc":[{"id":"1.170370562","rc":[{"atb":[[1.1,799.87]],"id":9631798}],"con":true,"img":false}]}
{"op":"mcm","clk":"1349945403","pt":1588413135366,"mc":[{"id":"1.170370562","rc":[{"atb":[[1.25,63.98]],"id":9625043}],"con":true,"img":false}]}
{"op":"mcm","clk":"1349945407","pt":1588413135468,"mc":[{"id":"1.170370562","rc":[{"atb":[[1.25,127.97]],"id":9625043}],"con":true,"img":false}]}
{"op":"mcm","clk":"1349945417","pt":1588413135932,"mc":[{"id":"1.170370562","rc":[{"atb":[[1.25,191.96]],"id":9625043}],"con":true,"img":false}]}
{"op":"mcm","clk":"1349945420","pt":1588413136034,"mc":[{"id":"1.170370562","rc":[{"atb":[[1.25,255.95]],"id":9625043}],"con":true,"img":false}]}
{"op":"mcm","clk":"1349945423","pt":1588413136138,"mc":[{"id":"1.170370562","rc":[{"atb":[[1.25,319.94]],"id":9625043}],"con":true,"img":false}]}
{"op":"mcm","clk":"1349945465","pt":1588413137637,"mc":[{"id":"1.170370562","rc":[{"atb":[[2.1,1.84]],"id":9625043}],"con":true,"img":false}]}
{"op":"mcm","clk":"1349945512","pt":1588413139541,"mc":[{"id":"1.170370562","rc":[{"atb":[[1.15,106.64]],"id":9631798}],"con":true,"img":false}]}
{"op":"mcm","clk":"1349945517","pt":1588413139749,"mc":[{"id":"1.170370562","rc":[{"atb":[[1.15,213.29]],"id":9631798}],"con":true,"img":false}]}
{"op":"mcm","clk":"1349945520","pt":1588413139851,"mc":[{"id":"1.170370562","rc":[{"atb":[[1.15,319.94]],"id":9631798}],"con":true,"img":false}]}
{"op":"mcm","clk":"1349945522","pt":1588413139956,"mc":[{"id":"1.170370562","rc":[{"atb":[[1.15,426.58]],"id":9631798}],"con":true,"img":false}]}
{"op":"mcm","clk":"1349945525","pt":1588413140057,"mc":[{"id":"1.170370562","rc":[{"atb":[[1.46,226.06]],"id":9631798}],"con":true,"img":false}]}
{"op":"mcm","clk":"1349945528","pt":1588413140160,"mc":[{"id":"1.170370562","rc":[{"atb":[[1.15,533.23]],"id":9631798}],"con":true,"img":false}]}
{"op":"mcm","clk":"1349945626","pt":1588413144281,"mc":[{"id":"1.170370562","rc":[{"atb":[[1.2,79.98]],"id":9631798}],"con":true,"img":false}]}
{"op":"mcm","clk":"1349945634","pt":1588413144645,"mc":[{"id":"1.170370562","rc":[{"atb":[[1.2,159.97]],"id":9631798}],"con":true,"img":false}]}
{"op":"mcm","clk":"1349945637","pt":1588413144745,"mc":[{"id":"1.170370562","rc":[{"atb":[[1.2,239.96]],"id":9631798}],"con":true,"img":false}]}
{"op":"mcm","clk":"1349945639","pt":1588413144852,"mc":[{"id":"1.170370562","rc":[{"atb":[[1.2,319.94]],"id":9631798}],"con":true,"img":false}]}
{"op":"mcm","clk":"1349945644","pt":1588413145057,"mc":[{"id":"1.170370562","rc":[{"atb":[[1.2,399.93]],"id":9631798}],"con":true,"img":false}]}
{"op":"mcm","clk":"1349945672","pt":1588413146091,"mc":[{"id":"1.170370562","rc":[{"atb":[[1.4,239.96]],"id":9631798}],"con":true,"img":false}]}
{"op":"mcm","clk":"1349945750","pt":1588413150266,"mc":[{"id":"1.170370562","rc":[{"atb":[[1.5,239.96]],"id":9631798}],"con":true,"img":false}]}
{"op":"mcm","clk":"1349945790","pt":1588413152288,"mc":[{"id":"1.170370562","rc":[{"atb":[[1.47,34.03]],"id":9631798}],"con":true,"img":false}]}
{"op":"mcm","clk":"1349945846","pt":1588413154510,"mc":[{"id":"1.170370562","rc":[{"atb":[[1.41,39.01]],"id":9631798}],"con":true,"img":false}]}
{"op":"mcm","clk":"1349946023","pt":1588413161482,"mc":[{"id":"1.170370562","rc":[{"atb":[[1.52,234.92]],"id":9631798}],"con":true,"img":false}]}
{"op":"mcm","clk":"1349946207","pt":1588413170798,"mc":[{"id":"1.170370562","rc":[{"atb":[[1.47,0]],"id":9631798}],"con":true,"img":false}]}
{"op":"mcm","clk":"1349946219","pt":1588413171314,"mc":[{"id":"1.170370562","rc":[{"atb":[[1.53,0.11]],"id":9631798}],"con":true,"img":false}]}
{"op":"mcm","clk":"1349946240","pt":1588413172706,"mc":[{"id":"1.170370562","rc":[{"atl":[[3,5]],"id":9625043}],"con":true,"img":false}]}
{"op":"mcm","clk":"1349946265","pt":1588413173894,"mc":[{"id":"1.170370562","rc":[{"atb":[[1.53,13.23]],"id":9631798}],"con":true,"img":false}]}
{"op":"mcm","clk":"1349946325","pt":1588413176733,"mc":[{"id":"1.170370562","rc":[{"atb":[[1.4,0],[1.5,0]],"id":9631798}],"con":true,"img":false}]}
{"op":"mcm","clk":"1349946359","pt":1588413179002,"mc":[{"id":"1.170370562","rc":[{"atb":[[1.41,0]],"id":9631798}],"con":true,"img":false}]}
{"op":"mcm","clk":"1349946496","pt":1588413185024,"mc":[{"id":"1.170370562","rc":[{"atb":[[1.53,90.36]],"id":9631798}],"con":true,"img":false}]}
{"op":"mcm","clk":"1349946557","pt":1588413187507,"mc":[{"id":"1.170370562","rc":[{"trd":[[2.4,48.86]],"ltp":2.4,"tv":48.86,"id":9625043},{"trd":[[1.71,308.47]],"ltp":1.71,"tv":308.47,"id":9631798},{"atl":[[1.71,3.05]],"id":9631798}],"con":true,"img":false}]}
{"op":"mcm","clk":"1349946865","pt":1588413203170,"mc":[{"id":"1.170370562","rc":[{"atb":[[1.55,0.47]],"id":9631798}],"con":true,"img":false}]}
{"op":"mcm","clk":"1349946952","pt":1588413208664,"mc":[{"id":"1.170370562","rc":[{"atb":[[1.53,90.24]],"id":9631798}],"con":true,"img":false}]}
{"op":"mcm","clk":"1349947141","pt":1588413219389,"mc":[{"id":"1.170370562","rc":[{"trd":[[2.1,3.69],[2.4,51.03]],"ltp":2.1,"tv":54.72,"id":9625043},{"atb":[[2.1,0]],"id":9625043},{"atl":[[2.1,66.36]],"id":9625043},{"trd":[[1.71,311.53]],"ltp":1.71,"tv":311.53,"id":9631798},{"atl":[[1.71,0]],"id":9631798}],"con":true,"img":false}]}
{"op":"mcm","clk":"1349947266","pt":1588413224266,"mc":[{"id":"1.170370562","rc":[{"atb":[[1.55,0]],"id":9631798}],"con":true,"img":false}]}
{"op":"mcm","clk":"1349947299","pt":1588413225765,"mc":[{"id":"1.170370562","rc":[{"atb":[[1.1,813]],"id":9631798}],"con":true,"img":false}]}
{"op":"mcm","clk":"1349947362","pt":1588413228191,"mc":[{"id":"1.170370562","rc":[{"trd":[[2.1,70.05]],"ltp":2.1,"tv":70.05,"id":9625043},{"atl":[[2.1,0]],"id":9625043},{"trd":[[1.9,73.35]],"ltp":1.9,"tv":73.35,"id":9631798},{"atl":[[1.9,4.66]],"id":9631798}],"con":true,"img":false}]}
{"op":"mcm","clk":"1349947446","pt":1588413231977,"mc":[{"id":"1.170370562","rc":[{"atl":[[1.91,4]],"id":9631798}],"con":true,"img":false}]}
{"op":"mcm","clk":"1349947471","pt":1588413232954,"mc":[{"id":"1.170370562","rc":[{"atl":[[1.9,9.03]],"id":9631798}],"con":true,"img":false}]}
{"op":"mcm","clk":"1349947499","pt":1588413234090,"mc":[{"id":"1.170370562","rc":[{"atl":[[1.9,9.15]],"id":9631798}],"con":true,"img":false}]}
{"op":"mcm","clk":"1349947840","pt":1588413246605,"mc":[{"id":"1.170370562","rc":[{"trd":[[2.1,75.15]],"ltp":2.1,"tv":75.15,"id":9625043},{"trd":[[1.9,78.98]],"ltp":1.9,"tv":78.98,"id":9631798},{"atl":[[1.9,3.51]],"id":9631798}],"con":true,"img":false}]}
{"op":"mcm","clk":"1349947957","pt":1588413252004,"mc":[{"id":"1.170370562","rc":[{"atl":[[1.88,0.11]],"id":9631798}],"con":true,"img":false}]}
{"op":"mcm","clk":"1349948068","pt":1588413256625,"mc":[{"id":"1.170370562","rc":[{"atl":[[1.9,9.4]],"id":9631798}],"con":true,"img":false}]}
{"op":"mcm","clk":"1349949377","pt":1588413273161,"mc":[{"id":"1.170370562","rc":[{"atb":[[1.6,71.98]],"id":9631798}],"con":true,"img":false}]}
{"op":"mcm","clk":"1349949388","pt":1588413273469,"mc":[{"id":"1.170370562","rc":[{"atb":[[2,126.77]],"id":9625043}],"con":true,"img":false}]}
{"op":"mcm","clk":"1349949544","pt":1588413281580,"mc":[{"id":"1.170370562","rc":[{"atl":[[1.9,129.38]],"id":9631798}],"con":true,"img":false}]}
{"op":"mcm","clk":"1349949661","pt":1588413287181,"mc":[{"id":"1.170370562","rc":[{"atl":[[1.8,71.98]],"id":9631798}],"con":true,"img":false}]}
{"op":"mcm","clk":"1349949695","pt":1588413288770,"mc":[{"id":"1.170370562","rc":[{"atb":[[1.1,3.19]],"id":9625043}],"con":true,"img":false}]}
{"op":"mcm","clk":"1349949770","pt":1588413292073,"mc":[{"id":"1.170370562","rc":[{"atl":[[1.89,86.87]],"id":9631798}],"con":true,"img":false}]}
{"op":"mcm","clk":"1349949973","pt":1588413301599,"mc":[{"id":"1.170370562","rc":[{"atl":[[1.9,9.4]],"id":9631798}],"con":true,"img":false}]}
{"op":"mcm","clk":"1349949989","pt":1588413302114,"mc":[{"id":"1.170370562","rc":[{"atb":[[1.1,4.99]],"id":9625043}],"con":true,"img":false}]}
{"op":"mcm","clk":"1349950065","pt":1588413304593,"mc":[{"id":"1.170370562","rc":[{"atb":[[1.68,88.65]],"id":9631798}],"con":true,"img":false}]}
{"op":"mcm","clk":"1349950094","pt":1588413305629,"mc":[{"id":"1.170370562","rc":[{"atb":[[1.1,1.79]],"id":9625043}],"con":true,"img":false}]}
{"op":"mcm","clk":"1349950277","pt":1588413312324,"mc":[{"id":"1.170370562","rc":[{"atl":[[1.78,0.11]],"id":9631798}],"con":true,"img":false}]}
{"op":"mcm","clk":"1349950420","pt":1588413318761,"mc":[{"id":"1.170370562","rc":[{"atl":[[1.88,0]],"id":9631798}],"con":true,"img":false}]}
{"op":"mcm","clk":"1349950495","pt":1588413321965,"mc":[{"id":"1.170370562","rc":[{"trd":[[1.68,23.03]],"ltp":1.68,"tv":23.03,"id":9631798},{"atb":[[1.68,79.9]],"id":9631798}],"con":true,"img":false}]}
{"op":"mcm","clk":"1349950610","pt":1588413326169,"mc":[{"id":"1.170370562","rc":[{"trd":[[1.8,252.33],[1.78,0.23]],"ltp":1.8,"tv":252.56,"id":9631798},{"atl":[[1.8,70.33],[1.78,0]],"id":9631798}],"con":true,"img":false}]}
{"op":"mcm","clk":"1349950749","pt":1588413332035,"mc":[{"id":"1.170370562","rc":[{"atl":[[1.9,9.28]],"id":9631798}],"con":true,"img":false}]}
{"op":"mcm","clk":"1349951101","pt":1588413349191,"mc":[{"id":"1.170370562","rc":[{"atb":[[1.01,1091.33]],"id":9631798}],"con":true,"img":false}]}
{"op":"mcm","clk":"1349951109","pt":1588413349499,"mc":[{"id":"1.170370562","rc":[{"atb":[[1.01,1089.78]],"id":9631798}],"con":true,"img":false}]}
{"op":"mcm","clk":"1349951117","pt":1588413349807,"mc":[{"id":"1.170370562","rc":[{"atb":[[1.01,1088.13]],"id":9631798}],"con":true,"img":false}]}
{"op":"mcm","clk":"1349951144","pt":1588413350787,"mc":[{"id":"1.170370562","rc":[{"atb":[[1.64,0.11]],"id":9631798}],"con":true,"img":false}]}
{"op":"mcm","clk":"1349951169","pt":1588413352075,"mc":[{"id":"1.170370562","rc":[{"trd":[[2.24,2.43]],"ltp":2.24,"tv":2.43,"id":9625043},{"trd":[[1.8,255.36]],"ltp":1.8,"tv":255.36,"id":9631798},{"atl":[[1.8,67.3]],"id":9631798}],"con":true,"img":false}]}
{"op":"mcm","clk":"1349951219","pt":1588413354905,"mc":[{"id":"1.170370562","rc":[{"atb":[[1.7,1.65]],"id":9631798}],"con":true,"img":false}]}
{"op":"mcm","clk":"1349951496","pt":1588413367417,"mc":[{"id":"1.170370562","rc":[{"atb":[[1.01,1091.33]],"id":9631798}],"con":true,"img":false}]}
{"op":"mcm","clk":"1349951505","pt":1588413367726,"mc":[{"id":"1.170370562","rc":[{"atb":[[1.01,1091.16]],"id":9631798}],"con":true,"img":false}]}
{"op":"mcm","clk":"1349951513","pt":1588413368034,"mc":[{"id":"1.170370562","rc":[{"atb":[[1.01,1088.13]],"id":9631798}],"con":true,"img":false}]}
{"op":"mcm","clk":"1349951630","pt":1588413373147,"mc":[{"id":"1.170370562","rc":[{"atb":[[1.7,4.68]],"id":9631798}],"con":true,"img":false}]}
{"op":"mcm","clk":"1349951729","pt":1588413377115,"mc":[{"id":"1.170370562","rc":[{"trd":[[1.7,20.15]],"ltp":1.7,"tv":20.15,"id":9631798},{"atb":[[1.7,0.98]],"id":9631798}],"con":true,"img":false}]}
{"op":"mcm","clk":"1349951946","pt":1588413386126,"mc":[{"id":"1.170370562","rc":[{"atl":[[1.9,3.39]],"id":9631798}],"con":true,"img":false}]}
{"op":"mcm","clk":"1349952106","pt":1588413391276,"mc":[{"id":"1.170370562","rc":[{"trd":[[1.68,32.83],[1.7,22.12]],"ltp":1.68,"tv":54.95,"id":9631798},{"atb":[[1.7,0],[1.68,75]],"id":9631798}],"con":true,"img":false}]}
{"op":"mcm","clk":"1349952229","pt":1588413395363,"mc":[{"id":"1.170370562","rc":[{"trd":[[1.68,33.04]],"ltp":1.68,"tv":33.04,"id":9631798},{"atb":[[1.68,74.89]],"id":9631798}],"con":true,"img":false}]}
{"op":"mcm","clk":"1349952283","pt":1588413396968,"mc":[{"id":"1.170370562","rc":[{"atb":[[1.64,0]],"id":9631798}],"con":true,"img":false}]}
{"op":"mcm","clk":"1349952373","pt":1588413400077,"mc":[{"id":"1.170370562","rc":[{"atb":[[1.69,0.11]],"id":9631798}],"con":true,"img":false}]}
{"op":"mcm","clk":"1349952409","pt":1588413401368,"mc":[{"id":"1.170370562","rc":[{"trd":[[1.68,39.87],[1.69,4.54]],"ltp":1.68,"tv":44.41,"id":9631798},{"atb":[[1.68,71.48],[1.69,0]],"id":9631798}],"con":true,"img":false}]}
{"op":"mcm","clk":"1349952839","pt":1588413418294,"mc":[{"id":"1.170370562","rc":[{"atl":[[1.89,0],[1.78,0.23]],"id":9631798}],"con":true,"img":false}]}
{"op":"mcm","clk":"1349953081","pt":1588413428127,"mc":[{"id":"1.170370562","rc":[{"atl":[[1.78,175.41]],"id":9631798}],"con":true,"img":false}]}
{"op":"mcm","clk":"1349953161","pt":1588413431116,"mc":[{"id":"1.170370562","rc":[{"atb":[[1.6,0]],"id":9631798}],"con":true,"img":false}]}
{"op":"mcm","clk":"1349953241","pt":1588413434421,"mc":[{"id":"1.170370562","rc":[{"atl":[[1.8,0]],"id":9631798}],"con":true,"img":false}]}
{"op":"mcm","clk":"1349953271","pt":1588413435920,"mc":[{"id":"1.170370562","rc":[{"trd":[[1.78,1.18]],"ltp":1.78,"tv":1.18,"id":9631798},{"atl":[[1.78,174.7]],"id":9631798}],"con":true,"img":false}]}
{"op":"mcm","clk":"1349953279","pt":1588413436228,"mc":[{"id":"1.170370562","rc":[{"atb":[[1.63,71.98]],"id":9631798}],"con":true,"img":false}]}
{"op":"mcm","clk":"1349953319","pt":1588413438243,"mc":[{"id":"1.170370562","rc":[{"atl":[[2.4,1.77]],"id":9625043}],"con":true,"img":false}]}
{"op":"mcm","clk":"1349953326","pt":1588413438606,"mc":[{"id":"1.170370562","rc":[{"atb":[[1.53,13.12]],"id":9631798}],"con":true,"img":false}]}
{"op":"mcm","clk":"1349953446","pt":1588413444319,"mc":[{"id":"1.170370562","rc":[{"atl":[[2.4,0]],"id":9625043}],"con":true,"img":false}]}
{"op":"mcm","clk":"1349953501","pt":1588413447154,"mc":[{"id":"1.170370562","rc":[{"atb":[[1.69,0.23]],"id":9631798}],"con":true,"img":false}]}
{"op":"mcm","clk":"1349953527","pt":1588413448033,"mc":[{"id":"1.170370562","rc":[{"atl":[[1.77,71.98]],"id":9631798}],"con":true,"img":false}]}
{"op":"mcm","clk":"1349953560","pt":1588413449422,"mc":[{"id":"1.170370562","rc":[{"atl":[[2.38,1.77]],"id":9625043}],"con":true,"img":false}]}
{"op":"mcm","clk":"1349953627","pt":1588413452054,"mc":[{"id":"1.170370562","rc":[{"atl":[[1.88,262.76]],"id":9631798}],"con":true,"img":false}]}
{"op":"mcm","clk":"1349953714","pt":1588413456957,"mc":[{"id":"1.170370562","rc":[{"atl":[[2.38,0]],"id":9625043}],"con":true,"img":false}]}
{"op":"mcm","clk":"1349953824","pt":1588413462059,"mc":[{"id":"1.170370562","rc":[{"atl":[[2.34,1.77]],"id":9625043}],"con":true,"img":false}]}
{"op":"mcm","clk":"1349953832","pt":1588413462470,"mc":[{"id":"1.170370562","rc":[{"trd":[[2.34,1.77]],"ltp":2.34,"tv":1.77,"id":9625043},{"atl":[[2.34,0]],"id":9625043},{"trd":[[1.74,11.12]],"ltp":1.74,"tv":11.12,"id":9631798},{"atl":[[1.72,0.19]],"id":9631798}],"con":true,"img":false}]}
{"op":"mcm","clk":"1349953921","pt":1588413465972,"mc":[{"id":"1.170370562","rc":[{"atb":[[1.53,0]],"id":9631798}],"con":true,"img":false}]}
{"op":"mcm","clk":"1349953994","pt":1588413468761,"mc":[{"id":"1.170370562","rc":[{"atl":[[1.76,175.17]],"id":9631798}],"con":true,"img":false}]}
{"op":"mcm","clk":"1349954080","pt":1588413472271,"mc":[{"id":"1.170370562","rc":[{"atl":[[1.9,0]],"id":9631798}],"con":true,"img":false}]}
{"op":"mcm","clk":"1349954155","pt":1588413476287,"mc":[{"id":"1.170370562","rc":[{"trd":[[1.68,46.09],[1.69,5.02]],"ltp":1.68,"tv":51.11,"id":9631798},{"atb":[[1.68,68.36],[1.69,0]],"id":9631798}],"con":true,"img":false}]}
{"op":"mcm","clk":"1349954330","pt":1588413482997,"mc":[{"id":"1.170370562","rc":[{"atl":[[1.76,350.35]],"id":9631798}],"con":true,"img":false}]}
{"op":"mcm","clk":"1349954353","pt":1588413484188,"mc":[{"id":"1.170370562","rc":[{"trd":[[1.72,0.18]],"ltp":1.72,"tv":0.18,"id":9631798},{"atl":[[1.72,0.09]],"id":9631798}],"con":true,"img":false}]}
{"op":"mcm","clk":"1349954521","pt":1588413490506,"mc":[{"id":"1.170370562","rc":[{"atl":[[1.75,0.23]],"id":9631798}],"con":true,"img":false}]}
{"op":"mcm","clk":"1349954692","pt":1588413497796,"mc":[{"id":"1.170370562","rc":[{"trd":[[1.68,50.97]],"ltp":1.68,"tv":50.97,"id":9631798},{"atb":[[1.68,65.93]],"id":9631798}],"con":true,"img":false}]}
{"op":"mcm","clk":"1349954791","pt":1588413502424,"mc":[{"id":"1.170370562","rc":[{"atl":[[1.76,525.53]],"id":9631798}],"con":true,"img":false}]}
{"op":"mcm","clk":"1349954818","pt":1588413503712,"mc":[{"id":"1.170370562","rc":[{"trd":[[1.68,150.97]],"ltp":1.68,"tv":150.97,"id":9631798},{"atb":[[1.68,15.93]],"id":9631798}],"con":true,"img":false}]}
{"op":"mcm","clk":"1349955100","pt":1588413516057,"mc":[{"id":"1.170370562","rc":[{"atb":[[2,0]],"id":9625043},{"atb":[[1.52,0]],"id":9631798}],"con":true,"img":false}]}
{"op":"mcm","clk":"1349955319","pt":1588413525672,"mc":[{"id":"1.170370562","rc":[{"atl":[[1.77,0]],"id":9631798}],"con":true,"img":false}]}
{"op":"mcm","clk":"1349955501","pt":1588413536057,"mc":[{"id":"1.170370562","rc":[{"atb":[[1.46,0]],"id":9631798}],"con":true,"img":false}]}
{"op":"mcm","clk":"1349955664","pt":1588413543280,"mc":[{"id":"1.170370562","rc":[{"trd":[[1.72,0.38]],"ltp":1.72,"tv":0.38,"id":9631798},{"atb":[[1.74,1.9]],"id":9631798},{"atl":[[1.72,0]],"id":9631798}],"con":true,"img":false}]}
{"op":"mcm","clk":"1349955705","pt":1588413544880,"mc":[{"id":"1.170370562","rc":[{"trd":[[1.76,7.68]],"ltp":1.76,"tv":7.68,"id":9631798},{"atl":[[1.75,0],[1.76,524.35]],"id":9631798}],"con":true,"img":false}]}
{"op":"mcm","clk":"1349955834","pt":1588413550399,"mc":[{"id":"1.170370562","rc":[{"trd":[[2.3,0.61]],"ltp":2.3,"tv":0.61,"id":9625043},{"trd":[[1.76,8.22]],"ltp":1.76,"tv":8.22,"id":9631798},{"atl":[[1.76,523.81]],"id":9631798}],"con":true,"img":false}]}
{"op":"mcm","clk":"1349955880","pt":1588413552413,"mc":[{"id":"1.170370562","rc":[{"atb":[[1.74,0]],"id":9631798}],"con":true,"img":false}]}
{"op":"mcm","clk":"1349955935","pt":1588413554789,"mc":[{"id":"1.170370562","rc":[{"atb":[[1.01,1091.33]],"id":9631798}],"con":true,"img":false}]}
{"op":"mcm","clk":"1349955938","pt":1588413554993,"mc":[{"id":"1.170370562","rc":[{"atl":[[1.74,17.51]],"id":9631798}],"con":true,"img":false}]}
{"op":"mcm","clk":"1349955939","pt":1588413555098,"mc":[{"id":"1.170370562","rc":[{"atb":[[1.01,1089.73]],"id":9631798}],"con":true,"img":false}]}
{"op":"mcm","clk":"1349955945","pt":1588413555304,"mc":[{"id":"1.170370562","rc":[{"atb":[[1.01,1088.13]],"id":9631798}],"con":true,"img":false}]}
{"op":"mcm","clk":"1349956065","pt":1588413558706,"mc":[{"id":"1.170370562","rc":[{"trd":[[2.34,5.27]],"ltp":2.34,"tv":5.27,"id":9625043},{"trd":[[1.74,15.84]],"ltp":1.74,"tv":15.84,"id":9631798},{"atl":[[1.74,12.8]],"id":9631798}],"con":true,"img":false}]}
{"op":"mcm","clk":"1349956070","pt":1588413558911,"mc":[{"id":"1.170370562","rc":[{"atb":[[1.69,0.23]],"id":9631798}],"con":true,"img":false}]}
{"op":"mcm","clk":"1349956105","pt":1588413560409,"mc":[{"id":"1.170370562","rc":[{"atb":[[1.15,534.83]],"id":9631798}],"con":true,"img":false}]}
{"op":"mcm","clk":"1349956246","pt":1588413567530,"mc":[{"id":"1.170370562","rc":[{"atl":[[1.7,2]],"id":9631798}],"con":true,"img":false}]}
{"op":"mcm","clk":"1349956298","pt":1588413570005,"mc":[{"id":"1.170370562","rc":[{"atb":[[1.68,61.56]],"id":9631798}],"con":true,"img":false}]}
{"op":"mcm","clk":"1349956328","pt":1588413571817,"mc":[{"id":"1.170370562","rc":[{"atl":[[1.7,0]],"id":9631798}],"con":true,"img":false}]}
{"op":"mcm","clk":"1349956333","pt":1588413571919,"mc":[{"id":"1.170370562","rc":[{"atl":[[1.74,0],[1.76,348.63]],"id":9631798}],"con":true,"img":false}]}
{"op":"mcm","clk":"1349956337","pt":1588413572022,"mc":[{"id":"1.170370562","rc":[{"atl":[[1.76,175.17]],"id":9631798}],"con":true,"img":false}]}
{"op":"mcm","clk":"1349956340","pt":1588413572125,"mc":[{"id":"1.170370562","rc":[{"atl":[[1.78,0]],"id":9631798}],"con":true,"img":false}]}
{"op":"mcm","clk":"1349956344","pt":1588413572226,"mc":[{"id":"1.170370562","rc":[{"atl":[[1.88,0],[1.76,0]],"id":9631798}],"con":true,"img":false}]}
{"op":"mcm","clk":"1349956354","pt":1588413572537,"mc":[{"id":"1.170370562","rc":[{"atb":[[1.64,22.16]],"id":9631798}],"con":true,"img":false}]}
{"op":"mcm","clk":"1349956543","pt":1588413579120,"mc":[{"id":"1.170370562","rc":[{"atl":[[2.34,100]],"id":9625043}],"con":true,"img":false}]}
{"op":"mcm","clk":"1349956677","pt":1588413582946,"mc":[{"id":"1.170370562","rc":[{"atl":[[2.34,0]],"id":9625043}],"con":true,"img":false}]}
{"op":"mcm","clk":"1349956793","pt":1588413587549,"mc":[{"id":"1.170370562","rc":[{"atl":[[1.88,0.23]],"id":9631798}],"con":true,"img":false}]}
{"op":"mcm","clk":"1349956809","pt":1588413588164,"mc":[{"id":"1.170370562","rc":[{"atl":[[1.86,71.98]],"id":9631798}],"con":true,"img":false}]}
{"op":"mcm","clk":"1349956989","pt":1588413597967,"mc":[{"id":"1.170370562","rc":[{"atl":[[1.8,34.98]],"id":9631798}],"con":true,"img":false}]}
{"op":"mcm","clk":"1349957111","pt":1588413602659,"mc":[{"id":"1.170370562","rc":[{"atl":[[1.85,87.58]],"id":9631798}],"con":true,"img":false}]}
{"op":"mcm","clk":"1349957129","pt":1588413603594,"mc":[{"id":"1.170370562","rc":[{"atl":[[1.85,87.82]],"id":9631798}],"con":true,"img":false}]}
{"op":"mcm","clk":"1349957159","pt":1588413604383,"mc":[{"id":"1.170370562","rc":[{"atb":[[1.68,45.62]],"id":9631798}],"con":true,"img":false}]}
{"op":"mcm","clk":"1349957211","pt":1588413605685,"mc":[{"id":"1.170370562","rc":[{"atb":[[1.72,15.07]],"id":9631798}],"con":true,"img":false}]}
{"op":"mcm","clk":"1349957311","pt":1588413609200,"mc":[{"id":"1.170370562","rc":[{"atl":[[1.88,0]],"id":9631798}],"con":true,"img":false}]}
{"op":"mcm","clk":"1349957456","pt":1588413614373,"mc":[{"id":"1.170370562","rc":[{"trd":[[1.68,207.94],[1.69,5.49],[1.72,30.52]],"ltp":1.68,"tv":243.95,"id":9631798},{"atb":[[1.68,17.14],[1.69,0],[1.72,0]],"id":9631798}],"con":true,"img":false}]}
{"op":"mcm","clk":"1349957687","pt":1588413625322,"mc":[{"id":"1.170370562","rc":[{"atl":[[1.85,87.58]],"id":9631798}],"con":true,"img":false}]}
{"op":"mcm","clk":"1349957742","pt":1588413627028,"mc":[{"id":"1.170370562","rc":[{"atl":[[1.79,2.32]],"id":9631798}],"con":true,"img":false}]}
{"op":"mcm","clk":"1349957770","pt":1588413627803,"mc":[{"id":"1.170370562","rc":[{"atl":[[1.79,2.55]],"id":9631798}],"con":true,"img":false}]}
{"op":"mcm","clk":"1349957816","pt":1588413630496,"mc":[{"id":"1.170370562","rc":[{"atb":[[1.63,0]],"id":9631798}],"con":true,"img":false}]}
{"op":"mcm","clk":"1349957823","pt":1588413630804,"mc":[{"id":"1.170370562","rc":[{"atl":[[1.86,0]],"id":9631798}],"con":true,"img":false}]}
{"op":"mcm","clk":"1349957841","pt":1588413632100,"mc":[{"id":"1.170370562","rc":[{"atl":[[1.79,15.69]],"id":9631798}],"con":true,"img":false}]}
{"op":"mcm","clk":"1349957890","pt":1588413635210,"mc":[{"id":"1.170370562","rc":[{"trd":[[1.79,12.79]],"ltp":1.79,"tv":12.79,"id":9631798},{"atl":[[1.79,9.29]],"id":9631798}],"con":true,"img":false}]}
{"op":"mcm","clk":"1349957923","pt":1588413637585,"mc":[{"id":"1.170370562","rc":[{"atb":[[1.01,1091.33]],"id":9631798}],"con":true,"img":false}]}
{"op":"mcm","clk":"1349957932","pt":1588413638107,"mc":[{"id":"1.170370562","rc":[{"atb":[[1.01,1088.39]],"id":9631798}],"con":true,"img":false}]}
{"op":"mcm","clk":"1349957937","pt":1588413638414,"mc":[{"id":"1.170370562","rc":[{"atb":[[1.01,1088.13]],"id":9631798}],"con":true,"img":false}]}
{"op":"mcm","clk":"1349957952","pt":1588413639623,"mc":[{"id":"1.170370562","marketDefinition":{"bspMarket":false,"turnInPlayEnabled":true,"persistenceEnabled":true,"marketBaseRate":5.0,"eventId":"29788105","eventTypeId":"2","numberOfWinners":1,"bettingType":"ODDS","marketType":"MATCH_ODDS","marketTime":"2020-05-02T10:00:38.000Z","suspendTime":"2020-05-02T10:00:38.000Z","bspReconciled":false,"complete":true,"inPlay":true,"crossMatching":true,"runnersVoidable":false,"numberOfActiveRunners":2,"betDelay":5,"status":"OPEN","runners":[{"status":"ACTIVE","sortPriority":1,"id":9631798,"name":"B Hassan"},{"status":"ACTIVE","sortPriority":2,"id":9625043,"name":"J Haerteis"}],"regulators":["MR_INT"],"countryCode":"GB","discountAllowed":true,"timezone":"GMT","openDate":"2020-05-02T09:50:00.000Z","version":3237484528,"name":"Match Odds","eventName":"B Hassan v J Haerteis"},"rc":[],"con":true,"img":false}]}
{"op":"mcm","clk":"1349957973","pt":1588413641619,"mc":[{"id":"1.170370562","marketDefinition":{"bspMarket":false,"turnInPlayEnabled":true,"persistenceEnabled":true,"marketBaseRate":5.0,"eventId":"29788105","eventTypeId":"2","numberOfWinners":1,"bettingType":"ODDS","marketType":"MATCH_ODDS","marketTime":"2020-05-02T10:00:38.000Z","suspendTime":"2020-05-02T10:00:38.000Z","bspReconciled":false,"complete":true,"inPlay":true,"crossMatching":true,"runnersVoidable":false,"numberOfActiveRunners":2,"betDelay":5,"status":"OPEN","runners":[{"status":"ACTIVE","sortPriority":1,"id":9631798,"name":"B Hassan"},{"status":"ACTIVE","sortPriority":2,"id":9625043,"name":"J Haerteis"}],"regulators":["MR_INT"],"countryCode":"GB","discountAllowed":true,"timezone":"GMT","openDate":"2020-05-02T10:00:38.000Z","version":3237484528,"name":"Match Odds","eventName":"B Hassan v J Haerteis"},"rc":[],"con":true,"img":false}]}
{"op":"mcm","clk":"1349958020","pt":1588413643540,"mc":[{"id":"1.170370562","rc":[{"trd":[[1.79,13.32]],"ltp":1.79,"tv":13.32,"id":9631798},{"atl":[[1.79,9.03]],"id":9631798}],"con":true,"img":false}]}
{"op":"mcm","clk":"1349958061","pt":1588413645348,"mc":[{"id":"1.170370562","rc":[{"trd":[[1.68,232.46]],"ltp":1.68,"tv":232.46,"id":9631798},{"atb":[[1.68,4.88]],"id":9631798}],"con":true,"img":false}]}
{"op":"mcm","clk":"1349958136","pt":1588413649429,"mc":[{"id":"1.170370562","rc":[{"atb":[[1.69,0.23]],"id":9631798}],"con":true,"img":false}]}
{"op":"mcm","clk":"1349958187","pt":1588413651606,"mc":[{"id":"1.170370562","rc":[{"atl":[[1.79,0]],"id":9631798}],"con":true,"img":false}]}
{"op":"mcm","clk":"1349958299","pt":1588413656852,"mc":[{"id":"1.170370562","rc":[{"atl":[[2.38,8.86]],"id":9625043}],"con":true,"img":false}]}
{"op":"mcm","clk":"1349958347","pt":1588413659533,"mc":[{"id":"1.170370562","rc":[{"trd":[[2.38,1.02]],"ltp":2.38,"tv":1.02,"id":9625043},{"atl":[[2.38,7.83]],"id":9625043},{"trd":[[1.72,31.94]],"ltp":1.72,"tv":31.94,"id":9631798}],"con":true,"img":false}]}
{"op":"mcm","clk":"1349958462","pt":1588413665783,"mc":[{"id":"1.170370562","rc":[{"trd":[[2.24,2.84]],"ltp":2.24,"tv":2.84,"id":9625043},{"trd":[[1.8,255.87]],"ltp":1.8,"tv":255.87,"id":9631798},{"atl":[[1.8,34.47]],"id":9631798}],"con":true,"img":false}]}
{"op":"mcm","clk":"1349958489","pt":1588413668257,"mc":[{"id":"1.170370562","rc":[{"trd":[[2.38,2.89]],"ltp":2.38,"tv":2.89,"id":9625043},{"atl":[[2.38,5.97]],"id":9625043},{"trd":[[1.72,34.52]],"ltp":1.72,"tv":34.52,"id":9631798}],"con":true,"img":false}]}
{"op":"mcm","clk":"1349958512","pt":1588413670364,"mc":[{"id":"1.170370562","rc":[{"trd":[[2.38,8.86]],"ltp":2.38,"tv":8.86,"id":9625043},{"atl":[[2.38,0]],"id":9625043},{"trd":[[1.72,42.79]],"ltp":1.72,"tv":42.79,"id":9631798},{"atl":[[1.72,3.99]],"id":9631798}],"con":true,"img":false}]}
{"op":"mcm","clk":"1349958543","pt":1588413671699,"mc":[{"id":"1.170370562","rc":[{"atl":[[1.72,58.99]],"id":9631798}],"con":true,"img":false}]}
{"op":"mcm","clk":"1349958577","pt":1588413673696,"mc":[{"id":"1.170370562","rc":[{"atl":[[1.72,55],[1.85,0]],"id":9631798}],"con":true,"img":false}]}
{"op":"mcm","clk":"1349958704","pt":1588413678974,"mc":[{"id":"1.170370562","rc":[{"trd":[[1.69,6.11]],"ltp":1.69,"tv":6.11,"id":9631798},{"atb":[[1.69,0]],"id":9631798},{"atl":[[1.69,491.71]],"id":9631798}],"con":true,"img":false}]}
{"op":"mcm","clk":"1349958706","pt":1588413679076,"mc":[{"id":"1.170370562","rc":[{"atl":[[1.8,0]],"id":9631798}],"con":true,"img":false}]}
{"op":"mcm","clk":"1349958725","pt":1588413680209,"mc":[{"id":"1.170370562","rc":[{"atl":[[1.69,0]],"id":9631798}],"con":true,"img":false}]}
{"op":"mcm","clk":"1349958790","pt":1588413683097,"mc":[{"id":"1.170370562","rc":[{"trd":[[1.72,51.19]],"ltp":1.72,"tv":51.19,"id":9631798},{"atl":[[1.72,50.8]],"id":9631798}],"con":true,"img":false}]}
{"op":"mcm","clk":"1349958828","pt":1588413684184,"mc":[{"id":"1.170370562","rc":[{"atb":[[1.01,1089.9]],"id":9631798}],"con":true,"img":false}]}
{"op":"mcm","clk":"1349958832","pt":1588413684385,"mc":[{"id":"1.170370562","rc":[{"atb":[[1.01,1088.44]],"id":9631798}],"con":true,"img":false}]}
{"op":"mcm","clk":"1349958836","pt":1588413684488,"mc":[{"id":"1.170370562","rc":[{"atb":[[1.01,1088.13]],"id":9631798}],"con":true,"img":false}]}
{"op":"mcm","clk":"1349958879","pt":1588413686088,"mc":[{"id":"1.170370562","rc":[{"trd":[[1.72,56.35]],"ltp":1.72,"tv":56.35,"id":9631798},{"atl":[[1.72,48.22]],"id":9631798}],"con":true,"img":false}]}
{"op":"mcm","clk":"1349958907","pt":1588413687225,"mc":[{"id":"1.170370562","rc":[{"trd":[[2.38,43.71]],"ltp":2.38,"tv":43.71,"id":9625043},{"atl":[[2.38,65.15]],"id":9625043},{"trd":[[1.72,104.57]],"ltp":1.72,"tv":104.57,"id":9631798},{"atl":[[1.72,0]],"id":9631798}],"con":true,"img":false}]}
{"op":"mcm","clk":"1349958982","pt":1588413689591,"mc":[{"id":"1.170370562","rc":[{"atb":[[1.68,5.19]],"id":9631798}],"con":true,"img":false}]}
{"op":"mcm","clk":"1349958996","pt":1588413690105,"mc":[{"id":"1.170370562","rc":[{"atb":[[1.64,0]],"id":9631798}],"con":true,"img":false}]}
{"op":"mcm","clk":"1349959041","pt":1588413691802,"mc":[{"id":"1.170370562","rc":[{"trd":[[2.38,45.57]],"ltp":2.38,"tv":45.57,"id":9625043},{"atl":[[2.38,63.29]],"id":9625043},{"trd":[[1.72,107.14]],"ltp":1.72,"tv":107.14,"id":9631798}],"con":true,"img":false}]}
{"op":"mcm","clk":"1349959064","pt":1588413692621,"mc":[{"id":"1.170370562","rc":[{"atb":[[1.68,4.88]],"id":9631798}],"con":true,"img":false}]}
{"op":"mcm","clk":"1349959137","pt":1588413695248,"mc":[{"id":"1.170370562","rc":[{"atb":[[1.58,22.16]],"id":9631798}],"con":true,"img":false}]}
{"op":"mcm","clk":"1349959158","pt":1588413695920,"mc":[{"id":"1.170370562","rc":[{"trd":[[2.38,46.52]],"ltp":2.38,"tv":46.52,"id":9625043},{"atl":[[2.38,62.34]],"id":9625043},{"trd":[[1.72,108.46]],"ltp":1.72,"tv":108.46,"id":9631798}],"con":true,"img":false}]}
{"op":"mcm","clk":"1349959174","pt":1588413696535,"mc":[{"id":"1.170370562","rc":[{"trd":[[2.38,108.86]],"ltp":2.38,"tv":108.86,"id":9625043},{"atl":[[2.38,0]],"id":9625043},{"trd":[[1.72,194.71]],"ltp":1.72,"tv":194.71,"id":9631798},{"atl":[[1.69,405.76]],"id":9631798}],"con":true,"img":false}]}
{"op":"mcm","clk":"1349959178","pt":1588413696742,"mc":[{"id":"1.170370562","rc":[{"trd":[[1.68,242.23]],"ltp":1.68,"tv":242.23,"id":9631798},{"atb":[[1.68,0]],"id":9631798},{"atl":[[1.68,958.59]],"id":9631798}],"con":true,"img":false}]}
{"op":"mcm","clk":"1349959184","pt":1588413696943,"mc":[{"id":"1.170370562","rc":[{"atl":[[1.68,1193.55]],"id":9631798}],"con":true,"img":false}]}
{"op":"mcm","clk":"1349959195","pt":1588413697618,"mc":[{"id":"1.170370562","rc":[{"atl":[[1.68,993.58]],"id":9631798}],"con":true,"img":false}]}
{"op":"mcm","clk":"1349959241","pt":1588413700032,"mc":[{"id":"1.170370562","rc":[{"atl":[[1.69,0]],"id":9631798}],"con":true,"img":false}]}
{"op":"mcm","clk":"1349959244","pt":1588413700135,"mc":[{"id":"1.170370562","rc":[{"atl":[[1.72,19.42],[1.9,0.23]],"id":9631798}],"con":true,"img":false}]}
{"op":"mcm","clk":"1349959247","pt":1588413700335,"mc":[{"id":"1.170370562","rc":[{"atl":[[1.72,0]],"id":9631798}],"con":true,"img":false}]}
{"op":"mcm","clk":"1349959255","pt":1588413700848,"mc":[{"id":"1.170370562","rc":[{"atl":[[1.72,44.32]],"id":9631798}],"con":true,"img":false}]}
{"op":"mcm","clk":"1349959275","pt":1588413701924,"mc":[{"id":"1.170370562","rc":[{"trd":[[1.68,415.78]],"ltp":1.68,"tv":415.78,"id":9631798},{"atl":[[1.68,906.8]],"id":9631798}],"con":true,"img":false}]}
{"op":"mcm","clk":"1349959283","pt":1588413702340,"mc":[{"id":"1.170370562","rc":[{"atl":[[1.65,222]],"id":9631798}],"con":true,"img":false}]}
{"op":"mcm","clk":"1349959303","pt":1588413703158,"mc":[{"id":"1.170370562","rc":[{"atl":[[1.64,196.8]],"id":9631798}],"con":true,"img":false}]}
{"op":"mcm","clk":"1349959329","pt":1588413705060,"mc":[{"id":"1.170370562","rc":[{"atl":[[1.64,0]],"id":9631798}],"con":true,"img":false}]}
{"op":"mcm","clk":"1349959333","pt":1588413705326,"mc":[{"id":"1.170370562","rc":[{"atl":[[1.72,110.32]],"id":9631798}],"con":true,"img":false}]}
{"op":"mcm","clk":"1349959354","pt":1588413706356,"mc":[{"id":"1.170370562","rc":[{"trd":[[1.58,44.32]],"ltp":1.58,"tv":44.32,"id":9631798},{"atb":[[1.58,0]],"id":9631798},{"atl":[[1.58,174.64]],"id":9631798}],"con":true,"img":false}]}
{"op":"mcm","clk":"1349959372","pt":1588413707141,"mc":[{"id":"1.170370562","rc":[{"atl":[[1.72,44.32],[1.58,0]],"id":9631798}],"con":true,"img":false}]}
{"op":"mcm","clk":"1349959406","pt":1588413708955,"mc":[{"id":"1.170370562","rc":[{"trd":[[2.52,0.1]],"ltp":2.52,"tv":0.1,"id":9625043},{"trd":[[1.65,104.16]],"ltp":1.65,"tv":104.16,"id":9631798},{"atl":[[1.65,221.84]],"id":9631798}],"con":true,"img":false}]}
{"op":"mcm","clk":"1349959471","pt":1588413712354,"mc":[{"id":"1.170370562","rc":[{"atl":[[1.57,492.02]],"id":9631798}],"con":true,"img":false}]}
{"op":"mcm","clk":"1349959473","pt":1588413712562,"mc":[{"id":"1.170370562","rc":[{"atl":[[1.55,199.96]],"id":9631798}],"con":true,"img":false}]}
{"op":"mcm","clk":"1349959487","pt":1588413713130,"mc":[{"id":"1.170370562","rc":[{"trd":[[1.55,5.31]],"ltp":1.55,"tv":5.31,"id":9631798},{"atl":[[1.55,197.31]],"id":9631798}],"con":true,"img":false}]}
{"op":"mcm","clk":"1349959489","pt":1588413713285,"mc":[{"id":"1.170370562","rc":[{"atb":[[1.39,750]],"id":9631798},{"atl":[[1.58,2.57],[1.68,871.82]],"id":9631798}],"con":true,"img":false}]}
{"op":"mcm","clk":"1349959494","pt":1588413713555,"mc":[{"id":"1.170370562","rc":[{"atb":[[1.2,0]],"id":9631798}],"con":true,"img":false}]}
{"op":"mcm","clk":"1349959499","pt":1588413713862,"mc":[{"id":"1.170370562","rc":[{"atl":[[1.58,265.34]],"id":9631798}],"con":true,"img":false}]}
{"op":"mcm","clk":"1349959502","pt":1588413713965,"mc":[{"id":"1.170370562","rc":[{"trd":[[3,5]],"ltp":3.0,"tv":5.0,"id":9625043},{"atl":[[3,0]],"id":9625043},{"trd":[[1.5,9.99]],"ltp":1.5,"tv":9.99,"id":9631798},{"atb":[[1.32,750]],"id":9631798},{"atl":[[1.5,189.96]],"id":9631798}],"con":true,"img":false}]}
{"op":"mcm","clk":"1349959508","pt":1588413714275,"mc":[{"id":"1.170370562","rc":[{"trd":[[1.5,55.78]],"ltp":1.5,"tv":55.78,"id":9631798},{"atl":[[1.5,167.07]],"id":9631798}],"con":true,"img":false}]}
{"op":"mcm","clk":"1349959533","pt":1588413715353,"mc":[{"id":"1.170370562","rc":[{"atl":[[1.57,0]],"id":9631798}],"con":true,"img":false}]}
{"op":"mcm","clk":"1349959542","pt":1588413715973,"mc":[{"id":"1.170370562","rc":[{"atl":[[1.5,367.04]],"id":9631798}],"con":true,"img":false}]}
{"op":"mcm","clk":"1349959547","pt":1588413716338,"mc":[{"id":"1.170370562","rc":[{"atb":[[1.39,0]],"id":9631798}],"con":true,"img":false}]}
{"op":"mcm","clk":"1349959549","pt":1588413716439,"mc":[{"id":"1.170370562","rc":[{"atb":[[1.1,799.87]],"id":9631798}],"con":true,"img":false}]}
{"op":"mcm","clk":"1349959550","pt":1588413716544,"mc":[{"id":"1.170370562","rc":[{"atl":[[1.55,210.61]],"id":9631798}],"con":true,"img":false}]}
{"op":"mcm","clk":"1349959562","pt":1588413717363,"mc":[{"id":"1.170370562","rc":[{"atl":[[1.58,2.57],[1.68,0]],"id":9631798}],"con":true,"img":false}]}
{"op":"mcm","clk":"1349959578","pt":1588413718237,"mc":[{"id":"1.170370562","rc":[{"atl":[[1.65,0]],"id":9631798}],"con":true,"img":false}]}
{"op":"mcm","clk":"1349959587","pt":1588413718548,"mc":[{"id":"1.170370562","rc":[{"atl":[[1.58,0]],"id":9631798}],"con":true,"img":false}]}
{"op":"mcm","clk":"1349959588","pt":1588413719073,"mc":[{"id":"1.170370562","rc":[{"trd":[[1.5,78.86]],"ltp":1.5,"tv":78.86,"id":9631798},{"atl":[[1.5,355.5]],"id":9631798}],"con":true,"img":false}]}
{"op":"mcm","clk":"1349959610","pt":1588413720678,"mc":[{"id":"1.170370562","rc":[{"atb":[[1.15,1.59]],"id":9631798}],"con":true,"img":false}]}
{"op":"mcm","clk":"1349959622","pt":1588413721144,"mc":[{"id":"1.170370562","rc":[{"atl":[[1.55,197.31]],"id":9631798}],"con":true,"img":false}]}
{"op":"mcm","clk":"1349959630","pt":1588413721655,"mc":[{"id":"1.170370562","rc":[{"atl":[[1.49,196.8]],"id":9631798}],"con":true,"img":false}]}
{"op":"mcm","clk":"1349959659","pt":1588413722789,"mc":[{"id":"1.170370562","rc":[{"atb":[[1.39,750]],"id":9631798}],"con":true,"img":false}]}
{"op":"mcm","clk":"1349959663","pt":1588413722947,"mc":[{"id":"1.170370562","rc":[{"trd":[[1.49,0.47]],"ltp":1.49,"tv":0.47,"id":9631798},{"atb":[[1.48,2.1]],"id":9631798},{"atl":[[1.49,196.56]],"id":9631798}],"con":true,"img":false}]}
{"op":"mcm","clk":"1349959775","pt":1588413729572,"mc":[{"id":"1.170370562","rc":[{"trd":[[1.39,17.34],[1.48,4.2]],"ltp":1.39,"tv":21.54,"id":9631798},{"atb":[[1.48,0],[1.39,741.33]],"id":9631798},{"atl":[[1.47,197.86]],"id":9631798}],"con":true,"img":false}]}
{"op":"mcm","clk":"1349959799","pt":1588413731169,"mc":[{"id":"1.170370562","rc":[{"atl":[[1.47,397.83]],"id":9631798}],"con":true,"img":false}]}
{"op":"mcm","clk":"1349959827","pt":1588413732306,"mc":[{"id":"1.170370562","rc":[{"atl":[[1.48,350.35],[1.47,0]],"id":9631798}],"con":true,"img":false}]}
{"op":"mcm","clk":"1349959843","pt":1588413733083,"mc":[{"id":"1.170370562","rc":[{"atl":[[1.5,0]],"id":9631798}],"con":true,"img":false}]}
{"op":"mcm","clk":"1349959868","pt":1588413734581,"mc":[{"id":"1.170370562","rc":[{"trd":[[1.39,57.34]],"ltp":1.39,"tv":57.34,"id":9631798},{"atb":[[1.39,721.33]],"id":9631798}],"con":true,"img":false}]}
{"op":"mcm","clk":"1349959873","pt":1588413734990,"mc":[{"id":"1.170370562","rc":[{"atl":[[1.48,385.34]],"id":9631798}],"con":true,"img":false}]}
{"op":"mcm","clk":"1349959878","pt":1588413735092,"mc":[{"id":"1.170370562","rc":[{"atb":[[1.39,0]],"id":9631798}],"con":true,"img":false}]}
{"op":"mcm","clk":"1349959886","pt":1588413735305,"mc":[{"id":"1.170370562","rc":[{"trd":[[1.32,33.68]],"ltp":1.32,"tv":33.68,"id":9631798},{"atb":[[1.32,733.16]],"id":9631798}],"con":true,"img":false}]}
{"op":"mcm","clk":"1349959899","pt":1588413735818,"mc":[{"id":"1.170370562","rc":[{"atb":[[1.32,0]],"id":9631798},{"atl":[[1.48,382.76]],"id":9631798}],"con":true,"img":false}]}
{"op":"mcm","clk":"1349959904","pt":1588413736024,"mc":[{"id":"1.170370562","rc":[{"atl":[[1.49,0]],"id":9631798}],"con":true,"img":false}]}
{"op":"mcm","clk":"1349959942","pt":1588413737514,"mc":[{"id":"1.170370562","rc":[{"atb":[[3.1,5.25]],"id":9625043}],"con":true,"img":false}]}
{"op":"mcm","clk":"1349959951","pt":1588413738031,"mc":[{"id":"1.170370562","rc":[{"atb":[[1.01,1089.9]],"id":9631798},{"atl":[[1.52,0.23]],"id":9631798}],"con":true,"img":false}]}
{"op":"mcm","clk":"1349959957","pt":1588413738339,"mc":[{"id":"1.170370562","rc":[{"atb":[[1.01,1088.86]],"id":9631798}],"con":true,"img":false}]}
{"op":"mcm","clk":"1349959962","pt":1588413738604,"mc":[{"id":"1.170370562","rc":[{"atb":[[1.01,1088.13]],"id":9631798}],"con":true,"img":false}]}
{"op":"mcm","clk":"1349960007","pt":1588413740111,"mc":[{"id":"1.170370562","rc":[{"atb":[[3.6,10]],"id":9625043},{"atl":[[1.48,347.77]],"id":9631798}],"con":true,"img":false}]}
{"op":"mcm","clk":"1349960032","pt":1588413742125,"mc":[{"id":"1.170370562","rc":[{"atl":[[1.53,265.95]],"id":9631798}],"con":true,"img":false}]}
{"op":"mcm","clk":"1349960037","pt":1588413742330,"mc":[{"id":"1.170370562","rc":[{"atb":[[1.29,750]],"id":9631798}],"con":true,"img":false}]}
{"op":"mcm","clk":"1349960052","pt":1588413742901,"mc":[{"id":"1.170370562","rc":[{"atl":[[1.39,1051.06]],"id":9631798}],"con":true,"img":false}]}
{"op":"mcm","clk":"1349960067","pt":1588413743734,"mc":[{"id":"1.170370562","rc":[{"trd":[[1.39,58.81]],"ltp":1.39,"tv":58.81,"id":9631798},{"atl":[[1.39,1050.33]],"id":9631798}],"con":true,"img":false}]}
{"op":"mcm","clk":"1349960071","pt":1588413743941,"mc":[{"id":"1.170370562","rc":[{"trd":[[3.6,0.38]],"ltp":3.6,"tv":0.38,"id":9625043},{"atb":[[3.6,9.81]],"id":9625043}],"con":true,"img":false}]}
{"op":"mcm","clk":"1349960080","pt":1588413744200,"mc":[{"id":"1.170370562","rc":[{"atb":[[1.38,750]],"id":9631798}],"con":true,"img":false}]}
{"op":"mcm","clk":"1349960102","pt":1588413745337,"mc":[{"id":"1.170370562","rc":[{"trd":[[3.6,3.02]],"ltp":3.6,"tv":3.02,"id":9625043},{"atb":[[3.6,8.49]],"id":9625043}],"con":true,"img":false}]}
{"op":"mcm","clk":"1349960113","pt":1588413745646,"mc":[{"id":"1.170370562","rc":[{"atb":[[1.26,265.95]],"id":9631798}],"con":true,"img":false}]}
{"op":"mcm","clk":"1349960129","pt":1588413746221,"mc":[{"id":"1.170370562","rc":[{"atl":[[1.39,0]],"id":9631798}],"con":true,"img":false}]}
{"op":"mcm","clk":"1349960132","pt":1588413746427,"mc":[{"id":"1.170370562","rc":[{"trd":[[3.6,20]],"ltp":3.6,"tv":20.0,"id":9625043},{"atb":[[3.6,0]],"id":9625043},{"atl":[[3.6,13.77]],"id":9625043}],"con":true,"img":false}]}
{"op":"mcm","clk":"1349960135","pt":1588413746531,"mc":[{"id":"1.170370562","rc":[{"atl":[[3.6,0]],"id":9625043},{"atl":[[1.48,0]],"id":9631798}],"con":true,"img":false}]}
{"op":"mcm","clk":"1349960145","pt":1588413747250,"mc":[{"id":"1.170370562","rc":[{"atb":[[1.4,196.8]],"id":9631798}],"con":true,"img":false}]}
{"op":"mcm","clk":"1349960168","pt":1588413748642,"mc":[{"id":"1.170370562","rc":[{"atl":[[3.6,10]],"id":9625043}],"con":true,"img":false}]}
{"op":"mcm","clk":"1349960183","pt":1588413749205,"mc":[{"id":"1.170370562","rc":[{"atl":[[3.6,0]],"id":9625043}],"con":true,"img":false}]}
{"op":"mcm","clk":"1349960239","pt":1588413752557,"mc":[{"id":"1.170370562","rc":[{"trd":[[3.5,0.18]],"ltp":3.5,"tv":0.18,"id":9625043},{"trd":[[1.4,0.45]],"ltp":1.4,"tv":0.45,"id":9631798},{"atb":[[1.4,196.35]],"id":9631798}],"con":true,"img":false}]}
{"op":"mcm","clk":"1349960306","pt":1588413756837,"mc":[{"id":"1.170370562","rc":[{"trd":[[3.5,8.17]],"ltp":3.5,"tv":8.17,"id":9625043},{"trd":[[1.4,20.45]],"ltp":1.4,"tv":20.45,"id":9631798},{"atb":[[1.4,176.35]],"id":9631798}],"con":true,"img":false}]}
{"op":"mcm","clk":"1349960315","pt":1588413757250,"mc":[{"id":"1.170370562","rc":[{"atl":[[1.52,0]],"id":9631798}],"con":true,"img":false}]}
{"op":"mcm","clk":"1349960375","pt":1588413760346,"mc":[{"id":"1.170370562","rc":[{"atl":[[1.47,0.23]],"id":9631798}],"con":true,"img":false}]}
{"op":"mcm","clk":"1349960392","pt":1588413761272,"mc":[{"id":"1.170370562","rc":[{"atb":[[1.43,265.95]],"id":9631798}],"con":true,"img":false}]}
{"op":"mcm","clk":"1349960399","pt":1588413761632,"mc":[{"id":"1.170370562","rc":[{"trd":[[1.43,66.29]],"ltp":1.43,"tv":66.29,"id":9631798},{"atb":[[1.43,232.81]],"id":9631798}],"con":true,"img":false}]}
{"op":"mcm","clk":"1349960422","pt":1588413762974,"mc":[{"id":"1.170370562","rc":[{"trd":[[3.1,2.05]],"ltp":3.1,"tv":2.05,"id":9625043},{"atb":[[3.1,3.19]],"id":9625043},{"trd":[[1.48,8.51],[1.47,0.47]],"ltp":1.48,"tv":8.98,"id":9631798},{"atb":[[1.43,0]],"id":9631798},{"atl":[[1.47,0]],"id":9631798}],"con":true,"img":false}]}
{"op":"mcm","clk":"1349960433","pt":1588413763336,"mc":[{"id":"1.170370562","rc":[{"trd":[[1.4,373.16]],"ltp":1.4,"tv":373.16,"id":9631798},{"atb":[[1.4,0]],"id":9631798},{"atl":[[1.4,86.41]],"id":9631798}],"con":true,"img":false}]}
{"op":"mcm","clk":"1349960443","pt":1588413763749,"mc":[{"id":"1.170370562","rc":[{"atb":[[1.26,0]],"id":9631798},{"atl":[[1.53,0]],"id":9631798}],"con":true,"img":false}]}
{"op":"mcm","clk":"1349960448","pt":1588413763954,"mc":[{"id":"1.170370562","rc":[{"atb":[[1.29,0]],"id":9631798}],"con":true,"img":false}]}
{"op":"mcm","clk":"1349960467","pt":1588413765137,"mc":[{"id":"1.170370562","rc":[{"trd":[[1.4,545.98]],"ltp":1.4,"tv":545.98,"id":9631798},{"atb":[[1.44,663.59]],"id":9631798},{"atl":[[1.4,0]],"id":9631798}],"con":true,"img":false}]}
{"op":"mcm","clk":"1349960482","pt":1588413765861,"mc":[{"id":"1.170370562","rc":[{"atl":[[2.08,16.83]],"id":9631798}],"con":true,"img":false}]}
{"op":"mcm","clk":"1349960492","pt":1588413766272,"mc":[{"id":"1.170370562","rc":[{"atb":[[1.44,0]],"id":9631798}],"con":true,"img":false}]}
{"op":"mcm","clk":"1349960497","pt":1588413766477,"mc":[{"id":"1.170370562","rc":[{"atl":[[1.47,19.46]],"id":9631798}],"con":true,"img":false}]}
{"op":"mcm","clk":"1349960512","pt":1588413767455,"mc":[{"id":"1.170370562","rc":[{"atl":[[1.47,0]],"id":9631798}],"con":true,"img":false}]}
{"op":"mcm","clk":"1349960520","pt":1588413767660,"mc":[{"id":"1.170370562","rc":[{"atb":[[1.38,0]],"id":9631798}],"con":true,"img":false}]}
{"op":"mcm","clk":"1349960536","pt":1588413768584,"mc":[{"id":"1.170370562","rc":[{"atl":[[1.45,32.68]],"id":9631798}],"con":true,"img":false}]}
{"op":"mcm","clk":"1349960595","pt":1588413770590,"mc":[{"id":"1.170370562","rc":[{"atl":[[1.43,192.66]],"id":9631798}],"con":true,"img":false}]}
{"op":"mcm","clk":"1349960600","pt":1588413770746,"mc":[{"id":"1.170370562","rc":[{"atl":[[1.4,2.43]],"id":9631798}],"con":true,"img":false}]}
{"op":"mcm","clk":"1349960619","pt":1588413771261,"mc":[{"id":"1.170370562","rc":[{"atb":[[1.24,265.95]],"id":9631798}],"con":true,"img":false}]}
{"op":"mcm","clk":"1349960662","pt":1588413772549,"mc":[{"id":"1.170370562","rc":[{"atl":[[1.45,0]],"id":9631798}],"con":true,"img":false}]}
{"op":"mcm","clk":"1349960678","pt":1588413772963,"mc":[{"id":"1.170370562","rc":[{"atl":[[1.39,31.11]],"id":9631798}],"con":true,"img":false}]}
{"op":"mcm","clk":"1349960688","pt":1588413773684,"mc":[{"id":"1.170370562","rc":[{"atb":[[3.1,0]],"id":9625043}],"con":true,"img":false}]}
{"op":"mcm","clk":"1349960697","pt":1588413774100,"mc":[{"id":"1.170370562","rc":[{"atb":[[1.3,750]],"id":9631798}],"con":true,"img":false}]}
{"op":"mcm","clk":"1349960703","pt":1588413774362,"mc":[{"id":"1.170370562","rc":[{"atl":[[1.63,265.95]],"id":9631798}],"con":true,"img":false}]}
{"op":"mcm","clk":"1349960727","pt":1588413775551,"mc":[{"id":"1.170370562","rc":[{"atl":[[1.39,0]],"id":9631798}],"con":true,"img":false}]}
{"op":"mcm","clk":"1349960750","pt":1588413776274,"mc":[{"id":"1.170370562","rc":[{"atb":[[1.17,750]],"id":9631798}],"con":true,"img":false}]}
{"op":"mcm","clk":"1349960762","pt":1588413776897,"mc":[{"id":"1.170370562","rc":[{"atl":[[1.4,0]],"id":9631798}],"con":true,"img":false}]}
{"op":"mcm","clk":"1349960776","pt":1588413777674,"mc":[{"id":"1.170370562","rc":[{"atl":[[1.41,32.68]],"id":9631798}],"con":true,"img":false}]}
{"op":"mcm","clk":"1349960787","pt":1588413777879,"mc":[{"id":"1.170370562","rc":[{"atb":[[1.25,222]],"id":9631798}],"con":true,"img":false}]}
{"op":"mcm","clk":"1349960792","pt":1588413777984,"mc":[{"id":"1.170370562","rc":[{"atb":[[1.3,0],[1.32,55.96]],"id":9631798},{"atl":[[1.42,66.48]],"id":9631798}],"con":true,"img":false}]}
{"op":"mcm","clk":"1349960807","pt":1588413778605,"mc":[{"id":"1.170370562","rc":[{"atb":[[1.2,222]],"id":9631798}],"con":true,"img":false}]}
{"op":"mcm","clk":"1349960820","pt":1588413779171,"mc":[{"id":"1.170370562","rc":[{"atl":[[1.43,0]],"id":9631798}],"con":true,"img":false}]}
{"op":"mcm","clk":"1349960827","pt":1588413779480,"mc":[{"id":"1.170370562","rc":[{"atb":[[1.16,222]],"id":9631798}],"con":true,"img":false}]}
{"op":"mcm","clk":"1349960846","pt":1588413780666,"mc":[{"id":"1.170370562","rc":[{"atl":[[1.42,0]],"id":9631798}],"con":true,"img":false}]}
{"op":"mcm","clk":"1349960883","pt":1588413782691,"mc":[{"id":"1.170370562","rc":[{"trd":[[1.41,57.48]],"ltp":1.41,"tv":57.48,"id":9631798},{"atl":[[1.41,3.94]],"id":9631798}],"con":true,"img":false}]}
{"op":"mcm","clk":"1349960908","pt":1588413783579,"mc":[{"id":"1.170370562","rc":[{"atb":[[1.27,750]],"id":9631798}],"con":true,"img":false}]}
{"op":"mcm","clk":"1349960917","pt":1588413783996,"mc":[{"id":"1.170370562","rc":[{"atl":[[1.7,0.74]],"id":9631798}],"con":true,"img":false}]}
{"op":"mcm","clk":"1349960919","pt":1588413784101,"mc":[{"id":"1.170370562","rc":[{"atb":[[1.12,0.23]],"id":9631798},{"atl":[[1.41,0]],"id":9631798}],"con":true,"img":false}]}
{"op":"mcm","clk":"1349960940","pt":1588413784779,"mc":[{"id":"1.170370562","rc":[{"atl":[[1.4,196.79]],"id":9631798}],"con":true,"img":false}]}
{"op":"mcm","clk":"1349960963","pt":1588413785612,"mc":[{"id":"1.170370562","rc":[{"atb":[[1.33,265.95]],"id":9631798}],"con":true,"img":false}]}
{"op":"mcm","clk":"1349961017","pt":1588413789484,"mc":[{"id":"1.170370562","rc":[{"trd":[[1.4,553.98]],"ltp":1.4,"tv":553.98,"id":9631798},{"atl":[[1.4,192.8]],"id":9631798}],"con":true,"img":false}]}
{"op":"mcm","clk":"1349961084","pt":1588413793101,"mc":[{"id":"1.170370562","rc":[{"atb":[[1.33,0]],"id":9631798}],"con":true,"img":false}]}
{"op":"mcm","clk":"1349961086","pt":1588413793204,"mc":[{"id":"1.170370562","rc":[{"trd":[[1.32,96.07]],"ltp":1.32,"tv":96.07,"id":9631798},{"atb":[[1.32,24.77]],"id":9631798}],"con":true,"img":false}]}
{"op":"mcm","clk":"1349961088","pt":1588413793616,"mc":[{"id":"1.170370562","rc":[{"trd":[[1.32,96.12]],"ltp":1.32,"tv":96.12,"id":9631798},{"atb":[[1.32,24.74]],"id":9631798}],"con":true,"img":false}]}
{"op":"mcm","clk":"1349961098","pt":1588413794186,"mc":[{"id":"1.170370562","rc":[{"trd":[[1.32,96.32]],"ltp":1.32,"tv":96.32,"id":9631798},{"atb":[[1.32,24.64]],"id":9631798}],"con":true,"img":false}]}
{"op":"mcm","clk":"1349961111","pt":1588413795116,"mc":[{"id":"1.170370562","rc":[{"trd":[[1.4,939.58]],"ltp":1.4,"tv":939.58,"id":9631798},{"atb":[[1.43,506.28]],"id":9631798},{"atl":[[1.4,0]],"id":9631798}],"con":true,"img":false}]}
{"op":"mcm","clk":"1349961119","pt":1588413795686,"mc":[{"id":"1.170370562","rc":[{"atb":[[1.48,1000]],"id":9631798}],"con":true,"img":false}]}
{"op":"mcm","clk":"1349961122","pt":1588413795787,"mc":[{"id":"1.170370562","rc":[{"atb":[[1.43,0]],"id":9631798}],"con":true,"img":false}]}
{"op":"mcm","clk":"1349961124","pt":1588413795891,"mc":[{"id":"1.170370562","rc":[{"atb":[[1.48,0]],"id":9631798}],"con":true,"img":false}]}
{"op":"mcm","clk":"1349961133","pt":1588413796407,"mc":[{"id":"1.170370562","rc":[{"atb":[[1.33,0.11]],"id":9631798}],"con":true,"img":false}]}
{"op":"mcm","clk":"1349961166","pt":1588413797601,"mc":[{"id":"1.170370562","rc":[{"atb":[[1.42,492.02]],"id":9631798}],"con":true,"img":false}]}
{"op":"mcm","clk":"1349961171","pt":1588413797910,"mc":[{"id":"1.170370562","rc":[{"atl":[[1.55,0]],"id":9631798}],"con":true,"img":false}]}
{"op":"mcm","clk":"1349961188","pt":1588413798684,"mc":[{"id":"1.170370562","rc":[{"atb":[[1.42,0]],"id":9631798}],"con":true,"img":false}]}
{"op":"mcm","clk":"1349961271","pt":1588413802735,"mc":[{"id":"1.170370562","rc":[{"atb":[[1.43,265.95]],"id":9631798}],"con":true,"img":false}]}
{"op":"mcm","clk":"1349961275","pt":1588413802838,"mc":[{"id":"1.170370562","rc":[{"atb":[[1.42,750]],"id":9631798}],"con":true,"img":false}]}
{"op":"mcm","clk":"1349961292","pt":1588413803818,"mc":[{"id":"1.170370562","rc":[{"atl":[[1.49,159.32]],"id":9631798}],"con":true,"img":false}]}
{"op":"mcm","clk":"1349961296","pt":1588413804025,"mc":[{"id":"1.170370562","rc":[{"atb":[[1.48,750]],"id":9631798}],"con":true,"img":false}]}
{"op":"mcm","clk":"1349961319","pt":1588413805421,"mc":[{"id":"1.170370562","rc":[{"atb":[[1.48,0]],"id":9631798}],"con":true,"img":false}]}
{"op":"mcm","clk":"1349961321","pt":1588413805631,"mc":[{"id":"1.170370562","rc":[{"atb":[[1.32,723.73]],"id":9631798}],"con":true,"img":false}]}
{"op":"mcm","clk":"1349961327","pt":1588413805943,"mc":[{"id":"1.170370562","rc":[{"atb":[[1.42,946.8]],"id":9631798}],"con":true,"img":false}]}
{"op":"mcm","clk":"1349961352","pt":1588413806826,"mc":[{"id":"1.170370562","rc":[{"atb":[[1.32,0]],"id":9631798}],"con":true,"img":false}]}
{"op":"mcm","clk":"1349961388","pt":1588413808942,"mc":[{"id":"1.170370562","rc":[{"atb":[[1.44,159.97]],"id":9631798}],"con":true,"img":false}]}
{"op":"mcm","clk":"1349961396","pt":1588413809356,"mc":[{"id":"1.170370562","rc":[{"atb":[[1.45,159.97],[1.27,0],[1.42,196.8],[1.17,0]],"id":9631798}],"con":true,"img":false}]}
{"op":"mcm","clk":"1349961411","pt":1588413810025,"mc":[{"id":"1.170370562","rc":[{"atb":[[1.42,0]],"id":9631798}],"con":true,"img":false}]}
{"op":"mcm","clk":"1349961448","pt":1588413811835,"mc":[{"id":"1.170370562","rc":[{"atl":[[1.62,0.23]],"id":9631798}],"con":true,"img":false}]}
{"op":"mcm","clk":"1349961452","pt":1588413812041,"mc":[{"id":"1.170370562","rc":[{"atl":[[1.7,0]],"id":9631798}],"con":true,"img":false}]}
{"op":"mcm","clk":"1349961472","pt":1588413812818,"mc":[{"id":"1.170370562","rc":[{"trd":[[3,49.32]],"ltp":3.0,"tv":49.32,"id":9625043},{"trd":[[1.49,89.72]],"ltp":1.49,"tv":89.72,"id":9631798},{"atl":[[1.49,70.07]],"id":9631798}],"con":true,"img":false}]}
{"op":"mcm","clk":"1349961478","pt":1588413813140,"mc":[{"id":"1.170370562","rc":[{"atb":[[1.25,0]],"id":9631798}],"con":true,"img":false}]}
{"op":"mcm","clk":"1349961496","pt":1588413814058,"mc":[{"id":"1.170370562","rc":[{"trd":[[1.49,199.72]],"ltp":1.49,"tv":199.72,"id":9631798},{"atl":[[1.49,15.07]],"id":9631798}],"con":true,"img":false}]}
{"op":"mcm","clk":"1349961498","pt":1588413814161,"mc":[{"id":"1.170370562","rc":[{"atl":[[1.87,265.95]],"id":9631798}],"con":true,"img":false}]}
{"op":"mcm","clk":"1349961514","pt":1588413815245,"mc":[{"id":"1.170370562","rc":[{"atb":[[1.44,0]],"id":9631798}],"con":true,"img":false}]}
{"op":"mcm","clk":"1349961524","pt":1588413815450,"mc":[{"id":"1.170370562","rc":[{"trd":[[1.49,229.88]],"ltp":1.49,"tv":229.88,"id":9631798},{"atb":[[1.49,39.92]],"id":9631798},{"atl":[[1.49,0]],"id":9631798}],"con":true,"img":false}]}
{"op":"mcm","clk":"1349961548","pt":1588413816220,"mc":[{"id":"1.170370562","rc":[{"atb":[[1.49,0]],"id":9631798}],"con":true,"img":false}]}
{"op":"mcm","clk":"1349961562","pt":1588413817145,"mc":[{"id":"1.170370562","rc":[{"trd":[[1.45,1.48]],"ltp":1.45,"tv":1.48,"id":9631798},{"atb":[[1.45,159.23]],"id":9631798}],"con":true,"img":false}]}
{"op":"mcm","clk":"1349961566","pt":1588413817455,"mc":[{"id":"1.170370562","rc":[{"atb":[[1.49,3.5]],"id":9631798}],"con":true,"img":false}]}
{"op":"mcm","clk":"1349961585","pt":1588413818227,"mc":[{"id":"1.170370562","rc":[{"atl":[[3,10]],"id":9625043}],"con":true,"img":false}]}
{"op":"mcm","clk":"1349961603","pt":1588413819356,"mc":[{"id":"1.170370562","rc":[{"atb":[[1.33,0]],"id":9631798}],"con":true,"img":false}]}
{"op":"mcm","clk":"1349961606","pt":1588413819666,"mc":[{"id":"1.170370562","rc":[{"atb":[[1.45,0],[1.49,6.07]],"id":9631798}],"con":true,"img":false}]}
{"op":"mcm","clk":"1349961620","pt":1588413820650,"mc":[{"id":"1.170370562","rc":[{"atl":[[1.63,0]],"id":9631798}],"con":true,"img":false}]}
{"op":"mcm","clk":"1349961659","pt":1588413822448,"mc":[{"id":"1.170370562","rc":[{"atb":[[1.43,0]],"id":9631798}],"con":true,"img":false}]}
{"op":"mcm","clk":"1349961667","pt":1588413822760,"mc":[{"id":"1.170370562","rc":[{"atb":[[1.25,314.71]],"id":9631798}],"con":true,"img":false}]}
{"op":"mcm","clk":"1349961670","pt":1588413822862,"mc":[{"id":"1.170370562","rc":[{"atb":[[1.49,2.57]],"id":9631798}],"con":true,"img":false}]}
{"op":"mcm","clk":"1349961681","pt":1588413823375,"mc":[{"id":"1.170370562","rc":[{"trd":[[3,50.54]],"ltp":3.0,"tv":50.54,"id":9625043},{"atl":[[3,8.78]],"id":9625043},{"trd":[[1.5,81.3]],"ltp":1.5,"tv":81.3,"id":9631798}],"con":true,"img":false}]}
{"op":"mcm","clk":"1349961694","pt":1588413824459,"mc":[{"id":"1.170370562","rc":[{"atb":[[1.12,0]],"id":9631798}],"con":true,"img":false}]}
{"op":"mcm","clk":"1349961705","pt":1588413825076,"mc":[{"id":"1.170370562","rc":[{"trd":[[3.2,5],[3,59.32]],"ltp":3.2,"tv":64.32,"id":9625043},{"atl":[[3,0]],"id":9625043},{"trd":[[1.45,12.51],[1.5,98.86]],"ltp":1.45,"tv":111.37,"id":9631798},{"atb":[[1.49,0]],"id":9631798},{"atl":[[1.45,12.62]],"id":9631798}],"con":true,"img":false}]}
{"op":"mcm","clk":"1349961780","pt":1588413828479,"mc":[{"id":"1.170370562","rc":[{"atl":[[1.45,0]],"id":9631798}],"con":true,"img":false}]}
{"op":"mcm","clk":"1349961782","pt":1588413828583,"mc":[{"id":"1.170370562","rc":[{"atl":[[1000,2.39]],"id":9631798}],"con":true,"img":false}]}
{"op":"mcm","clk":"1349961789","pt":1588413828839,"mc":[{"id":"1.170370562","rc":[{"atl":[[1000,0.71]],"id":9631798}],"con":true,"img":false}]}
{"op":"mcm","clk":"1349961795","pt":1588413829045,"mc":[{"id":"1.170370562","rc":[{"atl":[[1000,0]],"id":9631798}],"con":true,"img":false}]}
{"op":"mcm","clk":"1349961804","pt":1588413829871,"mc":[{"id":"1.170370562","rc":[{"atl":[[1.62,0]],"id":9631798}],"con":true,"img":false}]}
{"op":"mcm","clk":"1349961850","pt":1588413832293,"mc":[{"id":"1.170370562","rc":[{"atb":[[1.27,750]],"id":9631798}],"con":true,"img":false}]}
{"op":"mcm","clk":"1349961865","pt":1588413832962,"mc":[{"id":"1.170370562","rc":[{"atl":[[1.9,0]],"id":9631798}],"con":true,"img":false}]}
{"op":"mcm","clk":"1349961866","pt":1588413833374,"mc":[{"id":"1.170370562","rc":[{"atb":[[1.3,750]],"id":9631798}],"con":true,"img":false}]}
{"op":"mcm","clk":"1349961870","pt":1588413833581,"mc":[{"id":"1.170370562","rc":[{"atb":[[1.45,265.95]],"id":9631798}],"con":true,"img":false}]}
{"op":"mcm","clk":"1349961877","pt":1588413834148,"mc":[{"id":"1.170370562","rc":[{"atl":[[1.5,0.71]],"id":9631798}],"con":true,"img":false}]}
{"op":"mcm","clk":"1349962018","pt":1588413841166,"mc":[{"id":"1.170370562","rc":[{"atb":[[1.45,0]],"id":9631798}],"con":true,"img":false}]}
{"op":"mcm","clk":"1349962033","pt":1588413842196,"mc":[{"id":"1.170370562","rc":[{"atl":[[1.45,50]],"id":9631798}],"con":true,"img":false}]}
{"op":"mcm","clk":"1349962106","pt":1588413845215,"mc":[{"id":"1.170370562","rc":[{"atl":[[1.45,0]],"id":9631798}],"con":true,"img":false}]}
{"op":"mcm","clk":"1349962136","pt":1588413847076,"mc":[{"id":"1.170370562","rc":[{"atb":[[1.3,0]],"id":9631798}],"con":true,"img":false}]}
{"op":"mcm","clk":"1349962178","pt":1588413849716,"mc":[{"id":"1.170370562","rc":[{"atl":[[3.2,22.65]],"id":9625043}],"con":true,"img":false}]}
{"op":"mcm","clk":"1349962190","pt":1588413850284,"mc":[{"id":"1.170370562","rc":[{"atl":[[3.2,0]],"id":9625043}],"con":true,"img":false}]}
{"op":"mcm","clk":"1349962313","pt":1588413856591,"mc":[{"id":"1.170370562","rc":[{"trd":[[1.5,100.3]],"ltp":1.5,"tv":100.3,"id":9631798},{"atb":[[1.63,999.28]],"id":9631798},{"atl":[[1.5,0]],"id":9631798}],"con":true,"img":false}]}
{"op":"mcm","clk":"1349962329","pt":1588413857319,"mc":[{"id":"1.170370562","rc":[{"atb":[[1.63,0]],"id":9631798}],"con":true,"img":false}]}
{"op":"mcm","clk":"1349962336","pt":1588413857735,"mc":[{"id":"1.170370562","rc":[{"atb":[[1.7,6.56]],"id":9631798}],"con":true,"img":false}]}
{"op":"mcm","clk":"1349962343","pt":1588413858104,"mc":[{"id":"1.170370562","rc":[{"atl":[[1.71,0.23]],"id":9631798}],"con":true,"img":false}]}
{"op":"mcm","clk":"1349962360","pt":1588413858927,"mc":[{"id":"1.170370562","rc":[{"atb":[[1.68,4.79]],"id":9631798}],"con":true,"img":false}]}
{"op":"mcm","clk":"1349962460","pt":1588413864512,"mc":[{"id":"1.170370562","rc":[{"trd":[[1.72,283.37],[1.71,312]],"ltp":1.72,"tv":595.37,"id":9631798},{"atb":[[1.74,705.43]],"id":9631798},{"atl":[[1.72,0],[1.71,0]],"id":9631798}],"con":true,"img":false}]}
{"op":"mcm","clk":"1349962468","pt":1588413865339,"mc":[{"id":"1.170370562","rc":[{"atl":[[1000,2]],"id":9631798}],"con":true,"img":false}]}
{"op":"mcm","clk":"1349962473","pt":1588413865547,"mc":[{"id":"1.170370562","rc":[{"atl":[[1000,0.64]],"id":9631798}],"con":true,"img":false}]}
{"op":"mcm","clk":"1349962475","pt":1588413865652,"mc":[{"id":"1.170370562","rc":[{"atb":[[1.27,0],[1.74,0]],"id":9631798},{"atl":[[1000,0]],"id":9631798}],"con":true,"img":false}]}
{"op":"mcm","clk":"1349962480","pt":1588413865911,"mc":[{"id":"1.170370562","rc":[{"atb":[[1.73,221.63]],"id":9631798}],"con":true,"img":false}]}
{"op":"mcm","clk":"1349962494","pt":1588413866737,"mc":[{"id":"1.170370562","rc":[{"atb":[[1.62,265.95]],"id":9631798}],"con":true,"img":false}]}
{"op":"mcm","clk":"1349962499","pt":1588413866840,"mc":[{"id":"1.170370562","rc":[{"atb":[[1.56,314.71]],"id":9631798}],"con":true,"img":false}]}
{"op":"mcm","clk":"1349962565","pt":1588413868652,"mc":[{"id":"1.170370562","rc":[{"atb":[[1.59,222]],"id":9631798}],"con":true,"img":false}]}
{"op":"mcm","clk":"1349962574","pt":1588413869116,"mc":[{"id":"1.170370562","rc":[{"trd":[[1.73,580.16]],"ltp":1.73,"tv":580.16,"id":9631798},{"atb":[[1.73,21.66]],"id":9631798}],"con":true,"img":false}]}
{"op":"mcm","clk":"1349962582","pt":1588413869633,"mc":[{"id":"1.170370562","rc":[{"atb":[[1.73,0]],"id":9631798}],"con":true,"img":false}]}
{"op":"mcm","clk":"1349962591","pt":1588413870045,"mc":[{"id":"1.170370562","rc":[{"atb":[[1.25,0]],"id":9631798}],"con":true,"img":false}]}
{"op":"mcm","clk":"1349962593","pt":1588413870147,"mc":[{"id":"1.170370562","rc":[{"atl":[[2.36,157.83]],"id":9631798}],"con":true,"img":false}]}
{"op":"mcm","clk":"1349962595","pt":1588413870251,"mc":[{"id":"1.170370562","rc":[{"atb":[[1.52,224.47]],"id":9631798}],"con":true,"img":false}]}
{"op":"mcm","clk":"1349962599","pt":1588413870457,"mc":[{"id":"1.170370562","rc":[{"trd":[[1.62,377.2],[1.68,425.38],[1.7,35.25]],"ltp":1.62,"tv":837.82,"id":9631798},{"atb":[[1.7,0],[1.68,0],[1.62,77.35]],"id":9631798}],"con":true,"img":false}]}
{"op":"mcm","clk":"1349962604","pt":1588413870715,"mc":[{"id":"1.170370562","rc":[{"atl":[[1.68,0.64]],"id":9631798}],"con":true,"img":false}]}
{"op":"mcm","clk":"1349962612","pt":1588413871131,"mc":[{"id":"1.170370562","rc":[{"atl":[[1.7,0.74]],"id":9631798}],"con":true,"img":false}]}
{"op":"mcm","clk":"1349962621","pt":1588413871544,"mc":[{"id":"1.170370562","rc":[{"atl":[[1.7,3.31]],"id":9631798}],"con":true,"img":false}]}
{"op":"mcm","clk":"1349962647","pt":1588413872939,"mc":[{"id":"1.170370562","rc":[{"atl":[[1.7,90.9]],"id":9631798}],"con":true,"img":false}]}
{"op":"mcm","clk":"1349962665","pt":1588413874131,"mc":[{"id":"1.170370562","rc":[{"atl":[[1.8,3.82]],"id":9631798}],"con":true,"img":false}]}
{"op":"mcm","clk":"1349962677","pt":1588413874651,"mc":[{"id":"1.170370562","rc":[{"atl":[[1.83,55]],"id":9631798}],"con":true,"img":false}]}
{"op":"mcm","clk":"1349962700","pt":1588413875943,"mc":[{"id":"1.170370562","rc":[{"atl":[[1.7,3.31]],"id":9631798}],"con":true,"img":false}]}
{"op":"mcm","clk":"1349962708","pt":1588413876258,"mc":[{"id":"1.170370562","rc":[{"atb":[[1.65,222]],"id":9631798}],"con":true,"img":false}]}
{"op":"mcm","clk":"1349962713","pt":1588413876458,"mc":[{"id":"1.170370562","rc":[{"atb":[[1.64,492.02]],"id":9631798}],"con":true,"img":false}]}
{"op":"mcm","clk":"1349962721","pt":1588413876873,"mc":[{"id":"1.170370562","rc":[{"trd":[[1.68,425.58]],"ltp":1.68,"tv":425.58,"id":9631798},{"atb":[[1.65,0]],"id":9631798},{"atl":[[1.68,0.54]],"id":9631798}],"con":true,"img":false}]}
{"op":"mcm","clk":"1349962725","pt":1588413877132,"mc":[{"id":"1.170370562","rc":[{"atl":[[1.68,186.49]],"id":9631798}],"con":true,"img":false}]}
{"op":"mcm","clk":"1349962733","pt":1588413877552,"mc":[{"id":"1.170370562","rc":[{"atl":[[1.7,0.74]],"id":9631798}],"con":true,"img":false}]}
{"op":"mcm","clk":"1349962749","pt":1588413878326,"mc":[{"id":"1.170370562","rc":[{"atb":[[1.62,237.33]],"id":9631798}],"con":true,"img":false}]}
{"op":"mcm","clk":"1349962762","pt":1588413879048,"mc":[{"id":"1.170370562","rc":[{"atl":[[1.73,39.99],[1.76,8.75]],"id":9631798}],"con":true,"img":false}]}
{"op":"mcm","clk":"1349962765","pt":1588413879152,"mc":[{"id":"1.170370562","rc":[{"trd":[[2.46,64.29]],"ltp":2.46,"tv":64.29,"id":9625043},{"trd":[[1.68,519.74]],"ltp":1.68,"tv":519.74,"id":9631798},{"atl":[[1.68,92.34]],"id":9631798}],"con":true,"img":false}]}
{"op":"mcm","clk":"1349962776","pt":1588413879668,"mc":[{"id":"1.170370562","rc":[{"atb":[[1.64,0]],"id":9631798}],"con":true,"img":false}]}
{"op":"mcm","clk":"1349962835","pt":1588413882459,"mc":[{"id":"1.170370562","rc":[{"atl":[[1.86,0.23]],"id":9631798}],"con":true,"img":false}]}
{"op":"mcm","clk":"1349962847","pt":1588413883180,"mc":[{"id":"1.170370562","rc":[{"atb":[[1.67,88.65]],"id":9631798}],"con":true,"img":false}]}
{"op":"mcm","clk":"1349962859","pt":1588413883649,"mc":[{"id":"1.170370562","rc":[{"atb":[[1.2,0]],"id":9631798}],"con":true,"img":false}]}
{"op":"mcm","clk":"1349962867","pt":1588413883957,"mc":[{"id":"1.170370562","rc":[{"atl":[[1.8,0]],"id":9631798}],"con":true,"img":false}]}
{"op":"mcm","clk":"1349962878","pt":1588413884690,"mc":[{"id":"1.170370562","rc":[{"atl":[[1.87,0]],"id":9631798}],"con":true,"img":false}]}
{"op":"mcm","clk":"1349962882","pt":1588413885039,"mc":[{"id":"1.170370562","rc":[{"atb":[[1.67,0]],"id":9631798}],"con":true,"img":false}]}
{"op":"mcm","clk":"1349962908","pt":1588413886535,"mc":[{"id":"1.170370562","rc":[{"atl":[[1.73,0]],"id":9631798}],"con":true,"img":false}]}
{"op":"mcm","clk":"1349962934","pt":1588413888137,"mc":[{"id":"1.170370562","rc":[{"atb":[[1.6,159.97]],"id":9631798}],"con":true,"img":false}]}
{"op":"mcm","clk":"1349962948","pt":1588413888966,"mc":[{"id":"1.170370562","rc":[{"trd":[[2.46,66.94]],"ltp":2.46,"tv":66.94,"id":9625043},{"trd":[[1.68,523.61]],"ltp":1.68,"tv":523.61,"id":9631798},{"atl":[[1.68,88.46]],"id":9631798}],"con":true,"img":false}]}
{"op":"mcm","clk":"1349962961","pt":1588413889487,"mc":[{"id":"1.170370562","rc":[{"atl":[[1.76,0]],"id":9631798}],"con":true,"img":false}]}
{"op":"mcm","clk":"1349962978","pt":1588413890160,"mc":[{"id":"1.170370562","rc":[{"trd":[[1.68,524.71]],"ltp":1.68,"tv":524.71,"id":9631798},{"atb":[[1.66,88.65]],"id":9631798},{"atl":[[1.68,87.91]],"id":9631798}],"con":true,"img":false}]}
{"op":"mcm","clk":"1349962983","pt":1588413890469,"mc":[{"id":"1.170370562","rc":[{"atl":[[1.92,265.95]],"id":9631798}],"con":true,"img":false}]}
{"op":"mcm","clk":"1349962999","pt":1588413891655,"mc":[{"id":"1.170370562","rc":[{"trd":[[1.66,85.58]],"ltp":1.66,"tv":85.58,"id":9631798},{"atb":[[1.66,48.66]],"id":9631798}],"con":true,"img":false}]}
{"op":"mcm","clk":"1349963001","pt":1588413891757,"mc":[{"id":"1.170370562","rc":[{"trd":[[2.52,0.2]],"ltp":2.52,"tv":0.2,"id":9625043},{"trd":[[1.66,85.74]],"ltp":1.66,"tv":85.74,"id":9631798},{"atb":[[1.66,48.5]],"id":9631798}],"con":true,"img":false}]}
{"op":"mcm","clk":"1349963018","pt":1588413893154,"mc":[{"id":"1.170370562","rc":[{"atl":[[1.68,0]],"id":9631798}],"con":true,"img":false}]}
{"op":"mcm","clk":"1349963023","pt":1588413893775,"mc":[{"id":"1.170370562","rc":[{"atb":[[1.66,0]],"id":9631798}],"con":true,"img":false}]}
{"op":"mcm","clk":"1349963026","pt":1588413893983,"mc":[{"id":"1.170370562","rc":[{"atb":[[1.55,265.95]],"id":9631798}],"con":true,"img":false}]}
{"op":"mcm","clk":"1349963030","pt":1588413894188,"mc":[{"id":"1.170370562","rc":[{"atb":[[1.62,159.97]],"id":9631798}],"con":true,"img":false}]}
{"op":"mcm","clk":"1349963040","pt":1588413894551,"mc":[{"id":"1.170370562","rc":[{"atl":[[1.67,8.75]],"id":9631798}],"con":true,"img":false}]}
{"op":"mcm","clk":"1349963044","pt":1588413895068,"mc":[{"id":"1.170370562","rc":[{"trd":[[1.62,514.24]],"ltp":1.62,"tv":514.24,"id":9631798},{"atb":[[1.62,91.44]],"id":9631798}],"con":true,"img":false}]}
{"op":"mcm","clk":"1349963086","pt":1588413896984,"mc":[{"id":"1.170370562","rc":[{"trd":[[1.62,524.31]],"ltp":1.62,"tv":524.31,"id":9631798},{"atb":[[1.62,86.41]],"id":9631798}],"con":true,"img":false}]}
{"op":"mcm","clk":"1349963099","pt":1588413897768,"mc":[{"id":"1.170370562","rc":[{"atl":[[1.86,0]],"id":9631798}],"con":true,"img":false}]}
{"op":"mcm","clk":"1349963102","pt":1588413897976,"mc":[{"id":"1.170370562","rc":[{"atb":[[1.99,55]],"id":9625043}],"con":true,"img":false}]}
{"op":"mcm","clk":"1349963108","pt":1588413898287,"mc":[{"id":"1.170370562","rc":[{"atl":[[1.66,87.91]],"id":9631798}],"con":true,"img":false}]}
{"op":"mcm","clk":"1349963116","pt":1588413898698,"mc":[{"id":"1.170370562","rc":[{"atb":[[1.59,0]],"id":9631798}],"con":true,"img":false}]}
{"op":"mcm","clk":"1349963125","pt":1588413899267,"mc":[{"id":"1.170370562","rc":[{"atl":[[1.65,1000]],"id":9631798}],"con":true,"img":false}]}
{"op":"mcm","clk":"1349963130","pt":1588413899474,"mc":[{"id":"1.170370562","rc":[{"atl":[[2.36,0]],"id":9631798}],"con":true,"img":false}]}
{"op":"mcm","clk":"1349963145","pt":1588413900559,"mc":[{"id":"1.170370562","rc":[{"atl":[[1.63,248.76]],"id":9631798}],"con":true,"img":false}]}
{"op":"mcm","clk":"1349963158","pt":1588413901078,"mc":[{"id":"1.170370562","rc":[{"trd":[[1.62,697.14]],"ltp":1.62,"tv":697.14,"id":9631798},{"atb":[[1.62,0]],"id":9631798},{"atl":[[1.62,162.34]],"id":9631798}],"con":true,"img":false}]}
{"op":"mcm","clk":"1349963169","pt":1588413901904,"mc":[{"id":"1.170370562","rc":[{"atl":[[1.65,0]],"id":9631798}],"con":true,"img":false}]}
{"op":"mcm","clk":"1349963174","pt":1588413902474,"mc":[{"id":"1.170370562","rc":[{"atl":[[1.66,94.48]],"id":9631798}],"con":true,"img":false}]}
{"op":"mcm","clk":"1349963209","pt":1588413904660,"mc":[{"id":"1.170370562","rc":[{"atl":[[1.64,90.06]],"id":9631798}],"con":true,"img":false}]}
{"op":"mcm","clk":"1349963216","pt":1588413904871,"mc":[{"id":"1.170370562","rc":[{"atb":[[1.16,0]],"id":9631798}],"con":true,"img":false}]}
{"op":"mcm","clk":"1349963225","pt":1588413905077,"mc":[{"id":"1.170370562","rc":[{"atl":[[2.22,173.57]],"id":9631798}],"con":true,"img":false}]}
{"op":"mcm","clk":"1349963233","pt":1588413905287,"mc":[{"id":"1.170370562","rc":[{"trd":[[1.62,745.02]],"ltp":1.62,"tv":745.02,"id":9631798},{"atl":[[1.62,138.4]],"id":9631798}],"con":true,"img":false}]}
{"op":"mcm","clk":"1349963269","pt":1588413906590,"mc":[{"id":"1.170370562","rc":[{"atl":[[1.64,162.72]],"id":9631798}],"con":true,"img":false}]}
{"op":"mcm","clk":"1349963282","pt":1588413906900,"mc":[{"id":"1.170370562","rc":[{"trd":[[2.6,11.37]],"ltp":2.6,"tv":11.37,"id":9625043},{"trd":[[1.62,763.26]],"ltp":1.62,"tv":763.26,"id":9631798},{"atl":[[1.62,120.15]],"id":9631798}],"con":true,"img":false}]}
{"op":"mcm","clk":"1349963284","pt":1588413907005,"mc":[{"id":"1.170370562","rc":[{"trd":[[2.6,29.65]],"ltp":2.6,"tv":29.65,"id":9625043},{"trd":[[1.62,792.6]],"ltp":1.62,"tv":792.6,"id":9631798},{"atl":[[1.62,90.81]],"id":9631798}],"con":true,"img":false}]}
{"op":"mcm","clk":"1349963289","pt":1588413907106,"mc":[{"id":"1.170370562","rc":[{"atl":[[1.62,90.92]],"id":9631798}],"con":true,"img":false}]}
{"op":"mcm","clk":"1349963307","pt":1588413907677,"mc":[{"id":"1.170370562","rc":[{"atl":[[1.62,0.1]],"id":9631798}],"con":true,"img":false}]}
{"op":"mcm","clk":"1349963312","pt":1588413907780,"mc":[{"id":"1.170370562","rc":[{"atl":[[1.66,87.91]],"id":9631798}],"con":true,"img":false}]}
{"op":"mcm","clk":"1349963327","pt":1588413908404,"mc":[{"id":"1.170370562","rc":[{"atb":[[1.57,222]],"id":9631798}],"con":true,"img":false}]}
{"op":"mcm","clk":"1349963332","pt":1588413908765,"mc":[{"id":"1.170370562","rc":[{"atl":[[1.61,44.32]],"id":9631798}],"con":true,"img":false}]}
{"op":"mcm","clk":"1349963355","pt":1588413910210,"mc":[{"id":"1.170370562","rc":[{"atl":[[1.66,0]],"id":9631798}],"con":true,"img":false}]}
{"op":"mcm","clk":"1349963371","pt":1588413911087,"mc":[{"id":"1.170370562","rc":[{"trd":[[1.6,17.72]],"ltp":1.6,"tv":17.72,"id":9631798},{"atb":[[1.6,151.11]],"id":9631798}],"con":true,"img":false}]}
{"op":"mcm","clk":"1349963381","pt":1588413911499,"mc":[{"id":"1.170370562","rc":[{"trd":[[1.61,0.23]],"ltp":1.61,"tv":0.23,"id":9631798},{"atl":[[1.61,44.21]],"id":9631798}],"con":true,"img":false}]}
{"op":"mcm","clk":"1349963386","pt":1588413911808,"mc":[{"id":"1.170370562","rc":[{"trd":[[1.6,319.95]],"ltp":1.6,"tv":319.95,"id":9631798},{"atb":[[1.6,0]],"id":9631798},{"atl":[[1.6,10.86]],"id":9631798}],"con":true,"img":false}]}
{"op":"mcm","clk":"1349963401","pt":1588413912787,"mc":[{"id":"1.170370562","rc":[{"atl":[[1.64,90.06]],"id":9631798}],"con":true,"img":false}]}
{"op":"mcm","clk":"1349963403","pt":1588413912890,"mc":[{"id":"1.170370562","rc":[{"atb":[[1.55,0]],"id":9631798}],"con":true,"img":false}]}
{"op":"mcm","clk":"1349963409","pt":1588413913409,"mc":[{"id":"1.170370562","rc":[{"atb":[[1.56,0]],"id":9631798}],"con":true,"img":false}]}
{"op":"mcm","clk":"1349963423","pt":1588413913981,"mc":[{"id":"1.170370562","rc":[{"atl":[[1.6,186.04]],"id":9631798}],"con":true,"img":false}]}
{"op":"mcm","clk":"1349963428","pt":1588413914186,"mc":[{"id":"1.170370562","rc":[{"atl":[[1.64,0]],"id":9631798}],"con":true,"img":false}]}
{"op":"mcm","clk":"1349963430","pt":1588413914290,"mc":[{"id":"1.170370562","rc":[{"atl":[[1.6,175.17]],"id":9631798}],"con":true,"img":false}]}
{"op":"mcm","clk":"1349963461","pt":1588413915689,"mc":[{"id":"1.170370562","rc":[{"trd":[[1.61,88.65],[1.6,670.3]],"ltp":1.61,"tv":758.94,"id":9631798},{"atb":[[1.61,29.37]],"id":9631798},{"atl":[[1.6,0],[1.62,0],[1.61,0]],"id":9631798}],"con":true,"img":false}]}
{"op":"mcm","clk":"1349963486","pt":1588413917392,"mc":[{"id":"1.170370562","rc":[{"atb":[[1.61,0]],"id":9631798}],"con":true,"img":false}]}
{"op":"mcm","clk":"1349963499","pt":1588413918015,"mc":[{"id":"1.170370562","rc":[{"atb":[[1.5,265.95]],"id":9631798}],"con":true,"img":false}]}
{"op":"mcm","clk":"1349963515","pt":1588413919001,"mc":[{"id":"1.170370562","rc":[{"atb":[[1.53,196.8],[1.57,0]],"id":9631798}],"con":true,"img":false}]}
{"op":"mcm","clk":"1349963521","pt":1588413919619,"mc":[{"id":"1.170370562","rc":[{"atb":[[1.61,3.5]],"id":9631798}],"con":true,"img":false}]}
{"op":"mcm","clk":"1349963533","pt":1588413920084,"mc":[{"id":"1.170370562","rc":[{"atb":[[1.61,692.33]],"id":9631798}],"con":true,"img":false}]}
{"op":"mcm","clk":"1349963540","pt":1588413920394,"mc":[{"id":"1.170370562","rc":[{"atl":[[1.64,10.59]],"id":9631798}],"con":true,"img":false}]}
{"op":"mcm","clk":"1349963544","pt":1588413920500,"mc":[{"id":"1.170370562","rc":[{"atb":[[1.52,0]],"id":9631798},{"atl":[[2.22,0]],"id":9631798}],"con":true,"img":false}]}
{"op":"mcm","clk":"1349963551","pt":1588413920714,"mc":[{"id":"1.170370562","rc":[{"atb":[[1.1,0]],"id":9631798}],"con":true,"img":false}]}
{"op":"mcm","clk":"1349963570","pt":1588413921227,"mc":[{"id":"1.170370562","rc":[{"trd":[[1.61,1473.31]],"ltp":1.61,"tv":1473.31,"id":9631798},{"atb":[[1.61,0]],"id":9631798},{"atl":[[1.59,307.67]],"id":9631798}],"con":true,"img":false}]}
{"op":"mcm","clk":"1349963585","pt":1588413921904,"mc":[{"id":"1.170370562","rc":[{"atb":[[1.25,0]],"id":9625043}],"con":true,"img":false}]}
{"op":"mcm","clk":"1349963616","pt":1588413923032,"mc":[{"id":"1.170370562","rc":[{"atl":[[1.59,556.43]],"id":9631798}],"con":true,"img":false}]}
{"op":"mcm","clk":"1349963618","pt":1588413923083,"mc":[{"id":"1.170370562","rc":[{"atl":[[1.57,492.02]],"id":9631798}],"con":true,"img":false}]}
{"op":"mcm","clk":"1349963632","pt":1588413923809,"mc":[{"id":"1.170370562","rc":[{"atb":[[1.53,418.8]],"id":9631798}],"con":true,"img":false}]}
{"op":"mcm","clk":"1349963635","pt":1588413923912,"mc":[{"id":"1.170370562","rc":[{"atl":[[1.57,740.78]],"id":9631798}],"con":true,"img":false}]}
{"op":"mcm","clk":"1349963638","pt":1588413924120,"mc":[{"id":"1.170370562","rc":[{"trd":[[1.5,632.21],[1.53,837.61]],"ltp":1.5,"tv":1469.82,"id":9631798},{"atb":[[1.5,0],[1.53,0]],"id":9631798},{"atl":[[1.4,3439.79],[1.7,0]],"id":9631798}],"con":true,"img":false}]}
{"op":"mcm","clk":"1349963647","pt":1588413924532,"mc":[{"id":"1.170370562","rc":[{"atl":[[1.57,492.02]],"id":9631798}],"con":true,"img":false}]}
{"op":"mcm","clk":"1349963651","pt":1588413924638,"mc":[{"id":"1.170370562","rc":[{"atl":[[1.59,248.76]],"id":9631798}],"con":true,"img":false}]}
{"op":"mcm","clk":"1349963668","pt":1588413925408,"mc":[{"id":"1.170370562","rc":[{"atl":[[1.64,0]],"id":9631798}],"con":true,"img":false}]}
{"op":"mcm","clk":"1349963674","pt":1588413925616,"mc":[{"id":"1.170370562","rc":[{"atl":[[1.57,0]],"id":9631798}],"con":true,"img":false}]}
{"op":"mcm","clk":"1349963682","pt":1588413925991,"mc":[{"id":"1.170370562","rc":[{"atl":[[1.58,39.33]],"id":9631798}],"con":true,"img":false}]}
{"op":"mcm","clk":"1349963683","pt":1588413926095,"mc":[{"id":"1.170370562","rc":[{"trd":[[1.4,1415.45]],"ltp":1.4,"tv":1415.45,"id":9631798},{"atl":[[1.4,3201.86],[2.1,191.67]],"id":9631798}],"con":true,"img":false}]}
{"op":"mcm","clk":"1349963710","pt":1588413927495,"mc":[{"id":"1.170370562","rc":[{"atl":[[1.57,6.56]],"id":9631798}],"con":true,"img":false}]}
{"op":"mcm","clk":"1349963717","pt":1588413927801,"mc":[{"id":"1.170370562","rc":[{"atl":[[1.61,0.1]],"id":9631798}],"con":true,"img":false}]}
{"op":"mcm","clk":"1349963733","pt":1588413928938,"mc":[{"id":"1.170370562","rc":[{"atl":[[1.68,265.95]],"id":9631798}],"con":true,"img":false}]}
{"op":"mcm","clk":"1349963742","pt":1588413929406,"mc":[{"id":"1.170370562","rc":[{"trd":[[3.5,137.81]],"ltp":3.5,"tv":137.81,"id":9625043},{"trd":[[1.4,1739.55]],"ltp":1.4,"tv":1739.55,"id":9631798},{"atl":[[1.4,2877.76],[1.55,11.21]],"id":9631798}],"con":true,"img":false}]}
{"op":"mcm","clk":"1349963748","pt":1588413929712,"mc":[{"id":"1.170370562","rc":[{"trd":[[1.4,3150.49]],"ltp":1.4,"tv":3150.49,"id":9631798},{"atl":[[1.4,2172.29]],"id":9631798}],"con":true,"img":false}]}
{"op":"mcm","clk":"1349963758","pt":1588413930444,"mc":[{"id":"1.170370562","rc":[{"atl":[[1.61,0]],"id":9631798}],"con":true,"img":false}]}
{"op":"mcm","clk":"1349963763","pt":1588413930701,"mc":[{"id":"1.170370562","rc":[{"trd":[[1.4,3594.49]],"ltp":1.4,"tv":3594.49,"id":9631798},{"atl":[[1.4,1950.29]],"id":9631798}],"con":true,"img":false}]}
{"op":"mcm","clk":"1349963767","pt":1588413930805,"mc":[{"id":"1.170370562","rc":[{"trd":[[1.4,4038.49]],"ltp":1.4,"tv":4038.49,"id":9631798},{"atl":[[1.4,1728.29]],"id":9631798}],"con":true,"img":false}]}
{"op":"mcm","clk":"1349963769","pt":1588413930911,"mc":[{"id":"1.170370562","rc":[{"trd":[[1.4,4482.49]],"ltp":1.4,"tv":4482.49,"id":9631798},{"atl":[[1.4,1506.29]],"id":9631798}],"con":true,"img":false}]}
{"op":"mcm","clk":"1349963775","pt":1588413931014,"mc":[{"id":"1.170370562","rc":[{"trd":[[1.4,6482.49]],"ltp":1.4,"tv":6482.49,"id":9631798},{"atl":[[1.4,506.29]],"id":9631798}],"con":true,"img":false}]}
{"op":"mcm","clk":"1349963777","pt":1588413931119,"mc":[{"id":"1.170370562","rc":[{"trd":[[1.4,7304.08]],"ltp":1.4,"tv":7304.08,"id":9631798},{"atl":[[1.4,95.49]],"id":9631798}],"con":true,"img":false}]}
{"op":"mcm","clk":"1349963780","pt":1588413931222,"mc":[{"id":"1.170370562","rc":[{"trd":[[1.4,7495.08]],"ltp":1.4,"tv":7495.08,"id":9631798},{"atb":[[1.43,126.5]],"id":9631798},{"atl":[[1.4,0]],"id":9631798}],"con":true,"img":false}]}
{"op":"mcm","clk":"1349963784","pt":1588413931326,"mc":[{"id":"1.170370562","rc":[{"atl":[[1.54,195.53]],"id":9631798}],"con":true,"img":false}]}
{"op":"mcm","clk":"1349963785","pt":1588413931429,"mc":[{"id":"1.170370562","rc":[{"atb":[[1.43,348.5]],"id":9631798}],"con":true,"img":false}]}
{"op":"mcm","clk":"1349963809","pt":1588413932006,"mc":[{"id":"1.170370562","rc":[{"atb":[[1.4,1000]],"id":9631798}],"con":true,"img":false}]}
{"op":"mcm","clk":"1349963816","pt":1588413932217,"mc":[{"id":"1.170370562","rc":[{"atb":[[1.4,1159.97]],"id":9631798}],"con":true,"img":false}]}
{"op":"mcm","clk":"1349963820","pt":1588413932320,"mc":[{"id":"1.170370562","rc":[{"atb":[[1.4,2159.97],[1.43,0]],"id":9631798}],"con":true,"img":false}]}
{"op":"mcm","clk":"1349963829","pt":1588413932631,"mc":[{"id":"1.170370562","rc":[{"atb":[[1.4,2167.97]],"id":9631798}],"con":true,"img":false}]}
{"op":"mcm","clk":"1349963832","pt":1588413932735,"mc":[{"id":"1.170370562","rc":[{"atb":[[1.43,265.95]],"id":9631798}],"con":true,"img":false}]}
{"op":"mcm","clk":"1349963836","pt":1588413932942,"mc":[{"id":"1.170370562","rc":[{"atl":[[2.86,44.32]],"id":9625043},{"atb":[[1.41,333]],"id":9631798}],"con":true,"img":false}]}
{"op":"mcm","clk":"1349963838","pt":1588413933045,"mc":[{"id":"1.170370562","rc":[{"atb":[[1.4,167.97]],"id":9631798}],"con":true,"img":false}]}
{"op":"mcm","clk":"1349963841","pt":1588413933150,"mc":[{"id":"1.170370562","rc":[{"atb":[[1.44,265.95]],"id":9631798}],"con":true,"img":false}]}
{"op":"mcm","clk":"1349963860","pt":1588413933717,"mc":[{"id":"1.170370562","rc":[{"atb":[[1.45,265.95],[1.41,0]],"id":9631798}],"con":true,"img":false}]}
{"op":"mcm","clk":"1349963867","pt":1588413934133,"mc":[{"id":"1.170370562","rc":[{"atb":[[1.41,333]],"id":9631798}],"con":true,"img":false}]}
{"op":"mcm","clk":"1349963880","pt":1588413934653,"mc":[{"id":"1.170370562","rc":[{"atl":[[2.86,0]],"id":9625043}],"con":true,"img":false}]}
{"op":"mcm","clk":"1349963885","pt":1588413934705,"mc":[{"id":"1.170370562","rc":[{"atl":[[1.58,0]],"id":9631798}],"con":true,"img":false}]}
{"op":"mcm","clk":"1349963894","pt":1588413934911,"mc":[{"id":"1.170370562","rc":[{"atl":[[1.57,0]],"id":9631798}],"con":true,"img":false}]}
{"op":"mcm","clk":"1349963901","pt":1588413935120,"mc":[{"id":"1.170370562","rc":[{"atb":[[1.41,0]],"id":9631798}],"con":true,"img":false}]}
{"op":"mcm","clk":"1349963912","pt":1588413935740,"mc":[{"id":"1.170370562","rc":[{"atb":[[1.41,196.8]],"id":9631798}],"con":true,"img":false}]}
{"op":"mcm","clk":"1349963913","pt":1588413935843,"mc":[{"id":"1.170370562","rc":[{"atb":[[1.4,693.5]],"id":9631798}],"con":true,"img":false}]}
{"op":"mcm","clk":"1349963918","pt":1588413936051,"mc":[{"id":"1.170370562","rc":[{"atb":[[1.4,733.5]],"id":9631798}],"con":true,"img":false}]}
{"op":"mcm","clk":"1349963930","pt":1588413936526,"mc":[{"id":"1.170370562","rc":[{"atb":[[1.42,196.8]],"id":9631798}],"con":true,"img":false}]}
{"op":"mcm","clk":"1349963934","pt":1588413936734,"mc":[{"id":"1.170370562","rc":[{"atb":[[1.4,693.5]],"id":9631798}],"con":true,"img":false}]}
{"op":"mcm","clk":"1349963940","pt":1588413937041,"mc":[{"id":"1.170370562","rc":[{"atb":[[1.43,0]],"id":9631798}],"con":true,"img":false}]}
{"op":"mcm","clk":"1349963941","pt":1588413937144,"mc":[{"id":"1.170370562","rc":[{"atb":[[1.31,0.11]],"id":9631798}],"con":true,"img":false}]}
{"op":"mcm","clk":"1349963950","pt":1588413937558,"mc":[{"id":"1.170370562","rc":[{"atb":[[1.44,0]],"id":9631798}],"con":true,"img":false}]}
{"op":"mcm","clk":"1349963956","pt":1588413937820,"mc":[{"id":"1.170370562","rc":[{"atb":[[1.4,933.46]],"id":9631798}],"con":true,"img":false}]}
{"op":"mcm","clk":"1349963965","pt":1588413938446,"mc":[{"id":"1.170370562","rc":[{"atl":[[1.51,305.35]],"id":9631798}],"con":true,"img":false}]}
{"op":"mcm","clk":"1349963977","pt":1588413939119,"mc":[{"id":"1.170370562","rc":[{"atl":[[1.48,333]],"id":9631798}],"con":true,"img":false}]}
{"op":"mcm","clk":"1349963982","pt":1588413939429,"mc":[{"id":"1.170370562","rc":[{"atl":[[1.48,1193.14],[1.52,248.76]],"id":9631798}],"con":true,"img":false}]}
{"op":"mcm","clk":"1349963994","pt":1588413940151,"mc":[{"id":"1.170370562","rc":[{"atl":[[1.51,554.11]],"id":9631798}],"con":true,"img":false}]}
{"op":"mcm","clk":"1349964015","pt":1588413941339,"mc":[{"id":"1.170370562","rc":[{"atb":[[1.99,0]],"id":9625043},{"atl":[[1.83,0],[1.51,305.35]],"id":9631798}],"con":true,"img":false}]}
{"op":"mcm","clk":"1349964028","pt":1588413941752,"mc":[{"id":"1.170370562","rc":[{"atb":[[1.43,196.8]],"id":9631798}],"con":true,"img":false}]}
{"op":"mcm","clk":"1349964050","pt":1588413942761,"mc":[{"id":"1.170370562","rc":[{"atl":[[1.52,0]],"id":9631798}],"con":true,"img":false}]}
{"op":"mcm","clk":"1349964060","pt":1588413943067,"mc":[{"id":"1.170370562","rc":[{"atb":[[1.4,407.93]],"id":9631798}],"con":true,"img":false}]}
{"op":"mcm","clk":"1349964064","pt":1588413943273,"mc":[{"id":"1.170370562","rc":[{"atb":[[1.25,63.98]],"id":9631798}],"con":true,"img":false}]}
{"op":"mcm","clk":"1349964088","pt":1588413944261,"mc":[{"id":"1.170370562","rc":[{"atb":[[1.43,0]],"id":9631798}],"con":true,"img":false}]}
{"op":"mcm","clk":"1349964097","pt":1588413944571,"mc":[{"id":"1.170370562","rc":[{"atb":[[1.45,0]],"id":9631798}],"con":true,"img":false}]}
{"op":"mcm","clk":"1349964118","pt":1588413945349,"mc":[{"id":"1.170370562","rc":[{"atl":[[1.67,0]],"id":9631798}],"con":true,"img":false}]}
{"op":"mcm","clk":"1349964140","pt":1588413946182,"mc":[{"id":"1.170370562","rc":[{"atb":[[1.42,0]],"id":9631798}],"con":true,"img":false}]}
{"op":"mcm","clk":"1349964143","pt":1588413946280,"mc":[{"id":"1.170370562","rc":[{"atb":[[1.31,0]],"id":9631798}],"con":true,"img":false}]}
{"op":"mcm","clk":"1349964154","pt":1588413946539,"mc":[{"id":"1.170370562","rc":[{"trd":[[1.41,451.09]],"ltp":1.41,"tv":451.09,"id":9631798},{"atb":[[1.41,0]],"id":9631798},{"atl":[[1.41,136.19]],"id":9631798}],"con":true,"img":false}]}
{"op":"mcm","clk":"1349964157","pt":1588413946645,"mc":[{"id":"1.170370562","rc":[{"atl":[[1.47,492.02]],"id":9631798}],"con":true,"img":false}]}
{"op":"mcm","clk":"1349964175","pt":1588413947264,"mc":[{"id":"1.170370562","rc":[{"atl":[[1.91,0]],"id":9631798}],"con":true,"img":false}]}
{"op":"mcm","clk":"1349964188","pt":1588413947578,"mc":[{"id":"1.170370562","rc":[{"atl":[[1.48,333]],"id":9631798}],"con":true,"img":false}]}
{"op":"mcm","clk":"1349964200","pt":1588413947942,"mc":[{"id":"1.170370562","rc":[{"trd":[[1.47,48.04],[1.41,723.47]],"ltp":1.47,"tv":771.51,"id":9631798},{"atl":[[1.41,0],[1.47,468.23]],"id":9631798}],"con":true,"img":false}]}
{"op":"mcm","clk":"1349964202","pt":1588413948045,"mc":[{"id":"1.170370562","rc":[{"atb":[[1.4,247.96]],"id":9631798}],"con":true,"img":false}]}
{"op":"mcm","clk":"1349964206","pt":1588413948149,"mc":[{"id":"1.170370562","rc":[{"atl":[[1.48,0]],"id":9631798}],"con":true,"img":false}]}
{"op":"mcm","clk":"1349964212","pt":1588413948563,"mc":[{"id":"1.170370562","rc":[{"atb":[[1.25,0]],"id":9631798}],"con":true,"img":false}]}
{"op":"mcm","clk":"1349964225","pt":1588413949079,"mc":[{"id":"1.170370562","rc":[{"trd":[[1.45,12.75]],"ltp":1.45,"tv":12.75,"id":9631798},{"atl":[[1.45,332.88]],"id":9631798}],"con":true,"img":false}]}
{"op":"mcm","clk":"1349964228","pt":1588413949284,"mc":[{"id":"1.170370562","rc":[{"atb":[[1.38,115.46]],"id":9631798}],"con":true,"img":false}]}
{"op":"mcm","clk":"1349964240","pt":1588413949752,"mc":[{"id":"1.170370562","rc":[{"atl":[[1.54,0]],"id":9631798}],"con":true,"img":false}]}
{"op":"mcm","clk":"1349964250","pt":1588413950062,"mc":[{"id":"1.170370562","rc":[{"atl":[[1.51,0]],"id":9631798}],"con":true,"img":false}]}
{"op":"mcm","clk":"1349964253","pt":1588413950167,"mc":[{"id":"1.170370562","rc":[{"atl":[[1.47,781.89]],"id":9631798}],"con":true,"img":false}]}
{"op":"mcm","clk":"1349964257","pt":1588413950479,"mc":[{"id":"1.170370562","rc":[{"atl":[[1.47,313.66]],"id":9631798}],"con":true,"img":false}]}
{"op":"mcm","clk":"1349964269","pt":1588413951461,"mc":[{"id":"1.170370562","rc":[{"atb":[[1.39,265.95]],"id":9631798}],"con":true,"img":false}]}
{"op":"mcm","clk":"1349964296","pt":1588413953266,"mc":[{"id":"1.170370562","rc":[{"trd":[[1.45,60.65]],"ltp":1.45,"tv":60.65,"id":9631798},{"atl":[[1.45,308.93]],"id":9631798}],"con":true,"img":false}]}
{"op":"mcm","clk":"1349964297","pt":1588413953375,"mc":[{"id":"1.170370562","rc":[{"atl":[[1.68,0]],"id":9631798}],"con":true,"img":false}]}
{"op":"mcm","clk":"1349964303","pt":1588413953679,"mc":[{"id":"1.170370562","rc":[{"atb":[[1.3,159.97]],"id":9631798},{"atl":[[1.45,707.97]],"id":9631798}],"con":true,"img":false}]}
{"op":"mcm","clk":"1349964316","pt":1588413954091,"mc":[{"id":"1.170370562","rc":[{"atl":[[1.43,890.22]],"id":9631798}],"con":true,"img":false}]}
{"op":"mcm","clk":"1349964329","pt":1588413954555,"mc":[{"id":"1.170370562","rc":[{"atl":[[1.67,16.68]],"id":9631798}],"con":true,"img":false}]}
{"op":"mcm","clk":"1349964336","pt":1588413954866,"mc":[{"id":"1.170370562","rc":[{"atl":[[1.46,55],[1.92,0]],"id":9631798}],"con":true,"img":false}]}
{"op":"mcm","clk":"1349964343","pt":1588413955074,"mc":[{"id":"1.170370562","rc":[{"atb":[[1.4,367.64]],"id":9631798}],"con":true,"img":false}]}
{"op":"mcm","clk":"1349964354","pt":1588413955589,"mc":[{"id":"1.170370562","rc":[{"atl":[[1.44,55]],"id":9631798}],"con":true,"img":false}]}
{"op":"mcm","clk":"1349964378","pt":1588413956361,"mc":[{"id":"1.170370562","rc":[{"atl":[[1.44,320.95]],"id":9631798}],"con":true,"img":false}]}
{"op":"mcm","clk":"1349964403","pt":1588413957758,"mc":[{"id":"1.170370562","rc":[{"atl":[[1.45,399.04]],"id":9631798}],"con":true,"img":false}]}
{"op":"mcm","clk":"1349964405","pt":1588413957854,"mc":[{"id":"1.170370562","rc":[{"atb":[[1.1,159.97]],"id":9631798}],"con":true,"img":false}]}
{"op":"mcm","clk":"1349964411","pt":1588413958069,"mc":[{"id":"1.170370562","rc":[{"atb":[[1.1,319.94],[1.41,2.43]],"id":9631798}],"con":true,"img":false}]}
{"op":"mcm","clk":"1349964415","pt":1588413958164,"mc":[{"id":"1.170370562","rc":[{"atb":[[1.1,479.92]],"id":9631798}],"con":true,"img":false}]}
{"op":"mcm","clk":"1349964417","pt":1588413958272,"mc":[{"id":"1.170370562","rc":[{"atb":[[1.4,119.68]],"id":9631798}],"con":true,"img":false}]}
{"op":"mcm","clk":"1349964452","pt":1588413959567,"mc":[{"id":"1.170370562","rc":[{"atl":[[1.43,0]],"id":9631798}],"con":true,"img":false}]}
{"op":"mcm","clk":"1349964465","pt":1588413960085,"mc":[{"id":"1.170370562","rc":[{"trd":[[1.41,733.5]],"ltp":1.41,"tv":733.5,"id":9631798},{"atb":[[1.41,0]],"id":9631798},{"atl":[[1.41,13.59]],"id":9631798}],"con":true,"img":false}]}
{"op":"mcm","clk":"1349964484","pt":1588413960703,"mc":[{"id":"1.170370562","rc":[{"atb":[[1.35,159.97]],"id":9631798}],"con":true,"img":false}]}
{"op":"mcm","clk":"1349964492","pt":1588413960861,"mc":[{"id":"1.170370562","rc":[{"atl":[[1.41,346.59]],"id":9631798}],"con":true,"img":false}]}
{"op":"mcm","clk":"1349964500","pt":1588413961275,"mc":[{"id":"1.170370562","rc":[{"trd":[[3.4,22.16]],"ltp":3.4,"tv":22.16,"id":9625043},{"trd":[[1.41,786.94]],"ltp":1.41,"tv":786.94,"id":9631798},{"atl":[[1.41,293.16],[1.46,0]],"id":9631798}],"con":true,"img":false}]}
{"op":"mcm","clk":"1349964510","pt":1588413961694,"mc":[{"id":"1.170370562","rc":[{"atl":[[1.44,265.95]],"id":9631798}],"con":true,"img":false}]}
{"op":"mcm","clk":"1349964573","pt":1588413964075,"mc":[{"id":"1.170370562","rc":[{"trd":[[1.41,892.82]],"ltp":1.41,"tv":892.82,"id":9631798},{"atl":[[1.41,240.22]],"id":9631798}],"con":true,"img":false}]}
{"op":"mcm","clk":"1349964589","pt":1588413964593,"mc":[{"id":"1.170370562","rc":[{"trd":[[1.41,1278.36]],"ltp":1.41,"tv":1278.36,"id":9631798},{"atl":[[1.41,47.45]],"id":9631798}],"con":true,"img":false}]}
{"op":"mcm","clk":"1349964594","pt":1588413964695,"mc":[{"id":"1.170370562","rc":[{"atb":[[1.39,0]],"id":9631798}],"con":true,"img":false}]}
{"op":"mcm","clk":"1349964597","pt":1588413964798,"mc":[{"id":"1.170370562","rc":[{"trd":[[1.41,1367.02]],"ltp":1.41,"tv":1367.02,"id":9631798},{"atl":[[1.41,0]],"id":9631798}],"con":true,"img":false}]}
{"op":"mcm","clk":"1349964600","pt":1588413964903,"mc":[{"id":"1.170370562","rc":[{"trd":[[1.4,7605.08]],"ltp":1.4,"tv":7605.08,"id":9631798},{"atb":[[1.4,64.68]],"id":9631798},{"atl":[[1.42,12.23]],"id":9631798}],"con":true,"img":false}]}
{"op":"mcm","clk":"1349964604","pt":1588413965108,"mc":[{"id":"1.170370562","rc":[{"trd":[[1.4,7715.08]],"ltp":1.4,"tv":7715.08,"id":9631798},{"atb":[[1.4,9.68]],"id":9631798}],"con":true,"img":false}]}
{"op":"mcm","clk":"1349964652","pt":1588413966303,"mc":[{"id":"1.170370562","rc":[{"atl":[[1.42,336.94]],"id":9631798}],"con":true,"img":false}]}
{"op":"mcm","clk":"1349964656","pt":1588413966413,"mc":[{"id":"1.170370562","rc":[{"atl":[[3.5,44.32]],"id":9625043}],"con":true,"img":false}]}
{"op":"mcm","clk":"1349964660","pt":1588413966508,"mc":[{"id":"1.170370562","rc":[{"atl":[[1.42,324.7]],"id":9631798}],"con":true,"img":false}]}
{"op":"mcm","clk":"1349964671","pt":1588413966716,"mc":[{"id":"1.170370562","rc":[{"atl":[[1.42,0]],"id":9631798}],"con":true,"img":false}]}
{"op":"mcm","clk":"1349964684","pt":1588413967084,"mc":[{"id":"1.170370562","rc":[{"atl":[[3.3,2.39]],"id":9625043}],"con":true,"img":false}]}
{"op":"mcm","clk":"1349964697","pt":1588413967611,"mc":[{"id":"1.170370562","rc":[{"atb":[[1.38,0]],"id":9631798}],"con":true,"img":false}]}
{"op":"mcm","clk":"1349964703","pt":1588413967817,"mc":[{"id":"1.170370562","rc":[{"atb":[[1.41,1000]],"id":9631798}],"con":true,"img":false}]}
{"op":"mcm","clk":"1349964707","pt":1588413967873,"mc":[{"id":"1.170370562","rc":[{"atl":[[1.47,0]],"id":9631798}],"con":true,"img":false}]}
{"op":"mcm","clk":"1349964725","pt":1588413968390,"mc":[{"id":"1.170370562","rc":[{"atb":[[1.41,0]],"id":9631798}],"con":true,"img":false}]}
{"op":"mcm","clk":"1349964732","pt":1588413968599,"mc":[{"id":"1.170370562","rc":[{"atl":[[3.3,0]],"id":9625043}],"con":true,"img":false}]}
{"op":"mcm","clk":"1349964759","pt":1588413969781,"mc":[{"id":"1.170370562","rc":[{"atb":[[1.34,265.95]],"id":9631798}],"con":true,"img":false}]}
{"op":"mcm","clk":"1349964769","pt":1588413970089,"mc":[{"id":"1.170370562","rc":[{"atl":[[1.45,0],[1.55,0]],"id":9631798}],"con":true,"img":false}]}
{"op":"mcm","clk":"1349964785","pt":1588413970709,"mc":[{"id":"1.170370562","rc":[{"trd":[[3.5,182.14]],"ltp":3.5,"tv":182.14,"id":9625043},{"atl":[[3.5,0]],"id":9625043},{"trd":[[1.4,7845.26]],"ltp":1.4,"tv":7845.26,"id":9631798},{"atb":[[1.4,0]],"id":9631798},{"atl":[[1.4,35.21]],"id":9631798}],"con":true,"img":false}]}
{"op":"mcm","clk":"1349964805","pt":1588413971283,"mc":[{"id":"1.170370562","rc":[{"trd":[[1.4,7847.46]],"ltp":1.4,"tv":7847.46,"id":9631798},{"atl":[[1.4,34.11]],"id":9631798}],"con":true,"img":false}]}
{"op":"mcm","clk":"1349964854","pt":1588413973300,"mc":[{"id":"1.170370562","rc":[{"trd":[[1.4,7915.69]],"ltp":1.4,"tv":7915.69,"id":9631798},{"atb":[[1.4,82.9]],"id":9631798},{"atl":[[1.4,0]],"id":9631798}],"con":true,"img":false}]}
{"op":"mcm","clk":"1349964859","pt":1588413973503,"mc":[{"id":"1.170370562","rc":[{"atb":[[1.4,0]],"id":9631798}],"con":true,"img":false}]}
{"op":"mcm","clk":"1349964862","pt":1588413973709,"mc":[{"id":"1.170370562","rc":[{"atb":[[1.38,265.95]],"id":9631798}],"con":true,"img":false}]}
{"op":"mcm","clk":"1349964869","pt":1588413974117,"mc":[{"id":"1.170370562","rc":[{"trd":[[3.25,87.76]],"ltp":3.25,"tv":87.76,"id":9625043},{"trd":[[1.44,198.08]],"ltp":1.44,"tv":198.08,"id":9631798},{"atl":[[1.44,67.87]],"id":9631798}],"con":true,"img":false}]}
{"op":"mcm","clk":"1349964879","pt":1588413974483,"mc":[{"id":"1.170370562","rc":[{"atl":[[1.5,11.58]],"id":9631798}],"con":true,"img":false}]}
{"op":"mcm","clk":"1349964881","pt":1588413974585,"mc":[{"id":"1.170370562","rc":[{"atb":[[1.42,265.95]],"id":9631798}],"con":true,"img":false}]}
{"op":"mcm","clk":"1349964900","pt":1588413975715,"mc":[{"id":"1.170370562","rc":[{"atl":[[3.4,30.79]],"id":9625043}],"con":true,"img":false}]}
{"op":"mcm","clk":"1349964926","pt":1588413976693,"mc":[{"id":"1.170370562","rc":[{"atl":[[3.4,0]],"id":9625043}],"con":true,"img":false}]}
{"op":"mcm","clk":"1349964934","pt":1588413977001,"mc":[{"id":"1.170370562","rc":[{"trd":[[3.25,90.16]],"ltp":3.25,"tv":90.16,"id":9625043},{"trd":[[1.44,203.5]],"ltp":1.44,"tv":203.5,"id":9631798},{"atl":[[1.44,62.45]],"id":9631798}],"con":true,"img":false}]}
{"op":"mcm","clk":"1349964942","pt":1588413977411,"mc":[{"id":"1.170370562","rc":[{"atl":[[3.4,4.07]],"id":9625043}],"con":true,"img":false}]}
{"op":"mcm","clk":"1349964950","pt":1588413977825,"mc":[{"id":"1.170370562","rc":[{"atb":[[1.4,159.97]],"id":9631798}],"con":true,"img":false}]}
{"op":"mcm","clk":"1349964962","pt":1588413978392,"mc":[{"id":"1.170370562","rc":[{"trd":[[1.44,203.57]],"ltp":1.44,"tv":203.57,"id":9631798},{"atl":[[1.44,62.42]],"id":9631798}],"con":true,"img":false}]}
{"op":"mcm","clk":"1349964968","pt":1588413978805,"mc":[{"id":"1.170370562","rc":[{"atl":[[1.53,265.95]],"id":9631798}],"con":true,"img":false}]}
{"op":"mcm","clk":"1349964970","pt":1588413978908,"mc":[{"id":"1.170370562","rc":[{"atl":[[3.4,0]],"id":9625043}],"con":true,"img":false}]}
{"op":"mcm","clk":"1349964972","pt":1588413979009,"mc":[{"id":"1.170370562","rc":[{"atl":[[1.58,275.91]],"id":9631798}],"con":true,"img":false}]}
{"op":"mcm","clk":"1349964980","pt":1588413979524,"mc":[{"id":"1.170370562","rc":[{"trd":[[1.44,328.41]],"ltp":1.44,"tv":328.41,"id":9631798},{"atb":[[1.44,203.53]],"id":9631798},{"atl":[[1.44,0]],"id":9631798}],"con":true,"img":false}]}
{"op":"mcm","clk":"1349964992","pt":1588413979884,"mc":[{"id":"1.170370562","rc":[{"atb":[[1.39,240]],"id":9631798}],"con":true,"img":false}]}
{"op":"mcm","clk":"1349965010","pt":1588413980298,"mc":[{"id":"1.170370562","rc":[{"atb":[[1.44,212.99],[1.37,240]],"id":9631798}],"con":true,"img":false}]}
{"op":"mcm","clk":"1349965011","pt":1588413980401,"mc":[{"id":"1.170370562","rc":[{"atb":[[1.42,0]],"id":9631798}],"con":true,"img":false}]}
{"op":"mcm","clk":"1349965032","pt":1588413981027,"mc":[{"id":"1.170370562","rc":[{"atl":[[3.5,9.83]],"id":9625043},{"trd":[[1.44,754.39]],"ltp":1.44,"tv":754.39,"id":9631798},{"atb":[[1.44,0]],"id":9631798},{"atl":[[1.42,683.5]],"id":9631798}],"con":true,"img":false}]}
{"op":"mcm","clk":"1349965042","pt":1588413981489,"mc":[{"id":"1.170370562","rc":[{"atl":[[1.42,0]],"id":9631798}],"con":true,"img":false}]}
{"op":"mcm","clk":"1349965055","pt":1588413982010,"mc":[{"id":"1.170370562","rc":[{"atl":[[3.25,5.91]],"id":9625043}],"con":true,"img":false}]}
{"op":"mcm","clk":"1349965057","pt":1588413982112,"mc":[{"id":"1.170370562","rc":[{"atl":[[1.46,137.41]],"id":9631798}],"con":true,"img":false}]}
{"op":"mcm","clk":"1349965086","pt":1588413983396,"mc":[{"id":"1.170370562","rc":[{"atl":[[3.25,0]],"id":9625043}],"con":true,"img":false}]}
{"op":"mcm","clk":"1349965092","pt":1588413983909,"mc":[{"id":"1.170370562","rc":[{"atl":[[3.25,4.23]],"id":9625043}],"con":true,"img":false}]}
{"op":"mcm","clk":"1349965107","pt":1588413984321,"mc":[{"id":"1.170370562","rc":[{"trd":[[1.46,0.28]],"ltp":1.46,"tv":0.28,"id":9631798},{"atl":[[1.46,137.26]],"id":9631798}],"con":true,"img":false}]}
{"op":"mcm","clk":"1349965112","pt":1588413984524,"mc":[{"id":"1.170370562","rc":[{"atl":[[3.5,15.32]],"id":9625043}],"con":true,"img":false}]}
{"op":"mcm","clk":"1349965117","pt":1588413984989,"mc":[{"id":"1.170370562","rc":[{"atl":[[3.25,0]],"id":9625043}],"con":true,"img":false}]}
{"op":"mcm","clk":"1349965125","pt":1588413985507,"mc":[{"id":"1.170370562","rc":[{"atb":[[1.44,265.95]],"id":9631798}],"con":true,"img":false}]}
{"op":"mcm","clk":"1349965129","pt":1588413985713,"mc":[{"id":"1.170370562","rc":[{"atl":[[3.25,27.19]],"id":9625043}],"con":true,"img":false}]}
{"op":"mcm","clk":"1349965132","pt":1588413985816,"mc":[{"id":"1.170370562","rc":[{"atl":[[3.5,9.83]],"id":9625043}],"con":true,"img":false}]}
{"op":"mcm","clk":"1349965145","pt":1588413986230,"mc":[{"id":"1.170370562","rc":[{"atb":[[1.44,366.35]],"id":9631798},{"atl":[[1.5,251.58]],"id":9631798}],"con":true,"img":false}]}
{"op":"mcm","clk":"1349965149","pt":1588413986536,"mc":[{"id":"1.170370562","rc":[{"atl":[[1.46,386.02]],"id":9631798}],"con":true,"img":false}]}
{"op":"mcm","clk":"1349965156","pt":1588413986742,"mc":[{"id":"1.170370562","rc":[{"atb":[[1.44,406.34]],"id":9631798}],"con":true,"img":false}]}
{"op":"mcm","clk":"1349965158","pt":1588413986843,"mc":[{"id":"1.170370562","rc":[{"atl":[[3.25,0]],"id":9625043}],"con":true,"img":false}]}
{"op":"mcm","clk":"1349965160","pt":1588413986895,"mc":[{"id":"1.170370562","rc":[{"atb":[[1.44,408.92]],"id":9631798}],"con":true,"img":false}]}
{"op":"mcm","clk":"1349965162","pt":1588413987104,"mc":[{"id":"1.170370562","rc":[{"atl":[[3.5,15.2]],"id":9625043}],"con":true,"img":false}]}
{"op":"mcm","clk":"1349965166","pt":1588413987210,"mc":[{"id":"1.170370562","rc":[{"atl":[[3.25,4.25]],"id":9625043}],"con":true,"img":false}]}
{"op":"mcm","clk":"1349965172","pt":1588413987515,"mc":[{"id":"1.170370562","rc":[{"atb":[[1.44,452.91]],"id":9631798}],"con":true,"img":false}]}
{"op":"mcm","clk":"1349965182","pt":1588413988136,"mc":[{"id":"1.170370562","rc":[{"trd":[[1.44,1251.91]],"ltp":1.44,"tv":1251.91,"id":9631798},{"atb":[[1.44,204.16]],"id":9631798}],"con":true,"img":false}]}
{"op":"mcm","clk":"1349965185","pt":1588413988240,"mc":[{"id":"1.170370562","rc":[{"atl":[[3.5,9.83]],"id":9625043}],"con":true,"img":false}]}
{"op":"mcm","clk":"1349965195","pt":1588413988494,"mc":[{"id":"1.170370562","rc":[{"atl":[[3.25,0]],"id":9625043}],"con":true,"img":false}]}
{"op":"mcm","clk":"1349965201","pt":1588413988600,"mc":[{"id":"1.170370562","rc":[{"atl":[[3.5,0]],"id":9625043}],"con":true,"img":false}]}
{"op":"mcm","clk":"1349965209","pt":1588413989220,"mc":[{"id":"1.170370562","rc":[{"trd":[[1.44,1252.12]],"ltp":1.44,"tv":1252.12,"id":9631798},{"atb":[[1.44,204.05]],"id":9631798}],"con":true,"img":false}]}
{"op":"mcm","clk":"1349965231","pt":1588413990608,"mc":[{"id":"1.170370562","rc":[{"atb":[[1.44,201.39]],"id":9631798}],"con":true,"img":false}]}
{"op":"mcm","clk":"1349965250","pt":1588413991335,"mc":[{"id":"1.170370562","rc":[{"trd":[[3.15,35.19]],"ltp":3.15,"tv":35.19,"id":9625043},{"trd":[[1.46,76.21]],"ltp":1.46,"tv":76.21,"id":9631798},{"atl":[[1.46,310.09]],"id":9631798}],"con":true,"img":false}]}
{"op":"mcm","clk":"1349965253","pt":1588413991438,"mc":[{"id":"1.170370562","rc":[{"trd":[[1.44,1597.33]],"ltp":1.44,"tv":1597.33,"id":9631798},{"atb":[[1.44,26.21]],"id":9631798}],"con":true,"img":false}]}
{"op":"mcm","clk":"1349965261","pt":1588413991747,"mc":[{"id":"1.170370562","rc":[{"trd":[[3.15,41.27]],"ltp":3.15,"tv":41.27,"id":9625043},{"trd":[[1.46,89.32]],"ltp":1.46,"tv":89.32,"id":9631798},{"atl":[[1.46,296.98]],"id":9631798}],"con":true,"img":false}]}
{"op":"mcm","clk":"1349965271","pt":1588413992218,"mc":[{"id":"1.170370562","rc":[{"atl":[[3.5,0.41]],"id":9625043}],"con":true,"img":false}]}
{"op":"mcm","clk":"1349965300","pt":1588413993407,"mc":[{"id":"1.170370562","rc":[{"atl":[[1.5,11.58]],"id":9631798}],"con":true,"img":false}]}
{"op":"mcm","clk":"1349965308","pt":1588413993719,"mc":[{"id":"1.170370562","rc":[{"trd":[[3.15,52.19]],"ltp":3.15,"tv":52.19,"id":9625043},{"trd":[[1.46,112.89]],"ltp":1.46,"tv":112.89,"id":9631798},{"atl":[[1.46,273.42]],"id":9631798}],"con":true,"img":false}]}
{"op":"mcm","clk":"1349965312","pt":1588413994029,"mc":[{"id":"1.170370562","rc":[{"trd":[[3.15,56.59]],"ltp":3.15,"tv":56.59,"id":9625043},{"trd":[[1.46,122.38]],"ltp":1.46,"tv":122.38,"id":9631798},{"atl":[[1.46,263.92]],"id":9631798}],"con":true,"img":false}]}
{"op":"mcm","clk":"1349965317","pt":1588413994338,"mc":[{"id":"1.170370562","rc":[{"trd":[[1.46,388.34]],"ltp":1.46,"tv":388.34,"id":9631798},{"atl":[[1.46,130.94]],"id":9631798}],"con":true,"img":false}]}
{"op":"mcm","clk":"1349965321","pt":1588413994550,"mc":[{"id":"1.170370562","rc":[{"trd":[[3.15,62.7]],"ltp":3.15,"tv":62.7,"id":9625043},{"trd":[[1.46,401.54]],"ltp":1.46,"tv":401.54,"id":9631798},{"atl":[[1.46,117.74]],"id":9631798}],"con":true,"img":false}]}
{"op":"mcm","clk":"1349965332","pt":1588413994915,"mc":[{"id":"1.170370562","rc":[{"atb":[[1.41,240]],"id":9631798}],"con":true,"img":false}]}
{"op":"mcm","clk":"1349965337","pt":1588413995227,"mc":[{"id":"1.170370562","rc":[{"atb":[[1.44,0]],"id":9631798}],"con":true,"img":false}]}
{"op":"mcm","clk":"1349965345","pt":1588413995745,"mc":[{"id":"1.170370562","rc":[{"trd":[[1.46,406.86]],"ltp":1.46,"tv":406.86,"id":9631798},{"atl":[[1.46,115.08]],"id":9631798}],"con":true,"img":false}]}
{"op":"mcm","clk":"1349965348","pt":1588413995848,"mc":[{"id":"1.170370562","rc":[{"trd":[[3.15,95.9]],"ltp":3.15,"tv":95.9,"id":9625043},{"trd":[[1.46,478.49]],"ltp":1.46,"tv":478.49,"id":9631798},{"atl":[[1.46,43.46]],"id":9631798}],"con":true,"img":false}]}
{"op":"mcm","clk":"1349965356","pt":1588413996107,"mc":[{"id":"1.170370562","rc":[{"trd":[[1.46,497.68]],"ltp":1.46,"tv":497.68,"id":9631798},{"atl":[[1.46,33.86]],"id":9631798}],"con":true,"img":false}]}
{"op":"mcm","clk":"1349965376","pt":1588413996939,"mc":[{"id":"1.170370562","rc":[{"trd":[[1.46,532.46]],"ltp":1.46,"tv":532.46,"id":9631798},{"atl":[[1.46,16.47]],"id":9631798}],"con":true,"img":false}]}
{"op":"mcm","clk":"1349965388","pt":1588413997350,"mc":[{"id":"1.170370562","rc":[{"trd":[[3.15,100.33]],"ltp":3.15,"tv":100.33,"id":9625043},{"trd":[[1.46,542.03]],"ltp":1.46,"tv":542.03,"id":9631798},{"atl":[[1.46,6.91]],"id":9631798}],"con":true,"img":false}]}
{"op":"mcm","clk":"1349965391","pt":1588413997455,"mc":[{"id":"1.170370562","rc":[{"trd":[[3.15,103.53]],"ltp":3.15,"tv":103.53,"id":9625043},{"atl":[[3.15,2.76]],"id":9625043},{"trd":[[1.46,548.94]],"ltp":1.46,"tv":548.94,"id":9631798},{"atl":[[1.46,0]],"id":9631798}],"con":true,"img":false}]}
{"op":"mcm","clk":"1349965399","pt":1588413997609,"mc":[{"id":"1.170370562","rc":[{"atb":[[1.41,264.39]],"id":9631798}],"con":true,"img":false}]}
{"op":"mcm","clk":"1349965417","pt":1588413998438,"mc":[{"id":"1.170370562","rc":[{"trd":[[3.15,106.3]],"ltp":3.15,"tv":106.3,"id":9625043},{"atl":[[3.15,0]],"id":9625043},{"trd":[[1.46,554.91]],"ltp":1.46,"tv":554.91,"id":9631798},{"atl":[[1.43,669.77]],"id":9631798}],"con":true,"img":false}]}
{"op":"mcm","clk":"1349965422","pt":1588413998644,"mc":[{"id":"1.170370562","rc":[{"atb":[[1.37,0],[1.39,0],[1.41,24.39]],"id":9631798},{"atl":[[1.58,0]],"id":9631798}],"con":true,"img":false}]}
{"op":"mcm","clk":"1349965427","pt":1588413998952,"mc":[{"id":"1.170370562","rc":[{"atb":[[1.4,0]],"id":9631798}],"con":true,"img":false}]}
{"op":"mcm","clk":"1349965437","pt":1588413999260,"mc":[{"id":"1.170370562","rc":[{"trd":[[1.43,69.71]],"ltp":1.43,"tv":69.71,"id":9631798},{"atb":[[1.41,0]],"id":9631798},{"atl":[[1.43,668.06]],"id":9631798}],"con":true,"img":false}]}
{"op":"mcm","clk":"1349965456","pt":1588413999727,"mc":[{"id":"1.170370562","rc":[{"atl":[[1.44,248.76]],"id":9631798}],"con":true,"img":false}]}
{"op":"mcm","clk":"1349965470","pt":1588414000361,"mc":[{"id":"1.170370562","rc":[{"trd":[[1.43,122.13]],"ltp":1.43,"tv":122.13,"id":9631798},{"atl":[[1.43,641.85]],"id":9631798}],"con":true,"img":false}]}
{"op":"mcm","clk":"1349965478","pt":1588414000557,"mc":[{"id":"1.170370562","rc":[{"trd":[[1.43,842.13]],"ltp":1.43,"tv":842.13,"id":9631798},{"atl":[[1.43,281.85]],"id":9631798}],"con":true,"img":false}]}
{"op":"mcm","clk":"1349965491","pt":1588414001336,"mc":[{"id":"1.170370562","rc":[{"atl":[[1.53,0]],"id":9631798}],"con":true,"img":false}]}
{"op":"mcm","clk":"1349965499","pt":1588414001658,"mc":[{"id":"1.170370562","rc":[{"atl":[[1.43,0]],"id":9631798}],"con":true,"img":false}]}
{"op":"mcm","clk":"1349965526","pt":1588414002523,"mc":[{"id":"1.170370562","rc":[{"atl":[[1.47,48.75]],"id":9631798}],"con":true,"img":false}]}
{"op":"mcm","clk":"1349965531","pt":1588414002835,"mc":[{"id":"1.170370562","rc":[{"atl":[[1.46,248.76]],"id":9631798}],"con":true,"img":false}]}
{"op":"mcm","clk":"1349965552","pt":1588414003819,"mc":[{"id":"1.170370562","rc":[{"atl":[[1.41,309.17]],"id":9631798}],"con":true,"img":false}]}
{"op":"mcm","clk":"1349965574","pt":1588414004538,"mc":[{"id":"1.170370562","rc":[{"atl":[[1.47,314.71]],"id":9631798}],"con":true,"img":false}]}
{"op":"mcm","clk":"1349965582","pt":1588414004745,"mc":[{"id":"1.170370562","rc":[{"atl":[[1.45,240]],"id":9631798}],"con":true,"img":false}]}
{"op":"mcm","clk":"1349965587","pt":1588414005157,"mc":[{"id":"1.170370562","rc":[{"atl":[[1.48,240]],"id":9631798}],"con":true,"img":false}]}
{"op":"mcm","clk":"1349965591","pt":1588414005260,"mc":[{"id":"1.170370562","rc":[{"atb":[[1.38,312.59]],"id":9631798}],"con":true,"img":false}]}
{"op":"mcm","clk":"1349965612","pt":1588414006354,"mc":[{"id":"1.170370562","rc":[{"atb":[[1.36,27.77]],"id":9631798}],"con":true,"img":false}]}
{"op":"mcm","clk":"1349965621","pt":1588414006659,"mc":[{"id":"1.170370562","rc":[{"atb":[[1.4,159.97]],"id":9631798}],"con":true,"img":false}]}
{"op":"mcm","clk":"1349965624","pt":1588414006763,"mc":[{"id":"1.170370562","rc":[{"atb":[[1.39,248.76]],"id":9631798}],"con":true,"img":false}]}
{"op":"mcm","clk":"1349965641","pt":1588414007275,"mc":[{"id":"1.170370562","rc":[{"atl":[[1.41,1535.41]],"id":9631798}],"con":true,"img":false}]}
{"op":"mcm","clk":"1349965656","pt":1588414007844,"mc":[{"id":"1.170370562","rc":[{"atb":[[1.39,0]],"id":9631798}],"con":true,"img":false}]}
{"op":"mcm","clk":"1349965687","pt":1588414009041,"mc":[{"id":"1.170370562","rc":[{"atb":[[1.31,32.25]],"id":9631798}],"con":true,"img":false}]}
{"op":"mcm","clk":"1349965742","pt":1588414010751,"mc":[{"id":"1.170370562","rc":[{"trd":[[1.41,1864.54]],"ltp":1.41,"tv":1864.54,"id":9631798},{"atl":[[1.41,1286.65]],"id":9631798}],"con":true,"img":false}]}
{"op":"mcm","clk":"1349965750","pt":1588414011061,"mc":[{"id":"1.170370562","rc":[{"atb":[[1.36,0],[1.31,0]],"id":9631798}],"con":true,"img":false}]}
{"op":"mcm","clk":"1349965756","pt":1588414011267,"mc":[{"id":"1.170370562","rc":[{"atl":[[1.47,265.95]],"id":9631798}],"con":true,"img":false}]}
{"op":"mcm","clk":"1349965764","pt":1588414011574,"mc":[{"id":"1.170370562","rc":[{"atl":[[1.41,60.41]],"id":9631798}],"con":true,"img":false}]}
{"op":"mcm","clk":"1349965808","pt":1588414013282,"mc":[{"id":"1.170370562","rc":[{"atl":[[1.41,0]],"id":9631798}],"con":true,"img":false}]}
{"op":"mcm","clk":"1349965812","pt":1588414013338,"mc":[{"id":"1.170370562","rc":[{"trd":[[1.44,1600.4]],"ltp":1.44,"tv":1600.4,"id":9631798},{"atl":[[1.44,247.22]],"id":9631798}],"con":true,"img":false}]}
{"op":"mcm","clk":"1349965824","pt":1588414014274,"mc":[{"id":"1.170370562","rc":[{"trd":[[1.4,7916.16]],"ltp":1.4,"tv":7916.16,"id":9631798},{"atb":[[1.4,159.73]],"id":9631798}],"con":true,"img":false}]}
{"op":"mcm","clk":"1349965835","pt":1588414014643,"mc":[{"id":"1.170370562","rc":[{"trd":[[3.5,182.55]],"ltp":3.5,"tv":182.55,"id":9625043},{"atl":[[3.5,0]],"id":9625043},{"trd":[[1.4,8236.66]],"ltp":1.4,"tv":8236.66,"id":9631798},{"atb":[[1.4,0]],"id":9631798},{"atl":[[1.39,61.24]],"id":9631798}],"con":true,"img":false}]}
{"op":"mcm","clk":"1349965838","pt":1588414014955,"mc":[{"id":"1.170370562","rc":[{"trd":[[1.39,118.73]],"ltp":1.39,"tv":118.73,"id":9631798},{"atl":[[1.39,31.28]],"id":9631798}],"con":true,"img":false}]}
{"op":"mcm","clk":"1349965842","pt":1588414015060,"mc":[{"id":"1.170370562","rc":[{"atl":[[1.39,0]],"id":9631798}],"con":true,"img":false}]}
{"op":"mcm","clk":"1349965898","pt":1588414015266,"mc":[{"id":"1.170370562","rc":[{"atl":[[1.43,264.32]],"id":9631798}],"con":true,"img":false}]}
{"op":"mcm","clk":"1349965918","pt":1588414015938,"mc":[{"id":"1.170370562","rc":[{"atl":[[1.5,100.23]],"id":9631798}],"con":true,"img":false}]}
{"op":"mcm","clk":"1349965956","pt":1588414017081,"mc":[{"id":"1.170370562","rc":[{"atb":[[1.41,266.35]],"id":9631798}],"con":true,"img":false}]}
{"op":"mcm","clk":"1349965961","pt":1588414017242,"mc":[{"id":"1.170370562","rc":[{"atb":[[1.41,322.34]],"id":9631798}],"con":true,"img":false}]}
{"op":"mcm","clk":"1349965975","pt":1588414017768,"mc":[{"id":"1.170370562","rc":[{"atl":[[1.5,88.65]],"id":9631798}],"con":true,"img":false}]}
{"op":"mcm","clk":"1349965982","pt":1588414017869,"mc":[{"id":"1.170370562","rc":[{"atl":[[1.44,0]],"id":9631798}],"con":true,"img":false}]}
{"op":"mcm","clk":"1349966001","pt":1588414018382,"mc":[{"id":"1.170370562","rc":[{"atl":[[1000,2.6]],"id":9631798}],"con":true,"img":false}]}
{"op":"mcm","clk":"1349966010","pt":1588414018752,"mc":[{"id":"1.170370562","rc":[{"atl":[[1.46,0]],"id":9631798}],"con":true,"img":false}]}
{"op":"mcm","clk":"1349966014","pt":1588414018853,"mc":[{"id":"1.170370562","rc":[{"atb":[[1.41,325.19]],"id":9631798}],"con":true,"img":false}]}
{"op":"mcm","clk":"1349966025","pt":1588414019163,"mc":[{"id":"1.170370562","rc":[{"atl":[[3.4,0.1]],"id":9625043},{"atl":[[1.47,0],[1000,0.03]],"id":9631798}],"con":true,"img":false}]}
{"op":"mcm","clk":"1349966038","pt":1588414020100,"mc":[{"id":"1.170370562","rc":[{"atl":[[1.43,0],[1000,0]],"id":9631798}],"con":true,"img":false}]}
{"op":"mcm","clk":"1349966051","pt":1588414020672,"mc":[{"id":"1.170370562","rc":[{"atb":[[1.38,265.95]],"id":9631798}],"con":true,"img":false}]}
{"op":"mcm","clk":"1349966057","pt":1588414020878,"mc":[{"id":"1.170370562","rc":[{"atb":[[1.39,130.59]],"id":9631798}],"con":true,"img":false}]}
{"op":"mcm","clk":"1349966070","pt":1588414021351,"mc":[{"id":"1.170370562","rc":[{"atl":[[3.85,10]],"id":9625043}],"con":true,"img":false}]}
{"op":"mcm","clk":"1349966073","pt":1588414021457,"mc":[{"id":"1.170370562","rc":[{"atl":[[1.42,169.95]],"id":9631798}],"con":true,"img":false}]}
{"op":"mcm","clk":"1349966077","pt":1588414021564,"mc":[{"id":"1.170370562","rc":[{"atb":[[1.39,0]],"id":9631798},{"atl":[[1.45,0],[1.48,0]],"id":9631798}],"con":true,"img":false}]}
{"op":"mcm","clk":"1349966081","pt":1588414021663,"mc":[{"id":"1.170370562","rc":[{"atb":[[1.41,325.29]],"id":9631798}],"con":true,"img":false}]}
{"op":"mcm","clk":"1349966089","pt":1588414021984,"mc":[{"id":"1.170370562","rc":[{"trd":[[1.42,339.91]],"ltp":1.42,"tv":339.91,"id":9631798},{"atb":[[1.39,9.59],[1.41,574.05],[1.42,427.86]],"id":9631798},{"atl":[[1.42,0]],"id":9631798}],"con":true,"img":false}]}
{"op":"mcm","clk":"1349966100","pt":1588414022555,"mc":[{"id":"1.170370562","rc":[{"trd":[[1.42,410.65]],"ltp":1.42,"tv":410.65,"id":9631798},{"atb":[[1.42,392.49]],"id":9631798}],"con":true,"img":false}]}
{"op":"mcm","clk":"1349966105","pt":1588414022767,"mc":[{"id":"1.170370562","rc":[{"atb":[[1.44,83.09]],"id":9631798}],"con":true,"img":false}]}
{"op":"mcm","clk":"1349966106","pt":1588414022974,"mc":[{"id":"1.170370562","rc":[{"atb":[[1.43,126.94]],"id":9631798}],"con":true,"img":false}]}
{"op":"mcm","clk":"1349966113","pt":1588414023289,"mc":[{"id":"1.170370562","rc":[{"atl":[[3.4,0]],"id":9625043}],"con":true,"img":false}]}
{"op":"mcm","clk":"1349966117","pt":1588414023654,"mc":[{"id":"1.170370562","rc":[{"atl":[[3.4,5.49]],"id":9625043}],"con":true,"img":false}]}
{"op":"mcm","clk":"1349966123","pt":1588414024070,"mc":[{"id":"1.170370562","rc":[{"atb":[[1.38,0]],"id":9631798}],"con":true,"img":false}]}
{"op":"mcm","clk":"1349966126","pt":1588414024173,"mc":[{"id":"1.170370562","rc":[{"atb":[[1.41,575.82]],"id":9631798}],"con":true,"img":false}]}
{"op":"mcm","clk":"1349966133","pt":1588414024584,"mc":[{"id":"1.170370562","rc":[{"atb":[[1.4,159.97]],"id":9631798}],"con":true,"img":false}]}
{"op":"mcm","clk":"1349966134","pt":1588414024691,"mc":[{"id":"1.170370562","rc":[{"atb":[[1.34,0]],"id":9631798}],"con":true,"img":false}]}
{"op":"mcm","clk":"1349966137","pt":1588414024896,"mc":[{"id":"1.170370562","rc":[{"atl":[[1.51,265.95]],"id":9631798}],"con":true,"img":false}]}
{"op":"mcm","clk":"1349966140","pt":1588414024952,"mc":[{"id":"1.170370562","rc":[{"atl":[[3.4,0]],"id":9625043}],"con":true,"img":false}]}
{"op":"mcm","clk":"1349966145","pt":1588414025165,"mc":[{"id":"1.170370562","rc":[{"trd":[[1.44,1600.46]],"ltp":1.44,"tv":1600.46,"id":9631798},{"atb":[[1.44,83.06]],"id":9631798}],"con":true,"img":false}]}
{"op":"mcm","clk":"1349966157","pt":1588414025677,"mc":[{"id":"1.170370562","rc":[{"atl":[[3.6,10]],"id":9625043}],"con":true,"img":false}]}
{"op":"mcm","clk":"1349966162","pt":1588414025781,"mc":[{"id":"1.170370562","rc":[{"atb":[[1.41,519.83]],"id":9631798}],"con":true,"img":false}]}
{"op":"mcm","clk":"1349966165","pt":1588414025882,"mc":[{"id":"1.170370562","rc":[{"trd":[[1.44,1756.49]],"ltp":1.44,"tv":1756.49,"id":9631798},{"atb":[[1.44,5.04]],"id":9631798}],"con":true,"img":false}]}
{"op":"mcm","clk":"1349966177","pt":1588414026297,"mc":[{"id":"1.170370562","rc":[{"atb":[[1.44,53.57],[1.35,408.73]],"id":9631798}],"con":true,"img":false}]}
{"op":"mcm","clk":"1349966189","pt":1588414026558,"mc":[{"id":"1.170370562","rc":[{"atb":[[1.34,248.76]],"id":9631798}],"con":true,"img":false}]}
{"op":"mcm","clk":"1349966204","pt":1588414027186,"mc":[{"id":"1.170370562","rc":[{"trd":[[1.43,862.39],[1.44,1863.63]],"ltp":1.43,"tv":2726.02,"id":9631798},{"atb":[[1.44,0],[1.43,116.81]],"id":9631798}],"con":true,"img":false}]}
{"op":"mcm","clk":"1349966217","pt":1588414027865,"mc":[{"id":"1.170370562","rc":[{"trd":[[1.43,932.64]],"ltp":1.43,"tv":932.64,"id":9631798},{"atb":[[1.43,81.69]],"id":9631798}],"con":true,"img":false}]}
{"op":"mcm","clk":"1349966226","pt":1588414028177,"mc":[{"id":"1.170370562","rc":[{"atl":[[3.6,0]],"id":9625043},{"atb":[[1.42,658.44]],"id":9631798}],"con":true,"img":false}]}
{"op":"mcm","clk":"1349966238","pt":1588414028590,"mc":[{"id":"1.170370562","rc":[{"atl":[[2.1,0]],"id":9631798}],"con":true,"img":false}]}
{"op":"mcm","clk":"1349966242","pt":1588414028897,"mc":[{"id":"1.170370562","rc":[{"atb":[[1.41,519.73]],"id":9631798}],"con":true,"img":false}]}
{"op":"mcm","clk":"1349966243","pt":1588414028952,"mc":[{"id":"1.170370562","rc":[{"atl":[[1.47,248.76]],"id":9631798}],"con":true,"img":false}]}
{"op":"mcm","clk":"1349966247","pt":1588414029055,"mc":[{"id":"1.170370562","rc":[{"atb":[[1.45,159.97]],"id":9631798},{"atl":[[1.53,240]],"id":9631798}],"con":true,"img":false}]}
{"op":"mcm","clk":"1349966249","pt":1588414029160,"mc":[{"id":"1.170370562","rc":[{"atb":[[1.36,265.95]],"id":9631798}],"con":true,"img":false}]}
{"op":"mcm","clk":"1349966257","pt":1588414029468,"mc":[{"id":"1.170370562","rc":[{"atb":[[1.44,159.97]],"id":9631798}],"con":true,"img":false}]}
{"op":"mcm","clk":"1349966260","pt":1588414029571,"mc":[{"id":"1.170370562","rc":[{"atb":[[1.41,253.37]],"id":9631798},{"atl":[[1.57,240]],"id":9631798}],"con":true,"img":false}]}
{"op":"mcm","clk":"1349966274","pt":1588414030292,"mc":[{"id":"1.170370562","rc":[{"atb":[[1.45,194.43]],"id":9631798}],"con":true,"img":false}]}
{"op":"mcm","clk":"1349966286","pt":1588414030864,"mc":[{"id":"1.170370562","rc":[{"trd":[[1.47,160.02]],"ltp":1.47,"tv":160.02,"id":9631798},{"atl":[[1.47,192.76]],"id":9631798}],"con":true,"img":false}]}
{"op":"mcm","clk":"1349966291","pt":1588414031171,"mc":[{"id":"1.170370562","rc":[{"atb":[[1.43,0]],"id":9631798}],"con":true,"img":false}]}
{"op":"mcm","clk":"1349966294","pt":1588414031273,"mc":[{"id":"1.170370562","rc":[{"atl":[[3.35,10]],"id":9625043}],"con":true,"img":false}]}
{"op":"mcm","clk":"1349966295","pt":1588414031377,"mc":[{"id":"1.170370562","rc":[{"atl":[[1.51,0]],"id":9631798}],"con":true,"img":false}]}
{"op":"mcm","clk":"1349966297","pt":1588414031481,"mc":[{"id":"1.170370562","rc":[{"atb":[[1.44,0]],"id":9631798}],"con":true,"img":false}]}
{"op":"mcm","clk":"1349966309","pt":1588414032054,"mc":[{"id":"1.170370562","rc":[{"atl":[[1.5,328.65]],"id":9631798}],"con":true,"img":false}]}
{"op":"mcm","clk":"1349966315","pt":1588414032364,"mc":[{"id":"1.170370562","rc":[{"trd":[[1.47,161.67]],"ltp":1.47,"tv":161.67,"id":9631798},{"atl":[[1.56,265.95],[1.47,191.94]],"id":9631798}],"con":true,"img":false}]}
{"op":"mcm","clk":"1349966347","pt":1588414033606,"mc":[{"id":"1.170370562","rc":[{"atl":[[3.25,56.79]],"id":9625043}],"con":true,"img":false}]}
{"op":"mcm","clk":"1349966352","pt":1588414033663,"mc":[{"id":"1.170370562","rc":[{"trd":[[3.1,8.26]],"ltp":3.1,"tv":8.26,"id":9625043},{"trd":[[1.47,174.76]],"ltp":1.47,"tv":174.76,"id":9631798},{"atl":[[1.47,178.85]],"id":9631798}],"con":true,"img":false}]}
{"op":"mcm","clk":"1349966355","pt":1588414033770,"mc":[{"id":"1.170370562","rc":[{"atl":[[3.2,177.3]],"id":9625043},{"atl":[[1.49,270.38]],"id":9631798}],"con":true,"img":false}]}
{"op":"mcm","clk":"1349966380","pt":1588414034593,"mc":[{"id":"1.170370562","rc":[{"atb":[[1.41,250.53]],"id":9631798}],"con":true,"img":false}]}
{"op":"mcm","clk":"1349966382","pt":1588414034695,"mc":[{"id":"1.170370562","rc":[{"atb":[[1.43,266.35]],"id":9631798}],"con":true,"img":false}]}
{"op":"mcm","clk":"1349966388","pt":1588414035005,"mc":[{"id":"1.170370562","rc":[{"atl":[[1.49,0]],"id":9631798}],"con":true,"img":false}]}
{"op":"mcm","clk":"1349966397","pt":1588414035472,"mc":[{"id":"1.170370562","rc":[{"atb":[[1.45,34.46]],"id":9631798}],"con":true,"img":false}]}
{"op":"mcm","clk":"1349966403","pt":1588414035782,"mc":[{"id":"1.170370562","rc":[{"trd":[[3.1,8.44]],"ltp":3.1,"tv":8.44,"id":9625043},{"trd":[[1.47,175.15]],"ltp":1.47,"tv":175.15,"id":9631798},{"atl":[[1.47,178.46]],"id":9631798}],"con":true,"img":false}]}
{"op":"mcm","clk":"1349966409","pt":1588414036092,"mc":[{"id":"1.170370562","rc":[{"trd":[[1.5,1143.56],[1.47,532.08]],"ltp":1.5,"tv":1675.63,"id":9631798},{"atl":[[1.5,72.98],[1.47,0]],"id":9631798}],"con":true,"img":false}]}
{"op":"mcm","clk":"1349966415","pt":1588414036403,"mc":[{"id":"1.170370562","rc":[{"trd":[[1.5,1148.88]],"ltp":1.5,"tv":1148.88,"id":9631798},{"atb":[[1.46,80.01]],"id":9631798},{"atl":[[1.5,70.32]],"id":9631798}],"con":true,"img":false}]}
{"op":"mcm","clk":"1349966422","pt":1588414036769,"mc":[{"id":"1.170370562","rc":[{"atl":[[3.25,0]],"id":9625043}],"con":true,"img":false}]}
{"op":"mcm","clk":"1349966452","pt":1588414038570,"mc":[{"id":"1.170370562","rc":[{"atl":[[1.57,0],[1.5,0],[1.53,0]],"id":9631798}],"con":true,"img":false}]}
{"op":"mcm","clk":"1349966455","pt":1588414038773,"mc":[{"id":"1.170370562","rc":[{"atb":[[1.45,37.03]],"id":9631798}],"con":true,"img":false}]}
{"op":"mcm","clk":"1349966470","pt":1588414039494,"mc":[{"id":"1.170370562","rc":[{"atb":[[1.42,392.49]],"id":9631798}],"con":true,"img":false}]}
{"op":"mcm","clk":"1349966500","pt":1588414040482,"mc":[{"id":"1.170370562","rc":[{"atl":[[3.1,0.1]],"id":9625043}],"con":true,"img":false}]}
{"op":"mcm","clk":"1349966502","pt":1588414040791,"mc":[{"id":"1.170370562","rc":[{"atb":[[1.47,1000]],"id":9631798}],"con":true,"img":false}]}
{"op":"mcm","clk":"1349966508","pt":1588414041099,"mc":[{"id":"1.170370562","rc":[{"trd":[[1.47,549.82]],"ltp":1.47,"tv":549.82,"id":9631798},{"atb":[[1.47,991.13]],"id":9631798}],"con":true,"img":false}]}
{"op":"mcm","clk":"1349966519","pt":1588414041512,"mc":[{"id":"1.170370562","rc":[{"atl":[[3.85,0]],"id":9625043}],"con":true,"img":false}]}
{"op":"mcm","clk":"1349966522","pt":1588414041773,"mc":[{"id":"1.170370562","rc":[{"atb":[[1.48,248.76]],"id":9631798}],"con":true,"img":false}]}
{"op":"mcm","clk":"1349966523","pt":1588414041877,"mc":[{"id":"1.170370562","rc":[{"atb":[[1.48,740.78]],"id":9631798}],"con":true,"img":false}]}
{"op":"mcm","clk":"1349966558","pt":1588414043325,"mc":[{"id":"1.170370562","rc":[{"atl":[[3.1,0]],"id":9625043},{"atb":[[1.5,222]],"id":9631798}],"con":true,"img":false}]}
{"op":"mcm","clk":"1349966561","pt":1588414043381,"mc":[{"id":"1.170370562","rc":[{"atl":[[3,111.18]],"id":9625043},{"atb":[[1.42,0]],"id":9631798}],"con":true,"img":false}]}
{"op":"mcm","clk":"1349966565","pt":1588414043690,"mc":[{"id":"1.170370562","rc":[{"atb":[[1.49,159.97]],"id":9631798}],"con":true,"img":false}]}
{"op":"mcm","clk":"1349966570","pt":1588414044000,"mc":[{"id":"1.170370562","rc":[{"atb":[[1.5,381.97]],"id":9631798}],"con":true,"img":false}]}
{"op":"mcm","clk":"1349966582","pt":1588414044414,"mc":[{"id":"1.170370562","rc":[{"atb":[[1.47,0]],"id":9631798}],"con":true,"img":false}]}
{"op":"mcm","clk":"1349966584","pt":1588414044618,"mc":[{"id":"1.170370562","rc":[{"atl":[[3.15,10]],"id":9625043}],"con":true,"img":false}]}
{"op":"mcm","clk":"1349966588","pt":1588414044778,"mc":[{"id":"1.170370562","rc":[{"atb":[[1.51,168.56]],"id":9631798}],"con":true,"img":false}]}
{"op":"mcm","clk":"1349966590","pt":1588414044881,"mc":[{"id":"1.170370562","rc":[{"trd":[[1.51,59.64]],"ltp":1.51,"tv":59.64,"id":9631798},{"atb":[[1.51,138.74]],"id":9631798}],"con":true,"img":false}]}
{"op":"mcm","clk":"1349966594","pt":1588414044984,"mc":[{"id":"1.170370562","rc":[{"atb":[[1.48,248.76]],"id":9631798}],"con":true,"img":false}]}
{"op":"mcm","clk":"1349966598","pt":1588414045089,"mc":[{"id":"1.170370562","rc":[{"atb":[[1.47,265.95]],"id":9631798}],"con":true,"img":false}]}
{"op":"mcm","clk":"1349966602","pt":1588414045192,"mc":[{"id":"1.170370562","rc":[{"atl":[[3,0]],"id":9625043}],"con":true,"img":false}]}
{"op":"mcm","clk":"1349966612","pt":1588414045503,"mc":[{"id":"1.170370562","rc":[{"atb":[[1.49,0],[1.51,378.74]],"id":9631798}],"con":true,"img":false}]}
{"op":"mcm","clk":"1349966631","pt":1588414046481,"mc":[{"id":"1.170370562","rc":[{"atl":[[3.25,8.79]],"id":9625043}],"con":true,"img":false}]}
{"op":"mcm","clk":"1349966634","pt":1588414046893,"mc":[{"id":"1.170370562","rc":[{"atb":[[1.4,0]],"id":9631798}],"con":true,"img":false}]}
{"op":"mcm","clk":"1349966638","pt":1588414047099,"mc":[{"id":"1.170370562","rc":[{"atb":[[1.46,0],[1.5,159.97]],"id":9631798}],"con":true,"img":false}]}
{"op":"mcm","clk":"1349966642","pt":1588414047201,"mc":[{"id":"1.170370562","rc":[{"atl":[[3.1,2.3]],"id":9625043}],"con":true,"img":false}]}
{"op":"mcm","clk":"1349966652","pt":1588414047610,"mc":[{"id":"1.170370562","rc":[{"atl":[[3.1,12.3]],"id":9625043}],"con":true,"img":false}]}
{"op":"mcm","clk":"1349966657","pt":1588414047816,"mc":[{"id":"1.170370562","rc":[{"atb":[[1.43,0]],"id":9631798}],"con":true,"img":false}]}
{"op":"mcm","clk":"1349966665","pt":1588414048283,"mc":[{"id":"1.170370562","rc":[{"atl":[[3.05,10]],"id":9625043}],"con":true,"img":false}]}
{"op":"mcm","clk":"1349966669","pt":1588414048492,"mc":[{"id":"1.170370562","rc":[{"atl":[[2.88,56.79]],"id":9625043}],"con":true,"img":false}]}
{"op":"mcm","clk":"1349966674","pt":1588414048597,"mc":[{"id":"1.170370562","rc":[{"atb":[[1.47,0]],"id":9631798}],"con":true,"img":false}]}
{"op":"mcm","clk":"1349966676","pt":1588414048700,"mc":[{"id":"1.170370562","rc":[{"atb":[[1.5,433.19]],"id":9631798}],"con":true,"img":false}]}
{"op":"mcm","clk":"1349966682","pt":1588414048805,"mc":[{"id":"1.170370562","rc":[{"atb":[[1.54,27.56]],"id":9631798}],"con":true,"img":false}]}
{"op":"mcm","clk":"1349966692","pt":1588414049631,"mc":[{"id":"1.170370562","rc":[{"atb":[[1.36,0]],"id":9631798}],"con":true,"img":false}]}
{"op":"mcm","clk":"1349966696","pt":1588414049688,"mc":[{"id":"1.170370562","rc":[{"atb":[[1.51,538.71]],"id":9631798}],"con":true,"img":false}]}
{"op":"mcm","clk":"1349966727","pt":1588414050824,"mc":[{"id":"1.170370562","rc":[{"atl":[[1.65,265.95]],"id":9631798}],"con":true,"img":false}]}
{"op":"mcm","clk":"1349966732","pt":1588414051237,"mc":[{"id":"1.170370562","rc":[{"atl":[[3.1,46.3]],"id":9625043},{"atl":[[1.56,0]],"id":9631798}],"con":true,"img":false}]}
{"op":"mcm","clk":"1349966736","pt":1588414051391,"mc":[{"id":"1.170370562","rc":[{"atl":[[2.78,40.78]],"id":9625043}],"con":true,"img":false}]}
{"op":"mcm","clk":"1349966749","pt":1588414052013,"mc":[{"id":"1.170370562","rc":[{"atl":[[3.1,36.3],[3.35,0],[3.15,0],[3.05,0]],"id":9625043}],"con":true,"img":false}]}
{"op":"mcm","clk":"1349966756","pt":1588414052216,"mc":[{"id":"1.170370562","rc":[{"atl":[[2.88,0]],"id":9625043},{"atl":[[1.58,240]],"id":9631798}],"con":true,"img":false}]}
{"op":"mcm","clk":"1349966760","pt":1588414052320,"mc":[{"id":"1.170370562","rc":[{"atb":[[1.53,76.35]],"id":9631798}],"con":true,"img":false}]}
{"op":"mcm","clk":"1349966765","pt":1588414052633,"mc":[{"id":"1.170370562","rc":[{"atb":[[1.53,0]],"id":9631798}],"con":true,"img":false}]}
{"op":"mcm","clk":"1349966766","pt":1588414052736,"mc":[{"id":"1.170370562","rc":[{"atl":[[1.58,0]],"id":9631798}],"con":true,"img":false}]}
{"op":"mcm","clk":"1349966770","pt":1588414052942,"mc":[{"id":"1.170370562","rc":[{"atl":[[3.2,0]],"id":9625043},{"atb":[[1.46,265.95],[1.53,266.35]],"id":9631798},{"atl":[[1.62,240]],"id":9631798}],"con":true,"img":false}]}
{"op":"mcm","clk":"1349966777","pt":1588414053211,"mc":[{"id":"1.170370562","rc":[{"atb":[[1.56,3]],"id":9631798}],"con":true,"img":false}]}
{"op":"mcm","clk":"1349966784","pt":1588414053519,"mc":[{"id":"1.170370562","rc":[{"atb":[[1.45,2.57],[1.51,1538.71]],"id":9631798}],"con":true,"img":false}]}
{"op":"mcm","clk":"1349966791","pt":1588414053831,"mc":[{"id":"1.170370562","rc":[{"atl":[[2.78,0]],"id":9625043},{"atb":[[1.5,159.97]],"id":9631798}],"con":true,"img":false}]}
{"op":"mcm","clk":"1349966794","pt":1588414053933,"mc":[{"id":"1.170370562","rc":[{"atb":[[1.52,1000],[1.54,0]],"id":9631798}],"con":true,"img":false}]}
{"op":"mcm","clk":"1349966805","pt":1588414054506,"mc":[{"id":"1.170370562","rc":[{"atl":[[3.1,2.3]],"id":9625043}],"con":true,"img":false}]}
{"op":"mcm","clk":"1349966816","pt":1588414055023,"mc":[{"id":"1.170370562","rc":[{"trd":[[1.59,2.23]],"ltp":1.59,"tv":2.23,"id":9631798},{"atl":[[1.59,247.64]],"id":9631798}],"con":true,"img":false}]}
{"op":"mcm","clk":"1349966823","pt":1588414055437,"mc":[{"id":"1.170370562","rc":[{"atb":[[1.55,159.97]],"id":9631798}],"con":true,"img":false}]}
{"op":"mcm","clk":"1349966832","pt":1588414055799,"mc":[{"id":"1.170370562","rc":[{"atb":[[1.54,240]],"id":9631798}],"con":true,"img":false}]}
{"op":"mcm","clk":"1349966835","pt":1588414055906,"mc":[{"id":"1.170370562","rc":[{"atl":[[2.96,10]],"id":9625043},{"atb":[[1.52,1485.88]],"id":9631798}],"con":true,"img":false}]}
{"op":"mcm","clk":"1349966839","pt":1588414056005,"mc":[{"id":"1.170370562","rc":[{"atb":[[1.54,399.97]],"id":9631798}],"con":true,"img":false}]}
{"op":"mcm","clk":"1349966845","pt":1588414056214,"mc":[{"id":"1.170370562","rc":[{"atb":[[1.53,506.35]],"id":9631798}],"con":true,"img":false}]}
{"op":"mcm","clk":"1349966850","pt":1588414056320,"mc":[{"id":"1.170370562","rc":[{"atb":[[1.56,77.88]],"id":9631798}],"con":true,"img":false}]}
{"op":"mcm","clk":"1349966867","pt":1588414057039,"mc":[{"id":"1.170370562","rc":[{"atb":[[1.54,665.93]],"id":9631798}],"con":true,"img":false}]}
{"op":"mcm","clk":"1349966874","pt":1588414057408,"mc":[{"id":"1.170370562","rc":[{"atb":[[1.52,485.88],[1.51,538.71]],"id":9631798}],"con":true,"img":false}]}
{"op":"mcm","clk":"1349966879","pt":1588414057822,"mc":[{"id":"1.170370562","rc":[{"atb":[[1.51,378.74]],"id":9631798}],"con":true,"img":false}]}
{"op":"mcm","clk":"1349966882","pt":1588414058024,"mc":[{"id":"1.170370562","rc":[{"atb":[[1.47,0.47]],"id":9631798}],"con":true,"img":false}]}
{"op":"mcm","clk":"1349966886","pt":1588414058129,"mc":[{"id":"1.170370562","rc":[{"atb":[[1.5,0]],"id":9631798}],"con":true,"img":false}]}
{"op":"mcm","clk":"1349966890","pt":1588414058437,"mc":[{"id":"1.170370562","rc":[{"atb":[[1.51,381.04]],"id":9631798}],"con":true,"img":false}]}
{"op":"mcm","clk":"1349966894","pt":1588414058850,"mc":[{"id":"1.170370562","rc":[{"atb":[[1.53,240]],"id":9631798}],"con":true,"img":false}]}
{"op":"mcm","clk":"1349966896","pt":1588414058907,"mc":[{"id":"1.170370562","rc":[{"atb":[[1.58,273.21]],"id":9631798}],"con":true,"img":false}]}
{"op":"mcm","clk":"1349966902","pt":1588414059525,"mc":[{"id":"1.170370562","rc":[{"atb":[[1.58,347.15]],"id":9631798}],"con":true,"img":false}]}
{"op":"mcm","clk":"1349966917","pt":1588414060350,"mc":[{"id":"1.170370562","rc":[{"atb":[[1.54,905.93]],"id":9631798}],"con":true,"img":false}]}
{"op":"mcm","clk":"1349966921","pt":1588414060615,"mc":[{"id":"1.170370562","rc":[{"trd":[[1.59,26.23]],"ltp":1.59,"tv":26.23,"id":9631798},{"atl":[[1.59,235.64],[1.62,0]],"id":9631798}],"con":true,"img":false}]}
{"op":"mcm","clk":"1349966925","pt":1588414060716,"mc":[{"id":"1.170370562","rc":[{"atl":[[2.86,10]],"id":9625043}],"con":true,"img":false}]}
{"op":"mcm","clk":"1349966926","pt":1588414060819,"mc":[{"id":"1.170370562","rc":[{"atb":[[1.56,3]],"id":9631798}],"con":true,"img":false}]}
{"op":"mcm","clk":"1349966952","pt":1588414061850,"mc":[{"id":"1.170370562","rc":[{"atb":[[1.56,162.97]],"id":9631798}],"con":true,"img":false}]}
{"op":"mcm","clk":"1349966960","pt":1588414062114,"mc":[{"id":"1.170370562","rc":[{"atb":[[1.47,0]],"id":9631798}],"con":true,"img":false}]}
{"op":"mcm","clk":"1349966966","pt":1588414062214,"mc":[{"id":"1.170370562","rc":[{"atl":[[2.8,10]],"id":9625043}],"con":true,"img":false}]}
{"op":"mcm","clk":"1349966977","pt":1588414062632,"mc":[{"id":"1.170370562","rc":[{"trd":[[1.58,44.8]],"ltp":1.58,"tv":44.8,"id":9631798},{"atb":[[1.58,346.92]],"id":9631798}],"con":true,"img":false}]}
{"op":"mcm","clk":"1349966985","pt":1588414063041,"mc":[{"id":"1.170370562","rc":[{"atl":[[2.78,10]],"id":9625043}],"con":true,"img":false}]}
{"op":"mcm","clk":"1349967043","pt":1588414065635,"mc":[{"id":"1.170370562","rc":[{"trd":[[2.68,71.98]],"ltp":2.68,"tv":71.98,"id":9625043},{"trd":[[1.59,147.57]],"ltp":1.59,"tv":147.57,"id":9631798},{"atl":[[1.59,114.3]],"id":9631798}],"con":true,"img":false}]}
{"op":"mcm","clk":"1349967045","pt":1588414065940,"mc":[{"id":"1.170370562","rc":[{"trd":[[2.68,113.65]],"ltp":2.68,"tv":113.65,"id":9625043},{"trd":[[1.59,217.8]],"ltp":1.59,"tv":217.8,"id":9631798},{"atl":[[1.59,44.07]],"id":9631798}],"con":true,"img":false}]}
{"op":"mcm","clk":"1349967055","pt":1588414066561,"mc":[{"id":"1.170370562","rc":[{"atl":[[2.8,0],[2.86,0],[2.78,0],[2.96,0]],"id":9625043}],"con":true,"img":false}]}
{"op":"mcm","clk":"1349967063","pt":1588414066928,"mc":[{"id":"1.170370562","rc":[{"trd":[[1.59,233.67]],"ltp":1.59,"tv":233.67,"id":9631798},{"atl":[[1.59,36.13]],"id":9631798}],"con":true,"img":false}]}
{"op":"mcm","clk":"1349967094","pt":1588414068430,"mc":[{"id":"1.170370562","rc":[{"trd":[[1.59,305.94]],"ltp":1.59,"tv":305.94,"id":9631798},{"atb":[[1.59,230.21]],"id":9631798},{"atl":[[1.59,0]],"id":9631798}],"con":true,"img":false}]}
{"op":"mcm","clk":"1349967101","pt":1588414068740,"mc":[{"id":"1.170370562","rc":[{"atb":[[1.58,73.94]],"id":9631798}],"con":true,"img":false}]}
{"op":"mcm","clk":"1349967113","pt":1588414069355,"mc":[{"id":"1.170370562","rc":[{"atb":[[1.57,133.43],[1.54,639.97]],"id":9631798}],"con":true,"img":false}]}
{"op":"mcm","clk":"1349967123","pt":1588414069723,"mc":[{"id":"1.170370562","rc":[{"atl":[[3.25,0]],"id":9625043}],"con":true,"img":false}]}
{"op":"mcm","clk":"1349967127","pt":1588414069824,"mc":[{"id":"1.170370562","rc":[{"atb":[[1.58,0]],"id":9631798}],"con":true,"img":false}]}
{"op":"mcm","clk":"1349967133","pt":1588414070442,"mc":[{"id":"1.170370562","rc":[{"atb":[[1.54,480]],"id":9631798}],"con":true,"img":false}]}
{"op":"mcm","clk":"1349967148","pt":1588414070957,"mc":[{"id":"1.170370562","rc":[{"trd":[[1.59,319.85]],"ltp":1.59,"tv":319.85,"id":9631798},{"atb":[[1.59,223.26],[1.55,0]],"id":9631798}],"con":true,"img":false}]}
{"op":"mcm","clk":"1349967173","pt":1588414071835,"mc":[{"id":"1.170370562","rc":[{"trd":[[1.59,766.39]],"ltp":1.59,"tv":766.39,"id":9631798},{"atb":[[1.59,0]],"id":9631798},{"atl":[[1.58,39.96]],"id":9631798}],"con":true,"img":false}]}
{"op":"mcm","clk":"1349967176","pt":1588414072041,"mc":[{"id":"1.170370562","rc":[{"atb":[[1.35,248.76]],"id":9631798}],"con":true,"img":false}]}
{"op":"mcm","clk":"1349967185","pt":1588414072554,"mc":[{"id":"1.170370562","rc":[{"atl":[[1.58,0]],"id":9631798}],"con":true,"img":false}]}
{"op":"mcm","clk":"1349967200","pt":1588414073273,"mc":[{"id":"1.170370562","rc":[{"atb":[[1.54,0]],"id":9631798}],"con":true,"img":false}]}
{"op":"mcm","clk":"1349967209","pt":1588414073636,"mc":[{"id":"1.170370562","rc":[{"atb":[[1.3,0]],"id":9631798}],"con":true,"img":false}]}
{"op":"mcm","clk":"1349967218","pt":1588414073841,"mc":[{"id":"1.170370562","rc":[{"atb":[[1.61,272.98]],"id":9631798}],"con":true,"img":false}]}
{"op":"mcm","clk":"1349967237","pt":1588414074766,"mc":[{"id":"1.170370562","rc":[{"atb":[[1.5,0.11]],"id":9631798}],"con":true,"img":false}]}
{"op":"mcm","clk":"1349967281","pt":1588414076470,"mc":[{"id":"1.170370562","rc":[{"atb":[[2.6,6.25]],"id":9625043}],"con":true,"img":false}]}
{"op":"mcm","clk":"1349967292","pt":1588414076733,"mc":[{"id":"1.170370562","rc":[{"atb":[[1.01,1089.9]],"id":9631798}],"con":true,"img":false}]}
{"op":"mcm","clk":"1349967302","pt":1588414076938,"mc":[{"id":"1.170370562","rc":[{"atb":[[1.01,1088.62]],"id":9631798}],"con":true,"img":false}]}
{"op":"mcm","clk":"1349967308","pt":1588414077248,"mc":[{"id":"1.170370562","rc":[{"atb":[[1.01,1088.13]],"id":9631798}],"con":true,"img":false}]}
{"op":"mcm","clk":"1349967313","pt":1588414077449,"mc":[{"id":"1.170370562","rc":[{"atb":[[2.54,6.49]],"id":9625043}],"con":true,"img":false}]}
{"op":"mcm","clk":"1349967327","pt":1588414078170,"mc":[{"id":"1.170370562","rc":[{"atb":[[1.58,248.76]],"id":9631798}],"con":true,"img":false}]}
{"op":"mcm","clk":"1349967338","pt":1588414078845,"mc":[{"id":"1.170370562","rc":[{"atb":[[1.59,5.23]],"id":9631798}],"con":true,"img":false}]}
{"op":"mcm","clk":"1349967350","pt":1588414079588,"mc":[{"id":"1.170370562","rc":[{"atl":[[1.65,0]],"id":9631798}],"con":true,"img":false}]}
{"op":"mcm","clk":"1349967354","pt":1588414079979,"mc":[{"id":"1.170370562","rc":[{"trd":[[1.61,2019.27]],"ltp":1.61,"tv":2019.27,"id":9631798},{"atb":[[1.61,0]],"id":9631798},{"atl":[[1.6,727.02]],"id":9631798}],"con":true,"img":false}]}
{"op":"mcm","clk":"1349967359","pt":1588414080343,"mc":[{"id":"1.170370562","rc":[{"atb":[[1.59,0]],"id":9631798}],"con":true,"img":false}]}
{"op":"mcm","clk":"1349967362","pt":1588414080445,"mc":[{"id":"1.170370562","rc":[{"atl":[[1.6,0]],"id":9631798}],"con":true,"img":false}]}
{"op":"mcm","clk":"1349967381","pt":1588414081268,"mc":[{"id":"1.170370562","rc":[{"atl":[[1.6,492.02]],"id":9631798}],"con":true,"img":false}]}
{"op":"mcm","clk":"1349967388","pt":1588414081475,"mc":[{"id":"1.170370562","rc":[{"atl":[[1.61,248.76]],"id":9631798}],"con":true,"img":false}]}
{"op":"mcm","clk":"1349967400","pt":1588414082159,"mc":[{"id":"1.170370562","rc":[{"atl":[[1.61,0]],"id":9631798}],"con":true,"img":false}]}
{"op":"mcm","clk":"1349967401","pt":1588414082364,"mc":[{"id":"1.170370562","rc":[{"atl":[[1.6,491.53]],"id":9631798}],"con":true,"img":false}]}
{"op":"mcm","clk":"1349967408","pt":1588414082780,"mc":[{"id":"1.170370562","rc":[{"atb":[[2.64,22.16]],"id":9625043}],"con":true,"img":false}]}
{"op":"mcm","clk":"1349967414","pt":1588414082884,"mc":[{"id":"1.170370562","rc":[{"atb":[[1.56,3]],"id":9631798}],"con":true,"img":false}]}
{"op":"mcm","clk":"1349967424","pt":1588414083046,"mc":[{"id":"1.170370562","rc":[{"atb":[[1.53,0],[1.51,2.3],[1.57,0],[1.55,265.95]],"id":9631798}],"con":true,"img":false}]}
{"op":"mcm","clk":"1349967454","pt":1588414084287,"mc":[{"id":"1.170370562","rc":[{"atb":[[1.54,295.21]],"id":9631798}],"con":true,"img":false}]}
{"op":"mcm","clk":"1349967457","pt":1588414084343,"mc":[{"id":"1.170370562","rc":[{"atl":[[1.6,0]],"id":9631798}],"con":true,"img":false}]}
{"op":"mcm","clk":"1349967464","pt":1588414084658,"mc":[{"id":"1.170370562","rc":[{"atl":[[1.7,265.95]],"id":9631798}],"con":true,"img":false}]}
{"op":"mcm","clk":"1349967481","pt":1588414086049,"mc":[{"id":"1.170370562","rc":[{"atl":[[1.64,39.68]],"id":9631798}],"con":true,"img":false}]}
{"op":"mcm","clk":"1349967488","pt":1588414086457,"mc":[{"id":"1.170370562","rc":[{"atb":[[1.59,238.11]],"id":9631798}],"con":true,"img":false}]}
{"op":"mcm","clk":"1349967489","pt":1588414086559,"mc":[{"id":"1.170370562","rc":[{"atl":[[1.61,87.58]],"id":9631798}],"con":true,"img":false}]}
{"op":"mcm","clk":"1349967511","pt":1588414087542,"mc":[{"id":"1.170370562","rc":[{"trd":[[1.59,1210.39]],"ltp":1.59,"tv":1210.39,"id":9631798},{"atb":[[1.59,16.11]],"id":9631798}],"con":true,"img":false}]}
{"op":"mcm","clk":"1349967513","pt":1588414087647,"mc":[{"id":"1.170370562","rc":[{"atb":[[1.01,1089.9]],"id":9631798}],"con":true,"img":false}]}
{"op":"mcm","clk":"1349967520","pt":1588414087955,"mc":[{"id":"1.170370562","rc":[{"atb":[[1.01,1088.62]],"id":9631798}],"con":true,"img":false}]}
{"op":"mcm","clk":"1349967521","pt":1588414088061,"mc":[{"id":"1.170370562","rc":[{"atb":[[2.54,0],[2.6,0]],"id":9625043}],"con":true,"img":false}]}
{"op":"mcm","clk":"1349967522","pt":1588414088158,"mc":[{"id":"1.170370562","rc":[{"atb":[[1.01,1088.13]],"id":9631798}],"con":true,"img":false}]}
{"op":"mcm","clk":"1349967542","pt":1588414089457,"mc":[{"id":"1.170370562","rc":[{"atb":[[1.55,401.11]],"id":9631798}],"con":true,"img":false}]}
{"op":"mcm","clk":"1349967555","pt":1588414090073,"mc":[{"id":"1.170370562","rc":[{"atb":[[1.55,265.95]],"id":9631798}],"con":true,"img":false}]}
{"op":"mcm","clk":"1349967593","pt":1588414091572,"mc":[{"id":"1.170370562","rc":[{"atl":[[3.25,34]],"id":9625043},{"atl":[[1.88,0.11]],"id":9631798}],"con":true,"img":false}]}
{"op":"mcm","clk":"1349967601","pt":1588414091778,"mc":[{"id":"1.170370562","rc":[{"trd":[[1.61,2029.27]],"ltp":1.61,"tv":2029.27,"id":9631798},{"atl":[[1.61,82.58]],"id":9631798}],"con":true,"img":false}]}
{"op":"mcm","clk":"1349967607","pt":1588414092188,"mc":[{"id":"1.170370562","rc":[{"atl":[[1.61,82.82]],"id":9631798}],"con":true,"img":false}]}
{"op":"mcm","clk":"1349967610","pt":1588414092393,"mc":[{"id":"1.170370562","rc":[{"atb":[[1.56,137.29]],"id":9631798}],"con":true,"img":false}]}
{"op":"mcm","clk":"1349967618","pt":1588414092963,"mc":[{"id":"1.170370562","rc":[{"atb":[[1.6,35.46]],"id":9631798}],"con":true,"img":false}]}
{"op":"mcm","clk":"1349967623","pt":1588414093167,"mc":[{"id":"1.170370562","rc":[{"trd":[[2.64,44.32]],"ltp":2.64,"tv":44.32,"id":9625043},{"atb":[[2.64,0]],"id":9625043},{"atl":[[2.64,12.82]],"id":9625043},{"atb":[[1.59,0]],"id":9631798}],"con":true,"img":false}]}
{"op":"mcm","clk":"1349967627","pt":1588414093270,"mc":[{"id":"1.170370562","rc":[{"atb":[[1.59,0.48]],"id":9631798}],"con":true,"img":false}]}
{"op":"mcm","clk":"1349967650","pt":1588414094359,"mc":[{"id":"1.170370562","rc":[{"atb":[[1.54,0]],"id":9631798}],"con":true,"img":false}]}
{"op":"mcm","clk":"1349967665","pt":1588414095184,"mc":[{"id":"1.170370562","rc":[{"atl":[[1.64,0]],"id":9631798}],"con":true,"img":false}]}
{"op":"mcm","clk":"1349967697","pt":1588414096470,"mc":[{"id":"1.170370562","rc":[{"atb":[[1.53,66]],"id":9631798}],"con":true,"img":false}]}
{"op":"mcm","clk":"1349967701","pt":1588414096880,"mc":[{"id":"1.170370562","rc":[{"atb":[[1.51,68.3]],"id":9631798}],"con":true,"img":false}]}
{"op":"mcm","clk":"1349967717","pt":1588414097295,"mc":[{"id":"1.170370562","rc":[{"atb":[[1.49,66]],"id":9631798}],"con":true,"img":false}]}
{"op":"mcm","clk":"1349967739","pt":1588414098375,"mc":[{"id":"1.170370562","rc":[{"atb":[[1.6,35.56]],"id":9631798}],"con":true,"img":false}]}
{"op":"mcm","clk":"1349967787","pt":1588414100587,"mc":[{"id":"1.170370562","rc":[{"trd":[[1.6,679.17]],"ltp":1.6,"tv":679.17,"id":9631798},{"atb":[[1.6,31.13]],"id":9631798}],"con":true,"img":false}]}
{"op":"mcm","clk":"1349967791","pt":1588414100793,"mc":[{"id":"1.170370562","rc":[{"trd":[[1.6,688.04]],"ltp":1.6,"tv":688.04,"id":9631798},{"atb":[[1.6,26.69]],"id":9631798}],"con":true,"img":false}]}
{"op":"mcm","clk":"1349967799","pt":1588414101307,"mc":[{"id":"1.170370562","rc":[{"trd":[[1.6,696.9]],"ltp":1.6,"tv":696.9,"id":9631798},{"atb":[[1.6,22.26]],"id":9631798}],"con":true,"img":false}]}
{"op":"mcm","clk":"1349967802","pt":1588414101616,"mc":[{"id":"1.170370562","rc":[{"trd":[[1.6,705.77]],"ltp":1.6,"tv":705.77,"id":9631798},{"atb":[[1.6,17.83]],"id":9631798}],"con":true,"img":false}]}
{"op":"mcm","clk":"1349967828","pt":1588414102690,"mc":[{"id":"1.170370562","rc":[{"trd":[[1.6,714.63]],"ltp":1.6,"tv":714.63,"id":9631798},{"atb":[[1.6,13.4]],"id":9631798}],"con":true,"img":false}]}
{"op":"mcm","clk":"1349967842","pt":1588414103204,"mc":[{"id":"1.170370562","rc":[{"atl":[[1.63,0]],"id":9631798}],"con":true,"img":false}]}
{"op":"mcm","clk":"1349967859","pt":1588414103614,"mc":[{"id":"1.170370562","rc":[{"trd":[[1.6,719.79]],"ltp":1.6,"tv":719.79,"id":9631798},{"atb":[[1.6,10.82]],"id":9631798}],"con":true,"img":false}]}
{"op":"mcm","clk":"1349967883","pt":1588414104588,"mc":[{"id":"1.170370562","rc":[{"trd":[[2.64,54.92]],"ltp":2.64,"tv":54.92,"id":9625043},{"atl":[[2.64,2.22]],"id":9625043},{"trd":[[1.6,758.92]],"ltp":1.6,"tv":758.92,"id":9631798},{"atb":[[1.6,0]],"id":9631798}],"con":true,"img":false}]}
{"op":"mcm","clk":"1349967895","pt":1588414104898,"mc":[{"id":"1.170370562","rc":[{"trd":[[2.64,57.15]],"ltp":2.64,"tv":57.15,"id":9625043},{"atl":[[2.64,0]],"id":9625043},{"trd":[[1.6,762.59]],"ltp":1.6,"tv":762.59,"id":9631798},{"atl":[[1.6,2.89]],"id":9631798}],"con":true,"img":false}]}
{"op":"mcm","clk":"1349967921","pt":1588414106181,"mc":[{"id":"1.170370562","rc":[{"atl":[[1.6,4.53]],"id":9631798}],"con":true,"img":false}]}
{"op":"mcm","clk":"1349967963","pt":1588414108286,"mc":[{"id":"1.170370562","rc":[{"atl":[[1.6,31.53]],"id":9631798}],"con":true,"img":false}]}
{"op":"mcm","clk":"1349967994","pt":1588414109782,"mc":[{"id":"1.170370562","rc":[{"atl":[[1.6,127.95]],"id":9631798}],"con":true,"img":false}]}
{"op":"mcm","clk":"1349968009","pt":1588414110707,"mc":[{"id":"1.170370562","rc":[{"trd":[[1.6,771.46]],"ltp":1.6,"tv":771.46,"id":9631798},{"atl":[[1.6,123.51]],"id":9631798}],"con":true,"img":false}]}
{"op":"mcm","clk":"1349968018","pt":1588414111014,"mc":[{"id":"1.170370562","rc":[{"trd":[[1.6,782.65]],"ltp":1.6,"tv":782.65,"id":9631798},{"atl":[[1.6,117.92]],"id":9631798}],"con":true,"img":false}]}
{"op":"mcm","clk":"1349968027","pt":1588414111528,"mc":[{"id":"1.170370562","rc":[{"atl":[[1.61,0.23]],"id":9631798}],"con":true,"img":false}]}
{"op":"mcm","clk":"1349968041","pt":1588414111992,"mc":[{"id":"1.170370562","rc":[{"atl":[[1.6,205.51]],"id":9631798}],"con":true,"img":false}]}
{"op":"mcm","clk":"1349968066","pt":1588414113125,"mc":[{"id":"1.170370562","rc":[{"atb":[[1.55,0]],"id":9631798}],"con":true,"img":false}]}
{"op":"mcm","clk":"1349968104","pt":1588414115197,"mc":[{"id":"1.170370562","rc":[{"atl":[[1.61,0]],"id":9631798}],"con":true,"img":false}]}
{"op":"mcm","clk":"1349968166","pt":1588414118195,"mc":[{"id":"1.170370562","rc":[{"atb":[[1.54,265.95]],"id":9631798}],"con":true,"img":false}]}
{"op":"mcm","clk":"1349968167","pt":1588414118301,"mc":[{"id":"1.170370562","rc":[{"trd":[[1.58,48.97],[1.59,1211.36]],"ltp":1.58,"tv":1260.33,"id":9631798},{"atb":[[1.59,0],[1.58,246.67]],"id":9631798}],"con":true,"img":false}]}
{"op":"mcm","clk":"1349968218","pt":1588414121327,"mc":[{"id":"1.170370562","rc":[{"trd":[[1.58,58.41]],"ltp":1.58,"tv":58.41,"id":9631798},{"atb":[[1.58,241.95]],"id":9631798}],"con":true,"img":false}]}
{"op":"mcm","clk":"1349968238","pt":1588414122710,"mc":[{"id":"1.170370562","rc":[{"atl":[[1.6,227.39]],"id":9631798}],"con":true,"img":false}]}
{"op":"mcm","clk":"1349968240","pt":1588414122917,"mc":[{"id":"1.170370562","rc":[{"trd":[[2.66,1.58]],"ltp":2.66,"tv":1.58,"id":9625043},{"trd":[[1.6,785.29]],"ltp":1.6,"tv":785.29,"id":9631798},{"atl":[[1.6,224.75]],"id":9631798}],"con":true,"img":false}]}
{"op":"mcm","clk":"1349968314","pt":1588414127025,"mc":[{"id":"1.170370562","rc":[{"trd":[[1.58,542.31]],"ltp":1.58,"tv":542.31,"id":9631798},{"atb":[[1.58,0]],"id":9631798},{"atl":[[1.58,20.81]],"id":9631798}],"con":true,"img":false}]}
{"op":"mcm","clk":"1349968339","pt":1588414128514,"mc":[{"id":"1.170370562","rc":[{"trd":[[1.56,24.54]],"ltp":1.56,"tv":24.54,"id":9631798},{"atb":[[1.56,125.02]],"id":9631798}],"con":true,"img":false}]}
{"op":"mcm","clk":"1349968354","pt":1588414129439,"mc":[{"id":"1.170370562","rc":[{"trd":[[1.6,1234.81],[1.58,583.94]],"ltp":1.6,"tv":1818.75,"id":9631798},{"atb":[[1.62,754.43]],"id":9631798},{"atl":[[1.6,0],[1.58,0]],"id":9631798}],"con":true,"img":false}]}
{"op":"mcm","clk":"1349968361","pt":1588414129853,"mc":[{"id":"1.170370562","rc":[{"atb":[[1.62,0]],"id":9631798}],"con":true,"img":false}]}
{"op":"mcm","clk":"1349968376","pt":1588414130520,"mc":[{"id":"1.170370562","rc":[{"atb":[[1.54,0]],"id":9631798}],"con":true,"img":false}]}
{"op":"mcm","clk":"1349968386","pt":1588414131034,"mc":[{"id":"1.170370562","rc":[{"atb":[[1.52,0]],"id":9631798}],"con":true,"img":false}]}
{"op":"mcm","clk":"1349968397","pt":1588414131750,"mc":[{"id":"1.170370562","rc":[{"atb":[[1.6,492.02]],"id":9631798}],"con":true,"img":false}]}
{"op":"mcm","clk":"1349968410","pt":1588414132522,"mc":[{"id":"1.170370562","rc":[{"atb":[[1.51,2.3],[1.53,0],[1.49,0]],"id":9631798}],"con":true,"img":false}]}
{"op":"mcm","clk":"1349968450","pt":1588414134960,"mc":[{"id":"1.170370562","rc":[{"atb":[[1.56,373.78]],"id":9631798}],"con":true,"img":false}]}
{"op":"mcm","clk":"1349968454","pt":1588414135250,"mc":[{"id":"1.170370562","rc":[{"trd":[[1.6,1244.24]],"ltp":1.6,"tv":1244.24,"id":9631798},{"atb":[[1.6,487.3]],"id":9631798}],"con":true,"img":false}]}
{"op":"mcm","clk":"1349968460","pt":1588414135661,"mc":[{"id":"1.170370562","rc":[{"atb":[[1.51,268.25]],"id":9631798}],"con":true,"img":false}]}
{"op":"mcm","clk":"1349968463","pt":1588414135866,"mc":[{"id":"1.170370562","rc":[{"atb":[[1.6,0]],"id":9631798}],"con":true,"img":false}]}
{"op":"mcm","clk":"1349968467","pt":1588414136124,"mc":[{"id":"1.170370562","rc":[{"atl":[[2.08,0]],"id":9631798}],"con":true,"img":false}]}
{"op":"mcm","clk":"1349968483","pt":1588414137765,"mc":[{"id":"1.170370562","rc":[{"atb":[[1.63,288.22]],"id":9631798}],"con":true,"img":false}]}
{"op":"mcm","clk":"1349968485","pt":1588414138229,"mc":[{"id":"1.170370562","rc":[{"atb":[[1.6,23.04],[1.61,240]],"id":9631798}],"con":true,"img":false}]}
{"op":"mcm","clk":"1349968488","pt":1588414138537,"mc":[{"id":"1.170370562","rc":[{"atl":[[1.66,39.2]],"id":9631798}],"con":true,"img":false}]}
{"op":"mcm","clk":"1349968505","pt":1588414139770,"mc":[{"id":"1.170370562","rc":[{"atb":[[1.61,535.21],[1.55,159.97]],"id":9631798}],"con":true,"img":false}]}
{"op":"mcm","clk":"1349968531","pt":1588414140644,"mc":[{"id":"1.170370562","rc":[{"trd":[[1.63,9.37]],"ltp":1.63,"tv":9.37,"id":9631798},{"atb":[[1.63,283.53]],"id":9631798}],"con":true,"img":false}]}
{"op":"mcm","clk":"1349968553","pt":1588414141369,"mc":[{"id":"1.170370562","rc":[{"atb":[[1.6,23.15]],"id":9631798}],"con":true,"img":false}]}
{"op":"mcm","clk":"1349968594","pt":1588414143030,"mc":[{"id":"1.170370562","rc":[{"atb":[[1.54,265.95]],"id":9631798}],"con":true,"img":false}]}
{"op":"mcm","clk":"1349968621","pt":1588414144066,"mc":[{"id":"1.170370562","rc":[{"trd":[[1.63,459.53]],"ltp":1.63,"tv":459.53,"id":9631798},{"atb":[[1.63,58.45]],"id":9631798}],"con":true,"img":false}]}
{"op":"mcm","clk":"1349968624","pt":1588414144171,"mc":[{"id":"1.170370562","rc":[{"trd":[[1.6,1290.55],[1.63,576.43],[1.61,3099.7]],"ltp":1.6,"tv":4966.68,"id":9631798},{"atb":[[1.63,0],[1.61,0],[1.6,0]],"id":9631798},{"atl":[[1.6,259.07]],"id":9631798}],"con":true,"img":false}]}
{"op":"mcm","clk":"1349968636","pt":1588414144534,"mc":[{"id":"1.170370562","rc":[{"atl":[[1.7,0]],"id":9631798}],"con":true,"img":false}]}
{"op":"mcm","clk":"1349968692","pt":1588414146751,"mc":[{"id":"1.170370562","rc":[{"atl":[[1.63,4.43]],"id":9631798}],"con":true,"img":false}]}
{"op":"mcm","clk":"1349968697","pt":1588414146953,"mc":[{"id":"1.170370562","rc":[{"atl":[[1.63,8.86]],"id":9631798}],"con":true,"img":false}]}
{"op":"mcm","clk":"1349968706","pt":1588414147267,"mc":[{"id":"1.170370562","rc":[{"atl":[[1.63,13.29]],"id":9631798}],"con":true,"img":false}]}
{"op":"mcm","clk":"1349968709","pt":1588414147366,"mc":[{"id":"1.170370562","rc":[{"atl":[[1.63,17.73]],"id":9631798}],"con":true,"img":false}]}
{"op":"mcm","clk":"1349968713","pt":1588414147675,"mc":[{"id":"1.170370562","rc":[{"trd":[[1.6,1580.1]],"ltp":1.6,"tv":1580.1,"id":9631798},{"atl":[[1.6,114.29]],"id":9631798}],"con":true,"img":false}]}
{"op":"mcm","clk":"1349968716","pt":1588414147778,"mc":[{"id":"1.170370562","rc":[{"atb":[[1.51,2.3]],"id":9631798}],"con":true,"img":false}]}
{"op":"mcm","clk":"1349968726","pt":1588414148348,"mc":[{"id":"1.170370562","rc":[{"atl":[[1.63,21.73]],"id":9631798}],"con":true,"img":false}]}
{"op":"mcm","clk":"1349968738","pt":1588414148864,"mc":[{"id":"1.170370562","rc":[{"atb":[[1.46,0]],"id":9631798}],"con":true,"img":false}]}
{"op":"mcm","clk":"1349968761","pt":1588414149684,"mc":[{"id":"1.170370562","rc":[{"atl":[[1.73,265.95]],"id":9631798}],"con":true,"img":false}]}
{"op":"mcm","clk":"1349968778","pt":1588414150459,"mc":[{"id":"1.170370562","rc":[{"atb":[[1.24,0]],"id":9631798}],"con":true,"img":false}]}
{"op":"mcm","clk":"1349968788","pt":1588414150767,"mc":[{"id":"1.170370562","rc":[{"atl":[[1.59,4]],"id":9631798}],"con":true,"img":false}]}
{"op":"mcm","clk":"1349968793","pt":1588414150971,"mc":[{"id":"1.170370562","rc":[{"atl":[[1.63,139.13]],"id":9631798}],"con":true,"img":false}]}
{"op":"mcm","clk":"1349968800","pt":1588414151587,"mc":[{"id":"1.170370562","rc":[{"atl":[[1.65,240]],"id":9631798}],"con":true,"img":false}]}
{"op":"mcm","clk":"1349968805","pt":1588414151640,"mc":[{"id":"1.170370562","rc":[{"atb":[[1.57,17.54]],"id":9631798}],"con":true,"img":false}]}
{"op":"mcm","clk":"1349968828","pt":1588414152566,"mc":[{"id":"1.170370562","rc":[{"atl":[[1.63,162.71]],"id":9631798}],"con":true,"img":false}]}
{"op":"mcm","clk":"1349968837","pt":1588414153182,"mc":[{"id":"1.170370562","rc":[{"atl":[[1.62,295.21]],"id":9631798}],"con":true,"img":false}]}
{"op":"mcm","clk":"1349968840","pt":1588414153285,"mc":[{"id":"1.170370562","rc":[{"atb":[[1.49,265.95]],"id":9631798}],"con":true,"img":false}]}
{"op":"mcm","clk":"1349968863","pt":1588414154364,"mc":[{"id":"1.170370562","rc":[{"trd":[[1.62,876.93],[1.59,1219.36],[1.6,1808.7]],"ltp":1.62,"tv":3904.99,"id":9631798},{"atl":[[1.59,0],[1.6,0],[1.62,253.04]],"id":9631798}],"con":true,"img":false}]}
{"op":"mcm","clk":"1349968887","pt":1588414155754,"mc":[{"id":"1.170370562","rc":[{"atb":[[1.39,0]],"id":9631798}],"con":true,"img":false}]}
{"op":"mcm","clk":"1349968890","pt":1588414155856,"mc":[{"id":"1.170370562","rc":[{"trd":[[1.57,31.51]],"ltp":1.57,"tv":31.51,"id":9631798},{"atb":[[1.57,1.78]],"id":9631798}],"con":true,"img":false}]}
{"op":"mcm","clk":"1349968893","pt":1588414155956,"mc":[{"id":"1.170370562","rc":[{"trd":[[1.56,60.98],[1.57,35.07]],"ltp":1.56,"tv":96.05,"id":9631798},{"atb":[[1.56,355.56],[1.57,0]],"id":9631798}],"con":true,"img":false}]}
{"op":"mcm","clk":"1349968897","pt":1588414156366,"mc":[{"id":"1.170370562","rc":[{"atb":[[1.6,5.59]],"id":9631798}],"con":true,"img":false}]}
{"op":"mcm","clk":"1349968915","pt":1588414157189,"mc":[{"id":"1.170370562","rc":[{"atb":[[1.59,102]],"id":9631798}],"con":true,"img":false}]}
{"op":"mcm","clk":"1349968927","pt":1588414157961,"mc":[{"id":"1.170370562","rc":[{"atl":[[1.63,139.13]],"id":9631798}],"con":true,"img":false}]}
{"op":"mcm","clk":"1349968933","pt":1588414158164,"mc":[{"id":"1.170370562","rc":[{"atb":[[1.57,0.11]],"id":9631798}],"con":true,"img":false}]}
{"op":"mcm","clk":"1349968942","pt":1588414158587,"mc":[{"id":"1.170370562","rc":[{"trd":[[2.68,113.83]],"ltp":2.68,"tv":113.83,"id":9625043},{"trd":[[1.6,1809.01]],"ltp":1.6,"tv":1809.01,"id":9631798},{"atb":[[1.6,5.28]],"id":9631798}],"con":true,"img":false}]}
{"op":"mcm","clk":"1349968950","pt":1588414158884,"mc":[{"id":"1.170370562","rc":[{"atb":[[1.6,0]],"id":9631798}],"con":true,"img":false}]}
{"op":"mcm","clk":"1349969893","pt":1588414159969,"mc":[{"id":"1.170370562","rc":[{"atl":[[1.63,21.73]],"id":9631798}],"con":true,"img":false}]}
{"op":"mcm","clk":"1349969907","pt":1588414160282,"mc":[{"id":"1.170370562","rc":[{"atb":[[1.6,3.03]],"id":9631798}],"con":true,"img":false}]}
{"op":"mcm","clk":"1349969932","pt":1588414160851,"mc":[{"id":"1.170370562","rc":[{"atb":[[1.6,12.63]],"id":9631798}],"con":true,"img":false}]}
{"op":"mcm","clk":"1349969934","pt":1588414160954,"mc":[{"id":"1.170370562","rc":[{"trd":[[1.6,1811.07]],"ltp":1.6,"tv":1811.07,"id":9631798},{"atb":[[1.6,11.6]],"id":9631798}],"con":true,"img":false}]}
{"op":"mcm","clk":"1349969970","pt":1588414162502,"mc":[{"id":"1.170370562","rc":[{"trd":[[1.59,1230.8],[1.6,1834.27]],"ltp":1.59,"tv":3065.06,"id":9631798},{"atb":[[1.59,96.28],[1.6,0]],"id":9631798}],"con":true,"img":false}]}
{"op":"mcm","clk":"1349969980","pt":1588414162657,"mc":[{"id":"1.170370562","rc":[{"atl":[[1.61,136.52]],"id":9631798}],"con":true,"img":false}]}
{"op":"mcm","clk":"1349970005","pt":1588414163482,"mc":[{"id":"1.170370562","rc":[{"trd":[[1.59,1231.26]],"ltp":1.59,"tv":1231.26,"id":9631798},{"atb":[[1.59,96.05]],"id":9631798}],"con":true,"img":false}]}
{"op":"mcm","clk":"1349970035","pt":1588414164975,"mc":[{"id":"1.170370562","rc":[{"trd":[[1.61,3227.06]],"ltp":1.61,"tv":3227.06,"id":9631798},{"atl":[[1.61,72.84]],"id":9631798}],"con":true,"img":false}]}
{"op":"mcm","clk":"1349970056","pt":1588414165899,"mc":[{"id":"1.170370562","rc":[{"trd":[[1.62,1252.85],[1.61,3372.74]],"ltp":1.62,"tv":4625.59,"id":9631798},{"atl":[[1.62,65.08],[1.61,0]],"id":9631798}],"con":true,"img":false}]}
{"op":"mcm","clk":"1349970137","pt":1588414169164,"mc":[{"id":"1.170370562","rc":[{"atb":[[1.59,101.15]],"id":9631798}],"con":true,"img":false}]}
{"op":"mcm","clk":"1349970170","pt":1588414170606,"mc":[{"id":"1.170370562","rc":[{"atb":[[1.59,96.05]],"id":9631798}],"con":true,"img":false}]}
{"op":"mcm","clk":"1349970200","pt":1588414171999,"mc":[{"id":"1.170370562","rc":[{"atb":[[1.58,240]],"id":9631798}],"con":true,"img":false}]}
{"op":"mcm","clk":"1349970204","pt":1588414172204,"mc":[{"id":"1.170370562","rc":[{"atb":[[1.01,1090.13]],"id":9631798}],"con":true,"img":false}]}
{"op":"mcm","clk":"1349970206","pt":1588414172307,"mc":[{"id":"1.170370562","rc":[{"trd":[[1.62,1259.85]],"ltp":1.62,"tv":1259.85,"id":9631798},{"atl":[[1.62,61.58]],"id":9631798}],"con":true,"img":false}]}
{"op":"mcm","clk":"1349970208","pt":1588414172411,"mc":[{"id":"1.170370562","rc":[{"atb":[[1.01,1088.2]],"id":9631798}],"con":true,"img":false}]}
{"op":"mcm","clk":"1349970212","pt":1588414172566,"mc":[{"id":"1.170370562","rc":[{"atb":[[1.01,1088.13]],"id":9631798}],"con":true,"img":false}]}
{"op":"mcm","clk":"1349970223","pt":1588414173392,"mc":[{"id":"1.170370562","rc":[{"atl":[[1.6,23.57]],"id":9631798}],"con":true,"img":false}]}
{"op":"mcm","clk":"1349970239","pt":1588414174472,"mc":[{"id":"1.170370562","rc":[{"atl":[[1.6,24.52]],"id":9631798}],"con":true,"img":false}]}
{"op":"mcm","clk":"1349970240","pt":1588414174575,"mc":[{"id":"1.170370562","rc":[{"atl":[[1.65,0]],"id":9631798}],"con":true,"img":false}]}
{"op":"mcm","clk":"1349970255","pt":1588414175193,"mc":[{"id":"1.170370562","rc":[{"atb":[[1.59,344.81]],"id":9631798}],"con":true,"img":false}]}
{"op":"mcm","clk":"1349970261","pt":1588414175506,"mc":[{"id":"1.170370562","rc":[{"atb":[[1.56,106.8]],"id":9631798}],"con":true,"img":false}]}
{"op":"mcm","clk":"1349970291","pt":1588414177308,"mc":[{"id":"1.170370562","rc":[{"atl":[[1.6,23.91]],"id":9631798}],"con":true,"img":false}]}
{"op":"mcm","clk":"1349970297","pt":1588414177718,"mc":[{"id":"1.170370562","rc":[{"trd":[[1.6,1834.41]],"ltp":1.6,"tv":1834.41,"id":9631798},{"atl":[[1.6,23.84]],"id":9631798}],"con":true,"img":false}]}
{"op":"mcm","clk":"1349970300","pt":1588414177924,"mc":[{"id":"1.170370562","rc":[{"trd":[[1.63,619.89],[1.6,1882.09],[1.62,1383.03]],"ltp":1.63,"tv":3885.0,"id":9631798},{"atb":[[1.65,336.1]],"id":9631798},{"atl":[[1.6,0],[1.63,0],[1.62,0]],"id":9631798}],"con":true,"img":false}]}
{"op":"mcm","clk":"1349970303","pt":1588414177976,"mc":[{"id":"1.170370562","rc":[{"atb":[[1.62,5.59]],"id":9631798}],"con":true,"img":false}]}
{"op":"mcm","clk":"1349970310","pt":1588414178597,"mc":[{"id":"1.170370562","rc":[{"atl":[[2.58,54.96]],"id":9625043}],"con":true,"img":false}]}
{"op":"mcm","clk":"1349970313","pt":1588414178700,"mc":[{"id":"1.170370562","rc":[{"atb":[[1.62,27.76]],"id":9631798}],"con":true,"img":false}]}
{"op":"mcm","clk":"1349970355","pt":1588414180111,"mc":[{"id":"1.170370562","rc":[{"trd":[[1.65,142.12]],"ltp":1.65,"tv":142.12,"id":9631798},{"atb":[[1.65,317.12]],"id":9631798}],"con":true,"img":false}]}
{"op":"mcm","clk":"1349970367","pt":1588414180318,"mc":[{"id":"1.170370562","rc":[{"trd":[[1.65,142.59]],"ltp":1.65,"tv":142.59,"id":9631798},{"atb":[[1.65,316.88]],"id":9631798}],"con":true,"img":false}]}
{"op":"mcm","clk":"1349970370","pt":1588414180421,"mc":[{"id":"1.170370562","rc":[{"atl":[[2.6,20]],"id":9625043}],"con":true,"img":false}]}
{"op":"mcm","clk":"1349970385","pt":1588414180987,"mc":[{"id":"1.170370562","rc":[{"atb":[[1.54,272.95]],"id":9631798}],"con":true,"img":false}]}
{"op":"mcm","clk":"1349970391","pt":1588414181398,"mc":[{"id":"1.170370562","rc":[{"atb":[[1.54,521.71]],"id":9631798}],"con":true,"img":false}]}
{"op":"mcm","clk":"1349970399","pt":1588414181605,"mc":[{"id":"1.170370562","rc":[{"atb":[[1.62,50.8]],"id":9631798}],"con":true,"img":false}]}
{"op":"mcm","clk":"1349970407","pt":1588414181913,"mc":[{"id":"1.170370562","rc":[{"atb":[[1.62,45.21]],"id":9631798}],"con":true,"img":false}]}
{"op":"mcm","clk":"1349970420","pt":1588414182379,"mc":[{"id":"1.170370562","rc":[{"atb":[[1.45,5.15]],"id":9631798}],"con":true,"img":false}]}
{"op":"mcm","clk":"1349970446","pt":1588414183205,"mc":[{"id":"1.170370562","rc":[{"trd":[[1.65,143.21]],"ltp":1.65,"tv":143.21,"id":9631798},{"atb":[[1.65,316.57]],"id":9631798}],"con":true,"img":false}]}
{"op":"mcm","clk":"1349970450","pt":1588414183412,"mc":[{"id":"1.170370562","rc":[{"atb":[[1.59,248.76]],"id":9631798}],"con":true,"img":false}]}
{"op":"mcm","clk":"1349970479","pt":1588414184390,"mc":[{"id":"1.170370562","rc":[{"atb":[[1.62,50.21]],"id":9631798}],"con":true,"img":false}]}
{"op":"mcm","clk":"1349970512","pt":1588414186192,"mc":[{"id":"1.170370562","rc":[{"atb":[[1.6,47.99]],"id":9631798},{"atl":[[1.82,240]],"id":9631798}],"con":true,"img":false}]}
{"op":"mcm","clk":"1349970552","pt":1588414188303,"mc":[{"id":"1.170370562","rc":[{"atb":[[1.62,45.21]],"id":9631798}],"con":true,"img":false}]}
{"op":"mcm","clk":"1349970566","pt":1588414189235,"mc":[{"id":"1.170370562","rc":[{"atl":[[2.6,0]],"id":9625043}],"con":true,"img":false}]}
{"op":"mcm","clk":"1349970603","pt":1588414190340,"mc":[{"id":"1.170370562","rc":[{"atb":[[1.62,22.16]],"id":9631798}],"con":true,"img":false}]}
{"op":"mcm","clk":"1349970611","pt":1588414190596,"mc":[{"id":"1.170370562","rc":[{"trd":[[1.66,86.95]],"ltp":1.66,"tv":86.95,"id":9631798},{"atl":[[1.66,38.59]],"id":9631798}],"con":true,"img":false}]}
{"op":"mcm","clk":"1349970615","pt":1588414190751,"mc":[{"id":"1.170370562","rc":[{"trd":[[1.65,160.73],[1.66,109.34]],"ltp":1.65,"tv":270.07,"id":9631798},{"atb":[[1.65,307.81]],"id":9631798},{"atl":[[1.66,27.4]],"id":9631798}],"con":true,"img":false}]}
{"op":"mcm","clk":"1349970620","pt":1588414190906,"mc":[{"id":"1.170370562","rc":[{"trd":[[1.66,110.92],[1.65,161.86]],"ltp":1.66,"tv":272.78,"id":9631798},{"atb":[[1.65,307.25]],"id":9631798},{"atl":[[1.66,26.61]],"id":9631798}],"con":true,"img":false}]}
{"op":"mcm","clk":"1349970629","pt":1588414191323,"mc":[{"id":"1.170370562","rc":[{"trd":[[1.65,162.23]],"ltp":1.65,"tv":162.23,"id":9631798},{"atb":[[1.65,307.06]],"id":9631798}],"con":true,"img":false}]}
{"op":"mcm","clk":"1349970641","pt":1588414192146,"mc":[{"id":"1.170370562","rc":[{"trd":[[1.66,122.69]],"ltp":1.66,"tv":122.69,"id":9631798},{"atl":[[1.66,20.72]],"id":9631798}],"con":true,"img":false}]}
{"op":"mcm","clk":"1349970664","pt":1588414192817,"mc":[{"id":"1.170370562","rc":[{"trd":[[1.65,162.71]],"ltp":1.65,"tv":162.71,"id":9631798},{"atb":[[1.65,306.82]],"id":9631798}],"con":true,"img":false}]}
{"op":"mcm","clk":"1349970667","pt":1588414193022,"mc":[{"id":"1.170370562","rc":[{"trd":[[1.65,163.53]],"ltp":1.65,"tv":163.53,"id":9631798},{"atb":[[1.65,306.41]],"id":9631798}],"con":true,"img":false}]}
{"op":"mcm","clk":"1349970696","pt":1588414194316,"mc":[{"id":"1.170370562","rc":[{"trd":[[2.5,13.76]],"ltp":2.5,"tv":13.76,"id":9625043},{"atl":[[2.5,6.24]],"id":9625043},{"trd":[[1.66,143.42]],"ltp":1.66,"tv":143.42,"id":9631798},{"atl":[[1.66,0]],"id":9631798}],"con":true,"img":false}]}
{"op":"mcm","clk":"1349970712","pt":1588414194934,"mc":[{"id":"1.170370562","rc":[{"trd":[[2.5,15.9]],"ltp":2.5,"tv":15.9,"id":9625043},{"atl":[[2.5,4.1]],"id":9625043},{"trd":[[1.66,146.64]],"ltp":1.66,"tv":146.64,"id":9631798}],"con":true,"img":false}]}
{"op":"mcm","clk":"1349970715","pt":1588414195139,"mc":[{"id":"1.170370562","rc":[{"atl":[[2.58,0]],"id":9625043}],"con":true,"img":false}]}
{"op":"mcm","clk":"1349970719","pt":1588414195450,"mc":[{"id":"1.170370562","rc":[{"trd":[[1.68,536.39],[1.67,50.86]],"ltp":1.68,"tv":587.25,"id":9631798},{"atb":[[1.68,0.52]],"id":9631798},{"atl":[[1.67,0]],"id":9631798}],"con":true,"img":false}]}
{"op":"mcm","clk":"1349970724","pt":1588414195554,"mc":[{"id":"1.170370562","rc":[{"atb":[[1.49,0],[1.54,255.76]],"id":9631798},{"atl":[[1.73,0]],"id":9631798}],"con":true,"img":false}]}
{"op":"mcm","clk":"1349970814","pt":1588414200041,"mc":[{"id":"1.170370562","rc":[{"atl":[[1.82,0]],"id":9631798}],"con":true,"img":false}]}
{"op":"mcm","clk":"1349970817","pt":1588414200146,"mc":[{"id":"1.170370562","rc":[{"atb":[[1.68,2.97]],"id":9631798}],"con":true,"img":false}]}
{"op":"mcm","clk":"1349970879","pt":1588414202124,"mc":[{"id":"1.170370562","rc":[{"atl":[[1.76,265.95]],"id":9631798}],"con":true,"img":false}]}
{"op":"mcm","clk":"1349970925","pt":1588414203434,"mc":[{"id":"1.170370562","rc":[{"trd":[[1.68,538.83]],"ltp":1.68,"tv":538.83,"id":9631798},{"atb":[[1.68,1.75]],"id":9631798}],"con":true,"img":false}]}
{"op":"mcm","clk":"1349970949","pt":1588414204163,"mc":[{"id":"1.170370562","rc":[{"atl":[[2.5,4.57]],"id":9625043}],"con":true,"img":false}]}
{"op":"mcm","clk":"1349970955","pt":1588414204525,"mc":[{"id":"1.170370562","rc":[{"atb":[[1.65,749.68]],"id":9631798}],"con":true,"img":false}]}
{"op":"mcm","clk":"1349970990","pt":1588414205664,"mc":[{"id":"1.170370562","rc":[{"atb":[[1.58,505.95],[1.62,0]],"id":9631798}],"con":true,"img":false}]}
{"op":"mcm","clk":"1349971001","pt":1588414206129,"mc":[{"id":"1.170370562","rc":[{"atl":[[1.91,240]],"id":9631798}],"con":true,"img":false}]}
{"op":"mcm","clk":"1349971003","pt":1588414206335,"mc":[{"id":"1.170370562","rc":[{"atb":[[1.67,1.77]],"id":9631798}],"con":true,"img":false}]}
{"op":"mcm","clk":"1349971051","pt":1588414208870,"mc":[{"id":"1.170370562","rc":[{"atb":[[1.66,4.9]],"id":9631798}],"con":true,"img":false}]}
{"op":"mcm","clk":"1349971069","pt":1588414209435,"mc":[{"id":"1.170370562","rc":[{"atl":[[2.5,4.1]],"id":9625043}],"con":true,"img":false}]}
{"op":"mcm","clk":"1349971076","pt":1588414209539,"mc":[{"id":"1.170370562","rc":[{"atl":[[1.96,265.95]],"id":9631798}],"con":true,"img":false}]}
{"op":"mcm","clk":"1349971107","pt":1588414210260,"mc":[{"id":"1.170370562","rc":[{"atl":[[2.5,0]],"id":9625043}],"con":true,"img":false}]}
{"op":"mcm","clk":"1349971112","pt":1588414210362,"mc":[{"id":"1.170370562","rc":[{"atl":[[1.76,0]],"id":9631798}],"con":true,"img":false}]}
{"op":"mcm","clk":"1349971155","pt":1588414211551,"mc":[{"id":"1.170370562","rc":[{"atb":[[1.1,0]],"id":9625043}],"con":true,"img":false}]}
{"op":"mcm","clk":"1349971221","pt":1588414213662,"mc":[{"id":"1.170370562","rc":[{"atb":[[1.76,13.29]],"id":9631798}],"con":true,"img":false}]}
{"op":"mcm","clk":"1349971258","pt":1588414214955,"mc":[{"id":"1.170370562","rc":[{"atb":[[1.66,0]],"id":9631798}],"con":true,"img":false}]}
{"op":"mcm","clk":"1349971413","pt":1588414221368,"mc":[{"id":"1.170370562","rc":[{"atl":[[1.9,4]],"id":9631798}],"con":true,"img":false}]}
{"op":"mcm","clk":"1349971494","pt":1588414224886,"mc":[{"id":"1.170370562","rc":[{"trd":[[1.9,85.75],[1.88,0.23]],"ltp":1.9,"tv":85.98,"id":9631798},{"atl":[[1.88,0],[1.9,0.62]],"id":9631798}],"con":true,"img":false}]}
{"op":"mcm","clk":"1349971525","pt":1588414226390,"mc":[{"id":"1.170370562","rc":[{"trd":[[2.1,75.6]],"ltp":2.1,"tv":75.6,"id":9625043},{"trd":[[1.9,86.25]],"ltp":1.9,"tv":86.25,"id":9631798},{"atl":[[1.9,0.12]],"id":9631798}],"con":true,"img":false}]}
{"op":"mcm","clk":"1349971569","pt":1588414228399,"mc":[{"id":"1.170370562","rc":[{"trd":[[1.76,31.8]],"ltp":1.76,"tv":31.8,"id":9631798},{"atb":[[1.76,1.5]],"id":9631798}],"con":true,"img":false}]}
{"op":"mcm","clk":"1349971597","pt":1588414229697,"mc":[{"id":"1.170370562","rc":[{"atb":[[1.55,0]],"id":9631798}],"con":true,"img":false}]}
{"op":"mcm","clk":"1349971598","pt":1588414229801,"mc":[{"id":"1.170370562","rc":[{"atb":[[1.56,0],[1.58,265.95]],"id":9631798}],"con":true,"img":false}]}
{"op":"mcm","clk":"1349971630","pt":1588414230678,"mc":[{"id":"1.170370562","rc":[{"trd":[[1.76,34.82]],"ltp":1.76,"tv":34.82,"id":9631798},{"atb":[[1.76,0]],"id":9631798},{"atl":[[1.72,998.49]],"id":9631798}],"con":true,"img":false}]}
{"op":"mcm","clk":"1349971636","pt":1588414230882,"mc":[{"id":"1.170370562","rc":[{"trd":[[1.65,1418.67],[1.68,542.34],[1.67,54.41]],"ltp":1.65,"tv":2015.42,"id":9631798},{"atb":[[1.68,0],[1.67,0],[1.65,122.1]],"id":9631798},{"atl":[[1.76,4.71]],"id":9631798}],"con":true,"img":false}]}
{"op":"mcm","clk":"1349971645","pt":1588414231096,"mc":[{"id":"1.170370562","rc":[{"atl":[[1.74,492.02]],"id":9631798}],"con":true,"img":false}]}
{"op":"mcm","clk":"1349971728","pt":1588414233989,"mc":[{"id":"1.170370562","rc":[{"atl":[[1.86,240]],"id":9631798}],"con":true,"img":false}]}
{"op":"mcm","clk":"1349971730","pt":1588414234094,"mc":[{"id":"1.170370562","rc":[{"atl":[[1.74,0]],"id":9631798}],"con":true,"img":false}]}
{"op":"mcm","clk":"1349971747","pt":1588414234610,"mc":[{"id":"1.170370562","rc":[{"atl":[[1.78,240]],"id":9631798}],"con":true,"img":false}]}
{"op":"mcm","clk":"1349971763","pt":1588414235491,"mc":[{"id":"1.170370562","rc":[{"atl":[[1.72,0]],"id":9631798}],"con":true,"img":false}]}
{"op":"mcm","clk":"1349971766","pt":1588414235592,"mc":[{"id":"1.170370562","rc":[{"atl":[[2.22,307.06]],"id":9631798}],"con":true,"img":false}]}
{"op":"mcm","clk":"1349971767","pt":1588414235697,"mc":[{"id":"1.170370562","rc":[{"atb":[[1.46,25.84]],"id":9631798}],"con":true,"img":false}]}
{"op":"mcm","clk":"1349971779","pt":1588414236314,"mc":[{"id":"1.170370562","rc":[{"atb":[[1.58,0]],"id":9631798},{"atl":[[1.96,0]],"id":9631798}],"con":true,"img":false}]}
{"op":"mcm","clk":"1349971782","pt":1588414236418,"mc":[{"id":"1.170370562","rc":[{"atl":[[1.77,265.95]],"id":9631798}],"con":true,"img":false}]}
{"op":"mcm","clk":"1349971812","pt":1588414238121,"mc":[{"id":"1.170370562","rc":[{"atb":[[1.59,488.76]],"id":9631798}],"con":true,"img":false}]}
{"op":"mcm","clk":"1349971860","pt":1588414239828,"mc":[{"id":"1.170370562","rc":[{"atb":[[1.55,240]],"id":9631798}],"con":true,"img":false}]}
{"op":"mcm","clk":"1349971876","pt":1588414240499,"mc":[{"id":"1.170370562","rc":[{"atb":[[1.62,265.95]],"id":9631798},{"atl":[[1.83,159.97]],"id":9631798}],"con":true,"img":false}]}
{"op":"mcm","clk":"1349971918","pt":1588414242199,"mc":[{"id":"1.170370562","rc":[{"atl":[[1.83,0]],"id":9631798}],"con":true,"img":false}]}
{"op":"mcm","clk":"1349971954","pt":1588414243544,"mc":[{"id":"1.170370562","rc":[{"atl":[[1.9,266.07]],"id":9631798}],"con":true,"img":false}]}
{"op":"mcm","clk":"1349971968","pt":1588414244019,"mc":[{"id":"1.170370562","rc":[{"atb":[[1.64,0.23]],"id":9631798}],"con":true,"img":false}]}
{"op":"mcm","clk":"1349972056","pt":1588414246806,"mc":[{"id":"1.170370562","rc":[{"atl":[[1.76,116.71]],"id":9631798}],"con":true,"img":false}]}
{"op":"mcm","clk":"1349972087","pt":1588414247732,"mc":[{"id":"1.170370562","rc":[{"trd":[[2.3,60.01]],"ltp":2.3,"tv":60.01,"id":9625043},{"trd":[[1.76,112.44]],"ltp":1.76,"tv":112.44,"id":9631798},{"atl":[[1.76,39.09]],"id":9631798}],"con":true,"img":false}]}
{"op":"mcm","clk":"1349972091","pt":1588414247835,"mc":[{"id":"1.170370562","rc":[{"atl":[[1.78,0]],"id":9631798}],"con":true,"img":false}]}
{"op":"mcm","clk":"1349972129","pt":1588414249554,"mc":[{"id":"1.170370562","rc":[{"atb":[[1.62,0]],"id":9631798}],"con":true,"img":false}]}
{"op":"mcm","clk":"1349972136","pt":1588414249810,"mc":[{"id":"1.170370562","rc":[{"atb":[[1.58,265.95]],"id":9631798}],"con":true,"img":false}]}
{"op":"mcm","clk":"1349972146","pt":1588414250120,"mc":[{"id":"1.170370562","rc":[{"trd":[[1.65,1421.28]],"ltp":1.65,"tv":1421.28,"id":9631798},{"atb":[[1.65,120.8]],"id":9631798}],"con":true,"img":false}]}
{"op":"mcm","clk":"1349972172","pt":1588414250837,"mc":[{"id":"1.170370562","rc":[{"trd":[[1.76,112.85]],"ltp":1.76,"tv":112.85,"id":9631798},{"atl":[[1.76,38.89]],"id":9631798}],"con":true,"img":false}]}
{"op":"mcm","clk":"1349972248","pt":1588414253357,"mc":[{"id":"1.170370562","rc":[{"trd":[[2.3,60.48]],"ltp":2.3,"tv":60.48,"id":9625043},{"trd":[[1.76,113.47]],"ltp":1.76,"tv":113.47,"id":9631798},{"atl":[[1.76,38.27]],"id":9631798}],"con":true,"img":false}]}
{"op":"mcm","clk":"1349972283","pt":1588414254445,"mc":[{"id":"1.170370562","rc":[{"atb":[[1.68,76.38]],"id":9631798}],"con":true,"img":false}]}
{"op":"mcm","clk":"1349972299","pt":1588414254959,"mc":[{"id":"1.170370562","rc":[{"atl":[[1.77,0]],"id":9631798}],"con":true,"img":false}]}
{"op":"mcm","clk":"1349972304","pt":1588414255115,"mc":[{"id":"1.170370562","rc":[{"trd":[[2.3,65.48]],"ltp":2.3,"tv":65.48,"id":9625043},{"trd":[[1.76,120]],"ltp":1.76,"tv":120.0,"id":9631798},{"atl":[[1.76,31.74]],"id":9631798}],"con":true,"img":false}]}
{"op":"mcm","clk":"1349972338","pt":1588414256351,"mc":[{"id":"1.170370562","rc":[{"atb":[[1.62,112]],"id":9631798}],"con":true,"img":false}]}
{"op":"mcm","clk":"1349972385","pt":1588414258047,"mc":[{"id":"1.170370562","rc":[{"atl":[[1.76,0]],"id":9631798}],"con":true,"img":false}]}
{"op":"mcm","clk":"1349972466","pt":1588414260054,"mc":[{"id":"1.170370562","rc":[{"atb":[[1.76,4.6]],"id":9631798}],"con":true,"img":false}]}
{"op":"mcm","clk":"1349972605","pt":1588414264455,"mc":[{"id":"1.170370562","rc":[{"atb":[[1.74,1000]],"id":9631798}],"con":true,"img":false}]}
{"op":"mcm","clk":"1349972630","pt":1588414264972,"mc":[{"id":"1.170370562","rc":[{"atb":[[1.76,0]],"id":9631798}],"con":true,"img":false}]}
{"op":"mcm","clk":"1349972647","pt":1588414265385,"mc":[{"id":"1.170370562","rc":[{"atb":[[1.77,492.02]],"id":9631798}],"con":true,"img":false}]}
{"op":"mcm","clk":"1349972656","pt":1588414265697,"mc":[{"id":"1.170370562","rc":[{"atb":[[1.76,26.27]],"id":9631798}],"con":true,"img":false}]}
{"op":"mcm","clk":"1349972666","pt":1588414265898,"mc":[{"id":"1.170370562","rc":[{"atl":[[1.91,0],[1.86,0]],"id":9631798}],"con":true,"img":false}]}
{"op":"mcm","clk":"1349972669","pt":1588414266163,"mc":[{"id":"1.170370562","rc":[{"atb":[[1.45,2.57],[1.72,1232.6]],"id":9631798}],"con":true,"img":false}]}
{"op":"mcm","clk":"1349972703","pt":1588414267459,"mc":[{"id":"1.170370562","rc":[{"atb":[[1.74,0]],"id":9631798}],"con":true,"img":false}]}
{"op":"mcm","clk":"1349972726","pt":1588414268486,"mc":[{"id":"1.170370562","rc":[{"atb":[[1.77,509.75]],"id":9631798}],"con":true,"img":false}]}
{"op":"mcm","clk":"1349972733","pt":1588414268690,"mc":[{"id":"1.170370562","rc":[{"atb":[[1.77,17.73]],"id":9631798}],"con":true,"img":false}]}
{"op":"mcm","clk":"1349972752","pt":1588414269366,"mc":[{"id":"1.170370562","rc":[{"trd":[[1.77,10.04]],"ltp":1.77,"tv":10.04,"id":9631798},{"atb":[[1.77,17.57]],"id":9631798}],"con":true,"img":false}]}
{"op":"mcm","clk":"1349972753","pt":1588414269467,"mc":[{"id":"1.170370562","rc":[{"atb":[[1.72,0]],"id":9631798}],"con":true,"img":false}]}
{"op":"mcm","clk":"1349972776","pt":1588414270593,"mc":[{"id":"1.170370562","rc":[{"atb":[[1.78,17.73]],"id":9631798}],"con":true,"img":false}]}
{"op":"mcm","clk":"1349972822","pt":1588414271883,"mc":[{"id":"1.170370562","rc":[{"atb":[[1.79,112]],"id":9631798}],"con":true,"img":false}]}
{"op":"mcm","clk":"1349972830","pt":1588414272083,"mc":[{"id":"1.170370562","rc":[{"atb":[[1.79,129.73]],"id":9631798}],"con":true,"img":false}]}
{"op":"mcm","clk":"1349972838","pt":1588414272286,"mc":[{"id":"1.170370562","rc":[{"atb":[[1.78,283.68],[1.82,112]],"id":9631798}],"con":true,"img":false}]}
{"op":"mcm","clk":"1349972854","pt":1588414272699,"mc":[{"id":"1.170370562","rc":[{"atb":[[1.78,17.73],[1.76,0]],"id":9631798}],"con":true,"img":false}]}
{"op":"mcm","clk":"1349972861","pt":1588414273006,"mc":[{"id":"1.170370562","rc":[{"trd":[[1.82,5.89]],"ltp":1.82,"tv":5.89,"id":9631798},{"atb":[[1.82,111.26]],"id":9631798}],"con":true,"img":false}]}
{"op":"mcm","clk":"1349972867","pt":1588414273108,"mc":[{"id":"1.170370562","rc":[{"atl":[[1.89,17.73]],"id":9631798}],"con":true,"img":false}]}
{"op":"mcm","clk":"1349972869","pt":1588414273211,"mc":[{"id":"1.170370562","rc":[{"atb":[[1.01,1090.13]],"id":9631798}],"con":true,"img":false}]}
{"op":"mcm","clk":"1349972880","pt":1588414273370,"mc":[{"id":"1.170370562","rc":[{"atb":[[1.01,1089.51]],"id":9631798}],"con":true,"img":false}]}
{"op":"mcm","clk":"1349972887","pt":1588414273573,"mc":[{"id":"1.170370562","rc":[{"atb":[[1.01,1088.13]],"id":9631798}],"con":true,"img":false}]}
{"op":"mcm","clk":"1349972891","pt":1588414273677,"mc":[{"id":"1.170370562","rc":[{"atl":[[1.89,35.46]],"id":9631798}],"con":true,"img":false}]}
{"op":"mcm","clk":"1349972937","pt":1588414275376,"mc":[{"id":"1.170370562","rc":[{"atb":[[1.58,0]],"id":9631798}],"con":true,"img":false}]}
{"op":"mcm","clk":"1349972946","pt":1588414275582,"mc":[{"id":"1.170370562","rc":[{"trd":[[1.82,15.33]],"ltp":1.82,"tv":15.33,"id":9631798},{"atb":[[1.82,106.54]],"id":9631798}],"con":true,"img":false}]}
{"op":"mcm","clk":"1349972952","pt":1588414275788,"mc":[{"id":"1.170370562","rc":[{"atb":[[1.73,265.95]],"id":9631798}],"con":true,"img":false}]}
{"op":"mcm","clk":"1349972977","pt":1588414276767,"mc":[{"id":"1.170370562","rc":[{"atb":[[1.77,0]],"id":9631798}],"con":true,"img":false}]}
{"op":"mcm","clk":"1349972981","pt":1588414276971,"mc":[{"id":"1.170370562","rc":[{"atb":[[1.79,17.73]],"id":9631798}],"con":true,"img":false}]}
{"op":"mcm","clk":"1349973011","pt":1588414278313,"mc":[{"id":"1.170370562","rc":[{"trd":[[1.82,24.76]],"ltp":1.82,"tv":24.76,"id":9631798},{"atb":[[1.82,101.82]],"id":9631798}],"con":true,"img":false}]}
{"op":"mcm","clk":"1349973015","pt":1588414278469,"mc":[{"id":"1.170370562","rc":[{"trd":[[1.82,29.98]],"ltp":1.82,"tv":29.98,"id":9631798},{"atb":[[1.82,99.21]],"id":9631798}],"con":true,"img":false}]}
{"op":"mcm","clk":"1349973019","pt":1588414278725,"mc":[{"id":"1.170370562","rc":[{"trd":[[1.89,2.76]],"ltp":1.89,"tv":2.76,"id":9631798},{"atl":[[1.89,34.07]],"id":9631798}],"con":true,"img":false}]}
{"op":"mcm","clk":"1349973031","pt":1588414279290,"mc":[{"id":"1.170370562","rc":[{"atb":[[1.64,266.19]],"id":9631798}],"con":true,"img":false}]}
{"op":"mcm","clk":"1349973093","pt":1588414281921,"mc":[{"id":"1.170370562","rc":[{"trd":[[1.82,32.82]],"ltp":1.82,"tv":32.82,"id":9631798},{"atb":[[1.82,97.79]],"id":9631798}],"con":true,"img":false}]}
{"op":"mcm","clk":"1349973108","pt":1588414282595,"mc":[{"id":"1.170370562","rc":[{"trd":[[1.82,37.98]],"ltp":1.82,"tv":37.98,"id":9631798},{"atb":[[1.82,95.21]],"id":9631798}],"con":true,"img":false}]}
{"op":"mcm","clk":"1349973125","pt":1588414283318,"mc":[{"id":"1.170370562","rc":[{"atl":[[2.28,265.95]],"id":9631798}],"con":true,"img":false}]}
{"op":"mcm","clk":"1349973130","pt":1588414283420,"mc":[{"id":"1.170370562","rc":[{"atb":[[1.69,112]],"id":9631798}],"con":true,"img":false}]}
{"op":"mcm","clk":"1349973151","pt":1588414283988,"mc":[{"id":"1.170370562","rc":[{"trd":[[1.82,38.18]],"ltp":1.82,"tv":38.18,"id":9631798},{"atb":[[1.82,95.11]],"id":9631798}],"con":true,"img":false}]}
{"op":"mcm","clk":"1349973188","pt":1588414285428,"mc":[{"id":"1.170370562","rc":[{"atb":[[1.79,0]],"id":9631798}],"con":true,"img":false}]}
{"op":"mcm","clk":"1349973195","pt":1588414285585,"mc":[{"id":"1.170370562","rc":[{"atb":[[1.73,0]],"id":9631798}],"con":true,"img":false}]}
{"op":"mcm","clk":"1349973202","pt":1588414285795,"mc":[{"id":"1.170370562","rc":[{"trd":[[1.89,2.81]],"ltp":1.89,"tv":2.81,"id":9631798},{"atl":[[1.89,34.05]],"id":9631798}],"con":true,"img":false}]}
{"op":"mcm","clk":"1349973210","pt":1588414286003,"mc":[{"id":"1.170370562","rc":[{"atb":[[1.78,0]],"id":9631798}],"con":true,"img":false}]}
{"op":"mcm","clk":"1349973235","pt":1588414286933,"mc":[{"id":"1.170370562","rc":[{"trd":[[1.82,38.42]],"ltp":1.82,"tv":38.42,"id":9631798},{"atb":[[1.82,94.99]],"id":9631798}],"con":true,"img":false}]}
{"op":"mcm","clk":"1349973243","pt":1588414287093,"mc":[{"id":"1.170370562","rc":[{"atb":[[1.68,0],[1.59,248.76],[1.62,0],[1.69,0],[1.82,0],[1.55,0]],"id":9631798}],"con":true,"img":false}]}
{"op":"mcm","clk":"1349973245","pt":1588414287195,"mc":[{"id":"1.170370562","rc":[{"atl":[[1.82,15.99],[1.9,0.12]],"id":9631798}],"con":true,"img":false}]}
{"op":"mcm","clk":"1349973268","pt":1588414288016,"mc":[{"id":"1.170370562","rc":[{"atl":[[1.82,24.75]],"id":9631798}],"con":true,"img":false}]}
{"op":"mcm","clk":"1349973276","pt":1588414288428,"mc":[{"id":"1.170370562","rc":[{"atl":[[1.82,33.62]],"id":9631798}],"con":true,"img":false}]}
{"op":"mcm","clk":"1349973288","pt":1588414288891,"mc":[{"id":"1.170370562","rc":[{"atl":[[1.88,0.11]],"id":9631798}],"con":true,"img":false}]}
{"op":"mcm","clk":"1349973292","pt":1588414288995,"mc":[{"id":"1.170370562","rc":[{"atl":[[1.82,42.48]],"id":9631798}],"con":true,"img":false}]}
{"op":"mcm","clk":"1349973293","pt":1588414289095,"mc":[{"id":"1.170370562","rc":[{"atl":[[1.8,1000]],"id":9631798}],"con":true,"img":false}]}
{"op":"mcm","clk":"1349973300","pt":1588414289301,"mc":[{"id":"1.170370562","rc":[{"atl":[[1.82,33.62]],"id":9631798}],"con":true,"img":false}]}
{"op":"mcm","clk":"1349973306","pt":1588414289403,"mc":[{"id":"1.170370562","rc":[{"atl":[[1.78,307.95]],"id":9631798}],"con":true,"img":false}]}
{"op":"mcm","clk":"1349973324","pt":1588414290019,"mc":[{"id":"1.170370562","rc":[{"atl":[[1.82,24.75]],"id":9631798}],"con":true,"img":false}]}
{"op":"mcm","clk":"1349973335","pt":1588414290431,"mc":[{"id":"1.170370562","rc":[{"trd":[[2.28,1.41]],"ltp":2.28,"tv":1.41,"id":9625043},{"trd":[[1.78,2.99]],"ltp":1.78,"tv":2.99,"id":9631798},{"atl":[[1.78,306.14]],"id":9631798}],"con":true,"img":false}]}
{"op":"mcm","clk":"1349973345","pt":1588414290690,"mc":[{"id":"1.170370562","rc":[{"atb":[[2.22,9.45]],"id":9625043}],"con":true,"img":false}]}
{"op":"mcm","clk":"1349973357","pt":1588414290896,"mc":[{"id":"1.170370562","rc":[{"atl":[[1.82,8.75]],"id":9631798}],"con":true,"img":false}]}
{"op":"mcm","clk":"1349973375","pt":1588414291727,"mc":[{"id":"1.170370562","rc":[{"atl":[[1.8,0]],"id":9631798}],"con":true,"img":false}]}
{"op":"mcm","clk":"1349973379","pt":1588414291936,"mc":[{"id":"1.170370562","rc":[{"atb":[[2.22,0]],"id":9625043},{"atl":[[1.82,500.77]],"id":9631798}],"con":true,"img":false}]}
{"op":"mcm","clk":"1349973390","pt":1588414292193,"mc":[{"id":"1.170370562","rc":[{"trd":[[2.28,4.04]],"ltp":2.28,"tv":4.04,"id":9625043},{"trd":[[1.78,6.36]],"ltp":1.78,"tv":6.36,"id":9631798},{"atl":[[1.78,302.77]],"id":9631798}],"con":true,"img":false}]}
{"op":"mcm","clk":"1349973399","pt":1588414292500,"mc":[{"id":"1.170370562","rc":[{"atl":[[1.82,492.02]],"id":9631798}],"con":true,"img":false}]}
{"op":"mcm","clk":"1349973404","pt":1588414292807,"mc":[{"id":"1.170370562","rc":[{"trd":[[2.28,4.31]],"ltp":2.28,"tv":4.31,"id":9625043},{"trd":[[1.78,6.7]],"ltp":1.78,"tv":6.7,"id":9631798},{"atl":[[1.78,302.43]],"id":9631798}],"con":true,"img":false}]}
{"op":"mcm","clk":"1349973413","pt":1588414293119,"mc":[{"id":"1.170370562","rc":[{"atl":[[1.82,0]],"id":9631798}],"con":true,"img":false}]}
{"op":"mcm","clk":"1349973431","pt":1588414293534,"mc":[{"id":"1.170370562","rc":[{"atl":[[1.8,112]],"id":9631798}],"con":true,"img":false}]}
{"op":"mcm","clk":"1349973444","pt":1588414293893,"mc":[{"id":"1.170370562","rc":[{"atl":[[1.82,3.93],[1.88,112.11]],"id":9631798}],"con":true,"img":false}]}
{"op":"mcm","clk":"1349973449","pt":1588414294098,"mc":[{"id":"1.170370562","rc":[{"atl":[[1.82,4.17]],"id":9631798}],"con":true,"img":false}]}
{"op":"mcm","clk":"1349973454","pt":1588414294200,"mc":[{"id":"1.170370562","rc":[{"atl":[[1.81,265.95]],"id":9631798}],"con":true,"img":false}]}
{"op":"mcm","clk":"1349973455","pt":1588414294302,"mc":[{"id":"1.170370562","rc":[{"atl":[[1.8,129.73]],"id":9631798}],"con":true,"img":false}]}
{"op":"mcm","clk":"1349973477","pt":1588414295022,"mc":[{"id":"1.170370562","rc":[{"atl":[[1.8,147.46]],"id":9631798}],"con":true,"img":false}]}
{"op":"mcm","clk":"1349973498","pt":1588414295797,"mc":[{"id":"1.170370562","rc":[{"atb":[[1.66,112]],"id":9631798},{"atl":[[1.77,17.73]],"id":9631798}],"con":true,"img":false}]}
{"op":"mcm","clk":"1349973509","pt":1588414296317,"mc":[{"id":"1.170370562","rc":[{"atl":[[1.77,35.46]],"id":9631798}],"con":true,"img":false}]}
{"op":"mcm","clk":"1349973515","pt":1588414296421,"mc":[{"id":"1.170370562","rc":[{"atb":[[1.68,112]],"id":9631798}],"con":true,"img":false}]}
{"op":"mcm","clk":"1349973518","pt":1588414296522,"mc":[{"id":"1.170370562","rc":[{"atb":[[1.64,0.23]],"id":9631798}],"con":true,"img":false}]}
{"op":"mcm","clk":"1349973522","pt":1588414296728,"mc":[{"id":"1.170370562","rc":[{"atb":[[1.67,265.95]],"id":9631798}],"con":true,"img":false}]}
{"op":"mcm","clk":"1349973531","pt":1588414297037,"mc":[{"id":"1.170370562","rc":[{"atl":[[1.73,88.65]],"id":9631798}],"con":true,"img":false}]}
{"op":"mcm","clk":"1349973537","pt":1588414297243,"mc":[{"id":"1.170370562","rc":[{"atb":[[1.67,377.95]],"id":9631798}],"con":true,"img":false}]}
{"op":"mcm","clk":"1349973544","pt":1588414297400,"mc":[{"id":"1.170370562","rc":[{"atb":[[1.68,129.73]],"id":9631798}],"con":true,"img":false}]}
{"op":"mcm","clk":"1349973562","pt":1588414297916,"mc":[{"id":"1.170370562","rc":[{"atb":[[1.68,147.46]],"id":9631798}],"con":true,"img":false}]}
{"op":"mcm","clk":"1349973595","pt":1588414299518,"mc":[{"id":"1.170370562","rc":[{"atl":[[1.77,301.41]],"id":9631798}],"con":true,"img":false}]}
{"op":"mcm","clk":"1349973604","pt":1588414299724,"mc":[{"id":"1.170370562","rc":[{"trd":[[1.73,580.39]],"ltp":1.73,"tv":580.39,"id":9631798},{"atl":[[1.73,88.53]],"id":9631798}],"con":true,"img":false}]}
{"op":"mcm","clk":"1349973614","pt":1588414300340,"mc":[{"id":"1.170370562","rc":[{"atl":[[1.81,0]],"id":9631798}],"con":true,"img":false}]}
{"op":"mcm","clk":"1349973624","pt":1588414300698,"mc":[{"id":"1.170370562","rc":[{"trd":[[2.48,8.28]],"ltp":2.48,"tv":8.28,"id":9625043},{"trd":[[1.68,554.58]],"ltp":1.68,"tv":554.58,"id":9631798},{"atb":[[1.68,135.22]],"id":9631798}],"con":true,"img":false}]}
{"op":"mcm","clk":"1349973629","pt":1588414300908,"mc":[{"id":"1.170370562","rc":[{"atl":[[1.8,112]],"id":9631798}],"con":true,"img":false}]}
{"op":"mcm","clk":"1349973650","pt":1588414301629,"mc":[{"id":"1.170370562","rc":[{"atb":[[1.58,265.95]],"id":9631798}],"con":true,"img":false}]}
{"op":"mcm","clk":"1349973657","pt":1588414301836,"mc":[{"id":"1.170370562","rc":[{"atb":[[1.65,0]],"id":9631798}],"con":true,"img":false}]}
{"op":"mcm","clk":"1349973667","pt":1588414302148,"mc":[{"id":"1.170370562","rc":[{"atl":[[1.9,0],[2.28,0]],"id":9631798}],"con":true,"img":false}]}
{"op":"mcm","clk":"1349973682","pt":1588414302618,"mc":[{"id":"1.170370562","rc":[{"atb":[[1.69,17.73]],"id":9631798}],"con":true,"img":false}]}
{"op":"mcm","clk":"1349973695","pt":1588414303029,"mc":[{"id":"1.170370562","rc":[{"atb":[[1.69,35.46]],"id":9631798}],"con":true,"img":false}]}
{"op":"mcm","clk":"1349973707","pt":1588414303339,"mc":[{"id":"1.170370562","rc":[{"atb":[[1.68,99.76]],"id":9631798}],"con":true,"img":false}]}
{"op":"mcm","clk":"1349973734","pt":1588414304116,"mc":[{"id":"1.170370562","rc":[{"trd":[[1.73,632.94]],"ltp":1.73,"tv":632.94,"id":9631798},{"atl":[[1.73,62.26]],"id":9631798}],"con":true,"img":false}]}
{"op":"mcm","clk":"1349973761","pt":1588414304836,"mc":[{"id":"1.170370562","rc":[{"atl":[[1.82,6.97]],"id":9631798}],"con":true,"img":false}]}
{"op":"mcm","clk":"1349973782","pt":1588414305453,"mc":[{"id":"1.170370562","rc":[{"atl":[[1.91,265.95]],"id":9631798}],"con":true,"img":false}]}
{"op":"mcm","clk":"1349973785","pt":1588414305555,"mc":[{"id":"1.170370562","rc":[{"atb":[[1.66,0]],"id":9631798}],"con":true,"img":false}]}
{"op":"mcm","clk":"1349973788","pt":1588414305673,"mc":[{"id":"1.170370562","rc":[{"trd":[[1.69,41.57]],"ltp":1.69,"tv":41.57,"id":9631798},{"atb":[[1.69,17.73]],"id":9631798}],"con":true,"img":false}]}
{"op":"mcm","clk":"1349973793","pt":1588414305713,"mc":[{"id":"1.170370562","rc":[{"atb":[[1.64,0]],"id":9631798}],"con":true,"img":false}]}
{"op":"mcm","clk":"1349973806","pt":1588414306228,"mc":[{"id":"1.170370562","rc":[{"trd":[[1.69,48.58]],"ltp":1.69,"tv":48.58,"id":9631798},{"atb":[[1.69,14.22]],"id":9631798}],"con":true,"img":false}]}
{"op":"mcm","clk":"1349973811","pt":1588414306436,"mc":[{"id":"1.170370562","rc":[{"atb":[[1.67,112]],"id":9631798}],"con":true,"img":false}]}
{"op":"mcm","clk":"1349973823","pt":1588414306743,"mc":[{"id":"1.170370562","rc":[{"atl":[[1.9,159.97]],"id":9631798}],"con":true,"img":false}]}
{"op":"mcm","clk":"1349973828","pt":1588414306949,"mc":[{"id":"1.170370562","rc":[{"atb":[[1.68,220.56]],"id":9631798}],"con":true,"img":false}]}
{"op":"mcm","clk":"1349973829","pt":1588414307051,"mc":[{"id":"1.170370562","rc":[{"atl":[[1.82,3.03]],"id":9631798}],"con":true,"img":false}]}
{"op":"mcm","clk":"1349973834","pt":1588414307154,"mc":[{"id":"1.170370562","rc":[{"atb":[[1.6,0]],"id":9631798}],"con":true,"img":false}]}
{"op":"mcm","clk":"1349973871","pt":1588414308548,"mc":[{"id":"1.170370562","rc":[{"atb":[[1.66,0.11]],"id":9631798}],"con":true,"img":false}]}
{"op":"mcm","clk":"1349973878","pt":1588414308761,"mc":[{"id":"1.170370562","rc":[{"trd":[[1.73,641.81]],"ltp":1.73,"tv":641.81,"id":9631798},{"atl":[[1.73,57.82]],"id":9631798}],"con":true,"img":false}]}
{"op":"mcm","clk":"1349973886","pt":1588414308916,"mc":[{"id":"1.170370562","rc":[{"trd":[[1.73,646.01]],"ltp":1.73,"tv":646.01,"id":9631798},{"atl":[[1.73,55.72]],"id":9631798}],"con":true,"img":false}]}
{"op":"mcm","clk":"1349974015","pt":1588414312164,"mc":[{"id":"1.170370562","rc":[{"trd":[[1.69,56.45]],"ltp":1.69,"tv":56.45,"id":9631798},{"atb":[[1.69,10.29]],"id":9631798}],"con":true,"img":false}]}
{"op":"mcm","clk":"1349974022","pt":1588414312267,"mc":[{"id":"1.170370562","rc":[{"atb":[[1.66,48.11]],"id":9631798}],"con":true,"img":false}]}
{"op":"mcm","clk":"1349974031","pt":1588414312525,"mc":[{"id":"1.170370562","rc":[{"atl":[[1.77,35.46]],"id":9631798}],"con":true,"img":false}]}
{"op":"mcm","clk":"1349974053","pt":1588414313249,"mc":[{"id":"1.170370562","rc":[{"atl":[[1.73,0]],"id":9631798}],"con":true,"img":false}]}
{"op":"mcm","clk":"1349974096","pt":1588414314643,"mc":[{"id":"1.170370562","rc":[{"trd":[[1.69,63.45]],"ltp":1.69,"tv":63.45,"id":9631798},{"atb":[[1.69,6.79]],"id":9631798}],"con":true,"img":false}]}
{"op":"mcm","clk":"1349974138","pt":1588414316141,"mc":[{"id":"1.170370562","rc":[{"trd":[[1.69,64.45]],"ltp":1.69,"tv":64.45,"id":9631798},{"atb":[[1.69,6.29]],"id":9631798}],"con":true,"img":false}]}
{"op":"mcm","clk":"1349974178","pt":1588414317328,"mc":[{"id":"1.170370562","rc":[{"atb":[[1.55,4]],"id":9631798}],"con":true,"img":false}]}
{"op":"mcm","clk":"1349974230","pt":1588414319345,"mc":[{"id":"1.170370562","rc":[{"atb":[[1.67,0]],"id":9631798}],"con":true,"img":false}]}
{"op":"mcm","clk":"1349974330","pt":1588414322649,"mc":[{"id":"1.170370562","rc":[{"atl":[[1.77,0]],"id":9631798}],"con":true,"img":false}]}
{"op":"mcm","clk":"1349974338","pt":1588414322753,"mc":[{"id":"1.170370562","rc":[{"atb":[[1.6,222]],"id":9631798}],"con":true,"img":false}]}
{"op":"mcm","clk":"1349974343","pt":1588414322855,"mc":[{"id":"1.170370562","rc":[{"atl":[[1.78,0]],"id":9631798}],"con":true,"img":false}]}
{"op":"mcm","clk":"1349974372","pt":1588414323583,"mc":[{"id":"1.170370562","rc":[{"trd":[[1.69,71.46]],"ltp":1.69,"tv":71.46,"id":9631798},{"atb":[[1.69,2.79]],"id":9631798}],"con":true,"img":false}]}
{"op":"mcm","clk":"1349974382","pt":1588414323739,"mc":[{"id":"1.170370562","rc":[{"atl":[[1.8,0],[1.88,0.11]],"id":9631798}],"con":true,"img":false}]}
{"op":"mcm","clk":"1349974455","pt":1588414325871,"mc":[{"id":"1.170370562","rc":[{"trd":[[1.82,44.49]],"ltp":1.82,"tv":44.49,"id":9631798},{"atb":[[1.82,996.97]],"id":9631798},{"atl":[[1.82,0]],"id":9631798}],"con":true,"img":false}]}
{"op":"mcm","clk":"1349974463","pt":1588414326079,"mc":[{"id":"1.170370562","rc":[{"atb":[[1.82,0]],"id":9631798}],"con":true,"img":false}]}
{"op":"mcm","clk":"1349974487","pt":1588414326752,"mc":[{"id":"1.170370562","rc":[{"atb":[[1.86,360.74],[1.84,360.74]],"id":9631798}],"con":true,"img":false}]}
{"op":"mcm","clk":"1349974489","pt":1588414326859,"mc":[{"id":"1.170370562","rc":[{"atb":[[1.82,492.02]],"id":9631798}],"con":true,"img":false}]}
{"op":"mcm","clk":"1349974523","pt":1588414328046,"mc":[{"id":"1.170370562","rc":[{"atb":[[1.78,17.73]],"id":9631798}],"con":true,"img":false}]}
{"op":"mcm","clk":"1349974555","pt":1588414328771,"mc":[{"id":"1.170370562","rc":[{"atb":[[1.82,0]],"id":9631798}],"con":true,"img":false}]}
{"op":"mcm","clk":"1349974571","pt":1588414329085,"mc":[{"id":"1.170370562","rc":[{"atb":[[1.46,0]],"id":9631798}],"con":true,"img":false}]}
{"op":"mcm","clk":"1349974586","pt":1588414329493,"mc":[{"id":"1.170370562","rc":[{"atb":[[1.78,35.46]],"id":9631798}],"con":true,"img":false}]}
{"op":"mcm","clk":"1349974622","pt":1588414330694,"mc":[{"id":"1.170370562","rc":[{"atb":[[1.82,222]],"id":9631798}],"con":true,"img":false}]}
{"op":"mcm","clk":"1349974624","pt":1588414330794,"mc":[{"id":"1.170370562","rc":[{"atb":[[1.74,112]],"id":9631798}],"con":true,"img":false}]}
{"op":"mcm","clk":"1349974644","pt":1588414331262,"mc":[{"id":"1.170370562","rc":[{"atb":[[1.78,147.46]],"id":9631798}],"con":true,"img":false}]}
{"op":"mcm","clk":"1349974647","pt":1588414331365,"mc":[{"id":"1.170370562","rc":[{"atb":[[1.79,265.95]],"id":9631798}],"con":true,"img":false}]}
{"op":"mcm","clk":"1349974652","pt":1588414331472,"mc":[{"id":"1.170370562","rc":[{"atb":[[1.82,0]],"id":9631798}],"con":true,"img":false}]}
{"op":"mcm","clk":"1349974734","pt":1588414333480,"mc":[{"id":"1.170370562","rc":[{"atb":[[1.98,0]],"id":9625043},{"atl":[[3.1,0]],"id":9625043},{"atb":[[1.51,0]],"id":9631798},{"atl":[[1.93,0]],"id":9631798}],"con":true,"img":false}]}
{"op":"mcm","clk":"1349974760","pt":1588414333999,"mc":[{"id":"1.170370562","rc":[{"atl":[[1.97,17.73]],"id":9631798}],"con":true,"img":false}]}
{"op":"mcm","clk":"1349974777","pt":1588414334461,"mc":[{"id":"1.170370562","rc":[{"atl":[[2.36,1.77]],"id":9625043},{"trd":[[1.86,5.98]],"ltp":1.86,"tv":5.98,"id":9631798},{"atb":[[1.86,357.75]],"id":9631798}],"con":true,"img":false}]}
{"op":"mcm","clk":"1349974782","pt":1588414334669,"mc":[{"id":"1.170370562","rc":[{"atl":[[1.97,35.46],[1.91,0]],"id":9631798}],"con":true,"img":false}]}
{"op":"mcm","clk":"1349974786","pt":1588414334877,"mc":[{"id":"1.170370562","rc":[{"atb":[[1.84,0],[1.5,28.13]],"id":9631798}],"con":true,"img":false}]}
{"op":"mcm","clk":"1349974809","pt":1588414335662,"mc":[{"id":"1.170370562","rc":[{"atl":[[1.9,0]],"id":9631798}],"con":true,"img":false}]}
{"op":"mcm","clk":"1349974816","pt":1588414335868,"mc":[{"id":"1.170370562","rc":[{"atb":[[1.6,0]],"id":9631798}],"con":true,"img":false}]}
{"op":"mcm","clk":"1349974834","pt":1588414336487,"mc":[{"id":"1.170370562","rc":[{"atl":[[2.42,265.95]],"id":9631798}],"con":true,"img":false}]}
{"op":"mcm","clk":"1349974851","pt":1588414337158,"mc":[{"id":"1.170370562","rc":[{"atb":[[1.87,47.99]],"id":9631798}],"con":true,"img":false}]}
{"op":"mcm","clk":"1349974870","pt":1588414337779,"mc":[{"id":"1.170370562","rc":[{"trd":[[1.87,4.71]],"ltp":1.87,"tv":4.71,"id":9631798},{"atb":[[1.87,45.63]],"id":9631798}],"con":true,"img":false}]}
{"op":"mcm","clk":"1349974880","pt":1588414337988,"mc":[{"id":"1.170370562","rc":[{"atb":[[1.58,0]],"id":9631798}],"con":true,"img":false}]}
{"op":"mcm","clk":"1349974882","pt":1588414338089,"mc":[{"id":"1.170370562","rc":[{"atb":[[1.72,222]],"id":9631798}],"con":true,"img":false}]}
{"op":"mcm","clk":"1349974895","pt":1588414338503,"mc":[{"id":"1.170370562","rc":[{"trd":[[1.89,70.92],[1.88,0.47]],"ltp":1.89,"tv":71.39,"id":9631798},{"atb":[[1.91,214.58]],"id":9631798},{"atl":[[1.89,0],[1.88,0]],"id":9631798}],"con":true,"img":false}]}
{"op":"mcm","clk":"1349974912","pt":1588414338966,"mc":[{"id":"1.170370562","rc":[{"trd":[[2.1,78.09]],"ltp":2.1,"tv":78.09,"id":9625043},{"trd":[[1.91,7.01]],"ltp":1.91,"tv":7.01,"id":9631798},{"atb":[[1.91,209.71],[1.69,224.79]],"id":9631798}],"con":true,"img":false}]}
