{"op":"mcm","clk":"1349974916","pt":1588414339173,"mc":[{"id":"1.170370562","rc":[{"trd":[[1.91,14.02]],"ltp":1.91,"tv":14.02,"id":9631798},{"atb":[[1.91,206.2]],"id":9631798}],"con":true,"img":false}]}
{"op":"mcm","clk":"1349974925","pt":1588414339379,"mc":[{"id":"1.170370562","rc":[{"trd":[[1.91,37.02]],"ltp":1.91,"tv":37.02,"id":9631798},{"atb":[[1.91,194.7]],"id":9631798}],"con":true,"img":false}]}
{"op":"mcm","clk":"1349974934","pt":1588414339691,"mc":[{"id":"1.170370562","rc":[{"atb":[[1.79,0]],"id":9631798}],"con":true,"img":false}]}
{"op":"mcm","clk":"1349974937","pt":1588414339794,"mc":[{"id":"1.170370562","rc":[{"atb":[[1.66,0.11]],"id":9631798},{"atl":[[1.94,265.95]],"id":9631798}],"con":true,"img":false}]}
{"op":"mcm","clk":"1349974949","pt":1588414340004,"mc":[{"id":"1.170370562","rc":[{"atb":[[1.8,500]],"id":9631798}],"con":true,"img":false}]}
{"op":"mcm","clk":"1349974958","pt":1588414340214,"mc":[{"id":"1.170370562","rc":[{"trd":[[1.91,37.42]],"ltp":1.91,"tv":37.42,"id":9631798},{"atb":[[1.91,194.5],[1.62,222]],"id":9631798}],"con":true,"img":false}]}
{"op":"mcm","clk":"1349974974","pt":1588414340574,"mc":[{"id":"1.170370562","rc":[{"atb":[[1.89,2.57]],"id":9631798}],"con":true,"img":false}]}
{"op":"mcm","clk":"1349975000","pt":1588414341299,"mc":[{"id":"1.170370562","rc":[{"trd":[[2.1,84.87]],"ltp":2.1,"tv":84.87,"id":9625043},{"trd":[[1.91,62.59]],"ltp":1.91,"tv":62.59,"id":9631798},{"atb":[[1.91,178.19]],"id":9631798}],"con":true,"img":false}]}
{"op":"mcm","clk":"1349975019","pt":1588414341919,"mc":[{"id":"1.170370562","rc":[{"atb":[[1.73,265.95]],"id":9631798},{"atl":[[1.94,0]],"id":9631798}],"con":true,"img":false}]}
{"op":"mcm","clk":"1349975023","pt":1588414342179,"mc":[{"id":"1.170370562","rc":[{"trd":[[1.91,86.17]],"ltp":1.91,"tv":86.17,"id":9631798},{"atb":[[1.91,166.4],[1.86,0]],"id":9631798}],"con":true,"img":false}]}
{"op":"mcm","clk":"1349975030","pt":1588414342385,"mc":[{"id":"1.170370562","rc":[{"trd":[[1.91,110.17]],"ltp":1.91,"tv":110.17,"id":9631798},{"atb":[[1.91,154.4],[1.1,0]],"id":9631798}],"con":true,"img":false}]}
{"op":"mcm","clk":"1349975074","pt":1588414343727,"mc":[{"id":"1.170370562","rc":[{"trd":[[1.91,111.82]],"ltp":1.91,"tv":111.82,"id":9631798},{"atb":[[1.91,153.58]],"id":9631798}],"con":true,"img":false}]}
{"op":"mcm","clk":"1349975080","pt":1588414343887,"mc":[{"id":"1.170370562","rc":[{"trd":[[1.91,112.22]],"ltp":1.91,"tv":112.22,"id":9631798},{"atb":[[1.91,153.38]],"id":9631798}],"con":true,"img":false}]}
{"op":"mcm","clk":"1349975115","pt":1588414344717,"mc":[{"id":"1.170370562","rc":[{"trd":[[2.1,87.45]],"ltp":2.1,"tv":87.45,"id":9625043},{"trd":[[1.91,115.05]],"ltp":1.91,"tv":115.05,"id":9631798},{"atb":[[1.91,150.55]],"id":9631798}],"con":true,"img":false}]}
{"op":"mcm","clk":"1349975125","pt":1588414344922,"mc":[{"id":"1.170370562","rc":[{"atb":[[1.68,268.55]],"id":9631798}],"con":true,"img":false}]}
{"op":"mcm","clk":"1349975129","pt":1588414345022,"mc":[{"id":"1.170370562","rc":[{"atb":[[1.89,0]],"id":9631798}],"con":true,"img":false}]}
{"op":"mcm","clk":"1349975138","pt":1588414345184,"mc":[{"id":"1.170370562","rc":[{"atb":[[1.78,112],[1.69,222]],"id":9631798},{"atl":[[1.97,0]],"id":9631798}],"con":true,"img":false}]}
{"op":"mcm","clk":"1349975155","pt":1588414345801,"mc":[{"id":"1.170370562","rc":[{"atb":[[1.89,2.57]],"id":9631798}],"con":true,"img":false}]}
{"op":"mcm","clk":"1349975167","pt":1588414346113,"mc":[{"id":"1.170370562","rc":[{"atl":[[2.12,14.65]],"id":9625043}],"con":true,"img":false}]}
{"op":"mcm","clk":"1349975188","pt":1588414346475,"mc":[{"id":"1.170370562","rc":[{"atb":[[1.78,0]],"id":9631798}],"con":true,"img":false}]}
{"op":"mcm","clk":"1349975235","pt":1588414348285,"mc":[{"id":"1.170370562","rc":[{"atb":[[1.81,112]],"id":9631798}],"con":true,"img":false}]}
{"op":"mcm","clk":"1349975247","pt":1588414348904,"mc":[{"id":"1.170370562","rc":[{"atb":[[1.99,1000]],"id":9631798}],"con":true,"img":false}]}
{"op":"mcm","clk":"1349975268","pt":1588414349573,"mc":[{"id":"1.170370562","rc":[{"atb":[[2.02,492.02]],"id":9631798}],"con":true,"img":false}]}
{"op":"mcm","clk":"1349975321","pt":1588414351174,"mc":[{"id":"1.170370562","rc":[{"atb":[[1.98,17.73]],"id":9631798}],"con":true,"img":false}]}
{"op":"mcm","clk":"1349975336","pt":1588414351688,"mc":[{"id":"1.170370562","rc":[{"atb":[[2.1,761.8],[1.98,35.46]],"id":9631798}],"con":true,"img":false}]}
{"op":"mcm","clk":"1349975338","pt":1588414351793,"mc":[{"id":"1.170370562","rc":[{"trd":[[2.1,0.23]],"ltp":2.1,"tv":0.23,"id":9631798},{"atb":[[2.1,761.68]],"id":9631798}],"con":true,"img":false}]}
{"op":"mcm","clk":"1349975347","pt":1588414352419,"mc":[{"id":"1.170370562","rc":[{"atb":[[1.8,0]],"id":9631798}],"con":true,"img":false}]}
{"op":"mcm","clk":"1349975352","pt":1588414352575,"mc":[{"id":"1.170370562","rc":[{"atb":[[1.89,0]],"id":9631798}],"con":true,"img":false}]}
{"op":"mcm","clk":"1349975356","pt":1588414352679,"mc":[{"id":"1.170370562","rc":[{"trd":[[2.1,1.06]],"ltp":2.1,"tv":1.06,"id":9631798},{"atb":[[2.1,761.27]],"id":9631798}],"con":true,"img":false}]}
{"op":"mcm","clk":"1349975361","pt":1588414352887,"mc":[{"id":"1.170370562","rc":[{"atb":[[1.99,0]],"id":9631798}],"con":true,"img":false}]}
{"op":"mcm","clk":"1349975366","pt":1588414352991,"mc":[{"id":"1.170370562","rc":[{"atb":[[2.02,0]],"id":9631798}],"con":true,"img":false}]}
{"op":"mcm","clk":"1349975371","pt":1588414353095,"mc":[{"id":"1.170370562","rc":[{"atb":[[1.5,0.11]],"id":9631798},{"atl":[[2.22,0]],"id":9631798}],"con":true,"img":false}]}
{"op":"mcm","clk":"1349975415","pt":1588414354281,"mc":[{"id":"1.170370562","rc":[{"atb":[[1.98,0]],"id":9631798}],"con":true,"img":false}]}
{"op":"mcm","clk":"1349975434","pt":1588414355011,"mc":[{"id":"1.170370562","rc":[{"atb":[[2,17.73]],"id":9631798}],"con":true,"img":false}]}
{"op":"mcm","clk":"1349975445","pt":1588414355321,"mc":[{"id":"1.170370562","rc":[{"atl":[[1.98,500]],"id":9625043}],"con":true,"img":false}]}
{"op":"mcm","clk":"1349975454","pt":1588414355526,"mc":[{"id":"1.170370562","rc":[{"atl":[[1.96,240]],"id":9625043},{"atb":[[2.04,17.73]],"id":9631798}],"con":true,"img":false}]}
{"op":"mcm","clk":"1349975463","pt":1588414355684,"mc":[{"id":"1.170370562","rc":[{"atl":[[1.91,240]],"id":9625043}],"con":true,"img":false}]}
{"op":"mcm","clk":"1349975475","pt":1588414355890,"mc":[{"id":"1.170370562","rc":[{"atb":[[1.91,0],[2.06,17.73]],"id":9631798}],"con":true,"img":false}]}
{"op":"mcm","clk":"1349975500","pt":1588414356413,"mc":[{"id":"1.170370562","rc":[{"trd":[[1.91,20.65]],"ltp":1.91,"tv":20.65,"id":9625043},{"atl":[[1.91,229.67]],"id":9625043},{"atb":[[2.08,17.73]],"id":9631798}],"con":true,"img":false}]}
{"op":"mcm","clk":"1349975507","pt":1588414356520,"mc":[{"id":"1.170370562","rc":[{"atb":[[2.08,283.68]],"id":9631798}],"con":true,"img":false}]}
{"op":"mcm","clk":"1349975528","pt":1588414357032,"mc":[{"id":"1.170370562","rc":[{"trd":[[1.91,41.31]],"ltp":1.91,"tv":41.31,"id":9625043},{"atl":[[1.91,219.34]],"id":9625043}],"con":true,"img":false}]}
{"op":"mcm","clk":"1349975531","pt":1588414357085,"mc":[{"id":"1.170370562","rc":[{"atb":[[2.04,0]],"id":9631798}],"con":true,"img":false}]}
{"op":"mcm","clk":"1349975535","pt":1588414357188,"mc":[{"id":"1.170370562","rc":[{"atb":[[2.08,505.68]],"id":9631798}],"con":true,"img":false}]}
{"op":"mcm","clk":"1349975550","pt":1588414357606,"mc":[{"id":"1.170370562","rc":[{"atb":[[2.14,222]],"id":9631798}],"con":true,"img":false}]}
{"op":"mcm","clk":"1349975553","pt":1588414357710,"mc":[{"id":"1.170370562","rc":[{"atb":[[2.08,283.68]],"id":9631798}],"con":true,"img":false}]}
{"op":"mcm","clk":"1349975557","pt":1588414357812,"mc":[{"id":"1.170370562","rc":[{"atb":[[2,0],[2.12,17.73]],"id":9631798}],"con":true,"img":false}]}
{"op":"mcm","clk":"1349975565","pt":1588414358020,"mc":[{"id":"1.170370562","rc":[{"atl":[[1.98,0]],"id":9625043}],"con":true,"img":false}]}
{"op":"mcm","clk":"1349975573","pt":1588414358227,"mc":[{"id":"1.170370562","rc":[{"atb":[[2.14,239.73]],"id":9631798}],"con":true,"img":false}]}
{"op":"mcm","clk":"1349975590","pt":1588414358587,"mc":[{"id":"1.170370562","rc":[{"atl":[[1.85,112]],"id":9625043}],"con":true,"img":false}]}
{"op":"mcm","clk":"1349975594","pt":1588414358694,"mc":[{"id":"1.170370562","rc":[{"atb":[[2.06,0]],"id":9631798}],"con":true,"img":false}]}
{"op":"mcm","clk":"1349975600","pt":1588414358796,"mc":[{"id":"1.170370562","rc":[{"trd":[[1.85,122.44]],"ltp":1.85,"tv":122.44,"id":9625043},{"atl":[[1.85,50.78]],"id":9625043}],"con":true,"img":false}]}
{"op":"mcm","clk":"1349975602","pt":1588414358912,"mc":[{"id":"1.170370562","rc":[{"atb":[[1.62,258.92]],"id":9631798},{"atl":[[2.6,249.59]],"id":9631798}],"con":true,"img":false}]}
{"op":"mcm","clk":"1349975631","pt":1588414360101,"mc":[{"id":"1.170370562","rc":[{"atb":[[1.93,265.95]],"id":9631798}],"con":true,"img":false}]}
{"op":"mcm","clk":"1349975703","pt":1588414361919,"mc":[{"id":"1.170370562","rc":[{"trd":[[1.85,127.62]],"ltp":1.85,"tv":127.62,"id":9625043},{"atl":[[1.85,45.6],[1.9,8.86]],"id":9625043},{"trd":[[2.16,4.43]],"ltp":2.16,"tv":4.43,"id":9631798}],"con":true,"img":false}]}
{"op":"mcm","clk":"1349975706","pt":1588414362020,"mc":[{"id":"1.170370562","rc":[{"atl":[[1.89,500]],"id":9625043}],"con":true,"img":false}]}
{"op":"mcm","clk":"1349975710","pt":1588414362128,"mc":[{"id":"1.170370562","rc":[{"atl":[[3.25,265.95]],"id":9631798}],"con":true,"img":false}]}
{"op":"mcm","clk":"1349975715","pt":1588414362233,"mc":[{"id":"1.170370562","rc":[{"trd":[[1.85,132.8]],"ltp":1.85,"tv":132.8,"id":9625043},{"atl":[[1.85,40.42]],"id":9625043},{"trd":[[2.16,8.86]],"ltp":2.16,"tv":8.86,"id":9631798}],"con":true,"img":false}]}
{"op":"mcm","clk":"1349975719","pt":1588414362337,"mc":[{"id":"1.170370562","rc":[{"atb":[[2.12,0]],"id":9631798}],"con":true,"img":false}]}
{"op":"mcm","clk":"1349975750","pt":1588414363011,"mc":[{"id":"1.170370562","rc":[{"atb":[[2.08,265.95]],"id":9631798}],"con":true,"img":false}]}
{"op":"mcm","clk":"1349975768","pt":1588414363526,"mc":[{"id":"1.170370562","rc":[{"atb":[[2.08,0]],"id":9631798}],"con":true,"img":false}]}
{"op":"mcm","clk":"1349975806","pt":1588414364614,"mc":[{"id":"1.170370562","rc":[{"atl":[[1.9,0]],"id":9625043},{"atb":[[2.18,17.73]],"id":9631798}],"con":true,"img":false}]}
{"op":"mcm","clk":"1349975811","pt":1588414364717,"mc":[{"id":"1.170370562","rc":[{"atl":[[2.36,0]],"id":9625043}],"con":true,"img":false}]}
{"op":"mcm","clk":"1349975821","pt":1588414364924,"mc":[{"id":"1.170370562","rc":[{"atb":[[2.1,0]],"id":9631798}],"con":true,"img":false}]}
{"op":"mcm","clk":"1349975845","pt":1588414365443,"mc":[{"id":"1.170370562","rc":[{"atl":[[2.42,0]],"id":9631798}],"con":true,"img":false}]}
{"op":"mcm","clk":"1349975856","pt":1588414365754,"mc":[{"id":"1.170370562","rc":[{"trd":[[1.85,134.53]],"ltp":1.85,"tv":134.53,"id":9625043},{"atl":[[1.85,39.55]],"id":9625043},{"atb":[[2.14,17.73],[1.62,36.92],[1.69,0],[1.72,0]],"id":9631798}],"con":true,"img":false}]}
{"op":"mcm","clk":"1349975869","pt":1588414366016,"mc":[{"id":"1.170370562","rc":[{"atb":[[2.18,35.46]],"id":9631798}],"con":true,"img":false}]}
{"op":"mcm","clk":"1349975887","pt":1588414366533,"mc":[{"id":"1.170370562","rc":[{"trd":[[1.8,4]],"ltp":1.8,"tv":4.0,"id":9625043},{"atb":[[1.8,0]],"id":9625043},{"atl":[[1.8,0.57]],"id":9625043}],"con":true,"img":false}]}
{"op":"mcm","clk":"1349975906","pt":1588414367156,"mc":[{"id":"1.170370562","rc":[{"atb":[[1.75,7.36]],"id":9625043}],"con":true,"img":false}]}
{"op":"mcm","clk":"1349975914","pt":1588414367415,"mc":[{"id":"1.170370562","rc":[{"trd":[[1.75,14.73]],"ltp":1.75,"tv":14.73,"id":9625043},{"atb":[[1.75,0]],"id":9625043},{"atl":[[1.75,7.93]],"id":9625043}],"con":true,"img":false}]}
{"op":"mcm","clk":"1349975915","pt":1588414367517,"mc":[{"id":"1.170370562","rc":[{"trd":[[1.75,14.97]],"ltp":1.75,"tv":14.97,"id":9625043},{"atl":[[1.75,7.81]],"id":9625043}],"con":true,"img":false}]}
{"op":"mcm","clk":"1349975925","pt":1588414367931,"mc":[{"id":"1.170370562","rc":[{"atb":[[1.01,991.72]],"id":9625043},{"atb":[[1.01,1090.13]],"id":9631798}],"con":true,"img":false}]}
{"op":"mcm","clk":"1349975932","pt":1588414368140,"mc":[{"id":"1.170370562","rc":[{"atl":[[2.6,0]],"id":9631798}],"con":true,"img":false}]}
{"op":"mcm","clk":"1349975943","pt":1588414368348,"mc":[{"id":"1.170370562","rc":[{"atl":[[1.84,8.86]],"id":9625043}],"con":true,"img":false}]}
{"op":"mcm","clk":"1349975948","pt":1588414368450,"mc":[{"id":"1.170370562","rc":[{"trd":[[1.85,255.42],[1.84,17.72],[1.8,10.3],[1.75,30.6]],"ltp":1.85,"tv":314.03,"id":9625043},{"atb":[[1.85,98.8]],"id":9625043},{"atl":[[1.8,0],[1.84,0],[1.85,0],[1.75,0]],"id":9625043},{"trd":[[2.18,35.46]],"ltp":2.18,"tv":35.46,"id":9631798},{"atb":[[2.18,0]],"id":9631798}],"con":true,"img":false}]}
{"op":"mcm","clk":"1349975957","pt":1588414368657,"mc":[{"id":"1.170370562","rc":[{"atb":[[1.01,989.83]],"id":9625043},{"atb":[[1.01,1088.18]],"id":9631798}],"con":true,"img":false}]}
{"op":"mcm","clk":"1349975973","pt":1588414369220,"mc":[{"id":"1.170370562","rc":[{"atb":[[1.85,110.58]],"id":9625043}],"con":true,"img":false}]}
{"op":"mcm","clk":"1349975979","pt":1588414369425,"mc":[{"id":"1.170370562","rc":[{"atb":[[1.01,989.72],[1.71,50.62]],"id":9625043},{"atb":[[1.01,1088.13]],"id":9631798}],"con":true,"img":false}]}
{"op":"mcm","clk":"1349975989","pt":1588414369836,"mc":[{"id":"1.170370562","rc":[{"atl":[[1.91,0],[1.96,0]],"id":9625043},{"atb":[[1.54,7]],"id":9631798}],"con":true,"img":false}]}
{"op":"mcm","clk":"1349975996","pt":1588414370244,"mc":[{"id":"1.170370562","rc":[{"trd":[[1.85,265.42]],"ltp":1.85,"tv":265.42,"id":9625043},{"atb":[[1.85,105.58]],"id":9625043}],"con":true,"img":false}]}
{"op":"mcm","clk":"1349975999","pt":1588414370348,"mc":[{"id":"1.170370562","rc":[{"atb":[[1.48,0]],"id":9631798}],"con":true,"img":false}]}
{"op":"mcm","clk":"1349976007","pt":1588414370553,"mc":[{"id":"1.170370562","rc":[{"trd":[[1.89,125.81],[1.88,20.18]],"ltp":1.89,"tv":145.99,"id":9625043},{"atl":[[1.89,437.09]],"id":9625043},{"trd":[[2.14,17.73]],"ltp":2.14,"tv":17.73,"id":9631798},{"atb":[[2.14,0]],"id":9631798}],"con":true,"img":false}]}
{"op":"mcm","clk":"1349976027","pt":1588414371016,"mc":[{"id":"1.170370562","rc":[{"atb":[[1.41,1.77]],"id":9631798}],"con":true,"img":false}]}
{"op":"mcm","clk":"1349976047","pt":1588414371732,"mc":[{"id":"1.170370562","rc":[{"trd":[[1.85,265.63]],"ltp":1.85,"tv":265.63,"id":9625043},{"atb":[[1.85,105.48]],"id":9625043}],"con":true,"img":false}]}
{"op":"mcm","clk":"1349976053","pt":1588414371838,"mc":[{"id":"1.170370562","rc":[{"atb":[[1.85,110.74]],"id":9625043},{"atb":[[1.59,0]],"id":9631798}],"con":true,"img":false}]}
{"op":"mcm","clk":"1349976059","pt":1588414372041,"mc":[{"id":"1.170370562","rc":[{"atb":[[1.68,168.79],[1.81,0],[1.74,0],[1.87,0]],"id":9631798}],"con":true,"img":false}]}
{"op":"mcm","clk":"1349976064","pt":1588414372143,"mc":[{"id":"1.170370562","rc":[{"trd":[[1.71,101.24],[1.85,487.12]],"ltp":1.71,"tv":588.36,"id":9625043},{"atb":[[1.85,0],[1.71,0]],"id":9625043},{"atl":[[1.7,838.63]],"id":9625043}],"con":true,"img":false}]}
{"op":"mcm","clk":"1349976111","pt":1588414373221,"mc":[{"id":"1.170370562","rc":[{"atl":[[1.66,492.02]],"id":9625043}],"con":true,"img":false}]}
{"op":"mcm","clk":"1349976121","pt":1588414373426,"mc":[{"id":"1.170370562","rc":[{"trd":[[1.66,15.63]],"ltp":1.66,"tv":15.63,"id":9625043},{"atl":[[1.66,484.2]],"id":9625043}],"con":true,"img":false}]}
{"op":"mcm","clk":"1349976124","pt":1588414373529,"mc":[{"id":"1.170370562","rc":[{"atb":[[1.34,0]],"id":9631798}],"con":true,"img":false}]}
{"op":"mcm","clk":"1349976132","pt":1588414373736,"mc":[{"id":"1.170370562","rc":[{"atb":[[1.35,0]],"id":9631798}],"con":true,"img":false}]}
{"op":"mcm","clk":"1349976142","pt":1588414374042,"mc":[{"id":"1.170370562","rc":[{"trd":[[1.66,412.74]],"ltp":1.66,"tv":412.74,"id":9625043},{"atl":[[1.66,87.09]],"id":9625043},{"trd":[[2.5,263.67]],"ltp":2.5,"tv":263.67,"id":9631798}],"con":true,"img":false}]}
{"op":"mcm","clk":"1349976152","pt":1588414374354,"mc":[{"id":"1.170370562","rc":[{"atb":[[1.4,88.65]],"id":9625043}],"con":true,"img":false}]}
{"op":"mcm","clk":"1349976160","pt":1588414374556,"mc":[{"id":"1.170370562","rc":[{"trd":[[1.66,478.89]],"ltp":1.66,"tv":478.89,"id":9625043},{"atl":[[1.66,21.05]],"id":9625043},{"trd":[[2.5,307.45]],"ltp":2.5,"tv":307.45,"id":9631798},{"atb":[[2.26,0.05]],"id":9631798}],"con":true,"img":false}]}
{"op":"mcm","clk":"1349976187","pt":1588414375068,"mc":[{"id":"1.170370562","rc":[{"atb":[[1.15,0]],"id":9631798}],"con":true,"img":false}]}
{"op":"mcm","clk":"1349976195","pt":1588414375326,"mc":[{"id":"1.170370562","rc":[{"atl":[[1.75,43.79]],"id":9625043}],"con":true,"img":false}]}
{"op":"mcm","clk":"1349976201","pt":1588414375534,"mc":[{"id":"1.170370562","rc":[{"trd":[[1.66,479.83]],"ltp":1.66,"tv":479.83,"id":9625043},{"atl":[[1.66,20.58]],"id":9625043}],"con":true,"img":false}]}
{"op":"mcm","clk":"1349976222","pt":1588414376045,"mc":[{"id":"1.170370562","rc":[{"atb":[[1.62,0]],"id":9631798}],"con":true,"img":false}]}
{"op":"mcm","clk":"1349976247","pt":1588414376761,"mc":[{"id":"1.170370562","rc":[{"atb":[[1.44,4.03]],"id":9625043}],"con":true,"img":false}]}
{"op":"mcm","clk":"1349976275","pt":1588414377529,"mc":[{"id":"1.170370562","rc":[{"atl":[[1.85,5.88]],"id":9625043}],"con":true,"img":false}]}
{"op":"mcm","clk":"1349976298","pt":1588414378350,"mc":[{"id":"1.170370562","rc":[{"trd":[[1.66,481.99]],"ltp":1.66,"tv":481.99,"id":9625043},{"atl":[[1.66,19.5]],"id":9625043}],"con":true,"img":false}]}
{"op":"mcm","clk":"1349976305","pt":1588414378657,"mc":[{"id":"1.170370562","rc":[{"atl":[[1.75,0]],"id":9625043}],"con":true,"img":false}]}
{"op":"mcm","clk":"1349976311","pt":1588414378761,"mc":[{"id":"1.170370562","rc":[{"atl":[[1.67,222]],"id":9625043}],"con":true,"img":false}]}
{"op":"mcm","clk":"1349976314","pt":1588414378862,"mc":[{"id":"1.170370562","rc":[{"atb":[[1.65,7.86]],"id":9625043}],"con":true,"img":false}]}
{"op":"mcm","clk":"1349976317","pt":1588414378966,"mc":[{"id":"1.170370562","rc":[{"trd":[[1.65,15.72]],"ltp":1.65,"tv":15.72,"id":9625043},{"atb":[[1.65,0]],"id":9625043},{"atl":[[1.65,214.14]],"id":9625043}],"con":true,"img":false}]}
{"op":"mcm","clk":"1349976323","pt":1588414379171,"mc":[{"id":"1.170370562","rc":[{"trd":[[1.65,444]],"ltp":1.65,"tv":444.0,"id":9625043},{"atb":[[1.65,185.37]],"id":9625043},{"atl":[[1.65,0]],"id":9625043}],"con":true,"img":false}]}
{"op":"mcm","clk":"1349976327","pt":1588414379274,"mc":[{"id":"1.170370562","rc":[{"trd":[[1.65,814.74]],"ltp":1.65,"tv":814.74,"id":9625043},{"atb":[[1.65,0]],"id":9625043},{"atl":[[1.62,36.63]],"id":9625043}],"con":true,"img":false}]}
{"op":"mcm","clk":"1349976336","pt":1588414379482,"mc":[{"id":"1.170370562","rc":[{"atb":[[2.48,265.95]],"id":9631798}],"con":true,"img":false}]}
{"op":"mcm","clk":"1349976341","pt":1588414379534,"mc":[{"id":"1.170370562","rc":[{"atl":[[1.6,222]],"id":9625043}],"con":true,"img":false}]}
{"op":"mcm","clk":"1349976344","pt":1588414379635,"mc":[{"id":"1.170370562","rc":[{"trd":[[1.6,26.27]],"ltp":1.6,"tv":26.27,"id":9625043},{"atb":[[1.49,50.18]],"id":9625043},{"atl":[[1.6,208.86]],"id":9625043}],"con":true,"img":false}]}
{"op":"mcm","clk":"1349976354","pt":1588414379943,"mc":[{"id":"1.170370562","rc":[{"trd":[[1.6,159.15]],"ltp":1.6,"tv":159.15,"id":9625043},{"atb":[[1.4,93.08]],"id":9625043},{"atl":[[1.6,142.42]],"id":9625043}],"con":true,"img":false}]}
{"op":"mcm","clk":"1349976363","pt":1588414380248,"mc":[{"id":"1.170370562","rc":[{"atb":[[1.49,0]],"id":9625043}],"con":true,"img":false}]}
{"op":"mcm","clk":"1349976376","pt":1588414380659,"mc":[{"id":"1.170370562","rc":[{"atb":[[1.01,991.5]],"id":9625043}],"con":true,"img":false}]}
{"op":"mcm","clk":"1349976378","pt":1588414380864,"mc":[{"id":"1.170370562","rc":[{"atb":[[1.01,990.19]],"id":9625043},{"atl":[[1.6,0],[1.67,0],[1.62,0]],"id":9625043}],"con":true,"img":false}]}
{"op":"mcm","clk":"1349976381","pt":1588414380968,"mc":[{"id":"1.170370562","rc":[{"atl":[[1.8,2.62]],"id":9625043}],"con":true,"img":false}]}
{"op":"mcm","clk":"1349976384","pt":1588414381069,"mc":[{"id":"1.170370562","rc":[{"atb":[[1.01,989.72]],"id":9625043},{"atl":[[3,101.01]],"id":9631798}],"con":true,"img":false}]}
{"op":"mcm","clk":"1349976389","pt":1588414381377,"mc":[{"id":"1.170370562","rc":[{"atl":[[1.7,0]],"id":9625043}],"con":true,"img":false}]}
{"op":"mcm","clk":"1349976411","pt":1588414382047,"mc":[{"id":"1.170370562","rc":[{"atb":[[1.77,232.71]],"id":9631798}],"con":true,"img":false}]}
{"op":"mcm","clk":"1349976426","pt":1588414382460,"mc":[{"id":"1.170370562","rc":[{"atl":[[1.84,137.41]],"id":9625043}],"con":true,"img":false}]}
{"op":"mcm","clk":"1349976469","pt":1588414383443,"mc":[{"id":"1.170370562","rc":[{"atl":[[1.67,112]],"id":9625043}],"con":true,"img":false}]}
{"op":"mcm","clk":"1349976482","pt":1588414383648,"mc":[{"id":"1.170370562","rc":[{"atb":[[1.01,991.5]],"id":9625043}],"con":true,"img":false}]}
{"op":"mcm","clk":"1349976485","pt":1588414383751,"mc":[{"id":"1.170370562","rc":[{"atl":[[1.74,112]],"id":9625043}],"con":true,"img":false}]}
{"op":"mcm","clk":"1349976494","pt":1588414383955,"mc":[{"id":"1.170370562","rc":[{"atb":[[1.01,990.81]],"id":9625043}],"con":true,"img":false}]}
{"op":"mcm","clk":"1349976501","pt":1588414384160,"mc":[{"id":"1.170370562","rc":[{"atb":[[1.01,989.72]],"id":9625043}],"con":true,"img":false}]}
{"op":"mcm","clk":"1349976515","pt":1588414384573,"mc":[{"id":"1.170370562","rc":[{"atb":[[1.59,55]],"id":9625043}],"con":true,"img":false}]}
{"op":"mcm","clk":"1349976518","pt":1588414384677,"mc":[{"id":"1.170370562","rc":[{"atb":[[1.51,17.73]],"id":9625043}],"con":true,"img":false}]}
{"op":"mcm","clk":"1349976529","pt":1588414384934,"mc":[{"id":"1.170370562","rc":[{"trd":[[1.66,504.38]],"ltp":1.66,"tv":504.38,"id":9625043},{"atl":[[1.66,8.3]],"id":9625043}],"con":true,"img":false}]}
{"op":"mcm","clk":"1349976570","pt":1588414386175,"mc":[{"id":"1.170370562","rc":[{"atb":[[1.65,0.46]],"id":9625043}],"con":true,"img":false}]}
{"op":"mcm","clk":"1349976574","pt":1588414386276,"mc":[{"id":"1.170370562","rc":[{"atb":[[1.46,51.21]],"id":9625043}],"con":true,"img":false}]}
{"op":"mcm","clk":"1349976580","pt":1588414386492,"mc":[{"id":"1.170370562","rc":[{"trd":[[1.59,34.52],[1.65,815.68]],"ltp":1.59,"tv":850.19,"id":9625043},{"atb":[[1.59,37.74],[1.65,0],[1.52,55]],"id":9625043}],"con":true,"img":false}]}
{"op":"mcm","clk":"1349976587","pt":1588414386639,"mc":[{"id":"1.170370562","rc":[{"atb":[[1.68,120.8]],"id":9631798}],"con":true,"img":false}]}
{"op":"mcm","clk":"1349976599","pt":1588414386843,"mc":[{"id":"1.170370562","rc":[{"trd":[[1.66,512.69]],"ltp":1.66,"tv":512.69,"id":9625043},{"atl":[[1.66,0]],"id":9625043},{"trd":[[2.48,312.85],[2.5,312.97]],"ltp":2.48,"tv":625.82,"id":9631798},{"atb":[[2.48,109.53]],"id":9631798}],"con":true,"img":false}]}
{"op":"mcm","clk":"1349976605","pt":1588414387049,"mc":[{"id":"1.170370562","rc":[{"trd":[[1.59,69.98]],"ltp":1.59,"tv":69.98,"id":9625043},{"atb":[[1.59,20.01]],"id":9625043}],"con":true,"img":false}]}
{"op":"mcm","clk":"1349976621","pt":1588414387469,"mc":[{"id":"1.170370562","rc":[{"atl":[[1.84,0]],"id":9625043}],"con":true,"img":false}]}
{"op":"mcm","clk":"1349976632","pt":1588414387879,"mc":[{"id":"1.170370562","rc":[{"atb":[[1.4,4.43]],"id":9625043}],"con":true,"img":false}]}
{"op":"mcm","clk":"1349976636","pt":1588414387982,"mc":[{"id":"1.170370562","rc":[{"atl":[[1.8,0]],"id":9625043}],"con":true,"img":false}]}
{"op":"mcm","clk":"1349976651","pt":1588414388342,"mc":[{"id":"1.170370562","rc":[{"atl":[[1.64,17.73]],"id":9625043}],"con":true,"img":false}]}
{"op":"mcm","clk":"1349976654","pt":1588414388445,"mc":[{"id":"1.170370562","rc":[{"atb":[[1.58,506.01],[1.52,580.98]],"id":9625043}],"con":true,"img":false}]}
{"op":"mcm","clk":"1349976658","pt":1588414388549,"mc":[{"id":"1.170370562","rc":[{"trd":[[1.64,14.75]],"ltp":1.64,"tv":14.75,"id":9625043},{"atl":[[1.64,2.97],[1.85,0]],"id":9625043},{"trd":[[2.56,9.45]],"ltp":2.56,"tv":9.45,"id":9631798}],"con":true,"img":false}]}
{"op":"mcm","clk":"1349976676","pt":1588414388959,"mc":[{"id":"1.170370562","rc":[{"atl":[[1.64,20.7]],"id":9625043}],"con":true,"img":false}]}
{"op":"mcm","clk":"1349976688","pt":1588414389272,"mc":[{"id":"1.170370562","rc":[{"trd":[[1.64,56.17]],"ltp":1.64,"tv":56.17,"id":9625043},{"atb":[[1.65,156.96],[1.52,55]],"id":9625043},{"atl":[[1.64,0]],"id":9625043}],"con":true,"img":false}]}
{"op":"mcm","clk":"1349976709","pt":1588414389885,"mc":[{"id":"1.170370562","rc":[{"atb":[[1.44,8.06]],"id":9625043}],"con":true,"img":false}]}
{"op":"mcm","clk":"1349976714","pt":1588414390089,"mc":[{"id":"1.170370562","rc":[{"atb":[[1.51,129.73]],"id":9625043}],"con":true,"img":false}]}
{"op":"mcm","clk":"1349976720","pt":1588414390143,"mc":[{"id":"1.170370562","rc":[{"trd":[[1.65,834.16]],"ltp":1.65,"tv":834.16,"id":9625043},{"atb":[[1.65,147.72]],"id":9625043},{"atl":[[1.89,0]],"id":9625043}],"con":true,"img":false}]}
{"op":"mcm","clk":"1349976725","pt":1588414390245,"mc":[{"id":"1.170370562","rc":[{"atb":[[1.65,158.98]],"id":9625043}],"con":true,"img":false}]}
{"op":"mcm","clk":"1349976735","pt":1588414390654,"mc":[{"id":"1.170370562","rc":[{"atb":[[1.52,167]],"id":9625043}],"con":true,"img":false}]}
{"op":"mcm","clk":"1349976756","pt":1588414391574,"mc":[{"id":"1.170370562","rc":[{"atb":[[1.66,2.62]],"id":9625043}],"con":true,"img":false}]}
{"op":"mcm","clk":"1349976769","pt":1588414391987,"mc":[{"id":"1.170370562","rc":[{"atb":[[1.44,4.03]],"id":9625043}],"con":true,"img":false}]}
{"op":"mcm","clk":"1349976776","pt":1588414392193,"mc":[{"id":"1.170370562","rc":[{"atb":[[1.65,167.34]],"id":9625043}],"con":true,"img":false}]}
{"op":"mcm","clk":"1349976785","pt":1588414392554,"mc":[{"id":"1.170370562","rc":[{"atb":[[1.58,0],[1.53,112]],"id":9625043}],"con":true,"img":false}]}
{"op":"mcm","clk":"1349976804","pt":1588414393170,"mc":[{"id":"1.170370562","rc":[{"trd":[[1.66,517.94]],"ltp":1.66,"tv":517.94,"id":9625043},{"atb":[[1.66,0]],"id":9625043}],"con":true,"img":false}]}
{"op":"mcm","clk":"1349976812","pt":1588414393379,"mc":[{"id":"1.170370562","rc":[{"atl":[[1.88,0.11]],"id":9625043},{"atl":[[2.6,149.21]],"id":9631798}],"con":true,"img":false}]}
{"op":"mcm","clk":"1349976814","pt":1588414393483,"mc":[{"id":"1.170370562","rc":[{"atl":[[3.25,0]],"id":9631798}],"con":true,"img":false}]}
{"op":"mcm","clk":"1349976821","pt":1588414393689,"mc":[{"id":"1.170370562","rc":[{"trd":[[1.65,845.93]],"ltp":1.65,"tv":845.93,"id":9625043},{"atb":[[1.65,161.45]],"id":9625043}],"con":true,"img":false}]}
{"op":"mcm","clk":"1349976833","pt":1588414393995,"mc":[{"id":"1.170370562","rc":[{"atb":[[1.56,17.73]],"id":9625043}],"con":true,"img":false}]}
{"op":"mcm","clk":"1349976847","pt":1588414394560,"mc":[{"id":"1.170370562","rc":[{"atb":[[1.56,35.46]],"id":9625043}],"con":true,"img":false}]}
{"op":"mcm","clk":"1349976860","pt":1588414394973,"mc":[{"id":"1.170370562","rc":[{"atl":[[1.67,0],[1.74,0]],"id":9625043}],"con":true,"img":false}]}
{"op":"mcm","clk":"1349976894","pt":1588414395791,"mc":[{"id":"1.170370562","rc":[{"trd":[[1.65,846.35]],"ltp":1.65,"tv":846.35,"id":9625043},{"atb":[[1.65,161.03]],"id":9625043},{"trd":[[2.54,0.27]],"ltp":2.54,"tv":0.27,"id":9631798}],"con":true,"img":false}]}
{"op":"mcm","clk":"1349976899","pt":1588414395894,"mc":[{"id":"1.170370562","rc":[{"atb":[[1.6,30]],"id":9625043}],"con":true,"img":false}]}
{"op":"mcm","clk":"1349976915","pt":1588414396151,"mc":[{"id":"1.170370562","rc":[{"trd":[[1.65,881.81]],"ltp":1.65,"tv":881.81,"id":9625043},{"atb":[[1.65,143.3]],"id":9625043}],"con":true,"img":false}]}
{"op":"mcm","clk":"1349976916","pt":1588414396253,"mc":[{"id":"1.170370562","rc":[{"trd":[[1.65,918.91]],"ltp":1.65,"tv":918.91,"id":9625043},{"atb":[[1.63,222],[1.65,124.75]],"id":9625043}],"con":true,"img":false}]}
{"op":"mcm","clk":"1349976922","pt":1588414396356,"mc":[{"id":"1.170370562","rc":[{"trd":[[2.48,320.85]],"ltp":2.48,"tv":320.85,"id":9631798},{"atb":[[2.48,105.53]],"id":9631798}],"con":true,"img":false}]}
{"op":"mcm","clk":"1349976935","pt":1588414396769,"mc":[{"id":"1.170370562","rc":[{"trd":[[1.65,954.37]],"ltp":1.65,"tv":954.37,"id":9625043},{"atb":[[1.65,107.02]],"id":9625043}],"con":true,"img":false}]}
{"op":"mcm","clk":"1349976943","pt":1588414396970,"mc":[{"id":"1.170370562","rc":[{"trd":[[1.65,955.75]],"ltp":1.65,"tv":955.75,"id":9625043},{"atb":[[1.6,252],[1.65,106.33]],"id":9625043}],"con":true,"img":false}]}
{"op":"mcm","clk":"1349976948","pt":1588414397174,"mc":[{"id":"1.170370562","rc":[{"atb":[[1.4,0]],"id":9625043}],"con":true,"img":false}]}
{"op":"mcm","clk":"1349976952","pt":1588414397276,"mc":[{"id":"1.170370562","rc":[{"atb":[[1.59,132.01]],"id":9625043}],"con":true,"img":false}]}
{"op":"mcm","clk":"1349976967","pt":1588414397686,"mc":[{"id":"1.170370562","rc":[{"atb":[[1.6,364]],"id":9625043}],"con":true,"img":false}]}
{"op":"mcm","clk":"1349976977","pt":1588414398095,"mc":[{"id":"1.170370562","rc":[{"atb":[[1.6,381.73]],"id":9625043}],"con":true,"img":false}]}
{"op":"mcm","clk":"1349976981","pt":1588414398198,"mc":[{"id":"1.170370562","rc":[{"atb":[[1.6,493.73]],"id":9625043},{"atb":[[2.48,0]],"id":9631798}],"con":true,"img":false}]}
{"op":"mcm","clk":"1349976983","pt":1588414398300,"mc":[{"id":"1.170370562","rc":[{"atb":[[1.6,271.73]],"id":9625043}],"con":true,"img":false}]}
{"op":"mcm","clk":"1349977003","pt":1588414398661,"mc":[{"id":"1.170370562","rc":[{"atb":[[1.6,289.46]],"id":9625043}],"con":true,"img":false}]}
{"op":"mcm","clk":"1349977037","pt":1588414399690,"mc":[{"id":"1.170370562","rc":[{"trd":[[1.65,962.59]],"ltp":1.65,"tv":962.59,"id":9625043},{"atb":[[1.65,102.91]],"id":9625043}],"con":true,"img":false}]}
{"op":"mcm","clk":"1349977062","pt":1588414400307,"mc":[{"id":"1.170370562","rc":[{"trd":[[1.65,1012.31]],"ltp":1.65,"tv":1012.31,"id":9625043},{"atb":[[1.65,53.19]],"id":9625043},{"trd":[[2.54,32.56]],"ltp":2.54,"tv":32.56,"id":9631798}],"con":true,"img":false}]}
{"op":"mcm","clk":"1349977084","pt":1588414400772,"mc":[{"id":"1.170370562","rc":[{"atb":[[1.42,206.56]],"id":9625043}],"con":true,"img":false}]}
{"op":"mcm","clk":"1349977119","pt":1588414401692,"mc":[{"id":"1.170370562","rc":[{"atb":[[1.66,222]],"id":9625043},{"atl":[[2.6,0]],"id":9631798}],"con":true,"img":false}]}
{"op":"mcm","clk":"1349977127","pt":1588414401899,"mc":[{"id":"1.170370562","rc":[{"atl":[[2.48,3.53]],"id":9631798}],"con":true,"img":false}]}
{"op":"mcm","clk":"1349977130","pt":1588414401998,"mc":[{"id":"1.170370562","rc":[{"atl":[[1.78,112]],"id":9625043}],"con":true,"img":false}]}
{"op":"mcm","clk":"1349977142","pt":1588414402306,"mc":[{"id":"1.170370562","rc":[{"atl":[[1.88,0]],"id":9625043}],"con":true,"img":false}]}
{"op":"mcm","clk":"1349977154","pt":1588414402564,"mc":[{"id":"1.170370562","rc":[{"atl":[[1.84,112]],"id":9625043}],"con":true,"img":false}]}
{"op":"mcm","clk":"1349977187","pt":1588414403284,"mc":[{"id":"1.170370562","rc":[{"atb":[[2.4,105.53]],"id":9631798}],"con":true,"img":false}]}
{"op":"mcm","clk":"1349977196","pt":1588414403489,"mc":[{"id":"1.170370562","rc":[{"atl":[[2.48,0]],"id":9631798}],"con":true,"img":false}]}
{"op":"mcm","clk":"1349977204","pt":1588414403696,"mc":[{"id":"1.170370562","rc":[{"atl":[[1.93,500]],"id":9625043}],"con":true,"img":false}]}
{"op":"mcm","clk":"1349977214","pt":1588414404108,"mc":[{"id":"1.170370562","rc":[{"trd":[[1.66,520.3]],"ltp":1.66,"tv":520.3,"id":9625043},{"atb":[[1.66,220.82]],"id":9625043}],"con":true,"img":false}]}
{"op":"mcm","clk":"1349977217","pt":1588414404212,"mc":[{"id":"1.170370562","rc":[{"trd":[[1.66,521.44]],"ltp":1.66,"tv":521.44,"id":9625043},{"atb":[[1.66,220.25]],"id":9625043}],"con":true,"img":false}]}
{"op":"mcm","clk":"1349977223","pt":1588414404471,"mc":[{"id":"1.170370562","rc":[{"atb":[[2.4,0]],"id":9631798}],"con":true,"img":false}]}
{"op":"mcm","clk":"1349977228","pt":1588414404572,"mc":[{"id":"1.170370562","rc":[{"atb":[[1.9,4]],"id":9631798}],"con":true,"img":false}]}
{"op":"mcm","clk":"1349977236","pt":1588414404881,"mc":[{"id":"1.170370562","rc":[{"trd":[[1.66,521.47]],"ltp":1.66,"tv":521.47,"id":9625043},{"atb":[[1.66,220.22]],"id":9625043},{"trd":[[2.52,0.02]],"ltp":2.52,"tv":0.02,"id":9631798}],"con":true,"img":false}]}
{"op":"mcm","clk":"1349977274","pt":1588414406215,"mc":[{"id":"1.170370562","rc":[{"atl":[[3,0]],"id":9631798}],"con":true,"img":false}]}
{"op":"mcm","clk":"1349977297","pt":1588414407089,"mc":[{"id":"1.170370562","rc":[{"trd":[[1.66,524.09]],"ltp":1.66,"tv":524.09,"id":9625043},{"atb":[[1.66,218.91]],"id":9625043}],"con":true,"img":false}]}
{"op":"mcm","clk":"1349977309","pt":1588414407397,"mc":[{"id":"1.170370562","rc":[{"trd":[[1.66,531.09]],"ltp":1.66,"tv":531.09,"id":9625043},{"atb":[[1.66,215.41]],"id":9625043}],"con":true,"img":false}]}
{"op":"mcm","clk":"1349977373","pt":1588414410377,"mc":[{"id":"1.170370562","rc":[{"atb":[[1.68,1000]],"id":9625043}],"con":true,"img":false}]}
{"op":"mcm","clk":"1349977395","pt":1588414411200,"mc":[{"id":"1.170370562","rc":[{"atb":[[1.72,199.96]],"id":9625043}],"con":true,"img":false}]}
{"op":"mcm","clk":"1349977415","pt":1588414411711,"mc":[{"id":"1.170370562","rc":[{"atb":[[1.73,199.96]],"id":9625043}],"con":true,"img":false}]}
{"op":"mcm","clk":"1349977428","pt":1588414412018,"mc":[{"id":"1.170370562","rc":[{"atb":[[1.63,0],[1.66,0]],"id":9625043},{"atl":[[2.82,109.32]],"id":9631798}],"con":true,"img":false}]}
{"op":"mcm","clk":"1349977440","pt":1588414412223,"mc":[{"id":"1.170370562","rc":[{"atl":[[1.84,0],[1.78,0]],"id":9625043},{"atl":[[2.48,0.65]],"id":9631798}],"con":true,"img":false}]}
{"op":"mcm","clk":"1349977442","pt":1588414412274,"mc":[{"id":"1.170370562","rc":[{"atb":[[2.18,265.95]],"id":9631798}],"con":true,"img":false}]}
{"op":"mcm","clk":"1349977449","pt":1588414412378,"mc":[{"id":"1.170370562","rc":[{"atl":[[1.74,0.15]],"id":9625043}],"con":true,"img":false}]}
{"op":"mcm","clk":"1349977459","pt":1588414412685,"mc":[{"id":"1.170370562","rc":[{"atb":[[1.68,1492.02]],"id":9625043}],"con":true,"img":false}]}
{"op":"mcm","clk":"1349977471","pt":1588414413202,"mc":[{"id":"1.170370562","rc":[{"atb":[[1.77,0]],"id":9631798},{"atl":[[2.82,0]],"id":9631798}],"con":true,"img":false}]}
{"op":"mcm","clk":"1349977477","pt":1588414413410,"mc":[{"id":"1.170370562","rc":[{"atb":[[1.73,217.69]],"id":9625043}],"con":true,"img":false}]}
{"op":"mcm","clk":"1349977493","pt":1588414413922,"mc":[{"id":"1.170370562","rc":[{"atl":[[2,0.11]],"id":9625043}],"con":true,"img":false}]}
{"op":"mcm","clk":"1349977498","pt":1588414414027,"mc":[{"id":"1.170370562","rc":[{"trd":[[1.85,539.8],[1.74,0.3],[1.8,10.36]],"ltp":1.85,"tv":550.45,"id":9625043},{"atl":[[1.74,0]],"id":9625043},{"trd":[[2.18,80.16],[2.26,0.05]],"ltp":2.18,"tv":80.21,"id":9631798},{"atb":[[2.26,0],[2.18,221.25]],"id":9631798}],"con":true,"img":false}]}
{"op":"mcm","clk":"1349977500","pt":1588414414127,"mc":[{"id":"1.170370562","rc":[{"atb":[[1.68,1000]],"id":9625043}],"con":true,"img":false}]}
{"op":"mcm","clk":"1349977504","pt":1588414414231,"mc":[{"id":"1.170370562","rc":[{"trd":[[1.73,3.54]],"ltp":1.73,"tv":3.54,"id":9625043},{"atb":[[1.73,233.65],[1.68,0],[1.65,19.62]],"id":9625043}],"con":true,"img":false}]}
{"op":"mcm","clk":"1349977549","pt":1588414415214,"mc":[{"id":"1.170370562","rc":[{"atb":[[1.72,217.69]],"id":9625043}],"con":true,"img":false}]}
{"op":"mcm","clk":"1349977573","pt":1588414415724,"mc":[{"id":"1.170370562","rc":[{"atb":[[1.72,235.42]],"id":9625043}],"con":true,"img":false}]}
{"op":"mcm","clk":"1349977604","pt":1588414416497,"mc":[{"id":"1.170370562","rc":[{"atb":[[1.7,222]],"id":9625043}],"con":true,"img":false}]}
{"op":"mcm","clk":"1349977609","pt":1588414416599,"mc":[{"id":"1.170370562","rc":[{"atb":[[1.6,259.46]],"id":9625043}],"con":true,"img":false}]}
{"op":"mcm","clk":"1349977620","pt":1588414416912,"mc":[{"id":"1.170370562","rc":[{"atb":[[1.59,112]],"id":9625043}],"con":true,"img":false}]}
{"op":"mcm","clk":"1349977623","pt":1588414417011,"mc":[{"id":"1.170370562","rc":[{"atb":[[1.7,0]],"id":9625043}],"con":true,"img":false}]}
{"op":"mcm","clk":"1349977643","pt":1588414417424,"mc":[{"id":"1.170370562","rc":[{"atb":[[1.78,0.47]],"id":9625043}],"con":true,"img":false}]}
{"op":"mcm","clk":"1349977652","pt":1588414417733,"mc":[{"id":"1.170370562","rc":[{"atb":[[1.78,443.47],[1.74,17.73]],"id":9625043}],"con":true,"img":false}]}
{"op":"mcm","clk":"1349977657","pt":1588414417888,"mc":[{"id":"1.170370562","rc":[{"trd":[[1.78,3.54]],"ltp":1.78,"tv":3.54,"id":9625043},{"atb":[[1.78,441.7]],"id":9625043}],"con":true,"img":false}]}
{"op":"mcm","clk":"1349977660","pt":1588414417994,"mc":[{"id":"1.170370562","rc":[{"atb":[[1.73,198.19],[1.6,224],[1.51,112],[1.56,0],[1.72,199.96],[1.74,0]],"id":9625043},{"atl":[[2.48,0]],"id":9631798}],"con":true,"img":false}]}
{"op":"mcm","clk":"1349977668","pt":1588414418200,"mc":[{"id":"1.170370562","rc":[{"atb":[[1.75,129.73]],"id":9625043}],"con":true,"img":false}]}
{"op":"mcm","clk":"1349977682","pt":1588414418716,"mc":[{"id":"1.170370562","rc":[{"atb":[[1.74,112],[1.75,336.29]],"id":9625043}],"con":true,"img":false}]}
{"op":"mcm","clk":"1349977687","pt":1588414419023,"mc":[{"id":"1.170370562","rc":[{"atb":[[1.62,241.76]],"id":9631798}],"con":true,"img":false}]}
{"op":"mcm","clk":"1349977690","pt":1588414419125,"mc":[{"id":"1.170370562","rc":[{"atl":[[2.6,122.44]],"id":9631798}],"con":true,"img":false}]}
{"op":"mcm","clk":"1349977694","pt":1588414419229,"mc":[{"id":"1.170370562","rc":[{"atb":[[1.76,98.34]],"id":9625043}],"con":true,"img":false}]}
{"op":"mcm","clk":"1349977700","pt":1588414419536,"mc":[{"id":"1.170370562","rc":[{"atl":[[2.36,209.87]],"id":9631798}],"con":true,"img":false}]}
{"op":"mcm","clk":"1349977711","pt":1588414419896,"mc":[{"id":"1.170370562","rc":[{"trd":[[1.78,9.19]],"ltp":1.78,"tv":9.19,"id":9625043},{"atb":[[1.78,436.05]],"id":9625043},{"trd":[[2.3,4.37]],"ltp":2.3,"tv":4.37,"id":9631798}],"con":true,"img":false}]}
{"op":"mcm","clk":"1349977744","pt":1588414421027,"mc":[{"id":"1.170370562","rc":[{"atb":[[1.72,0],[1.52,112]],"id":9625043}],"con":true,"img":false}]}
{"op":"mcm","clk":"1349977752","pt":1588414421232,"mc":[{"id":"1.170370562","rc":[{"atb":[[1.75,129.73]],"id":9625043}],"con":true,"img":false}]}
{"op":"mcm","clk":"1349977755","pt":1588414421334,"mc":[{"id":"1.170370562","rc":[{"atb":[[1.78,438.62]],"id":9625043}],"con":true,"img":false}]}
{"op":"mcm","clk":"1349977763","pt":1588414421540,"mc":[{"id":"1.170370562","rc":[{"trd":[[1.85,569.84]],"ltp":1.85,"tv":569.84,"id":9625043},{"trd":[[2.18,105.66]],"ltp":2.18,"tv":105.66,"id":9631798},{"atb":[[2.18,195.75]],"id":9631798}],"con":true,"img":false}]}
{"op":"mcm","clk":"1349977781","pt":1588414422006,"mc":[{"id":"1.170370562","rc":[{"trd":[[1.85,572.42]],"ltp":1.85,"tv":572.42,"id":9625043},{"trd":[[2.18,107.85]],"ltp":2.18,"tv":107.85,"id":9631798},{"atb":[[2.18,193.56]],"id":9631798}],"con":true,"img":false}]}
{"op":"mcm","clk":"1349977787","pt":1588414422314,"mc":[{"id":"1.170370562","rc":[{"atl":[[2.36,0]],"id":9631798}],"con":true,"img":false}]}
{"op":"mcm","clk":"1349977789","pt":1588414422519,"mc":[{"id":"1.170370562","rc":[{"trd":[[1.78,10.24]],"ltp":1.78,"tv":10.24,"id":9625043},{"atb":[[1.78,437.57]],"id":9625043},{"trd":[[2.3,5.18]],"ltp":2.3,"tv":5.18,"id":9631798}],"con":true,"img":false}]}
{"op":"mcm","clk":"1349977796","pt":1588414422826,"mc":[{"id":"1.170370562","rc":[{"trd":[[2.18,108.06]],"ltp":2.18,"tv":108.06,"id":9631798},{"atb":[[2.18,193.45]],"id":9631798}],"con":true,"img":false}]}
{"op":"mcm","clk":"1349977798","pt":1588414422930,"mc":[{"id":"1.170370562","rc":[{"trd":[[1.78,21.61]],"ltp":1.78,"tv":21.61,"id":9625043},{"atb":[[1.78,431.88]],"id":9625043}],"con":true,"img":false}]}
{"op":"mcm","clk":"1349977810","pt":1588414423606,"mc":[{"id":"1.170370562","rc":[{"atl":[[1.93,0]],"id":9625043}],"con":true,"img":false}]}
{"op":"mcm","clk":"1349977824","pt":1588414424223,"mc":[{"id":"1.170370562","rc":[{"atb":[[1.75,112]],"id":9625043}],"con":true,"img":false}]}
{"op":"mcm","clk":"1349977831","pt":1588414424419,"mc":[{"id":"1.170370562","rc":[{"atb":[[1.75,0]],"id":9625043}],"con":true,"img":false}]}
{"op":"mcm","clk":"1349977835","pt":1588414424626,"mc":[{"id":"1.170370562","rc":[{"atb":[[1.79,17.73]],"id":9625043}],"con":true,"img":false}]}
{"op":"mcm","clk":"1349977838","pt":1588414424726,"mc":[{"id":"1.170370562","rc":[{"atb":[[1.79,72.73]],"id":9625043}],"con":true,"img":false}]}
{"op":"mcm","clk":"1349977841","pt":1588414424831,"mc":[{"id":"1.170370562","rc":[{"atl":[[1.83,0.68]],"id":9625043}],"con":true,"img":false}]}
{"op":"mcm","clk":"1349977848","pt":1588414424932,"mc":[{"id":"1.170370562","rc":[{"atb":[[1.78,484.78]],"id":9625043}],"con":true,"img":false}]}
{"op":"mcm","clk":"1349977855","pt":1588414425137,"mc":[{"id":"1.170370562","rc":[{"atb":[[1.79,132.23]],"id":9625043}],"con":true,"img":false}]}
{"op":"mcm","clk":"1349977863","pt":1588414425399,"mc":[{"id":"1.170370562","rc":[{"trd":[[1.85,580.83],[1.83,1.38]],"ltp":1.85,"tv":582.21,"id":9625043},{"atl":[[1.83,0]],"id":9625043},{"trd":[[2.18,115.2]],"ltp":2.18,"tv":115.2,"id":9631798},{"atb":[[2.18,186.32]],"id":9631798}],"con":true,"img":false}]}
{"op":"mcm","clk":"1349977897","pt":1588414426322,"mc":[{"id":"1.170370562","rc":[{"atl":[[2.28,110.81]],"id":9631798}],"con":true,"img":false}]}
{"op":"mcm","clk":"1349977927","pt":1588414427400,"mc":[{"id":"1.170370562","rc":[{"atb":[[1.79,149.96]],"id":9625043}],"con":true,"img":false}]}
{"op":"mcm","clk":"1349977933","pt":1588414427608,"mc":[{"id":"1.170370562","rc":[{"trd":[[1.85,585.89]],"ltp":1.85,"tv":585.89,"id":9625043},{"trd":[[2.18,119.49]],"ltp":2.18,"tv":119.49,"id":9631798},{"atb":[[2.18,182.03]],"id":9631798}],"con":true,"img":false}]}
{"op":"mcm","clk":"1349977945","pt":1588414428325,"mc":[{"id":"1.170370562","rc":[{"trd":[[1.79,5.24]],"ltp":1.79,"tv":5.24,"id":9625043},{"atb":[[1.79,147.33]],"id":9625043}],"con":true,"img":false}]}
{"op":"mcm","clk":"1349977976","pt":1588414429420,"mc":[{"id":"1.170370562","rc":[{"atb":[[1.98,500]],"id":9631798}],"con":true,"img":false}]}
{"op":"mcm","clk":"1349977985","pt":1588414429627,"mc":[{"id":"1.170370562","rc":[{"atb":[[2.18,0]],"id":9631798}],"con":true,"img":false}]}
{"op":"mcm","clk":"1349978011","pt":1588414430604,"mc":[{"id":"1.170370562","rc":[{"atb":[[1.74,0]],"id":9625043}],"con":true,"img":false}]}
{"op":"mcm","clk":"1349978026","pt":1588414430811,"mc":[{"id":"1.170370562","rc":[{"atb":[[1.73,0]],"id":9625043}],"con":true,"img":false}]}
{"op":"mcm","clk":"1349978047","pt":1588414431224,"mc":[{"id":"1.170370562","rc":[{"atb":[[1.85,222]],"id":9625043}],"con":true,"img":false}]}
{"op":"mcm","clk":"1349978061","pt":1588414431531,"mc":[{"id":"1.170370562","rc":[{"atl":[[2,112.11]],"id":9625043}],"con":true,"img":false}]}
{"op":"mcm","clk":"1349978065","pt":1588414431737,"mc":[{"id":"1.170370562","rc":[{"atb":[[1.85,0],[1.78,55.47]],"id":9625043}],"con":true,"img":false}]}
{"op":"mcm","clk":"1349978127","pt":1588414433544,"mc":[{"id":"1.170370562","rc":[{"trd":[[1.79,15.24]],"ltp":1.79,"tv":15.24,"id":9625043},{"atb":[[1.79,142.33]],"id":9625043}],"con":true,"img":false}]}
{"op":"mcm","clk":"1349978201","pt":1588414436229,"mc":[{"id":"1.170370562","rc":[{"trd":[[2,0.2]],"ltp":2.0,"tv":0.2,"id":9625043},{"atl":[[2,111.91]],"id":9625043},{"trd":[[2,0.2]],"ltp":2.0,"tv":0.2,"id":9631798}],"con":true,"img":false}]}
{"op":"mcm","clk":"1349978222","pt":1588414437153,"mc":[{"id":"1.170370562","rc":[{"trd":[[1.79,95.24]],"ltp":1.79,"tv":95.24,"id":9625043},{"atb":[[1.79,102.34]],"id":9625043}],"con":true,"img":false}]}
{"op":"mcm","clk":"1349978233","pt":1588414437512,"mc":[{"id":"1.170370562","rc":[{"trd":[[1.79,102.3]],"ltp":1.79,"tv":102.3,"id":9625043},{"atb":[[1.79,98.81]],"id":9625043}],"con":true,"img":false}]}
{"op":"mcm","clk":"1349978239","pt":1588414437823,"mc":[{"id":"1.170370562","rc":[{"atb":[[1.85,222]],"id":9625043}],"con":true,"img":false}]}
{"op":"mcm","clk":"1349978251","pt":1588414438544,"mc":[{"id":"1.170370562","rc":[{"atb":[[1.85,226.71]],"id":9625043}],"con":true,"img":false}]}
{"op":"mcm","clk":"1349978254","pt":1588414438649,"mc":[{"id":"1.170370562","rc":[{"atl":[[2.28,0]],"id":9631798}],"con":true,"img":false}]}
{"op":"mcm","clk":"1349978257","pt":1588414438750,"mc":[{"id":"1.170370562","rc":[{"atb":[[1.79,63.35]],"id":9625043}],"con":true,"img":false}]}
{"op":"mcm","clk":"1349978265","pt":1588414439058,"mc":[{"id":"1.170370562","rc":[{"atb":[[1.8,222]],"id":9625043}],"con":true,"img":false}]}
{"op":"mcm","clk":"1349978294","pt":1588414440347,"mc":[{"id":"1.170370562","rc":[{"atb":[[1.59,0],[1.46,0],[1.6,0],[1.51,0],[1.53,0],[1.79,21.58],[1.52,0]],"id":9625043}],"con":true,"img":false}]}
{"op":"mcm","clk":"1349978307","pt":1588414440757,"mc":[{"id":"1.170370562","rc":[{"atb":[[1.76,0]],"id":9625043}],"con":true,"img":false}]}
{"op":"mcm","clk":"1349978341","pt":1588414441948,"mc":[{"id":"1.170370562","rc":[{"atb":[[1.79,0]],"id":9625043}],"con":true,"img":false}]}
{"op":"mcm","clk":"1349978349","pt":1588414442152,"mc":[{"id":"1.170370562","rc":[{"atb":[[1.85,4.71]],"id":9625043}],"con":true,"img":false}]}
{"op":"mcm","clk":"1349978350","pt":1588414442256,"mc":[{"id":"1.170370562","rc":[{"atb":[[1.8,0]],"id":9625043},{"atb":[[1.62,0]],"id":9631798}],"con":true,"img":false}]}
{"op":"mcm","clk":"1349978354","pt":1588414442361,"mc":[{"id":"1.170370562","rc":[{"trd":[[1.78,132.57],[1.85,595.33]],"ltp":1.78,"tv":727.9,"id":9625043},{"atb":[[1.85,0],[1.78,0]],"id":9625043},{"atl":[[1.77,939.8]],"id":9625043}],"con":true,"img":false}]}
{"op":"mcm","clk":"1349978363","pt":1588414442977,"mc":[{"id":"1.170370562","rc":[{"atb":[[1.9,0]],"id":9631798}],"con":true,"img":false}]}
{"op":"mcm","clk":"1349978372","pt":1588414443343,"mc":[{"id":"1.170370562","rc":[{"trd":[[1.77,1.49]],"ltp":1.77,"tv":1.49,"id":9625043},{"atl":[[1.77,938.31]],"id":9625043},{"trd":[[2.28,1.15]],"ltp":2.28,"tv":1.15,"id":9631798}],"con":true,"img":false}]}
{"op":"mcm","clk":"1349978376","pt":1588414443548,"mc":[{"id":"1.170370562","rc":[{"atl":[[1.76,492.02]],"id":9625043}],"con":true,"img":false}]}
{"op":"mcm","clk":"1349978378","pt":1588414443652,"mc":[{"id":"1.170370562","rc":[{"atl":[[1.76,691.98]],"id":9625043}],"con":true,"img":false}]}
{"op":"mcm","clk":"1349978392","pt":1588414444273,"mc":[{"id":"1.170370562","rc":[{"atl":[[1.75,199.96]],"id":9625043}],"con":true,"img":false}]}
{"op":"mcm","clk":"1349978403","pt":1588414444584,"mc":[{"id":"1.170370562","rc":[{"atl":[[2.4,242]],"id":9631798}],"con":true,"img":false}]}
{"op":"mcm","clk":"1349978418","pt":1588414444951,"mc":[{"id":"1.170370562","rc":[{"atl":[[1.75,0]],"id":9625043}],"con":true,"img":false}]}
{"op":"mcm","clk":"1349978433","pt":1588414445571,"mc":[{"id":"1.170370562","rc":[{"atb":[[1.98,0]],"id":9631798}],"con":true,"img":false}]}
{"op":"mcm","clk":"1349978439","pt":1588414445776,"mc":[{"id":"1.170370562","rc":[{"atl":[[1.79,0.41]],"id":9625043}],"con":true,"img":false}]}
{"op":"mcm","clk":"1349978455","pt":1588414446351,"mc":[{"id":"1.170370562","rc":[{"atl":[[1.76,709.71]],"id":9625043}],"con":true,"img":false}]}
{"op":"mcm","clk":"1349978462","pt":1588414446449,"mc":[{"id":"1.170370562","rc":[{"atl":[[1.91,112]],"id":9625043}],"con":true,"img":false}]}
{"op":"mcm","clk":"1349978471","pt":1588414446756,"mc":[{"id":"1.170370562","rc":[{"atl":[[1.76,727.45]],"id":9625043}],"con":true,"img":false}]}
{"op":"mcm","clk":"1349978478","pt":1588414446964,"mc":[{"id":"1.170370562","rc":[{"atb":[[2.02,4]],"id":9631798}],"con":true,"img":false}]}
{"op":"mcm","clk":"1349978486","pt":1588414447272,"mc":[{"id":"1.170370562","rc":[{"atl":[[1.77,0]],"id":9625043}],"con":true,"img":false}]}
{"op":"mcm","clk":"1349978498","pt":1588414447687,"mc":[{"id":"1.170370562","rc":[{"trd":[[1.76,4]],"ltp":1.76,"tv":4.0,"id":9625043},{"atl":[[1.76,725.44]],"id":9625043}],"con":true,"img":false}]}
{"op":"mcm","clk":"1349978510","pt":1588414448101,"mc":[{"id":"1.170370562","rc":[{"atl":[[1.96,239.96]],"id":9625043},{"atb":[[1.7,237.92]],"id":9631798}],"con":true,"img":false}]}
{"op":"mcm","clk":"1349978522","pt":1588414448464,"mc":[{"id":"1.170370562","rc":[{"atl":[[1.76,235.42]],"id":9625043}],"con":true,"img":false}]}
{"op":"mcm","clk":"1349978545","pt":1588414449184,"mc":[{"id":"1.170370562","rc":[{"atl":[[1.96,0]],"id":9625043}],"con":true,"img":false}]}
{"op":"mcm","clk":"1349978552","pt":1588414449392,"mc":[{"id":"1.170370562","rc":[{"atl":[[1.75,17.73]],"id":9625043}],"con":true,"img":false}]}
{"op":"mcm","clk":"1349978555","pt":1588414449496,"mc":[{"id":"1.170370562","rc":[{"atb":[[1.67,457.59]],"id":9625043},{"atb":[[2.02,0]],"id":9631798}],"con":true,"img":false}]}
{"op":"mcm","clk":"1349978572","pt":1588414449965,"mc":[{"id":"1.170370562","rc":[{"atl":[[1.74,17.73]],"id":9625043}],"con":true,"img":false}]}
{"op":"mcm","clk":"1349978585","pt":1588414450480,"mc":[{"id":"1.170370562","rc":[{"atb":[[1.58,112]],"id":9625043}],"con":true,"img":false}]}
{"op":"mcm","clk":"1349978611","pt":1588414451408,"mc":[{"id":"1.170370562","rc":[{"atb":[[1.64,112]],"id":9625043}],"con":true,"img":false}]}
{"op":"mcm","clk":"1349978645","pt":1588414452287,"mc":[{"id":"1.170370562","rc":[{"atb":[[1.68,17.73]],"id":9625043}],"con":true,"img":false}]}
{"op":"mcm","clk":"1349978648","pt":1588414452391,"mc":[{"id":"1.170370562","rc":[{"trd":[[1.76,58.24],[1.74,35.76],[1.75,66.06]],"ltp":1.76,"tv":160.06,"id":9625043},{"atl":[[1.74,0],[1.75,0],[1.76,208.3]],"id":9625043}],"con":true,"img":false}]}
{"op":"mcm","clk":"1349978664","pt":1588414452806,"mc":[{"id":"1.170370562","rc":[{"atb":[[1.75,0.11]],"id":9625043}],"con":true,"img":false}]}
{"op":"mcm","clk":"1349978667","pt":1588414452910,"mc":[{"id":"1.170370562","rc":[{"atb":[[1.68,35.46]],"id":9625043}],"con":true,"img":false}]}
{"op":"mcm","clk":"1349978676","pt":1588414453171,"mc":[{"id":"1.170370562","rc":[{"atb":[[1.75,2.13]],"id":9625043}],"con":true,"img":false}]}
{"op":"mcm","clk":"1349978683","pt":1588414453377,"mc":[{"id":"1.170370562","rc":[{"atb":[[1.48,112]],"id":9625043}],"con":true,"img":false}]}
{"op":"mcm","clk":"1349978696","pt":1588414453690,"mc":[{"id":"1.170370562","rc":[{"trd":[[1.76,85.94],[1.75,69.61]],"ltp":1.76,"tv":155.55,"id":9625043},{"atb":[[1.75,0.35]],"id":9625043},{"atl":[[1.76,194.45]],"id":9625043}],"con":true,"img":false}]}
{"op":"mcm","clk":"1349978716","pt":1588414454567,"mc":[{"id":"1.170370562","rc":[{"trd":[[1.71,276.06],[1.75,70.32]],"ltp":1.71,"tv":346.38,"id":9625043},{"atb":[[1.75,0]],"id":9625043},{"trd":[[2.4,124.56]],"ltp":2.4,"tv":124.56,"id":9631798},{"atl":[[2.4,117.43]],"id":9631798}],"con":true,"img":false}]}
{"op":"mcm","clk":"1349978731","pt":1588414455081,"mc":[{"id":"1.170370562","rc":[{"trd":[[1.76,87.77]],"ltp":1.76,"tv":87.77,"id":9625043},{"atl":[[1.76,193.53]],"id":9625043}],"con":true,"img":false}]}
{"op":"mcm","clk":"1349978753","pt":1588414455598,"mc":[{"id":"1.170370562","rc":[{"atb":[[1.73,0],[1.93,0]],"id":9631798},{"atl":[[2.4,0]],"id":9631798}],"con":true,"img":false}]}
{"op":"mcm","clk":"1349978789","pt":1588414456476,"mc":[{"id":"1.170370562","rc":[{"atb":[[1.67,0]],"id":9625043}],"con":true,"img":false}]}
{"op":"mcm","clk":"1349978800","pt":1588414456887,"mc":[{"id":"1.170370562","rc":[{"trd":[[1.76,158.16]],"ltp":1.76,"tv":158.16,"id":9625043},{"atb":[[1.69,17.73]],"id":9625043},{"atl":[[1.76,158.34]],"id":9625043}],"con":true,"img":false}]}
{"op":"mcm","clk":"1349978807","pt":1588414457300,"mc":[{"id":"1.170370562","rc":[{"atb":[[1.68,147.46]],"id":9625043}],"con":true,"img":false}]}
{"op":"mcm","clk":"1349978813","pt":1588414457507,"mc":[{"id":"1.170370562","rc":[{"atb":[[1.69,35.46]],"id":9625043}],"con":true,"img":false}]}
{"op":"mcm","clk":"1349978856","pt":1588414458799,"mc":[{"id":"1.170370562","rc":[{"atb":[[1.72,17.73]],"id":9625043}],"con":true,"img":false}]}
{"op":"mcm","clk":"1349978872","pt":1588414459213,"mc":[{"id":"1.170370562","rc":[{"atl":[[2.6,0]],"id":9631798}],"con":true,"img":false}]}
{"op":"mcm","clk":"1349978881","pt":1588414459416,"mc":[{"id":"1.170370562","rc":[{"atb":[[1.72,35.46]],"id":9625043}],"con":true,"img":false}]}
{"op":"mcm","clk":"1349978883","pt":1588414459546,"mc":[{"id":"1.170370562","rc":[{"atb":[[1.75,13.13]],"id":9625043}],"con":true,"img":false}]}
{"op":"mcm","clk":"1349978895","pt":1588414459881,"mc":[{"id":"1.170370562","rc":[{"atl":[[1.76,358.31]],"id":9625043}],"con":true,"img":false}]}
{"op":"mcm","clk":"1349978922","pt":1588414460817,"mc":[{"id":"1.170370562","rc":[{"atb":[[1.73,222],[1.69,0]],"id":9625043}],"con":true,"img":false}]}
{"op":"mcm","clk":"1349978926","pt":1588414461025,"mc":[{"id":"1.170370562","rc":[{"atb":[[1.75,18.42]],"id":9625043}],"con":true,"img":false}]}
{"op":"mcm","clk":"1349978933","pt":1588414461287,"mc":[{"id":"1.170370562","rc":[{"atb":[[1.7,0]],"id":9631798}],"con":true,"img":false}]}
{"op":"mcm","clk":"1349978951","pt":1588414461808,"mc":[{"id":"1.170370562","rc":[{"trd":[[1.73,211.94],[1.75,80.9]],"ltp":1.73,"tv":292.84,"id":9625043},{"atb":[[1.73,117.8],[1.75,0]],"id":9625043}],"con":true,"img":false}]}
{"op":"mcm","clk":"1349978962","pt":1588414462328,"mc":[{"id":"1.170370562","rc":[{"atb":[[1.66,222]],"id":9625043}],"con":true,"img":false}]}
{"op":"mcm","clk":"1349978989","pt":1588414463103,"mc":[{"id":"1.170370562","rc":[{"atl":[[2.34,0.81]],"id":9631798}],"con":true,"img":false}]}
{"op":"mcm","clk":"1349979048","pt":1588414464915,"mc":[{"id":"1.170370562","rc":[{"trd":[[1.74,36.04]],"ltp":1.74,"tv":36.04,"id":9625043},{"trd":[[2.34,0.2]],"ltp":2.34,"tv":0.2,"id":9631798},{"atl":[[2.34,0.6]],"id":9631798}],"con":true,"img":false}]}
{"op":"mcm","clk":"1349979055","pt":1588414465121,"mc":[{"id":"1.170370562","rc":[{"trd":[[1.74,36.15]],"ltp":1.74,"tv":36.15,"id":9625043},{"trd":[[2.34,0.28]],"ltp":2.34,"tv":0.28,"id":9631798},{"atl":[[2.34,0.53]],"id":9631798}],"con":true,"img":false}]}
{"op":"mcm","clk":"1349979060","pt":1588414465327,"mc":[{"id":"1.170370562","rc":[{"atl":[[1.76,35.46]],"id":9625043}],"con":true,"img":false}]}
{"op":"mcm","clk":"1349979073","pt":1588414465693,"mc":[{"id":"1.170370562","rc":[{"atl":[[1.76,0]],"id":9625043}],"con":true,"img":false}]}
{"op":"mcm","clk":"1349979083","pt":1588414466000,"mc":[{"id":"1.170370562","rc":[{"atl":[[2.02,265.95]],"id":9625043}],"con":true,"img":false}]}
{"op":"mcm","clk":"1349979093","pt":1588414466206,"mc":[{"id":"1.170370562","rc":[{"atl":[[3,100.51]],"id":9631798}],"con":true,"img":false}]}
{"op":"mcm","clk":"1349979127","pt":1588414467191,"mc":[{"id":"1.170370562","rc":[{"atb":[[1.77,233.57]],"id":9631798}],"con":true,"img":false}]}
{"op":"mcm","clk":"1349979153","pt":1588414468122,"mc":[{"id":"1.170370562","rc":[{"atl":[[2,112.02]],"id":9625043}],"con":true,"img":false}]}
{"op":"mcm","clk":"1349979175","pt":1588414468538,"mc":[{"id":"1.170370562","rc":[{"atb":[[1.59,265.95]],"id":9625043}],"con":true,"img":false}]}
{"op":"mcm","clk":"1349979236","pt":1588414471123,"mc":[{"id":"1.170370562","rc":[{"atl":[[2.3,0.7]],"id":9631798}],"con":true,"img":false}]}
{"op":"mcm","clk":"1349979249","pt":1588414471803,"mc":[{"id":"1.170370562","rc":[{"atb":[[1.76,17.73]],"id":9625043}],"con":true,"img":false}]}
{"op":"mcm","clk":"1349979268","pt":1588414472527,"mc":[{"id":"1.170370562","rc":[{"atb":[[1.75,17.73]],"id":9625043}],"con":true,"img":false}]}
{"op":"mcm","clk":"1349979315","pt":1588414474140,"mc":[{"id":"1.170370562","rc":[{"atb":[[1.66,0]],"id":9625043}],"con":true,"img":false}]}
{"op":"mcm","clk":"1349979356","pt":1588414475544,"mc":[{"id":"1.170370562","rc":[{"atl":[[1.91,0]],"id":9625043}],"con":true,"img":false}]}
{"op":"mcm","clk":"1349979369","pt":1588414476112,"mc":[{"id":"1.170370562","rc":[{"atl":[[1.79,0]],"id":9625043}],"con":true,"img":false}]}
{"op":"mcm","clk":"1349979379","pt":1588414476737,"mc":[{"id":"1.170370562","rc":[{"trd":[[1.76,158.87]],"ltp":1.76,"tv":158.87,"id":9625043},{"atb":[[1.76,17.37]],"id":9625043}],"con":true,"img":false}]}
{"op":"mcm","clk":"1349979384","pt":1588414476945,"mc":[{"id":"1.170370562","rc":[{"atb":[[1.76,17.79]],"id":9625043}],"con":true,"img":false}]}
{"op":"mcm","clk":"1349979407","pt":1588414477825,"mc":[{"id":"1.170370562","rc":[{"atb":[[1.75,18.41]],"id":9625043}],"con":true,"img":false}]}
{"op":"mcm","clk":"1349979416","pt":1588414478038,"mc":[{"id":"1.170370562","rc":[{"atl":[[2.3,0]],"id":9631798}],"con":true,"img":false}]}
{"op":"mcm","clk":"1349979477","pt":1588414479737,"mc":[{"id":"1.170370562","rc":[{"atb":[[1.68,112],[1.76,0.42],[1.72,0],[1.75,0.68]],"id":9625043}],"con":true,"img":false}]}
{"op":"mcm","clk":"1349979514","pt":1588414481145,"mc":[{"id":"1.170370562","rc":[{"atb":[[1.73,0]],"id":9625043}],"con":true,"img":false}]}
{"op":"mcm","clk":"1349979558","pt":1588414483332,"mc":[{"id":"1.170370562","rc":[{"atb":[[1.64,0],[1.58,0],[1.68,0],[1.48,0],[1.86,1000]],"id":9625043}],"con":true,"img":false}]}
{"op":"mcm","clk":"1349979570","pt":1588414483747,"mc":[{"id":"1.170370562","rc":[{"atl":[[2,0.11]],"id":9625043}],"con":true,"img":false}]}
{"op":"mcm","clk":"1349979626","pt":1588414485053,"mc":[{"id":"1.170370562","rc":[{"atb":[[1.91,199.96]],"id":9625043}],"con":true,"img":false}]}
{"op":"mcm","clk":"1349979642","pt":1588414485462,"mc":[{"id":"1.170370562","rc":[{"atb":[[1.89,199.96]],"id":9625043}],"con":true,"img":false}]}
{"op":"mcm","clk":"1349979645","pt":1588414485565,"mc":[{"id":"1.170370562","rc":[{"atb":[[1.81,17.73]],"id":9625043}],"con":true,"img":false}]}
{"op":"mcm","clk":"1349979660","pt":1588414485927,"mc":[{"id":"1.170370562","rc":[{"atb":[[1.82,17.73]],"id":9625043}],"con":true,"img":false}]}
{"op":"mcm","clk":"1349979666","pt":1588414486340,"mc":[{"id":"1.170370562","rc":[{"atl":[[3,0]],"id":9631798}],"con":true,"img":false}]}
{"op":"mcm","clk":"1349979668","pt":1588414486443,"mc":[{"id":"1.170370562","rc":[{"atb":[[1.76,22.42]],"id":9625043}],"con":true,"img":false}]}
{"op":"mcm","clk":"1349979670","pt":1588414486546,"mc":[{"id":"1.170370562","rc":[{"atb":[[1.83,17.73]],"id":9625043}],"con":true,"img":false}]}
{"op":"mcm","clk":"1349979727","pt":1588414488666,"mc":[{"id":"1.170370562","rc":[{"atb":[[1.6,222]],"id":9625043}],"con":true,"img":false}]}
{"op":"mcm","clk":"1349979733","pt":1588414489241,"mc":[{"id":"1.170370562","rc":[{"atb":[[1.8,112]],"id":9625043}],"con":true,"img":false}]}
{"op":"mcm","clk":"1349979739","pt":1588414489446,"mc":[{"id":"1.170370562","rc":[{"atb":[[1.85,152.35]],"id":9625043}],"con":true,"img":false}]}
{"op":"mcm","clk":"1349979741","pt":1588414489654,"mc":[{"id":"1.170370562","rc":[{"atb":[[1.87,17.73]],"id":9625043}],"con":true,"img":false}]}
{"op":"mcm","clk":"1349979744","pt":1588414489757,"mc":[{"id":"1.170370562","rc":[{"atb":[[1.88,112]],"id":9625043}],"con":true,"img":false}]}
{"op":"mcm","clk":"1349979763","pt":1588414490330,"mc":[{"id":"1.170370562","rc":[{"atb":[[1.88,219.76]],"id":9625043}],"con":true,"img":false}]}
{"op":"mcm","clk":"1349979767","pt":1588414490432,"mc":[{"id":"1.170370562","rc":[{"atb":[[1.93,302.55]],"id":9625043}],"con":true,"img":false}]}
{"op":"mcm","clk":"1349979775","pt":1588414490746,"mc":[{"id":"1.170370562","rc":[{"atb":[[1.9,112]],"id":9625043}],"con":true,"img":false}]}
{"op":"mcm","clk":"1349979780","pt":1588414490846,"mc":[{"id":"1.170370562","rc":[{"atb":[[1.81,0],[1.88,112],[1.83,0],[1.87,0],[1.76,0.42],[1.82,0]],"id":9625043}],"con":true,"img":false}]}
{"op":"mcm","clk":"1349979786","pt":1588414490950,"mc":[{"id":"1.170370562","rc":[{"atb":[[1.86,0]],"id":9625043}],"con":true,"img":false}]}
{"op":"mcm","clk":"1349979799","pt":1588414491364,"mc":[{"id":"1.170370562","rc":[{"atb":[[1.92,112]],"id":9625043}],"con":true,"img":false}]}
{"op":"mcm","clk":"1349979812","pt":1588414491727,"mc":[{"id":"1.170370562","rc":[{"atb":[[1.93,502.51]],"id":9625043}],"con":true,"img":false}]}
{"op":"mcm","clk":"1349979816","pt":1588414491832,"mc":[{"id":"1.170370562","rc":[{"atb":[[1.94,112]],"id":9625043}],"con":true,"img":false}]}
{"op":"mcm","clk":"1349979824","pt":1588414492141,"mc":[{"id":"1.170370562","rc":[{"atl":[[2.72,114.44]],"id":9631798}],"con":true,"img":false}]}
{"op":"mcm","clk":"1349979831","pt":1588414492557,"mc":[{"id":"1.170370562","rc":[{"atb":[[1.93,302.55]],"id":9625043}],"con":true,"img":false}]}
{"op":"mcm","clk":"1349979834","pt":1588414492660,"mc":[{"id":"1.170370562","rc":[{"atb":[[1.93,413.21],[1.71,147.16],[1.59,0],[1.85,0]],"id":9625043},{"atl":[[2.02,0]],"id":9625043}],"con":true,"img":false}]}
{"op":"mcm","clk":"1349979837","pt":1588414492760,"mc":[{"id":"1.170370562","rc":[{"atb":[[1.92,217.52]],"id":9625043}],"con":true,"img":false}]}
{"op":"mcm","clk":"1349979871","pt":1588414493747,"mc":[{"id":"1.170370562","rc":[{"atb":[[1.92,235.25]],"id":9625043}],"con":true,"img":false}]}
{"op":"mcm","clk":"1349979875","pt":1588414493852,"mc":[{"id":"1.170370562","rc":[{"atb":[[1.93,302.55]],"id":9625043}],"con":true,"img":false}]}
{"op":"mcm","clk":"1349979893","pt":1588414494264,"mc":[{"id":"1.170370562","rc":[{"atb":[[1.89,0],[1.92,252.98]],"id":9625043}],"con":true,"img":false}]}
{"op":"mcm","clk":"1349979897","pt":1588414494368,"mc":[{"id":"1.170370562","rc":[{"atb":[[1.92,140.98]],"id":9625043}],"con":true,"img":false}]}
{"op":"mcm","clk":"1349979915","pt":1588414494783,"mc":[{"id":"1.170370562","rc":[{"atb":[[1.71,0]],"id":9625043}],"con":true,"img":false}]}
{"op":"mcm","clk":"1349979930","pt":1588414495354,"mc":[{"id":"1.170370562","rc":[{"atb":[[1.9,0]],"id":9625043}],"con":true,"img":false}]}
{"op":"mcm","clk":"1349979933","pt":1588414495561,"mc":[{"id":"1.170370562","rc":[{"atb":[[1.92,0]],"id":9625043}],"con":true,"img":false}]}
{"op":"mcm","clk":"1349979963","pt":1588414496649,"mc":[{"id":"1.170370562","rc":[{"atb":[[1.92,44.32]],"id":9625043}],"con":true,"img":false}]}
{"op":"mcm","clk":"1349979971","pt":1588414496959,"mc":[{"id":"1.170370562","rc":[{"atb":[[1.94,311.96]],"id":9625043}],"con":true,"img":false}]}
{"op":"mcm","clk":"1349979977","pt":1588414497166,"mc":[{"id":"1.170370562","rc":[{"atb":[[1.94,329.69]],"id":9625043}],"con":true,"img":false}]}
{"op":"mcm","clk":"1349979996","pt":1588414497685,"mc":[{"id":"1.170370562","rc":[{"atb":[[1.94,347.42]],"id":9625043}],"con":true,"img":false}]}
{"op":"mcm","clk":"1349980009","pt":1588414498157,"mc":[{"id":"1.170370562","rc":[{"atb":[[1.95,199.96]],"id":9625043}],"con":true,"img":false}]}
{"op":"mcm","clk":"1349980012","pt":1588414498267,"mc":[{"id":"1.170370562","rc":[{"atb":[[1.95,217.69]],"id":9625043}],"con":true,"img":false}]}
{"op":"mcm","clk":"1349980021","pt":1588414498469,"mc":[{"id":"1.170370562","rc":[{"atb":[[1.6,0]],"id":9625043}],"con":true,"img":false}]}
{"op":"mcm","clk":"1349980035","pt":1588414498881,"mc":[{"id":"1.170370562","rc":[{"trd":[[1.95,0.82]],"ltp":1.95,"tv":0.82,"id":9625043},{"atb":[[1.95,217.28]],"id":9625043}],"con":true,"img":false}]}
{"op":"mcm","clk":"1349980053","pt":1588414499350,"mc":[{"id":"1.170370562","rc":[{"atb":[[1.96,103.36]],"id":9625043}],"con":true,"img":false}]}
{"op":"mcm","clk":"1349980074","pt":1588414499973,"mc":[{"id":"1.170370562","rc":[{"trd":[[2,0.44]],"ltp":2.0,"tv":0.44,"id":9625043},{"atb":[[2,221.88],[1.92,0]],"id":9625043},{"atl":[[2,0]],"id":9625043}],"con":true,"img":false}]}
{"op":"mcm","clk":"1349980107","pt":1588414500865,"mc":[{"id":"1.170370562","rc":[{"trd":[[2,5.7]],"ltp":2.0,"tv":5.7,"id":9625043},{"atb":[[2,219.25]],"id":9625043}],"con":true,"img":false}]}
{"op":"mcm","clk":"1349980111","pt":1588414500966,"mc":[{"id":"1.170370562","rc":[{"atb":[[1.79,12.65]],"id":9631798}],"con":true,"img":false}]}
{"op":"mcm","clk":"1349980135","pt":1588414501597,"mc":[{"id":"1.170370562","rc":[{"trd":[[2,47.74]],"ltp":2.0,"tv":47.74,"id":9625043},{"atb":[[2,198.23]],"id":9625043}],"con":true,"img":false}]}
{"op":"mcm","clk":"1349980149","pt":1588414502058,"mc":[{"id":"1.170370562","rc":[{"atb":[[1.91,0]],"id":9625043}],"con":true,"img":false}]}
{"op":"mcm","clk":"1349980205","pt":1588414503576,"mc":[{"id":"1.170370562","rc":[{"atb":[[1.93,0]],"id":9625043}],"con":true,"img":false}]}
{"op":"mcm","clk":"1349980237","pt":1588414504406,"mc":[{"id":"1.170370562","rc":[{"trd":[[2,54.74]],"ltp":2.0,"tv":54.74,"id":9625043},{"atb":[[2,194.73],[1.94,235.42]],"id":9625043},{"atb":[[1.9,4]],"id":9631798}],"con":true,"img":false}]}
{"op":"mcm","clk":"1349980241","pt":1588414504470,"mc":[{"id":"1.170370562","rc":[{"trd":[[2,58.32]],"ltp":2.0,"tv":58.32,"id":9625043},{"atb":[[2,192.94]],"id":9625043}],"con":true,"img":false}]}
{"op":"mcm","clk":"1349980253","pt":1588414504884,"mc":[{"id":"1.170370562","rc":[{"atb":[[1.94,35.46]],"id":9625043}],"con":true,"img":false}]}
{"op":"mcm","clk":"1349980258","pt":1588414505090,"mc":[{"id":"1.170370562","rc":[{"atb":[[1.96,147.69]],"id":9625043}],"con":true,"img":false}]}
{"op":"mcm","clk":"1349980311","pt":1588414507167,"mc":[{"id":"1.170370562","rc":[{"atb":[[1.88,0]],"id":9625043},{"atl":[[2.7,265.95]],"id":9625043}],"con":true,"img":false}]}
{"op":"mcm","clk":"1349980338","pt":1588414508200,"mc":[{"id":"1.170370562","rc":[{"atb":[[2.02,37.11]],"id":9625043},{"atb":[[1.95,819.82]],"id":9631798}],"con":true,"img":false}]}
{"op":"mcm","clk":"1349980388","pt":1588414509718,"mc":[{"id":"1.170370562","rc":[{"atb":[[1.95,17.73]],"id":9625043}],"con":true,"img":false}]}
{"op":"mcm","clk":"1349980390","pt":1588414509771,"mc":[{"id":"1.170370562","rc":[{"atb":[[1.78,265.95]],"id":9625043}],"con":true,"img":false}]}
{"op":"mcm","clk":"1349980397","pt":1588414509877,"mc":[{"id":"1.170370562","rc":[{"trd":[[2.02,17.51]],"ltp":2.02,"tv":17.51,"id":9625043},{"atb":[[2.02,28.35]],"id":9625043}],"con":true,"img":false}]}
{"op":"mcm","clk":"1349980438","pt":1588414511175,"mc":[{"id":"1.170370562","rc":[{"atb":[[1.8,0]],"id":9625043}],"con":true,"img":false}]}
{"op":"mcm","clk":"1349980466","pt":1588414512319,"mc":[{"id":"1.170370562","rc":[{"atb":[[1.96,44.32],[1.94,0],[1.95,0]],"id":9625043}],"con":true,"img":false}]}
{"op":"mcm","clk":"1349980471","pt":1588414512372,"mc":[{"id":"1.170370562","rc":[{"atb":[[1.72,221.63]],"id":9631798}],"con":true,"img":false}]}
{"op":"mcm","clk":"1349980495","pt":1588414513097,"mc":[{"id":"1.170370562","rc":[{"atb":[[2,0],[2.02,0]],"id":9625043}],"con":true,"img":false}]}
{"op":"mcm","clk":"1349980518","pt":1588414513718,"mc":[{"id":"1.170370562","rc":[{"atb":[[1.96,0]],"id":9625043}],"con":true,"img":false}]}
{"op":"mcm","clk":"1349980547","pt":1588414514521,"mc":[{"id":"1.170370562","rc":[{"atl":[[2,8.75]],"id":9625043},{"atb":[[1.9,0]],"id":9631798}],"con":true,"img":false}]}
{"op":"mcm","clk":"1349980582","pt":1588414515375,"mc":[{"id":"1.170370562","rc":[{"atl":[[2.72,0]],"id":9631798}],"con":true,"img":false}]}
{"op":"mcm","clk":"1349980605","pt":1588414516096,"mc":[{"id":"1.170370562","rc":[{"atl":[[1.91,1000]],"id":9625043}],"con":true,"img":false}]}
{"op":"mcm","clk":"1349980647","pt":1588414517499,"mc":[{"id":"1.170370562","rc":[{"atb":[[1.95,0]],"id":9631798}],"con":true,"img":false}]}
{"op":"mcm","clk":"1349980658","pt":1588414517914,"mc":[{"id":"1.170370562","rc":[{"atb":[[2.08,248.76]],"id":9631798}],"con":true,"img":false}]}
{"op":"mcm","clk":"1349980668","pt":1588414518173,"mc":[{"id":"1.170370562","rc":[{"atb":[[2.08,497.52]],"id":9631798}],"con":true,"img":false}]}
{"op":"mcm","clk":"1349980670","pt":1588414518277,"mc":[{"id":"1.170370562","rc":[{"atb":[[1.99,4]],"id":9631798}],"con":true,"img":false}]}
{"op":"mcm","clk":"1349980682","pt":1588414518588,"mc":[{"id":"1.170370562","rc":[{"atl":[[1.93,492.02]],"id":9625043}],"con":true,"img":false}]}
{"op":"mcm","clk":"1349980687","pt":1588414518952,"mc":[{"id":"1.170370562","rc":[{"atl":[[1.99,112],[1.91,0]],"id":9625043}],"con":true,"img":false}]}
{"op":"mcm","clk":"1349980690","pt":1588414519001,"mc":[{"id":"1.170370562","rc":[{"atl":[[1.94,17.73]],"id":9625043},{"trd":[[2.08,0.06]],"ltp":2.08,"tv":0.06,"id":9631798},{"atb":[[2.08,497.48]],"id":9631798}],"con":true,"img":false}]}
{"op":"mcm","clk":"1349980701","pt":1588414519420,"mc":[{"id":"1.170370562","rc":[{"atl":[[1.99,377.95]],"id":9625043}],"con":true,"img":false}]}
{"op":"mcm","clk":"1349980706","pt":1588414519475,"mc":[{"id":"1.170370562","rc":[{"atl":[[1.94,35.46],[1.93,0]],"id":9625043}],"con":true,"img":false}]}
{"op":"mcm","clk":"1349980726","pt":1588414520101,"mc":[{"id":"1.170370562","rc":[{"atl":[[2.02,12.26]],"id":9625043}],"con":true,"img":false}]}
{"op":"mcm","clk":"1349980731","pt":1588414520304,"mc":[{"id":"1.170370562","rc":[{"atb":[[1.84,222]],"id":9625043}],"con":true,"img":false}]}
{"op":"mcm","clk":"1349980757","pt":1588414521278,"mc":[{"id":"1.170370562","rc":[{"atl":[[3.15,94.11]],"id":9631798}],"con":true,"img":false}]}
{"op":"mcm","clk":"1349980766","pt":1588414521587,"mc":[{"id":"1.170370562","rc":[{"atb":[[1.99,0]],"id":9631798}],"con":true,"img":false}]}
{"op":"mcm","clk":"1349980783","pt":1588414522208,"mc":[{"id":"1.170370562","rc":[{"atb":[[1.72,221.74]],"id":9631798}],"con":true,"img":false}]}
{"op":"mcm","clk":"1349980793","pt":1588414522518,"mc":[{"id":"1.170370562","rc":[{"atl":[[1.9,17.73]],"id":9625043}],"con":true,"img":false}]}
{"op":"mcm","clk":"1349980800","pt":1588414522724,"mc":[{"id":"1.170370562","rc":[{"atl":[[2.02,0]],"id":9625043}],"con":true,"img":false}]}
{"op":"mcm","clk":"1349980809","pt":1588414523031,"mc":[{"id":"1.170370562","rc":[{"atl":[[1.89,17.73]],"id":9625043}],"con":true,"img":false}]}
{"op":"mcm","clk":"1349980831","pt":1588414523702,"mc":[{"id":"1.170370562","rc":[{"atb":[[1.79,112]],"id":9625043}],"con":true,"img":false}]}
{"op":"mcm","clk":"1349980863","pt":1588414524734,"mc":[{"id":"1.170370562","rc":[{"atb":[[1.67,112]],"id":9625043}],"con":true,"img":false}]}
{"op":"mcm","clk":"1349980869","pt":1588414524888,"mc":[{"id":"1.170370562","rc":[{"atb":[[1.79,129.73]],"id":9625043}],"con":true,"img":false}]}
{"op":"mcm","clk":"1349980884","pt":1588414525402,"mc":[{"id":"1.170370562","rc":[{"atb":[[1.79,147.46]],"id":9625043}],"con":true,"img":false}]}
{"op":"mcm","clk":"1349980988","pt":1588414528594,"mc":[{"id":"1.170370562","rc":[{"atb":[[1.75,0]],"id":9625043}],"con":true,"img":false}]}
{"op":"mcm","clk":"1349981009","pt":1588414529415,"mc":[{"id":"1.170370562","rc":[{"atl":[[2.82,10]],"id":9631798}],"con":true,"img":false}]}
{"op":"mcm","clk":"1349981015","pt":1588414529518,"mc":[{"id":"1.170370562","rc":[{"trd":[[1.84,123.72]],"ltp":1.84,"tv":123.72,"id":9625043},{"atb":[[1.84,116]],"id":9625043},{"trd":[[2.2,88.65]],"ltp":2.2,"tv":88.65,"id":9631798}],"con":true,"img":false}]}
{"op":"mcm","clk":"1349981026","pt":1588414530135,"mc":[{"id":"1.170370562","rc":[{"atb":[[1.81,17.73]],"id":9625043}],"con":true,"img":false}]}
{"op":"mcm","clk":"1349981031","pt":1588414530343,"mc":[{"id":"1.170370562","rc":[{"trd":[[1.89,126.76]],"ltp":1.89,"tv":126.76,"id":9625043},{"atl":[[1.89,16.78]],"id":9625043},{"trd":[[2.12,0.84]],"ltp":2.12,"tv":0.84,"id":9631798}],"con":true,"img":false}]}
{"op":"mcm","clk":"1349981039","pt":1588414530704,"mc":[{"id":"1.170370562","rc":[{"atb":[[1.81,35.46]],"id":9625043}],"con":true,"img":false}]}
{"op":"mcm","clk":"1349981054","pt":1588414531016,"mc":[{"id":"1.170370562","rc":[{"atl":[[2.82,0]],"id":9631798}],"con":true,"img":false}]}
{"op":"mcm","clk":"1349981063","pt":1588414531224,"mc":[{"id":"1.170370562","rc":[{"atl":[[1.99,265.95]],"id":9625043}],"con":true,"img":false}]}
{"op":"mcm","clk":"1349981070","pt":1588414531327,"mc":[{"id":"1.170370562","rc":[{"trd":[[1.84,125.48]],"ltp":1.84,"tv":125.48,"id":9625043},{"atb":[[1.84,115.12]],"id":9625043}],"con":true,"img":false}]}
{"op":"mcm","clk":"1349981114","pt":1588414532512,"mc":[{"id":"1.170370562","rc":[{"trd":[[1.84,125.79]],"ltp":1.84,"tv":125.79,"id":9625043},{"atb":[[1.84,114.97]],"id":9625043}],"con":true,"img":false}]}
{"op":"mcm","clk":"1349981169","pt":1588414533909,"mc":[{"id":"1.170370562","rc":[{"atb":[[1.78,0]],"id":9625043},{"atl":[[1.99,0],[2.7,0]],"id":9625043}],"con":true,"img":false}]}
{"op":"mcm","clk":"1349981173","pt":1588414534013,"mc":[{"id":"1.170370562","rc":[{"atb":[[1.72,0.11]],"id":9631798}],"con":true,"img":false}]}
{"op":"mcm","clk":"1349981207","pt":1588414535149,"mc":[{"id":"1.170370562","rc":[{"trd":[[1.89,126.88]],"ltp":1.89,"tv":126.88,"id":9625043},{"atl":[[1.89,16.66]],"id":9625043},{"trd":[[2.12,0.95]],"ltp":2.12,"tv":0.95,"id":9631798}],"con":true,"img":false}]}
{"op":"mcm","clk":"1349981215","pt":1588414535303,"mc":[{"id":"1.170370562","rc":[{"atb":[[1.81,0]],"id":9625043}],"con":true,"img":false}]}
{"op":"mcm","clk":"1349981243","pt":1588414536439,"mc":[{"id":"1.170370562","rc":[{"atb":[[1.79,112]],"id":9625043}],"con":true,"img":false}]}
{"op":"mcm","clk":"1349981255","pt":1588414536801,"mc":[{"id":"1.170370562","rc":[{"atb":[[1.79,112.11]],"id":9625043}],"con":true,"img":false}]}
{"op":"mcm","clk":"1349981282","pt":1588414537629,"mc":[{"id":"1.170370562","rc":[{"trd":[[1.84,150.31]],"ltp":1.84,"tv":150.31,"id":9625043},{"atb":[[1.84,102.71]],"id":9625043}],"con":true,"img":false}]}
{"op":"mcm","clk":"1349981287","pt":1588414537731,"mc":[{"id":"1.170370562","rc":[{"atb":[[1.79,0.11],[1.67,0]],"id":9625043}],"con":true,"img":false}]}
{"op":"mcm","clk":"1349981289","pt":1588414537835,"mc":[{"id":"1.170370562","rc":[{"atb":[[1.84,0]],"id":9625043},{"atl":[[3.1,10]],"id":9631798}],"con":true,"img":false}]}
{"op":"mcm","clk":"1349981301","pt":1588414538147,"mc":[{"id":"1.170370562","rc":[{"atl":[[1.84,0.46]],"id":9625043}],"con":true,"img":false}]}
{"op":"mcm","clk":"1349981314","pt":1588414538403,"mc":[{"id":"1.170370562","rc":[{"atl":[[1.84,0.25]],"id":9625043}],"con":true,"img":false}]}
{"op":"mcm","clk":"1349981336","pt":1588414539246,"mc":[{"id":"1.170370562","rc":[{"atl":[[1.8,1000]],"id":9625043}],"con":true,"img":false}]}
{"op":"mcm","clk":"1349981354","pt":1588414539919,"mc":[{"id":"1.170370562","rc":[{"atl":[[4.3,10]],"id":9631798}],"con":true,"img":false}]}
{"op":"mcm","clk":"1349981367","pt":1588414540436,"mc":[{"id":"1.170370562","rc":[{"trd":[[1.74,36.86],[1.76,159.72],[1.79,102.53]],"ltp":1.74,"tv":299.11,"id":9625043},{"atb":[[1.76,0],[1.79,0]],"id":9625043},{"atl":[[1.74,490.76]],"id":9625043},{"trd":[[2.34,0.81]],"ltp":2.34,"tv":0.81,"id":9631798},{"atl":[[2.34,0]],"id":9631798}],"con":true,"img":false}]}
{"op":"mcm","clk":"1349981375","pt":1588414540745,"mc":[{"id":"1.170370562","rc":[{"atb":[[2.28,248.76]],"id":9631798}],"con":true,"img":false}]}
{"op":"mcm","clk":"1349981384","pt":1588414541053,"mc":[{"id":"1.170370562","rc":[{"trd":[[1.74,37.43]],"ltp":1.74,"tv":37.43,"id":9625043},{"atl":[[1.74,490.19]],"id":9625043},{"trd":[[2.34,1.23]],"ltp":2.34,"tv":1.23,"id":9631798}],"con":true,"img":false}]}
{"op":"mcm","clk":"1349981387","pt":1588414541156,"mc":[{"id":"1.170370562","rc":[{"atb":[[2.28,497.52]],"id":9631798}],"con":true,"img":false}]}
{"op":"mcm","clk":"1349981403","pt":1588414541828,"mc":[{"id":"1.170370562","rc":[{"atl":[[1.84,2.82]],"id":9625043}],"con":true,"img":false}]}
{"op":"mcm","clk":"1349981408","pt":1588414542035,"mc":[{"id":"1.170370562","rc":[{"atl":[[1.81,43.79],[1.76,17.73]],"id":9625043}],"con":true,"img":false}]}
{"op":"mcm","clk":"1349981418","pt":1588414542344,"mc":[{"id":"1.170370562","rc":[{"atb":[[1.77,0]],"id":9631798}],"con":true,"img":false}]}
{"op":"mcm","clk":"1349981422","pt":1588414542446,"mc":[{"id":"1.170370562","rc":[{"atl":[[1.84,3.05]],"id":9625043}],"con":true,"img":false}]}
{"op":"mcm","clk":"1349981426","pt":1588414542549,"mc":[{"id":"1.170370562","rc":[{"atl":[[1.76,35.46]],"id":9625043}],"con":true,"img":false}]}
{"op":"mcm","clk":"1349981442","pt":1588414543013,"mc":[{"id":"1.170370562","rc":[{"atb":[[2.08,0]],"id":9631798}],"con":true,"img":false}]}
{"op":"mcm","clk":"1349981458","pt":1588414543323,"mc":[{"id":"1.170370562","rc":[{"atb":[[1.73,44.32]],"id":9625043}],"con":true,"img":false}]}
{"op":"mcm","clk":"1349981466","pt":1588414543530,"mc":[{"id":"1.170370562","rc":[{"atl":[[1.83,112]],"id":9625043}],"con":true,"img":false}]}
{"op":"mcm","clk":"1349981470","pt":1588414543632,"mc":[{"id":"1.170370562","rc":[{"atl":[[1.8,1222]],"id":9625043}],"con":true,"img":false}]}
{"op":"mcm","clk":"1349981474","pt":1588414543735,"mc":[{"id":"1.170370562","rc":[{"atl":[[1.8,222]],"id":9625043}],"con":true,"img":false}]}
{"op":"mcm","clk":"1349981478","pt":1588414543838,"mc":[{"id":"1.170370562","rc":[{"atl":[[1.78,222]],"id":9625043}],"con":true,"img":false}]}
{"op":"mcm","clk":"1349981482","pt":1588414543943,"mc":[{"id":"1.170370562","rc":[{"atl":[[1.78,334]],"id":9625043}],"con":true,"img":false}]}
{"op":"mcm","clk":"1349981488","pt":1588414544046,"mc":[{"id":"1.170370562","rc":[{"atb":[[2.18,8.47]],"id":9631798}],"con":true,"img":false}]}
{"op":"mcm","clk":"1349981494","pt":1588414544253,"mc":[{"id":"1.170370562","rc":[{"atl":[[1.8,0]],"id":9625043}],"con":true,"img":false}]}
{"op":"mcm","clk":"1349981502","pt":1588414544460,"mc":[{"id":"1.170370562","rc":[{"atl":[[1.81,0]],"id":9625043}],"con":true,"img":false}]}
{"op":"mcm","clk":"1349981511","pt":1588414544614,"mc":[{"id":"1.170370562","rc":[{"atl":[[1.74,0]],"id":9625043}],"con":true,"img":false}]}
{"op":"mcm","clk":"1349981517","pt":1588414544716,"mc":[{"id":"1.170370562","rc":[{"atl":[[1.78,112]],"id":9625043}],"con":true,"img":false}]}
{"op":"mcm","clk":"1349981523","pt":1588414544925,"mc":[{"id":"1.170370562","rc":[{"atb":[[2.18,0]],"id":9631798}],"con":true,"img":false}]}
{"op":"mcm","clk":"1349981539","pt":1588414545234,"mc":[{"id":"1.170370562","rc":[{"trd":[[1.73,247.4]],"ltp":1.73,"tv":247.4,"id":9625043},{"atb":[[1.73,26.59]],"id":9625043}],"con":true,"img":false}]}
{"op":"mcm","clk":"1349981545","pt":1588414545336,"mc":[{"id":"1.170370562","rc":[{"atb":[[1.66,184.52]],"id":9625043}],"con":true,"img":false}]}
{"op":"mcm","clk":"1349981556","pt":1588414545646,"mc":[{"id":"1.170370562","rc":[{"trd":[[1.76,170.17]],"ltp":1.76,"tv":170.17,"id":9625043},{"atb":[[1.42,0]],"id":9625043},{"atl":[[1.76,25]],"id":9625043},{"trd":[[2.3,13.18]],"ltp":2.3,"tv":13.18,"id":9631798}],"con":true,"img":false}]}
{"op":"mcm","clk":"1349981559","pt":1588414545749,"mc":[{"id":"1.170370562","rc":[{"atb":[[1.01,991.5]],"id":9625043}],"con":true,"img":false}]}
{"op":"mcm","clk":"1349981565","pt":1588414545955,"mc":[{"id":"1.170370562","rc":[{"atb":[[1.01,990.99]],"id":9625043}],"con":true,"img":false}]}
{"op":"mcm","clk":"1349981570","pt":1588414546162,"mc":[{"id":"1.170370562","rc":[{"atb":[[1.01,989.72]],"id":9625043}],"con":true,"img":false}]}
{"op":"mcm","clk":"1349981584","pt":1588414546419,"mc":[{"id":"1.170370562","rc":[{"atb":[[1.01,991.5]],"id":9625043}],"con":true,"img":false}]}
{"op":"mcm","clk":"1349981594","pt":1588414546624,"mc":[{"id":"1.170370562","rc":[{"atb":[[1.01,990.29]],"id":9625043}],"con":true,"img":false}]}
{"op":"mcm","clk":"1349981600","pt":1588414546728,"mc":[{"id":"1.170370562","rc":[{"atl":[[1.84,0.47]],"id":9625043}],"con":true,"img":false}]}
{"op":"mcm","clk":"1349981607","pt":1588414546829,"mc":[{"id":"1.170370562","rc":[{"atb":[[1.59,192.64],[1.01,989.72]],"id":9625043}],"con":true,"img":false}]}
{"op":"mcm","clk":"1349981610","pt":1588414546933,"mc":[{"id":"1.170370562","rc":[{"trd":[[1.73,282.86]],"ltp":1.73,"tv":282.86,"id":9625043},{"atb":[[1.73,8.86]],"id":9625043}],"con":true,"img":false}]}
{"op":"mcm","clk":"1349981614","pt":1588414547036,"mc":[{"id":"1.170370562","rc":[{"atb":[[1.6,112]],"id":9625043}],"con":true,"img":false}]}
{"op":"mcm","clk":"1349981627","pt":1588414547555,"mc":[{"id":"1.170370562","rc":[{"trd":[[1.73,300.59]],"ltp":1.73,"tv":300.59,"id":9625043},{"atb":[[1.73,0]],"id":9625043},{"atl":[[1.71,8.86]],"id":9625043}],"con":true,"img":false}]}
{"op":"mcm","clk":"1349981647","pt":1588414548122,"mc":[{"id":"1.170370562","rc":[{"atb":[[1.55,112]],"id":9625043}],"con":true,"img":false}]}
{"op":"mcm","clk":"1349981652","pt":1588414548228,"mc":[{"id":"1.170370562","rc":[{"atb":[[1.92,228.72]],"id":9631798}],"con":true,"img":false}]}
{"op":"mcm","clk":"1349981672","pt":1588414548853,"mc":[{"id":"1.170370562","rc":[{"atb":[[1.49,112]],"id":9625043}],"con":true,"img":false}]}
{"op":"mcm","clk":"1349981704","pt":1588414549636,"mc":[{"id":"1.170370562","rc":[{"atb":[[1.51,17.73]],"id":9625043}],"con":true,"img":false}]}
{"op":"mcm","clk":"1349981725","pt":1588414550256,"mc":[{"id":"1.170370562","rc":[{"atl":[[1.83,0],[1.78,0]],"id":9625043}],"con":true,"img":false}]}
{"op":"mcm","clk":"1349981730","pt":1588414550357,"mc":[{"id":"1.170370562","rc":[{"atb":[[1.59,0]],"id":9625043}],"con":true,"img":false}]}
{"op":"mcm","clk":"1349981740","pt":1588414550665,"mc":[{"id":"1.170370562","rc":[{"atl":[[1.7,13.78]],"id":9625043}],"con":true,"img":false}]}
{"op":"mcm","clk":"1349981759","pt":1588414551133,"mc":[{"id":"1.170370562","rc":[{"atb":[[1.66,202.25]],"id":9625043}],"con":true,"img":false}]}
{"op":"mcm","clk":"1349981761","pt":1588414551237,"mc":[{"id":"1.170370562","rc":[{"trd":[[1.7,2.53]],"ltp":1.7,"tv":2.53,"id":9625043},{"atl":[[1.7,12.51]],"id":9625043}],"con":true,"img":false}]}
{"op":"mcm","clk":"1349981769","pt":1588414551547,"mc":[{"id":"1.170370562","rc":[{"atb":[[1.67,17.73],[1.66,17.73]],"id":9625043}],"con":true,"img":false}]}
{"op":"mcm","clk":"1349981775","pt":1588414551753,"mc":[{"id":"1.170370562","rc":[{"atl":[[1000,2]],"id":9631798}],"con":true,"img":false}]}
{"op":"mcm","clk":"1349981779","pt":1588414551857,"mc":[{"id":"1.170370562","rc":[{"atb":[[1.67,129.73]],"id":9625043}],"con":true,"img":false}]}
{"op":"mcm","clk":"1349981784","pt":1588414551959,"mc":[{"id":"1.170370562","rc":[{"trd":[[1.7,3.67]],"ltp":1.7,"tv":3.67,"id":9625043},{"atl":[[1.7,11.94]],"id":9625043},{"atl":[[1000,0.01]],"id":9631798}],"con":true,"img":false}]}
{"op":"mcm","clk":"1349981792","pt":1588414552165,"mc":[{"id":"1.170370562","rc":[{"atb":[[1.68,17.73]],"id":9625043}],"con":true,"img":false}]}
{"op":"mcm","clk":"1349981795","pt":1588414552269,"mc":[{"id":"1.170370562","rc":[{"atl":[[1000,0]],"id":9631798}],"con":true,"img":false}]}
{"op":"mcm","clk":"1349981805","pt":1588414552426,"mc":[{"id":"1.170370562","rc":[{"atl":[[1000,2]],"id":9631798}],"con":true,"img":false}]}
{"op":"mcm","clk":"1349981814","pt":1588414552629,"mc":[{"id":"1.170370562","rc":[{"atb":[[1.68,35.46]],"id":9625043},{"atl":[[1000,0.01]],"id":9631798}],"con":true,"img":false}]}
{"op":"mcm","clk":"1349981823","pt":1588414552835,"mc":[{"id":"1.170370562","rc":[{"atb":[[1.67,174.05]],"id":9625043},{"atl":[[1000,0]],"id":9631798}],"con":true,"img":false}]}
{"op":"mcm","clk":"1349981843","pt":1588414553352,"mc":[{"id":"1.170370562","rc":[{"atl":[[1.84,0.25]],"id":9625043}],"con":true,"img":false}]}
{"op":"mcm","clk":"1349981880","pt":1588414554846,"mc":[{"id":"1.170370562","rc":[{"atl":[[2,8.87]],"id":9625043}],"con":true,"img":false}]}
{"op":"mcm","clk":"1349981883","pt":1588414554948,"mc":[{"id":"1.170370562","rc":[{"atb":[[2.4,43.73]],"id":9631798}],"con":true,"img":false}]}
{"op":"mcm","clk":"1349981889","pt":1588414555263,"mc":[{"id":"1.170370562","rc":[{"trd":[[1.71,291.17],[1.7,27.57]],"ltp":1.71,"tv":318.74,"id":9625043},{"atl":[[1.7,0],[1.71,1.31]],"id":9625043}],"con":true,"img":false}]}
{"op":"mcm","clk":"1349981928","pt":1588414556754,"mc":[{"id":"1.170370562","rc":[{"atb":[[1.64,186.77]],"id":9625043}],"con":true,"img":false}]}
{"op":"mcm","clk":"1349981936","pt":1588414557062,"mc":[{"id":"1.170370562","rc":[{"atb":[[2.4,0]],"id":9631798}],"con":true,"img":false}]}
{"op":"mcm","clk":"1349981944","pt":1588414557370,"mc":[{"id":"1.170370562","rc":[{"atl":[[2.6,0.01]],"id":9631798}],"con":true,"img":false}]}
{"op":"mcm","clk":"1349981947","pt":1588414557473,"mc":[{"id":"1.170370562","rc":[{"atl":[[2,508.87]],"id":9625043}],"con":true,"img":false}]}
{"op":"mcm","clk":"1349981965","pt":1588414557936,"mc":[{"id":"1.170370562","rc":[{"atl":[[2.46,0.01]],"id":9631798}],"con":true,"img":false}]}
{"op":"mcm","clk":"1349981972","pt":1588414558142,"mc":[{"id":"1.170370562","rc":[{"atb":[[1.64,0]],"id":9625043}],"con":true,"img":false}]}
{"op":"mcm","clk":"1349981984","pt":1588414558455,"mc":[{"id":"1.170370562","rc":[{"atb":[[1.56,177.3]],"id":9625043}],"con":true,"img":false}]}
{"op":"mcm","clk":"1349981989","pt":1588414558559,"mc":[{"id":"1.170370562","rc":[{"atl":[[3.1,0]],"id":9631798}],"con":true,"img":false}]}
{"op":"mcm","clk":"1349981997","pt":1588414558765,"mc":[{"id":"1.170370562","rc":[{"atb":[[1.67,129.73]],"id":9625043}],"con":true,"img":false}]}
{"op":"mcm","clk":"1349982005","pt":1588414559073,"mc":[{"id":"1.170370562","rc":[{"atb":[[1.68,36.15]],"id":9625043}],"con":true,"img":false}]}
{"op":"mcm","clk":"1349982025","pt":1588414559642,"mc":[{"id":"1.170370562","rc":[{"trd":[[1.71,293.79]],"ltp":1.71,"tv":293.79,"id":9625043},{"atb":[[1.71,53.69]],"id":9625043},{"atl":[[1.71,0]],"id":9625043}],"con":true,"img":false}]}
{"op":"mcm","clk":"1349982034","pt":1588414559847,"mc":[{"id":"1.170370562","rc":[{"trd":[[1.71,313.79]],"ltp":1.71,"tv":313.79,"id":9625043},{"atb":[[1.71,43.69]],"id":9625043}],"con":true,"img":false}]}
{"op":"mcm","clk":"1349982041","pt":1588414560053,"mc":[{"id":"1.170370562","rc":[{"atb":[[1.7,0.15]],"id":9625043}],"con":true,"img":false}]}
{"op":"mcm","clk":"1349982050","pt":1588414560364,"mc":[{"id":"1.170370562","rc":[{"atb":[[1.7,2.73]],"id":9625043}],"con":true,"img":false}]}
{"op":"mcm","clk":"1349982054","pt":1588414560570,"mc":[{"id":"1.170370562","rc":[{"atl":[[1.76,0]],"id":9625043}],"con":true,"img":false}]}
{"op":"mcm","clk":"1349982067","pt":1588414560933,"mc":[{"id":"1.170370562","rc":[{"trd":[[1.71,342.95]],"ltp":1.71,"tv":342.95,"id":9625043},{"atb":[[1.71,31.75]],"id":9625043}],"con":true,"img":false}]}
{"op":"mcm","clk":"1349982079","pt":1588414561344,"mc":[{"id":"1.170370562","rc":[{"trd":[[1.67,18.66],[1.7,33.02],[1.68,72.32],[1.71,406.46]],"ltp":1.67,"tv":530.46,"id":9625043},{"atb":[[1.7,0],[1.68,0],[1.71,0],[1.67,120.39]],"id":9625043},{"trd":[[2.46,0.01]],"ltp":2.46,"tv":0.01,"id":9631798},{"atl":[[2.46,0]],"id":9631798}],"con":true,"img":false}]}
{"op":"mcm","clk":"1349982139","pt":1588414563261,"mc":[{"id":"1.170370562","rc":[{"atb":[[1.61,186.77]],"id":9625043}],"con":true,"img":false}]}
{"op":"mcm","clk":"1349982143","pt":1588414563467,"mc":[{"id":"1.170370562","rc":[{"atl":[[1.68,245.24]],"id":9625043}],"con":true,"img":false}]}
{"op":"mcm","clk":"1349982146","pt":1588414563570,"mc":[{"id":"1.170370562","rc":[{"atb":[[1.65,0],[1.61,0]],"id":9625043}],"con":true,"img":false}]}
{"op":"mcm","clk":"1349982191","pt":1588414564986,"mc":[{"id":"1.170370562","rc":[{"atl":[[1.68,250.49]],"id":9625043}],"con":true,"img":false}]}
{"op":"mcm","clk":"1349982217","pt":1588414565869,"mc":[{"id":"1.170370562","rc":[{"atb":[[1.6,0]],"id":9625043}],"con":true,"img":false}]}
{"op":"mcm","clk":"1349982237","pt":1588414566283,"mc":[{"id":"1.170370562","rc":[{"trd":[[1.68,217.78]],"ltp":1.68,"tv":217.78,"id":9625043},{"atl":[[1.68,177.76]],"id":9625043}],"con":true,"img":false}]}
{"op":"mcm","clk":"1349982260","pt":1588414566754,"mc":[{"id":"1.170370562","rc":[{"trd":[[1.68,253.24]],"ltp":1.68,"tv":253.24,"id":9625043},{"atl":[[1.68,160.03]],"id":9625043}],"con":true,"img":false}]}
{"op":"mcm","clk":"1349982326","pt":1588414568406,"mc":[{"id":"1.170370562","rc":[{"atl":[[1.68,156.88]],"id":9625043}],"con":true,"img":false}]}
{"op":"mcm","clk":"1349982334","pt":1588414568663,"mc":[{"id":"1.170370562","rc":[{"trd":[[1.68,330.7]],"ltp":1.68,"tv":330.7,"id":9625043},{"atl":[[1.68,118.15]],"id":9625043}],"con":true,"img":false}]}
{"op":"mcm","clk":"1349982350","pt":1588414569077,"mc":[{"id":"1.170370562","rc":[{"atl":[[1.68,112.9]],"id":9625043}],"con":true,"img":false}]}
{"op":"mcm","clk":"1349982352","pt":1588414569180,"mc":[{"id":"1.170370562","rc":[{"trd":[[1.68,366.16]],"ltp":1.68,"tv":366.16,"id":9625043},{"atl":[[1.68,95.17]],"id":9625043}],"con":true,"img":false}]}
{"op":"mcm","clk":"1349982360","pt":1588414569385,"mc":[{"id":"1.170370562","rc":[{"trd":[[1.68,373.24]],"ltp":1.68,"tv":373.24,"id":9625043},{"atl":[[1.68,91.63]],"id":9625043}],"con":true,"img":false}]}
{"op":"mcm","clk":"1349982372","pt":1588414569694,"mc":[{"id":"1.170370562","rc":[{"atb":[[1.57,135.19]],"id":9625043}],"con":true,"img":false}]}
{"op":"mcm","clk":"1349982382","pt":1588414570004,"mc":[{"id":"1.170370562","rc":[{"atl":[[1.68,0]],"id":9625043}],"con":true,"img":false}]}
{"op":"mcm","clk":"1349982389","pt":1588414570156,"mc":[{"id":"1.170370562","rc":[{"atb":[[1.71,1.72]],"id":9625043}],"con":true,"img":false}]}
{"op":"mcm","clk":"1349982445","pt":1588414572070,"mc":[{"id":"1.170370562","rc":[{"atb":[[1.69,0.11]],"id":9625043}],"con":true,"img":false}]}
{"op":"mcm","clk":"1349982458","pt":1588414572475,"mc":[{"id":"1.170370562","rc":[{"atb":[[1.7,17.73]],"id":9625043}],"con":true,"img":false}]}
{"op":"mcm","clk":"1349982474","pt":1588414573194,"mc":[{"id":"1.170370562","rc":[{"atb":[[1.68,8.75]],"id":9625043}],"con":true,"img":false}]}
{"op":"mcm","clk":"1349982482","pt":1588414573657,"mc":[{"id":"1.170370562","rc":[{"atb":[[1.69,44.44]],"id":9625043}],"con":true,"img":false}]}
{"op":"mcm","clk":"1349982499","pt":1588414574172,"mc":[{"id":"1.170370562","rc":[{"trd":[[1.7,40.08],[1.71,409.9]],"ltp":1.7,"tv":449.97,"id":9625043},{"atb":[[1.7,14.2],[1.71,0]],"id":9625043},{"atb":[[2.28,0]],"id":9631798}],"con":true,"img":false}]}
{"op":"mcm","clk":"1349982511","pt":1588414574585,"mc":[{"id":"1.170370562","rc":[{"atb":[[1.68,135.09]],"id":9625043}],"con":true,"img":false}]}
{"op":"mcm","clk":"1349982539","pt":1588414575200,"mc":[{"id":"1.170370562","rc":[{"atl":[[1.89,0]],"id":9625043}],"con":true,"img":false}]}
{"op":"mcm","clk":"1349982555","pt":1588414575559,"mc":[{"id":"1.170370562","rc":[{"atl":[[2.46,2.57]],"id":9631798}],"con":true,"img":false}]}
{"op":"mcm","clk":"1349982609","pt":1588414577206,"mc":[{"id":"1.170370562","rc":[{"atb":[[1.69,0.11]],"id":9625043}],"con":true,"img":false}]}
{"op":"mcm","clk":"1349982621","pt":1588414577463,"mc":[{"id":"1.170370562","rc":[{"atb":[[1.73,1000]],"id":9625043}],"con":true,"img":false}]}
{"op":"mcm","clk":"1349982648","pt":1588414578287,"mc":[{"id":"1.170370562","rc":[{"trd":[[1.84,150.56]],"ltp":1.84,"tv":150.56,"id":9625043},{"atl":[[1.84,0]],"id":9625043},{"trd":[[2.18,119.7]],"ltp":2.18,"tv":119.7,"id":9631798},{"atl":[[2.14,248.54]],"id":9631798}],"con":true,"img":false}]}
{"op":"mcm","clk":"1349982659","pt":1588414578594,"mc":[{"id":"1.170370562","rc":[{"atl":[[2.14,497.3]],"id":9631798}],"con":true,"img":false}]}
{"op":"mcm","clk":"1349982694","pt":1588414579471,"mc":[{"id":"1.170370562","rc":[{"atl":[[2.04,265.95]],"id":9625043}],"con":true,"img":false}]}
{"op":"mcm","clk":"1349982726","pt":1588414580299,"mc":[{"id":"1.170370562","rc":[{"atb":[[1.73,0]],"id":9625043}],"con":true,"img":false}]}
{"op":"mcm","clk":"1349982742","pt":1588414580612,"mc":[{"id":"1.170370562","rc":[{"atb":[[1.7,0],[1.51,0],[1.67,112],[1.66,0]],"id":9625043},{"atl":[[1.9,0],[1.94,0]],"id":9625043}],"con":true,"img":false}]}
{"op":"mcm","clk":"1349982761","pt":1588414580975,"mc":[{"id":"1.170370562","rc":[{"atl":[[2.08,248.76]],"id":9631798}],"con":true,"img":false}]}
{"op":"mcm","clk":"1349982771","pt":1588414581288,"mc":[{"id":"1.170370562","rc":[{"atl":[[2,8.87]],"id":9625043}],"con":true,"img":false}]}
{"op":"mcm","clk":"1349982787","pt":1588414581801,"mc":[{"id":"1.170370562","rc":[{"atb":[[1.77,17.73]],"id":9625043}],"con":true,"img":false}]}
{"op":"mcm","clk":"1349982790","pt":1588414581904,"mc":[{"id":"1.170370562","rc":[{"trd":[[1.92,0.23]],"ltp":1.92,"tv":0.23,"id":9625043},{"atb":[[1.68,8.75],[1.57,0]],"id":9625043},{"trd":[[2.08,0.27]],"ltp":2.08,"tv":0.27,"id":9631798},{"atl":[[2.08,248.54]],"id":9631798}],"con":true,"img":false}]}
{"op":"mcm","clk":"1349982809","pt":1588414582369,"mc":[{"id":"1.170370562","rc":[{"atb":[[1.77,35.46]],"id":9625043}],"con":true,"img":false}]}
{"op":"mcm","clk":"1349982837","pt":1588414583401,"mc":[{"id":"1.170370562","rc":[{"trd":[[1.92,40.64]],"ltp":1.92,"tv":40.64,"id":9625043},{"trd":[[2.08,37.57]],"ltp":2.08,"tv":37.57,"id":9631798},{"atl":[[2.08,211.24]],"id":9631798}],"con":true,"img":false}]}
{"op":"mcm","clk":"1349982840","pt":1588414583503,"mc":[{"id":"1.170370562","rc":[{"trd":[[1.92,79.97]],"ltp":1.92,"tv":79.97,"id":9625043},{"trd":[[2.08,73.88]],"ltp":2.08,"tv":73.88,"id":9631798},{"atl":[[2.08,174.94]],"id":9631798}],"con":true,"img":false}]}
{"op":"mcm","clk":"1349982848","pt":1588414583709,"mc":[{"id":"1.170370562","rc":[{"atl":[[2.08,0]],"id":9631798}],"con":true,"img":false}]}
{"op":"mcm","clk":"1349982857","pt":1588414583914,"mc":[{"id":"1.170370562","rc":[{"atb":[[1.77,53.19]],"id":9625043}],"con":true,"img":false}]}
{"op":"mcm","clk":"1349982866","pt":1588414584173,"mc":[{"id":"1.170370562","rc":[{"atb":[[1.76,112]],"id":9625043}],"con":true,"img":false}]}
{"op":"mcm","clk":"1349982870","pt":1588414584277,"mc":[{"id":"1.170370562","rc":[{"trd":[[1.87,90.24]],"ltp":1.87,"tv":90.24,"id":9625043},{"trd":[[2.14,96.58]],"ltp":2.14,"tv":96.58,"id":9631798},{"atl":[[2.14,418.45]],"id":9631798}],"con":true,"img":false}]}
{"op":"mcm","clk":"1349982877","pt":1588414584379,"mc":[{"id":"1.170370562","rc":[{"atb":[[1.77,70.92]],"id":9625043}],"con":true,"img":false}]}
{"op":"mcm","clk":"1349982895","pt":1588414584894,"mc":[{"id":"1.170370562","rc":[{"atb":[[1.82,112]],"id":9625043}],"con":true,"img":false}]}
{"op":"mcm","clk":"1349982918","pt":1588414585408,"mc":[{"id":"1.170370562","rc":[{"atb":[[1.92,0]],"id":9631798},{"atl":[[3.15,0]],"id":9631798}],"con":true,"img":false}]}
{"op":"mcm","clk":"1349982931","pt":1588414585717,"mc":[{"id":"1.170370562","rc":[{"atb":[[1.9,112]],"id":9625043}],"con":true,"img":false}]}
{"op":"mcm","clk":"1349982980","pt":1588414587108,"mc":[{"id":"1.170370562","rc":[{"atb":[[1.85,114.73]],"id":9625043}],"con":true,"img":false}]}
{"op":"mcm","clk":"1349982997","pt":1588414587777,"mc":[{"id":"1.170370562","rc":[{"trd":[[1.9,0.94]],"ltp":1.9,"tv":0.94,"id":9625043},{"atb":[[1.9,111.53]],"id":9625043}],"con":true,"img":false}]}
{"op":"mcm","clk":"1349983011","pt":1588414588191,"mc":[{"id":"1.170370562","rc":[{"atb":[[1.93,29.67]],"id":9625043}],"con":true,"img":false}]}
{"op":"mcm","clk":"1349983019","pt":1588414588399,"mc":[{"id":"1.170370562","rc":[{"atb":[[1.9,0]],"id":9625043}],"con":true,"img":false}]}
{"op":"mcm","clk":"1349983034","pt":1588414588708,"mc":[{"id":"1.170370562","rc":[{"atb":[[1.9,8.75]],"id":9625043}],"con":true,"img":false}]}
{"op":"mcm","clk":"1349983038","pt":1588414588810,"mc":[{"id":"1.170370562","rc":[{"atb":[[1.79,44.32]],"id":9625043}],"con":true,"img":false}]}
{"op":"mcm","clk":"1349983046","pt":1588414589016,"mc":[{"id":"1.170370562","rc":[{"atb":[[1.41,0]],"id":9631798}],"con":true,"img":false}]}
{"op":"mcm","clk":"1349983060","pt":1588414589480,"mc":[{"id":"1.170370562","rc":[{"atl":[[2.1,1.54]],"id":9631798}],"con":true,"img":false}]}
{"op":"mcm","clk":"1349983120","pt":1588414591392,"mc":[{"id":"1.170370562","rc":[{"atb":[[2.04,248.76],[1.77,233.57]],"id":9631798},{"atl":[[3,100.51]],"id":9631798}],"con":true,"img":false}]}
{"op":"mcm","clk":"1349983125","pt":1588414591599,"mc":[{"id":"1.170370562","rc":[{"atb":[[2.04,497.52]],"id":9631798}],"con":true,"img":false}]}
{"op":"mcm","clk":"1349983160","pt":1588414592686,"mc":[{"id":"1.170370562","rc":[{"trd":[[2.04,8.86]],"ltp":2.04,"tv":8.86,"id":9631798},{"atb":[[2.04,493.08]],"id":9631798}],"con":true,"img":false}]}
{"op":"mcm","clk":"1349983170","pt":1588414592994,"mc":[{"id":"1.170370562","rc":[{"atb":[[1.85,0]],"id":9625043}],"con":true,"img":false}]}
{"op":"mcm","clk":"1349983196","pt":1588414593721,"mc":[{"id":"1.170370562","rc":[{"atb":[[1.82,0]],"id":9625043}],"con":true,"img":false}]}
{"op":"mcm","clk":"1349983216","pt":1588414594234,"mc":[{"id":"1.170370562","rc":[{"atl":[[1000,2]],"id":9631798}],"con":true,"img":false}]}
{"op":"mcm","clk":"1349983223","pt":1588414594286,"mc":[{"id":"1.170370562","rc":[{"trd":[[1.93,0.45]],"ltp":1.93,"tv":0.45,"id":9625043},{"atb":[[1.93,29.44]],"id":9625043}],"con":true,"img":false}]}
{"op":"mcm","clk":"1349983228","pt":1588414594390,"mc":[{"id":"1.170370562","rc":[{"atl":[[1000,0.01]],"id":9631798}],"con":true,"img":false}]}
{"op":"mcm","clk":"1349983232","pt":1588414594496,"mc":[{"id":"1.170370562","rc":[{"atl":[[1000,0]],"id":9631798}],"con":true,"img":false}]}
{"op":"mcm","clk":"1349983237","pt":1588414594597,"mc":[{"id":"1.170370562","rc":[{"atl":[[1.94,4.43]],"id":9625043}],"con":true,"img":false}]}
{"op":"mcm","clk":"1349983252","pt":1588414595012,"mc":[{"id":"1.170370562","rc":[{"atb":[[1.76,0]],"id":9625043}],"con":true,"img":false}]}
{"op":"mcm","clk":"1349983259","pt":1588414595293,"mc":[{"id":"1.170370562","rc":[{"trd":[[1.94,8.86]],"ltp":1.94,"tv":8.86,"id":9625043},{"atb":[[1.96,13.29]],"id":9625043},{"atl":[[1.94,0]],"id":9625043},{"atl":[[1000,2]],"id":9631798}],"con":true,"img":false}]}
{"op":"mcm","clk":"1349983271","pt":1588414595500,"mc":[{"id":"1.170370562","rc":[{"atl":[[1000,0.01]],"id":9631798}],"con":true,"img":false}]}
{"op":"mcm","clk":"1349983278","pt":1588414595602,"mc":[{"id":"1.170370562","rc":[{"atl":[[2.04,0]],"id":9625043}],"con":true,"img":false}]}
{"op":"mcm","clk":"1349983285","pt":1588414595703,"mc":[{"id":"1.170370562","rc":[{"trd":[[1.97,3.5]],"ltp":1.97,"tv":3.5,"id":9625043},{"trd":[[2.04,12.24]],"ltp":2.04,"tv":12.24,"id":9631798},{"atb":[[2.04,489.7]],"id":9631798},{"atl":[[1000,0]],"id":9631798}],"con":true,"img":false}]}
{"op":"mcm","clk":"1349983293","pt":1588414595913,"mc":[{"id":"1.170370562","rc":[{"trd":[[1.9,2.64],[1.96,26.59],[1.93,59.33]],"ltp":1.9,"tv":88.56,"id":9625043},{"atb":[[1.96,0],[1.93,0],[1.9,0]],"id":9625043},{"atl":[[1.9,34.38]],"id":9625043},{"trd":[[2.1,2.61]],"ltp":2.1,"tv":2.61,"id":9631798},{"atl":[[2.1,0]],"id":9631798}],"con":true,"img":false}]}
{"op":"mcm","clk":"1349983340","pt":1588414597096,"mc":[{"id":"1.170370562","rc":[{"atl":[[2,8.75]],"id":9625043}],"con":true,"img":false}]}
{"op":"mcm","clk":"1349983371","pt":1588414597920,"mc":[{"id":"1.170370562","rc":[{"atb":[[1.74,5.29]],"id":9625043}],"con":true,"img":false}]}
{"op":"mcm","clk":"1349983375","pt":1588414598126,"mc":[{"id":"1.170370562","rc":[{"trd":[[1.9,71.41]],"ltp":1.9,"tv":71.41,"id":9625043},{"atb":[[1.94,75.03]],"id":9625043},{"atl":[[1.9,0]],"id":9625043}],"con":true,"img":false}]}
{"op":"mcm","clk":"1349983380","pt":1588414598231,"mc":[{"id":"1.170370562","rc":[{"atb":[[1.77,0]],"id":9625043}],"con":true,"img":false}]}
{"op":"mcm","clk":"1349983416","pt":1588414599207,"mc":[{"id":"1.170370562","rc":[{"trd":[[1.97,8.55]],"ltp":1.97,"tv":8.55,"id":9625043},{"trd":[[2.04,17.12]],"ltp":2.04,"tv":17.12,"id":9631798},{"atb":[[2.04,484.82]],"id":9631798}],"con":true,"img":false}]}
{"op":"mcm","clk":"1349983427","pt":1588414599417,"mc":[{"id":"1.170370562","rc":[{"atb":[[2.04,0]],"id":9631798}],"con":true,"img":false}]}
{"op":"mcm","clk":"1349983435","pt":1588414599622,"mc":[{"id":"1.170370562","rc":[{"trd":[[1.94,27]],"ltp":1.94,"tv":27.0,"id":9625043},{"atb":[[1.94,56.89]],"id":9625043},{"trd":[[2.08,90.8]],"ltp":2.08,"tv":90.8,"id":9631798},{"atl":[[2.36,0.01]],"id":9631798}],"con":true,"img":false}]}
{"op":"mcm","clk":"1349983438","pt":1588414599728,"mc":[{"id":"1.170370562","rc":[{"trd":[[1.94,81.6]],"ltp":1.94,"tv":81.6,"id":9625043},{"atb":[[1.94,2.29]],"id":9625043},{"trd":[[2.08,141.72]],"ltp":2.08,"tv":141.72,"id":9631798}],"con":true,"img":false}]}
{"op":"mcm","clk":"1349983448","pt":1588414600240,"mc":[{"id":"1.170370562","rc":[{"trd":[[1.94,81.84]],"ltp":1.94,"tv":81.84,"id":9625043},{"atb":[[1.94,2.17]],"id":9625043}],"con":true,"img":false}]}
{"op":"mcm","clk":"1349983461","pt":1588414600808,"mc":[{"id":"1.170370562","rc":[{"atl":[[2.16,0.01]],"id":9631798}],"con":true,"img":false}]}
{"op":"mcm","clk":"1349983465","pt":1588414600912,"mc":[{"id":"1.170370562","rc":[{"atb":[[1.94,0]],"id":9625043}],"con":true,"img":false}]}
{"op":"mcm","clk":"1349983472","pt":1588414601118,"mc":[{"id":"1.170370562","rc":[{"trd":[[2,75.84]],"ltp":2.0,"tv":75.84,"id":9625043},{"atb":[[2,0.51]],"id":9625043},{"atl":[[2,0]],"id":9625043}],"con":true,"img":false}]}
{"op":"mcm","clk":"1349983474","pt":1588414601219,"mc":[{"id":"1.170370562","rc":[{"trd":[[1.87,569.11],[2,76.87]],"ltp":1.87,"tv":645.98,"id":9625043},{"atb":[[2,0]],"id":9625043},{"atl":[[1.87,551.75]],"id":9625043},{"trd":[[2.14,515.03]],"ltp":2.14,"tv":515.03,"id":9631798},{"atl":[[2.14,0]],"id":9631798}],"con":true,"img":false}]}
{"op":"mcm","clk":"1349983480","pt":1588414601629,"mc":[{"id":"1.170370562","rc":[{"atb":[[1.68,0]],"id":9625043}],"con":true,"img":false}]}
{"op":"mcm","clk":"1349983493","pt":1588414602042,"mc":[{"id":"1.170370562","rc":[{"atl":[[1.87,0]],"id":9625043}],"con":true,"img":false}]}
{"op":"mcm","clk":"1349983510","pt":1588414602713,"mc":[{"id":"1.170370562","rc":[{"atb":[[1.79,0]],"id":9625043}],"con":true,"img":false}]}
{"op":"mcm","clk":"1349983543","pt":1588414603793,"mc":[{"id":"1.170370562","rc":[{"atl":[[2.88,265.95]],"id":9625043}],"con":true,"img":false}]}
{"op":"mcm","clk":"1349983586","pt":1588414605235,"mc":[{"id":"1.170370562","rc":[{"atb":[[2,248.76]],"id":9631798}],"con":true,"img":false}]}
{"op":"mcm","clk":"1349983594","pt":1588414605442,"mc":[{"id":"1.170370562","rc":[{"atb":[[2,497.52]],"id":9631798}],"con":true,"img":false}]}
{"op":"mcm","clk":"1349983621","pt":1588414606319,"mc":[{"id":"1.170370562","rc":[{"atb":[[1.88,17.73]],"id":9625043}],"con":true,"img":false}]}
{"op":"mcm","clk":"1349983643","pt":1588414606835,"mc":[{"id":"1.170370562","rc":[{"atb":[[1.89,17.73]],"id":9625043}],"con":true,"img":false}]}
{"op":"mcm","clk":"1349983653","pt":1588414607041,"mc":[{"id":"1.170370562","rc":[{"atb":[[1.71,500]],"id":9631798}],"con":true,"img":false}]}
{"op":"mcm","clk":"1349983726","pt":1588414609111,"mc":[{"id":"1.170370562","rc":[{"atb":[[1.64,103.97]],"id":9625043}],"con":true,"img":false}]}
{"op":"mcm","clk":"1349983811","pt":1588414611836,"mc":[{"id":"1.170370562","rc":[{"trd":[[1.88,55.64],[1.89,162.34]],"ltp":1.88,"tv":217.98,"id":9625043},{"atb":[[1.89,0],[1.88,0]],"id":9625043},{"atl":[[1.88,4.82]],"id":9625043}],"con":true,"img":false}]}
{"op":"mcm","clk":"1349983819","pt":1588414612042,"mc":[{"id":"1.170370562","rc":[{"atl":[[1.88,0]],"id":9625043}],"con":true,"img":false}]}
{"op":"mcm","clk":"1349984016","pt":1588414617616,"mc":[{"id":"1.170370562","rc":[{"atl":[[1.89,43.79]],"id":9625043}],"con":true,"img":false}]}
{"op":"mcm","clk":"1349984105","pt":1588414619944,"mc":[{"id":"1.170370562","rc":[{"atl":[[1.89,44.04]],"id":9625043}],"con":true,"img":false}]}
{"op":"mcm","clk":"1349984133","pt":1588414620768,"mc":[{"id":"1.170370562","rc":[{"atl":[[1.89,0.25]],"id":9625043}],"con":true,"img":false}]}
{"op":"mcm","clk":"1349984269","pt":1588414625446,"mc":[{"id":"1.170370562","rc":[{"trd":[[1.67,242.66],[1.86,0.01],[1.73,300.6],[1.68,377.01],[1.74,48.01],[1.69,0.23]],"ltp":1.67,"tv":968.52,"id":9625043},{"atb":[[1.69,0],[1.74,0],[1.67,0]],"id":9625043},{"atl":[[1.67,878.8]],"id":9625043},{"trd":[[2.46,2.58],[2.16,8.87],[2.36,0.01]],"ltp":2.46,"tv":11.45,"id":9631798},{"atl":[[2.36,0],[2.46,0],[2.16,0]],"id":9631798}],"con":true,"img":false}]}
{"op":"mcm","clk":"1349984300","pt":1588414626429,"mc":[{"id":"1.170370562","rc":[{"atl":[[1.72,492.02]],"id":9625043}],"con":true,"img":false}]}
{"op":"mcm","clk":"1349984305","pt":1588414626636,"mc":[{"id":"1.170370562","rc":[{"atb":[[1.55,0],[1.49,0]],"id":9625043}],"con":true,"img":false}]}
{"op":"mcm","clk":"1349984320","pt":1588414627151,"mc":[{"id":"1.170370562","rc":[{"atb":[[2,0]],"id":9631798}],"con":true,"img":false}]}
{"op":"mcm","clk":"1349984333","pt":1588414627566,"mc":[{"id":"1.170370562","rc":[{"atl":[[1.83,17.73]],"id":9625043}],"con":true,"img":false}]}
{"op":"mcm","clk":"1349984352","pt":1588414628080,"mc":[{"id":"1.170370562","rc":[{"atl":[[1.83,35.46]],"id":9625043}],"con":true,"img":false}]}
{"op":"mcm","clk":"1349984375","pt":1588414628855,"mc":[{"id":"1.170370562","rc":[{"trd":[[1.67,243.14]],"ltp":1.67,"tv":243.14,"id":9625043},{"atl":[[1.67,878.56]],"id":9625043}],"con":true,"img":false}]}
{"op":"mcm","clk":"1349984394","pt":1588414629579,"mc":[{"id":"1.170370562","rc":[{"atl":[[1.74,1031.14]],"id":9625043}],"con":true,"img":false}]}
{"op":"mcm","clk":"1349984396","pt":1588414629681,"mc":[{"id":"1.170370562","rc":[{"atb":[[2.34,1192.71]],"id":9631798}],"con":true,"img":false}]}
{"op":"mcm","clk":"1349984406","pt":1588414630149,"mc":[{"id":"1.170370562","rc":[{"trd":[[1.67,250.04]],"ltp":1.67,"tv":250.04,"id":9625043},{"atl":[[1.67,875.11]],"id":9625043}],"con":true,"img":false}]}
{"op":"mcm","clk":"1349984428","pt":1588414631079,"mc":[{"id":"1.170370562","rc":[{"atl":[[1.77,17.73]],"id":9625043}],"con":true,"img":false}]}
{"op":"mcm","clk":"1349984436","pt":1588414631389,"mc":[{"id":"1.170370562","rc":[{"atb":[[2.34,0]],"id":9631798}],"con":true,"img":false}]}
{"op":"mcm","clk":"1349984437","pt":1588414631441,"mc":[{"id":"1.170370562","rc":[{"atl":[[1.77,35.46]],"id":9625043}],"con":true,"img":false}]}
{"op":"mcm","clk":"1349984467","pt":1588414632580,"mc":[{"id":"1.170370562","rc":[{"atl":[[1.67,0],[1.74,1031.98]],"id":9625043}],"con":true,"img":false}]}
{"op":"mcm","clk":"1349984472","pt":1588414632682,"mc":[{"id":"1.170370562","rc":[{"atl":[[1.66,17.73]],"id":9625043}],"con":true,"img":false}]}
{"op":"mcm","clk":"1349984477","pt":1588414632786,"mc":[{"id":"1.170370562","rc":[{"trd":[[1.64,264.11]],"ltp":1.64,"tv":264.11,"id":9625043},{"atb":[[1.64,0]],"id":9625043},{"atl":[[1.63,396.03]],"id":9625043}],"con":true,"img":false}]}
{"op":"mcm","clk":"1349984493","pt":1588414633250,"mc":[{"id":"1.170370562","rc":[{"atl":[[1.64,17.73]],"id":9625043}],"con":true,"img":false}]}
{"op":"mcm","clk":"1349984512","pt":1588414633766,"mc":[{"id":"1.170370562","rc":[{"atl":[[1.64,35.46]],"id":9625043}],"con":true,"img":false}]}
{"op":"mcm","clk":"1349984515","pt":1588414633869,"mc":[{"id":"1.170370562","rc":[{"atl":[[1.66,32.57]],"id":9625043}],"con":true,"img":false}]}
{"op":"mcm","clk":"1349984522","pt":1588414634074,"mc":[{"id":"1.170370562","rc":[{"atl":[[1.64,53.19]],"id":9625043}],"con":true,"img":false}]}
{"op":"mcm","clk":"1349984533","pt":1588414634487,"mc":[{"id":"1.170370562","rc":[{"atl":[[1.64,70.92]],"id":9625043}],"con":true,"img":false}]}
{"op":"mcm","clk":"1349984565","pt":1588414635779,"mc":[{"id":"1.170370562","rc":[{"atl":[[1.64,185.52],[1.63,0]],"id":9625043},{"atb":[[1.71,0]],"id":9631798}],"con":true,"img":false}]}
{"op":"mcm","clk":"1349984581","pt":1588414636449,"mc":[{"id":"1.170370562","rc":[{"atb":[[1.59,17.73]],"id":9625043}],"con":true,"img":false}]}
{"op":"mcm","clk":"1349984585","pt":1588414636552,"mc":[{"id":"1.170370562","rc":[{"atb":[[1.77,0]],"id":9631798},{"atl":[[3,0]],"id":9631798}],"con":true,"img":false}]}
{"op":"mcm","clk":"1349984595","pt":1588414636758,"mc":[{"id":"1.170370562","rc":[{"trd":[[1.64,269.26]],"ltp":1.64,"tv":269.26,"id":9625043},{"atl":[[1.64,182.94]],"id":9625043}],"con":true,"img":false}]}
{"op":"mcm","clk":"1349984600","pt":1588414636966,"mc":[{"id":"1.170370562","rc":[{"atb":[[1.59,35.46]],"id":9625043}],"con":true,"img":false}]}
{"op":"mcm","clk":"1349984614","pt":1588414637584,"mc":[{"id":"1.170370562","rc":[{"atb":[[1.59,53.19]],"id":9625043}],"con":true,"img":false}]}
{"op":"mcm","clk":"1349984622","pt":1588414637891,"mc":[{"id":"1.170370562","rc":[{"atl":[[1.7,196.8]],"id":9625043}],"con":true,"img":false}]}
{"op":"mcm","clk":"1349984637","pt":1588414638353,"mc":[{"id":"1.170370562","rc":[{"atb":[[2.68,14.87]],"id":9631798},{"atl":[[2.6,0]],"id":9631798}],"con":true,"img":false}]}
{"op":"mcm","clk":"1349984657","pt":1588414639074,"mc":[{"id":"1.170370562","rc":[{"atl":[[1.61,112]],"id":9625043}],"con":true,"img":false}]}
{"op":"mcm","clk":"1349984669","pt":1588414639279,"mc":[{"id":"1.170370562","rc":[{"atl":[[1.7,462.76]],"id":9625043}],"con":true,"img":false}]}
{"op":"mcm","clk":"1349984673","pt":1588414639382,"mc":[{"id":"1.170370562","rc":[{"trd":[[1.59,93.55]],"ltp":1.59,"tv":93.55,"id":9625043},{"atb":[[1.59,29.61]],"id":9625043},{"atl":[[1.64,68.34],[1.61,0]],"id":9625043},{"trd":[[2.7,13.88]],"ltp":2.7,"tv":13.88,"id":9631798}],"con":true,"img":false}]}
{"op":"mcm","clk":"1349984686","pt":1588414639689,"mc":[{"id":"1.170370562","rc":[{"atl":[[1.7,265.95],[1.66,17.73]],"id":9625043}],"con":true,"img":false}]}
{"op":"mcm","clk":"1349984692","pt":1588414639896,"mc":[{"id":"1.170370562","rc":[{"atb":[[1.57,3.55]],"id":9625043}],"con":true,"img":false}]}
{"op":"mcm","clk":"1349984696","pt":1588414640004,"mc":[{"id":"1.170370562","rc":[{"atl":[[1.62,17.73]],"id":9625043},{"atb":[[2.68,0]],"id":9631798}],"con":true,"img":false}]}
{"op":"mcm","clk":"1349984706","pt":1588414640264,"mc":[{"id":"1.170370562","rc":[{"atl":[[1.72,0]],"id":9625043}],"con":true,"img":false}]}
{"op":"mcm","clk":"1349984714","pt":1588414640472,"mc":[{"id":"1.170370562","rc":[{"trd":[[1.62,70.92]],"ltp":1.62,"tv":70.92,"id":9625043},{"atb":[[1.63,93.07]],"id":9625043},{"atl":[[1.62,0]],"id":9625043}],"con":true,"img":false}]}
{"op":"mcm","clk":"1349984745","pt":1588414641194,"mc":[{"id":"1.170370562","rc":[{"trd":[[1.63,186.14]],"ltp":1.63,"tv":186.14,"id":9625043},{"atb":[[1.63,0]],"id":9625043},{"atl":[[1.6,650.64]],"id":9625043}],"con":true,"img":false}]}
{"op":"mcm","clk":"1349984750","pt":1588414641400,"mc":[{"id":"1.170370562","rc":[{"trd":[[1.6,161.21]],"ltp":1.6,"tv":161.21,"id":9625043},{"atl":[[1.6,649.61]],"id":9625043}],"con":true,"img":false}]}
{"op":"mcm","clk":"1349984753","pt":1588414641453,"mc":[{"id":"1.170370562","rc":[{"atb":[[1.79,0]],"id":9631798},{"atl":[[4.3,0]],"id":9631798}],"con":true,"img":false}]}
{"op":"mcm","clk":"1349984771","pt":1588414641966,"mc":[{"id":"1.170370562","rc":[{"trd":[[1.6,161.77]],"ltp":1.6,"tv":161.77,"id":9625043},{"atl":[[1.6,649.33]],"id":9625043}],"con":true,"img":false}]}
{"op":"mcm","clk":"1349984774","pt":1588414642175,"mc":[{"id":"1.170370562","rc":[{"trd":[[1.59,127.2]],"ltp":1.59,"tv":127.2,"id":9625043},{"atb":[[1.59,12.79]],"id":9625043}],"con":true,"img":false}]}
{"op":"mcm","clk":"1349984786","pt":1588414642486,"mc":[{"id":"1.170370562","rc":[{"atb":[[2.12,224.34]],"id":9631798},{"atl":[[4.2,68.82]],"id":9631798}],"con":true,"img":false}]}
{"op":"mcm","clk":"1349984801","pt":1588414642950,"mc":[{"id":"1.170370562","rc":[{"atb":[[1.49,79.78]],"id":9625043}],"con":true,"img":false}]}
{"op":"mcm","clk":"1349984809","pt":1588414643157,"mc":[{"id":"1.170370562","rc":[{"atb":[[1.56,0],[1.49,159.57]],"id":9625043}],"con":true,"img":false}]}
{"op":"mcm","clk":"1349984818","pt":1588414643468,"mc":[{"id":"1.170370562","rc":[{"atb":[[1.49,239.36]],"id":9625043}],"con":true,"img":false}]}
{"op":"mcm","clk":"1349984822","pt":1588414643573,"mc":[{"id":"1.170370562","rc":[{"atb":[[1.49,319.14]],"id":9625043}],"con":true,"img":false}]}
{"op":"mcm","clk":"1349984828","pt":1588414643780,"mc":[{"id":"1.170370562","rc":[{"trd":[[1.6,271.77]],"ltp":1.6,"tv":271.77,"id":9625043},{"atl":[[1.6,594.33]],"id":9625043}],"con":true,"img":false}]}
{"op":"mcm","clk":"1349984834","pt":1588414644092,"mc":[{"id":"1.170370562","rc":[{"atl":[[1.74,0.84],[1.9,0.23]],"id":9625043}],"con":true,"img":false}]}
{"op":"mcm","clk":"1349984840","pt":1588414644299,"mc":[{"id":"1.170370562","rc":[{"atb":[[1.58,17.73]],"id":9625043}],"con":true,"img":false}]}
{"op":"mcm","clk":"1349984848","pt":1588414644454,"mc":[{"id":"1.170370562","rc":[{"atl":[[1.63,265.95]],"id":9625043}],"con":true,"img":false}]}
{"op":"mcm","clk":"1349984860","pt":1588414644868,"mc":[{"id":"1.170370562","rc":[{"atb":[[1.58,35.46]],"id":9625043}],"con":true,"img":false}]}
{"op":"mcm","clk":"1349984877","pt":1588414645489,"mc":[{"id":"1.170370562","rc":[{"atl":[[1.65,113.9]],"id":9625043}],"con":true,"img":false}]}
{"op":"mcm","clk":"1349984891","pt":1588414646006,"mc":[{"id":"1.170370562","rc":[{"atl":[[1.62,15.2]],"id":9625043}],"con":true,"img":false}]}
{"op":"mcm","clk":"1349984902","pt":1588414646212,"mc":[{"id":"1.170370562","rc":[{"trd":[[1.6,449.08]],"ltp":1.6,"tv":449.08,"id":9625043},{"atl":[[1.6,505.68]],"id":9625043}],"con":true,"img":false}]}
{"op":"mcm","clk":"1349984913","pt":1588414646471,"mc":[{"id":"1.170370562","rc":[{"atl":[[1.63,283.68]],"id":9625043}],"con":true,"img":false}]}
{"op":"mcm","clk":"1349984918","pt":1588414646574,"mc":[{"id":"1.170370562","rc":[{"atl":[[2.72,13.76]],"id":9631798}],"con":true,"img":false}]}
{"op":"mcm","clk":"1349984924","pt":1588414646780,"mc":[{"id":"1.170370562","rc":[{"atl":[[1.7,0]],"id":9625043}],"con":true,"img":false}]}
{"op":"mcm","clk":"1349984933","pt":1588414646986,"mc":[{"id":"1.170370562","rc":[{"trd":[[1.6,450.16]],"ltp":1.6,"tv":450.16,"id":9625043},{"atl":[[1.6,505.14]],"id":9625043}],"con":true,"img":false}]}
{"op":"mcm","clk":"1349984936","pt":1588414647089,"mc":[{"id":"1.170370562","rc":[{"atl":[[1.63,301.41]],"id":9625043}],"con":true,"img":false}]}
{"op":"mcm","clk":"1349984962","pt":1588414647707,"mc":[{"id":"1.170370562","rc":[{"trd":[[1.59,152.79]],"ltp":1.59,"tv":152.79,"id":9625043},{"atb":[[1.59,0]],"id":9625043},{"atl":[[1.59,66.99]],"id":9625043}],"con":true,"img":false}]}
{"op":"mcm","clk":"1349984971","pt":1588414647913,"mc":[{"id":"1.170370562","rc":[{"atl":[[1.59,146.78]],"id":9625043}],"con":true,"img":false}]}
{"op":"mcm","clk":"1349984976","pt":1588414647964,"mc":[{"id":"1.170370562","rc":[{"atl":[[1.59,226.56]],"id":9625043}],"con":true,"img":false}]}
{"op":"mcm","clk":"1349984984","pt":1588414648170,"mc":[{"id":"1.170370562","rc":[{"trd":[[1.59,188.25]],"ltp":1.59,"tv":188.25,"id":9625043},{"atl":[[1.59,208.83]],"id":9625043}],"con":true,"img":false}]}
{"op":"mcm","clk":"1349984990","pt":1588414648273,"mc":[{"id":"1.170370562","rc":[{"atb":[[1.51,177.3]],"id":9625043}],"con":true,"img":false}]}
{"op":"mcm","clk":"1349984995","pt":1588414648376,"mc":[{"id":"1.170370562","rc":[{"atb":[[1.46,112]],"id":9625043}],"con":true,"img":false}]}
{"op":"mcm","clk":"1349984999","pt":1588414648482,"mc":[{"id":"1.170370562","rc":[{"trd":[[1.59,298.25]],"ltp":1.59,"tv":298.25,"id":9625043},{"atl":[[1.59,153.83]],"id":9625043}],"con":true,"img":false}]}
{"op":"mcm","clk":"1349985006","pt":1588414648586,"mc":[{"id":"1.170370562","rc":[{"atb":[[1.57,0]],"id":9625043}],"con":true,"img":false}]}
{"op":"mcm","clk":"1349985013","pt":1588414648791,"mc":[{"id":"1.170370562","rc":[{"atb":[[1.44,116.03]],"id":9625043}],"con":true,"img":false}]}
{"op":"mcm","clk":"1349985021","pt":1588414648998,"mc":[{"id":"1.170370562","rc":[{"atb":[[1.5,196.8]],"id":9625043}],"con":true,"img":false}]}
{"op":"mcm","clk":"1349985034","pt":1588414649203,"mc":[{"id":"1.170370562","rc":[{"trd":[[1.59,467.36]],"ltp":1.59,"tv":467.36,"id":9625043},{"atl":[[1.59,69.28]],"id":9625043}],"con":true,"img":false}]}
{"op":"mcm","clk":"1349985047","pt":1588414649719,"mc":[{"id":"1.170370562","rc":[{"trd":[[1.59,474.83]],"ltp":1.59,"tv":474.83,"id":9625043},{"atl":[[1.59,61.8]],"id":9625043},{"trd":[[2.68,4.43]],"ltp":2.68,"tv":4.43,"id":9631798}],"con":true,"img":false}]}
{"op":"mcm","clk":"1349985060","pt":1588414649981,"mc":[{"id":"1.170370562","rc":[{"trd":[[1.59,482.31]],"ltp":1.59,"tv":482.31,"id":9625043},{"atl":[[1.59,54.33]],"id":9625043},{"trd":[[2.68,8.86]],"ltp":2.68,"tv":8.86,"id":9631798}],"con":true,"img":false}]}
{"op":"mcm","clk":"1349985068","pt":1588414650190,"mc":[{"id":"1.170370562","rc":[{"trd":[[1.59,489.78]],"ltp":1.59,"tv":489.78,"id":9625043},{"atl":[[1.59,46.86]],"id":9625043},{"trd":[[2.68,13.29]],"ltp":2.68,"tv":13.29,"id":9631798}],"con":true,"img":false}]}
{"op":"mcm","clk":"1349985069","pt":1588414650292,"mc":[{"id":"1.170370562","rc":[{"trd":[[1.59,497.25]],"ltp":1.59,"tv":497.25,"id":9625043},{"atl":[[1.59,39.38]],"id":9625043},{"trd":[[2.68,17.73]],"ltp":2.68,"tv":17.73,"id":9631798}],"con":true,"img":false}]}
{"op":"mcm","clk":"1349985092","pt":1588414650705,"mc":[{"id":"1.170370562","rc":[{"atl":[[2.72,0]],"id":9631798}],"con":true,"img":false}]}
{"op":"mcm","clk":"1349985096","pt":1588414650808,"mc":[{"id":"1.170370562","rc":[{"trd":[[1.59,504.73]],"ltp":1.59,"tv":504.73,"id":9625043},{"atl":[[1.59,31.91]],"id":9625043},{"trd":[[2.68,22.16]],"ltp":2.68,"tv":22.16,"id":9631798}],"con":true,"img":false}]}
{"op":"mcm","clk":"1349985110","pt":1588414651221,"mc":[{"id":"1.170370562","rc":[{"trd":[[1.59,506.14]],"ltp":1.59,"tv":506.14,"id":9625043},{"atl":[[1.59,31.2]],"id":9625043}],"con":true,"img":false}]}
{"op":"mcm","clk":"1349985116","pt":1588414651377,"mc":[{"id":"1.170370562","rc":[{"atb":[[1.49,0]],"id":9625043}],"con":true,"img":false}]}
{"op":"mcm","clk":"1349985130","pt":1588414651893,"mc":[{"id":"1.170370562","rc":[{"trd":[[1.59,508.23]],"ltp":1.59,"tv":508.23,"id":9625043},{"atl":[[1.59,29.12]],"id":9625043},{"trd":[[2.68,23.39]],"ltp":2.68,"tv":23.39,"id":9631798}],"con":true,"img":false}]}
{"op":"mcm","clk":"1349985137","pt":1588414652101,"mc":[{"id":"1.170370562","rc":[{"trd":[[1.59,508.74]],"ltp":1.59,"tv":508.74,"id":9625043},{"atl":[[1.59,28.86]],"id":9625043}],"con":true,"img":false}]}
{"op":"mcm","clk":"1349985146","pt":1588414652515,"mc":[{"id":"1.170370562","rc":[{"trd":[[1.59,509.18]],"ltp":1.59,"tv":509.18,"id":9625043},{"atl":[[1.59,28.64]],"id":9625043}],"con":true,"img":false}]}
{"op":"mcm","clk":"1349985151","pt":1588414652671,"mc":[{"id":"1.170370562","rc":[{"atb":[[1.51,289.3]],"id":9625043}],"con":true,"img":false}]}
{"op":"mcm","clk":"1349985160","pt":1588414652982,"mc":[{"id":"1.170370562","rc":[{"trd":[[1.58,35.46]],"ltp":1.58,"tv":35.46,"id":9625043},{"atb":[[1.58,0]],"id":9625043},{"trd":[[2.74,20.44]],"ltp":2.74,"tv":20.44,"id":9631798},{"atb":[[2.74,23.28]],"id":9631798}],"con":true,"img":false}]}
{"op":"mcm","clk":"1349985172","pt":1588414653395,"mc":[{"id":"1.170370562","rc":[{"trd":[[1.58,41.34]],"ltp":1.58,"tv":41.34,"id":9625043},{"trd":[[2.74,23.84]],"ltp":2.74,"tv":23.84,"id":9631798},{"atb":[[2.74,19.89]],"id":9631798}],"con":true,"img":false}]}
{"op":"mcm","clk":"1349985176","pt":1588414653498,"mc":[{"id":"1.170370562","rc":[{"atl":[[1.69,0.86]],"id":9625043}],"con":true,"img":false}]}
{"op":"mcm","clk":"1349985182","pt":1588414653704,"mc":[{"id":"1.170370562","rc":[{"trd":[[1.58,41.46]],"ltp":1.58,"tv":41.46,"id":9625043},{"atb":[[1.54,3.62]],"id":9625043},{"trd":[[2.74,23.91]],"ltp":2.74,"tv":23.91,"id":9631798},{"atb":[[2.74,19.82]],"id":9631798}],"con":true,"img":false}]}
{"op":"mcm","clk":"1349985194","pt":1588414654012,"mc":[{"id":"1.170370562","rc":[{"atb":[[1.5,308.8]],"id":9625043}],"con":true,"img":false}]}
{"op":"mcm","clk":"1349985201","pt":1588414654320,"mc":[{"id":"1.170370562","rc":[{"trd":[[1.58,44.96]],"ltp":1.58,"tv":44.96,"id":9625043},{"trd":[[2.74,25.93]],"ltp":2.74,"tv":25.93,"id":9631798},{"atb":[[2.74,17.8]],"id":9631798}],"con":true,"img":false}]}
{"op":"mcm","clk":"1349985207","pt":1588414654579,"mc":[{"id":"1.170370562","rc":[{"atb":[[1.51,304.81]],"id":9625043}],"con":true,"img":false}]}
{"op":"mcm","clk":"1349985211","pt":1588414654682,"mc":[{"id":"1.170370562","rc":[{"atb":[[1.53,112]],"id":9625043},{"atl":[[1.62,0]],"id":9625043}],"con":true,"img":false}]}
{"op":"mcm","clk":"1349985217","pt":1588414654892,"mc":[{"id":"1.170370562","rc":[{"atb":[[1.52,79.78]],"id":9625043}],"con":true,"img":false}]}
{"op":"mcm","clk":"1349985221","pt":1588414654995,"mc":[{"id":"1.170370562","rc":[{"atb":[[1.52,159.57]],"id":9625043}],"con":true,"img":false}]}
{"op":"mcm","clk":"1349985224","pt":1588414655202,"mc":[{"id":"1.170370562","rc":[{"atb":[[1.52,239.36]],"id":9625043}],"con":true,"img":false}]}
{"op":"mcm","clk":"1349985227","pt":1588414655305,"mc":[{"id":"1.170370562","rc":[{"atb":[[1.52,351.36]],"id":9625043}],"con":true,"img":false}]}
{"op":"mcm","clk":"1349985230","pt":1588414655511,"mc":[{"id":"1.170370562","rc":[{"trd":[[1.58,45.43]],"ltp":1.58,"tv":45.43,"id":9625043},{"trd":[[2.74,26.19]],"ltp":2.74,"tv":26.19,"id":9631798},{"atb":[[2.74,17.53]],"id":9631798}],"con":true,"img":false}]}
{"op":"mcm","clk":"1349985236","pt":1588414655614,"mc":[{"id":"1.170370562","rc":[{"trd":[[1.58,45.54]],"ltp":1.58,"tv":45.54,"id":9625043},{"trd":[[2.74,26.26]],"ltp":2.74,"tv":26.26,"id":9631798},{"atb":[[2.74,17.47]],"id":9631798}],"con":true,"img":false}]}
{"op":"mcm","clk":"1349985244","pt":1588414655819,"mc":[{"id":"1.170370562","rc":[{"trd":[[1.58,48.12]],"ltp":1.58,"tv":48.12,"id":9625043},{"atb":[[1.53,129.73]],"id":9625043},{"trd":[[2.74,27.75]],"ltp":2.74,"tv":27.75,"id":9631798},{"atb":[[2.74,15.98]],"id":9631798}],"con":true,"img":false}]}
{"op":"mcm","clk":"1349985258","pt":1588414656127,"mc":[{"id":"1.170370562","rc":[{"atb":[[1.53,147.46]],"id":9625043}],"con":true,"img":false}]}
{"op":"mcm","clk":"1349985262","pt":1588414656230,"mc":[{"id":"1.170370562","rc":[{"trd":[[1.6,484.59],[1.59,566.47],[1.58,75.84]],"ltp":1.6,"tv":1126.89,"id":9625043},{"atl":[[1.59,0],[1.6,487.92]],"id":9625043},{"trd":[[2.74,43.73]],"ltp":2.74,"tv":43.73,"id":9631798},{"atb":[[2.74,0]],"id":9631798}],"con":true,"img":false}]}
{"op":"mcm","clk":"1349985267","pt":1588414656337,"mc":[{"id":"1.170370562","rc":[{"atb":[[1.53,165.19]],"id":9625043}],"con":true,"img":false}]}
{"op":"mcm","clk":"1349985273","pt":1588414656489,"mc":[{"id":"1.170370562","rc":[{"atb":[[1.53,241.16]],"id":9625043}],"con":true,"img":false}]}
{"op":"mcm","clk":"1349985281","pt":1588414656696,"mc":[{"id":"1.170370562","rc":[{"atb":[[1.53,258.89]],"id":9625043}],"con":true,"img":false}]}
{"op":"mcm","clk":"1349985289","pt":1588414657005,"mc":[{"id":"1.170370562","rc":[{"trd":[[1.6,496.15]],"ltp":1.6,"tv":496.15,"id":9625043},{"atb":[[1.53,276.62]],"id":9625043},{"atl":[[1.6,482.14]],"id":9625043}],"con":true,"img":false}]}
{"op":"mcm","clk":"1349985294","pt":1588414657112,"mc":[{"id":"1.170370562","rc":[{"atb":[[2.68,1041.4]],"id":9631798}],"con":true,"img":false}]}
{"op":"mcm","clk":"1349985299","pt":1588414657213,"mc":[{"id":"1.170370562","rc":[{"atl":[[1.69,0]],"id":9625043},{"atl":[[2.74,13.66]],"id":9631798}],"con":true,"img":false}]}
{"op":"mcm","clk":"1349985302","pt":1588414657318,"mc":[{"id":"1.170370562","rc":[{"atb":[[1.53,294.35]],"id":9625043}],"con":true,"img":false}]}
{"op":"mcm","clk":"1349985311","pt":1588414657630,"mc":[{"id":"1.170370562","rc":[{"trd":[[1.57,15.95]],"ltp":1.57,"tv":15.95,"id":9625043},{"atb":[[1.54,83.4]],"id":9625043},{"trd":[[2.74,52.87]],"ltp":2.74,"tv":52.87,"id":9631798},{"atl":[[2.74,4.52]],"id":9631798}],"con":true,"img":false}]}
{"op":"mcm","clk":"1349985315","pt":1588414657731,"mc":[{"id":"1.170370562","rc":[{"atb":[[1.54,163.19]],"id":9625043}],"con":true,"img":false}]}
{"op":"mcm","clk":"1349985323","pt":1588414657785,"mc":[{"id":"1.170370562","rc":[{"trd":[[1.6,501.31]],"ltp":1.6,"tv":501.31,"id":9625043},{"atl":[[1.6,479.56]],"id":9625043}],"con":true,"img":false}]}
{"op":"mcm","clk":"1349985327","pt":1588414657889,"mc":[{"id":"1.170370562","rc":[{"atb":[[1.54,242.98]],"id":9625043}],"con":true,"img":false}]}
{"op":"mcm","clk":"1349985333","pt":1588414658098,"mc":[{"id":"1.170370562","rc":[{"trd":[[1.6,501.85]],"ltp":1.6,"tv":501.85,"id":9625043},{"atl":[[1.6,479.29]],"id":9625043}],"con":true,"img":false}]}
{"op":"mcm","clk":"1349985337","pt":1588414658198,"mc":[{"id":"1.170370562","rc":[{"atb":[[1.54,0]],"id":9631798}],"con":true,"img":false}]}
{"op":"mcm","clk":"1349985345","pt":1588414658505,"mc":[{"id":"1.170370562","rc":[{"atl":[[1.58,15.59]],"id":9625043}],"con":true,"img":false}]}
{"op":"mcm","clk":"1349985352","pt":1588414658920,"mc":[{"id":"1.170370562","rc":[{"trd":[[1.58,77.33]],"ltp":1.58,"tv":77.33,"id":9625043},{"atl":[[1.58,14.84]],"id":9625043}],"con":true,"img":false}]}
{"op":"mcm","clk":"1349985365","pt":1588414659331,"mc":[{"id":"1.170370562","rc":[{"trd":[[1.58,78.14]],"ltp":1.58,"tv":78.14,"id":9625043},{"atl":[[1.58,14.03]],"id":9625043},{"trd":[[2.72,0.47]],"ltp":2.72,"tv":0.47,"id":9631798}],"con":true,"img":false}]}
{"op":"mcm","clk":"1349985401","pt":1588414660210,"mc":[{"id":"1.170370562","rc":[{"atl":[[2.74,0]],"id":9631798}],"con":true,"img":false}]}
{"op":"mcm","clk":"1349985413","pt":1588414660618,"mc":[{"id":"1.170370562","rc":[{"trd":[[1.58,81.58]],"ltp":1.58,"tv":81.58,"id":9625043},{"atl":[[1.58,12.31]],"id":9625043}],"con":true,"img":false}]}
{"op":"mcm","clk":"1349985419","pt":1588414660721,"mc":[{"id":"1.170370562","rc":[{"atb":[[1.45,0.1]],"id":9625043}],"con":true,"img":false}]}
{"op":"mcm","clk":"1349985453","pt":1588414661399,"mc":[{"id":"1.170370562","rc":[{"trd":[[1.58,81.79]],"ltp":1.58,"tv":81.79,"id":9625043},{"atl":[[1.58,12.2]],"id":9625043}],"con":true,"img":false}]}
{"op":"mcm","clk":"1349985463","pt":1588414661712,"mc":[{"id":"1.170370562","rc":[{"trd":[[1.58,84.15]],"ltp":1.58,"tv":84.15,"id":9625043},{"atl":[[1.58,11.02]],"id":9625043}],"con":true,"img":false}]}
{"op":"mcm","clk":"1349985473","pt":1588414661921,"mc":[{"id":"1.170370562","rc":[{"atb":[[1.51,127.5]],"id":9625043},{"atl":[[1.63,35.46],[2.88,0]],"id":9625043}],"con":true,"img":false}]}
{"op":"mcm","clk":"1349985493","pt":1588414662435,"mc":[{"id":"1.170370562","rc":[{"atl":[[1.65,0]],"id":9625043}],"con":true,"img":false}]}
{"op":"mcm","clk":"1349985543","pt":1588414663701,"mc":[{"id":"1.170370562","rc":[{"atl":[[1.59,118.2]],"id":9625043}],"con":true,"img":false}]}
{"op":"mcm","clk":"1349985580","pt":1588414664735,"mc":[{"id":"1.170370562","rc":[{"trd":[[1.58,86.18]],"ltp":1.58,"tv":86.18,"id":9625043},{"atl":[[1.58,8.99]],"id":9625043},{"trd":[[2.72,1.65]],"ltp":2.72,"tv":1.65,"id":9631798}],"con":true,"img":false}]}
{"op":"mcm","clk":"1349985592","pt":1588414665043,"mc":[{"id":"1.170370562","rc":[{"atl":[[1.59,315]],"id":9625043}],"con":true,"img":false}]}
{"op":"mcm","clk":"1349985607","pt":1588414665507,"mc":[{"id":"1.170370562","rc":[{"atl":[[1.58,26.72]],"id":9625043}],"con":true,"img":false}]}
{"op":"mcm","clk":"1349985616","pt":1588414665920,"mc":[{"id":"1.170370562","rc":[{"atl":[[1.59,332.73]],"id":9625043}],"con":true,"img":false}]}
{"op":"mcm","clk":"1349985624","pt":1588414666333,"mc":[{"id":"1.170370562","rc":[{"atb":[[1.53,182.35]],"id":9625043},{"atl":[[1.59,350.46]],"id":9625043}],"con":true,"img":false}]}
{"op":"mcm","clk":"1349985628","pt":1588414666435,"mc":[{"id":"1.170370562","rc":[{"atl":[[2.78,4.45]],"id":9631798}],"con":true,"img":false}]}
{"op":"mcm","clk":"1349985632","pt":1588414666538,"mc":[{"id":"1.170370562","rc":[{"atl":[[1.58,28.72]],"id":9625043}],"con":true,"img":false}]}
{"op":"mcm","clk":"1349985636","pt":1588414666642,"mc":[{"id":"1.170370562","rc":[{"atl":[[1.59,368.2]],"id":9625043}],"con":true,"img":false}]}
{"op":"mcm","clk":"1349985641","pt":1588414666749,"mc":[{"id":"1.170370562","rc":[{"trd":[[1.51,255.01],[1.56,7.92],[1.54,485.96],[1.53,364.7],[1.52,702.72]],"ltp":1.51,"tv":1816.31,"id":9625043},{"atb":[[1.51,0],[1.53,0],[1.54,0],[1.52,0]],"id":9625043},{"atl":[[1.51,264.91]],"id":9625043},{"trd":[[2.78,4.45]],"ltp":2.78,"tv":4.45,"id":9631798},{"atl":[[2.78,0]],"id":9631798}],"con":true,"img":false}]}
{"op":"mcm","clk":"1349985689","pt":1588414667836,"mc":[{"id":"1.170370562","rc":[{"trd":[[1.51,272.39]],"ltp":1.51,"tv":272.39,"id":9625043},{"atl":[[1.51,247.54]],"id":9625043},{"trd":[[2.96,8.86]],"ltp":2.96,"tv":8.86,"id":9631798}],"con":true,"img":false}]}
{"op":"mcm","clk":"1349985702","pt":1588414668139,"mc":[{"id":"1.170370562","rc":[{"atl":[[1.59,385.93]],"id":9625043}],"con":true,"img":false}]}
{"op":"mcm","clk":"1349985709","pt":1588414668353,"mc":[{"id":"1.170370562","rc":[{"trd":[[1.51,273.52]],"ltp":1.51,"tv":273.52,"id":9625043},{"atl":[[1.51,246.97]],"id":9625043}],"con":true,"img":false}]}
{"op":"mcm","clk":"1349985726","pt":1588414668821,"mc":[{"id":"1.170370562","rc":[{"atb":[[2.7,38.39]],"id":9631798}],"con":true,"img":false}]}
{"op":"mcm","clk":"1349985747","pt":1588414669345,"mc":[{"id":"1.170370562","rc":[{"trd":[[1.51,308.98]],"ltp":1.51,"tv":308.98,"id":9625043},{"atl":[[1.51,229.24]],"id":9625043}],"con":true,"img":false}]}
{"op":"mcm","clk":"1349985762","pt":1588414669711,"mc":[{"id":"1.170370562","rc":[{"trd":[[1.51,344.44]],"ltp":1.51,"tv":344.44,"id":9625043},{"atl":[[1.51,211.51]],"id":9625043}],"con":true,"img":false}]}
{"op":"mcm","clk":"1349985765","pt":1588414669819,"mc":[{"id":"1.170370562","rc":[{"atl":[[1.53,15]],"id":9625043}],"con":true,"img":false}]}
{"op":"mcm","clk":"1349985777","pt":1588414670124,"mc":[{"id":"1.170370562","rc":[{"atl":[[1.57,0.74]],"id":9625043}],"con":true,"img":false}]}
{"op":"mcm","clk":"1349985782","pt":1588414670230,"mc":[{"id":"1.170370562","rc":[{"atb":[[1.5,112]],"id":9625043}],"con":true,"img":false}]}
{"op":"mcm","clk":"1349985787","pt":1588414670333,"mc":[{"id":"1.170370562","rc":[{"trd":[[1.51,379.9]],"ltp":1.51,"tv":379.9,"id":9625043},{"atl":[[1.51,193.78]],"id":9625043}],"con":true,"img":false}]}
{"op":"mcm","clk":"1349985793","pt":1588414670540,"mc":[{"id":"1.170370562","rc":[{"trd":[[1.51,380.29]],"ltp":1.51,"tv":380.29,"id":9625043},{"atl":[[1.51,193.59]],"id":9625043}],"con":true,"img":false}]}
{"op":"mcm","clk":"1349985821","pt":1588414671217,"mc":[{"id":"1.170370562","rc":[{"trd":[[1.51,389.01]],"ltp":1.51,"tv":389.01,"id":9625043},{"atl":[[1.51,184.86]],"id":9625043},{"trd":[[2.96,13.31]],"ltp":2.96,"tv":13.31,"id":9631798}],"con":true,"img":false}]}
{"op":"mcm","clk":"1349985851","pt":1588414672146,"mc":[{"id":"1.170370562","rc":[{"trd":[[1.51,428.33]],"ltp":1.51,"tv":428.33,"id":9625043},{"atl":[[1.51,163.27]],"id":9625043},{"trd":[[2.96,15.28]],"ltp":2.96,"tv":15.28,"id":9631798}],"con":true,"img":false}]}
{"op":"mcm","clk":"1349985863","pt":1588414672451,"mc":[{"id":"1.170370562","rc":[{"atl":[[1.54,68]],"id":9625043}],"con":true,"img":false}]}
{"op":"mcm","clk":"1349985869","pt":1588414672609,"mc":[{"id":"1.170370562","rc":[{"atl":[[1.6,0]],"id":9625043}],"con":true,"img":false}]}
{"op":"mcm","clk":"1349985880","pt":1588414673025,"mc":[{"id":"1.170370562","rc":[{"trd":[[1.51,754.89]],"ltp":1.51,"tv":754.89,"id":9625043},{"atb":[[1.51,58.72]],"id":9625043},{"atl":[[1.51,0],[1.54,88]],"id":9625043}],"con":true,"img":false}]}
{"op":"mcm","clk":"1349985892","pt":1588414673334,"mc":[{"id":"1.170370562","rc":[{"atb":[[2.68,0]],"id":9631798}],"con":true,"img":false}]}
{"op":"mcm","clk":"1349985897","pt":1588414673440,"mc":[{"id":"1.170370562","rc":[{"atl":[[1.57,336.6]],"id":9625043}],"con":true,"img":false}]}
{"op":"mcm","clk":"1349985904","pt":1588414673647,"mc":[{"id":"1.170370562","rc":[{"trd":[[1.53,380.7]],"ltp":1.53,"tv":380.7,"id":9625043},{"atb":[[1.52,17.73]],"id":9625043},{"atl":[[1.53,7],[1.56,225.54]],"id":9625043}],"con":true,"img":false}]}
{"op":"mcm","clk":"1349985905","pt":1588414673746,"mc":[{"id":"1.170370562","rc":[{"trd":[[1.53,381.16]],"ltp":1.53,"tv":381.16,"id":9625043},{"atl":[[1.53,6.77]],"id":9625043}],"con":true,"img":false}]}
{"op":"mcm","clk":"1349985919","pt":1588414674056,"mc":[{"id":"1.170370562","rc":[{"atb":[[1.51,0]],"id":9625043},{"atl":[[1.54,316.48]],"id":9625043}],"con":true,"img":false}]}
{"op":"mcm","clk":"1349985922","pt":1588414674109,"mc":[{"id":"1.170370562","rc":[{"atb":[[1.52,35.46]],"id":9625043}],"con":true,"img":false}]}
{"op":"mcm","clk":"1349985925","pt":1588414674211,"mc":[{"id":"1.170370562","rc":[{"atl":[[1.57,448.6]],"id":9625043}],"con":true,"img":false}]}
{"op":"mcm","clk":"1349985933","pt":1588414674420,"mc":[{"id":"1.170370562","rc":[{"atl":[[1.72,0.11]],"id":9625043}],"con":true,"img":false}]}
{"op":"mcm","clk":"1349985945","pt":1588414674731,"mc":[{"id":"1.170370562","rc":[{"atb":[[1.51,112]],"id":9625043}],"con":true,"img":false}]}
{"op":"mcm","clk":"1349985948","pt":1588414674831,"mc":[{"id":"1.170370562","rc":[{"atb":[[1.52,53.19]],"id":9625043}],"con":true,"img":false}]}
{"op":"mcm","clk":"1349985969","pt":1588414675353,"mc":[{"id":"1.170370562","rc":[{"atb":[[1.51,224],[1.52,70.92]],"id":9625043}],"con":true,"img":false}]}
{"op":"mcm","clk":"1349985997","pt":1588414676131,"mc":[{"id":"1.170370562","rc":[{"trd":[[1.56,52.1],[1.54,802.44],[1.53,387.93]],"ltp":1.56,"tv":1242.47,"id":9625043},{"atl":[[1.53,0],[1.56,181.37],[1.54,0]],"id":9625043},{"trd":[[2.78,29.24],[2.88,3.6],[2.84,171.61]],"ltp":2.78,"tv":204.45,"id":9631798}],"con":true,"img":false}]}
{"op":"mcm","clk":"1349986002","pt":1588414676339,"mc":[{"id":"1.170370562","rc":[{"atl":[[1.56,0]],"id":9625043}],"con":true,"img":false}]}
{"op":"mcm","clk":"1349986014","pt":1588414676650,"mc":[{"id":"1.170370562","rc":[{"atb":[[1.53,17.73]],"id":9625043}],"con":true,"img":false}]}
{"op":"mcm","clk":"1349986023","pt":1588414676911,"mc":[{"id":"1.170370562","rc":[{"atb":[[1.51,225.05]],"id":9625043}],"con":true,"img":false}]}
{"op":"mcm","clk":"1349986029","pt":1588414677116,"mc":[{"id":"1.170370562","rc":[{"atb":[[1.53,35.46]],"id":9625043}],"con":true,"img":false}]}
{"op":"mcm","clk":"1349986045","pt":1588414677744,"mc":[{"id":"1.170370562","rc":[{"trd":[[1.5,224],[1.51,1205.01],[1.53,458.85],[1.52,844.56]],"ltp":1.5,"tv":2732.42,"id":9625043},{"atb":[[1.51,0],[1.53,0],[1.5,0],[1.52,0]],"id":9625043},{"atl":[[1.5,35.85]],"id":9625043}],"con":true,"img":false}]}
{"op":"mcm","clk":"1349986051","pt":1588414677842,"mc":[{"id":"1.170370562","rc":[{"trd":[[1.5,237.13]],"ltp":1.5,"tv":237.13,"id":9625043},{"atl":[[1.5,29.28]],"id":9625043}],"con":true,"img":false}]}
{"op":"mcm","clk":"1349986053","pt":1588414677945,"mc":[{"id":"1.170370562","rc":[{"atl":[[1.56,211.08]],"id":9625043}],"con":true,"img":false}]}
{"op":"mcm","clk":"1349986062","pt":1588414678154,"mc":[{"id":"1.170370562","rc":[{"trd":[[1.5,239.61]],"ltp":1.5,"tv":239.61,"id":9625043},{"atl":[[1.5,28.04]],"id":9625043}],"con":true,"img":false}]}
{"op":"mcm","clk":"1349986067","pt":1588414678358,"mc":[{"id":"1.170370562","rc":[{"trd":[[1.5,247.03]],"ltp":1.5,"tv":247.03,"id":9625043},{"atl":[[1.5,24.33]],"id":9625043}],"con":true,"img":false}]}
{"op":"mcm","clk":"1349986076","pt":1588414678635,"mc":[{"id":"1.170370562","rc":[{"atb":[[3,4.39]],"id":9631798}],"con":true,"img":false}]}
{"op":"mcm","clk":"1349986088","pt":1588414678939,"mc":[{"id":"1.170370562","rc":[{"atl":[[1.59,189.12],[1.56,228.81]],"id":9625043}],"con":true,"img":false}]}
{"op":"mcm","clk":"1349986092","pt":1588414679041,"mc":[{"id":"1.170370562","rc":[{"trd":[[1.5,252.19]],"ltp":1.5,"tv":252.19,"id":9625043},{"atl":[[1.5,21.75]],"id":9625043}],"con":true,"img":false}]}
{"op":"mcm","clk":"1349986112","pt":1588414679514,"mc":[{"id":"1.170370562","rc":[{"atl":[[1.56,246.54]],"id":9625043}],"con":true,"img":false}]}
{"op":"mcm","clk":"1349986122","pt":1588414679823,"mc":[{"id":"1.170370562","rc":[{"atb":[[3,0]],"id":9631798}],"con":true,"img":false}]}
{"op":"mcm","clk":"1349986132","pt":1588414680030,"mc":[{"id":"1.170370562","rc":[{"atl":[[1.54,2.57]],"id":9625043}],"con":true,"img":false}]}
{"op":"mcm","clk":"1349986135","pt":1588414680133,"mc":[{"id":"1.170370562","rc":[{"atl":[[1.53,161.14],[1.55,17.73]],"id":9625043}],"con":true,"img":false}]}
{"op":"mcm","clk":"1349986151","pt":1588414680657,"mc":[{"id":"1.170370562","rc":[{"atl":[[1.55,35.46]],"id":9625043}],"con":true,"img":false}]}
{"op":"mcm","clk":"1349986159","pt":1588414680916,"mc":[{"id":"1.170370562","rc":[{"atl":[[1.57,0.74]],"id":9625043}],"con":true,"img":false}]}
{"op":"mcm","clk":"1349986168","pt":1588414681125,"mc":[{"id":"1.170370562","rc":[{"atb":[[1.46,0],[1.44,4.03]],"id":9625043}],"con":true,"img":false}]}
{"op":"mcm","clk":"1349986190","pt":1588414681856,"mc":[{"id":"1.170370562","rc":[{"atl":[[1.55,53.19]],"id":9625043}],"con":true,"img":false}]}
{"op":"mcm","clk":"1349986211","pt":1588414682742,"mc":[{"id":"1.170370562","rc":[{"atl":[[1.59,70.92]],"id":9625043}],"con":true,"img":false}]}
{"op":"mcm","clk":"1349986218","pt":1588414682950,"mc":[{"id":"1.170370562","rc":[{"atl":[[1.56,255.65]],"id":9625043}],"con":true,"img":false}]}
{"op":"mcm","clk":"1349986263","pt":1588414684046,"mc":[{"id":"1.170370562","rc":[{"atl":[[1.55,70.92]],"id":9625043}],"con":true,"img":false}]}
{"op":"mcm","clk":"1349986275","pt":1588414684371,"mc":[{"id":"1.170370562","rc":[{"atl":[[1.54,82.36]],"id":9625043}],"con":true,"img":false}]}
{"op":"mcm","clk":"1349986280","pt":1588414684467,"mc":[{"id":"1.170370562","rc":[{"atl":[[1.54,162.15]],"id":9625043}],"con":true,"img":false}]}
{"op":"mcm","clk":"1349986286","pt":1588414684519,"mc":[{"id":"1.170370562","rc":[{"atl":[[1.55,88.65]],"id":9625043}],"con":true,"img":false}]}
{"op":"mcm","clk":"1349986299","pt":1588414684833,"mc":[{"id":"1.170370562","rc":[{"atl":[[1.55,755.45]],"id":9625043}],"con":true,"img":false}]}
{"op":"mcm","clk":"1349986311","pt":1588414685248,"mc":[{"id":"1.170370562","rc":[{"trd":[[1.5,287.65]],"ltp":1.5,"tv":287.65,"id":9625043},{"atl":[[1.5,4.02]],"id":9625043}],"con":true,"img":false}]}
{"op":"mcm","clk":"1349986318","pt":1588414685457,"mc":[{"id":"1.170370562","rc":[{"atb":[[1.45,196.91]],"id":9625043}],"con":true,"img":false}]}
{"op":"mcm","clk":"1349986323","pt":1588414685567,"mc":[{"id":"1.170370562","rc":[{"trd":[[1.5,291.19]],"ltp":1.5,"tv":291.19,"id":9625043},{"atl":[[1.5,2.25]],"id":9625043}],"con":true,"img":false}]}
{"op":"mcm","clk":"1349986328","pt":1588414685666,"mc":[{"id":"1.170370562","rc":[{"trd":[[1.5,291.56]],"ltp":1.5,"tv":291.56,"id":9625043},{"atl":[[1.5,2.06]],"id":9625043}],"con":true,"img":false}]}
{"op":"mcm","clk":"1349986333","pt":1588414685768,"mc":[{"id":"1.170370562","rc":[{"trd":[[1.5,295.68]],"ltp":1.5,"tv":295.68,"id":9625043},{"atb":[[1.51,15.67]],"id":9625043},{"atl":[[1.5,0]],"id":9625043}],"con":true,"img":false}]}
{"op":"mcm","clk":"1349986352","pt":1588414686342,"mc":[{"id":"1.170370562","rc":[{"atl":[[1.58,19.73]],"id":9625043}],"con":true,"img":false}]}
{"op":"mcm","clk":"1349986372","pt":1588414686963,"mc":[{"id":"1.170370562","rc":[{"atb":[[1.5,0.61]],"id":9625043}],"con":true,"img":false}]}
{"op":"mcm","clk":"1349986401","pt":1588414687939,"mc":[{"id":"1.170370562","rc":[{"atb":[[1.35,79.78],[1.5,0.73],[1.47,0.17]],"id":9625043}],"con":true,"img":false}]}
{"op":"mcm","clk":"1349986403","pt":1588414688042,"mc":[{"id":"1.170370562","rc":[{"atb":[[1.35,159.57]],"id":9625043}],"con":true,"img":false}]}
{"op":"mcm","clk":"1349986409","pt":1588414688249,"mc":[{"id":"1.170370562","rc":[{"atb":[[1.35,239.36]],"id":9625043}],"con":true,"img":false}]}
{"op":"mcm","clk":"1349986418","pt":1588414688663,"mc":[{"id":"1.170370562","rc":[{"atl":[[1.55,88.65]],"id":9625043}],"con":true,"img":false}]}
{"op":"mcm","clk":"1349986434","pt":1588414689024,"mc":[{"id":"1.170370562","rc":[{"atb":[[1.34,79.78]],"id":9625043}],"con":true,"img":false}]}
{"op":"mcm","clk":"1349986442","pt":1588414689230,"mc":[{"id":"1.170370562","rc":[{"atb":[[1.34,159.57]],"id":9625043}],"con":true,"img":false}]}
{"op":"mcm","clk":"1349986445","pt":1588414689333,"mc":[{"id":"1.170370562","rc":[{"atb":[[1.34,239.36]],"id":9625043}],"con":true,"img":false}]}
{"op":"mcm","clk":"1349986456","pt":1588414689745,"mc":[{"id":"1.170370562","rc":[{"atl":[[1.58,17.73]],"id":9625043}],"con":true,"img":false}]}
{"op":"mcm","clk":"1349986469","pt":1588414690156,"mc":[{"id":"1.170370562","rc":[{"atb":[[1.33,79.78]],"id":9625043}],"con":true,"img":false}]}
{"op":"mcm","clk":"1349986479","pt":1588414690362,"mc":[{"id":"1.170370562","rc":[{"atb":[[1.33,159.57]],"id":9625043}],"con":true,"img":false}]}
{"op":"mcm","clk":"1349986481","pt":1588414690465,"mc":[{"id":"1.170370562","rc":[{"atb":[[1.33,239.36]],"id":9625043}],"con":true,"img":false}]}
{"op":"mcm","clk":"1349986508","pt":1588414691136,"mc":[{"id":"1.170370562","rc":[{"trd":[[1.41,4.04],[1.51,1236.36],[1.47,0.35],[1.45,393.82],[1.44,8.06],[1.5,297.16]],"ltp":1.41,"tv":1939.79,"id":9625043},{"atb":[[1.44,0],[1.45,0],[1.51,0],[1.41,0],[1.5,0],[1.47,0]],"id":9625043},{"atl":[[1.4,1584.94]],"id":9625043}],"con":true,"img":false}]}
{"op":"mcm","clk":"1349986515","pt":1588414691240,"mc":[{"id":"1.170370562","rc":[{"atl":[[1.52,112]],"id":9625043}],"con":true,"img":false}]}
{"op":"mcm","clk":"1349986527","pt":1588414691652,"mc":[{"id":"1.170370562","rc":[{"atl":[[1.56,246.54]],"id":9625043}],"con":true,"img":false}]}
{"op":"mcm","clk":"1349986541","pt":1588414692169,"mc":[{"id":"1.170370562","rc":[{"atl":[[1.52,224]],"id":9625043}],"con":true,"img":false}]}
{"op":"mcm","clk":"1349986563","pt":1588414692843,"mc":[{"id":"1.170370562","rc":[{"atl":[[1000,2]],"id":9631798}],"con":true,"img":false}]}
{"op":"mcm","clk":"1349986566","pt":1588414692946,"mc":[{"id":"1.170370562","rc":[{"atl":[[1.54,2.57]],"id":9625043}],"con":true,"img":false}]}
{"op":"mcm","clk":"1349986572","pt":1588414693151,"mc":[{"id":"1.170370562","rc":[{"atl":[[1000,0.01]],"id":9631798}],"con":true,"img":false}]}
{"op":"mcm","clk":"1349986579","pt":1588414693359,"mc":[{"id":"1.170370562","rc":[{"atl":[[1000,2]],"id":9631798}],"con":true,"img":false}]}
{"op":"mcm","clk":"1349986590","pt":1588414693669,"mc":[{"id":"1.170370562","rc":[{"atl":[[1000,2.01]],"id":9631798}],"con":true,"img":false}]}
{"op":"mcm","clk":"1349986599","pt":1588414693874,"mc":[{"id":"1.170370562","rc":[{"atl":[[1000,0.01]],"id":9631798}],"con":true,"img":false}]}
{"op":"mcm","clk":"1349986603","pt":1588414693979,"mc":[{"id":"1.170370562","rc":[{"atl":[[1000,0]],"id":9631798}],"con":true,"img":false}]}
{"op":"mcm","clk":"1349986625","pt":1588414694234,"mc":[{"id":"1.170370562","rc":[{"atb":[[2.9,4.54]],"id":9631798}],"con":true,"img":false}]}
{"op":"mcm","clk":"1349986690","pt":1588414695787,"mc":[{"id":"1.170370562","rc":[{"atl":[[1.51,9.41]],"id":9625043}],"con":true,"img":false}]}
{"op":"mcm","clk":"1349986712","pt":1588414696256,"mc":[{"id":"1.170370562","rc":[{"atl":[[1.53,0]],"id":9625043}],"con":true,"img":false}]}
{"op":"mcm","clk":"1349986722","pt":1588414696463,"mc":[{"id":"1.170370562","rc":[{"atl":[[1.51,9.53]],"id":9625043}],"con":true,"img":false}]}
{"op":"mcm","clk":"1349986733","pt":1588414696671,"mc":[{"id":"1.170370562","rc":[{"atb":[[3.25,6]],"id":9631798}],"con":true,"img":false}]}
{"op":"mcm","clk":"1349986752","pt":1588414697138,"mc":[{"id":"1.170370562","rc":[{"atb":[[2.98,15.19]],"id":9631798}],"con":true,"img":false}]}
{"op":"mcm","clk":"1349986770","pt":1588414697657,"mc":[{"id":"1.170370562","rc":[{"trd":[[1.4,443.99]],"ltp":1.4,"tv":443.99,"id":9625043},{"atl":[[1.4,1362.94]],"id":9625043}],"con":true,"img":false}]}
{"op":"mcm","clk":"1349986782","pt":1588414697973,"mc":[{"id":"1.170370562","rc":[{"trd":[[1.4,887.99]],"ltp":1.4,"tv":887.99,"id":9625043},{"atl":[[1.51,10.27],[1.4,1140.94]],"id":9625043}],"con":true,"img":false}]}
{"op":"mcm","clk":"1349986788","pt":1588414698180,"mc":[{"id":"1.170370562","rc":[{"trd":[[1.4,1367.45]],"ltp":1.4,"tv":1367.45,"id":9625043},{"atl":[[1.4,901.21]],"id":9625043}],"con":true,"img":false}]}
{"op":"mcm","clk":"1349986800","pt":1588414698492,"mc":[{"id":"1.170370562","rc":[{"trd":[[1.4,1367.48]],"ltp":1.4,"tv":1367.48,"id":9625043},{"atl":[[1.4,901.19]],"id":9625043},{"trd":[[3.5,0.01]],"ltp":3.5,"tv":0.01,"id":9631798}],"con":true,"img":false}]}
{"op":"mcm","clk":"1349986803","pt":1588414698561,"mc":[{"id":"1.170370562","rc":[{"trd":[[1.4,1811.48]],"ltp":1.4,"tv":1811.48,"id":9625043},{"atb":[[1.35,0]],"id":9625043},{"atl":[[1.4,679.19]],"id":9625043},{"atb":[[2.98,0]],"id":9631798}],"con":true,"img":false}]}
{"op":"mcm","clk":"1349986808","pt":1588414698662,"mc":[{"id":"1.170370562","rc":[{"atl":[[1.5,79.78],[1.49,201.06]],"id":9625043}],"con":true,"img":false}]}
{"op":"mcm","clk":"1349986822","pt":1588414698869,"mc":[{"id":"1.170370562","rc":[{"atl":[[1.5,159.57]],"id":9625043}],"con":true,"img":false}]}
{"op":"mcm","clk":"1349986826","pt":1588414698973,"mc":[{"id":"1.170370562","rc":[{"trd":[[1.4,1811.51]],"ltp":1.4,"tv":1811.51,"id":9625043},{"atl":[[1.4,679.16]],"id":9625043},{"trd":[[3.5,0.02]],"ltp":3.5,"tv":0.02,"id":9631798}],"con":true,"img":false}]}
{"op":"mcm","clk":"1349986831","pt":1588414699079,"mc":[{"id":"1.170370562","rc":[{"trd":[[1.4,1811.53]],"ltp":1.4,"tv":1811.53,"id":9625043},{"atl":[[1.4,679.14]],"id":9625043},{"trd":[[3.5,0.03]],"ltp":3.5,"tv":0.03,"id":9631798}],"con":true,"img":false}]}
{"op":"mcm","clk":"1349986878","pt":1588414700270,"mc":[{"id":"1.170370562","rc":[{"atb":[[1.3,1177.05]],"id":9625043}],"con":true,"img":false}]}
{"op":"mcm","clk":"1349986893","pt":1588414700580,"mc":[{"id":"1.170370562","rc":[{"atl":[[4.2,0]],"id":9631798}],"con":true,"img":false}]}
{"op":"mcm","clk":"1349986920","pt":1588414701403,"mc":[{"id":"1.170370562","rc":[{"atb":[[2.9,0]],"id":9631798}],"con":true,"img":false}]}
{"op":"mcm","clk":"1349986932","pt":1588414701975,"mc":[{"id":"1.170370562","rc":[{"trd":[[1.4,1909.99]],"ltp":1.4,"tv":1909.99,"id":9625043},{"atl":[[1.4,629.91]],"id":9625043}],"con":true,"img":false}]}
{"op":"mcm","clk":"1349986936","pt":1588414702078,"mc":[{"id":"1.170370562","rc":[{"trd":[[1.4,1945.45]],"ltp":1.4,"tv":1945.45,"id":9625043},{"atl":[[1.4,612.18]],"id":9625043}],"con":true,"img":false}]}
{"op":"mcm","clk":"1349986944","pt":1588414702387,"mc":[{"id":"1.170370562","rc":[{"atl":[[1000,2]],"id":9631798}],"con":true,"img":false}]}
{"op":"mcm","clk":"1349986949","pt":1588414702487,"mc":[{"id":"1.170370562","rc":[{"trd":[[1.4,3169.81]],"ltp":1.4,"tv":3169.81,"id":9625043},{"atb":[[1.4,387.82]],"id":9625043},{"atl":[[1.4,0]],"id":9625043}],"con":true,"img":false}]}
{"op":"mcm","clk":"1349986953","pt":1588414702590,"mc":[{"id":"1.170370562","rc":[{"atb":[[1.42,17.73]],"id":9625043}],"con":true,"img":false}]}
{"op":"mcm","clk":"1349986956","pt":1588414702692,"mc":[{"id":"1.170370562","rc":[{"atl":[[1000,2.01]],"id":9631798}],"con":true,"img":false}]}
{"op":"mcm","clk":"1349986963","pt":1588414702952,"mc":[{"id":"1.170370562","rc":[{"trd":[[1.45,396.39]],"ltp":1.45,"tv":396.39,"id":9625043},{"trd":[[3.25,1.15]],"ltp":3.25,"tv":1.15,"id":9631798},{"atb":[[3.25,4.85]],"id":9631798}],"con":true,"img":false}]}
{"op":"mcm","clk":"1349986966","pt":1588414703054,"mc":[{"id":"1.170370562","rc":[{"atl":[[1000,0.01]],"id":9631798}],"con":true,"img":false}]}
{"op":"mcm","clk":"1349986969","pt":1588414703159,"mc":[{"id":"1.170370562","rc":[{"atb":[[1.42,35.46]],"id":9625043},{"atl":[[1000,2.01]],"id":9631798}],"con":true,"img":false}]}
{"op":"mcm","clk":"1349986971","pt":1588414703263,"mc":[{"id":"1.170370562","rc":[{"atl":[[1000,2]],"id":9631798}],"con":true,"img":false}]}
{"op":"mcm","clk":"1349986975","pt":1588414703366,"mc":[{"id":"1.170370562","rc":[{"atl":[[1000,4]],"id":9631798}],"con":true,"img":false}]}
{"op":"mcm","clk":"1349986978","pt":1588414703469,"mc":[{"id":"1.170370562","rc":[{"atl":[[1000,2.01]],"id":9631798}],"con":true,"img":false}]}
{"op":"mcm","clk":"1349986982","pt":1588414703573,"mc":[{"id":"1.170370562","rc":[{"atl":[[1000,2.02]],"id":9631798}],"con":true,"img":false}]}
{"op":"mcm","clk":"1349986986","pt":1588414703677,"mc":[{"id":"1.170370562","rc":[{"atl":[[1000,2.01]],"id":9631798}],"con":true,"img":false}]}
{"op":"mcm","clk":"1349986993","pt":1588414703779,"mc":[{"id":"1.170370562","rc":[{"atb":[[1.4,1405.33]],"id":9625043}],"con":true,"img":false}]}
{"op":"mcm","clk":"1349987002","pt":1588414704102,"mc":[{"id":"1.170370562","rc":[{"atb":[[1.4,2405.33]],"id":9625043},{"atl":[[1000,0.02]],"id":9631798}],"con":true,"img":false}]}
{"op":"mcm","clk":"1349987006","pt":1588414704192,"mc":[{"id":"1.170370562","rc":[{"atl":[[1000,0.01]],"id":9631798}],"con":true,"img":false}]}
{"op":"mcm","clk":"1349987012","pt":1588414704295,"mc":[{"id":"1.170370562","rc":[{"atb":[[1.42,53.19]],"id":9625043},{"atl":[[1000,0]],"id":9631798}],"con":true,"img":false}]}
{"op":"mcm","clk":"1349987021","pt":1588414704557,"mc":[{"id":"1.170370562","rc":[{"trd":[[1.45,396.63]],"ltp":1.45,"tv":396.63,"id":9625043},{"trd":[[3.25,1.24]],"ltp":3.25,"tv":1.24,"id":9631798},{"atb":[[3.25,4.75]],"id":9631798}],"con":true,"img":false}]}
{"op":"mcm","clk":"1349987029","pt":1588414704762,"mc":[{"id":"1.170370562","rc":[{"atl":[[1000,2]],"id":9631798}],"con":true,"img":false}]}
{"op":"mcm","clk":"1349987031","pt":1588414704866,"mc":[{"id":"1.170370562","rc":[{"atb":[[1.43,17.73]],"id":9625043}],"con":true,"img":false}]}
{"op":"mcm","clk":"1349987036","pt":1588414704968,"mc":[{"id":"1.170370562","rc":[{"atl":[[1000,2.01]],"id":9631798}],"con":true,"img":false}]}
{"op":"mcm","clk":"1349987042","pt":1588414705173,"mc":[{"id":"1.170370562","rc":[{"atb":[[1.4,17.51]],"id":9625043},{"atl":[[1000,2]],"id":9631798}],"con":true,"img":false}]}
{"op":"mcm","clk":"1349987045","pt":1588414705279,"mc":[{"id":"1.170370562","rc":[{"atb":[[3.25,0]],"id":9631798},{"atl":[[1000,2.01]],"id":9631798}],"con":true,"img":false}]}
{"op":"mcm","clk":"1349987048","pt":1588414705381,"mc":[{"id":"1.170370562","rc":[{"atb":[[1.43,35.46]],"id":9625043},{"atl":[[1000,4.01]],"id":9631798}],"con":true,"img":false}]}
{"op":"mcm","clk":"1349987051","pt":1588414705484,"mc":[{"id":"1.170370562","rc":[{"atl":[[1000,2.01]],"id":9631798}],"con":true,"img":false}]}
{"op":"mcm","clk":"1349987054","pt":1588414705587,"mc":[{"id":"1.170370562","rc":[{"atb":[[1.43,53.19]],"id":9625043},{"atl":[[1.48,112]],"id":9625043},{"atl":[[1000,0.02]],"id":9631798}],"con":true,"img":false}]}
{"op":"mcm","clk":"1349987056","pt":1588414705690,"mc":[{"id":"1.170370562","rc":[{"atl":[[1.5,0]],"id":9625043},{"atl":[[1000,0.01]],"id":9631798}],"con":true,"img":false}]}
{"op":"mcm","clk":"1349987061","pt":1588414705793,"mc":[{"id":"1.170370562","rc":[{"atl":[[1000,0]],"id":9631798}],"con":true,"img":false}]}
{"op":"mcm","clk":"1349987066","pt":1588414705894,"mc":[{"id":"1.170370562","rc":[{"atb":[[1.43,70.92]],"id":9625043}],"con":true,"img":false}]}
{"op":"mcm","clk":"1349987074","pt":1588414706100,"mc":[{"id":"1.170370562","rc":[{"atl":[[1.48,224]],"id":9625043}],"con":true,"img":false}]}
{"op":"mcm","clk":"1349987081","pt":1588414706156,"mc":[{"id":"1.170370562","rc":[{"atl":[[1.45,222],[1.51,30.5],[1.47,222]],"id":9625043}],"con":true,"img":false}]}
{"op":"mcm","clk":"1349987086","pt":1588414706255,"mc":[{"id":"1.170370562","rc":[{"atb":[[1.43,88.65]],"id":9625043}],"con":true,"img":false}]}
{"op":"mcm","clk":"1349987096","pt":1588414706573,"mc":[{"id":"1.170370562","rc":[{"trd":[[1.45,401.35]],"ltp":1.45,"tv":401.35,"id":9625043},{"atl":[[1.45,219.64]],"id":9625043},{"atl":[[3.9,73.69]],"id":9631798}],"con":true,"img":false}]}
{"op":"mcm","clk":"1349987103","pt":1588414706776,"mc":[{"id":"1.170370562","rc":[{"atl":[[1.51,21.08],[1.49,0]],"id":9625043}],"con":true,"img":false}]}
{"op":"mcm","clk":"1349987109","pt":1588414707000,"mc":[{"id":"1.170370562","rc":[{"trd":[[1.43,68.11]],"ltp":1.43,"tv":68.11,"id":9625043},{"atb":[[1.43,54.59]],"id":9625043}],"con":true,"img":false}]}
{"op":"mcm","clk":"1349987115","pt":1588414707087,"mc":[{"id":"1.170370562","rc":[{"atl":[[1000,2]],"id":9631798}],"con":true,"img":false}]}
{"op":"mcm","clk":"1349987119","pt":1588414707190,"mc":[{"id":"1.170370562","rc":[{"atl":[[1000,4]],"id":9631798}],"con":true,"img":false}]}
{"op":"mcm","clk":"1349987122","pt":1588414707294,"mc":[{"id":"1.170370562","rc":[{"atl":[[1000,0.02]],"id":9631798}],"con":true,"img":false}]}
{"op":"mcm","clk":"1349987128","pt":1588414707499,"mc":[{"id":"1.170370562","rc":[{"atl":[[1000,2]],"id":9631798}],"con":true,"img":false}]}
{"op":"mcm","clk":"1349987135","pt":1588414707602,"mc":[{"id":"1.170370562","rc":[{"atl":[[3.9,0],[1000,0.01]],"id":9631798}],"con":true,"img":false}]}
{"op":"mcm","clk":"1349987143","pt":1588414707709,"mc":[{"id":"1.170370562","rc":[{"atl":[[1000,0]],"id":9631798}],"con":true,"img":false}]}
{"op":"mcm","clk":"1349987145","pt":1588414707759,"mc":[{"id":"1.170370562","rc":[{"atb":[[1.4,20.09]],"id":9625043}],"con":true,"img":false}]}
{"op":"mcm","clk":"1349987153","pt":1588414707965,"mc":[{"id":"1.170370562","rc":[{"atl":[[3.8,0.01],[3.5,5]],"id":9631798}],"con":true,"img":false}]}
{"op":"mcm","clk":"1349987161","pt":1588414708170,"mc":[{"id":"1.170370562","rc":[{"atl":[[3.75,0.01]],"id":9631798}],"con":true,"img":false}]}
{"op":"mcm","clk":"1349987163","pt":1588414708274,"mc":[{"id":"1.170370562","rc":[{"atb":[[1.4,139.77]],"id":9625043}],"con":true,"img":false}]}
{"op":"mcm","clk":"1349987167","pt":1588414708376,"mc":[{"id":"1.170370562","rc":[{"atl":[[3.6,0.01]],"id":9631798}],"con":true,"img":false}]}
{"op":"mcm","clk":"1349987176","pt":1588414708582,"mc":[{"id":"1.170370562","rc":[{"atl":[[1000,2]],"id":9631798}],"con":true,"img":false}]}
{"op":"mcm","clk":"1349987182","pt":1588414708788,"mc":[{"id":"1.170370562","rc":[{"atl":[[1.51,23.08]],"id":9625043},{"atl":[[3.6,0],[3.8,0],[3.5,5.01],[3.75,0],[1000,0]],"id":9631798}],"con":true,"img":false}]}
{"op":"mcm","clk":"1349987185","pt":1588414708891,"mc":[{"id":"1.170370562","rc":[{"atl":[[1000,2]],"id":9631798}],"con":true,"img":false}]}
{"op":"mcm","clk":"1349987188","pt":1588414708995,"mc":[{"id":"1.170370562","rc":[{"atl":[[3.4,0.01],[1000,4]],"id":9631798}],"con":true,"img":false}]}
{"op":"mcm","clk":"1349987190","pt":1588414709098,"mc":[{"id":"1.170370562","rc":[{"atl":[[1000,2.01]],"id":9631798}],"con":true,"img":false}]}
{"op":"mcm","clk":"1349987195","pt":1588414709200,"mc":[{"id":"1.170370562","rc":[{"atl":[[1000,0.02]],"id":9631798}],"con":true,"img":false}]}
{"op":"mcm","clk":"1349987201","pt":1588414709303,"mc":[{"id":"1.170370562","rc":[{"atl":[[3.3,0.01],[1000,2.01]],"id":9631798}],"con":true,"img":false}]}
{"op":"mcm","clk":"1349987205","pt":1588414709358,"mc":[{"id":"1.170370562","rc":[{"trd":[[1.45,401.37]],"ltp":1.45,"tv":401.37,"id":9625043},{"atl":[[1.45,219.62]],"id":9625043},{"trd":[[3.2,0.01]],"ltp":3.2,"tv":0.01,"id":9631798},{"atl":[[1000,2]],"id":9631798}],"con":true,"img":false}]}
{"op":"mcm","clk":"1349987208","pt":1588414709462,"mc":[{"id":"1.170370562","rc":[{"atl":[[3.5,0.01],[1000,2.01]],"id":9631798}],"con":true,"img":false}]}
{"op":"mcm","clk":"1349987217","pt":1588414709771,"mc":[{"id":"1.170370562","rc":[{"atl":[[1.48,241.73]],"id":9625043}],"con":true,"img":false}]}
{"op":"mcm","clk":"1349987219","pt":1588414709874,"mc":[{"id":"1.170370562","rc":[{"trd":[[1.43,108.11]],"ltp":1.43,"tv":108.11,"id":9625043},{"atb":[[1.43,34.59]],"id":9625043},{"atl":[[1000,0.01]],"id":9631798}],"con":true,"img":false}]}
{"op":"mcm","clk":"1349987225","pt":1588414710186,"mc":[{"id":"1.170370562","rc":[{"atl":[[1.48,259.46]],"id":9625043},{"atl":[[1000,2]],"id":9631798}],"con":true,"img":false}]}
{"op":"mcm","clk":"1349987227","pt":1588414710288,"mc":[{"id":"1.170370562","rc":[{"atl":[[3.85,0.01]],"id":9631798}],"con":true,"img":false}]}
{"op":"mcm","clk":"1349987230","pt":1588414710390,"mc":[{"id":"1.170370562","rc":[{"trd":[[1.43,119.22]],"ltp":1.43,"tv":119.22,"id":9625043},{"atb":[[1.43,23.48]],"id":9625043},{"trd":[[3.35,4.74],[3.3,0.02]],"ltp":3.35,"tv":4.76,"id":9631798},{"atl":[[3.3,0],[1000,0.01]],"id":9631798}],"con":true,"img":false}]}
{"op":"mcm","clk":"1349987235","pt":1588414710595,"mc":[{"id":"1.170370562","rc":[{"atb":[[3.1,900.3]],"id":9631798},{"atl":[[3.65,0.01],[1000,0]],"id":9631798}],"con":true,"img":false}]}
{"op":"mcm","clk":"1349987240","pt":1588414710801,"mc":[{"id":"1.170370562","rc":[{"atl":[[1.48,277.19]],"id":9625043},{"atl":[[3.5,3.74]],"id":9631798}],"con":true,"img":false}]}
{"op":"mcm","clk":"1349987242","pt":1588414710904,"mc":[{"id":"1.170370562","rc":[{"atl":[[3.35,0.01]],"id":9631798}],"con":true,"img":false}]}
{"op":"mcm","clk":"1349987273","pt":1588414711679,"mc":[{"id":"1.170370562","rc":[{"atl":[[1.46,586.78]],"id":9625043}],"con":true,"img":false}]}
{"op":"mcm","clk":"1349987291","pt":1588414712095,"mc":[{"id":"1.170370562","rc":[{"atl":[[1.89,0]],"id":9625043},{"atl":[[3.5,0.02]],"id":9631798}],"con":true,"img":false}]}
{"op":"mcm","clk":"1349987310","pt":1588414712560,"mc":[{"id":"1.170370562","rc":[{"atl":[[3.85,0.02],[3.7,0.01]],"id":9631798}],"con":true,"img":false}]}
{"op":"mcm","clk":"1349987314","pt":1588414712664,"mc":[{"id":"1.170370562","rc":[{"atl":[[1.44,208.04]],"id":9625043}],"con":true,"img":false}]}
{"op":"mcm","clk":"1349987319","pt":1588414712768,"mc":[{"id":"1.170370562","rc":[{"atl":[[3.6,0.01]],"id":9631798}],"con":true,"img":false}]}
{"op":"mcm","clk":"1349987325","pt":1588414712870,"mc":[{"id":"1.170370562","rc":[{"atb":[[1.4,1015.66]],"id":9625043}],"con":true,"img":false}]}
{"op":"mcm","clk":"1349987358","pt":1588414713804,"mc":[{"id":"1.170370562","rc":[{"atl":[[1.46,0]],"id":9625043}],"con":true,"img":false}]}
{"op":"mcm","clk":"1349987361","pt":1588414713909,"mc":[{"id":"1.170370562","rc":[{"atb":[[3.25,4.09]],"id":9631798}],"con":true,"img":false}]}
{"op":"mcm","clk":"1349987366","pt":1588414713961,"mc":[{"id":"1.170370562","rc":[{"trd":[[1.44,13.7]],"ltp":1.44,"tv":13.7,"id":9625043},{"atl":[[1.44,205.22]],"id":9625043}],"con":true,"img":false}]}
{"op":"mcm","clk":"1349987382","pt":1588414714373,"mc":[{"id":"1.170370562","rc":[{"atl":[[4.8,0.01]],"id":9631798}],"con":true,"img":false}]}
{"op":"mcm","clk":"1349987387","pt":1588414714476,"mc":[{"id":"1.170370562","rc":[{"atl":[[4.2,0.01]],"id":9631798}],"con":true,"img":false}]}
{"op":"mcm","clk":"1349987393","pt":1588414714683,"mc":[{"id":"1.170370562","rc":[{"trd":[[1.44,18.32]],"ltp":1.44,"tv":18.32,"id":9625043},{"atl":[[1.44,202.9]],"id":9625043}],"con":true,"img":false}]}
{"op":"mcm","clk":"1349987399","pt":1588414714785,"mc":[{"id":"1.170370562","rc":[{"atl":[[3.75,0.01]],"id":9631798}],"con":true,"img":false}]}
{"op":"mcm","clk":"1349987405","pt":1588414714991,"mc":[{"id":"1.170370562","rc":[{"atl":[[3.7,0.02]],"id":9631798}],"con":true,"img":false}]}
{"op":"mcm","clk":"1349987414","pt":1588414715299,"mc":[{"id":"1.170370562","rc":[{"atl":[[4.2,0.02]],"id":9631798}],"con":true,"img":false}]}
{"op":"mcm","clk":"1349987427","pt":1588414715661,"mc":[{"id":"1.170370562","rc":[{"atl":[[4.8,0.02]],"id":9631798}],"con":true,"img":false}]}
{"op":"mcm","clk":"1349987431","pt":1588414715764,"mc":[{"id":"1.170370562","rc":[{"atl":[[1.51,21.08]],"id":9625043}],"con":true,"img":false}]}
{"op":"mcm","clk":"1349987443","pt":1588414716281,"mc":[{"id":"1.170370562","rc":[{"atb":[[1.4,139.77]],"id":9625043}],"con":true,"img":false}]}
{"op":"mcm","clk":"1349987454","pt":1588414716591,"mc":[{"id":"1.170370562","rc":[{"trd":[[1.44,20.38]],"ltp":1.44,"tv":20.38,"id":9625043},{"atl":[[1.44,200.85]],"id":9625043},{"trd":[[3.25,10.34]],"ltp":3.25,"tv":10.34,"id":9631798},{"atb":[[3.25,0]],"id":9631798}],"con":true,"img":false}]}
{"op":"mcm","clk":"1349987459","pt":1588414716695,"mc":[{"id":"1.170370562","rc":[{"trd":[[1.44,55.41]],"ltp":1.44,"tv":55.41,"id":9625043},{"atl":[[1.44,183.33]],"id":9625043}],"con":true,"img":false}]}
{"op":"mcm","clk":"1349987476","pt":1588414717209,"mc":[{"id":"1.170370562","rc":[{"trd":[[1.44,82.5]],"ltp":1.44,"tv":82.5,"id":9625043},{"atl":[[1.44,156.25]],"id":9625043},{"trd":[[3.25,22.34]],"ltp":3.25,"tv":22.34,"id":9631798}],"con":true,"img":false}]}
{"op":"mcm","clk":"1349987527","pt":1588414718395,"mc":[{"id":"1.170370562","rc":[{"trd":[[1.44,83.2]],"ltp":1.44,"tv":83.2,"id":9625043},{"atl":[[1.44,155.89]],"id":9625043}],"con":true,"img":false}]}
{"op":"mcm","clk":"1349987534","pt":1588414718601,"mc":[{"id":"1.170370562","rc":[{"trd":[[1.44,153.23]],"ltp":1.44,"tv":153.23,"id":9625043},{"atl":[[1.44,85.86]],"id":9625043},{"trd":[[3.25,53.36]],"ltp":3.25,"tv":53.36,"id":9631798}],"con":true,"img":false}]}
{"op":"mcm","clk":"1349987545","pt":1588414718911,"mc":[{"id":"1.170370562","rc":[{"trd":[[1.43,166.19]],"ltp":1.43,"tv":166.19,"id":9625043},{"atb":[[1.43,0]],"id":9625043},{"atl":[[1.43,575.61]],"id":9625043}],"con":true,"img":false}]}
{"op":"mcm","clk":"1349987549","pt":1588414719066,"mc":[{"id":"1.170370562","rc":[{"atb":[[1.4,20.09]],"id":9625043},{"atl":[[1.48,53.19]],"id":9625043}],"con":true,"img":false}]}
{"op":"mcm","clk":"1349987559","pt":1588414719482,"mc":[{"id":"1.170370562","rc":[{"atl":[[1.43,687.61]],"id":9625043}],"con":true,"img":false}]}
{"op":"mcm","clk":"1349987567","pt":1588414719792,"mc":[{"id":"1.170370562","rc":[{"trd":[[1.43,173.19]],"ltp":1.43,"tv":173.19,"id":9625043},{"atl":[[1.43,684.11]],"id":9625043},{"atl":[[4.8,0],[3.6,0],[3.85,0],[3.35,0],[3.7,0],[3.4,0],[3.5,0],[4.2,0],[3.65,0],[3.75,0]],"id":9631798}],"con":true,"img":false}]}
{"op":"mcm","clk":"1349987575","pt":1588414720203,"mc":[{"id":"1.170370562","rc":[{"trd":[[1.43,173.87]],"ltp":1.43,"tv":173.87,"id":9625043},{"atl":[[1.43,683.77]],"id":9625043}],"con":true,"img":false}]}
{"op":"mcm","clk":"1349987597","pt":1588414721081,"mc":[{"id":"1.170370562","rc":[{"atl":[[1000,2]],"id":9631798}],"con":true,"img":false}]}
{"op":"mcm","clk":"1349987600","pt":1588414721186,"mc":[{"id":"1.170370562","rc":[{"atb":[[1.4,2.57]],"id":9625043}],"con":true,"img":false}]}
{"op":"mcm","clk":"1349987604","pt":1588414721289,"mc":[{"id":"1.170370562","rc":[{"atl":[[1000,2.01]],"id":9631798}],"con":true,"img":false}]}
{"op":"mcm","clk":"1349987610","pt":1588414721496,"mc":[{"id":"1.170370562","rc":[{"atl":[[1000,2.02]],"id":9631798}],"con":true,"img":false}]}
{"op":"mcm","clk":"1349987613","pt":1588414721599,"mc":[{"id":"1.170370562","rc":[{"atl":[[1000,2.01]],"id":9631798}],"con":true,"img":false}]}
{"op":"mcm","clk":"1349987616","pt":1588414721701,"mc":[{"id":"1.170370562","rc":[{"atl":[[1000,0.01]],"id":9631798}],"con":true,"img":false}]}
{"op":"mcm","clk":"1349987620","pt":1588414721804,"mc":[{"id":"1.170370562","rc":[{"atl":[[1.44,0]],"id":9625043},{"atl":[[1000,0]],"id":9631798}],"con":true,"img":false}]}
{"op":"mcm","clk":"1349987623","pt":1588414721909,"mc":[{"id":"1.170370562","rc":[{"atl":[[1000,2]],"id":9631798}],"con":true,"img":false}]}
{"op":"mcm","clk":"1349987630","pt":1588414722115,"mc":[{"id":"1.170370562","rc":[{"atl":[[1000,0.01]],"id":9631798}],"con":true,"img":false}]}
{"op":"mcm","clk":"1349987632","pt":1588414722219,"mc":[{"id":"1.170370562","rc":[{"atl":[[1000,2.01]],"id":9631798}],"con":true,"img":false}]}
{"op":"mcm","clk":"1349987636","pt":1588414722272,"mc":[{"id":"1.170370562","rc":[{"atl":[[1000,0.01]],"id":9631798}],"con":true,"img":false}]}
{"op":"mcm","clk":"1349987641","pt":1588414722378,"mc":[{"id":"1.170370562","rc":[{"atl":[[1000,2.01]],"id":9631798}],"con":true,"img":false}]}
{"op":"mcm","clk":"1349987646","pt":1588414722482,"mc":[{"id":"1.170370562","rc":[{"atl":[[1.51,20.97]],"id":9625043},{"atl":[[1000,2]],"id":9631798}],"con":true,"img":false}]}
{"op":"mcm","clk":"1349987650","pt":1588414722587,"mc":[{"id":"1.170370562","rc":[{"trd":[[1.43,177.99]],"ltp":1.43,"tv":177.99,"id":9625043},{"atl":[[1.43,681.71]],"id":9625043},{"atl":[[1000,0.01]],"id":9631798}],"con":true,"img":false}]}
{"op":"mcm","clk":"1349987659","pt":1588414722794,"mc":[{"id":"1.170370562","rc":[{"atb":[[1.34,0]],"id":9625043},{"atl":[[1.43,793.71]],"id":9625043}],"con":true,"img":false}]}
{"op":"mcm","clk":"1349987663","pt":1588414722899,"mc":[{"id":"1.170370562","rc":[{"atl":[[1000,0]],"id":9631798}],"con":true,"img":false}]}
{"op":"mcm","clk":"1349987668","pt":1588414723001,"mc":[{"id":"1.170370562","rc":[{"atl":[[1.47,301.78]],"id":9625043}],"con":true,"img":false}]}
{"op":"mcm","clk":"1349987676","pt":1588414723207,"mc":[{"id":"1.170370562","rc":[{"atl":[[1.47,381.57]],"id":9625043}],"con":true,"img":false}]}
{"op":"mcm","clk":"1349987681","pt":1588414723310,"mc":[{"id":"1.170370562","rc":[{"atl":[[1.47,461.36]],"id":9625043}],"con":true,"img":false}]}
{"op":"mcm","clk":"1349987712","pt":1588414724188,"mc":[{"id":"1.170370562","rc":[{"trd":[[1.43,417.36]],"ltp":1.43,"tv":417.36,"id":9625043},{"atl":[[1.43,674.03]],"id":9625043}],"con":true,"img":false}]}
{"op":"mcm","clk":"1349987741","pt":1588414724808,"mc":[{"id":"1.170370562","rc":[{"atl":[[1.45,0]],"id":9625043}],"con":true,"img":false}]}
{"op":"mcm","clk":"1349987744","pt":1588414724911,"mc":[{"id":"1.170370562","rc":[{"trd":[[1.43,417.45]],"ltp":1.43,"tv":417.45,"id":9625043},{"atl":[[1.43,673.98]],"id":9625043}],"con":true,"img":false}]}
{"op":"mcm","clk":"1349987753","pt":1588414725117,"mc":[{"id":"1.170370562","rc":[{"atb":[[1.4,5.41]],"id":9625043}],"con":true,"img":false}]}
{"op":"mcm","clk":"1349987779","pt":1588414725634,"mc":[{"id":"1.170370562","rc":[{"trd":[[1.42,106.38]],"ltp":1.42,"tv":106.38,"id":9625043},{"atb":[[1.42,0]],"id":9625043},{"atl":[[1.42,168.81]],"id":9625043}],"con":true,"img":false}]}
{"op":"mcm","clk":"1349987785","pt":1588414725787,"mc":[{"id":"1.170370562","rc":[{"atl":[[1.42,280.81]],"id":9625043}],"con":true,"img":false}]}
{"op":"mcm","clk":"1349987810","pt":1588414726422,"mc":[{"id":"1.170370562","rc":[{"atl":[[1.42,392.81]],"id":9625043}],"con":true,"img":false}]}
{"op":"mcm","clk":"1349987820","pt":1588414726681,"mc":[{"id":"1.170370562","rc":[{"atb":[[1.31,79.78]],"id":9625043},{"atl":[[3.95,0.01]],"id":9631798}],"con":true,"img":false}]}
{"op":"mcm","clk":"1349987823","pt":1588414726787,"mc":[{"id":"1.170370562","rc":[{"atl":[[1.43,675.75]],"id":9625043},{"atl":[[3.6,0.01]],"id":9631798}],"con":true,"img":false}]}
{"op":"mcm","clk":"1349987827","pt":1588414726888,"mc":[{"id":"1.170370562","rc":[{"trd":[[1.42,107.86]],"ltp":1.42,"tv":107.86,"id":9625043},{"atb":[[1.31,159.57]],"id":9625043},{"atl":[[1.42,392.07]],"id":9625043},{"atl":[[3.45,0.01]],"id":9631798}],"con":true,"img":false}]}
{"op":"mcm","clk":"1349987831","pt":1588414726991,"mc":[{"id":"1.170370562","rc":[{"atb":[[1.31,239.36]],"id":9625043}],"con":true,"img":false}]}
{"op":"mcm","clk":"1349987846","pt":1588414727405,"mc":[{"id":"1.170370562","rc":[{"trd":[[1.42,107.88]],"ltp":1.42,"tv":107.88,"id":9625043},{"atl":[[1.42,392.05]],"id":9625043},{"trd":[[3.35,4.75]],"ltp":3.35,"tv":4.75,"id":9631798}],"con":true,"img":false}]}
{"op":"mcm","clk":"1349987855","pt":1588414727612,"mc":[{"id":"1.170370562","rc":[{"atl":[[3.7,0.01]],"id":9631798}],"con":true,"img":false}]}
{"op":"mcm","clk":"1349987860","pt":1588414727715,"mc":[{"id":"1.170370562","rc":[{"atl":[[1.42,479.13]],"id":9625043}],"con":true,"img":false}]}
{"op":"mcm","clk":"1349987862","pt":1588414727820,"mc":[{"id":"1.170370562","rc":[{"atl":[[1.51,0.74]],"id":9625043}],"con":true,"img":false}]}
{"op":"mcm","clk":"1349987867","pt":1588414727922,"mc":[{"id":"1.170370562","rc":[{"trd":[[1.42,363.2]],"ltp":1.42,"tv":363.2,"id":9625043},{"atl":[[1.42,351.47]],"id":9625043},{"atb":[[3.1,0]],"id":9631798}],"con":true,"img":false}]}
{"op":"mcm","clk":"1349987872","pt":1588414728027,"mc":[{"id":"1.170370562","rc":[{"atl":[[4.1,0.01]],"id":9631798}],"con":true,"img":false}]}
{"op":"mcm","clk":"1349987877","pt":1588414728129,"mc":[{"id":"1.170370562","rc":[{"atl":[[1.43,451.75]],"id":9625043}],"con":true,"img":false}]}
{"op":"mcm","clk":"1349987901","pt":1588414728697,"mc":[{"id":"1.170370562","rc":[{"atl":[[1.42,264.39]],"id":9625043}],"con":true,"img":false}]}
{"op":"mcm","clk":"1349987945","pt":1588414729892,"mc":[{"id":"1.170370562","rc":[{"trd":[[1.42,503.15]],"ltp":1.42,"tv":503.15,"id":9625043},{"atl":[[1.42,194.41]],"id":9625043}],"con":true,"img":false}]}
{"op":"mcm","clk":"1349987959","pt":1588414730413,"mc":[{"id":"1.170370562","rc":[{"atl":[[1.43,453.75]],"id":9625043}],"con":true,"img":false}]}
{"op":"mcm","clk":"1349988044","pt":1588414732743,"mc":[{"id":"1.170370562","rc":[{"atl":[[1.54,0]],"id":9625043}],"con":true,"img":false}]}
{"op":"mcm","clk":"1349988048","pt":1588414732795,"mc":[{"id":"1.170370562","rc":[{"trd":[[1.42,513.14]],"ltp":1.42,"tv":513.14,"id":9625043},{"atl":[[1.42,184.42]],"id":9625043},{"trd":[[3.35,8.98]],"ltp":3.35,"tv":8.98,"id":9631798}],"con":true,"img":false}]}
{"op":"mcm","clk":"1349988052","pt":1588414732898,"mc":[{"id":"1.170370562","rc":[{"atb":[[1.41,11.35]],"id":9625043}],"con":true,"img":false}]}
{"op":"mcm","clk":"1349988068","pt":1588414733413,"mc":[{"id":"1.170370562","rc":[{"trd":[[1.42,548.18]],"ltp":1.42,"tv":548.18,"id":9625043},{"atl":[[1.42,166.9],[1.52,0]],"id":9625043}],"con":true,"img":false}]}
{"op":"mcm","clk":"1349988071","pt":1588414733519,"mc":[{"id":"1.170370562","rc":[{"atl":[[1.47,222]],"id":9625043}],"con":true,"img":false}]}
{"op":"mcm","clk":"1349988088","pt":1588414734034,"mc":[{"id":"1.170370562","rc":[{"atl":[[1.47,0]],"id":9625043}],"con":true,"img":false}]}
{"op":"mcm","clk":"1349988096","pt":1588414734343,"mc":[{"id":"1.170370562","rc":[{"atl":[[1.43,451.75]],"id":9625043}],"con":true,"img":false}]}
{"op":"mcm","clk":"1349988103","pt":1588414734547,"mc":[{"id":"1.170370562","rc":[{"atb":[[1.33,0]],"id":9625043}],"con":true,"img":false}]}
{"op":"mcm","clk":"1349988107","pt":1588414734599,"mc":[{"id":"1.170370562","rc":[{"trd":[[1.41,26.73]],"ltp":1.41,"tv":26.73,"id":9625043},{"atb":[[1.41,0]],"id":9625043},{"atl":[[1.45,112],[1.41,76.34]],"id":9625043}],"con":true,"img":false}]}
{"op":"mcm","clk":"1349988111","pt":1588414734704,"mc":[{"id":"1.170370562","rc":[{"atl":[[1.43,449.98]],"id":9625043}],"con":true,"img":false}]}
{"op":"mcm","clk":"1349988123","pt":1588414735220,"mc":[{"id":"1.170370562","rc":[{"atl":[[1.46,112]],"id":9625043}],"con":true,"img":false}]}
{"op":"mcm","clk":"1349988129","pt":1588414735424,"mc":[{"id":"1.170370562","rc":[{"atb":[[1.31,0]],"id":9625043}],"con":true,"img":false}]}
{"op":"mcm","clk":"1349988181","pt":1588414737030,"mc":[{"id":"1.170370562","rc":[{"trd":[[1.41,29.82]],"ltp":1.41,"tv":29.82,"id":9625043},{"atl":[[1.41,74.8]],"id":9625043}],"con":true,"img":false}]}
{"op":"mcm","clk":"1349988201","pt":1588414737749,"mc":[{"id":"1.170370562","rc":[{"trd":[[1.41,34.98]],"ltp":1.41,"tv":34.98,"id":9625043},{"atl":[[1.41,72.22]],"id":9625043}],"con":true,"img":false}]}
{"op":"mcm","clk":"1349988228","pt":1588414738831,"mc":[{"id":"1.170370562","rc":[{"trd":[[1.41,43.84]],"ltp":1.41,"tv":43.84,"id":9625043},{"atl":[[1.41,67.79]],"id":9625043}],"con":true,"img":false}]}
{"op":"mcm","clk":"1349988235","pt":1588414739138,"mc":[{"id":"1.170370562","rc":[{"atl":[[1.46,334]],"id":9625043},{"atl":[[3.45,0],[3.6,0],[3.95,0],[4.1,0],[3.7,0]],"id":9631798}],"con":true,"img":false}]}
{"op":"mcm","clk":"1349988261","pt":1588414739806,"mc":[{"id":"1.170370562","rc":[{"trd":[[1.4,3173.36]],"ltp":1.4,"tv":3173.36,"id":9625043},{"atb":[[1.4,3.64]],"id":9625043}],"con":true,"img":false}]}
{"op":"mcm","clk":"1349988266","pt":1588414740012,"mc":[{"id":"1.170370562","rc":[{"atl":[[1.43,0]],"id":9625043}],"con":true,"img":false}]}
{"op":"mcm","clk":"1349988273","pt":1588414740221,"mc":[{"id":"1.170370562","rc":[{"trd":[[1.41,49]],"ltp":1.41,"tv":49.0,"id":9625043},{"atl":[[1.41,65.21]],"id":9625043}],"con":true,"img":false}]}
{"op":"mcm","clk":"1349988317","pt":1588414741629,"mc":[{"id":"1.170370562","rc":[{"atl":[[1.45,0]],"id":9625043},{"atb":[[1.01,1090.13]],"id":9631798}],"con":true,"img":false}]}
{"op":"mcm","clk":"1349988322","pt":1588414741734,"mc":[{"id":"1.170370562","rc":[{"trd":[[1.41,49.85]],"ltp":1.41,"tv":49.85,"id":9625043},{"atl":[[1.41,64.78]],"id":9625043}],"con":true,"img":false}]}
{"op":"mcm","clk":"1349988326","pt":1588414741839,"mc":[{"id":"1.170370562","rc":[{"atb":[[1.01,1088.14]],"id":9631798}],"con":true,"img":false}]}
{"op":"mcm","clk":"1349988329","pt":1588414741943,"mc":[{"id":"1.170370562","rc":[{"atb":[[1.01,1090.14]],"id":9631798}],"con":true,"img":false}]}
{"op":"mcm","clk":"1349988331","pt":1588414742048,"mc":[{"id":"1.170370562","rc":[{"atb":[[1.01,1090.13]],"id":9631798}],"con":true,"img":false}]}
{"op":"mcm","clk":"1349988334","pt":1588414742153,"mc":[{"id":"1.170370562","rc":[{"atb":[[1.01,1090.14]],"id":9631798}],"con":true,"img":false}]}
{"op":"mcm","clk":"1349988337","pt":1588414742205,"mc":[{"id":"1.170370562","rc":[{"atb":[[1.01,1092.14]],"id":9631798}],"con":true,"img":false}]}
{"op":"mcm","clk":"1349988339","pt":1588414742317,"mc":[{"id":"1.170370562","rc":[{"atb":[[1.01,1090.14]],"id":9631798}],"con":true,"img":false}]}
{"op":"mcm","clk":"1349988344","pt":1588414742415,"mc":[{"id":"1.170370562","rc":[{"atb":[[1.01,1088.14]],"id":9631798}],"con":true,"img":false}]}
{"op":"mcm","clk":"1349988346","pt":1588414742519,"mc":[{"id":"1.170370562","rc":[{"atb":[[1.01,1088.13]],"id":9631798}],"con":true,"img":false}]}
{"op":"mcm","clk":"1349988351","pt":1588414742623,"mc":[{"id":"1.170370562","rc":[{"trd":[[1.41,74.11]],"ltp":1.41,"tv":74.11,"id":9625043},{"atl":[[1.41,52.65]],"id":9625043},{"atb":[[1.01,1090.13]],"id":9631798}],"con":true,"img":false}]}
{"op":"mcm","clk":"1349988360","pt":1588414742833,"mc":[{"id":"1.170370562","rc":[{"atb":[[1.01,1088.14]],"id":9631798}],"con":true,"img":false}]}
{"op":"mcm","clk":"1349988366","pt":1588414743043,"mc":[{"id":"1.170370562","rc":[{"atb":[[1.01,1088.13]],"id":9631798}],"con":true,"img":false}]}
{"op":"mcm","clk":"1349988393","pt":1588414743721,"mc":[{"id":"1.170370562","rc":[{"trd":[[1.41,142.8]],"ltp":1.41,"tv":142.8,"id":9625043},{"atl":[[1.41,18.31]],"id":9625043}],"con":true,"img":false}]}
{"op":"mcm","clk":"1349988397","pt":1588414743824,"mc":[{"id":"1.170370562","rc":[{"atl":[[1.42,278.9]],"id":9625043}],"con":true,"img":false}]}
{"op":"mcm","clk":"1349988413","pt":1588414744445,"mc":[{"id":"1.170370562","rc":[{"trd":[[1.41,147.51]],"ltp":1.41,"tv":147.51,"id":9625043},{"atl":[[1.41,15.95]],"id":9625043}],"con":true,"img":false}]}
{"op":"mcm","clk":"1349988424","pt":1588414744652,"mc":[{"id":"1.170370562","rc":[{"trd":[[1.41,170.65]],"ltp":1.41,"tv":170.65,"id":9625043},{"atb":[[1.38,0.16]],"id":9625043},{"atl":[[1.41,4.38]],"id":9625043}],"con":true,"img":false}]}
{"op":"mcm","clk":"1349988441","pt":1588414745122,"mc":[{"id":"1.170370562","rc":[{"trd":[[1.4,3180.64]],"ltp":1.4,"tv":3180.64,"id":9625043},{"atb":[[1.4,0]],"id":9625043},{"atl":[[1.39,459.29]],"id":9625043}],"con":true,"img":false}]}
{"op":"mcm","clk":"1349988453","pt":1588414745534,"mc":[{"id":"1.170370562","rc":[{"atb":[[1.01,1090.13]],"id":9631798}],"con":true,"img":false}]}
{"op":"mcm","clk":"1349988459","pt":1588414745740,"mc":[{"id":"1.170370562","rc":[{"atb":[[1.01,1088.14]],"id":9631798}],"con":true,"img":false}]}
{"op":"mcm","clk":"1349988465","pt":1588414745946,"mc":[{"id":"1.170370562","rc":[{"atb":[[1.01,1088.13]],"id":9631798}],"con":true,"img":false}]}
{"op":"mcm","clk":"1349988477","pt":1588414746520,"mc":[{"id":"1.170370562","rc":[{"trd":[[1.39,5.21]],"ltp":1.39,"tv":5.21,"id":9625043},{"atl":[[1.39,456.68]],"id":9625043}],"con":true,"img":false}]}
{"op":"mcm","clk":"1349988487","pt":1588414746936,"mc":[{"id":"1.170370562","rc":[{"atl":[[1.41,0]],"id":9625043}],"con":true,"img":false}]}
{"op":"mcm","clk":"1349988492","pt":1588414747142,"mc":[{"id":"1.170370562","rc":[{"atb":[[2.98,0.01]],"id":9631798}],"con":true,"img":false}]}
{"op":"mcm","clk":"1349988498","pt":1588414747448,"mc":[{"id":"1.170370562","rc":[{"atb":[[2.92,0.01]],"id":9631798}],"con":true,"img":false}]}
{"op":"mcm","clk":"1349988505","pt":1588414747656,"mc":[{"id":"1.170370562","rc":[{"atb":[[2.84,0.01]],"id":9631798}],"con":true,"img":false}]}
{"op":"mcm","clk":"1349988519","pt":1588414748170,"mc":[{"id":"1.170370562","rc":[{"trd":[[1.39,12.21]],"ltp":1.39,"tv":12.21,"id":9625043},{"atl":[[1.39,453.18]],"id":9625043},{"atb":[[2.9,0.01]],"id":9631798}],"con":true,"img":false}]}
{"op":"mcm","clk":"1349988528","pt":1588414748530,"mc":[{"id":"1.170370562","rc":[{"atl":[[1.41,222]],"id":9625043}],"con":true,"img":false}]}
{"op":"mcm","clk":"1349988547","pt":1588414749252,"mc":[{"id":"1.170370562","rc":[{"atl":[[4.3,17]],"id":9631798}],"con":true,"img":false}]}
{"op":"mcm","clk":"1349988557","pt":1588414749766,"mc":[{"id":"1.170370562","rc":[{"atl":[[1.41,0]],"id":9625043}],"con":true,"img":false}]}
{"op":"mcm","clk":"1349988578","pt":1588414750645,"mc":[{"id":"1.170370562","rc":[{"atl":[[1.4,2.57]],"id":9625043}],"con":true,"img":false}]}
{"op":"mcm","clk":"1349988591","pt":1588414751060,"mc":[{"id":"1.170370562","rc":[{"trd":[[1.39,18.21]],"ltp":1.39,"tv":18.21,"id":9625043},{"atl":[[1.39,450.18]],"id":9625043},{"atb":[[2.88,0.01]],"id":9631798}],"con":true,"img":false}]}
{"op":"mcm","clk":"1349988597","pt":1588414751265,"mc":[{"id":"1.170370562","rc":[{"atl":[[1.4,27.8],[1.41,2]],"id":9625043}],"con":true,"img":false}]}
{"op":"mcm","clk":"1349988627","pt":1588414752147,"mc":[{"id":"1.170370562","rc":[{"trd":[[1.38,0.32]],"ltp":1.38,"tv":0.32,"id":9625043},{"atb":[[1.38,0]],"id":9625043},{"atl":[[1.38,111.84]],"id":9625043}],"con":true,"img":false}]}
{"op":"mcm","clk":"1349988650","pt":1588414753027,"mc":[{"id":"1.170370562","rc":[{"atl":[[1.4,32.04]],"id":9625043}],"con":true,"img":false}]}
{"op":"mcm","clk":"1349988672","pt":1588414753856,"mc":[{"id":"1.170370562","rc":[{"trd":[[1.38,12.14]],"ltp":1.38,"tv":12.14,"id":9625043},{"atl":[[1.38,105.93]],"id":9625043}],"con":true,"img":false}]}
{"op":"mcm","clk":"1349988678","pt":1588414754061,"mc":[{"id":"1.170370562","rc":[{"trd":[[1.39,160.95],[1.38,224]],"ltp":1.39,"tv":384.95,"id":9625043},{"atl":[[1.39,378.81],[1.38,0]],"id":9625043}],"con":true,"img":false}]}
{"op":"mcm","clk":"1349988683","pt":1588414754164,"mc":[{"id":"1.170370562","rc":[{"atb":[[1.35,500]],"id":9625043}],"con":true,"img":false}]}
{"op":"mcm","clk":"1349988699","pt":1588414754627,"mc":[{"id":"1.170370562","rc":[{"trd":[[1.39,166.11]],"ltp":1.39,"tv":166.11,"id":9625043},{"atl":[[1.39,376.23]],"id":9625043}],"con":true,"img":false}]}
{"op":"mcm","clk":"1349988717","pt":1588414755248,"mc":[{"id":"1.170370562","rc":[{"trd":[[1.39,166.57]],"ltp":1.39,"tv":166.57,"id":9625043},{"atl":[[1.39,376]],"id":9625043}],"con":true,"img":false}]}
{"op":"mcm","clk":"1349988732","pt":1588414755659,"mc":[{"id":"1.170370562","rc":[{"trd":[[1.39,171.68]],"ltp":1.39,"tv":171.68,"id":9625043},{"atl":[[1.39,370.89]],"id":9625043},{"trd":[[3.55,2]],"ltp":3.55,"tv":2.0,"id":9631798}],"con":true,"img":false}]}
{"op":"mcm","clk":"1349988750","pt":1588414756279,"mc":[{"id":"1.170370562","rc":[{"trd":[[1.39,185.49]],"ltp":1.39,"tv":185.49,"id":9625043},{"atl":[[1.39,357.08]],"id":9625043},{"trd":[[3.55,7.4]],"ltp":3.55,"tv":7.4,"id":9631798}],"con":true,"img":false}]}
{"op":"mcm","clk":"1349988755","pt":1588414756380,"mc":[{"id":"1.170370562","rc":[{"trd":[[1.39,571.31]],"ltp":1.39,"tv":571.31,"id":9625043},{"atl":[[1.39,157.43]],"id":9625043},{"trd":[[3.55,12.68]],"ltp":3.55,"tv":12.68,"id":9631798}],"con":true,"img":false}]}
{"op":"mcm","clk":"1349988778","pt":1588414757051,"mc":[{"id":"1.170370562","rc":[{"atl":[[1.39,0]],"id":9625043}],"con":true,"img":false}]}
{"op":"mcm","clk":"1349988786","pt":1588414757360,"mc":[{"id":"1.170370562","rc":[{"atl":[[1.38,4.48]],"id":9625043}],"con":true,"img":false}]}
{"op":"mcm","clk":"1349988809","pt":1588414757980,"mc":[{"id":"1.170370562","rc":[{"trd":[[1.35,4.1]],"ltp":1.35,"tv":4.1,"id":9625043},{"atb":[[1.35,495.9]],"id":9625043},{"trd":[[3.9,1.41]],"ltp":3.9,"tv":1.41,"id":9631798}],"con":true,"img":false}]}
{"op":"mcm","clk":"1349988830","pt":1588414758655,"mc":[{"id":"1.170370562","rc":[{"atl":[[1.48,0]],"id":9625043}],"con":true,"img":false}]}
{"op":"mcm","clk":"1349988841","pt":1588414758960,"mc":[{"id":"1.170370562","rc":[{"atl":[[1.46,222],[1.42,0]],"id":9625043}],"con":true,"img":false}]}
{"op":"mcm","clk":"1349988848","pt":1588414759168,"mc":[{"id":"1.170370562","rc":[{"atl":[[1.46,0]],"id":9625043}],"con":true,"img":false}]}
{"op":"mcm","clk":"1349988892","pt":1588414760357,"mc":[{"id":"1.170370562","rc":[{"atb":[[1.31,0.23]],"id":9625043}],"con":true,"img":false}]}
{"op":"mcm","clk":"1349988909","pt":1588414760874,"mc":[{"id":"1.170370562","rc":[{"atl":[[4.3,0]],"id":9631798}],"con":true,"img":false}]}
{"op":"mcm","clk":"1349988938","pt":1588414761648,"mc":[{"id":"1.170370562","rc":[{"atb":[[1.35,500.96]],"id":9625043}],"con":true,"img":false}]}
{"op":"mcm","clk":"1349988944","pt":1588414761751,"mc":[{"id":"1.170370562","rc":[{"atb":[[2.12,0]],"id":9631798}],"con":true,"img":false}]}
{"op":"mcm","clk":"1349988967","pt":1588414762379,"mc":[{"id":"1.170370562","rc":[{"trd":[[1.3,2354.1],[1.31,0.47],[1.35,1006.02]],"ltp":1.3,"tv":3360.59,"id":9625043},{"atb":[[1.3,0],[1.31,0],[1.35,0]],"id":9625043},{"atl":[[1.3,384.02]],"id":9625043}],"con":true,"img":false}]}
{"op":"mcm","clk":"1349988978","pt":1588414762795,"mc":[{"id":"1.170370562","rc":[{"trd":[[1.41,174.65],[1.4,3244.73],[1.3,3122.16],[1.38,232.98]],"ltp":1.41,"tv":6774.51,"id":9625043},{"atb":[[1.41,577.43]],"id":9625043},{"atl":[[1.4,0],[1.41,0],[1.3,0],[1.38,0]],"id":9625043}],"con":true,"img":false}]}
{"op":"mcm","clk":"1349988981","pt":1588414762847,"mc":[{"id":"1.170370562","rc":[{"atb":[[1.44,360.74],[1.42,360.74]],"id":9625043}],"con":true,"img":false}]}
{"op":"mcm","clk":"1349988986","pt":1588414763052,"mc":[{"id":"1.170370562","rc":[{"atb":[[1.42,1360.74]],"id":9625043}],"con":true,"img":false}]}
{"op":"mcm","clk":"1349988992","pt":1588414763258,"mc":[{"id":"1.170370562","rc":[{"atb":[[1.42,2852.76]],"id":9625043}],"con":true,"img":false}]}
{"op":"mcm","clk":"1349989011","pt":1588414763982,"mc":[{"id":"1.170370562","rc":[{"trd":[[1.44,154.82]],"ltp":1.44,"tv":154.82,"id":9625043},{"atb":[[1.44,359.95]],"id":9625043},{"atl":[[3.55,0.79]],"id":9631798}],"con":true,"img":false}]}
{"op":"mcm","clk":"1349989058","pt":1588414765584,"mc":[{"id":"1.170370562","rc":[{"atb":[[1.41,1077.43]],"id":9625043}],"con":true,"img":false}]}
{"op":"mcm","clk":"1349989068","pt":1588414765793,"mc":[{"id":"1.170370562","rc":[{"trd":[[1.44,194.81]],"ltp":1.44,"tv":194.81,"id":9625043},{"atb":[[1.44,339.95]],"id":9625043},{"atl":[[1.49,222]],"id":9625043}],"con":true,"img":false}]}
{"op":"mcm","clk":"1349989077","pt":1588414765998,"mc":[{"id":"1.170370562","rc":[{"trd":[[1.44,500.81]],"ltp":1.44,"tv":500.81,"id":9625043},{"atb":[[1.44,186.95]],"id":9625043},{"atl":[[1.53,112]],"id":9625043}],"con":true,"img":false}]}
{"op":"mcm","clk":"1349989085","pt":1588414766156,"mc":[{"id":"1.170370562","rc":[{"atl":[[3.8,17]],"id":9631798}],"con":true,"img":false}]}
{"op":"mcm","clk":"1349989095","pt":1588414766363,"mc":[{"id":"1.170370562","rc":[{"atl":[[1.53,334]],"id":9625043}],"con":true,"img":false}]}
{"op":"mcm","clk":"1349989099","pt":1588414766466,"mc":[{"id":"1.170370562","rc":[{"atb":[[1.41,577.43]],"id":9625043},{"atl":[[1.55,200.65]],"id":9625043}],"con":true,"img":false}]}
{"op":"mcm","clk":"1349989105","pt":1588414766669,"mc":[{"id":"1.170370562","rc":[{"atl":[[3.45,84.36]],"id":9631798}],"con":true,"img":false}]}
{"op":"mcm","clk":"1349989120","pt":1588414767200,"mc":[{"id":"1.170370562","rc":[{"atb":[[1.22,8.05]],"id":9625043}],"con":true,"img":false}]}
{"op":"mcm","clk":"1349989133","pt":1588414767497,"mc":[{"id":"1.170370562","rc":[{"atb":[[1.38,0.47]],"id":9625043}],"con":true,"img":false}]}
{"op":"mcm","clk":"1349989140","pt":1588414767759,"mc":[{"id":"1.170370562","rc":[{"atb":[[1.41,0],[1.42,852.76]],"id":9625043},{"atb":[[1.92,228.72]],"id":9631798}],"con":true,"img":false}]}
{"op":"mcm","clk":"1349989146","pt":1588414767964,"mc":[{"id":"1.170370562","rc":[{"atb":[[1.39,0.91]],"id":9625043}],"con":true,"img":false}]}
{"op":"mcm","clk":"1349989152","pt":1588414768170,"mc":[{"id":"1.170370562","rc":[{"atl":[[3.8,0]],"id":9631798}],"con":true,"img":false}]}
{"op":"mcm","clk":"1349989155","pt":1588414768376,"mc":[{"id":"1.170370562","rc":[{"atb":[[1.38,1.06]],"id":9625043}],"con":true,"img":false}]}
{"op":"mcm","clk":"1349989165","pt":1588414768990,"mc":[{"id":"1.170370562","rc":[{"atb":[[1.46,48.24]],"id":9625043}],"con":true,"img":false}]}
{"op":"mcm","clk":"1349989171","pt":1588414769195,"mc":[{"id":"1.170370562","rc":[{"atb":[[1.11,16.11]],"id":9625043}],"con":true,"img":false}]}
{"op":"mcm","clk":"1349989177","pt":1588414769400,"mc":[{"id":"1.170370562","rc":[{"atb":[[1.39,13.83]],"id":9625043}],"con":true,"img":false}]}
{"op":"mcm","clk":"1349989194","pt":1588414769971,"mc":[{"id":"1.170370562","rc":[{"atb":[[1.35,20.99]],"id":9625043}],"con":true,"img":false}]}
{"op":"mcm","clk":"1349989199","pt":1588414770073,"mc":[{"id":"1.170370562","rc":[{"trd":[[1.46,96.49]],"ltp":1.46,"tv":96.49,"id":9625043},{"atb":[[1.46,0]],"id":9625043},{"atl":[[1.45,173.75]],"id":9625043}],"con":true,"img":false}]}
{"op":"mcm","clk":"1349989203","pt":1588414770178,"mc":[{"id":"1.170370562","rc":[{"atb":[[1.39,0.91]],"id":9625043}],"con":true,"img":false}]}
{"op":"mcm","clk":"1349989222","pt":1588414771061,"mc":[{"id":"1.170370562","rc":[{"atb":[[1.39,1.81]],"id":9625043}],"con":true,"img":false}]}
{"op":"mcm","clk":"1349989239","pt":1588414771787,"mc":[{"id":"1.170370562","rc":[{"atb":[[1.38,3.63]],"id":9625043}],"con":true,"img":false}]}
{"op":"mcm","clk":"1349989244","pt":1588414771891,"mc":[{"id":"1.170370562","rc":[{"atb":[[1.38,3.05]],"id":9625043},{"atl":[[1.62,177.3],[1.51,112.74]],"id":9625043}],"con":true,"img":false}]}
{"op":"mcm","clk":"1349989259","pt":1588414772302,"mc":[{"id":"1.170370562","rc":[{"atl":[[4.2,17]],"id":9631798}],"con":true,"img":false}]}
{"op":"mcm","clk":"1349989297","pt":1588414773490,"mc":[{"id":"1.170370562","rc":[{"trd":[[1.44,610.81]],"ltp":1.44,"tv":610.81,"id":9625043},{"atb":[[1.44,131.95]],"id":9625043}],"con":true,"img":false}]}
{"op":"mcm","clk":"1349989319","pt":1588414774063,"mc":[{"id":"1.170370562","rc":[{"trd":[[1.44,720.81]],"ltp":1.44,"tv":720.81,"id":9625043},{"atb":[[1.44,76.95]],"id":9625043}],"con":true,"img":false}]}
{"op":"mcm","clk":"1349989330","pt":1588414774373,"mc":[{"id":"1.170370562","rc":[{"trd":[[1.42,1171.16],[1.44,874.73]],"ltp":1.42,"tv":2045.89,"id":9625043},{"atb":[[1.44,0],[1.42,541.27]],"id":9625043}],"con":true,"img":false}]}
{"op":"mcm","clk":"1349989335","pt":1588414774579,"mc":[{"id":"1.170370562","rc":[{"atl":[[1.44,0.23]],"id":9625043}],"con":true,"img":false}]}
{"op":"mcm","clk":"1349989339","pt":1588414774786,"mc":[{"id":"1.170370562","rc":[{"atl":[[1.44,0.35]],"id":9625043}],"con":true,"img":false}]}
{"op":"mcm","clk":"1349989344","pt":1588414774991,"mc":[{"id":"1.170370562","rc":[{"trd":[[1.44,875.44]],"ltp":1.44,"tv":875.44,"id":9625043},{"atb":[[1.44,9.16]],"id":9625043},{"atl":[[1.44,0],[1.53,112]],"id":9625043}],"con":true,"img":false}]}
{"op":"mcm","clk":"1349989403","pt":1588414776387,"mc":[{"id":"1.170370562","rc":[{"atb":[[1.42,492.02]],"id":9625043}],"con":true,"img":false}]}
{"op":"mcm","clk":"1349989420","pt":1588414777011,"mc":[{"id":"1.170370562","rc":[{"atb":[[1.15,9.27]],"id":9625043}],"con":true,"img":false}]}
{"op":"mcm","clk":"1349989426","pt":1588414777116,"mc":[{"id":"1.170370562","rc":[{"atb":[[1.35,0]],"id":9625043}],"con":true,"img":false}]}
{"op":"mcm","clk":"1349989438","pt":1588414777377,"mc":[{"id":"1.170370562","rc":[{"trd":[[1.45,528.77]],"ltp":1.45,"tv":528.77,"id":9625043},{"atl":[[1.45,110.05]],"id":9625043}],"con":true,"img":false}]}
{"op":"mcm","clk":"1349989453","pt":1588414778099,"mc":[{"id":"1.170370562","rc":[{"atb":[[1.38,0.47]],"id":9625043}],"con":true,"img":false}]}
{"op":"mcm","clk":"1349989455","pt":1588414778203,"mc":[{"id":"1.170370562","rc":[{"trd":[[1.49,444],[1.45,748.87]],"ltp":1.49,"tv":1192.87,"id":9625043},{"atb":[[1.49,543.84]],"id":9625043},{"atl":[[1.45,0],[1.49,0]],"id":9625043}],"con":true,"img":false}]}
{"op":"mcm","clk":"1349989473","pt":1588414778820,"mc":[{"id":"1.170370562","rc":[{"atl":[[1.51,0.74]],"id":9625043}],"con":true,"img":false}]}
{"op":"mcm","clk":"1349989479","pt":1588414778978,"mc":[{"id":"1.170370562","rc":[{"trd":[[1.49,452.47]],"ltp":1.49,"tv":452.47,"id":9625043},{"atb":[[1.49,539.6]],"id":9625043},{"atl":[[1.53,0],[1.55,88.65]],"id":9625043}],"con":true,"img":false}]}
{"op":"mcm","clk":"1349989481","pt":1588414779081,"mc":[{"id":"1.170370562","rc":[{"atb":[[1.38,0]],"id":9625043}],"con":true,"img":false}]}
{"op":"mcm","clk":"1349989487","pt":1588414779391,"mc":[{"id":"1.170370562","rc":[{"atb":[[1.45,12.43]],"id":9625043}],"con":true,"img":false}]}
{"op":"mcm","clk":"1349989499","pt":1588414780008,"mc":[{"id":"1.170370562","rc":[{"atb":[[1.45,47.43]],"id":9625043}],"con":true,"img":false}]}
{"op":"mcm","clk":"1349989502","pt":1588414780110,"mc":[{"id":"1.170370562","rc":[{"trd":[[1.49,896.47]],"ltp":1.49,"tv":896.47,"id":9625043},{"atb":[[1.49,317.6]],"id":9625043}],"con":true,"img":false}]}
{"op":"mcm","clk":"1349989514","pt":1588414780523,"mc":[{"id":"1.170370562","rc":[{"atb":[[1.45,35]],"id":9625043}],"con":true,"img":false}]}
{"op":"mcm","clk":"1349989521","pt":1588414780682,"mc":[{"id":"1.170370562","rc":[{"atb":[[1.45,35.34]],"id":9625043}],"con":true,"img":false}]}
{"op":"mcm","clk":"1349989524","pt":1588414780783,"mc":[{"id":"1.170370562","rc":[{"atl":[[3.45,0]],"id":9631798}],"con":true,"img":false}]}
{"op":"mcm","clk":"1349989537","pt":1588414781198,"mc":[{"id":"1.170370562","rc":[{"trd":[[1.49,1006.47]],"ltp":1.49,"tv":1006.47,"id":9625043},{"atb":[[1.49,262.6]],"id":9625043}],"con":true,"img":false}]}
{"op":"mcm","clk":"1349989551","pt":1588414781610,"mc":[{"id":"1.170370562","rc":[{"atb":[[1.45,35.44],[1.49,262.7]],"id":9625043}],"con":true,"img":false}]}
{"op":"mcm","clk":"1349989565","pt":1588414782021,"mc":[{"id":"1.170370562","rc":[{"atb":[[1.49,1262.7]],"id":9625043},{"atl":[[3.55,0]],"id":9631798}],"con":true,"img":false}]}
{"op":"mcm","clk":"1349989569","pt":1588414782125,"mc":[{"id":"1.170370562","rc":[{"trd":[[1.49,1230.47]],"ltp":1.49,"tv":1230.47,"id":9625043},{"atb":[[1.49,1150.7]],"id":9625043}],"con":true,"img":false}]}
{"op":"mcm","clk":"1349989610","pt":1588414783884,"mc":[{"id":"1.170370562","rc":[{"atb":[[1.42,0]],"id":9625043}],"con":true,"img":false}]}
{"op":"mcm","clk":"1349989616","pt":1588414784090,"mc":[{"id":"1.170370562","rc":[{"atb":[[1.46,492.02]],"id":9625043}],"con":true,"img":false}]}
{"op":"mcm","clk":"1349989629","pt":1588414784504,"mc":[{"id":"1.170370562","rc":[{"atb":[[1.45,39.87]],"id":9625043}],"con":true,"img":false}]}
{"op":"mcm","clk":"1349989636","pt":1588414784660,"mc":[{"id":"1.170370562","rc":[{"atb":[[1.49,1148.13]],"id":9625043}],"con":true,"img":false}]}
{"op":"mcm","clk":"1349989659","pt":1588414785586,"mc":[{"id":"1.170370562","rc":[{"atb":[[1.45,39.53]],"id":9625043}],"con":true,"img":false}]}
{"op":"mcm","clk":"1349989664","pt":1588414785791,"mc":[{"id":"1.170370562","rc":[{"atb":[[1.45,39.76]],"id":9625043}],"con":true,"img":false}]}
{"op":"mcm","clk":"1349989669","pt":1588414785998,"mc":[{"id":"1.170370562","rc":[{"atb":[[1.48,0.7]],"id":9625043}],"con":true,"img":false}]}
{"op":"mcm","clk":"1349989684","pt":1588414786409,"mc":[{"id":"1.170370562","rc":[{"atl":[[3.2,17]],"id":9631798}],"con":true,"img":false}]}
{"op":"mcm","clk":"1349989695","pt":1588414786771,"mc":[{"id":"1.170370562","rc":[{"atl":[[3.15,94.11]],"id":9631798}],"con":true,"img":false}]}
{"op":"mcm","clk":"1349989704","pt":1588414787079,"mc":[{"id":"1.170370562","rc":[{"trd":[[1.51,1237.1]],"ltp":1.51,"tv":1237.1,"id":9625043},{"atl":[[1.51,0]],"id":9625043},{"trd":[[2.96,15.66],[2.98,0.02]],"ltp":2.96,"tv":15.68,"id":9631798},{"atb":[[2.98,0]],"id":9631798},{"atl":[[2.96,0.4]],"id":9631798}],"con":true,"img":false}]}
{"op":"mcm","clk":"1349989707","pt":1588414787183,"mc":[{"id":"1.170370562","rc":[{"atl":[[1.55,209.37]],"id":9625043}],"con":true,"img":false}]}
{"op":"mcm","clk":"1349989723","pt":1588414787802,"mc":[{"id":"1.170370562","rc":[{"atl":[[3.2,0]],"id":9631798}],"con":true,"img":false}]}
{"op":"mcm","clk":"1349989729","pt":1588414788110,"mc":[{"id":"1.170370562","rc":[{"atb":[[1.46,0]],"id":9625043}],"con":true,"img":false}]}
{"op":"mcm","clk":"1349989733","pt":1588414788214,"mc":[{"id":"1.170370562","rc":[{"atb":[[1.45,4.76]],"id":9625043}],"con":true,"img":false}]}
{"op":"mcm","clk":"1349989735","pt":1588414788270,"mc":[{"id":"1.170370562","rc":[{"trd":[[1.55,335.82],[1.54,802.46],[1.53,458.89]],"ltp":1.55,"tv":1597.17,"id":9625043},{"atl":[[1.55,0]],"id":9625043},{"trd":[[2.88,3.61],[2.92,0.01],[2.9,0.01]],"ltp":2.88,"tv":3.63,"id":9631798},{"atb":[[2.92,0],[2.88,0],[2.9,0]],"id":9631798}],"con":true,"img":false}]}
{"op":"mcm","clk":"1349989747","pt":1588414788577,"mc":[{"id":"1.170370562","rc":[{"atl":[[1.55,112]],"id":9625043}],"con":true,"img":false}]}
{"op":"mcm","clk":"1349989770","pt":1588414789098,"mc":[{"id":"1.170370562","rc":[{"trd":[[1.51,1237.22]],"ltp":1.51,"tv":1237.22,"id":9625043},{"trd":[[2.96,15.72]],"ltp":2.96,"tv":15.72,"id":9631798},{"atl":[[2.96,0.34]],"id":9631798}],"con":true,"img":false}]}
{"op":"mcm","clk":"1349989773","pt":1588414789201,"mc":[{"id":"1.170370562","rc":[{"atl":[[1.54,112]],"id":9625043}],"con":true,"img":false}]}
{"op":"mcm","clk":"1349989775","pt":1588414789306,"mc":[{"id":"1.170370562","rc":[{"atb":[[1.48,0]],"id":9625043}],"con":true,"img":false}]}
{"op":"mcm","clk":"1349989783","pt":1588414789566,"mc":[{"id":"1.170370562","rc":[{"atl":[[1.54,167]],"id":9625043}],"con":true,"img":false}]}
{"op":"mcm","clk":"1349989786","pt":1588414789669,"mc":[{"id":"1.170370562","rc":[{"trd":[[1.54,825.72]],"ltp":1.54,"tv":825.72,"id":9625043},{"atb":[[1.49,1148.02]],"id":9625043},{"atl":[[1.54,155.37]],"id":9625043}],"con":true,"img":false}]}
{"op":"mcm","clk":"1349989812","pt":1588414790805,"mc":[{"id":"1.170370562","rc":[{"atb":[[1.49,148.02]],"id":9625043}],"con":true,"img":false}]}
{"op":"mcm","clk":"1349989819","pt":1588414791011,"mc":[{"id":"1.170370562","rc":[{"atl":[[1.52,199.96]],"id":9625043}],"con":true,"img":false}]}
{"op":"mcm","clk":"1349989821","pt":1588414791115,"mc":[{"id":"1.170370562","rc":[{"atb":[[1.45,4.53]],"id":9625043}],"con":true,"img":false}]}
{"op":"mcm","clk":"1349989838","pt":1588414791687,"mc":[{"id":"1.170370562","rc":[{"trd":[[1.51,1247.16]],"ltp":1.51,"tv":1247.16,"id":9625043},{"atl":[[1.51,194.65]],"id":9625043},{"trd":[[2.96,16.06]],"ltp":2.96,"tv":16.06,"id":9631798},{"atl":[[2.96,0]],"id":9631798}],"con":true,"img":false}]}
{"op":"mcm","clk":"1349989877","pt":1588414792877,"mc":[{"id":"1.170370562","rc":[{"trd":[[1.49,1235.18]],"ltp":1.49,"tv":1235.18,"id":9625043},{"atb":[[1.49,145.67]],"id":9625043}],"con":true,"img":false}]}
{"op":"mcm","clk":"1349989882","pt":1588414793084,"mc":[{"id":"1.170370562","rc":[{"atl":[[1.51,0]],"id":9625043}],"con":true,"img":false}]}
{"op":"mcm","clk":"1349989888","pt":1588414793288,"mc":[{"id":"1.170370562","rc":[{"trd":[[1.52,914.56]],"ltp":1.52,"tv":914.56,"id":9625043},{"atl":[[1.52,164.96]],"id":9625043}],"con":true,"img":false}]}
{"op":"mcm","clk":"1349989892","pt":1588414793392,"mc":[{"id":"1.170370562","rc":[{"atl":[[1.55,112.23]],"id":9625043}],"con":true,"img":false}]}
{"op":"mcm","clk":"1349989924","pt":1588414794481,"mc":[{"id":"1.170370562","rc":[{"atl":[[1.56,0]],"id":9625043}],"con":true,"img":false}]}
{"op":"mcm","clk":"1349989926","pt":1588414794582,"mc":[{"id":"1.170370562","rc":[{"atl":[[1.55,0.23],[1.54,55]],"id":9625043}],"con":true,"img":false}]}
{"op":"mcm","clk":"1349989936","pt":1588414794996,"mc":[{"id":"1.170370562","rc":[{"trd":[[1.52,919.52]],"ltp":1.52,"tv":919.52,"id":9625043},{"atl":[[1.52,160.01]],"id":9625043},{"trd":[[2.92,2.58]],"ltp":2.92,"tv":2.58,"id":9631798}],"con":true,"img":false}]}
{"op":"mcm","clk":"1349989944","pt":1588414795306,"mc":[{"id":"1.170370562","rc":[{"atl":[[1.58,0]],"id":9625043}],"con":true,"img":false}]}
{"op":"mcm","clk":"1349989974","pt":1588414796186,"mc":[{"id":"1.170370562","rc":[{"atl":[[1.54,0]],"id":9625043}],"con":true,"img":false}]}
{"op":"mcm","clk":"1349989988","pt":1588414796499,"mc":[{"id":"1.170370562","rc":[{"trd":[[1.44,893.77],[1.46,299.54],[1.45,757.94],[1.49,1526.52]],"ltp":1.44,"tv":3477.77,"id":9625043},{"atb":[[1.44,0],[1.45,0],[1.49,0]],"id":9625043},{"atl":[[1.44,153.14]],"id":9625043},{"trd":[[3.15,94.11]],"ltp":3.15,"tv":94.11,"id":9631798},{"atl":[[3.15,0]],"id":9631798}],"con":true,"img":false}]}
{"op":"mcm","clk":"1349989995","pt":1588414796809,"mc":[{"id":"1.170370562","rc":[{"atb":[[1.92,0]],"id":9631798}],"con":true,"img":false}]}
{"op":"mcm","clk":"1349990004","pt":1588414797119,"mc":[{"id":"1.170370562","rc":[{"trd":[[1.52,1239.54],[1.44,1200.06]],"ltp":1.52,"tv":2439.6,"id":9625043},{"atb":[[1.53,686.85]],"id":9625043},{"atl":[[1.44,0],[1.52,0]],"id":9625043}],"con":true,"img":false}]}
{"op":"mcm","clk":"1349990006","pt":1588414797174,"mc":[{"id":"1.170370562","rc":[{"atl":[[1.6,112]],"id":9625043}],"con":true,"img":false}]}
{"op":"mcm","clk":"1349990017","pt":1588414797381,"mc":[{"id":"1.170370562","rc":[{"atb":[[1.5,1000]],"id":9625043}],"con":true,"img":false}]}
{"op":"mcm","clk":"1349990039","pt":1588414798001,"mc":[{"id":"1.170370562","rc":[{"trd":[[1.55,336.3]],"ltp":1.55,"tv":336.3,"id":9625043},{"atb":[[1.55,2.32]],"id":9625043},{"atl":[[1.59,182.92],[1.55,0]],"id":9625043},{"trd":[[2.84,171.62]],"ltp":2.84,"tv":171.62,"id":9631798},{"atb":[[2.84,0]],"id":9631798}],"con":true,"img":false}]}
{"op":"mcm","clk":"1349990052","pt":1588414798472,"mc":[{"id":"1.170370562","rc":[{"atb":[[1.5,1492.02]],"id":9625043}],"con":true,"img":false}]}
{"op":"mcm","clk":"1349990079","pt":1588414799715,"mc":[{"id":"1.170370562","rc":[{"atb":[[1.5,1714.02]],"id":9625043}],"con":true,"img":false}]}
{"op":"mcm","clk":"1349990084","pt":1588414799819,"mc":[{"id":"1.170370562","rc":[{"atl":[[2.92,30.14]],"id":9631798}],"con":true,"img":false}]}
{"op":"mcm","clk":"1349990089","pt":1588414799977,"mc":[{"id":"1.170370562","rc":[{"atb":[[1.53,908.85]],"id":9625043},{"atl":[[2.92,0]],"id":9631798}],"con":true,"img":false}]}
{"op":"mcm","clk":"1349990093","pt":1588414800081,"mc":[{"id":"1.170370562","rc":[{"atl":[[3,17]],"id":9631798}],"con":true,"img":false}]}
{"op":"mcm","clk":"1349990117","pt":1588414801016,"mc":[{"id":"1.170370562","rc":[{"atl":[[3,0]],"id":9631798}],"con":true,"img":false}]}
{"op":"mcm","clk":"1349990122","pt":1588414801121,"mc":[{"id":"1.170370562","rc":[{"atl":[[1.61,177.3]],"id":9625043}],"con":true,"img":false}]}
{"op":"mcm","clk":"1349990139","pt":1588414801489,"mc":[{"id":"1.170370562","rc":[{"atl":[[1.6,224]],"id":9625043}],"con":true,"img":false}]}
{"op":"mcm","clk":"1349990158","pt":1588414802010,"mc":[{"id":"1.170370562","rc":[{"atb":[[1.53,0],[1.5,714.02]],"id":9625043},{"atl":[[2.96,28.69]],"id":9631798}],"con":true,"img":false}]}
{"op":"mcm","clk":"1349990166","pt":1588414802322,"mc":[{"id":"1.170370562","rc":[{"atb":[[1.5,222]],"id":9625043}],"con":true,"img":false}]}
{"op":"mcm","clk":"1349990180","pt":1588414802585,"mc":[{"id":"1.170370562","rc":[{"atb":[[1.5,0]],"id":9625043}],"con":true,"img":false}]}
{"op":"mcm","clk":"1349990184","pt":1588414802690,"mc":[{"id":"1.170370562","rc":[{"atl":[[1.59,112]],"id":9625043}],"con":true,"img":false}]}
{"op":"mcm","clk":"1349990188","pt":1588414802793,"mc":[{"id":"1.170370562","rc":[{"atb":[[1.77,317.32]],"id":9631798},{"atl":[[3,51.71]],"id":9631798}],"con":true,"img":false}]}
{"op":"mcm","clk":"1349990201","pt":1588414803109,"mc":[{"id":"1.170370562","rc":[{"atb":[[1.45,112]],"id":9625043}],"con":true,"img":false}]}
{"op":"mcm","clk":"1349990209","pt":1588414803211,"mc":[{"id":"1.170370562","rc":[{"atb":[[1.55,29.32]],"id":9625043}],"con":true,"img":false}]}
{"op":"mcm","clk":"1349990216","pt":1588414803315,"mc":[{"id":"1.170370562","rc":[{"atb":[[1.4,112]],"id":9625043}],"con":true,"img":false}]}
{"op":"mcm","clk":"1349990240","pt":1588414803793,"mc":[{"id":"1.170370562","rc":[{"atb":[[1.52,4.23]],"id":9625043}],"con":true,"img":false}]}
{"op":"mcm","clk":"1349990257","pt":1588414804210,"mc":[{"id":"1.170370562","rc":[{"atb":[[1.55,27]],"id":9625043}],"con":true,"img":false}]}
{"op":"mcm","clk":"1349990274","pt":1588414804631,"mc":[{"id":"1.170370562","rc":[{"trd":[[1.57,16.69]],"ltp":1.57,"tv":16.69,"id":9625043},{"atl":[[1.57,0]],"id":9625043},{"trd":[[2.7,14.28],[2.74,53.3]],"ltp":2.7,"tv":67.58,"id":9631798},{"atb":[[2.7,38.19]],"id":9631798}],"con":true,"img":false}]}
{"op":"mcm","clk":"1349990277","pt":1588414804685,"mc":[{"id":"1.170370562","rc":[{"trd":[[1.55,336.6]],"ltp":1.55,"tv":336.6,"id":9625043},{"atb":[[1.55,26.85]],"id":9625043}],"con":true,"img":false}]}
{"op":"mcm","clk":"1349990290","pt":1588414804895,"mc":[{"id":"1.170370562","rc":[{"atb":[[1.5,79.78],[1.52,4.33]],"id":9625043}],"con":true,"img":false}]}
{"op":"mcm","clk":"1349990303","pt":1588414805204,"mc":[{"id":"1.170370562","rc":[{"atl":[[3.45,17]],"id":9631798}],"con":true,"img":false}]}
{"op":"mcm","clk":"1349990328","pt":1588414805822,"mc":[{"id":"1.170370562","rc":[{"atb":[[1.41,112]],"id":9625043}],"con":true,"img":false}]}
