{"op":"mcm","clk":"1362105338","pt":1588427785455,"mc":[{"id":"1.170370557","rc":[{"trd":[[1.18,928.55]],"ltp":1.18,"tv":928.55,"id":9624350},{"atl":[[1.18,24.5]],"id":9624350}],"con":true,"img":false}]}
{"op":"mcm","clk":"1362105352","pt":1588427786936,"mc":[{"id":"1.170370557","rc":[{"atb":[[1.17,101.15]],"id":9624350}],"con":true,"img":false}]}
{"op":"mcm","clk":"1362105355","pt":1588427787243,"mc":[{"id":"1.170370557","rc":[{"atl":[[1.25,495.79]],"id":9624350}],"con":true,"img":false}]}
{"op":"mcm","clk":"1362105360","pt":1588427787958,"mc":[{"id":"1.170370557","rc":[{"trd":[[1.18,932.57]],"ltp":1.18,"tv":932.57,"id":9624350},{"atl":[[1.18,22.49]],"id":9624350}],"con":true,"img":false}]}
{"op":"mcm","clk":"1362105366","pt":1588427788569,"mc":[{"id":"1.170370557","rc":[{"trd":[[1.18,934.69]],"ltp":1.18,"tv":934.69,"id":9624350},{"atl":[[1.18,21.43]],"id":9624350}],"con":true,"img":false}]}
{"op":"mcm","clk":"1362105373","pt":1588427789236,"mc":[{"id":"1.170370557","rc":[{"atl":[[1.18,149.73]],"id":9624350}],"con":true,"img":false}]}
{"op":"mcm","clk":"1362105378","pt":1588427789748,"mc":[{"id":"1.170370557","rc":[{"atl":[[1.18,371.36]],"id":9624350}],"con":true,"img":false}]}
{"op":"mcm","clk":"1362105381","pt":1588427790257,"mc":[{"id":"1.170370557","rc":[{"atb":[[1.15,492.02],[1.13,492.02]],"id":9624350},{"atl":[[1.25,52.53]],"id":9624350}],"con":true,"img":false}]}
{"op":"mcm","clk":"1362105391","pt":1588427790765,"mc":[{"id":"1.170370557","rc":[{"trd":[[1.18,1065.33]],"ltp":1.18,"tv":1065.33,"id":9624350},{"atl":[[1.18,306.04]],"id":9624350}],"con":true,"img":false}]}
{"op":"mcm","clk":"1362105396","pt":1588427790969,"mc":[{"id":"1.170370557","rc":[{"trd":[[1.18,1169.5]],"ltp":1.18,"tv":1169.5,"id":9624350},{"atl":[[1.18,253.96]],"id":9624350}],"con":true,"img":false}]}
{"op":"mcm","clk":"1362105399","pt":1588427791173,"mc":[{"id":"1.170370557","rc":[{"atl":[[1.2,0]],"id":9624350}],"con":true,"img":false}]}
{"op":"mcm","clk":"1362105412","pt":1588427791685,"mc":[{"id":"1.170370557","rc":[{"atb":[[1.16,55.84]],"id":9624350}],"con":true,"img":false}]}
{"op":"mcm","clk":"1362105419","pt":1588427792046,"mc":[{"id":"1.170370557","rc":[{"atb":[[1.15,0]],"id":9624350}],"con":true,"img":false}]}
{"op":"mcm","clk":"1362105423","pt":1588427792251,"mc":[{"id":"1.170370557","rc":[{"atl":[[1.19,221.63]],"id":9624350}],"con":true,"img":false}]}
{"op":"mcm","clk":"1362105430","pt":1588427792659,"mc":[{"id":"1.170370557","rc":[{"trd":[[1.17,19.5]],"ltp":1.17,"tv":19.5,"id":9624350},{"atb":[[1.17,91.4]],"id":9624350}],"con":true,"img":false}]}
{"op":"mcm","clk":"1362105433","pt":1588427792764,"mc":[{"id":"1.170370557","rc":[{"atl":[[1.21,0]],"id":9624350}],"con":true,"img":false}]}
{"op":"mcm","clk":"1362105456","pt":1588427794147,"mc":[{"id":"1.170370557","rc":[{"atl":[[1.18,32.33]],"id":9624350}],"con":true,"img":false}]}
{"op":"mcm","clk":"1362105457","pt":1588427794247,"mc":[{"id":"1.170370557","rc":[{"trd":[[1.18,1188.4]],"ltp":1.18,"tv":1188.4,"id":9624350},{"atl":[[1.18,22.88]],"id":9624350}],"con":true,"img":false}]}
{"op":"mcm","clk":"1362105477","pt":1588427796288,"mc":[{"id":"1.170370557","rc":[{"trd":[[6.4,4.22]],"ltp":6.4,"tv":4.22,"id":9622734},{"atl":[[6.4,0.78]],"id":9622734},{"trd":[[1.18,1211.28]],"ltp":1.18,"tv":1211.28,"id":9624350},{"atl":[[1.18,0]],"id":9624350}],"con":true,"img":false}]}
{"op":"mcm","clk":"1362105493","pt":1588427797369,"mc":[{"id":"1.170370557","rc":[{"trd":[[6.4,5]],"ltp":6.4,"tv":5.0,"id":9622734},{"atl":[[6.4,0]],"id":9622734},{"trd":[[1.18,1215.51]],"ltp":1.18,"tv":1215.51,"id":9624350},{"atl":[[1.18,62.26]],"id":9624350}],"con":true,"img":false}]}
{"op":"mcm","clk":"1362105496","pt":1588427797569,"mc":[{"id":"1.170370557","rc":[{"atl":[[1.18,128.75]],"id":9624350}],"con":true,"img":false}]}
{"op":"mcm","clk":"1362105502","pt":1588427797977,"mc":[{"id":"1.170370557","rc":[{"trd":[[1.18,1217.27]],"ltp":1.18,"tv":1217.27,"id":9624350},{"atb":[[1.16,277.47]],"id":9624350},{"atl":[[1.18,127.87]],"id":9624350}],"con":true,"img":false}]}
{"op":"mcm","clk":"1362105511","pt":1588427798795,"mc":[{"id":"1.170370557","rc":[{"trd":[[1.18,1217.62]],"ltp":1.18,"tv":1217.62,"id":9624350},{"atl":[[1.18,127.69]],"id":9624350}],"con":true,"img":false}]}
{"op":"mcm","clk":"1362105513","pt":1588427798896,"mc":[{"id":"1.170370557","rc":[{"trd":[[1.18,1222.33]],"ltp":1.18,"tv":1222.33,"id":9624350},{"atl":[[1.18,125.33]],"id":9624350}],"con":true,"img":false}]}
{"op":"mcm","clk":"1362105550","pt":1588427802983,"mc":[{"id":"1.170370557","rc":[{"atb":[[1.15,51.31]],"id":9624350}],"con":true,"img":false}]}
{"op":"mcm","clk":"1362105553","pt":1588427803188,"mc":[{"id":"1.170370557","rc":[{"trd":[[1.18,1222.73]],"ltp":1.18,"tv":1222.73,"id":9624350},{"atl":[[1.18,125.14]],"id":9624350}],"con":true,"img":false}]}
{"op":"mcm","clk":"1362105556","pt":1588427803701,"mc":[{"id":"1.170370557","rc":[{"atb":[[1.17,180.05]],"id":9624350}],"con":true,"img":false}]}
{"op":"mcm","clk":"1362105566","pt":1588427804473,"mc":[{"id":"1.170370557","rc":[{"atb":[[1.11,552.02]],"id":9624350}],"con":true,"img":false}]}
{"op":"mcm","clk":"1362105569","pt":1588427804779,"mc":[{"id":"1.170370557","rc":[{"atb":[[1.14,0]],"id":9624350}],"con":true,"img":false}]}
{"op":"mcm","clk":"1362105571","pt":1588427805186,"mc":[{"id":"1.170370557","rc":[{"atb":[[1.12,1476.89]],"id":9624350}],"con":true,"img":false}]}
{"op":"mcm","clk":"1362105573","pt":1588427805390,"mc":[{"id":"1.170370557","rc":[{"atl":[[1.24,52.9]],"id":9624350}],"con":true,"img":false}]}
{"op":"mcm","clk":"1362105583","pt":1588427806004,"mc":[{"id":"1.170370557","rc":[{"atl":[[1.22,228.4]],"id":9624350}],"con":true,"img":false}]}
{"op":"mcm","clk":"1362105588","pt":1588427806311,"mc":[{"id":"1.170370557","rc":[{"atl":[[1.18,0]],"id":9624350}],"con":true,"img":false}]}
{"op":"mcm","clk":"1362105597","pt":1588427806772,"mc":[{"id":"1.170370557","rc":[{"atl":[[1.19,0]],"id":9624350}],"con":true,"img":false}]}
{"op":"mcm","clk":"1362105604","pt":1588427807283,"mc":[{"id":"1.170370557","rc":[{"atl":[[1.25,35.01],[1.24,35.38]],"id":9624350}],"con":true,"img":false}]}
{"op":"mcm","clk":"1362105607","pt":1588427807384,"mc":[{"id":"1.170370557","rc":[{"atb":[[1.16,233.68]],"id":9624350}],"con":true,"img":false}]}
{"op":"mcm","clk":"1362105610","pt":1588427807488,"mc":[{"id":"1.170370557","rc":[{"atl":[[1.22,221.63],[1.24,17.86]],"id":9624350}],"con":true,"img":false}]}
{"op":"mcm","clk":"1362105613","pt":1588427807691,"mc":[{"id":"1.170370557","rc":[{"atb":[[1.17,146.01]],"id":9624350}],"con":true,"img":false}]}
{"op":"mcm","clk":"1362105618","pt":1588427807998,"mc":[{"id":"1.170370557","rc":[{"atb":[[1.01,4103.75]],"id":9624350}],"con":true,"img":false}]}
{"op":"mcm","clk":"1362105620","pt":1588427808100,"mc":[{"id":"1.170370557","rc":[{"atb":[[1.09,0.31]],"id":9624350}],"con":true,"img":false}]}
{"op":"mcm","clk":"1362105621","pt":1588427808203,"mc":[{"id":"1.170370557","rc":[{"atb":[[1.01,4102.75]],"id":9624350},{"atl":[[1.24,0.35]],"id":9624350}],"con":true,"img":false}]}
{"op":"mcm","clk":"1362105624","pt":1588427808407,"mc":[{"id":"1.170370557","rc":[{"atb":[[1.01,4101.75]],"id":9624350}],"con":true,"img":false}]}
{"op":"mcm","clk":"1362105626","pt":1588427808509,"mc":[{"id":"1.170370557","rc":[{"atl":[[1.25,17.49]],"id":9624350}],"con":true,"img":false}]}
{"op":"mcm","clk":"1362105644","pt":1588427809991,"mc":[{"id":"1.170370557","rc":[{"atb":[[1.1,492.02]],"id":9624350}],"con":true,"img":false}]}
{"op":"mcm","clk":"1362105645","pt":1588427810094,"mc":[{"id":"1.170370557","rc":[{"trd":[[7.2,1.72]],"ltp":7.2,"tv":1.72,"id":9622734},{"atl":[[7.2,0]],"id":9622734},{"trd":[[1.16,478.06],[1.17,311.52]],"ltp":1.16,"tv":789.57,"id":9624350},{"atb":[[1.16,0],[1.17,0]],"id":9624350},{"atl":[[1.16,53.61]],"id":9624350}],"con":true,"img":false}]}
{"op":"mcm","clk":"1362105648","pt":1588427810195,"mc":[{"id":"1.170370557","rc":[{"atl":[[1.22,0]],"id":9624350}],"con":true,"img":false}]}
{"op":"mcm","clk":"1362105652","pt":1588427810503,"mc":[{"id":"1.170370557","rc":[{"atl":[[1.16,0]],"id":9624350}],"con":true,"img":false}]}
{"op":"mcm","clk":"1362105658","pt":1588427810916,"mc":[{"id":"1.170370557","rc":[{"atb":[[1.18,55.55]],"id":9624350}],"con":true,"img":false}]}
{"op":"mcm","clk":"1362105663","pt":1588427811320,"mc":[{"id":"1.170370557","rc":[{"atb":[[1.13,625]],"id":9624350}],"con":true,"img":false}]}
{"op":"mcm","clk":"1362105664","pt":1588427811524,"mc":[{"id":"1.170370557","rc":[{"atb":[[1.19,88.65]],"id":9624350}],"con":true,"img":false}]}
{"op":"mcm","clk":"1362105667","pt":1588427811729,"mc":[{"id":"1.170370557","rc":[{"atb":[[1.19,177.3]],"id":9624350}],"con":true,"img":false}]}
{"op":"mcm","clk":"1362105669","pt":1588427811885,"mc":[{"id":"1.170370557","rc":[{"atb":[[1.19,265.95]],"id":9624350}],"con":true,"img":false}]}
{"op":"mcm","clk":"1362105670","pt":1588427811988,"mc":[{"id":"1.170370557","rc":[{"atb":[[1.18,355.55]],"id":9624350}],"con":true,"img":false}]}
{"op":"mcm","clk":"1362105672","pt":1588427812090,"mc":[{"id":"1.170370557","rc":[{"atb":[[1.19,354.6]],"id":9624350}],"con":true,"img":false}]}
{"op":"mcm","clk":"1362105674","pt":1588427812395,"mc":[{"id":"1.170370557","rc":[{"atb":[[1.18,655.55]],"id":9624350}],"con":true,"img":false}]}
{"op":"mcm","clk":"1362105678","pt":1588427812701,"mc":[{"id":"1.170370557","rc":[{"trd":[[1.19,659.78]],"ltp":1.19,"tv":659.78,"id":9624350},{"atb":[[1.19,350.61]],"id":9624350}],"con":true,"img":false}]}
{"op":"mcm","clk":"1362105681","pt":1588427812906,"mc":[{"id":"1.170370557","rc":[{"atb":[[1.14,51.76]],"id":9624350}],"con":true,"img":false}]}
{"op":"mcm","clk":"1362105687","pt":1588427813520,"mc":[{"id":"1.170370557","rc":[{"atb":[[1.15,52.31]],"id":9624350}],"con":true,"img":false}]}
{"op":"mcm","clk":"1362105689","pt":1588427813725,"mc":[{"id":"1.170370557","rc":[{"atb":[[1.11,913.04]],"id":9624350}],"con":true,"img":false}]}
{"op":"mcm","clk":"1362105691","pt":1588427813929,"mc":[{"id":"1.170370557","rc":[{"atb":[[1.19,572.24]],"id":9624350}],"con":true,"img":false}]}
{"op":"mcm","clk":"1362105702","pt":1588427814392,"mc":[{"id":"1.170370557","rc":[{"atb":[[1.2,221.63]],"id":9624350}],"con":true,"img":false}]}
{"op":"mcm","clk":"1362105707","pt":1588427814800,"mc":[{"id":"1.170370557","rc":[{"atl":[[1.24,69.64]],"id":9624350}],"con":true,"img":false}]}
{"op":"mcm","clk":"1362105710","pt":1588427814902,"mc":[{"id":"1.170370557","rc":[{"atb":[[1.2,0]],"id":9624350}],"con":true,"img":false}]}
{"op":"mcm","clk":"1362105717","pt":1588427815209,"mc":[{"id":"1.170370557","rc":[{"atl":[[6.4,0.31]],"id":9622734}],"con":true,"img":false}]}
{"op":"mcm","clk":"1362105726","pt":1588427815925,"mc":[{"id":"1.170370557","rc":[{"atb":[[1.18,600]],"id":9624350}],"con":true,"img":false}]}
{"op":"mcm","clk":"1362105737","pt":1588427816796,"mc":[{"id":"1.170370557","rc":[{"atb":[[1.2,381.15]],"id":9624350}],"con":true,"img":false}]}
{"op":"mcm","clk":"1362105744","pt":1588427817509,"mc":[{"id":"1.170370557","rc":[{"atl":[[1.22,221.63]],"id":9624350}],"con":true,"img":false}]}
{"op":"mcm","clk":"1362105749","pt":1588427817918,"mc":[{"id":"1.170370557","rc":[{"trd":[[1.2,851.14]],"ltp":1.2,"tv":851.14,"id":9624350},{"atb":[[1.2,292.5]],"id":9624350},{"atl":[[1.23,69.85]],"id":9624350}],"con":true,"img":false}]}
{"op":"mcm","clk":"1362105751","pt":1588427818632,"mc":[{"id":"1.170370557","rc":[{"atb":[[1.21,38.32]],"id":9624350}],"con":true,"img":false}]}
{"op":"mcm","clk":"1362105753","pt":1588427818734,"mc":[{"id":"1.170370557","rc":[{"atl":[[1.26,421.63]],"id":9624350}],"con":true,"img":false}]}
{"op":"mcm","clk":"1362105757","pt":1588427819143,"mc":[{"id":"1.170370557","rc":[{"atb":[[1.16,492.02]],"id":9624350}],"con":true,"img":false}]}
{"op":"mcm","clk":"1362105759","pt":1588427819245,"mc":[{"id":"1.170370557","rc":[{"atb":[[1.21,0]],"id":9624350}],"con":true,"img":false}]}
{"op":"mcm","clk":"1362105762","pt":1588427819605,"mc":[{"id":"1.170370557","rc":[{"atb":[[1.18,987.61]],"id":9624350}],"con":true,"img":false}]}
{"op":"mcm","clk":"1362105764","pt":1588427819910,"mc":[{"id":"1.170370557","rc":[{"atb":[[1.15,544.33]],"id":9624350},{"atl":[[1.25,460.75]],"id":9624350}],"con":true,"img":false}]}
{"op":"mcm","clk":"1362105767","pt":1588427820115,"mc":[{"id":"1.170370557","rc":[{"atl":[[6.4,0]],"id":9622734},{"atb":[[1.18,600]],"id":9624350}],"con":true,"img":false}]}
{"op":"mcm","clk":"1362105769","pt":1588427820216,"mc":[{"id":"1.170370557","rc":[{"atb":[[1.1,0]],"id":9624350}],"con":true,"img":false}]}
{"op":"mcm","clk":"1362105772","pt":1588427820525,"mc":[{"id":"1.170370557","rc":[{"atb":[[1.11,421.02]],"id":9624350}],"con":true,"img":false}]}
{"op":"mcm","clk":"1362105776","pt":1588427821139,"mc":[{"id":"1.170370557","rc":[{"atb":[[1.15,543.33]],"id":9624350}],"con":true,"img":false}]}
{"op":"mcm","clk":"1362105779","pt":1588427821806,"mc":[{"id":"1.170370557","rc":[{"atl":[[1.23,262.57]],"id":9624350}],"con":true,"img":false}]}
{"op":"mcm","clk":"1362105783","pt":1588427822417,"mc":[{"id":"1.170370557","rc":[{"atl":[[1.23,69.85]],"id":9624350}],"con":true,"img":false}]}
{"op":"mcm","clk":"1362105807","pt":1588427824217,"mc":[{"id":"1.170370557","rc":[{"atb":[[1.2,0]],"id":9624350}],"con":true,"img":false}]}
{"op":"mcm","clk":"1362105809","pt":1588427824318,"mc":[{"id":"1.170370557","rc":[{"atb":[[1.14,543.78]],"id":9624350}],"con":true,"img":false}]}
{"op":"mcm","clk":"1362105816","pt":1588427825347,"mc":[{"id":"1.170370557","rc":[{"atb":[[1.2,38.64]],"id":9624350}],"con":true,"img":false}]}
{"op":"mcm","clk":"1362105819","pt":1588427825655,"mc":[{"id":"1.170370557","rc":[{"atb":[[1.19,350.61]],"id":9624350}],"con":true,"img":false}]}
{"op":"mcm","clk":"1362105828","pt":1588427826219,"mc":[{"id":"1.170370557","rc":[{"atb":[[1.13,626]],"id":9624350}],"con":true,"img":false}]}
{"op":"mcm","clk":"1362105829","pt":1588427826424,"mc":[{"id":"1.170370557","rc":[{"atb":[[1.14,987.04]],"id":9624350}],"con":true,"img":false}]}
{"op":"mcm","clk":"1362105840","pt":1588427828215,"mc":[{"id":"1.170370557","rc":[{"atb":[[1.2,260.27]],"id":9624350}],"con":true,"img":false}]}
{"op":"mcm","clk":"1362105843","pt":1588427828419,"mc":[{"id":"1.170370557","rc":[{"atb":[[1.18,0]],"id":9624350},{"atl":[[1.46,0],[1.44,0],[1.41,0]],"id":9624350}],"con":true,"img":false}]}
{"op":"mcm","clk":"1362105853","pt":1588427829440,"mc":[{"id":"1.170370557","rc":[{"trd":[[1.22,2520.13]],"ltp":1.22,"tv":2520.13,"id":9624350},{"atb":[[1.22,66.08]],"id":9624350},{"atl":[[1.22,0]],"id":9624350}],"con":true,"img":false}]}
{"op":"mcm","clk":"1362105857","pt":1588427830053,"mc":[{"id":"1.170370557","rc":[{"trd":[[1.22,2530.13]],"ltp":1.22,"tv":2530.13,"id":9624350},{"atb":[[1.22,61.08]],"id":9624350}],"con":true,"img":false}]}
{"op":"mcm","clk":"1362105865","pt":1588427830564,"mc":[{"id":"1.170370557","rc":[{"trd":[[1.22,2652.29]],"ltp":1.22,"tv":2652.29,"id":9624350},{"atb":[[1.22,0]],"id":9624350},{"atl":[[1.21,9.92]],"id":9624350}],"con":true,"img":false}]}
{"op":"mcm","clk":"1362105871","pt":1588427830924,"mc":[{"id":"1.170370557","rc":[{"trd":[[1.2,882.67]],"ltp":1.2,"tv":882.67,"id":9624350},{"atb":[[1.2,244.51]],"id":9624350}],"con":true,"img":false}]}
{"op":"mcm","clk":"1362105877","pt":1588427831329,"mc":[{"id":"1.170370557","rc":[{"atl":[[1.21,0]],"id":9624350}],"con":true,"img":false}]}
{"op":"mcm","clk":"1362105881","pt":1588427831738,"mc":[{"id":"1.170370557","rc":[{"atb":[[1.19,550.61]],"id":9624350}],"con":true,"img":false}]}
{"op":"mcm","clk":"1362105884","pt":1588427832045,"mc":[{"id":"1.170370557","rc":[{"atb":[[1.18,200]],"id":9624350}],"con":true,"img":false}]}
{"op":"mcm","clk":"1362105886","pt":1588427832250,"mc":[{"id":"1.170370557","rc":[{"trd":[[1.2,891.53]],"ltp":1.2,"tv":891.53,"id":9624350},{"atb":[[1.2,240.07],[1.16,692.02]],"id":9624350}],"con":true,"img":false}]}
{"op":"mcm","clk":"1362105891","pt":1588427832762,"mc":[{"id":"1.170370557","rc":[{"atb":[[1.2,18.44]],"id":9624350}],"con":true,"img":false}]}
{"op":"mcm","clk":"1362105893","pt":1588427833169,"mc":[{"id":"1.170370557","rc":[{"atb":[[1.17,200]],"id":9624350}],"con":true,"img":false}]}
{"op":"mcm","clk":"1362105897","pt":1588427833633,"mc":[{"id":"1.170370557","rc":[{"atb":[[1.18,400]],"id":9624350}],"con":true,"img":false}]}
{"op":"mcm","clk":"1362105907","pt":1588427834455,"mc":[{"id":"1.170370557","rc":[{"trd":[[1.2,928.43]],"ltp":1.2,"tv":928.43,"id":9624350},{"atb":[[1.2,0]],"id":9624350},{"atl":[[1.2,203.18]],"id":9624350}],"con":true,"img":false}]}
{"op":"mcm","clk":"1362105912","pt":1588427834966,"mc":[{"id":"1.170370557","rc":[{"trd":[[1.2,933.68]],"ltp":1.2,"tv":933.68,"id":9624350},{"atl":[[1.2,200.55]],"id":9624350}],"con":true,"img":false}]}
{"op":"mcm","clk":"1362105914","pt":1588427835169,"mc":[{"id":"1.170370557","rc":[{"trd":[[6,0.28]],"ltp":6.0,"tv":0.28,"id":9622734},{"trd":[[1.2,935.1]],"ltp":1.2,"tv":935.1,"id":9624350},{"atl":[[1.2,199.14]],"id":9624350}],"con":true,"img":false}]}
{"op":"mcm","clk":"1362105918","pt":1588427835373,"mc":[{"id":"1.170370557","rc":[{"atl":[[1.2,0]],"id":9624350}],"con":true,"img":false}]}
{"op":"mcm","clk":"1362105931","pt":1588427837060,"mc":[{"id":"1.170370557","rc":[{"atl":[[1.2,3.99]],"id":9624350}],"con":true,"img":false}]}
{"op":"mcm","clk":"1362105933","pt":1588427837264,"mc":[{"id":"1.170370557","rc":[{"atb":[[1.19,772.24]],"id":9624350}],"con":true,"img":false}]}
{"op":"mcm","clk":"1362105935","pt":1588427837471,"mc":[{"id":"1.170370557","rc":[{"atl":[[1.26,221.63]],"id":9624350}],"con":true,"img":false}]}
{"op":"mcm","clk":"1362105942","pt":1588427838285,"mc":[{"id":"1.170370557","rc":[{"atb":[[1.19,1005.53]],"id":9624350}],"con":true,"img":false}]}
{"op":"mcm","clk":"1362105943","pt":1588427838388,"mc":[{"id":"1.170370557","rc":[{"atb":[[1.17,421.63]],"id":9624350},{"atl":[[1.24,0.35]],"id":9624350}],"con":true,"img":false}]}
{"op":"mcm","clk":"1362105947","pt":1588427838850,"mc":[{"id":"1.170370557","rc":[{"atb":[[5,50]],"id":9622734}],"con":true,"img":false}]}
{"op":"mcm","clk":"1362105950","pt":1588427839157,"mc":[{"id":"1.170370557","rc":[{"atl":[[1.25,17.49]],"id":9624350}],"con":true,"img":false}]}
{"op":"mcm","clk":"1362105952","pt":1588427839258,"mc":[{"id":"1.170370557","rc":[{"trd":[[1.2,936.52]],"ltp":1.2,"tv":936.52,"id":9624350},{"atl":[[1.2,3.28]],"id":9624350}],"con":true,"img":false}]}
{"op":"mcm","clk":"1362105956","pt":1588427839565,"mc":[{"id":"1.170370557","rc":[{"atl":[[1.28,443.26]],"id":9624350}],"con":true,"img":false}]}
{"op":"mcm","clk":"1362105959","pt":1588427839871,"mc":[{"id":"1.170370557","rc":[{"atb":[[1.17,621.63]],"id":9624350}],"con":true,"img":false}]}
{"op":"mcm","clk":"1362105961","pt":1588427840382,"mc":[{"id":"1.170370557","rc":[{"atl":[[1.2,63.28]],"id":9624350}],"con":true,"img":false}]}
{"op":"mcm","clk":"1362105964","pt":1588427840606,"mc":[{"id":"1.170370557","rc":[{"atb":[[1.17,821.63]],"id":9624350}],"con":true,"img":false}]}
{"op":"mcm","clk":"1362105970","pt":1588427841153,"mc":[{"id":"1.170370557","rc":[{"atb":[[1.16,892.02]],"id":9624350}],"con":true,"img":false}]}
{"op":"mcm","clk":"1362105974","pt":1588427842173,"mc":[{"id":"1.170370557","rc":[{"atb":[[1.11,60]],"id":9624350}],"con":true,"img":false}]}
{"op":"mcm","clk":"1362105980","pt":1588427842788,"mc":[{"id":"1.170370557","rc":[{"trd":[[1.23,1932.32],[1.2,1063.1]],"ltp":1.23,"tv":2995.42,"id":9624350},{"atb":[[1.23,358.88]],"id":9624350},{"atl":[[1.2,0],[1.23,0]],"id":9624350}],"con":true,"img":false}]}
{"op":"mcm","clk":"1362105984","pt":1588427843350,"mc":[{"id":"1.170370557","rc":[{"atl":[[1.26,0]],"id":9624350}],"con":true,"img":false}]}
{"op":"mcm","clk":"1362105990","pt":1588427843961,"mc":[{"id":"1.170370557","rc":[{"atb":[[1.22,444]],"id":9624350}],"con":true,"img":false}]}
{"op":"mcm","clk":"1362105995","pt":1588427844167,"mc":[{"id":"1.170370557","rc":[{"atb":[[1.22,532.65]],"id":9624350}],"con":true,"img":false}]}
{"op":"mcm","clk":"1362105996","pt":1588427844268,"mc":[{"id":"1.170370557","rc":[{"atb":[[1.23,802.88]],"id":9624350}],"con":true,"img":false}]}
{"op":"mcm","clk":"1362105998","pt":1588427844370,"mc":[{"id":"1.170370557","rc":[{"atb":[[1.22,621.3]],"id":9624350}],"con":true,"img":false}]}
{"op":"mcm","clk":"1362105999","pt":1588427844471,"mc":[{"id":"1.170370557","rc":[{"atb":[[1.22,709.95]],"id":9624350}],"con":true,"img":false}]}
{"op":"mcm","clk":"1362106001","pt":1588427844675,"mc":[{"id":"1.170370557","rc":[{"atb":[[1.21,443.26]],"id":9624350}],"con":true,"img":false}]}
{"op":"mcm","clk":"1362106009","pt":1588427845698,"mc":[{"id":"1.170370557","rc":[{"atb":[[1.2,15.35]],"id":9624350}],"con":true,"img":false}]}
{"op":"mcm","clk":"1362106011","pt":1588427845856,"mc":[{"id":"1.170370557","rc":[{"atb":[[1.2,0]],"id":9624350}],"con":true,"img":false}]}
{"op":"mcm","clk":"1362106017","pt":1588427847090,"mc":[{"id":"1.170370557","rc":[{"atb":[[1.14,543.78]],"id":9624350}],"con":true,"img":false}]}
{"op":"mcm","clk":"1362106018","pt":1588427847398,"mc":[{"id":"1.170370557","rc":[{"atb":[[1.22,931.58]],"id":9624350}],"con":true,"img":false}]}
{"op":"mcm","clk":"1362106019","pt":1588427847500,"mc":[{"id":"1.170370557","rc":[{"atb":[[1.2,49.17]],"id":9624350}],"con":true,"img":false}]}
{"op":"mcm","clk":"1362106024","pt":1588427847757,"mc":[{"id":"1.170370557","rc":[{"atb":[[1.14,875.05]],"id":9624350}],"con":true,"img":false}]}
{"op":"mcm","clk":"1362106026","pt":1588427848066,"mc":[{"id":"1.170370557","rc":[{"atl":[[1.25,0],[1.24,132.41]],"id":9624350}],"con":true,"img":false}]}
{"op":"mcm","clk":"1362106029","pt":1588427848376,"mc":[{"id":"1.170370557","rc":[{"atb":[[1.21,492.02]],"id":9624350}],"con":true,"img":false}]}
{"op":"mcm","clk":"1362106034","pt":1588427848784,"mc":[{"id":"1.170370557","rc":[{"atb":[[1.2,0],[1.21,443.26],[1.14,823.29],[1.15,492.02]],"id":9624350}],"con":true,"img":false}]}
{"op":"mcm","clk":"1362106036","pt":1588427848886,"mc":[{"id":"1.170370557","rc":[{"atb":[[1.21,0]],"id":9624350}],"con":true,"img":false}]}
{"op":"mcm","clk":"1362106043","pt":1588427849396,"mc":[{"id":"1.170370557","rc":[{"atb":[[1.2,62.1]],"id":9624350}],"con":true,"img":false}]}
{"op":"mcm","clk":"1362106046","pt":1588427849602,"mc":[{"id":"1.170370557","rc":[{"trd":[[1.23,1935.87]],"ltp":1.23,"tv":1935.87,"id":9624350},{"atb":[[1.23,801.1]],"id":9624350}],"con":true,"img":false}]}
{"op":"mcm","clk":"1362106047","pt":1588427849807,"mc":[{"id":"1.170370557","rc":[{"trd":[[1.23,1939.42]],"ltp":1.23,"tv":1939.42,"id":9624350},{"atb":[[1.23,799.33]],"id":9624350}],"con":true,"img":false}]}
{"op":"mcm","clk":"1362106050","pt":1588427849966,"mc":[{"id":"1.170370557","rc":[{"trd":[[1.23,1942.96]],"ltp":1.23,"tv":1942.96,"id":9624350},{"atb":[[1.23,797.56]],"id":9624350}],"con":true,"img":false}]}
{"op":"mcm","clk":"1362106052","pt":1588427850168,"mc":[{"id":"1.170370557","rc":[{"trd":[[1.23,1946.51]],"ltp":1.23,"tv":1946.51,"id":9624350},{"atb":[[1.23,795.79]],"id":9624350}],"con":true,"img":false}]}
{"op":"mcm","clk":"1362106057","pt":1588427850576,"mc":[{"id":"1.170370557","rc":[{"atl":[[1.28,0]],"id":9624350}],"con":true,"img":false}]}
{"op":"mcm","clk":"1362106059","pt":1588427850779,"mc":[{"id":"1.170370557","rc":[{"atb":[[1.23,444]],"id":9624350}],"con":true,"img":false}]}
{"op":"mcm","clk":"1362106060","pt":1588427850880,"mc":[{"id":"1.170370557","rc":[{"trd":[[1.24,2845.28]],"ltp":1.24,"tv":2845.28,"id":9624350},{"atb":[[1.24,367.58]],"id":9624350},{"atl":[[1.24,0]],"id":9624350}],"con":true,"img":false}]}
{"op":"mcm","clk":"1362106061","pt":1588427851495,"mc":[{"id":"1.170370557","rc":[{"atb":[[1.17,1264.89]],"id":9624350}],"con":true,"img":false}]}
{"op":"mcm","clk":"1362106063","pt":1588427851701,"mc":[{"id":"1.170370557","rc":[{"trd":[[1.24,2945.28]],"ltp":1.24,"tv":2945.28,"id":9624350},{"atb":[[1.24,317.58]],"id":9624350}],"con":true,"img":false}]}
{"op":"mcm","clk":"1362106066","pt":1588427851905,"mc":[{"id":"1.170370557","rc":[{"trd":[[1.24,2948.82]],"ltp":1.24,"tv":2948.82,"id":9624350},{"atb":[[1.24,315.81]],"id":9624350}],"con":true,"img":false}]}
{"op":"mcm","clk":"1362106067","pt":1588427852007,"mc":[{"id":"1.170370557","rc":[{"trd":[[5,16.03]],"ltp":5.0,"tv":16.03,"id":9622734},{"atb":[[5,38.2]],"id":9622734},{"trd":[[1.25,2133.21]],"ltp":1.25,"tv":2133.21,"id":9624350}],"con":true,"img":false}]}
{"op":"mcm","clk":"1362106068","pt":1588427852109,"mc":[{"id":"1.170370557","rc":[{"trd":[[1.24,2952.37]],"ltp":1.24,"tv":2952.37,"id":9624350},{"atb":[[1.19,772.24],[1.24,814.04]],"id":9624350}],"con":true,"img":false}]}
{"op":"mcm","clk":"1362106072","pt":1588427852369,"mc":[{"id":"1.170370557","rc":[{"trd":[[5,27.83]],"ltp":5.0,"tv":27.83,"id":9622734},{"atb":[[5,26.4]],"id":9622734},{"trd":[[1.25,2180.41],[1.24,2955.91]],"ltp":1.25,"tv":5136.32,"id":9624350},{"atb":[[1.24,1033.9]],"id":9624350}],"con":true,"img":false}]}
{"op":"mcm","clk":"1362106073","pt":1588427852471,"mc":[{"id":"1.170370557","rc":[{"trd":[[1.24,2990.95]],"ltp":1.24,"tv":2990.95,"id":9624350},{"atb":[[1.24,1016.38]],"id":9624350}],"con":true,"img":false}]}
{"op":"mcm","clk":"1362106075","pt":1588427852576,"mc":[{"id":"1.170370557","rc":[{"trd":[[1.24,2994.49]],"ltp":1.24,"tv":2994.49,"id":9624350},{"atb":[[1.24,1014.61]],"id":9624350}],"con":true,"img":false}]}
{"op":"mcm","clk":"1362106078","pt":1588427852676,"mc":[{"id":"1.170370557","rc":[{"atb":[[1.13,625]],"id":9624350}],"con":true,"img":false}]}
{"op":"mcm","clk":"1362106081","pt":1588427852780,"mc":[{"id":"1.170370557","rc":[{"trd":[[1.24,2998.03]],"ltp":1.24,"tv":2998.03,"id":9624350},{"atb":[[1.24,1012.84]],"id":9624350}],"con":true,"img":false}]}
{"op":"mcm","clk":"1362106086","pt":1588427853187,"mc":[{"id":"1.170370557","rc":[{"trd":[[1.24,3033.02]],"ltp":1.24,"tv":3033.02,"id":9624350},{"atb":[[1.24,995.35]],"id":9624350}],"con":true,"img":false}]}
{"op":"mcm","clk":"1362106089","pt":1588427853290,"mc":[{"id":"1.170370557","rc":[{"trd":[[1.24,3036.56]],"ltp":1.24,"tv":3036.56,"id":9624350},{"atb":[[1.24,993.58]],"id":9624350}],"con":true,"img":false}]}
{"op":"mcm","clk":"1362106090","pt":1588427853393,"mc":[{"id":"1.170370557","rc":[{"trd":[[1.24,3040.1]],"ltp":1.24,"tv":3040.1,"id":9624350},{"atb":[[1.24,991.81]],"id":9624350}],"con":true,"img":false}]}
{"op":"mcm","clk":"1362106092","pt":1588427853493,"mc":[{"id":"1.170370557","rc":[{"trd":[[1.24,3043.65]],"ltp":1.24,"tv":3043.65,"id":9624350},{"atb":[[1.24,990.04]],"id":9624350}],"con":true,"img":false}]}
{"op":"mcm","clk":"1362106094","pt":1588427853699,"mc":[{"id":"1.170370557","rc":[{"trd":[[1.24,3047.19]],"ltp":1.24,"tv":3047.19,"id":9624350},{"atb":[[1.24,988.27]],"id":9624350}],"con":true,"img":false}]}
{"op":"mcm","clk":"1362106098","pt":1588427853908,"mc":[{"id":"1.170370557","rc":[{"trd":[[1.24,3050.73]],"ltp":1.24,"tv":3050.73,"id":9624350},{"atb":[[1.24,986.5]],"id":9624350},{"atl":[[1.48,0.1]],"id":9624350}],"con":true,"img":false}]}
{"op":"mcm","clk":"1362106103","pt":1588427854213,"mc":[{"id":"1.170370557","rc":[{"atb":[[1.17,821.63]],"id":9624350}],"con":true,"img":false}]}
{"op":"mcm","clk":"1362106106","pt":1588427854413,"mc":[{"id":"1.170370557","rc":[{"trd":[[1.24,3054.28]],"ltp":1.24,"tv":3054.28,"id":9624350},{"atb":[[1.24,984.73]],"id":9624350}],"con":true,"img":false}]}
{"op":"mcm","clk":"1362106110","pt":1588427854618,"mc":[{"id":"1.170370557","rc":[{"trd":[[1.24,3057.82]],"ltp":1.24,"tv":3057.82,"id":9624350},{"atb":[[1.24,982.96]],"id":9624350}],"con":true,"img":false}]}
{"op":"mcm","clk":"1362106112","pt":1588427854674,"mc":[{"id":"1.170370557","rc":[{"atl":[[1000,1.77]],"id":9624350}],"con":true,"img":false}]}
{"op":"mcm","clk":"1362106116","pt":1588427854979,"mc":[{"id":"1.170370557","rc":[{"atl":[[1000,1.75]],"id":9624350}],"con":true,"img":false}]}
{"op":"mcm","clk":"1362106118","pt":1588427855083,"mc":[{"id":"1.170370557","rc":[{"atl":[[1000,3.52]],"id":9624350}],"con":true,"img":false}]}
{"op":"mcm","clk":"1362106120","pt":1588427855182,"mc":[{"id":"1.170370557","rc":[{"atl":[[1.25,221.63]],"id":9624350}],"con":true,"img":false}]}
{"op":"mcm","clk":"1362106122","pt":1588427855285,"mc":[{"id":"1.170370557","rc":[{"atl":[[1000,1.77]],"id":9624350}],"con":true,"img":false}]}
{"op":"mcm","clk":"1362106124","pt":1588427855393,"mc":[{"id":"1.170370557","rc":[{"atl":[[1000,1.75]],"id":9624350}],"con":true,"img":false}]}
{"op":"mcm","clk":"1362106126","pt":1588427855492,"mc":[{"id":"1.170370557","rc":[{"trd":[[1.24,3064.86]],"ltp":1.24,"tv":3064.86,"id":9624350},{"atb":[[1.24,979.44]],"id":9624350}],"con":true,"img":false}]}
{"op":"mcm","clk":"1362106129","pt":1588427855697,"mc":[{"id":"1.170370557","rc":[{"atl":[[1.33,443.26],[1000,0]],"id":9624350}],"con":true,"img":false}]}
{"op":"mcm","clk":"1362106144","pt":1588427857184,"mc":[{"id":"1.170370557","rc":[{"atb":[[1.14,492.02]],"id":9624350}],"con":true,"img":false}]}
{"op":"mcm","clk":"1362106146","pt":1588427857391,"mc":[{"id":"1.170370557","rc":[{"atl":[[1.25,0]],"id":9624350}],"con":true,"img":false}]}
{"op":"mcm","clk":"1362106157","pt":1588427858514,"mc":[{"id":"1.170370557","rc":[{"atb":[[1.22,487.58]],"id":9624350}],"con":true,"img":false}]}
{"op":"mcm","clk":"1362106160","pt":1588427858718,"mc":[{"id":"1.170370557","rc":[{"atl":[[1.29,221.63]],"id":9624350}],"con":true,"img":false}]}
{"op":"mcm","clk":"1362106165","pt":1588427859126,"mc":[{"id":"1.170370557","rc":[{"trd":[[5,54.23]],"ltp":5.0,"tv":54.23,"id":9622734},{"atb":[[5,0]],"id":9622734},{"trd":[[1.25,2286.01]],"ltp":1.25,"tv":2286.01,"id":9624350},{"atb":[[1.23,0],[1.27,386.41]],"id":9624350}],"con":true,"img":false}]}
{"op":"mcm","clk":"1362106169","pt":1588427859286,"mc":[{"id":"1.170370557","rc":[{"atb":[[1.18,843.26]],"id":9624350},{"atl":[[1.29,0]],"id":9624350}],"con":true,"img":false}]}
{"op":"mcm","clk":"1362106173","pt":1588427859695,"mc":[{"id":"1.170370557","rc":[{"atb":[[1.26,444]],"id":9624350}],"con":true,"img":false}]}
{"op":"mcm","clk":"1362106174","pt":1588427860204,"mc":[{"id":"1.170370557","rc":[{"atb":[[1.28,444]],"id":9624350}],"con":true,"img":false}]}
{"op":"mcm","clk":"1362106177","pt":1588427860409,"mc":[{"id":"1.170370557","rc":[{"trd":[[1.28,931.26]],"ltp":1.28,"tv":931.26,"id":9624350},{"atb":[[1.28,442.24]],"id":9624350}],"con":true,"img":false}]}
{"op":"mcm","clk":"1362106178","pt":1588427860510,"mc":[{"id":"1.170370557","rc":[{"atb":[[1.25,310.28]],"id":9624350}],"con":true,"img":false}]}
{"op":"mcm","clk":"1362106181","pt":1588427860816,"mc":[{"id":"1.170370557","rc":[{"trd":[[1.28,934.77]],"ltp":1.28,"tv":934.77,"id":9624350},{"atb":[[1.28,440.48]],"id":9624350}],"con":true,"img":false}]}
{"op":"mcm","clk":"1362106183","pt":1588427861021,"mc":[{"id":"1.170370557","rc":[{"trd":[[1.28,939.93]],"ltp":1.28,"tv":939.93,"id":9624350},{"atb":[[1.28,437.9],[1.27,829.68]],"id":9624350}],"con":true,"img":false}]}
{"op":"mcm","clk":"1362106188","pt":1588427861283,"mc":[{"id":"1.170370557","rc":[{"atb":[[1.27,918.33]],"id":9624350}],"con":true,"img":false}]}
{"op":"mcm","clk":"1362106191","pt":1588427861485,"mc":[{"id":"1.170370557","rc":[{"atb":[[1.27,1006.98]],"id":9624350}],"con":true,"img":false}]}
{"op":"mcm","clk":"1362106197","pt":1588427861895,"mc":[{"id":"1.170370557","rc":[{"atb":[[1.27,1329.68],[1.19,421.63],[1.22,221.63]],"id":9624350}],"con":true,"img":false}]}
{"op":"mcm","clk":"1362106200","pt":1588427862101,"mc":[{"id":"1.170370557","rc":[{"atb":[[1.25,0]],"id":9624350}],"con":true,"img":false}]}
{"op":"mcm","clk":"1362106207","pt":1588427862710,"mc":[{"id":"1.170370557","rc":[{"atb":[[1.26,0]],"id":9624350}],"con":true,"img":false}]}
{"op":"mcm","clk":"1362106209","pt":1588427862813,"mc":[{"id":"1.170370557","rc":[{"atb":[[1.18,1133.28]],"id":9624350}],"con":true,"img":false}]}
{"op":"mcm","clk":"1362106217","pt":1588427863323,"mc":[{"id":"1.170370557","rc":[{"atb":[[1.18,690.01]],"id":9624350}],"con":true,"img":false}]}
{"op":"mcm","clk":"1362106224","pt":1588427863998,"mc":[{"id":"1.170370557","rc":[{"trd":[[1.28,945.61]],"ltp":1.28,"tv":945.61,"id":9624350},{"atb":[[1.28,435.06]],"id":9624350}],"con":true,"img":false}]}
{"op":"mcm","clk":"1362106228","pt":1588427864302,"mc":[{"id":"1.170370557","rc":[{"atb":[[1.26,50]],"id":9624350}],"con":true,"img":false}]}
{"op":"mcm","clk":"1362106230","pt":1588427864405,"mc":[{"id":"1.170370557","rc":[{"trd":[[1.28,1155.17]],"ltp":1.28,"tv":1155.17,"id":9624350},{"atb":[[1.28,330.28]],"id":9624350}],"con":true,"img":false}]}
{"op":"mcm","clk":"1362106233","pt":1588427864714,"mc":[{"id":"1.170370557","rc":[{"trd":[[1.28,1247.89]],"ltp":1.28,"tv":1247.89,"id":9624350},{"atb":[[1.28,283.92]],"id":9624350}],"con":true,"img":false}]}
{"op":"mcm","clk":"1362106236","pt":1588427864917,"mc":[{"id":"1.170370557","rc":[{"atb":[[1.28,340.14]],"id":9624350}],"con":true,"img":false}]}
{"op":"mcm","clk":"1362106238","pt":1588427865225,"mc":[{"id":"1.170370557","rc":[{"atb":[[1.27,1379.68]],"id":9624350}],"con":true,"img":false}]}
{"op":"mcm","clk":"1362106239","pt":1588427865328,"mc":[{"id":"1.170370557","rc":[{"atb":[[1.28,561.77]],"id":9624350}],"con":true,"img":false}]}
{"op":"mcm","clk":"1362106245","pt":1588427865894,"mc":[{"id":"1.170370557","rc":[{"atb":[[1.28,555.55]],"id":9624350}],"con":true,"img":false}]}
{"op":"mcm","clk":"1362106253","pt":1588427866404,"mc":[{"id":"1.170370557","rc":[{"atb":[[1.29,50]],"id":9624350}],"con":true,"img":false}]}
{"op":"mcm","clk":"1362106254","pt":1588427866608,"mc":[{"id":"1.170370557","rc":[{"atb":[[1.26,0]],"id":9624350}],"con":true,"img":false}]}
{"op":"mcm","clk":"1362106255","pt":1588427867220,"mc":[{"id":"1.170370557","rc":[{"atb":[[1.29,55.54]],"id":9624350}],"con":true,"img":false}]}
{"op":"mcm","clk":"1362106257","pt":1588427867323,"mc":[{"id":"1.170370557","rc":[{"atb":[[1.27,1329.68]],"id":9624350}],"con":true,"img":false}]}
{"op":"mcm","clk":"1362106259","pt":1588427867630,"mc":[{"id":"1.170370557","rc":[{"atb":[[1.27,443.26]],"id":9624350}],"con":true,"img":false}]}
{"op":"mcm","clk":"1362106260","pt":1588427867732,"mc":[{"id":"1.170370557","rc":[{"atb":[[1.23,443.26]],"id":9624350}],"con":true,"img":false}]}
{"op":"mcm","clk":"1362106261","pt":1588427867834,"mc":[{"id":"1.170370557","rc":[{"atb":[[1.28,644.2]],"id":9624350}],"con":true,"img":false}]}
{"op":"mcm","clk":"1362106265","pt":1588427868141,"mc":[{"id":"1.170370557","rc":[{"atb":[[1.28,660.02]],"id":9624350}],"con":true,"img":false}]}
{"op":"mcm","clk":"1362106269","pt":1588427868243,"mc":[{"id":"1.170370557","rc":[{"atl":[[1.31,221.63]],"id":9624350}],"con":true,"img":false}]}
{"op":"mcm","clk":"1362106270","pt":1588427868295,"mc":[{"id":"1.170370557","rc":[{"atb":[[1.29,144.19]],"id":9624350}],"con":true,"img":false}]}
{"op":"mcm","clk":"1362106274","pt":1588427868500,"mc":[{"id":"1.170370557","rc":[{"atb":[[1.28,610.02]],"id":9624350}],"con":true,"img":false}]}
{"op":"mcm","clk":"1362106275","pt":1588427868602,"mc":[{"id":"1.170370557","rc":[{"atb":[[1.29,232.84]],"id":9624350}],"con":true,"img":false}]}
{"op":"mcm","clk":"1362106283","pt":1588427869113,"mc":[{"id":"1.170370557","rc":[{"trd":[[1.29,550.31]],"ltp":1.29,"tv":550.31,"id":9624350},{"atb":[[1.29,215.32]],"id":9624350}],"con":true,"img":false}]}
{"op":"mcm","clk":"1362106289","pt":1588427869930,"mc":[{"id":"1.170370557","rc":[{"atb":[[1.3,24.05]],"id":9624350}],"con":true,"img":false}]}
{"op":"mcm","clk":"1362106292","pt":1588427870236,"mc":[{"id":"1.170370557","rc":[{"atl":[[1.42,443.26]],"id":9624350}],"con":true,"img":false}]}
{"op":"mcm","clk":"1362106295","pt":1588427870645,"mc":[{"id":"1.170370557","rc":[{"atl":[[1.48,0]],"id":9624350}],"con":true,"img":false}]}
{"op":"mcm","clk":"1362106298","pt":1588427870849,"mc":[{"id":"1.170370557","rc":[{"atb":[[1.29,182.84]],"id":9624350}],"con":true,"img":false}]}
{"op":"mcm","clk":"1362106299","pt":1588427871211,"mc":[{"id":"1.170370557","rc":[{"atb":[[1.28,326.1]],"id":9624350}],"con":true,"img":false}]}
{"op":"mcm","clk":"1362106301","pt":1588427871318,"mc":[{"id":"1.170370557","rc":[{"atb":[[1.27,0]],"id":9624350}],"con":true,"img":false}]}
{"op":"mcm","clk":"1362106305","pt":1588427871824,"mc":[{"id":"1.170370557","rc":[{"atb":[[1.29,682.84]],"id":9624350}],"con":true,"img":false}]}
{"op":"mcm","clk":"1362106316","pt":1588427872639,"mc":[{"id":"1.170370557","rc":[{"atl":[[1.32,17.73]],"id":9624350}],"con":true,"img":false}]}
{"op":"mcm","clk":"1362106321","pt":1588427872844,"mc":[{"id":"1.170370557","rc":[{"atb":[[1.29,686.1]],"id":9624350}],"con":true,"img":false}]}
{"op":"mcm","clk":"1362106325","pt":1588427873357,"mc":[{"id":"1.170370557","rc":[{"atl":[[1.33,0]],"id":9624350}],"con":true,"img":false}]}
{"op":"mcm","clk":"1362106335","pt":1588427874751,"mc":[{"id":"1.170370557","rc":[{"trd":[[1.3,566.5]],"ltp":1.3,"tv":566.5,"id":9624350},{"atb":[[1.3,22.28],[1.29,682.84]],"id":9624350},{"atl":[[1.37,221.63]],"id":9624350}],"con":true,"img":false}]}
{"op":"mcm","clk":"1362106336","pt":1588427874853,"mc":[{"id":"1.170370557","rc":[{"atl":[[1.31,0]],"id":9624350}],"con":true,"img":false}]}
{"op":"mcm","clk":"1362106338","pt":1588427874955,"mc":[{"id":"1.170370557","rc":[{"trd":[[1.3,570.05]],"ltp":1.3,"tv":570.05,"id":9624350},{"atb":[[1.3,20.5]],"id":9624350}],"con":true,"img":false}]}
{"op":"mcm","clk":"1362106342","pt":1588427875160,"mc":[{"id":"1.170370557","rc":[{"trd":[[1.3,573.6]],"ltp":1.3,"tv":573.6,"id":9624350},{"atb":[[1.3,18.73]],"id":9624350}],"con":true,"img":false}]}
{"op":"mcm","clk":"1362106344","pt":1588427875364,"mc":[{"id":"1.170370557","rc":[{"trd":[[1.3,577.14]],"ltp":1.3,"tv":577.14,"id":9624350},{"atb":[[1.3,16.96]],"id":9624350}],"con":true,"img":false}]}
{"op":"mcm","clk":"1362106350","pt":1588427876032,"mc":[{"id":"1.170370557","rc":[{"atb":[[1.3,0]],"id":9624350}],"con":true,"img":false}]}
{"op":"mcm","clk":"1362106364","pt":1588427878134,"mc":[{"id":"1.170370557","rc":[{"atl":[[4.2,10]],"id":9622734}],"con":true,"img":false}]}
{"op":"mcm","clk":"1362106370","pt":1588427878745,"mc":[{"id":"1.170370557","rc":[{"trd":[[4.2,10.42]],"ltp":4.2,"tv":10.42,"id":9622734},{"atl":[[4.2,0]],"id":9622734},{"trd":[[1.31,77.97]],"ltp":1.31,"tv":77.97,"id":9624350},{"atl":[[1.3,189.57]],"id":9624350}],"con":true,"img":false}]}
{"op":"mcm","clk":"1362106382","pt":1588427879972,"mc":[{"id":"1.170370557","rc":[{"trd":[[1.3,583.58]],"ltp":1.3,"tv":583.58,"id":9624350},{"atl":[[1.3,203.85]],"id":9624350}],"con":true,"img":false}]}
{"op":"mcm","clk":"1362106392","pt":1588427880638,"mc":[{"id":"1.170370557","rc":[{"atb":[[1.25,59.61]],"id":9624350}],"con":true,"img":false}]}
{"op":"mcm","clk":"1362106408","pt":1588427882750,"mc":[{"id":"1.170370557","rc":[{"atl":[[1.32,0]],"id":9624350}],"con":true,"img":false}]}
{"op":"mcm","clk":"1362106418","pt":1588427883363,"mc":[{"id":"1.170370557","rc":[{"trd":[[1.3,584.14]],"ltp":1.3,"tv":584.14,"id":9624350},{"atl":[[1.3,203.56]],"id":9624350}],"con":true,"img":false}]}
{"op":"mcm","clk":"1362106420","pt":1588427883465,"mc":[{"id":"1.170370557","rc":[{"atl":[[1.3,204.62]],"id":9624350}],"con":true,"img":false}]}
{"op":"mcm","clk":"1362106424","pt":1588427883976,"mc":[{"id":"1.170370557","rc":[{"trd":[[1.3,592.89]],"ltp":1.3,"tv":592.89,"id":9624350},{"atl":[[1.3,200.25]],"id":9624350}],"con":true,"img":false}]}
{"op":"mcm","clk":"1362106430","pt":1588427884848,"mc":[{"id":"1.170370557","rc":[{"atb":[[1.28,310.28]],"id":9624350}],"con":true,"img":false}]}
{"op":"mcm","clk":"1362106446","pt":1588427886076,"mc":[{"id":"1.170370557","rc":[{"atl":[[1.3,18.55]],"id":9624350}],"con":true,"img":false}]}
{"op":"mcm","clk":"1362106447","pt":1588427886179,"mc":[{"id":"1.170370557","rc":[{"atb":[[1.18,400]],"id":9624350},{"atl":[[1.49,0]],"id":9624350}],"con":true,"img":false}]}
{"op":"mcm","clk":"1362106466","pt":1588427887870,"mc":[{"id":"1.170370557","rc":[{"atl":[[1.36,17.73]],"id":9624350}],"con":true,"img":false}]}
{"op":"mcm","clk":"1362106480","pt":1588427889763,"mc":[{"id":"1.170370557","rc":[{"atl":[[1.3,17.49]],"id":9624350}],"con":true,"img":false}]}
{"op":"mcm","clk":"1362106495","pt":1588427891659,"mc":[{"id":"1.170370557","rc":[{"trd":[[1.3,622.43]],"ltp":1.3,"tv":622.43,"id":9624350},{"atl":[[1.3,2.72],[1.33,221.63]],"id":9624350}],"con":true,"img":false}]}
{"op":"mcm","clk":"1362106498","pt":1588427891864,"mc":[{"id":"1.170370557","rc":[{"atb":[[1.2,342.17]],"id":9624350},{"atl":[[1.66,345.34]],"id":9624350}],"con":true,"img":false}]}
{"op":"mcm","clk":"1362106504","pt":1588427892883,"mc":[{"id":"1.170370557","rc":[{"trd":[[1.3,627.87]],"ltp":1.3,"tv":627.87,"id":9624350},{"atb":[[1.3,72.28]],"id":9624350},{"atl":[[1.3,0]],"id":9624350}],"con":true,"img":false}]}
{"op":"mcm","clk":"1362106505","pt":1588427892985,"mc":[{"id":"1.170370557","rc":[{"atb":[[1.3,74.9]],"id":9624350}],"con":true,"img":false}]}
{"op":"mcm","clk":"1362106507","pt":1588427893190,"mc":[{"id":"1.170370557","rc":[{"atb":[[1.26,75]],"id":9624350}],"con":true,"img":false}]}
{"op":"mcm","clk":"1362106508","pt":1588427893598,"mc":[{"id":"1.170370557","rc":[{"atb":[[1.25,134.61]],"id":9624350}],"con":true,"img":false}]}
{"op":"mcm","clk":"1362106517","pt":1588427894979,"mc":[{"id":"1.170370557","rc":[{"atl":[[8.4,0]],"id":9622734}],"con":true,"img":false}]}
{"op":"mcm","clk":"1362106541","pt":1588427896262,"mc":[{"id":"1.170370557","rc":[{"atb":[[1.3,72.28]],"id":9624350}],"con":true,"img":false}]}
{"op":"mcm","clk":"1362106545","pt":1588427896569,"mc":[{"id":"1.170370557","rc":[{"atb":[[1.31,0.46]],"id":9624350}],"con":true,"img":false}]}
{"op":"mcm","clk":"1362106560","pt":1588427897692,"mc":[{"id":"1.170370557","rc":[{"atb":[[1.29,771.49]],"id":9624350}],"con":true,"img":false}]}
{"op":"mcm","clk":"1362106564","pt":1588427898101,"mc":[{"id":"1.170370557","rc":[{"atb":[[1.3,160.93]],"id":9624350}],"con":true,"img":false}]}
{"op":"mcm","clk":"1362106566","pt":1588427898203,"mc":[{"id":"1.170370557","rc":[{"trd":[[1.3,629.97],[1.31,78.9]],"ltp":1.3,"tv":708.87,"id":9624350},{"atb":[[1.31,0],[1.3,748.53]],"id":9624350}],"con":true,"img":false}]}
{"op":"mcm","clk":"1362106573","pt":1588427898766,"mc":[{"id":"1.170370557","rc":[{"atb":[[1.28,221.63]],"id":9624350}],"con":true,"img":false}]}
{"op":"mcm","clk":"1362106575","pt":1588427898971,"mc":[{"id":"1.170370557","rc":[{"atb":[[1.24,1025.8]],"id":9624350}],"con":true,"img":false}]}
{"op":"mcm","clk":"1362106590","pt":1588427900606,"mc":[{"id":"1.170370557","rc":[{"atb":[[1.24,267.99]],"id":9624350}],"con":true,"img":false}]}
{"op":"mcm","clk":"1362106598","pt":1588427901175,"mc":[{"id":"1.170370557","rc":[{"atb":[[1.2,62.1]],"id":9624350},{"atl":[[1.66,39.45]],"id":9624350}],"con":true,"img":false}]}
{"op":"mcm","clk":"1362106606","pt":1588427901482,"mc":[{"id":"1.170370557","rc":[{"trd":[[1.33,18.26]],"ltp":1.33,"tv":18.26,"id":9624350},{"atl":[[1.33,219]],"id":9624350}],"con":true,"img":false}]}
{"op":"mcm","clk":"1362106618","pt":1588427902606,"mc":[{"id":"1.170370557","rc":[{"atl":[[1.36,0],[1.33,0]],"id":9624350}],"con":true,"img":false}]}
{"op":"mcm","clk":"1362106623","pt":1588427902969,"mc":[{"id":"1.170370557","rc":[{"atb":[[1.23,0]],"id":9624350}],"con":true,"img":false}]}
{"op":"mcm","clk":"1362106627","pt":1588427903174,"mc":[{"id":"1.170370557","rc":[{"atb":[[1.34,492.02]],"id":9624350}],"con":true,"img":false}]}
{"op":"mcm","clk":"1362106634","pt":1588427903680,"mc":[{"id":"1.170370557","rc":[{"atl":[[1.37,0]],"id":9624350}],"con":true,"img":false}]}
{"op":"mcm","clk":"1362106638","pt":1588427903986,"mc":[{"id":"1.170370557","rc":[{"atb":[[1.35,500]],"id":9624350}],"con":true,"img":false}]}
{"op":"mcm","clk":"1362106642","pt":1588427904395,"mc":[{"id":"1.170370557","rc":[{"atb":[[1.34,890.95]],"id":9624350}],"con":true,"img":false}]}
{"op":"mcm","clk":"1362106643","pt":1588427904497,"mc":[{"id":"1.170370557","rc":[{"atb":[[1.34,979.6]],"id":9624350}],"con":true,"img":false}]}
{"op":"mcm","clk":"1362106646","pt":1588427904703,"mc":[{"id":"1.170370557","rc":[{"atb":[[1.34,1068.26]],"id":9624350}],"con":true,"img":false}]}
{"op":"mcm","clk":"1362106648","pt":1588427904805,"mc":[{"id":"1.170370557","rc":[{"atb":[[1.12,492.02],[1.33,112],[1.34,1156.91]],"id":9624350}],"con":true,"img":false}]}
{"op":"mcm","clk":"1362106652","pt":1588427905010,"mc":[{"id":"1.170370557","rc":[{"atl":[[1.41,145.32]],"id":9624350}],"con":true,"img":false}]}
{"op":"mcm","clk":"1362106655","pt":1588427905112,"mc":[{"id":"1.170370557","rc":[{"atb":[[1.29,500]],"id":9624350}],"con":true,"img":false}]}
{"op":"mcm","clk":"1362106659","pt":1588427905371,"mc":[{"id":"1.170370557","rc":[{"atb":[[1.34,846.63],[1.3,571.23]],"id":9624350}],"con":true,"img":false}]}
{"op":"mcm","clk":"1362106662","pt":1588427905473,"mc":[{"id":"1.170370557","rc":[{"atb":[[1.33,224]],"id":9624350}],"con":true,"img":false}]}
{"op":"mcm","clk":"1362106671","pt":1588427905881,"mc":[{"id":"1.170370557","rc":[{"atb":[[1.33,667.26]],"id":9624350}],"con":true,"img":false}]}
{"op":"mcm","clk":"1362106683","pt":1588427907107,"mc":[{"id":"1.170370557","rc":[{"atb":[[1.28,664.89]],"id":9624350}],"con":true,"img":false}]}
{"op":"mcm","clk":"1362106691","pt":1588427907876,"mc":[{"id":"1.170370557","rc":[{"atb":[[1.22,497.54]],"id":9624350},{"atl":[[1.71,285.97]],"id":9624350}],"con":true,"img":false}]}
{"op":"mcm","clk":"1362106696","pt":1588427908388,"mc":[{"id":"1.170370557","rc":[{"atl":[[4.2,2.48]],"id":9622734}],"con":true,"img":false}]}
{"op":"mcm","clk":"1362106701","pt":1588427908796,"mc":[{"id":"1.170370557","rc":[{"atb":[[1.37,52.52]],"id":9624350}],"con":true,"img":false}]}
{"op":"mcm","clk":"1362106709","pt":1588427909511,"mc":[{"id":"1.170370557","rc":[{"atl":[[1.41,366.95]],"id":9624350}],"con":true,"img":false}]}
{"op":"mcm","clk":"1362106715","pt":1588427909974,"mc":[{"id":"1.170370557","rc":[{"atb":[[1.36,112]],"id":9624350}],"con":true,"img":false}]}
{"op":"mcm","clk":"1362106722","pt":1588427910385,"mc":[{"id":"1.170370557","rc":[{"atb":[[1.37,164.52]],"id":9624350}],"con":true,"img":false}]}
{"op":"mcm","clk":"1362106726","pt":1588427910689,"mc":[{"id":"1.170370557","rc":[{"atb":[[1.36,333.63]],"id":9624350}],"con":true,"img":false}]}
{"op":"mcm","clk":"1362106729","pt":1588427910790,"mc":[{"id":"1.170370557","rc":[{"trd":[[1.41,378.15]],"ltp":1.41,"tv":378.15,"id":9624350},{"atl":[[1.41,133.55]],"id":9624350}],"con":true,"img":false}]}
{"op":"mcm","clk":"1362106731","pt":1588427910993,"mc":[{"id":"1.170370557","rc":[{"atb":[[1.36,422.28]],"id":9624350}],"con":true,"img":false}]}
{"op":"mcm","clk":"1362106732","pt":1588427911095,"mc":[{"id":"1.170370557","rc":[{"atb":[[1.36,510.93]],"id":9624350}],"con":true,"img":false}]}
{"op":"mcm","clk":"1362106735","pt":1588427911299,"mc":[{"id":"1.170370557","rc":[{"atb":[[1.36,599.58]],"id":9624350}],"con":true,"img":false}]}
{"op":"mcm","clk":"1362106737","pt":1588427911401,"mc":[{"id":"1.170370557","rc":[{"atb":[[1.36,688.24]],"id":9624350}],"con":true,"img":false}]}
{"op":"mcm","clk":"1362106740","pt":1588427911607,"mc":[{"id":"1.170370557","rc":[{"atb":[[1.36,776.89]],"id":9624350}],"con":true,"img":false}]}
{"op":"mcm","clk":"1362106741","pt":1588427911709,"mc":[{"id":"1.170370557","rc":[{"atl":[[1.4,17.73]],"id":9624350}],"con":true,"img":false}]}
{"op":"mcm","clk":"1362106744","pt":1588427911914,"mc":[{"id":"1.170370557","rc":[{"atl":[[1.39,221.63]],"id":9624350}],"con":true,"img":false}]}
{"op":"mcm","clk":"1362106764","pt":1588427914122,"mc":[{"id":"1.170370557","rc":[{"atb":[[1.34,492.02]],"id":9624350}],"con":true,"img":false}]}
{"op":"mcm","clk":"1362106781","pt":1588427916219,"mc":[{"id":"1.170370557","rc":[{"atb":[[1.28,221.63]],"id":9624350}],"con":true,"img":false}]}
{"op":"mcm","clk":"1362106785","pt":1588427916681,"mc":[{"id":"1.170370557","rc":[{"atb":[[1.33,669.74]],"id":9624350}],"con":true,"img":false}]}
{"op":"mcm","clk":"1362106787","pt":1588427916884,"mc":[{"id":"1.170370557","rc":[{"atb":[[1.36,333.63]],"id":9624350}],"con":true,"img":false}]}
{"op":"mcm","clk":"1362106798","pt":1588427917704,"mc":[{"id":"1.170370557","rc":[{"trd":[[1.39,883.26]],"ltp":1.39,"tv":883.26,"id":9624350},{"atb":[[1.37,112]],"id":9624350},{"atl":[[1.39,202.76]],"id":9624350}],"con":true,"img":false}]}
{"op":"mcm","clk":"1362106805","pt":1588427918216,"mc":[{"id":"1.170370557","rc":[{"atl":[[1.45,221.63]],"id":9624350}],"con":true,"img":false}]}
{"op":"mcm","clk":"1362106808","pt":1588427918827,"mc":[{"id":"1.170370557","rc":[{"atl":[[1.46,443.26]],"id":9624350}],"con":true,"img":false}]}
{"op":"mcm","clk":"1362106819","pt":1588427919800,"mc":[{"id":"1.170370557","rc":[{"trd":[[1.39,883.95]],"ltp":1.39,"tv":883.95,"id":9624350},{"atl":[[1.39,202.42]],"id":9624350}],"con":true,"img":false}]}
{"op":"mcm","clk":"1362106826","pt":1588427920515,"mc":[{"id":"1.170370557","rc":[{"atb":[[1.37,200.65]],"id":9624350}],"con":true,"img":false}]}
{"op":"mcm","clk":"1362106828","pt":1588427920718,"mc":[{"id":"1.170370557","rc":[{"atb":[[1.37,289.3]],"id":9624350}],"con":true,"img":false}]}
{"op":"mcm","clk":"1362106830","pt":1588427920922,"mc":[{"id":"1.170370557","rc":[{"atb":[[1.37,377.95]],"id":9624350}],"con":true,"img":false}]}
{"op":"mcm","clk":"1362106831","pt":1588427921126,"mc":[{"id":"1.170370557","rc":[{"atb":[[1.37,466.6]],"id":9624350}],"con":true,"img":false}]}
{"op":"mcm","clk":"1362106835","pt":1588427921433,"mc":[{"id":"1.170370557","rc":[{"trd":[[1.39,885.84]],"ltp":1.39,"tv":885.84,"id":9624350},{"atl":[[1.39,201.48]],"id":9624350}],"con":true,"img":false}]}
{"op":"mcm","clk":"1362106837","pt":1588427921536,"mc":[{"id":"1.170370557","rc":[{"atl":[[1.41,0]],"id":9624350}],"con":true,"img":false}]}
{"op":"mcm","clk":"1362106840","pt":1588427921692,"mc":[{"id":"1.170370557","rc":[{"atb":[[1.34,0]],"id":9624350}],"con":true,"img":false}]}
{"op":"mcm","clk":"1362106844","pt":1588427921999,"mc":[{"id":"1.170370557","rc":[{"trd":[[1.39,1158.6]],"ltp":1.39,"tv":1158.6,"id":9624350},{"atl":[[1.39,65.09]],"id":9624350}],"con":true,"img":false}]}
{"op":"mcm","clk":"1362106857","pt":1588427923431,"mc":[{"id":"1.170370557","rc":[{"trd":[[3.55,3.62]],"ltp":3.55,"tv":3.62,"id":9622734},{"trd":[[1.39,1166.93]],"ltp":1.39,"tv":1166.93,"id":9624350},{"atl":[[1.39,58.37]],"id":9624350}],"con":true,"img":false}]}
{"op":"mcm","clk":"1362106861","pt":1588427923737,"mc":[{"id":"1.170370557","rc":[{"trd":[[3.55,8.05]],"ltp":3.55,"tv":8.05,"id":9622734},{"trd":[[1.39,1178.26]],"ltp":1.39,"tv":1178.26,"id":9624350},{"atl":[[1.39,47.05]],"id":9624350}],"con":true,"img":false}]}
{"op":"mcm","clk":"1362106868","pt":1588427924200,"mc":[{"id":"1.170370557","rc":[{"trd":[[1.37,200]],"ltp":1.37,"tv":200.0,"id":9624350},{"atb":[[1.37,366.6]],"id":9624350}],"con":true,"img":false}]}
{"op":"mcm","clk":"1362106896","pt":1588427926240,"mc":[{"id":"1.170370557","rc":[{"trd":[[1.39,1180.88]],"ltp":1.39,"tv":1180.88,"id":9624350},{"atl":[[1.39,45.74]],"id":9624350}],"con":true,"img":false}]}
{"op":"mcm","clk":"1362106903","pt":1588427926704,"mc":[{"id":"1.170370557","rc":[{"atl":[[1.38,136.46]],"id":9624350}],"con":true,"img":false}]}
{"op":"mcm","clk":"1362106912","pt":1588427928439,"mc":[{"id":"1.170370557","rc":[{"trd":[[1.37,235.03]],"ltp":1.37,"tv":235.03,"id":9624350},{"atb":[[1.37,349.09]],"id":9624350}],"con":true,"img":false}]}
{"op":"mcm","clk":"1362106913","pt":1588427928648,"mc":[{"id":"1.170370557","rc":[{"atl":[[1.41,83.41]],"id":9624350}],"con":true,"img":false}]}
{"op":"mcm","clk":"1362106929","pt":1588427930954,"mc":[{"id":"1.170370557","rc":[{"trd":[[3.6,1.17]],"ltp":3.6,"tv":1.17,"id":9622734},{"trd":[[1.38,3.86]],"ltp":1.38,"tv":3.86,"id":9624350},{"atl":[[1.38,133.38]],"id":9624350}],"con":true,"img":false}]}
{"op":"mcm","clk":"1362106931","pt":1588427931010,"mc":[{"id":"1.170370557","rc":[{"atl":[[1.41,184.05]],"id":9624350}],"con":true,"img":false}]}
{"op":"mcm","clk":"1362106941","pt":1588427932233,"mc":[{"id":"1.170370557","rc":[{"atb":[[1.22,221.63]],"id":9624350},{"atl":[[1.71,0]],"id":9624350}],"con":true,"img":false}]}
{"op":"mcm","clk":"1362106961","pt":1588427933821,"mc":[{"id":"1.170370557","rc":[{"atl":[[1.39,0]],"id":9624350}],"con":true,"img":false}]}
{"op":"mcm","clk":"1362106974","pt":1588427935144,"mc":[{"id":"1.170370557","rc":[{"atl":[[1.45,0]],"id":9624350}],"con":true,"img":false}]}
{"op":"mcm","clk":"1362106980","pt":1588427935859,"mc":[{"id":"1.170370557","rc":[{"atb":[[1.35,0]],"id":9624350}],"con":true,"img":false}]}
{"op":"mcm","clk":"1362106985","pt":1588427936633,"mc":[{"id":"1.170370557","rc":[{"atl":[[1.42,0]],"id":9624350}],"con":true,"img":false}]}
{"op":"mcm","clk":"1362106991","pt":1588427937344,"mc":[{"id":"1.170370557","rc":[{"trd":[[1.38,4.07]],"ltp":1.38,"tv":4.07,"id":9624350},{"atl":[[1.38,133.28]],"id":9624350}],"con":true,"img":false}]}
{"op":"mcm","clk":"1362107000","pt":1588427938058,"mc":[{"id":"1.170370557","rc":[{"atl":[[1.41,100.64]],"id":9624350}],"con":true,"img":false}]}
{"op":"mcm","clk":"1362107002","pt":1588427938160,"mc":[{"id":"1.170370557","rc":[{"atb":[[1.36,221.63]],"id":9624350}],"con":true,"img":false}]}
{"op":"mcm","clk":"1362107006","pt":1588427938468,"mc":[{"id":"1.170370557","rc":[{"atl":[[1.5,171.01],[1.38,0]],"id":9624350}],"con":true,"img":false}]}
{"op":"mcm","clk":"1362107010","pt":1588427938829,"mc":[{"id":"1.170370557","rc":[{"trd":[[3.4,5.81]],"ltp":3.4,"tv":5.81,"id":9622734},{"atb":[[3.4,0]],"id":9622734},{"trd":[[1.42,374.21],[1.4,1630.66],[1.41,579.43]],"ltp":1.42,"tv":2584.3,"id":9624350},{"atb":[[1.42,359.72]],"id":9624350},{"atl":[[1.4,0],[1.41,0]],"id":9624350}],"con":true,"img":false}]}
{"op":"mcm","clk":"1362107013","pt":1588427939033,"mc":[{"id":"1.170370557","rc":[{"atl":[[1.5,191.01]],"id":9624350}],"con":true,"img":false}]}
{"op":"mcm","clk":"1362107017","pt":1588427939237,"mc":[{"id":"1.170370557","rc":[{"atb":[[1.4,221.63]],"id":9624350}],"con":true,"img":false}]}
{"op":"mcm","clk":"1362107031","pt":1588427940364,"mc":[{"id":"1.170370557","rc":[{"atb":[[1.38,8.86]],"id":9624350}],"con":true,"img":false}]}
{"op":"mcm","clk":"1362107049","pt":1588427941449,"mc":[{"id":"1.170370557","rc":[{"atb":[[1.3,71.23]],"id":9624350},{"atl":[[1.46,0]],"id":9624350}],"con":true,"img":false}]}
{"op":"mcm","clk":"1362107056","pt":1588427941760,"mc":[{"id":"1.170370557","rc":[{"atb":[[1.39,492.02]],"id":9624350}],"con":true,"img":false}]}
{"op":"mcm","clk":"1362107064","pt":1588427942074,"mc":[{"id":"1.170370557","rc":[{"atb":[[1.29,0]],"id":9624350}],"con":true,"img":false}]}
{"op":"mcm","clk":"1362107083","pt":1588427943267,"mc":[{"id":"1.170370557","rc":[{"atb":[[1.26,0],[1.33,445.74],[1.25,59.61],[1.3,0]],"id":9624350}],"con":true,"img":false}]}
{"op":"mcm","clk":"1362107084","pt":1588427943369,"mc":[{"id":"1.170370557","rc":[{"atb":[[1.39,984.04]],"id":9624350}],"con":true,"img":false}]}
{"op":"mcm","clk":"1362107091","pt":1588427944042,"mc":[{"id":"1.170370557","rc":[{"atl":[[1.43,131.37]],"id":9624350}],"con":true,"img":false}]}
{"op":"mcm","clk":"1362107101","pt":1588427944555,"mc":[{"id":"1.170370557","rc":[{"atl":[[1.5,229.41]],"id":9624350}],"con":true,"img":false}]}
{"op":"mcm","clk":"1362107109","pt":1588427945172,"mc":[{"id":"1.170370557","rc":[{"atl":[[1.5,151.01]],"id":9624350}],"con":true,"img":false}]}
{"op":"mcm","clk":"1362107110","pt":1588427945276,"mc":[{"id":"1.170370557","rc":[{"trd":[[1.43,1677.99]],"ltp":1.43,"tv":1677.99,"id":9624350},{"atl":[[1.43,42.72]],"id":9624350}],"con":true,"img":false}]}
{"op":"mcm","clk":"1362107115","pt":1588427945378,"mc":[{"id":"1.170370557","rc":[{"trd":[[1.43,1763.44]],"ltp":1.43,"tv":1763.44,"id":9624350},{"atb":[[1.43,45.93]],"id":9624350},{"atl":[[1.43,0]],"id":9624350}],"con":true,"img":false}]}
{"op":"mcm","clk":"1362107120","pt":1588427945539,"mc":[{"id":"1.170370557","rc":[{"atb":[[1.43,134.58]],"id":9624350},{"atl":[[1.45,11.34]],"id":9624350}],"con":true,"img":false}]}
{"op":"mcm","clk":"1362107126","pt":1588427945944,"mc":[{"id":"1.170370557","rc":[{"atb":[[1.39,0]],"id":9624350}],"con":true,"img":false}]}
{"op":"mcm","clk":"1362107141","pt":1588427946862,"mc":[{"id":"1.170370557","rc":[{"atl":[[1.45,55.34]],"id":9624350}],"con":true,"img":false}]}
{"op":"mcm","clk":"1362107146","pt":1588427947372,"mc":[{"id":"1.170370557","rc":[{"atb":[[1.33,2.48]],"id":9624350}],"con":true,"img":false}]}
{"op":"mcm","clk":"1362107147","pt":1588427947474,"mc":[{"id":"1.170370557","rc":[{"atl":[[1.49,44]],"id":9624350}],"con":true,"img":false}]}
{"op":"mcm","clk":"1362107149","pt":1588427947678,"mc":[{"id":"1.170370557","rc":[{"atb":[[1.4,0]],"id":9624350}],"con":true,"img":false}]}
{"op":"mcm","clk":"1362107152","pt":1588427947781,"mc":[{"id":"1.170370557","rc":[{"atl":[[1.45,11.34]],"id":9624350}],"con":true,"img":false}]}
{"op":"mcm","clk":"1362107160","pt":1588427948652,"mc":[{"id":"1.170370557","rc":[{"atl":[[1.59,300]],"id":9624350}],"con":true,"img":false}]}
{"op":"mcm","clk":"1362107162","pt":1588427948751,"mc":[{"id":"1.170370557","rc":[{"atb":[[1.36,0]],"id":9624350}],"con":true,"img":false}]}
{"op":"mcm","clk":"1362107169","pt":1588427949159,"mc":[{"id":"1.170370557","rc":[{"atb":[[1.42,534.72]],"id":9624350}],"con":true,"img":false}]}
{"op":"mcm","clk":"1362107176","pt":1588427949568,"mc":[{"id":"1.170370557","rc":[{"atl":[[1.61,300]],"id":9624350}],"con":true,"img":false}]}
{"op":"mcm","clk":"1362107177","pt":1588427949671,"mc":[{"id":"1.170370557","rc":[{"atb":[[1.43,309.58],[1.41,17.59]],"id":9624350}],"con":true,"img":false}]}
{"op":"mcm","clk":"1362107182","pt":1588427950283,"mc":[{"id":"1.170370557","rc":[{"atl":[[1.62,300]],"id":9624350}],"con":true,"img":false}]}
{"op":"mcm","clk":"1362107183","pt":1588427950385,"mc":[{"id":"1.170370557","rc":[{"atb":[[1.43,134.58]],"id":9624350}],"con":true,"img":false}]}
{"op":"mcm","clk":"1362107188","pt":1588427950745,"mc":[{"id":"1.170370557","rc":[{"atl":[[1.47,443.26]],"id":9624350}],"con":true,"img":false}]}
{"op":"mcm","clk":"1362107191","pt":1588427951155,"mc":[{"id":"1.170370557","rc":[{"atl":[[1.49,219]],"id":9624350}],"con":true,"img":false}]}
{"op":"mcm","clk":"1362107196","pt":1588427951664,"mc":[{"id":"1.170370557","rc":[{"atb":[[1.41,460.85]],"id":9624350}],"con":true,"img":false}]}
{"op":"mcm","clk":"1362107199","pt":1588427952685,"mc":[{"id":"1.170370557","rc":[{"atb":[[3.25,5]],"id":9622734}],"con":true,"img":false}]}
{"op":"mcm","clk":"1362107202","pt":1588427952889,"mc":[{"id":"1.170370557","rc":[{"atl":[[1.46,44]],"id":9624350}],"con":true,"img":false}]}
{"op":"mcm","clk":"1362107206","pt":1588427953196,"mc":[{"id":"1.170370557","rc":[{"trd":[[3.25,7.18]],"ltp":3.25,"tv":7.18,"id":9622734},{"atb":[[3.25,0]],"id":9622734},{"trd":[[1.46,373.41],[1.45,857.83]],"ltp":1.46,"tv":1231.23,"id":9624350},{"atl":[[1.46,18.55],[1.45,0]],"id":9624350}],"con":true,"img":false}]}
{"op":"mcm","clk":"1362107210","pt":1588427953658,"mc":[{"id":"1.170370557","rc":[{"atb":[[1.42,359.72]],"id":9624350}],"con":true,"img":false}]}
{"op":"mcm","clk":"1362107215","pt":1588427954167,"mc":[{"id":"1.170370557","rc":[{"atb":[[1.39,175]],"id":9624350}],"con":true,"img":false}]}
{"op":"mcm","clk":"1362107223","pt":1588427954881,"mc":[{"id":"1.170370557","rc":[{"atl":[[1.45,44.21]],"id":9624350}],"con":true,"img":false}]}
{"op":"mcm","clk":"1362107225","pt":1588427954983,"mc":[{"id":"1.170370557","rc":[{"atb":[[1.38,0]],"id":9624350}],"con":true,"img":false}]}
{"op":"mcm","clk":"1362107233","pt":1588427955852,"mc":[{"id":"1.170370557","rc":[{"atb":[[1.42,0]],"id":9624350}],"con":true,"img":false}]}
{"op":"mcm","clk":"1362107234","pt":1588427955954,"mc":[{"id":"1.170370557","rc":[{"atl":[[1.49,237.08]],"id":9624350}],"con":true,"img":false}]}
{"op":"mcm","clk":"1362107236","pt":1588427956055,"mc":[{"id":"1.170370557","rc":[{"atb":[[1.44,0.92]],"id":9624350}],"con":true,"img":false}]}
{"op":"mcm","clk":"1362107240","pt":1588427956463,"mc":[{"id":"1.170370557","rc":[{"atb":[[1.44,0.74]],"id":9624350}],"con":true,"img":false}]}
{"op":"mcm","clk":"1362107244","pt":1588427956869,"mc":[{"id":"1.170370557","rc":[{"atb":[[1.44,222.37]],"id":9624350}],"con":true,"img":false}]}
{"op":"mcm","clk":"1362107252","pt":1588427958197,"mc":[{"id":"1.170370557","rc":[{"trd":[[1.44,2856.53]],"ltp":1.44,"tv":2856.53,"id":9624350},{"atb":[[1.44,221.19]],"id":9624350}],"con":true,"img":false}]}
{"op":"mcm","clk":"1362107256","pt":1588427958558,"mc":[{"id":"1.170370557","rc":[{"trd":[[1.45,869.66]],"ltp":1.45,"tv":869.66,"id":9624350},{"atl":[[1.45,38.3]],"id":9624350}],"con":true,"img":false}]}
{"op":"mcm","clk":"1362107262","pt":1588427959068,"mc":[{"id":"1.170370557","rc":[{"trd":[[1.45,876.59],[1.44,2856.74]],"ltp":1.45,"tv":3733.33,"id":9624350},{"atb":[[1.44,221.09]],"id":9624350},{"atl":[[1.45,34.84]],"id":9624350}],"con":true,"img":false}]}
{"op":"mcm","clk":"1362107265","pt":1588427959270,"mc":[{"id":"1.170370557","rc":[{"atl":[[1.46,240.18]],"id":9624350}],"con":true,"img":false}]}
{"op":"mcm","clk":"1362108049","pt":1588427959678,"mc":[{"id":"1.170370557","rc":[{"atb":[[1.44,272.84]],"id":9624350}],"con":true,"img":false}]}
{"op":"mcm","clk":"1362108060","pt":1588427960599,"mc":[{"id":"1.170370557","rc":[{"atb":[[1.44,221.09]],"id":9624350}],"con":true,"img":false}]}
{"op":"mcm","clk":"1362108083","pt":1588427962185,"mc":[{"id":"1.170370557","rc":[{"trd":[[1.45,880.14]],"ltp":1.45,"tv":880.14,"id":9624350},{"atl":[[1.45,33.06]],"id":9624350}],"con":true,"img":false}]}
{"op":"mcm","clk":"1362108084","pt":1588427962287,"mc":[{"id":"1.170370557","rc":[{"trd":[[1.45,883.08]],"ltp":1.45,"tv":883.08,"id":9624350},{"atl":[[1.45,31.59]],"id":9624350}],"con":true,"img":false}]}
{"op":"mcm","clk":"1362108086","pt":1588427962595,"mc":[{"id":"1.170370557","rc":[{"atb":[[3.25,50.87]],"id":9622734},{"atl":[[1.59,0],[1.62,0],[1.61,0]],"id":9624350}],"con":true,"img":false}]}
{"op":"mcm","clk":"1362108095","pt":1588427965097,"mc":[{"id":"1.170370557","rc":[{"atb":[[1.44,222.12]],"id":9624350}],"con":true,"img":false}]}
{"op":"mcm","clk":"1362108098","pt":1588427965306,"mc":[{"id":"1.170370557","rc":[{"atb":[[1.28,0]],"id":9624350}],"con":true,"img":false}]}
{"op":"mcm","clk":"1362108102","pt":1588427965768,"mc":[{"id":"1.170370557","rc":[{"atb":[[3.2,8.05]],"id":9622734}],"con":true,"img":false}]}
{"op":"mcm","clk":"1362108105","pt":1588427965972,"mc":[{"id":"1.170370557","rc":[{"atb":[[1.24,46.36]],"id":9624350}],"con":true,"img":false}]}
{"op":"mcm","clk":"1362108107","pt":1588427966074,"mc":[{"id":"1.170370557","rc":[{"atl":[[1.46,253.33]],"id":9624350}],"con":true,"img":false}]}
{"op":"mcm","clk":"1362108111","pt":1588427966283,"mc":[{"id":"1.170370557","rc":[{"trd":[[1.44,2875.12]],"ltp":1.44,"tv":2875.12,"id":9624350},{"atb":[[1.44,212.93]],"id":9624350}],"con":true,"img":false}]}
{"op":"mcm","clk":"1362108114","pt":1588427966382,"mc":[{"id":"1.170370557","rc":[{"trd":[[1.45,918.54]],"ltp":1.45,"tv":918.54,"id":9624350},{"atl":[[1.45,13.86]],"id":9624350}],"con":true,"img":false}]}
{"op":"mcm","clk":"1362108116","pt":1588427966485,"mc":[{"id":"1.170370557","rc":[{"atb":[[1.42,175],[1.22,0]],"id":9624350}],"con":true,"img":false}]}
{"op":"mcm","clk":"1362108121","pt":1588427966995,"mc":[{"id":"1.170370557","rc":[{"trd":[[1.45,920.4]],"ltp":1.45,"tv":920.4,"id":9624350},{"atl":[[1.45,12.93]],"id":9624350}],"con":true,"img":false}]}
{"op":"mcm","clk":"1362108122","pt":1588427967098,"mc":[{"id":"1.170370557","rc":[{"atb":[[1.19,200]],"id":9624350}],"con":true,"img":false}]}
{"op":"mcm","clk":"1362108125","pt":1588427967405,"mc":[{"id":"1.170370557","rc":[{"trd":[[1.45,925.55]],"ltp":1.45,"tv":925.55,"id":9624350},{"atl":[[1.45,10.35]],"id":9624350}],"con":true,"img":false}]}
{"op":"mcm","clk":"1362108146","pt":1588427968887,"mc":[{"id":"1.170370557","rc":[{"atb":[[1.17,600]],"id":9624350}],"con":true,"img":false}]}
{"op":"mcm","clk":"1362108152","pt":1588427969305,"mc":[{"id":"1.170370557","rc":[{"atl":[[1.45,76.35]],"id":9624350}],"con":true,"img":false}]}
{"op":"mcm","clk":"1362108163","pt":1588427970023,"mc":[{"id":"1.170370557","rc":[{"trd":[[1.45,1060.26]],"ltp":1.45,"tv":1060.26,"id":9624350},{"atl":[[1.45,9]],"id":9624350}],"con":true,"img":false}]}
{"op":"mcm","clk":"1362108166","pt":1588427970179,"mc":[{"id":"1.170370557","rc":[{"trd":[[1.44,2910.16]],"ltp":1.44,"tv":2910.16,"id":9624350},{"atb":[[1.44,195.41]],"id":9624350}],"con":true,"img":false}]}
{"op":"mcm","clk":"1362108171","pt":1588427970382,"mc":[{"id":"1.170370557","rc":[{"trd":[[1.44,2950.16]],"ltp":1.44,"tv":2950.16,"id":9624350},{"atb":[[1.44,175.41]],"id":9624350}],"con":true,"img":false}]}
{"op":"mcm","clk":"1362108198","pt":1588427972179,"mc":[{"id":"1.170370557","rc":[{"trd":[[1.44,2970.16]],"ltp":1.44,"tv":2970.16,"id":9624350},{"atb":[[1.44,165.41]],"id":9624350}],"con":true,"img":false}]}
{"op":"mcm","clk":"1362108202","pt":1588427972381,"mc":[{"id":"1.170370557","rc":[{"atl":[[1.46,240.18]],"id":9624350}],"con":true,"img":false}]}
{"op":"mcm","clk":"1362108208","pt":1588427973200,"mc":[{"id":"1.170370557","rc":[{"atb":[[1.41,17.59]],"id":9624350},{"atl":[[1.47,0]],"id":9624350}],"con":true,"img":false}]}
{"op":"mcm","clk":"1362108216","pt":1588427973711,"mc":[{"id":"1.170370557","rc":[{"trd":[[1.44,3010.16]],"ltp":1.44,"tv":3010.16,"id":9624350},{"atb":[[1.44,145.41]],"id":9624350}],"con":true,"img":false}]}
{"op":"mcm","clk":"1362108219","pt":1588427973813,"mc":[{"id":"1.170370557","rc":[{"atb":[[1.44,144.37]],"id":9624350}],"con":true,"img":false}]}
{"op":"mcm","clk":"1362108228","pt":1588427975092,"mc":[{"id":"1.170370557","rc":[{"trd":[[1.44,3187.46]],"ltp":1.44,"tv":3187.46,"id":9624350},{"atb":[[1.44,55.72]],"id":9624350},{"atl":[[1000,3.19]],"id":9624350}],"con":true,"img":false}]}
{"op":"mcm","clk":"1362108231","pt":1588427975297,"mc":[{"id":"1.170370557","rc":[{"trd":[[1.43,1764.36],[1.44,3298.92]],"ltp":1.43,"tv":5063.28,"id":9624350},{"atb":[[1.43,134.12],[1.44,0]],"id":9624350},{"atl":[[1.44,32.92]],"id":9624350}],"con":true,"img":false}]}
{"op":"mcm","clk":"1362108233","pt":1588427975503,"mc":[{"id":"1.170370557","rc":[{"atl":[[1000,0.79]],"id":9624350}],"con":true,"img":false}]}
{"op":"mcm","clk":"1362108235","pt":1588427975605,"mc":[{"id":"1.170370557","rc":[{"atb":[[1.42,0]],"id":9624350}],"con":true,"img":false}]}
{"op":"mcm","clk":"1362108238","pt":1588427975911,"mc":[{"id":"1.170370557","rc":[{"atl":[[1000,0]],"id":9624350}],"con":true,"img":false}]}
{"op":"mcm","clk":"1362108241","pt":1588427976319,"mc":[{"id":"1.170370557","rc":[{"trd":[[1.44,3307.44]],"ltp":1.44,"tv":3307.44,"id":9624350},{"atl":[[1.44,28.66]],"id":9624350}],"con":true,"img":false}]}
{"op":"mcm","clk":"1362108243","pt":1588427976625,"mc":[{"id":"1.170370557","rc":[{"atb":[[3.2,0]],"id":9622734}],"con":true,"img":false}]}
{"op":"mcm","clk":"1362108247","pt":1588427976985,"mc":[{"id":"1.170370557","rc":[{"trd":[[1.45,1063.73],[1.44,3364.76]],"ltp":1.45,"tv":4428.49,"id":9624350},{"atl":[[1.44,0],[1.45,7.26]],"id":9624350}],"con":true,"img":false}]}
{"op":"mcm","clk":"1362108256","pt":1588427977493,"mc":[{"id":"1.170370557","rc":[{"atl":[[1.44,1079.62]],"id":9624350}],"con":true,"img":false}]}
{"op":"mcm","clk":"1362108274","pt":1588427978622,"mc":[{"id":"1.170370557","rc":[{"atl":[[1.48,443.26]],"id":9624350}],"con":true,"img":false}]}
{"op":"mcm","clk":"1362108283","pt":1588427979389,"mc":[{"id":"1.170370557","rc":[{"atb":[[1.39,618.26]],"id":9624350}],"con":true,"img":false}]}
{"op":"mcm","clk":"1362108291","pt":1588427979800,"mc":[{"id":"1.170370557","rc":[{"atl":[[1.49,219]],"id":9624350}],"con":true,"img":false}]}
{"op":"mcm","clk":"1362108293","pt":1588427979902,"mc":[{"id":"1.170370557","rc":[{"atl":[[1.46,221.63]],"id":9624350}],"con":true,"img":false}]}
{"op":"mcm","clk":"1362108305","pt":1588427980824,"mc":[{"id":"1.170370557","rc":[{"atb":[[1.39,443.26]],"id":9624350},{"atl":[[1.44,0]],"id":9624350}],"con":true,"img":false}]}
{"op":"mcm","clk":"1362108308","pt":1588427981029,"mc":[{"id":"1.170370557","rc":[{"atl":[[1.44,0.79]],"id":9624350}],"con":true,"img":false}]}
{"op":"mcm","clk":"1362108319","pt":1588427982931,"mc":[{"id":"1.170370557","rc":[{"atb":[[3.3,7.8]],"id":9622734},{"atl":[[1.49,44]],"id":9624350}],"con":true,"img":false}]}
{"op":"mcm","clk":"1362108326","pt":1588427983699,"mc":[{"id":"1.170370557","rc":[{"trd":[[1.43,1805.58]],"ltp":1.43,"tv":1805.58,"id":9624350},{"atb":[[1.43,113.51]],"id":9624350}],"con":true,"img":false}]}
{"op":"mcm","clk":"1362108330","pt":1588427984108,"mc":[{"id":"1.170370557","rc":[{"trd":[[1.44,3365.71]],"ltp":1.44,"tv":3365.71,"id":9624350},{"atl":[[1.44,0.32]],"id":9624350}],"con":true,"img":false}]}
{"op":"mcm","clk":"1362108333","pt":1588427984313,"mc":[{"id":"1.170370557","rc":[{"trd":[[1.43,1905.58]],"ltp":1.43,"tv":1905.58,"id":9624350},{"atb":[[1.43,63.51]],"id":9624350}],"con":true,"img":false}]}
{"op":"mcm","clk":"1362108338","pt":1588427984733,"mc":[{"id":"1.170370557","rc":[{"atl":[[1.44,0]],"id":9624350}],"con":true,"img":false}]}
{"op":"mcm","clk":"1362108341","pt":1588427985031,"mc":[{"id":"1.170370557","rc":[{"trd":[[3.3,0.21]],"ltp":3.3,"tv":0.21,"id":9622734},{"atb":[[3.3,7.59]],"id":9622734},{"trd":[[1.44,3366.18],[1.43,1942.68]],"ltp":1.44,"tv":5308.86,"id":9624350},{"atb":[[1.43,44.96]],"id":9624350}],"con":true,"img":false}]}
{"op":"mcm","clk":"1362108351","pt":1588427985902,"mc":[{"id":"1.170370557","rc":[{"trd":[[1.43,2032.61]],"ltp":1.43,"tv":2032.61,"id":9624350},{"atb":[[1.43,0]],"id":9624350},{"atl":[[1.43,1034.65]],"id":9624350}],"con":true,"img":false}]}
{"op":"mcm","clk":"1362108354","pt":1588427986209,"mc":[{"id":"1.170370557","rc":[{"trd":[[1.41,604.38]],"ltp":1.41,"tv":604.38,"id":9624350},{"atb":[[1.41,5.12]],"id":9624350}],"con":true,"img":false}]}
{"op":"mcm","clk":"1362108358","pt":1588427986516,"mc":[{"id":"1.170370557","rc":[{"atl":[[1.49,0]],"id":9624350}],"con":true,"img":false}]}
{"op":"mcm","clk":"1362108373","pt":1588427988416,"mc":[{"id":"1.170370557","rc":[{"atl":[[1.43,1067.65]],"id":9624350}],"con":true,"img":false}]}
{"op":"mcm","clk":"1362108376","pt":1588427988724,"mc":[{"id":"1.170370557","rc":[{"atb":[[1.37,0]],"id":9624350}],"con":true,"img":false}]}
{"op":"mcm","clk":"1362108388","pt":1588427989853,"mc":[{"id":"1.170370557","rc":[{"trd":[[1.41,605.03]],"ltp":1.41,"tv":605.03,"id":9624350},{"atb":[[1.41,4.79]],"id":9624350},{"atl":[[1.55,221.63]],"id":9624350}],"con":true,"img":false}]}
{"op":"mcm","clk":"1362108418","pt":1588427992115,"mc":[{"id":"1.170370557","rc":[{"atl":[[1.43,1067.88]],"id":9624350}],"con":true,"img":false}]}
{"op":"mcm","clk":"1362108419","pt":1588427992218,"mc":[{"id":"1.170370557","rc":[{"atl":[[1.43,33.23]],"id":9624350}],"con":true,"img":false}]}
{"op":"mcm","clk":"1362108423","pt":1588427992525,"mc":[{"id":"1.170370557","rc":[{"atb":[[3.3,0]],"id":9622734}],"con":true,"img":false}]}
{"op":"mcm","clk":"1362108431","pt":1588427993141,"mc":[{"id":"1.170370557","rc":[{"trd":[[1.43,2033.66]],"ltp":1.43,"tv":2033.66,"id":9624350},{"atl":[[1.43,32.7]],"id":9624350}],"con":true,"img":false}]}
{"op":"mcm","clk":"1362108439","pt":1588427993755,"mc":[{"id":"1.170370557","rc":[{"atl":[[1.43,34.31]],"id":9624350}],"con":true,"img":false}]}
{"op":"mcm","clk":"1362108445","pt":1588427994013,"mc":[{"id":"1.170370557","rc":[{"atb":[[3.35,37.43]],"id":9622734}],"con":true,"img":false}]}
{"op":"mcm","clk":"1362108448","pt":1588427994114,"mc":[{"id":"1.170370557","rc":[{"atb":[[1.39,0]],"id":9624350},{"atl":[[1.48,0]],"id":9624350}],"con":true,"img":false}]}
{"op":"mcm","clk":"1362108466","pt":1588427995342,"mc":[{"id":"1.170370557","rc":[{"atb":[[1.25,109.61]],"id":9624350}],"con":true,"img":false}]}
{"op":"mcm","clk":"1362108487","pt":1588427996727,"mc":[{"id":"1.170370557","rc":[{"trd":[[3.45,1.96]],"ltp":3.45,"tv":1.96,"id":9622734},{"atb":[[3.45,5.3]],"id":9622734},{"trd":[[1.41,609.83]],"ltp":1.41,"tv":609.83,"id":9624350},{"atb":[[1.41,0]],"id":9624350}],"con":true,"img":false}]}
{"op":"mcm","clk":"1362108492","pt":1588427997237,"mc":[{"id":"1.170370557","rc":[{"atl":[[1000,1.45]],"id":9622734}],"con":true,"img":false}]}
{"op":"mcm","clk":"1362108494","pt":1588427997341,"mc":[{"id":"1.170370557","rc":[{"atl":[[1.41,1034.65]],"id":9624350}],"con":true,"img":false}]}
{"op":"mcm","clk":"1362108510","pt":1588427999032,"mc":[{"id":"1.170370557","rc":[{"atl":[[1.54,78.08]],"id":9624350}],"con":true,"img":false}]}
{"op":"mcm","clk":"1362108518","pt":1588427999544,"mc":[{"id":"1.170370557","rc":[{"atb":[[3.45,0]],"id":9622734}],"con":true,"img":false}]}
{"op":"mcm","clk":"1362108521","pt":1588427999963,"mc":[{"id":"1.170370557","rc":[{"atb":[[3.35,0]],"id":9622734}],"con":true,"img":false}]}
{"op":"mcm","clk":"1362108523","pt":1588428000058,"mc":[{"id":"1.170370557","rc":[{"atl":[[1.63,73.77]],"id":9624350}],"con":true,"img":false}]}
{"op":"mcm","clk":"1362108527","pt":1588428000266,"mc":[{"id":"1.170370557","rc":[{"trd":[[1.41,637.4]],"ltp":1.41,"tv":637.4,"id":9624350},{"atl":[[1.41,1020.87]],"id":9624350}],"con":true,"img":false}]}
{"op":"mcm","clk":"1362108552","pt":1588428001451,"mc":[{"id":"1.170370557","rc":[{"atb":[[3.25,0]],"id":9622734}],"con":true,"img":false}]}
{"op":"mcm","clk":"1362108584","pt":1588428003060,"mc":[{"id":"1.170370557","rc":[{"trd":[[1.41,699.79]],"ltp":1.41,"tv":699.79,"id":9624350},{"atl":[[1.41,989.67]],"id":9624350}],"con":true,"img":false}]}
{"op":"mcm","clk":"1362108596","pt":1588428004042,"mc":[{"id":"1.170370557","rc":[{"atl":[[1.4,62.95]],"id":9624350}],"con":true,"img":false}]}
{"op":"mcm","clk":"1362108625","pt":1588428005234,"mc":[{"id":"1.170370557","rc":[{"atb":[[3.45,36.34]],"id":9622734}],"con":true,"img":false}]}
{"op":"mcm","clk":"1362108634","pt":1588428005954,"mc":[{"id":"1.170370557","rc":[{"trd":[[1.4,1638.02]],"ltp":1.4,"tv":1638.02,"id":9624350},{"atl":[[1.4,59.27]],"id":9624350}],"con":true,"img":false}]}
{"op":"mcm","clk":"1362108660","pt":1588428007444,"mc":[{"id":"1.170370557","rc":[{"atb":[[1.34,17.73]],"id":9624350}],"con":true,"img":false}]}
{"op":"mcm","clk":"1362108665","pt":1588428008161,"mc":[{"id":"1.170370557","rc":[{"atb":[[1.34,106.38]],"id":9624350}],"con":true,"img":false}]}
{"op":"mcm","clk":"1362108668","pt":1588428008365,"mc":[{"id":"1.170370557","rc":[{"atb":[[1.34,195.03]],"id":9624350}],"con":true,"img":false}]}
{"op":"mcm","clk":"1362108672","pt":1588428008673,"mc":[{"id":"1.170370557","rc":[{"atb":[[1.34,283.68]],"id":9624350}],"con":true,"img":false}]}
{"op":"mcm","clk":"1362108675","pt":1588428008876,"mc":[{"id":"1.170370557","rc":[{"atb":[[1.34,372.34]],"id":9624350}],"con":true,"img":false}]}
{"op":"mcm","clk":"1362108679","pt":1588428009439,"mc":[{"id":"1.170370557","rc":[{"atl":[[1.43,34.08]],"id":9624350}],"con":true,"img":false}]}
{"op":"mcm","clk":"1362108690","pt":1588428010155,"mc":[{"id":"1.170370557","rc":[{"trd":[[3.5,12.75]],"ltp":3.5,"tv":12.75,"id":9622734},{"trd":[[1.4,1646.78]],"ltp":1.4,"tv":1646.78,"id":9624350},{"atl":[[1.4,50.51]],"id":9624350}],"con":true,"img":false}]}
{"op":"mcm","clk":"1362108727","pt":1588428012863,"mc":[{"id":"1.170370557","rc":[{"trd":[[3.5,26.05]],"ltp":3.5,"tv":26.05,"id":9622734},{"trd":[[1.4,1680.02]],"ltp":1.4,"tv":1680.02,"id":9624350},{"atl":[[1.4,17.26]],"id":9624350}],"con":true,"img":false}]}
{"op":"mcm","clk":"1362108731","pt":1588428013375,"mc":[{"id":"1.170370557","rc":[{"atl":[[1.43,32.47]],"id":9624350}],"con":true,"img":false}]}
{"op":"mcm","clk":"1362108734","pt":1588428013590,"mc":[{"id":"1.170370557","rc":[{"trd":[[1.4,1688.89]],"ltp":1.4,"tv":1688.89,"id":9624350},{"atl":[[1.4,12.83]],"id":9624350}],"con":true,"img":false}]}
{"op":"mcm","clk":"1362108739","pt":1588428013939,"mc":[{"id":"1.170370557","rc":[{"trd":[[3.5,26.92]],"ltp":3.5,"tv":26.92,"id":9622734},{"trd":[[1.4,1691.07]],"ltp":1.4,"tv":1691.07,"id":9624350},{"atl":[[1.4,10.65]],"id":9624350}],"con":true,"img":false}]}
{"op":"mcm","clk":"1362108747","pt":1588428014651,"mc":[{"id":"1.170370557","rc":[{"trd":[[1.34,171.63]],"ltp":1.34,"tv":171.63,"id":9624350},{"atb":[[1.34,372.23]],"id":9624350}],"con":true,"img":false}]}
{"op":"mcm","clk":"1362108750","pt":1588428015060,"mc":[{"id":"1.170370557","rc":[{"atl":[[1.43,0],[1.45,0]],"id":9624350}],"con":true,"img":false}]}
{"op":"mcm","clk":"1362108755","pt":1588428015775,"mc":[{"id":"1.170370557","rc":[{"atl":[[1.5,0]],"id":9624350}],"con":true,"img":false}]}
{"op":"mcm","clk":"1362108759","pt":1588428015983,"mc":[{"id":"1.170370557","rc":[{"trd":[[1.4,1712.38]],"ltp":1.4,"tv":1712.38,"id":9624350},{"atb":[[1.4,13.86]],"id":9624350},{"atl":[[1.4,0]],"id":9624350}],"con":true,"img":false}]}
{"op":"mcm","clk":"1362108781","pt":1588428018252,"mc":[{"id":"1.170370557","rc":[{"atb":[[1.4,16.44]],"id":9624350}],"con":true,"img":false}]}
{"op":"mcm","clk":"1362108796","pt":1588428019484,"mc":[{"id":"1.170370557","rc":[{"atb":[[1.4,21.08]],"id":9624350}],"con":true,"img":false}]}
{"op":"mcm","clk":"1362108797","pt":1588428019586,"mc":[{"id":"1.170370557","rc":[{"atb":[[1.4,7.21]],"id":9624350}],"con":true,"img":false}]}
{"op":"mcm","clk":"1362108808","pt":1588428020567,"mc":[{"id":"1.170370557","rc":[{"atb":[[1.35,108.16]],"id":9624350}],"con":true,"img":false}]}
{"op":"mcm","clk":"1362108823","pt":1588428021387,"mc":[{"id":"1.170370557","rc":[{"atl":[[1.53,221.63]],"id":9624350}],"con":true,"img":false}]}
{"op":"mcm","clk":"1362108828","pt":1588428021747,"mc":[{"id":"1.170370557","rc":[{"atb":[[1.4,95.19]],"id":9624350}],"con":true,"img":false}]}
{"op":"mcm","clk":"1362108835","pt":1588428022157,"mc":[{"id":"1.170370557","rc":[{"atb":[[1.2,66.53]],"id":9624350}],"con":true,"img":false}]}
{"op":"mcm","clk":"1362108843","pt":1588428022569,"mc":[{"id":"1.170370557","rc":[{"trd":[[1.4,1889.68]],"ltp":1.4,"tv":1889.68,"id":9624350},{"atb":[[1.4,6.55]],"id":9624350}],"con":true,"img":false}]}
{"op":"mcm","clk":"1362108856","pt":1588428023493,"mc":[{"id":"1.170370557","rc":[{"atb":[[1.4,6.76]],"id":9624350}],"con":true,"img":false}]}
{"op":"mcm","clk":"1362108867","pt":1588428024262,"mc":[{"id":"1.170370557","rc":[{"atl":[[1000,1.6]],"id":9622734}],"con":true,"img":false}]}
{"op":"mcm","clk":"1362108932","pt":1588428026773,"mc":[{"id":"1.170370557","rc":[{"trd":[[1.4,1903.22]],"ltp":1.4,"tv":1903.22,"id":9624350},{"atb":[[1.4,0]],"id":9624350},{"atl":[[1.38,13.23]],"id":9624350}],"con":true,"img":false}]}
{"op":"mcm","clk":"1362108936","pt":1588428027590,"mc":[{"id":"1.170370557","rc":[{"atb":[[3.1,5.9]],"id":9622734}],"con":true,"img":false}]}
{"op":"mcm","clk":"1362108940","pt":1588428027998,"mc":[{"id":"1.170370557","rc":[{"trd":[[1.41,738.21],[1.38,30.52]],"ltp":1.41,"tv":768.73,"id":9624350},{"atl":[[1.41,970.46],[1.38,0]],"id":9624350}],"con":true,"img":false}]}
{"op":"mcm","clk":"1362108950","pt":1588428029685,"mc":[{"id":"1.170370557","rc":[{"trd":[[1.41,800.6]],"ltp":1.41,"tv":800.6,"id":9624350},{"atl":[[1.41,939.26]],"id":9624350}],"con":true,"img":false}]}
{"op":"mcm","clk":"1362108953","pt":1588428029991,"mc":[{"id":"1.170370557","rc":[{"atl":[[1.39,1.61]],"id":9624350}],"con":true,"img":false}]}
{"op":"mcm","clk":"1362108962","pt":1588428031780,"mc":[{"id":"1.170370557","rc":[{"atl":[[1.4,0.25]],"id":9624350}],"con":true,"img":false}]}
{"op":"mcm","clk":"1362108972","pt":1588428033166,"mc":[{"id":"1.170370557","rc":[{"atl":[[1.4,0.72]],"id":9624350}],"con":true,"img":false}]}
{"op":"mcm","clk":"1362108992","pt":1588428034802,"mc":[{"id":"1.170370557","rc":[{"atb":[[1.34,354.6]],"id":9624350},{"atl":[[1.52,0.23]],"id":9624350}],"con":true,"img":false}]}
{"op":"mcm","clk":"1362108994","pt":1588428034905,"mc":[{"id":"1.170370557","rc":[{"atb":[[1.2,70.96]],"id":9624350}],"con":true,"img":false}]}
{"op":"mcm","clk":"1362109004","pt":1588428035880,"mc":[{"id":"1.170370557","rc":[{"atl":[[1.4,0.47]],"id":9624350}],"con":true,"img":false}]}
{"op":"mcm","clk":"1362109012","pt":1588428036494,"mc":[{"id":"1.170370557","rc":[{"atl":[[1.4,0.58]],"id":9624350}],"con":true,"img":false}]}
{"op":"mcm","clk":"1362109015","pt":1588428036801,"mc":[{"id":"1.170370557","rc":[{"atb":[[1.38,3.54]],"id":9624350}],"con":true,"img":false}]}
{"op":"mcm","clk":"1362109043","pt":1588428039872,"mc":[{"id":"1.170370557","rc":[{"atb":[[1.36,17.62]],"id":9624350}],"con":true,"img":false}]}
{"op":"mcm","clk":"1362109044","pt":1588428040075,"mc":[{"id":"1.170370557","rc":[{"atb":[[1.25,376.08]],"id":9624350},{"atl":[[1.77,264.1]],"id":9624350}],"con":true,"img":false}]}
{"op":"mcm","clk":"1362109047","pt":1588428040279,"mc":[{"id":"1.170370557","rc":[{"atb":[[3.1,0]],"id":9622734},{"atb":[[1.38,0]],"id":9624350}],"con":true,"img":false}]}
{"op":"mcm","clk":"1362109050","pt":1588428040383,"mc":[{"id":"1.170370557","rc":[{"atb":[[1.28,500]],"id":9624350}],"con":true,"img":false}]}
{"op":"mcm","clk":"1362109070","pt":1588428042226,"mc":[{"id":"1.170370557","rc":[{"atl":[[1.4,112.58]],"id":9624350}],"con":true,"img":false}]}
{"op":"mcm","clk":"1362109080","pt":1588428043098,"mc":[{"id":"1.170370557","rc":[{"trd":[[1.4,1907.98],[1.39,1184.11]],"ltp":1.4,"tv":3092.09,"id":9624350},{"atl":[[1.39,0],[1.4,110.21]],"id":9624350}],"con":true,"img":false}]}
{"op":"mcm","clk":"1362109084","pt":1588428043407,"mc":[{"id":"1.170370557","rc":[{"atl":[[1.48,112]],"id":9624350}],"con":true,"img":false}]}
{"op":"mcm","clk":"1362109089","pt":1588428044228,"mc":[{"id":"1.170370557","rc":[{"atb":[[3.5,5.23]],"id":9622734}],"con":true,"img":false}]}
{"op":"mcm","clk":"1362109121","pt":1588428046793,"mc":[{"id":"1.170370557","rc":[{"atl":[[1.55,664.89]],"id":9624350}],"con":true,"img":false}]}
{"op":"mcm","clk":"1362109128","pt":1588428047409,"mc":[{"id":"1.170370557","rc":[{"atl":[[1.48,0],[1.4,0]],"id":9624350}],"con":true,"img":false}]}
{"op":"mcm","clk":"1362109135","pt":1588428047819,"mc":[{"id":"1.170370557","rc":[{"atb":[[3.5,0]],"id":9622734}],"con":true,"img":false}]}
{"op":"mcm","clk":"1362109137","pt":1588428047921,"mc":[{"id":"1.170370557","rc":[{"atl":[[1.38,88.65]],"id":9624350}],"con":true,"img":false}]}
{"op":"mcm","clk":"1362109141","pt":1588428048127,"mc":[{"id":"1.170370557","rc":[{"atl":[[1.38,177.3]],"id":9624350}],"con":true,"img":false}]}
{"op":"mcm","clk":"1362109147","pt":1588428048690,"mc":[{"id":"1.170370557","rc":[{"atl":[[1.38,0]],"id":9624350}],"con":true,"img":false}]}
{"op":"mcm","clk":"1362109150","pt":1588428048895,"mc":[{"id":"1.170370557","rc":[{"atb":[[1.39,12.26]],"id":9624350}],"con":true,"img":false}]}
{"op":"mcm","clk":"1362109156","pt":1588428049101,"mc":[{"id":"1.170370557","rc":[{"atl":[[1.55,221.63]],"id":9624350}],"con":true,"img":false}]}
{"op":"mcm","clk":"1362109162","pt":1588428049411,"mc":[{"id":"1.170370557","rc":[{"atb":[[1.25,109.61]],"id":9624350},{"atl":[[1.46,0]],"id":9624350}],"con":true,"img":false}]}
{"op":"mcm","clk":"1362109165","pt":1588428049514,"mc":[{"id":"1.170370557","rc":[{"atb":[[3.45,0]],"id":9622734},{"atl":[[1000,0]],"id":9622734}],"con":true,"img":false}]}
{"op":"mcm","clk":"1362109204","pt":1588428051545,"mc":[{"id":"1.170370557","rc":[{"trd":[[1.41,1466.6]],"ltp":1.41,"tv":1466.6,"id":9624350},{"atl":[[1.41,606.26]],"id":9624350}],"con":true,"img":false}]}
{"op":"mcm","clk":"1362109209","pt":1588428051615,"mc":[{"id":"1.170370557","rc":[{"trd":[[1.41,2450.65]],"ltp":1.41,"tv":2450.65,"id":9624350},{"atl":[[1.41,114.24]],"id":9624350}],"con":true,"img":false}]}
{"op":"mcm","clk":"1362109229","pt":1588428052333,"mc":[{"id":"1.170370557","rc":[{"atb":[[1.38,500]],"id":9624350}],"con":true,"img":false}]}
{"op":"mcm","clk":"1362109235","pt":1588428052741,"mc":[{"id":"1.170370557","rc":[{"atb":[[1.39,0]],"id":9624350}],"con":true,"img":false}]}
{"op":"mcm","clk":"1362109239","pt":1588428052894,"mc":[{"id":"1.170370557","rc":[{"atb":[[1.39,300]],"id":9624350}],"con":true,"img":false}]}
{"op":"mcm","clk":"1362109243","pt":1588428053200,"mc":[{"id":"1.170370557","rc":[{"atb":[[1.39,600]],"id":9624350}],"con":true,"img":false}]}
{"op":"mcm","clk":"1362109246","pt":1588428053506,"mc":[{"id":"1.170370557","rc":[{"trd":[[1.41,2674.65]],"ltp":1.41,"tv":2674.65,"id":9624350},{"atl":[[1.41,2.24]],"id":9624350}],"con":true,"img":false}]}
{"op":"mcm","clk":"1362109251","pt":1588428053913,"mc":[{"id":"1.170370557","rc":[{"trd":[[1.41,2679.14]],"ltp":1.41,"tv":2679.14,"id":9624350},{"atb":[[1.42,109.75],[1.35,0]],"id":9624350},{"atl":[[1.41,0]],"id":9624350}],"con":true,"img":false}]}
{"op":"mcm","clk":"1362109261","pt":1588428054626,"mc":[{"id":"1.170370557","rc":[{"atl":[[3.5,0.14]],"id":9622734}],"con":true,"img":false}]}
{"op":"mcm","clk":"1362109264","pt":1588428054830,"mc":[{"id":"1.170370557","rc":[{"atb":[[1.46,221.63]],"id":9624350}],"con":true,"img":false}]}
{"op":"mcm","clk":"1362109269","pt":1588428055135,"mc":[{"id":"1.170370557","rc":[{"atb":[[1.31,251.91]],"id":9624350}],"con":true,"img":false}]}
{"op":"mcm","clk":"1362109274","pt":1588428055646,"mc":[{"id":"1.170370557","rc":[{"atb":[[1.37,88.65]],"id":9624350}],"con":true,"img":false}]}
{"op":"mcm","clk":"1362109276","pt":1588428055697,"mc":[{"id":"1.170370557","rc":[{"atb":[[1.41,94.3]],"id":9624350}],"con":true,"img":false}]}
{"op":"mcm","clk":"1362109278","pt":1588428055800,"mc":[{"id":"1.170370557","rc":[{"atb":[[1.37,177.3]],"id":9624350}],"con":true,"img":false}]}
{"op":"mcm","clk":"1362109280","pt":1588428056003,"mc":[{"id":"1.170370557","rc":[{"atb":[[1.37,265.95]],"id":9624350}],"con":true,"img":false}]}
{"op":"mcm","clk":"1362109284","pt":1588428056207,"mc":[{"id":"1.170370557","rc":[{"atb":[[1.41,0]],"id":9624350}],"con":true,"img":false}]}
{"op":"mcm","clk":"1362109289","pt":1588428056513,"mc":[{"id":"1.170370557","rc":[{"trd":[[1.42,593.71],[1.46,816.67]],"ltp":1.42,"tv":1410.38,"id":9624350},{"atb":[[1.46,0],[1.42,0]],"id":9624350},{"atl":[[1.42,111.87]],"id":9624350}],"con":true,"img":false}]}
{"op":"mcm","clk":"1362109293","pt":1588428056818,"mc":[{"id":"1.170370557","rc":[{"atb":[[1.36,0]],"id":9624350},{"atl":[[1.43,488.58],[1.42,0]],"id":9624350}],"con":true,"img":false}]}
{"op":"mcm","clk":"1362109295","pt":1588428056920,"mc":[{"id":"1.170370557","rc":[{"atl":[[1.52,300.23]],"id":9624350}],"con":true,"img":false}]}
{"op":"mcm","clk":"1362109298","pt":1588428057225,"mc":[{"id":"1.170370557","rc":[{"atl":[[1.52,600.23]],"id":9624350}],"con":true,"img":false}]}
{"op":"mcm","clk":"1362109300","pt":1588428057326,"mc":[{"id":"1.170370557","rc":[{"atb":[[1.3,443.26]],"id":9624350}],"con":true,"img":false}]}
{"op":"mcm","clk":"1362109308","pt":1588428057733,"mc":[{"id":"1.170370557","rc":[{"atl":[[1.51,300]],"id":9624350}],"con":true,"img":false}]}
{"op":"mcm","clk":"1362109312","pt":1588428058038,"mc":[{"id":"1.170370557","rc":[{"atl":[[1.51,600]],"id":9624350}],"con":true,"img":false}]}
{"op":"mcm","clk":"1362109316","pt":1588428058445,"mc":[{"id":"1.170370557","rc":[{"atb":[[1.41,108.11]],"id":9624350}],"con":true,"img":false}]}
{"op":"mcm","clk":"1362109318","pt":1588428058597,"mc":[{"id":"1.170370557","rc":[{"atl":[[1.43,599.58]],"id":9624350}],"con":true,"img":false}]}
{"op":"mcm","clk":"1362109321","pt":1588428058699,"mc":[{"id":"1.170370557","rc":[{"atb":[[1.41,600.13]],"id":9624350}],"con":true,"img":false}]}
{"op":"mcm","clk":"1362109345","pt":1588428060126,"mc":[{"id":"1.170370557","rc":[{"atl":[[1.48,111]],"id":9624350}],"con":true,"img":false}]}
{"op":"mcm","clk":"1362109348","pt":1588428060228,"mc":[{"id":"1.170370557","rc":[{"trd":[[1.43,2237.88]],"ltp":1.43,"tv":2237.88,"id":9624350},{"atl":[[1.43,497.47],[1.49,112]],"id":9624350}],"con":true,"img":false}]}
{"op":"mcm","clk":"1362109354","pt":1588428060534,"mc":[{"id":"1.170370557","rc":[{"atb":[[3.05,6]],"id":9622734}],"con":true,"img":false}]}
{"op":"mcm","clk":"1362109357","pt":1588428060640,"mc":[{"id":"1.170370557","rc":[{"atl":[[1.52,711.23]],"id":9624350}],"con":true,"img":false}]}
{"op":"mcm","clk":"1362109370","pt":1588428061247,"mc":[{"id":"1.170370557","rc":[{"atb":[[3.05,0]],"id":9622734},{"atl":[[1.51,712]],"id":9624350}],"con":true,"img":false}]}
{"op":"mcm","clk":"1362109382","pt":1588428061816,"mc":[{"id":"1.170370557","rc":[{"atb":[[1.41,108.11]],"id":9624350}],"con":true,"img":false}]}
{"op":"mcm","clk":"1362109387","pt":1588428062122,"mc":[{"id":"1.170370557","rc":[{"atl":[[1.51,933.63]],"id":9624350}],"con":true,"img":false}]}
{"op":"mcm","clk":"1362109402","pt":1588428062947,"mc":[{"id":"1.170370557","rc":[{"trd":[[1.43,2252.16]],"ltp":1.43,"tv":2252.16,"id":9624350},{"atl":[[1.43,490.33],[1.54,0]],"id":9624350}],"con":true,"img":false}]}
{"op":"mcm","clk":"1362109409","pt":1588428063250,"mc":[{"id":"1.170370557","rc":[{"atb":[[1.41,448.13]],"id":9624350}],"con":true,"img":false}]}
{"op":"mcm","clk":"1362109414","pt":1588428063404,"mc":[{"id":"1.170370557","rc":[{"atb":[[1.41,449.38]],"id":9624350}],"con":true,"img":false}]}
{"op":"mcm","clk":"1362109419","pt":1588428063612,"mc":[{"id":"1.170370557","rc":[{"atl":[[1.49,333.63]],"id":9624350}],"con":true,"img":false}]}
{"op":"mcm","clk":"1362109422","pt":1588428063726,"mc":[{"id":"1.170370557","rc":[{"atb":[[3.35,5.46]],"id":9622734}],"con":true,"img":false}]}
{"op":"mcm","clk":"1362109425","pt":1588428063918,"mc":[{"id":"1.170370557","rc":[{"atb":[[1.41,109.36]],"id":9624350}],"con":true,"img":false}]}
{"op":"mcm","clk":"1362109453","pt":1588428065248,"mc":[{"id":"1.170370557","rc":[{"atl":[[1.49,388.63]],"id":9624350}],"con":true,"img":false}]}
{"op":"mcm","clk":"1362109456","pt":1588428065348,"mc":[{"id":"1.170370557","rc":[{"atl":[[1.51,821.63]],"id":9624350}],"con":true,"img":false}]}
{"op":"mcm","clk":"1362109460","pt":1588428065450,"mc":[{"id":"1.170370557","rc":[{"atl":[[1.46,0.11]],"id":9624350}],"con":true,"img":false}]}
{"op":"mcm","clk":"1362109479","pt":1588428066218,"mc":[{"id":"1.170370557","rc":[{"atb":[[1.42,337.62]],"id":9624350}],"con":true,"img":false}]}
{"op":"mcm","clk":"1362109491","pt":1588428067033,"mc":[{"id":"1.170370557","rc":[{"atl":[[3.5,81.73]],"id":9622734}],"con":true,"img":false}]}
{"op":"mcm","clk":"1362109496","pt":1588428067237,"mc":[{"id":"1.170370557","rc":[{"atl":[[1.47,221.63]],"id":9624350}],"con":true,"img":false}]}
{"op":"mcm","clk":"1362109512","pt":1588428067952,"mc":[{"id":"1.170370557","rc":[{"atl":[[1.52,600.23]],"id":9624350}],"con":true,"img":false}]}
{"op":"mcm","clk":"1362109517","pt":1588428068154,"mc":[{"id":"1.170370557","rc":[{"atb":[[1.41,108.11]],"id":9624350},{"atl":[[1.49,167]],"id":9624350}],"con":true,"img":false}]}
{"op":"mcm","clk":"1362109563","pt":1588428070145,"mc":[{"id":"1.170370557","rc":[{"atb":[[1.42,346.48]],"id":9624350}],"con":true,"img":false}]}
{"op":"mcm","clk":"1362109582","pt":1588428070960,"mc":[{"id":"1.170370557","rc":[{"trd":[[1.43,2284.16]],"ltp":1.43,"tv":2284.16,"id":9624350},{"atl":[[1.43,474.33]],"id":9624350}],"con":true,"img":false}]}
{"op":"mcm","clk":"1362109603","pt":1588428071835,"mc":[{"id":"1.170370557","rc":[{"atl":[[3.5,0.14]],"id":9622734},{"trd":[[1.43,2330.21]],"ltp":1.43,"tv":2330.21,"id":9624350},{"atl":[[1.43,451.31]],"id":9624350}],"con":true,"img":false}]}
{"op":"mcm","clk":"1362109623","pt":1588428073056,"mc":[{"id":"1.170370557","rc":[{"trd":[[1.42,815.71]],"ltp":1.42,"tv":815.71,"id":9624350},{"atb":[[1.42,235.48],[1.3,0]],"id":9624350}],"con":true,"img":false}]}
{"op":"mcm","clk":"1362109628","pt":1588428073261,"mc":[{"id":"1.170370557","rc":[{"trd":[[1.42,859.72]],"ltp":1.42,"tv":859.72,"id":9624350},{"atb":[[1.42,213.48]],"id":9624350}],"con":true,"img":false}]}
{"op":"mcm","clk":"1362109631","pt":1588428073361,"mc":[{"id":"1.170370557","rc":[{"trd":[[1.43,2339.07]],"ltp":1.43,"tv":2339.07,"id":9624350},{"atl":[[1.43,446.87]],"id":9624350}],"con":true,"img":false}]}
{"op":"mcm","clk":"1362109641","pt":1588428073720,"mc":[{"id":"1.170370557","rc":[{"atb":[[3.35,0]],"id":9622734}],"con":true,"img":false}]}
{"op":"mcm","clk":"1362109673","pt":1588428075151,"mc":[{"id":"1.170370557","rc":[{"atl":[[1.43,335.87],[1.58,443.26],[1.48,0],[1.63,0]],"id":9624350}],"con":true,"img":false}]}
{"op":"mcm","clk":"1362109677","pt":1588428075250,"mc":[{"id":"1.170370557","rc":[{"atb":[[1.39,0]],"id":9624350}],"con":true,"img":false}]}
{"op":"mcm","clk":"1362109682","pt":1588428075350,"mc":[{"id":"1.170370557","rc":[{"atl":[[1.43,0]],"id":9624350}],"con":true,"img":false}]}
{"op":"mcm","clk":"1362109686","pt":1588428075555,"mc":[{"id":"1.170370557","rc":[{"atb":[[1.41,0]],"id":9624350}],"con":true,"img":false}]}
{"op":"mcm","clk":"1362109690","pt":1588428075658,"mc":[{"id":"1.170370557","rc":[{"atl":[[1.45,112]],"id":9624350}],"con":true,"img":false}]}
{"op":"mcm","clk":"1362109705","pt":1588428076066,"mc":[{"id":"1.170370557","rc":[{"atb":[[1.37,0],[1.34,0]],"id":9624350}],"con":true,"img":false}]}
{"op":"mcm","clk":"1362109711","pt":1588428076270,"mc":[{"id":"1.170370557","rc":[{"atb":[[1.38,0]],"id":9624350}],"con":true,"img":false}]}
{"op":"mcm","clk":"1362109715","pt":1588428076323,"mc":[{"id":"1.170370557","rc":[{"atb":[[1.43,15.16]],"id":9624350}],"con":true,"img":false}]}
{"op":"mcm","clk":"1362109724","pt":1588428076732,"mc":[{"id":"1.170370557","rc":[{"atb":[[1.43,17.16]],"id":9624350}],"con":true,"img":false}]}
{"op":"mcm","clk":"1362109730","pt":1588428077039,"mc":[{"id":"1.170370557","rc":[{"atb":[[1.42,8.86]],"id":9624350}],"con":true,"img":false}]}
{"op":"mcm","clk":"1362109735","pt":1588428077241,"mc":[{"id":"1.170370557","rc":[{"atb":[[1.35,443.26]],"id":9624350}],"con":true,"img":false}]}
{"op":"mcm","clk":"1362109738","pt":1588428077345,"mc":[{"id":"1.170370557","rc":[{"atl":[[3.5,0]],"id":9622734}],"con":true,"img":false}]}
{"op":"mcm","clk":"1362109743","pt":1588428077547,"mc":[{"id":"1.170370557","rc":[{"atb":[[1.43,18.41]],"id":9624350}],"con":true,"img":false}]}
{"op":"mcm","clk":"1362109759","pt":1588428078259,"mc":[{"id":"1.170370557","rc":[{"atb":[[1.43,17.94]],"id":9624350}],"con":true,"img":false}]}
{"op":"mcm","clk":"1362109780","pt":1588428079129,"mc":[{"id":"1.170370557","rc":[{"atb":[[1.42,0]],"id":9624350}],"con":true,"img":false}]}
{"op":"mcm","clk":"1362109785","pt":1588428079332,"mc":[{"id":"1.170370557","rc":[{"trd":[[3.35,16.33]],"ltp":3.35,"tv":16.33,"id":9622734},{"atl":[[3.35,6.61]],"id":9622734}],"con":true,"img":false}]}
{"op":"mcm","clk":"1362109787","pt":1588428079433,"mc":[{"id":"1.170370557","rc":[{"atb":[[1.31,0]],"id":9624350}],"con":true,"img":false}]}
{"op":"mcm","clk":"1362109804","pt":1588428080254,"mc":[{"id":"1.170370557","rc":[{"atb":[[1.43,17.69]],"id":9624350}],"con":true,"img":false}]}
{"op":"mcm","clk":"1362109807","pt":1588428080355,"mc":[{"id":"1.170370557","rc":[{"trd":[[3.35,22.94]],"ltp":3.35,"tv":22.94,"id":9622734},{"atl":[[3.35,0]],"id":9622734},{"trd":[[1.42,875.33],[1.43,2374.47]],"ltp":1.42,"tv":3249.79,"id":9624350},{"atb":[[1.43,0],[1.35,0]],"id":9624350},{"atl":[[1.37,282.13],[1.58,0]],"id":9624350}],"con":true,"img":false}]}
{"op":"mcm","clk":"1362109809","pt":1588428080458,"mc":[{"id":"1.170370557","rc":[{"atl":[[1.4,112]],"id":9624350}],"con":true,"img":false}]}
{"op":"mcm","clk":"1362109812","pt":1588428080561,"mc":[{"id":"1.170370557","rc":[{"atl":[[1.42,333.79]],"id":9624350}],"con":true,"img":false}]}
{"op":"mcm","clk":"1362109815","pt":1588428080662,"mc":[{"id":"1.170370557","rc":[{"atl":[[1.38,112]],"id":9624350}],"con":true,"img":false}]}
{"op":"mcm","clk":"1362109824","pt":1588428081071,"mc":[{"id":"1.170370557","rc":[{"atl":[[1.42,633.79]],"id":9624350}],"con":true,"img":false}]}
{"op":"mcm","clk":"1362109832","pt":1588428081377,"mc":[{"id":"1.170370557","rc":[{"atl":[[1000,1.77],[1.42,933.79]],"id":9624350}],"con":true,"img":false}]}
{"op":"mcm","clk":"1362109839","pt":1588428081535,"mc":[{"id":"1.170370557","rc":[{"atl":[[1.43,88.65]],"id":9624350}],"con":true,"img":false}]}
{"op":"mcm","clk":"1362109841","pt":1588428081638,"mc":[{"id":"1.170370557","rc":[{"trd":[[3.7,2.43]],"ltp":3.7,"tv":2.43,"id":9622734},{"trd":[[1.37,241.61]],"ltp":1.37,"tv":241.61,"id":9624350},{"atl":[[1.37,275.55],[1000,0.93]],"id":9624350}],"con":true,"img":false}]}
{"op":"mcm","clk":"1362109845","pt":1588428081738,"mc":[{"id":"1.170370557","rc":[{"atl":[[1.42,1022.44]],"id":9624350}],"con":true,"img":false}]}
{"op":"mcm","clk":"1362109849","pt":1588428081842,"mc":[{"id":"1.170370557","rc":[{"atl":[[1000,0]],"id":9624350}],"con":true,"img":false}]}
{"op":"mcm","clk":"1362109852","pt":1588428081943,"mc":[{"id":"1.170370557","rc":[{"atl":[[1.42,1111.09]],"id":9624350}],"con":true,"img":false}]}
{"op":"mcm","clk":"1362109866","pt":1588428082455,"mc":[{"id":"1.170370557","rc":[{"trd":[[3.7,2.58]],"ltp":3.7,"tv":2.58,"id":9622734},{"trd":[[1.37,242]],"ltp":1.37,"tv":242.0,"id":9624350},{"atl":[[1.37,275.16]],"id":9624350}],"con":true,"img":false}]}
{"op":"mcm","clk":"1362109930","pt":1588428084753,"mc":[{"id":"1.170370557","rc":[{"atl":[[1.51,830.49]],"id":9624350}],"con":true,"img":false}]}
{"op":"mcm","clk":"1362109943","pt":1588428085165,"mc":[{"id":"1.170370557","rc":[{"atb":[[1.25,376.08]],"id":9624350},{"atl":[[1.42,1332.73]],"id":9624350}],"con":true,"img":false}]}
{"op":"mcm","clk":"1362109952","pt":1588428085475,"mc":[{"id":"1.170370557","rc":[{"trd":[[1.37,267.68]],"ltp":1.37,"tv":267.68,"id":9624350},{"atl":[[1.37,262.32]],"id":9624350}],"con":true,"img":false}]}
{"op":"mcm","clk":"1362109958","pt":1588428085677,"mc":[{"id":"1.170370557","rc":[{"atl":[[1.42,1438.26],[1.38,0]],"id":9624350}],"con":true,"img":false}]}
{"op":"mcm","clk":"1362109968","pt":1588428085982,"mc":[{"id":"1.170370557","rc":[{"atl":[[1.47,0]],"id":9624350}],"con":true,"img":false}]}
{"op":"mcm","clk":"1362109987","pt":1588428086650,"mc":[{"id":"1.170370557","rc":[{"atl":[[1.36,112]],"id":9624350}],"con":true,"img":false}]}
{"op":"mcm","clk":"1362109992","pt":1588428086856,"mc":[{"id":"1.170370557","rc":[{"atl":[[1.35,112]],"id":9624350}],"con":true,"img":false}]}
{"op":"mcm","clk":"1362109996","pt":1588428086962,"mc":[{"id":"1.170370557","rc":[{"atl":[[1.38,0.93]],"id":9624350}],"con":true,"img":false}]}
{"op":"mcm","clk":"1362110001","pt":1588428087165,"mc":[{"id":"1.170370557","rc":[{"atb":[[1.32,500]],"id":9624350}],"con":true,"img":false}]}
{"op":"mcm","clk":"1362110005","pt":1588428087267,"mc":[{"id":"1.170370557","rc":[{"atb":[[1.25,266.47]],"id":9624350}],"con":true,"img":false}]}
{"op":"mcm","clk":"1362110011","pt":1588428087581,"mc":[{"id":"1.170370557","rc":[{"trd":[[1.35,300.28]],"ltp":1.35,"tv":300.28,"id":9624350},{"atb":[[1.35,103.22]],"id":9624350},{"atl":[[1.35,0]],"id":9624350}],"con":true,"img":false}]}
{"op":"mcm","clk":"1362110020","pt":1588428088080,"mc":[{"id":"1.170370557","rc":[{"atb":[[1.29,300]],"id":9624350}],"con":true,"img":false}]}
{"op":"mcm","clk":"1362110022","pt":1588428088183,"mc":[{"id":"1.170370557","rc":[{"trd":[[3.75,35.93]],"ltp":3.75,"tv":35.93,"id":9622734},{"trd":[[1.36,332.24]],"ltp":1.36,"tv":332.24,"id":9624350},{"atl":[[1.36,12.9]],"id":9624350}],"con":true,"img":false}]}
{"op":"mcm","clk":"1362110026","pt":1588428088338,"mc":[{"id":"1.170370557","rc":[{"atb":[[1.29,600]],"id":9624350},{"atl":[[1.46,443.38]],"id":9624350}],"con":true,"img":false}]}
{"op":"mcm","clk":"1362110030","pt":1588428088540,"mc":[{"id":"1.170370557","rc":[{"atl":[[1000,2]],"id":9624350}],"con":true,"img":false}]}
{"op":"mcm","clk":"1362110034","pt":1588428088743,"mc":[{"id":"1.170370557","rc":[{"atl":[[1.37,0],[1.4,0]],"id":9624350}],"con":true,"img":false}]}
{"op":"mcm","clk":"1362110038","pt":1588428088848,"mc":[{"id":"1.170370557","rc":[{"atb":[[1.31,142.98],[1.3,300]],"id":9624350}],"con":true,"img":false}]}
{"op":"mcm","clk":"1362110042","pt":1588428088950,"mc":[{"id":"1.170370557","rc":[{"atl":[[1000,0.2]],"id":9624350}],"con":true,"img":false}]}
{"op":"mcm","clk":"1362110047","pt":1588428089154,"mc":[{"id":"1.170370557","rc":[{"atb":[[1.32,517.73]],"id":9624350},{"atl":[[1.45,0],[1.36,0],[1.49,55]],"id":9624350}],"con":true,"img":false}]}
{"op":"mcm","clk":"1362110050","pt":1588428089361,"mc":[{"id":"1.170370557","rc":[{"atb":[[1.3,600]],"id":9624350},{"atl":[[1000,0]],"id":9624350}],"con":true,"img":false}]}
{"op":"mcm","clk":"1362110057","pt":1588428089566,"mc":[{"id":"1.170370557","rc":[{"atb":[[1.32,17.73]],"id":9624350}],"con":true,"img":false}]}
{"op":"mcm","clk":"1362110058","pt":1588428089664,"mc":[{"id":"1.170370557","rc":[{"atl":[[3.7,60]],"id":9622734}],"con":true,"img":false}]}
{"op":"mcm","clk":"1362110062","pt":1588428089972,"mc":[{"id":"1.170370557","rc":[{"atl":[[1.43,0]],"id":9624350}],"con":true,"img":false}]}
{"op":"mcm","clk":"1362110073","pt":1588428090584,"mc":[{"id":"1.170370557","rc":[{"atl":[[1.38,89.58]],"id":9624350}],"con":true,"img":false}]}
{"op":"mcm","clk":"1362110078","pt":1588428090788,"mc":[{"id":"1.170370557","rc":[{"atl":[[1.38,178.23]],"id":9624350}],"con":true,"img":false}]}
{"op":"mcm","clk":"1362110081","pt":1588428090944,"mc":[{"id":"1.170370557","rc":[{"atl":[[1.55,0],[1.38,266.88]],"id":9624350}],"con":true,"img":false}]}
{"op":"mcm","clk":"1362110093","pt":1588428091351,"mc":[{"id":"1.170370557","rc":[{"atb":[[1.31,0]],"id":9624350}],"con":true,"img":false}]}
{"op":"mcm","clk":"1362110100","pt":1588428091757,"mc":[{"id":"1.170370557","rc":[{"atl":[[1.39,221.63]],"id":9624350}],"con":true,"img":false}]}
{"op":"mcm","clk":"1362110107","pt":1588428092168,"mc":[{"id":"1.170370557","rc":[{"atb":[[1.37,0.11]],"id":9624350}],"con":true,"img":false}]}
{"op":"mcm","clk":"1362110125","pt":1588428092782,"mc":[{"id":"1.170370557","rc":[{"atb":[[1.35,103.45]],"id":9624350}],"con":true,"img":false}]}
{"op":"mcm","clk":"1362110158","pt":1588428093951,"mc":[{"id":"1.170370557","rc":[{"trd":[[3.7,62.58]],"ltp":3.7,"tv":62.58,"id":9622734},{"atl":[[3.7,0]],"id":9622734},{"trd":[[1.35,507.19],[1.37,429.95]],"ltp":1.35,"tv":937.14,"id":9624350},{"atb":[[1.37,0],[1.35,0]],"id":9624350},{"atl":[[1.34,1.19]],"id":9624350}],"con":true,"img":false}]}
{"op":"mcm","clk":"1362110161","pt":1588428094057,"mc":[{"id":"1.170370557","rc":[{"atl":[[1.42,1104.46]],"id":9624350}],"con":true,"img":false}]}
{"op":"mcm","clk":"1362110170","pt":1588428094463,"mc":[{"id":"1.170370557","rc":[{"trd":[[1.33,18.66]],"ltp":1.33,"tv":18.66,"id":9624350},{"atb":[[1.33,2.28]],"id":9624350}],"con":true,"img":false}]}
{"op":"mcm","clk":"1362110177","pt":1588428094973,"mc":[{"id":"1.170370557","rc":[{"trd":[[1.34,174.01]],"ltp":1.34,"tv":174.01,"id":9624350},{"atb":[[1.37,7.56]],"id":9624350},{"atl":[[1.34,0]],"id":9624350}],"con":true,"img":false}]}
{"op":"mcm","clk":"1362110180","pt":1588428095073,"mc":[{"id":"1.170370557","rc":[{"atb":[[1.24,489.62]],"id":9624350}],"con":true,"img":false}]}
{"op":"mcm","clk":"1362110183","pt":1588428095278,"mc":[{"id":"1.170370557","rc":[{"trd":[[1.38,41.5]],"ltp":1.38,"tv":41.5,"id":9624350},{"atl":[[1.38,261.4]],"id":9624350}],"con":true,"img":false}]}
{"op":"mcm","clk":"1362110185","pt":1588428095381,"mc":[{"id":"1.170370557","rc":[{"atl":[[1.41,20.18]],"id":9624350}],"con":true,"img":false}]}
{"op":"mcm","clk":"1362110189","pt":1588428095890,"mc":[{"id":"1.170370557","rc":[{"atl":[[1.42,927.16]],"id":9624350}],"con":true,"img":false}]}
{"op":"mcm","clk":"1362110193","pt":1588428096248,"mc":[{"id":"1.170370557","rc":[{"trd":[[1.38,48.25]],"ltp":1.38,"tv":48.25,"id":9624350},{"atl":[[1.38,258.02]],"id":9624350}],"con":true,"img":false}]}
{"op":"mcm","clk":"1362110198","pt":1588428096658,"mc":[{"id":"1.170370557","rc":[{"atl":[[1.42,327.16]],"id":9624350}],"con":true,"img":false}]}
{"op":"mcm","clk":"1362110232","pt":1588428099159,"mc":[{"id":"1.170370557","rc":[{"atl":[[1.42,221.63]],"id":9624350}],"con":true,"img":false}]}
{"op":"mcm","clk":"1362110234","pt":1588428099262,"mc":[{"id":"1.170370557","rc":[{"trd":[[1.37,533.75]],"ltp":1.37,"tv":533.75,"id":9624350},{"atb":[[1.37,0]],"id":9624350},{"atl":[[1.37,294.07]],"id":9624350}],"con":true,"img":false}]}
{"op":"mcm","clk":"1362110238","pt":1588428099468,"mc":[{"id":"1.170370557","rc":[{"trd":[[1.37,597.74]],"ltp":1.37,"tv":597.74,"id":9624350},{"atl":[[1.37,262.08]],"id":9624350}],"con":true,"img":false}]}
{"op":"mcm","clk":"1362110260","pt":1588428101563,"mc":[{"id":"1.170370557","rc":[{"atb":[[1.3,0]],"id":9624350}],"con":true,"img":false}]}
{"op":"mcm","clk":"1362110282","pt":1588428102896,"mc":[{"id":"1.170370557","rc":[{"trd":[[1.37,615.25]],"ltp":1.37,"tv":615.25,"id":9624350},{"atl":[[1.37,253.32]],"id":9624350}],"con":true,"img":false}]}
{"op":"mcm","clk":"1362110292","pt":1588428103471,"mc":[{"id":"1.170370557","rc":[{"trd":[[3.7,67.58]],"ltp":3.7,"tv":67.58,"id":9622734},{"trd":[[1.37,628.75]],"ltp":1.37,"tv":628.75,"id":9624350},{"atl":[[1.37,239.82]],"id":9624350}],"con":true,"img":false}]}
{"op":"mcm","clk":"1362110301","pt":1588428103867,"mc":[{"id":"1.170370557","rc":[{"atb":[[1.34,4.4]],"id":9624350}],"con":true,"img":false}]}
{"op":"mcm","clk":"1362110313","pt":1588428104784,"mc":[{"id":"1.170370557","rc":[{"atl":[[1.44,0.23]],"id":9624350}],"con":true,"img":false}]}
{"op":"mcm","clk":"1362110320","pt":1588428105299,"mc":[{"id":"1.170370557","rc":[{"atl":[[3.75,39.89]],"id":9622734},{"atb":[[1.34,134.76]],"id":9624350}],"con":true,"img":false}]}
{"op":"mcm","clk":"1362110335","pt":1588428106007,"mc":[{"id":"1.170370557","rc":[{"trd":[[3.75,36.88]],"ltp":3.75,"tv":36.88,"id":9622734},{"atl":[[3.75,38.94]],"id":9622734},{"trd":[[1.36,334.86]],"ltp":1.36,"tv":334.86,"id":9624350}],"con":true,"img":false}]}
{"op":"mcm","clk":"1362110347","pt":1588428106673,"mc":[{"id":"1.170370557","rc":[{"atb":[[1.34,4.4]],"id":9624350}],"con":true,"img":false}]}
{"op":"mcm","clk":"1362110358","pt":1588428107390,"mc":[{"id":"1.170370557","rc":[{"trd":[[3.7,67.84]],"ltp":3.7,"tv":67.84,"id":9622734},{"atl":[[3.75,0]],"id":9622734},{"trd":[[1.37,629.46]],"ltp":1.37,"tv":629.46,"id":9624350},{"atl":[[1.37,239.11]],"id":9624350}],"con":true,"img":false}]}
{"op":"mcm","clk":"1362110370","pt":1588428108308,"mc":[{"id":"1.170370557","rc":[{"atl":[[1.41,0]],"id":9624350}],"con":true,"img":false}]}
{"op":"mcm","clk":"1362110380","pt":1588428109077,"mc":[{"id":"1.170370557","rc":[{"trd":[[1.37,632.09]],"ltp":1.37,"tv":632.09,"id":9624350},{"atl":[[1.37,237.8]],"id":9624350}],"con":true,"img":false}]}
{"op":"mcm","clk":"1362110389","pt":1588428109585,"mc":[{"id":"1.170370557","rc":[{"atl":[[1.39,0]],"id":9624350}],"con":true,"img":false}]}
{"op":"mcm","clk":"1362110392","pt":1588428109687,"mc":[{"id":"1.170370557","rc":[{"atl":[[1.37,0]],"id":9624350}],"con":true,"img":false}]}
{"op":"mcm","clk":"1362110394","pt":1588428109790,"mc":[{"id":"1.170370557","rc":[{"atl":[[1.38,0]],"id":9624350}],"con":true,"img":false}]}
{"op":"mcm","clk":"1362110402","pt":1588428110199,"mc":[{"id":"1.170370557","rc":[{"atl":[[1.42,0]],"id":9624350}],"con":true,"img":false}]}
{"op":"mcm","clk":"1362110414","pt":1588428111011,"mc":[{"id":"1.170370557","rc":[{"atl":[[1.52,600]],"id":9624350}],"con":true,"img":false}]}
{"op":"mcm","clk":"1362110422","pt":1588428111471,"mc":[{"id":"1.170370557","rc":[{"atb":[[1.25,0]],"id":9624350}],"con":true,"img":false}]}
{"op":"mcm","clk":"1362110446","pt":1588428113106,"mc":[{"id":"1.170370557","rc":[{"atb":[[1.42,492.02]],"id":9624350}],"con":true,"img":false}]}
{"op":"mcm","clk":"1362110460","pt":1588428113874,"mc":[{"id":"1.170370557","rc":[{"atb":[[1.39,112]],"id":9624350}],"con":true,"img":false}]}
{"op":"mcm","clk":"1362110464","pt":1588428114081,"mc":[{"id":"1.170370557","rc":[{"atb":[[1.38,112],[1.35,300]],"id":9624350},{"atl":[[1.5,0.25]],"id":9624350}],"con":true,"img":false}]}
{"op":"mcm","clk":"1362110467","pt":1588428114185,"mc":[{"id":"1.170370557","rc":[{"atb":[[1.34,0]],"id":9624350}],"con":true,"img":false}]}
{"op":"mcm","clk":"1362110470","pt":1588428114387,"mc":[{"id":"1.170370557","rc":[{"atb":[[1.35,600]],"id":9624350}],"con":true,"img":false}]}
{"op":"mcm","clk":"1362110473","pt":1588428114590,"mc":[{"id":"1.170370557","rc":[{"atb":[[1.39,224]],"id":9624350}],"con":true,"img":false}]}
{"op":"mcm","clk":"1362110478","pt":1588428114997,"mc":[{"id":"1.170370557","rc":[{"atb":[[1.4,0.26]],"id":9624350}],"con":true,"img":false}]}
{"op":"mcm","clk":"1362110479","pt":1588428115098,"mc":[{"id":"1.170370557","rc":[{"trd":[[1.44,3366.64]],"ltp":1.44,"tv":3366.64,"id":9624350},{"atb":[[1.44,7.36]],"id":9624350},{"atl":[[1.44,0]],"id":9624350}],"con":true,"img":false}]}
{"op":"mcm","clk":"1362110485","pt":1588428115609,"mc":[{"id":"1.170370557","rc":[{"atb":[[1.41,221.63]],"id":9624350}],"con":true,"img":false}]}
{"op":"mcm","clk":"1362110496","pt":1588428116481,"mc":[{"id":"1.170370557","rc":[{"atb":[[1.35,712]],"id":9624350}],"con":true,"img":false}]}
{"op":"mcm","clk":"1362110500","pt":1588428116582,"mc":[{"id":"1.170370557","rc":[{"atl":[[1.46,666.52]],"id":9624350}],"con":true,"img":false}]}
{"op":"mcm","clk":"1362110518","pt":1588428117295,"mc":[{"id":"1.170370557","rc":[{"atb":[[1.31,251.91],[1.37,443.26]],"id":9624350}],"con":true,"img":false}]}
{"op":"mcm","clk":"1362110524","pt":1588428117605,"mc":[{"id":"1.170370557","rc":[{"atb":[[1.39,314.92]],"id":9624350}],"con":true,"img":false}]}
{"op":"mcm","clk":"1362110530","pt":1588428117810,"mc":[{"id":"1.170370557","rc":[{"atb":[[1.37,446.76]],"id":9624350}],"con":true,"img":false}]}
{"op":"mcm","clk":"1362110547","pt":1588428118419,"mc":[{"id":"1.170370557","rc":[{"atl":[[1.45,300]],"id":9624350}],"con":true,"img":false}]}
{"op":"mcm","clk":"1362110568","pt":1588428119388,"mc":[{"id":"1.170370557","rc":[{"atb":[[1.44,11.45]],"id":9624350}],"con":true,"img":false}]}
{"op":"mcm","clk":"1362110580","pt":1588428120307,"mc":[{"id":"1.170370557","rc":[{"atl":[[1.5,112.25]],"id":9624350}],"con":true,"img":false}]}
{"op":"mcm","clk":"1362110585","pt":1588428120511,"mc":[{"id":"1.170370557","rc":[{"atb":[[1.42,0]],"id":9624350},{"atl":[[1.46,443.38],[1.45,521.63]],"id":9624350}],"con":true,"img":false}]}
{"op":"mcm","clk":"1362110594","pt":1588428121019,"mc":[{"id":"1.170370557","rc":[{"atl":[[1.49,167]],"id":9624350}],"con":true,"img":false}]}
{"op":"mcm","clk":"1362110597","pt":1588428121224,"mc":[{"id":"1.170370557","rc":[{"atb":[[1.13,492.02],[1.32,0]],"id":9624350}],"con":true,"img":false}]}
{"op":"mcm","clk":"1362110609","pt":1588428121890,"mc":[{"id":"1.170370557","rc":[{"atl":[[1.49,388.63]],"id":9624350}],"con":true,"img":false}]}
{"op":"mcm","clk":"1362110633","pt":1588428123229,"mc":[{"id":"1.170370557","rc":[{"atb":[[1.43,0.86]],"id":9624350}],"con":true,"img":false}]}
{"op":"mcm","clk":"1362110682","pt":1588428125585,"mc":[{"id":"1.170370557","rc":[{"trd":[[1.44,3389.55]],"ltp":1.44,"tv":3389.55,"id":9624350},{"atb":[[1.44,0]],"id":9624350},{"atl":[[1.44,30.71]],"id":9624350}],"con":true,"img":false}]}
{"op":"mcm","clk":"1362110687","pt":1588428125690,"mc":[{"id":"1.170370557","rc":[{"atl":[[1.44,256.95]],"id":9624350}],"con":true,"img":false}]}
{"op":"mcm","clk":"1362110696","pt":1588428126096,"mc":[{"id":"1.170370557","rc":[{"trd":[[1.44,3418.68]],"ltp":1.44,"tv":3418.68,"id":9624350},{"atl":[[1.44,242.39]],"id":9624350}],"con":true,"img":false}]}
{"op":"mcm","clk":"1362110700","pt":1588428126301,"mc":[{"id":"1.170370557","rc":[{"atl":[[1.51,1273.75]],"id":9624350}],"con":true,"img":false}]}
{"op":"mcm","clk":"1362110703","pt":1588428126404,"mc":[{"id":"1.170370557","rc":[{"atl":[[1.46,0.11]],"id":9624350}],"con":true,"img":false}]}
{"op":"mcm","clk":"1362110711","pt":1588428127013,"mc":[{"id":"1.170370557","rc":[{"atl":[[1.44,464.02]],"id":9624350}],"con":true,"img":false}]}
{"op":"mcm","clk":"1362110726","pt":1588428127929,"mc":[{"id":"1.170370557","rc":[{"atl":[[1.44,464.49],[1.45,300]],"id":9624350}],"con":true,"img":false}]}
{"op":"mcm","clk":"1362110730","pt":1588428128031,"mc":[{"id":"1.170370557","rc":[{"trd":[[3.25,7.72]],"ltp":3.25,"tv":7.72,"id":9622734},{"trd":[[1.44,3419.9]],"ltp":1.44,"tv":3419.9,"id":9624350},{"atl":[[1.44,463.28]],"id":9624350}],"con":true,"img":false}]}
{"op":"mcm","clk":"1362110735","pt":1588428128286,"mc":[{"id":"1.170370557","rc":[{"atb":[[1.37,3.5]],"id":9624350},{"atl":[[1.44,472.03]],"id":9624350}],"con":true,"img":false}]}
{"op":"mcm","clk":"1362110739","pt":1588428128489,"mc":[{"id":"1.170370557","rc":[{"atb":[[1.39,224]],"id":9624350}],"con":true,"img":false}]}
{"op":"mcm","clk":"1362110742","pt":1588428128593,"mc":[{"id":"1.170370557","rc":[{"atb":[[1.43,0]],"id":9624350},{"atl":[[1.42,1.49]],"id":9624350}],"con":true,"img":false}]}
{"op":"mcm","clk":"1362110747","pt":1588428129003,"mc":[{"id":"1.170370557","rc":[{"trd":[[1.44,3421.14]],"ltp":1.44,"tv":3421.14,"id":9624350},{"atl":[[1.44,471.41],[1.42,0]],"id":9624350}],"con":true,"img":false}]}
{"op":"mcm","clk":"1362110749","pt":1588428129106,"mc":[{"id":"1.170370557","rc":[{"atl":[[1.44,471.53]],"id":9624350}],"con":true,"img":false}]}
{"op":"mcm","clk":"1362110802","pt":1588428132114,"mc":[{"id":"1.170370557","rc":[{"atl":[[1.44,471.76]],"id":9624350}],"con":true,"img":false}]}
{"op":"mcm","clk":"1362110811","pt":1588428132723,"mc":[{"id":"1.170370557","rc":[{"atl":[[1.44,472.02]],"id":9624350}],"con":true,"img":false}]}
{"op":"mcm","clk":"1362110816","pt":1588428132829,"mc":[{"id":"1.170370557","rc":[{"atb":[[1.42,90.76],[1.35,112],[1.29,0]],"id":9624350},{"atl":[[1.45,0],[1.51,673.75],[1.52,0]],"id":9624350}],"con":true,"img":false}]}
{"op":"mcm","clk":"1362110833","pt":1588428133591,"mc":[{"id":"1.170370557","rc":[{"trd":[[1.44,3421.53]],"ltp":1.44,"tv":3421.53,"id":9624350},{"atl":[[1.44,471.83]],"id":9624350}],"con":true,"img":false}]}
{"op":"mcm","clk":"1362110853","pt":1588428134613,"mc":[{"id":"1.170370557","rc":[{"atb":[[1.32,443.26]],"id":9624350}],"con":true,"img":false}]}
{"op":"mcm","clk":"1362110863","pt":1588428135122,"mc":[{"id":"1.170370557","rc":[{"atl":[[1.44,473.83]],"id":9624350}],"con":true,"img":false}]}
{"op":"mcm","clk":"1362110865","pt":1588428135224,"mc":[{"id":"1.170370557","rc":[{"trd":[[1.42,985.33]],"ltp":1.42,"tv":985.33,"id":9624350},{"atb":[[1.42,35.76]],"id":9624350},{"atl":[[1.5,112]],"id":9624350}],"con":true,"img":false}]}
{"op":"mcm","clk":"1362110893","pt":1588428136809,"mc":[{"id":"1.170370557","rc":[{"atb":[[3,0]],"id":9622734}],"con":true,"img":false}]}
{"op":"mcm","clk":"1362110908","pt":1588428137625,"mc":[{"id":"1.170370557","rc":[{"atl":[[1.44,473.6]],"id":9624350}],"con":true,"img":false}]}
{"op":"mcm","clk":"1362110912","pt":1588428137829,"mc":[{"id":"1.170370557","rc":[{"atl":[[1.44,464.84]],"id":9624350}],"con":true,"img":false}]}
{"op":"mcm","clk":"1362110915","pt":1588428137931,"mc":[{"id":"1.170370557","rc":[{"atb":[[1.37,0]],"id":9624350}],"con":true,"img":false}]}
{"op":"mcm","clk":"1362110920","pt":1588428138241,"mc":[{"id":"1.170370557","rc":[{"trd":[[3.25,213.68]],"ltp":3.25,"tv":213.68,"id":9622734},{"atl":[[3.25,1794.04]],"id":9622734},{"trd":[[1.44,3886.38]],"ltp":1.44,"tv":3886.38,"id":9624350},{"atl":[[1.44,0]],"id":9624350}],"con":true,"img":false}]}
{"op":"mcm","clk":"1362110948","pt":1588428139717,"mc":[{"id":"1.170370557","rc":[{"atb":[[1.42,0]],"id":9624350}],"con":true,"img":false}]}
{"op":"mcm","clk":"1362110955","pt":1588428140327,"mc":[{"id":"1.170370557","rc":[{"atb":[[1.44,2.57]],"id":9624350}],"con":true,"img":false}]}
{"op":"mcm","clk":"1362110965","pt":1588428140839,"mc":[{"id":"1.170370557","rc":[{"atb":[[1.38,0],[1.39,0],[1.35,0]],"id":9624350}],"con":true,"img":false}]}
{"op":"mcm","clk":"1362110974","pt":1588428141298,"mc":[{"id":"1.170370557","rc":[{"trd":[[1.44,3886.92]],"ltp":1.44,"tv":3886.92,"id":9624350},{"atb":[[1.44,2.3]],"id":9624350}],"con":true,"img":false}]}
{"op":"mcm","clk":"1362111021","pt":1588428143601,"mc":[{"id":"1.170370557","rc":[{"trd":[[3.25,315.03]],"ltp":3.25,"tv":315.03,"id":9622734},{"atl":[[3.25,1692.69]],"id":9622734},{"trd":[[1.44,4120.28]],"ltp":1.44,"tv":4120.28,"id":9624350},{"atb":[[1.44,0]],"id":9624350}],"con":true,"img":false}]}
{"op":"mcm","clk":"1362111026","pt":1588428144009,"mc":[{"id":"1.170370557","rc":[{"atl":[[3.25,1701.55]],"id":9622734}],"con":true,"img":false}]}
{"op":"mcm","clk":"1362111048","pt":1588428145339,"mc":[{"id":"1.170370557","rc":[{"atl":[[3.25,1738.78]],"id":9622734}],"con":true,"img":false}]}
{"op":"mcm","clk":"1362111059","pt":1588428146309,"mc":[{"id":"1.170370557","rc":[{"trd":[[3.25,316.09]],"ltp":3.25,"tv":316.09,"id":9622734},{"atl":[[3.25,1737.72]],"id":9622734},{"trd":[[1.44,4122.68]],"ltp":1.44,"tv":4122.68,"id":9624350}],"con":true,"img":false}]}
{"op":"mcm","clk":"1362111061","pt":1588428146411,"mc":[{"id":"1.170370557","rc":[{"atl":[[1.57,49.74]],"id":9624350}],"con":true,"img":false}]}
{"op":"mcm","clk":"1362111071","pt":1588428147126,"mc":[{"id":"1.170370557","rc":[{"atb":[[1.28,0]],"id":9624350}],"con":true,"img":false}]}
{"op":"mcm","clk":"1362111087","pt":1588428148552,"mc":[{"id":"1.170370557","rc":[{"atb":[[1.41,0],[1.31,0]],"id":9624350}],"con":true,"img":false}]}
{"op":"mcm","clk":"1362111093","pt":1588428149112,"mc":[{"id":"1.170370557","rc":[{"trd":[[3.25,365.71]],"ltp":3.25,"tv":365.71,"id":9622734},{"atl":[[3.25,1688.1]],"id":9622734},{"trd":[[1.44,4234.68]],"ltp":1.44,"tv":4234.68,"id":9624350}],"con":true,"img":false}]}
{"op":"mcm","clk":"1362111095","pt":1588428149214,"mc":[{"id":"1.170370557","rc":[{"trd":[[3.25,513.25]],"ltp":3.25,"tv":513.25,"id":9622734},{"atl":[[3.25,1540.56]],"id":9622734},{"trd":[[1.44,4567.68]],"ltp":1.44,"tv":4567.68,"id":9624350}],"con":true,"img":false}]}
{"op":"mcm","clk":"1362111097","pt":1588428149316,"mc":[{"id":"1.170370557","rc":[{"atl":[[3.25,1531.7]],"id":9622734}],"con":true,"img":false}]}
{"op":"mcm","clk":"1362111099","pt":1588428149419,"mc":[{"id":"1.170370557","rc":[{"trd":[[3.25,562.87]],"ltp":3.25,"tv":562.87,"id":9622734},{"atl":[[3.25,1482.08]],"id":9622734},{"trd":[[1.44,4679.68]],"ltp":1.44,"tv":4679.68,"id":9624350}],"con":true,"img":false}]}
{"op":"mcm","clk":"1362111105","pt":1588428149930,"mc":[{"id":"1.170370557","rc":[{"trd":[[3.25,695.79]],"ltp":3.25,"tv":695.79,"id":9622734},{"atl":[[3.25,1349.16]],"id":9622734},{"trd":[[1.44,4979.68]],"ltp":1.44,"tv":4979.68,"id":9624350}],"con":true,"img":false}]}
{"op":"mcm","clk":"1362111107","pt":1588428150031,"mc":[{"id":"1.170370557","rc":[{"atl":[[3.25,1311.93]],"id":9622734}],"con":true,"img":false}]}
{"op":"mcm","clk":"1362111113","pt":1588428150438,"mc":[{"id":"1.170370557","rc":[{"trd":[[3.25,892.29]],"ltp":3.25,"tv":892.29,"id":9622734},{"atl":[[3.25,1115.43]],"id":9622734},{"trd":[[1.44,5423.18]],"ltp":1.44,"tv":5423.18,"id":9624350}],"con":true,"img":false}]}
{"op":"mcm","clk":"1362111116","pt":1588428150540,"mc":[{"id":"1.170370557","rc":[{"atl":[[1.51,452.12]],"id":9624350}],"con":true,"img":false}]}
{"op":"mcm","clk":"1362111118","pt":1588428150643,"mc":[{"id":"1.170370557","rc":[{"trd":[[3.25,931.57]],"ltp":3.25,"tv":931.57,"id":9622734},{"atl":[[3.25,1076.15]],"id":9622734},{"trd":[[1.44,5511.83]],"ltp":1.44,"tv":5511.83,"id":9624350}],"con":true,"img":false}]}
{"op":"mcm","clk":"1362111121","pt":1588428150744,"mc":[{"id":"1.170370557","rc":[{"trd":[[3.25,1153.11]],"ltp":3.25,"tv":1153.11,"id":9622734},{"atl":[[3.25,854.61]],"id":9622734},{"trd":[[1.44,6011.83]],"ltp":1.44,"tv":6011.83,"id":9624350},{"atl":[[1.46,300.11]],"id":9624350}],"con":true,"img":false}]}
{"op":"mcm","clk":"1362111123","pt":1588428150847,"mc":[{"id":"1.170370557","rc":[{"trd":[[3.25,1339.93]],"ltp":3.25,"tv":1339.93,"id":9622734},{"atl":[[3.25,667.79]],"id":9622734},{"trd":[[1.44,6433.48]],"ltp":1.44,"tv":6433.48,"id":9624350}],"con":true,"img":false}]}
{"op":"mcm","clk":"1362111127","pt":1588428151051,"mc":[{"id":"1.170370557","rc":[{"trd":[[3.25,1557.93]],"ltp":3.25,"tv":1557.93,"id":9622734},{"atl":[[3.25,449.79]],"id":9622734},{"trd":[[1.44,6925.5]],"ltp":1.44,"tv":6925.5,"id":9624350}],"con":true,"img":false}]}
{"op":"mcm","clk":"1362111132","pt":1588428151307,"mc":[{"id":"1.170370557","rc":[{"atl":[[1.48,300]],"id":9624350}],"con":true,"img":false}]}
{"op":"mcm","clk":"1362111134","pt":1588428151409,"mc":[{"id":"1.170370557","rc":[{"trd":[[3.25,1607.55]],"ltp":3.25,"tv":1607.55,"id":9622734},{"atl":[[3.25,400.17]],"id":9622734},{"trd":[[1.44,7037.5]],"ltp":1.44,"tv":7037.5,"id":9624350}],"con":true,"img":false}]}
{"op":"mcm","clk":"1362111148","pt":1588428152430,"mc":[{"id":"1.170370557","rc":[{"atl":[[1.53,0]],"id":9624350}],"con":true,"img":false}]}
{"op":"mcm","clk":"1362111153","pt":1588428152838,"mc":[{"id":"1.170370557","rc":[{"trd":[[3.25,1705.75]],"ltp":3.25,"tv":1705.75,"id":9622734},{"atl":[[3.25,301.97]],"id":9622734},{"trd":[[1.44,7259.13]],"ltp":1.44,"tv":7259.13,"id":9624350}],"con":true,"img":false}]}
{"op":"mcm","clk":"1362111158","pt":1588428153247,"mc":[{"id":"1.170370557","rc":[{"atl":[[1.46,388.77]],"id":9624350}],"con":true,"img":false}]}
{"op":"mcm","clk":"1362111160","pt":1588428153349,"mc":[{"id":"1.170370557","rc":[{"atl":[[1.49,333.63]],"id":9624350}],"con":true,"img":false}]}
{"op":"mcm","clk":"1362111163","pt":1588428153553,"mc":[{"id":"1.170370557","rc":[{"atl":[[1.45,88.65]],"id":9624350}],"con":true,"img":false}]}
{"op":"mcm","clk":"1362111165","pt":1588428153655,"mc":[{"id":"1.170370557","rc":[{"trd":[[3.25,1713.61]],"ltp":3.25,"tv":1713.61,"id":9622734},{"atl":[[3.25,294.11]],"id":9622734},{"trd":[[1.44,7276.86]],"ltp":1.44,"tv":7276.86,"id":9624350}],"con":true,"img":false}]}
{"op":"mcm","clk":"1362111167","pt":1588428153757,"mc":[{"id":"1.170370557","rc":[{"atl":[[1.45,177.3]],"id":9624350}],"con":true,"img":false}]}
{"op":"mcm","clk":"1362111169","pt":1588428153859,"mc":[{"id":"1.170370557","rc":[{"atl":[[1.46,389.02]],"id":9624350}],"con":true,"img":false}]}
{"op":"mcm","clk":"1362111171","pt":1588428153910,"mc":[{"id":"1.170370557","rc":[{"atl":[[1.45,265.95]],"id":9624350}],"con":true,"img":false}]}
{"op":"mcm","clk":"1362111175","pt":1588428154114,"mc":[{"id":"1.170370557","rc":[{"atl":[[1.5,0],[1.49,221.63]],"id":9624350}],"con":true,"img":false}]}
{"op":"mcm","clk":"1362111181","pt":1588428154317,"mc":[{"id":"1.170370557","rc":[{"atb":[[1.23,272.47]],"id":9624350}],"con":true,"img":false}]}
{"op":"mcm","clk":"1362111185","pt":1588428154421,"mc":[{"id":"1.170370557","rc":[{"trd":[[3.25,1758.24],[3.2,20.69]],"ltp":3.25,"tv":1778.93,"id":9622734},{"atl":[[3.25,249.48]],"id":9622734},{"trd":[[1.44,7377.6],[1.45,1083.3]],"ltp":1.44,"tv":8460.9,"id":9624350},{"atl":[[1.45,246.39]],"id":9624350}],"con":true,"img":false}]}
{"op":"mcm","clk":"1362111194","pt":1588428154933,"mc":[{"id":"1.170370557","rc":[{"trd":[[3.25,1767.83]],"ltp":3.25,"tv":1767.83,"id":9622734},{"atl":[[3.25,239.89]],"id":9622734},{"trd":[[1.44,7399.24]],"ltp":1.44,"tv":7399.24,"id":9624350}],"con":true,"img":false}]}
{"op":"mcm","clk":"1362111196","pt":1588428155137,"mc":[{"id":"1.170370557","rc":[{"trd":[[3.25,1816.93]],"ltp":3.25,"tv":1816.93,"id":9622734},{"atl":[[3.25,190.79]],"id":9622734},{"trd":[[1.44,7510.05]],"ltp":1.44,"tv":7510.05,"id":9624350}],"con":true,"img":false}]}
{"op":"mcm","clk":"1362111210","pt":1588428156157,"mc":[{"id":"1.170370557","rc":[{"trd":[[3.25,1915.13]],"ltp":3.25,"tv":1915.13,"id":9622734},{"atl":[[3.25,92.59]],"id":9622734},{"trd":[[1.44,7731.69]],"ltp":1.44,"tv":7731.69,"id":9624350}],"con":true,"img":false}]}
{"op":"mcm","clk":"1362111212","pt":1588428156258,"mc":[{"id":"1.170370557","rc":[{"atb":[[1.42,495.48]],"id":9624350}],"con":true,"img":false}]}
{"op":"mcm","clk":"1362111213","pt":1588428156309,"mc":[{"id":"1.170370557","rc":[{"atb":[[1.38,443.26]],"id":9624350}],"con":true,"img":false}]}
{"op":"mcm","clk":"1362111219","pt":1588428156824,"mc":[{"id":"1.170370557","rc":[{"atb":[[1.4,333.26],[1.37,300]],"id":9624350}],"con":true,"img":false}]}
{"op":"mcm","clk":"1362111224","pt":1588428157131,"mc":[{"id":"1.170370557","rc":[{"trd":[[3.25,1921.84]],"ltp":3.25,"tv":1921.84,"id":9622734},{"atl":[[3.25,85.88]],"id":9622734},{"trd":[[1.44,7746.83]],"ltp":1.44,"tv":7746.83,"id":9624350}],"con":true,"img":false}]}
{"op":"mcm","clk":"1362111226","pt":1588428157335,"mc":[{"id":"1.170370557","rc":[{"atb":[[1.38,776.26]],"id":9624350}],"con":true,"img":false}]}
{"op":"mcm","clk":"1362111230","pt":1588428157747,"mc":[{"id":"1.170370557","rc":[{"atb":[[1.36,112]],"id":9624350}],"con":true,"img":false}]}
{"op":"mcm","clk":"1362111233","pt":1588428157951,"mc":[{"id":"1.170370557","rc":[{"atb":[[1.32,0]],"id":9624350}],"con":true,"img":false}]}
{"op":"mcm","clk":"1362111242","pt":1588428158412,"mc":[{"id":"1.170370557","rc":[{"atb":[[1.37,412]],"id":9624350}],"con":true,"img":false}]}
{"op":"mcm","clk":"1362111248","pt":1588428158822,"mc":[{"id":"1.170370557","rc":[{"trd":[[3.25,2007.72]],"ltp":3.25,"tv":2007.72,"id":9622734},{"atl":[[3.25,0]],"id":9622734},{"trd":[[1.44,7940.66]],"ltp":1.44,"tv":7940.66,"id":9624350},{"atb":[[1.4,0.26],[1.38,443.26]],"id":9624350},{"atl":[[1.43,27.8]],"id":9624350}],"con":true,"img":false}]}
{"op":"mcm","clk":"1362111253","pt":1588428159332,"mc":[{"id":"1.170370557","rc":[{"atl":[[1.44,0.68]],"id":9624350}],"con":true,"img":false}]}
{"op":"mcm","clk":"1362111260","pt":1588428159841,"mc":[{"id":"1.170370557","rc":[{"atl":[[1.43,77.8]],"id":9624350}],"con":true,"img":false}]}
{"op":"mcm","clk":"1362111283","pt":1588428161117,"mc":[{"id":"1.170370557","rc":[{"atl":[[1.46,89.02],[1.48,0]],"id":9624350}],"con":true,"img":false}]}
{"op":"mcm","clk":"1362111287","pt":1588428161219,"mc":[{"id":"1.170370557","rc":[{"atb":[[1.37,300],[1.34,18.95]],"id":9624350},{"atl":[[1.44,222.68]],"id":9624350}],"con":true,"img":false}]}
{"op":"mcm","clk":"1362111290","pt":1588428161323,"mc":[{"id":"1.170370557","rc":[{"atb":[[3,2.92]],"id":9622734}],"con":true,"img":false}]}
{"op":"mcm","clk":"1362111295","pt":1588428161630,"mc":[{"id":"1.170370557","rc":[{"atl":[[1.57,0]],"id":9624350}],"con":true,"img":false}]}
{"op":"mcm","clk":"1362111308","pt":1588428162550,"mc":[{"id":"1.170370557","rc":[{"atb":[[1.42,0]],"id":9624350}],"con":true,"img":false}]}
{"op":"mcm","clk":"1362111310","pt":1588428162652,"mc":[{"id":"1.170370557","rc":[{"atb":[[3.25,97.51]],"id":9622734}],"con":true,"img":false}]}
{"op":"mcm","clk":"1362111319","pt":1588428163061,"mc":[{"id":"1.170370557","rc":[{"atb":[[1.42,221.63]],"id":9624350}],"con":true,"img":false}]}
{"op":"mcm","clk":"1362111326","pt":1588428163316,"mc":[{"id":"1.170370557","rc":[{"trd":[[1.44,8386.04],[1.43,2530.07]],"ltp":1.44,"tv":10916.11,"id":9624350},{"atb":[[1.43,112],[1.44,32.51]],"id":9624350},{"atl":[[1.44,0],[1.43,0]],"id":9624350}],"con":true,"img":false}]}
{"op":"mcm","clk":"1362111329","pt":1588428163418,"mc":[{"id":"1.170370557","rc":[{"atb":[[1.43,167]],"id":9624350}],"con":true,"img":false}]}
{"op":"mcm","clk":"1362111341","pt":1588428163827,"mc":[{"id":"1.170370557","rc":[{"trd":[[1.44,8386.5]],"ltp":1.44,"tv":8386.5,"id":9624350},{"atb":[[1.44,32.28]],"id":9624350},{"atl":[[1.51,8.86]],"id":9624350}],"con":true,"img":false}]}
{"op":"mcm","clk":"1362111344","pt":1588428163929,"mc":[{"id":"1.170370557","rc":[{"trd":[[3.25,2010.08]],"ltp":3.25,"tv":2010.08,"id":9622734},{"atb":[[3.25,96.33]],"id":9622734}],"con":true,"img":false}]}
{"op":"mcm","clk":"1362111347","pt":1588428164031,"mc":[{"id":"1.170370557","rc":[{"trd":[[1.44,8451.06]],"ltp":1.44,"tv":8451.06,"id":9624350},{"atb":[[1.4,221.89],[1.44,0]],"id":9624350},{"atl":[[1.44,67.72]],"id":9624350}],"con":true,"img":false}]}
{"op":"mcm","clk":"1362111350","pt":1588428164133,"mc":[{"id":"1.170370557","rc":[{"atb":[[1.41,112]],"id":9624350}],"con":true,"img":false}]}
{"op":"mcm","clk":"1362111356","pt":1588428164441,"mc":[{"id":"1.170370557","rc":[{"atb":[[1.39,333]],"id":9624350}],"con":true,"img":false}]}
{"op":"mcm","clk":"1362111372","pt":1588428165263,"mc":[{"id":"1.170370557","rc":[{"atb":[[3.25,0]],"id":9622734}],"con":true,"img":false}]}
{"op":"mcm","clk":"1362111375","pt":1588428165366,"mc":[{"id":"1.170370557","rc":[{"atb":[[1.43,344.3],[1.39,0]],"id":9624350}],"con":true,"img":false}]}
{"op":"mcm","clk":"1362111381","pt":1588428165621,"mc":[{"id":"1.170370557","rc":[{"atb":[[1.43,432.95],[1.4,443.52]],"id":9624350}],"con":true,"img":false}]}
{"op":"mcm","clk":"1362111386","pt":1588428165826,"mc":[{"id":"1.170370557","rc":[{"atb":[[1.43,521.6]],"id":9624350}],"con":true,"img":false}]}
{"op":"mcm","clk":"1362111389","pt":1588428165928,"mc":[{"id":"1.170370557","rc":[{"trd":[[1.43,2547.8]],"ltp":1.43,"tv":2547.8,"id":9624350},{"atb":[[1.43,512.73],[1.38,0]],"id":9624350}],"con":true,"img":false}]}
{"op":"mcm","clk":"1362111398","pt":1588428166240,"mc":[{"id":"1.170370557","rc":[{"atb":[[1.4,532.17]],"id":9624350}],"con":true,"img":false}]}
{"op":"mcm","clk":"1362111406","pt":1588428166755,"mc":[{"id":"1.170370557","rc":[{"trd":[[1.43,3208.39]],"ltp":1.43,"tv":3208.39,"id":9624350},{"atb":[[1.43,182.44]],"id":9624350}],"con":true,"img":false}]}
{"op":"mcm","clk":"1362111411","pt":1588428167061,"mc":[{"id":"1.170370557","rc":[{"trd":[[1.44,8451.72]],"ltp":1.44,"tv":8451.72,"id":9624350},{"atb":[[1.38,221.63]],"id":9624350},{"atl":[[1.44,67.39]],"id":9624350}],"con":true,"img":false}]}
{"op":"mcm","clk":"1362111418","pt":1588428167419,"mc":[{"id":"1.170370557","rc":[{"atb":[[1.4,443.52]],"id":9624350}],"con":true,"img":false}]}
{"op":"mcm","clk":"1362111421","pt":1588428167521,"mc":[{"id":"1.170370557","rc":[{"atb":[[1.37,0]],"id":9624350}],"con":true,"img":false}]}
{"op":"mcm","clk":"1362111426","pt":1588428167724,"mc":[{"id":"1.170370557","rc":[{"atb":[[1.43,910.57]],"id":9624350}],"con":true,"img":false}]}
{"op":"mcm","clk":"1362111429","pt":1588428167826,"mc":[{"id":"1.170370557","rc":[{"atb":[[1.38,443.26]],"id":9624350}],"con":true,"img":false}]}
{"op":"mcm","clk":"1362111438","pt":1588428168233,"mc":[{"id":"1.170370557","rc":[{"atb":[[1.43,821.92]],"id":9624350}],"con":true,"img":false}]}
{"op":"mcm","clk":"1362111449","pt":1588428168847,"mc":[{"id":"1.170370557","rc":[{"atb":[[1.43,93.79]],"id":9624350}],"con":true,"img":false}]}
{"op":"mcm","clk":"1362111452","pt":1588428168948,"mc":[{"id":"1.170370557","rc":[{"atl":[[1.56,443.26]],"id":9624350}],"con":true,"img":false}]}
{"op":"mcm","clk":"1362111478","pt":1588428170331,"mc":[{"id":"1.170370557","rc":[{"atb":[[1.43,93.91]],"id":9624350}],"con":true,"img":false}]}
{"op":"mcm","clk":"1362111481","pt":1588428170434,"mc":[{"id":"1.170370557","rc":[{"atb":[[1.43,126.7]],"id":9624350}],"con":true,"img":false}]}
{"op":"mcm","clk":"1362111495","pt":1588428171252,"mc":[{"id":"1.170370557","rc":[{"atb":[[1.41,0]],"id":9624350}],"con":true,"img":false}]}
{"op":"mcm","clk":"1362111501","pt":1588428171458,"mc":[{"id":"1.170370557","rc":[{"trd":[[1.44,8587.07]],"ltp":1.44,"tv":8587.07,"id":9624350},{"atb":[[1.44,20.97]],"id":9624350},{"atl":[[1.44,0]],"id":9624350}],"con":true,"img":false}]}
{"op":"mcm","clk":"1362111510","pt":1588428171868,"mc":[{"id":"1.170370557","rc":[{"atb":[[1.43,209.17]],"id":9624350}],"con":true,"img":false}]}
{"op":"mcm","clk":"1362111513","pt":1588428171971,"mc":[{"id":"1.170370557","rc":[{"trd":[[1.44,8604.56]],"ltp":1.44,"tv":8604.56,"id":9624350},{"atb":[[1.44,12.22],[1.26,381.19]],"id":9624350}],"con":true,"img":false}]}
{"op":"mcm","clk":"1362111523","pt":1588428172537,"mc":[{"id":"1.170370557","rc":[{"atb":[[1.2,8.86],[1.18,0],[1.16,492.02],[1.17,0],[1.19,0]],"id":9624350}],"con":true,"img":false}]}
{"op":"mcm","clk":"1362111531","pt":1588428172946,"mc":[{"id":"1.170370557","rc":[{"trd":[[3.2,57.04]],"ltp":3.2,"tv":57.04,"id":9622734},{"trd":[[1.45,1163.51]],"ltp":1.45,"tv":1163.51,"id":9624350},{"atl":[[1.45,166.17]],"id":9624350}],"con":true,"img":false}]}
{"op":"mcm","clk":"1362111543","pt":1588428173660,"mc":[{"id":"1.170370557","rc":[{"atb":[[1.43,204.02]],"id":9624350}],"con":true,"img":false}]}
{"op":"mcm","clk":"1362111551","pt":1588428174068,"mc":[{"id":"1.170370557","rc":[{"trd":[[1.45,1495.87]],"ltp":1.45,"tv":1495.87,"id":9624350},{"atb":[[1.45,551.9]],"id":9624350},{"atl":[[1.45,0]],"id":9624350}],"con":true,"img":false}]}
{"op":"mcm","clk":"1362111556","pt":1588428174273,"mc":[{"id":"1.170370557","rc":[{"atb":[[1.43,171.23]],"id":9624350}],"con":true,"img":false}]}
{"op":"mcm","clk":"1362111568","pt":1588428174734,"mc":[{"id":"1.170370557","rc":[{"atl":[[1000,1.77]],"id":9622734}],"con":true,"img":false}]}
{"op":"mcm","clk":"1362111575","pt":1588428175144,"mc":[{"id":"1.170370557","rc":[{"trd":[[3,90.22]],"ltp":3.0,"tv":90.22,"id":9622734},{"atb":[[3,0]],"id":9622734},{"atl":[[1000,1.17]],"id":9622734},{"trd":[[1.51,229.92],[1.46,994.72],[1.49,1236.96],[1.5,1100.67]],"ltp":1.51,"tv":3562.27,"id":9624350},{"atl":[[1.46,0],[1.49,0],[1.51,5.16]],"id":9624350}],"con":true,"img":false}]}
{"op":"mcm","clk":"1362111578","pt":1588428175350,"mc":[{"id":"1.170370557","rc":[{"atb":[[1.43,283.23]],"id":9624350}],"con":true,"img":false}]}
{"op":"mcm","clk":"1362111582","pt":1588428175555,"mc":[{"id":"1.170370557","rc":[{"atl":[[1000,0]],"id":9622734}],"con":true,"img":false}]}
{"op":"mcm","clk":"1362111598","pt":1588428176273,"mc":[{"id":"1.170370557","rc":[{"atb":[[1.38,0]],"id":9624350}],"con":true,"img":false}]}
{"op":"mcm","clk":"1362111611","pt":1588428177140,"mc":[{"id":"1.170370557","rc":[{"trd":[[1.45,1513.6]],"ltp":1.45,"tv":1513.6,"id":9624350},{"atb":[[1.45,543.04]],"id":9624350}],"con":true,"img":false}]}
{"op":"mcm","clk":"1362111613","pt":1588428177244,"mc":[{"id":"1.170370557","rc":[{"atb":[[1.26,0]],"id":9624350}],"con":true,"img":false}]}
{"op":"mcm","clk":"1362111631","pt":1588428178070,"mc":[{"id":"1.170370557","rc":[{"trd":[[3.25,2060.95]],"ltp":3.25,"tv":2060.95,"id":9622734},{"trd":[[1.45,1627.62]],"ltp":1.45,"tv":1627.62,"id":9624350},{"atb":[[1.45,429.02]],"id":9624350}],"con":true,"img":false}]}
{"op":"mcm","clk":"1362111644","pt":1588428178532,"mc":[{"id":"1.170370557","rc":[{"trd":[[1.45,1636.89]],"ltp":1.45,"tv":1636.89,"id":9624350},{"atb":[[1.45,424.38]],"id":9624350}],"con":true,"img":false}]}
{"op":"mcm","clk":"1362111653","pt":1588428179351,"mc":[{"id":"1.170370557","rc":[{"atb":[[1.44,45.01]],"id":9624350}],"con":true,"img":false}]}
{"op":"mcm","clk":"1362111657","pt":1588428179555,"mc":[{"id":"1.170370557","rc":[{"atb":[[1.23,0]],"id":9624350}],"con":true,"img":false}]}
{"op":"mcm","clk":"1362111664","pt":1588428179862,"mc":[{"id":"1.170370557","rc":[{"atb":[[1.34,0]],"id":9624350}],"con":true,"img":false}]}
{"op":"mcm","clk":"1362111668","pt":1588428180067,"mc":[{"id":"1.170370557","rc":[{"atb":[[1.44,47.59]],"id":9624350}],"con":true,"img":false}]}
{"op":"mcm","clk":"1362111676","pt":1588428180681,"mc":[{"id":"1.170370557","rc":[{"atl":[[3.25,1.17]],"id":9622734}],"con":true,"img":false}]}
{"op":"mcm","clk":"1362111699","pt":1588428181960,"mc":[{"id":"1.170370557","rc":[{"trd":[[1.51,234.49]],"ltp":1.51,"tv":234.49,"id":9624350},{"atl":[[1.51,2.88]],"id":9624350}],"con":true,"img":false}]}
{"op":"mcm","clk":"1362111708","pt":1588428182371,"mc":[{"id":"1.170370557","rc":[{"atb":[[1.49,88.65]],"id":9624350}],"con":true,"img":false}]}
{"op":"mcm","clk":"1362111710","pt":1588428182474,"mc":[{"id":"1.170370557","rc":[{"trd":[[1.51,240.26]],"ltp":1.51,"tv":240.26,"id":9624350},{"atb":[[1.51,315.2],[1.47,300]],"id":9624350},{"atl":[[1.51,0]],"id":9624350}],"con":true,"img":false}]}
{"op":"mcm","clk":"1362111712","pt":1588428182576,"mc":[{"id":"1.170370557","rc":[{"atb":[[1.51,427.2]],"id":9624350}],"con":true,"img":false}]}
{"op":"mcm","clk":"1362111715","pt":1588428182678,"mc":[{"id":"1.170370557","rc":[{"atb":[[1.49,177.3]],"id":9624350}],"con":true,"img":false}]}
{"op":"mcm","clk":"1362111717","pt":1588428182781,"mc":[{"id":"1.170370557","rc":[{"atb":[[1.49,289.3]],"id":9624350}],"con":true,"img":false}]}
{"op":"mcm","clk":"1362111720","pt":1588428182884,"mc":[{"id":"1.170370557","rc":[{"atb":[[1.49,377.95]],"id":9624350}],"con":true,"img":false}]}
{"op":"mcm","clk":"1362111724","pt":1588428182987,"mc":[{"id":"1.170370557","rc":[{"trd":[[2.98,50.87]],"ltp":2.98,"tv":50.87,"id":9622734},{"trd":[[1.51,340.65]],"ltp":1.51,"tv":340.65,"id":9624350},{"atb":[[1.49,466.6],[1.51,326.81],[1.48,112]],"id":9624350}],"con":true,"img":false}]}
{"op":"mcm","clk":"1362111727","pt":1588428183038,"mc":[{"id":"1.170370557","rc":[{"atb":[[1.43,200.76]],"id":9624350}],"con":true,"img":false}]}
{"op":"mcm","clk":"1362111730","pt":1588428183141,"mc":[{"id":"1.170370557","rc":[{"atb":[[1.49,555.26]],"id":9624350}],"con":true,"img":false}]}
{"op":"mcm","clk":"1362111734","pt":1588428183243,"mc":[{"id":"1.170370557","rc":[{"atl":[[1.6,500.28]],"id":9624350}],"con":true,"img":false}]}
{"op":"mcm","clk":"1362111736","pt":1588428183346,"mc":[{"id":"1.170370557","rc":[{"atl":[[3.25,0]],"id":9622734},{"atb":[[1.49,643.91]],"id":9624350}],"con":true,"img":false}]}
{"op":"mcm","clk":"1362111739","pt":1588428183551,"mc":[{"id":"1.170370557","rc":[{"trd":[[2.98,101.74]],"ltp":2.98,"tv":101.74,"id":9622734},{"trd":[[1.51,441.04]],"ltp":1.51,"tv":441.04,"id":9624350},{"atb":[[1.51,226.42]],"id":9624350}],"con":true,"img":false}]}
{"op":"mcm","clk":"1362111746","pt":1588428184165,"mc":[{"id":"1.170370557","rc":[{"atb":[[1.43,112.11]],"id":9624350}],"con":true,"img":false}]}
{"op":"mcm","clk":"1362111749","pt":1588428184267,"mc":[{"id":"1.170370557","rc":[{"atb":[[1.49,943.91]],"id":9624350}],"con":true,"img":false}]}
{"op":"mcm","clk":"1362111753","pt":1588428184472,"mc":[{"id":"1.170370557","rc":[{"atb":[[1.44,35.37]],"id":9624350}],"con":true,"img":false}]}
{"op":"mcm","clk":"1362111759","pt":1588428184780,"mc":[{"id":"1.170370557","rc":[{"atb":[[1.51,526.42]],"id":9624350}],"con":true,"img":false}]}
{"op":"mcm","clk":"1362111761","pt":1588428184882,"mc":[{"id":"1.170370557","rc":[{"atb":[[1.46,354.6]],"id":9624350}],"con":true,"img":false}]}
{"op":"mcm","clk":"1362111765","pt":1588428185086,"mc":[{"id":"1.170370557","rc":[{"atb":[[1.48,376.93],[1.47,0]],"id":9624350}],"con":true,"img":false}]}
{"op":"mcm","clk":"1362111767","pt":1588428185189,"mc":[{"id":"1.170370557","rc":[{"atb":[[1.45,0]],"id":9624350}],"con":true,"img":false}]}
{"op":"mcm","clk":"1362111771","pt":1588428185342,"mc":[{"id":"1.170370557","rc":[{"atb":[[1.28,256.34],[1.45,354.6]],"id":9624350}],"con":true,"img":false}]}
{"op":"mcm","clk":"1362111782","pt":1588428186059,"mc":[{"id":"1.170370557","rc":[{"atb":[[1.48,396.93]],"id":9624350}],"con":true,"img":false}]}
{"op":"mcm","clk":"1362111784","pt":1588428186161,"mc":[{"id":"1.170370557","rc":[{"atb":[[1.46,372],[1.49,831.91]],"id":9624350}],"con":true,"img":false}]}
{"op":"mcm","clk":"1362111789","pt":1588428186468,"mc":[{"id":"1.170370557","rc":[{"atb":[[1.48,470.81]],"id":9624350}],"con":true,"img":false}]}
{"op":"mcm","clk":"1362111798","pt":1588428187081,"mc":[{"id":"1.170370557","rc":[{"atb":[[1.49,531.91]],"id":9624350}],"con":true,"img":false}]}
{"op":"mcm","clk":"1362111806","pt":1588428187540,"mc":[{"id":"1.170370557","rc":[{"trd":[[1.51,445.6]],"ltp":1.51,"tv":445.6,"id":9624350},{"atb":[[1.51,524.14]],"id":9624350}],"con":true,"img":false}]}
{"op":"mcm","clk":"1362111812","pt":1588428188050,"mc":[{"id":"1.170370557","rc":[{"atb":[[1.43,112]],"id":9624350}],"con":true,"img":false}]}
{"op":"mcm","clk":"1362111823","pt":1588428188662,"mc":[{"id":"1.170370557","rc":[{"atb":[[1.44,2.57]],"id":9624350}],"con":true,"img":false}]}
{"op":"mcm","clk":"1362111828","pt":1588428189071,"mc":[{"id":"1.170370557","rc":[{"trd":[[1.56,1433.51]],"ltp":1.56,"tv":1433.51,"id":9624350},{"atl":[[1.56,443.07]],"id":9624350}],"con":true,"img":false}]}
{"op":"mcm","clk":"1362111834","pt":1588428189583,"mc":[{"id":"1.170370557","rc":[{"atb":[[1.52,20]],"id":9624350}],"con":true,"img":false}]}
{"op":"mcm","clk":"1362111842","pt":1588428190247,"mc":[{"id":"1.170370557","rc":[{"atb":[[1.46,372.28]],"id":9624350}],"con":true,"img":false}]}
{"op":"mcm","clk":"1362111844","pt":1588428190349,"mc":[{"id":"1.170370557","rc":[{"atb":[[1.52,424.84]],"id":9624350}],"con":true,"img":false}]}
{"op":"mcm","clk":"1362111848","pt":1588428190658,"mc":[{"id":"1.170370557","rc":[{"atb":[[1.42,0]],"id":9624350}],"con":true,"img":false}]}
{"op":"mcm","clk":"1362111852","pt":1588428191108,"mc":[{"id":"1.170370557","rc":[{"atb":[[1.52,479.84]],"id":9624350}],"con":true,"img":false}]}
{"op":"mcm","clk":"1362111857","pt":1588428191375,"mc":[{"id":"1.170370557","rc":[{"atb":[[1.4,0.26]],"id":9624350}],"con":true,"img":false}]}
{"op":"mcm","clk":"1362111862","pt":1588428191480,"mc":[{"id":"1.170370557","rc":[{"atb":[[1.53,55],[1.48,396.93]],"id":9624350}],"con":true,"img":false}]}
{"op":"mcm","clk":"1362111872","pt":1588428191992,"mc":[{"id":"1.170370557","rc":[{"atb":[[1.51,413.03],[1.47,354.6]],"id":9624350}],"con":true,"img":false}]}
{"op":"mcm","clk":"1362111874","pt":1588428192094,"mc":[{"id":"1.170370557","rc":[{"trd":[[2.78,160.58]],"ltp":2.78,"tv":160.58,"id":9622734},{"trd":[[1.56,1505.51]],"ltp":1.56,"tv":1505.51,"id":9624350},{"atl":[[1.56,371.08]],"id":9624350}],"con":true,"img":false}]}
{"op":"mcm","clk":"1362111893","pt":1588428193471,"mc":[{"id":"1.170370557","rc":[{"atb":[[1.51,301.03]],"id":9624350}],"con":true,"img":false}]}
{"op":"mcm","clk":"1362111895","pt":1588428193573,"mc":[{"id":"1.170370557","rc":[{"atl":[[1.56,0]],"id":9624350}],"con":true,"img":false}]}
{"op":"mcm","clk":"1362111897","pt":1588428193676,"mc":[{"id":"1.170370557","rc":[{"atl":[[1.59,300]],"id":9624350}],"con":true,"img":false}]}
{"op":"mcm","clk":"1362111900","pt":1588428193779,"mc":[{"id":"1.170370557","rc":[{"atb":[[1.55,32.79]],"id":9624350}],"con":true,"img":false}]}
{"op":"mcm","clk":"1362111902","pt":1588428194084,"mc":[{"id":"1.170370557","rc":[{"atb":[[1.46,372],[1.5,132.97]],"id":9624350}],"con":true,"img":false}]}
{"op":"mcm","clk":"1362111906","pt":1588428194394,"mc":[{"id":"1.170370557","rc":[{"atl":[[1.62,300]],"id":9624350}],"con":true,"img":false}]}
{"op":"mcm","clk":"1362111913","pt":1588428194803,"mc":[{"id":"1.170370557","rc":[{"atb":[[1.47,0]],"id":9624350},{"atl":[[1.63,300]],"id":9624350}],"con":true,"img":false}]}
{"op":"mcm","clk":"1362111916","pt":1588428194854,"mc":[{"id":"1.170370557","rc":[{"atb":[[1.48,376.93]],"id":9624350}],"con":true,"img":false}]}
{"op":"mcm","clk":"1362111921","pt":1588428195263,"mc":[{"id":"1.170370557","rc":[{"trd":[[1.52,1158.48],[1.55,1066.24],[1.53,1926.97]],"ltp":1.52,"tv":4151.69,"id":9624350},{"atb":[[1.53,0],[1.52,435.21],[1.55,0]],"id":9624350}],"con":true,"img":false}]}
{"op":"mcm","clk":"1362111924","pt":1588428195467,"mc":[{"id":"1.170370557","rc":[{"atb":[[1.54,147.1]],"id":9624350}],"con":true,"img":false}]}
{"op":"mcm","clk":"1362111927","pt":1588428195671,"mc":[{"id":"1.170370557","rc":[{"atl":[[1.55,88.65]],"id":9624350}],"con":true,"img":false}]}
{"op":"mcm","clk":"1362111929","pt":1588428195773,"mc":[{"id":"1.170370557","rc":[{"trd":[[1.55,1066.7]],"ltp":1.55,"tv":1066.7,"id":9624350},{"atl":[[1.55,88.42]],"id":9624350}],"con":true,"img":false}]}
{"op":"mcm","clk":"1362111931","pt":1588428195876,"mc":[{"id":"1.170370557","rc":[{"atl":[[1.55,177.07]],"id":9624350}],"con":true,"img":false}]}
{"op":"mcm","clk":"1362111934","pt":1588428196081,"mc":[{"id":"1.170370557","rc":[{"atl":[[1.55,265.72]],"id":9624350}],"con":true,"img":false}]}
{"op":"mcm","clk":"1362111941","pt":1588428196489,"mc":[{"id":"1.170370557","rc":[{"atb":[[1.53,112]],"id":9624350}],"con":true,"img":false}]}
{"op":"mcm","clk":"1362111952","pt":1588428196796,"mc":[{"id":"1.170370557","rc":[{"atb":[[1.45,0]],"id":9624350}],"con":true,"img":false}]}
{"op":"mcm","clk":"1362111959","pt":1588428197203,"mc":[{"id":"1.170370557","rc":[{"atb":[[1.53,222.67],[1.54,259.1]],"id":9624350}],"con":true,"img":false}]}
{"op":"mcm","clk":"1362111963","pt":1588428197457,"mc":[{"id":"1.170370557","rc":[{"atb":[[1.48,112]],"id":9624350}],"con":true,"img":false}]}
{"op":"mcm","clk":"1362111965","pt":1588428197560,"mc":[{"id":"1.170370557","rc":[{"atb":[[1.53,112]],"id":9624350}],"con":true,"img":false}]}
{"op":"mcm","clk":"1362111970","pt":1588428197763,"mc":[{"id":"1.170370557","rc":[{"atb":[[1.5,487.58]],"id":9624350}],"con":true,"img":false}]}
{"op":"mcm","clk":"1362111972","pt":1588428197865,"mc":[{"id":"1.170370557","rc":[{"atb":[[2.62,4]],"id":9622734}],"con":true,"img":false}]}
{"op":"mcm","clk":"1362111976","pt":1588428198272,"mc":[{"id":"1.170370557","rc":[{"atb":[[1.46,354.6]],"id":9624350}],"con":true,"img":false}]}
{"op":"mcm","clk":"1362111981","pt":1588428198680,"mc":[{"id":"1.170370557","rc":[{"atb":[[1.53,55],[1.51,300]],"id":9624350},{"atl":[[1.59,0],[1.63,0],[1.62,0]],"id":9624350}],"con":true,"img":false}]}
{"op":"mcm","clk":"1362111996","pt":1588428200208,"mc":[{"id":"1.170370557","rc":[{"atb":[[1.51,0]],"id":9624350}],"con":true,"img":false}]}
{"op":"mcm","clk":"1362112003","pt":1588428200679,"mc":[{"id":"1.170370557","rc":[{"atb":[[1.48,0]],"id":9624350}],"con":true,"img":false}]}
{"op":"mcm","clk":"1362112007","pt":1588428200882,"mc":[{"id":"1.170370557","rc":[{"atl":[[1.69,443.26]],"id":9624350}],"con":true,"img":false}]}
{"op":"mcm","clk":"1362112023","pt":1588428202268,"mc":[{"id":"1.170370557","rc":[{"atl":[[1.6,500]],"id":9624350}],"con":true,"img":false}]}
{"op":"mcm","clk":"1362112027","pt":1588428202473,"mc":[{"id":"1.170370557","rc":[{"trd":[[1.54,3790.99]],"ltp":1.54,"tv":3790.99,"id":9624350},{"atb":[[1.54,258.94]],"id":9624350}],"con":true,"img":false}]}
{"op":"mcm","clk":"1362112037","pt":1588428203293,"mc":[{"id":"1.170370557","rc":[{"atb":[[1.38,443.26]],"id":9624350}],"con":true,"img":false}]}
{"op":"mcm","clk":"1362112054","pt":1588428204268,"mc":[{"id":"1.170370557","rc":[{"atb":[[1.5,354.6]],"id":9624350}],"con":true,"img":false}]}
{"op":"mcm","clk":"1362112066","pt":1588428205190,"mc":[{"id":"1.170370557","rc":[{"atb":[[2.62,0]],"id":9622734},{"trd":[[1.54,3818.98]],"ltp":1.54,"tv":3818.98,"id":9624350},{"atb":[[1.54,244.94]],"id":9624350}],"con":true,"img":false}]}
{"op":"mcm","clk":"1362112069","pt":1588428205395,"mc":[{"id":"1.170370557","rc":[{"atb":[[2.6,0]],"id":9622734},{"atl":[[4.2,0]],"id":9622734},{"atb":[[1.33,0]],"id":9624350},{"atl":[[1.7,0]],"id":9624350}],"con":true,"img":false}]}
{"op":"mcm","clk":"1362112076","pt":1588428206008,"mc":[{"id":"1.170370557","rc":[{"trd":[[1.55,1598.15]],"ltp":1.55,"tv":1598.15,"id":9624350},{"atb":[[1.58,484.28]],"id":9624350},{"atl":[[1.55,0]],"id":9624350}],"con":true,"img":false}]}
{"op":"mcm","clk":"1362112080","pt":1588428206212,"mc":[{"id":"1.170370557","rc":[{"atb":[[1.2,28.86]],"id":9624350}],"con":true,"img":false}]}
{"op":"mcm","clk":"1362112089","pt":1588428206978,"mc":[{"id":"1.170370557","rc":[{"trd":[[1.58,341.37]],"ltp":1.58,"tv":341.37,"id":9624350},{"atb":[[1.58,483.68]],"id":9624350}],"con":true,"img":false}]}
{"op":"mcm","clk":"1362112098","pt":1588428207488,"mc":[{"id":"1.170370557","rc":[{"trd":[[1.58,341.61]],"ltp":1.58,"tv":341.61,"id":9624350},{"atb":[[1.58,483.56]],"id":9624350}],"con":true,"img":false}]}
{"op":"mcm","clk":"1362112104","pt":1588428207897,"mc":[{"id":"1.170370557","rc":[{"trd":[[1.58,350.47]],"ltp":1.58,"tv":350.47,"id":9624350},{"atb":[[1.58,479.13]],"id":9624350}],"con":true,"img":false}]}
{"op":"mcm","clk":"1362112112","pt":1588428208408,"mc":[{"id":"1.170370557","rc":[{"atb":[[1.53,0],[1.52,380.21],[1.58,0]],"id":9624350},{"atl":[[1.6,0]],"id":9624350}],"con":true,"img":false}]}
{"op":"mcm","clk":"1362112121","pt":1588428209279,"mc":[{"id":"1.170370557","rc":[{"atb":[[1.49,0]],"id":9624350}],"con":true,"img":false}]}
{"op":"mcm","clk":"1362112131","pt":1588428210101,"mc":[{"id":"1.170370557","rc":[{"atl":[[1.55,0.42]],"id":9624350}],"con":true,"img":false}]}
{"op":"mcm","clk":"1362112140","pt":1588428210818,"mc":[{"id":"1.170370557","rc":[{"trd":[[2.86,3.73]],"ltp":2.86,"tv":3.73,"id":9622734},{"trd":[[1.54,3829.16]],"ltp":1.54,"tv":3829.16,"id":9624350},{"atb":[[1.54,237.27]],"id":9624350}],"con":true,"img":false}]}
{"op":"mcm","clk":"1362112142","pt":1588428210920,"mc":[{"id":"1.170370557","rc":[{"trd":[[2.86,53.73]],"ltp":2.86,"tv":53.73,"id":9622734},{"trd":[[1.54,3922.02]],"ltp":1.54,"tv":3922.02,"id":9624350},{"atb":[[1.54,144.42]],"id":9624350}],"con":true,"img":false}]}
{"op":"mcm","clk":"1362112147","pt":1588428211075,"mc":[{"id":"1.170370557","rc":[{"atb":[[1.55,0.61]],"id":9624350},{"atl":[[1.55,0]],"id":9624350}],"con":true,"img":false}]}
{"op":"mcm","clk":"1362112149","pt":1588428211279,"mc":[{"id":"1.170370557","rc":[{"trd":[[2.86,103.39],[2.82,10.34]],"ltp":2.86,"tv":113.73,"id":9622734},{"trd":[[1.54,4014.25],[1.55,1598.76]],"ltp":1.54,"tv":5613.01,"id":9624350},{"atb":[[1.55,0],[1.54,52.19]],"id":9624350}],"con":true,"img":false}]}
{"op":"mcm","clk":"1362112153","pt":1588428211483,"mc":[{"id":"1.170370557","rc":[{"trd":[[1.54,4014.95]],"ltp":1.54,"tv":4014.95,"id":9624350},{"atb":[[1.54,51.84]],"id":9624350}],"con":true,"img":false}]}
{"op":"mcm","clk":"1362112162","pt":1588428212199,"mc":[{"id":"1.170370557","rc":[{"atl":[[2.8,22.68]],"id":9622734}],"con":true,"img":false}]}
{"op":"mcm","clk":"1362112177","pt":1588428213326,"mc":[{"id":"1.170370557","rc":[{"trd":[[2.8,187.97]],"ltp":2.8,"tv":187.97,"id":9622734},{"atl":[[2.8,17.14]],"id":9622734}],"con":true,"img":false}]}
{"op":"mcm","clk":"1362112189","pt":1588428214298,"mc":[{"id":"1.170370557","rc":[{"atb":[[1.5,0]],"id":9624350}],"con":true,"img":false}]}
{"op":"mcm","clk":"1362112193","pt":1588428214604,"mc":[{"id":"1.170370557","rc":[{"atb":[[1.28,0],[1.55,691.98]],"id":9624350},{"atl":[[1.77,0]],"id":9624350}],"con":true,"img":false}]}
{"op":"mcm","clk":"1362112198","pt":1588428214915,"mc":[{"id":"1.170370557","rc":[{"trd":[[1.55,1602.81]],"ltp":1.55,"tv":1602.81,"id":9624350},{"atb":[[1.55,689.95]],"id":9624350}],"con":true,"img":false}]}
{"op":"mcm","clk":"1362112204","pt":1588428215119,"mc":[{"id":"1.170370557","rc":[{"atb":[[2.58,4]],"id":9622734},{"atb":[[1.46,0]],"id":9624350}],"con":true,"img":false}]}
{"op":"mcm","clk":"1362112208","pt":1588428215323,"mc":[{"id":"1.170370557","rc":[{"atl":[[2.8,0]],"id":9622734}],"con":true,"img":false}]}
{"op":"mcm","clk":"1362112215","pt":1588428215783,"mc":[{"id":"1.170370557","rc":[{"atl":[[1.58,2.57]],"id":9624350}],"con":true,"img":false}]}
{"op":"mcm","clk":"1362112220","pt":1588428216192,"mc":[{"id":"1.170370557","rc":[{"trd":[[1.55,1603.29]],"ltp":1.55,"tv":1603.29,"id":9624350},{"atb":[[1.55,689.71]],"id":9624350}],"con":true,"img":false}]}
{"op":"mcm","clk":"1362112230","pt":1588428217009,"mc":[{"id":"1.170370557","rc":[{"atb":[[1.4,23.39]],"id":9624350}],"con":true,"img":false}]}
{"op":"mcm","clk":"1362112242","pt":1588428217824,"mc":[{"id":"1.170370557","rc":[{"atb":[[1.57,321.47]],"id":9624350}],"con":true,"img":false}]}
{"op":"mcm","clk":"1362112247","pt":1588428218130,"mc":[{"id":"1.170370557","rc":[{"trd":[[2.76,23.84]],"ltp":2.76,"tv":23.84,"id":9622734},{"trd":[[1.57,488.42]],"ltp":1.57,"tv":488.42,"id":9624350},{"atb":[[1.57,279.54]],"id":9624350}],"con":true,"img":false}]}
{"op":"mcm","clk":"1362112257","pt":1588428218896,"mc":[{"id":"1.170370557","rc":[{"trd":[[2.76,40.46]],"ltp":2.76,"tv":40.46,"id":9622734},{"trd":[[1.57,517.63]],"ltp":1.57,"tv":517.63,"id":9624350},{"atb":[[1.57,250.33]],"id":9624350}],"con":true,"img":false}]}
{"op":"mcm","clk":"1362112265","pt":1588428219405,"mc":[{"id":"1.170370557","rc":[{"trd":[[1.58,355.63]],"ltp":1.58,"tv":355.63,"id":9624350},{"atb":[[1.58,747.42]],"id":9624350},{"atl":[[1.58,0]],"id":9624350}],"con":true,"img":false}]}
{"op":"mcm","clk":"1362112277","pt":1588428219915,"mc":[{"id":"1.170370557","rc":[{"atb":[[1.58,0]],"id":9624350}],"con":true,"img":false}]}
{"op":"mcm","clk":"1362112303","pt":1588428221703,"mc":[{"id":"1.170370557","rc":[{"atb":[[1.43,0],[1.36,0],[1.54,0]],"id":9624350}],"con":true,"img":false}]}
{"op":"mcm","clk":"1362112307","pt":1588428221908,"mc":[{"id":"1.170370557","rc":[{"atb":[[1.57,338.98]],"id":9624350}],"con":true,"img":false}]}
{"op":"mcm","clk":"1362112320","pt":1588428222725,"mc":[{"id":"1.170370557","rc":[{"trd":[[2.76,185.85]],"ltp":2.76,"tv":185.85,"id":9622734},{"trd":[[1.57,773.23]],"ltp":1.57,"tv":773.23,"id":9624350},{"atb":[[1.57,83.39]],"id":9624350}],"con":true,"img":false}]}
{"op":"mcm","clk":"1362112329","pt":1588428223133,"mc":[{"id":"1.170370557","rc":[{"atb":[[1.57,0]],"id":9624350}],"con":true,"img":false}]}
{"op":"mcm","clk":"1362112331","pt":1588428223235,"mc":[{"id":"1.170370557","rc":[{"atl":[[1.63,70.35]],"id":9624350}],"con":true,"img":false}]}
{"op":"mcm","clk":"1362112341","pt":1588428223900,"mc":[{"id":"1.170370557","rc":[{"atl":[[1.63,0]],"id":9624350}],"con":true,"img":false}]}
{"op":"mcm","clk":"1362112357","pt":1588428225124,"mc":[{"id":"1.170370557","rc":[{"atb":[[1.4,0.26]],"id":9624350}],"con":true,"img":false}]}
{"op":"mcm","clk":"1362112359","pt":1588428225226,"mc":[{"id":"1.170370557","rc":[{"atb":[[1.6,143.23]],"id":9624350}],"con":true,"img":false}]}
{"op":"mcm","clk":"1362112362","pt":1588428225431,"mc":[{"id":"1.170370557","rc":[{"atb":[[1.6,0]],"id":9624350}],"con":true,"img":false}]}
{"op":"mcm","clk":"1362112364","pt":1588428225533,"mc":[{"id":"1.170370557","rc":[{"atb":[[1.58,88.65]],"id":9624350}],"con":true,"img":false}]}
{"op":"mcm","clk":"1362112367","pt":1588428225737,"mc":[{"id":"1.170370557","rc":[{"atb":[[1.59,88.65]],"id":9624350}],"con":true,"img":false}]}
{"op":"mcm","clk":"1362112370","pt":1588428225840,"mc":[{"id":"1.170370557","rc":[{"trd":[[1.58,532.93],[1.59,366.91]],"ltp":1.58,"tv":899.83,"id":9624350},{"atb":[[1.59,0],[1.58,0]],"id":9624350},{"atl":[[1.56,94.55]],"id":9624350}],"con":true,"img":false}]}
{"op":"mcm","clk":"1362112372","pt":1588428225942,"mc":[{"id":"1.170370557","rc":[{"trd":[[1.56,1682.81]],"ltp":1.56,"tv":1682.81,"id":9624350},{"atl":[[1.56,5.9]],"id":9624350}],"con":true,"img":false}]}
{"op":"mcm","clk":"1362112374","pt":1588428226095,"mc":[{"id":"1.170370557","rc":[{"trd":[[1.56,1694.61]],"ltp":1.56,"tv":1694.61,"id":9624350},{"atb":[[1.59,82.74]],"id":9624350},{"atl":[[1.56,0]],"id":9624350}],"con":true,"img":false}]}
{"op":"mcm","clk":"1362112380","pt":1588428226400,"mc":[{"id":"1.170370557","rc":[{"atb":[[1.58,88.65]],"id":9624350}],"con":true,"img":false}]}
{"op":"mcm","clk":"1362112382","pt":1588428226502,"mc":[{"id":"1.170370557","rc":[{"atb":[[1.58,177.3]],"id":9624350}],"con":true,"img":false}]}
{"op":"mcm","clk":"1362112385","pt":1588428226706,"mc":[{"id":"1.170370557","rc":[{"atb":[[1.58,265.95]],"id":9624350}],"con":true,"img":false}]}
{"op":"mcm","clk":"1362112388","pt":1588428226909,"mc":[{"id":"1.170370557","rc":[{"atb":[[1.58,354.6],[1.55,0]],"id":9624350}],"con":true,"img":false}]}
{"op":"mcm","clk":"1362112401","pt":1588428227522,"mc":[{"id":"1.170370557","rc":[{"trd":[[1.59,454.91]],"ltp":1.59,"tv":454.91,"id":9624350},{"atb":[[1.59,38.75],[1.58,443.26]],"id":9624350}],"con":true,"img":false}]}
{"op":"mcm","clk":"1362112404","pt":1588428227624,"mc":[{"id":"1.170370557","rc":[{"atb":[[1.58,88.65]],"id":9624350}],"con":true,"img":false}]}
{"op":"mcm","clk":"1362112406","pt":1588428227726,"mc":[{"id":"1.170370557","rc":[{"atb":[[1.58,265.95]],"id":9624350}],"con":true,"img":false}]}
{"op":"mcm","clk":"1362112408","pt":1588428227828,"mc":[{"id":"1.170370557","rc":[{"atb":[[1.59,0]],"id":9624350}],"con":true,"img":false}]}
{"op":"mcm","clk":"1362112410","pt":1588428227931,"mc":[{"id":"1.170370557","rc":[{"atb":[[1.58,354.6]],"id":9624350}],"con":true,"img":false}]}
{"op":"mcm","clk":"1362112414","pt":1588428228236,"mc":[{"id":"1.170370557","rc":[{"atb":[[1.58,438]],"id":9624350}],"con":true,"img":false}]}
{"op":"mcm","clk":"1362112418","pt":1588428228542,"mc":[{"id":"1.170370557","rc":[{"atb":[[1.58,83.39]],"id":9624350}],"con":true,"img":false}]}
{"op":"mcm","clk":"1362112435","pt":1588428229826,"mc":[{"id":"1.170370557","rc":[{"trd":[[2.74,18.83]],"ltp":2.74,"tv":18.83,"id":9622734},{"trd":[[1.58,561.75]],"ltp":1.58,"tv":561.75,"id":9624350},{"atb":[[1.58,54.57]],"id":9624350}],"con":true,"img":false}]}
{"op":"mcm","clk":"1362112438","pt":1588428229928,"mc":[{"id":"1.170370557","rc":[{"trd":[[2.74,21.32]],"ltp":2.74,"tv":21.32,"id":9622734},{"trd":[[1.58,566.08]],"ltp":1.58,"tv":566.08,"id":9624350},{"atb":[[1.58,50.24]],"id":9624350}],"con":true,"img":false}]}
{"op":"mcm","clk":"1362112458","pt":1588428231306,"mc":[{"id":"1.170370557","rc":[{"atl":[[1.63,70.35]],"id":9624350}],"con":true,"img":false}]}
{"op":"mcm","clk":"1362112466","pt":1588428231919,"mc":[{"id":"1.170370557","rc":[{"atb":[[1.39,23.3]],"id":9624350}],"con":true,"img":false}]}
{"op":"mcm","clk":"1362112493","pt":1588428234112,"mc":[{"id":"1.170370557","rc":[{"trd":[[1.58,666.58]],"ltp":1.58,"tv":666.58,"id":9624350},{"atb":[[1.58,0]],"id":9624350},{"atl":[[1.58,26.17]],"id":9624350}],"con":true,"img":false}]}
{"op":"mcm","clk":"1362112532","pt":1588428236919,"mc":[{"id":"1.170370557","rc":[{"atb":[[1.55,88.65]],"id":9624350},{"atl":[[1.57,0.23]],"id":9624350}],"con":true,"img":false}]}
{"op":"mcm","clk":"1362112537","pt":1588428237327,"mc":[{"id":"1.170370557","rc":[{"trd":[[1.58,671.49],[1.57,773.69]],"ltp":1.58,"tv":1445.18,"id":9624350},{"atb":[[1.55,177.3]],"id":9624350},{"atl":[[1.57,0],[1.58,23.71]],"id":9624350}],"con":true,"img":false}]}
{"op":"mcm","clk":"1362112545","pt":1588428237836,"mc":[{"id":"1.170370557","rc":[{"atb":[[1.55,265.95]],"id":9624350}],"con":true,"img":false}]}
{"op":"mcm","clk":"1362112548","pt":1588428238040,"mc":[{"id":"1.170370557","rc":[{"atb":[[1.55,354.6]],"id":9624350}],"con":true,"img":false}]}
{"op":"mcm","clk":"1362112551","pt":1588428238243,"mc":[{"id":"1.170370557","rc":[{"atb":[[1.55,443.26]],"id":9624350}],"con":true,"img":false}]}
{"op":"mcm","clk":"1362112553","pt":1588428238345,"mc":[{"id":"1.170370557","rc":[{"trd":[[2.58,6.74],[2.72,55.57]],"ltp":2.58,"tv":62.31,"id":9622734},{"atb":[[2.58,0.63]],"id":9622734},{"trd":[[1.58,695.21]],"ltp":1.58,"tv":695.21,"id":9624350},{"atl":[[1.58,0]],"id":9624350}],"con":true,"img":false}]}
{"op":"mcm","clk":"1362112569","pt":1588428239622,"mc":[{"id":"1.170370557","rc":[{"atl":[[1.58,0.46]],"id":9624350}],"con":true,"img":false}]}
{"op":"mcm","clk":"1362112572","pt":1588428239826,"mc":[{"id":"1.170370557","rc":[{"atl":[[1.58,2.09]],"id":9624350}],"con":true,"img":false}]}
{"op":"mcm","clk":"1362112579","pt":1588428240441,"mc":[{"id":"1.170370557","rc":[{"atb":[[1.41,354.6]],"id":9624350}],"con":true,"img":false}]}
{"op":"mcm","clk":"1362112588","pt":1588428241053,"mc":[{"id":"1.170370557","rc":[{"atl":[[1.62,443.26]],"id":9624350}],"con":true,"img":false}]}
{"op":"mcm","clk":"1362112591","pt":1588428241154,"mc":[{"id":"1.170370557","rc":[{"atl":[[1.58,2.27]],"id":9624350}],"con":true,"img":false}]}
{"op":"mcm","clk":"1362112599","pt":1588428241721,"mc":[{"id":"1.170370557","rc":[{"atl":[[1.57,355]],"id":9624350}],"con":true,"img":false}]}
{"op":"mcm","clk":"1362112607","pt":1588428242236,"mc":[{"id":"1.170370557","rc":[{"atb":[[1.26,354.6]],"id":9624350}],"con":true,"img":false}]}
{"op":"mcm","clk":"1362112615","pt":1588428242749,"mc":[{"id":"1.170370557","rc":[{"atb":[[1.27,354.6]],"id":9624350}],"con":true,"img":false}]}
{"op":"mcm","clk":"1362112620","pt":1588428242954,"mc":[{"id":"1.170370557","rc":[{"trd":[[1.57,776.72]],"ltp":1.57,"tv":776.72,"id":9624350},{"atl":[[1.57,353.48]],"id":9624350}],"con":true,"img":false}]}
{"op":"mcm","clk":"1362112625","pt":1588428243261,"mc":[{"id":"1.170370557","rc":[{"atl":[[1.63,0]],"id":9624350}],"con":true,"img":false}]}
{"op":"mcm","clk":"1362112630","pt":1588428243621,"mc":[{"id":"1.170370557","rc":[{"atl":[[1.57,442.13]],"id":9624350}],"con":true,"img":false}]}
{"op":"mcm","clk":"1362112633","pt":1588428243827,"mc":[{"id":"1.170370557","rc":[{"atl":[[1.57,530.78]],"id":9624350}],"con":true,"img":false}]}
{"op":"mcm","clk":"1362112636","pt":1588428244031,"mc":[{"id":"1.170370557","rc":[{"atl":[[1.57,619.43]],"id":9624350}],"con":true,"img":false}]}
{"op":"mcm","clk":"1362112639","pt":1588428244133,"mc":[{"id":"1.170370557","rc":[{"atb":[[1.21,354.6]],"id":9624350}],"con":true,"img":false}]}
{"op":"mcm","clk":"1362112640","pt":1588428244235,"mc":[{"id":"1.170370557","rc":[{"atl":[[1.57,708.08]],"id":9624350}],"con":true,"img":false}]}
{"op":"mcm","clk":"1362112648","pt":1588428244954,"mc":[{"id":"1.170370557","rc":[{"atl":[[1.58,2.09]],"id":9624350}],"con":true,"img":false}]}
{"op":"mcm","clk":"1362112650","pt":1588428245057,"mc":[{"id":"1.170370557","rc":[{"atb":[[1.21,709.21]],"id":9624350}],"con":true,"img":false}]}
{"op":"mcm","clk":"1362112655","pt":1588428245413,"mc":[{"id":"1.170370557","rc":[{"trd":[[1.55,1603.6]],"ltp":1.55,"tv":1603.6,"id":9624350},{"atb":[[1.55,443.11]],"id":9624350}],"con":true,"img":false}]}
{"op":"mcm","clk":"1362112663","pt":1588428245720,"mc":[{"id":"1.170370557","rc":[{"atb":[[1.55,0]],"id":9624350}],"con":true,"img":false}]}
{"op":"mcm","clk":"1362112684","pt":1588428247350,"mc":[{"id":"1.170370557","rc":[{"atl":[[1.59,0.11]],"id":9624350}],"con":true,"img":false}]}
{"op":"mcm","clk":"1362112692","pt":1588428247960,"mc":[{"id":"1.170370557","rc":[{"atl":[[1.59,0.38]],"id":9624350}],"con":true,"img":false}]}
{"op":"mcm","clk":"1362112713","pt":1588428249948,"mc":[{"id":"1.170370557","rc":[{"trd":[[1.57,780.96]],"ltp":1.57,"tv":780.96,"id":9624350},{"atl":[[1.57,705.96]],"id":9624350}],"con":true,"img":false}]}
{"op":"mcm","clk":"1362112727","pt":1588428250917,"mc":[{"id":"1.170370557","rc":[{"atb":[[1.4,86.5]],"id":9624350}],"con":true,"img":false}]}
{"op":"mcm","clk":"1362112734","pt":1588428251324,"mc":[{"id":"1.170370557","rc":[{"atl":[[1.62,0]],"id":9624350}],"con":true,"img":false}]}
{"op":"mcm","clk":"1362112737","pt":1588428251528,"mc":[{"id":"1.170370557","rc":[{"atb":[[1.54,88.65]],"id":9624350}],"con":true,"img":false}]}
{"op":"mcm","clk":"1362112741","pt":1588428251836,"mc":[{"id":"1.170370557","rc":[{"atb":[[1.54,177.3]],"id":9624350}],"con":true,"img":false}]}
{"op":"mcm","clk":"1362112745","pt":1588428252148,"mc":[{"id":"1.170370557","rc":[{"trd":[[1.57,781.2]],"ltp":1.57,"tv":781.2,"id":9624350},{"atl":[[1.57,705.84]],"id":9624350}],"con":true,"img":false}]}
{"op":"mcm","clk":"1362112751","pt":1588428252655,"mc":[{"id":"1.170370557","rc":[{"atb":[[1.54,265.95]],"id":9624350}],"con":true,"img":false}]}
{"op":"mcm","clk":"1362112763","pt":1588428253725,"mc":[{"id":"1.170370557","rc":[{"atb":[[2.82,1.93]],"id":9622734}],"con":true,"img":false}]}
{"op":"mcm","clk":"1362112782","pt":1588428254948,"mc":[{"id":"1.170370557","rc":[{"trd":[[2.82,12.27]],"ltp":2.82,"tv":12.27,"id":9622734},{"atb":[[2.82,0]],"id":9622734},{"trd":[[1.57,792.14],[1.55,1607.13]],"ltp":1.57,"tv":2399.27,"id":9624350},{"atl":[[1.57,700.37]],"id":9624350}],"con":true,"img":false}]}
{"op":"mcm","clk":"1362112800","pt":1588428256531,"mc":[{"id":"1.170370557","rc":[{"trd":[[1.54,4019.66]],"ltp":1.54,"tv":4019.66,"id":9624350},{"atb":[[1.54,263.59]],"id":9624350}],"con":true,"img":false}]}
{"op":"mcm","clk":"1362112820","pt":1588428257756,"mc":[{"id":"1.170370557","rc":[{"atl":[[1.57,354.6]],"id":9624350}],"con":true,"img":false}]}
{"op":"mcm","clk":"1362112829","pt":1588428258573,"mc":[{"id":"1.170370557","rc":[{"trd":[[1.54,4546.86]],"ltp":1.54,"tv":4546.86,"id":9624350},{"atb":[[1.54,0]],"id":9624350},{"atl":[[1.54,179.66]],"id":9624350}],"con":true,"img":false}]}
{"op":"mcm","clk":"1362112842","pt":1588428259134,"mc":[{"id":"1.170370557","rc":[{"atl":[[1.57,0]],"id":9624350}],"con":true,"img":false}]}
{"op":"mcm","clk":"1362112852","pt":1588428259744,"mc":[{"id":"1.170370557","rc":[{"trd":[[2.84,4.46]],"ltp":2.84,"tv":4.46,"id":9622734},{"trd":[[1.54,4550.13]],"ltp":1.54,"tv":4550.13,"id":9624350},{"atl":[[1.54,176.39]],"id":9624350}],"con":true,"img":false}]}
{"op":"mcm","clk":"1362112857","pt":1588428260256,"mc":[{"id":"1.170370557","rc":[{"trd":[[1.52,1188.67]],"ltp":1.52,"tv":1188.67,"id":9624350},{"atb":[[1.52,365.11]],"id":9624350}],"con":true,"img":false}]}
{"op":"mcm","clk":"1362112864","pt":1588428260871,"mc":[{"id":"1.170370557","rc":[{"atl":[[1.54,0]],"id":9624350}],"con":true,"img":false}]}
{"op":"mcm","clk":"1362112873","pt":1588428261737,"mc":[{"id":"1.170370557","rc":[{"atl":[[1.58,1.63]],"id":9624350}],"con":true,"img":false}]}
{"op":"mcm","clk":"1362112887","pt":1588428262654,"mc":[{"id":"1.170370557","rc":[{"trd":[[1.59,455.69],[1.58,698.48]],"ltp":1.59,"tv":1154.17,"id":9624350},{"atb":[[1.4,0.26],[1.63,103.88],[1.61,123.8]],"id":9624350},{"atl":[[1.59,0],[1.58,0]],"id":9624350}],"con":true,"img":false}]}
{"op":"mcm","clk":"1362112892","pt":1588428263065,"mc":[{"id":"1.170370557","rc":[{"atb":[[1.57,4.7]],"id":9624350}],"con":true,"img":false}]}
{"op":"mcm","clk":"1362112898","pt":1588428263577,"mc":[{"id":"1.170370557","rc":[{"atb":[[1.59,300]],"id":9624350}],"con":true,"img":false}]}
{"op":"mcm","clk":"1362112901","pt":1588428263781,"mc":[{"id":"1.170370557","rc":[{"atb":[[1.61,275.14]],"id":9624350}],"con":true,"img":false}]}
{"op":"mcm","clk":"1362112906","pt":1588428264137,"mc":[{"id":"1.170370557","rc":[{"atb":[[1.24,46.36],[1.38,0]],"id":9624350},{"atl":[[1.69,0]],"id":9624350}],"con":true,"img":false}]}
{"op":"mcm","clk":"1362112912","pt":1588428264545,"mc":[{"id":"1.170370557","rc":[{"atb":[[1.34,245.54],[1.57,93.35]],"id":9624350},{"atl":[[1.95,216.23]],"id":9624350}],"con":true,"img":false}]}
{"op":"mcm","clk":"1362112916","pt":1588428264851,"mc":[{"id":"1.170370557","rc":[{"atb":[[1.56,88.65]],"id":9624350}],"con":true,"img":false}]}
{"op":"mcm","clk":"1362112919","pt":1588428265055,"mc":[{"id":"1.170370557","rc":[{"atb":[[1.56,177.3],[1.55,112]],"id":9624350}],"con":true,"img":false}]}
{"op":"mcm","clk":"1362112922","pt":1588428265259,"mc":[{"id":"1.170370557","rc":[{"atb":[[1.56,265.95]],"id":9624350}],"con":true,"img":false}]}
{"op":"mcm","clk":"1362112925","pt":1588428265463,"mc":[{"id":"1.170370557","rc":[{"atb":[[1.56,354.6]],"id":9624350}],"con":true,"img":false}]}
{"op":"mcm","clk":"1362112929","pt":1588428265771,"mc":[{"id":"1.170370557","rc":[{"atb":[[1.56,443.26]],"id":9624350}],"con":true,"img":false}]}
{"op":"mcm","clk":"1362112935","pt":1588428266234,"mc":[{"id":"1.170370557","rc":[{"atb":[[1.59,375.12]],"id":9624350}],"con":true,"img":false}]}
{"op":"mcm","clk":"1362112950","pt":1588428267258,"mc":[{"id":"1.170370557","rc":[{"trd":[[1.61,413.63],[1.63,348.45]],"ltp":1.61,"tv":762.07,"id":9624350},{"atb":[[1.63,0],[1.61,259.04]],"id":9624350}],"con":true,"img":false}]}
{"op":"mcm","clk":"1362112953","pt":1588428267361,"mc":[{"id":"1.170370557","rc":[{"atb":[[1.56,0]],"id":9624350}],"con":true,"img":false}]}
{"op":"mcm","clk":"1362112967","pt":1588428268739,"mc":[{"id":"1.170370557","rc":[{"atb":[[1.56,263.44],[1.61,107.7]],"id":9624350}],"con":true,"img":false}]}
{"op":"mcm","clk":"1362112970","pt":1588428269045,"mc":[{"id":"1.170370557","rc":[{"trd":[[2.58,7.37]],"ltp":2.58,"tv":7.37,"id":9622734},{"atb":[[2.58,0]],"id":9622734},{"trd":[[1.64,222.85]],"ltp":1.64,"tv":222.85,"id":9624350},{"atb":[[1.64,54.01]],"id":9624350},{"atl":[[1.64,0]],"id":9624350}],"con":true,"img":false}]}
{"op":"mcm","clk":"1362112975","pt":1588428269452,"mc":[{"id":"1.170370557","rc":[{"trd":[[1.64,222.87]],"ltp":1.64,"tv":222.87,"id":9624350},{"atb":[[1.64,54]],"id":9624350}],"con":true,"img":false}]}
{"op":"mcm","clk":"1362112977","pt":1588428269554,"mc":[{"id":"1.170370557","rc":[{"trd":[[1.66,111.75]],"ltp":1.66,"tv":111.75,"id":9624350},{"atb":[[1.53,354.6],[1.66,110.55]],"id":9624350},{"atl":[[1.66,0]],"id":9624350}],"con":true,"img":false}]}
{"op":"mcm","clk":"1362112982","pt":1588428269962,"mc":[{"id":"1.170370557","rc":[{"atb":[[1.39,0]],"id":9624350}],"con":true,"img":false}]}
{"op":"mcm","clk":"1362112984","pt":1588428270064,"mc":[{"id":"1.170370557","rc":[{"atb":[[1.54,0.11]],"id":9624350}],"con":true,"img":false}]}
{"op":"mcm","clk":"1362112986","pt":1588428270167,"mc":[{"id":"1.170370557","rc":[{"atb":[[1.64,166]],"id":9624350}],"con":true,"img":false}]}
{"op":"mcm","clk":"1362112988","pt":1588428270268,"mc":[{"id":"1.170370557","rc":[{"atb":[[1.64,314.57]],"id":9624350}],"con":true,"img":false}]}
{"op":"mcm","clk":"1362112991","pt":1588428270370,"mc":[{"id":"1.170370557","rc":[{"atl":[[1.72,443.26]],"id":9624350}],"con":true,"img":false}]}
{"op":"mcm","clk":"1362112996","pt":1588428270778,"mc":[{"id":"1.170370557","rc":[{"atb":[[1.64,358.17]],"id":9624350}],"con":true,"img":false}]}
{"op":"mcm","clk":"1362113005","pt":1588428271542,"mc":[{"id":"1.170370557","rc":[{"atb":[[1.68,150]],"id":9624350}],"con":true,"img":false}]}
{"op":"mcm","clk":"1362113063","pt":1588428274965,"mc":[{"id":"1.170370557","rc":[{"trd":[[2.48,11.89]],"ltp":2.48,"tv":11.89,"id":9622734},{"trd":[[1.68,0.3]],"ltp":1.68,"tv":0.3,"id":9624350},{"atb":[[1.68,149.7]],"id":9624350}],"con":true,"img":false}]}
{"op":"mcm","clk":"1362113070","pt":1588428275577,"mc":[{"id":"1.170370557","rc":[{"atb":[[1.3,8.52]],"id":9624350}],"con":true,"img":false}]}
{"op":"mcm","clk":"1362113072","pt":1588428275679,"mc":[{"id":"1.170370557","rc":[{"atb":[[1.67,112]],"id":9624350}],"con":true,"img":false}]}
{"op":"mcm","clk":"1362113074","pt":1588428275781,"mc":[{"id":"1.170370557","rc":[{"atb":[[1.64,314.57]],"id":9624350}],"con":true,"img":false}]}
{"op":"mcm","clk":"1362113076","pt":1588428275883,"mc":[{"id":"1.170370557","rc":[{"trd":[[1.64,656.19],[1.67,226.72],[1.68,299.7],[1.66,332.85]],"ltp":1.64,"tv":1515.46,"id":9624350},{"atb":[[1.68,0],[1.67,0],[1.66,0],[1.64,97.91]],"id":9624350}],"con":true,"img":false}]}
{"op":"mcm","clk":"1362113078","pt":1588428275985,"mc":[{"id":"1.170370557","rc":[{"trd":[[1.64,833.5]],"ltp":1.64,"tv":833.5,"id":9624350},{"atb":[[1.64,9.26]],"id":9624350}],"con":true,"img":false}]}
{"op":"mcm","clk":"1362113086","pt":1588428276749,"mc":[{"id":"1.170370557","rc":[{"atl":[[2.56,100]],"id":9622734}],"con":true,"img":false}]}
{"op":"mcm","clk":"1362113096","pt":1588428277770,"mc":[{"id":"1.170370557","rc":[{"atb":[[1.61,0],[1.59,75.12],[1.55,0]],"id":9624350}],"con":true,"img":false}]}
{"op":"mcm","clk":"1362113101","pt":1588428277974,"mc":[{"id":"1.170370557","rc":[{"atb":[[1.52,0]],"id":9624350}],"con":true,"img":false}]}
{"op":"mcm","clk":"1362113109","pt":1588428278382,"mc":[{"id":"1.170370557","rc":[{"trd":[[1.64,834.42]],"ltp":1.64,"tv":834.42,"id":9624350},{"atb":[[1.64,8.8]],"id":9624350}],"con":true,"img":false}]}
{"op":"mcm","clk":"1362113113","pt":1588428278687,"mc":[{"id":"1.170370557","rc":[{"atb":[[1.59,0]],"id":9624350}],"con":true,"img":false}]}
{"op":"mcm","clk":"1362113115","pt":1588428278790,"mc":[{"id":"1.170370557","rc":[{"atl":[[1.68,79.15]],"id":9624350}],"con":true,"img":false}]}
{"op":"mcm","clk":"1362113117","pt":1588428278891,"mc":[{"id":"1.170370557","rc":[{"atb":[[1.65,110.81]],"id":9624350}],"con":true,"img":false}]}
{"op":"mcm","clk":"1362113124","pt":1588428279351,"mc":[{"id":"1.170370557","rc":[{"atl":[[1.68,0]],"id":9624350}],"con":true,"img":false}]}
{"op":"mcm","clk":"1362113127","pt":1588428279553,"mc":[{"id":"1.170370557","rc":[{"atl":[[2.56,0]],"id":9622734}],"con":true,"img":false}]}
{"op":"mcm","clk":"1362113145","pt":1588428280573,"mc":[{"id":"1.170370557","rc":[{"trd":[[1.65,26.34]],"ltp":1.65,"tv":26.34,"id":9624350},{"atb":[[1.65,99.64]],"id":9624350}],"con":true,"img":false}]}
{"op":"mcm","clk":"1362113152","pt":1588428280981,"mc":[{"id":"1.170370557","rc":[{"trd":[[1.65,48.68]],"ltp":1.65,"tv":48.68,"id":9624350},{"atb":[[1.65,88.47]],"id":9624350}],"con":true,"img":false}]}
{"op":"mcm","clk":"1362113156","pt":1588428281388,"mc":[{"id":"1.170370557","rc":[{"atl":[[1.68,0.23]],"id":9624350}],"con":true,"img":false}]}
{"op":"mcm","clk":"1362113159","pt":1588428281591,"mc":[{"id":"1.170370557","rc":[{"atl":[[1.68,100.23]],"id":9624350}],"con":true,"img":false}]}
{"op":"mcm","clk":"1362113166","pt":1588428281795,"mc":[{"id":"1.170370557","rc":[{"atb":[[2.48,13.84]],"id":9622734}],"con":true,"img":false}]}
{"op":"mcm","clk":"1362113170","pt":1588428281999,"mc":[{"id":"1.170370557","rc":[{"trd":[[2.58,12.96],[2.54,57.47]],"ltp":2.58,"tv":70.43,"id":9622734},{"atb":[[2.58,193.98]],"id":9622734},{"trd":[[1.64,843.22],[1.65,137.15]],"ltp":1.64,"tv":980.37,"id":9624350},{"atb":[[1.65,0],[1.64,0]],"id":9624350}],"con":true,"img":false}]}
{"op":"mcm","clk":"1362113172","pt":1588428282101,"mc":[{"id":"1.170370557","rc":[{"trd":[[2.58,40.5]],"ltp":2.58,"tv":40.5,"id":9622734},{"atb":[[2.58,166.44]],"id":9622734},{"trd":[[1.64,886.55]],"ltp":1.64,"tv":886.55,"id":9624350}],"con":true,"img":false}]}
{"op":"mcm","clk":"1362113175","pt":1588428282155,"mc":[{"id":"1.170370557","rc":[{"atb":[[2.52,7.63]],"id":9622734}],"con":true,"img":false}]}
{"op":"mcm","clk":"1362113178","pt":1588428282256,"mc":[{"id":"1.170370557","rc":[{"atl":[[1.68,100.68],[1.71,135.36]],"id":9624350}],"con":true,"img":false}]}
{"op":"mcm","clk":"1362113181","pt":1588428282458,"mc":[{"id":"1.170370557","rc":[{"atl":[[1.66,11.83]],"id":9624350}],"con":true,"img":false}]}
{"op":"mcm","clk":"1362113187","pt":1588428282763,"mc":[{"id":"1.170370557","rc":[{"trd":[[2.58,56.1]],"ltp":2.58,"tv":56.1,"id":9622734},{"atb":[[2.58,150.84]],"id":9622734},{"trd":[[1.64,911.09]],"ltp":1.64,"tv":911.09,"id":9624350}],"con":true,"img":false}]}
{"op":"mcm","clk":"1362113191","pt":1588428282968,"mc":[{"id":"1.170370557","rc":[{"atb":[[2.52,0]],"id":9622734},{"atl":[[1.69,186.39]],"id":9624350}],"con":true,"img":false}]}
{"op":"mcm","clk":"1362113196","pt":1588428283174,"mc":[{"id":"1.170370557","rc":[{"trd":[[2.58,206.94]],"ltp":2.58,"tv":206.94,"id":9622734},{"atb":[[2.58,0]],"id":9622734},{"trd":[[1.64,1148.39]],"ltp":1.64,"tv":1148.39,"id":9624350},{"atb":[[1.64,101.09]],"id":9624350}],"con":true,"img":false}]}
{"op":"mcm","clk":"1362113205","pt":1588428283481,"mc":[{"id":"1.170370557","rc":[{"trd":[[1.68,302.14],[1.66,356.53]],"ltp":1.68,"tv":658.67,"id":9624350},{"atl":[[1.68,99.46],[1.66,0]],"id":9624350}],"con":true,"img":false}]}
{"op":"mcm","clk":"1362113231","pt":1588428285066,"mc":[{"id":"1.170370557","rc":[{"atl":[[1.68,99.68],[1.71,20]],"id":9624350}],"con":true,"img":false}]}
{"op":"mcm","clk":"1362113233","pt":1588428285168,"mc":[{"id":"1.170370557","rc":[{"atl":[[1.69,0]],"id":9624350}],"con":true,"img":false}]}
{"op":"mcm","clk":"1362113237","pt":1588428285474,"mc":[{"id":"1.170370557","rc":[{"atb":[[2.48,21.41]],"id":9622734}],"con":true,"img":false}]}
{"op":"mcm","clk":"1362113240","pt":1588428285576,"mc":[{"id":"1.170370557","rc":[{"atl":[[1.66,11.59]],"id":9624350}],"con":true,"img":false}]}
{"op":"mcm","clk":"1362113249","pt":1588428286188,"mc":[{"id":"1.170370557","rc":[{"atb":[[2.48,13.84]],"id":9622734}],"con":true,"img":false}]}
{"op":"mcm","clk":"1362113251","pt":1588428286301,"mc":[{"id":"1.170370557","rc":[{"atl":[[1.66,0]],"id":9624350}],"con":true,"img":false}]}
{"op":"mcm","clk":"1362113266","pt":1588428287162,"mc":[{"id":"1.170370557","rc":[{"atb":[[1.56,0],[1.57,4.7]],"id":9624350},{"atl":[[1.72,0]],"id":9624350}],"con":true,"img":false}]}
{"op":"mcm","clk":"1362113271","pt":1588428287374,"mc":[{"id":"1.170370557","rc":[{"atb":[[1.64,0]],"id":9624350}],"con":true,"img":false}]}
{"op":"mcm","clk":"1362113275","pt":1588428287672,"mc":[{"id":"1.170370557","rc":[{"atl":[[1.64,20.79],[1.65,88.65]],"id":9624350}],"con":true,"img":false}]}
{"op":"mcm","clk":"1362113277","pt":1588428287774,"mc":[{"id":"1.170370557","rc":[{"atb":[[1.34,0]],"id":9624350}],"con":true,"img":false}]}
{"op":"mcm","clk":"1362113279","pt":1588428287876,"mc":[{"id":"1.170370557","rc":[{"atl":[[1.65,177.3]],"id":9624350}],"con":true,"img":false}]}
{"op":"mcm","clk":"1362113282","pt":1588428288081,"mc":[{"id":"1.170370557","rc":[{"atl":[[1.65,265.95]],"id":9624350}],"con":true,"img":false}]}
{"op":"mcm","clk":"1362113285","pt":1588428288183,"mc":[{"id":"1.170370557","rc":[{"atb":[[1.21,0],[1.53,0],[1.41,0],[1.27,0],[1.26,0]],"id":9624350}],"con":true,"img":false}]}
{"op":"mcm","clk":"1362113292","pt":1588428288492,"mc":[{"id":"1.170370557","rc":[{"atb":[[1.59,500]],"id":9624350}],"con":true,"img":false}]}
{"op":"mcm","clk":"1362113296","pt":1588428288696,"mc":[{"id":"1.170370557","rc":[{"atb":[[1.59,0]],"id":9624350}],"con":true,"img":false}]}
{"op":"mcm","clk":"1362113299","pt":1588428288800,"mc":[{"id":"1.170370557","rc":[{"atl":[[1.95,0]],"id":9624350}],"con":true,"img":false}]}
{"op":"mcm","clk":"1362113301","pt":1588428288902,"mc":[{"id":"1.170370557","rc":[{"atl":[[1.64,29.66]],"id":9624350}],"con":true,"img":false}]}
{"op":"mcm","clk":"1362113316","pt":1588428289678,"mc":[{"id":"1.170370557","rc":[{"trd":[[1.64,1148.85]],"ltp":1.64,"tv":1148.85,"id":9624350},{"atl":[[1.64,29.42]],"id":9624350}],"con":true,"img":false}]}
{"op":"mcm","clk":"1362113322","pt":1588428290183,"mc":[{"id":"1.170370557","rc":[{"atl":[[1.64,20.56]],"id":9624350}],"con":true,"img":false}]}
{"op":"mcm","clk":"1362113326","pt":1588428290387,"mc":[{"id":"1.170370557","rc":[{"atl":[[1.66,189.76]],"id":9624350}],"con":true,"img":false}]}
{"op":"mcm","clk":"1362113329","pt":1588428290693,"mc":[{"id":"1.170370557","rc":[{"atl":[[1.67,118.13]],"id":9624350}],"con":true,"img":false}]}
{"op":"mcm","clk":"1362113334","pt":1588428291100,"mc":[{"id":"1.170370557","rc":[{"atl":[[1.71,0]],"id":9624350}],"con":true,"img":false}]}
{"op":"mcm","clk":"1362113342","pt":1588428291869,"mc":[{"id":"1.170370557","rc":[{"atl":[[1.62,112]],"id":9624350}],"con":true,"img":false}]}
{"op":"mcm","clk":"1362113346","pt":1588428292073,"mc":[{"id":"1.170370557","rc":[{"atl":[[1.68,100.39]],"id":9624350}],"con":true,"img":false}]}
{"op":"mcm","clk":"1362113349","pt":1588428292174,"mc":[{"id":"1.170370557","rc":[{"atb":[[1.55,51.92]],"id":9624350},{"atl":[[1.63,150]],"id":9624350}],"con":true,"img":false}]}
{"op":"mcm","clk":"1362113353","pt":1588428292277,"mc":[{"id":"1.170370557","rc":[{"atb":[[1.58,20.5]],"id":9624350},{"atl":[[1.59,112]],"id":9624350}],"con":true,"img":false}]}
{"op":"mcm","clk":"1362113355","pt":1588428292392,"mc":[{"id":"1.170370557","rc":[{"atl":[[1.59,200.65]],"id":9624350}],"con":true,"img":false}]}
{"op":"mcm","clk":"1362113357","pt":1588428292491,"mc":[{"id":"1.170370557","rc":[{"atl":[[1.68,100.17]],"id":9624350}],"con":true,"img":false}]}
{"op":"mcm","clk":"1362113360","pt":1588428292583,"mc":[{"id":"1.170370557","rc":[{"atl":[[1.59,289.3]],"id":9624350}],"con":true,"img":false}]}
{"op":"mcm","clk":"1362113362","pt":1588428292788,"mc":[{"id":"1.170370557","rc":[{"atl":[[1.59,377.95]],"id":9624350}],"con":true,"img":false}]}
{"op":"mcm","clk":"1362113364","pt":1588428292890,"mc":[{"id":"1.170370557","rc":[{"trd":[[1.59,540.67]],"ltp":1.59,"tv":540.67,"id":9624350},{"atl":[[1.59,335.46]],"id":9624350}],"con":true,"img":false}]}
{"op":"mcm","clk":"1362113366","pt":1588428292992,"mc":[{"id":"1.170370557","rc":[{"trd":[[1.59,579.15]],"ltp":1.59,"tv":579.15,"id":9624350},{"atl":[[1.64,22.92],[1.59,404.87]],"id":9624350}],"con":true,"img":false}]}
{"op":"mcm","clk":"1362113368","pt":1588428293095,"mc":[{"id":"1.170370557","rc":[{"atb":[[1.58,0]],"id":9624350}],"con":true,"img":false}]}
{"op":"mcm","clk":"1362113380","pt":1588428293611,"mc":[{"id":"1.170370557","rc":[{"atl":[[1.64,23.21]],"id":9624350}],"con":true,"img":false}]}
{"op":"mcm","clk":"1362113387","pt":1588428293971,"mc":[{"id":"1.170370557","rc":[{"atl":[[1.66,0]],"id":9624350}],"con":true,"img":false}]}
{"op":"mcm","clk":"1362113389","pt":1588428294077,"mc":[{"id":"1.170370557","rc":[{"atl":[[1.61,150]],"id":9624350}],"con":true,"img":false}]}
{"op":"mcm","clk":"1362113394","pt":1588428294379,"mc":[{"id":"1.170370557","rc":[{"atl":[[1.67,0]],"id":9624350}],"con":true,"img":false}]}
{"op":"mcm","clk":"1362113400","pt":1588428294790,"mc":[{"id":"1.170370557","rc":[{"atl":[[1.59,50.27]],"id":9624350}],"con":true,"img":false}]}
{"op":"mcm","clk":"1362113402","pt":1588428294892,"mc":[{"id":"1.170370557","rc":[{"atl":[[1.63,0],[1.61,0]],"id":9624350}],"con":true,"img":false}]}
{"op":"mcm","clk":"1362113405","pt":1588428295097,"mc":[{"id":"1.170370557","rc":[{"atl":[[1.64,34.96]],"id":9624350}],"con":true,"img":false}]}
{"op":"mcm","clk":"1362113408","pt":1588428295199,"mc":[{"id":"1.170370557","rc":[{"atl":[[1.7,2]],"id":9624350}],"con":true,"img":false}]}
{"op":"mcm","clk":"1362113411","pt":1588428295303,"mc":[{"id":"1.170370557","rc":[{"atb":[[2.7,6.95]],"id":9622734}],"con":true,"img":false}]}
{"op":"mcm","clk":"1362113414","pt":1588428295507,"mc":[{"id":"1.170370557","rc":[{"atl":[[1.65,0]],"id":9624350}],"con":true,"img":false}]}
{"op":"mcm","clk":"1362113418","pt":1588428295713,"mc":[{"id":"1.170370557","rc":[{"atb":[[1.55,0]],"id":9624350}],"con":true,"img":false}]}
{"op":"mcm","clk":"1362113422","pt":1588428295870,"mc":[{"id":"1.170370557","rc":[{"atl":[[1.62,0]],"id":9624350}],"con":true,"img":false}]}
{"op":"mcm","clk":"1362113428","pt":1588428296381,"mc":[{"id":"1.170370557","rc":[{"atb":[[2.7,0]],"id":9622734}],"con":true,"img":false}]}
{"op":"mcm","clk":"1362113437","pt":1588428297099,"mc":[{"id":"1.170370557","rc":[{"atl":[[1.64,23.21]],"id":9624350}],"con":true,"img":false}]}
{"op":"mcm","clk":"1362113464","pt":1588428299301,"mc":[{"id":"1.170370557","rc":[{"atb":[[1.58,44.32]],"id":9624350}],"con":true,"img":false}]}
{"op":"mcm","clk":"1362113472","pt":1588428300014,"mc":[{"id":"1.170370557","rc":[{"atb":[[1.46,354.6]],"id":9624350}],"con":true,"img":false}]}
{"op":"mcm","clk":"1362113474","pt":1588428300117,"mc":[{"id":"1.170370557","rc":[{"trd":[[1.58,787.14]],"ltp":1.58,"tv":787.14,"id":9624350},{"atb":[[1.58,0]],"id":9624350},{"atl":[[1.58,155.04]],"id":9624350}],"con":true,"img":false}]}
{"op":"mcm","clk":"1362113480","pt":1588428300577,"mc":[{"id":"1.170370557","rc":[{"trd":[[1.57,802]],"ltp":1.57,"tv":802.0,"id":9624350},{"atb":[[1.57,0]],"id":9624350},{"atl":[[1.57,15.07]],"id":9624350}],"con":true,"img":false}]}
{"op":"mcm","clk":"1362113483","pt":1588428300783,"mc":[{"id":"1.170370557","rc":[{"trd":[[1.57,832.14]],"ltp":1.57,"tv":832.14,"id":9624350},{"atb":[[1.57,87.32]],"id":9624350},{"atl":[[1.57,0]],"id":9624350}],"con":true,"img":false}]}
{"op":"mcm","clk":"1362113495","pt":1588428301596,"mc":[{"id":"1.170370557","rc":[{"atl":[[1.72,443.26]],"id":9624350}],"con":true,"img":false}]}
{"op":"mcm","clk":"1362113500","pt":1588428301803,"mc":[{"id":"1.170370557","rc":[{"atl":[[1.63,88.65]],"id":9624350}],"con":true,"img":false}]}
{"op":"mcm","clk":"1362113504","pt":1588428302007,"mc":[{"id":"1.170370557","rc":[{"atl":[[1.63,177.3]],"id":9624350}],"con":true,"img":false}]}
{"op":"mcm","clk":"1362113507","pt":1588428302213,"mc":[{"id":"1.170370557","rc":[{"atl":[[1.63,265.95]],"id":9624350}],"con":true,"img":false}]}
{"op":"mcm","clk":"1362113517","pt":1588428302892,"mc":[{"id":"1.170370557","rc":[{"atb":[[1.46,376.79]],"id":9624350}],"con":true,"img":false}]}
{"op":"mcm","clk":"1362113520","pt":1588428302992,"mc":[{"id":"1.170370557","rc":[{"atb":[[1.45,112]],"id":9624350}],"con":true,"img":false}]}
{"op":"mcm","clk":"1362113525","pt":1588428303298,"mc":[{"id":"1.170370557","rc":[{"atb":[[1.37,443.26]],"id":9624350}],"con":true,"img":false}]}
{"op":"mcm","clk":"1362113528","pt":1588428303400,"mc":[{"id":"1.170370557","rc":[{"atb":[[1.34,354.6]],"id":9624350}],"con":true,"img":false}]}
{"op":"mcm","clk":"1362113533","pt":1588428303605,"mc":[{"id":"1.170370557","rc":[{"atb":[[1.4,112.26]],"id":9624350}],"con":true,"img":false}]}
{"op":"mcm","clk":"1362113535","pt":1588428303709,"mc":[{"id":"1.170370557","rc":[{"atl":[[1.68,1.16]],"id":9624350}],"con":true,"img":false}]}
{"op":"mcm","clk":"1362113546","pt":1588428304384,"mc":[{"id":"1.170370557","rc":[{"atb":[[1.46,354.6]],"id":9624350}],"con":true,"img":false}]}
{"op":"mcm","clk":"1362113555","pt":1588428304793,"mc":[{"id":"1.170370557","rc":[{"atl":[[1.59,0]],"id":9624350}],"con":true,"img":false}]}
{"op":"mcm","clk":"1362113557","pt":1588428304892,"mc":[{"id":"1.170370557","rc":[{"atl":[[1.66,443.26]],"id":9624350}],"con":true,"img":false}]}
{"op":"mcm","clk":"1362113570","pt":1588428305506,"mc":[{"id":"1.170370557","rc":[{"trd":[[2.76,189.05]],"ltp":2.76,"tv":189.05,"id":9622734},{"trd":[[1.57,837.76]],"ltp":1.57,"tv":837.76,"id":9624350},{"atb":[[1.57,81.7]],"id":9624350}],"con":true,"img":false}]}
{"op":"mcm","clk":"1362113580","pt":1588428305915,"mc":[{"id":"1.170370557","rc":[{"trd":[[1.58,788.52]],"ltp":1.58,"tv":788.52,"id":9624350},{"atl":[[1.58,154.35]],"id":9624350}],"con":true,"img":false}]}
{"op":"mcm","clk":"1362113593","pt":1588428306631,"mc":[{"id":"1.170370557","rc":[{"trd":[[1.57,845.76]],"ltp":1.57,"tv":845.76,"id":9624350},{"atb":[[1.57,77.7]],"id":9624350}],"con":true,"img":false}]}
{"op":"mcm","clk":"1362113596","pt":1588428306790,"mc":[{"id":"1.170370557","rc":[{"trd":[[1.58,876.1]],"ltp":1.58,"tv":876.1,"id":9624350},{"atl":[[1.58,110.56]],"id":9624350}],"con":true,"img":false}]}
{"op":"mcm","clk":"1362113598","pt":1588428306891,"mc":[{"id":"1.170370557","rc":[{"trd":[[1.57,885.76]],"ltp":1.57,"tv":885.76,"id":9624350},{"atb":[[1.57,57.7]],"id":9624350}],"con":true,"img":false}]}
{"op":"mcm","clk":"1362113633","pt":1588428308527,"mc":[{"id":"1.170370557","rc":[{"trd":[[1.57,1001.16]],"ltp":1.57,"tv":1001.16,"id":9624350},{"atb":[[1.57,0]],"id":9624350},{"atl":[[1.57,5.43]],"id":9624350}],"con":true,"img":false}]}
{"op":"mcm","clk":"1362113647","pt":1588428309398,"mc":[{"id":"1.170370557","rc":[{"atb":[[1.45,0],[1.4,0.26]],"id":9624350}],"con":true,"img":false}]}
{"op":"mcm","clk":"1362113655","pt":1588428309809,"mc":[{"id":"1.170370557","rc":[{"atl":[[1.56,0.34],[1.57,160.43]],"id":9624350}],"con":true,"img":false}]}
{"op":"mcm","clk":"1362113673","pt":1588428310727,"mc":[{"id":"1.170370557","rc":[{"atb":[[1.47,22.03]],"id":9624350}],"con":true,"img":false}]}
{"op":"mcm","clk":"1362113676","pt":1588428310931,"mc":[{"id":"1.170370557","rc":[{"atl":[[1.66,0]],"id":9624350}],"con":true,"img":false}]}
{"op":"mcm","clk":"1362113680","pt":1588428311135,"mc":[{"id":"1.170370557","rc":[{"atb":[[1.46,0]],"id":9624350}],"con":true,"img":false}]}
{"op":"mcm","clk":"1362113682","pt":1588428311237,"mc":[{"id":"1.170370557","rc":[{"atb":[[2.76,97.51]],"id":9622734}],"con":true,"img":false}]}
{"op":"mcm","clk":"1362113693","pt":1588428311800,"mc":[{"id":"1.170370557","rc":[{"trd":[[2.76,298.65],[2.78,160.78]],"ltp":2.76,"tv":459.42,"id":9622734},{"atb":[[2.76,42.72]],"id":9622734},{"trd":[[1.56,1694.96]],"ltp":1.56,"tv":1694.96,"id":9624350},{"atl":[[1.56,0],[1.58,0]],"id":9624350}],"con":true,"img":false}]}
{"op":"mcm","clk":"1362113699","pt":1588428312209,"mc":[{"id":"1.170370557","rc":[{"atb":[[2.5,0.28]],"id":9622734}],"con":true,"img":false}]}
{"op":"mcm","clk":"1362113706","pt":1588428312719,"mc":[{"id":"1.170370557","rc":[{"atl":[[1.63,0],[1.57,163]],"id":9624350}],"con":true,"img":false}]}
{"op":"mcm","clk":"1362113711","pt":1588428313026,"mc":[{"id":"1.170370557","rc":[{"atb":[[2.76,0]],"id":9622734}],"con":true,"img":false}]}
{"op":"mcm","clk":"1362113716","pt":1588428313334,"mc":[{"id":"1.170370557","rc":[{"atl":[[1.57,157.57]],"id":9624350}],"con":true,"img":false}]}
{"op":"mcm","clk":"1362113725","pt":1588428313998,"mc":[{"id":"1.170370557","rc":[{"atl":[[1.57,246.76]],"id":9624350}],"con":true,"img":false}]}
{"op":"mcm","clk":"1362113756","pt":1588428316143,"mc":[{"id":"1.170370557","rc":[{"atl":[[1.64,20.84]],"id":9624350}],"con":true,"img":false}]}
{"op":"mcm","clk":"1362113767","pt":1588428316709,"mc":[{"id":"1.170370557","rc":[{"atl":[[1.57,244.18]],"id":9624350}],"con":true,"img":false}]}
{"op":"mcm","clk":"1362113771","pt":1588428317014,"mc":[{"id":"1.170370557","rc":[{"trd":[[1.57,1489.53]],"ltp":1.57,"tv":1489.53,"id":9624350},{"atb":[[1.6,199.07]],"id":9624350},{"atl":[[1.57,0]],"id":9624350}],"con":true,"img":false}]}
{"op":"mcm","clk":"1362113773","pt":1588428317115,"mc":[{"id":"1.170370557","rc":[{"atb":[[1.47,0]],"id":9624350}],"con":true,"img":false}]}
{"op":"mcm","clk":"1362113790","pt":1588428317934,"mc":[{"id":"1.170370557","rc":[{"trd":[[1.6,591.91]],"ltp":1.6,"tv":591.91,"id":9624350},{"atb":[[1.6,196.45]],"id":9624350}],"con":true,"img":false}]}
{"op":"mcm","clk":"1362113797","pt":1588428318446,"mc":[{"id":"1.170370557","rc":[{"atb":[[1.6,300.07]],"id":9624350}],"con":true,"img":false}]}
{"op":"mcm","clk":"1362113802","pt":1588428318709,"mc":[{"id":"1.170370557","rc":[{"atb":[[1.6,103.62],[1.37,0]],"id":9624350},{"atl":[[1.72,0]],"id":9624350}],"con":true,"img":false}]}
{"op":"mcm","clk":"1362113809","pt":1588428319216,"mc":[{"id":"1.170370557","rc":[{"atl":[[1.67,104.6]],"id":9624350}],"con":true,"img":false}]}
{"op":"mcm","clk":"1362113812","pt":1588428319418,"mc":[{"id":"1.170370557","rc":[{"atb":[[1.54,0]],"id":9624350}],"con":true,"img":false}]}
{"op":"mcm","clk":"1362113815","pt":1588428319520,"mc":[{"id":"1.170370557","rc":[{"atb":[[1.57,112]],"id":9624350}],"con":true,"img":false}]}
{"op":"mcm","clk":"1362113821","pt":1588428319827,"mc":[{"id":"1.170370557","rc":[{"atb":[[1.54,112]],"id":9624350}],"con":true,"img":false}]}
{"op":"mcm","clk":"1362113827","pt":1588428320044,"mc":[{"id":"1.170370557","rc":[{"atb":[[1.51,112]],"id":9624350}],"con":true,"img":false}]}
{"op":"mcm","clk":"1362113867","pt":1588428321937,"mc":[{"id":"1.170370557","rc":[{"atl":[[1.68,0.45]],"id":9624350}],"con":true,"img":false}]}
{"op":"mcm","clk":"1362113878","pt":1588428322521,"mc":[{"id":"1.170370557","rc":[{"atb":[[1.57,466.6]],"id":9624350}],"con":true,"img":false}]}
{"op":"mcm","clk":"1362113881","pt":1588428322622,"mc":[{"id":"1.170370557","rc":[{"atb":[[1.38,236.58]],"id":9624350},{"atl":[[2.04,202.06]],"id":9624350}],"con":true,"img":false}]}
{"op":"mcm","clk":"1362113885","pt":1588428322827,"mc":[{"id":"1.170370557","rc":[{"trd":[[1.64,1190.55]],"ltp":1.64,"tv":1190.55,"id":9624350},{"atb":[[1.64,23.47]],"id":9624350},{"atl":[[1.64,0]],"id":9624350}],"con":true,"img":false}]}
{"op":"mcm","clk":"1362113890","pt":1588428323133,"mc":[{"id":"1.170370557","rc":[{"atb":[[1.58,354.6]],"id":9624350}],"con":true,"img":false}]}
{"op":"mcm","clk":"1362113894","pt":1588428323235,"mc":[{"id":"1.170370557","rc":[{"atb":[[1.62,112],[1.34,0],[1.57,112]],"id":9624350}],"con":true,"img":false}]}
{"op":"mcm","clk":"1362113897","pt":1588428323439,"mc":[{"id":"1.170370557","rc":[{"trd":[[1.64,1237.51]],"ltp":1.64,"tv":1237.51,"id":9624350},{"atb":[[1.64,0]],"id":9624350},{"atl":[[1.63,117.3],[1.67,0]],"id":9624350}],"con":true,"img":false}]}
{"op":"mcm","clk":"1362113905","pt":1588428323949,"mc":[{"id":"1.170370557","rc":[{"atb":[[1.61,88.65]],"id":9624350}],"con":true,"img":false}]}
{"op":"mcm","clk":"1362113909","pt":1588428324153,"mc":[{"id":"1.170370557","rc":[{"atb":[[1.61,177.3]],"id":9624350}],"con":true,"img":false}]}
{"op":"mcm","clk":"1362113915","pt":1588428324310,"mc":[{"id":"1.170370557","rc":[{"atb":[[1.61,620.56]],"id":9624350}],"con":true,"img":false}]}
{"op":"mcm","clk":"1362113919","pt":1588428324513,"mc":[{"id":"1.170370557","rc":[{"atb":[[1.61,709.21]],"id":9624350}],"con":true,"img":false}]}
{"op":"mcm","clk":"1362113925","pt":1588428324920,"mc":[{"id":"1.170370557","rc":[{"atl":[[1.68,0]],"id":9624350}],"con":true,"img":false}]}
{"op":"mcm","clk":"1362113935","pt":1588428325329,"mc":[{"id":"1.170370557","rc":[{"trd":[[1.63,352.95]],"ltp":1.63,"tv":352.95,"id":9624350},{"atl":[[1.63,115.05]],"id":9624350}],"con":true,"img":false}]}
{"op":"mcm","clk":"1362113948","pt":1588428325945,"mc":[{"id":"1.170370557","rc":[{"atb":[[1.58,0],[1.51,133.45]],"id":9624350}],"con":true,"img":false}]}
{"op":"mcm","clk":"1362113950","pt":1588428326046,"mc":[{"id":"1.170370557","rc":[{"atb":[[1.6,0]],"id":9624350}],"con":true,"img":false}]}
{"op":"mcm","clk":"1362113968","pt":1588428326612,"mc":[{"id":"1.170370557","rc":[{"atb":[[1.61,354.6]],"id":9624350},{"atl":[[1.64,88.65]],"id":9624350}],"con":true,"img":false}]}
{"op":"mcm","clk":"1362113970","pt":1588428326714,"mc":[{"id":"1.170370557","rc":[{"atl":[[1.63,0]],"id":9624350}],"con":true,"img":false}]}
{"op":"mcm","clk":"1362113973","pt":1588428326829,"mc":[{"id":"1.170370557","rc":[{"atl":[[1.64,177.3]],"id":9624350}],"con":true,"img":false}]}
{"op":"mcm","clk":"1362113978","pt":1588428327020,"mc":[{"id":"1.170370557","rc":[{"atl":[[1.64,265.95]],"id":9624350}],"con":true,"img":false}]}
{"op":"mcm","clk":"1362113982","pt":1588428327124,"mc":[{"id":"1.170370557","rc":[{"atb":[[1.62,0]],"id":9624350}],"con":true,"img":false}]}
{"op":"mcm","clk":"1362113986","pt":1588428327223,"mc":[{"id":"1.170370557","rc":[{"atl":[[1.64,354.6]],"id":9624350}],"con":true,"img":false}]}
{"op":"mcm","clk":"1362113987","pt":1588428327336,"mc":[{"id":"1.170370557","rc":[{"atb":[[1.61,0]],"id":9624350}],"con":true,"img":false}]}
{"op":"mcm","clk":"1362114007","pt":1588428328551,"mc":[{"id":"1.170370557","rc":[{"atb":[[1.38,679.84]],"id":9624350}],"con":true,"img":false}]}
{"op":"mcm","clk":"1362114012","pt":1588428328817,"mc":[{"id":"1.170370557","rc":[{"atl":[[1.6,3.28]],"id":9624350}],"con":true,"img":false}]}
{"op":"mcm","clk":"1362114017","pt":1588428329016,"mc":[{"id":"1.170370557","rc":[{"atb":[[1.57,0]],"id":9624350}],"con":true,"img":false}]}
{"op":"mcm","clk":"1362114031","pt":1588428329730,"mc":[{"id":"1.170370557","rc":[{"atb":[[1.38,443.26]],"id":9624350},{"atl":[[2.04,0]],"id":9624350}],"con":true,"img":false}]}
{"op":"mcm","clk":"1362114035","pt":1588428329832,"mc":[{"id":"1.170370557","rc":[{"atb":[[1.51,112]],"id":9624350}],"con":true,"img":false}]}
{"op":"mcm","clk":"1362114042","pt":1588428330241,"mc":[{"id":"1.170370557","rc":[{"atb":[[1.51,0],[1.54,0]],"id":9624350}],"con":true,"img":false}]}
{"op":"mcm","clk":"1362114048","pt":1588428330750,"mc":[{"id":"1.170370557","rc":[{"atl":[[1.94,443.26]],"id":9624350}],"con":true,"img":false}]}
{"op":"mcm","clk":"1362114054","pt":1588428331260,"mc":[{"id":"1.170370557","rc":[{"atb":[[1.54,107.66]],"id":9624350}],"con":true,"img":false}]}
{"op":"mcm","clk":"1362114056","pt":1588428331363,"mc":[{"id":"1.170370557","rc":[{"trd":[[1.54,4765.47]],"ltp":1.54,"tv":4765.47,"id":9624350},{"atb":[[1.54,0]],"id":9624350},{"atl":[[1.52,642.33]],"id":9624350}],"con":true,"img":false}]}
{"op":"mcm","clk":"1362114068","pt":1588428332334,"mc":[{"id":"1.170370557","rc":[{"trd":[[1.52,1897.89]],"ltp":1.52,"tv":1897.89,"id":9624350},{"atl":[[1.56,150],[1.52,287.72]],"id":9624350}],"con":true,"img":false}]}
{"op":"mcm","clk":"1362114072","pt":1588428332534,"mc":[{"id":"1.170370557","rc":[{"atl":[[1.56,238.65]],"id":9624350}],"con":true,"img":false}]}
{"op":"mcm","clk":"1362114076","pt":1588428332739,"mc":[{"id":"1.170370557","rc":[{"atl":[[1.54,88.65]],"id":9624350}],"con":true,"img":false}]}
{"op":"mcm","clk":"1362114079","pt":1588428332842,"mc":[{"id":"1.170370557","rc":[{"trd":[[2.92,79.97]],"ltp":2.92,"tv":79.97,"id":9622734},{"trd":[[1.52,1897.97]],"ltp":1.52,"tv":1897.97,"id":9624350},{"atl":[[1.53,443.26],[1.52,376.29]],"id":9624350}],"con":true,"img":false}]}
{"op":"mcm","clk":"1362114083","pt":1588428333046,"mc":[{"id":"1.170370557","rc":[{"atl":[[1.52,464.94]],"id":9624350}],"con":true,"img":false}]}
{"op":"mcm","clk":"1362114087","pt":1588428333250,"mc":[{"id":"1.170370557","rc":[{"atl":[[1.54,238.65]],"id":9624350}],"con":true,"img":false}]}
{"op":"mcm","clk":"1362114093","pt":1588428333557,"mc":[{"id":"1.170370557","rc":[{"atl":[[1.54,388.65]],"id":9624350}],"con":true,"img":false}]}
{"op":"mcm","clk":"1362114100","pt":1588428334067,"mc":[{"id":"1.170370557","rc":[{"atb":[[1.39,500]],"id":9624350},{"atl":[[1.64,0],[1.62,8.75]],"id":9624350}],"con":true,"img":false}]}
{"op":"mcm","clk":"1362114112","pt":1588428334942,"mc":[{"id":"1.170370557","rc":[{"atb":[[2.86,50.87]],"id":9622734}],"con":true,"img":false}]}
{"op":"mcm","clk":"1362114117","pt":1588428335344,"mc":[{"id":"1.170370557","rc":[{"atl":[[1.52,177.3]],"id":9624350}],"con":true,"img":false}]}
{"op":"mcm","clk":"1362114120","pt":1588428335548,"mc":[{"id":"1.170370557","rc":[{"atl":[[1.7,0]],"id":9624350}],"con":true,"img":false}]}
{"op":"mcm","clk":"1362114122","pt":1588428335649,"mc":[{"id":"1.170370557","rc":[{"atb":[[1.25,266.47]],"id":9624350},{"atl":[[1.77,264.1]],"id":9624350}],"con":true,"img":false}]}
{"op":"mcm","clk":"1362114127","pt":1588428336057,"mc":[{"id":"1.170370557","rc":[{"atl":[[1.56,150]],"id":9624350}],"con":true,"img":false}]}
{"op":"mcm","clk":"1362114132","pt":1588428336465,"mc":[{"id":"1.170370557","rc":[{"atl":[[1.54,300]],"id":9624350}],"con":true,"img":false}]}
{"op":"mcm","clk":"1362114142","pt":1588428337034,"mc":[{"id":"1.170370557","rc":[{"atl":[[1.62,9.91]],"id":9624350}],"con":true,"img":false}]}
{"op":"mcm","clk":"1362114145","pt":1588428337131,"mc":[{"id":"1.170370557","rc":[{"atb":[[2.76,4.06]],"id":9622734}],"con":true,"img":false}]}
{"op":"mcm","clk":"1362114159","pt":1588428337640,"mc":[{"id":"1.170370557","rc":[{"atl":[[1.51,150]],"id":9624350}],"con":true,"img":false}]}
{"op":"mcm","clk":"1362114168","pt":1588428338049,"mc":[{"id":"1.170370557","rc":[{"atl":[[1.49,443.26]],"id":9624350}],"con":true,"img":false}]}
{"op":"mcm","clk":"1362114173","pt":1588428338253,"mc":[{"id":"1.170370557","rc":[{"atl":[[1.56,0]],"id":9624350}],"con":true,"img":false}]}
{"op":"mcm","clk":"1362114182","pt":1588428338864,"mc":[{"id":"1.170370557","rc":[{"atb":[[1.39,523.3]],"id":9624350}],"con":true,"img":false}]}
{"op":"mcm","clk":"1362114185","pt":1588428338966,"mc":[{"id":"1.170370557","rc":[{"atl":[[1.51,504.6]],"id":9624350}],"con":true,"img":false}]}
{"op":"mcm","clk":"1362114186","pt":1588428339068,"mc":[{"id":"1.170370557","rc":[{"atl":[[1.54,0],[1.53,0]],"id":9624350}],"con":true,"img":false}]}
{"op":"mcm","clk":"1362114191","pt":1588428339426,"mc":[{"id":"1.170370557","rc":[{"atl":[[1.51,593.26]],"id":9624350}],"con":true,"img":false}]}
{"op":"mcm","clk":"1362114194","pt":1588428339529,"mc":[{"id":"1.170370557","rc":[{"atl":[[1.51,681.91]],"id":9624350}],"con":true,"img":false}]}
{"op":"mcm","clk":"1362114196","pt":1588428339630,"mc":[{"id":"1.170370557","rc":[{"atl":[[1.5,5.69]],"id":9624350}],"con":true,"img":false}]}
{"op":"mcm","clk":"1362114198","pt":1588428339732,"mc":[{"id":"1.170370557","rc":[{"atl":[[1.51,770.56]],"id":9624350}],"con":true,"img":false}]}
{"op":"mcm","clk":"1362114202","pt":1588428339938,"mc":[{"id":"1.170370557","rc":[{"atb":[[1.41,443.26]],"id":9624350},{"atl":[[1.51,859.21]],"id":9624350}],"con":true,"img":false}]}
{"op":"mcm","clk":"1362114206","pt":1588428340144,"mc":[{"id":"1.170370557","rc":[{"atl":[[1.49,533.72]],"id":9624350}],"con":true,"img":false}]}
{"op":"mcm","clk":"1362114209","pt":1588428340341,"mc":[{"id":"1.170370557","rc":[{"atl":[[1.62,20.55]],"id":9624350}],"con":true,"img":false}]}
{"op":"mcm","clk":"1362114212","pt":1588428340447,"mc":[{"id":"1.170370557","rc":[{"trd":[[1.49,2170.9]],"ltp":1.49,"tv":2170.9,"id":9624350},{"atl":[[1.49,66.75]],"id":9624350}],"con":true,"img":false}]}
{"op":"mcm","clk":"1362114217","pt":1588428340647,"mc":[{"id":"1.170370557","rc":[{"atl":[[1.6,5.28]],"id":9624350}],"con":true,"img":false}]}
{"op":"mcm","clk":"1362114225","pt":1588428340953,"mc":[{"id":"1.170370557","rc":[{"atl":[[1.62,19.39],[1.51,971.21]],"id":9624350}],"con":true,"img":false}]}
{"op":"mcm","clk":"1362114230","pt":1588428341324,"mc":[{"id":"1.170370557","rc":[{"trd":[[1.41,2766.46],[1.44,8609.71]],"ltp":1.41,"tv":11376.16,"id":9624350},{"atb":[[1.44,0],[1.41,399.6]],"id":9624350}],"con":true,"img":false}]}
{"op":"mcm","clk":"1362114233","pt":1588428341426,"mc":[{"id":"1.170370557","rc":[{"atb":[[1.41,549.6]],"id":9624350}],"con":true,"img":false}]}
{"op":"mcm","clk":"1362114237","pt":1588428341733,"mc":[{"id":"1.170370557","rc":[{"atb":[[1.41,699.6]],"id":9624350}],"con":true,"img":false}]}
{"op":"mcm","clk":"1362114239","pt":1588428341836,"mc":[{"id":"1.170370557","rc":[{"atl":[[1.51,859.21]],"id":9624350}],"con":true,"img":false}]}
{"op":"mcm","clk":"1362114241","pt":1588428341934,"mc":[{"id":"1.170370557","rc":[{"trd":[[1.49,2171.13]],"ltp":1.49,"tv":2171.13,"id":9624350},{"atb":[[1.43,88.65]],"id":9624350},{"atl":[[1.49,66.64]],"id":9624350}],"con":true,"img":false}]}
{"op":"mcm","clk":"1362114246","pt":1588428342140,"mc":[{"id":"1.170370557","rc":[{"atb":[[1.43,177.3]],"id":9624350}],"con":true,"img":false}]}
{"op":"mcm","clk":"1362114249","pt":1588428342241,"mc":[{"id":"1.170370557","rc":[{"atb":[[1.41,1054.21]],"id":9624350}],"con":true,"img":false}]}
{"op":"mcm","clk":"1362114250","pt":1588428342342,"mc":[{"id":"1.170370557","rc":[{"atb":[[1.43,265.95]],"id":9624350}],"con":true,"img":false}]}
{"op":"mcm","clk":"1362114254","pt":1588428342550,"mc":[{"id":"1.170370557","rc":[{"atb":[[1.43,354.6]],"id":9624350}],"con":true,"img":false}]}
{"op":"mcm","clk":"1362114256","pt":1588428342648,"mc":[{"id":"1.170370557","rc":[{"atb":[[1.43,443.26]],"id":9624350}],"con":true,"img":false}]}
