{"op":"mcm","clk":"1349418886","pt":1588396480947,"mc":[{"id":"1.170370562","marketDefinition":{"bspMarket":false,"turnInPlayEnabled":true,"persistenceEnabled":true,"marketBaseRate":5.0,"eventId":"29788105","eventTypeId":"2","numberOfWinners":1,"bettingType":"ODDS","marketType":"MATCH_ODDS","marketTime":"2020-05-02T09:00:00.000Z","suspendTime":"2020-05-02T09:00:00.000Z","bspReconciled":false,"complete":true,"inPlay":false,"crossMatching":false,"runnersVoidable":false,"numberOfActiveRunners":2,"betDelay":0,"status":"OPEN","runners":[{"status":"ACTIVE","sortPriority":1,"id":9631798,"name":"B Hassan"},{"status":"ACTIVE","sortPriority":2,"id":9625043,"name":"J Haerteis"}],"regulators":["MR_INT"],"countryCode":"GB","discountAllowed":false,"timezone":"GMT","openDate":"2020-05-02T09:00:00.000Z","version":3237452726,"name":"Match Odds","eventName":"B Hassan v J Haerteis"},"rc":[],"con":true,"img":false}]}
{"op":"mcm","clk":"1349418967","pt":1588396482946,"mc":[{"id":"1.170370562","marketDefinition":{"bspMarket":false,"turnInPlayEnabled":true,"persistenceEnabled":true,"marketBaseRate":5.0,"eventId":"29788105","eventTypeId":"2","numberOfWinners":1,"bettingType":"ODDS","marketType":"MATCH_ODDS","marketTime":"2020-05-02T09:00:00.000Z","suspendTime":"2020-05-02T09:00:00.000Z","bspReconciled":false,"complete":true,"inPlay":false,"crossMatching":false,"runnersVoidable":false,"numberOfActiveRunners":2,"betDelay":0,"status":"OPEN","runners":[{"status":"ACTIVE","sortPriority":1,"id":9631798,"name":"B Hassan"},{"status":"ACTIVE","sortPriority":2,"id":9625043,"name":"J Haerteis"}],"regulators":["MR_INT"],"countryCode":"GB","discountAllowed":true,"timezone":"GMT","openDate":"2020-05-02T09:00:00.000Z","version":3237452726,"name":"Match Odds","eventName":"B Hassan v J Haerteis"},"rc":[],"con":true,"img":false}]}
{"op":"mcm","clk":"1349423098","pt":1588396573076,"mc":[{"id":"1.170370562","rc":[{"atb":[[1.64,29.59]],"id":9631798}],"con":true,"img":false}]}
{"op":"mcm","clk":"1349423110","pt":1588396573386,"mc":[{"id":"1.170370562","rc":[{"atb":[[1.7,27.99]],"id":9625043}],"con":true,"img":false}]}
{"op":"mcm","clk":"1349423433","pt":1588396580669,"mc":[{"id":"1.170370562","rc":[{"atb":[[1.7,0]],"id":9625043},{"atb":[[1.64,0]],"id":9631798}],"con":true,"img":false}]}
{"op":"mcm","clk":"1349423437","pt":1588396580771,"mc":[{"id":"1.170370562","rc":[{"atb":[[1.78,27.99]],"id":9625043},{"atb":[[1.56,29.59]],"id":9631798}],"con":true,"img":false}]}
{"op":"mcm","clk":"1349423767","pt":1588396588102,"mc":[{"id":"1.170370562","rc":[{"atb":[[1.78,0]],"id":9625043},{"atb":[[1.56,0]],"id":9631798}],"con":true,"img":false}]}
{"op":"mcm","clk":"1349423772","pt":1588396588206,"mc":[{"id":"1.170370562","rc":[{"atb":[[1.7,27.99]],"id":9625043},{"atb":[[1.64,29.59]],"id":9631798}],"con":true,"img":false}]}
{"op":"mcm","clk":"1349424121","pt":1588396595790,"mc":[{"id":"1.170370562","rc":[{"atb":[[1.7,0]],"id":9625043},{"atb":[[1.64,0]],"id":9631798}],"con":true,"img":false}]}
{"op":"mcm","clk":"1349424128","pt":1588396595893,"mc":[{"id":"1.170370562","rc":[{"atb":[[1.78,27.99]],"id":9625043},{"atb":[[1.56,29.59]],"id":9631798}],"con":true,"img":false}]}
{"op":"mcm","clk":"1349424465","pt":1588396603244,"mc":[{"id":"1.170370562","rc":[{"atb":[[1.78,0]],"id":9625043},{"atb":[[1.56,0]],"id":9631798}],"con":true,"img":false}]}
{"op":"mcm","clk":"1349424471","pt":1588396603347,"mc":[{"id":"1.170370562","rc":[{"atb":[[1.7,27.99]],"id":9625043},{"atb":[[1.64,29.59]],"id":9631798}],"con":true,"img":false}]}
{"op":"mcm","clk":"1349424812","pt":1588396610420,"mc":[{"id":"1.170370562","rc":[{"atb":[[1.7,0]],"id":9625043},{"atb":[[1.64,0]],"id":9631798}],"con":true,"img":false}]}
{"op":"mcm","clk":"1349424816","pt":1588396610523,"mc":[{"id":"1.170370562","rc":[{"atb":[[1.78,27.99]],"id":9625043},{"atb":[[1.56,29.59]],"id":9631798}],"con":true,"img":false}]}
{"op":"mcm","clk":"1349425177","pt":1588396618137,"mc":[{"id":"1.170370562","rc":[{"atb":[[1.78,0]],"id":9625043},{"atb":[[1.56,0]],"id":9631798}],"con":true,"img":false}]}
{"op":"mcm","clk":"1349425181","pt":1588396618240,"mc":[{"id":"1.170370562","rc":[{"atb":[[1.7,27.99]],"id":9625043},{"atb":[[1.64,29.59]],"id":9631798}],"con":true,"img":false}]}
{"op":"mcm","clk":"1349425565","pt":1588396625875,"mc":[{"id":"1.170370562","rc":[{"atb":[[1.7,0]],"id":9625043},{"atb":[[1.64,0]],"id":9631798}],"con":true,"img":false}]}
{"op":"mcm","clk":"1349425569","pt":1588396625978,"mc":[{"id":"1.170370562","rc":[{"atb":[[1.78,27.99]],"id":9625043},{"atb":[[1.56,29.59]],"id":9631798}],"con":true,"img":false}]}
{"op":"mcm","clk":"1349425923","pt":1588396633791,"mc":[{"id":"1.170370562","rc":[{"atb":[[1.78,0]],"id":9625043},{"atb":[[1.56,0]],"id":9631798}],"con":true,"img":false}]}
{"op":"mcm","clk":"1349425930","pt":1588396633895,"mc":[{"id":"1.170370562","rc":[{"atb":[[1.7,27.99]],"id":9625043},{"atb":[[1.64,29.59]],"id":9631798}],"con":true,"img":false}]}
{"op":"mcm","clk":"1349426268","pt":1588396640968,"mc":[{"id":"1.170370562","rc":[{"atb":[[1.7,0]],"id":9625043},{"atb":[[1.64,0]],"id":9631798}],"con":true,"img":false}]}
{"op":"mcm","clk":"1349426275","pt":1588396641071,"mc":[{"id":"1.170370562","rc":[{"atb":[[1.78,27.99]],"id":9625043},{"atb":[[1.56,29.59]],"id":9631798}],"con":true,"img":false}]}
{"op":"mcm","clk":"1349426458","pt":1588396644698,"mc":[{"id":"1.170370562","rc":[{"atb":[[1.88,87.96]],"id":9625043},{"atb":[[1.61,119.86]],"id":9631798}],"con":true,"img":false}]}
{"op":"mcm","clk":"1349426651","pt":1588396648718,"mc":[{"id":"1.170370562","rc":[{"atb":[[1.78,0]],"id":9625043},{"atb":[[1.56,0]],"id":9631798}],"con":true,"img":false}]}
{"op":"mcm","clk":"1349426659","pt":1588396648821,"mc":[{"id":"1.170370562","rc":[{"atb":[[1.7,27.99]],"id":9625043},{"atb":[[1.64,29.59]],"id":9631798}],"con":true,"img":false}]}
{"op":"mcm","clk":"1349426673","pt":1588396649084,"mc":[{"id":"1.170370562","rc":[{"atb":[[1.61,0]],"id":9631798}],"con":true,"img":false}]}
{"op":"mcm","clk":"1349426681","pt":1588396649190,"mc":[{"id":"1.170370562","rc":[{"atb":[[1.65,116.93]],"id":9631798}],"con":true,"img":false}]}
{"op":"mcm","clk":"1349426987","pt":1588396655928,"mc":[{"id":"1.170370562","rc":[{"atb":[[1.7,0]],"id":9625043},{"atb":[[1.64,0]],"id":9631798}],"con":true,"img":false}]}
{"op":"mcm","clk":"1349426993","pt":1588396656036,"mc":[{"id":"1.170370562","rc":[{"atb":[[1.78,27.99]],"id":9625043},{"atb":[[1.56,29.59]],"id":9631798}],"con":true,"img":false}]}
{"op":"mcm","clk":"1349427338","pt":1588396663428,"mc":[{"id":"1.170370562","rc":[{"atb":[[1.78,0]],"id":9625043},{"atb":[[1.56,0]],"id":9631798}],"con":true,"img":false}]}
{"op":"mcm","clk":"1349427344","pt":1588396663534,"mc":[{"id":"1.170370562","rc":[{"atb":[[1.7,27.99]],"id":9625043},{"atb":[[1.64,29.59]],"id":9631798}],"con":true,"img":false}]}
{"op":"mcm","clk":"1349427680","pt":1588396670624,"mc":[{"id":"1.170370562","rc":[{"atb":[[1.7,0]],"id":9625043},{"atb":[[1.64,0]],"id":9631798}],"con":true,"img":false}]}
{"op":"mcm","clk":"1349427684","pt":1588396670782,"mc":[{"id":"1.170370562","rc":[{"atb":[[1.78,27.99]],"id":9625043},{"atb":[[1.56,29.59]],"id":9631798}],"con":true,"img":false}]}
{"op":"mcm","clk":"1349428026","pt":1588396678160,"mc":[{"id":"1.170370562","rc":[{"atb":[[1.78,0]],"id":9625043},{"atb":[[1.56,0]],"id":9631798}],"con":true,"img":false}]}
{"op":"mcm","clk":"1349428035","pt":1588396678273,"mc":[{"id":"1.170370562","rc":[{"atb":[[1.7,27.99]],"id":9625043},{"atb":[[1.64,29.59]],"id":9631798}],"con":true,"img":false}]}
{"op":"mcm","clk":"1349428410","pt":1588396686069,"mc":[{"id":"1.170370562","rc":[{"atb":[[1.7,0]],"id":9625043},{"atb":[[1.64,0]],"id":9631798}],"con":true,"img":false}]}
{"op":"mcm","clk":"1349428418","pt":1588396686181,"mc":[{"id":"1.170370562","rc":[{"atb":[[1.78,27.99]],"id":9625043},{"atb":[[1.56,29.59]],"id":9631798}],"con":true,"img":false}]}
{"op":"mcm","clk":"1349428754","pt":1588396693805,"mc":[{"id":"1.170370562","rc":[{"atb":[[1.78,0]],"id":9625043},{"atb":[[1.56,0]],"id":9631798}],"con":true,"img":false}]}
{"op":"mcm","clk":"1349428758","pt":1588396693908,"mc":[{"id":"1.170370562","rc":[{"atb":[[1.7,27.99]],"id":9625043},{"atb":[[1.64,29.59]],"id":9631798}],"con":true,"img":false}]}
{"op":"mcm","clk":"1349429141","pt":1588396702235,"mc":[{"id":"1.170370562","rc":[{"atb":[[1.7,0]],"id":9625043},{"atb":[[1.64,0]],"id":9631798}],"con":true,"img":false}]}
{"op":"mcm","clk":"1349429148","pt":1588396702338,"mc":[{"id":"1.170370562","rc":[{"atb":[[1.78,27.99]],"id":9625043},{"atb":[[1.56,29.59]],"id":9631798}],"con":true,"img":false}]}
{"op":"mcm","clk":"1349429515","pt":1588396709756,"mc":[{"id":"1.170370562","rc":[{"atb":[[1.78,0]],"id":9625043},{"atb":[[1.56,0]],"id":9631798}],"con":true,"img":false}]}
{"op":"mcm","clk":"1349429519","pt":1588396709858,"mc":[{"id":"1.170370562","rc":[{"atb":[[1.7,27.99]],"id":9625043},{"atb":[[1.64,29.59]],"id":9631798}],"con":true,"img":false}]}
{"op":"mcm","clk":"1349429910","pt":1588396718341,"mc":[{"id":"1.170370562","rc":[{"atb":[[1.7,0]],"id":9625043},{"atb":[[1.64,0]],"id":9631798}],"con":true,"img":false}]}
{"op":"mcm","clk":"1349429914","pt":1588396718443,"mc":[{"id":"1.170370562","rc":[{"atb":[[1.78,27.99]],"id":9625043},{"atb":[[1.56,29.59]],"id":9631798}],"con":true,"img":false}]}
{"op":"mcm","clk":"1349430217","pt":1588396725440,"mc":[{"id":"1.170370562","rc":[{"atb":[[1.78,0]],"id":9625043},{"atb":[[1.56,0]],"id":9631798}],"con":true,"img":false}]}
{"op":"mcm","clk":"1349430226","pt":1588396725543,"mc":[{"id":"1.170370562","rc":[{"atb":[[1.7,27.99]],"id":9625043},{"atb":[[1.64,29.59]],"id":9631798}],"con":true,"img":false}]}
{"op":"mcm","clk":"1349430575","pt":1588396732874,"mc":[{"id":"1.170370562","rc":[{"atb":[[1.7,0]],"id":9625043},{"atb":[[1.64,0]],"id":9631798}],"con":true,"img":false}]}
{"op":"mcm","clk":"1349430581","pt":1588396732982,"mc":[{"id":"1.170370562","rc":[{"atb":[[1.78,27.99]],"id":9625043},{"atb":[[1.56,29.59]],"id":9631798}],"con":true,"img":false}]}
{"op":"mcm","clk":"1349430916","pt":1588396740412,"mc":[{"id":"1.170370562","rc":[{"atb":[[1.78,0]],"id":9625043},{"atb":[[1.56,0]],"id":9631798}],"con":true,"img":false}]}
{"op":"mcm","clk":"1349430924","pt":1588396740472,"mc":[{"id":"1.170370562","rc":[{"atb":[[1.7,27.99]],"id":9625043},{"atb":[[1.64,29.59]],"id":9631798}],"con":true,"img":false}]}
{"op":"mcm","clk":"1349431257","pt":1588396747806,"mc":[{"id":"1.170370562","rc":[{"atb":[[1.7,0]],"id":9625043},{"atb":[[1.64,0]],"id":9631798}],"con":true,"img":false}]}
{"op":"mcm","clk":"1349431266","pt":1588396747916,"mc":[{"id":"1.170370562","rc":[{"atb":[[1.78,27.99]],"id":9625043},{"atb":[[1.56,29.59]],"id":9631798}],"con":true,"img":false}]}
{"op":"mcm","clk":"1349431604","pt":1588396755293,"mc":[{"id":"1.170370562","rc":[{"atb":[[1.78,0]],"id":9625043},{"atb":[[1.56,0]],"id":9631798}],"con":true,"img":false}]}
{"op":"mcm","clk":"1349431607","pt":1588396755394,"mc":[{"id":"1.170370562","rc":[{"atb":[[1.7,27.99]],"id":9625043},{"atb":[[1.64,29.59]],"id":9631798}],"con":true,"img":false}]}
{"op":"mcm","clk":"1349431897","pt":1588396762511,"mc":[{"id":"1.170370562","rc":[{"atb":[[1.7,0]],"id":9625043},{"atb":[[1.64,0]],"id":9631798}],"con":true,"img":false}]}
{"op":"mcm","clk":"1349431903","pt":1588396762618,"mc":[{"id":"1.170370562","rc":[{"atb":[[1.78,27.99]],"id":9625043},{"atb":[[1.56,29.59]],"id":9631798}],"con":true,"img":false}]}
{"op":"mcm","clk":"1349432187","pt":1588396769723,"mc":[{"id":"1.170370562","rc":[{"atb":[[1.78,0]],"id":9625043},{"atb":[[1.56,0]],"id":9631798}],"con":true,"img":false}]}
{"op":"mcm","clk":"1349432191","pt":1588396769827,"mc":[{"id":"1.170370562","rc":[{"atb":[[1.7,27.99]],"id":9625043},{"atb":[[1.64,29.59]],"id":9631798}],"con":true,"img":false}]}
{"op":"mcm","clk":"1349432550","pt":1588396778464,"mc":[{"id":"1.170370562","rc":[{"atb":[[1.7,0]],"id":9625043},{"atb":[[1.64,0]],"id":9631798}],"con":true,"img":false}]}
{"op":"mcm","clk":"1349432555","pt":1588396778569,"mc":[{"id":"1.170370562","rc":[{"atb":[[1.78,27.99]],"id":9625043},{"atb":[[1.56,29.59]],"id":9631798}],"con":true,"img":false}]}
{"op":"mcm","clk":"1349432823","pt":1588396785468,"mc":[{"id":"1.170370562","rc":[{"atb":[[1.8,84.21]],"id":9631798}],"con":true,"img":false}]}
{"op":"mcm","clk":"1349432833","pt":1588396785776,"mc":[{"id":"1.170370562","rc":[{"atb":[[1.65,0]],"id":9631798}],"con":true,"img":false}]}
{"op":"mcm","clk":"1349432884","pt":1588396787073,"mc":[{"id":"1.170370562","rc":[{"atb":[[1.78,0]],"id":9625043},{"atb":[[1.56,0]],"id":9631798}],"con":true,"img":false}]}
{"op":"mcm","clk":"1349432891","pt":1588396787174,"mc":[{"id":"1.170370562","rc":[{"atb":[[1.7,27.99]],"id":9625043},{"atb":[[1.64,29.59]],"id":9631798}],"con":true,"img":false}]}
{"op":"mcm","clk":"1349433245","pt":1588396794601,"mc":[{"id":"1.170370562","rc":[{"atb":[[1.7,0]],"id":9625043},{"atb":[[1.64,0]],"id":9631798}],"con":true,"img":false}]}
{"op":"mcm","clk":"1349433252","pt":1588396794662,"mc":[{"id":"1.170370562","rc":[{"atb":[[1.78,27.99]],"id":9625043},{"atb":[[1.56,29.59]],"id":9631798}],"con":true,"img":false}]}
{"op":"mcm","clk":"1349433596","pt":1588396801876,"mc":[{"id":"1.170370562","rc":[{"atb":[[1.78,0]],"id":9625043},{"atb":[[1.56,0]],"id":9631798}],"con":true,"img":false}]}
{"op":"mcm","clk":"1349433602","pt":1588396801982,"mc":[{"id":"1.170370562","rc":[{"atb":[[1.7,27.99]],"id":9625043},{"atb":[[1.64,29.59]],"id":9631798}],"con":true,"img":false}]}
{"op":"mcm","clk":"1349433977","pt":1588396808985,"mc":[{"id":"1.170370562","rc":[{"atb":[[1.7,0]],"id":9625043},{"atb":[[1.64,0]],"id":9631798}],"con":true,"img":false}]}
{"op":"mcm","clk":"1349433983","pt":1588396809089,"mc":[{"id":"1.170370562","rc":[{"atb":[[1.78,27.99]],"id":9625043},{"atb":[[1.56,29.59]],"id":9631798}],"con":true,"img":false}]}
{"op":"mcm","clk":"1349434364","pt":1588396816718,"mc":[{"id":"1.170370562","rc":[{"atb":[[1.78,0]],"id":9625043},{"atb":[[1.56,0]],"id":9631798}],"con":true,"img":false}]}
{"op":"mcm","clk":"1349434369","pt":1588396816819,"mc":[{"id":"1.170370562","rc":[{"atb":[[1.7,27.99]],"id":9625043},{"atb":[[1.64,29.59]],"id":9631798}],"con":true,"img":false}]}
{"op":"mcm","clk":"1349434778","pt":1588396824019,"mc":[{"id":"1.170370562","rc":[{"atb":[[1.7,0]],"id":9625043},{"atb":[[1.64,0]],"id":9631798}],"con":true,"img":false}]}
{"op":"mcm","clk":"1349434783","pt":1588396824122,"mc":[{"id":"1.170370562","rc":[{"atb":[[1.78,27.99]],"id":9625043},{"atb":[[1.56,29.59]],"id":9631798}],"con":true,"img":false}]}
{"op":"mcm","clk":"1349435114","pt":1588396831336,"mc":[{"id":"1.170370562","rc":[{"atb":[[1.78,0]],"id":9625043},{"atb":[[1.56,0]],"id":9631798}],"con":true,"img":false}]}
{"op":"mcm","clk":"1349435120","pt":1588396831387,"mc":[{"id":"1.170370562","rc":[{"atb":[[1.7,27.99]],"id":9625043},{"atb":[[1.64,29.59]],"id":9631798}],"con":true,"img":false}]}
{"op":"mcm","clk":"1349435411","pt":1588396838629,"mc":[{"id":"1.170370562","rc":[{"atb":[[1.7,0]],"id":9625043},{"atb":[[1.64,0]],"id":9631798}],"con":true,"img":false}]}
{"op":"mcm","clk":"1349435414","pt":1588396838733,"mc":[{"id":"1.170370562","rc":[{"atb":[[1.78,27.99]],"id":9625043},{"atb":[[1.56,29.59]],"id":9631798}],"con":true,"img":false}]}
{"op":"mcm","clk":"1349435760","pt":1588396846043,"mc":[{"id":"1.170370562","rc":[{"atb":[[1.78,0]],"id":9625043},{"atb":[[1.56,0]],"id":9631798}],"con":true,"img":false}]}
{"op":"mcm","clk":"1349435768","pt":1588396846146,"mc":[{"id":"1.170370562","rc":[{"atb":[[1.7,27.99]],"id":9625043},{"atb":[[1.64,29.59]],"id":9631798}],"con":true,"img":false}]}
{"op":"mcm","clk":"1349436143","pt":1588396853239,"mc":[{"id":"1.170370562","rc":[{"atb":[[1.7,0]],"id":9625043},{"atb":[[1.64,0]],"id":9631798}],"con":true,"img":false}]}
{"op":"mcm","clk":"1349436149","pt":1588396853345,"mc":[{"id":"1.170370562","rc":[{"atb":[[1.78,27.99]],"id":9625043},{"atb":[[1.56,29.59]],"id":9631798}],"con":true,"img":false}]}
{"op":"mcm","clk":"1349436579","pt":1588396862282,"mc":[{"id":"1.170370562","rc":[{"atb":[[1.78,0]],"id":9625043},{"atb":[[1.56,0]],"id":9631798}],"con":true,"img":false}]}
{"op":"mcm","clk":"1349436587","pt":1588396862387,"mc":[{"id":"1.170370562","rc":[{"atb":[[1.7,27.99]],"id":9625043},{"atb":[[1.64,29.59]],"id":9631798}],"con":true,"img":false}]}
{"op":"mcm","clk":"1349437006","pt":1588396870289,"mc":[{"id":"1.170370562","rc":[{"atb":[[1.7,0]],"id":9625043},{"atb":[[1.64,0]],"id":9631798}],"con":true,"img":false}]}
{"op":"mcm","clk":"1349437010","pt":1588396870389,"mc":[{"id":"1.170370562","rc":[{"atb":[[1.78,27.99]],"id":9625043},{"atb":[[1.56,29.59]],"id":9631798}],"con":true,"img":false}]}
{"op":"mcm","clk":"1349437343","pt":1588396877789,"mc":[{"id":"1.170370562","rc":[{"atb":[[1.78,0]],"id":9625043},{"atb":[[1.56,0]],"id":9631798}],"con":true,"img":false}]}
{"op":"mcm","clk":"1349437349","pt":1588396877892,"mc":[{"id":"1.170370562","rc":[{"atb":[[1.7,27.99]],"id":9625043},{"atb":[[1.64,29.59]],"id":9631798}],"con":true,"img":false}]}
{"op":"mcm","clk":"1349437520","pt":1588396881809,"mc":[{"id":"1.170370562","rc":[{"atl":[[990,1.59]],"id":9625043},{"atl":[[990,1.59]],"id":9631798}],"con":true,"img":false}]}
{"op":"mcm","clk":"1349437670","pt":1588396885105,"mc":[{"id":"1.170370562","rc":[{"atb":[[1.7,0]],"id":9625043},{"atb":[[1.64,0]],"id":9631798}],"con":true,"img":false}]}
{"op":"mcm","clk":"1349437675","pt":1588396885213,"mc":[{"id":"1.170370562","rc":[{"atb":[[1.78,27.99]],"id":9625043},{"atb":[[1.56,29.59]],"id":9631798}],"con":true,"img":false}]}
{"op":"mcm","clk":"1349437982","pt":1588396892629,"mc":[{"id":"1.170370562","rc":[{"atb":[[1.78,0]],"id":9625043},{"atb":[[1.56,0]],"id":9631798}],"con":true,"img":false}]}
{"op":"mcm","clk":"1349437988","pt":1588396892730,"mc":[{"id":"1.170370562","rc":[{"atb":[[1.7,27.99]],"id":9625043},{"atb":[[1.64,29.59]],"id":9631798}],"con":true,"img":false}]}
{"op":"mcm","clk":"1349438266","pt":1588396898469,"mc":[{"id":"1.170370562","marketDefinition":{"bspMarket":false,"turnInPlayEnabled":true,"persistenceEnabled":true,"marketBaseRate":5.0,"eventId":"29788105","eventTypeId":"2","numberOfWinners":1,"bettingType":"ODDS","marketType":"MATCH_ODDS","marketTime":"2020-05-02T09:00:00.000Z","suspendTime":"2020-05-02T09:00:00.000Z","bspReconciled":false,"complete":true,"inPlay":false,"crossMatching":true,"runnersVoidable":false,"numberOfActiveRunners":2,"betDelay":0,"status":"OPEN","runners":[{"status":"ACTIVE","sortPriority":1,"id":9631798,"name":"B Hassan"},{"status":"ACTIVE","sortPriority":2,"id":9625043,"name":"J Haerteis"}],"regulators":["MR_INT"],"countryCode":"GB","discountAllowed":true,"timezone":"GMT","openDate":"2020-05-02T09:00:00.000Z","version":3237452726,"name":"Match Odds","eventName":"B Hassan v J Haerteis"},"rc":[],"con":true,"img":false}]}
{"op":"mcm","clk":"1349438341","pt":1588396899797,"mc":[{"id":"1.170370562","rc":[{"atb":[[1.7,0]],"id":9625043},{"atb":[[1.64,0]],"id":9631798}],"con":true,"img":false}]}
{"op":"mcm","clk":"1349438346","pt":1588396899900,"mc":[{"id":"1.170370562","rc":[{"atb":[[1.78,27.99]],"id":9625043},{"atb":[[1.56,29.59]],"id":9631798}],"con":true,"img":false}]}
{"op":"mcm","clk":"1349438705","pt":1588396907219,"mc":[{"id":"1.170370562","rc":[{"atb":[[1.78,0]],"id":9625043},{"atb":[[1.56,0]],"id":9631798}],"con":true,"img":false}]}
{"op":"mcm","clk":"1349438710","pt":1588396907315,"mc":[{"id":"1.170370562","rc":[{"atb":[[1.7,27.99]],"id":9625043},{"atb":[[1.64,29.59]],"id":9631798}],"con":true,"img":false}]}
{"op":"mcm","clk":"1349439085","pt":1588396914539,"mc":[{"id":"1.170370562","rc":[{"atb":[[1.7,0]],"id":9625043},{"atb":[[1.64,0]],"id":9631798}],"con":true,"img":false}]}
{"op":"mcm","clk":"1349439095","pt":1588396914642,"mc":[{"id":"1.170370562","rc":[{"atb":[[1.78,27.99]],"id":9625043},{"atb":[[1.56,29.59]],"id":9631798}],"con":true,"img":false}]}
{"op":"mcm","clk":"1349439497","pt":1588396922245,"mc":[{"id":"1.170370562","rc":[{"atb":[[1.78,0]],"id":9625043},{"atb":[[1.56,0]],"id":9631798}],"con":true,"img":false}]}
{"op":"mcm","clk":"1349439501","pt":1588396922349,"mc":[{"id":"1.170370562","rc":[{"atb":[[1.7,27.99]],"id":9625043},{"atb":[[1.64,29.59]],"id":9631798}],"con":true,"img":false}]}
{"op":"mcm","clk":"1349439858","pt":1588396929453,"mc":[{"id":"1.170370562","rc":[{"atb":[[1.7,0]],"id":9625043},{"atb":[[1.64,0]],"id":9631798}],"con":true,"img":false}]}
{"op":"mcm","clk":"1349439864","pt":1588396929552,"mc":[{"id":"1.170370562","rc":[{"atb":[[1.78,27.99]],"id":9625043},{"atb":[[1.56,29.59]],"id":9631798}],"con":true,"img":false}]}
{"op":"mcm","clk":"1349440215","pt":1588396937147,"mc":[{"id":"1.170370562","rc":[{"atb":[[1.78,0]],"id":9625043},{"atb":[[1.56,0]],"id":9631798}],"con":true,"img":false}]}
{"op":"mcm","clk":"1349440221","pt":1588396937249,"mc":[{"id":"1.170370562","rc":[{"atb":[[1.7,27.99]],"id":9625043},{"atb":[[1.64,29.59]],"id":9631798}],"con":true,"img":false}]}
{"op":"mcm","clk":"1349440578","pt":1588396945173,"mc":[{"id":"1.170370562","rc":[{"atb":[[1.7,0]],"id":9625043},{"atb":[[1.64,0]],"id":9631798}],"con":true,"img":false}]}
{"op":"mcm","clk":"1349440584","pt":1588396945277,"mc":[{"id":"1.170370562","rc":[{"atb":[[1.78,27.99]],"id":9625043},{"atb":[[1.56,29.59]],"id":9631798}],"con":true,"img":false}]}
{"op":"mcm","clk":"1349440992","pt":1588396954877,"mc":[{"id":"1.170370562","rc":[{"atb":[[1.78,0]],"id":9625043},{"atb":[[1.56,0]],"id":9631798}],"con":true,"img":false}]}
{"op":"mcm","clk":"1349440997","pt":1588396954982,"mc":[{"id":"1.170370562","rc":[{"atb":[[1.7,27.99]],"id":9625043},{"atb":[[1.64,29.59]],"id":9631798}],"con":true,"img":false}]}
{"op":"mcm","clk":"1349441326","pt":1588396962284,"mc":[{"id":"1.170370562","rc":[{"atb":[[1.7,0]],"id":9625043},{"atb":[[1.64,0]],"id":9631798}],"con":true,"img":false}]}
{"op":"mcm","clk":"1349441331","pt":1588396962387,"mc":[{"id":"1.170370562","rc":[{"atb":[[1.78,27.99]],"id":9625043},{"atb":[[1.56,29.59]],"id":9631798}],"con":true,"img":false}]}
{"op":"mcm","clk":"1349441647","pt":1588396969579,"mc":[{"id":"1.170370562","rc":[{"atb":[[1.78,0]],"id":9625043},{"atb":[[1.56,0]],"id":9631798}],"con":true,"img":false}]}
{"op":"mcm","clk":"1349441654","pt":1588396969682,"mc":[{"id":"1.170370562","rc":[{"atb":[[1.7,27.99]],"id":9625043},{"atb":[[1.64,29.59]],"id":9631798}],"con":true,"img":false}]}
{"op":"mcm","clk":"1349441955","pt":1588396976996,"mc":[{"id":"1.170370562","rc":[{"atb":[[1.7,0]],"id":9625043},{"atb":[[1.64,0]],"id":9631798}],"con":true,"img":false}]}
{"op":"mcm","clk":"1349441959","pt":1588396977100,"mc":[{"id":"1.170370562","rc":[{"atb":[[1.78,27.99]],"id":9625043},{"atb":[[1.56,29.59]],"id":9631798}],"con":true,"img":false}]}
{"op":"mcm","clk":"1349442279","pt":1588396984649,"mc":[{"id":"1.170370562","rc":[{"atb":[[1.78,0]],"id":9625043},{"atb":[[1.56,0]],"id":9631798}],"con":true,"img":false}]}
{"op":"mcm","clk":"1349442282","pt":1588396984702,"mc":[{"id":"1.170370562","rc":[{"atb":[[1.7,27.99]],"id":9625043},{"atb":[[1.64,29.59]],"id":9631798}],"con":true,"img":false}]}
{"op":"mcm","clk":"1349442514","pt":1588396990206,"mc":[{"id":"1.170370562","rc":[{"atb":[[1.88,0]],"id":9625043}],"con":true,"img":false}]}
{"op":"mcm","clk":"1349442576","pt":1588396991652,"mc":[{"id":"1.170370562","rc":[{"atb":[[1.7,0]],"id":9625043},{"atb":[[1.64,0]],"id":9631798}],"con":true,"img":false}]}
{"op":"mcm","clk":"1349442581","pt":1588396991755,"mc":[{"id":"1.170370562","rc":[{"atb":[[1.78,27.99]],"id":9625043},{"atb":[[1.56,29.59]],"id":9631798}],"con":true,"img":false}]}
{"op":"mcm","clk":"1349442590","pt":1588396991911,"mc":[{"id":"1.170370562","rc":[{"atb":[[1.79,91.93]],"id":9625043}],"con":true,"img":false}]}
{"op":"mcm","clk":"1349442843","pt":1588396998847,"mc":[{"id":"1.170370562","rc":[{"atb":[[1.78,0]],"id":9625043},{"atb":[[1.56,0]],"id":9631798}],"con":true,"img":false}]}
{"op":"mcm","clk":"1349442847","pt":1588396998951,"mc":[{"id":"1.170370562","rc":[{"atb":[[1.7,27.99]],"id":9625043},{"atb":[[1.64,29.59]],"id":9631798}],"con":true,"img":false}]}
{"op":"mcm","clk":"1349443122","pt":1588397005954,"mc":[{"id":"1.170370562","rc":[{"atb":[[1.7,0]],"id":9625043},{"atb":[[1.64,0]],"id":9631798}],"con":true,"img":false}]}
{"op":"mcm","clk":"1349443124","pt":1588397006054,"mc":[{"id":"1.170370562","rc":[{"atb":[[1.78,27.99]],"id":9625043},{"atb":[[1.56,29.59]],"id":9631798}],"con":true,"img":false}]}
{"op":"mcm","clk":"1349443454","pt":1588397014260,"mc":[{"id":"1.170370562","rc":[{"atb":[[1.78,0]],"id":9625043},{"atb":[[1.56,0]],"id":9631798}],"con":true,"img":false}]}
{"op":"mcm","clk":"1349443457","pt":1588397014363,"mc":[{"id":"1.170370562","rc":[{"atb":[[1.7,27.99]],"id":9625043},{"atb":[[1.64,29.59]],"id":9631798}],"con":true,"img":false}]}
{"op":"mcm","clk":"1349443740","pt":1588397021369,"mc":[{"id":"1.170370562","rc":[{"atb":[[1.7,0]],"id":9625043},{"atb":[[1.64,0]],"id":9631798}],"con":true,"img":false}]}
{"op":"mcm","clk":"1349443743","pt":1588397021465,"mc":[{"id":"1.170370562","rc":[{"atb":[[1.78,27.99]],"id":9625043},{"atb":[[1.56,29.59]],"id":9631798}],"con":true,"img":false}]}
{"op":"mcm","clk":"1349444058","pt":1588397029186,"mc":[{"id":"1.170370562","rc":[{"atb":[[1.78,0]],"id":9625043},{"atb":[[1.56,0]],"id":9631798}],"con":true,"img":false}]}
{"op":"mcm","clk":"1349444062","pt":1588397029284,"mc":[{"id":"1.170370562","rc":[{"atb":[[1.7,27.99]],"id":9625043},{"atb":[[1.64,29.59]],"id":9631798}],"con":true,"img":false}]}
{"op":"mcm","clk":"1349444345","pt":1588397036602,"mc":[{"id":"1.170370562","rc":[{"atb":[[1.7,0]],"id":9625043},{"atb":[[1.64,0]],"id":9631798}],"con":true,"img":false}]}
{"op":"mcm","clk":"1349444349","pt":1588397036704,"mc":[{"id":"1.170370562","rc":[{"atb":[[1.78,27.99]],"id":9625043},{"atb":[[1.56,29.59]],"id":9631798}],"con":true,"img":false}]}
{"op":"mcm","clk":"1349444626","pt":1588397043621,"mc":[{"id":"1.170370562","rc":[{"atb":[[1.56,0]],"id":9631798}],"con":true,"img":false}]}
{"op":"mcm","clk":"1349444636","pt":1588397043882,"mc":[{"id":"1.170370562","rc":[{"atb":[[1.56,68.78]],"id":9631798}],"con":true,"img":false}]}
{"op":"mcm","clk":"1349444642","pt":1588397044093,"mc":[{"id":"1.170370562","rc":[{"atb":[[1.78,0]],"id":9625043}],"con":true,"img":false}]}
{"op":"mcm","clk":"1349444646","pt":1588397044195,"mc":[{"id":"1.170370562","rc":[{"atb":[[1.71,27.99]],"id":9625043}],"con":true,"img":false}]}
{"op":"mcm","clk":"1349444969","pt":1588397051996,"mc":[{"id":"1.170370562","rc":[{"atb":[[1.71,0]],"id":9625043},{"atb":[[1.56,0]],"id":9631798}],"con":true,"img":false}]}
{"op":"mcm","clk":"1349444972","pt":1588397052100,"mc":[{"id":"1.170370562","rc":[{"atb":[[1.8,27.99]],"id":9625043},{"atb":[[1.57,68.78]],"id":9631798}],"con":true,"img":false}]}
{"op":"mcm","clk":"1349444978","pt":1588397052306,"mc":[{"id":"1.170370562","rc":[{"atb":[[1.79,0]],"id":9625043}],"con":true,"img":false}]}
{"op":"mcm","clk":"1349444984","pt":1588397052410,"mc":[{"id":"1.170370562","rc":[{"atb":[[1.83,89.8]],"id":9625043}],"con":true,"img":false}]}
{"op":"mcm","clk":"1349446229","pt":1588397060130,"mc":[{"id":"1.170370562","rc":[{"atb":[[1.8,0]],"id":9625043},{"atb":[[1.57,0]],"id":9631798}],"con":true,"img":false}]}
{"op":"mcm","clk":"1349446234","pt":1588397060233,"mc":[{"id":"1.170370562","rc":[{"atb":[[1.71,27.99]],"id":9625043},{"atb":[[1.65,68.78]],"id":9631798}],"con":true,"img":false}]}
{"op":"mcm","clk":"1349446509","pt":1588397067259,"mc":[{"id":"1.170370562","rc":[{"atb":[[1.71,0]],"id":9625043},{"atb":[[1.65,0]],"id":9631798}],"con":true,"img":false}]}
{"op":"mcm","clk":"1349446514","pt":1588397067310,"mc":[{"id":"1.170370562","rc":[{"atb":[[1.8,27.99]],"id":9625043},{"atb":[[1.57,68.78]],"id":9631798}],"con":true,"img":false}]}
{"op":"mcm","clk":"1349446802","pt":1588397074643,"mc":[{"id":"1.170370562","rc":[{"atb":[[1.8,0]],"id":9625043},{"atb":[[1.57,0]],"id":9631798}],"con":true,"img":false}]}
{"op":"mcm","clk":"1349446807","pt":1588397074746,"mc":[{"id":"1.170370562","rc":[{"atb":[[1.71,27.99]],"id":9625043},{"atb":[[1.65,68.78]],"id":9631798}],"con":true,"img":false}]}
{"op":"mcm","clk":"1349447157","pt":1588397082482,"mc":[{"id":"1.170370562","rc":[{"atb":[[1.71,0]],"id":9625043},{"atb":[[1.65,0]],"id":9631798}],"con":true,"img":false}]}
{"op":"mcm","clk":"1349447159","pt":1588397082534,"mc":[{"id":"1.170370562","rc":[{"atb":[[1.8,27.99]],"id":9625043},{"atb":[[1.57,68.78]],"id":9631798}],"con":true,"img":false}]}
{"op":"mcm","clk":"1349447483","pt":1588397090073,"mc":[{"id":"1.170370562","rc":[{"atb":[[1.8,0]],"id":9625043},{"atb":[[1.57,0]],"id":9631798}],"con":true,"img":false}]}
{"op":"mcm","clk":"1349447490","pt":1588397090180,"mc":[{"id":"1.170370562","rc":[{"atb":[[1.71,27.99]],"id":9625043},{"atb":[[1.65,68.78]],"id":9631798}],"con":true,"img":false}]}
{"op":"mcm","clk":"1349447781","pt":1588397097570,"mc":[{"id":"1.170370562","rc":[{"atb":[[1.71,0]],"id":9625043},{"atb":[[1.65,0]],"id":9631798}],"con":true,"img":false}]}
{"op":"mcm","clk":"1349447788","pt":1588397097680,"mc":[{"id":"1.170370562","rc":[{"atb":[[1.8,27.99]],"id":9625043},{"atb":[[1.57,68.78]],"id":9631798}],"con":true,"img":false}]}
{"op":"mcm","clk":"1349453204","pt":1588397230131,"mc":[{"id":"1.170370562","rc":[{"atb":[[1.8,0]],"id":9625043}],"con":true,"img":false}]}
{"op":"mcm","clk":"1349453211","pt":1588397230331,"mc":[{"id":"1.170370562","rc":[{"atb":[[1.8,59.99]],"id":9625043}],"con":true,"img":false}]}
{"op":"mcm","clk":"1349453678","pt":1588397240519,"mc":[{"id":"1.170370562","rc":[{"atb":[[2,44.75]],"id":9625043},{"atb":[[1.73,61.31]],"id":9631798}],"con":true,"img":false}]}
{"op":"mcm","clk":"1349453687","pt":1588397240725,"mc":[{"id":"1.170370562","rc":[{"atb":[[1.83,0]],"id":9625043}],"con":true,"img":false}]}
{"op":"mcm","clk":"1349497851","pt":1588398280418,"mc":[{"id":"1.170370562","rc":[{"atb":[[1.1,121.58]],"id":9625043},{"atb":[[1.1,121.58]],"id":9631798}],"con":true,"img":false}]}
{"op":"mcm","clk":"1349536218","pt":1588399205976,"mc":[{"id":"1.170370562","rc":[{"atb":[[1.8,0]],"id":9625043},{"atb":[[1.57,0]],"id":9631798}],"con":true,"img":false}]}
{"op":"mcm","clk":"1349536223","pt":1588399206079,"mc":[{"id":"1.170370562","rc":[{"atb":[[1.71,59.99]],"id":9625043},{"atb":[[1.65,68.78]],"id":9631798}],"con":true,"img":false}]}
{"op":"mcm","clk":"1349536653","pt":1588399214717,"mc":[{"id":"1.170370562","rc":[{"atb":[[1.71,0]],"id":9625043},{"atb":[[1.65,0]],"id":9631798}],"con":true,"img":false}]}
{"op":"mcm","clk":"1349536657","pt":1588399214776,"mc":[{"id":"1.170370562","rc":[{"atb":[[1.78,59.99]],"id":9625043},{"atb":[[1.59,68.78]],"id":9631798}],"con":true,"img":false}]}
{"op":"mcm","clk":"1349536992","pt":1588399221285,"mc":[{"id":"1.170370562","rc":[{"atl":[[990,0]],"id":9625043},{"atl":[[990,0]],"id":9631798}],"con":true,"img":false}]}
{"op":"mcm","clk":"1349537177","pt":1588399224685,"mc":[{"id":"1.170370562","rc":[{"atb":[[1.78,0]],"id":9625043},{"atb":[[1.59,0]],"id":9631798}],"con":true,"img":false}]}
{"op":"mcm","clk":"1349537182","pt":1588399224788,"mc":[{"id":"1.170370562","rc":[{"atb":[[1.71,59.99]],"id":9625043},{"atb":[[1.65,68.78]],"id":9631798}],"con":true,"img":false}]}
{"op":"mcm","clk":"1349537587","pt":1588399232893,"mc":[{"id":"1.170370562","rc":[{"atb":[[1.71,0]],"id":9625043},{"atb":[[1.65,0]],"id":9631798}],"con":true,"img":false}]}
{"op":"mcm","clk":"1349537593","pt":1588399232999,"mc":[{"id":"1.170370562","rc":[{"atb":[[1.78,59.99]],"id":9625043},{"atb":[[1.59,68.78]],"id":9631798}],"con":true,"img":false}]}
{"op":"mcm","clk":"1349537985","pt":1588399241421,"mc":[{"id":"1.170370562","rc":[{"atb":[[1.78,0]],"id":9625043},{"atb":[[1.59,0]],"id":9631798}],"con":true,"img":false}]}
{"op":"mcm","clk":"1349537993","pt":1588399241514,"mc":[{"id":"1.170370562","rc":[{"atb":[[1.71,59.99]],"id":9625043},{"atb":[[1.65,68.78]],"id":9631798}],"con":true,"img":false}]}
{"op":"mcm","clk":"1349538302","pt":1588399248463,"mc":[{"id":"1.170370562","rc":[{"atb":[[1.71,0]],"id":9625043},{"atb":[[1.65,0]],"id":9631798}],"con":true,"img":false}]}
{"op":"mcm","clk":"1349538308","pt":1588399248631,"mc":[{"id":"1.170370562","rc":[{"atb":[[1.78,59.99]],"id":9625043},{"atb":[[1.59,68.78]],"id":9631798}],"con":true,"img":false}]}
{"op":"mcm","clk":"1349538619","pt":1588399255243,"mc":[{"id":"1.170370562","rc":[{"atb":[[1.78,0]],"id":9625043},{"atb":[[1.59,0]],"id":9631798}],"con":true,"img":false}]}
{"op":"mcm","clk":"1349538624","pt":1588399255345,"mc":[{"id":"1.170370562","rc":[{"atb":[[1.71,59.99]],"id":9625043},{"atb":[[1.65,68.78]],"id":9631798}],"con":true,"img":false}]}
{"op":"mcm","clk":"1349538941","pt":1588399262490,"mc":[{"id":"1.170370562","rc":[{"atb":[[1.71,0]],"id":9625043},{"atb":[[1.65,0]],"id":9631798}],"con":true,"img":false}]}
{"op":"mcm","clk":"1349538947","pt":1588399262594,"mc":[{"id":"1.170370562","rc":[{"atb":[[1.78,59.99]],"id":9625043},{"atb":[[1.59,68.78]],"id":9631798}],"con":true,"img":false}]}
{"op":"mcm","clk":"1349539464","pt":1588399273323,"mc":[{"id":"1.170370562","rc":[{"atb":[[1.78,0]],"id":9625043},{"atb":[[1.59,0]],"id":9631798}],"con":true,"img":false}]}
{"op":"mcm","clk":"1349539471","pt":1588399273427,"mc":[{"id":"1.170370562","rc":[{"atb":[[1.71,59.99]],"id":9625043},{"atb":[[1.65,68.78]],"id":9631798}],"con":true,"img":false}]}
{"op":"mcm","clk":"1349539875","pt":1588399282249,"mc":[{"id":"1.170370562","rc":[{"atb":[[1.71,0]],"id":9625043},{"atb":[[1.65,0]],"id":9631798}],"con":true,"img":false}]}
{"op":"mcm","clk":"1349539885","pt":1588399282302,"mc":[{"id":"1.170370562","rc":[{"atb":[[1.78,59.99]],"id":9625043},{"atb":[[1.59,68.78]],"id":9631798}],"con":true,"img":false}]}
{"op":"mcm","clk":"1349540243","pt":1588399289840,"mc":[{"id":"1.170370562","rc":[{"atb":[[1.78,0]],"id":9625043},{"atb":[[1.59,0]],"id":9631798}],"con":true,"img":false}]}
{"op":"mcm","clk":"1349540248","pt":1588399289944,"mc":[{"id":"1.170370562","rc":[{"atb":[[1.71,59.99]],"id":9625043},{"atb":[[1.65,68.78]],"id":9631798}],"con":true,"img":false}]}
{"op":"mcm","clk":"1349540603","pt":1588399298280,"mc":[{"id":"1.170370562","rc":[{"atb":[[1.71,0]],"id":9625043},{"atb":[[1.65,0]],"id":9631798}],"con":true,"img":false}]}
{"op":"mcm","clk":"1349540611","pt":1588399298339,"mc":[{"id":"1.170370562","rc":[{"atb":[[1.78,59.99]],"id":9625043},{"atb":[[1.59,68.78]],"id":9631798}],"con":true,"img":false}]}
{"op":"mcm","clk":"1349540905","pt":1588399305087,"mc":[{"id":"1.170370562","rc":[{"atb":[[1.78,0]],"id":9625043},{"atb":[[1.59,0]],"id":9631798}],"con":true,"img":false}]}
{"op":"mcm","clk":"1349540911","pt":1588399305182,"mc":[{"id":"1.170370562","rc":[{"atb":[[1.71,59.99]],"id":9625043},{"atb":[[1.65,68.78]],"id":9631798}],"con":true,"img":false}]}
{"op":"mcm","clk":"1349541215","pt":1588399312180,"mc":[{"id":"1.170370562","rc":[{"atb":[[1.71,0]],"id":9625043},{"atb":[[1.65,0]],"id":9631798}],"con":true,"img":false}]}
{"op":"mcm","clk":"1349541218","pt":1588399312282,"mc":[{"id":"1.170370562","rc":[{"atb":[[1.78,59.99]],"id":9625043},{"atb":[[1.59,68.78]],"id":9631798}],"con":true,"img":false}]}
{"op":"mcm","clk":"1349541525","pt":1588399319454,"mc":[{"id":"1.170370562","rc":[{"atb":[[1.78,0]],"id":9625043},{"atb":[[1.59,0]],"id":9631798}],"con":true,"img":false}]}
{"op":"mcm","clk":"1349541530","pt":1588399319556,"mc":[{"id":"1.170370562","rc":[{"atb":[[1.71,59.99]],"id":9625043},{"atb":[[1.65,68.78]],"id":9631798}],"con":true,"img":false}]}
{"op":"mcm","clk":"1349541840","pt":1588399326798,"mc":[{"id":"1.170370562","rc":[{"atb":[[1.71,0]],"id":9625043},{"atb":[[1.65,0]],"id":9631798}],"con":true,"img":false}]}
{"op":"mcm","clk":"1349541847","pt":1588399326900,"mc":[{"id":"1.170370562","rc":[{"atb":[[1.78,59.99]],"id":9625043},{"atb":[[1.59,68.78]],"id":9631798}],"con":true,"img":false}]}
{"op":"mcm","clk":"1349542152","pt":1588399333772,"mc":[{"id":"1.170370562","rc":[{"atb":[[1.78,0]],"id":9625043},{"atb":[[1.59,0]],"id":9631798}],"con":true,"img":false}]}
{"op":"mcm","clk":"1349542157","pt":1588399333875,"mc":[{"id":"1.170370562","rc":[{"atb":[[1.71,59.99]],"id":9625043},{"atb":[[1.65,68.78]],"id":9631798}],"con":true,"img":false}]}
{"op":"mcm","clk":"1349542453","pt":1588399340602,"mc":[{"id":"1.170370562","rc":[{"atb":[[1.71,0]],"id":9625043},{"atb":[[1.65,0]],"id":9631798}],"con":true,"img":false}]}
{"op":"mcm","clk":"1349542462","pt":1588399340705,"mc":[{"id":"1.170370562","rc":[{"atb":[[1.78,59.99]],"id":9625043},{"atb":[[1.59,68.78]],"id":9631798}],"con":true,"img":false}]}
{"op":"mcm","clk":"1349542847","pt":1588399348625,"mc":[{"id":"1.170370562","rc":[{"atb":[[1.78,0]],"id":9625043},{"atb":[[1.59,0]],"id":9631798}],"con":true,"img":false}]}
{"op":"mcm","clk":"1349542854","pt":1588399348729,"mc":[{"id":"1.170370562","rc":[{"atb":[[1.71,59.99]],"id":9625043},{"atb":[[1.65,68.78]],"id":9631798}],"con":true,"img":false}]}
{"op":"mcm","clk":"1349543171","pt":1588399355943,"mc":[{"id":"1.170370562","rc":[{"atb":[[1.71,0]],"id":9625043},{"atb":[[1.65,0]],"id":9631798}],"con":true,"img":false}]}
{"op":"mcm","clk":"1349543179","pt":1588399356148,"mc":[{"id":"1.170370562","rc":[{"atb":[[1.78,59.99]],"id":9625043},{"atb":[[1.59,68.78]],"id":9631798}],"con":true,"img":false}]}
{"op":"mcm","clk":"1349543462","pt":1588399362746,"mc":[{"id":"1.170370562","rc":[{"atb":[[1.78,0]],"id":9625043},{"atb":[[1.59,0]],"id":9631798}],"con":true,"img":false}]}
{"op":"mcm","clk":"1349543466","pt":1588399362842,"mc":[{"id":"1.170370562","rc":[{"atb":[[1.71,59.99]],"id":9625043},{"atb":[[1.65,68.78]],"id":9631798}],"con":true,"img":false}]}
{"op":"mcm","clk":"1349543768","pt":1588399369547,"mc":[{"id":"1.170370562","rc":[{"atb":[[1.71,0]],"id":9625043},{"atb":[[1.65,0]],"id":9631798}],"con":true,"img":false}]}
{"op":"mcm","clk":"1349543774","pt":1588399369650,"mc":[{"id":"1.170370562","rc":[{"atb":[[1.78,59.99]],"id":9625043},{"atb":[[1.59,68.78]],"id":9631798}],"con":true,"img":false}]}
{"op":"mcm","clk":"1349544065","pt":1588399376091,"mc":[{"id":"1.170370562","rc":[{"atb":[[1.78,0]],"id":9625043},{"atb":[[1.59,0]],"id":9631798}],"con":true,"img":false}]}
{"op":"mcm","clk":"1349544072","pt":1588399376189,"mc":[{"id":"1.170370562","rc":[{"atb":[[1.71,59.99]],"id":9625043},{"atb":[[1.65,68.78]],"id":9631798}],"con":true,"img":false}]}
{"op":"mcm","clk":"1349544475","pt":1588399383178,"mc":[{"id":"1.170370562","rc":[{"atb":[[1.71,0]],"id":9625043},{"atb":[[1.65,0]],"id":9631798}],"con":true,"img":false}]}
{"op":"mcm","clk":"1349544481","pt":1588399383282,"mc":[{"id":"1.170370562","rc":[{"atb":[[1.78,59.99]],"id":9625043},{"atb":[[1.59,68.78]],"id":9631798}],"con":true,"img":false}]}
{"op":"mcm","clk":"1349544804","pt":1588399389798,"mc":[{"id":"1.170370562","rc":[{"atb":[[1.78,0]],"id":9625043},{"atb":[[1.59,0]],"id":9631798}],"con":true,"img":false}]}
{"op":"mcm","clk":"1349544810","pt":1588399389897,"mc":[{"id":"1.170370562","rc":[{"atb":[[1.71,59.99]],"id":9625043},{"atb":[[1.65,68.78]],"id":9631798}],"con":true,"img":false}]}
{"op":"mcm","clk":"1349545145","pt":1588399396885,"mc":[{"id":"1.170370562","rc":[{"atb":[[1.71,0]],"id":9625043},{"atb":[[1.65,0]],"id":9631798}],"con":true,"img":false}]}
{"op":"mcm","clk":"1349545150","pt":1588399396988,"mc":[{"id":"1.170370562","rc":[{"atb":[[1.78,59.99]],"id":9625043},{"atb":[[1.59,68.78]],"id":9631798}],"con":true,"img":false}]}
{"op":"mcm","clk":"1349545514","pt":1588399404400,"mc":[{"id":"1.170370562","rc":[{"atb":[[1.78,0]],"id":9625043},{"atb":[[1.59,0]],"id":9631798}],"con":true,"img":false}]}
{"op":"mcm","clk":"1349545520","pt":1588399404503,"mc":[{"id":"1.170370562","rc":[{"atb":[[1.71,59.99]],"id":9625043},{"atb":[[1.65,68.78]],"id":9631798}],"con":true,"img":false}]}
{"op":"mcm","clk":"1349545873","pt":1588399412042,"mc":[{"id":"1.170370562","rc":[{"atb":[[1.71,0]],"id":9625043},{"atb":[[1.65,0]],"id":9631798}],"con":true,"img":false}]}
{"op":"mcm","clk":"1349545879","pt":1588399412143,"mc":[{"id":"1.170370562","rc":[{"atb":[[1.78,59.99]],"id":9625043},{"atb":[[1.59,68.78]],"id":9631798}],"con":true,"img":false}]}
{"op":"mcm","clk":"1349546207","pt":1588399418844,"mc":[{"id":"1.170370562","rc":[{"atb":[[1.78,0]],"id":9625043},{"atb":[[1.59,0]],"id":9631798}],"con":true,"img":false}]}
{"op":"mcm","clk":"1349546212","pt":1588399418948,"mc":[{"id":"1.170370562","rc":[{"atb":[[1.71,59.99]],"id":9625043},{"atb":[[1.65,68.78]],"id":9631798}],"con":true,"img":false}]}
{"op":"mcm","clk":"1349546558","pt":1588399425859,"mc":[{"id":"1.170370562","rc":[{"atb":[[1.71,0]],"id":9625043},{"atb":[[1.65,0]],"id":9631798}],"con":true,"img":false}]}
{"op":"mcm","clk":"1349546565","pt":1588399425911,"mc":[{"id":"1.170370562","rc":[{"atb":[[1.78,59.99]],"id":9625043},{"atb":[[1.59,68.78]],"id":9631798}],"con":true,"img":false}]}
{"op":"mcm","clk":"1349546890","pt":1588399432877,"mc":[{"id":"1.170370562","rc":[{"atb":[[1.78,0]],"id":9625043},{"atb":[[1.59,0]],"id":9631798}],"con":true,"img":false}]}
{"op":"mcm","clk":"1349546895","pt":1588399432929,"mc":[{"id":"1.170370562","rc":[{"atb":[[1.71,59.99]],"id":9625043},{"atb":[[1.65,68.78]],"id":9631798}],"con":true,"img":false}]}
{"op":"mcm","clk":"1349547180","pt":1588399440246,"mc":[{"id":"1.170370562","rc":[{"atb":[[1.71,0]],"id":9625043},{"atb":[[1.65,0]],"id":9631798}],"con":true,"img":false}]}
{"op":"mcm","clk":"1349547185","pt":1588399440352,"mc":[{"id":"1.170370562","rc":[{"atb":[[1.78,59.99]],"id":9625043},{"atb":[[1.59,68.78]],"id":9631798}],"con":true,"img":false}]}
{"op":"mcm","clk":"1349547423","pt":1588399447234,"mc":[{"id":"1.170370562","rc":[{"atb":[[1.78,0]],"id":9625043},{"atb":[[1.59,0]],"id":9631798}],"con":true,"img":false}]}
{"op":"mcm","clk":"1349547426","pt":1588399447336,"mc":[{"id":"1.170370562","rc":[{"atb":[[1.71,59.99]],"id":9625043},{"atb":[[1.65,68.78]],"id":9631798}],"con":true,"img":false}]}
{"op":"mcm","clk":"1349547683","pt":1588399454036,"mc":[{"id":"1.170370562","rc":[{"atb":[[1.71,0]],"id":9625043},{"atb":[[1.65,0]],"id":9631798}],"con":true,"img":false}]}
{"op":"mcm","clk":"1349547687","pt":1588399454139,"mc":[{"id":"1.170370562","rc":[{"atb":[[1.78,59.99]],"id":9625043},{"atb":[[1.59,68.78]],"id":9631798}],"con":true,"img":false}]}
{"op":"mcm","clk":"1349547942","pt":1588399461063,"mc":[{"id":"1.170370562","rc":[{"atb":[[1.78,0]],"id":9625043},{"atb":[[1.59,0]],"id":9631798}],"con":true,"img":false}]}
{"op":"mcm","clk":"1349547946","pt":1588399461166,"mc":[{"id":"1.170370562","rc":[{"atb":[[1.71,59.99]],"id":9625043},{"atb":[[1.65,68.78]],"id":9631798}],"con":true,"img":false}]}
{"op":"mcm","clk":"1349548189","pt":1588399468689,"mc":[{"id":"1.170370562","rc":[{"atb":[[1.71,0]],"id":9625043},{"atb":[[1.65,0]],"id":9631798}],"con":true,"img":false}]}
{"op":"mcm","clk":"1349548194","pt":1588399468745,"mc":[{"id":"1.170370562","rc":[{"atb":[[1.78,59.99]],"id":9625043},{"atb":[[1.59,68.78]],"id":9631798}],"con":true,"img":false}]}
{"op":"mcm","clk":"1349548492","pt":1588399476472,"mc":[{"id":"1.170370562","rc":[{"atb":[[1.78,0]],"id":9625043},{"atb":[[1.59,0]],"id":9631798}],"con":true,"img":false}]}
{"op":"mcm","clk":"1349548498","pt":1588399476577,"mc":[{"id":"1.170370562","rc":[{"atb":[[1.71,59.99]],"id":9625043},{"atb":[[1.65,68.78]],"id":9631798}],"con":true,"img":false}]}
{"op":"mcm","clk":"1349548759","pt":1588399483189,"mc":[{"id":"1.170370562","rc":[{"atb":[[1.71,0]],"id":9625043},{"atb":[[1.65,0]],"id":9631798}],"con":true,"img":false}]}
{"op":"mcm","clk":"1349548766","pt":1588399483294,"mc":[{"id":"1.170370562","rc":[{"atb":[[1.78,59.99]],"id":9625043},{"atb":[[1.59,68.78]],"id":9631798}],"con":true,"img":false}]}
{"op":"mcm","clk":"1349549027","pt":1588399490210,"mc":[{"id":"1.170370562","rc":[{"atb":[[1.78,0]],"id":9625043},{"atb":[[1.59,0]],"id":9631798}],"con":true,"img":false}]}
{"op":"mcm","clk":"1349549032","pt":1588399490309,"mc":[{"id":"1.170370562","rc":[{"atb":[[1.71,59.99]],"id":9625043},{"atb":[[1.65,68.78]],"id":9631798}],"con":true,"img":false}]}
{"op":"mcm","clk":"1349549283","pt":1588399497197,"mc":[{"id":"1.170370562","rc":[{"atb":[[1.71,0]],"id":9625043},{"atb":[[1.65,0]],"id":9631798}],"con":true,"img":false}]}
{"op":"mcm","clk":"1349549287","pt":1588399497297,"mc":[{"id":"1.170370562","rc":[{"atb":[[1.78,59.99]],"id":9625043},{"atb":[[1.59,68.78]],"id":9631798}],"con":true,"img":false}]}
{"op":"mcm","clk":"1349549512","pt":1588399504443,"mc":[{"id":"1.170370562","rc":[{"atb":[[1.78,0]],"id":9625043},{"atb":[[1.59,0]],"id":9631798}],"con":true,"img":false}]}
{"op":"mcm","clk":"1349549517","pt":1588399504547,"mc":[{"id":"1.170370562","rc":[{"atb":[[1.71,59.99]],"id":9625043},{"atb":[[1.65,68.78]],"id":9631798}],"con":true,"img":false}]}
{"op":"mcm","clk":"1349549843","pt":1588399513154,"mc":[{"id":"1.170370562","rc":[{"atb":[[1.71,0]],"id":9625043},{"atb":[[1.65,0]],"id":9631798}],"con":true,"img":false}]}
{"op":"mcm","clk":"1349549845","pt":1588399513214,"mc":[{"id":"1.170370562","rc":[{"atb":[[1.78,59.99]],"id":9625043},{"atb":[[1.59,68.78]],"id":9631798}],"con":true,"img":false}]}
{"op":"mcm","clk":"1349550124","pt":1588399519916,"mc":[{"id":"1.170370562","rc":[{"atb":[[1.78,0]],"id":9625043},{"atb":[[1.59,0]],"id":9631798}],"con":true,"img":false}]}
{"op":"mcm","clk":"1349550131","pt":1588399520033,"mc":[{"id":"1.170370562","rc":[{"atb":[[1.71,59.99]],"id":9625043},{"atb":[[1.65,68.78]],"id":9631798}],"con":true,"img":false}]}
{"op":"mcm","clk":"1349550391","pt":1588399526850,"mc":[{"id":"1.170370562","rc":[{"atb":[[1.71,0]],"id":9625043},{"atb":[[1.65,0]],"id":9631798}],"con":true,"img":false}]}
{"op":"mcm","clk":"1349550395","pt":1588399526955,"mc":[{"id":"1.170370562","rc":[{"atb":[[1.78,59.99]],"id":9625043},{"atb":[[1.59,68.78]],"id":9631798}],"con":true,"img":false}]}
{"op":"mcm","clk":"1349550655","pt":1588399533968,"mc":[{"id":"1.170370562","rc":[{"atb":[[1.78,0]],"id":9625043},{"atb":[[1.59,0]],"id":9631798}],"con":true,"img":false}]}
{"op":"mcm","clk":"1349550658","pt":1588399534072,"mc":[{"id":"1.170370562","rc":[{"atb":[[1.71,59.99]],"id":9625043},{"atb":[[1.65,68.78]],"id":9631798}],"con":true,"img":false}]}
{"op":"mcm","clk":"1349550887","pt":1588399540975,"mc":[{"id":"1.170370562","rc":[{"atb":[[1.71,0]],"id":9625043},{"atb":[[1.65,0]],"id":9631798}],"con":true,"img":false}]}
{"op":"mcm","clk":"1349550889","pt":1588399541073,"mc":[{"id":"1.170370562","rc":[{"atb":[[1.78,59.99]],"id":9625043},{"atb":[[1.59,68.78]],"id":9631798}],"con":true,"img":false}]}
{"op":"mcm","clk":"1349551147","pt":1588399547784,"mc":[{"id":"1.170370562","rc":[{"atb":[[1.78,0]],"id":9625043},{"atb":[[1.59,0]],"id":9631798}],"con":true,"img":false}]}
{"op":"mcm","clk":"1349551152","pt":1588399547886,"mc":[{"id":"1.170370562","rc":[{"atb":[[1.71,59.99]],"id":9625043},{"atb":[[1.65,68.78]],"id":9631798}],"con":true,"img":false}]}
{"op":"mcm","clk":"1349551422","pt":1588399554999,"mc":[{"id":"1.170370562","rc":[{"atb":[[1.71,0]],"id":9625043},{"atb":[[1.65,0]],"id":9631798}],"con":true,"img":false}]}
{"op":"mcm","clk":"1349551427","pt":1588399555102,"mc":[{"id":"1.170370562","rc":[{"atb":[[1.78,59.99]],"id":9625043},{"atb":[[1.59,68.78]],"id":9631798}],"con":true,"img":false}]}
{"op":"mcm","clk":"1349551657","pt":1588399561642,"mc":[{"id":"1.170370562","rc":[{"atb":[[1.78,0]],"id":9625043},{"atb":[[1.59,0]],"id":9631798}],"con":true,"img":false}]}
{"op":"mcm","clk":"1349551663","pt":1588399561745,"mc":[{"id":"1.170370562","rc":[{"atb":[[1.71,59.99]],"id":9625043},{"atb":[[1.65,68.78]],"id":9631798}],"con":true,"img":false}]}
{"op":"mcm","clk":"1349551977","pt":1588399568651,"mc":[{"id":"1.170370562","rc":[{"atb":[[1.71,0]],"id":9625043},{"atb":[[1.65,0]],"id":9631798}],"con":true,"img":false}]}
{"op":"mcm","clk":"1349551985","pt":1588399568753,"mc":[{"id":"1.170370562","rc":[{"atb":[[1.78,59.99]],"id":9625043},{"atb":[[1.59,68.78]],"id":9631798}],"con":true,"img":false}]}
{"op":"mcm","clk":"1349552319","pt":1588399575451,"mc":[{"id":"1.170370562","rc":[{"atb":[[1.78,0]],"id":9625043},{"atb":[[1.59,0]],"id":9631798}],"con":true,"img":false}]}
{"op":"mcm","clk":"1349552323","pt":1588399575553,"mc":[{"id":"1.170370562","rc":[{"atb":[[1.71,59.99]],"id":9625043},{"atb":[[1.65,68.78]],"id":9631798}],"con":true,"img":false}]}
{"op":"mcm","clk":"1349552610","pt":1588399582446,"mc":[{"id":"1.170370562","rc":[{"atb":[[1.71,0]],"id":9625043},{"atb":[[1.65,0]],"id":9631798}],"con":true,"img":false}]}
{"op":"mcm","clk":"1349552617","pt":1588399582548,"mc":[{"id":"1.170370562","rc":[{"atb":[[1.78,59.99]],"id":9625043},{"atb":[[1.59,68.78]],"id":9631798}],"con":true,"img":false}]}
{"op":"mcm","clk":"1349552916","pt":1588399590261,"mc":[{"id":"1.170370562","rc":[{"atb":[[1.78,0]],"id":9625043},{"atb":[[1.59,0]],"id":9631798}],"con":true,"img":false}]}
{"op":"mcm","clk":"1349552919","pt":1588399590364,"mc":[{"id":"1.170370562","rc":[{"atb":[[1.71,59.99]],"id":9625043},{"atb":[[1.65,68.78]],"id":9631798}],"con":true,"img":false}]}
{"op":"mcm","clk":"1349553216","pt":1588399597190,"mc":[{"id":"1.170370562","rc":[{"atb":[[1.71,0]],"id":9625043},{"atb":[[1.65,0]],"id":9631798}],"con":true,"img":false}]}
{"op":"mcm","clk":"1349553221","pt":1588399597242,"mc":[{"id":"1.170370562","rc":[{"atb":[[1.78,59.99]],"id":9625043},{"atb":[[1.59,68.78]],"id":9631798}],"con":true,"img":false}]}
{"op":"mcm","clk":"1349553510","pt":1588399604181,"mc":[{"id":"1.170370562","rc":[{"atb":[[1.78,0]],"id":9625043},{"atb":[[1.59,0]],"id":9631798}],"con":true,"img":false}]}
{"op":"mcm","clk":"1349553513","pt":1588399604284,"mc":[{"id":"1.170370562","rc":[{"atb":[[1.71,59.99]],"id":9625043},{"atb":[[1.65,68.78]],"id":9631798}],"con":true,"img":false}]}
{"op":"mcm","clk":"1349553802","pt":1588399611064,"mc":[{"id":"1.170370562","rc":[{"atb":[[1.71,0]],"id":9625043},{"atb":[[1.65,0]],"id":9631798}],"con":true,"img":false}]}
{"op":"mcm","clk":"1349553807","pt":1588399611167,"mc":[{"id":"1.170370562","rc":[{"atb":[[1.78,59.99]],"id":9625043},{"atb":[[1.59,68.78]],"id":9631798}],"con":true,"img":false}]}
{"op":"mcm","clk":"1349554088","pt":1588399617697,"mc":[{"id":"1.170370562","rc":[{"atb":[[1.78,0]],"id":9625043},{"atb":[[1.59,0]],"id":9631798}],"con":true,"img":false}]}
{"op":"mcm","clk":"1349554092","pt":1588399617800,"mc":[{"id":"1.170370562","rc":[{"atb":[[1.71,59.99]],"id":9625043},{"atb":[[1.65,68.78]],"id":9631798}],"con":true,"img":false}]}
{"op":"mcm","clk":"1349554441","pt":1588399625514,"mc":[{"id":"1.170370562","rc":[{"atb":[[1.71,0]],"id":9625043},{"atb":[[1.65,0]],"id":9631798}],"con":true,"img":false}]}
{"op":"mcm","clk":"1349554445","pt":1588399625615,"mc":[{"id":"1.170370562","rc":[{"atb":[[1.78,59.99]],"id":9625043},{"atb":[[1.59,68.78]],"id":9631798}],"con":true,"img":false}]}
{"op":"mcm","clk":"1349554755","pt":1588399632410,"mc":[{"id":"1.170370562","rc":[{"atb":[[1.78,0]],"id":9625043},{"atb":[[1.59,0]],"id":9631798}],"con":true,"img":false}]}
{"op":"mcm","clk":"1349554760","pt":1588399632512,"mc":[{"id":"1.170370562","rc":[{"atb":[[1.71,59.99]],"id":9625043},{"atb":[[1.65,68.78]],"id":9631798}],"con":true,"img":false}]}
{"op":"mcm","clk":"1349555034","pt":1588399639412,"mc":[{"id":"1.170370562","rc":[{"atb":[[1.71,0]],"id":9625043},{"atb":[[1.65,0]],"id":9631798}],"con":true,"img":false}]}
{"op":"mcm","clk":"1349555039","pt":1588399639515,"mc":[{"id":"1.170370562","rc":[{"atb":[[1.78,59.99]],"id":9625043},{"atb":[[1.59,68.78]],"id":9631798}],"con":true,"img":false}]}
{"op":"mcm","clk":"1349555320","pt":1588399646649,"mc":[{"id":"1.170370562","rc":[{"atb":[[1.78,0]],"id":9625043},{"atb":[[1.59,0]],"id":9631798}],"con":true,"img":false}]}
{"op":"mcm","clk":"1349555325","pt":1588399646750,"mc":[{"id":"1.170370562","rc":[{"atb":[[1.71,59.99]],"id":9625043},{"atb":[[1.65,68.78]],"id":9631798}],"con":true,"img":false}]}
{"op":"mcm","clk":"1349555558","pt":1588399653256,"mc":[{"id":"1.170370562","rc":[{"atb":[[1.71,0]],"id":9625043},{"atb":[[1.65,0]],"id":9631798}],"con":true,"img":false}]}
{"op":"mcm","clk":"1349555562","pt":1588399653361,"mc":[{"id":"1.170370562","rc":[{"atb":[[1.78,59.99]],"id":9625043},{"atb":[[1.59,68.78]],"id":9631798}],"con":true,"img":false}]}
{"op":"mcm","clk":"1349555829","pt":1588399660474,"mc":[{"id":"1.170370562","rc":[{"atb":[[1.78,0]],"id":9625043},{"atb":[[1.59,0]],"id":9631798}],"con":true,"img":false}]}
{"op":"mcm","clk":"1349555833","pt":1588399660577,"mc":[{"id":"1.170370562","rc":[{"atb":[[1.71,59.99]],"id":9625043},{"atb":[[1.65,68.78]],"id":9631798}],"con":true,"img":false}]}
{"op":"mcm","clk":"1349556118","pt":1588399667981,"mc":[{"id":"1.170370562","rc":[{"atb":[[1.71,0]],"id":9625043},{"atb":[[1.65,0]],"id":9631798}],"con":true,"img":false}]}
{"op":"mcm","clk":"1349556122","pt":1588399668081,"mc":[{"id":"1.170370562","rc":[{"atb":[[1.78,59.99]],"id":9625043},{"atb":[[1.59,68.78]],"id":9631798}],"con":true,"img":false}]}
{"op":"mcm","clk":"1349556412","pt":1588399676494,"mc":[{"id":"1.170370562","rc":[{"atb":[[1.78,0]],"id":9625043},{"atb":[[1.59,0]],"id":9631798}],"con":true,"img":false}]}
{"op":"mcm","clk":"1349556417","pt":1588399676589,"mc":[{"id":"1.170370562","rc":[{"atb":[[1.71,59.99]],"id":9625043},{"atb":[[1.65,68.78]],"id":9631798}],"con":true,"img":false}]}
{"op":"mcm","clk":"1349556665","pt":1588399683511,"mc":[{"id":"1.170370562","rc":[{"atb":[[1.71,0]],"id":9625043},{"atb":[[1.65,0]],"id":9631798}],"con":true,"img":false}]}
{"op":"mcm","clk":"1349556668","pt":1588399683602,"mc":[{"id":"1.170370562","rc":[{"atb":[[1.78,59.99]],"id":9625043},{"atb":[[1.59,68.78]],"id":9631798}],"con":true,"img":false}]}
{"op":"mcm","clk":"1349556906","pt":1588399690192,"mc":[{"id":"1.170370562","rc":[{"atb":[[1.78,0]],"id":9625043},{"atb":[[1.59,0]],"id":9631798}],"con":true,"img":false}]}
{"op":"mcm","clk":"1349556910","pt":1588399690294,"mc":[{"id":"1.170370562","rc":[{"atb":[[1.71,59.99]],"id":9625043},{"atb":[[1.65,68.78]],"id":9631798}],"con":true,"img":false}]}
{"op":"mcm","clk":"1349557116","pt":1588399697425,"mc":[{"id":"1.170370562","rc":[{"atb":[[1.71,0]],"id":9625043},{"atb":[[1.65,0]],"id":9631798}],"con":true,"img":false}]}
{"op":"mcm","clk":"1349557121","pt":1588399697527,"mc":[{"id":"1.170370562","rc":[{"atb":[[1.78,59.99]],"id":9625043},{"atb":[[1.59,68.78]],"id":9631798}],"con":true,"img":false}]}
{"op":"mcm","clk":"1349557364","pt":1588399704943,"mc":[{"id":"1.170370562","rc":[{"atb":[[1.78,0]],"id":9625043},{"atb":[[1.59,0]],"id":9631798}],"con":true,"img":false}]}
{"op":"mcm","clk":"1349557368","pt":1588399705046,"mc":[{"id":"1.170370562","rc":[{"atb":[[1.71,59.99]],"id":9625043},{"atb":[[1.65,68.78]],"id":9631798}],"con":true,"img":false}]}
{"op":"mcm","clk":"1349557584","pt":1588399712194,"mc":[{"id":"1.170370562","rc":[{"atb":[[1.71,0]],"id":9625043},{"atb":[[1.65,0]],"id":9631798}],"con":true,"img":false}]}
{"op":"mcm","clk":"1349557587","pt":1588399712248,"mc":[{"id":"1.170370562","rc":[{"atb":[[1.78,59.99]],"id":9625043},{"atb":[[1.59,68.78]],"id":9631798}],"con":true,"img":false}]}
{"op":"mcm","clk":"1349557826","pt":1588399719396,"mc":[{"id":"1.170370562","rc":[{"atb":[[1.78,0]],"id":9625043},{"atb":[[1.59,0]],"id":9631798}],"con":true,"img":false}]}
{"op":"mcm","clk":"1349557830","pt":1588399719499,"mc":[{"id":"1.170370562","rc":[{"atb":[[1.71,59.99]],"id":9625043},{"atb":[[1.65,68.78]],"id":9631798}],"con":true,"img":false}]}
{"op":"mcm","clk":"1349558091","pt":1588399726683,"mc":[{"id":"1.170370562","rc":[{"atb":[[1.71,0]],"id":9625043},{"atb":[[1.65,0]],"id":9631798}],"con":true,"img":false}]}
{"op":"mcm","clk":"1349558095","pt":1588399726788,"mc":[{"id":"1.170370562","rc":[{"atb":[[1.78,59.99]],"id":9625043},{"atb":[[1.59,68.78]],"id":9631798}],"con":true,"img":false}]}
{"op":"mcm","clk":"1349558358","pt":1588399734790,"mc":[{"id":"1.170370562","rc":[{"atb":[[1.78,0]],"id":9625043},{"atb":[[1.59,0]],"id":9631798}],"con":true,"img":false}]}
{"op":"mcm","clk":"1349558362","pt":1588399734893,"mc":[{"id":"1.170370562","rc":[{"atb":[[1.71,59.99]],"id":9625043},{"atb":[[1.65,68.78]],"id":9631798}],"con":true,"img":false}]}
{"op":"mcm","clk":"1349558615","pt":1588399741633,"mc":[{"id":"1.170370562","rc":[{"atb":[[1.71,0]],"id":9625043},{"atb":[[1.65,0]],"id":9631798}],"con":true,"img":false}]}
{"op":"mcm","clk":"1349558620","pt":1588399741735,"mc":[{"id":"1.170370562","rc":[{"atb":[[1.78,59.99]],"id":9625043},{"atb":[[1.59,68.78]],"id":9631798}],"con":true,"img":false}]}
{"op":"mcm","clk":"1349566963","pt":1588399930000,"mc":[{"id":"1.170370562","rc":[{"atb":[[1.8,89.77]],"id":9631798}],"con":true,"img":false}]}
{"op":"mcm","clk":"1349613197","pt":1588401177755,"mc":[{"id":"1.170370562","rc":[{"atb":[[1.8,84.21]],"id":9631798}],"con":true,"img":false}]}
{"op":"mcm","clk":"1349613201","pt":1588401177857,"mc":[{"id":"1.170370562","rc":[{"atb":[[1.79,5.56]],"id":9631798}],"con":true,"img":false}]}
{"op":"mcm","clk":"1349645515","pt":1588402226590,"mc":[{"id":"1.170370562","rc":[{"atl":[[1.88,3.99]],"id":9631798}],"con":true,"img":false}]}
{"op":"mcm","clk":"1349649261","pt":1588402368127,"mc":[{"id":"1.170370562","rc":[{"atb":[[1.11,31.99]],"id":9625043},{"atb":[[1.11,31.99]],"id":9631798}],"con":true,"img":false}]}
{"op":"mcm","clk":"1349649567","pt":1588402378924,"mc":[{"id":"1.170370562","rc":[{"atb":[[1.4,7.99]],"id":9631798},{"atl":[[2.4,3.19]],"id":9631798}],"con":true,"img":false}]}
{"op":"mcm","clk":"1349649606","pt":1588402380115,"mc":[{"id":"1.170370562","rc":[{"atb":[[1.79,0]],"id":9631798}],"con":true,"img":false}]}
{"op":"mcm","clk":"1349649607","pt":1588402380209,"mc":[{"id":"1.170370562","rc":[{"atb":[[1.8,89.77]],"id":9631798}],"con":true,"img":false}]}
{"op":"mcm","clk":"1349651580","pt":1588402445035,"mc":[{"id":"1.170370562","rc":[{"atb":[[1.01,4.79]],"id":9625043},{"atb":[[1.01,4.79]],"id":9631798}],"con":true,"img":false}]}
{"op":"mcm","clk":"1349655119","pt":1588402540822,"mc":[{"id":"1.170370562","rc":[{"atb":[[1.41,39.01]],"id":9631798}],"con":true,"img":false}]}
{"op":"mcm","clk":"1349655123","pt":1588402540925,"mc":[{"id":"1.170370562","rc":[{"atb":[[1.41,78.03]],"id":9631798}],"con":true,"img":false}]}
{"op":"mcm","clk":"1349655128","pt":1588402541131,"mc":[{"id":"1.170370562","rc":[{"atb":[[1.41,117.05]],"id":9631798}],"con":true,"img":false}]}
{"op":"mcm","clk":"1349655349","pt":1588402549062,"mc":[{"id":"1.170370562","rc":[{"atb":[[1.5,31.99]],"id":9625043}],"con":true,"img":false}]}
{"op":"mcm","clk":"1349655354","pt":1588402549166,"mc":[{"id":"1.170370562","rc":[{"atb":[[1.5,63.98]],"id":9625043}],"con":true,"img":false}]}
{"op":"mcm","clk":"1349655362","pt":1588402549365,"mc":[{"id":"1.170370562","rc":[{"atb":[[1.5,95.98]],"id":9625043}],"con":true,"img":false}]}
{"op":"mcm","clk":"1349655366","pt":1588402549468,"mc":[{"id":"1.170370562","rc":[{"atb":[[1.5,127.97]],"id":9625043}],"con":true,"img":false}]}
{"op":"mcm","clk":"1349655370","pt":1588402549571,"mc":[{"id":"1.170370562","rc":[{"atb":[[1.5,159.97]],"id":9625043}],"con":true,"img":false}]}
{"op":"mcm","clk":"1349655432","pt":1588402551739,"mc":[{"id":"1.170370562","rc":[{"atb":[[1.41,156.07]],"id":9631798}],"con":true,"img":false}]}
{"op":"mcm","clk":"1349655494","pt":1588402554161,"mc":[{"id":"1.170370562","rc":[{"atb":[[1.41,195.08]],"id":9631798}],"con":true,"img":false}]}
{"op":"mcm","clk":"1349663202","pt":1588402804690,"mc":[{"id":"1.170370562","rc":[{"atb":[[2,59.67]],"id":9625043},{"atb":[[1.73,81.74]],"id":9631798}],"con":true,"img":false}]}
{"op":"mcm","clk":"1349663580","pt":1588402814308,"mc":[{"id":"1.170370562","rc":[{"atb":[[1.59,0]],"id":9631798}],"con":true,"img":false}]}
{"op":"mcm","clk":"1349663582","pt":1588402814406,"mc":[{"id":"1.170370562","rc":[{"atb":[[1.65,68.78]],"id":9631798}],"con":true,"img":false}]}
{"op":"mcm","clk":"1349663830","pt":1588402821223,"mc":[{"id":"1.170370562","rc":[{"atb":[[1.78,0]],"id":9625043},{"atb":[[1.65,0]],"id":9631798}],"con":true,"img":false}]}
{"op":"mcm","clk":"1349663837","pt":1588402821326,"mc":[{"id":"1.170370562","rc":[{"atb":[[1.71,59.99]],"id":9625043},{"atb":[[1.59,68.78]],"id":9631798}],"con":true,"img":false}]}
{"op":"mcm","clk":"1349664059","pt":1588402827641,"mc":[{"id":"1.170370562","rc":[{"atb":[[1.71,0]],"id":9625043},{"atb":[[1.59,0]],"id":9631798}],"con":true,"img":false}]}
{"op":"mcm","clk":"1349664065","pt":1588402827743,"mc":[{"id":"1.170370562","rc":[{"atb":[[1.78,59.99]],"id":9625043},{"atb":[[1.65,68.78]],"id":9631798}],"con":true,"img":false}]}
{"op":"mcm","clk":"1349664322","pt":1588402834027,"mc":[{"id":"1.170370562","rc":[{"atb":[[1.78,0]],"id":9625043},{"atb":[[1.65,0]],"id":9631798}],"con":true,"img":false}]}
{"op":"mcm","clk":"1349664328","pt":1588402834138,"mc":[{"id":"1.170370562","rc":[{"atb":[[1.71,59.99]],"id":9625043},{"atb":[[1.59,68.78]],"id":9631798}],"con":true,"img":false}]}
{"op":"mcm","clk":"1349664579","pt":1588402840250,"mc":[{"id":"1.170370562","rc":[{"atb":[[1.71,0]],"id":9625043},{"atb":[[1.59,0]],"id":9631798}],"con":true,"img":false}]}
{"op":"mcm","clk":"1349664580","pt":1588402840347,"mc":[{"id":"1.170370562","rc":[{"atb":[[1.78,59.99]],"id":9625043},{"atb":[[1.65,68.78]],"id":9631798}],"con":true,"img":false}]}
{"op":"mcm","clk":"1349664814","pt":1588402846739,"mc":[{"id":"1.170370562","rc":[{"atb":[[1.78,0]],"id":9625043},{"atb":[[1.65,0]],"id":9631798}],"con":true,"img":false}]}
{"op":"mcm","clk":"1349664817","pt":1588402846835,"mc":[{"id":"1.170370562","rc":[{"atb":[[1.71,59.99]],"id":9625043},{"atb":[[1.59,68.78]],"id":9631798}],"con":true,"img":false}]}
{"op":"mcm","clk":"1349665059","pt":1588402852960,"mc":[{"id":"1.170370562","rc":[{"atb":[[1.71,0]],"id":9625043},{"atb":[[1.59,0]],"id":9631798}],"con":true,"img":false}]}
{"op":"mcm","clk":"1349665063","pt":1588402853063,"mc":[{"id":"1.170370562","rc":[{"atb":[[1.78,59.99]],"id":9625043},{"atb":[[1.65,68.78]],"id":9631798}],"con":true,"img":false}]}
{"op":"mcm","clk":"1349665275","pt":1588402859088,"mc":[{"id":"1.170370562","rc":[{"atb":[[1.78,0]],"id":9625043},{"atb":[[1.65,0]],"id":9631798}],"con":true,"img":false}]}
{"op":"mcm","clk":"1349665281","pt":1588402859190,"mc":[{"id":"1.170370562","rc":[{"atb":[[1.71,59.99]],"id":9625043},{"atb":[[1.59,68.78]],"id":9631798}],"con":true,"img":false}]}
{"op":"mcm","clk":"1349665509","pt":1588402865561,"mc":[{"id":"1.170370562","rc":[{"atb":[[1.71,0]],"id":9625043},{"atb":[[1.59,0]],"id":9631798}],"con":true,"img":false}]}
{"op":"mcm","clk":"1349665515","pt":1588402865664,"mc":[{"id":"1.170370562","rc":[{"atb":[[1.78,59.99]],"id":9625043},{"atb":[[1.65,68.78]],"id":9631798}],"con":true,"img":false}]}
{"op":"mcm","clk":"1349665711","pt":1588402871177,"mc":[{"id":"1.170370562","rc":[{"atb":[[1.78,0]],"id":9625043},{"atb":[[1.65,0]],"id":9631798}],"con":true,"img":false}]}
{"op":"mcm","clk":"1349665716","pt":1588402871311,"mc":[{"id":"1.170370562","rc":[{"atb":[[1.71,59.99]],"id":9625043},{"atb":[[1.59,68.78]],"id":9631798}],"con":true,"img":false}]}
{"op":"mcm","clk":"1349665927","pt":1588402877305,"mc":[{"id":"1.170370562","rc":[{"atb":[[1.71,0]],"id":9625043},{"atb":[[1.59,0]],"id":9631798}],"con":true,"img":false}]}
{"op":"mcm","clk":"1349665932","pt":1588402877408,"mc":[{"id":"1.170370562","rc":[{"atb":[[1.78,59.99]],"id":9625043},{"atb":[[1.65,68.78]],"id":9631798}],"con":true,"img":false}]}
{"op":"mcm","clk":"1349666163","pt":1588402883940,"mc":[{"id":"1.170370562","rc":[{"atb":[[1.78,0]],"id":9625043},{"atb":[[1.65,0]],"id":9631798}],"con":true,"img":false}]}
{"op":"mcm","clk":"1349666166","pt":1588402884035,"mc":[{"id":"1.170370562","rc":[{"atb":[[1.71,59.99]],"id":9625043},{"atb":[[1.59,68.78]],"id":9631798}],"con":true,"img":false}]}
{"op":"mcm","clk":"1349666404","pt":1588402891019,"mc":[{"id":"1.170370562","rc":[{"atb":[[1.71,0]],"id":9625043},{"atb":[[1.59,0]],"id":9631798}],"con":true,"img":false}]}
{"op":"mcm","clk":"1349666408","pt":1588402891122,"mc":[{"id":"1.170370562","rc":[{"atb":[[1.78,59.99]],"id":9625043},{"atb":[[1.65,68.78]],"id":9631798}],"con":true,"img":false}]}
{"op":"mcm","clk":"1349666595","pt":1588402897240,"mc":[{"id":"1.170370562","rc":[{"atb":[[1.78,0]],"id":9625043},{"atb":[[1.65,0]],"id":9631798}],"con":true,"img":false}]}
{"op":"mcm","clk":"1349666598","pt":1588402897343,"mc":[{"id":"1.170370562","rc":[{"atb":[[1.71,59.99]],"id":9625043},{"atb":[[1.59,68.78]],"id":9631798}],"con":true,"img":false}]}
{"op":"mcm","clk":"1349666792","pt":1588402903054,"mc":[{"id":"1.170370562","rc":[{"atb":[[1.71,0]],"id":9625043},{"atb":[[1.59,0]],"id":9631798}],"con":true,"img":false}]}
{"op":"mcm","clk":"1349666795","pt":1588402903156,"mc":[{"id":"1.170370562","rc":[{"atb":[[1.78,59.99]],"id":9625043},{"atb":[[1.65,68.78]],"id":9631798}],"con":true,"img":false}]}
{"op":"mcm","clk":"1349666990","pt":1588402909073,"mc":[{"id":"1.170370562","rc":[{"atb":[[1.78,0]],"id":9625043},{"atb":[[1.65,0]],"id":9631798}],"con":true,"img":false}]}
{"op":"mcm","clk":"1349666996","pt":1588402909174,"mc":[{"id":"1.170370562","rc":[{"atb":[[1.71,59.99]],"id":9625043},{"atb":[[1.59,68.78]],"id":9631798}],"con":true,"img":false}]}
{"op":"mcm","clk":"1349667208","pt":1588402915142,"mc":[{"id":"1.170370562","rc":[{"atb":[[1.71,0]],"id":9625043},{"atb":[[1.59,0]],"id":9631798}],"con":true,"img":false}]}
{"op":"mcm","clk":"1349667209","pt":1588402915242,"mc":[{"id":"1.170370562","rc":[{"atb":[[1.78,59.99]],"id":9625043},{"atb":[[1.65,68.78]],"id":9631798}],"con":true,"img":false}]}
{"op":"mcm","clk":"1349667393","pt":1588402921055,"mc":[{"id":"1.170370562","rc":[{"atb":[[1.78,0]],"id":9625043},{"atb":[[1.65,0]],"id":9631798}],"con":true,"img":false}]}
{"op":"mcm","clk":"1349667394","pt":1588402921150,"mc":[{"id":"1.170370562","rc":[{"atb":[[1.71,59.99]],"id":9625043},{"atb":[[1.59,68.78]],"id":9631798}],"con":true,"img":false}]}
{"op":"mcm","clk":"1349667582","pt":1588402927018,"mc":[{"id":"1.170370562","rc":[{"atb":[[1.71,0]],"id":9625043},{"atb":[[1.59,0]],"id":9631798}],"con":true,"img":false}]}
{"op":"mcm","clk":"1349667590","pt":1588402927121,"mc":[{"id":"1.170370562","rc":[{"atb":[[1.78,59.99]],"id":9625043},{"atb":[[1.65,68.78]],"id":9631798}],"con":true,"img":false}]}
{"op":"mcm","clk":"1349667807","pt":1588402932945,"mc":[{"id":"1.170370562","rc":[{"atb":[[1.78,0]],"id":9625043},{"atb":[[1.65,0]],"id":9631798}],"con":true,"img":false}]}
{"op":"mcm","clk":"1349667809","pt":1588402933041,"mc":[{"id":"1.170370562","rc":[{"atb":[[1.71,59.99]],"id":9625043},{"atb":[[1.59,68.78]],"id":9631798}],"con":true,"img":false}]}
{"op":"mcm","clk":"1349668018","pt":1588402938963,"mc":[{"id":"1.170370562","rc":[{"atb":[[1.71,0]],"id":9625043},{"atb":[[1.59,0]],"id":9631798}],"con":true,"img":false}]}
{"op":"mcm","clk":"1349668023","pt":1588402939064,"mc":[{"id":"1.170370562","rc":[{"atb":[[1.78,59.99]],"id":9625043},{"atb":[[1.65,68.78]],"id":9631798}],"con":true,"img":false}]}
{"op":"mcm","clk":"1349668244","pt":1588402944728,"mc":[{"id":"1.170370562","rc":[{"atb":[[1.78,0]],"id":9625043},{"atb":[[1.65,0]],"id":9631798}],"con":true,"img":false}]}
{"op":"mcm","clk":"1349668249","pt":1588402944831,"mc":[{"id":"1.170370562","rc":[{"atb":[[1.71,59.99]],"id":9625043},{"atb":[[1.59,68.78]],"id":9631798}],"con":true,"img":false}]}
{"op":"mcm","clk":"1349668464","pt":1588402951494,"mc":[{"id":"1.170370562","rc":[{"atb":[[1.71,0]],"id":9625043},{"atb":[[1.59,0]],"id":9631798}],"con":true,"img":false}]}
{"op":"mcm","clk":"1349668467","pt":1588402951583,"mc":[{"id":"1.170370562","rc":[{"atb":[[1.78,59.99]],"id":9625043},{"atb":[[1.65,68.78]],"id":9631798}],"con":true,"img":false}]}
{"op":"mcm","clk":"1349668700","pt":1588402957680,"mc":[{"id":"1.170370562","rc":[{"atb":[[1.78,0]],"id":9625043},{"atb":[[1.65,0]],"id":9631798}],"con":true,"img":false}]}
{"op":"mcm","clk":"1349668705","pt":1588402957785,"mc":[{"id":"1.170370562","rc":[{"atb":[[1.71,59.99]],"id":9625043},{"atb":[[1.59,68.78]],"id":9631798}],"con":true,"img":false}]}
{"op":"mcm","clk":"1349668895","pt":1588402963597,"mc":[{"id":"1.170370562","rc":[{"atb":[[1.71,0]],"id":9625043},{"atb":[[1.59,0]],"id":9631798}],"con":true,"img":false}]}
{"op":"mcm","clk":"1349668900","pt":1588402963705,"mc":[{"id":"1.170370562","rc":[{"atb":[[1.78,59.99]],"id":9625043},{"atb":[[1.65,68.78]],"id":9631798}],"con":true,"img":false}]}
{"op":"mcm","clk":"1349669107","pt":1588402969199,"mc":[{"id":"1.170370562","rc":[{"atb":[[1.78,0]],"id":9625043},{"atb":[[1.65,0]],"id":9631798}],"con":true,"img":false}]}
{"op":"mcm","clk":"1349669111","pt":1588402969303,"mc":[{"id":"1.170370562","rc":[{"atb":[[1.71,59.99]],"id":9625043},{"atb":[[1.59,68.78]],"id":9631798}],"con":true,"img":false}]}
{"op":"mcm","clk":"1349669331","pt":1588402975409,"mc":[{"id":"1.170370562","rc":[{"atb":[[1.71,0]],"id":9625043},{"atb":[[1.59,0]],"id":9631798}],"con":true,"img":false}]}
{"op":"mcm","clk":"1349669336","pt":1588402975512,"mc":[{"id":"1.170370562","rc":[{"atb":[[1.78,59.99]],"id":9625043},{"atb":[[1.65,68.78]],"id":9631798}],"con":true,"img":false}]}
{"op":"mcm","clk":"1349669552","pt":1588402981813,"mc":[{"id":"1.170370562","rc":[{"atb":[[1.78,0]],"id":9625043},{"atb":[[1.65,0]],"id":9631798}],"con":true,"img":false}]}
{"op":"mcm","clk":"1349669557","pt":1588402981914,"mc":[{"id":"1.170370562","rc":[{"atb":[[1.71,59.99]],"id":9625043},{"atb":[[1.59,68.78]],"id":9631798}],"con":true,"img":false}]}
{"op":"mcm","clk":"1349669757","pt":1588402987523,"mc":[{"id":"1.170370562","rc":[{"atb":[[1.71,0]],"id":9625043},{"atb":[[1.59,0]],"id":9631798}],"con":true,"img":false}]}
{"op":"mcm","clk":"1349669763","pt":1588402987621,"mc":[{"id":"1.170370562","rc":[{"atb":[[1.78,59.99]],"id":9625043},{"atb":[[1.65,68.78]],"id":9631798}],"con":true,"img":false}]}
{"op":"mcm","clk":"1349669984","pt":1588402993635,"mc":[{"id":"1.170370562","rc":[{"atb":[[1.78,0]],"id":9625043},{"atb":[[1.65,0]],"id":9631798}],"con":true,"img":false}]}
{"op":"mcm","clk":"1349669991","pt":1588402993737,"mc":[{"id":"1.170370562","rc":[{"atb":[[1.71,59.99]],"id":9625043},{"atb":[[1.59,68.78]],"id":9631798}],"con":true,"img":false}]}
{"op":"mcm","clk":"1349670301","pt":1588403001140,"mc":[{"id":"1.170370562","rc":[{"atb":[[1.71,0]],"id":9625043},{"atb":[[1.59,0]],"id":9631798}],"con":true,"img":false}]}
{"op":"mcm","clk":"1349670304","pt":1588403001238,"mc":[{"id":"1.170370562","rc":[{"atb":[[1.78,59.99]],"id":9625043},{"atb":[[1.65,68.78]],"id":9631798}],"con":true,"img":false}]}
{"op":"mcm","clk":"1349670540","pt":1588403007349,"mc":[{"id":"1.170370562","rc":[{"atb":[[1.78,0]],"id":9625043},{"atb":[[1.65,0]],"id":9631798}],"con":true,"img":false}]}
{"op":"mcm","clk":"1349670544","pt":1588403007452,"mc":[{"id":"1.170370562","rc":[{"atb":[[1.71,59.99]],"id":9625043},{"atb":[[1.59,68.78]],"id":9631798}],"con":true,"img":false}]}
{"op":"mcm","clk":"1349670751","pt":1588403013259,"mc":[{"id":"1.170370562","rc":[{"atb":[[1.71,0]],"id":9625043},{"atb":[[1.59,0]],"id":9631798}],"con":true,"img":false}]}
{"op":"mcm","clk":"1349670760","pt":1588403013463,"mc":[{"id":"1.170370562","rc":[{"atb":[[1.78,59.99]],"id":9625043},{"atb":[[1.65,68.78]],"id":9631798}],"con":true,"img":false}]}
{"op":"mcm","clk":"1349670947","pt":1588403019371,"mc":[{"id":"1.170370562","rc":[{"atb":[[1.78,0]],"id":9625043},{"atb":[[1.65,0]],"id":9631798}],"con":true,"img":false}]}
{"op":"mcm","clk":"1349670951","pt":1588403019473,"mc":[{"id":"1.170370562","rc":[{"atb":[[1.71,59.99]],"id":9625043},{"atb":[[1.59,68.78]],"id":9631798}],"con":true,"img":false}]}
{"op":"mcm","clk":"1349671155","pt":1588403025485,"mc":[{"id":"1.170370562","rc":[{"atb":[[1.71,0]],"id":9625043},{"atb":[[1.59,0]],"id":9631798}],"con":true,"img":false}]}
{"op":"mcm","clk":"1349671159","pt":1588403025588,"mc":[{"id":"1.170370562","rc":[{"atb":[[1.78,59.99]],"id":9625043},{"atb":[[1.65,68.78]],"id":9631798}],"con":true,"img":false}]}
{"op":"mcm","clk":"1349671413","pt":1588403032695,"mc":[{"id":"1.170370562","rc":[{"atb":[[1.78,0]],"id":9625043},{"atb":[[1.65,0]],"id":9631798}],"con":true,"img":false}]}
{"op":"mcm","clk":"1349671419","pt":1588403032793,"mc":[{"id":"1.170370562","rc":[{"atb":[[1.71,59.99]],"id":9625043},{"atb":[[1.59,68.78]],"id":9631798}],"con":true,"img":false}]}
{"op":"mcm","clk":"1349671631","pt":1588403038705,"mc":[{"id":"1.170370562","rc":[{"atb":[[1.71,0]],"id":9625043},{"atb":[[1.59,0]],"id":9631798}],"con":true,"img":false}]}
{"op":"mcm","clk":"1349671634","pt":1588403038805,"mc":[{"id":"1.170370562","rc":[{"atb":[[1.78,59.99]],"id":9625043},{"atb":[[1.65,68.78]],"id":9631798}],"con":true,"img":false}]}
{"op":"mcm","clk":"1349671877","pt":1588403045264,"mc":[{"id":"1.170370562","rc":[{"atb":[[1.78,0]],"id":9625043},{"atb":[[1.65,0]],"id":9631798}],"con":true,"img":false}]}
{"op":"mcm","clk":"1349671883","pt":1588403045367,"mc":[{"id":"1.170370562","rc":[{"atb":[[1.71,59.99]],"id":9625043},{"atb":[[1.59,68.78]],"id":9631798}],"con":true,"img":false}]}
{"op":"mcm","clk":"1349672073","pt":1588403051484,"mc":[{"id":"1.170370562","rc":[{"atb":[[1.71,0]],"id":9625043},{"atb":[[1.59,0]],"id":9631798}],"con":true,"img":false}]}
{"op":"mcm","clk":"1349672077","pt":1588403051535,"mc":[{"id":"1.170370562","rc":[{"atb":[[1.78,59.99]],"id":9625043},{"atb":[[1.65,68.78]],"id":9631798}],"con":true,"img":false}]}
{"op":"mcm","clk":"1349672292","pt":1588403058161,"mc":[{"id":"1.170370562","rc":[{"atb":[[1.78,0]],"id":9625043},{"atb":[[1.65,0]],"id":9631798}],"con":true,"img":false}]}
{"op":"mcm","clk":"1349672297","pt":1588403058264,"mc":[{"id":"1.170370562","rc":[{"atb":[[1.71,59.99]],"id":9625043},{"atb":[[1.59,68.78]],"id":9631798}],"con":true,"img":false}]}
{"op":"mcm","clk":"1349672534","pt":1588403064079,"mc":[{"id":"1.170370562","rc":[{"atb":[[1.71,0]],"id":9625043},{"atb":[[1.59,0]],"id":9631798}],"con":true,"img":false}]}
{"op":"mcm","clk":"1349672537","pt":1588403064184,"mc":[{"id":"1.170370562","rc":[{"atb":[[1.78,59.99]],"id":9625043},{"atb":[[1.65,68.78]],"id":9631798}],"con":true,"img":false}]}
{"op":"mcm","clk":"1349672848","pt":1588403073179,"mc":[{"id":"1.170370562","rc":[{"atb":[[1.78,0]],"id":9625043},{"atb":[[1.65,0]],"id":9631798}],"con":true,"img":false}]}
{"op":"mcm","clk":"1349672851","pt":1588403073283,"mc":[{"id":"1.170370562","rc":[{"atb":[[1.71,59.99]],"id":9625043},{"atb":[[1.59,68.78]],"id":9631798}],"con":true,"img":false}]}
{"op":"mcm","clk":"1349673063","pt":1588403079216,"mc":[{"id":"1.170370562","rc":[{"atb":[[1.71,0]],"id":9625043},{"atb":[[1.59,0]],"id":9631798}],"con":true,"img":false}]}
{"op":"mcm","clk":"1349673066","pt":1588403079319,"mc":[{"id":"1.170370562","rc":[{"atb":[[1.78,59.99]],"id":9625043},{"atb":[[1.65,68.78]],"id":9631798}],"con":true,"img":false}]}
{"op":"mcm","clk":"1349673278","pt":1588403085288,"mc":[{"id":"1.170370562","rc":[{"atb":[[1.78,0]],"id":9625043},{"atb":[[1.65,0]],"id":9631798}],"con":true,"img":false}]}
{"op":"mcm","clk":"1349673282","pt":1588403085391,"mc":[{"id":"1.170370562","rc":[{"atb":[[1.71,59.99]],"id":9625043},{"atb":[[1.59,68.78]],"id":9631798}],"con":true,"img":false}]}
{"op":"mcm","clk":"1349673509","pt":1588403091321,"mc":[{"id":"1.170370562","rc":[{"atb":[[1.71,0]],"id":9625043},{"atb":[[1.59,0]],"id":9631798}],"con":true,"img":false}]}
{"op":"mcm","clk":"1349673511","pt":1588403091424,"mc":[{"id":"1.170370562","rc":[{"atb":[[1.78,59.99]],"id":9625043},{"atb":[[1.65,68.78]],"id":9631798}],"con":true,"img":false}]}
{"op":"mcm","clk":"1349673734","pt":1588403097452,"mc":[{"id":"1.170370562","rc":[{"atb":[[1.78,0]],"id":9625043},{"atb":[[1.65,0]],"id":9631798}],"con":true,"img":false}]}
{"op":"mcm","clk":"1349673740","pt":1588403097555,"mc":[{"id":"1.170370562","rc":[{"atb":[[1.71,59.99]],"id":9625043},{"atb":[[1.59,68.78]],"id":9631798}],"con":true,"img":false}]}
{"op":"mcm","clk":"1349673949","pt":1588403103459,"mc":[{"id":"1.170370562","rc":[{"atb":[[1.71,0]],"id":9625043},{"atb":[[1.59,0]],"id":9631798}],"con":true,"img":false}]}
{"op":"mcm","clk":"1349673955","pt":1588403103565,"mc":[{"id":"1.170370562","rc":[{"atb":[[1.78,59.99]],"id":9625043},{"atb":[[1.65,68.78]],"id":9631798}],"con":true,"img":false}]}
{"op":"mcm","clk":"1349674201","pt":1588403109550,"mc":[{"id":"1.170370562","rc":[{"atb":[[1.78,0]],"id":9625043},{"atb":[[1.65,0]],"id":9631798}],"con":true,"img":false}]}
{"op":"mcm","clk":"1349674205","pt":1588403109652,"mc":[{"id":"1.170370562","rc":[{"atb":[[1.71,59.99]],"id":9625043},{"atb":[[1.59,68.78]],"id":9631798}],"con":true,"img":false}]}
{"op":"mcm","clk":"1349674400","pt":1588403115486,"mc":[{"id":"1.170370562","rc":[{"atb":[[1.71,0]],"id":9625043},{"atb":[[1.59,0]],"id":9631798}],"con":true,"img":false}]}
{"op":"mcm","clk":"1349674404","pt":1588403115589,"mc":[{"id":"1.170370562","rc":[{"atb":[[1.78,59.99]],"id":9625043},{"atb":[[1.65,68.78]],"id":9631798}],"con":true,"img":false}]}
{"op":"mcm","clk":"1349674656","pt":1588403121676,"mc":[{"id":"1.170370562","rc":[{"atb":[[1.78,0]],"id":9625043},{"atb":[[1.65,0]],"id":9631798}],"con":true,"img":false}]}
{"op":"mcm","clk":"1349674661","pt":1588403121780,"mc":[{"id":"1.170370562","rc":[{"atb":[[1.71,59.99]],"id":9625043},{"atb":[[1.59,68.78]],"id":9631798}],"con":true,"img":false}]}
{"op":"mcm","clk":"1349674862","pt":1588403127402,"mc":[{"id":"1.170370562","rc":[{"atb":[[1.71,0]],"id":9625043},{"atb":[[1.59,0]],"id":9631798}],"con":true,"img":false}]}
{"op":"mcm","clk":"1349674864","pt":1588403127453,"mc":[{"id":"1.170370562","rc":[{"atb":[[1.78,59.99]],"id":9625043},{"atb":[[1.65,68.78]],"id":9631798}],"con":true,"img":false}]}
{"op":"mcm","clk":"1349675055","pt":1588403133068,"mc":[{"id":"1.170370562","rc":[{"atb":[[1.78,0]],"id":9625043},{"atb":[[1.65,0]],"id":9631798}],"con":true,"img":false}]}
{"op":"mcm","clk":"1349675059","pt":1588403133171,"mc":[{"id":"1.170370562","rc":[{"atb":[[1.71,59.99]],"id":9625043},{"atb":[[1.59,68.78]],"id":9631798}],"con":true,"img":false}]}
{"op":"mcm","clk":"1349675256","pt":1588403139082,"mc":[{"id":"1.170370562","rc":[{"atb":[[1.71,0]],"id":9625043},{"atb":[[1.59,0]],"id":9631798}],"con":true,"img":false}]}
{"op":"mcm","clk":"1349675260","pt":1588403139185,"mc":[{"id":"1.170370562","rc":[{"atb":[[1.78,59.99]],"id":9625043},{"atb":[[1.65,68.78]],"id":9631798}],"con":true,"img":false}]}
{"op":"mcm","clk":"1349675454","pt":1588403145516,"mc":[{"id":"1.170370562","rc":[{"atb":[[1.78,0]],"id":9625043},{"atb":[[1.65,0]],"id":9631798}],"con":true,"img":false}]}
{"op":"mcm","clk":"1349675460","pt":1588403145619,"mc":[{"id":"1.170370562","rc":[{"atb":[[1.71,59.99]],"id":9625043},{"atb":[[1.59,68.78]],"id":9631798}],"con":true,"img":false}]}
{"op":"mcm","clk":"1349675664","pt":1588403151705,"mc":[{"id":"1.170370562","rc":[{"atb":[[1.71,0]],"id":9625043},{"atb":[[1.59,0]],"id":9631798}],"con":true,"img":false}]}
{"op":"mcm","clk":"1349675668","pt":1588403151808,"mc":[{"id":"1.170370562","rc":[{"atb":[[1.78,59.99]],"id":9625043},{"atb":[[1.65,68.78]],"id":9631798}],"con":true,"img":false}]}
{"op":"mcm","clk":"1349675850","pt":1588403157643,"mc":[{"id":"1.170370562","rc":[{"atb":[[1.78,0]],"id":9625043},{"atb":[[1.65,0]],"id":9631798}],"con":true,"img":false}]}
{"op":"mcm","clk":"1349675855","pt":1588403157743,"mc":[{"id":"1.170370562","rc":[{"atb":[[1.71,59.99]],"id":9625043},{"atb":[[1.59,68.78]],"id":9631798}],"con":true,"img":false}]}
{"op":"mcm","clk":"1349676027","pt":1588403163530,"mc":[{"id":"1.170370562","rc":[{"atb":[[1.71,0]],"id":9625043},{"atb":[[1.59,0]],"id":9631798}],"con":true,"img":false}]}
{"op":"mcm","clk":"1349676031","pt":1588403163633,"mc":[{"id":"1.170370562","rc":[{"atb":[[1.78,59.99]],"id":9625043},{"atb":[[1.65,68.78]],"id":9631798}],"con":true,"img":false}]}
{"op":"mcm","clk":"1349676211","pt":1588403169265,"mc":[{"id":"1.170370562","rc":[{"atb":[[1.78,0]],"id":9625043},{"atb":[[1.65,0]],"id":9631798}],"con":true,"img":false}]}
{"op":"mcm","clk":"1349676216","pt":1588403169369,"mc":[{"id":"1.170370562","rc":[{"atb":[[1.71,59.99]],"id":9625043},{"atb":[[1.59,68.78]],"id":9631798}],"con":true,"img":false}]}
{"op":"mcm","clk":"1349676429","pt":1588403175360,"mc":[{"id":"1.170370562","rc":[{"atb":[[1.71,0]],"id":9625043},{"atb":[[1.59,0]],"id":9631798}],"con":true,"img":false}]}
{"op":"mcm","clk":"1349676432","pt":1588403175464,"mc":[{"id":"1.170370562","rc":[{"atb":[[1.78,59.99]],"id":9625043},{"atb":[[1.65,68.78]],"id":9631798}],"con":true,"img":false}]}
{"op":"mcm","clk":"1349676668","pt":1588403181182,"mc":[{"id":"1.170370562","rc":[{"atb":[[1.78,0]],"id":9625043},{"atb":[[1.65,0]],"id":9631798}],"con":true,"img":false}]}
{"op":"mcm","clk":"1349676672","pt":1588403181284,"mc":[{"id":"1.170370562","rc":[{"atb":[[1.71,59.99]],"id":9625043},{"atb":[[1.59,68.78]],"id":9631798}],"con":true,"img":false}]}
{"op":"mcm","clk":"1349676881","pt":1588403186956,"mc":[{"id":"1.170370562","rc":[{"atb":[[1.71,0]],"id":9625043},{"atb":[[1.59,0]],"id":9631798}],"con":true,"img":false}]}
{"op":"mcm","clk":"1349676885","pt":1588403187060,"mc":[{"id":"1.170370562","rc":[{"atb":[[1.78,59.99]],"id":9625043},{"atb":[[1.65,68.78]],"id":9631798}],"con":true,"img":false}]}
{"op":"mcm","clk":"1349677082","pt":1588403192885,"mc":[{"id":"1.170370562","rc":[{"atb":[[1.78,0]],"id":9625043},{"atb":[[1.65,0]],"id":9631798}],"con":true,"img":false}]}
{"op":"mcm","clk":"1349677089","pt":1588403192988,"mc":[{"id":"1.170370562","rc":[{"atb":[[1.71,59.99]],"id":9625043},{"atb":[[1.59,68.78]],"id":9631798}],"con":true,"img":false}]}
{"op":"mcm","clk":"1349677295","pt":1588403198678,"mc":[{"id":"1.170370562","rc":[{"atb":[[1.71,0]],"id":9625043},{"atb":[[1.59,0]],"id":9631798}],"con":true,"img":false}]}
{"op":"mcm","clk":"1349677300","pt":1588403198781,"mc":[{"id":"1.170370562","rc":[{"atb":[[1.78,59.99]],"id":9625043},{"atb":[[1.65,68.78]],"id":9631798}],"con":true,"img":false}]}
{"op":"mcm","clk":"1349677510","pt":1588403205427,"mc":[{"id":"1.170370562","rc":[{"atb":[[1.78,0]],"id":9625043},{"atb":[[1.65,0]],"id":9631798}],"con":true,"img":false}]}
{"op":"mcm","clk":"1349677514","pt":1588403205478,"mc":[{"id":"1.170370562","rc":[{"atb":[[1.71,59.99]],"id":9625043},{"atb":[[1.59,68.78]],"id":9631798}],"con":true,"img":false}]}
{"op":"mcm","clk":"1349677730","pt":1588403211409,"mc":[{"id":"1.170370562","rc":[{"atb":[[1.71,0]],"id":9625043},{"atb":[[1.59,0]],"id":9631798}],"con":true,"img":false}]}
{"op":"mcm","clk":"1349677737","pt":1588403211516,"mc":[{"id":"1.170370562","rc":[{"atb":[[1.78,59.99]],"id":9625043},{"atb":[[1.65,68.78]],"id":9631798}],"con":true,"img":false}]}
{"op":"mcm","clk":"1349677927","pt":1588403217315,"mc":[{"id":"1.170370562","rc":[{"atb":[[1.78,0]],"id":9625043},{"atb":[[1.65,0]],"id":9631798}],"con":true,"img":false}]}
{"op":"mcm","clk":"1349677932","pt":1588403217416,"mc":[{"id":"1.170370562","rc":[{"atb":[[1.71,59.99]],"id":9625043},{"atb":[[1.59,68.78]],"id":9631798}],"con":true,"img":false}]}
{"op":"mcm","clk":"1349678184","pt":1588403224919,"mc":[{"id":"1.170370562","rc":[{"atb":[[1.71,0]],"id":9625043},{"atb":[[1.59,0]],"id":9631798}],"con":true,"img":false}]}
{"op":"mcm","clk":"1349678189","pt":1588403225042,"mc":[{"id":"1.170370562","rc":[{"atb":[[1.78,59.99]],"id":9625043},{"atb":[[1.65,68.78]],"id":9631798}],"con":true,"img":false}]}
{"op":"mcm","clk":"1349678390","pt":1588403230970,"mc":[{"id":"1.170370562","rc":[{"atb":[[1.78,0]],"id":9625043},{"atb":[[1.65,0]],"id":9631798}],"con":true,"img":false}]}
{"op":"mcm","clk":"1349678394","pt":1588403231026,"mc":[{"id":"1.170370562","rc":[{"atb":[[1.71,59.99]],"id":9625043},{"atb":[[1.59,68.78]],"id":9631798}],"con":true,"img":false}]}
{"op":"mcm","clk":"1349678606","pt":1588403237278,"mc":[{"id":"1.170370562","rc":[{"atb":[[1.71,0]],"id":9625043},{"atb":[[1.59,0]],"id":9631798}],"con":true,"img":false}]}
{"op":"mcm","clk":"1349678610","pt":1588403237379,"mc":[{"id":"1.170370562","rc":[{"atb":[[1.78,59.99]],"id":9625043},{"atb":[[1.65,68.78]],"id":9631798}],"con":true,"img":false}]}
{"op":"mcm","clk":"1349678832","pt":1588403243068,"mc":[{"id":"1.170370562","rc":[{"atb":[[1.78,0]],"id":9625043},{"atb":[[1.65,0]],"id":9631798}],"con":true,"img":false}]}
{"op":"mcm","clk":"1349678836","pt":1588403243172,"mc":[{"id":"1.170370562","rc":[{"atb":[[1.71,59.99]],"id":9625043},{"atb":[[1.59,68.78]],"id":9631798}],"con":true,"img":false}]}
{"op":"mcm","clk":"1349679058","pt":1588403248982,"mc":[{"id":"1.170370562","rc":[{"atb":[[1.71,0]],"id":9625043},{"atb":[[1.59,0]],"id":9631798}],"con":true,"img":false}]}
{"op":"mcm","clk":"1349679065","pt":1588403249085,"mc":[{"id":"1.170370562","rc":[{"atb":[[1.78,59.99]],"id":9625043},{"atb":[[1.65,68.78]],"id":9631798}],"con":true,"img":false}]}
{"op":"mcm","clk":"1349679272","pt":1588403255017,"mc":[{"id":"1.170370562","rc":[{"atb":[[1.78,0]],"id":9625043},{"atb":[[1.65,0]],"id":9631798}],"con":true,"img":false}]}
{"op":"mcm","clk":"1349679277","pt":1588403255098,"mc":[{"id":"1.170370562","rc":[{"atb":[[1.71,59.99]],"id":9625043},{"atb":[[1.59,68.78]],"id":9631798}],"con":true,"img":false}]}
{"op":"mcm","clk":"1349679494","pt":1588403260909,"mc":[{"id":"1.170370562","rc":[{"atb":[[1.71,0]],"id":9625043},{"atb":[[1.59,0]],"id":9631798}],"con":true,"img":false}]}
{"op":"mcm","clk":"1349679497","pt":1588403261010,"mc":[{"id":"1.170370562","rc":[{"atb":[[1.78,59.99]],"id":9625043},{"atb":[[1.65,68.78]],"id":9631798}],"con":true,"img":false}]}
{"op":"mcm","clk":"1349679708","pt":1588403266993,"mc":[{"id":"1.170370562","rc":[{"atb":[[1.78,0]],"id":9625043},{"atb":[[1.65,0]],"id":9631798}],"con":true,"img":false}]}
{"op":"mcm","clk":"1349679712","pt":1588403267096,"mc":[{"id":"1.170370562","rc":[{"atb":[[1.71,59.99]],"id":9625043},{"atb":[[1.59,68.78]],"id":9631798}],"con":true,"img":false}]}
{"op":"mcm","clk":"1349679965","pt":1588403274623,"mc":[{"id":"1.170370562","rc":[{"atb":[[1.71,0]],"id":9625043},{"atb":[[1.59,0]],"id":9631798}],"con":true,"img":false}]}
{"op":"mcm","clk":"1349679969","pt":1588403274723,"mc":[{"id":"1.170370562","rc":[{"atb":[[1.78,59.99]],"id":9625043},{"atb":[[1.65,68.78]],"id":9631798}],"con":true,"img":false}]}
{"op":"mcm","clk":"1349680169","pt":1588403280646,"mc":[{"id":"1.170370562","rc":[{"atb":[[1.78,0]],"id":9625043},{"atb":[[1.65,0]],"id":9631798}],"con":true,"img":false}]}
{"op":"mcm","clk":"1349680173","pt":1588403280717,"mc":[{"id":"1.170370562","rc":[{"atb":[[1.71,59.99]],"id":9625043},{"atb":[[1.59,68.78]],"id":9631798}],"con":true,"img":false}]}
{"op":"mcm","clk":"1349680373","pt":1588403286643,"mc":[{"id":"1.170370562","rc":[{"atb":[[1.71,0]],"id":9625043},{"atb":[[1.59,0]],"id":9631798}],"con":true,"img":false}]}
{"op":"mcm","clk":"1349680376","pt":1588403286746,"mc":[{"id":"1.170370562","rc":[{"atb":[[1.78,59.99]],"id":9625043},{"atb":[[1.65,68.78]],"id":9631798}],"con":true,"img":false}]}
{"op":"mcm","clk":"1349680563","pt":1588403292550,"mc":[{"id":"1.170370562","rc":[{"atb":[[1.78,0]],"id":9625043},{"atb":[[1.65,0]],"id":9631798}],"con":true,"img":false}]}
{"op":"mcm","clk":"1349680568","pt":1588403292652,"mc":[{"id":"1.170370562","rc":[{"atb":[[1.71,59.99]],"id":9625043},{"atb":[[1.59,68.78]],"id":9631798}],"con":true,"img":false}]}
{"op":"mcm","clk":"1349688985","pt":1588403504517,"mc":[{"id":"1.170370562","rc":[{"atl":[[1.81,20]],"id":9631798}],"con":true,"img":false}]}
{"op":"mcm","clk":"1349689121","pt":1588403508504,"mc":[{"id":"1.170370562","rc":[{"atl":[[1.81,0]],"id":9631798}],"con":true,"img":false}]}
{"op":"mcm","clk":"1349689124","pt":1588403508607,"mc":[{"id":"1.170370562","rc":[{"atl":[[1.82,20]],"id":9631798}],"con":true,"img":false}]}
{"op":"mcm","clk":"1349689492","pt":1588403518974,"mc":[{"id":"1.170370562","rc":[{"atl":[[1.82,0]],"id":9631798}],"con":true,"img":false}]}
{"op":"mcm","clk":"1349689495","pt":1588403519026,"mc":[{"id":"1.170370562","rc":[{"trd":[[1.8,40]],"ltp":1.8,"tv":40.0,"id":9631798},{"atb":[[1.8,69.77]],"id":9631798}],"con":true,"img":false}]}
{"op":"mcm","clk":"1349747034","pt":1588405610217,"mc":[{"id":"1.170370562","rc":[{"atb":[[2,141.89]],"id":9625043}],"con":true,"img":false}]}
{"op":"mcm","clk":"1349752532","pt":1588405813226,"mc":[{"id":"1.170370562","rc":[{"atl":[[2.18,1.77]],"id":9625043}],"con":true,"img":false}]}
{"op":"mcm","clk":"1349764903","pt":1588406264645,"mc":[{"id":"1.170370562","rc":[{"atb":[[2,59.67]],"id":9625043}],"con":true,"img":false}]}
{"op":"mcm","clk":"1349764908","pt":1588406264750,"mc":[{"id":"1.170370562","rc":[{"atb":[[2.04,84.12]],"id":9625043}],"con":true,"img":false}]}
{"op":"mcm","clk":"1349768709","pt":1588406401665,"mc":[{"id":"1.170370562","rc":[{"atb":[[2.04,109.69]],"id":9625043},{"atb":[[1.8,103.02]],"id":9631798}],"con":true,"img":false}]}
{"op":"mcm","clk":"1349768798","pt":1588406403999,"mc":[{"id":"1.170370562","rc":[{"atb":[[1.71,0]],"id":9625043},{"atb":[[1.59,0]],"id":9631798}],"con":true,"img":false}]}
{"op":"mcm","clk":"1349770057","pt":1588406438395,"mc":[{"id":"1.170370562","rc":[{"trd":[[2.18,1.49]],"ltp":2.18,"tv":1.49,"id":9625043},{"atl":[[2.18,0.27]],"id":9625043},{"trd":[[1.84,1.77]],"ltp":1.84,"tv":1.77,"id":9631798}],"con":true,"img":false}]}
{"op":"mcm","clk":"1349770420","pt":1588406450725,"mc":[{"id":"1.170370562","rc":[{"trd":[[2.18,1.77]],"ltp":2.18,"tv":1.77,"id":9625043},{"atl":[[2.18,0]],"id":9625043},{"trd":[[1.8,245.01],[1.84,2.1]],"ltp":1.8,"tv":247.1,"id":9631798},{"atb":[[1.8,0.51]],"id":9631798}],"con":true,"img":false}]}
{"op":"mcm","clk":"1349770450","pt":1588406451755,"mc":[{"id":"1.170370562","rc":[{"atb":[[1.73,118.17]],"id":9631798}],"con":true,"img":false}]}
{"op":"mcm","clk":"1349770454","pt":1588406451858,"mc":[{"id":"1.170370562","rc":[{"atb":[[1.8,0]],"id":9631798}],"con":true,"img":false}]}
{"op":"mcm","clk":"1349773045","pt":1588406531048,"mc":[{"id":"1.170370562","rc":[{"atb":[[2.1,1.84]],"id":9625043}],"con":true,"img":false}]}
{"op":"mcm","clk":"1349773058","pt":1588406531307,"mc":[{"id":"1.170370562","rc":[{"atb":[[2.04,25.57]],"id":9625043}],"con":true,"img":false}]}
{"op":"mcm","clk":"1349773061","pt":1588406531408,"mc":[{"id":"1.170370562","rc":[{"atb":[[2.1,83.38]],"id":9625043}],"con":true,"img":false}]}
{"op":"mcm","clk":"1349773105","pt":1588406532846,"mc":[{"id":"1.170370562","rc":[{"atb":[[2.1,107.55]],"id":9625043}],"con":true,"img":false}]}
{"op":"mcm","clk":"1349778420","pt":1588406680827,"mc":[{"id":"1.170370562","rc":[{"atb":[[2.1,26.01]],"id":9625043}],"con":true,"img":false}]}
{"op":"mcm","clk":"1349778454","pt":1588406681809,"mc":[{"id":"1.170370562","rc":[{"atb":[[2,86.26]],"id":9625043}],"con":true,"img":false}]}
{"op":"mcm","clk":"1349778458","pt":1588406681912,"mc":[{"id":"1.170370562","rc":[{"atb":[[2.04,0],[2.1,1.84]],"id":9625043}],"con":true,"img":false}]}
{"op":"mcm","clk":"1349778607","pt":1588406686631,"mc":[{"id":"1.170370562","rc":[{"atb":[[1.65,39.99]],"id":9631798}],"con":true,"img":false}]}
{"op":"mcm","clk":"1349778614","pt":1588406686837,"mc":[{"id":"1.170370562","rc":[{"atb":[[2,126.25]],"id":9625043}],"con":true,"img":false}]}
{"op":"mcm","clk":"1349779176","pt":1588406704350,"mc":[{"id":"1.170370562","rc":[{"atb":[[2,86.26]],"id":9625043},{"atb":[[1.65,0]],"id":9631798}],"con":true,"img":false}]}
{"op":"mcm","clk":"1349779238","pt":1588406706270,"mc":[{"id":"1.170370562","rc":[{"atb":[[1.65,39.99]],"id":9631798}],"con":true,"img":false}]}
{"op":"mcm","clk":"1349779245","pt":1588406706475,"mc":[{"id":"1.170370562","rc":[{"atb":[[2,126.25]],"id":9625043}],"con":true,"img":false}]}
{"op":"mcm","clk":"1349781032","pt":1588406765074,"mc":[{"id":"1.170370562","rc":[{"atb":[[2,86.26]],"id":9625043},{"atb":[[1.65,0]],"id":9631798}],"con":true,"img":false}]}
{"op":"mcm","clk":"1349781111","pt":1588406767962,"mc":[{"id":"1.170370562","rc":[{"atb":[[1.65,39.99]],"id":9631798}],"con":true,"img":false}]}
{"op":"mcm","clk":"1349781117","pt":1588406768171,"mc":[{"id":"1.170370562","rc":[{"atb":[[2,126.25]],"id":9625043}],"con":true,"img":false}]}
{"op":"mcm","clk":"1349782855","pt":1588406825613,"mc":[{"id":"1.170370562","rc":[{"atb":[[2,86.26]],"id":9625043},{"atb":[[1.65,0]],"id":9631798}],"con":true,"img":false}]}
{"op":"mcm","clk":"1349782939","pt":1588406828405,"mc":[{"id":"1.170370562","rc":[{"atb":[[1.65,39.99]],"id":9631798}],"con":true,"img":false}]}
{"op":"mcm","clk":"1349782946","pt":1588406828611,"mc":[{"id":"1.170370562","rc":[{"atb":[[2,126.25]],"id":9625043}],"con":true,"img":false}]}
{"op":"mcm","clk":"1349784419","pt":1588406886274,"mc":[{"id":"1.170370562","rc":[{"atb":[[2,86.26]],"id":9625043},{"atb":[[1.65,0]],"id":9631798}],"con":true,"img":false}]}
{"op":"mcm","clk":"1349784427","pt":1588406886637,"mc":[{"id":"1.170370562","rc":[{"atb":[[1.65,39.99]],"id":9631798}],"con":true,"img":false}]}
{"op":"mcm","clk":"1349784433","pt":1588406886843,"mc":[{"id":"1.170370562","rc":[{"atb":[[2,126.25]],"id":9625043}],"con":true,"img":false}]}
{"op":"mcm","clk":"1349785920","pt":1588406946845,"mc":[{"id":"1.170370562","rc":[{"atb":[[2,86.26]],"id":9625043},{"atb":[[1.65,0]],"id":9631798}],"con":true,"img":false}]}
{"op":"mcm","clk":"1349785995","pt":1588406949436,"mc":[{"id":"1.170370562","rc":[{"atb":[[1.65,39.99]],"id":9631798}],"con":true,"img":false}]}
{"op":"mcm","clk":"1349786000","pt":1588406949642,"mc":[{"id":"1.170370562","rc":[{"atb":[[2,126.25]],"id":9625043}],"con":true,"img":false}]}
{"op":"mcm","clk":"1349787453","pt":1588406967136,"mc":[{"id":"1.170370562","rc":[{"trd":[[1.73,141.84]],"ltp":1.73,"tv":141.84,"id":9631798},{"atb":[[1.73,47.25]],"id":9631798}],"con":true,"img":false}]}
{"op":"mcm","clk":"1349787473","pt":1588406967966,"mc":[{"id":"1.170370562","rc":[{"atb":[[2,99.66]],"id":9625043},{"atb":[[1.73,10.81]],"id":9631798}],"con":true,"img":false}]}
{"op":"mcm","clk":"1349787492","pt":1588406968845,"mc":[{"id":"1.170370562","rc":[{"atb":[[1.73,0],[1.65,131.79]],"id":9631798}],"con":true,"img":false}]}
{"op":"mcm","clk":"1349787498","pt":1588406969052,"mc":[{"id":"1.170370562","rc":[{"atb":[[1.66,118.49]],"id":9631798}],"con":true,"img":false}]}
{"op":"mcm","clk":"1349787751","pt":1588406979474,"mc":[{"id":"1.170370562","rc":[{"atb":[[1.41,234.1]],"id":9631798}],"con":true,"img":false}]}
{"op":"mcm","clk":"1349787859","pt":1588406983280,"mc":[{"id":"1.170370562","rc":[{"atb":[[1.71,22.53]],"id":9625043}],"con":true,"img":false}]}
{"op":"mcm","clk":"1349787862","pt":1588406983383,"mc":[{"id":"1.170370562","rc":[{"atb":[[1.71,45.06]],"id":9625043}],"con":true,"img":false}]}
{"op":"mcm","clk":"1349788474","pt":1588407007413,"mc":[{"id":"1.170370562","rc":[{"atb":[[2,59.67]],"id":9625043},{"atb":[[1.65,91.8]],"id":9631798}],"con":true,"img":false}]}
{"op":"mcm","clk":"1349788538","pt":1588407010093,"mc":[{"id":"1.170370562","rc":[{"atb":[[1.65,131.79]],"id":9631798}],"con":true,"img":false}]}
{"op":"mcm","clk":"1349788545","pt":1588407010298,"mc":[{"id":"1.170370562","rc":[{"atb":[[2,99.66]],"id":9625043}],"con":true,"img":false}]}
{"op":"mcm","clk":"1349789049","pt":1588407030205,"mc":[{"id":"1.170370562","rc":[{"atb":[[1.7,37.59]],"id":9631798}],"con":true,"img":false}]}
{"op":"mcm","clk":"1349789055","pt":1588407030414,"mc":[{"id":"1.170370562","rc":[{"atb":[[1.66,0]],"id":9631798}],"con":true,"img":false}]}
{"op":"mcm","clk":"1349789071","pt":1588407030929,"mc":[{"id":"1.170370562","rc":[{"atb":[[2,126.25]],"id":9625043},{"atb":[[1.7,75.59]],"id":9631798}],"con":true,"img":false}]}
{"op":"mcm","clk":"1349789945","pt":1588407068056,"mc":[{"id":"1.170370562","rc":[{"atb":[[2,86.26]],"id":9625043},{"atb":[[1.65,91.8]],"id":9631798}],"con":true,"img":false}]}
{"op":"mcm","clk":"1349789998","pt":1588407070537,"mc":[{"id":"1.170370562","rc":[{"atb":[[1.65,131.79]],"id":9631798}],"con":true,"img":false}]}
{"op":"mcm","clk":"1349790007","pt":1588407070744,"mc":[{"id":"1.170370562","rc":[{"atb":[[2,126.25]],"id":9625043}],"con":true,"img":false}]}
{"op":"mcm","clk":"1349791560","pt":1588407128742,"mc":[{"id":"1.170370562","rc":[{"atb":[[2,86.26]],"id":9625043},{"atb":[[1.65,91.8]],"id":9631798}],"con":true,"img":false}]}
{"op":"mcm","clk":"1349791674","pt":1588407132507,"mc":[{"id":"1.170370562","rc":[{"atb":[[1.65,131.79]],"id":9631798}],"con":true,"img":false}]}
{"op":"mcm","clk":"1349791680","pt":1588407132714,"mc":[{"id":"1.170370562","rc":[{"atb":[[2,126.25]],"id":9625043}],"con":true,"img":false}]}
{"op":"mcm","clk":"1349793286","pt":1588407189406,"mc":[{"id":"1.170370562","rc":[{"atb":[[2,86.26]],"id":9625043},{"atb":[[1.65,91.8]],"id":9631798}],"con":true,"img":false}]}
{"op":"mcm","clk":"1349793409","pt":1588407194705,"mc":[{"id":"1.170370562","rc":[{"atb":[[1.65,131.79]],"id":9631798}],"con":true,"img":false}]}
{"op":"mcm","clk":"1349793414","pt":1588407194912,"mc":[{"id":"1.170370562","rc":[{"atb":[[2,126.25]],"id":9625043}],"con":true,"img":false}]}
{"op":"mcm","clk":"1349794947","pt":1588407249990,"mc":[{"id":"1.170370562","rc":[{"atb":[[2,86.26]],"id":9625043},{"atb":[[1.65,91.8]],"id":9631798}],"con":true,"img":false}]}
{"op":"mcm","clk":"1349795026","pt":1588407253498,"mc":[{"id":"1.170370562","rc":[{"atb":[[1.65,131.79]],"id":9631798}],"con":true,"img":false}]}
{"op":"mcm","clk":"1349795031","pt":1588407253706,"mc":[{"id":"1.170370562","rc":[{"atb":[[2,126.25]],"id":9625043}],"con":true,"img":false}]}
{"op":"mcm","clk":"1349796465","pt":1588407310631,"mc":[{"id":"1.170370562","rc":[{"atb":[[2,86.26]],"id":9625043},{"atb":[[1.65,91.8]],"id":9631798}],"con":true,"img":false}]}
{"op":"mcm","clk":"1349796559","pt":1588407314141,"mc":[{"id":"1.170370562","rc":[{"atb":[[1.65,131.79]],"id":9631798}],"con":true,"img":false}]}
{"op":"mcm","clk":"1349796564","pt":1588407314349,"mc":[{"id":"1.170370562","rc":[{"atb":[[2,126.25]],"id":9625043}],"con":true,"img":false}]}
{"op":"mcm","clk":"1349797719","pt":1588407354567,"mc":[{"id":"1.170370562","rc":[{"atb":[[1.01,6.79]],"id":9625043},{"atl":[[1000,2]],"id":9625043},{"atl":[[1000,2]],"id":9631798}],"con":true,"img":false}]}
{"op":"mcm","clk":"1349797726","pt":1588407354773,"mc":[{"id":"1.170370562","rc":[{"atb":[[1.01,6.77]],"id":9625043}],"con":true,"img":false}]}
{"op":"mcm","clk":"1349797730","pt":1588407354877,"mc":[{"id":"1.170370562","rc":[{"atl":[[1000,0.22]],"id":9625043},{"atl":[[1000,1.79]],"id":9631798}],"con":true,"img":false}]}
{"op":"mcm","clk":"1349797737","pt":1588407355081,"mc":[{"id":"1.170370562","rc":[{"atb":[[1.01,4.79]],"id":9625043}],"con":true,"img":false}]}
{"op":"mcm","clk":"1349797740","pt":1588407355189,"mc":[{"id":"1.170370562","rc":[{"atb":[[1.66,1.98]],"id":9625043},{"atl":[[1000,0]],"id":9625043},{"atl":[[1000,0]],"id":9631798}],"con":true,"img":false}]}
{"op":"mcm","clk":"1349797745","pt":1588407355293,"mc":[{"id":"1.170370562","rc":[{"atl":[[2.44,0.22]],"id":9625043},{"atl":[[3.1,1.79]],"id":9631798}],"con":true,"img":false}]}
{"op":"mcm","clk":"1349797749","pt":1588407355388,"mc":[{"id":"1.170370562","rc":[{"atb":[[1.42,2.58]],"id":9631798}],"con":true,"img":false}]}
{"op":"mcm","clk":"1349798195","pt":1588407371287,"mc":[{"id":"1.170370562","rc":[{"atb":[[2,86.26]],"id":9625043},{"atb":[[1.65,91.8]],"id":9631798}],"con":true,"img":false}]}
{"op":"mcm","clk":"1349798263","pt":1588407373807,"mc":[{"id":"1.170370562","rc":[{"atb":[[1.65,131.79]],"id":9631798}],"con":true,"img":false}]}
{"op":"mcm","clk":"1349798269","pt":1588407374012,"mc":[{"id":"1.170370562","rc":[{"atb":[[2,126.25]],"id":9625043}],"con":true,"img":false}]}
{"op":"mcm","clk":"1349799830","pt":1588407431938,"mc":[{"id":"1.170370562","rc":[{"atb":[[2,86.26]],"id":9625043},{"atb":[[1.65,91.8]],"id":9631798}],"con":true,"img":false}]}
{"op":"mcm","clk":"1349802626","pt":1588407539163,"mc":[{"id":"1.170370562","rc":[{"atb":[[1.7,37.99]],"id":9631798}],"con":true,"img":false}]}
{"op":"mcm","clk":"1349802668","pt":1588407540142,"mc":[{"id":"1.170370562","rc":[{"atb":[[2,59.67]],"id":9625043},{"atb":[[1.7,0]],"id":9631798}],"con":true,"img":false}]}
{"op":"mcm","clk":"1349802675","pt":1588407540348,"mc":[{"id":"1.170370562","rc":[{"atb":[[1.66,118.49]],"id":9631798}],"con":true,"img":false}]}
{"op":"mcm","clk":"1349816690","pt":1588407995964,"mc":[{"id":"1.170370562","rc":[{"atb":[[1.67,7.08]],"id":9631798}],"con":true,"img":false}]}
{"op":"mcm","clk":"1349816695","pt":1588407996169,"mc":[{"id":"1.170370562","rc":[{"atb":[[1.66,0]],"id":9631798}],"con":true,"img":false}]}
{"op":"mcm","clk":"1349816701","pt":1588407996273,"mc":[{"id":"1.170370562","rc":[{"atb":[[1.67,125.07]],"id":9631798}],"con":true,"img":false}]}
{"op":"mcm","clk":"1349816717","pt":1588407997247,"mc":[{"id":"1.170370562","rc":[{"atb":[[2,86.26]],"id":9625043},{"atb":[[1.67,164.77]],"id":9631798}],"con":true,"img":false}]}
{"op":"mcm","clk":"1349832463","pt":1588408528986,"mc":[{"id":"1.170370562","rc":[{"atl":[[1.87,52.48]],"id":9631798}],"con":true,"img":false}]}
{"op":"mcm","clk":"1349832475","pt":1588408529398,"mc":[{"id":"1.170370562","rc":[{"atb":[[2.14,23.33]],"id":9625043}],"con":true,"img":false}]}
{"op":"mcm","clk":"1349832681","pt":1588408536183,"mc":[{"id":"1.170370562","rc":[{"atl":[[2.48,52.48]],"id":9625043}],"con":true,"img":false}]}
{"op":"mcm","clk":"1349834778","pt":1588408604522,"mc":[{"id":"1.170370562","rc":[{"atl":[[1.85,0.17]],"id":9631798}],"con":true,"img":false}]}
{"op":"mcm","clk":"1349835376","pt":1588408625415,"mc":[{"id":"1.170370562","rc":[{"atl":[[1.85,0]],"id":9631798}],"con":true,"img":false}]}
{"op":"mcm","clk":"1349835766","pt":1588408638914,"mc":[{"id":"1.170370562","rc":[{"atl":[[1.86,1.77]],"id":9631798}],"con":true,"img":false}]}
{"op":"mcm","clk":"1349836297","pt":1588408657380,"mc":[{"id":"1.170370562","rc":[{"atl":[[2.4,20]],"id":9625043}],"con":true,"img":false}]}
{"op":"mcm","clk":"1349836337","pt":1588408658467,"mc":[{"id":"1.170370562","rc":[{"atb":[[1.71,37.45]],"id":9631798}],"con":true,"img":false}]}
{"op":"mcm","clk":"1349836343","pt":1588408658673,"mc":[{"id":"1.170370562","rc":[{"atb":[[1.67,46.78]],"id":9631798}],"con":true,"img":false}]}
{"op":"mcm","clk":"1349837154","pt":1588408688140,"mc":[{"id":"1.170370562","marketDefinition":{"bspMarket":false,"turnInPlayEnabled":true,"persistenceEnabled":true,"marketBaseRate":5.0,"eventId":"29788105","eventTypeId":"2","numberOfWinners":1,"bettingType":"ODDS","marketType":"MATCH_ODDS","marketTime":"2020-05-02T09:10:00.000Z","suspendTime":"2020-05-02T09:10:00.000Z","bspReconciled":false,"complete":true,"inPlay":false,"crossMatching":true,"runnersVoidable":false,"numberOfActiveRunners":2,"betDelay":0,"status":"OPEN","runners":[{"status":"ACTIVE","sortPriority":1,"id":9631798,"name":"B Hassan"},{"status":"ACTIVE","sortPriority":2,"id":9625043,"name":"J Haerteis"}],"regulators":["MR_INT"],"countryCode":"GB","discountAllowed":true,"timezone":"GMT","openDate":"2020-05-02T09:00:00.000Z","version":3237467176,"name":"Match Odds","eventName":"B Hassan v J Haerteis"},"rc":[],"con":true,"img":false}]}
{"op":"mcm","clk":"1349837209","pt":1588408690145,"mc":[{"id":"1.170370562","marketDefinition":{"bspMarket":false,"turnInPlayEnabled":true,"persistenceEnabled":true,"marketBaseRate":5.0,"eventId":"29788105","eventTypeId":"2","numberOfWinners":1,"bettingType":"ODDS","marketType":"MATCH_ODDS","marketTime":"2020-05-02T09:10:00.000Z","suspendTime":"2020-05-02T09:10:00.000Z","bspReconciled":false,"complete":true,"inPlay":false,"crossMatching":true,"runnersVoidable":false,"numberOfActiveRunners":2,"betDelay":0,"status":"OPEN","runners":[{"status":"ACTIVE","sortPriority":1,"id":9631798,"name":"B Hassan"},{"status":"ACTIVE","sortPriority":2,"id":9625043,"name":"J Haerteis"}],"regulators":["MR_INT"],"countryCode":"GB","discountAllowed":true,"timezone":"GMT","openDate":"2020-05-02T09:10:00.000Z","version":3237467176,"name":"Match Odds","eventName":"B Hassan v J Haerteis"},"rc":[],"con":true,"img":false}]}
{"op":"mcm","clk":"1349837706","pt":1588408706627,"mc":[{"id":"1.170370562","rc":[{"atl":[[1.86,0]],"id":9631798}],"con":true,"img":false}]}
{"op":"mcm","clk":"1349838232","pt":1588408723152,"mc":[{"id":"1.170370562","rc":[{"atl":[[1.86,0.71]],"id":9631798}],"con":true,"img":false}]}
{"op":"mcm","clk":"1349838730","pt":1588408739615,"mc":[{"id":"1.170370562","rc":[{"atb":[[1.67,47.49]],"id":9631798}],"con":true,"img":false}]}
{"op":"mcm","clk":"1349842110","pt":1588408818499,"mc":[{"id":"1.170370562","rc":[{"atb":[[1.01,6.57]],"id":9625043},{"atb":[[1.01,6.57]],"id":9631798}],"con":true,"img":false}]}
{"op":"mcm","clk":"1349842121","pt":1588408818804,"mc":[{"id":"1.170370562","rc":[{"atb":[[1.01,5.01]],"id":9625043},{"atb":[[1.01,5.01]],"id":9631798}],"con":true,"img":false}]}
{"op":"mcm","clk":"1349842126","pt":1588408819011,"mc":[{"id":"1.170370562","rc":[{"atb":[[1.01,4.79]],"id":9625043},{"atb":[[1.01,4.79]],"id":9631798}],"con":true,"img":false}]}
{"op":"mcm","clk":"1349842132","pt":1588408819114,"mc":[{"id":"1.170370562","rc":[{"atb":[[1.02,0.21]],"id":9625043},{"atb":[[1.02,0.21]],"id":9631798}],"con":true,"img":false}]}
{"op":"mcm","clk":"1349843402","pt":1588408859562,"mc":[{"id":"1.170370562","rc":[{"atb":[[2.16,81.53]],"id":9625043}],"con":true,"img":false}]}
{"op":"mcm","clk":"1349843430","pt":1588408860597,"mc":[{"id":"1.170370562","rc":[{"atb":[[2.16,104.45]],"id":9625043}],"con":true,"img":false}]}
{"op":"mcm","clk":"1349843899","pt":1588408876312,"mc":[{"id":"1.170370562","rc":[{"atb":[[2.16,22.92]],"id":9625043}],"con":true,"img":false}]}
{"op":"mcm","clk":"1349843907","pt":1588408876415,"mc":[{"id":"1.170370562","rc":[{"atb":[[2.18,82.36]],"id":9625043}],"con":true,"img":false}]}
{"op":"mcm","clk":"1349843939","pt":1588408877496,"mc":[{"id":"1.170370562","rc":[{"atb":[[2.18,104.89]],"id":9625043}],"con":true,"img":false}]}
{"op":"mcm","clk":"1349845137","pt":1588408918259,"mc":[{"id":"1.170370562","rc":[{"atb":[[2.18,22.53]],"id":9625043}],"con":true,"img":false}]}
{"op":"mcm","clk":"1349845142","pt":1588408918415,"mc":[{"id":"1.170370562","rc":[{"atb":[[2.2,83.97]],"id":9625043}],"con":true,"img":false}]}
{"op":"mcm","clk":"1349847610","pt":1588409001987,"mc":[{"id":"1.170370562","rc":[{"trd":[[1.71,8.74]],"ltp":1.71,"tv":8.74,"id":9631798},{"atb":[[1.71,33.08]],"id":9631798}],"con":true,"img":false}]}
{"op":"mcm","clk":"1349847629","pt":1588409002610,"mc":[{"id":"1.170370562","rc":[{"atb":[[2.2,106.13]],"id":9625043},{"atb":[[1.71,0]],"id":9631798}],"con":true,"img":false}]}
{"op":"mcm","clk":"1349847656","pt":1588409003699,"mc":[{"id":"1.170370562","rc":[{"atb":[[2.2,83.97]],"id":9625043}],"con":true,"img":false}]}
{"op":"mcm","clk":"1349849420","pt":1588409060299,"mc":[{"id":"1.170370562","rc":[{"atl":[[2.48,0]],"id":9625043}],"con":true,"img":false}]}
{"op":"mcm","clk":"1349849470","pt":1588409061592,"mc":[{"id":"1.170370562","rc":[{"atb":[[1.71,37.45]],"id":9631798}],"con":true,"img":false}]}
{"op":"mcm","clk":"1349849691","pt":1588409068080,"mc":[{"id":"1.170370562","rc":[{"atl":[[1.87,0]],"id":9631798}],"con":true,"img":false}]}
{"op":"mcm","clk":"1349855414","pt":1588409231671,"mc":[{"id":"1.170370562","rc":[{"atb":[[1.67,40.4]],"id":9631798}],"con":true,"img":false}]}
{"op":"mcm","clk":"1349855419","pt":1588409231774,"mc":[{"id":"1.170370562","rc":[{"atb":[[1.66,7.08]],"id":9631798}],"con":true,"img":false}]}
{"op":"mcm","clk":"1349857491","pt":1588409287888,"mc":[{"id":"1.170370562","marketDefinition":{"bspMarket":false,"turnInPlayEnabled":true,"persistenceEnabled":true,"marketBaseRate":5.0,"eventId":"29788105","eventTypeId":"2","numberOfWinners":1,"bettingType":"ODDS","marketType":"MATCH_ODDS","marketTime":"2020-05-02T09:40:00.000Z","suspendTime":"2020-05-02T09:40:00.000Z","bspReconciled":false,"complete":true,"inPlay":false,"crossMatching":true,"runnersVoidable":false,"numberOfActiveRunners":2,"betDelay":0,"status":"OPEN","runners":[{"status":"ACTIVE","sortPriority":1,"id":9631798,"name":"B Hassan"},{"status":"ACTIVE","sortPriority":2,"id":9625043,"name":"J Haerteis"}],"regulators":["MR_INT"],"countryCode":"GB","discountAllowed":true,"timezone":"GMT","openDate":"2020-05-02T09:10:00.000Z","version":3237467648,"name":"Match Odds","eventName":"B Hassan v J Haerteis"},"rc":[],"con":true,"img":false}]}
{"op":"mcm","clk":"1349857550","pt":1588409289891,"mc":[{"id":"1.170370562","marketDefinition":{"bspMarket":false,"turnInPlayEnabled":true,"persistenceEnabled":true,"marketBaseRate":5.0,"eventId":"29788105","eventTypeId":"2","numberOfWinners":1,"bettingType":"ODDS","marketType":"MATCH_ODDS","marketTime":"2020-05-02T09:40:00.000Z","suspendTime":"2020-05-02T09:40:00.000Z","bspReconciled":false,"complete":true,"inPlay":false,"crossMatching":true,"runnersVoidable":false,"numberOfActiveRunners":2,"betDelay":0,"status":"OPEN","runners":[{"status":"ACTIVE","sortPriority":1,"id":9631798,"name":"B Hassan"},{"status":"ACTIVE","sortPriority":2,"id":9625043,"name":"J Haerteis"}],"regulators":["MR_INT"],"countryCode":"GB","discountAllowed":true,"timezone":"GMT","openDate":"2020-05-02T09:40:00.000Z","version":3237467648,"name":"Match Odds","eventName":"B Hassan v J Haerteis"},"rc":[],"con":true,"img":false}]}
{"op":"mcm","clk":"1349860443","pt":1588409385876,"mc":[{"id":"1.170370562","rc":[{"atl":[[1.88,0]],"id":9631798}],"con":true,"img":false}]}
{"op":"mcm","clk":"1349860507","pt":1588409388253,"mc":[{"id":"1.170370562","rc":[{"trd":[[2.42,4.36],[2.4,39.99]],"ltp":2.42,"tv":44.35,"id":9625043},{"atl":[[2.4,0]],"id":9625043},{"trd":[[1.71,14.91]],"ltp":1.71,"tv":14.91,"id":9631798},{"atb":[[1.71,31.28]],"id":9631798}],"con":true,"img":false}]}
{"op":"mcm","clk":"1349860516","pt":1588409388664,"mc":[{"id":"1.170370562","rc":[{"atb":[[2,59.67],[2.2,106.13]],"id":9625043},{"atb":[[1.67,0.71],[1.65,132.71],[1.71,0]],"id":9631798}],"con":true,"img":false}]}
{"op":"mcm","clk":"1349863274","pt":1588409497719,"mc":[{"id":"1.170370562","rc":[{"atl":[[1.83,23.99]],"id":9631798}],"con":true,"img":false}]}
{"op":"mcm","clk":"1349870349","pt":1588409713023,"mc":[{"id":"1.170370562","rc":[{"atl":[[1000,3.83]],"id":9631798}],"con":true,"img":false}]}
{"op":"mcm","clk":"1349870358","pt":1588409713229,"mc":[{"id":"1.170370562","rc":[{"atl":[[1000,0.3]],"id":9631798}],"con":true,"img":false}]}
{"op":"mcm","clk":"1349870365","pt":1588409713435,"mc":[{"id":"1.170370562","rc":[{"atl":[[1000,0]],"id":9631798}],"con":true,"img":false}]}
{"op":"mcm","clk":"1349870370","pt":1588409713538,"mc":[{"id":"1.170370562","rc":[{"trd":[[2.44,0.21]],"ltp":2.44,"tv":0.21,"id":9625043},{"atl":[[2.44,0.01]],"id":9625043},{"trd":[[1.69,0.3]],"ltp":1.69,"tv":0.3,"id":9631798}],"con":true,"img":false}]}
{"op":"mcm","clk":"1349870517","pt":1588409718074,"mc":[{"id":"1.170370562","rc":[{"atl":[[1.88,24.37]],"id":9631798}],"con":true,"img":false}]}
{"op":"mcm","clk":"1349871793","pt":1588409771676,"mc":[{"id":"1.170370562","rc":[{"atl":[[1.86,0]],"id":9631798}],"con":true,"img":false}]}
{"op":"mcm","clk":"1349872415","pt":1588409794795,"mc":[{"id":"1.170370562","rc":[{"atb":[[1.67,0]],"id":9631798}],"con":true,"img":false}]}
{"op":"mcm","clk":"1349874321","pt":1588409875753,"mc":[{"id":"1.170370562","rc":[{"atb":[[1.66,0]],"id":9631798}],"con":true,"img":false}]}
{"op":"mcm","clk":"1349875099","pt":1588409915585,"mc":[{"id":"1.170370562","rc":[{"atl":[[1.7,2]],"id":9631798}],"con":true,"img":false}]}
{"op":"mcm","clk":"1349875102","pt":1588409915790,"mc":[{"id":"1.170370562","rc":[{"atb":[[1.59,45.07]],"id":9631798}],"con":true,"img":false}]}
{"op":"mcm","clk":"1349875107","pt":1588409915995,"mc":[{"id":"1.170370562","rc":[{"atb":[[1.65,91.8]],"id":9631798}],"con":true,"img":false}]}
{"op":"mcm","clk":"1349875228","pt":1588409925277,"mc":[{"id":"1.170370562","rc":[{"atl":[[1.7,0]],"id":9631798}],"con":true,"img":false}]}
{"op":"mcm","clk":"1349875235","pt":1588409925891,"mc":[{"id":"1.170370562","rc":[{"atb":[[1.65,132.71]],"id":9631798}],"con":true,"img":false}]}
{"op":"mcm","clk":"1349875521","pt":1588409943320,"mc":[{"id":"1.170370562","rc":[{"atb":[[1.8,2]],"id":9631798}],"con":true,"img":false}]}
{"op":"mcm","clk":"1349875526","pt":1588409943528,"mc":[{"id":"1.170370562","rc":[{"trd":[[1.8,249.01]],"ltp":1.8,"tv":249.01,"id":9631798},{"atb":[[1.8,0]],"id":9631798}],"con":true,"img":false}]}
{"op":"mcm","clk":"1349875697","pt":1588409955051,"mc":[{"id":"1.170370562","rc":[{"atb":[[1.77,2]],"id":9631798}],"con":true,"img":false}]}
{"op":"mcm","clk":"1349875705","pt":1588409955873,"mc":[{"id":"1.170370562","rc":[{"atb":[[2.14,0],[2.1,26.01],[2.18,0],[2.2,83.97],[2.16,0]],"id":9625043}],"con":true,"img":false}]}
{"op":"mcm","clk":"1349875710","pt":1588409956133,"mc":[{"id":"1.170370562","rc":[{"atb":[[2.2,0]],"id":9625043}],"con":true,"img":false}]}
{"op":"mcm","clk":"1349876063","pt":1588409973996,"mc":[{"id":"1.170370562","rc":[{"atb":[[1.77,0]],"id":9631798}],"con":true,"img":false}]}
{"op":"mcm","clk":"1349876089","pt":1588409974876,"mc":[{"id":"1.170370562","rc":[{"atb":[[2.2,22.16]],"id":9625043}],"con":true,"img":false}]}
{"op":"mcm","clk":"1349877441","pt":1588410039045,"mc":[{"id":"1.170370562","rc":[{"atb":[[1.54,39.99]],"id":9631798}],"con":true,"img":false}]}
{"op":"mcm","clk":"1349877447","pt":1588410039250,"mc":[{"id":"1.170370562","rc":[{"atb":[[2.14,39.99]],"id":9625043}],"con":true,"img":false}]}
{"op":"mcm","clk":"1349877558","pt":1588410045888,"mc":[{"id":"1.170370562","rc":[{"atb":[[2.14,0]],"id":9625043},{"atb":[[1.54,0]],"id":9631798}],"con":true,"img":false}]}
{"op":"mcm","clk":"1349877680","pt":1588410051804,"mc":[{"id":"1.170370562","rc":[{"atb":[[1.54,39.99]],"id":9631798}],"con":true,"img":false}]}
{"op":"mcm","clk":"1349877684","pt":1588410052009,"mc":[{"id":"1.170370562","rc":[{"atb":[[2.14,39.99]],"id":9625043}],"con":true,"img":false}]}
{"op":"mcm","clk":"1349877801","pt":1588410058231,"mc":[{"id":"1.170370562","rc":[{"atb":[[2.14,0]],"id":9625043},{"atb":[[1.54,0]],"id":9631798}],"con":true,"img":false}]}
{"op":"mcm","clk":"1349877962","pt":1588410065244,"mc":[{"id":"1.170370562","rc":[{"atb":[[1.54,39.99]],"id":9631798}],"con":true,"img":false}]}
{"op":"mcm","clk":"1349877968","pt":1588410065449,"mc":[{"id":"1.170370562","rc":[{"atb":[[2.14,39.99]],"id":9625043}],"con":true,"img":false}]}
{"op":"mcm","clk":"1349878126","pt":1588410071469,"mc":[{"id":"1.170370562","rc":[{"atb":[[2.14,0]],"id":9625043},{"atb":[[1.54,0]],"id":9631798}],"con":true,"img":false}]}
{"op":"mcm","clk":"1349878272","pt":1588410078152,"mc":[{"id":"1.170370562","rc":[{"atb":[[1.54,39.99]],"id":9631798}],"con":true,"img":false}]}
{"op":"mcm","clk":"1349878280","pt":1588410078460,"mc":[{"id":"1.170370562","rc":[{"atb":[[2.14,39.99]],"id":9625043}],"con":true,"img":false}]}
{"op":"mcm","clk":"1349878438","pt":1588410084786,"mc":[{"id":"1.170370562","rc":[{"atb":[[2.14,0]],"id":9625043},{"atb":[[1.54,0]],"id":9631798}],"con":true,"img":false}]}
{"op":"mcm","clk":"1349878562","pt":1588410090271,"mc":[{"id":"1.170370562","rc":[{"atb":[[1.54,39.99]],"id":9631798}],"con":true,"img":false}]}
{"op":"mcm","clk":"1349878567","pt":1588410090475,"mc":[{"id":"1.170370562","rc":[{"atb":[[2.14,39.99]],"id":9625043}],"con":true,"img":false}]}
{"op":"mcm","clk":"1349878670","pt":1588410095809,"mc":[{"id":"1.170370562","rc":[{"trd":[[2.44,0.22]],"ltp":2.44,"tv":0.22,"id":9625043},{"atl":[[2.44,0]],"id":9625043},{"trd":[[1.69,0.31]],"ltp":1.69,"tv":0.31,"id":9631798},{"atl":[[1.69,1.99]],"id":9631798}],"con":true,"img":false}]}
{"op":"mcm","clk":"1349878676","pt":1588410096014,"mc":[{"id":"1.170370562","rc":[{"atb":[[2.22,83.34]],"id":9625043}],"con":true,"img":false}]}
{"op":"mcm","clk":"1349878693","pt":1588410096579,"mc":[{"id":"1.170370562","rc":[{"atb":[[2.14,0]],"id":9625043},{"atb":[[1.54,0]],"id":9631798}],"con":true,"img":false}]}
{"op":"mcm","clk":"1349878700","pt":1588410096886,"mc":[{"id":"1.170370562","rc":[{"atb":[[2.22,105.13]],"id":9625043},{"atb":[[1.65,91.8]],"id":9631798}],"con":true,"img":false}]}
{"op":"mcm","clk":"1349878783","pt":1588410102013,"mc":[{"id":"1.170370562","rc":[{"atb":[[1.54,39.99]],"id":9631798}],"con":true,"img":false}]}
{"op":"mcm","clk":"1349878788","pt":1588410102218,"mc":[{"id":"1.170370562","rc":[{"atb":[[2.14,39.99]],"id":9625043}],"con":true,"img":false}]}
{"op":"mcm","clk":"1349878938","pt":1588410107916,"mc":[{"id":"1.170370562","rc":[{"atb":[[2.14,0]],"id":9625043},{"atb":[[1.54,0]],"id":9631798}],"con":true,"img":false}]}
{"op":"mcm","clk":"1349878986","pt":1588410110340,"mc":[{"id":"1.170370562","rc":[{"atl":[[1.69,0]],"id":9631798}],"con":true,"img":false}]}
{"op":"mcm","clk":"1349878998","pt":1588410110908,"mc":[{"id":"1.170370562","rc":[{"atb":[[1.65,132.71]],"id":9631798}],"con":true,"img":false}]}
{"op":"mcm","clk":"1349879096","pt":1588410115227,"mc":[{"id":"1.170370562","rc":[{"atb":[[1.54,39.99]],"id":9631798}],"con":true,"img":false}]}
{"op":"mcm","clk":"1349879106","pt":1588410115432,"mc":[{"id":"1.170370562","rc":[{"atb":[[2.14,39.99]],"id":9625043}],"con":true,"img":false}]}
{"op":"mcm","clk":"1349879114","pt":1588410115741,"mc":[{"id":"1.170370562","rc":[{"atb":[[1.77,2]],"id":9631798}],"con":true,"img":false}]}
{"op":"mcm","clk":"1349879141","pt":1588410116927,"mc":[{"id":"1.170370562","rc":[{"atb":[[2.22,83.34],[2.12,23.75],[2.2,0]],"id":9625043}],"con":true,"img":false}]}
{"op":"mcm","clk":"1349879226","pt":1588410121238,"mc":[{"id":"1.170370562","rc":[{"atb":[[2.14,0]],"id":9625043},{"atb":[[1.54,0]],"id":9631798}],"con":true,"img":false}]}
{"op":"mcm","clk":"1349879351","pt":1588410126731,"mc":[{"id":"1.170370562","rc":[{"atb":[[1.54,39.99]],"id":9631798}],"con":true,"img":false}]}
{"op":"mcm","clk":"1349879355","pt":1588410126934,"mc":[{"id":"1.170370562","rc":[{"atb":[[2.14,39.99]],"id":9625043}],"con":true,"img":false}]}
{"op":"mcm","clk":"1349879449","pt":1588410131762,"mc":[{"id":"1.170370562","rc":[{"atb":[[1.77,0]],"id":9631798}],"con":true,"img":false}]}
{"op":"mcm","clk":"1349879469","pt":1588410132740,"mc":[{"id":"1.170370562","rc":[{"atb":[[2.14,0]],"id":9625043},{"atb":[[1.54,0]],"id":9631798}],"con":true,"img":false}]}
{"op":"mcm","clk":"1349879476","pt":1588410132950,"mc":[{"id":"1.170370562","rc":[{"atb":[[2.22,105.13]],"id":9625043}],"con":true,"img":false}]}
{"op":"mcm","clk":"1349879581","pt":1588410138762,"mc":[{"id":"1.170370562","rc":[{"atb":[[1.54,39.99]],"id":9631798}],"con":true,"img":false}]}
{"op":"mcm","clk":"1349879586","pt":1588410138966,"mc":[{"id":"1.170370562","rc":[{"atb":[[2.14,39.99]],"id":9625043}],"con":true,"img":false}]}
{"op":"mcm","clk":"1349879608","pt":1588410139742,"mc":[{"id":"1.170370562","rc":[{"atl":[[1.69,2]],"id":9631798}],"con":true,"img":false}]}
{"op":"mcm","clk":"1349879641","pt":1588410141075,"mc":[{"id":"1.170370562","rc":[{"atb":[[1.65,91.8]],"id":9631798}],"con":true,"img":false}]}
{"op":"mcm","clk":"1349879724","pt":1588410145045,"mc":[{"id":"1.170370562","rc":[{"atb":[[2.14,0]],"id":9625043},{"atb":[[1.54,0]],"id":9631798}],"con":true,"img":false}]}
{"op":"mcm","clk":"1349879864","pt":1588410151488,"mc":[{"id":"1.170370562","rc":[{"atb":[[1.54,39.99]],"id":9631798}],"con":true,"img":false}]}
{"op":"mcm","clk":"1349879868","pt":1588410151660,"mc":[{"id":"1.170370562","rc":[{"atb":[[2.14,39.99]],"id":9625043}],"con":true,"img":false}]}
{"op":"mcm","clk":"1349879916","pt":1588410154268,"mc":[{"id":"1.170370562","rc":[{"atl":[[1.69,0]],"id":9631798}],"con":true,"img":false}]}
{"op":"mcm","clk":"1349879929","pt":1588410154984,"mc":[{"id":"1.170370562","rc":[{"atb":[[1.65,132.71]],"id":9631798}],"con":true,"img":false}]}
{"op":"mcm","clk":"1349879993","pt":1588410158885,"mc":[{"id":"1.170370562","rc":[{"atb":[[2.14,0]],"id":9625043},{"atb":[[1.54,0]],"id":9631798}],"con":true,"img":false}]}
{"op":"mcm","clk":"1349880052","pt":1588410162182,"mc":[{"id":"1.170370562","rc":[{"atb":[[1.77,2]],"id":9631798}],"con":true,"img":false}]}
{"op":"mcm","clk":"1349880065","pt":1588410163006,"mc":[{"id":"1.170370562","rc":[{"atb":[[2.22,83.34]],"id":9625043}],"con":true,"img":false}]}
{"op":"mcm","clk":"1349880102","pt":1588410164671,"mc":[{"id":"1.170370562","rc":[{"atb":[[1.54,39.99]],"id":9631798}],"con":true,"img":false}]}
{"op":"mcm","clk":"1349880105","pt":1588410164877,"mc":[{"id":"1.170370562","rc":[{"atb":[[2.14,39.99]],"id":9625043}],"con":true,"img":false}]}
{"op":"mcm","clk":"1349880214","pt":1588410170693,"mc":[{"id":"1.170370562","rc":[{"atb":[[2.14,0]],"id":9625043},{"atb":[[1.54,0]],"id":9631798}],"con":true,"img":false}]}
{"op":"mcm","clk":"1349880337","pt":1588410176310,"mc":[{"id":"1.170370562","rc":[{"atb":[[1.54,39.99]],"id":9631798}],"con":true,"img":false}]}
{"op":"mcm","clk":"1349880344","pt":1588410176517,"mc":[{"id":"1.170370562","rc":[{"atb":[[2.14,39.99]],"id":9625043}],"con":true,"img":false}]}
{"op":"mcm","clk":"1349880452","pt":1588410182518,"mc":[{"id":"1.170370562","rc":[{"atb":[[2.14,0]],"id":9625043},{"atb":[[1.54,0]],"id":9631798}],"con":true,"img":false}]}
{"op":"mcm","clk":"1349880590","pt":1588410188014,"mc":[{"id":"1.170370562","rc":[{"atb":[[1.77,0]],"id":9631798}],"con":true,"img":false}]}
{"op":"mcm","clk":"1349880607","pt":1588410188527,"mc":[{"id":"1.170370562","rc":[{"atb":[[1.54,39.99]],"id":9631798}],"con":true,"img":false}]}
{"op":"mcm","clk":"1349880616","pt":1588410188733,"mc":[{"id":"1.170370562","rc":[{"atb":[[2.14,39.99]],"id":9625043}],"con":true,"img":false}]}
{"op":"mcm","clk":"1349880622","pt":1588410188939,"mc":[{"id":"1.170370562","rc":[{"atb":[[2.22,105.13]],"id":9625043}],"con":true,"img":false}]}
{"op":"mcm","clk":"1349880767","pt":1588410194517,"mc":[{"id":"1.170370562","rc":[{"atb":[[2.14,0]],"id":9625043},{"atb":[[1.54,0]],"id":9631798}],"con":true,"img":false}]}
{"op":"mcm","clk":"1349880907","pt":1588410200343,"mc":[{"id":"1.170370562","rc":[{"atb":[[1.54,39.99]],"id":9631798}],"con":true,"img":false}]}
{"op":"mcm","clk":"1349880915","pt":1588410200548,"mc":[{"id":"1.170370562","rc":[{"atb":[[2.14,39.99]],"id":9625043}],"con":true,"img":false}]}
{"op":"mcm","clk":"1349881091","pt":1588410207929,"mc":[{"id":"1.170370562","rc":[{"atb":[[2.14,0]],"id":9625043},{"atb":[[1.54,0]],"id":9631798}],"con":true,"img":false}]}
{"op":"mcm","clk":"1349881216","pt":1588410213646,"mc":[{"id":"1.170370562","rc":[{"atb":[[1.54,39.99]],"id":9631798}],"con":true,"img":false}]}
{"op":"mcm","clk":"1349881224","pt":1588410213855,"mc":[{"id":"1.170370562","rc":[{"atb":[[2.14,39.99]],"id":9625043}],"con":true,"img":false}]}
{"op":"mcm","clk":"1349881358","pt":1588410220157,"mc":[{"id":"1.170370562","rc":[{"atb":[[2.14,0]],"id":9625043},{"atb":[[1.54,0]],"id":9631798}],"con":true,"img":false}]}
{"op":"mcm","clk":"1349881483","pt":1588410226585,"mc":[{"id":"1.170370562","rc":[{"atb":[[1.54,39.99]],"id":9631798}],"con":true,"img":false}]}
{"op":"mcm","clk":"1349881485","pt":1588410226739,"mc":[{"id":"1.170370562","rc":[{"atb":[[2.14,39.99]],"id":9625043}],"con":true,"img":false}]}
{"op":"mcm","clk":"1349881617","pt":1588410233050,"mc":[{"id":"1.170370562","rc":[{"atb":[[2.14,0]],"id":9625043},{"atb":[[1.54,0]],"id":9631798}],"con":true,"img":false}]}
{"op":"mcm","clk":"1349881695","pt":1588410236695,"mc":[{"id":"1.170370562","rc":[{"atl":[[1.69,2]],"id":9631798}],"con":true,"img":false}]}
{"op":"mcm","clk":"1349881700","pt":1588410236952,"mc":[{"id":"1.170370562","rc":[{"atb":[[1.65,91.8]],"id":9631798}],"con":true,"img":false}]}
{"op":"mcm","clk":"1349881738","pt":1588410238962,"mc":[{"id":"1.170370562","rc":[{"atb":[[1.54,39.99]],"id":9631798}],"con":true,"img":false}]}
{"op":"mcm","clk":"1349881744","pt":1588410239168,"mc":[{"id":"1.170370562","rc":[{"atb":[[2.14,39.99]],"id":9625043}],"con":true,"img":false}]}
{"op":"mcm","clk":"1349881872","pt":1588410245814,"mc":[{"id":"1.170370562","rc":[{"atb":[[2.14,0]],"id":9625043},{"atb":[[1.54,0]],"id":9631798}],"con":true,"img":false}]}
{"op":"mcm","clk":"1349881985","pt":1588410251887,"mc":[{"id":"1.170370562","rc":[{"atb":[[1.54,39.99]],"id":9631798},{"atl":[[1.69,0]],"id":9631798}],"con":true,"img":false}]}
{"op":"mcm","clk":"1349881993","pt":1588410252095,"mc":[{"id":"1.170370562","rc":[{"atb":[[2.14,39.99]],"id":9625043}],"con":true,"img":false}]}
{"op":"mcm","clk":"1349882007","pt":1588410253021,"mc":[{"id":"1.170370562","rc":[{"atb":[[1.65,132.71]],"id":9631798}],"con":true,"img":false}]}
{"op":"mcm","clk":"1349882101","pt":1588410256591,"mc":[{"id":"1.170370562","rc":[{"atb":[[2.14,0]],"id":9625043},{"atb":[[1.54,0]],"id":9631798}],"con":true,"img":false}]}
{"op":"mcm","clk":"1349882148","pt":1588410258188,"mc":[{"id":"1.170370562","rc":[{"atb":[[1.77,2]],"id":9631798}],"con":true,"img":false}]}
{"op":"mcm","clk":"1349882160","pt":1588410259012,"mc":[{"id":"1.170370562","rc":[{"atb":[[2.22,83.34]],"id":9625043}],"con":true,"img":false}]}
{"op":"mcm","clk":"1349882290","pt":1588410263609,"mc":[{"id":"1.170370562","rc":[{"atb":[[1.54,39.99]],"id":9631798}],"con":true,"img":false}]}
{"op":"mcm","clk":"1349882296","pt":1588410263814,"mc":[{"id":"1.170370562","rc":[{"atb":[[2.14,39.99]],"id":9625043}],"con":true,"img":false}]}
{"op":"mcm","clk":"1349882439","pt":1588410269814,"mc":[{"id":"1.170370562","rc":[{"atb":[[2.14,0]],"id":9625043},{"atb":[[1.54,0]],"id":9631798}],"con":true,"img":false}]}
{"op":"mcm","clk":"1349882585","pt":1588410276109,"mc":[{"id":"1.170370562","rc":[{"atb":[[1.54,39.99]],"id":9631798}],"con":true,"img":false}]}
{"op":"mcm","clk":"1349882588","pt":1588410276314,"mc":[{"id":"1.170370562","rc":[{"atb":[[2.14,39.99]],"id":9625043}],"con":true,"img":false}]}
{"op":"mcm","clk":"1349882702","pt":1588410281414,"mc":[{"id":"1.170370562","rc":[{"atb":[[1.77,0]],"id":9631798}],"con":true,"img":false}]}
{"op":"mcm","clk":"1349882720","pt":1588410281929,"mc":[{"id":"1.170370562","rc":[{"atb":[[2.22,105.13]],"id":9625043}],"con":true,"img":false}]}
{"op":"mcm","clk":"1349882729","pt":1588410282136,"mc":[{"id":"1.170370562","rc":[{"atb":[[2.14,0]],"id":9625043},{"atb":[[1.54,0]],"id":9631798}],"con":true,"img":false}]}
{"op":"mcm","clk":"1349882893","pt":1588410287960,"mc":[{"id":"1.170370562","rc":[{"atb":[[1.54,39.99]],"id":9631798}],"con":true,"img":false}]}
{"op":"mcm","clk":"1349882899","pt":1588410288269,"mc":[{"id":"1.170370562","rc":[{"atb":[[2.14,39.99]],"id":9625043}],"con":true,"img":false}]}
{"op":"mcm","clk":"1349882961","pt":1588410290337,"mc":[{"id":"1.170370562","rc":[{"atl":[[1.69,2]],"id":9631798}],"con":true,"img":false}]}
{"op":"mcm","clk":"1349882979","pt":1588410291062,"mc":[{"id":"1.170370562","rc":[{"atb":[[1.65,91.8]],"id":9631798}],"con":true,"img":false}]}
{"op":"mcm","clk":"1349883082","pt":1588410294061,"mc":[{"id":"1.170370562","rc":[{"atb":[[2.14,0]],"id":9625043},{"atb":[[1.54,0]],"id":9631798}],"con":true,"img":false}]}
{"op":"mcm","clk":"1349883111","pt":1588410295357,"mc":[{"id":"1.170370562","rc":[{"trd":[[1.65,100]],"ltp":1.65,"tv":100.0,"id":9631798},{"atb":[[1.65,41.8]],"id":9631798}],"con":true,"img":false}]}
{"op":"mcm","clk":"1349883121","pt":1588410295669,"mc":[{"id":"1.170370562","rc":[{"atb":[[1.65,133.6]],"id":9631798}],"con":true,"img":false}]}
{"op":"mcm","clk":"1349883125","pt":1588410295773,"mc":[{"id":"1.170370562","rc":[{"atb":[[1.65,91.8]],"id":9631798}],"con":true,"img":false}]}
{"op":"mcm","clk":"1349883204","pt":1588410299444,"mc":[{"id":"1.170370562","rc":[{"atb":[[1.54,39.99]],"id":9631798}],"con":true,"img":false}]}
{"op":"mcm","clk":"1349883210","pt":1588410299651,"mc":[{"id":"1.170370562","rc":[{"atb":[[2.14,39.99]],"id":9625043}],"con":true,"img":false}]}
{"op":"mcm","clk":"1349883361","pt":1588410306150,"mc":[{"id":"1.170370562","rc":[{"atl":[[1.69,0]],"id":9631798}],"con":true,"img":false}]}
{"op":"mcm","clk":"1349883374","pt":1588410306664,"mc":[{"id":"1.170370562","rc":[{"atb":[[2.14,0]],"id":9625043},{"atb":[[1.54,0]],"id":9631798}],"con":true,"img":false}]}
{"op":"mcm","clk":"1349883385","pt":1588410306973,"mc":[{"id":"1.170370562","rc":[{"atb":[[1.65,132.71]],"id":9631798}],"con":true,"img":false}]}
{"op":"mcm","clk":"1349883425","pt":1588410308677,"mc":[{"id":"1.170370562","rc":[{"trd":[[1.65,104]],"ltp":1.65,"tv":104.0,"id":9631798},{"atb":[[1.65,130.71]],"id":9631798}],"con":true,"img":false}]}
{"op":"mcm","clk":"1349883471","pt":1588410310797,"mc":[{"id":"1.170370562","rc":[{"atb":[[1.65,132.71]],"id":9631798}],"con":true,"img":false}]}
{"op":"mcm","clk":"1349883506","pt":1588410311881,"mc":[{"id":"1.170370562","rc":[{"atb":[[1.77,2]],"id":9631798}],"con":true,"img":false}]}
{"op":"mcm","clk":"1349883538","pt":1588410313011,"mc":[{"id":"1.170370562","rc":[{"atb":[[2.22,83.34]],"id":9625043}],"con":true,"img":false}]}
{"op":"mcm","clk":"1349883574","pt":1588410314610,"mc":[{"id":"1.170370562","rc":[{"atb":[[1.54,39.99]],"id":9631798}],"con":true,"img":false}]}
{"op":"mcm","clk":"1349883576","pt":1588410314770,"mc":[{"id":"1.170370562","rc":[{"atb":[[2.14,39.99]],"id":9625043}],"con":true,"img":false}]}
{"op":"mcm","clk":"1349883621","pt":1588410317100,"mc":[{"id":"1.170370562","rc":[{"atb":[[2.14,0]],"id":9625043},{"atb":[[1.54,0]],"id":9631798}],"con":true,"img":false}]}
{"op":"mcm","clk":"1349883852","pt":1588410326407,"mc":[{"id":"1.170370562","rc":[{"atb":[[1.54,39.99]],"id":9631798}],"con":true,"img":false}]}
{"op":"mcm","clk":"1349883857","pt":1588410326615,"mc":[{"id":"1.170370562","rc":[{"atb":[[2.14,39.99]],"id":9625043}],"con":true,"img":false}]}
{"op":"mcm","clk":"1349883909","pt":1588410329097,"mc":[{"id":"1.170370562","rc":[{"atb":[[1.77,0]],"id":9631798}],"con":true,"img":false}]}
{"op":"mcm","clk":"1349883938","pt":1588410330029,"mc":[{"id":"1.170370562","rc":[{"atb":[[2.22,105.13]],"id":9625043}],"con":true,"img":false}]}
{"op":"mcm","clk":"1349883979","pt":1588410332194,"mc":[{"id":"1.170370562","rc":[{"atb":[[2.14,0]],"id":9625043},{"atb":[[1.54,0]],"id":9631798}],"con":true,"img":false}]}
{"op":"mcm","clk":"1349884039","pt":1588410335348,"mc":[{"id":"1.170370562","rc":[{"atl":[[1.69,2]],"id":9631798}],"con":true,"img":false}]}
{"op":"mcm","clk":"1349884057","pt":1588410336000,"mc":[{"id":"1.170370562","rc":[{"atb":[[1.65,91.8]],"id":9631798}],"con":true,"img":false}]}
{"op":"mcm","clk":"1349884092","pt":1588410338227,"mc":[{"id":"1.170370562","rc":[{"atb":[[1.54,39.99]],"id":9631798}],"con":true,"img":false}]}
{"op":"mcm","clk":"1349884095","pt":1588410338433,"mc":[{"id":"1.170370562","rc":[{"atb":[[2.14,39.99]],"id":9625043}],"con":true,"img":false}]}
{"op":"mcm","clk":"1349884232","pt":1588410344332,"mc":[{"id":"1.170370562","rc":[{"atb":[[2.14,0]],"id":9625043},{"atb":[[1.54,0]],"id":9631798}],"con":true,"img":false}]}
{"op":"mcm","clk":"1349884353","pt":1588410349853,"mc":[{"id":"1.170370562","rc":[{"atb":[[1.54,39.99]],"id":9631798}],"con":true,"img":false}]}
{"op":"mcm","clk":"1349884362","pt":1588410350010,"mc":[{"id":"1.170370562","rc":[{"atb":[[2.14,39.99]],"id":9625043}],"con":true,"img":false}]}
{"op":"mcm","clk":"1349884421","pt":1588410352848,"mc":[{"id":"1.170370562","rc":[{"atl":[[1.69,0]],"id":9631798}],"con":true,"img":false}]}
{"op":"mcm","clk":"1349884449","pt":1588410354034,"mc":[{"id":"1.170370562","rc":[{"atb":[[1.65,132.71]],"id":9631798}],"con":true,"img":false}]}
{"op":"mcm","clk":"1349884478","pt":1588410355731,"mc":[{"id":"1.170370562","rc":[{"atb":[[2.14,0]],"id":9625043},{"atb":[[1.54,0]],"id":9631798}],"con":true,"img":false}]}
{"op":"mcm","clk":"1349884607","pt":1588410361360,"mc":[{"id":"1.170370562","rc":[{"atb":[[1.54,39.99]],"id":9631798}],"con":true,"img":false}]}
{"op":"mcm","clk":"1349884613","pt":1588410361562,"mc":[{"id":"1.170370562","rc":[{"atb":[[2.14,39.99]],"id":9625043}],"con":true,"img":false}]}
{"op":"mcm","clk":"1349884758","pt":1588410368351,"mc":[{"id":"1.170370562","rc":[{"atb":[[2.14,0]],"id":9625043},{"atb":[[1.54,0]],"id":9631798}],"con":true,"img":false}]}
{"op":"mcm","clk":"1349884883","pt":1588410374568,"mc":[{"id":"1.170370562","rc":[{"atb":[[1.54,39.99]],"id":9631798}],"con":true,"img":false}]}
{"op":"mcm","clk":"1349884889","pt":1588410374774,"mc":[{"id":"1.170370562","rc":[{"atb":[[2.14,39.99]],"id":9625043}],"con":true,"img":false}]}
{"op":"mcm","clk":"1349884966","pt":1588410377655,"mc":[{"id":"1.170370562","rc":[{"atb":[[2.14,0]],"id":9625043},{"atb":[[1.54,0]],"id":9631798}],"con":true,"img":false}]}
{"op":"mcm","clk":"1349885030","pt":1588410380834,"mc":[{"id":"1.170370562","rc":[{"atb":[[1.77,2]],"id":9631798}],"con":true,"img":false}]}
{"op":"mcm","clk":"1349885057","pt":1588410382074,"mc":[{"id":"1.170370562","rc":[{"atb":[[2.22,83.34]],"id":9625043}],"con":true,"img":false}]}
{"op":"mcm","clk":"1349885165","pt":1588410386293,"mc":[{"id":"1.170370562","rc":[{"atb":[[1.54,39.99]],"id":9631798}],"con":true,"img":false}]}
{"op":"mcm","clk":"1349885168","pt":1588410386452,"mc":[{"id":"1.170370562","rc":[{"atb":[[2.14,39.99]],"id":9625043}],"con":true,"img":false}]}
{"op":"mcm","clk":"1349885326","pt":1588410393091,"mc":[{"id":"1.170370562","rc":[{"atb":[[2.14,0]],"id":9625043},{"atb":[[1.54,0]],"id":9631798}],"con":true,"img":false}]}
{"op":"mcm","clk":"1349885485","pt":1588410399271,"mc":[{"id":"1.170370562","rc":[{"atb":[[1.54,39.99]],"id":9631798}],"con":true,"img":false}]}
{"op":"mcm","clk":"1349885490","pt":1588410399478,"mc":[{"id":"1.170370562","rc":[{"atb":[[2.14,39.99]],"id":9625043}],"con":true,"img":false}]}
{"op":"mcm","clk":"1349885526","pt":1588410401174,"mc":[{"id":"1.170370562","rc":[{"atb":[[1.77,0]],"id":9631798}],"con":true,"img":false}]}
{"op":"mcm","clk":"1349885551","pt":1588410401994,"mc":[{"id":"1.170370562","rc":[{"atb":[[2.22,105.13]],"id":9625043}],"con":true,"img":false}]}
{"op":"mcm","clk":"1349885638","pt":1588410405503,"mc":[{"id":"1.170370562","rc":[{"atb":[[2.14,0]],"id":9625043},{"atb":[[1.54,0]],"id":9631798}],"con":true,"img":false}]}
{"op":"mcm","clk":"1349885742","pt":1588410410492,"mc":[{"id":"1.170370562","rc":[{"atl":[[1.69,2]],"id":9631798}],"con":true,"img":false}]}
{"op":"mcm","clk":"1349885756","pt":1588410411107,"mc":[{"id":"1.170370562","rc":[{"atb":[[1.65,91.8]],"id":9631798}],"con":true,"img":false}]}
{"op":"mcm","clk":"1349885779","pt":1588410412290,"mc":[{"id":"1.170370562","rc":[{"atb":[[1.54,39.99]],"id":9631798}],"con":true,"img":false}]}
{"op":"mcm","clk":"1349885785","pt":1588410412497,"mc":[{"id":"1.170370562","rc":[{"atb":[[2.14,39.99]],"id":9625043}],"con":true,"img":false}]}
{"op":"mcm","clk":"1349885903","pt":1588410418110,"mc":[{"id":"1.170370562","rc":[{"atb":[[2.14,0]],"id":9625043},{"atb":[[1.54,0]],"id":9631798}],"con":true,"img":false}]}
{"op":"mcm","clk":"1349886042","pt":1588410424588,"mc":[{"id":"1.170370562","rc":[{"atb":[[1.54,39.99]],"id":9631798}],"con":true,"img":false}]}
{"op":"mcm","clk":"1349886049","pt":1588410424796,"mc":[{"id":"1.170370562","rc":[{"atb":[[2.14,39.99]],"id":9625043}],"con":true,"img":false}]}
{"op":"mcm","clk":"1349886073","pt":1588410426143,"mc":[{"id":"1.170370562","rc":[{"atl":[[1.69,0]],"id":9631798}],"con":true,"img":false}]}
{"op":"mcm","clk":"1349886087","pt":1588410427015,"mc":[{"id":"1.170370562","rc":[{"atb":[[1.65,132.71]],"id":9631798}],"con":true,"img":false}]}
{"op":"mcm","clk":"1349886160","pt":1588410430930,"mc":[{"id":"1.170370562","rc":[{"atb":[[2.14,0]],"id":9625043},{"atb":[[1.54,0]],"id":9631798}],"con":true,"img":false}]}
{"op":"mcm","clk":"1349886273","pt":1588410436404,"mc":[{"id":"1.170370562","rc":[{"atb":[[1.54,39.99]],"id":9631798}],"con":true,"img":false}]}
{"op":"mcm","clk":"1349886279","pt":1588410436611,"mc":[{"id":"1.170370562","rc":[{"atb":[[2.14,39.99]],"id":9625043}],"con":true,"img":false}]}
{"op":"mcm","clk":"1349886295","pt":1588410437331,"mc":[{"id":"1.170370562","rc":[{"atb":[[1.77,2]],"id":9631798}],"con":true,"img":false}]}
{"op":"mcm","clk":"1349886308","pt":1588410438157,"mc":[{"id":"1.170370562","rc":[{"atb":[[2.22,83.34]],"id":9625043}],"con":true,"img":false}]}
{"op":"mcm","clk":"1349886314","pt":1588410438312,"mc":[{"id":"1.170370562","rc":[{"atb":[[2.14,0]],"id":9625043},{"atb":[[1.54,0]],"id":9631798}],"con":true,"img":false}]}
{"op":"mcm","clk":"1349886501","pt":1588410447964,"mc":[{"id":"1.170370562","rc":[{"atb":[[1.54,39.99]],"id":9631798}],"con":true,"img":false}]}
{"op":"mcm","clk":"1349886506","pt":1588410448119,"mc":[{"id":"1.170370562","rc":[{"atb":[[2.14,39.99]],"id":9625043}],"con":true,"img":false}]}
{"op":"mcm","clk":"1349886637","pt":1588410454062,"mc":[{"id":"1.170370562","rc":[{"atb":[[2.14,0]],"id":9625043},{"atb":[[1.54,0]],"id":9631798}],"con":true,"img":false}]}
{"op":"mcm","clk":"1349886735","pt":1588410457678,"mc":[{"id":"1.170370562","rc":[{"atb":[[1.77,0]],"id":9631798}],"con":true,"img":false}]}
{"op":"mcm","clk":"1349886745","pt":1588410458040,"mc":[{"id":"1.170370562","rc":[{"atb":[[2.22,105.13]],"id":9625043}],"con":true,"img":false}]}
{"op":"mcm","clk":"1349886790","pt":1588410460050,"mc":[{"id":"1.170370562","rc":[{"atb":[[1.54,39.99]],"id":9631798}],"con":true,"img":false}]}
{"op":"mcm","clk":"1349886793","pt":1588410460258,"mc":[{"id":"1.170370562","rc":[{"atb":[[2.14,39.99]],"id":9625043}],"con":true,"img":false}]}
{"op":"mcm","clk":"1349886959","pt":1588410466571,"mc":[{"id":"1.170370562","rc":[{"atb":[[2.14,0]],"id":9625043},{"atb":[[1.54,0]],"id":9631798}],"con":true,"img":false}]}
{"op":"mcm","clk":"1349887034","pt":1588410470085,"mc":[{"id":"1.170370562","rc":[{"atl":[[1.69,2]],"id":9631798}],"con":true,"img":false}]}
{"op":"mcm","clk":"1349887072","pt":1588410471172,"mc":[{"id":"1.170370562","rc":[{"atb":[[1.65,91.8]],"id":9631798}],"con":true,"img":false}]}
{"op":"mcm","clk":"1349887112","pt":1588410473189,"mc":[{"id":"1.170370562","rc":[{"atb":[[1.54,39.99]],"id":9631798}],"con":true,"img":false}]}
{"op":"mcm","clk":"1349887117","pt":1588410473396,"mc":[{"id":"1.170370562","rc":[{"atb":[[2.14,39.99]],"id":9625043}],"con":true,"img":false}]}
{"op":"mcm","clk":"1349887204","pt":1588410477784,"mc":[{"id":"1.170370562","rc":[{"atb":[[2.22,21.79]],"id":9625043},{"trd":[[1.69,4.31]],"ltp":1.69,"tv":4.31,"id":9631798},{"atl":[[1.69,0]],"id":9631798}],"con":true,"img":false}]}
{"op":"mcm","clk":"1349887208","pt":1588410477888,"mc":[{"id":"1.170370562","rc":[{"atb":[[1.66,117.02]],"id":9631798}],"con":true,"img":false}]}
{"op":"mcm","clk":"1349887230","pt":1588410479078,"mc":[{"id":"1.170370562","rc":[{"atb":[[2.22,0],[2.2,22.16]],"id":9625043},{"atb":[[1.66,157.31]],"id":9631798}],"con":true,"img":false}]}
{"op":"mcm","clk":"1349887232","pt":1588410479181,"mc":[{"id":"1.170370562","rc":[{"atb":[[2.14,0]],"id":9625043},{"atb":[[1.54,0]],"id":9631798}],"con":true,"img":false}]}
{"op":"mcm","clk":"1349887345","pt":1588410484701,"mc":[{"id":"1.170370562","rc":[{"atb":[[1.66,197.3]],"id":9631798}],"con":true,"img":false}]}
{"op":"mcm","clk":"1349887349","pt":1588410484909,"mc":[{"id":"1.170370562","rc":[{"atb":[[1.99,39.99]],"id":9625043},{"atb":[[1.78,2]],"id":9631798}],"con":true,"img":false}]}
{"op":"mcm","clk":"1349887351","pt":1588410485116,"mc":[{"id":"1.170370562","rc":[{"atb":[[1.66,80.28]],"id":9631798}],"con":true,"img":false}]}
{"op":"mcm","clk":"1349887367","pt":1588410486110,"mc":[{"id":"1.170370562","rc":[{"atb":[[2.12,0],[2.2,0]],"id":9625043}],"con":true,"img":false}]}
{"op":"mcm","clk":"1349887451","pt":1588410490300,"mc":[{"id":"1.170370562","rc":[{"atb":[[1.99,0]],"id":9625043},{"atb":[[1.66,40.29]],"id":9631798}],"con":true,"img":false}]}
{"op":"mcm","clk":"1349887462","pt":1588410490978,"mc":[{"id":"1.170370562","rc":[{"atb":[[1.66,0],[1.65,132.71]],"id":9631798}],"con":true,"img":false}]}
{"op":"mcm","clk":"1349887510","pt":1588410492789,"mc":[{"id":"1.170370562","rc":[{"atb":[[1.78,0]],"id":9631798}],"con":true,"img":false}]}
{"op":"mcm","clk":"1349887517","pt":1588410492997,"mc":[{"id":"1.170370562","rc":[{"atb":[[1.66,117.02]],"id":9631798}],"con":true,"img":false}]}
{"op":"mcm","clk":"1349887539","pt":1588410494034,"mc":[{"id":"1.170370562","rc":[{"atb":[[2.2,22.16]],"id":9625043}],"con":true,"img":false}]}
{"op":"mcm","clk":"1349887544","pt":1588410494087,"mc":[{"id":"1.170370562","rc":[{"atb":[[1.59,0]],"id":9631798}],"con":true,"img":false}]}
{"op":"mcm","clk":"1349887564","pt":1588410495018,"mc":[{"id":"1.170370562","rc":[{"atb":[[1.66,157.31]],"id":9631798}],"con":true,"img":false}]}
{"op":"mcm","clk":"1349887582","pt":1588410495896,"mc":[{"id":"1.170370562","rc":[{"atb":[[1.66,197.3]],"id":9631798}],"con":true,"img":false}]}
{"op":"mcm","clk":"1349887586","pt":1588410496105,"mc":[{"id":"1.170370562","rc":[{"atb":[[1.99,39.99]],"id":9625043}],"con":true,"img":false}]}
{"op":"mcm","clk":"1349887643","pt":1588410498626,"mc":[{"id":"1.170370562","rc":[{"atb":[[1.99,0]],"id":9625043},{"atb":[[1.66,157.31]],"id":9631798}],"con":true,"img":false}]}
{"op":"mcm","clk":"1349887664","pt":1588410499712,"mc":[{"id":"1.170370562","rc":[{"atl":[[1.7,2]],"id":9631798}],"con":true,"img":false}]}
{"op":"mcm","clk":"1349887668","pt":1588410500023,"mc":[{"id":"1.170370562","rc":[{"atb":[[1.6,44.32],[1.66,117.02],[1.65,91.8]],"id":9631798}],"con":true,"img":false}]}
{"op":"mcm","clk":"1349887878","pt":1588410507804,"mc":[{"id":"1.170370562","rc":[{"atl":[[1.7,0]],"id":9631798}],"con":true,"img":false}]}
{"op":"mcm","clk":"1349887885","pt":1588410508008,"mc":[{"id":"1.170370562","rc":[{"atb":[[1.66,157.01]],"id":9631798}],"con":true,"img":false}]}
{"op":"mcm","clk":"1349887890","pt":1588410508214,"mc":[{"id":"1.170370562","rc":[{"atb":[[1.99,39.99]],"id":9625043}],"con":true,"img":false}]}
{"op":"mcm","clk":"1349887906","pt":1588410509033,"mc":[{"id":"1.170370562","rc":[{"atb":[[1.66,197.3]],"id":9631798}],"con":true,"img":false}]}
{"op":"mcm","clk":"1349888032","pt":1588410514824,"mc":[{"id":"1.170370562","rc":[{"atb":[[1.99,0]],"id":9625043},{"atb":[[1.66,157.31]],"id":9631798}],"con":true,"img":false}]}
{"op":"mcm","clk":"1349888116","pt":1588410517794,"mc":[{"id":"1.170370562","rc":[{"atb":[[1.78,2]],"id":9631798}],"con":true,"img":false}]}
{"op":"mcm","clk":"1349888119","pt":1588410518003,"mc":[{"id":"1.170370562","rc":[{"atb":[[1.66,40.29]],"id":9631798}],"con":true,"img":false}]}
{"op":"mcm","clk":"1349888145","pt":1588410518979,"mc":[{"id":"1.170370562","rc":[{"atb":[[2.2,0]],"id":9625043},{"atb":[[1.66,0],[1.65,132.71]],"id":9631798}],"con":true,"img":false}]}
{"op":"mcm","clk":"1349888182","pt":1588410520918,"mc":[{"id":"1.170370562","rc":[{"atb":[[1.66,39.99]],"id":9631798}],"con":true,"img":false}]}
{"op":"mcm","clk":"1349888185","pt":1588410521125,"mc":[{"id":"1.170370562","rc":[{"atb":[[1.99,39.99]],"id":9625043}],"con":true,"img":false}]}
{"op":"mcm","clk":"1349888206","pt":1588410522100,"mc":[{"id":"1.170370562","rc":[{"atb":[[1.6,0]],"id":9631798}],"con":true,"img":false}]}
{"op":"mcm","clk":"1349888227","pt":1588410523019,"mc":[{"id":"1.170370562","rc":[{"atb":[[1.66,80.28]],"id":9631798}],"con":true,"img":false}]}
{"op":"mcm","clk":"1349888326","pt":1588410528137,"mc":[{"id":"1.170370562","rc":[{"atb":[[1.99,0]],"id":9625043},{"atb":[[1.66,40.29]],"id":9631798}],"con":true,"img":false}]}
{"op":"mcm","clk":"1349888349","pt":1588410529211,"mc":[{"id":"1.170370562","rc":[{"atb":[[1.66,0]],"id":9631798}],"con":true,"img":false}]}
{"op":"mcm","clk":"1349888413","pt":1588410531829,"mc":[{"id":"1.170370562","rc":[{"atb":[[1.78,0]],"id":9631798}],"con":true,"img":false}]}
{"op":"mcm","clk":"1349888416","pt":1588410532032,"mc":[{"id":"1.170370562","rc":[{"atb":[[1.68,115.61]],"id":9631798}],"con":true,"img":false}]}
{"op":"mcm","clk":"1349888436","pt":1588410533004,"mc":[{"id":"1.170370562","rc":[{"atb":[[2.2,22.16]],"id":9625043},{"atb":[[1.68,154.72]],"id":9631798}],"con":true,"img":false}]}
{"op":"mcm","clk":"1349888468","pt":1588410534233,"mc":[{"id":"1.170370562","rc":[{"atb":[[1.66,39.99]],"id":9631798}],"con":true,"img":false}]}
{"op":"mcm","clk":"1349888475","pt":1588410534437,"mc":[{"id":"1.170370562","rc":[{"atb":[[1.99,39.99]],"id":9625043}],"con":true,"img":false}]}
{"op":"mcm","clk":"1349888565","pt":1588410538823,"mc":[{"id":"1.170370562","rc":[{"atl":[[1.71,2]],"id":9631798}],"con":true,"img":false}]}
{"op":"mcm","clk":"1349888591","pt":1588410540047,"mc":[{"id":"1.170370562","rc":[{"atb":[[1.62,42.89]],"id":9631798}],"con":true,"img":false}]}
{"op":"mcm","clk":"1349888592","pt":1588410540153,"mc":[{"id":"1.170370562","rc":[{"atb":[[1.99,0]],"id":9625043},{"atb":[[1.68,115.61],[1.66,0],[1.65,91.8]],"id":9631798}],"con":true,"img":false}]}
{"op":"mcm","clk":"1349888750","pt":1588410547050,"mc":[{"id":"1.170370562","rc":[{"atb":[[1.66,39.99]],"id":9631798}],"con":true,"img":false}]}
{"op":"mcm","clk":"1349888756","pt":1588410547254,"mc":[{"id":"1.170370562","rc":[{"atb":[[1.99,39.99]],"id":9625043}],"con":true,"img":false}]}
{"op":"mcm","clk":"1349888772","pt":1588410548143,"mc":[{"id":"1.170370562","rc":[{"atl":[[1.71,0]],"id":9631798}],"con":true,"img":false}]}
{"op":"mcm","clk":"1349888787","pt":1588410549062,"mc":[{"id":"1.170370562","rc":[{"atb":[[1.68,154.72]],"id":9631798}],"con":true,"img":false}]}
{"op":"mcm","clk":"1349888861","pt":1588410553159,"mc":[{"id":"1.170370562","rc":[{"atb":[[1.99,0]],"id":9625043},{"atb":[[1.66,0]],"id":9631798}],"con":true,"img":false}]}
{"op":"mcm","clk":"1349888898","pt":1588410554849,"mc":[{"id":"1.170370562","rc":[{"atb":[[1.8,2]],"id":9631798}],"con":true,"img":false}]}
{"op":"mcm","clk":"1349888905","pt":1588410555157,"mc":[{"id":"1.170370562","rc":[{"atb":[[1.68,39.11]],"id":9631798}],"con":true,"img":false}]}
{"op":"mcm","clk":"1349888922","pt":1588410556075,"mc":[{"id":"1.170370562","rc":[{"atb":[[2.2,0]],"id":9625043},{"atb":[[1.68,0],[1.65,132.71]],"id":9631798}],"con":true,"img":false}]}
{"op":"mcm","clk":"1349889917","pt":1588410559871,"mc":[{"id":"1.170370562","rc":[{"atb":[[1.66,39.99]],"id":9631798}],"con":true,"img":false}]}
{"op":"mcm","clk":"1349889922","pt":1588410560077,"mc":[{"id":"1.170370562","rc":[{"atb":[[1.99,39.99]],"id":9625043}],"con":true,"img":false}]}
{"op":"mcm","clk":"1349889972","pt":1588410562179,"mc":[{"id":"1.170370562","rc":[{"atb":[[1.62,0]],"id":9631798}],"con":true,"img":false}]}
{"op":"mcm","clk":"1349889990","pt":1588410563052,"mc":[{"id":"1.170370562","rc":[{"atb":[[1.66,80.28]],"id":9631798}],"con":true,"img":false}]}
{"op":"mcm","clk":"1349890055","pt":1588410566070,"mc":[{"id":"1.170370562","rc":[{"atb":[[1.99,0]],"id":9625043},{"atb":[[1.66,40.29]],"id":9631798}],"con":true,"img":false}]}
{"op":"mcm","clk":"1349890072","pt":1588410567093,"mc":[{"id":"1.170370562","rc":[{"atb":[[1.66,0]],"id":9631798}],"con":true,"img":false}]}
{"op":"mcm","clk":"1349890090","pt":1588410568066,"mc":[{"id":"1.170370562","rc":[{"atb":[[1.8,0]],"id":9631798}],"con":true,"img":false}]}
{"op":"mcm","clk":"1349890094","pt":1588410568270,"mc":[{"id":"1.170370562","rc":[{"atb":[[1.66,117.02]],"id":9631798}],"con":true,"img":false}]}
{"op":"mcm","clk":"1349890110","pt":1588410569086,"mc":[{"id":"1.170370562","rc":[{"atb":[[2.2,22.16]],"id":9625043},{"atb":[[1.66,157.31]],"id":9631798}],"con":true,"img":false}]}
{"op":"mcm","clk":"1349890170","pt":1588410571856,"mc":[{"id":"1.170370562","rc":[{"atb":[[1.66,197.3]],"id":9631798}],"con":true,"img":false}]}
{"op":"mcm","clk":"1349890174","pt":1588410572061,"mc":[{"id":"1.170370562","rc":[{"atb":[[1.99,39.99]],"id":9625043}],"con":true,"img":false}]}
{"op":"mcm","clk":"1349890248","pt":1588410575905,"mc":[{"id":"1.170370562","rc":[{"atl":[[1.7,2]],"id":9631798}],"con":true,"img":false}]}
{"op":"mcm","clk":"1349890272","pt":1588410576981,"mc":[{"id":"1.170370562","rc":[{"atb":[[1.6,44.32],[1.66,157.01],[1.65,91.8]],"id":9631798}],"con":true,"img":false}]}
{"op":"mcm","clk":"1349890283","pt":1588410577592,"mc":[{"id":"1.170370562","rc":[{"atb":[[1.99,0]],"id":9625043},{"atb":[[1.66,117.02]],"id":9631798}],"con":true,"img":false}]}
{"op":"mcm","clk":"1349890293","pt":1588410578005,"mc":[{"id":"1.170370562","rc":[{"atb":[[1.68,221.63]],"id":9631798}],"con":true,"img":false}]}
{"op":"mcm","clk":"1349890300","pt":1588410578207,"mc":[{"id":"1.170370562","rc":[{"atb":[[1.66,0]],"id":9631798}],"con":true,"img":false}]}
{"op":"mcm","clk":"1349890303","pt":1588410578308,"mc":[{"id":"1.170370562","rc":[{"atb":[[1.69,114.92]],"id":9631798}],"con":true,"img":false}]}
{"op":"mcm","clk":"1349890318","pt":1588410579084,"mc":[{"id":"1.170370562","rc":[{"atb":[[1.63,42.21]],"id":9631798}],"con":true,"img":false}]}
{"op":"mcm","clk":"1349890370","pt":1588410581177,"mc":[{"id":"1.170370562","rc":[{"atb":[[1.68,0]],"id":9631798}],"con":true,"img":false}]}
{"op":"mcm","clk":"1349890372","pt":1588410581279,"mc":[{"id":"1.170370562","rc":[{"trd":[[1.7,4]],"ltp":1.7,"tv":4.0,"id":9631798},{"atb":[[1.7,219.62]],"id":9631798},{"atl":[[1.7,0]],"id":9631798}],"con":true,"img":false}]}
{"op":"mcm","clk":"1349890378","pt":1588410581486,"mc":[{"id":"1.170370562","rc":[{"atb":[[1.69,0]],"id":9631798}],"con":true,"img":false}]}
{"op":"mcm","clk":"1349890388","pt":1588410582099,"mc":[{"id":"1.170370562","rc":[{"atb":[[1.6,0]],"id":9631798}],"con":true,"img":false}]}
{"op":"mcm","clk":"1349890402","pt":1588410582916,"mc":[{"id":"1.170370562","rc":[{"atb":[[1.66,39.99]],"id":9631798}],"con":true,"img":false}]}
{"op":"mcm","clk":"1349890406","pt":1588410582972,"mc":[{"id":"1.170370562","rc":[{"atb":[[1.7,257.62]],"id":9631798}],"con":true,"img":false}]}
{"op":"mcm","clk":"1349890411","pt":1588410583077,"mc":[{"id":"1.170370562","rc":[{"atb":[[1.99,39.99]],"id":9625043}],"con":true,"img":false}]}
{"op":"mcm","clk":"1349890435","pt":1588410583795,"mc":[{"id":"1.170370562","rc":[{"atb":[[1.7,37.99]],"id":9631798}],"con":true,"img":false}]}
{"op":"mcm","clk":"1349890436","pt":1588410583896,"mc":[{"id":"1.170370562","rc":[{"atb":[[1.68,219.62]],"id":9631798}],"con":true,"img":false}]}
{"op":"mcm","clk":"1349890467","pt":1588410585079,"mc":[{"id":"1.170370562","rc":[{"atb":[[1.7,0],[1.68,258.74]],"id":9631798}],"con":true,"img":false}]}
{"op":"mcm","clk":"1349890475","pt":1588410585284,"mc":[{"id":"1.170370562","rc":[{"atb":[[1.69,114.92]],"id":9631798}],"con":true,"img":false}]}
{"op":"mcm","clk":"1349890492","pt":1588410586205,"mc":[{"id":"1.170370562","rc":[{"atb":[[1.63,0]],"id":9631798}],"con":true,"img":false}]}
{"op":"mcm","clk":"1349890500","pt":1588410586612,"mc":[{"id":"1.170370562","rc":[{"atl":[[1.71,2]],"id":9631798}],"con":true,"img":false}]}
{"op":"mcm","clk":"1349890508","pt":1588410586976,"mc":[{"id":"1.170370562","rc":[{"atb":[[1.63,42.21]],"id":9631798}],"con":true,"img":false}]}
{"op":"mcm","clk":"1349890510","pt":1588410587080,"mc":[{"id":"1.170370562","rc":[{"atb":[[1.68,219.62]],"id":9631798}],"con":true,"img":false}]}
{"op":"mcm","clk":"1349890548","pt":1588410589023,"mc":[{"id":"1.170370562","rc":[{"atl":[[1.8,88.65]],"id":9631798}],"con":true,"img":false}]}
{"op":"mcm","clk":"1349890572","pt":1588410590001,"mc":[{"id":"1.170370562","rc":[{"atb":[[1.99,0],[2.22,21.79]],"id":9625043},{"atb":[[1.66,0]],"id":9631798}],"con":true,"img":false}]}
{"op":"mcm","clk":"1349890680","pt":1588410595894,"mc":[{"id":"1.170370562","rc":[{"atl":[[1.71,0]],"id":9631798}],"con":true,"img":false}]}
{"op":"mcm","clk":"1349890682","pt":1588410595998,"mc":[{"id":"1.170370562","rc":[{"atb":[[1.66,39.99]],"id":9631798}],"con":true,"img":false}]}
{"op":"mcm","clk":"1349890688","pt":1588410596203,"mc":[{"id":"1.170370562","rc":[{"atb":[[1.99,39.99]],"id":9625043}],"con":true,"img":false}]}
{"op":"mcm","clk":"1349890712","pt":1588410597124,"mc":[{"id":"1.170370562","rc":[{"atb":[[1.68,258.74]],"id":9631798}],"con":true,"img":false}]}
{"op":"mcm","clk":"1349890817","pt":1588410602324,"mc":[{"id":"1.170370562","rc":[{"atb":[[1.99,0]],"id":9625043},{"atb":[[1.66,0]],"id":9631798}],"con":true,"img":false}]}
{"op":"mcm","clk":"1349890841","pt":1588410603243,"mc":[{"id":"1.170370562","rc":[{"atb":[[1.7,22.85]],"id":9631798}],"con":true,"img":false}]}
{"op":"mcm","clk":"1349890847","pt":1588410603511,"mc":[{"id":"1.170370562","rc":[{"atb":[[1.69,0]],"id":9631798}],"con":true,"img":false}]}
{"op":"mcm","clk":"1349890861","pt":1588410604122,"mc":[{"id":"1.170370562","rc":[{"atb":[[2.24,21.44]],"id":9625043}],"con":true,"img":false}]}
{"op":"mcm","clk":"1349890898","pt":1588410605531,"mc":[{"id":"1.170370562","rc":[{"atb":[[1.7,0]],"id":9631798}],"con":true,"img":false}]}
{"op":"mcm","clk":"1349890902","pt":1588410605632,"mc":[{"id":"1.170370562","rc":[{"atb":[[1.69,22.85]],"id":9631798}],"con":true,"img":false}]}
{"op":"mcm","clk":"1349890907","pt":1588410605739,"mc":[{"id":"1.170370562","rc":[{"atb":[[1.69,137.77]],"id":9631798}],"con":true,"img":false}]}
{"op":"mcm","clk":"1349890911","pt":1588410605838,"mc":[{"id":"1.170370562","rc":[{"atb":[[1.78,2]],"id":9631798}],"con":true,"img":false}]}
{"op":"mcm","clk":"1349890920","pt":1588410606147,"mc":[{"id":"1.170370562","rc":[{"atb":[[1.69,22.85]],"id":9631798}],"con":true,"img":false}]}
{"op":"mcm","clk":"1349890925","pt":1588410606252,"mc":[{"id":"1.170370562","rc":[{"atb":[[2.24,0]],"id":9625043}],"con":true,"img":false}]}
{"op":"mcm","clk":"1349890943","pt":1588410607137,"mc":[{"id":"1.170370562","rc":[{"atb":[[2.22,0],[2.2,0],[2.14,23.33]],"id":9625043}],"con":true,"img":false}]}
{"op":"mcm","clk":"1349890954","pt":1588410607747,"mc":[{"id":"1.170370562","rc":[{"atb":[[1.66,39.99]],"id":9631798}],"con":true,"img":false}]}
{"op":"mcm","clk":"1349890966","pt":1588410607952,"mc":[{"id":"1.170370562","rc":[{"atb":[[1.99,39.99]],"id":9625043}],"con":true,"img":false}]}
{"op":"mcm","clk":"1349891031","pt":1588410609855,"mc":[{"id":"1.170370562","rc":[{"atb":[[1.5,31.99]],"id":9631798}],"con":true,"img":false}]}
{"op":"mcm","clk":"1349891038","pt":1588410610018,"mc":[{"id":"1.170370562","rc":[{"atb":[[1.5,63.98]],"id":9631798}],"con":true,"img":false}]}
{"op":"mcm","clk":"1349891149","pt":1588410614953,"mc":[{"id":"1.170370562","rc":[{"atb":[[1.99,0]],"id":9625043},{"atb":[[1.66,0]],"id":9631798}],"con":true,"img":false}]}
{"op":"mcm","clk":"1349891174","pt":1588410616141,"mc":[{"id":"1.170370562","rc":[{"atb":[[1.78,0]],"id":9631798}],"con":true,"img":false}]}
{"op":"mcm","clk":"1349891178","pt":1588410616342,"mc":[{"id":"1.170370562","rc":[{"atb":[[1.69,137.77]],"id":9631798}],"con":true,"img":false}]}
{"op":"mcm","clk":"1349891193","pt":1588410617059,"mc":[{"id":"1.170370562","rc":[{"atb":[[2.22,21.79]],"id":9625043}],"con":true,"img":false}]}
{"op":"mcm","clk":"1349891306","pt":1588410621441,"mc":[{"id":"1.170370562","rc":[{"atb":[[1.66,39.99]],"id":9631798}],"con":true,"img":false}]}
{"op":"mcm","clk":"1349891310","pt":1588410621646,"mc":[{"id":"1.170370562","rc":[{"atb":[[1.99,39.99]],"id":9625043}],"con":true,"img":false}]}
{"op":"mcm","clk":"1349891332","pt":1588410622767,"mc":[{"id":"1.170370562","rc":[{"atb":[[1.71,67.59]],"id":9625043}],"con":true,"img":false}]}
{"op":"mcm","clk":"1349891335","pt":1588410622971,"mc":[{"id":"1.170370562","rc":[{"atb":[[1.71,90.12]],"id":9625043}],"con":true,"img":false}]}
{"op":"mcm","clk":"1349891408","pt":1588410626056,"mc":[{"id":"1.170370562","rc":[{"atb":[[1.5,95.98]],"id":9631798}],"con":true,"img":false}]}
{"op":"mcm","clk":"1349891430","pt":1588410627244,"mc":[{"id":"1.170370562","rc":[{"atb":[[1.99,0]],"id":9625043},{"atb":[[1.66,0]],"id":9631798}],"con":true,"img":false}]}
{"op":"mcm","clk":"1349891447","pt":1588410627758,"mc":[{"id":"1.170370562","rc":[{"atb":[[1.68,39.11]],"id":9631798}],"con":true,"img":false}]}
{"op":"mcm","clk":"1349891452","pt":1588410627861,"mc":[{"id":"1.170370562","rc":[{"atb":[[1.7,219.62]],"id":9631798}],"con":true,"img":false}]}
{"op":"mcm","clk":"1349891460","pt":1588410628167,"mc":[{"id":"1.170370562","rc":[{"atb":[[1.69,22.85]],"id":9631798}],"con":true,"img":false}]}
{"op":"mcm","clk":"1349891538","pt":1588410631655,"mc":[{"id":"1.170370562","rc":[{"atb":[[1.69,0]],"id":9631798}],"con":true,"img":false}]}
{"op":"mcm","clk":"1349891540","pt":1588410631756,"mc":[{"id":"1.170370562","rc":[{"atb":[[1.66,22.85]],"id":9631798}],"con":true,"img":false}]}
{"op":"mcm","clk":"1349891564","pt":1588410633089,"mc":[{"id":"1.170370562","rc":[{"atb":[[1.66,62.84]],"id":9631798}],"con":true,"img":false}]}
{"op":"mcm","clk":"1349891570","pt":1588410633292,"mc":[{"id":"1.170370562","rc":[{"atb":[[1.99,39.99]],"id":9625043}],"con":true,"img":false}]}
{"op":"mcm","clk":"1349891574","pt":1588410633394,"mc":[{"id":"1.170370562","rc":[{"atb":[[1.77,2]],"id":9631798}],"con":true,"img":false}]}
{"op":"mcm","clk":"1349891597","pt":1588410634168,"mc":[{"id":"1.170370562","rc":[{"atb":[[2.22,0]],"id":9625043}],"con":true,"img":false}]}
{"op":"mcm","clk":"1349891754","pt":1588410640371,"mc":[{"id":"1.170370562","rc":[{"atb":[[1.99,0]],"id":9625043},{"atb":[[1.66,22.85]],"id":9631798}],"con":true,"img":false}]}
{"op":"mcm","clk":"1349891861","pt":1588410645094,"mc":[{"id":"1.170370562","rc":[{"atb":[[1.77,0]],"id":9631798}],"con":true,"img":false}]}
{"op":"mcm","clk":"1349891893","pt":1588410646075,"mc":[{"id":"1.170370562","rc":[{"atb":[[2.22,21.79]],"id":9625043}],"con":true,"img":false}]}
{"op":"mcm","clk":"1349891903","pt":1588410646590,"mc":[{"id":"1.170370562","rc":[{"atb":[[1.66,62.84]],"id":9631798}],"con":true,"img":false}]}
{"op":"mcm","clk":"1349891906","pt":1588410646795,"mc":[{"id":"1.170370562","rc":[{"atb":[[1.99,39.99]],"id":9625043}],"con":true,"img":false}]}
{"op":"mcm","clk":"1349892016","pt":1588410651675,"mc":[{"id":"1.170370562","rc":[{"atl":[[1.72,2]],"id":9631798}],"con":true,"img":false}]}
{"op":"mcm","clk":"1349892027","pt":1588410652087,"mc":[{"id":"1.170370562","rc":[{"atb":[[1.64,41.56],[1.68,0]],"id":9631798}],"con":true,"img":false}]}
{"op":"mcm","clk":"1349892047","pt":1588410653007,"mc":[{"id":"1.170370562","rc":[{"atb":[[1.99,0]],"id":9625043},{"atb":[[1.66,22.85]],"id":9631798}],"con":true,"img":false}]}
{"op":"mcm","clk":"1349892238","pt":1588410659223,"mc":[{"id":"1.170370562","rc":[{"atb":[[1.66,62.84]],"id":9631798}],"con":true,"img":false}]}
{"op":"mcm","clk":"1349892248","pt":1588410659429,"mc":[{"id":"1.170370562","rc":[{"atb":[[1.99,39.99]],"id":9625043}],"con":true,"img":false}]}
{"op":"mcm","clk":"1349892261","pt":1588410659898,"mc":[{"id":"1.170370562","rc":[{"atl":[[1.72,0]],"id":9631798}],"con":true,"img":false}]}
{"op":"mcm","clk":"1349892294","pt":1588410661129,"mc":[{"id":"1.170370562","rc":[{"atb":[[1.63,0]],"id":9631798}],"con":true,"img":false}]}
{"op":"mcm","clk":"1349892318","pt":1588410662005,"mc":[{"id":"1.170370562","rc":[{"atb":[[1.68,39.11]],"id":9631798}],"con":true,"img":false}]}
{"op":"mcm","clk":"1349892399","pt":1588410665616,"mc":[{"id":"1.170370562","rc":[{"atb":[[1.99,0]],"id":9625043},{"atb":[[1.66,22.85]],"id":9631798}],"con":true,"img":false}]}
{"op":"mcm","clk":"1349892520","pt":1588410669997,"mc":[{"id":"1.170370562","rc":[{"atb":[[1.78,2]],"id":9631798}],"con":true,"img":false}]}
{"op":"mcm","clk":"1349892555","pt":1588410671237,"mc":[{"id":"1.170370562","rc":[{"atb":[[2.22,0]],"id":9625043}],"con":true,"img":false}]}
{"op":"mcm","clk":"1349892565","pt":1588410671450,"mc":[{"id":"1.170370562","rc":[{"atb":[[1.66,62.84]],"id":9631798}],"con":true,"img":false}]}
{"op":"mcm","clk":"1349892573","pt":1588410671605,"mc":[{"id":"1.170370562","rc":[{"atb":[[1.99,39.99]],"id":9625043}],"con":true,"img":false}]}
{"op":"mcm","clk":"1349892768","pt":1588410679640,"mc":[{"id":"1.170370562","rc":[{"atb":[[1.99,0]],"id":9625043},{"atb":[[1.66,22.85]],"id":9631798}],"con":true,"img":false}]}
{"op":"mcm","clk":"1349892911","pt":1588410685259,"mc":[{"id":"1.170370562","rc":[{"atb":[[1.78,0]],"id":9631798}],"con":true,"img":false}]}
{"op":"mcm","clk":"1349892935","pt":1588410686138,"mc":[{"id":"1.170370562","rc":[{"atb":[[2.22,21.79]],"id":9625043}],"con":true,"img":false}]}
{"op":"mcm","clk":"1349892973","pt":1588410687641,"mc":[{"id":"1.170370562","rc":[{"atb":[[1.66,62.84]],"id":9631798}],"con":true,"img":false}]}
{"op":"mcm","clk":"1349892979","pt":1588410687845,"mc":[{"id":"1.170370562","rc":[{"atb":[[1.99,39.99]],"id":9625043}],"con":true,"img":false}]}
{"op":"mcm","clk":"1349893020","pt":1588410689443,"mc":[{"id":"1.170370562","rc":[{"atl":[[1.72,2]],"id":9631798}],"con":true,"img":false}]}
{"op":"mcm","clk":"1349893042","pt":1588410690263,"mc":[{"id":"1.170370562","rc":[{"atb":[[1.68,0]],"id":9631798}],"con":true,"img":false}]}
{"op":"mcm","clk":"1349893240","pt":1588410698145,"mc":[{"id":"1.170370562","rc":[{"atl":[[1.72,0]],"id":9631798}],"con":true,"img":false}]}
{"op":"mcm","clk":"1349893270","pt":1588410699174,"mc":[{"id":"1.170370562","rc":[{"atb":[[1.68,39.11]],"id":9631798}],"con":true,"img":false}]}
{"op":"mcm","clk":"1349893387","pt":1588410704389,"mc":[{"id":"1.170370562","rc":[{"atb":[[1.78,2]],"id":9631798}],"con":true,"img":false}]}
{"op":"mcm","clk":"1349893411","pt":1588410705299,"mc":[{"id":"1.170370562","rc":[{"atb":[[2.22,0]],"id":9625043}],"con":true,"img":false}]}
{"op":"mcm","clk":"1349893728","pt":1588410719585,"mc":[{"id":"1.170370562","rc":[{"atb":[[1.78,0]],"id":9631798}],"con":true,"img":false}]}
{"op":"mcm","clk":"1349893741","pt":1588410720103,"mc":[{"id":"1.170370562","rc":[{"atb":[[2.22,21.79]],"id":9625043}],"con":true,"img":false}]}
{"op":"mcm","clk":"1349893942","pt":1588410726799,"mc":[{"id":"1.170370562","rc":[{"atl":[[1.72,2]],"id":9631798}],"con":true,"img":false}]}
{"op":"mcm","clk":"1349893952","pt":1588410727209,"mc":[{"id":"1.170370562","rc":[{"atb":[[1.68,0]],"id":9631798}],"con":true,"img":false}]}
{"op":"mcm","clk":"1349894199","pt":1588410735826,"mc":[{"id":"1.170370562","rc":[{"atl":[[1.72,0]],"id":9631798}],"con":true,"img":false}]}
{"op":"mcm","clk":"1349894206","pt":1588410736135,"mc":[{"id":"1.170370562","rc":[{"atb":[[1.68,39.11]],"id":9631798}],"con":true,"img":false}]}
{"op":"mcm","clk":"1349894301","pt":1588410739991,"mc":[{"id":"1.170370562","rc":[{"atb":[[1.99,0]],"id":9625043},{"atb":[[1.66,22.85]],"id":9631798}],"con":true,"img":false}]}
{"op":"mcm","clk":"1349894365","pt":1588410742889,"mc":[{"id":"1.170370562","rc":[{"atb":[[1.66,62.84]],"id":9631798}],"con":true,"img":false}]}
{"op":"mcm","clk":"1349894370","pt":1588410743092,"mc":[{"id":"1.170370562","rc":[{"atb":[[1.99,39.99]],"id":9625043}],"con":true,"img":false}]}
{"op":"mcm","clk":"1349894394","pt":1588410744178,"mc":[{"id":"1.170370562","rc":[{"atb":[[1.78,2]],"id":9631798}],"con":true,"img":false}]}
{"op":"mcm","clk":"1349894419","pt":1588410745270,"mc":[{"id":"1.170370562","rc":[{"atb":[[2.22,0]],"id":9625043}],"con":true,"img":false}]}
{"op":"mcm","clk":"1349894830","pt":1588410761590,"mc":[{"id":"1.170370562","rc":[{"atb":[[1.78,0]],"id":9631798}],"con":true,"img":false}]}
{"op":"mcm","clk":"1349894844","pt":1588410762104,"mc":[{"id":"1.170370562","rc":[{"atb":[[2.22,21.79]],"id":9625043}],"con":true,"img":false}]}
{"op":"mcm","clk":"1349895051","pt":1588410769798,"mc":[{"id":"1.170370562","rc":[{"atl":[[1.72,2]],"id":9631798}],"con":true,"img":false}]}
{"op":"mcm","clk":"1349895062","pt":1588410770109,"mc":[{"id":"1.170370562","rc":[{"atb":[[1.68,0]],"id":9631798}],"con":true,"img":false}]}
{"op":"mcm","clk":"1349895351","pt":1588410781350,"mc":[{"id":"1.170370562","rc":[{"atl":[[1.72,0]],"id":9631798}],"con":true,"img":false}]}
{"op":"mcm","clk":"1349895368","pt":1588410782123,"mc":[{"id":"1.170370562","rc":[{"atb":[[1.68,39.11]],"id":9631798}],"con":true,"img":false}]}
{"op":"mcm","clk":"1349895552","pt":1588410788824,"mc":[{"id":"1.170370562","rc":[{"atb":[[1.78,2]],"id":9631798}],"con":true,"img":false}]}
{"op":"mcm","clk":"1349895560","pt":1588410789131,"mc":[{"id":"1.170370562","rc":[{"atb":[[2.22,0]],"id":9625043}],"con":true,"img":false}]}
{"op":"mcm","clk":"1349895787","pt":1588410800264,"mc":[{"id":"1.170370562","rc":[{"atb":[[1.99,0]],"id":9625043},{"atb":[[1.66,22.85]],"id":9631798}],"con":true,"img":false}]}
{"op":"mcm","clk":"1349895794","pt":1588410800572,"mc":[{"id":"1.170370562","rc":[{"atb":[[1.78,0]],"id":9631798}],"con":true,"img":false}]}
{"op":"mcm","clk":"1349895807","pt":1588410801144,"mc":[{"id":"1.170370562","rc":[{"atb":[[2.22,21.79]],"id":9625043}],"con":true,"img":false}]}
{"op":"mcm","clk":"1349895882","pt":1588410804545,"mc":[{"id":"1.170370562","rc":[{"atb":[[1.66,62.84]],"id":9631798}],"con":true,"img":false}]}
{"op":"mcm","clk":"1349895886","pt":1588410804748,"mc":[{"id":"1.170370562","rc":[{"atb":[[1.99,39.99]],"id":9625043}],"con":true,"img":false}]}
{"op":"mcm","clk":"1349895996","pt":1588410809080,"mc":[{"id":"1.170370562","rc":[{"atl":[[1.72,2]],"id":9631798}],"con":true,"img":false}]}
{"op":"mcm","clk":"1349896043","pt":1588410810169,"mc":[{"id":"1.170370562","rc":[{"atb":[[1.68,0]],"id":9631798}],"con":true,"img":false}]}
{"op":"mcm","clk":"1349896300","pt":1588410819492,"mc":[{"id":"1.170370562","rc":[{"atl":[[1.72,0]],"id":9631798}],"con":true,"img":false}]}
{"op":"mcm","clk":"1349896323","pt":1588410820111,"mc":[{"id":"1.170370562","rc":[{"atb":[[1.68,39.11]],"id":9631798}],"con":true,"img":false}]}
{"op":"mcm","clk":"1349896465","pt":1588410825607,"mc":[{"id":"1.170370562","rc":[{"atb":[[1.78,2]],"id":9631798}],"con":true,"img":false}]}
{"op":"mcm","clk":"1349896481","pt":1588410826175,"mc":[{"id":"1.170370562","rc":[{"atb":[[2.22,0]],"id":9625043}],"con":true,"img":false}]}
{"op":"mcm","clk":"1349896522","pt":1588410827871,"mc":[{"id":"1.170370562","rc":[{"atb":[[1.72,2.46]],"id":9631798}],"con":true,"img":false}]}
{"op":"mcm","clk":"1349896786","pt":1588410839617,"mc":[{"id":"1.170370562","rc":[{"atb":[[1.78,0]],"id":9631798}],"con":true,"img":false}]}
{"op":"mcm","clk":"1349896798","pt":1588410840132,"mc":[{"id":"1.170370562","rc":[{"atb":[[2.22,21.79]],"id":9625043}],"con":true,"img":false}]}
{"op":"mcm","clk":"1349896900","pt":1588410844349,"mc":[{"id":"1.170370562","rc":[{"atl":[[1.74,2]],"id":9631798}],"con":true,"img":false}]}
{"op":"mcm","clk":"1349896919","pt":1588410845129,"mc":[{"id":"1.170370562","rc":[{"atb":[[1.66,103.13]],"id":9631798}],"con":true,"img":false}]}
{"op":"mcm","clk":"1349896924","pt":1588410845231,"mc":[{"id":"1.170370562","rc":[{"atb":[[1.68,0]],"id":9631798}],"con":true,"img":false}]}
{"op":"mcm","clk":"1349897152","pt":1588410855614,"mc":[{"id":"1.170370562","rc":[{"atl":[[1.74,0]],"id":9631798}],"con":true,"img":false}]}
{"op":"mcm","clk":"1349897158","pt":1588410855822,"mc":[{"id":"1.170370562","rc":[{"atb":[[1.72,0]],"id":9631798}],"con":true,"img":false}]}
{"op":"mcm","clk":"1349897163","pt":1588410855924,"mc":[{"id":"1.170370562","rc":[{"atb":[[1.74,2.46]],"id":9631798}],"con":true,"img":false}]}
{"op":"mcm","clk":"1349897171","pt":1588410856231,"mc":[{"id":"1.170370562","rc":[{"atb":[[1.64,0]],"id":9631798}],"con":true,"img":false}]}
{"op":"mcm","clk":"1349897198","pt":1588410857112,"mc":[{"id":"1.170370562","rc":[{"atb":[[1.68,39.11]],"id":9631798}],"con":true,"img":false}]}
{"op":"mcm","clk":"1349897283","pt":1588410860518,"mc":[{"id":"1.170370562","rc":[{"atb":[[1.99,0]],"id":9625043},{"atb":[[1.66,63.14]],"id":9631798}],"con":true,"img":false}]}
{"op":"mcm","clk":"1349897342","pt":1588410863147,"mc":[{"id":"1.170370562","rc":[{"atb":[[1.78,2]],"id":9631798}],"con":true,"img":false}]}
{"op":"mcm","clk":"1349897370","pt":1588410864129,"mc":[{"id":"1.170370562","rc":[{"atb":[[2.22,0]],"id":9625043}],"con":true,"img":false}]}
{"op":"mcm","clk":"1349897380","pt":1588410864540,"mc":[{"id":"1.170370562","rc":[{"atb":[[1.66,103.13]],"id":9631798}],"con":true,"img":false}]}
{"op":"mcm","clk":"1349897382","pt":1588410864741,"mc":[{"id":"1.170370562","rc":[{"atb":[[1.99,39.99]],"id":9625043}],"con":true,"img":false}]}
{"op":"mcm","clk":"1349897701","pt":1588410877974,"mc":[{"id":"1.170370562","rc":[{"atb":[[1.78,0]],"id":9631798}],"con":true,"img":false}]}
{"op":"mcm","clk":"1349897732","pt":1588410879168,"mc":[{"id":"1.170370562","rc":[{"atb":[[2.22,21.79]],"id":9625043}],"con":true,"img":false}]}
{"op":"mcm","clk":"1349897846","pt":1588410883758,"mc":[{"id":"1.170370562","rc":[{"atl":[[1.76,2]],"id":9631798}],"con":true,"img":false}]}
{"op":"mcm","clk":"1349898103","pt":1588410894580,"mc":[{"id":"1.170370562","rc":[{"atl":[[2.36,27.62]],"id":9625043}],"con":true,"img":false}]}
{"op":"mcm","clk":"1349898118","pt":1588410895095,"mc":[{"id":"1.170370562","rc":[{"atb":[[2.2,22.16]],"id":9625043}],"con":true,"img":false}]}
{"op":"mcm","clk":"1349898125","pt":1588410895302,"mc":[{"id":"1.170370562","rc":[{"atb":[[2.22,0]],"id":9625043}],"con":true,"img":false}]}
{"op":"mcm","clk":"1349898231","pt":1588410899965,"mc":[{"id":"1.170370562","rc":[{"atl":[[1.76,0]],"id":9631798}],"con":true,"img":false}]}
{"op":"mcm","clk":"1349898268","pt":1588410901207,"mc":[{"id":"1.170370562","rc":[{"atb":[[1.66,62.84]],"id":9631798}],"con":true,"img":false}]}
{"op":"mcm","clk":"1349898292","pt":1588410902096,"mc":[{"id":"1.170370562","rc":[{"atb":[[1.7,257.62]],"id":9631798}],"con":true,"img":false}]}
{"op":"mcm","clk":"1349898325","pt":1588410903499,"mc":[{"id":"1.170370562","rc":[{"atb":[[1.7,37.99]],"id":9631798},{"atl":[[1.8,0]],"id":9631798}],"con":true,"img":false}]}
{"op":"mcm","clk":"1349898348","pt":1588410904184,"mc":[{"id":"1.170370562","rc":[{"atb":[[2.18,22.53]],"id":9625043}],"con":true,"img":false}]}
{"op":"mcm","clk":"1349898354","pt":1588410904288,"mc":[{"id":"1.170370562","rc":[{"atb":[[2.2,0]],"id":9625043},{"atb":[[1.68,0]],"id":9631798}],"con":true,"img":false}]}
{"op":"mcm","clk":"1349898383","pt":1588410905072,"mc":[{"id":"1.170370562","rc":[{"atb":[[1.72,36.94]],"id":9631798}],"con":true,"img":false}]}
{"op":"mcm","clk":"1349898390","pt":1588410905281,"mc":[{"id":"1.170370562","rc":[{"atb":[[1.79,2]],"id":9631798}],"con":true,"img":false}]}
{"op":"mcm","clk":"1349898785","pt":1588410920834,"mc":[{"id":"1.170370562","rc":[{"atb":[[1.99,0]],"id":9625043},{"atb":[[1.79,0],[1.66,22.85]],"id":9631798}],"con":true,"img":false}]}
{"op":"mcm","clk":"1349898882","pt":1588410924460,"mc":[{"id":"1.170370562","rc":[{"atb":[[1.66,62.84]],"id":9631798}],"con":true,"img":false}]}
{"op":"mcm","clk":"1349898889","pt":1588410924668,"mc":[{"id":"1.170370562","rc":[{"atb":[[1.99,39.99]],"id":9625043}],"con":true,"img":false}]}
{"op":"mcm","clk":"1349899016","pt":1588410928550,"mc":[{"id":"1.170370562","rc":[{"atl":[[1.76,2]],"id":9631798}],"con":true,"img":false}]}
{"op":"mcm","clk":"1349899031","pt":1588410929170,"mc":[{"id":"1.170370562","rc":[{"atb":[[1.68,39.11]],"id":9631798}],"con":true,"img":false}]}
{"op":"mcm","clk":"1349899035","pt":1588410929276,"mc":[{"id":"1.170370562","rc":[{"atb":[[1.7,0],[1.72,0]],"id":9631798}],"con":true,"img":false}]}
{"op":"mcm","clk":"1349899303","pt":1588410938575,"mc":[{"id":"1.170370562","rc":[{"atl":[[1.76,0]],"id":9631798}],"con":true,"img":false}]}
{"op":"mcm","clk":"1349899325","pt":1588410939142,"mc":[{"id":"1.170370562","rc":[{"atb":[[1.72,36.94]],"id":9631798}],"con":true,"img":false}]}
{"op":"mcm","clk":"1349899455","pt":1588410943780,"mc":[{"id":"1.170370562","rc":[{"atb":[[1.81,2]],"id":9631798}],"con":true,"img":false}]}
{"op":"mcm","clk":"1349899468","pt":1588410944142,"mc":[{"id":"1.170370562","rc":[{"atb":[[2.18,0],[2.14,0]],"id":9625043}],"con":true,"img":false}]}
{"op":"mcm","clk":"1349899707","pt":1588410953873,"mc":[{"id":"1.170370562","rc":[{"atb":[[1.81,0]],"id":9631798}],"con":true,"img":false}]}
{"op":"mcm","clk":"1349899716","pt":1588410954180,"mc":[{"id":"1.170370562","rc":[{"atb":[[2.18,22.53]],"id":9625043}],"con":true,"img":false}]}
{"op":"mcm","clk":"1349899830","pt":1588410958475,"mc":[{"id":"1.170370562","rc":[{"atl":[[1.76,2]],"id":9631798}],"con":true,"img":false}]}
{"op":"mcm","clk":"1349899853","pt":1588410959295,"mc":[{"id":"1.170370562","rc":[{"atb":[[1.72,0]],"id":9631798}],"con":true,"img":false}]}
{"op":"mcm","clk":"1349899949","pt":1588410963095,"mc":[{"id":"1.170370562","rc":[{"trd":[[1.76,4]],"ltp":1.76,"tv":4.0,"id":9631798},{"atb":[[1.76,0.65]],"id":9631798},{"atl":[[1.76,0]],"id":9631798}],"con":true,"img":false}]}
{"op":"mcm","clk":"1349899974","pt":1588410964179,"mc":[{"id":"1.170370562","rc":[{"atb":[[1.72,36.94]],"id":9631798}],"con":true,"img":false}]}
{"op":"mcm","clk":"1349900193","pt":1588410973792,"mc":[{"id":"1.170370562","rc":[{"atb":[[1.74,0]],"id":9631798}],"con":true,"img":false}]}
{"op":"mcm","clk":"1349900342","pt":1588410978713,"mc":[{"id":"1.170370562","rc":[{"trd":[[1.76,5.31]],"ltp":1.76,"tv":5.31,"id":9631798},{"atb":[[1.76,0]],"id":9631798},{"atl":[[1.76,1.34]],"id":9631798}],"con":true,"img":false}]}
{"op":"mcm","clk":"1349900359","pt":1588410979227,"mc":[{"id":"1.170370562","rc":[{"atb":[[1.68,0],[1.72,0],[1.67,39.69]],"id":9631798}],"con":true,"img":false}]}
{"op":"mcm","clk":"1349900364","pt":1588410979432,"mc":[{"id":"1.170370562","rc":[{"atb":[[1.68,115.61]],"id":9631798}],"con":true,"img":false}]}
{"op":"mcm","clk":"1349900394","pt":1588410980617,"mc":[{"id":"1.170370562","rc":[{"atb":[[1.41,0]],"id":9631798}],"con":true,"img":false}]}
{"op":"mcm","clk":"1349900398","pt":1588410980719,"mc":[{"id":"1.170370562","rc":[{"atb":[[1.42,236.68]],"id":9631798}],"con":true,"img":false}]}
{"op":"mcm","clk":"1349900408","pt":1588410981129,"mc":[{"id":"1.170370562","rc":[{"atb":[[1.99,0]],"id":9625043},{"atb":[[1.66,22.85]],"id":9631798}],"con":true,"img":false}]}
{"op":"mcm","clk":"1349900414","pt":1588410981539,"mc":[{"id":"1.170370562","rc":[{"atb":[[1.5,0]],"id":9631798}],"con":true,"img":false}]}
{"op":"mcm","clk":"1349900647","pt":1588410989916,"mc":[{"id":"1.170370562","rc":[{"atl":[[1.76,0]],"id":9631798}],"con":true,"img":false}]}
{"op":"mcm","clk":"1349900657","pt":1588410990224,"mc":[{"id":"1.170370562","rc":[{"atb":[[1.72,36.94]],"id":9631798}],"con":true,"img":false}]}
{"op":"mcm","clk":"1349900659","pt":1588410990428,"mc":[{"id":"1.170370562","rc":[{"atb":[[1.68,0]],"id":9631798}],"con":true,"img":false}]}
{"op":"mcm","clk":"1349900784","pt":1588410996118,"mc":[{"id":"1.170370562","rc":[{"atb":[[1.81,2]],"id":9631798}],"con":true,"img":false}]}
{"op":"mcm","clk":"1349900811","pt":1588410997246,"mc":[{"id":"1.170370562","rc":[{"atb":[[2.18,0]],"id":9625043}],"con":true,"img":false}]}
{"op":"mcm","clk":"1349900837","pt":1588410998118,"mc":[{"id":"1.170370562","rc":[{"atb":[[1.41,2.02]],"id":9625043}],"con":true,"img":false}]}
{"op":"mcm","clk":"1349901055","pt":1588411005354,"mc":[{"id":"1.170370562","rc":[{"atl":[[1.82,0.71]],"id":9631798}],"con":true,"img":false}]}
{"op":"mcm","clk":"1349901062","pt":1588411005559,"mc":[{"id":"1.170370562","rc":[{"atb":[[1.81,0]],"id":9631798}],"con":true,"img":false}]}
{"op":"mcm","clk":"1349901094","pt":1588411006227,"mc":[{"id":"1.170370562","rc":[{"atb":[[2.18,22.53]],"id":9625043}],"con":true,"img":false}]}
{"op":"mcm","clk":"1349901345","pt":1588411015977,"mc":[{"id":"1.170370562","rc":[{"atl":[[1.75,2]],"id":9631798}],"con":true,"img":false}]}
{"op":"mcm","clk":"1349901377","pt":1588411017261,"mc":[{"id":"1.170370562","rc":[{"atb":[[1.72,0]],"id":9631798}],"con":true,"img":false}]}
{"op":"mcm","clk":"1349901383","pt":1588411017466,"mc":[{"id":"1.170370562","rc":[{"atb":[[1.68,115.61]],"id":9631798}],"con":true,"img":false}]}
{"op":"mcm","clk":"1349901561","pt":1588411024344,"mc":[{"id":"1.170370562","rc":[{"atl":[[1.75,0]],"id":9631798}],"con":true,"img":false}]}
{"op":"mcm","clk":"1349901584","pt":1588411025274,"mc":[{"id":"1.170370562","rc":[{"atb":[[1.72,36.94]],"id":9631798}],"con":true,"img":false}]}
{"op":"mcm","clk":"1349901591","pt":1588411025482,"mc":[{"id":"1.170370562","rc":[{"atb":[[1.68,0]],"id":9631798}],"con":true,"img":false}]}
{"op":"mcm","clk":"1349901712","pt":1588411029968,"mc":[{"id":"1.170370562","rc":[{"atb":[[1.81,2]],"id":9631798}],"con":true,"img":false}]}
{"op":"mcm","clk":"1349901747","pt":1588411031255,"mc":[{"id":"1.170370562","rc":[{"atb":[[2.18,0]],"id":9625043}],"con":true,"img":false}]}
{"op":"mcm","clk":"1349901942","pt":1588411038671,"mc":[{"id":"1.170370562","rc":[{"atb":[[1.81,0]],"id":9631798}],"con":true,"img":false}]}
{"op":"mcm","clk":"1349901956","pt":1588411039184,"mc":[{"id":"1.170370562","rc":[{"atb":[[2.18,22.53]],"id":9625043}],"con":true,"img":false}]}
{"op":"mcm","clk":"1349902074","pt":1588411043786,"mc":[{"id":"1.170370562","rc":[{"atl":[[1.75,2]],"id":9631798}],"con":true,"img":false}]}
{"op":"mcm","clk":"1349902089","pt":1588411044302,"mc":[{"id":"1.170370562","rc":[{"atb":[[1.72,0]],"id":9631798}],"con":true,"img":false}]}
{"op":"mcm","clk":"1349902093","pt":1588411044508,"mc":[{"id":"1.170370562","rc":[{"atb":[[1.68,115.61]],"id":9631798}],"con":true,"img":false}]}
{"op":"mcm","clk":"1349902292","pt":1588411052121,"mc":[{"id":"1.170370562","rc":[{"atl":[[1.82,1.77]],"id":9631798}],"con":true,"img":false}]}
{"op":"mcm","clk":"1349902373","pt":1588411056200,"mc":[{"id":"1.170370562","rc":[{"atl":[[1.75,0]],"id":9631798}],"con":true,"img":false}]}
{"op":"mcm","clk":"1349902392","pt":1588411057232,"mc":[{"id":"1.170370562","rc":[{"atb":[[1.72,36.94]],"id":9631798}],"con":true,"img":false}]}
{"op":"mcm","clk":"1349902402","pt":1588411057494,"mc":[{"id":"1.170370562","rc":[{"atb":[[1.68,0]],"id":9631798}],"con":true,"img":false}]}
{"op":"mcm","clk":"1349902508","pt":1588411061415,"mc":[{"id":"1.170370562","rc":[{"trd":[[1.83,5.03],[1.82,3.55]],"ltp":1.83,"tv":8.58,"id":9631798},{"atl":[[1.82,0],[1.83,21.47]],"id":9631798}],"con":true,"img":false}]}
{"op":"mcm","clk":"1349902981","pt":1588411078266,"mc":[{"id":"1.170370562","rc":[{"atb":[[1.7,0.71]],"id":9631798}],"con":true,"img":false}]}
{"op":"mcm","clk":"1349903044","pt":1588411080387,"mc":[{"id":"1.170370562","rc":[{"atl":[[1.75,2]],"id":9631798}],"con":true,"img":false}]}
{"op":"mcm","clk":"1349903070","pt":1588411081275,"mc":[{"id":"1.170370562","rc":[{"atb":[[1.72,0]],"id":9631798}],"con":true,"img":false}]}
{"op":"mcm","clk":"1349903078","pt":1588411081475,"mc":[{"id":"1.170370562","rc":[{"atb":[[1.68,115.61]],"id":9631798}],"con":true,"img":false}]}
{"op":"mcm","clk":"1349903359","pt":1588411090968,"mc":[{"id":"1.170370562","rc":[{"atl":[[1.75,0]],"id":9631798}],"con":true,"img":false}]}
{"op":"mcm","clk":"1349903371","pt":1588411091793,"mc":[{"id":"1.170370562","rc":[{"atb":[[1.7,1.77]],"id":9631798}],"con":true,"img":false}]}
{"op":"mcm","clk":"1349903380","pt":1588411092101,"mc":[{"id":"1.170370562","rc":[{"atb":[[1.68,0]],"id":9631798}],"con":true,"img":false}]}
{"op":"mcm","clk":"1349903383","pt":1588411092157,"mc":[{"id":"1.170370562","rc":[{"atb":[[1.72,36.94]],"id":9631798}],"con":true,"img":false}]}
{"op":"mcm","clk":"1349903752","pt":1588411104576,"mc":[{"id":"1.170370562","rc":[{"atb":[[1.81,2]],"id":9631798}],"con":true,"img":false}]}
{"op":"mcm","clk":"1349903767","pt":1588411105407,"mc":[{"id":"1.170370562","rc":[{"atb":[[2.18,0]],"id":9625043}],"con":true,"img":false}]}
{"op":"mcm","clk":"1349904046","pt":1588411116512,"mc":[{"id":"1.170370562","rc":[{"atb":[[1.7,0.71]],"id":9631798}],"con":true,"img":false}]}
{"op":"mcm","clk":"1349904245","pt":1588411123494,"mc":[{"id":"1.170370562","rc":[{"atb":[[1.81,0]],"id":9631798}],"con":true,"img":false}]}
{"op":"mcm","clk":"1349904263","pt":1588411124318,"mc":[{"id":"1.170370562","rc":[{"atb":[[2.18,22.53]],"id":9625043}],"con":true,"img":false}]}
{"op":"mcm","clk":"1349904390","pt":1588411129427,"mc":[{"id":"1.170370562","rc":[{"atb":[[1.1,124.78]],"id":9625043}],"con":true,"img":false}]}
{"op":"mcm","clk":"1349904492","pt":1588411133036,"mc":[{"id":"1.170370562","rc":[{"atb":[[1.67,40.76]],"id":9631798}],"con":true,"img":false}]}
{"op":"mcm","clk":"1349904858","pt":1588411146260,"mc":[{"id":"1.170370562","rc":[{"atb":[[1.71,1.77]],"id":9631798}],"con":true,"img":false}]}
{"op":"mcm","clk":"1349904877","pt":1588411147141,"mc":[{"id":"1.170370562","rc":[{"atb":[[1.1,126.57]],"id":9625043}],"con":true,"img":false}]}
{"op":"mcm","clk":"1349904984","pt":1588411151268,"mc":[{"id":"1.170370562","rc":[{"atb":[[1.61,1.77]],"id":9631798}],"con":true,"img":false}]}
{"op":"mcm","clk":"1349905018","pt":1588411152661,"mc":[{"id":"1.170370562","rc":[{"atb":[[1.51,1.77]],"id":9631798}],"con":true,"img":false}]}
{"op":"mcm","clk":"1349905049","pt":1588411154055,"mc":[{"id":"1.170370562","rc":[{"atb":[[1.1,123.38]],"id":9625043}],"con":true,"img":false}]}
{"op":"mcm","clk":"1349905626","pt":1588411175774,"mc":[{"id":"1.170370562","rc":[{"atb":[[1.1,121.58]],"id":9625043}],"con":true,"img":false}]}
{"op":"mcm","clk":"1349905633","pt":1588411175878,"mc":[{"id":"1.170370562","rc":[{"atb":[[2.2,1.79]],"id":9625043}],"con":true,"img":false}]}
{"op":"mcm","clk":"1349906165","pt":1588411196026,"mc":[{"id":"1.170370562","rc":[{"atb":[[2.22,2.62]],"id":9625043}],"con":true,"img":false}]}
{"op":"mcm","clk":"1349909989","pt":1588411322867,"mc":[{"id":"1.170370562","rc":[{"trd":[[2.36,0.39]],"ltp":2.36,"tv":0.39,"id":9625043},{"atl":[[2.36,27.23]],"id":9625043},{"trd":[[1.73,142.37]],"ltp":1.73,"tv":142.37,"id":9631798}],"con":true,"img":false}]}
{"op":"mcm","clk":"1349911204","pt":1588411364323,"mc":[{"id":"1.170370562","rc":[{"atb":[[1.1,122.11]],"id":9631798}],"con":true,"img":false}]}
{"op":"mcm","clk":"1349913538","pt":1588411455277,"mc":[{"id":"1.170370562","rc":[{"atb":[[1.7,0]],"id":9631798}],"con":true,"img":false}]}
{"op":"mcm","clk":"1349914779","pt":1588411469276,"mc":[{"id":"1.170370562","rc":[{"atb":[[1.67,41.47]],"id":9631798}],"con":true,"img":false}]}
{"op":"mcm","clk":"1349915969","pt":1588411524771,"mc":[{"id":"1.170370562","rc":[{"trd":[[2.36,10.64]],"ltp":2.36,"tv":10.64,"id":9625043},{"atl":[[2.36,22.1]],"id":9625043}],"con":true,"img":false}]}
{"op":"mcm","clk":"1349915997","pt":1588411525958,"mc":[{"id":"1.170370562","rc":[{"atb":[[1.77,5]],"id":9631798}],"con":true,"img":false}]}
{"op":"mcm","clk":"1349916245","pt":1588411538189,"mc":[{"id":"1.170370562","rc":[{"atb":[[1.75,5]],"id":9625043}],"con":true,"img":false}]}
{"op":"mcm","clk":"1349918984","pt":1588411669306,"mc":[{"id":"1.170370562","rc":[{"atl":[[1.82,15]],"id":9631798}],"con":true,"img":false}]}
{"op":"mcm","clk":"1349922637","pt":1588411864387,"mc":[{"id":"1.170370562","rc":[{"trd":[[1.77,0.2]],"ltp":1.77,"tv":0.2,"id":9631798},{"atb":[[1.77,4.9]],"id":9631798}],"con":true,"img":false}]}
{"op":"mcm","clk":"1349925402","pt":1588412073021,"mc":[{"id":"1.170370562","rc":[{"trd":[[1.77,5.44]],"ltp":1.77,"tv":5.44,"id":9631798},{"atb":[[1.77,2.28]],"id":9631798}],"con":true,"img":false}]}
{"op":"mcm","clk":"1349926103","pt":1588412129522,"mc":[{"id":"1.170370562","rc":[{"trd":[[2.3,0.2]],"ltp":2.3,"tv":0.2,"id":9625043},{"trd":[[1.77,5.71]],"ltp":1.77,"tv":5.71,"id":9631798},{"atb":[[1.77,2.01]],"id":9631798}],"con":true,"img":false}]}
{"op":"mcm","clk":"1349926634","pt":1588412167666,"mc":[{"id":"1.170370562","marketDefinition":{"bspMarket":false,"turnInPlayEnabled":true,"persistenceEnabled":true,"marketBaseRate":5.0,"eventId":"29788105","eventTypeId":"2","numberOfWinners":1,"bettingType":"ODDS","marketType":"MATCH_ODDS","marketTime":"2020-05-02T09:45:00.000Z","suspendTime":"2020-05-02T09:45:00.000Z","bspReconciled":false,"complete":true,"inPlay":false,"crossMatching":true,"runnersVoidable":false,"numberOfActiveRunners":2,"betDelay":0,"status":"OPEN","runners":[{"status":"ACTIVE","sortPriority":1,"id":9631798,"name":"B Hassan"},{"status":"ACTIVE","sortPriority":2,"id":9625043,"name":"J Haerteis"}],"regulators":["MR_INT"],"countryCode":"GB","discountAllowed":true,"timezone":"GMT","openDate":"2020-05-02T09:40:00.000Z","version":3237478306,"name":"Match Odds","eventName":"B Hassan v J Haerteis"},"rc":[],"con":true,"img":false}]}
{"op":"mcm","clk":"1349926700","pt":1588412171668,"mc":[{"id":"1.170370562","marketDefinition":{"bspMarket":false,"turnInPlayEnabled":true,"persistenceEnabled":true,"marketBaseRate":5.0,"eventId":"29788105","eventTypeId":"2","numberOfWinners":1,"bettingType":"ODDS","marketType":"MATCH_ODDS","marketTime":"2020-05-02T09:45:00.000Z","suspendTime":"2020-05-02T09:45:00.000Z","bspReconciled":false,"complete":true,"inPlay":false,"crossMatching":true,"runnersVoidable":false,"numberOfActiveRunners":2,"betDelay":0,"status":"OPEN","runners":[{"status":"ACTIVE","sortPriority":1,"id":9631798,"name":"B Hassan"},{"status":"ACTIVE","sortPriority":2,"id":9625043,"name":"J Haerteis"}],"regulators":["MR_INT"],"countryCode":"GB","discountAllowed":true,"timezone":"GMT","openDate":"2020-05-02T09:45:00.000Z","version":3237478306,"name":"Match Odds","eventName":"B Hassan v J Haerteis"},"rc":[],"con":true,"img":false}]}
{"op":"mcm","clk":"1349927675","pt":1588412249336,"mc":[{"id":"1.170370562","rc":[{"trd":[[1.77,8.63]],"ltp":1.77,"tv":8.63,"id":9631798},{"atb":[[1.77,0.55]],"id":9631798}],"con":true,"img":false}]}
{"op":"mcm","clk":"1349928730","pt":1588412327171,"mc":[{"id":"1.170370562","rc":[{"trd":[[2.36,17.57]],"ltp":2.36,"tv":17.57,"id":9625043},{"atl":[[2.36,15.17]],"id":9625043},{"trd":[[1.73,151.82],[1.77,9.73]],"ltp":1.73,"tv":161.54,"id":9631798},{"atb":[[1.77,0]],"id":9631798}],"con":true,"img":false}]}
{"op":"mcm","clk":"1349928732","pt":1588412327681,"mc":[{"id":"1.170370562","rc":[{"atb":[[2.2,23.96]],"id":9625043},{"atb":[[1.72,0]],"id":9631798}],"con":true,"img":false}]}
{"op":"mcm","clk":"1349928833","pt":1588412336784,"mc":[{"id":"1.170370562","rc":[{"trd":[[1.82,4.41]],"ltp":1.82,"tv":4.41,"id":9631798},{"atl":[[1.82,14.57]],"id":9631798}],"con":true,"img":false}]}
{"op":"mcm","clk":"1349930763","pt":1588412408015,"mc":[{"id":"1.170370562","marketDefinition":{"bspMarket":false,"turnInPlayEnabled":true,"persistenceEnabled":true,"marketBaseRate":5.0,"eventId":"29788105","eventTypeId":"2","numberOfWinners":1,"bettingType":"ODDS","marketType":"MATCH_ODDS","marketTime":"2020-05-02T09:50:00.000Z","suspendTime":"2020-05-02T09:50:00.000Z","bspReconciled":false,"complete":true,"inPlay":false,"crossMatching":true,"runnersVoidable":false,"numberOfActiveRunners":2,"betDelay":0,"status":"OPEN","runners":[{"status":"ACTIVE","sortPriority":1,"id":9631798,"name":"B Hassan"},{"status":"ACTIVE","sortPriority":2,"id":9625043,"name":"J Haerteis"}],"regulators":["MR_INT"],"countryCode":"GB","discountAllowed":true,"timezone":"GMT","openDate":"2020-05-02T09:45:00.000Z","version":3237478643,"name":"Match Odds","eventName":"B Hassan v J Haerteis"},"rc":[],"con":true,"img":false}]}
{"op":"mcm","clk":"1349930815","pt":1588412411022,"mc":[{"id":"1.170370562","marketDefinition":{"bspMarket":false,"turnInPlayEnabled":true,"persistenceEnabled":true,"marketBaseRate":5.0,"eventId":"29788105","eventTypeId":"2","numberOfWinners":1,"bettingType":"ODDS","marketType":"MATCH_ODDS","marketTime":"2020-05-02T09:50:00.000Z","suspendTime":"2020-05-02T09:50:00.000Z","bspReconciled":false,"complete":true,"inPlay":false,"crossMatching":true,"runnersVoidable":false,"numberOfActiveRunners":2,"betDelay":0,"status":"OPEN","runners":[{"status":"ACTIVE","sortPriority":1,"id":9631798,"name":"B Hassan"},{"status":"ACTIVE","sortPriority":2,"id":9625043,"name":"J Haerteis"}],"regulators":["MR_INT"],"countryCode":"GB","discountAllowed":true,"timezone":"GMT","openDate":"2020-05-02T09:50:00.000Z","version":3237478643,"name":"Match Odds","eventName":"B Hassan v J Haerteis"},"rc":[],"con":true,"img":false}]}
{"op":"mcm","clk":"1349931492","pt":1588412441374,"mc":[{"id":"1.170370562","rc":[{"atb":[[2.22,155.62]],"id":9625043}],"con":true,"img":false}]}
{"op":"mcm","clk":"1349931496","pt":1588412441683,"mc":[{"id":"1.170370562","rc":[{"atb":[[2.22,177.42]],"id":9625043}],"con":true,"img":false}]}
{"op":"mcm","clk":"1349931665","pt":1588412451067,"mc":[{"id":"1.170370562","rc":[{"atb":[[2.22,126.42]],"id":9625043}],"con":true,"img":false}]}
{"op":"mcm","clk":"1349932060","pt":1588412470600,"mc":[{"id":"1.170370562","rc":[{"trd":[[2.22,0.2]],"ltp":2.22,"tv":0.2,"id":9625043},{"atb":[[2.22,126.32]],"id":9625043}],"con":true,"img":false}]}
{"op":"mcm","clk":"1349933951","pt":1588412564954,"mc":[{"id":"1.170370562","rc":[{"atb":[[1.74,4.37]],"id":9631798}],"con":true,"img":false}]}
{"op":"mcm","clk":"1349933966","pt":1588412565778,"mc":[{"id":"1.170370562","rc":[{"atb":[[1.71,39.22]],"id":9631798}],"con":true,"img":false}]}
{"op":"mcm","clk":"1349933967","pt":1588412565873,"mc":[{"id":"1.170370562","rc":[{"atb":[[2.22,104.52],[2.2,1.79]],"id":9625043}],"con":true,"img":false}]}
{"op":"mcm","clk":"1349935654","pt":1588412646022,"mc":[{"id":"1.170370562","rc":[{"atb":[[1.06,1083.33]],"id":9631798}],"con":true,"img":false}]}
{"op":"mcm","clk":"1349935669","pt":1588412646285,"mc":[{"id":"1.170370562","rc":[{"atb":[[1.05,1083.33]],"id":9631798}],"con":true,"img":false}]}
{"op":"mcm","clk":"1349935686","pt":1588412646694,"mc":[{"id":"1.170370562","rc":[{"atb":[[1.04,1083.33]],"id":9631798}],"con":true,"img":false}]}
{"op":"mcm","clk":"1349935699","pt":1588412647470,"mc":[{"id":"1.170370562","rc":[{"atb":[[1.01,1088.13]],"id":9631798}],"con":true,"img":false}]}
{"op":"mcm","clk":"1349935713","pt":1588412648299,"mc":[{"id":"1.170370562","rc":[{"atb":[[1.02,1083.54]],"id":9631798}],"con":true,"img":false}]}
{"op":"mcm","clk":"1349935728","pt":1588412648919,"mc":[{"id":"1.170370562","rc":[{"atb":[[1.03,1083.33]],"id":9631798}],"con":true,"img":false}]}
{"op":"mcm","clk":"1349937500","pt":1588412734618,"mc":[{"id":"1.170370562","rc":[{"atb":[[1.51,33.14]],"id":9631798}],"con":true,"img":false}]}
{"op":"mcm","clk":"1349938250","pt":1588412770469,"mc":[{"id":"1.170370562","rc":[{"atb":[[2.1,24.17]],"id":9625043}],"con":true,"img":false}]}
{"op":"mcm","clk":"1349938362","pt":1588412775380,"mc":[{"id":"1.170370562","rc":[{"atb":[[2.1,26.01]],"id":9625043}],"con":true,"img":false}]}
{"op":"mcm","clk":"1349940421","pt":1588412873848,"mc":[{"id":"1.170370562","rc":[{"trd":[[1.74,8.74]],"ltp":1.74,"tv":8.74,"id":9631798},{"atb":[[1.74,0]],"id":9631798},{"atl":[[1.74,157.57]],"id":9631798}],"con":true,"img":false}]}
{"op":"mcm","clk":"1349940424","pt":1588412874051,"mc":[{"id":"1.170370562","rc":[{"atb":[[1.71,150.41]],"id":9631798}],"con":true,"img":false}]}
{"op":"mcm","clk":"1349940444","pt":1588412874768,"mc":[{"id":"1.170370562","rc":[{"atb":[[2.24,21.44]],"id":9625043}],"con":true,"img":false}]}
{"op":"mcm","clk":"1349940447","pt":1588412874870,"mc":[{"id":"1.170370562","rc":[{"atb":[[1.71,112.96]],"id":9631798}],"con":true,"img":false}]}
{"op":"mcm","clk":"1349940610","pt":1588412883090,"mc":[{"id":"1.170370562","rc":[{"atl":[[1.74,0]],"id":9631798}],"con":true,"img":false}]}
{"op":"mcm","clk":"1349940614","pt":1588412883191,"mc":[{"id":"1.170370562","rc":[{"trd":[[2.36,32.75]],"ltp":2.36,"tv":32.75,"id":9625043},{"atl":[[2.36,0]],"id":9625043},{"trd":[[1.73,172.53]],"ltp":1.73,"tv":172.53,"id":9631798},{"atl":[[1.73,136.86]],"id":9631798}],"con":true,"img":false}]}
{"op":"mcm","clk":"1349940630","pt":1588412883759,"mc":[{"id":"1.170370562","rc":[{"atb":[[2.28,20.78]],"id":9625043},{"atb":[[1.66,63.14]],"id":9631798}],"con":true,"img":false}]}
{"op":"mcm","clk":"1349940634","pt":1588412883868,"mc":[{"id":"1.170370562","rc":[{"atb":[[1.67,1.77]],"id":9631798}],"con":true,"img":false}]}
{"op":"mcm","clk":"1349940803","pt":1588412891584,"mc":[{"id":"1.170370562","rc":[{"atl":[[1.73,0]],"id":9631798}],"con":true,"img":false}]}
{"op":"mcm","clk":"1349940806","pt":1588412891685,"mc":[{"id":"1.170370562","rc":[{"trd":[[1.71,240.83]],"ltp":1.71,"tv":240.83,"id":9631798},{"atb":[[1.71,0]],"id":9631798},{"atl":[[1.71,23.9]],"id":9631798}],"con":true,"img":false}]}
{"op":"mcm","clk":"1349940812","pt":1588412891888,"mc":[{"id":"1.170370562","rc":[{"trd":[[1.71,288.59]],"ltp":1.71,"tv":288.59,"id":9631798},{"atl":[[1.71,0.02]],"id":9631798}],"con":true,"img":false}]}
{"op":"mcm","clk":"1349940822","pt":1588412892298,"mc":[{"id":"1.170370562","rc":[{"trd":[[1.71,288.64]],"ltp":1.71,"tv":288.64,"id":9631798},{"atb":[[1.73,2.28]],"id":9631798},{"atl":[[1.71,0]],"id":9631798}],"con":true,"img":false}]}
{"op":"mcm","clk":"1349940831","pt":1588412892769,"mc":[{"id":"1.170370562","rc":[{"atb":[[2.22,126.32]],"id":9625043}],"con":true,"img":false}]}
{"op":"mcm","clk":"1349940833","pt":1588412892871,"mc":[{"id":"1.170370562","rc":[{"atb":[[2.24,0],[2.28,0]],"id":9625043}],"con":true,"img":false}]}
{"op":"mcm","clk":"1349940837","pt":1588412892975,"mc":[{"id":"1.170370562","rc":[{"atl":[[1000,2]],"id":9631798}],"con":true,"img":false}]}
{"op":"mcm","clk":"1349940860","pt":1588412894470,"mc":[{"id":"1.170370562","rc":[{"atl":[[1000,0.02]],"id":9631798}],"con":true,"img":false}]}
{"op":"mcm","clk":"1349940865","pt":1588412894781,"mc":[{"id":"1.170370562","rc":[{"atl":[[2.36,2.3]],"id":9625043}],"con":true,"img":false}]}
{"op":"mcm","clk":"1349940879","pt":1588412895902,"mc":[{"id":"1.170370562","rc":[{"atl":[[1000,0]],"id":9631798}],"con":true,"img":false}]}
{"op":"mcm","clk":"1349940882","pt":1588412896005,"mc":[{"id":"1.170370562","rc":[{"atl":[[1.93,0.02]],"id":9631798}],"con":true,"img":false}]}
{"op":"mcm","clk":"1349940913","pt":1588412897405,"mc":[{"id":"1.170370562","rc":[{"trd":[[2.36,35.05]],"ltp":2.36,"tv":35.05,"id":9625043},{"atl":[[2.36,0]],"id":9625043},{"trd":[[1.66,5.59],[1.73,180.23],[1.67,3.55]],"ltp":1.66,"tv":189.37,"id":9631798},{"atb":[[1.73,0],[1.67,0],[1.66,60.34]],"id":9631798}],"con":true,"img":false}]}
{"op":"mcm","clk":"1349940922","pt":1588412897920,"mc":[{"id":"1.170370562","rc":[{"atb":[[1.98,2.74]],"id":9625043},{"atb":[[1.65,132.71]],"id":9631798},{"atl":[[1.93,2.06]],"id":9631798}],"con":true,"img":false}]}
{"op":"mcm","clk":"1349940925","pt":1588412897975,"mc":[{"id":"1.170370562","rc":[{"atb":[[1.66,20.05]],"id":9631798}],"con":true,"img":false}]}
{"op":"mcm","clk":"1349940994","pt":1588412900902,"mc":[{"id":"1.170370562","rc":[{"atb":[[2.1,24.17]],"id":9625043}],"con":true,"img":false}]}
{"op":"mcm","clk":"1349941006","pt":1588412901721,"mc":[{"id":"1.170370562","rc":[{"atb":[[1.07,1083.33]],"id":9631798}],"con":true,"img":false}]}
{"op":"mcm","clk":"1349941014","pt":1588412902085,"mc":[{"id":"1.170370562","rc":[{"atb":[[1.08,1083.33]],"id":9631798},{"atl":[[1000,3.19]],"id":9631798}],"con":true,"img":false}]}
{"op":"mcm","clk":"1349941020","pt":1588412902393,"mc":[{"id":"1.170370562","rc":[{"atl":[[1000,2.58]],"id":9631798}],"con":true,"img":false}]}
{"op":"mcm","clk":"1349941028","pt":1588412902594,"mc":[{"id":"1.170370562","rc":[{"atb":[[2.1,26.01]],"id":9625043}],"con":true,"img":false}]}
{"op":"mcm","clk":"1349941031","pt":1588412902697,"mc":[{"id":"1.170370562","rc":[{"atl":[[1000,0]],"id":9631798}],"con":true,"img":false}]}
{"op":"mcm","clk":"1349941034","pt":1588412902799,"mc":[{"id":"1.170370562","rc":[{"atl":[[1.8,2.58]],"id":9631798}],"con":true,"img":false}]}
{"op":"mcm","clk":"1349941196","pt":1588412911217,"mc":[{"id":"1.170370562","rc":[{"atb":[[1.08,984.92]],"id":9625043}],"con":true,"img":false}]}
{"op":"mcm","clk":"1349941205","pt":1588412911628,"mc":[{"id":"1.170370562","rc":[{"atb":[[1.07,984.92]],"id":9625043}],"con":true,"img":false}]}
{"op":"mcm","clk":"1349941214","pt":1588412912038,"mc":[{"id":"1.170370562","rc":[{"atb":[[1.06,984.92]],"id":9625043}],"con":true,"img":false}]}
{"op":"mcm","clk":"1349941222","pt":1588412912501,"mc":[{"id":"1.170370562","rc":[{"atb":[[1.05,984.92]],"id":9625043}],"con":true,"img":false}]}
{"op":"mcm","clk":"1349941235","pt":1588412913219,"mc":[{"id":"1.170370562","rc":[{"atb":[[1.03,984.92]],"id":9625043}],"con":true,"img":false}]}
{"op":"mcm","clk":"1349941248","pt":1588412914045,"mc":[{"id":"1.170370562","rc":[{"atb":[[1.04,984.92]],"id":9625043}],"con":true,"img":false}]}
{"op":"mcm","clk":"1349941257","pt":1588412914611,"mc":[{"id":"1.170370562","rc":[{"atb":[[1.01,989.72]],"id":9625043}],"con":true,"img":false}]}
{"op":"mcm","clk":"1349941273","pt":1588412915229,"mc":[{"id":"1.170370562","rc":[{"atb":[[1.02,985.14]],"id":9625043}],"con":true,"img":false}]}
{"op":"mcm","clk":"1349941345","pt":1588412919338,"mc":[{"id":"1.170370562","rc":[{"atl":[[1.75,4]],"id":9631798}],"con":true,"img":false}]}
{"op":"mcm","clk":"1349941384","pt":1588412921748,"mc":[{"id":"1.170370562","rc":[{"atl":[[1.8,0]],"id":9631798}],"con":true,"img":false}]}
{"op":"mcm","clk":"1349941405","pt":1588412922521,"mc":[{"id":"1.170370562","rc":[{"atl":[[1000,3.19]],"id":9631798}],"con":true,"img":false}]}
{"op":"mcm","clk":"1349941414","pt":1588412922826,"mc":[{"id":"1.170370562","rc":[{"atl":[[1000,2.67]],"id":9631798}],"con":true,"img":false}]}
{"op":"mcm","clk":"1349941420","pt":1588412923135,"mc":[{"id":"1.170370562","rc":[{"atl":[[1000,0]],"id":9631798}],"con":true,"img":false}]}
{"op":"mcm","clk":"1349941423","pt":1588412923237,"mc":[{"id":"1.170370562","rc":[{"atl":[[1.74,2.67]],"id":9631798}],"con":true,"img":false}]}
{"op":"mcm","clk":"1349941588","pt":1588412931945,"mc":[{"id":"1.170370562","rc":[{"atl":[[1.73,4.37]],"id":9631798}],"con":true,"img":false}]}
{"op":"mcm","clk":"1349941605","pt":1588412932768,"mc":[{"id":"1.170370562","rc":[{"atb":[[1.6,44.32],[1.65,91.8]],"id":9631798}],"con":true,"img":false}]}
{"op":"mcm","clk":"1349941616","pt":1588412933129,"mc":[{"id":"1.170370562","rc":[{"atl":[[1.73,1.69]],"id":9631798}],"con":true,"img":false}]}
{"op":"mcm","clk":"1349941689","pt":1588412937348,"mc":[{"id":"1.170370562","rc":[{"atb":[[1.66,0]],"id":9631798}],"con":true,"img":false}]}
{"op":"mcm","clk":"1349941691","pt":1588412937448,"mc":[{"id":"1.170370562","rc":[{"atb":[[1.61,21.82]],"id":9631798}],"con":true,"img":false}]}
{"op":"mcm","clk":"1349941698","pt":1588412937859,"mc":[{"id":"1.170370562","rc":[{"atb":[[1.59,45.07],[1.6,0]],"id":9631798}],"con":true,"img":false}]}
{"op":"mcm","clk":"1349941739","pt":1588412939860,"mc":[{"id":"1.170370562","rc":[{"atb":[[1.61,1.77]],"id":9631798}],"con":true,"img":false}]}
{"op":"mcm","clk":"1349941743","pt":1588412939961,"mc":[{"id":"1.170370562","rc":[{"atb":[[1.6,20.05]],"id":9631798}],"con":true,"img":false}]}
{"op":"mcm","clk":"1349941781","pt":1588412941564,"mc":[{"id":"1.170370562","rc":[{"atl":[[1.83,0]],"id":9631798}],"con":true,"img":false}]}
{"op":"mcm","clk":"1349941820","pt":1588412943988,"mc":[{"id":"1.170370562","rc":[{"atb":[[1.66,4.37]],"id":9631798}],"con":true,"img":false}]}
{"op":"mcm","clk":"1349941833","pt":1588412944764,"mc":[{"id":"1.170370562","rc":[{"atb":[[1.6,64.37]],"id":9631798}],"con":true,"img":false}]}
{"op":"mcm","clk":"1349942295","pt":1588412971126,"mc":[{"id":"1.170370562","rc":[{"atb":[[2,0],[2.1,80.26]],"id":9625043},{"atb":[[1.67,89.06],[1.65,0]],"id":9631798}],"con":true,"img":false}]}
{"op":"mcm","clk":"1349942304","pt":1588412971899,"mc":[{"id":"1.170370562","rc":[{"atb":[[1.59,0]],"id":9631798}],"con":true,"img":false}]}
{"op":"mcm","clk":"1349942322","pt":1588412972826,"mc":[{"id":"1.170370562","rc":[{"atb":[[1.61,45.37]],"id":9631798}],"con":true,"img":false}]}
{"op":"mcm","clk":"1349942469","pt":1588412979724,"mc":[{"id":"1.170370562","rc":[{"atl":[[1.71,19.19]],"id":9631798}],"con":true,"img":false}]}
{"op":"mcm","clk":"1349942492","pt":1588412980937,"mc":[{"id":"1.170370562","rc":[{"atb":[[2.32,20.15]],"id":9625043},{"atb":[[1.6,20.05]],"id":9631798}],"con":true,"img":false}]}
{"op":"mcm","clk":"1349942509","pt":1588412981818,"mc":[{"id":"1.170370562","rc":[{"atb":[[1.63,42.21]],"id":9631798}],"con":true,"img":false}]}
{"op":"mcm","clk":"1349942715","pt":1588412991982,"mc":[{"id":"1.170370562","rc":[{"atb":[[1.68,2.62]],"id":9631798}],"con":true,"img":false}]}
{"op":"mcm","clk":"1349942814","pt":1588412998065,"mc":[{"id":"1.170370562","rc":[{"atl":[[1.74,0]],"id":9631798}],"con":true,"img":false}]}
{"op":"mcm","clk":"1349942834","pt":1588412999247,"mc":[{"id":"1.170370562","rc":[{"atb":[[2.2,0]],"id":9625043}],"con":true,"img":false}]}
{"op":"mcm","clk":"1349942837","pt":1588412999352,"mc":[{"id":"1.170370562","rc":[{"atb":[[2.36,1.79]],"id":9625043}],"con":true,"img":false}]}
{"op":"mcm","clk":"1349942844","pt":1588412999661,"mc":[{"id":"1.170370562","rc":[{"atl":[[1000,3.19]],"id":9631798}],"con":true,"img":false}]}
{"op":"mcm","clk":"1349942848","pt":1588412999968,"mc":[{"id":"1.170370562","rc":[{"atl":[[1000,2.76]],"id":9631798}],"con":true,"img":false}]}
{"op":"mcm","clk":"1349942857","pt":1588413000276,"mc":[{"id":"1.170370562","rc":[{"atl":[[1000,0]],"id":9631798}],"con":true,"img":false}]}
{"op":"mcm","clk":"1349942859","pt":1588413000379,"mc":[{"id":"1.170370562","rc":[{"trd":[[1.68,5.24]],"ltp":1.68,"tv":5.24,"id":9631798},{"atb":[[1.68,0]],"id":9631798},{"atl":[[1.68,0.14]],"id":9631798}],"con":true,"img":false}]}
{"op":"mcm","clk":"1349942891","pt":1588413002294,"mc":[{"id":"1.170370562","rc":[{"atb":[[1.6,0]],"id":9631798}],"con":true,"img":false}]}
{"op":"mcm","clk":"1349943066","pt":1588413009769,"mc":[{"id":"1.170370562","rc":[{"atb":[[2.1,78.42]],"id":9625043}],"con":true,"img":false}]}
{"op":"mcm","clk":"1349943073","pt":1588413010180,"mc":[{"id":"1.170370562","rc":[{"atl":[[1.81,4]],"id":9631798}],"con":true,"img":false}]}
