{"op":"mcm","clk":"1349990348","pt":1588414806291,"mc":[{"id":"1.170370562","rc":[{"atl":[[1.61,0]],"id":9625043}],"con":true,"img":false}]}
{"op":"mcm","clk":"1349990383","pt":1588414807122,"mc":[{"id":"1.170370562","rc":[{"trd":[[1.54,1258.34],[1.55,390.3]],"ltp":1.54,"tv":1648.63,"id":9625043},{"atb":[[1.55,0]],"id":9625043},{"atl":[[1.53,58.93]],"id":9625043}],"con":true,"img":false}]}
{"op":"mcm","clk":"1349990403","pt":1588414807799,"mc":[{"id":"1.170370562","rc":[{"atl":[[1.6,0]],"id":9625043}],"con":true,"img":false}]}
{"op":"mcm","clk":"1349990412","pt":1588414808003,"mc":[{"id":"1.170370562","rc":[{"atl":[[1.55,334.21]],"id":9625043}],"con":true,"img":false}]}
{"op":"mcm","clk":"1349990427","pt":1588414808416,"mc":[{"id":"1.170370562","rc":[{"atb":[[1.52,0.1]],"id":9625043}],"con":true,"img":false}]}
{"op":"mcm","clk":"1349990435","pt":1588414808518,"mc":[{"id":"1.170370562","rc":[{"atl":[[1.59,289.3]],"id":9625043}],"con":true,"img":false}]}
{"op":"mcm","clk":"1349990460","pt":1588414809092,"mc":[{"id":"1.170370562","rc":[{"atl":[[1.53,59.04]],"id":9625043}],"con":true,"img":false}]}
{"op":"mcm","clk":"1349990463","pt":1588414809195,"mc":[{"id":"1.170370562","rc":[{"atl":[[1.58,177.3]],"id":9625043}],"con":true,"img":false}]}
{"op":"mcm","clk":"1349990467","pt":1588414809301,"mc":[{"id":"1.170370562","rc":[{"atl":[[1.58,217.97]],"id":9625043}],"con":true,"img":false}]}
{"op":"mcm","clk":"1349990474","pt":1588414809507,"mc":[{"id":"1.170370562","rc":[{"atb":[[1.5,80.13]],"id":9625043}],"con":true,"img":false}]}
{"op":"mcm","clk":"1349990484","pt":1588414809818,"mc":[{"id":"1.170370562","rc":[{"atb":[[1.01,1090.13]],"id":9631798}],"con":true,"img":false}]}
{"op":"mcm","clk":"1349990488","pt":1588414810027,"mc":[{"id":"1.170370562","rc":[{"atb":[[1.01,1088.14]],"id":9631798}],"con":true,"img":false}]}
{"op":"mcm","clk":"1349990494","pt":1588414810232,"mc":[{"id":"1.170370562","rc":[{"atb":[[1.01,1088.13]],"id":9631798},{"atl":[[2.96,0]],"id":9631798}],"con":true,"img":false}]}
{"op":"mcm","clk":"1349990498","pt":1588414810337,"mc":[{"id":"1.170370562","rc":[{"trd":[[1.53,460.49]],"ltp":1.53,"tv":460.49,"id":9625043},{"atl":[[1.53,57.44]],"id":9625043},{"trd":[[2.88,4.46]],"ltp":2.88,"tv":4.46,"id":9631798}],"con":true,"img":false}]}
{"op":"mcm","clk":"1349990505","pt":1588414810494,"mc":[{"id":"1.170370562","rc":[{"atl":[[1.57,112]],"id":9625043}],"con":true,"img":false}]}
{"op":"mcm","clk":"1349990513","pt":1588414810703,"mc":[{"id":"1.170370562","rc":[{"atb":[[1.01,1090.13]],"id":9631798}],"con":true,"img":false}]}
{"op":"mcm","clk":"1349990522","pt":1588414810908,"mc":[{"id":"1.170370562","rc":[{"atb":[[1.01,1088.14]],"id":9631798}],"con":true,"img":false}]}
{"op":"mcm","clk":"1349990533","pt":1588414811115,"mc":[{"id":"1.170370562","rc":[{"atb":[[1.01,1088.13]],"id":9631798}],"con":true,"img":false}]}
{"op":"mcm","clk":"1349990566","pt":1588414811895,"mc":[{"id":"1.170370562","rc":[{"atl":[[1.58,177.3]],"id":9625043},{"atb":[[1.01,1090.13]],"id":9631798}],"con":true,"img":false}]}
{"op":"mcm","clk":"1349990577","pt":1588414812205,"mc":[{"id":"1.170370562","rc":[{"atb":[[1.01,1088.14]],"id":9631798}],"con":true,"img":false}]}
{"op":"mcm","clk":"1349990589","pt":1588414812415,"mc":[{"id":"1.170370562","rc":[{"atb":[[1.01,1090.13]],"id":9631798}],"con":true,"img":false}]}
{"op":"mcm","clk":"1349990594","pt":1588414812622,"mc":[{"id":"1.170370562","rc":[{"atb":[[1.01,1088.14]],"id":9631798}],"con":true,"img":false}]}
{"op":"mcm","clk":"1349990605","pt":1588414812931,"mc":[{"id":"1.170370562","rc":[{"atb":[[1.01,1090.13]],"id":9631798}],"con":true,"img":false}]}
{"op":"mcm","clk":"1349990612","pt":1588414813034,"mc":[{"id":"1.170370562","rc":[{"trd":[[1.53,517.22]],"ltp":1.53,"tv":517.22,"id":9625043},{"atl":[[1.53,0.71]],"id":9625043},{"trd":[[2.88,34.6]],"ltp":2.88,"tv":34.6,"id":9631798}],"con":true,"img":false}]}
{"op":"mcm","clk":"1349990617","pt":1588414813138,"mc":[{"id":"1.170370562","rc":[{"atb":[[1.01,1088.14]],"id":9631798}],"con":true,"img":false}]}
{"op":"mcm","clk":"1349990628","pt":1588414813296,"mc":[{"id":"1.170370562","rc":[{"atb":[[1.01,1088.13]],"id":9631798}],"con":true,"img":false}]}
{"op":"mcm","clk":"1349990661","pt":1588414814338,"mc":[{"id":"1.170370562","rc":[{"atl":[[1.54,55]],"id":9625043}],"con":true,"img":false}]}
{"op":"mcm","clk":"1349990666","pt":1588414814443,"mc":[{"id":"1.170370562","rc":[{"atb":[[1.47,112]],"id":9625043}],"con":true,"img":false}]}
{"op":"mcm","clk":"1349990679","pt":1588414814811,"mc":[{"id":"1.170370562","rc":[{"trd":[[1.52,1239.74]],"ltp":1.52,"tv":1239.74,"id":9625043},{"atb":[[1.52,0]],"id":9625043},{"atl":[[1.52,54.9]],"id":9625043}],"con":true,"img":false}]}
{"op":"mcm","clk":"1349990683","pt":1588414815022,"mc":[{"id":"1.170370562","rc":[{"atl":[[1.59,112]],"id":9625043}],"con":true,"img":false}]}
{"op":"mcm","clk":"1349990695","pt":1588414815229,"mc":[{"id":"1.170370562","rc":[{"atl":[[1.72,0]],"id":9625043}],"con":true,"img":false}]}
{"op":"mcm","clk":"1349990701","pt":1588414815336,"mc":[{"id":"1.170370562","rc":[{"trd":[[1.53,517.43],[1.52,1294.64]],"ltp":1.53,"tv":1812.07,"id":9625043},{"atl":[[1.53,0.5],[1.52,0]],"id":9625043},{"trd":[[2.88,34.71],[2.92,31.16]],"ltp":2.88,"tv":65.87,"id":9631798},{"atb":[[2.8,0.01]],"id":9631798}],"con":true,"img":false}]}
{"op":"mcm","clk":"1349990705","pt":1588414815437,"mc":[{"id":"1.170370562","rc":[{"atl":[[1.54,271.31]],"id":9625043}],"con":true,"img":false}]}
{"op":"mcm","clk":"1349990715","pt":1588414815699,"mc":[{"id":"1.170370562","rc":[{"atl":[[1.52,0.48]],"id":9625043}],"con":true,"img":false}]}
{"op":"mcm","clk":"1349990719","pt":1588414815806,"mc":[{"id":"1.170370562","rc":[{"atl":[[1.63,0]],"id":9625043}],"con":true,"img":false}]}
{"op":"mcm","clk":"1349990731","pt":1588414816221,"mc":[{"id":"1.170370562","rc":[{"atb":[[2.74,0.01]],"id":9631798}],"con":true,"img":false}]}
{"op":"mcm","clk":"1349990779","pt":1588414817517,"mc":[{"id":"1.170370562","rc":[{"atb":[[1.39,0.91]],"id":9625043},{"atb":[[2.84,0.01]],"id":9631798}],"con":true,"img":false}]}
{"op":"mcm","clk":"1349990793","pt":1588414818036,"mc":[{"id":"1.170370562","rc":[{"atb":[[2.58,0.01]],"id":9631798}],"con":true,"img":false}]}
{"op":"mcm","clk":"1349990799","pt":1588414818240,"mc":[{"id":"1.170370562","rc":[{"atl":[[3.45,34]],"id":9631798}],"con":true,"img":false}]}
{"op":"mcm","clk":"1349990803","pt":1588414818397,"mc":[{"id":"1.170370562","rc":[{"atb":[[2.4,0.01]],"id":9631798}],"con":true,"img":false}]}
{"op":"mcm","clk":"1349990825","pt":1588414819224,"mc":[{"id":"1.170370562","rc":[{"atl":[[1.58,0]],"id":9625043}],"con":true,"img":false}]}
{"op":"mcm","clk":"1349990829","pt":1588414819327,"mc":[{"id":"1.170370562","rc":[{"trd":[[1.54,1334.42],[1.53,518.16],[1.52,1295.6]],"ltp":1.54,"tv":3148.18,"id":9625043},{"atl":[[1.53,0],[1.54,195.23],[1.52,0]],"id":9625043},{"trd":[[2.84,212.89],[2.88,34.86]],"ltp":2.84,"tv":247.75,"id":9631798},{"atb":[[2.84,0]],"id":9631798}],"con":true,"img":false}]}
{"op":"mcm","clk":"1349990838","pt":1588414819847,"mc":[{"id":"1.170370562","rc":[{"atl":[[3.2,17]],"id":9631798}],"con":true,"img":false}]}
{"op":"mcm","clk":"1349990842","pt":1588414819903,"mc":[{"id":"1.170370562","rc":[{"atl":[[1.62,0]],"id":9625043}],"con":true,"img":false}]}
{"op":"mcm","clk":"1349990848","pt":1588414820005,"mc":[{"id":"1.170370562","rc":[{"atb":[[1.47,0]],"id":9625043}],"con":true,"img":false}]}
{"op":"mcm","clk":"1349990850","pt":1588414820133,"mc":[{"id":"1.170370562","rc":[{"atl":[[1.61,39.91]],"id":9625043}],"con":true,"img":false}]}
{"op":"mcm","clk":"1349990853","pt":1588414820237,"mc":[{"id":"1.170370562","rc":[{"atl":[[3.2,34]],"id":9631798}],"con":true,"img":false}]}
{"op":"mcm","clk":"1349990879","pt":1588414821131,"mc":[{"id":"1.170370562","rc":[{"atl":[[3.1,17]],"id":9631798}],"con":true,"img":false}]}
{"op":"mcm","clk":"1349990882","pt":1588414821234,"mc":[{"id":"1.170370562","rc":[{"atl":[[1.9,0]],"id":9625043},{"atb":[[1.72,0],[1.57,0],[1.5,0],[1.66,0]],"id":9631798}],"con":true,"img":false}]}
{"op":"mcm","clk":"1349990891","pt":1588414821543,"mc":[{"id":"1.170370562","rc":[{"atl":[[1.53,55]],"id":9625043}],"con":true,"img":false}]}
{"op":"mcm","clk":"1349990897","pt":1588414821749,"mc":[{"id":"1.170370562","rc":[{"trd":[[1.53,522.6]],"ltp":1.53,"tv":522.6,"id":9625043},{"atl":[[1.53,50.56]],"id":9625043},{"trd":[[2.88,37.21]],"ltp":2.88,"tv":37.21,"id":9631798}],"con":true,"img":false}]}
{"op":"mcm","clk":"1349990905","pt":1588414822010,"mc":[{"id":"1.170370562","rc":[{"atl":[[3.1,0]],"id":9631798}],"con":true,"img":false}]}
{"op":"mcm","clk":"1349990928","pt":1588414822528,"mc":[{"id":"1.170370562","rc":[{"atl":[[1.54,307.23]],"id":9625043}],"con":true,"img":false}]}
{"op":"mcm","clk":"1349990947","pt":1588414823043,"mc":[{"id":"1.170370562","rc":[{"atl":[[1.53,162.56]],"id":9625043}],"con":true,"img":false}]}
{"op":"mcm","clk":"1349990954","pt":1588414823249,"mc":[{"id":"1.170370562","rc":[{"trd":[[1.53,847.72]],"ltp":1.53,"tv":847.72,"id":9625043},{"atb":[[1.53,837.44]],"id":9625043},{"atl":[[1.53,0]],"id":9625043}],"con":true,"img":false}]}
{"op":"mcm","clk":"1349990968","pt":1588414823617,"mc":[{"id":"1.170370562","rc":[{"atl":[[2.88,2.57]],"id":9631798}],"con":true,"img":false}]}
{"op":"mcm","clk":"1349990972","pt":1588414823719,"mc":[{"id":"1.170370562","rc":[{"atb":[[1.53,841.67]],"id":9625043}],"con":true,"img":false}]}
{"op":"mcm","clk":"1349990976","pt":1588414823823,"mc":[{"id":"1.170370562","rc":[{"atb":[[1.53,1004.23]],"id":9625043}],"con":true,"img":false}]}
{"op":"mcm","clk":"1349991005","pt":1588414824653,"mc":[{"id":"1.170370562","rc":[{"atb":[[1.53,1496.25]],"id":9625043}],"con":true,"img":false}]}
{"op":"mcm","clk":"1349991009","pt":1588414824707,"mc":[{"id":"1.170370562","rc":[{"trd":[[1.54,1339.57]],"ltp":1.54,"tv":1339.57,"id":9625043},{"atb":[[1.53,496.25]],"id":9625043},{"atl":[[1.59,0],[1.57,0],[1.54,192.65]],"id":9625043}],"con":true,"img":false}]}
{"op":"mcm","clk":"1349991019","pt":1588414825122,"mc":[{"id":"1.170370562","rc":[{"trd":[[1.53,852.98]],"ltp":1.53,"tv":852.98,"id":9625043},{"atb":[[1.53,493.62]],"id":9625043}],"con":true,"img":false}]}
{"op":"mcm","clk":"1349991023","pt":1588414825227,"mc":[{"id":"1.170370562","rc":[{"atl":[[1.55,0]],"id":9625043}],"con":true,"img":false}]}
{"op":"mcm","clk":"1349991038","pt":1588414825744,"mc":[{"id":"1.170370562","rc":[{"atb":[[1.53,1.6]],"id":9625043}],"con":true,"img":false}]}
{"op":"mcm","clk":"1349991041","pt":1588414825847,"mc":[{"id":"1.170370562","rc":[{"atl":[[1.61,0]],"id":9625043}],"con":true,"img":false}]}
{"op":"mcm","clk":"1349991046","pt":1588414825951,"mc":[{"id":"1.170370562","rc":[{"atl":[[1.7,177.3]],"id":9625043}],"con":true,"img":false}]}
{"op":"mcm","clk":"1349991055","pt":1588414826211,"mc":[{"id":"1.170370562","rc":[{"trd":[[1.54,1453.91]],"ltp":1.54,"tv":1453.91,"id":9625043},{"atl":[[1.54,78.32]],"id":9625043},{"trd":[[2.84,274.89]],"ltp":2.84,"tv":274.89,"id":9631798}],"con":true,"img":false}]}
{"op":"mcm","clk":"1349991082","pt":1588414827141,"mc":[{"id":"1.170370562","rc":[{"atl":[[3.05,17]],"id":9631798}],"con":true,"img":false}]}
{"op":"mcm","clk":"1349991096","pt":1588414827560,"mc":[{"id":"1.170370562","rc":[{"atl":[[1.54,0]],"id":9625043}],"con":true,"img":false}]}
{"op":"mcm","clk":"1349991173","pt":1588414830718,"mc":[{"id":"1.170370562","rc":[{"atb":[[1.45,0]],"id":9625043}],"con":true,"img":false}]}
{"op":"mcm","clk":"1349991185","pt":1588414831236,"mc":[{"id":"1.170370562","rc":[{"atl":[[1.54,159.75]],"id":9625043}],"con":true,"img":false}]}
{"op":"mcm","clk":"1349991193","pt":1588414831442,"mc":[{"id":"1.170370562","rc":[{"atl":[[1.63,39.42],[1.58,112]],"id":9625043}],"con":true,"img":false}]}
{"op":"mcm","clk":"1349991197","pt":1588414831648,"mc":[{"id":"1.170370562","rc":[{"atl":[[2.88,0]],"id":9631798}],"con":true,"img":false}]}
{"op":"mcm","clk":"1349991212","pt":1588414832221,"mc":[{"id":"1.170370562","rc":[{"atl":[[1.61,112]],"id":9625043}],"con":true,"img":false}]}
{"op":"mcm","clk":"1349991217","pt":1588414832428,"mc":[{"id":"1.170370562","rc":[{"trd":[[1.5,299.09],[1.53,856.2]],"ltp":1.5,"tv":1155.29,"id":9625043},{"atb":[[1.53,0],[1.5,571.18]],"id":9625043}],"con":true,"img":false}]}
{"op":"mcm","clk":"1349991244","pt":1588414833263,"mc":[{"id":"1.170370562","rc":[{"atl":[[1.54,496.12]],"id":9625043}],"con":true,"img":false}]}
{"op":"mcm","clk":"1349991261","pt":1588414833730,"mc":[{"id":"1.170370562","rc":[{"atl":[[1.55,77.81]],"id":9625043}],"con":true,"img":false}]}
{"op":"mcm","clk":"1349991263","pt":1588414833833,"mc":[{"id":"1.170370562","rc":[{"atl":[[1.56,112]],"id":9625043}],"con":true,"img":false}]}
{"op":"mcm","clk":"1349991268","pt":1588414833938,"mc":[{"id":"1.170370562","rc":[{"atb":[[1.43,500]],"id":9625043},{"atl":[[2.98,17]],"id":9631798}],"con":true,"img":false}]}
{"op":"mcm","clk":"1349991280","pt":1588414834353,"mc":[{"id":"1.170370562","rc":[{"atb":[[2.7,0]],"id":9631798}],"con":true,"img":false}]}
{"op":"mcm","clk":"1349991284","pt":1588414834455,"mc":[{"id":"1.170370562","rc":[{"atb":[[1.37,500]],"id":9625043}],"con":true,"img":false}]}
{"op":"mcm","clk":"1349991297","pt":1588414834867,"mc":[{"id":"1.170370562","rc":[{"atl":[[1.55,0]],"id":9625043}],"con":true,"img":false}]}
{"op":"mcm","clk":"1349991304","pt":1588414834969,"mc":[{"id":"1.170370562","rc":[{"atl":[[1.53,2.57]],"id":9625043}],"con":true,"img":false}]}
{"op":"mcm","clk":"1349991311","pt":1588414835073,"mc":[{"id":"1.170370562","rc":[{"atl":[[1.63,119.2]],"id":9625043}],"con":true,"img":false}]}
{"op":"mcm","clk":"1349991317","pt":1588414835230,"mc":[{"id":"1.170370562","rc":[{"atl":[[1.63,198.99]],"id":9625043}],"con":true,"img":false}]}
{"op":"mcm","clk":"1349991320","pt":1588414835331,"mc":[{"id":"1.170370562","rc":[{"atl":[[1.73,177.3],[1.63,278.78]],"id":9625043}],"con":true,"img":false}]}
{"op":"mcm","clk":"1349991350","pt":1588414836466,"mc":[{"id":"1.170370562","rc":[{"trd":[[1.53,860.83]],"ltp":1.53,"tv":860.83,"id":9625043},{"atl":[[1.53,0.25]],"id":9625043}],"con":true,"img":false}]}
{"op":"mcm","clk":"1349991361","pt":1588414836831,"mc":[{"id":"1.170370562","rc":[{"atb":[[1.43,1000]],"id":9625043}],"con":true,"img":false}]}
{"op":"mcm","clk":"1349991364","pt":1588414836935,"mc":[{"id":"1.170370562","rc":[{"atl":[[1.54,159.75]],"id":9625043}],"con":true,"img":false}]}
{"op":"mcm","clk":"1349991372","pt":1588414837248,"mc":[{"id":"1.170370562","rc":[{"atb":[[1.15,0]],"id":9625043}],"con":true,"img":false}]}
{"op":"mcm","clk":"1349991383","pt":1588414837767,"mc":[{"id":"1.170370562","rc":[{"atl":[[1.66,0]],"id":9625043}],"con":true,"img":false}]}
{"op":"mcm","clk":"1349991391","pt":1588414838074,"mc":[{"id":"1.170370562","rc":[{"atb":[[1.01,994.72]],"id":9625043},{"atb":[[1.01,1093.13]],"id":9631798},{"atl":[[3.2,0]],"id":9631798}],"con":true,"img":false}]}
{"op":"mcm","clk":"1349991404","pt":1588414838437,"mc":[{"id":"1.170370562","rc":[{"atl":[[1.53,79.09]],"id":9625043}],"con":true,"img":false}]}
{"op":"mcm","clk":"1349991406","pt":1588414838541,"mc":[{"id":"1.170370562","rc":[{"atl":[[1.56,0]],"id":9625043}],"con":true,"img":false}]}
{"op":"mcm","clk":"1349991421","pt":1588414838953,"mc":[{"id":"1.170370562","rc":[{"atl":[[3.45,0]],"id":9631798}],"con":true,"img":false}]}
{"op":"mcm","clk":"1349991424","pt":1588414839058,"mc":[{"id":"1.170370562","rc":[{"atb":[[1.5,79.16]],"id":9625043}],"con":true,"img":false}]}
{"op":"mcm","clk":"1349991438","pt":1588414839466,"mc":[{"id":"1.170370562","rc":[{"atb":[[2.76,38.19]],"id":9631798}],"con":true,"img":false}]}
{"op":"mcm","clk":"1349991443","pt":1588414839569,"mc":[{"id":"1.170370562","rc":[{"atl":[[1.58,0]],"id":9625043}],"con":true,"img":false}]}
{"op":"mcm","clk":"1349991449","pt":1588414839877,"mc":[{"id":"1.170370562","rc":[{"atl":[[1.53,367.81]],"id":9625043}],"con":true,"img":false}]}
{"op":"mcm","clk":"1349991469","pt":1588414840554,"mc":[{"id":"1.170370562","rc":[{"atl":[[1.63,0]],"id":9625043}],"con":true,"img":false}]}
{"op":"mcm","clk":"1349991485","pt":1588414841276,"mc":[{"id":"1.170370562","rc":[{"atl":[[1.52,340.8]],"id":9625043}],"con":true,"img":false}]}
{"op":"mcm","clk":"1349991497","pt":1588414841641,"mc":[{"id":"1.170370562","rc":[{"atl":[[1.61,0]],"id":9625043}],"con":true,"img":false}]}
{"op":"mcm","clk":"1349991507","pt":1588414841951,"mc":[{"id":"1.170370562","rc":[{"trd":[[2.98,26.02]],"ltp":2.98,"tv":26.02,"id":9631798},{"atl":[[2.98,4]],"id":9631798}],"con":true,"img":false}]}
{"op":"mcm","clk":"1349991516","pt":1588414842159,"mc":[{"id":"1.170370562","rc":[{"atb":[[1.5,100.15]],"id":9625043}],"con":true,"img":false}]}
{"op":"mcm","clk":"1349991524","pt":1588414842366,"mc":[{"id":"1.170370562","rc":[{"atl":[[2.98,0]],"id":9631798}],"con":true,"img":false}]}
{"op":"mcm","clk":"1349991537","pt":1588414842682,"mc":[{"id":"1.170370562","rc":[{"trd":[[1.52,1633.15]],"ltp":1.52,"tv":1633.15,"id":9625043},{"atb":[[1.42,500]],"id":9625043},{"atl":[[1.52,172.02]],"id":9625043}],"con":true,"img":false}]}
{"op":"mcm","clk":"1349991569","pt":1588414843457,"mc":[{"id":"1.170370562","rc":[{"trd":[[1.52,1706.91]],"ltp":1.52,"tv":1706.91,"id":9625043},{"atl":[[1.52,98.27]],"id":9625043},{"trd":[[2.92,69.55]],"ltp":2.92,"tv":69.55,"id":9631798}],"con":true,"img":false}]}
{"op":"mcm","clk":"1349991646","pt":1588414845588,"mc":[{"id":"1.170370562","rc":[{"atl":[[3.05,0]],"id":9631798}],"con":true,"img":false}]}
{"op":"mcm","clk":"1349991666","pt":1588414846165,"mc":[{"id":"1.170370562","rc":[{"atl":[[1.54,0]],"id":9625043}],"con":true,"img":false}]}
{"op":"mcm","clk":"1349991690","pt":1588414846783,"mc":[{"id":"1.170370562","rc":[{"atb":[[1.46,222]],"id":9625043}],"con":true,"img":false}]}
{"op":"mcm","clk":"1349991697","pt":1588414847091,"mc":[{"id":"1.170370562","rc":[{"atb":[[2.76,0]],"id":9631798}],"con":true,"img":false}]}
{"op":"mcm","clk":"1349991740","pt":1588414848689,"mc":[{"id":"1.170370562","rc":[{"atl":[[1.53,288.97]],"id":9625043}],"con":true,"img":false}]}
{"op":"mcm","clk":"1349991760","pt":1588414849361,"mc":[{"id":"1.170370562","rc":[{"trd":[[1.53,862.79],[1.52,1805.18]],"ltp":1.53,"tv":2667.97,"id":9625043},{"atl":[[1.53,287.62],[1.52,0]],"id":9625043},{"trd":[[2.88,37.62],[2.92,120.71]],"ltp":2.88,"tv":158.32,"id":9631798}],"con":true,"img":false}]}
{"op":"mcm","clk":"1349991770","pt":1588414849567,"mc":[{"id":"1.170370562","rc":[{"atl":[[1.6,137.41]],"id":9625043}],"con":true,"img":false}]}
{"op":"mcm","clk":"1349991781","pt":1588414849876,"mc":[{"id":"1.170370562","rc":[{"atb":[[2.8,0],[2.58,0],[2.4,0],[2.74,0]],"id":9631798}],"con":true,"img":false}]}
{"op":"mcm","clk":"1349991789","pt":1588414850184,"mc":[{"id":"1.170370562","rc":[{"trd":[[1.53,884.95]],"ltp":1.53,"tv":884.95,"id":9625043},{"atl":[[1.77,0],[1.53,276.54]],"id":9625043}],"con":true,"img":false}]}
{"op":"mcm","clk":"1349991810","pt":1588414850757,"mc":[{"id":"1.170370562","rc":[{"atb":[[1.52,88.65]],"id":9625043}],"con":true,"img":false}]}
{"op":"mcm","clk":"1349991815","pt":1588414850859,"mc":[{"id":"1.170370562","rc":[{"atl":[[1.53,0]],"id":9625043}],"con":true,"img":false}]}
{"op":"mcm","clk":"1349991827","pt":1588414851276,"mc":[{"id":"1.170370562","rc":[{"trd":[[1.5,449.81],[1.52,1982.48]],"ltp":1.5,"tv":2432.29,"id":9625043},{"atb":[[1.5,24.79],[1.52,0]],"id":9625043}],"con":true,"img":false}]}
{"op":"mcm","clk":"1349991839","pt":1588414851688,"mc":[{"id":"1.170370562","rc":[{"atl":[[1.72,0.11],[1.7,0]],"id":9625043}],"con":true,"img":false}]}
{"op":"mcm","clk":"1349991848","pt":1588414851893,"mc":[{"id":"1.170370562","rc":[{"atl":[[2.88,2.57]],"id":9631798}],"con":true,"img":false}]}
{"op":"mcm","clk":"1349991858","pt":1588414852154,"mc":[{"id":"1.170370562","rc":[{"trd":[[2.88,42.77]],"ltp":2.88,"tv":42.77,"id":9631798},{"atb":[[2.9,35.61]],"id":9631798},{"atl":[[2.88,0]],"id":9631798}],"con":true,"img":false}]}
{"op":"mcm","clk":"1349991865","pt":1588414852477,"mc":[{"id":"1.170370562","rc":[{"atl":[[1000,2]],"id":9631798}],"con":true,"img":false}]}
{"op":"mcm","clk":"1349991872","pt":1588414852670,"mc":[{"id":"1.170370562","rc":[{"atl":[[1000,0.01]],"id":9631798}],"con":true,"img":false}]}
{"op":"mcm","clk":"1349991875","pt":1588414852773,"mc":[{"id":"1.170370562","rc":[{"atl":[[1000,2.01]],"id":9631798}],"con":true,"img":false}]}
{"op":"mcm","clk":"1349991878","pt":1588414852874,"mc":[{"id":"1.170370562","rc":[{"atl":[[1000,4.01]],"id":9631798}],"con":true,"img":false}]}
{"op":"mcm","clk":"1349991881","pt":1588414852979,"mc":[{"id":"1.170370562","rc":[{"atl":[[1000,2.01]],"id":9631798}],"con":true,"img":false}]}
{"op":"mcm","clk":"1349991884","pt":1588414853081,"mc":[{"id":"1.170370562","rc":[{"atl":[[1000,2.02]],"id":9631798}],"con":true,"img":false}]}
{"op":"mcm","clk":"1349991886","pt":1588414853184,"mc":[{"id":"1.170370562","rc":[{"atl":[[4.2,0],[1000,2]],"id":9631798}],"con":true,"img":false}]}
{"op":"mcm","clk":"1349991890","pt":1588414853284,"mc":[{"id":"1.170370562","rc":[{"atl":[[1000,4]],"id":9631798}],"con":true,"img":false}]}
{"op":"mcm","clk":"1349991894","pt":1588414853492,"mc":[{"id":"1.170370562","rc":[{"atl":[[1000,2.02]],"id":9631798}],"con":true,"img":false}]}
{"op":"mcm","clk":"1349991904","pt":1588414853754,"mc":[{"id":"1.170370562","rc":[{"atb":[[1.41,0],[1.4,0]],"id":9625043},{"atl":[[1000,0.01]],"id":9631798}],"con":true,"img":false}]}
{"op":"mcm","clk":"1349991908","pt":1588414853856,"mc":[{"id":"1.170370562","rc":[{"atl":[[1000,2.01]],"id":9631798}],"con":true,"img":false}]}
{"op":"mcm","clk":"1349991915","pt":1588414853959,"mc":[{"id":"1.170370562","rc":[{"atl":[[1.6,0]],"id":9625043},{"atl":[[1000,2]],"id":9631798}],"con":true,"img":false}]}
{"op":"mcm","clk":"1349991919","pt":1588414854062,"mc":[{"id":"1.170370562","rc":[{"trd":[[1.5,454.97]],"ltp":1.5,"tv":454.97,"id":9625043},{"atb":[[1.5,22.21]],"id":9625043},{"atl":[[1000,0.01]],"id":9631798}],"con":true,"img":false}]}
{"op":"mcm","clk":"1349991929","pt":1588414854373,"mc":[{"id":"1.170370562","rc":[{"atl":[[1.51,79.88]],"id":9625043},{"atl":[[1000,0]],"id":9631798}],"con":true,"img":false}]}
{"op":"mcm","clk":"1349991966","pt":1588414855975,"mc":[{"id":"1.170370562","rc":[{"trd":[[1.5,503.63]],"ltp":1.5,"tv":503.63,"id":9625043},{"atb":[[1.5,0]],"id":9625043},{"trd":[[3,2.11]],"ltp":3.0,"tv":2.11,"id":9631798},{"atl":[[3,49.59]],"id":9631798}],"con":true,"img":false}]}
{"op":"mcm","clk":"1349991980","pt":1588414856494,"mc":[{"id":"1.170370562","rc":[{"atl":[[1.57,112]],"id":9625043}],"con":true,"img":false}]}
{"op":"mcm","clk":"1349991995","pt":1588414856912,"mc":[{"id":"1.170370562","rc":[{"trd":[[1.5,505.08]],"ltp":1.5,"tv":505.08,"id":9625043},{"trd":[[3,2.83]],"ltp":3.0,"tv":2.83,"id":9631798},{"atl":[[3,48.87]],"id":9631798}],"con":true,"img":false}]}
{"op":"mcm","clk":"1349991997","pt":1588414856966,"mc":[{"id":"1.170370562","rc":[{"atb":[[1.39,0]],"id":9625043}],"con":true,"img":false}]}
{"op":"mcm","clk":"1349992001","pt":1588414857172,"mc":[{"id":"1.170370562","rc":[{"atl":[[1000,2]],"id":9631798}],"con":true,"img":false}]}
{"op":"mcm","clk":"1349992003","pt":1588414857274,"mc":[{"id":"1.170370562","rc":[{"atl":[[1000,0.01]],"id":9631798}],"con":true,"img":false}]}
{"op":"mcm","clk":"1349992009","pt":1588414857481,"mc":[{"id":"1.170370562","rc":[{"atl":[[1000,0]],"id":9631798}],"con":true,"img":false}]}
{"op":"mcm","clk":"1349992012","pt":1588414857584,"mc":[{"id":"1.170370562","rc":[{"atl":[[1.63,112]],"id":9625043}],"con":true,"img":false}]}
{"op":"mcm","clk":"1349992031","pt":1588414858101,"mc":[{"id":"1.170370562","rc":[{"atl":[[3.3,0.01]],"id":9631798}],"con":true,"img":false}]}
{"op":"mcm","clk":"1349992039","pt":1588414858305,"mc":[{"id":"1.170370562","rc":[{"atb":[[2.72,14.21]],"id":9631798}],"con":true,"img":false}]}
{"op":"mcm","clk":"1349992053","pt":1588414858874,"mc":[{"id":"1.170370562","rc":[{"trd":[[1.51,1247.2]],"ltp":1.51,"tv":1247.2,"id":9625043},{"atl":[[1.51,79.84]],"id":9625043},{"trd":[[2.96,16.08]],"ltp":2.96,"tv":16.08,"id":9631798}],"con":true,"img":false}]}
{"op":"mcm","clk":"1349992061","pt":1588414859084,"mc":[{"id":"1.170370562","rc":[{"trd":[[1.51,1247.22]],"ltp":1.51,"tv":1247.22,"id":9625043},{"atl":[[1.51,79.83]],"id":9625043},{"trd":[[2.96,16.09]],"ltp":2.96,"tv":16.09,"id":9631798}],"con":true,"img":false}]}
{"op":"mcm","clk":"1349992070","pt":1588414859494,"mc":[{"id":"1.170370562","rc":[{"atl":[[3.1,0.01],[1000,2]],"id":9631798}],"con":true,"img":false}]}
{"op":"mcm","clk":"1349992074","pt":1588414859700,"mc":[{"id":"1.170370562","rc":[{"atl":[[1000,0.01]],"id":9631798}],"con":true,"img":false}]}
{"op":"mcm","clk":"1349992078","pt":1588414859804,"mc":[{"id":"1.170370562","rc":[{"atl":[[1000,0]],"id":9631798}],"con":true,"img":false}]}
{"op":"mcm","clk":"1349992091","pt":1588414860266,"mc":[{"id":"1.170370562","rc":[{"atb":[[2.72,0]],"id":9631798}],"con":true,"img":false}]}
{"op":"mcm","clk":"1349992095","pt":1588414860369,"mc":[{"id":"1.170370562","rc":[{"atl":[[1000,2]],"id":9631798}],"con":true,"img":false}]}
{"op":"mcm","clk":"1349992100","pt":1588414860577,"mc":[{"id":"1.170370562","rc":[{"atl":[[1000,4]],"id":9631798}],"con":true,"img":false}]}
{"op":"mcm","clk":"1349992102","pt":1588414860681,"mc":[{"id":"1.170370562","rc":[{"atl":[[1000,2.01]],"id":9631798}],"con":true,"img":false}]}
{"op":"mcm","clk":"1349992107","pt":1588414860784,"mc":[{"id":"1.170370562","rc":[{"atl":[[1000,0.02]],"id":9631798}],"con":true,"img":false}]}
{"op":"mcm","clk":"1349992109","pt":1588414860885,"mc":[{"id":"1.170370562","rc":[{"atl":[[1000,2.01]],"id":9631798}],"con":true,"img":false}]}
{"op":"mcm","clk":"1349992111","pt":1588414860993,"mc":[{"id":"1.170370562","rc":[{"atl":[[1000,2]],"id":9631798}],"con":true,"img":false}]}
{"op":"mcm","clk":"1349992114","pt":1588414861100,"mc":[{"id":"1.170370562","rc":[{"atl":[[1000,0.01]],"id":9631798}],"con":true,"img":false}]}
{"op":"mcm","clk":"1349992119","pt":1588414861306,"mc":[{"id":"1.170370562","rc":[{"atl":[[1000,2]],"id":9631798}],"con":true,"img":false}]}
{"op":"mcm","clk":"1349992126","pt":1588414861512,"mc":[{"id":"1.170370562","rc":[{"atl":[[1000,0.01]],"id":9631798}],"con":true,"img":false}]}
{"op":"mcm","clk":"1349992132","pt":1588414861674,"mc":[{"id":"1.170370562","rc":[{"atl":[[1000,2]],"id":9631798}],"con":true,"img":false}]}
{"op":"mcm","clk":"1349992138","pt":1588414861884,"mc":[{"id":"1.170370562","rc":[{"atl":[[1000,0.01]],"id":9631798}],"con":true,"img":false}]}
{"op":"mcm","clk":"1349992142","pt":1588414861985,"mc":[{"id":"1.170370562","rc":[{"atl":[[1000,2]],"id":9631798}],"con":true,"img":false}]}
{"op":"mcm","clk":"1349992149","pt":1588414862089,"mc":[{"id":"1.170370562","rc":[{"trd":[[1.51,1260.6]],"ltp":1.51,"tv":1260.6,"id":9625043},{"atl":[[1.51,66.45]],"id":9625043},{"trd":[[2.96,22.92]],"ltp":2.96,"tv":22.92,"id":9631798}],"con":true,"img":false}]}
{"op":"mcm","clk":"1349992153","pt":1588414862190,"mc":[{"id":"1.170370562","rc":[{"trd":[[1.51,1262.44]],"ltp":1.51,"tv":1262.44,"id":9625043},{"atl":[[1.51,65.53]],"id":9625043},{"atl":[[1000,0.01]],"id":9631798}],"con":true,"img":false}]}
{"op":"mcm","clk":"1349992157","pt":1588414862399,"mc":[{"id":"1.170370562","rc":[{"atl":[[1000,0]],"id":9631798}],"con":true,"img":false}]}
{"op":"mcm","clk":"1349992164","pt":1588414862607,"mc":[{"id":"1.170370562","rc":[{"trd":[[1.51,1262.45]],"ltp":1.51,"tv":1262.45,"id":9625043},{"atl":[[1.51,65.51]],"id":9625043},{"trd":[[2.96,22.93]],"ltp":2.96,"tv":22.93,"id":9631798},{"atl":[[1000,2]],"id":9631798}],"con":true,"img":false}]}
{"op":"mcm","clk":"1349992170","pt":1588414862817,"mc":[{"id":"1.170370562","rc":[{"atl":[[1000,4]],"id":9631798}],"con":true,"img":false}]}
{"op":"mcm","clk":"1349992173","pt":1588414862873,"mc":[{"id":"1.170370562","rc":[{"atl":[[1000,2.01]],"id":9631798}],"con":true,"img":false}]}
{"op":"mcm","clk":"1349992178","pt":1588414862975,"mc":[{"id":"1.170370562","rc":[{"atl":[[1000,2.02]],"id":9631798}],"con":true,"img":false}]}
{"op":"mcm","clk":"1349992182","pt":1588414863081,"mc":[{"id":"1.170370562","rc":[{"atl":[[1000,2.01]],"id":9631798}],"con":true,"img":false}]}
{"op":"mcm","clk":"1349992190","pt":1588414863286,"mc":[{"id":"1.170370562","rc":[{"atl":[[1000,0.01]],"id":9631798}],"con":true,"img":false}]}
{"op":"mcm","clk":"1349992198","pt":1588414863391,"mc":[{"id":"1.170370562","rc":[{"trd":[[1.53,952.46],[1.51,1393.48]],"ltp":1.53,"tv":2345.94,"id":9625043},{"atb":[[1.53,26.94]],"id":9625043},{"atl":[[1.51,0]],"id":9625043},{"trd":[[2.9,35.62]],"ltp":2.9,"tv":35.62,"id":9631798},{"atb":[[2.9,0]],"id":9631798}],"con":true,"img":false}]}
{"op":"mcm","clk":"1349992202","pt":1588414863499,"mc":[{"id":"1.170370562","rc":[{"atl":[[1000,0]],"id":9631798}],"con":true,"img":false}]}
{"op":"mcm","clk":"1349992228","pt":1588414864792,"mc":[{"id":"1.170370562","rc":[{"atb":[[1.53,71.27]],"id":9625043}],"con":true,"img":false}]}
{"op":"mcm","clk":"1349992231","pt":1588414864895,"mc":[{"id":"1.170370562","rc":[{"atb":[[1.46,0]],"id":9625043},{"atl":[[2.98,0.01]],"id":9631798}],"con":true,"img":false}]}
{"op":"mcm","clk":"1349992242","pt":1588414865411,"mc":[{"id":"1.170370562","rc":[{"atb":[[2.8,14.21]],"id":9631798}],"con":true,"img":false}]}
{"op":"mcm","clk":"1349992246","pt":1588414865566,"mc":[{"id":"1.170370562","rc":[{"atl":[[2.92,0.84]],"id":9631798}],"con":true,"img":false}]}
{"op":"mcm","clk":"1349992255","pt":1588414865976,"mc":[{"id":"1.170370562","rc":[{"atl":[[3.45,0.01]],"id":9631798}],"con":true,"img":false}]}
{"op":"mcm","clk":"1349992258","pt":1588414866081,"mc":[{"id":"1.170370562","rc":[{"atl":[[2.98,0.02]],"id":9631798}],"con":true,"img":false}]}
{"op":"mcm","clk":"1349992264","pt":1588414866288,"mc":[{"id":"1.170370562","rc":[{"atl":[[1000,2]],"id":9631798}],"con":true,"img":false}]}
{"op":"mcm","clk":"1349992267","pt":1588414866391,"mc":[{"id":"1.170370562","rc":[{"atl":[[2.88,0.01]],"id":9631798}],"con":true,"img":false}]}
{"op":"mcm","clk":"1349992269","pt":1588414866494,"mc":[{"id":"1.170370562","rc":[{"atl":[[1000,2.01]],"id":9631798}],"con":true,"img":false}]}
{"op":"mcm","clk":"1349992272","pt":1588414866702,"mc":[{"id":"1.170370562","rc":[{"atl":[[1000,0.01]],"id":9631798}],"con":true,"img":false}]}
{"op":"mcm","clk":"1349992276","pt":1588414866805,"mc":[{"id":"1.170370562","rc":[{"atl":[[2.84,0.01],[1000,2.01]],"id":9631798}],"con":true,"img":false}]}
{"op":"mcm","clk":"1349992280","pt":1588414866906,"mc":[{"id":"1.170370562","rc":[{"atl":[[1000,2]],"id":9631798}],"con":true,"img":false}]}
{"op":"mcm","clk":"1349992288","pt":1588414867111,"mc":[{"id":"1.170370562","rc":[{"atl":[[2.82,0.01],[1000,0.01]],"id":9631798}],"con":true,"img":false}]}
{"op":"mcm","clk":"1349992300","pt":1588414867374,"mc":[{"id":"1.170370562","rc":[{"atl":[[1000,0]],"id":9631798}],"con":true,"img":false}]}
{"op":"mcm","clk":"1349992306","pt":1588414867477,"mc":[{"id":"1.170370562","rc":[{"atl":[[3,48.88]],"id":9631798}],"con":true,"img":false}]}
{"op":"mcm","clk":"1349992322","pt":1588414868197,"mc":[{"id":"1.170370562","rc":[{"atl":[[3.45,0.02]],"id":9631798}],"con":true,"img":false}]}
{"op":"mcm","clk":"1349992327","pt":1588414868300,"mc":[{"id":"1.170370562","rc":[{"atl":[[3.1,0.02]],"id":9631798}],"con":true,"img":false}]}
{"op":"mcm","clk":"1349992331","pt":1588414868406,"mc":[{"id":"1.170370562","rc":[{"atl":[[2.9,0.01]],"id":9631798}],"con":true,"img":false}]}
{"op":"mcm","clk":"1349992340","pt":1588414868611,"mc":[{"id":"1.170370562","rc":[{"atb":[[2.8,14.2]],"id":9631798}],"con":true,"img":false}]}
{"op":"mcm","clk":"1349992356","pt":1588414869386,"mc":[{"id":"1.170370562","rc":[{"atb":[[1.51,3.99]],"id":9625043}],"con":true,"img":false}]}
{"op":"mcm","clk":"1349992375","pt":1588414870106,"mc":[{"id":"1.170370562","rc":[{"trd":[[1.52,1984.13],[1.54,1453.95],[1.53,1095.04]],"ltp":1.52,"tv":4533.12,"id":9625043},{"atb":[[1.53,0]],"id":9625043},{"atl":[[1.52,39.01]],"id":9625043},{"trd":[[2.92,121.56],[2.88,42.78],[2.82,0.01],[2.9,35.63],[2.84,274.9]],"ltp":2.92,"tv":474.88,"id":9631798},{"atl":[[2.82,0],[2.92,0],[2.88,0],[2.9,0],[2.84,0]],"id":9631798}],"con":true,"img":false}]}
{"op":"mcm","clk":"1349992379","pt":1588414870312,"mc":[{"id":"1.170370562","rc":[{"atl":[[1000,2]],"id":9631798}],"con":true,"img":false}]}
{"op":"mcm","clk":"1349992384","pt":1588414870517,"mc":[{"id":"1.170370562","rc":[{"trd":[[1.5,602.89],[1.51,1401.48]],"ltp":1.5,"tv":2004.37,"id":9625043},{"atb":[[1.51,0]],"id":9625043},{"atl":[[1.5,10.19]],"id":9625043},{"trd":[[3,51.72],[2.98,26.04]],"ltp":3.0,"tv":77.75,"id":9631798},{"atl":[[3,0],[2.98,0],[1000,0.01]],"id":9631798}],"con":true,"img":false}]}
{"op":"mcm","clk":"1349992389","pt":1588414870619,"mc":[{"id":"1.170370562","rc":[{"atl":[[1000,2.01]],"id":9631798}],"con":true,"img":false}]}
{"op":"mcm","clk":"1349992393","pt":1588414870723,"mc":[{"id":"1.170370562","rc":[{"atl":[[1.49,112]],"id":9625043},{"atl":[[1000,2]],"id":9631798}],"con":true,"img":false}]}
{"op":"mcm","clk":"1349992397","pt":1588414870779,"mc":[{"id":"1.170370562","rc":[{"atl":[[1.5,12.76]],"id":9625043}],"con":true,"img":false}]}
{"op":"mcm","clk":"1349992401","pt":1588414870882,"mc":[{"id":"1.170370562","rc":[{"atl":[[1.53,0.25]],"id":9625043},{"atl":[[1000,2.01]],"id":9631798}],"con":true,"img":false}]}
{"op":"mcm","clk":"1349992414","pt":1588414871190,"mc":[{"id":"1.170370562","rc":[{"atl":[[1.48,43.42],[1.5,341.51]],"id":9625043}],"con":true,"img":false}]}
{"op":"mcm","clk":"1349992419","pt":1588414871294,"mc":[{"id":"1.170370562","rc":[{"atl":[[1000,0.01]],"id":9631798}],"con":true,"img":false}]}
{"op":"mcm","clk":"1349992424","pt":1588414871500,"mc":[{"id":"1.170370562","rc":[{"atl":[[1000,0]],"id":9631798}],"con":true,"img":false}]}
{"op":"mcm","clk":"1349992430","pt":1588414871602,"mc":[{"id":"1.170370562","rc":[{"trd":[[1.48,0.23]],"ltp":1.48,"tv":0.23,"id":9625043},{"atl":[[1.48,43.3]],"id":9625043}],"con":true,"img":false}]}
{"op":"mcm","clk":"1349992435","pt":1588414871809,"mc":[{"id":"1.170370562","rc":[{"atl":[[3.25,0.01]],"id":9631798}],"con":true,"img":false}]}
{"op":"mcm","clk":"1349992443","pt":1588414872016,"mc":[{"id":"1.170370562","rc":[{"trd":[[1.48,0.25]],"ltp":1.48,"tv":0.25,"id":9625043},{"atl":[[1.48,43.28]],"id":9625043},{"trd":[[3.05,0.01]],"ltp":3.05,"tv":0.01,"id":9631798}],"con":true,"img":false}]}
{"op":"mcm","clk":"1349992444","pt":1588414872119,"mc":[{"id":"1.170370562","rc":[{"atl":[[1.52,367.75]],"id":9625043}],"con":true,"img":false}]}
{"op":"mcm","clk":"1349992449","pt":1588414872220,"mc":[{"id":"1.170370562","rc":[{"atb":[[1.44,222]],"id":9625043}],"con":true,"img":false}]}
{"op":"mcm","clk":"1349992453","pt":1588414872426,"mc":[{"id":"1.170370562","rc":[{"atb":[[1.43,0]],"id":9625043}],"con":true,"img":false}]}
{"op":"mcm","clk":"1349992455","pt":1588414872480,"mc":[{"id":"1.170370562","rc":[{"trd":[[1.48,0.27]],"ltp":1.48,"tv":0.27,"id":9625043},{"atl":[[1.48,43.26]],"id":9625043},{"trd":[[3.05,0.02]],"ltp":3.05,"tv":0.02,"id":9631798}],"con":true,"img":false}]}
{"op":"mcm","clk":"1349992469","pt":1588414873208,"mc":[{"id":"1.170370562","rc":[{"atb":[[1.42,0]],"id":9625043}],"con":true,"img":false}]}
{"op":"mcm","clk":"1349992476","pt":1588414873518,"mc":[{"id":"1.170370562","rc":[{"atl":[[1.52,39.01]],"id":9625043}],"con":true,"img":false}]}
{"op":"mcm","clk":"1349992480","pt":1588414873825,"mc":[{"id":"1.170370562","rc":[{"atl":[[1.49,0]],"id":9625043}],"con":true,"img":false}]}
{"op":"mcm","clk":"1349992502","pt":1588414874606,"mc":[{"id":"1.170370562","rc":[{"atb":[[1.44,0]],"id":9625043}],"con":true,"img":false}]}
{"op":"mcm","clk":"1349992531","pt":1588414875799,"mc":[{"id":"1.170370562","rc":[{"trd":[[1.48,0.29]],"ltp":1.48,"tv":0.29,"id":9625043},{"atl":[[1.48,43.24]],"id":9625043},{"trd":[[3.05,0.03]],"ltp":3.05,"tv":0.03,"id":9631798}],"con":true,"img":false}]}
{"op":"mcm","clk":"1349992545","pt":1588414876215,"mc":[{"id":"1.170370562","rc":[{"trd":[[1.48,0.31]],"ltp":1.48,"tv":0.31,"id":9625043},{"atl":[[1.48,43.22]],"id":9625043},{"trd":[[3.05,0.04]],"ltp":3.05,"tv":0.04,"id":9631798}],"con":true,"img":false}]}
{"op":"mcm","clk":"1349992551","pt":1588414876420,"mc":[{"id":"1.170370562","rc":[{"trd":[[1.48,0.33]],"ltp":1.48,"tv":0.33,"id":9625043},{"atl":[[1.48,43.2]],"id":9625043},{"trd":[[3.05,0.05]],"ltp":3.05,"tv":0.05,"id":9631798}],"con":true,"img":false}]}
{"op":"mcm","clk":"1349992560","pt":1588414876627,"mc":[{"id":"1.170370562","rc":[{"trd":[[1.48,0.35]],"ltp":1.48,"tv":0.35,"id":9625043},{"atl":[[1.48,43.18]],"id":9625043},{"trd":[[3.05,0.06]],"ltp":3.05,"tv":0.06,"id":9631798}],"con":true,"img":false}]}
{"op":"mcm","clk":"1349992595","pt":1588414878126,"mc":[{"id":"1.170370562","rc":[{"trd":[[1.48,1.88]],"ltp":1.48,"tv":1.88,"id":9625043},{"atl":[[1.48,41.65]],"id":9625043},{"trd":[[3.05,0.8]],"ltp":3.05,"tv":0.8,"id":9631798}],"con":true,"img":false}]}
{"op":"mcm","clk":"1349992614","pt":1588414878796,"mc":[{"id":"1.170370562","rc":[{"trd":[[1.48,43.53]],"ltp":1.48,"tv":43.53,"id":9625043},{"atl":[[1.48,0]],"id":9625043},{"trd":[[3.05,21.01]],"ltp":3.05,"tv":21.01,"id":9631798},{"atl":[[3.05,0.77],[1000,2]],"id":9631798}],"con":true,"img":false}]}
{"op":"mcm","clk":"1349992618","pt":1588414879003,"mc":[{"id":"1.170370562","rc":[{"atl":[[1000,2.01]],"id":9631798}],"con":true,"img":false}]}
{"op":"mcm","clk":"1349992620","pt":1588414879207,"mc":[{"id":"1.170370562","rc":[{"atl":[[1000,4.01]],"id":9631798}],"con":true,"img":false}]}
{"op":"mcm","clk":"1349992623","pt":1588414879312,"mc":[{"id":"1.170370562","rc":[{"atl":[[1000,2.01]],"id":9631798}],"con":true,"img":false}]}
{"op":"mcm","clk":"1349992628","pt":1588414879519,"mc":[{"id":"1.170370562","rc":[{"atl":[[1000,0.01]],"id":9631798}],"con":true,"img":false}]}
{"op":"mcm","clk":"1349992635","pt":1588414879727,"mc":[{"id":"1.170370562","rc":[{"atb":[[1.42,222]],"id":9625043},{"atl":[[1000,0]],"id":9631798}],"con":true,"img":false}]}
{"op":"mcm","clk":"1349992649","pt":1588414880193,"mc":[{"id":"1.170370562","rc":[{"atb":[[1.39,112]],"id":9625043}],"con":true,"img":false}]}
{"op":"mcm","clk":"1349992660","pt":1588414880501,"mc":[{"id":"1.170370562","rc":[{"atb":[[1.42,0]],"id":9625043}],"con":true,"img":false}]}
{"op":"mcm","clk":"1349992662","pt":1588414880606,"mc":[{"id":"1.170370562","rc":[{"atb":[[1.37,612]],"id":9625043}],"con":true,"img":false}]}
{"op":"mcm","clk":"1349992679","pt":1588414881124,"mc":[{"id":"1.170370562","rc":[{"atl":[[1.76,10.57]],"id":9625043}],"con":true,"img":false}]}
{"op":"mcm","clk":"1349992684","pt":1588414881227,"mc":[{"id":"1.170370562","rc":[{"atb":[[1.38,112]],"id":9625043}],"con":true,"img":false}]}
{"op":"mcm","clk":"1349992688","pt":1588414881330,"mc":[{"id":"1.170370562","rc":[{"atb":[[2.8,0]],"id":9631798},{"atl":[[3.45,0],[3.1,0],[3.25,0],[3.3,0]],"id":9631798}],"con":true,"img":false}]}
{"op":"mcm","clk":"1349992696","pt":1588414881590,"mc":[{"id":"1.170370562","rc":[{"trd":[[1.5,604.34]],"ltp":1.5,"tv":604.34,"id":9625043},{"atl":[[1.5,340.06]],"id":9625043},{"trd":[[3,52.44]],"ltp":3.0,"tv":52.44,"id":9631798}],"con":true,"img":false}]}
{"op":"mcm","clk":"1349992715","pt":1588414882313,"mc":[{"id":"1.170370562","rc":[{"atl":[[1.5,11.31]],"id":9625043}],"con":true,"img":false}]}
{"op":"mcm","clk":"1349992720","pt":1588414882521,"mc":[{"id":"1.170370562","rc":[{"atl":[[3.05,0]],"id":9631798}],"con":true,"img":false}]}
{"op":"mcm","clk":"1349992730","pt":1588414882929,"mc":[{"id":"1.170370562","rc":[{"atb":[[1.48,0.91]],"id":9625043}],"con":true,"img":false}]}
{"op":"mcm","clk":"1349992741","pt":1588414883292,"mc":[{"id":"1.170370562","rc":[{"atb":[[1.28,500]],"id":9625043}],"con":true,"img":false}]}
{"op":"mcm","clk":"1349992749","pt":1588414883499,"mc":[{"id":"1.170370562","rc":[{"atb":[[1.28,1000]],"id":9625043}],"con":true,"img":false}]}
{"op":"mcm","clk":"1349992751","pt":1588414883605,"mc":[{"id":"1.170370562","rc":[{"atl":[[1.63,0],[1.57,0],[1.5,2.57],[1.52,0]],"id":9625043}],"con":true,"img":false}]}
{"op":"mcm","clk":"1349992768","pt":1588414884328,"mc":[{"id":"1.170370562","rc":[{"atl":[[1000,2]],"id":9631798}],"con":true,"img":false}]}
{"op":"mcm","clk":"1349992773","pt":1588414884431,"mc":[{"id":"1.170370562","rc":[{"atl":[[3.3,0.01]],"id":9631798}],"con":true,"img":false}]}
{"op":"mcm","clk":"1349992777","pt":1588414884539,"mc":[{"id":"1.170370562","rc":[{"atl":[[1000,2.01]],"id":9631798}],"con":true,"img":false}]}
{"op":"mcm","clk":"1349992780","pt":1588414884591,"mc":[{"id":"1.170370562","rc":[{"trd":[[1.5,604.36]],"ltp":1.5,"tv":604.36,"id":9625043},{"atb":[[1.32,500]],"id":9625043},{"atl":[[1.5,2.55]],"id":9625043},{"trd":[[3,52.45]],"ltp":3.0,"tv":52.45,"id":9631798}],"con":true,"img":false}]}
{"op":"mcm","clk":"1349992783","pt":1588414884694,"mc":[{"id":"1.170370562","rc":[{"atl":[[1000,4.01]],"id":9631798}],"con":true,"img":false}]}
{"op":"mcm","clk":"1349992786","pt":1588414884802,"mc":[{"id":"1.170370562","rc":[{"trd":[[1.5,604.38]],"ltp":1.5,"tv":604.38,"id":9625043},{"atl":[[1.5,2.53]],"id":9625043},{"trd":[[3,52.46]],"ltp":3.0,"tv":52.46,"id":9631798},{"atl":[[1000,2.01]],"id":9631798}],"con":true,"img":false}]}
{"op":"mcm","clk":"1349992790","pt":1588414884903,"mc":[{"id":"1.170370562","rc":[{"atl":[[1000,0.02]],"id":9631798}],"con":true,"img":false}]}
{"op":"mcm","clk":"1349992792","pt":1588414885006,"mc":[{"id":"1.170370562","rc":[{"atl":[[1000,0.01]],"id":9631798}],"con":true,"img":false}]}
{"op":"mcm","clk":"1349992796","pt":1588414885111,"mc":[{"id":"1.170370562","rc":[{"atl":[[1000,0]],"id":9631798}],"con":true,"img":false}]}
{"op":"mcm","clk":"1349992816","pt":1588414885731,"mc":[{"id":"1.170370562","rc":[{"trd":[[1.5,609.45]],"ltp":1.5,"tv":609.45,"id":9625043},{"atb":[[1.51,997.46]],"id":9625043},{"atl":[[1.5,0]],"id":9625043}],"con":true,"img":false}]}
{"op":"mcm","clk":"1349992823","pt":1588414885989,"mc":[{"id":"1.170370562","rc":[{"atb":[[1.4,222]],"id":9625043}],"con":true,"img":false}]}
{"op":"mcm","clk":"1349992824","pt":1588414886092,"mc":[{"id":"1.170370562","rc":[{"atb":[[1.48,0]],"id":9625043}],"con":true,"img":false}]}
{"op":"mcm","clk":"1349992833","pt":1588414886403,"mc":[{"id":"1.170370562","rc":[{"trd":[[1.51,1426.82]],"ltp":1.51,"tv":1426.82,"id":9625043},{"atb":[[1.51,972.12],[1.5,328.74]],"id":9625043},{"trd":[[2.98,38.88]],"ltp":2.98,"tv":38.88,"id":9631798}],"con":true,"img":false}]}
{"op":"mcm","clk":"1349992842","pt":1588414886714,"mc":[{"id":"1.170370562","rc":[{"atb":[[1.5,657.49]],"id":9625043}],"con":true,"img":false}]}
{"op":"mcm","clk":"1349992844","pt":1588414886818,"mc":[{"id":"1.170370562","rc":[{"trd":[[1.53,1095.55]],"ltp":1.53,"tv":1095.55,"id":9625043},{"atb":[[1.53,491.76]],"id":9625043},{"atl":[[1.53,0]],"id":9625043}],"con":true,"img":false}]}
{"op":"mcm","clk":"1349992872","pt":1588414887702,"mc":[{"id":"1.170370562","rc":[{"atb":[[1.48,12.92]],"id":9625043}],"con":true,"img":false}]}
{"op":"mcm","clk":"1349992882","pt":1588414887910,"mc":[{"id":"1.170370562","rc":[{"atb":[[1.4,224.65]],"id":9625043}],"con":true,"img":false}]}
{"op":"mcm","clk":"1349992888","pt":1588414888010,"mc":[{"id":"1.170370562","rc":[{"atb":[[1.52,1000]],"id":9625043},{"atl":[[1000,2]],"id":9631798}],"con":true,"img":false}]}
{"op":"mcm","clk":"1349992897","pt":1588414888219,"mc":[{"id":"1.170370562","rc":[{"atl":[[1000,2.01]],"id":9631798}],"con":true,"img":false}]}
{"op":"mcm","clk":"1349992904","pt":1588414888426,"mc":[{"id":"1.170370562","rc":[{"atb":[[1.51,0],[1.52,0]],"id":9625043}],"con":true,"img":false}]}
{"op":"mcm","clk":"1349992912","pt":1588414888738,"mc":[{"id":"1.170370562","rc":[{"atb":[[1.5,0]],"id":9625043}],"con":true,"img":false}]}
{"op":"mcm","clk":"1349992917","pt":1588414888841,"mc":[{"id":"1.170370562","rc":[{"atl":[[1000,0.01]],"id":9631798}],"con":true,"img":false}]}
{"op":"mcm","clk":"1349992922","pt":1588414888998,"mc":[{"id":"1.170370562","rc":[{"atb":[[1.48,0],[1.5,222]],"id":9625043},{"atl":[[1000,0]],"id":9631798}],"con":true,"img":false}]}
{"op":"mcm","clk":"1349992926","pt":1588414889100,"mc":[{"id":"1.170370562","rc":[{"atb":[[1.53,820.51]],"id":9625043}],"con":true,"img":false}]}
{"op":"mcm","clk":"1349992939","pt":1588414889513,"mc":[{"id":"1.170370562","rc":[{"atb":[[1.44,222]],"id":9625043},{"atl":[[3.3,0]],"id":9631798}],"con":true,"img":false}]}
{"op":"mcm","clk":"1349992952","pt":1588414889925,"mc":[{"id":"1.170370562","rc":[{"atb":[[1.5,334]],"id":9625043},{"atl":[[4.6,0.01]],"id":9631798}],"con":true,"img":false}]}
{"op":"mcm","clk":"1349992960","pt":1588414890131,"mc":[{"id":"1.170370562","rc":[{"atl":[[3.75,0.01]],"id":9631798}],"con":true,"img":false}]}
{"op":"mcm","clk":"1349992962","pt":1588414890235,"mc":[{"id":"1.170370562","rc":[{"atl":[[3.1,0.01]],"id":9631798}],"con":true,"img":false}]}
{"op":"mcm","clk":"1349992968","pt":1588414890340,"mc":[{"id":"1.170370562","rc":[{"atb":[[1.48,612]],"id":9625043}],"con":true,"img":false}]}
{"op":"mcm","clk":"1349992976","pt":1588414890498,"mc":[{"id":"1.170370562","rc":[{"atb":[[1.5,112]],"id":9625043}],"con":true,"img":false}]}
{"op":"mcm","clk":"1349992991","pt":1588414890810,"mc":[{"id":"1.170370562","rc":[{"atb":[[1.33,196.8]],"id":9625043}],"con":true,"img":false}]}
{"op":"mcm","clk":"1349993007","pt":1588414891226,"mc":[{"id":"1.170370562","rc":[{"atb":[[1.5,112.91]],"id":9625043}],"con":true,"img":false}]}
{"op":"mcm","clk":"1349993033","pt":1588414892009,"mc":[{"id":"1.170370562","rc":[{"atb":[[1.53,328.74]],"id":9625043},{"atl":[[2.92,27.35]],"id":9631798}],"con":true,"img":false}]}
{"op":"mcm","clk":"1349993039","pt":1588414892113,"mc":[{"id":"1.170370562","rc":[{"atl":[[1000,1.77]],"id":9625043}],"con":true,"img":false}]}
{"op":"mcm","clk":"1349993041","pt":1588414892216,"mc":[{"id":"1.170370562","rc":[{"atb":[[1.28,0],[1.37,112],[1.48,112],[1.32,0]],"id":9625043}],"con":true,"img":false}]}
{"op":"mcm","clk":"1349993044","pt":1588414892422,"mc":[{"id":"1.170370562","rc":[{"atb":[[1.52,222]],"id":9625043},{"atl":[[1000,0.25]],"id":9625043}],"con":true,"img":false}]}
{"op":"mcm","clk":"1349993049","pt":1588414892628,"mc":[{"id":"1.170370562","rc":[{"atl":[[3,0.25]],"id":9631798}],"con":true,"img":false}]}
{"op":"mcm","clk":"1349993051","pt":1588414892734,"mc":[{"id":"1.170370562","rc":[{"atl":[[1000,0]],"id":9625043}],"con":true,"img":false}]}
{"op":"mcm","clk":"1349993057","pt":1588414892936,"mc":[{"id":"1.170370562","rc":[{"atb":[[1.52,0]],"id":9625043}],"con":true,"img":false}]}
{"op":"mcm","clk":"1349993060","pt":1588414893042,"mc":[{"id":"1.170370562","rc":[{"atb":[[1.54,112]],"id":9625043}],"con":true,"img":false}]}
{"op":"mcm","clk":"1349993068","pt":1588414893503,"mc":[{"id":"1.170370562","rc":[{"trd":[[1.54,1506.97]],"ltp":1.54,"tv":1506.97,"id":9625043},{"atb":[[1.54,85.49]],"id":9625043},{"atl":[[3.85,0.01]],"id":9631798}],"con":true,"img":false}]}
{"op":"mcm","clk":"1349993071","pt":1588414893709,"mc":[{"id":"1.170370562","rc":[{"atb":[[1.54,197.49]],"id":9625043},{"atl":[[3.55,0.01]],"id":9631798}],"con":true,"img":false}]}
{"op":"mcm","clk":"1349993077","pt":1588414893915,"mc":[{"id":"1.170370562","rc":[{"atl":[[3.25,0.01]],"id":9631798}],"con":true,"img":false}]}
{"op":"mcm","clk":"1349993080","pt":1588414894019,"mc":[{"id":"1.170370562","rc":[{"atb":[[1.53,373.96]],"id":9625043}],"con":true,"img":false}]}
{"op":"mcm","clk":"1349993083","pt":1588414894123,"mc":[{"id":"1.170370562","rc":[{"atl":[[3,0.26]],"id":9631798}],"con":true,"img":false}]}
{"op":"mcm","clk":"1349993090","pt":1588414894330,"mc":[{"id":"1.170370562","rc":[{"atb":[[1.45,328.74],[1.54,394.29]],"id":9625043}],"con":true,"img":false}]}
{"op":"mcm","clk":"1349993099","pt":1588414894639,"mc":[{"id":"1.170370562","rc":[{"atb":[[1.01,1095.13]],"id":9631798}],"con":true,"img":false}]}
{"op":"mcm","clk":"1349993103","pt":1588414894744,"mc":[{"id":"1.170370562","rc":[{"atb":[[1.42,328.74]],"id":9625043}],"con":true,"img":false}]}
{"op":"mcm","clk":"1349993108","pt":1588414894850,"mc":[{"id":"1.170370562","rc":[{"atb":[[1.01,1093.45]],"id":9631798}],"con":true,"img":false}]}
{"op":"mcm","clk":"1349993115","pt":1588414895053,"mc":[{"id":"1.170370562","rc":[{"atb":[[1.01,1093.13]],"id":9631798}],"con":true,"img":false}]}
{"op":"mcm","clk":"1349993125","pt":1588414895416,"mc":[{"id":"1.170370562","rc":[{"atl":[[1.83,0]],"id":9625043}],"con":true,"img":false}]}
{"op":"mcm","clk":"1349993133","pt":1588414895621,"mc":[{"id":"1.170370562","rc":[{"atb":[[1.53,328.74]],"id":9625043}],"con":true,"img":false}]}
{"op":"mcm","clk":"1349993182","pt":1588414897226,"mc":[{"id":"1.170370562","rc":[{"trd":[[1.54,1507.2]],"ltp":1.54,"tv":1507.2,"id":9625043},{"atb":[[1.54,394.17]],"id":9625043}],"con":true,"img":false}]}
{"op":"mcm","clk":"1349993191","pt":1588414897536,"mc":[{"id":"1.170370562","rc":[{"atl":[[1.69,92.62]],"id":9625043}],"con":true,"img":false}]}
{"op":"mcm","clk":"1349993193","pt":1588414897639,"mc":[{"id":"1.170370562","rc":[{"trd":[[1.54,1507.67]],"ltp":1.54,"tv":1507.67,"id":9625043},{"atb":[[1.54,393.94]],"id":9625043}],"con":true,"img":false}]}
{"op":"mcm","clk":"1349993197","pt":1588414897742,"mc":[{"id":"1.170370562","rc":[{"trd":[[1.64,292.54]],"ltp":1.64,"tv":292.54,"id":9625043},{"atl":[[1.64,56.7]],"id":9625043}],"con":true,"img":false}]}
{"op":"mcm","clk":"1349993203","pt":1588414897846,"mc":[{"id":"1.170370562","rc":[{"trd":[[1.54,1508.18]],"ltp":1.54,"tv":1508.18,"id":9625043},{"atb":[[1.54,393.68]],"id":9625043}],"con":true,"img":false}]}
{"op":"mcm","clk":"1349993212","pt":1588414898257,"mc":[{"id":"1.170370562","rc":[{"atb":[[1.54,196.88]],"id":9625043},{"atl":[[3,0.01]],"id":9631798}],"con":true,"img":false}]}
{"op":"mcm","clk":"1349993214","pt":1588414898363,"mc":[{"id":"1.170370562","rc":[{"trd":[[1.54,1550.22]],"ltp":1.54,"tv":1550.22,"id":9625043},{"atb":[[1.54,175.86]],"id":9625043}],"con":true,"img":false}]}
{"op":"mcm","clk":"1349993243","pt":1588414899240,"mc":[{"id":"1.170370562","rc":[{"atl":[[1.62,0.11]],"id":9625043}],"con":true,"img":false}]}
{"op":"mcm","clk":"1349993254","pt":1588414899548,"mc":[{"id":"1.170370562","rc":[{"atb":[[1.56,50]],"id":9625043}],"con":true,"img":false}]}
{"op":"mcm","clk":"1349993258","pt":1588414899754,"mc":[{"id":"1.170370562","rc":[{"trd":[[1.64,297.85],[1.62,71.15]],"ltp":1.64,"tv":369.0,"id":9625043},{"atl":[[1.64,54.05],[1.62,0]],"id":9625043},{"atl":[[3.85,0],[4.6,0],[3.1,0],[3,0],[3.25,0],[3.55,0],[3.75,0]],"id":9631798}],"con":true,"img":false}]}
{"op":"mcm","clk":"1349993265","pt":1588414900164,"mc":[{"id":"1.170370562","rc":[{"trd":[[1.56,52.67]],"ltp":1.56,"tv":52.67,"id":9625043},{"atb":[[1.56,49.43]],"id":9625043},{"trd":[[2.8,0.32]],"ltp":2.8,"tv":0.32,"id":9631798}],"con":true,"img":false}]}
{"op":"mcm","clk":"1349993301","pt":1588414901555,"mc":[{"id":"1.170370562","rc":[{"atl":[[1.95,177.3]],"id":9625043}],"con":true,"img":false}]}
{"op":"mcm","clk":"1349993305","pt":1588414901658,"mc":[{"id":"1.170370562","rc":[{"atb":[[2.6,39]],"id":9631798}],"con":true,"img":false}]}
{"op":"mcm","clk":"1349993324","pt":1588414902226,"mc":[{"id":"1.170370562","rc":[{"atb":[[1.33,0]],"id":9625043}],"con":true,"img":false}]}
{"op":"mcm","clk":"1349993332","pt":1588414902330,"mc":[{"id":"1.170370562","rc":[{"trd":[[1.63,189.64]],"ltp":1.63,"tv":189.64,"id":9625043},{"trd":[[2.6,2.2]],"ltp":2.6,"tv":2.2,"id":9631798},{"atb":[[2.6,36.8]],"id":9631798}],"con":true,"img":false}]}
{"op":"mcm","clk":"1349993370","pt":1588414904028,"mc":[{"id":"1.170370562","rc":[{"trd":[[2.6,3.12]],"ltp":2.6,"tv":3.12,"id":9631798},{"atb":[[2.6,36.34]],"id":9631798}],"con":true,"img":false}]}
{"op":"mcm","clk":"1349993381","pt":1588414904437,"mc":[{"id":"1.170370562","rc":[{"atb":[[1.46,196.8]],"id":9625043}],"con":true,"img":false}]}
{"op":"mcm","clk":"1349993389","pt":1588414904752,"mc":[{"id":"1.170370562","rc":[{"atb":[[1.01,1003.72]],"id":9625043},{"atb":[[1.01,1102.13]],"id":9631798}],"con":true,"img":false}]}
{"op":"mcm","clk":"1349993392","pt":1588414904856,"mc":[{"id":"1.170370562","rc":[{"atb":[[1.01,1005.72]],"id":9625043},{"atl":[[1000,2]],"id":9625043},{"atb":[[1.01,1104.13]],"id":9631798},{"atl":[[1000,2]],"id":9631798}],"con":true,"img":false}]}
{"op":"mcm","clk":"1349993399","pt":1588414904959,"mc":[{"id":"1.170370562","rc":[{"atb":[[1.01,1004.72]],"id":9625043},{"atb":[[1.01,1103.13]],"id":9631798}],"con":true,"img":false}]}
{"op":"mcm","clk":"1349993403","pt":1588414905062,"mc":[{"id":"1.170370562","rc":[{"atl":[[1000,0.05]],"id":9625043},{"atl":[[1000,0.05]],"id":9631798}],"con":true,"img":false}]}
{"op":"mcm","clk":"1349993407","pt":1588414905165,"mc":[{"id":"1.170370562","rc":[{"atb":[[1.01,1003.22]],"id":9625043},{"atb":[[1.01,1101.63]],"id":9631798}],"con":true,"img":false}]}
{"op":"mcm","clk":"1349993411","pt":1588414905269,"mc":[{"id":"1.170370562","rc":[{"atb":[[1.01,1002.22]],"id":9625043},{"atb":[[1.01,1100.63]],"id":9631798}],"con":true,"img":false}]}
{"op":"mcm","clk":"1349993415","pt":1588414905370,"mc":[{"id":"1.170370562","rc":[{"atb":[[1.53,0],[1.5,113.38]],"id":9625043}],"con":true,"img":false}]}
{"op":"mcm","clk":"1349993418","pt":1588414905475,"mc":[{"id":"1.170370562","rc":[{"trd":[[1.56,56.38]],"ltp":1.56,"tv":56.38,"id":9625043},{"atb":[[1.01,1001.72],[1.56,47.58]],"id":9625043},{"atb":[[1.01,1100.13]],"id":9631798}],"con":true,"img":false}]}
{"op":"mcm","clk":"1349993429","pt":1588414905634,"mc":[{"id":"1.170370562","rc":[{"atl":[[1.63,0.17]],"id":9625043}],"con":true,"img":false}]}
{"op":"mcm","clk":"1349993446","pt":1588414906253,"mc":[{"id":"1.170370562","rc":[{"trd":[[2.6,72.38]],"ltp":2.6,"tv":72.38,"id":9631798},{"atb":[[2.6,1.7]],"id":9631798}],"con":true,"img":false}]}
{"op":"mcm","clk":"1349993462","pt":1588414906869,"mc":[{"id":"1.170370562","rc":[{"trd":[[1.56,80.9]],"ltp":1.56,"tv":80.9,"id":9625043},{"atb":[[1.56,35.32]],"id":9625043}],"con":true,"img":false}]}
{"op":"mcm","clk":"1349993499","pt":1588414908162,"mc":[{"id":"1.170370562","rc":[{"atb":[[1.54,0]],"id":9625043},{"atl":[[1.6,1.77]],"id":9625043}],"con":true,"img":false}]}
{"op":"mcm","clk":"1349993504","pt":1588414908265,"mc":[{"id":"1.170370562","rc":[{"atb":[[1.01,1102.13]],"id":9631798}],"con":true,"img":false}]}
{"op":"mcm","clk":"1349993511","pt":1588414908367,"mc":[{"id":"1.170370562","rc":[{"atb":[[1.01,1100.15]],"id":9631798}],"con":true,"img":false}]}
{"op":"mcm","clk":"1349993520","pt":1588414908573,"mc":[{"id":"1.170370562","rc":[{"atb":[[1.01,1100.13]],"id":9631798}],"con":true,"img":false}]}
{"op":"mcm","clk":"1349993557","pt":1588414909866,"mc":[{"id":"1.170370562","rc":[{"trd":[[1.56,82.14]],"ltp":1.56,"tv":82.14,"id":9625043},{"atb":[[1.56,34.7]],"id":9625043}],"con":true,"img":false}]}
{"op":"mcm","clk":"1349993571","pt":1588414910381,"mc":[{"id":"1.170370562","rc":[{"atb":[[1.03,985.92]],"id":9625043},{"atb":[[1.03,1084.33]],"id":9631798}],"con":true,"img":false}]}
{"op":"mcm","clk":"1349993577","pt":1588414910584,"mc":[{"id":"1.170370562","rc":[{"atb":[[1.1,0.5]],"id":9625043},{"atb":[[1.1,0.5]],"id":9631798}],"con":true,"img":false}]}
{"op":"mcm","clk":"1349993604","pt":1588414911467,"mc":[{"id":"1.170370562","rc":[{"atl":[[1.57,1000]],"id":9625043}],"con":true,"img":false}]}
{"op":"mcm","clk":"1349993611","pt":1588414911880,"mc":[{"id":"1.170370562","rc":[{"atb":[[1.37,0],[1.48,0],[1.39,0],[1.5,1.38],[1.38,0]],"id":9625043}],"con":true,"img":false}]}
{"op":"mcm","clk":"1349993628","pt":1588414912650,"mc":[{"id":"1.170370562","rc":[{"trd":[[1.56,83.08]],"ltp":1.56,"tv":83.08,"id":9625043},{"atb":[[1.56,34.23]],"id":9625043},{"atl":[[1.6,0]],"id":9625043}],"con":true,"img":false}]}
{"op":"mcm","clk":"1349993631","pt":1588414912857,"mc":[{"id":"1.170370562","rc":[{"trd":[[1.56,151.53]],"ltp":1.56,"tv":151.53,"id":9625043},{"atb":[[1.56,0]],"id":9625043},{"atl":[[1.54,294.52]],"id":9625043}],"con":true,"img":false}]}
{"op":"mcm","clk":"1349993635","pt":1588414912959,"mc":[{"id":"1.170370562","rc":[{"atl":[[1.56,11.77]],"id":9625043}],"con":true,"img":false}]}
{"op":"mcm","clk":"1349993643","pt":1588414913372,"mc":[{"id":"1.170370562","rc":[{"atl":[[1.56,340.52]],"id":9625043}],"con":true,"img":false}]}
{"op":"mcm","clk":"1349993651","pt":1588414913681,"mc":[{"id":"1.170370562","rc":[{"atb":[[2.68,0.02]],"id":9631798}],"con":true,"img":false}]}
{"op":"mcm","clk":"1349993657","pt":1588414913888,"mc":[{"id":"1.170370562","rc":[{"atl":[[1.59,492.02]],"id":9625043}],"con":true,"img":false}]}
{"op":"mcm","clk":"1349993660","pt":1588414913989,"mc":[{"id":"1.170370562","rc":[{"atb":[[1.77,0]],"id":9631798},{"atl":[[2.92,0]],"id":9631798}],"con":true,"img":false}]}
{"op":"mcm","clk":"1349993667","pt":1588414914197,"mc":[{"id":"1.170370562","rc":[{"atl":[[1.54,0]],"id":9625043}],"con":true,"img":false}]}
{"op":"mcm","clk":"1349993676","pt":1588414914454,"mc":[{"id":"1.170370562","rc":[{"atl":[[1.56,517.82]],"id":9625043}],"con":true,"img":false}]}
{"op":"mcm","clk":"1349993684","pt":1588414914764,"mc":[{"id":"1.170370562","rc":[{"atb":[[1.44,0]],"id":9625043},{"atl":[[1.57,0]],"id":9625043}],"con":true,"img":false}]}
{"op":"mcm","clk":"1349993692","pt":1588414914969,"mc":[{"id":"1.170370562","rc":[{"atl":[[1.59,0]],"id":9625043}],"con":true,"img":false}]}
{"op":"mcm","clk":"1349993710","pt":1588414915588,"mc":[{"id":"1.170370562","rc":[{"atl":[[1.56,530.09]],"id":9625043}],"con":true,"img":false}]}
{"op":"mcm","clk":"1349993719","pt":1588414915997,"mc":[{"id":"1.170370562","rc":[{"trd":[[1.56,151.99]],"ltp":1.56,"tv":151.99,"id":9625043},{"atl":[[1.56,529.63]],"id":9625043},{"trd":[[2.78,29.49]],"ltp":2.78,"tv":29.49,"id":9631798}],"con":true,"img":false}]}
{"op":"mcm","clk":"1349993760","pt":1588414917494,"mc":[{"id":"1.170370562","rc":[{"atl":[[1.52,112]],"id":9625043}],"con":true,"img":false}]}
{"op":"mcm","clk":"1349993776","pt":1588414917858,"mc":[{"id":"1.170370562","rc":[{"trd":[[1.5,612.23]],"ltp":1.5,"tv":612.23,"id":9625043},{"atb":[[1.5,0]],"id":9625043},{"atl":[[1.5,110.61]],"id":9625043}],"con":true,"img":false}]}
{"op":"mcm","clk":"1349993784","pt":1588414918166,"mc":[{"id":"1.170370562","rc":[{"atl":[[1.55,177.3]],"id":9625043}],"con":true,"img":false}]}
{"op":"mcm","clk":"1349993787","pt":1588414918270,"mc":[{"id":"1.170370562","rc":[{"atb":[[1.48,222]],"id":9625043}],"con":true,"img":false}]}
{"op":"mcm","clk":"1349993793","pt":1588414918578,"mc":[{"id":"1.170370562","rc":[{"atl":[[1.56,641.63]],"id":9625043}],"con":true,"img":false}]}
{"op":"mcm","clk":"1349993817","pt":1588414919866,"mc":[{"id":"1.170370562","rc":[{"atl":[[1.53,177.3]],"id":9625043}],"con":true,"img":false}]}
{"op":"mcm","clk":"1349993820","pt":1588414919968,"mc":[{"id":"1.170370562","rc":[{"atb":[[1.92,346.21]],"id":9631798},{"atl":[[3.45,18.98]],"id":9631798}],"con":true,"img":false}]}
{"op":"mcm","clk":"1349993834","pt":1588414920587,"mc":[{"id":"1.170370562","rc":[{"atl":[[4.9,25]],"id":9631798}],"con":true,"img":false}]}
{"op":"mcm","clk":"1349993840","pt":1588414920801,"mc":[{"id":"1.170370562","rc":[{"atl":[[1.56,529.63]],"id":9625043}],"con":true,"img":false}]}
{"op":"mcm","clk":"1349993843","pt":1588414920903,"mc":[{"id":"1.170370562","rc":[{"atb":[[1.4,2.65]],"id":9625043}],"con":true,"img":false}]}
{"op":"mcm","clk":"1349993855","pt":1588414921473,"mc":[{"id":"1.170370562","rc":[{"atl":[[1.55,0]],"id":9625043}],"con":true,"img":false}]}
{"op":"mcm","clk":"1349993887","pt":1588414922711,"mc":[{"id":"1.170370562","rc":[{"atl":[[1.69,0]],"id":9625043}],"con":true,"img":false}]}
{"op":"mcm","clk":"1349993907","pt":1588414923392,"mc":[{"id":"1.170370562","rc":[{"atb":[[2.6,0]],"id":9631798}],"con":true,"img":false}]}
{"op":"mcm","clk":"1349993944","pt":1588414924805,"mc":[{"id":"1.170370562","rc":[{"atl":[[1.54,112]],"id":9625043}],"con":true,"img":false}]}
{"op":"mcm","clk":"1349993958","pt":1588414925477,"mc":[{"id":"1.170370562","rc":[{"atb":[[1.46,0]],"id":9625043}],"con":true,"img":false}]}
{"op":"mcm","clk":"1349993968","pt":1588414925894,"mc":[{"id":"1.170370562","rc":[{"atb":[[1.42,0]],"id":9625043}],"con":true,"img":false}]}
{"op":"mcm","clk":"1349994004","pt":1588414926975,"mc":[{"id":"1.170370562","rc":[{"atl":[[1.54,0]],"id":9625043}],"con":true,"img":false}]}
{"op":"mcm","clk":"1349994018","pt":1588414927492,"mc":[{"id":"1.170370562","rc":[{"trd":[[1.5,638.51]],"ltp":1.5,"tv":638.51,"id":9625043},{"atl":[[1.5,97.47]],"id":9625043}],"con":true,"img":false}]}
{"op":"mcm","clk":"1349994028","pt":1588414928004,"mc":[{"id":"1.170370562","rc":[{"trd":[[1.48,43.84]],"ltp":1.48,"tv":43.84,"id":9625043},{"atb":[[1.48,221.85]],"id":9625043}],"con":true,"img":false}]}
{"op":"mcm","clk":"1349994038","pt":1588414928210,"mc":[{"id":"1.170370562","rc":[{"trd":[[1.5,643.22]],"ltp":1.5,"tv":643.22,"id":9625043},{"atl":[[1.5,95.11]],"id":9625043}],"con":true,"img":false}]}
{"op":"mcm","clk":"1349994050","pt":1588414928675,"mc":[{"id":"1.170370562","rc":[{"trd":[[1.5,659.22]],"ltp":1.5,"tv":659.22,"id":9625043},{"atl":[[1.5,87.11]],"id":9625043}],"con":true,"img":false}]}
{"op":"mcm","clk":"1349994053","pt":1588414928777,"mc":[{"id":"1.170370562","rc":[{"atb":[[1.01,1102.13]],"id":9631798}],"con":true,"img":false}]}
{"op":"mcm","clk":"1349994055","pt":1588414928881,"mc":[{"id":"1.170370562","rc":[{"trd":[[1.5,673.24]],"ltp":1.5,"tv":673.24,"id":9625043},{"atl":[[1.5,80.1]],"id":9625043}],"con":true,"img":false}]}
{"op":"mcm","clk":"1349994060","pt":1588414928982,"mc":[{"id":"1.170370562","rc":[{"atb":[[1.01,1100.14]],"id":9631798}],"con":true,"img":false}]}
{"op":"mcm","clk":"1349994063","pt":1588414929086,"mc":[{"id":"1.170370562","rc":[{"trd":[[1.5,674.99]],"ltp":1.5,"tv":674.99,"id":9625043},{"atl":[[1.5,79.23]],"id":9625043}],"con":true,"img":false}]}
{"op":"mcm","clk":"1349994066","pt":1588414929189,"mc":[{"id":"1.170370562","rc":[{"atb":[[1.01,1100.13]],"id":9631798}],"con":true,"img":false}]}
{"op":"mcm","clk":"1349994068","pt":1588414929290,"mc":[{"id":"1.170370562","rc":[{"atb":[[1.01,1102.13]],"id":9631798}],"con":true,"img":false}]}
{"op":"mcm","clk":"1349994070","pt":1588414929395,"mc":[{"id":"1.170370562","rc":[{"trd":[[1.5,675.2]],"ltp":1.5,"tv":675.2,"id":9625043},{"atl":[[1.5,79.02]],"id":9625043},{"trd":[[3,52.57]],"ltp":3.0,"tv":52.57,"id":9631798},{"atb":[[1.01,1100.14]],"id":9631798}],"con":true,"img":false}]}
{"op":"mcm","clk":"1349994074","pt":1588414929599,"mc":[{"id":"1.170370562","rc":[{"atb":[[1.01,1100.13]],"id":9631798}],"con":true,"img":false}]}
{"op":"mcm","clk":"1349994080","pt":1588414929805,"mc":[{"id":"1.170370562","rc":[{"trd":[[1.48,133.44]],"ltp":1.48,"tv":133.44,"id":9625043},{"atb":[[1.48,177.05]],"id":9625043},{"atl":[[1.52,0]],"id":9625043},{"atb":[[1.01,1102.13]],"id":9631798}],"con":true,"img":false}]}
{"op":"mcm","clk":"1349994088","pt":1588414930111,"mc":[{"id":"1.170370562","rc":[{"atb":[[1.01,1100.14]],"id":9631798}],"con":true,"img":false}]}
{"op":"mcm","clk":"1349994090","pt":1588414930215,"mc":[{"id":"1.170370562","rc":[{"atb":[[1.01,1100.13]],"id":9631798}],"con":true,"img":false}]}
{"op":"mcm","clk":"1349994105","pt":1588414930680,"mc":[{"id":"1.170370562","rc":[{"trd":[[1.5,675.67]],"ltp":1.5,"tv":675.67,"id":9625043},{"atl":[[1.5,78.78]],"id":9625043}],"con":true,"img":false}]}
{"op":"mcm","clk":"1349994122","pt":1588414931299,"mc":[{"id":"1.170370562","rc":[{"trd":[[1.5,695.67]],"ltp":1.5,"tv":695.67,"id":9625043},{"atl":[[1.5,58.78]],"id":9625043},{"trd":[[3,62.57]],"ltp":3.0,"tv":62.57,"id":9631798}],"con":true,"img":false}]}
{"op":"mcm","clk":"1349994129","pt":1588414931510,"mc":[{"id":"1.170370562","rc":[{"atb":[[1.4,331.4]],"id":9625043}],"con":true,"img":false}]}
{"op":"mcm","clk":"1349994133","pt":1588414931615,"mc":[{"id":"1.170370562","rc":[{"atl":[[1.53,0]],"id":9625043}],"con":true,"img":false}]}
{"op":"mcm","clk":"1349994149","pt":1588414932393,"mc":[{"id":"1.170370562","rc":[{"atl":[[1.63,0]],"id":9625043}],"con":true,"img":false}]}
{"op":"mcm","clk":"1349994172","pt":1588414933114,"mc":[{"id":"1.170370562","rc":[{"trd":[[1.5,813.23]],"ltp":1.5,"tv":813.23,"id":9625043},{"atb":[[1.5,28.8]],"id":9625043},{"atl":[[1.5,0]],"id":9625043}],"con":true,"img":false}]}
{"op":"mcm","clk":"1349994177","pt":1588414933318,"mc":[{"id":"1.170370562","rc":[{"atb":[[1.45,0]],"id":9625043}],"con":true,"img":false}]}
{"op":"mcm","clk":"1349994204","pt":1588414933991,"mc":[{"id":"1.170370562","rc":[{"atb":[[1.39,196.8]],"id":9625043}],"con":true,"img":false}]}
{"op":"mcm","clk":"1349994211","pt":1588414934299,"mc":[{"id":"1.170370562","rc":[{"atb":[[2.98,0.01]],"id":9631798}],"con":true,"img":false}]}
{"op":"mcm","clk":"1349994215","pt":1588414934407,"mc":[{"id":"1.170370562","rc":[{"atb":[[1.5,38.2]],"id":9625043}],"con":true,"img":false}]}
{"op":"mcm","clk":"1349994223","pt":1588414934608,"mc":[{"id":"1.170370562","rc":[{"atb":[[1.48,0]],"id":9625043}],"con":true,"img":false}]}
{"op":"mcm","clk":"1349994229","pt":1588414934712,"mc":[{"id":"1.170370562","rc":[{"atb":[[2.84,0.01]],"id":9631798}],"con":true,"img":false}]}
{"op":"mcm","clk":"1349994243","pt":1588414935325,"mc":[{"id":"1.170370562","rc":[{"atl":[[1.56,352.33]],"id":9625043},{"atb":[[2.7,0.01]],"id":9631798}],"con":true,"img":false}]}
{"op":"mcm","clk":"1349994246","pt":1588414935427,"mc":[{"id":"1.170370562","rc":[{"atb":[[1.5,28.8]],"id":9625043}],"con":true,"img":false}]}
{"op":"mcm","clk":"1349994251","pt":1588414935584,"mc":[{"id":"1.170370562","rc":[{"atl":[[3,39.5]],"id":9631798}],"con":true,"img":false}]}
{"op":"mcm","clk":"1349994260","pt":1588414936001,"mc":[{"id":"1.170370562","rc":[{"atl":[[3,0]],"id":9631798}],"con":true,"img":false}]}
{"op":"mcm","clk":"1349994270","pt":1588414936206,"mc":[{"id":"1.170370562","rc":[{"trd":[[1.56,330.31],[1.51,1426.84],[1.55,390.32]],"ltp":1.56,"tv":2147.47,"id":9625043},{"atl":[[1.56,263.16]],"id":9625043},{"trd":[[2.84,274.91],[2.98,38.89]],"ltp":2.84,"tv":313.8,"id":9631798},{"atb":[[2.98,0],[2.84,0]],"id":9631798}],"con":true,"img":false}]}
{"op":"mcm","clk":"1349994283","pt":1588414936821,"mc":[{"id":"1.170370562","rc":[{"trd":[[1.5,833.23]],"ltp":1.5,"tv":833.23,"id":9625043},{"atb":[[1.5,18.8]],"id":9625043}],"con":true,"img":false}]}
{"op":"mcm","clk":"1349994294","pt":1588414937396,"mc":[{"id":"1.170370562","rc":[{"atb":[[1.31,500]],"id":9625043}],"con":true,"img":false}]}
{"op":"mcm","clk":"1349994306","pt":1588414937812,"mc":[{"id":"1.170370562","rc":[{"atb":[[1.36,500]],"id":9625043}],"con":true,"img":false}]}
{"op":"mcm","clk":"1349994323","pt":1588414938491,"mc":[{"id":"1.170370562","rc":[{"trd":[[1.5,853.23]],"ltp":1.5,"tv":853.23,"id":9625043},{"atb":[[1.5,8.8]],"id":9625043}],"con":true,"img":false}]}
{"op":"mcm","clk":"1349994340","pt":1588414939313,"mc":[{"id":"1.170370562","rc":[{"atb":[[1.5,24.8]],"id":9625043}],"con":true,"img":false}]}
{"op":"mcm","clk":"1349994348","pt":1588414939523,"mc":[{"id":"1.170370562","rc":[{"atb":[[1.53,5.53]],"id":9625043}],"con":true,"img":false}]}
{"op":"mcm","clk":"1349994356","pt":1588414939826,"mc":[{"id":"1.170370562","rc":[{"atb":[[1.49,492.02]],"id":9625043}],"con":true,"img":false}]}
{"op":"mcm","clk":"1349994361","pt":1588414939928,"mc":[{"id":"1.170370562","rc":[{"atb":[[1.5,8.8]],"id":9625043},{"atl":[[3.45,0]],"id":9631798}],"con":true,"img":false}]}
{"op":"mcm","clk":"1349994388","pt":1588414940806,"mc":[{"id":"1.170370562","rc":[{"atl":[[1.61,1.77]],"id":9625043}],"con":true,"img":false}]}
{"op":"mcm","clk":"1349994392","pt":1588414940909,"mc":[{"id":"1.170370562","rc":[{"atl":[[1.62,177.3]],"id":9625043}],"con":true,"img":false}]}
{"op":"mcm","clk":"1349994397","pt":1588414941010,"mc":[{"id":"1.170370562","rc":[{"atb":[[1.49,0]],"id":9625043}],"con":true,"img":false}]}
{"op":"mcm","clk":"1349994412","pt":1588414941319,"mc":[{"id":"1.170370562","rc":[{"atb":[[1.42,222]],"id":9625043}],"con":true,"img":false}]}
{"op":"mcm","clk":"1349994422","pt":1588414941625,"mc":[{"id":"1.170370562","rc":[{"atb":[[1.42,334]],"id":9625043}],"con":true,"img":false}]}
{"op":"mcm","clk":"1349994442","pt":1588414942199,"mc":[{"id":"1.170370562","rc":[{"atb":[[1.38,112]],"id":9625043}],"con":true,"img":false}]}
{"op":"mcm","clk":"1349994446","pt":1588414942302,"mc":[{"id":"1.170370562","rc":[{"atb":[[1.42,834]],"id":9625043}],"con":true,"img":false}]}
{"op":"mcm","clk":"1349994461","pt":1588414942816,"mc":[{"id":"1.170370562","rc":[{"atb":[[1.44,500]],"id":9625043}],"con":true,"img":false}]}
{"op":"mcm","clk":"1349994484","pt":1588414943494,"mc":[{"id":"1.170370562","rc":[{"atb":[[1.5,9.08]],"id":9625043}],"con":true,"img":false}]}
{"op":"mcm","clk":"1349994487","pt":1588414943598,"mc":[{"id":"1.170370562","rc":[{"atb":[[1.41,112]],"id":9625043}],"con":true,"img":false}]}
{"op":"mcm","clk":"1349994530","pt":1588414944995,"mc":[{"id":"1.170370562","rc":[{"atl":[[3.3,21.09]],"id":9631798}],"con":true,"img":false}]}
{"op":"mcm","clk":"1349994541","pt":1588414945302,"mc":[{"id":"1.170370562","rc":[{"trd":[[1.56,500.79]],"ltp":1.56,"tv":500.79,"id":9625043},{"atl":[[1.56,92.69]],"id":9625043},{"trd":[[2.78,125.16]],"ltp":2.78,"tv":125.16,"id":9631798}],"con":true,"img":false}]}
{"op":"mcm","clk":"1349994565","pt":1588414946227,"mc":[{"id":"1.170370562","rc":[{"trd":[[1.56,501.48]],"ltp":1.56,"tv":501.48,"id":9625043},{"atl":[[1.56,92.34]],"id":9625043}],"con":true,"img":false}]}
{"op":"mcm","clk":"1349994585","pt":1588414947000,"mc":[{"id":"1.170370562","rc":[{"atl":[[3,5.31]],"id":9631798}],"con":true,"img":false}]}
{"op":"mcm","clk":"1349994639","pt":1588414948697,"mc":[{"id":"1.170370562","rc":[{"atl":[[1.58,0.11]],"id":9625043}],"con":true,"img":false}]}
{"op":"mcm","clk":"1349994655","pt":1588414949420,"mc":[{"id":"1.170370562","rc":[{"atb":[[1.46,112]],"id":9625043}],"con":true,"img":false}]}
{"op":"mcm","clk":"1349994664","pt":1588414949728,"mc":[{"id":"1.170370562","rc":[{"trd":[[1.53,1100.7]],"ltp":1.53,"tv":1100.7,"id":9625043},{"atb":[[1.53,2.96]],"id":9625043}],"con":true,"img":false}]}
{"op":"mcm","clk":"1349994680","pt":1588414950141,"mc":[{"id":"1.170370562","rc":[{"atb":[[1.46,334]],"id":9625043}],"con":true,"img":false}]}
{"op":"mcm","clk":"1349994702","pt":1588414950917,"mc":[{"id":"1.170370562","rc":[{"trd":[[1.53,1106.03]],"ltp":1.53,"tv":1106.03,"id":9625043},{"atb":[[1.53,0.29]],"id":9625043}],"con":true,"img":false}]}
{"op":"mcm","clk":"1349994730","pt":1588414951846,"mc":[{"id":"1.170370562","rc":[{"trd":[[1.53,1106.63]],"ltp":1.53,"tv":1106.63,"id":9625043},{"atb":[[1.53,0]],"id":9625043},{"atl":[[1.53,20.3]],"id":9625043}],"con":true,"img":false}]}
{"op":"mcm","clk":"1349994735","pt":1588414952106,"mc":[{"id":"1.170370562","rc":[{"atl":[[1.53,20.42]],"id":9625043}],"con":true,"img":false}]}
{"op":"mcm","clk":"1349994741","pt":1588414952312,"mc":[{"id":"1.170370562","rc":[{"atl":[[1.56,12.26]],"id":9625043}],"con":true,"img":false}]}
{"op":"mcm","clk":"1349994769","pt":1588414953237,"mc":[{"id":"1.170370562","rc":[{"atb":[[1.46,112],[1.42,612]],"id":9625043}],"con":true,"img":false}]}
{"op":"mcm","clk":"1349994782","pt":1588414953648,"mc":[{"id":"1.170370562","rc":[{"atb":[[1.46,0],[1.41,0],[1.42,500],[1.38,0]],"id":9625043}],"con":true,"img":false}]}
{"op":"mcm","clk":"1349994785","pt":1588414953749,"mc":[{"id":"1.170370562","rc":[{"atl":[[1.62,0]],"id":9625043}],"con":true,"img":false}]}
{"op":"mcm","clk":"1349994788","pt":1588414953852,"mc":[{"id":"1.170370562","rc":[{"trd":[[1.5,882.04]],"ltp":1.5,"tv":882.04,"id":9625043},{"atb":[[1.5,0]],"id":9625043},{"atl":[[1.49,646.27]],"id":9625043},{"trd":[[3,67.89]],"ltp":3.0,"tv":67.89,"id":9631798},{"atl":[[3,0]],"id":9631798}],"con":true,"img":false}]}
{"op":"mcm","clk":"1349994797","pt":1588414954112,"mc":[{"id":"1.170370562","rc":[{"atb":[[1.44,0]],"id":9625043}],"con":true,"img":false}]}
{"op":"mcm","clk":"1349994811","pt":1588414954628,"mc":[{"id":"1.170370562","rc":[{"atl":[[1.53,37.94]],"id":9625043}],"con":true,"img":false}]}
{"op":"mcm","clk":"1349994815","pt":1588414954731,"mc":[{"id":"1.170370562","rc":[{"atb":[[1.42,0]],"id":9625043}],"con":true,"img":false}]}
{"op":"mcm","clk":"1349994820","pt":1588414954835,"mc":[{"id":"1.170370562","rc":[{"trd":[[1.49,1527.47]],"ltp":1.49,"tv":1527.47,"id":9625043},{"atl":[[1.49,645.32]],"id":9625043},{"trd":[[3,68.36]],"ltp":3.0,"tv":68.36,"id":9631798}],"con":true,"img":false}]}
{"op":"mcm","clk":"1349994842","pt":1588414955610,"mc":[{"id":"1.170370562","rc":[{"atl":[[1.53,215.24]],"id":9625043}],"con":true,"img":false}]}
{"op":"mcm","clk":"1349994851","pt":1588414955816,"mc":[{"id":"1.170370562","rc":[{"atl":[[1.5,492.02]],"id":9625043}],"con":true,"img":false}]}
{"op":"mcm","clk":"1349994854","pt":1588414955921,"mc":[{"id":"1.170370562","rc":[{"atb":[[1.92,0]],"id":9631798},{"atl":[[3.3,0]],"id":9631798}],"con":true,"img":false}]}
{"op":"mcm","clk":"1349994867","pt":1588414956231,"mc":[{"id":"1.170370562","rc":[{"atb":[[1.36,0]],"id":9625043}],"con":true,"img":false}]}
{"op":"mcm","clk":"1349994906","pt":1588414957523,"mc":[{"id":"1.170370562","rc":[{"atb":[[1.31,0]],"id":9625043}],"con":true,"img":false}]}
{"op":"mcm","clk":"1349994918","pt":1588414957934,"mc":[{"id":"1.170370562","rc":[{"trd":[[1.49,1793.43]],"ltp":1.49,"tv":1793.43,"id":9625043},{"atl":[[1.49,512.34]],"id":9625043}],"con":true,"img":false}]}
{"op":"mcm","clk":"1349994951","pt":1588414959023,"mc":[{"id":"1.170370562","rc":[{"atl":[[1.47,45.25]],"id":9625043}],"con":true,"img":false}]}
{"op":"mcm","clk":"1349994957","pt":1588414959332,"mc":[{"id":"1.170370562","rc":[{"atl":[[1.5,0]],"id":9625043}],"con":true,"img":false}]}
{"op":"mcm","clk":"1349994960","pt":1588414959434,"mc":[{"id":"1.170370562","rc":[{"atl":[[1.47,157.25]],"id":9625043}],"con":true,"img":false}]}
{"op":"mcm","clk":"1349994965","pt":1588414959587,"mc":[{"id":"1.170370562","rc":[{"atl":[[1.53,37.94]],"id":9625043}],"con":true,"img":false}]}
{"op":"mcm","clk":"1349994976","pt":1588414959895,"mc":[{"id":"1.170370562","rc":[{"atl":[[1.51,112]],"id":9625043}],"con":true,"img":false}]}
{"op":"mcm","clk":"1349994993","pt":1588414960464,"mc":[{"id":"1.170370562","rc":[{"atl":[[1.48,177.3]],"id":9625043}],"con":true,"img":false}]}
{"op":"mcm","clk":"1349994996","pt":1588414960565,"mc":[{"id":"1.170370562","rc":[{"atl":[[1.47,269.25]],"id":9625043}],"con":true,"img":false}]}
{"op":"mcm","clk":"1349995004","pt":1588414960878,"mc":[{"id":"1.170370562","rc":[{"atl":[[1.49,0]],"id":9625043}],"con":true,"img":false}]}
{"op":"mcm","clk":"1349995012","pt":1588414961189,"mc":[{"id":"1.170370562","rc":[{"atb":[[2.04,338.78]],"id":9631798},{"atl":[[3.9,15.52]],"id":9631798}],"con":true,"img":false}]}
{"op":"mcm","clk":"1349995023","pt":1588414961498,"mc":[{"id":"1.170370562","rc":[{"atl":[[1.47,446.55]],"id":9625043}],"con":true,"img":false}]}
{"op":"mcm","clk":"1349995053","pt":1588414962585,"mc":[{"id":"1.170370562","rc":[{"atb":[[1.4,2.65]],"id":9625043}],"con":true,"img":false}]}
{"op":"mcm","clk":"1349995057","pt":1588414962688,"mc":[{"id":"1.170370562","rc":[{"atl":[[1.61,0]],"id":9625043}],"con":true,"img":false}]}
{"op":"mcm","clk":"1349995088","pt":1588414964079,"mc":[{"id":"1.170370562","rc":[{"trd":[[1.47,17.87]],"ltp":1.47,"tv":17.87,"id":9625043},{"atl":[[1.47,437.79]],"id":9625043}],"con":true,"img":false}]}
{"op":"mcm","clk":"1349995130","pt":1588414965375,"mc":[{"id":"1.170370562","rc":[{"atb":[[1.42,222]],"id":9625043}],"con":true,"img":false}]}
{"op":"mcm","clk":"1349995142","pt":1588414965685,"mc":[{"id":"1.170370562","rc":[{"atl":[[1.5,2.75]],"id":9625043}],"con":true,"img":false}]}
{"op":"mcm","clk":"1349995147","pt":1588414965787,"mc":[{"id":"1.170370562","rc":[{"atl":[[1.46,177.3]],"id":9625043}],"con":true,"img":false}]}
{"op":"mcm","clk":"1349995154","pt":1588414965993,"mc":[{"id":"1.170370562","rc":[{"trd":[[1.46,612.03]],"ltp":1.46,"tv":612.03,"id":9625043},{"atl":[[1.46,21.06]],"id":9625043}],"con":true,"img":false}]}
{"op":"mcm","clk":"1349995156","pt":1588414966096,"mc":[{"id":"1.170370562","rc":[{"trd":[[1.46,612.54]],"ltp":1.46,"tv":612.54,"id":9625043},{"atl":[[1.46,20.8]],"id":9625043}],"con":true,"img":false}]}
{"op":"mcm","clk":"1349995164","pt":1588414966507,"mc":[{"id":"1.170370562","rc":[{"trd":[[1.42,1214.32]],"ltp":1.42,"tv":1214.32,"id":9625043},{"atb":[[1.42,200.42]],"id":9625043}],"con":true,"img":false}]}
{"op":"mcm","clk":"1349995167","pt":1588414966561,"mc":[{"id":"1.170370562","rc":[{"atl":[[1.48,0]],"id":9625043}],"con":true,"img":false}]}
{"op":"mcm","clk":"1349995176","pt":1588414967177,"mc":[{"id":"1.170370562","rc":[{"trd":[[1.47,32.75],[1.46,654.16]],"ltp":1.47,"tv":686.91,"id":9625043},{"atl":[[1.46,0],[1.47,430.35]],"id":9625043}],"con":true,"img":false}]}
{"op":"mcm","clk":"1349995180","pt":1588414967280,"mc":[{"id":"1.170370562","rc":[{"atb":[[1.4,0]],"id":9625043}],"con":true,"img":false}]}
{"op":"mcm","clk":"1349995189","pt":1588414967591,"mc":[{"id":"1.170370562","rc":[{"atb":[[1.42,0]],"id":9625043}],"con":true,"img":false}]}
{"op":"mcm","clk":"1349995210","pt":1588414968682,"mc":[{"id":"1.170370562","rc":[{"trd":[[1.47,65.99]],"ltp":1.47,"tv":65.99,"id":9625043},{"atl":[[1.47,413.73]],"id":9625043}],"con":true,"img":false}]}
{"op":"mcm","clk":"1349995213","pt":1588414968785,"mc":[{"id":"1.170370562","rc":[{"trd":[[1.47,69.53]],"ltp":1.47,"tv":69.53,"id":9625043},{"atl":[[1.47,411.96]],"id":9625043}],"con":true,"img":false}]}
{"op":"mcm","clk":"1349995224","pt":1588414969095,"mc":[{"id":"1.170370562","rc":[{"atb":[[1.01,1102.13]],"id":9631798}],"con":true,"img":false}]}
{"op":"mcm","clk":"1349995232","pt":1588414969302,"mc":[{"id":"1.170370562","rc":[{"atb":[[1.32,112]],"id":9625043},{"atb":[[1.01,1100.14]],"id":9631798}],"con":true,"img":false}]}
{"op":"mcm","clk":"1349995238","pt":1588414969508,"mc":[{"id":"1.170370562","rc":[{"atb":[[1.01,1100.13]],"id":9631798}],"con":true,"img":false}]}
{"op":"mcm","clk":"1349995249","pt":1588414969768,"mc":[{"id":"1.170370562","rc":[{"atb":[[1.29,112]],"id":9625043}],"con":true,"img":false}]}
{"op":"mcm","clk":"1349995286","pt":1588414971002,"mc":[{"id":"1.170370562","rc":[{"atl":[[1.47,412.3]],"id":9625043}],"con":true,"img":false}]}
{"op":"mcm","clk":"1349995335","pt":1588414972393,"mc":[{"id":"1.170370562","rc":[{"trd":[[1.47,87.26]],"ltp":1.47,"tv":87.26,"id":9625043},{"atl":[[1.47,403.43]],"id":9625043}],"con":true,"img":false}]}
{"op":"mcm","clk":"1349995354","pt":1588414972965,"mc":[{"id":"1.170370562","rc":[{"trd":[[1.47,104.78]],"ltp":1.47,"tv":104.78,"id":9625043},{"atl":[[1.47,394.67]],"id":9625043}],"con":true,"img":false}]}
{"op":"mcm","clk":"1349995358","pt":1588414973069,"mc":[{"id":"1.170370562","rc":[{"atb":[[1.4,0.15]],"id":9625043},{"atl":[[3.9,0]],"id":9631798}],"con":true,"img":false}]}
{"op":"mcm","clk":"1349995366","pt":1588414973380,"mc":[{"id":"1.170370562","rc":[{"atl":[[1.49,177.3]],"id":9625043}],"con":true,"img":false}]}
{"op":"mcm","clk":"1349995386","pt":1588414974105,"mc":[{"id":"1.170370562","rc":[{"atb":[[1.39,0]],"id":9625043}],"con":true,"img":false}]}
{"op":"mcm","clk":"1349995396","pt":1588414974473,"mc":[{"id":"1.170370562","rc":[{"trd":[[1.47,105.62]],"ltp":1.47,"tv":105.62,"id":9625043},{"atl":[[1.47,394.25]],"id":9625043}],"con":true,"img":false}]}
{"op":"mcm","clk":"1349995399","pt":1588414974574,"mc":[{"id":"1.170370562","rc":[{"atb":[[2.98,0.01]],"id":9631798}],"con":true,"img":false}]}
{"op":"mcm","clk":"1349995520","pt":1588414978876,"mc":[{"id":"1.170370562","rc":[{"atl":[[4.9,0]],"id":9631798}],"con":true,"img":false}]}
{"op":"mcm","clk":"1349995531","pt":1588414979186,"mc":[{"id":"1.170370562","rc":[{"trd":[[1.47,467.46]],"ltp":1.47,"tv":467.46,"id":9625043},{"atl":[[1.47,213.33]],"id":9625043},{"atl":[[3.65,17.31]],"id":9631798}],"con":true,"img":false}]}
{"op":"mcm","clk":"1349995546","pt":1588414979810,"mc":[{"id":"1.170370562","rc":[{"atb":[[1.36,196.8]],"id":9625043}],"con":true,"img":false}]}
{"op":"mcm","clk":"1349995592","pt":1588414981580,"mc":[{"id":"1.170370562","rc":[{"atb":[[1.02,985.81]],"id":9625043}],"con":true,"img":false}]}
{"op":"mcm","clk":"1349995596","pt":1588414981684,"mc":[{"id":"1.170370562","rc":[{"atb":[[1.4,10.15]],"id":9625043}],"con":true,"img":false}]}
{"op":"mcm","clk":"1349995623","pt":1588414982774,"mc":[{"id":"1.170370562","rc":[{"atb":[[1.39,177.3]],"id":9625043}],"con":true,"img":false}]}
{"op":"mcm","clk":"1349995655","pt":1588414983976,"mc":[{"id":"1.170370562","rc":[{"atl":[[4.1,25]],"id":9631798}],"con":true,"img":false}]}
{"op":"mcm","clk":"1349995669","pt":1588414984285,"mc":[{"id":"1.170370562","rc":[{"atb":[[1.4,0.15]],"id":9625043}],"con":true,"img":false}]}
{"op":"mcm","clk":"1349995693","pt":1588414985008,"mc":[{"id":"1.170370562","rc":[{"atl":[[1.43,666]],"id":9625043}],"con":true,"img":false}]}
{"op":"mcm","clk":"1349995701","pt":1588414985316,"mc":[{"id":"1.170370562","rc":[{"atl":[[4.1,0]],"id":9631798}],"con":true,"img":false}]}
{"op":"mcm","clk":"1349995736","pt":1588414986299,"mc":[{"id":"1.170370562","rc":[{"trd":[[1.43,420.99]],"ltp":1.43,"tv":420.99,"id":9625043},{"atl":[[1.43,664.23]],"id":9625043}],"con":true,"img":false}]}
{"op":"mcm","clk":"1349995741","pt":1588414986402,"mc":[{"id":"1.170370562","rc":[{"atl":[[1.42,492.02]],"id":9625043}],"con":true,"img":false}]}
{"op":"mcm","clk":"1349995744","pt":1588414986505,"mc":[{"id":"1.170370562","rc":[{"atb":[[1.41,151.88]],"id":9625043}],"con":true,"img":false}]}
{"op":"mcm","clk":"1349995755","pt":1588414986917,"mc":[{"id":"1.170370562","rc":[{"atb":[[1.41,0],[1.32,0],[1.29,0]],"id":9625043}],"con":true,"img":false}]}
{"op":"mcm","clk":"1349995780","pt":1588414988202,"mc":[{"id":"1.170370562","rc":[{"atl":[[1.46,55],[1.43,0]],"id":9625043}],"con":true,"img":false}]}
{"op":"mcm","clk":"1349995785","pt":1588414988307,"mc":[{"id":"1.170370562","rc":[{"atb":[[1.39,0]],"id":9625043}],"con":true,"img":false}]}
{"op":"mcm","clk":"1349995811","pt":1588414989285,"mc":[{"id":"1.170370562","rc":[{"atl":[[1.46,240],[1.42,0]],"id":9625043}],"con":true,"img":false}]}
{"op":"mcm","clk":"1349995820","pt":1588414989694,"mc":[{"id":"1.170370562","rc":[{"atb":[[1.36,0]],"id":9625043}],"con":true,"img":false}]}
{"op":"mcm","clk":"1349995838","pt":1588414990417,"mc":[{"id":"1.170370562","rc":[{"atl":[[4.8,25]],"id":9631798}],"con":true,"img":false}]}
{"op":"mcm","clk":"1349995853","pt":1588414990986,"mc":[{"id":"1.170370562","rc":[{"atl":[[3.5,38]],"id":9631798}],"con":true,"img":false}]}
{"op":"mcm","clk":"1349995861","pt":1588414991398,"mc":[{"id":"1.170370562","rc":[{"atl":[[1.42,55]],"id":9625043}],"con":true,"img":false}]}
{"op":"mcm","clk":"1349995875","pt":1588414992020,"mc":[{"id":"1.170370562","rc":[{"trd":[[1.4,3266.78]],"ltp":1.4,"tv":3266.78,"id":9625043},{"atb":[[1.4,0]],"id":9625043},{"trd":[[3.5,8.72]],"ltp":3.5,"tv":8.72,"id":9631798},{"atl":[[3.5,29.3]],"id":9631798}],"con":true,"img":false}]}
{"op":"mcm","clk":"1349995904","pt":1588414992897,"mc":[{"id":"1.170370562","rc":[{"atb":[[1.39,154.07]],"id":9625043}],"con":true,"img":false}]}
{"op":"mcm","clk":"1349995917","pt":1588414993723,"mc":[{"id":"1.170370562","rc":[{"atl":[[1.47,36.03]],"id":9625043}],"con":true,"img":false}]}
{"op":"mcm","clk":"1349995932","pt":1588414994190,"mc":[{"id":"1.170370562","rc":[{"atb":[[1.3,222]],"id":9625043}],"con":true,"img":false}]}
{"op":"mcm","clk":"1349995939","pt":1588414994495,"mc":[{"id":"1.170370562","rc":[{"atb":[[1.25,222]],"id":9625043}],"con":true,"img":false}]}
{"op":"mcm","clk":"1349995955","pt":1588414994907,"mc":[{"id":"1.170370562","rc":[{"atb":[[1.21,222]],"id":9625043},{"atl":[[1.46,732.02]],"id":9625043}],"con":true,"img":false}]}
{"op":"mcm","clk":"1349995963","pt":1588414995115,"mc":[{"id":"1.170370562","rc":[{"trd":[[1.4,3321.78]],"ltp":1.4,"tv":3321.78,"id":9625043},{"atb":[[1.19,222]],"id":9625043},{"trd":[[3.5,30.73]],"ltp":3.5,"tv":30.73,"id":9631798},{"atl":[[3.5,7.3]],"id":9631798}],"con":true,"img":false}]}
{"op":"mcm","clk":"1349995972","pt":1588414995631,"mc":[{"id":"1.170370562","rc":[{"trd":[[1.42,1214.56]],"ltp":1.42,"tv":1214.56,"id":9625043},{"atl":[[1.46,492.02],[1.42,54.88]],"id":9625043}],"con":true,"img":false}]}
{"op":"mcm","clk":"1349995988","pt":1588414995889,"mc":[{"id":"1.170370562","rc":[{"atb":[[3.35,833.12]],"id":9631798}],"con":true,"img":false}]}
{"op":"mcm","clk":"1349995990","pt":1588414995989,"mc":[{"id":"1.170370562","rc":[{"atb":[[1.31,240]],"id":9625043}],"con":true,"img":false}]}
{"op":"mcm","clk":"1349995993","pt":1588414996200,"mc":[{"id":"1.170370562","rc":[{"atl":[[1.42,0]],"id":9625043}],"con":true,"img":false}]}
{"op":"mcm","clk":"1349995999","pt":1588414996509,"mc":[{"id":"1.170370562","rc":[{"atl":[[1.46,0]],"id":9625043}],"con":true,"img":false}]}
{"op":"mcm","clk":"1349996003","pt":1588414996610,"mc":[{"id":"1.170370562","rc":[{"atb":[[1.26,240]],"id":9625043}],"con":true,"img":false}]}
{"op":"mcm","clk":"1349996015","pt":1588414997123,"mc":[{"id":"1.170370562","rc":[{"atb":[[1.29,240]],"id":9625043}],"con":true,"img":false}]}
{"op":"mcm","clk":"1349996019","pt":1588414997228,"mc":[{"id":"1.170370562","rc":[{"atb":[[1.19,0],[1.42,2.57]],"id":9625043}],"con":true,"img":false}]}
{"op":"mcm","clk":"1349996026","pt":1588414997534,"mc":[{"id":"1.170370562","rc":[{"atl":[[1.45,177.3]],"id":9625043}],"con":true,"img":false}]}
{"op":"mcm","clk":"1349996035","pt":1588414998002,"mc":[{"id":"1.170370562","rc":[{"atb":[[1.42,5.15]],"id":9625043}],"con":true,"img":false}]}
{"op":"mcm","clk":"1349996054","pt":1588414998892,"mc":[{"id":"1.170370562","rc":[{"atb":[[1.35,2.65],[1.42,21.26]],"id":9625043},{"atb":[[1.01,1102.13]],"id":9631798}],"con":true,"img":false}]}
{"op":"mcm","clk":"1349996057","pt":1588414998994,"mc":[{"id":"1.170370562","rc":[{"atb":[[1.36,265.95]],"id":9625043}],"con":true,"img":false}]}
{"op":"mcm","clk":"1349996061","pt":1588414999098,"mc":[{"id":"1.170370562","rc":[{"atb":[[1.01,1100.14]],"id":9631798}],"con":true,"img":false}]}
{"op":"mcm","clk":"1349996067","pt":1588414999308,"mc":[{"id":"1.170370562","rc":[{"atb":[[1.01,1100.13]],"id":9631798}],"con":true,"img":false}]}
{"op":"mcm","clk":"1349996079","pt":1588414999722,"mc":[{"id":"1.170370562","rc":[{"atb":[[1.02,985.14]],"id":9625043}],"con":true,"img":false}]}
{"op":"mcm","clk":"1349996095","pt":1588415000188,"mc":[{"id":"1.170370562","rc":[{"atl":[[1.45,443.26]],"id":9625043}],"con":true,"img":false}]}
{"op":"mcm","clk":"1349996097","pt":1588415000291,"mc":[{"id":"1.170370562","rc":[{"atb":[[1.42,23.32]],"id":9625043},{"atl":[[1000,2.65]],"id":9625043}],"con":true,"img":false}]}
{"op":"mcm","clk":"1349996102","pt":1588415000395,"mc":[{"id":"1.170370562","rc":[{"atb":[[1.42,32.08],[1.31,0]],"id":9625043}],"con":true,"img":false}]}
{"op":"mcm","clk":"1349996105","pt":1588415000502,"mc":[{"id":"1.170370562","rc":[{"atb":[[1.35,0]],"id":9625043}],"con":true,"img":false}]}
{"op":"mcm","clk":"1349996118","pt":1588415000920,"mc":[{"id":"1.170370562","rc":[{"trd":[[1.3,3566.16],[1.4,3340.03],[1.36,531.91],[1.42,1278.74],[1.37,46.12],[1.39,879.45]],"ltp":1.3,"tv":9642.41,"id":9625043},{"atb":[[1.39,0],[1.36,0],[1.3,0],[1.42,0]],"id":9625043},{"atl":[[1.3,6479.48]],"id":9625043},{"trd":[[3.65,17.31],[3.5,38.03]],"ltp":3.65,"tv":55.34,"id":9631798},{"atl":[[3.5,0],[3.65,0]],"id":9631798}],"con":true,"img":false}]}
{"op":"mcm","clk":"1349996127","pt":1588415001132,"mc":[{"id":"1.170370562","rc":[{"atl":[[1000,0.08]],"id":9625043},{"atb":[[1.01,1102.13]],"id":9631798}],"con":true,"img":false}]}
{"op":"mcm","clk":"1349996136","pt":1588415001337,"mc":[{"id":"1.170370562","rc":[{"atb":[[1.01,1100.14]],"id":9631798}],"con":true,"img":false}]}
{"op":"mcm","clk":"1349996145","pt":1588415001542,"mc":[{"id":"1.170370562","rc":[{"trd":[[1.3,3579.39]],"ltp":1.3,"tv":3579.39,"id":9625043},{"atl":[[1.3,6466.25]],"id":9625043},{"trd":[[4.3,4]],"ltp":4.3,"tv":4.0,"id":9631798},{"atb":[[1.01,1100.13]],"id":9631798}],"con":true,"img":false}]}
{"op":"mcm","clk":"1349996161","pt":1588415001905,"mc":[{"id":"1.170370562","rc":[{"trd":[[1.3,3581.22]],"ltp":1.3,"tv":3581.22,"id":9625043},{"atl":[[1.3,6465.33]],"id":9625043}],"con":true,"img":false}]}
{"op":"mcm","clk":"1349996166","pt":1588415002007,"mc":[{"id":"1.170370562","rc":[{"atl":[[1000,0.05]],"id":9625043}],"con":true,"img":false}]}
{"op":"mcm","clk":"1349996171","pt":1588415002215,"mc":[{"id":"1.170370562","rc":[{"trd":[[1.3,3639.87]],"ltp":1.3,"tv":3639.87,"id":9625043},{"atl":[[1.3,6406.69]],"id":9625043},{"trd":[[4.3,21.73]],"ltp":4.3,"tv":21.73,"id":9631798}],"con":true,"img":false}]}
{"op":"mcm","clk":"1349996175","pt":1588415002319,"mc":[{"id":"1.170370562","rc":[{"atb":[[1.17,222]],"id":9625043}],"con":true,"img":false}]}
{"op":"mcm","clk":"1349996183","pt":1588415002524,"mc":[{"id":"1.170370562","rc":[{"trd":[[1.3,3698.51]],"ltp":1.3,"tv":3698.51,"id":9625043},{"atl":[[1.3,6348.04]],"id":9625043},{"trd":[[4.3,39.46]],"ltp":4.3,"tv":39.46,"id":9631798}],"con":true,"img":false}]}
{"op":"mcm","clk":"1349996186","pt":1588415002629,"mc":[{"id":"1.170370562","rc":[{"atl":[[1.47,35.69]],"id":9625043}],"con":true,"img":false}]}
{"op":"mcm","clk":"1349996191","pt":1588415002740,"mc":[{"id":"1.170370562","rc":[{"trd":[[1.3,3757.16]],"ltp":1.3,"tv":3757.16,"id":9625043},{"atl":[[1.3,6289.39]],"id":9625043},{"trd":[[4.3,57.19]],"ltp":4.3,"tv":57.19,"id":9631798}],"con":true,"img":false}]}
{"op":"mcm","clk":"1349996210","pt":1588415003143,"mc":[{"id":"1.170370562","rc":[{"atl":[[1.37,15.2]],"id":9625043}],"con":true,"img":false}]}
{"op":"mcm","clk":"1349996214","pt":1588415003243,"mc":[{"id":"1.170370562","rc":[{"atb":[[3.35,0]],"id":9631798}],"con":true,"img":false}]}
{"op":"mcm","clk":"1349996220","pt":1588415003298,"mc":[{"id":"1.170370562","rc":[{"trd":[[1.3,3874.45]],"ltp":1.3,"tv":3874.45,"id":9625043},{"atl":[[1.3,6172.1]],"id":9625043},{"trd":[[4.3,92.65]],"ltp":4.3,"tv":92.65,"id":9631798}],"con":true,"img":false}]}
{"op":"mcm","clk":"1349996234","pt":1588415003609,"mc":[{"id":"1.170370562","rc":[{"trd":[[1.3,4318.45]],"ltp":1.3,"tv":4318.45,"id":9625043},{"atl":[[1.3,5950.1]],"id":9625043}],"con":true,"img":false}]}
{"op":"mcm","clk":"1349996237","pt":1588415003711,"mc":[{"id":"1.170370562","rc":[{"atl":[[4.8,0]],"id":9631798}],"con":true,"img":false}]}
{"op":"mcm","clk":"1349996256","pt":1588415004128,"mc":[{"id":"1.170370562","rc":[{"atl":[[1.44,72.94]],"id":9625043}],"con":true,"img":false}]}
{"op":"mcm","clk":"1349996262","pt":1588415004335,"mc":[{"id":"1.170370562","rc":[{"atl":[[1.42,37.47]],"id":9625043}],"con":true,"img":false}]}
{"op":"mcm","clk":"1349996264","pt":1588415004440,"mc":[{"id":"1.170370562","rc":[{"atb":[[1.29,0]],"id":9625043},{"atb":[[3.45,0.01]],"id":9631798}],"con":true,"img":false}]}
{"op":"mcm","clk":"1349996280","pt":1588415004851,"mc":[{"id":"1.170370562","rc":[{"trd":[[1.3,4323.61]],"ltp":1.3,"tv":4323.61,"id":9625043},{"atl":[[1.3,5947.53]],"id":9625043}],"con":true,"img":false}]}
{"op":"mcm","clk":"1349996326","pt":1588415006652,"mc":[{"id":"1.170370562","rc":[{"atb":[[3.25,0.01]],"id":9631798}],"con":true,"img":false}]}
{"op":"mcm","clk":"1349996332","pt":1588415006913,"mc":[{"id":"1.170370562","rc":[{"trd":[[1.3,4325.17]],"ltp":1.3,"tv":4325.17,"id":9625043},{"atl":[[1.3,5945.96]],"id":9625043},{"trd":[[4.3,93.12]],"ltp":4.3,"tv":93.12,"id":9631798}],"con":true,"img":false}]}
{"op":"mcm","clk":"1349996337","pt":1588415007120,"mc":[{"id":"1.170370562","rc":[{"atl":[[1.4,0.03]],"id":9625043}],"con":true,"img":false}]}
{"op":"mcm","clk":"1349996356","pt":1588415007744,"mc":[{"id":"1.170370562","rc":[{"trd":[[1.3,5325.17]],"ltp":1.3,"tv":5325.17,"id":9625043},{"atl":[[1.3,5445.96]],"id":9625043}],"con":true,"img":false}]}
{"op":"mcm","clk":"1349996360","pt":1588415007847,"mc":[{"id":"1.170370562","rc":[{"trd":[[1.3,5679.78]],"ltp":1.3,"tv":5679.78,"id":9625043},{"atl":[[1.3,5268.66]],"id":9625043}],"con":true,"img":false}]}
{"op":"mcm","clk":"1349996362","pt":1588415007947,"mc":[{"id":"1.170370562","rc":[{"trd":[[1.3,6663.82]],"ltp":1.3,"tv":6663.82,"id":9625043},{"atl":[[1.3,4776.64]],"id":9625043}],"con":true,"img":false}]}
{"op":"mcm","clk":"1349996365","pt":1588415008053,"mc":[{"id":"1.170370562","rc":[{"trd":[[1.3,8195.73]],"ltp":1.3,"tv":8195.73,"id":9625043},{"atl":[[1.3,4010.68]],"id":9625043}],"con":true,"img":false}]}
{"op":"mcm","clk":"1349996370","pt":1588415008103,"mc":[{"id":"1.170370562","rc":[{"atl":[[1000,1.94],[1.47,35.8]],"id":9625043}],"con":true,"img":false}]}
{"op":"mcm","clk":"1349996373","pt":1588415008207,"mc":[{"id":"1.170370562","rc":[{"atb":[[1.21,0],[1.25,0],[1.17,0]],"id":9625043}],"con":true,"img":false}]}
{"op":"mcm","clk":"1349996377","pt":1588415008310,"mc":[{"id":"1.170370562","rc":[{"trd":[[1.3,8202.74]],"ltp":1.3,"tv":8202.74,"id":9625043},{"atl":[[1.3,4007.18]],"id":9625043}],"con":true,"img":false}]}
{"op":"mcm","clk":"1349996379","pt":1588415008413,"mc":[{"id":"1.170370562","rc":[{"trd":[[1.3,8557.35]],"ltp":1.3,"tv":8557.35,"id":9625043},{"atl":[[1.3,3829.87],[1.42,0]],"id":9625043}],"con":true,"img":false}]}
{"op":"mcm","clk":"1349996382","pt":1588415008518,"mc":[{"id":"1.170370562","rc":[{"trd":[[1.3,9089.26]],"ltp":1.3,"tv":9089.26,"id":9625043},{"atl":[[1.3,3563.92]],"id":9625043}],"con":true,"img":false}]}
{"op":"mcm","clk":"1349996386","pt":1588415008722,"mc":[{"id":"1.170370562","rc":[{"atl":[[1000,0.48]],"id":9625043}],"con":true,"img":false}]}
{"op":"mcm","clk":"1349996400","pt":1588415009239,"mc":[{"id":"1.170370562","rc":[{"trd":[[1.3,9621.18]],"ltp":1.3,"tv":9621.18,"id":9625043},{"atl":[[1.3,3297.96]],"id":9625043}],"con":true,"img":false}]}
{"op":"mcm","clk":"1349996405","pt":1588415009445,"mc":[{"id":"1.170370562","rc":[{"atl":[[1000,0.05]],"id":9625043}],"con":true,"img":false}]}
{"op":"mcm","clk":"1349996416","pt":1588415009755,"mc":[{"id":"1.170370562","rc":[{"atb":[[1.01,1102.13]],"id":9631798}],"con":true,"img":false}]}
{"op":"mcm","clk":"1349996420","pt":1588415009857,"mc":[{"id":"1.170370562","rc":[{"trd":[[1.3,10065.18]],"ltp":1.3,"tv":10065.18,"id":9625043},{"atl":[[1.3,3075.96]],"id":9625043},{"atb":[[1.01,1100.14]],"id":9631798}],"con":true,"img":false}]}
{"op":"mcm","clk":"1349996424","pt":1588415009912,"mc":[{"id":"1.170370562","rc":[{"trd":[[1.3,10509.18]],"ltp":1.3,"tv":10509.18,"id":9625043},{"atl":[[1.3,2853.96]],"id":9625043}],"con":true,"img":false}]}
{"op":"mcm","clk":"1349996426","pt":1588415010064,"mc":[{"id":"1.170370562","rc":[{"trd":[[1.3,11041.09]],"ltp":1.3,"tv":11041.09,"id":9625043},{"atl":[[1.3,2588]],"id":9625043},{"atb":[[1.01,1100.13]],"id":9631798}],"con":true,"img":false}]}
{"op":"mcm","clk":"1349996444","pt":1588415010606,"mc":[{"id":"1.170370562","rc":[{"atb":[[1.01,1102.13]],"id":9631798}],"con":true,"img":false}]}
{"op":"mcm","clk":"1349996451","pt":1588415010732,"mc":[{"id":"1.170370562","rc":[{"atb":[[1.01,1100.14]],"id":9631798}],"con":true,"img":false}]}
{"op":"mcm","clk":"1349996458","pt":1588415010959,"mc":[{"id":"1.170370562","rc":[{"atb":[[1.01,1100.13]],"id":9631798}],"con":true,"img":false}]}
{"op":"mcm","clk":"1349996469","pt":1588415011247,"mc":[{"id":"1.170370562","rc":[{"trd":[[1.3,11054.29]],"ltp":1.3,"tv":11054.29,"id":9625043},{"atl":[[1.3,2574.81]],"id":9625043},{"trd":[[4.3,97.11]],"ltp":4.3,"tv":97.11,"id":9631798}],"con":true,"img":false}]}
{"op":"mcm","clk":"1349996473","pt":1588415011451,"mc":[{"id":"1.170370562","rc":[{"atb":[[1.17,240]],"id":9625043},{"atl":[[1.45,177.3]],"id":9625043}],"con":true,"img":false}]}
{"op":"mcm","clk":"1349996482","pt":1588415011756,"mc":[{"id":"1.170370562","rc":[{"trd":[[1.3,11054.49]],"ltp":1.3,"tv":11054.49,"id":9625043},{"atl":[[1.3,2574.71]],"id":9625043}],"con":true,"img":false}]}
{"op":"mcm","clk":"1349996486","pt":1588415011858,"mc":[{"id":"1.170370562","rc":[{"trd":[[1.3,11058.61]],"ltp":1.3,"tv":11058.61,"id":9625043},{"atl":[[1.3,2572.64]],"id":9625043}],"con":true,"img":false}]}
{"op":"mcm","clk":"1349996492","pt":1588415012168,"mc":[{"id":"1.170370562","rc":[{"trd":[[1.3,11099.46]],"ltp":1.3,"tv":11099.46,"id":9625043},{"atl":[[1.3,2552.22]],"id":9625043}],"con":true,"img":false}]}
{"op":"mcm","clk":"1349996496","pt":1588415012221,"mc":[{"id":"1.170370562","rc":[{"trd":[[1.3,11121.62]],"ltp":1.3,"tv":11121.62,"id":9625043},{"atl":[[1.3,2541.14]],"id":9625043}],"con":true,"img":false}]}
{"op":"mcm","clk":"1349996504","pt":1588415012426,"mc":[{"id":"1.170370562","rc":[{"trd":[[1.3,11125.33]],"ltp":1.3,"tv":11125.33,"id":9625043},{"atl":[[1.37,281.15],[1.3,2539.29]],"id":9625043}],"con":true,"img":false}]}
{"op":"mcm","clk":"1349996512","pt":1588415012632,"mc":[{"id":"1.170370562","rc":[{"atl":[[1.37,265.95]],"id":9625043}],"con":true,"img":false}]}
{"op":"mcm","clk":"1349996527","pt":1588415013146,"mc":[{"id":"1.170370562","rc":[{"trd":[[1.3,11126.75]],"ltp":1.3,"tv":11126.75,"id":9625043},{"atl":[[1.3,2538.58]],"id":9625043}],"con":true,"img":false}]}
{"op":"mcm","clk":"1349996529","pt":1588415013249,"mc":[{"id":"1.170370562","rc":[{"atl":[[1.33,488.32]],"id":9625043}],"con":true,"img":false}]}
{"op":"mcm","clk":"1349996533","pt":1588415013352,"mc":[{"id":"1.170370562","rc":[{"trd":[[1.3,11153.06]],"ltp":1.3,"tv":11153.06,"id":9625043},{"atl":[[1.3,2525.25]],"id":9625043},{"trd":[[4.3,97.21]],"ltp":4.3,"tv":97.21,"id":9631798}],"con":true,"img":false}]}
{"op":"mcm","clk":"1349996543","pt":1588415013862,"mc":[{"id":"1.170370562","rc":[{"atb":[[1.27,196.8]],"id":9625043}],"con":true,"img":false}]}
{"op":"mcm","clk":"1349996546","pt":1588415013916,"mc":[{"id":"1.170370562","rc":[{"atl":[[1.35,265.95]],"id":9625043}],"con":true,"img":false}]}
{"op":"mcm","clk":"1349996553","pt":1588415014222,"mc":[{"id":"1.170370562","rc":[{"trd":[[1.3,11153.99]],"ltp":1.3,"tv":11153.99,"id":9625043},{"atl":[[1.3,2524.78]],"id":9625043}],"con":true,"img":false}]}
{"op":"mcm","clk":"1349996558","pt":1588415014426,"mc":[{"id":"1.170370562","rc":[{"atb":[[1.27,0]],"id":9625043}],"con":true,"img":false}]}
{"op":"mcm","clk":"1349996561","pt":1588415014531,"mc":[{"id":"1.170370562","rc":[{"atl":[[1.29,0.43]],"id":9625043}],"con":true,"img":false}]}
{"op":"mcm","clk":"1349996564","pt":1588415014634,"mc":[{"id":"1.170370562","rc":[{"atl":[[1.33,754.28]],"id":9625043}],"con":true,"img":false}]}
{"op":"mcm","clk":"1349996569","pt":1588415014738,"mc":[{"id":"1.170370562","rc":[{"trd":[[1.3,11157.84],[1.29,0.87]],"ltp":1.3,"tv":11158.71,"id":9625043},{"atl":[[1.3,2522.86],[1.29,0]],"id":9625043}],"con":true,"img":false}]}
{"op":"mcm","clk":"1349996581","pt":1588415015046,"mc":[{"id":"1.170370562","rc":[{"atl":[[1.36,177.3]],"id":9625043}],"con":true,"img":false}]}
{"op":"mcm","clk":"1349996584","pt":1588415015149,"mc":[{"id":"1.170370562","rc":[{"atb":[[3.8,0.01]],"id":9631798}],"con":true,"img":false}]}
{"op":"mcm","clk":"1349996590","pt":1588415015356,"mc":[{"id":"1.170370562","rc":[{"atl":[[5.6,25]],"id":9631798}],"con":true,"img":false}]}
{"op":"mcm","clk":"1349996597","pt":1588415015459,"mc":[{"id":"1.170370562","rc":[{"trd":[[1.3,11159.4]],"ltp":1.3,"tv":11159.4,"id":9625043},{"atl":[[1.35,0],[1.3,2522.08]],"id":9625043}],"con":true,"img":false}]}
{"op":"mcm","clk":"1349996601","pt":1588415015563,"mc":[{"id":"1.170370562","rc":[{"atl":[[1.44,0]],"id":9625043}],"con":true,"img":false}]}
{"op":"mcm","clk":"1349996605","pt":1588415015661,"mc":[{"id":"1.170370562","rc":[{"atl":[[1.39,177.3]],"id":9625043}],"con":true,"img":false}]}
{"op":"mcm","clk":"1349996610","pt":1588415015865,"mc":[{"id":"1.170370562","rc":[{"atl":[[6.2,25]],"id":9631798}],"con":true,"img":false}]}
{"op":"mcm","clk":"1349996613","pt":1588415015967,"mc":[{"id":"1.170370562","rc":[{"trd":[[1.3,11169.96]],"ltp":1.3,"tv":11169.96,"id":9625043},{"atl":[[1.37,0],[1.3,2516.8]],"id":9625043}],"con":true,"img":false}]}
{"op":"mcm","clk":"1349996617","pt":1588415016020,"mc":[{"id":"1.170370562","rc":[{"atb":[[3.55,0.01]],"id":9631798}],"con":true,"img":false}]}
{"op":"mcm","clk":"1349996619","pt":1588415016123,"mc":[{"id":"1.170370562","rc":[{"atl":[[5.6,0]],"id":9631798}],"con":true,"img":false}]}
{"op":"mcm","clk":"1349996625","pt":1588415016329,"mc":[{"id":"1.170370562","rc":[{"atl":[[1.34,222]],"id":9625043}],"con":true,"img":false}]}
{"op":"mcm","clk":"1349996640","pt":1588415016945,"mc":[{"id":"1.170370562","rc":[{"atl":[[1.32,222]],"id":9625043}],"con":true,"img":false}]}
{"op":"mcm","clk":"1349996645","pt":1588415017153,"mc":[{"id":"1.170370562","rc":[{"trd":[[1.3,11170.2]],"ltp":1.3,"tv":11170.2,"id":9625043},{"atl":[[1.3,2516.68]],"id":9625043}],"con":true,"img":false}]}
{"op":"mcm","clk":"1349996661","pt":1588415017665,"mc":[{"id":"1.170370562","rc":[{"trd":[[1.3,11195.79]],"ltp":1.3,"tv":11195.79,"id":9625043},{"atl":[[1.34,487.95],[1.3,2503.88]],"id":9625043}],"con":true,"img":false}]}
{"op":"mcm","clk":"1349996681","pt":1588415018129,"mc":[{"id":"1.170370562","rc":[{"trd":[[1.3,11207.55]],"ltp":1.3,"tv":11207.55,"id":9625043},{"atl":[[1.3,2498]],"id":9625043}],"con":true,"img":false}]}
{"op":"mcm","clk":"1349996684","pt":1588415018234,"mc":[{"id":"1.170370562","rc":[{"trd":[[1.26,40]],"ltp":1.26,"tv":40.0,"id":9625043},{"atb":[[1.26,220]],"id":9625043}],"con":true,"img":false}]}
{"op":"mcm","clk":"1349996697","pt":1588415018641,"mc":[{"id":"1.170370562","rc":[{"trd":[[1.3,11234.74]],"ltp":1.3,"tv":11234.74,"id":9625043},{"atl":[[1.3,2484.41]],"id":9625043}],"con":true,"img":false}]}
{"op":"mcm","clk":"1349996709","pt":1588415018848,"mc":[{"id":"1.170370562","rc":[{"atl":[[1.38,222]],"id":9625043}],"con":true,"img":false}]}
{"op":"mcm","clk":"1349996738","pt":1588415019771,"mc":[{"id":"1.170370562","rc":[{"trd":[[1.3,11239.89]],"ltp":1.3,"tv":11239.89,"id":9625043},{"atl":[[1.3,2481.83]],"id":9625043}],"con":true,"img":false}]}
{"op":"mcm","clk":"1349996748","pt":1588415020028,"mc":[{"id":"1.170370562","rc":[{"trd":[[1.3,11750.12]],"ltp":1.3,"tv":11750.12,"id":9625043},{"atl":[[1.3,1971.6],[1.29,355]],"id":9625043},{"trd":[[4.3,251.47]],"ltp":4.3,"tv":251.47,"id":9631798}],"con":true,"img":false}]}
{"op":"mcm","clk":"1349996753","pt":1588415020131,"mc":[{"id":"1.170370562","rc":[{"trd":[[1.29,25.24]],"ltp":1.29,"tv":25.24,"id":9625043},{"atl":[[1.29,330.63]],"id":9625043},{"trd":[[4.4,7.14]],"ltp":4.4,"tv":7.14,"id":9631798}],"con":true,"img":false}]}
{"op":"mcm","clk":"1349996770","pt":1588415020745,"mc":[{"id":"1.170370562","rc":[{"trd":[[1.29,78.56]],"ltp":1.29,"tv":78.56,"id":9625043},{"atb":[[1.26,0],[1.17,0]],"id":9625043},{"atl":[[1.29,303.97]],"id":9625043}],"con":true,"img":false}]}
{"op":"mcm","clk":"1349996781","pt":1588415021258,"mc":[{"id":"1.170370562","rc":[{"trd":[[1.29,82.56]],"ltp":1.29,"tv":82.56,"id":9625043},{"atl":[[1.29,301.97]],"id":9625043}],"con":true,"img":false}]}
{"op":"mcm","clk":"1349996798","pt":1588415021773,"mc":[{"id":"1.170370562","rc":[{"atl":[[1.36,0]],"id":9625043},{"atl":[[6.2,0]],"id":9631798}],"con":true,"img":false}]}
{"op":"mcm","clk":"1349996803","pt":1588415021825,"mc":[{"id":"1.170370562","rc":[{"atl":[[1.26,23.02]],"id":9625043}],"con":true,"img":false}]}
{"op":"mcm","clk":"1349996818","pt":1588415022238,"mc":[{"id":"1.170370562","rc":[{"atl":[[1.33,265.95]],"id":9625043}],"con":true,"img":false}]}
{"op":"mcm","clk":"1349996823","pt":1588415022339,"mc":[{"id":"1.170370562","rc":[{"atl":[[1.39,0]],"id":9625043}],"con":true,"img":false}]}
{"op":"mcm","clk":"1349996834","pt":1588415022752,"mc":[{"id":"1.170370562","rc":[{"atb":[[1.17,265.95]],"id":9625043}],"con":true,"img":false}]}
{"op":"mcm","clk":"1349996845","pt":1588415023365,"mc":[{"id":"1.170370562","rc":[{"atl":[[1.32,0]],"id":9625043}],"con":true,"img":false}]}
{"op":"mcm","clk":"1349996849","pt":1588415023674,"mc":[{"id":"1.170370562","rc":[{"trd":[[1.3,12851.92],[1.26,86.05],[1.29,686.5]],"ltp":1.3,"tv":13624.47,"id":9625043},{"atl":[[1.26,0],[1.3,1420.71],[1.29,0]],"id":9625043}],"con":true,"img":false}]}
{"op":"mcm","clk":"1349996856","pt":1588415023933,"mc":[{"id":"1.170370562","rc":[{"trd":[[1.3,12862.5]],"ltp":1.3,"tv":12862.5,"id":9625043},{"atl":[[1.3,1415.42]],"id":9625043}],"con":true,"img":false}]}
{"op":"mcm","clk":"1349996891","pt":1588415025165,"mc":[{"id":"1.170370562","rc":[{"trd":[[1.3,12885.55]],"ltp":1.3,"tv":12885.55,"id":9625043},{"atl":[[1.3,1403.89]],"id":9625043}],"con":true,"img":false}]}
{"op":"mcm","clk":"1349996895","pt":1588415025267,"mc":[{"id":"1.170370562","rc":[{"trd":[[1.3,15693.34]],"ltp":1.3,"tv":15693.34,"id":9625043},{"atb":[[1.31,1821.91]],"id":9625043},{"atl":[[1.3,0]],"id":9625043}],"con":true,"img":false}]}
{"op":"mcm","clk":"1349996898","pt":1588415025370,"mc":[{"id":"1.170370562","rc":[{"atl":[[1.34,222]],"id":9625043}],"con":true,"img":false}]}
{"op":"mcm","clk":"1349996917","pt":1588415025942,"mc":[{"id":"1.170370562","rc":[{"atb":[[1.3,1679.73]],"id":9625043}],"con":true,"img":false}]}
{"op":"mcm","clk":"1349996922","pt":1588415026146,"mc":[{"id":"1.170370562","rc":[{"atb":[[1.3,3359.46],[1.31,2313.93]],"id":9625043}],"con":true,"img":false}]}
{"op":"mcm","clk":"1349996941","pt":1588415026864,"mc":[{"id":"1.170370562","rc":[{"trd":[[1.31,400.47]],"ltp":1.31,"tv":400.47,"id":9625043},{"atb":[[1.31,2113.93]],"id":9625043},{"atl":[[7,25]],"id":9631798}],"con":true,"img":false}]}
{"op":"mcm","clk":"1349996948","pt":1588415027070,"mc":[{"id":"1.170370562","rc":[{"atb":[[1.17,0]],"id":9625043},{"atl":[[1.33,0]],"id":9625043}],"con":true,"img":false}]}
{"op":"mcm","clk":"1349996954","pt":1588415027277,"mc":[{"id":"1.170370562","rc":[{"atb":[[1.19,240]],"id":9625043},{"atl":[[1.34,0],[1.38,0]],"id":9625043}],"con":true,"img":false}]}
{"op":"mcm","clk":"1349996982","pt":1588415028147,"mc":[{"id":"1.170370562","rc":[{"atb":[[1.3,1679.73]],"id":9625043}],"con":true,"img":false}]}
{"op":"mcm","clk":"1349996986","pt":1588415028252,"mc":[{"id":"1.170370562","rc":[{"atb":[[1.12,240]],"id":9625043}],"con":true,"img":false}]}
{"op":"mcm","clk":"1349996990","pt":1588415028353,"mc":[{"id":"1.170370562","rc":[{"atl":[[1.35,473.48]],"id":9625043}],"con":true,"img":false}]}
{"op":"mcm","clk":"1349997004","pt":1588415028767,"mc":[{"id":"1.170370562","rc":[{"atl":[[1.51,0],[1.47,0.11]],"id":9625043}],"con":true,"img":false}]}
{"op":"mcm","clk":"1349997007","pt":1588415028870,"mc":[{"id":"1.170370562","rc":[{"atb":[[1.3,1862.35]],"id":9625043}],"con":true,"img":false}]}
{"op":"mcm","clk":"1349997081","pt":1588415030979,"mc":[{"id":"1.170370562","rc":[{"atb":[[1.3,1895.35]],"id":9625043}],"con":true,"img":false}]}
{"op":"mcm","clk":"1349997096","pt":1588415031544,"mc":[{"id":"1.170370562","rc":[{"atl":[[1.39,265.95]],"id":9625043}],"con":true,"img":false}]}
{"op":"mcm","clk":"1349997102","pt":1588415031751,"mc":[{"id":"1.170370562","rc":[{"trd":[[1.31,844.47]],"ltp":1.31,"tv":844.47,"id":9625043},{"atb":[[1.31,1891.93]],"id":9625043}],"con":true,"img":false}]}
{"op":"mcm","clk":"1349997106","pt":1588415031853,"mc":[{"id":"1.170370562","rc":[{"atl":[[1.39,531.91]],"id":9625043}],"con":true,"img":false}]}
{"op":"mcm","clk":"1349997110","pt":1588415032059,"mc":[{"id":"1.170370562","rc":[{"atb":[[1.33,240]],"id":9625043}],"con":true,"img":false}]}
{"op":"mcm","clk":"1349997115","pt":1588415032162,"mc":[{"id":"1.170370562","rc":[{"atb":[[1.31,492.02]],"id":9625043}],"con":true,"img":false}]}
{"op":"mcm","clk":"1349997118","pt":1588415032265,"mc":[{"id":"1.170370562","rc":[{"atb":[[1.29,3.15]],"id":9625043}],"con":true,"img":false}]}
{"op":"mcm","clk":"1349997121","pt":1588415032367,"mc":[{"id":"1.170370562","rc":[{"atb":[[1.34,240]],"id":9625043}],"con":true,"img":false}]}
{"op":"mcm","clk":"1349997137","pt":1588415032981,"mc":[{"id":"1.170370562","rc":[{"atb":[[1.26,2.57]],"id":9625043}],"con":true,"img":false}]}
{"op":"mcm","clk":"1349997139","pt":1588415033084,"mc":[{"id":"1.170370562","rc":[{"atb":[[1.33,248.86]],"id":9625043}],"con":true,"img":false}]}
{"op":"mcm","clk":"1349997143","pt":1588415033289,"mc":[{"id":"1.170370562","rc":[{"atb":[[1.26,6.57]],"id":9625043}],"con":true,"img":false}]}
{"op":"mcm","clk":"1349997150","pt":1588415033443,"mc":[{"id":"1.170370562","rc":[{"atb":[[1.34,0]],"id":9625043}],"con":true,"img":false}]}
{"op":"mcm","clk":"1349997156","pt":1588415033647,"mc":[{"id":"1.170370562","rc":[{"trd":[[1.35,1077.32]],"ltp":1.35,"tv":1077.32,"id":9625043},{"atl":[[1.35,402.18]],"id":9625043},{"trd":[[3.85,25]],"ltp":3.85,"tv":25.0,"id":9631798}],"con":true,"img":false}]}
{"op":"mcm","clk":"1349997158","pt":1588415033750,"mc":[{"id":"1.170370562","rc":[{"atl":[[1.39,753.91]],"id":9625043}],"con":true,"img":false}]}
{"op":"mcm","clk":"1349997175","pt":1588415034267,"mc":[{"id":"1.170370562","rc":[{"atl":[[1.44,222],[1.37,265.95]],"id":9625043}],"con":true,"img":false}]}
{"op":"mcm","clk":"1349997181","pt":1588415034574,"mc":[{"id":"1.170370562","rc":[{"atb":[[1.26,2.57]],"id":9625043}],"con":true,"img":false}]}
{"op":"mcm","clk":"1349997191","pt":1588415035087,"mc":[{"id":"1.170370562","rc":[{"atb":[[1.29,3.55]],"id":9625043},{"atl":[[4.4,2.79]],"id":9631798}],"con":true,"img":false}]}
{"op":"mcm","clk":"1349997204","pt":1588415035445,"mc":[{"id":"1.170370562","rc":[{"atb":[[1.3,1862.35]],"id":9625043}],"con":true,"img":false}]}
{"op":"mcm","clk":"1349997208","pt":1588415035548,"mc":[{"id":"1.170370562","rc":[{"atb":[[1.33,8.86]],"id":9625043}],"con":true,"img":false}]}
{"op":"mcm","clk":"1349997212","pt":1588415035752,"mc":[{"id":"1.170370562","rc":[{"atb":[[1.33,0]],"id":9625043}],"con":true,"img":false}]}
{"op":"mcm","clk":"1349997227","pt":1588415036473,"mc":[{"id":"1.170370562","rc":[{"trd":[[1.31,845.39]],"ltp":1.31,"tv":845.39,"id":9625043},{"atb":[[1.31,491.56]],"id":9625043}],"con":true,"img":false}]}
{"op":"mcm","clk":"1349997242","pt":1588415036989,"mc":[{"id":"1.170370562","rc":[{"atl":[[1.33,265.95]],"id":9625043}],"con":true,"img":false}]}
{"op":"mcm","clk":"1349997245","pt":1588415037092,"mc":[{"id":"1.170370562","rc":[{"atl":[[1.45,0]],"id":9625043}],"con":true,"img":false}]}
{"op":"mcm","clk":"1349997248","pt":1588415037298,"mc":[{"id":"1.170370562","rc":[{"trd":[[1.33,79.99]],"ltp":1.33,"tv":79.99,"id":9625043},{"atl":[[1.33,185.96]],"id":9625043},{"trd":[[4,26.59]],"ltp":4.0,"tv":26.59,"id":9631798},{"atb":[[3.8,0],[3.55,0],[3.25,0],[2.98,0],[3.45,0],[2.68,0],[2.7,0]],"id":9631798}],"con":true,"img":false}]}
{"op":"mcm","clk":"1349997251","pt":1588415037452,"mc":[{"id":"1.170370562","rc":[{"atl":[[1.55,177.3]],"id":9625043}],"con":true,"img":false}]}
{"op":"mcm","clk":"1349997259","pt":1588415037657,"mc":[{"id":"1.170370562","rc":[{"atl":[[4.4,0]],"id":9631798}],"con":true,"img":false}]}
{"op":"mcm","clk":"1349997266","pt":1588415037862,"mc":[{"id":"1.170370562","rc":[{"atb":[[1.3,1679.73]],"id":9625043}],"con":true,"img":false}]}
{"op":"mcm","clk":"1349997269","pt":1588415037965,"mc":[{"id":"1.170370562","rc":[{"trd":[[1.3,18368.49],[1.31,1828.51]],"ltp":1.3,"tv":20197.0,"id":9625043},{"atb":[[1.3,342.15],[1.31,0]],"id":9625043}],"con":true,"img":false}]}
{"op":"mcm","clk":"1349997277","pt":1588415038273,"mc":[{"id":"1.170370562","rc":[{"atl":[[1.39,222]],"id":9625043}],"con":true,"img":false}]}
{"op":"mcm","clk":"1349997299","pt":1588415038796,"mc":[{"id":"1.170370562","rc":[{"atl":[[1.37,0],[1.34,265.95]],"id":9625043}],"con":true,"img":false}]}
{"op":"mcm","clk":"1349997315","pt":1588415039258,"mc":[{"id":"1.170370562","rc":[{"trd":[[1.33,96.52]],"ltp":1.33,"tv":96.52,"id":9625043},{"atl":[[1.33,169.43]],"id":9625043},{"trd":[[4,32.09]],"ltp":4.0,"tv":32.09,"id":9631798}],"con":true,"img":false}]}
{"op":"mcm","clk":"1349997318","pt":1588415039361,"mc":[{"id":"1.170370562","rc":[{"atl":[[1000,2.67]],"id":9625043}],"con":true,"img":false}]}
{"op":"mcm","clk":"1349997329","pt":1588415039774,"mc":[{"id":"1.170370562","rc":[{"atb":[[1.29,3.15]],"id":9625043}],"con":true,"img":false}]}
{"op":"mcm","clk":"1349997343","pt":1588415040287,"mc":[{"id":"1.170370562","rc":[{"atl":[[1000,0.09]],"id":9625043}],"con":true,"img":false}]}
{"op":"mcm","clk":"1349997352","pt":1588415040599,"mc":[{"id":"1.170370562","rc":[{"trd":[[1.33,162.52]],"ltp":1.33,"tv":162.52,"id":9625043},{"atl":[[1.33,136.43]],"id":9625043}],"con":true,"img":false}]}
{"op":"mcm","clk":"1349997358","pt":1588415040804,"mc":[{"id":"1.170370562","rc":[{"atl":[[1.43,177.3]],"id":9625043}],"con":true,"img":false}]}
{"op":"mcm","clk":"1349997361","pt":1588415040857,"mc":[{"id":"1.170370562","rc":[{"trd":[[1.33,180.25]],"ltp":1.33,"tv":180.25,"id":9625043},{"atl":[[1.33,127.57]],"id":9625043}],"con":true,"img":false}]}
{"op":"mcm","clk":"1349997372","pt":1588415041167,"mc":[{"id":"1.170370562","rc":[{"atl":[[1000,0.05]],"id":9625043}],"con":true,"img":false}]}
{"op":"mcm","clk":"1349997375","pt":1588415041269,"mc":[{"id":"1.170370562","rc":[{"atb":[[1.32,240]],"id":9625043}],"con":true,"img":false}]}
{"op":"mcm","clk":"1349997378","pt":1588415041373,"mc":[{"id":"1.170370562","rc":[{"atb":[[1.12,0],[1.19,0]],"id":9625043}],"con":true,"img":false}]}
{"op":"mcm","clk":"1349997381","pt":1588415041480,"mc":[{"id":"1.170370562","rc":[{"atl":[[1.34,0]],"id":9625043}],"con":true,"img":false}]}
{"op":"mcm","clk":"1349997385","pt":1588415041583,"mc":[{"id":"1.170370562","rc":[{"atl":[[1.33,128.74]],"id":9625043}],"con":true,"img":false}]}
{"op":"mcm","clk":"1349997390","pt":1588415041686,"mc":[{"id":"1.170370562","rc":[{"atb":[[1.32,0]],"id":9625043}],"con":true,"img":false}]}
{"op":"mcm","clk":"1349997398","pt":1588415041999,"mc":[{"id":"1.170370562","rc":[{"atl":[[1000,1.82]],"id":9625043}],"con":true,"img":false}]}
{"op":"mcm","clk":"1349997402","pt":1588415042102,"mc":[{"id":"1.170370562","rc":[{"atl":[[1.34,222]],"id":9625043}],"con":true,"img":false}]}
{"op":"mcm","clk":"1349997406","pt":1588415042204,"mc":[{"id":"1.170370562","rc":[{"trd":[[1.33,183.79]],"ltp":1.33,"tv":183.79,"id":9625043},{"atl":[[1.33,126.97],[1.34,277]],"id":9625043}],"con":true,"img":false}]}
{"op":"mcm","clk":"1349997409","pt":1588415042306,"mc":[{"id":"1.170370562","rc":[{"atl":[[1000,0.51]],"id":9625043}],"con":true,"img":false}]}
{"op":"mcm","clk":"1349997414","pt":1588415042487,"mc":[{"id":"1.170370562","rc":[{"atl":[[1.34,332]],"id":9625043}],"con":true,"img":false}]}
{"op":"mcm","clk":"1349997417","pt":1588415042565,"mc":[{"id":"1.170370562","rc":[{"atl":[[1000,0.05]],"id":9625043}],"con":true,"img":false}]}
{"op":"mcm","clk":"1349997422","pt":1588415042776,"mc":[{"id":"1.170370562","rc":[{"atl":[[1.34,110]],"id":9625043}],"con":true,"img":false}]}
{"op":"mcm","clk":"1349997429","pt":1588415042985,"mc":[{"id":"1.170370562","rc":[{"trd":[[1.22,16.11],[1.26,91.2],[1.34,111.29],[1.3,19052.8],[1.29,692.81],[1.33,437.74]],"ltp":1.22,"tv":20401.94,"id":9625043},{"atb":[[1.26,0],[1.3,0],[1.22,0],[1.29,0]],"id":9625043},{"atl":[[1.2,159.62],[1.33,0],[1.34,54.35]],"id":9625043}],"con":true,"img":false}]}
{"op":"mcm","clk":"1349997434","pt":1588415043190,"mc":[{"id":"1.170370562","rc":[{"atl":[[1.35,405.73]],"id":9625043}],"con":true,"img":false}]}
{"op":"mcm","clk":"1349997437","pt":1588415043294,"mc":[{"id":"1.170370562","rc":[{"trd":[[1.2,7.31]],"ltp":1.2,"tv":7.31,"id":9625043},{"atl":[[1.2,155.97]],"id":9625043}],"con":true,"img":false}]}
{"op":"mcm","clk":"1349997443","pt":1588415043500,"mc":[{"id":"1.170370562","rc":[{"atl":[[1.35,402.36],[1.32,487.83]],"id":9625043}],"con":true,"img":false}]}
{"op":"mcm","clk":"1349997447","pt":1588415043710,"mc":[{"id":"1.170370562","rc":[{"atl":[[1.42,0.11]],"id":9625043}],"con":true,"img":false}]}
{"op":"mcm","clk":"1349997450","pt":1588415043762,"mc":[{"id":"1.170370562","rc":[{"atl":[[1000,2.05]],"id":9631798}],"con":true,"img":false}]}
{"op":"mcm","clk":"1349997453","pt":1588415043864,"mc":[{"id":"1.170370562","rc":[{"atl":[[1000,4.05]],"id":9631798}],"con":true,"img":false}]}
{"op":"mcm","clk":"1349997455","pt":1588415043968,"mc":[{"id":"1.170370562","rc":[{"atl":[[1000,2.06]],"id":9631798}],"con":true,"img":false}]}
{"op":"mcm","clk":"1349997457","pt":1588415044071,"mc":[{"id":"1.170370562","rc":[{"trd":[[1.2,7.7]],"ltp":1.2,"tv":7.7,"id":9625043},{"atl":[[1.2,155.77]],"id":9625043},{"atl":[[1000,0.07]],"id":9631798}],"con":true,"img":false}]}
{"op":"mcm","clk":"1349997461","pt":1588415044174,"mc":[{"id":"1.170370562","rc":[{"atl":[[1000,2.06]],"id":9631798}],"con":true,"img":false}]}
{"op":"mcm","clk":"1349997465","pt":1588415044281,"mc":[{"id":"1.170370562","rc":[{"atl":[[1000,2.05]],"id":9631798}],"con":true,"img":false}]}
{"op":"mcm","clk":"1349997469","pt":1588415044387,"mc":[{"id":"1.170370562","rc":[{"atl":[[1000,0.06]],"id":9631798}],"con":true,"img":false}]}
{"op":"mcm","clk":"1349997472","pt":1588415044491,"mc":[{"id":"1.170370562","rc":[{"atl":[[1.32,753.79]],"id":9625043}],"con":true,"img":false}]}
{"op":"mcm","clk":"1349997478","pt":1588415044702,"mc":[{"id":"1.170370562","rc":[{"atl":[[1000,0.05]],"id":9631798}],"con":true,"img":false}]}
{"op":"mcm","clk":"1349997484","pt":1588415044804,"mc":[{"id":"1.170370562","rc":[{"atl":[[1000,2.05]],"id":9631798}],"con":true,"img":false}]}
{"op":"mcm","clk":"1349997492","pt":1588415045012,"mc":[{"id":"1.170370562","rc":[{"atl":[[1000,2.06]],"id":9631798}],"con":true,"img":false}]}
{"op":"mcm","clk":"1349997500","pt":1588415045168,"mc":[{"id":"1.170370562","rc":[{"atl":[[1000,0.06]],"id":9631798}],"con":true,"img":false}]}
{"op":"mcm","clk":"1349997504","pt":1588415045271,"mc":[{"id":"1.170370562","rc":[{"atl":[[1.35,0.17]],"id":9625043}],"con":true,"img":false}]}
{"op":"mcm","clk":"1349997507","pt":1588415045374,"mc":[{"id":"1.170370562","rc":[{"atl":[[1000,2.05]],"id":9631798}],"con":true,"img":false}]}
{"op":"mcm","clk":"1349997512","pt":1588415045475,"mc":[{"id":"1.170370562","rc":[{"atl":[[1.32,808.79]],"id":9625043}],"con":true,"img":false}]}
{"op":"mcm","clk":"1349997518","pt":1588415045579,"mc":[{"id":"1.170370562","rc":[{"atl":[[1000,0.06]],"id":9631798}],"con":true,"img":false}]}
{"op":"mcm","clk":"1349997521","pt":1588415045682,"mc":[{"id":"1.170370562","rc":[{"trd":[[1.2,31.19]],"ltp":1.2,"tv":31.19,"id":9625043},{"atl":[[1.2,132.27]],"id":9625043},{"trd":[[6,4.69]],"ltp":6.0,"tv":4.69,"id":9631798}],"con":true,"img":false}]}
{"op":"mcm","clk":"1349997524","pt":1588415045788,"mc":[{"id":"1.170370562","rc":[{"atl":[[1000,0.05]],"id":9631798}],"con":true,"img":false}]}
{"op":"mcm","clk":"1349997528","pt":1588415045888,"mc":[{"id":"1.170370562","rc":[{"atl":[[1.31,222]],"id":9625043}],"con":true,"img":false}]}
{"op":"mcm","clk":"1349997533","pt":1588415045993,"mc":[{"id":"1.170370562","rc":[{"atl":[[1.31,277]],"id":9625043}],"con":true,"img":false}]}
{"op":"mcm","clk":"1349997545","pt":1588415046303,"mc":[{"id":"1.170370562","rc":[{"trd":[[1.2,46.79]],"ltp":1.2,"tv":46.79,"id":9625043},{"atl":[[1.2,116.68],[1.34,54.39],[1.32,320.95]],"id":9625043},{"trd":[[6,7.81]],"ltp":6.0,"tv":7.81,"id":9631798}],"con":true,"img":false}]}
{"op":"mcm","clk":"1349997551","pt":1588415046406,"mc":[{"id":"1.170370562","rc":[{"atl":[[1.43,0]],"id":9625043}],"con":true,"img":false}]}
{"op":"mcm","clk":"1349997556","pt":1588415046613,"mc":[{"id":"1.170370562","rc":[{"atl":[[1.42,266.07]],"id":9625043}],"con":true,"img":false}]}
{"op":"mcm","clk":"1349997585","pt":1588415047596,"mc":[{"id":"1.170370562","rc":[{"atl":[[7,0]],"id":9631798}],"con":true,"img":false}]}
{"op":"mcm","clk":"1349997588","pt":1588415047698,"mc":[{"id":"1.170370562","rc":[{"atl":[[1.32,321.41]],"id":9625043}],"con":true,"img":false}]}
{"op":"mcm","clk":"1349997596","pt":1588415048005,"mc":[{"id":"1.170370562","rc":[{"trd":[[1.2,280.15]],"ltp":1.2,"tv":280.15,"id":9625043},{"atb":[[1.2,123.32]],"id":9625043},{"atl":[[1.2,0]],"id":9625043}],"con":true,"img":false}]}
{"op":"mcm","clk":"1349997602","pt":1588415048109,"mc":[{"id":"1.170370562","rc":[{"trd":[[1.35,1077.67],[1.34,220.09],[1.31,2382.51],[1.32,642.83]],"ltp":1.35,"tv":4323.1,"id":9625043},{"atb":[[1.35,347]],"id":9625043},{"atl":[[1.34,0],[1.35,0],[1.32,0],[1.31,0]],"id":9625043}],"con":true,"img":false}]}
{"op":"mcm","clk":"1349997608","pt":1588415048314,"mc":[{"id":"1.170370562","rc":[{"atb":[[1.35,1347]],"id":9625043}],"con":true,"img":false}]}
{"op":"mcm","clk":"1349997611","pt":1588415048416,"mc":[{"id":"1.170370562","rc":[{"atb":[[1.34,1000]],"id":9625043}],"con":true,"img":false}]}
{"op":"mcm","clk":"1349997613","pt":1588415048519,"mc":[{"id":"1.170370562","rc":[{"atb":[[1.16,240]],"id":9625043}],"con":true,"img":false}]}
{"op":"mcm","clk":"1349997616","pt":1588415048621,"mc":[{"id":"1.170370562","rc":[{"atb":[[1.33,1.77],[1.32,1000]],"id":9625043}],"con":true,"img":false}]}
{"op":"mcm","clk":"1349997619","pt":1588415048675,"mc":[{"id":"1.170370562","rc":[{"atl":[[1.44,0],[1.39,0]],"id":9625043}],"con":true,"img":false}]}
{"op":"mcm","clk":"1349997628","pt":1588415048982,"mc":[{"id":"1.170370562","rc":[{"atb":[[1.36,492.02]],"id":9625043}],"con":true,"img":false}]}
{"op":"mcm","clk":"1349997639","pt":1588415049290,"mc":[{"id":"1.170370562","rc":[{"atl":[[4.2,0.01]],"id":9631798}],"con":true,"img":false}]}
{"op":"mcm","clk":"1349997642","pt":1588415049394,"mc":[{"id":"1.170370562","rc":[{"atl":[[3.95,0.01]],"id":9631798}],"con":true,"img":false}]}
{"op":"mcm","clk":"1349997645","pt":1588415049495,"mc":[{"id":"1.170370562","rc":[{"atb":[[1.33,15.98]],"id":9625043}],"con":true,"img":false}]}
{"op":"mcm","clk":"1349997652","pt":1588415049703,"mc":[{"id":"1.170370562","rc":[{"atb":[[1.22,265.95]],"id":9625043}],"con":true,"img":false}]}
{"op":"mcm","clk":"1349997658","pt":1588415049805,"mc":[{"id":"1.170370562","rc":[{"trd":[[1.4,3340.06]],"ltp":1.4,"tv":3340.06,"id":9625043},{"atl":[[1.4,0]],"id":9625043},{"trd":[[3.5,38.04]],"ltp":3.5,"tv":38.04,"id":9631798}],"con":true,"img":false}]}
{"op":"mcm","clk":"1349997667","pt":1588415050215,"mc":[{"id":"1.170370562","rc":[{"atb":[[2.04,0]],"id":9631798},{"atl":[[3.95,0],[4.2,0]],"id":9631798}],"con":true,"img":false}]}
{"op":"mcm","clk":"1349997670","pt":1588415050318,"mc":[{"id":"1.170370562","rc":[{"atb":[[1.37,177.3]],"id":9625043},{"atl":[[3.85,0.01]],"id":9631798}],"con":true,"img":false}]}
{"op":"mcm","clk":"1349997677","pt":1588415050523,"mc":[{"id":"1.170370562","rc":[{"trd":[[1.42,1278.76],[1.4,3340.06]],"ltp":1.42,"tv":4618.82,"id":9625043},{"atl":[[1.4,0],[1.42,266.05]],"id":9625043},{"trd":[[3.35,8.99]],"ltp":3.35,"tv":8.99,"id":9631798}],"con":true,"img":false}]}
{"op":"mcm","clk":"1349997683","pt":1588415050679,"mc":[{"id":"1.170370562","rc":[{"atb":[[1.22,1945.68]],"id":9625043}],"con":true,"img":false}]}
{"op":"mcm","clk":"1349997688","pt":1588415050780,"mc":[{"id":"1.170370562","rc":[{"atb":[[1.22,2211.64]],"id":9625043}],"con":true,"img":false}]}
{"op":"mcm","clk":"1349997691","pt":1588415050885,"mc":[{"id":"1.170370562","rc":[{"atb":[[1.33,14.21]],"id":9625043},{"atl":[[4.6,0.01]],"id":9631798}],"con":true,"img":false}]}
{"op":"mcm","clk":"1349997693","pt":1588415050988,"mc":[{"id":"1.170370562","rc":[{"atb":[[1.34,0],[1.35,0],[1.32,0]],"id":9625043}],"con":true,"img":false}]}
{"op":"mcm","clk":"1349997700","pt":1588415051092,"mc":[{"id":"1.170370562","rc":[{"atb":[[1.36,0]],"id":9625043}],"con":true,"img":false}]}
{"op":"mcm","clk":"1349997705","pt":1588415051198,"mc":[{"id":"1.170370562","rc":[{"atb":[[1.2,308.6]],"id":9625043}],"con":true,"img":false}]}
{"op":"mcm","clk":"1349997712","pt":1588415051402,"mc":[{"id":"1.170370562","rc":[{"atl":[[5.9,14]],"id":9631798}],"con":true,"img":false}]}
{"op":"mcm","clk":"1349997719","pt":1588415051609,"mc":[{"id":"1.170370562","rc":[{"atl":[[5.9,28]],"id":9631798}],"con":true,"img":false}]}
{"op":"mcm","clk":"1349997732","pt":1588415052020,"mc":[{"id":"1.170370562","rc":[{"atb":[[1.33,0]],"id":9625043}],"con":true,"img":false}]}
{"op":"mcm","clk":"1349997735","pt":1588415052225,"mc":[{"id":"1.170370562","rc":[{"trd":[[1.37,400.73]],"ltp":1.37,"tv":400.73,"id":9625043},{"atb":[[1.37,0]],"id":9625043},{"atl":[[1.37,689.48]],"id":9625043}],"con":true,"img":false}]}
{"op":"mcm","clk":"1349997759","pt":1588415053312,"mc":[{"id":"1.170370562","rc":[{"trd":[[1.27,0.44],[1.35,1077.7]],"ltp":1.27,"tv":1078.14,"id":9625043},{"atl":[[1.27,221.73]],"id":9625043},{"trd":[[4.6,0.01],[3.85,25.01]],"ltp":4.6,"tv":25.02,"id":9631798},{"atl":[[3.85,0],[4.6,0]],"id":9631798}],"con":true,"img":false}]}
{"op":"mcm","clk":"1349997769","pt":1588415053620,"mc":[{"id":"1.170370562","rc":[{"trd":[[1.27,6.74]],"ltp":1.27,"tv":6.74,"id":9625043},{"atl":[[1.27,218.58]],"id":9625043}],"con":true,"img":false}]}
{"op":"mcm","clk":"1349997774","pt":1588415053725,"mc":[{"id":"1.170370562","rc":[{"trd":[[1.27,16.27]],"ltp":1.27,"tv":16.27,"id":9625043},{"atb":[[1.2,312.31]],"id":9625043},{"atl":[[1.27,0]],"id":9625043},{"trd":[[4.7,2.57]],"ltp":4.7,"tv":2.57,"id":9631798}],"con":true,"img":false}]}
{"op":"mcm","clk":"1349997779","pt":1588415053927,"mc":[{"id":"1.170370562","rc":[{"atb":[[1.32,265.95]],"id":9625043}],"con":true,"img":false}]}
{"op":"mcm","clk":"1349997813","pt":1588415055009,"mc":[{"id":"1.170370562","rc":[{"atb":[[1.2,812.31]],"id":9625043}],"con":true,"img":false}]}
{"op":"mcm","clk":"1349997823","pt":1588415055317,"mc":[{"id":"1.170370562","rc":[{"trd":[[1.37,767.17]],"ltp":1.37,"tv":767.17,"id":9625043},{"atl":[[1.37,500.35],[1.4,265.95]],"id":9625043},{"trd":[[3.7,4.37]],"ltp":3.7,"tv":4.37,"id":9631798},{"atb":[[3.55,27.12]],"id":9631798}],"con":true,"img":false}]}
{"op":"mcm","clk":"1349997831","pt":1588415055626,"mc":[{"id":"1.170370562","rc":[{"atb":[[1.24,500]],"id":9625043}],"con":true,"img":false}]}
{"op":"mcm","clk":"1349997841","pt":1588415056036,"mc":[{"id":"1.170370562","rc":[{"atb":[[1.3,265.95]],"id":9625043}],"con":true,"img":false}]}
{"op":"mcm","clk":"1349997847","pt":1588415056191,"mc":[{"id":"1.170370562","rc":[{"atb":[[1.2,812.55]],"id":9625043}],"con":true,"img":false}]}
{"op":"mcm","clk":"1349997851","pt":1588415056294,"mc":[{"id":"1.170370562","rc":[{"atb":[[1.86,383.97]],"id":9631798}],"con":true,"img":false}]}
{"op":"mcm","clk":"1349997854","pt":1588415056400,"mc":[{"id":"1.170370562","rc":[{"atb":[[3.55,0]],"id":9631798}],"con":true,"img":false}]}
{"op":"mcm","clk":"1349997864","pt":1588415056914,"mc":[{"id":"1.170370562","rc":[{"atb":[[1.2,627.27]],"id":9625043}],"con":true,"img":false}]}
{"op":"mcm","clk":"1349997873","pt":1588415057224,"mc":[{"id":"1.170370562","rc":[{"atl":[[1.38,1262.56]],"id":9625043}],"con":true,"img":false}]}
{"op":"mcm","clk":"1349997899","pt":1588415058102,"mc":[{"id":"1.170370562","rc":[{"atb":[[1.27,240]],"id":9625043}],"con":true,"img":false}]}
{"op":"mcm","clk":"1349997903","pt":1588415058204,"mc":[{"id":"1.170370562","rc":[{"atl":[[1.35,1.17]],"id":9625043},{"atl":[[5.9,0]],"id":9631798}],"con":true,"img":false}]}
{"op":"mcm","clk":"1349997915","pt":1588415058615,"mc":[{"id":"1.170370562","rc":[{"atb":[[1.25,500]],"id":9625043}],"con":true,"img":false}]}
{"op":"mcm","clk":"1349997922","pt":1588415058924,"mc":[{"id":"1.170370562","rc":[{"trd":[[1.37,870.61],[1.35,1080.05]],"ltp":1.37,"tv":1950.65,"id":9625043},{"atb":[[1.33,295.21]],"id":9625043},{"atl":[[1.37,448.63],[1.35,0]],"id":9625043}],"con":true,"img":false}]}
{"op":"mcm","clk":"1349997927","pt":1588415059129,"mc":[{"id":"1.170370562","rc":[{"atl":[[1.42,0.09]],"id":9625043}],"con":true,"img":false}]}
{"op":"mcm","clk":"1349997933","pt":1588415059335,"mc":[{"id":"1.170370562","rc":[{"atb":[[1.2,628.45]],"id":9625043}],"con":true,"img":false}]}
{"op":"mcm","clk":"1349998848","pt":1588415059548,"mc":[{"id":"1.170370562","rc":[{"atl":[[1.36,0.11]],"id":9625043}],"con":true,"img":false}]}
{"op":"mcm","clk":"1349998851","pt":1588415059594,"mc":[{"id":"1.170370562","rc":[{"atb":[[1.28,500]],"id":9625043}],"con":true,"img":false}]}
{"op":"mcm","clk":"1349998853","pt":1588415059696,"mc":[{"id":"1.170370562","rc":[{"atl":[[1.35,412.09]],"id":9625043}],"con":true,"img":false}]}
{"op":"mcm","clk":"1349998864","pt":1588415060213,"mc":[{"id":"1.170370562","rc":[{"atb":[[1.32,0]],"id":9625043}],"con":true,"img":false}]}
{"op":"mcm","clk":"1349998867","pt":1588415060316,"mc":[{"id":"1.170370562","rc":[{"atl":[[1.35,0]],"id":9625043}],"con":true,"img":false}]}
{"op":"mcm","clk":"1349998872","pt":1588415060424,"mc":[{"id":"1.170370562","rc":[{"atl":[[1.38,1528.52]],"id":9625043}],"con":true,"img":false}]}
{"op":"mcm","clk":"1349998876","pt":1588415060524,"mc":[{"id":"1.170370562","rc":[{"atl":[[1.39,118.86]],"id":9625043}],"con":true,"img":false}]}
{"op":"mcm","clk":"1349998915","pt":1588415061815,"mc":[{"id":"1.170370562","rc":[{"atl":[[1.46,177.3]],"id":9625043}],"con":true,"img":false}]}
{"op":"mcm","clk":"1349998921","pt":1588415062022,"mc":[{"id":"1.170370562","rc":[{"atb":[[1.2,128.45]],"id":9625043}],"con":true,"img":false}]}
{"op":"mcm","clk":"1349998935","pt":1588415062739,"mc":[{"id":"1.170370562","rc":[{"atl":[[1.38,265.95]],"id":9625043}],"con":true,"img":false}]}
{"op":"mcm","clk":"1349998942","pt":1588415063046,"mc":[{"id":"1.170370562","rc":[{"trd":[[1.37,966.87]],"ltp":1.37,"tv":966.87,"id":9625043},{"atl":[[1.37,400.5],[1.39,0],[1.36,0],[1.38,0]],"id":9625043}],"con":true,"img":false}]}
{"op":"mcm","clk":"1349998948","pt":1588415063202,"mc":[{"id":"1.170370562","rc":[{"atl":[[1.52,177.3]],"id":9625043}],"con":true,"img":false}]}
{"op":"mcm","clk":"1349998951","pt":1588415063304,"mc":[{"id":"1.170370562","rc":[{"atb":[[3.75,25.71]],"id":9631798}],"con":true,"img":false}]}
{"op":"mcm","clk":"1349998962","pt":1588415063819,"mc":[{"id":"1.170370562","rc":[{"atl":[[1.4,0]],"id":9625043}],"con":true,"img":false}]}
{"op":"mcm","clk":"1349998968","pt":1588415064128,"mc":[{"id":"1.170370562","rc":[{"atb":[[3.75,0]],"id":9631798}],"con":true,"img":false}]}
{"op":"mcm","clk":"1349998972","pt":1588415064231,"mc":[{"id":"1.170370562","rc":[{"atl":[[1.49,443.26]],"id":9625043}],"con":true,"img":false}]}
{"op":"mcm","clk":"1349998984","pt":1588415064644,"mc":[{"id":"1.170370562","rc":[{"atl":[[1000,2.05]],"id":9631798}],"con":true,"img":false}]}
{"op":"mcm","clk":"1349998988","pt":1588415064745,"mc":[{"id":"1.170370562","rc":[{"trd":[[1.37,1034.39]],"ltp":1.37,"tv":1034.39,"id":9625043},{"atl":[[1.37,332.98]],"id":9625043},{"trd":[[3.7,29.37]],"ltp":3.7,"tv":29.37,"id":9631798}],"con":true,"img":false}]}
{"op":"mcm","clk":"1349998993","pt":1588415064850,"mc":[{"id":"1.170370562","rc":[{"atl":[[1000,2.06]],"id":9631798}],"con":true,"img":false}]}
{"op":"mcm","clk":"1349999002","pt":1588415065007,"mc":[{"id":"1.170370562","rc":[{"atl":[[1000,4.06]],"id":9631798}],"con":true,"img":false}]}
{"op":"mcm","clk":"1349999003","pt":1588415065110,"mc":[{"id":"1.170370562","rc":[{"atl":[[1000,0.07]],"id":9631798}],"con":true,"img":false}]}
{"op":"mcm","clk":"1349999010","pt":1588415065314,"mc":[{"id":"1.170370562","rc":[{"atl":[[1000,2.06]],"id":9631798}],"con":true,"img":false}]}
{"op":"mcm","clk":"1349999013","pt":1588415065417,"mc":[{"id":"1.170370562","rc":[{"atl":[[1000,0.06]],"id":9631798}],"con":true,"img":false}]}
{"op":"mcm","clk":"1349999024","pt":1588415065622,"mc":[{"id":"1.170370562","rc":[{"atl":[[1000,0.05]],"id":9631798}],"con":true,"img":false}]}
{"op":"mcm","clk":"1349999026","pt":1588415065724,"mc":[{"id":"1.170370562","rc":[{"atb":[[1.23,500]],"id":9625043}],"con":true,"img":false}]}
{"op":"mcm","clk":"1349999030","pt":1588415065826,"mc":[{"id":"1.170370562","rc":[{"trd":[[1.37,1700.37]],"ltp":1.37,"tv":1700.37,"id":9625043},{"atb":[[1.38,667.01]],"id":9625043},{"atl":[[1.37,0]],"id":9625043}],"con":true,"img":false}]}
{"op":"mcm","clk":"1349999033","pt":1588415065930,"mc":[{"id":"1.170370562","rc":[{"atb":[[1.23,1000]],"id":9625043}],"con":true,"img":false}]}
{"op":"mcm","clk":"1349999035","pt":1588415066033,"mc":[{"id":"1.170370562","rc":[{"atb":[[1.39,1000]],"id":9625043}],"con":true,"img":false}]}
{"op":"mcm","clk":"1349999043","pt":1588415066342,"mc":[{"id":"1.170370562","rc":[{"atb":[[1.39,2000]],"id":9625043},{"atl":[[1000,2.05]],"id":9631798}],"con":true,"img":false}]}
{"op":"mcm","clk":"1349999046","pt":1588415066443,"mc":[{"id":"1.170370562","rc":[{"trd":[[1.39,1323.45]],"ltp":1.39,"tv":1323.45,"id":9625043},{"atb":[[1.39,1778]],"id":9625043}],"con":true,"img":false}]}
{"op":"mcm","clk":"1349999050","pt":1588415066546,"mc":[{"id":"1.170370562","rc":[{"atl":[[1000,0.06]],"id":9631798}],"con":true,"img":false}]}
{"op":"mcm","clk":"1349999052","pt":1588415066649,"mc":[{"id":"1.170370562","rc":[{"atb":[[1.37,185.28]],"id":9625043},{"atl":[[1000,2.06]],"id":9631798}],"con":true,"img":false}]}
{"op":"mcm","clk":"1349999058","pt":1588415066805,"mc":[{"id":"1.170370562","rc":[{"atl":[[1000,4.05]],"id":9631798}],"con":true,"img":false}]}
{"op":"mcm","clk":"1349999062","pt":1588415066909,"mc":[{"id":"1.170370562","rc":[{"trd":[[1.46,832.38],[1.42,1278.94]],"ltp":1.46,"tv":2111.32,"id":9625043},{"atl":[[1.46,88.19],[1.42,0]],"id":9625043},{"atl":[[1000,2.06]],"id":9631798}],"con":true,"img":false}]}
{"op":"mcm","clk":"1349999063","pt":1588415067013,"mc":[{"id":"1.170370562","rc":[{"atl":[[1000,0.07]],"id":9631798}],"con":true,"img":false}]}
{"op":"mcm","clk":"1349999065","pt":1588415067116,"mc":[{"id":"1.170370562","rc":[{"atl":[[1000,0.06]],"id":9631798}],"con":true,"img":false}]}
{"op":"mcm","clk":"1349999068","pt":1588415067219,"mc":[{"id":"1.170370562","rc":[{"atl":[[1000,0.05]],"id":9631798}],"con":true,"img":false}]}
{"op":"mcm","clk":"1349999085","pt":1588415067630,"mc":[{"id":"1.170370562","rc":[{"atl":[[1000,2.05]],"id":9631798}],"con":true,"img":false}]}
{"op":"mcm","clk":"1349999090","pt":1588415067835,"mc":[{"id":"1.170370562","rc":[{"atl":[[1000,2.06]],"id":9631798}],"con":true,"img":false}]}
{"op":"mcm","clk":"1349999101","pt":1588415068146,"mc":[{"id":"1.170370562","rc":[{"trd":[[1.39,1325.25]],"ltp":1.39,"tv":1325.25,"id":9625043},{"atb":[[1.39,1777.1]],"id":9625043}],"con":true,"img":false}]}
{"op":"mcm","clk":"1349999109","pt":1588415068352,"mc":[{"id":"1.170370562","rc":[{"atb":[[1.32,492.02]],"id":9625043},{"atl":[[1000,2.07]],"id":9631798}],"con":true,"img":false}]}
{"op":"mcm","clk":"1349999113","pt":1588415068450,"mc":[{"id":"1.170370562","rc":[{"atb":[[1.39,1161.73]],"id":9625043},{"atl":[[1000,2.06]],"id":9631798}],"con":true,"img":false}]}
{"op":"mcm","clk":"1349999118","pt":1588415068506,"mc":[{"id":"1.170370562","rc":[{"atl":[[1000,0.06]],"id":9631798}],"con":true,"img":false}]}
{"op":"mcm","clk":"1349999127","pt":1588415068813,"mc":[{"id":"1.170370562","rc":[{"atl":[[1000,0.05]],"id":9631798}],"con":true,"img":false}]}
{"op":"mcm","clk":"1349999137","pt":1588415069017,"mc":[{"id":"1.170370562","rc":[{"trd":[[1.38,434.66],[1.39,3648.7]],"ltp":1.38,"tv":4083.35,"id":9625043},{"atb":[[1.38,566.17],[1.39,0],[1.35,240]],"id":9625043},{"atl":[[3.7,25.7]],"id":9631798}],"con":true,"img":false}]}
{"op":"mcm","clk":"1349999142","pt":1588415069224,"mc":[{"id":"1.170370562","rc":[{"atl":[[3.7,0]],"id":9631798}],"con":true,"img":false}]}
{"op":"mcm","clk":"1349999151","pt":1588415069532,"mc":[{"id":"1.170370562","rc":[{"atb":[[1.36,240]],"id":9625043}],"con":true,"img":false}]}
{"op":"mcm","clk":"1349999159","pt":1588415069741,"mc":[{"id":"1.170370562","rc":[{"atl":[[1.43,265.95]],"id":9625043}],"con":true,"img":false}]}
{"op":"mcm","clk":"1349999163","pt":1588415069947,"mc":[{"id":"1.170370562","rc":[{"atb":[[1.32,0]],"id":9625043}],"con":true,"img":false}]}
{"op":"mcm","clk":"1349999166","pt":1588415070050,"mc":[{"id":"1.170370562","rc":[{"atl":[[1000,2.05]],"id":9631798}],"con":true,"img":false}]}
{"op":"mcm","clk":"1349999173","pt":1588415070253,"mc":[{"id":"1.170370562","rc":[{"atl":[[5.2,0.01],[1000,0.06]],"id":9631798}],"con":true,"img":false}]}
{"op":"mcm","clk":"1349999177","pt":1588415070357,"mc":[{"id":"1.170370562","rc":[{"atl":[[1000,2.06]],"id":9631798}],"con":true,"img":false}]}
{"op":"mcm","clk":"1349999181","pt":1588415070453,"mc":[{"id":"1.170370562","rc":[{"atl":[[4.5,0.01],[1000,4.05]],"id":9631798}],"con":true,"img":false}]}
{"op":"mcm","clk":"1349999185","pt":1588415070509,"mc":[{"id":"1.170370562","rc":[{"atl":[[4,0.01]],"id":9631798}],"con":true,"img":false}]}
{"op":"mcm","clk":"1349999187","pt":1588415070660,"mc":[{"id":"1.170370562","rc":[{"atl":[[1000,0.07]],"id":9631798}],"con":true,"img":false}]}
{"op":"mcm","clk":"1349999193","pt":1588415070714,"mc":[{"id":"1.170370562","rc":[{"atl":[[3.65,0.01]],"id":9631798}],"con":true,"img":false}]}
{"op":"mcm","clk":"1349999197","pt":1588415070920,"mc":[{"id":"1.170370562","rc":[{"atl":[[1000,0.05]],"id":9631798}],"con":true,"img":false}]}
{"op":"mcm","clk":"1349999203","pt":1588415071228,"mc":[{"id":"1.170370562","rc":[{"atb":[[1.37,198.46],[1.36,0]],"id":9625043},{"atl":[[3.7,25.59]],"id":9631798}],"con":true,"img":false}]}
{"op":"mcm","clk":"1349999207","pt":1588415071332,"mc":[{"id":"1.170370562","rc":[{"trd":[[1.43,427.03]],"ltp":1.43,"tv":427.03,"id":9625043},{"atl":[[1.43,259.92]],"id":9625043},{"trd":[[3.3,2.63]],"ltp":3.3,"tv":2.63,"id":9631798},{"atl":[[1000,2.05]],"id":9631798}],"con":true,"img":false}]}
{"op":"mcm","clk":"1349999212","pt":1588415071538,"mc":[{"id":"1.170370562","rc":[{"atl":[[1000,4.05]],"id":9631798}],"con":true,"img":false}]}
{"op":"mcm","clk":"1349999215","pt":1588415071641,"mc":[{"id":"1.170370562","rc":[{"atl":[[1000,2.06]],"id":9631798}],"con":true,"img":false}]}
{"op":"mcm","clk":"1349999217","pt":1588415071744,"mc":[{"id":"1.170370562","rc":[{"atl":[[1000,0.07]],"id":9631798}],"con":true,"img":false}]}
{"op":"mcm","clk":"1349999221","pt":1588415071847,"mc":[{"id":"1.170370562","rc":[{"atl":[[1000,0.06]],"id":9631798}],"con":true,"img":false}]}
{"op":"mcm","clk":"1349999226","pt":1588415071951,"mc":[{"id":"1.170370562","rc":[{"atl":[[4.8,0.01],[1000,0.05]],"id":9631798}],"con":true,"img":false}]}
{"op":"mcm","clk":"1349999230","pt":1588415072156,"mc":[{"id":"1.170370562","rc":[{"trd":[[1.38,437]],"ltp":1.38,"tv":437.0,"id":9625043},{"atb":[[1.38,565]],"id":9625043}],"con":true,"img":false}]}
{"op":"mcm","clk":"1349999234","pt":1588415072256,"mc":[{"id":"1.170370562","rc":[{"atl":[[3.95,0.01]],"id":9631798}],"con":true,"img":false}]}
{"op":"mcm","clk":"1349999237","pt":1588415072357,"mc":[{"id":"1.170370562","rc":[{"atb":[[1.2,129.14],[1.37,13.18]],"id":9625043},{"atb":[[3.25,29.66]],"id":9631798},{"atl":[[3.7,25.82],[3.75,0.01]],"id":9631798}],"con":true,"img":false}]}
{"op":"mcm","clk":"1349999240","pt":1588415072514,"mc":[{"id":"1.170370562","rc":[{"atb":[[1.37,0]],"id":9625043}],"con":true,"img":false}]}
{"op":"mcm","clk":"1349999247","pt":1588415072721,"mc":[{"id":"1.170370562","rc":[{"atl":[[1.45,113.94]],"id":9625043}],"con":true,"img":false}]}
{"op":"mcm","clk":"1349999253","pt":1588415072932,"mc":[{"id":"1.170370562","rc":[{"atl":[[1000,2.05]],"id":9631798}],"con":true,"img":false}]}
{"op":"mcm","clk":"1349999257","pt":1588415073035,"mc":[{"id":"1.170370562","rc":[{"atb":[[1.01,1003.5],[1.22,531.91]],"id":9625043},{"atl":[[3.7,0.23]],"id":9631798}],"con":true,"img":false}]}
{"op":"mcm","clk":"1349999262","pt":1588415073135,"mc":[{"id":"1.170370562","rc":[{"atb":[[3.25,0]],"id":9631798},{"atl":[[1000,2.06]],"id":9631798}],"con":true,"img":false}]}
{"op":"mcm","clk":"1349999265","pt":1588415073237,"mc":[{"id":"1.170370562","rc":[{"atl":[[5.5,0.01]],"id":9631798}],"con":true,"img":false}]}
{"op":"mcm","clk":"1349999269","pt":1588415073341,"mc":[{"id":"1.170370562","rc":[{"atb":[[1.01,1002.14],[1.38,0]],"id":9625043},{"atl":[[1000,0.06]],"id":9631798}],"con":true,"img":false}]}
{"op":"mcm","clk":"1349999274","pt":1588415073545,"mc":[{"id":"1.170370562","rc":[{"atl":[[4.5,0.02],[1000,0.05]],"id":9631798}],"con":true,"img":false}]}
{"op":"mcm","clk":"1349999278","pt":1588415073647,"mc":[{"id":"1.170370562","rc":[{"atb":[[1.01,1001.72]],"id":9625043},{"atl":[[3.95,0.02]],"id":9631798}],"con":true,"img":false}]}
{"op":"mcm","clk":"1349999287","pt":1588415073852,"mc":[{"id":"1.170370562","rc":[{"atl":[[4,0],[4.8,0],[4.5,0],[3.95,0],[5.5,0],[5.2,0],[3.65,0],[3.75,0]],"id":9631798}],"con":true,"img":false}]}
{"op":"mcm","clk":"1349999292","pt":1588415073956,"mc":[{"id":"1.170370562","rc":[{"atl":[[3.9,0.01]],"id":9631798}],"con":true,"img":false}]}
{"op":"mcm","clk":"1349999301","pt":1588415074161,"mc":[{"id":"1.170370562","rc":[{"atl":[[1.46,257.87]],"id":9625043}],"con":true,"img":false}]}
{"op":"mcm","clk":"1349999305","pt":1588415074216,"mc":[{"id":"1.170370562","rc":[{"atl":[[1.53,37.82]],"id":9625043},{"atl":[[1000,2.05]],"id":9631798}],"con":true,"img":false}]}
{"op":"mcm","clk":"1349999308","pt":1588415074316,"mc":[{"id":"1.170370562","rc":[{"atl":[[1000,0.06]],"id":9631798}],"con":true,"img":false}]}
{"op":"mcm","clk":"1349999314","pt":1588415074523,"mc":[{"id":"1.170370562","rc":[{"atl":[[1000,2.05]],"id":9631798}],"con":true,"img":false}]}
{"op":"mcm","clk":"1349999320","pt":1588415074729,"mc":[{"id":"1.170370562","rc":[{"atl":[[1.49,177.3]],"id":9625043},{"atl":[[1000,4.05]],"id":9631798}],"con":true,"img":false}]}
{"op":"mcm","clk":"1349999324","pt":1588415074834,"mc":[{"id":"1.170370562","rc":[{"atl":[[1000,4.06]],"id":9631798}],"con":true,"img":false}]}
{"op":"mcm","clk":"1349999330","pt":1588415075047,"mc":[{"id":"1.170370562","rc":[{"atl":[[1000,0.07]],"id":9631798}],"con":true,"img":false}]}
{"op":"mcm","clk":"1349999334","pt":1588415075151,"mc":[{"id":"1.170370562","rc":[{"atl":[[1000,2.06]],"id":9631798}],"con":true,"img":false}]}
{"op":"mcm","clk":"1349999337","pt":1588415075251,"mc":[{"id":"1.170370562","rc":[{"atl":[[1000,4.06]],"id":9631798}],"con":true,"img":false}]}
{"op":"mcm","clk":"1349999341","pt":1588415075358,"mc":[{"id":"1.170370562","rc":[{"atl":[[1.43,314.92]],"id":9625043},{"atl":[[1000,2.06]],"id":9631798}],"con":true,"img":false}]}
{"op":"mcm","clk":"1349999348","pt":1588415075515,"mc":[{"id":"1.170370562","rc":[{"atl":[[4.4,0.01],[1000,0.06]],"id":9631798}],"con":true,"img":false}]}
{"op":"mcm","clk":"1349999357","pt":1588415075723,"mc":[{"id":"1.170370562","rc":[{"atb":[[1.35,240.42]],"id":9625043},{"atl":[[1.44,55]],"id":9625043},{"atl":[[1000,2.05]],"id":9631798}],"con":true,"img":false}]}
{"op":"mcm","clk":"1349999360","pt":1588415075823,"mc":[{"id":"1.170370562","rc":[{"atl":[[1.46,169.68]],"id":9625043}],"con":true,"img":false}]}
{"op":"mcm","clk":"1349999363","pt":1588415075925,"mc":[{"id":"1.170370562","rc":[{"atl":[[1000,0.06]],"id":9631798}],"con":true,"img":false}]}
{"op":"mcm","clk":"1349999367","pt":1588415076027,"mc":[{"id":"1.170370562","rc":[{"atl":[[3.8,0.01],[3.75,0.01]],"id":9631798}],"con":true,"img":false}]}
{"op":"mcm","clk":"1349999371","pt":1588415076132,"mc":[{"id":"1.170370562","rc":[{"atl":[[1000,0.05]],"id":9631798}],"con":true,"img":false}]}
{"op":"mcm","clk":"1349999382","pt":1588415076438,"mc":[{"id":"1.170370562","rc":[{"atl":[[1.41,265.95]],"id":9625043}],"con":true,"img":false}]}
{"op":"mcm","clk":"1349999389","pt":1588415076558,"mc":[{"id":"1.170370562","rc":[{"atl":[[1.42,55]],"id":9625043}],"con":true,"img":false}]}
{"op":"mcm","clk":"1349999399","pt":1588415076753,"mc":[{"id":"1.170370562","rc":[{"atl":[[1.39,1.54]],"id":9625043}],"con":true,"img":false}]}
{"op":"mcm","clk":"1349999407","pt":1588415076957,"mc":[{"id":"1.170370562","rc":[{"trd":[[1.39,3648.73]],"ltp":1.39,"tv":3648.73,"id":9625043},{"atl":[[1.39,1.51]],"id":9625043},{"trd":[[3.55,12.69]],"ltp":3.55,"tv":12.69,"id":9631798}],"con":true,"img":false}]}
{"op":"mcm","clk":"1349999411","pt":1588415077060,"mc":[{"id":"1.170370562","rc":[{"trd":[[1.39,3648.76]],"ltp":1.39,"tv":3648.76,"id":9625043},{"atl":[[1.39,1.49]],"id":9625043},{"trd":[[3.55,12.7]],"ltp":3.55,"tv":12.7,"id":9631798},{"atl":[[3.7,0]],"id":9631798}],"con":true,"img":false}]}
{"op":"mcm","clk":"1349999414","pt":1588415077161,"mc":[{"id":"1.170370562","rc":[{"atb":[[1.31,240]],"id":9625043},{"atl":[[1.5,0]],"id":9625043}],"con":true,"img":false}]}
{"op":"mcm","clk":"1349999428","pt":1588415077421,"mc":[{"id":"1.170370562","rc":[{"trd":[[1.41,542.22],[1.39,3651.75]],"ltp":1.41,"tv":4193.97,"id":9625043},{"atl":[[1.39,0],[1.41,82.17]],"id":9625043}],"con":true,"img":false}]}
{"op":"mcm","clk":"1349999457","pt":1588415078142,"mc":[{"id":"1.170370562","rc":[{"trd":[[1.41,630.87]],"ltp":1.41,"tv":630.87,"id":9625043},{"atl":[[1.41,37.84]],"id":9625043}],"con":true,"img":false}]}
{"op":"mcm","clk":"1349999466","pt":1588415078445,"mc":[{"id":"1.170370562","rc":[{"atl":[[3.5,0.01]],"id":9631798}],"con":true,"img":false}]}
{"op":"mcm","clk":"1349999475","pt":1588415078652,"mc":[{"id":"1.170370562","rc":[{"trd":[[1.41,630.9]],"ltp":1.41,"tv":630.9,"id":9625043},{"atl":[[1.41,37.81]],"id":9625043},{"trd":[[3.4,0.01]],"ltp":3.4,"tv":0.01,"id":9631798}],"con":true,"img":false}]}
{"op":"mcm","clk":"1349999478","pt":1588415078756,"mc":[{"id":"1.170370562","rc":[{"trd":[[1.41,631.73]],"ltp":1.41,"tv":631.73,"id":9625043},{"atb":[[1.33,0]],"id":9625043},{"atl":[[1.41,37.4]],"id":9625043}],"con":true,"img":false}]}
{"op":"mcm","clk":"1349999481","pt":1588415078858,"mc":[{"id":"1.170370562","rc":[{"atb":[[1.4,2.65]],"id":9625043}],"con":true,"img":false}]}
{"op":"mcm","clk":"1349999485","pt":1588415078960,"mc":[{"id":"1.170370562","rc":[{"atb":[[3.4,28.35]],"id":9631798}],"con":true,"img":false}]}
{"op":"mcm","clk":"1349999498","pt":1588415079632,"mc":[{"id":"1.170370562","rc":[{"atb":[[1.39,1000]],"id":9625043},{"atl":[[5,0.01]],"id":9631798}],"con":true,"img":false}]}
{"op":"mcm","clk":"1349999502","pt":1588415079837,"mc":[{"id":"1.170370562","rc":[{"atl":[[1.53,303.78]],"id":9625043}],"con":true,"img":false}]}
{"op":"mcm","clk":"1349999506","pt":1588415079940,"mc":[{"id":"1.170370562","rc":[{"atl":[[1000,2.05]],"id":9631798}],"con":true,"img":false}]}
{"op":"mcm","clk":"1349999510","pt":1588415080042,"mc":[{"id":"1.170370562","rc":[{"atl":[[1000,0.06]],"id":9631798}],"con":true,"img":false}]}
{"op":"mcm","clk":"1349999512","pt":1588415080143,"mc":[{"id":"1.170370562","rc":[{"atl":[[3.9,0.02],[1000,2.06]],"id":9631798}],"con":true,"img":false}]}
{"op":"mcm","clk":"1349999517","pt":1588415080247,"mc":[{"id":"1.170370562","rc":[{"atl":[[3.6,0.01],[1000,2.05]],"id":9631798}],"con":true,"img":false}]}
{"op":"mcm","clk":"1349999520","pt":1588415080350,"mc":[{"id":"1.170370562","rc":[{"atb":[[3.4,0]],"id":9631798},{"atl":[[1000,4.05]],"id":9631798}],"con":true,"img":false}]}
{"op":"mcm","clk":"1349999526","pt":1588415080452,"mc":[{"id":"1.170370562","rc":[{"trd":[[1.41,631.76]],"ltp":1.41,"tv":631.76,"id":9625043},{"atl":[[1.41,37.37]],"id":9625043},{"trd":[[3.4,0.02]],"ltp":3.4,"tv":0.02,"id":9631798},{"atl":[[1000,2.06]],"id":9631798}],"con":true,"img":false}]}
{"op":"mcm","clk":"1349999531","pt":1588415080555,"mc":[{"id":"1.170370562","rc":[{"atb":[[1.35,240]],"id":9625043},{"atl":[[1000,2.07]],"id":9631798}],"con":true,"img":false}]}
{"op":"mcm","clk":"1349999535","pt":1588415080660,"mc":[{"id":"1.170370562","rc":[{"trd":[[1.41,631.79]],"ltp":1.41,"tv":631.79,"id":9625043},{"atl":[[1.41,37.34]],"id":9625043},{"trd":[[3.4,0.03]],"ltp":3.4,"tv":0.03,"id":9631798},{"atb":[[1.45,0]],"id":9631798}],"con":true,"img":false}]}
{"op":"mcm","clk":"1349999537","pt":1588415080761,"mc":[{"id":"1.170370562","rc":[{"atl":[[1000,2.06]],"id":9631798}],"con":true,"img":false}]}
{"op":"mcm","clk":"1349999540","pt":1588415080866,"mc":[{"id":"1.170370562","rc":[{"trd":[[1.41,631.81]],"ltp":1.41,"tv":631.81,"id":9625043},{"atl":[[1.41,37.32]],"id":9625043},{"trd":[[3.4,0.04]],"ltp":3.4,"tv":0.04,"id":9631798}],"con":true,"img":false}]}
{"op":"mcm","clk":"1349999547","pt":1588415081069,"mc":[{"id":"1.170370562","rc":[{"atb":[[1.39,0]],"id":9625043},{"atl":[[1.42,295]],"id":9625043},{"atl":[[1000,0.06]],"id":9631798}],"con":true,"img":false}]}
{"op":"mcm","clk":"1349999549","pt":1588415081121,"mc":[{"id":"1.170370562","rc":[{"atl":[[1000,2.06]],"id":9631798}],"con":true,"img":false}]}
{"op":"mcm","clk":"1349999554","pt":1588415081231,"mc":[{"id":"1.170370562","rc":[{"atl":[[3.6,0.02],[1000,2.05]],"id":9631798}],"con":true,"img":false}]}
{"op":"mcm","clk":"1349999559","pt":1588415081334,"mc":[{"id":"1.170370562","rc":[{"trd":[[1.41,656.97]],"ltp":1.41,"tv":656.97,"id":9625043},{"atl":[[1.41,24.74]],"id":9625043},{"atl":[[1000,4.05]],"id":9631798}],"con":true,"img":false}]}
{"op":"mcm","clk":"1349999560","pt":1588415081437,"mc":[{"id":"1.170370562","rc":[{"atl":[[1000,0.07]],"id":9631798}],"con":true,"img":false}]}
{"op":"mcm","clk":"1349999566","pt":1588415081539,"mc":[{"id":"1.170370562","rc":[{"atl":[[1000,2.07]],"id":9631798}],"con":true,"img":false}]}
{"op":"mcm","clk":"1349999576","pt":1588415081747,"mc":[{"id":"1.170370562","rc":[{"atl":[[1.45,0],[1.42,55]],"id":9625043},{"atl":[[1000,0.06]],"id":9631798}],"con":true,"img":false}]}
{"op":"mcm","clk":"1349999585","pt":1588415081953,"mc":[{"id":"1.170370562","rc":[{"trd":[[1.43,485.2],[1.42,1333.94],[1.41,681.72]],"ltp":1.43,"tv":2500.86,"id":9625043},{"atl":[[1.43,256.74],[1.41,0],[1.42,0]],"id":9625043},{"trd":[[3.3,27.84],[3.4,10.3],[3.35,32.3]],"ltp":3.3,"tv":70.44,"id":9631798}],"con":true,"img":false}]}
{"op":"mcm","clk":"1349999589","pt":1588415082058,"mc":[{"id":"1.170370562","rc":[{"atl":[[1000,0.05]],"id":9631798}],"con":true,"img":false}]}
{"op":"mcm","clk":"1349999612","pt":1588415082675,"mc":[{"id":"1.170370562","rc":[{"atl":[[1.46,0]],"id":9625043}],"con":true,"img":false}]}
{"op":"mcm","clk":"1349999618","pt":1588415082827,"mc":[{"id":"1.170370562","rc":[{"atb":[[1.39,127.65]],"id":9625043}],"con":true,"img":false}]}
{"op":"mcm","clk":"1349999637","pt":1588415083651,"mc":[{"id":"1.170370562","rc":[{"trd":[[1.4,3342.72]],"ltp":1.4,"tv":3342.72,"id":9625043},{"atb":[[1.4,0]],"id":9625043},{"trd":[[3.5,39.12]],"ltp":3.5,"tv":39.12,"id":9631798},{"atb":[[3.5,796.34]],"id":9631798},{"atl":[[3.5,0]],"id":9631798}],"con":true,"img":false}]}
{"op":"mcm","clk":"1349999647","pt":1588415084064,"mc":[{"id":"1.170370562","rc":[{"trd":[[1.4,3640.78]],"ltp":1.4,"tv":3640.78,"id":9625043},{"trd":[[3.5,158.34]],"ltp":3.5,"tv":158.34,"id":9631798},{"atb":[[3.5,677.12]],"id":9631798}],"con":true,"img":false}]}
{"op":"mcm","clk":"1349999668","pt":1588415084631,"mc":[{"id":"1.170370562","rc":[{"atl":[[3.8,75.01]],"id":9631798}],"con":true,"img":false}]}
{"op":"mcm","clk":"1349999672","pt":1588415084733,"mc":[{"id":"1.170370562","rc":[{"trd":[[1.39,3657]],"ltp":1.39,"tv":3657.0,"id":9625043},{"atb":[[1.39,125.03]],"id":9625043},{"atl":[[1.43,55]],"id":9625043}],"con":true,"img":false}]}
{"op":"mcm","clk":"1349999692","pt":1588415085351,"mc":[{"id":"1.170370562","rc":[{"atl":[[4.8,0.01]],"id":9631798}],"con":true,"img":false}]}
{"op":"mcm","clk":"1349999702","pt":1588415085556,"mc":[{"id":"1.170370562","rc":[{"atl":[[1.4,1.17]],"id":9625043}],"con":true,"img":false}]}
{"op":"mcm","clk":"1349999707","pt":1588415085660,"mc":[{"id":"1.170370562","rc":[{"atb":[[1.36,265.95]],"id":9625043}],"con":true,"img":false}]}
{"op":"mcm","clk":"1349999715","pt":1588415085865,"mc":[{"id":"1.170370562","rc":[{"atl":[[3.8,75.02]],"id":9631798}],"con":true,"img":false}]}
{"op":"mcm","clk":"1349999718","pt":1588415085968,"mc":[{"id":"1.170370562","rc":[{"atl":[[3.55,0.01]],"id":9631798}],"con":true,"img":false}]}
{"op":"mcm","clk":"1349999724","pt":1588415086174,"mc":[{"id":"1.170370562","rc":[{"trd":[[3.5,158.36]],"ltp":3.5,"tv":158.36,"id":9631798},{"atb":[[3.5,677.11]],"id":9631798}],"con":true,"img":false}]}
{"op":"mcm","clk":"1349999735","pt":1588415086388,"mc":[{"id":"1.170370562","rc":[{"atl":[[3.85,0.01]],"id":9631798}],"con":true,"img":false}]}
{"op":"mcm","clk":"1349999751","pt":1588415086846,"mc":[{"id":"1.170370562","rc":[{"atb":[[1.23,0]],"id":9625043},{"trd":[[3.5,158.37]],"ltp":3.5,"tv":158.37,"id":9631798},{"atb":[[3.5,677.1]],"id":9631798},{"atl":[[3.9,0.03]],"id":9631798}],"con":true,"img":false}]}
{"op":"mcm","clk":"1349999755","pt":1588415086948,"mc":[{"id":"1.170370562","rc":[{"atb":[[1.33,265.95]],"id":9625043}],"con":true,"img":false}]}
{"op":"mcm","clk":"1349999760","pt":1588415087155,"mc":[{"id":"1.170370562","rc":[{"trd":[[3.5,158.39]],"ltp":3.5,"tv":158.39,"id":9631798},{"atb":[[3.5,677.09]],"id":9631798}],"con":true,"img":false}]}
{"op":"mcm","clk":"1349999763","pt":1588415087257,"mc":[{"id":"1.170370562","rc":[{"atb":[[1.24,0]],"id":9625043}],"con":true,"img":false}]}
{"op":"mcm","clk":"1349999769","pt":1588415087361,"mc":[{"id":"1.170370562","rc":[{"trd":[[1.4,3669.43]],"ltp":1.4,"tv":3669.43,"id":9625043},{"atl":[[1.4,0]],"id":9625043},{"trd":[[3.5,168.91]],"ltp":3.5,"tv":168.91,"id":9631798},{"atb":[[3.5,666.58]],"id":9631798}],"con":true,"img":false}]}
{"op":"mcm","clk":"1349999776","pt":1588415087667,"mc":[{"id":"1.170370562","rc":[{"atl":[[1.44,169.73]],"id":9625043}],"con":true,"img":false}]}
{"op":"mcm","clk":"1349999779","pt":1588415087772,"mc":[{"id":"1.170370562","rc":[{"atb":[[1.25,0]],"id":9625043}],"con":true,"img":false}]}
{"op":"mcm","clk":"1349999782","pt":1588415087876,"mc":[{"id":"1.170370562","rc":[{"atb":[[1.39,0]],"id":9625043},{"atl":[[1.48,167.39]],"id":9625043}],"con":true,"img":false}]}
{"op":"mcm","clk":"1349999795","pt":1588415088442,"mc":[{"id":"1.170370562","rc":[{"trd":[[3.5,204.37]],"ltp":3.5,"tv":204.37,"id":9631798},{"atb":[[3.5,648.84]],"id":9631798}],"con":true,"img":false}]}
{"op":"mcm","clk":"1349999801","pt":1588415088750,"mc":[{"id":"1.170370562","rc":[{"atb":[[3.4,17.73]],"id":9631798}],"con":true,"img":false}]}
{"op":"mcm","clk":"1349999804","pt":1588415088854,"mc":[{"id":"1.170370562","rc":[{"trd":[[1.4,3671.43]],"ltp":1.4,"tv":3671.43,"id":9625043},{"trd":[[3.5,205.17]],"ltp":3.5,"tv":205.17,"id":9631798},{"atb":[[3.5,648.04]],"id":9631798}],"con":true,"img":false}]}
{"op":"mcm","clk":"1349999807","pt":1588415088958,"mc":[{"id":"1.170370562","rc":[{"atl":[[1.48,433.34]],"id":9625043}],"con":true,"img":false}]}
{"op":"mcm","clk":"1349999813","pt":1588415089165,"mc":[{"id":"1.170370562","rc":[{"atb":[[3.4,35.46]],"id":9631798}],"con":true,"img":false}]}
{"op":"mcm","clk":"1349999817","pt":1588415089267,"mc":[{"id":"1.170370562","rc":[{"trd":[[1.4,3673.43]],"ltp":1.4,"tv":3673.43,"id":9625043},{"trd":[[3.5,205.97]],"ltp":3.5,"tv":205.97,"id":9631798},{"atb":[[3.5,647.24]],"id":9631798}],"con":true,"img":false}]}
{"op":"mcm","clk":"1349999823","pt":1588415089471,"mc":[{"id":"1.170370562","rc":[{"atb":[[3.4,53.19]],"id":9631798},{"atl":[[1000,2.05]],"id":9631798}],"con":true,"img":false}]}
{"op":"mcm","clk":"1349999828","pt":1588415089575,"mc":[{"id":"1.170370562","rc":[{"trd":[[1.4,3801.09]],"ltp":1.4,"tv":3801.09,"id":9625043},{"trd":[[3.5,257.5]],"ltp":3.5,"tv":257.5,"id":9631798},{"atb":[[3.5,595.95]],"id":9631798}],"con":true,"img":false}]}
{"op":"mcm","clk":"1349999832","pt":1588415089679,"mc":[{"id":"1.170370562","rc":[{"atl":[[1.4,12.26]],"id":9625043},{"atl":[[1000,0.06]],"id":9631798}],"con":true,"img":false}]}
{"op":"mcm","clk":"1349999835","pt":1588415089733,"mc":[{"id":"1.170370562","rc":[{"atl":[[1000,4.06]],"id":9631798}],"con":true,"img":false}]}
{"op":"mcm","clk":"1349999839","pt":1588415089834,"mc":[{"id":"1.170370562","rc":[{"atb":[[3.4,70.92]],"id":9631798}],"con":true,"img":false}]}
{"op":"mcm","clk":"1349999842","pt":1588415089937,"mc":[{"id":"1.170370562","rc":[{"atl":[[1000,0.07]],"id":9631798}],"con":true,"img":false}]}
{"op":"mcm","clk":"1349999849","pt":1588415090144,"mc":[{"id":"1.170370562","rc":[{"atl":[[1000,0.05]],"id":9631798}],"con":true,"img":false}]}
{"op":"mcm","clk":"1349999859","pt":1588415090453,"mc":[{"id":"1.170370562","rc":[{"atl":[[1.42,174.46]],"id":9625043}],"con":true,"img":false}]}
{"op":"mcm","clk":"1349999864","pt":1588415090557,"mc":[{"id":"1.170370562","rc":[{"atb":[[3.4,88.65]],"id":9631798}],"con":true,"img":false}]}
{"op":"mcm","clk":"1349999875","pt":1588415090868,"mc":[{"id":"1.170370562","rc":[{"atb":[[1.32,500]],"id":9625043}],"con":true,"img":false}]}
{"op":"mcm","clk":"1349999878","pt":1588415090970,"mc":[{"id":"1.170370562","rc":[{"atb":[[1.28,0]],"id":9625043}],"con":true,"img":false}]}
{"op":"mcm","clk":"1349999889","pt":1588415091230,"mc":[{"id":"1.170370562","rc":[{"trd":[[1.4,3801.49]],"ltp":1.4,"tv":3801.49,"id":9625043},{"atl":[[1.4,12.06]],"id":9625043}],"con":true,"img":false}]}
{"op":"mcm","clk":"1349999893","pt":1588415091333,"mc":[{"id":"1.170370562","rc":[{"atl":[[1000,2.05]],"id":9631798}],"con":true,"img":false}]}
{"op":"mcm","clk":"1349999897","pt":1588415091435,"mc":[{"id":"1.170370562","rc":[{"atl":[[1000,4.05]],"id":9631798}],"con":true,"img":false}]}
{"op":"mcm","clk":"1349999903","pt":1588415091538,"mc":[{"id":"1.170370562","rc":[{"atl":[[1000,2.06]],"id":9631798}],"con":true,"img":false}]}
{"op":"mcm","clk":"1349999906","pt":1588415091640,"mc":[{"id":"1.170370562","rc":[{"atl":[[1000,0.07]],"id":9631798}],"con":true,"img":false}]}
{"op":"mcm","clk":"1349999914","pt":1588415091847,"mc":[{"id":"1.170370562","rc":[{"atl":[[1.47,0]],"id":9625043},{"atl":[[1000,0.05]],"id":9631798}],"con":true,"img":false}]}
{"op":"mcm","clk":"1349999920","pt":1588415092053,"mc":[{"id":"1.170370562","rc":[{"atl":[[1000,2.05]],"id":9631798}],"con":true,"img":false}]}
{"op":"mcm","clk":"1349999927","pt":1588415092260,"mc":[{"id":"1.170370562","rc":[{"atl":[[1000,0.06]],"id":9631798}],"con":true,"img":false}]}
{"op":"mcm","clk":"1349999931","pt":1588415092363,"mc":[{"id":"1.170370562","rc":[{"trd":[[1.4,4017.56]],"ltp":1.4,"tv":4017.56,"id":9625043},{"atl":[[1.4,0]],"id":9625043},{"trd":[[3.5,334.28]],"ltp":3.5,"tv":334.28,"id":9631798},{"atb":[[3.5,519.17]],"id":9631798}],"con":true,"img":false}]}
{"op":"mcm","clk":"1349999936","pt":1588415092468,"mc":[{"id":"1.170370562","rc":[{"atl":[[1000,0.05]],"id":9631798}],"con":true,"img":false}]}
{"op":"mcm","clk":"1349999938","pt":1588415092570,"mc":[{"id":"1.170370562","rc":[{"atl":[[1000,2.05]],"id":9631798}],"con":true,"img":false}]}
{"op":"mcm","clk":"1349999943","pt":1588415092672,"mc":[{"id":"1.170370562","rc":[{"atl":[[1000,4.05]],"id":9631798}],"con":true,"img":false}]}
{"op":"mcm","clk":"1349999945","pt":1588415092777,"mc":[{"id":"1.170370562","rc":[{"atl":[[1000,2.06]],"id":9631798}],"con":true,"img":false}]}
{"op":"mcm","clk":"1349999951","pt":1588415092878,"mc":[{"id":"1.170370562","rc":[{"atl":[[1000,0.07]],"id":9631798}],"con":true,"img":false}]}
{"op":"mcm","clk":"1349999962","pt":1588415093034,"mc":[{"id":"1.170370562","rc":[{"atl":[[1000,0.06]],"id":9631798}],"con":true,"img":false}]}
{"op":"mcm","clk":"1349999965","pt":1588415093136,"mc":[{"id":"1.170370562","rc":[{"atl":[[1000,0.05]],"id":9631798}],"con":true,"img":false}]}
{"op":"mcm","clk":"1349999972","pt":1588415093342,"mc":[{"id":"1.170370562","rc":[{"atl":[[1000,2.05]],"id":9631798}],"con":true,"img":false}]}
{"op":"mcm","clk":"1349999975","pt":1588415093445,"mc":[{"id":"1.170370562","rc":[{"atl":[[3.8,0.02]],"id":9631798}],"con":true,"img":false}]}
{"op":"mcm","clk":"1349999978","pt":1588415093549,"mc":[{"id":"1.170370562","rc":[{"trd":[[1.4,4017.87]],"ltp":1.4,"tv":4017.87,"id":9625043},{"trd":[[3.5,334.41]],"ltp":3.5,"tv":334.41,"id":9631798},{"atb":[[3.5,519.04]],"id":9631798},{"atl":[[1000,2.06]],"id":9631798}],"con":true,"img":false}]}
{"op":"mcm","clk":"1349999986","pt":1588415093755,"mc":[{"id":"1.170370562","rc":[{"atl":[[1000,0.06]],"id":9631798}],"con":true,"img":false}]}
{"op":"mcm","clk":"1349999991","pt":1588415093858,"mc":[{"id":"1.170370562","rc":[{"atl":[[1000,0.05]],"id":9631798}],"con":true,"img":false}]}
{"op":"mcm","clk":"1350000000","pt":1588415094268,"mc":[{"id":"1.170370562","rc":[{"trd":[[3.5,395.2]],"ltp":3.5,"tv":395.2,"id":9631798},{"atb":[[3.5,488.64]],"id":9631798}],"con":true,"img":false}]}
{"op":"mcm","clk":"1350000008","pt":1588415094578,"mc":[{"id":"1.170370562","rc":[{"trd":[[1.4,4044.47]],"ltp":1.4,"tv":4044.47,"id":9625043},{"atl":[[1.53,286.26]],"id":9625043},{"trd":[[3.5,405.84]],"ltp":3.5,"tv":405.84,"id":9631798},{"atb":[[3.5,478.01]],"id":9631798}],"con":true,"img":false}]}
{"op":"mcm","clk":"1350000011","pt":1588415094680,"mc":[{"id":"1.170370562","rc":[{"trd":[[1.39,3657.03]],"ltp":1.39,"tv":3657.03,"id":9625043},{"atl":[[1.39,3.12]],"id":9625043},{"trd":[[3.55,12.71],[3.5,445.83]],"ltp":3.55,"tv":458.53,"id":9631798},{"atb":[[3.5,458.01]],"id":9631798},{"atl":[[3.55,0]],"id":9631798}],"con":true,"img":false}]}
{"op":"mcm","clk":"1350000016","pt":1588415094884,"mc":[{"id":"1.170370562","rc":[{"atb":[[1.33,0]],"id":9625043}],"con":true,"img":false}]}
{"op":"mcm","clk":"1350000021","pt":1588415095039,"mc":[{"id":"1.170370562","rc":[{"trd":[[1.39,3657.05]],"ltp":1.39,"tv":3657.05,"id":9625043},{"atl":[[1.39,3.1]],"id":9625043},{"trd":[[3.55,12.72]],"ltp":3.55,"tv":12.72,"id":9631798}],"con":true,"img":false}]}
{"op":"mcm","clk":"1350000025","pt":1588415095141,"mc":[{"id":"1.170370562","rc":[{"trd":[[1.4,4223.99],[1.39,3663.26]],"ltp":1.4,"tv":7887.25,"id":9625043},{"atl":[[1.39,132.97]],"id":9625043},{"trd":[[3.5,517.65]],"ltp":3.5,"tv":517.65,"id":9631798},{"atb":[[3.5,386.2]],"id":9631798}],"con":true,"img":false}]}
{"op":"mcm","clk":"1350000028","pt":1588415095246,"mc":[{"id":"1.170370562","rc":[{"trd":[[1.39,3663.31]],"ltp":1.39,"tv":3663.31,"id":9625043},{"atl":[[1.39,132.92]],"id":9625043},{"trd":[[3.55,12.74]],"ltp":3.55,"tv":12.74,"id":9631798}],"con":true,"img":false}]}
{"op":"mcm","clk":"1350000035","pt":1588415095349,"mc":[{"id":"1.170370562","rc":[{"atb":[[1.3,0]],"id":9625043}],"con":true,"img":false}]}
{"op":"mcm","clk":"1350000052","pt":1588415095760,"mc":[{"id":"1.170370562","rc":[{"trd":[[1.4,4357.02],[1.39,3929.16]],"ltp":1.4,"tv":8286.18,"id":9625043},{"atb":[[1.31,0]],"id":9625043},{"atl":[[1.39,0]],"id":9625043},{"trd":[[3.5,570.86]],"ltp":3.5,"tv":570.86,"id":9631798},{"atb":[[3.5,332.98]],"id":9631798}],"con":true,"img":false}]}
{"op":"mcm","clk":"1350000057","pt":1588415095967,"mc":[{"id":"1.170370562","rc":[{"trd":[[1.4,4540.99]],"ltp":1.4,"tv":4540.99,"id":9625043},{"trd":[[3.5,644.45]],"ltp":3.5,"tv":644.45,"id":9631798},{"atb":[[3.5,259.39]],"id":9631798}],"con":true,"img":false}]}
{"op":"mcm","clk":"1350000062","pt":1588415096173,"mc":[{"id":"1.170370562","rc":[{"trd":[[3.5,714.43]],"ltp":3.5,"tv":714.43,"id":9631798},{"atb":[[3.5,224.41]],"id":9631798}],"con":true,"img":false}]}
{"op":"mcm","clk":"1350000082","pt":1588415096793,"mc":[{"id":"1.170370562","rc":[{"atb":[[1.22,0]],"id":9625043}],"con":true,"img":false}]}
{"op":"mcm","clk":"1350000091","pt":1588415096949,"mc":[{"id":"1.170370562","rc":[{"atl":[[4.8,0],[3.6,0],[3.85,0],[5,0],[4.1,0.01],[3.8,0],[4.4,0],[3.9,0],[3.75,0],[3.65,0.01]],"id":9631798}],"con":true,"img":false}]}
{"op":"mcm","clk":"1350000100","pt":1588415097257,"mc":[{"id":"1.170370562","rc":[{"trd":[[3.5,799.53]],"ltp":3.5,"tv":799.53,"id":9631798},{"atb":[[3.5,181.85]],"id":9631798}],"con":true,"img":false}]}
{"op":"mcm","clk":"1350000103","pt":1588415097360,"mc":[{"id":"1.170370562","rc":[{"atb":[[1.35,0]],"id":9625043}],"con":true,"img":false}]}
{"op":"mcm","clk":"1350000108","pt":1588415097568,"mc":[{"id":"1.170370562","rc":[{"trd":[[3.5,799.55]],"ltp":3.5,"tv":799.55,"id":9631798},{"atb":[[3.5,181.85]],"id":9631798}],"con":true,"img":false}]}
{"op":"mcm","clk":"1350000112","pt":1588415097671,"mc":[{"id":"1.170370562","rc":[{"trd":[[3.5,834.47]],"ltp":3.5,"tv":834.47,"id":9631798},{"atb":[[3.5,164.38]],"id":9631798}],"con":true,"img":false}]}
{"op":"mcm","clk":"1350000117","pt":1588415097774,"mc":[{"id":"1.170370562","rc":[{"trd":[[1.4,4543.62]],"ltp":1.4,"tv":4543.62,"id":9625043},{"trd":[[3.5,835.52]],"ltp":3.5,"tv":835.52,"id":9631798},{"atb":[[3.5,163.34]],"id":9631798}],"con":true,"img":false}]}
{"op":"mcm","clk":"1350000126","pt":1588415098082,"mc":[{"id":"1.170370562","rc":[{"trd":[[1.4,4544.51]],"ltp":1.4,"tv":4544.51,"id":9625043},{"atl":[[1.48,265.95]],"id":9625043},{"trd":[[3.5,835.88]],"ltp":3.5,"tv":835.88,"id":9631798},{"atb":[[3.5,162.98]],"id":9631798}],"con":true,"img":false}]}
{"op":"mcm","clk":"1350000130","pt":1588415098194,"mc":[{"id":"1.170370562","rc":[{"atl":[[3.55,0.01]],"id":9631798}],"con":true,"img":false}]}
{"op":"mcm","clk":"1350000133","pt":1588415098290,"mc":[{"id":"1.170370562","rc":[{"trd":[[1.4,4572.76]],"ltp":1.4,"tv":4572.76,"id":9625043},{"trd":[[3.5,847.2]],"ltp":3.5,"tv":847.2,"id":9631798},{"atb":[[3.5,151.67]],"id":9631798}],"con":true,"img":false}]}
{"op":"mcm","clk":"1350000139","pt":1588415098551,"mc":[{"id":"1.170370562","rc":[{"atl":[[3.7,75]],"id":9631798}],"con":true,"img":false}]}
{"op":"mcm","clk":"1350000146","pt":1588415098858,"mc":[{"id":"1.170370562","rc":[{"atl":[[5,0.01]],"id":9631798}],"con":true,"img":false}]}
{"op":"mcm","clk":"1350000150","pt":1588415098961,"mc":[{"id":"1.170370562","rc":[{"atl":[[4,0.01]],"id":9631798}],"con":true,"img":false}]}
{"op":"mcm","clk":"1350000157","pt":1588415099167,"mc":[{"id":"1.170370562","rc":[{"atb":[[1.36,531.91]],"id":9625043}],"con":true,"img":false}]}
{"op":"mcm","clk":"1350000166","pt":1588415099481,"mc":[{"id":"1.170370562","rc":[{"trd":[[1.4,4870.82]],"ltp":1.4,"tv":4870.82,"id":9625043},{"trd":[[3.5,966.42]],"ltp":3.5,"tv":966.42,"id":9631798},{"atb":[[3.5,32.45]],"id":9631798}],"con":true,"img":false}]}
{"op":"mcm","clk":"1350000171","pt":1588415099591,"mc":[{"id":"1.170370562","rc":[{"trd":[[1.4,4875.32]],"ltp":1.4,"tv":4875.32,"id":9625043},{"trd":[[3.5,968.22]],"ltp":3.5,"tv":968.22,"id":9631798},{"atb":[[3.5,30.65]],"id":9631798}],"con":true,"img":false}]}
{"op":"mcm","clk":"1350000175","pt":1588415099693,"mc":[{"id":"1.170370562","rc":[{"trd":[[1.4,4951.95]],"ltp":1.4,"tv":4951.95,"id":9625043},{"atb":[[1.4,142.34]],"id":9625043},{"trd":[[3.5,998.87]],"ltp":3.5,"tv":998.87,"id":9631798},{"atb":[[3.5,0]],"id":9631798}],"con":true,"img":false}]}
{"op":"mcm","clk":"1350000237","pt":1588415101672,"mc":[{"id":"1.170370562","rc":[{"atl":[[1.49,0]],"id":9625043}],"con":true,"img":false}]}
{"op":"mcm","clk":"1350000245","pt":1588415101985,"mc":[{"id":"1.170370562","rc":[{"atl":[[1.44,55]],"id":9625043}],"con":true,"img":false}]}
{"op":"mcm","clk":"1350000250","pt":1588415102089,"mc":[{"id":"1.170370562","rc":[{"trd":[[1.4,5020.2]],"ltp":1.4,"tv":5020.2,"id":9625043},{"atb":[[1.4,74.08]],"id":9625043},{"trd":[[3.5,1026.17]],"ltp":3.5,"tv":1026.17,"id":9631798}],"con":true,"img":false}]}
{"op":"mcm","clk":"1350000259","pt":1588415102354,"mc":[{"id":"1.170370562","rc":[{"atl":[[1.52,0]],"id":9625043}],"con":true,"img":false}]}
{"op":"mcm","clk":"1350000266","pt":1588415102562,"mc":[{"id":"1.170370562","rc":[{"atl":[[1.43,0]],"id":9625043}],"con":true,"img":false}]}
{"op":"mcm","clk":"1350000270","pt":1588415102665,"mc":[{"id":"1.170370562","rc":[{"atb":[[1.4,124.08]],"id":9625043},{"atl":[[1000,2.05]],"id":9631798}],"con":true,"img":false}]}
{"op":"mcm","clk":"1350000272","pt":1588415102770,"mc":[{"id":"1.170370562","rc":[{"atl":[[1000,4.05]],"id":9631798}],"con":true,"img":false}]}
{"op":"mcm","clk":"1350000275","pt":1588415102873,"mc":[{"id":"1.170370562","rc":[{"atl":[[1000,2.06]],"id":9631798}],"con":true,"img":false}]}
{"op":"mcm","clk":"1350000279","pt":1588415102977,"mc":[{"id":"1.170370562","rc":[{"atb":[[1.28,500]],"id":9625043},{"atl":[[1000,2.07]],"id":9631798}],"con":true,"img":false}]}
{"op":"mcm","clk":"1350000281","pt":1588415103081,"mc":[{"id":"1.170370562","rc":[{"trd":[[1.4,5022.56]],"ltp":1.4,"tv":5022.56,"id":9625043},{"atb":[[1.4,122.9]],"id":9625043},{"atl":[[1000,2.06]],"id":9631798}],"con":true,"img":false}]}
{"op":"mcm","clk":"1350000285","pt":1588415103186,"mc":[{"id":"1.170370562","rc":[{"atl":[[1.44,0]],"id":9625043},{"atl":[[1000,4.06]],"id":9631798}],"con":true,"img":false}]}
{"op":"mcm","clk":"1350000289","pt":1588415103290,"mc":[{"id":"1.170370562","rc":[{"atb":[[1.4,126.41]],"id":9625043},{"atl":[[1000,2.06]],"id":9631798}],"con":true,"img":false}]}
{"op":"mcm","clk":"1350000292","pt":1588415103395,"mc":[{"id":"1.170370562","rc":[{"atl":[[1000,0.07]],"id":9631798}],"con":true,"img":false}]}
{"op":"mcm","clk":"1350000297","pt":1588415103500,"mc":[{"id":"1.170370562","rc":[{"atb":[[1.24,500]],"id":9625043},{"atl":[[1000,2.06]],"id":9631798}],"con":true,"img":false}]}
{"op":"mcm","clk":"1350000301","pt":1588415103554,"mc":[{"id":"1.170370562","rc":[{"trd":[[1.4,5261.99]],"ltp":1.4,"tv":5261.99,"id":9625043},{"atb":[[1.4,6.69]],"id":9625043}],"con":true,"img":false}]}
{"op":"mcm","clk":"1350000304","pt":1588415103656,"mc":[{"id":"1.170370562","rc":[{"atl":[[1000,0.06]],"id":9631798}],"con":true,"img":false}]}
{"op":"mcm","clk":"1350000312","pt":1588415103863,"mc":[{"id":"1.170370562","rc":[{"atl":[[1000,0.05]],"id":9631798}],"con":true,"img":false}]}
{"op":"mcm","clk":"1350000322","pt":1588415104178,"mc":[{"id":"1.170370562","rc":[{"atl":[[1000,2.05]],"id":9631798}],"con":true,"img":false}]}
{"op":"mcm","clk":"1350000329","pt":1588415104386,"mc":[{"id":"1.170370562","rc":[{"atl":[[1000,4.05]],"id":9631798}],"con":true,"img":false}]}
{"op":"mcm","clk":"1350000332","pt":1588415104489,"mc":[{"id":"1.170370562","rc":[{"atl":[[1000,2.06]],"id":9631798}],"con":true,"img":false}]}
{"op":"mcm","clk":"1350000335","pt":1588415104594,"mc":[{"id":"1.170370562","rc":[{"atb":[[1.34,265.95]],"id":9625043},{"atl":[[1000,2.07]],"id":9631798}],"con":true,"img":false}]}
{"op":"mcm","clk":"1350000339","pt":1588415104696,"mc":[{"id":"1.170370562","rc":[{"atb":[[1.4,10.19]],"id":9625043},{"atl":[[1000,2.06]],"id":9631798}],"con":true,"img":false}]}
{"op":"mcm","clk":"1350000342","pt":1588415104751,"mc":[{"id":"1.170370562","rc":[{"atl":[[1000,0.06]],"id":9631798}],"con":true,"img":false}]}
{"op":"mcm","clk":"1350000349","pt":1588415104958,"mc":[{"id":"1.170370562","rc":[{"atl":[[1000,0.05]],"id":9631798}],"con":true,"img":false}]}
{"op":"mcm","clk":"1350000356","pt":1588415105165,"mc":[{"id":"1.170370562","rc":[{"atb":[[1.4,11.04]],"id":9625043},{"atl":[[4,0],[5,0],[4.1,0],[3.55,0],[3.65,0]],"id":9631798}],"con":true,"img":false}]}
{"op":"mcm","clk":"1350000359","pt":1588415105269,"mc":[{"id":"1.170370562","rc":[{"atl":[[1000,2.05]],"id":9631798}],"con":true,"img":false}]}
{"op":"mcm","clk":"1350000371","pt":1588415105476,"mc":[{"id":"1.170370562","rc":[{"atl":[[1000,2.06]],"id":9631798}],"con":true,"img":false}]}
{"op":"mcm","clk":"1350000381","pt":1588415105681,"mc":[{"id":"1.170370562","rc":[{"atl":[[1000,4.06]],"id":9631798}],"con":true,"img":false}]}
{"op":"mcm","clk":"1350000384","pt":1588415105784,"mc":[{"id":"1.170370562","rc":[{"atl":[[1000,2.06]],"id":9631798}],"con":true,"img":false}]}
{"op":"mcm","clk":"1350000389","pt":1588415105888,"mc":[{"id":"1.170370562","rc":[{"atl":[[1000,0.07]],"id":9631798}],"con":true,"img":false}]}
{"op":"mcm","clk":"1350000395","pt":1588415105991,"mc":[{"id":"1.170370562","rc":[{"trd":[[1.37,1719.33],[1.4,5284.08]],"ltp":1.37,"tv":7003.41,"id":9625043},{"atb":[[1.4,0]],"id":9625043},{"trd":[[3.7,36.39]],"ltp":3.7,"tv":36.39,"id":9631798},{"atl":[[3.7,67.98],[1000,0.06]],"id":9631798}],"con":true,"img":false}]}
{"op":"mcm","clk":"1350000399","pt":1588415106095,"mc":[{"id":"1.170370562","rc":[{"atl":[[1000,0.05]],"id":9631798}],"con":true,"img":false}]}
{"op":"mcm","clk":"1350000452","pt":1588415107806,"mc":[{"id":"1.170370562","rc":[{"atl":[[1.51,79.78],[1.42,0]],"id":9625043}],"con":true,"img":false}]}
{"op":"mcm","clk":"1350000460","pt":1588415107964,"mc":[{"id":"1.170370562","rc":[{"atl":[[1.51,159.57]],"id":9625043}],"con":true,"img":false}]}
{"op":"mcm","clk":"1350000467","pt":1588415108169,"mc":[{"id":"1.170370562","rc":[{"atl":[[1.51,239.36]],"id":9625043},{"atl":[[4.8,0.01]],"id":9631798}],"con":true,"img":false}]}
{"op":"mcm","clk":"1350000474","pt":1588415108377,"mc":[{"id":"1.170370562","rc":[{"atl":[[4.3,0.01]],"id":9631798}],"con":true,"img":false}]}
{"op":"mcm","clk":"1350000482","pt":1588415108584,"mc":[{"id":"1.170370562","rc":[{"atl":[[3.8,0.01]],"id":9631798}],"con":true,"img":false}]}
{"op":"mcm","clk":"1350000491","pt":1588415108791,"mc":[{"id":"1.170370562","rc":[{"atl":[[3.65,0.01]],"id":9631798}],"con":true,"img":false}]}
{"op":"mcm","clk":"1350000496","pt":1588415108997,"mc":[{"id":"1.170370562","rc":[{"atl":[[1.62,177.3]],"id":9625043},{"atl":[[3.45,0.01]],"id":9631798}],"con":true,"img":false}]}
{"op":"mcm","clk":"1350000507","pt":1588415109305,"mc":[{"id":"1.170370562","rc":[{"trd":[[1.4,5284.11]],"ltp":1.4,"tv":5284.11,"id":9625043},{"atl":[[1.4,2.03]],"id":9625043},{"trd":[[3.45,0.01]],"ltp":3.45,"tv":0.01,"id":9631798},{"atl":[[3.45,0]],"id":9631798}],"con":true,"img":false}]}
{"op":"mcm","clk":"1350000513","pt":1588415109359,"mc":[{"id":"1.170370562","rc":[{"atl":[[1.53,20.3]],"id":9625043}],"con":true,"img":false}]}
{"op":"mcm","clk":"1350000525","pt":1588415109766,"mc":[{"id":"1.170370562","rc":[{"atl":[[1.8,0.34]],"id":9625043},{"atl":[[5,0.01]],"id":9631798}],"con":true,"img":false}]}
{"op":"mcm","clk":"1350000528","pt":1588415109870,"mc":[{"id":"1.170370562","rc":[{"atl":[[4.8,0],[4.3,0],[3.95,0.01],[3.8,0],[3.65,0]],"id":9631798}],"con":true,"img":false}]}
{"op":"mcm","clk":"1350000532","pt":1588415109972,"mc":[{"id":"1.170370562","rc":[{"atb":[[1.35,240]],"id":9625043}],"con":true,"img":false}]}
{"op":"mcm","clk":"1350000535","pt":1588415110076,"mc":[{"id":"1.170370562","rc":[{"atl":[[3.75,0.01]],"id":9631798}],"con":true,"img":false}]}
{"op":"mcm","clk":"1350000539","pt":1588415110181,"mc":[{"id":"1.170370562","rc":[{"trd":[[1.42,1437.45],[1.4,5288.18]],"ltp":1.42,"tv":6725.63,"id":9625043},{"atl":[[1.4,0]],"id":9625043},{"trd":[[3.4,53.52]],"ltp":3.4,"tv":53.52,"id":9631798},{"atb":[[3.4,45.42]],"id":9631798}],"con":true,"img":false}]}
{"op":"mcm","clk":"1350000543","pt":1588415110284,"mc":[{"id":"1.170370562","rc":[{"atl":[[1.4,0.11]],"id":9625043}],"con":true,"img":false}]}
{"op":"mcm","clk":"1350000546","pt":1588415110389,"mc":[{"id":"1.170370562","rc":[{"atb":[[1.32,740]],"id":9625043}],"con":true,"img":false}]}
{"op":"mcm","clk":"1350000554","pt":1588415110593,"mc":[{"id":"1.170370562","rc":[{"trd":[[1.42,1441.76],[1.4,5288.42]],"ltp":1.42,"tv":6730.18,"id":9625043},{"atl":[[1.4,0]],"id":9625043},{"trd":[[3.4,55.32]],"ltp":3.4,"tv":55.32,"id":9631798},{"atb":[[3.4,43.62]],"id":9631798}],"con":true,"img":false}]}
{"op":"mcm","clk":"1350000567","pt":1588415110902,"mc":[{"id":"1.170370562","rc":[{"atl":[[4.7,0.01]],"id":9631798}],"con":true,"img":false}]}
{"op":"mcm","clk":"1350000578","pt":1588415111058,"mc":[{"id":"1.170370562","rc":[{"atl":[[3.95,0.02]],"id":9631798}],"con":true,"img":false}]}
{"op":"mcm","clk":"1350000582","pt":1588415111161,"mc":[{"id":"1.170370562","rc":[{"atl":[[3.75,0.02]],"id":9631798}],"con":true,"img":false}]}
{"op":"mcm","clk":"1350000607","pt":1588415112090,"mc":[{"id":"1.170370562","rc":[{"atl":[[1.4,2.57]],"id":9625043}],"con":true,"img":false}]}
{"op":"mcm","clk":"1350000629","pt":1588415112967,"mc":[{"id":"1.170370562","rc":[{"trd":[[1.4,5290.99]],"ltp":1.4,"tv":5290.99,"id":9625043},{"atl":[[1.4,0]],"id":9625043},{"trd":[[3.4,55.75],[3.5,1027.2]],"ltp":3.4,"tv":1082.95,"id":9631798},{"atb":[[3.4,43.41]],"id":9631798}],"con":true,"img":false}]}
{"op":"mcm","clk":"1350000643","pt":1588415113379,"mc":[{"id":"1.170370562","rc":[{"atl":[[1.47,177.3]],"id":9625043}],"con":true,"img":false}]}
{"op":"mcm","clk":"1350000652","pt":1588415113584,"mc":[{"id":"1.170370562","rc":[{"atb":[[1.21,500]],"id":9625043}],"con":true,"img":false}]}
{"op":"mcm","clk":"1350000673","pt":1588415114510,"mc":[{"id":"1.170370562","rc":[{"atl":[[1.4,2.34],[1.54,265.95]],"id":9625043}],"con":true,"img":false}]}
{"op":"mcm","clk":"1350000684","pt":1588415114984,"mc":[{"id":"1.170370562","rc":[{"atb":[[1.01,1102.13]],"id":9631798}],"con":true,"img":false}]}
{"op":"mcm","clk":"1350000688","pt":1588415115088,"mc":[{"id":"1.170370562","rc":[{"atb":[[1.01,1100.56]],"id":9631798}],"con":true,"img":false}]}
{"op":"mcm","clk":"1350000691","pt":1588415115195,"mc":[{"id":"1.170370562","rc":[{"atb":[[1.01,1100.13]],"id":9631798}],"con":true,"img":false}]}
{"op":"mcm","clk":"1350000697","pt":1588415115298,"mc":[{"id":"1.170370562","rc":[{"atb":[[1.3,500]],"id":9625043}],"con":true,"img":false}]}
{"op":"mcm","clk":"1350000710","pt":1588415115812,"mc":[{"id":"1.170370562","rc":[{"trd":[[1.48,162.34],[1.47,822.07],[1.4,5295.69],[1.42,1545.71]],"ltp":1.48,"tv":7825.8,"id":9625043},{"atl":[[1.48,251.5],[1.4,0],[1.47,0]],"id":9625043},{"trd":[[3.4,99.16]],"ltp":3.4,"tv":99.16,"id":9631798},{"atb":[[3.4,0]],"id":9631798}],"con":true,"img":false}]}
{"op":"mcm","clk":"1350000713","pt":1588415115867,"mc":[{"id":"1.170370562","rc":[{"atb":[[1.42,6]],"id":9625043}],"con":true,"img":false}]}
{"op":"mcm","clk":"1350000724","pt":1588415116176,"mc":[{"id":"1.170370562","rc":[{"atb":[[1.43,7.09]],"id":9625043}],"con":true,"img":false}]}
{"op":"mcm","clk":"1350000730","pt":1588415116380,"mc":[{"id":"1.170370562","rc":[{"atl":[[1.47,55]],"id":9625043}],"con":true,"img":false}]}
{"op":"mcm","clk":"1350000741","pt":1588415116896,"mc":[{"id":"1.170370562","rc":[{"trd":[[1.37,1745.07],[1.43,499.38],[1.42,1557.71]],"ltp":1.37,"tv":3802.16,"id":9625043},{"atb":[[1.43,0],[1.42,0]],"id":9625043},{"atl":[[1.4,2.57]],"id":9625043},{"trd":[[3.7,45.92]],"ltp":3.7,"tv":45.92,"id":9631798},{"atl":[[3.7,58.45]],"id":9631798}],"con":true,"img":false}]}
{"op":"mcm","clk":"1350000749","pt":1588415117208,"mc":[{"id":"1.170370562","rc":[{"atl":[[1.43,55]],"id":9625043}],"con":true,"img":false}]}
{"op":"mcm","clk":"1350000769","pt":1588415118083,"mc":[{"id":"1.170370562","rc":[{"atl":[[5,0],[3.95,0],[3.75,0],[4.7,0]],"id":9631798}],"con":true,"img":false}]}
{"op":"mcm","clk":"1350000793","pt":1588415119173,"mc":[{"id":"1.170370562","rc":[{"atl":[[1.4,4.34]],"id":9625043}],"con":true,"img":false}]}
{"op":"mcm","clk":"1350000811","pt":1588415119890,"mc":[{"id":"1.170370562","rc":[{"atb":[[1.32,500]],"id":9625043},{"atl":[[1.51,0]],"id":9625043}],"con":true,"img":false}]}
{"op":"mcm","clk":"1350000815","pt":1588415119995,"mc":[{"id":"1.170370562","rc":[{"trd":[[1.4,5300.04]],"ltp":1.4,"tv":5300.04,"id":9625043},{"atl":[[1.4,0]],"id":9625043},{"trd":[[3.5,1028.94]],"ltp":3.5,"tv":1028.94,"id":9631798},{"atl":[[3.4,11.38]],"id":9631798}],"con":true,"img":false}]}
{"op":"mcm","clk":"1350000823","pt":1588415120310,"mc":[{"id":"1.170370562","rc":[{"trd":[[3.4,100.02]],"ltp":3.4,"tv":100.02,"id":9631798},{"atl":[[3.4,10.95]],"id":9631798}],"con":true,"img":false}]}
{"op":"mcm","clk":"1350000833","pt":1588415120576,"mc":[{"id":"1.170370562","rc":[{"atl":[[3.4,41.34]],"id":9631798}],"con":true,"img":false}]}
{"op":"mcm","clk":"1350000838","pt":1588415120681,"mc":[{"id":"1.170370562","rc":[{"atb":[[1.42,27.48]],"id":9625043}],"con":true,"img":false}]}
{"op":"mcm","clk":"1350000867","pt":1588415121608,"mc":[{"id":"1.170370562","rc":[{"atb":[[1.38,1165.41]],"id":9625043}],"con":true,"img":false}]}
{"op":"mcm","clk":"1350000872","pt":1588415121814,"mc":[{"id":"1.170370562","rc":[{"atb":[[1.2,128.89]],"id":9625043}],"con":true,"img":false}]}
{"op":"mcm","clk":"1350000878","pt":1588415121971,"mc":[{"id":"1.170370562","rc":[{"atb":[[1.42,30.54]],"id":9625043}],"con":true,"img":false}]}
{"op":"mcm","clk":"1350000890","pt":1588415122486,"mc":[{"id":"1.170370562","rc":[{"atl":[[3.4,10.95]],"id":9631798}],"con":true,"img":false}]}
{"op":"mcm","clk":"1350000904","pt":1588415123103,"mc":[{"id":"1.170370562","rc":[{"atb":[[1.42,33.11]],"id":9625043}],"con":true,"img":false}]}
{"op":"mcm","clk":"1350000919","pt":1588415123719,"mc":[{"id":"1.170370562","rc":[{"atb":[[1.4,177.3]],"id":9625043}],"con":true,"img":false}]}
{"op":"mcm","clk":"1350000948","pt":1588415124597,"mc":[{"id":"1.170370562","rc":[{"atb":[[1.01,1003.72]],"id":9625043}],"con":true,"img":false}]}
{"op":"mcm","clk":"1350000953","pt":1588415124804,"mc":[{"id":"1.170370562","rc":[{"atl":[[1.46,2313]],"id":9625043}],"con":true,"img":false}]}
{"op":"mcm","clk":"1350000957","pt":1588415124908,"mc":[{"id":"1.170370562","rc":[{"atb":[[1.01,1002.23]],"id":9625043}],"con":true,"img":false}]}
{"op":"mcm","clk":"1350000962","pt":1588415125114,"mc":[{"id":"1.170370562","rc":[{"atb":[[1.01,1001.72]],"id":9625043}],"con":true,"img":false}]}
{"op":"mcm","clk":"1350000969","pt":1588415125273,"mc":[{"id":"1.170370562","rc":[{"atl":[[1.46,2392.78]],"id":9625043}],"con":true,"img":false}]}
{"op":"mcm","clk":"1350000977","pt":1588415125481,"mc":[{"id":"1.170370562","rc":[{"atl":[[1.46,2472.57]],"id":9625043}],"con":true,"img":false}]}
{"op":"mcm","clk":"1350000985","pt":1588415125583,"mc":[{"id":"1.170370562","rc":[{"atb":[[1.4,186.17]],"id":9625043},{"atl":[[1.46,2552.36]],"id":9625043}],"con":true,"img":false}]}
{"op":"mcm","clk":"1350000992","pt":1588415125894,"mc":[{"id":"1.170370562","rc":[{"atl":[[1.47,232.3]],"id":9625043}],"con":true,"img":false}]}
{"op":"mcm","clk":"1350000998","pt":1588415126201,"mc":[{"id":"1.170370562","rc":[{"atb":[[1.18,240]],"id":9625043}],"con":true,"img":false}]}
{"op":"mcm","clk":"1350001003","pt":1588415126409,"mc":[{"id":"1.170370562","rc":[{"atl":[[1.5,2.57]],"id":9625043}],"con":true,"img":false}]}
{"op":"mcm","clk":"1350001027","pt":1588415127185,"mc":[{"id":"1.170370562","rc":[{"atl":[[3.4,12.95]],"id":9631798}],"con":true,"img":false}]}
{"op":"mcm","clk":"1350001030","pt":1588415127286,"mc":[{"id":"1.170370562","rc":[{"atb":[[1.38,1245.2]],"id":9625043}],"con":true,"img":false}]}
{"op":"mcm","clk":"1350001033","pt":1588415127390,"mc":[{"id":"1.170370562","rc":[{"atb":[[1.38,1324.98]],"id":9625043}],"con":true,"img":false}]}
{"op":"mcm","clk":"1350001038","pt":1588415127493,"mc":[{"id":"1.170370562","rc":[{"trd":[[1.43,609.38]],"ltp":1.43,"tv":609.38,"id":9625043},{"atb":[[1.38,1404.77],[1.44,365]],"id":9625043},{"atl":[[1.43,0]],"id":9625043}],"con":true,"img":false}]}
{"op":"mcm","clk":"1350001046","pt":1588415127905,"mc":[{"id":"1.170370562","rc":[{"atb":[[1.4,189.67]],"id":9625043},{"atl":[[1.47,55]],"id":9625043}],"con":true,"img":false}]}
{"op":"mcm","clk":"1350001057","pt":1588415128110,"mc":[{"id":"1.170370562","rc":[{"atb":[[1.4,180.8]],"id":9625043},{"atb":[[1.01,1102.13]],"id":9631798}],"con":true,"img":false}]}
{"op":"mcm","clk":"1350001064","pt":1588415128316,"mc":[{"id":"1.170370562","rc":[{"atb":[[1.01,1100.14]],"id":9631798}],"con":true,"img":false}]}
{"op":"mcm","clk":"1350001072","pt":1588415128490,"mc":[{"id":"1.170370562","rc":[{"atb":[[1.4,181.04],[1.39,79.78]],"id":9625043},{"atb":[[1.01,1100.13]],"id":9631798}],"con":true,"img":false}]}
{"op":"mcm","clk":"1350001077","pt":1588415128695,"mc":[{"id":"1.170370562","rc":[{"atb":[[1.39,159.57]],"id":9625043}],"con":true,"img":false}]}
{"op":"mcm","clk":"1350001084","pt":1588415128797,"mc":[{"id":"1.170370562","rc":[{"atb":[[1.39,239.36]],"id":9625043}],"con":true,"img":false}]}
{"op":"mcm","clk":"1350001104","pt":1588415129419,"mc":[{"id":"1.170370562","rc":[{"atl":[[1.46,239.36]],"id":9625043}],"con":true,"img":false}]}
{"op":"mcm","clk":"1350001113","pt":1588415129624,"mc":[{"id":"1.170370562","rc":[{"atl":[[1.47,0]],"id":9625043}],"con":true,"img":false}]}
{"op":"mcm","clk":"1350001118","pt":1588415129830,"mc":[{"id":"1.170370562","rc":[{"trd":[[1.44,1200.26]],"ltp":1.44,"tv":1200.26,"id":9625043},{"atb":[[1.44,364.9]],"id":9625043}],"con":true,"img":false}]}
{"op":"mcm","clk":"1350001128","pt":1588415130194,"mc":[{"id":"1.170370562","rc":[{"atb":[[1.4,181.55]],"id":9625043}],"con":true,"img":false}]}
{"op":"mcm","clk":"1350001149","pt":1588415130916,"mc":[{"id":"1.170370562","rc":[{"atl":[[1000,1.53]],"id":9625043}],"con":true,"img":false}]}
{"op":"mcm","clk":"1350001153","pt":1588415131037,"mc":[{"id":"1.170370562","rc":[{"trd":[[1.44,1242.3]],"ltp":1.44,"tv":1242.3,"id":9625043},{"atb":[[1.44,343.88]],"id":9625043}],"con":true,"img":false}]}
{"op":"mcm","clk":"1350001157","pt":1588415131122,"mc":[{"id":"1.170370562","rc":[{"atl":[[1000,0.05]],"id":9625043}],"con":true,"img":false}]}
{"op":"mcm","clk":"1350001167","pt":1588415131329,"mc":[{"id":"1.170370562","rc":[{"atb":[[1.42,30.54]],"id":9625043}],"con":true,"img":false}]}
{"op":"mcm","clk":"1350001182","pt":1588415131592,"mc":[{"id":"1.170370562","rc":[{"trd":[[1.46,920.36]],"ltp":1.46,"tv":920.36,"id":9625043},{"atl":[[1.46,195.37]],"id":9625043}],"con":true,"img":false}]}
{"op":"mcm","clk":"1350001187","pt":1588415131696,"mc":[{"id":"1.170370562","rc":[{"atl":[[1.46,0]],"id":9625043}],"con":true,"img":false}]}
{"op":"mcm","clk":"1350001191","pt":1588415131797,"mc":[{"id":"1.170370562","rc":[{"atl":[[1.48,0]],"id":9625043}],"con":true,"img":false}]}
{"op":"mcm","clk":"1350001196","pt":1588415131902,"mc":[{"id":"1.170370562","rc":[{"atb":[[1.43,1.05]],"id":9625043},{"atl":[[1.45,177.3]],"id":9625043},{"atl":[[3.5,1.39]],"id":9631798}],"con":true,"img":false}]}
{"op":"mcm","clk":"1350001217","pt":1588415132829,"mc":[{"id":"1.170370562","rc":[{"atb":[[1.42,3.06]],"id":9625043}],"con":true,"img":false}]}
{"op":"mcm","clk":"1350001225","pt":1588415133036,"mc":[{"id":"1.170370562","rc":[{"atb":[[1.4,181.04]],"id":9625043},{"atl":[[1.45,0]],"id":9625043}],"con":true,"img":false}]}
{"op":"mcm","clk":"1350001234","pt":1588415133193,"mc":[{"id":"1.170370562","rc":[{"atb":[[1.43,9.92]],"id":9625043}],"con":true,"img":false}]}
{"op":"mcm","clk":"1350001238","pt":1588415133296,"mc":[{"id":"1.170370562","rc":[{"atb":[[1.43,55.57]],"id":9625043}],"con":true,"img":false}]}
{"op":"mcm","clk":"1350001249","pt":1588415133604,"mc":[{"id":"1.170370562","rc":[{"trd":[[1.44,1242.32]],"ltp":1.44,"tv":1242.32,"id":9625043},{"atb":[[1.44,343.86]],"id":9625043},{"trd":[[3.3,27.85]],"ltp":3.3,"tv":27.85,"id":9631798},{"atl":[[3.35,39.99]],"id":9631798}],"con":true,"img":false}]}
{"op":"mcm","clk":"1350001257","pt":1588415133810,"mc":[{"id":"1.170370562","rc":[{"atb":[[1.4,182.57]],"id":9625043}],"con":true,"img":false}]}
{"op":"mcm","clk":"1350001260","pt":1588415133913,"mc":[{"id":"1.170370562","rc":[{"atb":[[1.4,182.34]],"id":9625043}],"con":true,"img":false}]}
{"op":"mcm","clk":"1350001264","pt":1588415134016,"mc":[{"id":"1.170370562","rc":[{"trd":[[1.44,1242.56]],"ltp":1.44,"tv":1242.56,"id":9625043},{"atb":[[1.44,343.62]],"id":9625043},{"trd":[[3.3,27.95]],"ltp":3.3,"tv":27.95,"id":9631798}],"con":true,"img":false}]}
{"op":"mcm","clk":"1350001279","pt":1588415134532,"mc":[{"id":"1.170370562","rc":[{"trd":[[1.44,1929.8]],"ltp":1.44,"tv":1929.8,"id":9625043},{"atb":[[1.44,0]],"id":9625043},{"atl":[[1.44,2001.5]],"id":9625043}],"con":true,"img":false}]}
{"op":"mcm","clk":"1350001282","pt":1588415134637,"mc":[{"id":"1.170370562","rc":[{"atl":[[1.44,2178.8]],"id":9625043}],"con":true,"img":false}]}
{"op":"mcm","clk":"1350001286","pt":1588415134741,"mc":[{"id":"1.170370562","rc":[{"atb":[[1.39,0]],"id":9625043},{"atl":[[1.44,2233.8]],"id":9625043}],"con":true,"img":false}]}
{"op":"mcm","clk":"1350001289","pt":1588415134796,"mc":[{"id":"1.170370562","rc":[{"atb":[[1.01,1102.13]],"id":9631798}],"con":true,"img":false}]}
{"op":"mcm","clk":"1350001296","pt":1588415135002,"mc":[{"id":"1.170370562","rc":[{"trd":[[1.44,2477.68]],"ltp":1.44,"tv":2477.68,"id":9625043},{"atb":[[1.38,1165.41]],"id":9625043},{"atl":[[1.44,1959.86]],"id":9625043},{"atb":[[1.01,1100.14]],"id":9631798}],"con":true,"img":false}]}
{"op":"mcm","clk":"1350001307","pt":1588415135310,"mc":[{"id":"1.170370562","rc":[{"atb":[[1.01,1100.13]],"id":9631798}],"con":true,"img":false}]}
{"op":"mcm","clk":"1350001326","pt":1588415136030,"mc":[{"id":"1.170370562","rc":[{"atb":[[1.01,1102.13]],"id":9631798}],"con":true,"img":false}]}
{"op":"mcm","clk":"1350001334","pt":1588415136237,"mc":[{"id":"1.170370562","rc":[{"atb":[[1.2,127.71]],"id":9625043},{"atl":[[1.45,88.65],[1.89,1.48],[1.76,0]],"id":9625043},{"atb":[[1.01,1100.14]],"id":9631798}],"con":true,"img":false}]}
{"op":"mcm","clk":"1350001341","pt":1588415136445,"mc":[{"id":"1.170370562","rc":[{"atb":[[1.01,1100.13]],"id":9631798}],"con":true,"img":false}]}
{"op":"mcm","clk":"1350001358","pt":1588415136806,"mc":[{"id":"1.170370562","rc":[{"atb":[[1.43,46.71]],"id":9625043}],"con":true,"img":false}]}
{"op":"mcm","clk":"1350001367","pt":1588415137112,"mc":[{"id":"1.170370562","rc":[{"atl":[[3.4,2]],"id":9631798}],"con":true,"img":false}]}
{"op":"mcm","clk":"1350001373","pt":1588415137318,"mc":[{"id":"1.170370562","rc":[{"atl":[[1.45,0]],"id":9625043}],"con":true,"img":false}]}
{"op":"mcm","clk":"1350001377","pt":1588415137423,"mc":[{"id":"1.170370562","rc":[{"atl":[[1.51,88.65]],"id":9625043}],"con":true,"img":false}]}
{"op":"mcm","clk":"1350001390","pt":1588415137837,"mc":[{"id":"1.170370562","rc":[{"atb":[[1.01,1102.13]],"id":9631798}],"con":true,"img":false}]}
{"op":"mcm","clk":"1350001392","pt":1588415137941,"mc":[{"id":"1.170370562","rc":[{"trd":[[1.44,2532.64]],"ltp":1.44,"tv":2532.64,"id":9625043},{"atl":[[1.44,1932.38]],"id":9625043}],"con":true,"img":false}]}
{"op":"mcm","clk":"1350001396","pt":1588415138046,"mc":[{"id":"1.170370562","rc":[{"atb":[[1.42,0]],"id":9625043},{"atl":[[1.44,1877.38]],"id":9625043},{"atb":[[1.01,1100.14]],"id":9631798},{"atl":[[3.3,23.04]],"id":9631798}],"con":true,"img":false}]}
{"op":"mcm","clk":"1350001401","pt":1588415138113,"mc":[{"id":"1.170370562","rc":[{"atb":[[1.01,1003.72]],"id":9625043}],"con":true,"img":false}]}
{"op":"mcm","clk":"1350001406","pt":1588415138204,"mc":[{"id":"1.170370562","rc":[{"atb":[[1.43,49.29]],"id":9625043},{"atl":[[1.44,1878.55]],"id":9625043},{"atb":[[1.01,1100.13]],"id":9631798}],"con":true,"img":false}]}
{"op":"mcm","clk":"1350001411","pt":1588415138319,"mc":[{"id":"1.170370562","rc":[{"atb":[[1.01,1002.22]],"id":9625043}],"con":true,"img":false}]}
{"op":"mcm","clk":"1350001415","pt":1588415138409,"mc":[{"id":"1.170370562","rc":[{"trd":[[1.44,2621.22]],"ltp":1.44,"tv":2621.22,"id":9625043},{"atl":[[1.44,1834.26]],"id":9625043}],"con":true,"img":false}]}
{"op":"mcm","clk":"1350001418","pt":1588415138513,"mc":[{"id":"1.170370562","rc":[{"atb":[[1.01,1001.72]],"id":9625043}],"con":true,"img":false}]}
{"op":"mcm","clk":"1350001427","pt":1588415138718,"mc":[{"id":"1.170370562","rc":[{"trd":[[1.44,2777.29]],"ltp":1.44,"tv":2777.29,"id":9625043},{"atl":[[1.44,1678.19]],"id":9625043},{"trd":[[3.25,122.51]],"ltp":3.25,"tv":122.51,"id":9631798}],"con":true,"img":false}]}
{"op":"mcm","clk":"1350001431","pt":1588415138822,"mc":[{"id":"1.170370562","rc":[{"atb":[[1.4,5.03]],"id":9625043}],"con":true,"img":false}]}
{"op":"mcm","clk":"1350001437","pt":1588415139028,"mc":[{"id":"1.170370562","rc":[{"trd":[[1.44,2780.23]],"ltp":1.44,"tv":2780.23,"id":9625043},{"atl":[[1.44,1675.25]],"id":9625043},{"trd":[[3.25,123.81]],"ltp":3.25,"tv":123.81,"id":9631798}],"con":true,"img":false}]}
{"op":"mcm","clk":"1350001444","pt":1588415139132,"mc":[{"id":"1.170370562","rc":[{"atb":[[1.43,2.57]],"id":9625043}],"con":true,"img":false}]}
{"op":"mcm","clk":"1350001457","pt":1588415139443,"mc":[{"id":"1.170370562","rc":[{"atb":[[1.01,1102.13]],"id":9631798}],"con":true,"img":false}]}
{"op":"mcm","clk":"1350001460","pt":1588415139546,"mc":[{"id":"1.170370562","rc":[{"atb":[[1.43,179.88]],"id":9625043}],"con":true,"img":false}]}
{"op":"mcm","clk":"1350001463","pt":1588415139650,"mc":[{"id":"1.170370562","rc":[{"atb":[[1.01,1100.14]],"id":9631798}],"con":true,"img":false}]}
{"op":"mcm","clk":"1350001468","pt":1588415139808,"mc":[{"id":"1.170370562","rc":[{"atb":[[1.01,1100.13]],"id":9631798}],"con":true,"img":false}]}
{"op":"mcm","clk":"1350001478","pt":1588415140218,"mc":[{"id":"1.170370562","rc":[{"atb":[[1.43,2.57]],"id":9625043}],"con":true,"img":false}]}
{"op":"mcm","clk":"1350001484","pt":1588415140425,"mc":[{"id":"1.170370562","rc":[{"atb":[[2.94,0.01]],"id":9631798}],"con":true,"img":false}]}
{"op":"mcm","clk":"1350001488","pt":1588415140527,"mc":[{"id":"1.170370562","rc":[{"atb":[[1.43,91.22]],"id":9625043}],"con":true,"img":false}]}
{"op":"mcm","clk":"1350001499","pt":1588415140840,"mc":[{"id":"1.170370562","rc":[{"atl":[[1.44,1745.33]],"id":9625043}],"con":true,"img":false}]}
{"op":"mcm","clk":"1350001501","pt":1588415140944,"mc":[{"id":"1.170370562","rc":[{"atb":[[1.43,2.57]],"id":9625043}],"con":true,"img":false}]}
{"op":"mcm","clk":"1350001510","pt":1588415141148,"mc":[{"id":"1.170370562","rc":[{"atl":[[1.44,1746.5]],"id":9625043}],"con":true,"img":false}]}
{"op":"mcm","clk":"1350001521","pt":1588415141511,"mc":[{"id":"1.170370562","rc":[{"atb":[[1.4,3.5]],"id":9625043},{"atb":[[2.74,0.01]],"id":9631798}],"con":true,"img":false}]}
{"op":"mcm","clk":"1350001529","pt":1588415141921,"mc":[{"id":"1.170370562","rc":[{"trd":[[1.44,2803.22]],"ltp":1.44,"tv":2803.22,"id":9625043},{"atl":[[1.44,1735]],"id":9625043}],"con":true,"img":false}]}
{"op":"mcm","clk":"1350001535","pt":1588415142128,"mc":[{"id":"1.170370562","rc":[{"atl":[[3.4,0]],"id":9631798}],"con":true,"img":false}]}
{"op":"mcm","clk":"1350001541","pt":1588415142333,"mc":[{"id":"1.170370562","rc":[{"trd":[[1.44,2827.94]],"ltp":1.44,"tv":2827.94,"id":9625043},{"atl":[[1.44,1710.28]],"id":9625043},{"trd":[[3.25,134.77]],"ltp":3.25,"tv":134.77,"id":9631798}],"con":true,"img":false}]}
{"op":"mcm","clk":"1350001545","pt":1588415142437,"mc":[{"id":"1.170370562","rc":[{"atl":[[1.48,88.65]],"id":9625043}],"con":true,"img":false}]}
{"op":"mcm","clk":"1350001571","pt":1588415143158,"mc":[{"id":"1.170370562","rc":[{"trd":[[1.44,2834.06],[1.43,666.96]],"ltp":1.44,"tv":3501.02,"id":9625043},{"atb":[[1.43,0]],"id":9625043},{"atl":[[1.44,1707.22]],"id":9625043},{"trd":[[3.3,50.66]],"ltp":3.3,"tv":50.66,"id":9631798},{"atl":[[3.3,0.33]],"id":9631798}],"con":true,"img":false}]}
{"op":"mcm","clk":"1350001578","pt":1588415143315,"mc":[{"id":"1.170370562","rc":[{"atb":[[2.64,0.01]],"id":9631798}],"con":true,"img":false}]}
{"op":"mcm","clk":"1350001591","pt":1588415143623,"mc":[{"id":"1.170370562","rc":[{"trd":[[1.44,2835.06]],"ltp":1.44,"tv":2835.06,"id":9625043},{"atl":[[1.44,1706.72]],"id":9625043}],"con":true,"img":false}]}
{"op":"mcm","clk":"1350001606","pt":1588415144241,"mc":[{"id":"1.170370562","rc":[{"trd":[[1.44,2926.38]],"ltp":1.44,"tv":2926.38,"id":9625043},{"atl":[[1.44,1661.06]],"id":9625043}],"con":true,"img":false}]}
{"op":"mcm","clk":"1350001611","pt":1588415144344,"mc":[{"id":"1.170370562","rc":[{"trd":[[1.44,2928.5]],"ltp":1.44,"tv":2928.5,"id":9625043},{"atl":[[1.44,1660]],"id":9625043}],"con":true,"img":false}]}
{"op":"mcm","clk":"1350001617","pt":1588415144552,"mc":[{"id":"1.170370562","rc":[{"atb":[[1.39,177.3]],"id":9625043}],"con":true,"img":false}]}
{"op":"mcm","clk":"1350001622","pt":1588415144654,"mc":[{"id":"1.170370562","rc":[{"atb":[[1.28,0],[1.21,0],[1.24,0],[1.32,0],[1.3,0]],"id":9625043}],"con":true,"img":false}]}
{"op":"mcm","clk":"1350001626","pt":1588415144757,"mc":[{"id":"1.170370562","rc":[{"trd":[[1.44,3450.1]],"ltp":1.44,"tv":3450.1,"id":9625043},{"atl":[[1.44,1399.2]],"id":9625043}],"con":true,"img":false}]}
{"op":"mcm","clk":"1350001632","pt":1588415144964,"mc":[{"id":"1.170370562","rc":[{"atl":[[1.55,0]],"id":9625043},{"atb":[[2.9,0.01]],"id":9631798}],"con":true,"img":false}]}
{"op":"mcm","clk":"1350001636","pt":1588415145017,"mc":[{"id":"1.170370562","rc":[{"atl":[[3.35,0]],"id":9631798}],"con":true,"img":false}]}
{"op":"mcm","clk":"1350001640","pt":1588415145223,"mc":[{"id":"1.170370562","rc":[{"atl":[[3.3,0]],"id":9631798}],"con":true,"img":false}]}
{"op":"mcm","clk":"1350001660","pt":1588415146049,"mc":[{"id":"1.170370562","rc":[{"atb":[[1.39,417.3]],"id":9625043}],"con":true,"img":false}]}
{"op":"mcm","clk":"1350001664","pt":1588415146151,"mc":[{"id":"1.170370562","rc":[{"trd":[[1.44,3455.25]],"ltp":1.44,"tv":3455.25,"id":9625043},{"atl":[[1.44,1396.62]],"id":9625043}],"con":true,"img":false}]}
{"op":"mcm","clk":"1350001686","pt":1588415146824,"mc":[{"id":"1.170370562","rc":[{"atl":[[1.44,1219.32]],"id":9625043}],"con":true,"img":false}]}
{"op":"mcm","clk":"1350001693","pt":1588415147030,"mc":[{"id":"1.170370562","rc":[{"trd":[[1.44,5425.11]],"ltp":1.44,"tv":5425.11,"id":9625043},{"atl":[[1.44,234.39]],"id":9625043}],"con":true,"img":false}]}
{"op":"mcm","clk":"1350001701","pt":1588415147234,"mc":[{"id":"1.170370562","rc":[{"trd":[[1.44,5429.62]],"ltp":1.44,"tv":5429.62,"id":9625043},{"atl":[[1.44,229.88]],"id":9625043},{"trd":[[3.25,136.77]],"ltp":3.25,"tv":136.77,"id":9631798}],"con":true,"img":false}]}
{"op":"mcm","clk":"1350001720","pt":1588415147855,"mc":[{"id":"1.170370562","rc":[{"atl":[[1.44,72.42]],"id":9625043}],"con":true,"img":false}]}
{"op":"mcm","clk":"1350001733","pt":1588415148272,"mc":[{"id":"1.170370562","rc":[{"atl":[[1.62,0]],"id":9625043}],"con":true,"img":false}]}
{"op":"mcm","clk":"1350001745","pt":1588415148532,"mc":[{"id":"1.170370562","rc":[{"atb":[[1.39,917.3]],"id":9625043}],"con":true,"img":false}]}
{"op":"mcm","clk":"1350001771","pt":1588415149255,"mc":[{"id":"1.170370562","rc":[{"trd":[[1.44,5574.47]],"ltp":1.44,"tv":5574.47,"id":9625043},{"atb":[[1.44,55.23]],"id":9625043},{"atl":[[1.44,0]],"id":9625043}],"con":true,"img":false}]}
{"op":"mcm","clk":"1350001812","pt":1588415150749,"mc":[{"id":"1.170370562","rc":[{"atb":[[1.39,1417.3]],"id":9625043},{"atl":[[1.64,0],[1.73,0],[1.95,0]],"id":9625043}],"con":true,"img":false}]}
{"op":"mcm","clk":"1350001814","pt":1588415150852,"mc":[{"id":"1.170370562","rc":[{"atb":[[1.38,0]],"id":9625043}],"con":true,"img":false}]}
{"op":"mcm","clk":"1350001833","pt":1588415151730,"mc":[{"id":"1.170370562","rc":[{"atl":[[1.74,0]],"id":9625043}],"con":true,"img":false}]}
{"op":"mcm","clk":"1350001858","pt":1588415152351,"mc":[{"id":"1.170370562","rc":[{"atl":[[3.25,5.19]],"id":9631798}],"con":true,"img":false}]}
{"op":"mcm","clk":"1350001914","pt":1588415153946,"mc":[{"id":"1.170370562","rc":[{"trd":[[1.44,5599]],"ltp":1.44,"tv":5599.0,"id":9625043},{"atb":[[1.44,42.96]],"id":9625043}],"con":true,"img":false}]}
{"op":"mcm","clk":"1350001928","pt":1588415154666,"mc":[{"id":"1.170370562","rc":[{"trd":[[1.44,5601.06]],"ltp":1.44,"tv":5601.06,"id":9625043},{"atb":[[1.44,41.94]],"id":9625043}],"con":true,"img":false}]}
{"op":"mcm","clk":"1350001950","pt":1588415155543,"mc":[{"id":"1.170370562","rc":[{"atb":[[1.4,7.93]],"id":9625043}],"con":true,"img":false}]}
{"op":"mcm","clk":"1350001989","pt":1588415157249,"mc":[{"id":"1.170370562","rc":[{"atb":[[1.42,500]],"id":9625043}],"con":true,"img":false}]}
{"op":"mcm","clk":"1350001996","pt":1588415157553,"mc":[{"id":"1.170370562","rc":[{"trd":[[1.54,2036.29],[1.52,1984.15],[1.51,1604.15],[1.48,339.65],[1.53,1147.26],[1.5,887.2]],"ltp":1.54,"tv":7998.7,"id":9625043},{"atl":[[1.51,0],[1.48,0],[1.53,0],[1.54,22.92],[1.5,0]],"id":9625043},{"trd":[[2.9,35.64],[2.94,0.01]],"ltp":2.9,"tv":35.65,"id":9631798},{"atb":[[2.94,0],[2.9,0]],"id":9631798},{"atl":[[3.25,52.18]],"id":9631798}],"con":true,"img":false}]}
{"op":"mcm","clk":"1350002039","pt":1588415158950,"mc":[{"id":"1.170370562","rc":[{"atb":[[1.48,4.81]],"id":9625043}],"con":true,"img":false}]}
{"op":"mcm","clk":"1350002100","pt":1588415160868,"mc":[{"id":"1.170370562","rc":[{"trd":[[1.48,349.27]],"ltp":1.48,"tv":349.27,"id":9625043},{"atb":[[1.48,0]],"id":9625043},{"atl":[[1.46,43.43]],"id":9625043}],"con":true,"img":false}]}
{"op":"mcm","clk":"1350002128","pt":1588415161651,"mc":[{"id":"1.170370562","rc":[{"trd":[[1.46,1007.24]],"ltp":1.46,"tv":1007.24,"id":9625043},{"atb":[[1.48,141.84]],"id":9625043},{"atl":[[1.46,0]],"id":9625043}],"con":true,"img":false}]}
{"op":"mcm","clk":"1350002134","pt":1588415161756,"mc":[{"id":"1.170370562","rc":[{"atb":[[1.39,1240],[1.34,0],[1.36,0]],"id":9625043},{"atl":[[1.54,0]],"id":9625043}],"con":true,"img":false}]}
{"op":"mcm","clk":"1350002179","pt":1588415162647,"mc":[{"id":"1.170370562","rc":[{"trd":[[1.48,453.78]],"ltp":1.48,"tv":453.78,"id":9625043},{"atb":[[1.48,89.59]],"id":9625043}],"con":true,"img":false}]}
{"op":"mcm","clk":"1350002237","pt":1588415164256,"mc":[{"id":"1.170370562","rc":[{"atb":[[1.48,0]],"id":9625043}],"con":true,"img":false}]}
{"op":"mcm","clk":"1350002254","pt":1588415164881,"mc":[{"id":"1.170370562","rc":[{"atl":[[1.53,177.3]],"id":9625043}],"con":true,"img":false}]}
{"op":"mcm","clk":"1350002279","pt":1588415165979,"mc":[{"id":"1.170370562","rc":[{"atl":[[1.51,55]],"id":9625043}],"con":true,"img":false}]}
{"op":"mcm","clk":"1350002299","pt":1588415166498,"mc":[{"id":"1.170370562","rc":[{"atb":[[1.01,1102.13]],"id":9631798}],"con":true,"img":false}]}
{"op":"mcm","clk":"1350002303","pt":1588415166551,"mc":[{"id":"1.170370562","rc":[{"atl":[[1.48,55]],"id":9625043}],"con":true,"img":false}]}
{"op":"mcm","clk":"1350002307","pt":1588415166653,"mc":[{"id":"1.170370562","rc":[{"atb":[[1.46,186.64]],"id":9625043}],"con":true,"img":false}]}
{"op":"mcm","clk":"1350002312","pt":1588415166767,"mc":[{"id":"1.170370562","rc":[{"atb":[[1.01,1100.14]],"id":9631798}],"con":true,"img":false}]}
{"op":"mcm","clk":"1350002319","pt":1588415166963,"mc":[{"id":"1.170370562","rc":[{"atb":[[1.01,1100.13]],"id":9631798}],"con":true,"img":false}]}
