{"op":"mcm","clk":"1362324476","pt":1588439147986,"mc":[{"id":"1.170370564","rc":[{"trd":[[1.29,21524.61],[1.28,3398.42]],"ltp":1.29,"tv":24923.03,"id":8509691},{"atl":[[1.28,0],[1.29,1309.06]],"id":8509691}],"con":true,"img":false}]}
{"op":"mcm","clk":"1362324508","pt":1588439151908,"mc":[{"id":"1.170370564","rc":[{"atb":[[1.26,81.97]],"id":8509691}],"con":true,"img":false}]}
{"op":"mcm","clk":"1362324566","pt":1588439157005,"mc":[{"id":"1.170370564","rc":[{"atb":[[1.27,432.57]],"id":8509691}],"con":true,"img":false}]}
{"op":"mcm","clk":"1362324587","pt":1588439160016,"mc":[{"id":"1.170370564","rc":[{"atb":[[1.26,12]],"id":8509691}],"con":true,"img":false}]}
{"op":"mcm","clk":"1362324606","pt":1588439162210,"mc":[{"id":"1.170370564","rc":[{"atb":[[1.27,424.68]],"id":8509691}],"con":true,"img":false}]}
{"op":"mcm","clk":"1362324619","pt":1588439163593,"mc":[{"id":"1.170370564","rc":[{"atb":[[1.27,413.59]],"id":8509691}],"con":true,"img":false}]}
{"op":"mcm","clk":"1362324668","pt":1588439168401,"mc":[{"id":"1.170370564","rc":[{"atb":[[1.28,67.59]],"id":8509691}],"con":true,"img":false}]}
{"op":"mcm","clk":"1362324709","pt":1588439173244,"mc":[{"id":"1.170370564","rc":[{"atb":[[4.1,0]],"id":9630572}],"con":true,"img":false}]}
{"op":"mcm","clk":"1362324715","pt":1588439174520,"mc":[{"id":"1.170370564","rc":[{"atb":[[4.1,2.33]],"id":9630572}],"con":true,"img":false}]}
{"op":"mcm","clk":"1362324742","pt":1588439178141,"mc":[{"id":"1.170370564","rc":[{"trd":[[1.28,3403.57]],"ltp":1.28,"tv":3403.57,"id":8509691},{"atb":[[1.28,65.02]],"id":8509691}],"con":true,"img":false}]}
{"op":"mcm","clk":"1362324835","pt":1588439188951,"mc":[{"id":"1.170370564","rc":[{"trd":[[1.28,3492.22]],"ltp":1.28,"tv":3492.22,"id":8509691},{"atb":[[1.28,20.69]],"id":8509691}],"con":true,"img":false}]}
{"op":"mcm","clk":"1362324840","pt":1588439189664,"mc":[{"id":"1.170370564","rc":[{"trd":[[1.28,3533.61]],"ltp":1.28,"tv":3533.61,"id":8509691},{"atb":[[1.28,0]],"id":8509691},{"atl":[[1.28,23.63]],"id":8509691}],"con":true,"img":false}]}
{"op":"mcm","clk":"1362324867","pt":1588439191243,"mc":[{"id":"1.170370564","rc":[{"atb":[[1.27,479.82]],"id":8509691}],"con":true,"img":false}]}
{"op":"mcm","clk":"1362324872","pt":1588439192159,"mc":[{"id":"1.170370564","rc":[{"atb":[[1.27,524.15]],"id":8509691}],"con":true,"img":false}]}
{"op":"mcm","clk":"1362324875","pt":1588439192621,"mc":[{"id":"1.170370564","rc":[{"atb":[[1.27,568.48]],"id":8509691}],"con":true,"img":false}]}
{"op":"mcm","clk":"1362324950","pt":1588439199957,"mc":[{"id":"1.170370564","rc":[{"atb":[[4.5,10.49]],"id":9630572}],"con":true,"img":false}]}
{"op":"mcm","clk":"1362324988","pt":1588439205356,"mc":[{"id":"1.170370564","rc":[{"trd":[[1.27,1827.02]],"ltp":1.27,"tv":1827.02,"id":8509691},{"atb":[[1.27,564.18]],"id":8509691}],"con":true,"img":false}]}
{"op":"mcm","clk":"1362325026","pt":1588439208874,"mc":[{"id":"1.170370564","rc":[{"atb":[[1.27,241.26]],"id":8509691}],"con":true,"img":false}]}
{"op":"mcm","clk":"1362325151","pt":1588439218507,"mc":[{"id":"1.170370565","rc":[{"atb":[[6.4,10]],"id":11340557},{"atb":[[6.4,10]],"id":11340560},{"atb":[[1.82,63.78]],"id":11269555},{"atb":[[3.3,22.73]],"id":11269557}],"con":true,"img":false},{"id":"1.170370566","rc":[{"atb":[[2.74,30.05]],"id":9630572},{"atb":[[1.31,168.71]],"id":8509691}],"con":true,"img":false},{"id":"1.170370567","rc":[{"atb":[[2.88,27.81]],"id":9630572},{"atb":[[1.36,145.27]],"id":8509691}],"con":true,"img":false}]}
{"op":"mcm","clk":"1362325327","pt":1588439241148,"mc":[{"id":"1.170370565","marketDefinition":{"bspMarket":false,"turnInPlayEnabled":true,"persistenceEnabled":true,"marketBaseRate":5.0,"eventId":"29788457","eventTypeId":"2","numberOfWinners":1,"bettingType":"ODDS","marketType":"SET_BETTING","marketTime":"2020-05-02T17:30:00.000Z","suspendTime":"2020-05-02T17:30:00.000Z","bspReconciled":false,"complete":true,"inPlay":false,"crossMatching":true,"runnersVoidable":false,"numberOfActiveRunners":4,"betDelay":0,"status":"OPEN","runners":[{"status":"ACTIVE","sortPriority":1,"id":11269555,"name":"P Lorenzi 2-0"},{"status":"ACTIVE","sortPriority":2,"id":11269557,"name":"P Lorenzi 2-1"},{"status":"ACTIVE","sortPriority":3,"id":11340557,"name":"S Kirchheimer 2-0"},{"status":"ACTIVE","sortPriority":4,"id":11340560,"name":"S Kirchheimer 2-1"}],"regulators":["MR_INT"],"countryCode":"GB","discountAllowed":true,"timezone":"GMT","openDate":"2020-05-02T16:00:00.000Z","version":3237631482,"name":"Set Betting","eventName":"P Lorenzi v S Kirchheimer"},"rc":[],"con":true,"img":false}]}
{"op":"mcm","clk":"1362325328","pt":1588439241148,"mc":[{"id":"1.170370567","marketDefinition":{"bspMarket":false,"turnInPlayEnabled":true,"persistenceEnabled":true,"marketBaseRate":5.0,"eventId":"29788457","eventTypeId":"2","numberOfWinners":1,"bettingType":"ODDS","marketType":"SET_WINNER","marketTime":"2020-05-02T17:30:00.000Z","suspendTime":"2020-05-02T17:30:00.000Z","bspReconciled":false,"complete":true,"inPlay":false,"crossMatching":true,"runnersVoidable":false,"numberOfActiveRunners":2,"betDelay":0,"status":"OPEN","runners":[{"status":"ACTIVE","sortPriority":1,"id":8509691,"name":"P Lorenzi"},{"status":"ACTIVE","sortPriority":2,"id":9630572,"name":"S Kirchheimer"}],"regulators":["MR_INT"],"countryCode":"GB","discountAllowed":true,"timezone":"GMT","openDate":"2020-05-02T16:00:00.000Z","version":3237631486,"name":"Set 2 Winner","eventName":"P Lorenzi v S Kirchheimer"},"rc":[],"con":true,"img":false}]}
{"op":"mcm","clk":"1362325329","pt":1588439241148,"mc":[{"id":"1.170370564","marketDefinition":{"bspMarket":false,"turnInPlayEnabled":true,"persistenceEnabled":true,"marketBaseRate":5.0,"eventId":"29788457","eventTypeId":"2","numberOfWinners":1,"bettingType":"ODDS","marketType":"MATCH_ODDS","marketTime":"2020-05-02T17:30:00.000Z","suspendTime":"2020-05-02T17:30:00.000Z","bspReconciled":false,"complete":true,"inPlay":false,"crossMatching":true,"runnersVoidable":false,"numberOfActiveRunners":2,"betDelay":0,"status":"OPEN","runners":[{"status":"ACTIVE","sortPriority":1,"id":8509691,"name":"P Lorenzi"},{"status":"ACTIVE","sortPriority":2,"id":9630572,"name":"S Kirchheimer"}],"regulators":["MR_INT"],"countryCode":"GB","discountAllowed":true,"timezone":"GMT","openDate":"2020-05-02T16:00:00.000Z","version":3237631480,"name":"Match Odds","eventName":"P Lorenzi v S Kirchheimer"},"rc":[],"con":true,"img":false}]}
{"op":"mcm","clk":"1362325330","pt":1588439241148,"mc":[{"id":"1.170370566","marketDefinition":{"bspMarket":false,"turnInPlayEnabled":true,"persistenceEnabled":true,"marketBaseRate":5.0,"eventId":"29788457","eventTypeId":"2","numberOfWinners":1,"bettingType":"ODDS","marketType":"SET_WINNER","marketTime":"2020-05-02T17:30:00.000Z","suspendTime":"2020-05-02T17:30:00.000Z","bspReconciled":false,"complete":true,"inPlay":false,"crossMatching":true,"runnersVoidable":false,"numberOfActiveRunners":2,"betDelay":0,"status":"OPEN","runners":[{"status":"ACTIVE","sortPriority":1,"id":8509691,"name":"P Lorenzi"},{"status":"ACTIVE","sortPriority":2,"id":9630572,"name":"S Kirchheimer"}],"regulators":["MR_INT"],"countryCode":"GB","discountAllowed":true,"timezone":"GMT","openDate":"2020-05-02T16:00:00.000Z","version":3237631484,"name":"Set 1 Winner","eventName":"P Lorenzi v S Kirchheimer"},"rc":[],"con":true,"img":false}]}
{"op":"mcm","clk":"1362325347","pt":1588439244150,"mc":[{"id":"1.170370566","marketDefinition":{"bspMarket":false,"turnInPlayEnabled":true,"persistenceEnabled":true,"marketBaseRate":5.0,"eventId":"29788457","eventTypeId":"2","numberOfWinners":1,"bettingType":"ODDS","marketType":"SET_WINNER","marketTime":"2020-05-02T17:30:00.000Z","suspendTime":"2020-05-02T17:30:00.000Z","bspReconciled":false,"complete":true,"inPlay":false,"crossMatching":true,"runnersVoidable":false,"numberOfActiveRunners":2,"betDelay":0,"status":"OPEN","runners":[{"status":"ACTIVE","sortPriority":1,"id":8509691,"name":"P Lorenzi"},{"status":"ACTIVE","sortPriority":2,"id":9630572,"name":"S Kirchheimer"}],"regulators":["MR_INT"],"countryCode":"GB","discountAllowed":true,"timezone":"GMT","openDate":"2020-05-02T17:30:00.000Z","version":3237631484,"name":"Set 1 Winner","eventName":"P Lorenzi v S Kirchheimer"},"rc":[],"con":true,"img":false}]}
{"op":"mcm","clk":"1362325348","pt":1588439244150,"mc":[{"id":"1.170370567","marketDefinition":{"bspMarket":false,"turnInPlayEnabled":true,"persistenceEnabled":true,"marketBaseRate":5.0,"eventId":"29788457","eventTypeId":"2","numberOfWinners":1,"bettingType":"ODDS","marketType":"SET_WINNER","marketTime":"2020-05-02T17:30:00.000Z","suspendTime":"2020-05-02T17:30:00.000Z","bspReconciled":false,"complete":true,"inPlay":false,"crossMatching":true,"runnersVoidable":false,"numberOfActiveRunners":2,"betDelay":0,"status":"OPEN","runners":[{"status":"ACTIVE","sortPriority":1,"id":8509691,"name":"P Lorenzi"},{"status":"ACTIVE","sortPriority":2,"id":9630572,"name":"S Kirchheimer"}],"regulators":["MR_INT"],"countryCode":"GB","discountAllowed":true,"timezone":"GMT","openDate":"2020-05-02T17:30:00.000Z","version":3237631486,"name":"Set 2 Winner","eventName":"P Lorenzi v S Kirchheimer"},"rc":[],"con":true,"img":false}]}
{"op":"mcm","clk":"1362325349","pt":1588439244151,"mc":[{"id":"1.170370565","marketDefinition":{"bspMarket":false,"turnInPlayEnabled":true,"persistenceEnabled":true,"marketBaseRate":5.0,"eventId":"29788457","eventTypeId":"2","numberOfWinners":1,"bettingType":"ODDS","marketType":"SET_BETTING","marketTime":"2020-05-02T17:30:00.000Z","suspendTime":"2020-05-02T17:30:00.000Z","bspReconciled":false,"complete":true,"inPlay":false,"crossMatching":true,"runnersVoidable":false,"numberOfActiveRunners":4,"betDelay":0,"status":"OPEN","runners":[{"status":"ACTIVE","sortPriority":1,"id":11269555,"name":"P Lorenzi 2-0"},{"status":"ACTIVE","sortPriority":2,"id":11269557,"name":"P Lorenzi 2-1"},{"status":"ACTIVE","sortPriority":3,"id":11340557,"name":"S Kirchheimer 2-0"},{"status":"ACTIVE","sortPriority":4,"id":11340560,"name":"S Kirchheimer 2-1"}],"regulators":["MR_INT"],"countryCode":"GB","discountAllowed":true,"timezone":"GMT","openDate":"2020-05-02T17:30:00.000Z","version":3237631482,"name":"Set Betting","eventName":"P Lorenzi v S Kirchheimer"},"rc":[],"con":true,"img":false}]}
{"op":"mcm","clk":"1362325350","pt":1588439244151,"mc":[{"id":"1.170370564","marketDefinition":{"bspMarket":false,"turnInPlayEnabled":true,"persistenceEnabled":true,"marketBaseRate":5.0,"eventId":"29788457","eventTypeId":"2","numberOfWinners":1,"bettingType":"ODDS","marketType":"MATCH_ODDS","marketTime":"2020-05-02T17:30:00.000Z","suspendTime":"2020-05-02T17:30:00.000Z","bspReconciled":false,"complete":true,"inPlay":false,"crossMatching":true,"runnersVoidable":false,"numberOfActiveRunners":2,"betDelay":0,"status":"OPEN","runners":[{"status":"ACTIVE","sortPriority":1,"id":8509691,"name":"P Lorenzi"},{"status":"ACTIVE","sortPriority":2,"id":9630572,"name":"S Kirchheimer"}],"regulators":["MR_INT"],"countryCode":"GB","discountAllowed":true,"timezone":"GMT","openDate":"2020-05-02T17:30:00.000Z","version":3237631480,"name":"Match Odds","eventName":"P Lorenzi v S Kirchheimer"},"rc":[],"con":true,"img":false}]}
{"op":"mcm","clk":"1362325695","pt":1588439282596,"mc":[{"id":"1.170370564","rc":[{"atb":[[1.26,329.46]],"id":8509691}],"con":true,"img":false}]}
{"op":"mcm","clk":"1362325700","pt":1588439283978,"mc":[{"id":"1.170370564","rc":[{"atl":[[1.28,336.13]],"id":8509691}],"con":true,"img":false}]}
{"op":"mcm","clk":"1362325753","pt":1588439290603,"mc":[{"id":"1.170370564","rc":[{"atb":[[4.1,0]],"id":9630572}],"con":true,"img":false}]}
{"op":"mcm","clk":"1362325783","pt":1588439294012,"mc":[{"id":"1.170370564","rc":[{"atb":[[4.1,2.33]],"id":9630572}],"con":true,"img":false}]}
{"op":"mcm","clk":"1362325794","pt":1588439295233,"mc":[{"id":"1.170370564","rc":[{"atb":[[4.5,99.37]],"id":9630572}],"con":true,"img":false}]}
{"op":"mcm","clk":"1362325795","pt":1588439296100,"mc":[{"id":"1.170370564","rc":[{"atl":[[5,80]],"id":9630572}],"con":true,"img":false}]}
{"op":"mcm","clk":"1362325832","pt":1588439299919,"mc":[{"id":"1.170370564","rc":[{"atl":[[5,0]],"id":9630572}],"con":true,"img":false}]}
{"op":"mcm","clk":"1362325985","pt":1588439317431,"mc":[{"id":"1.170370564","rc":[{"atl":[[4.8,100.82]],"id":9630572}],"con":true,"img":false}]}
{"op":"mcm","clk":"1362326118","pt":1588439329970,"mc":[{"id":"1.170370564","rc":[{"atb":[[1.23,131.79]],"id":8509691}],"con":true,"img":false}]}
{"op":"mcm","clk":"1362326200","pt":1588439339962,"mc":[{"id":"1.170370564","rc":[{"atb":[[3.8,13.12]],"id":9630572}],"con":true,"img":false}]}
{"op":"mcm","clk":"1362326697","pt":1588439389715,"mc":[{"id":"1.170370564","rc":[{"atb":[[1.26,317.46]],"id":8509691}],"con":true,"img":false}]}
{"op":"mcm","clk":"1362326847","pt":1588439413189,"mc":[{"id":"1.170370564","rc":[{"atb":[[4.1,0]],"id":9630572}],"con":true,"img":false}]}
{"op":"mcm","clk":"1362326862","pt":1588439414463,"mc":[{"id":"1.170370564","rc":[{"atb":[[4.1,2.33]],"id":9630572}],"con":true,"img":false}]}
{"op":"mcm","clk":"1362327521","pt":1588439501841,"mc":[{"id":"1.170370564","rc":[{"trd":[[1.28,3560.2]],"ltp":1.28,"tv":3560.2,"id":8509691},{"atl":[[1.28,322.83]],"id":8509691}],"con":true,"img":false}]}
{"op":"mcm","clk":"1362327726","pt":1588439533012,"mc":[{"id":"1.170370564","rc":[{"atb":[[4.1,0]],"id":9630572}],"con":true,"img":false}]}
{"op":"mcm","clk":"1362327742","pt":1588439534287,"mc":[{"id":"1.170370564","rc":[{"atb":[[4.1,2.33]],"id":9630572}],"con":true,"img":false}]}
{"op":"mcm","clk":"1362327745","pt":1588439534693,"mc":[{"id":"1.170370564","rc":[{"atb":[[1.26,335.19]],"id":8509691}],"con":true,"img":false}]}
{"op":"mcm","clk":"1362327749","pt":1588439535506,"mc":[{"id":"1.170370565","rc":[{"atl":[[4,3.19]],"id":11269555}],"con":true,"img":false}]}
{"op":"mcm","clk":"1362327752","pt":1588439536273,"mc":[{"id":"1.170370564","rc":[{"atb":[[1.26,352.92]],"id":8509691}],"con":true,"img":false}]}
{"op":"mcm","clk":"1362327759","pt":1588439537088,"mc":[{"id":"1.170370564","rc":[{"atb":[[1.26,370.65]],"id":8509691}],"con":true,"img":false}]}
{"op":"mcm","clk":"1362327771","pt":1588439538819,"mc":[{"id":"1.170370564","rc":[{"atb":[[1.26,388.38]],"id":8509691}],"con":true,"img":false}]}
{"op":"mcm","clk":"1362327795","pt":1588439542898,"mc":[{"id":"1.170370565","rc":[{"atl":[[4,3.51]],"id":11269555}],"con":true,"img":false}]}
{"op":"mcm","clk":"1362327832","pt":1588439547997,"mc":[{"id":"1.170370565","rc":[{"atl":[[4,0]],"id":11269555}],"con":true,"img":false}]}
{"op":"mcm","clk":"1362327835","pt":1588439548099,"mc":[{"id":"1.170370565","rc":[{"trd":[[1.82,0.63]],"ltp":1.82,"tv":0.63,"id":11269555},{"atb":[[1.82,63.46]],"id":11269555}],"con":true,"img":false}]}
{"op":"mcm","clk":"1362327848","pt":1588439549728,"mc":[{"id":"1.170370565","rc":[{"atb":[[1.82,127.24]],"id":11269555}],"con":true,"img":false}]}
{"op":"mcm","clk":"1362327849","pt":1588439549830,"mc":[{"id":"1.170370565","rc":[{"atb":[[1.82,63.78]],"id":11269555}],"con":true,"img":false}]}
{"op":"mcm","clk":"1362327918","pt":1588439558036,"mc":[{"id":"1.170370564","rc":[{"trd":[[1.28,3561.38]],"ltp":1.28,"tv":3561.38,"id":8509691},{"atl":[[1.28,322.25]],"id":8509691}],"con":true,"img":false}]}
{"op":"mcm","clk":"1362328006","pt":1588439568449,"mc":[{"id":"1.170370564","rc":[{"atl":[[4.7,25]],"id":9630572}],"con":true,"img":false}]}
{"op":"mcm","clk":"1362328033","pt":1588439573037,"mc":[{"id":"1.170370564","rc":[{"atl":[[1.28,325.45]],"id":8509691}],"con":true,"img":false}]}
{"op":"mcm","clk":"1362328112","pt":1588439583817,"mc":[{"id":"1.170370566","rc":[{"atl":[[4.2,10]],"id":9630572}],"con":true,"img":false}]}
{"op":"mcm","clk":"1362328172","pt":1588439592341,"mc":[{"id":"1.170370564","rc":[{"atb":[[4.3,8.05]],"id":9630572},{"atb":[[1.23,220.45]],"id":8509691}],"con":true,"img":false}]}
{"op":"mcm","clk":"1362328289","pt":1588439609985,"mc":[{"id":"1.170370564","rc":[{"atb":[[1.27,284.99]],"id":8509691}],"con":true,"img":false}]}
{"op":"mcm","clk":"1362328488","pt":1588439634312,"mc":[{"id":"1.170370564","rc":[{"atb":[[1.26,317.46]],"id":8509691}],"con":true,"img":false}]}
{"op":"mcm","clk":"1362328593","pt":1588439648111,"mc":[{"id":"1.170370564","rc":[{"atb":[[1.26,335.19]],"id":8509691}],"con":true,"img":false}]}
{"op":"mcm","clk":"1362328598","pt":1588439648519,"mc":[{"id":"1.170370564","rc":[{"atb":[[1.26,352.92]],"id":8509691}],"con":true,"img":false}]}
{"op":"mcm","clk":"1362328606","pt":1588439648877,"mc":[{"id":"1.170370564","rc":[{"atb":[[1.26,370.65]],"id":8509691}],"con":true,"img":false}]}
{"op":"mcm","clk":"1362328612","pt":1588439650102,"mc":[{"id":"1.170370564","rc":[{"atb":[[1.26,388.38]],"id":8509691}],"con":true,"img":false}]}
{"op":"mcm","clk":"1362328618","pt":1588439651025,"mc":[{"id":"1.170370564","rc":[{"atb":[[1.26,406.11]],"id":8509691}],"con":true,"img":false}]}
{"op":"mcm","clk":"1362329395","pt":1588439660506,"mc":[{"id":"1.170370564","rc":[{"atb":[[4.1,0]],"id":9630572}],"con":true,"img":false}]}
{"op":"mcm","clk":"1362329406","pt":1588439661831,"mc":[{"id":"1.170370564","rc":[{"atb":[[4.1,2.33]],"id":9630572}],"con":true,"img":false}]}
{"op":"mcm","clk":"1362329515","pt":1588439678608,"mc":[{"id":"1.170370564","rc":[{"trd":[[4.7,162.42]],"ltp":4.7,"tv":162.42,"id":9630572},{"atl":[[4.7,0]],"id":9630572},{"trd":[[1.27,2489.54]],"ltp":1.27,"tv":2489.54,"id":8509691},{"atb":[[1.27,0]],"id":8509691},{"atl":[[1.27,1263.02]],"id":8509691}],"con":true,"img":false}]}
{"op":"mcm","clk":"1362329520","pt":1588439679322,"mc":[{"id":"1.170370564","rc":[{"atb":[[4.5,106.97]],"id":9630572},{"atb":[[1.22,88.65]],"id":8509691}],"con":true,"img":false}]}
{"op":"mcm","clk":"1362329524","pt":1588439679424,"mc":[{"id":"1.170370564","rc":[{"atb":[[1.23,131.79]],"id":8509691}],"con":true,"img":false}]}
{"op":"mcm","clk":"1362329544","pt":1588439681311,"mc":[{"id":"1.170370564","rc":[{"atb":[[3.5,22.3]],"id":9630572},{"atb":[[1.25,1504.11]],"id":8509691}],"con":true,"img":false}]}
{"op":"mcm","clk":"1362329563","pt":1588439684523,"mc":[{"id":"1.170370564","rc":[{"atl":[[1.27,0]],"id":8509691}],"con":true,"img":false}]}
{"op":"mcm","clk":"1362329566","pt":1588439685339,"mc":[{"id":"1.170370564","rc":[{"atb":[[4.5,99.37]],"id":9630572},{"atb":[[1.23,220.45]],"id":8509691}],"con":true,"img":false}]}
{"op":"mcm","clk":"1362329616","pt":1588439693752,"mc":[{"id":"1.170370564","rc":[{"atl":[[1.28,369.77]],"id":8509691}],"con":true,"img":false}]}
{"op":"mcm","clk":"1362329619","pt":1588439694211,"mc":[{"id":"1.170370564","rc":[{"atl":[[1.28,414.1]],"id":8509691}],"con":true,"img":false}]}
{"op":"mcm","clk":"1362329633","pt":1588439696349,"mc":[{"id":"1.170370564","rc":[{"atb":[[1.27,3.19]],"id":8509691}],"con":true,"img":false}]}
{"op":"mcm","clk":"1362329639","pt":1588439697162,"mc":[{"id":"1.170370564","rc":[{"atb":[[4.5,10.49]],"id":9630572},{"atl":[[4.8,17.49]],"id":9630572},{"atb":[[1.26,88.65]],"id":8509691},{"atl":[[1.28,101.6]],"id":8509691}],"con":true,"img":false}]}
{"op":"mcm","clk":"1362329647","pt":1588439697927,"mc":[{"id":"1.170370564","rc":[{"trd":[[4.8,101.87]],"ltp":4.8,"tv":101.87,"id":9630572},{"atl":[[4.8,0]],"id":9630572},{"trd":[[1.26,413.68],[1.27,2495.94]],"ltp":1.26,"tv":2909.62,"id":8509691},{"atb":[[1.26,0],[1.27,0]],"id":8509691},{"atl":[[1.26,1101.55]],"id":8509691}],"con":true,"img":false}]}
{"op":"mcm","clk":"1362329653","pt":1588439698335,"mc":[{"id":"1.170370564","rc":[{"atb":[[4.6,7.38]],"id":9630572},{"atb":[[1.21,88.65],[1.23,131.79],[1.22,0]],"id":8509691}],"con":true,"img":false}]}
{"op":"mcm","clk":"1362329656","pt":1588439698436,"mc":[{"id":"1.170370564","rc":[{"atl":[[1.27,35.17]],"id":8509691}],"con":true,"img":false}]}
{"op":"mcm","clk":"1362329660","pt":1588439698741,"mc":[{"id":"1.170370564","rc":[{"atl":[[1.27,87.94]],"id":8509691}],"con":true,"img":false}]}
{"op":"mcm","clk":"1362329683","pt":1588439702164,"mc":[{"id":"1.170370564","rc":[{"atl":[[1.26,0]],"id":8509691}],"con":true,"img":false}]}
{"op":"mcm","clk":"1362329691","pt":1588439703349,"mc":[{"id":"1.170370564","rc":[{"atb":[[4.5,18.09],[4.6,0]],"id":9630572}],"con":true,"img":false}]}
{"op":"mcm","clk":"1362329701","pt":1588439705346,"mc":[{"id":"1.170370564","rc":[{"atl":[[1.28,104.8]],"id":8509691}],"con":true,"img":false}]}
{"op":"mcm","clk":"1362329740","pt":1588439709171,"mc":[{"id":"1.170370564","rc":[{"atl":[[1.27,227.89]],"id":8509691}],"con":true,"img":false}]}
{"op":"mcm","clk":"1362329808","pt":1588439714236,"mc":[{"id":"1.170370566","rc":[{"trd":[[1.31,7.99]],"ltp":1.31,"tv":7.99,"id":8509691},{"atb":[[1.31,164.71]],"id":8509691}],"con":true,"img":false}]}
{"op":"mcm","clk":"1362329813","pt":1588439715255,"mc":[{"id":"1.170370566","rc":[{"atb":[[1.31,333.42]],"id":8509691}],"con":true,"img":false}]}
{"op":"mcm","clk":"1362329814","pt":1588439715357,"mc":[{"id":"1.170370566","rc":[{"atb":[[1.31,168.71]],"id":8509691}],"con":true,"img":false}]}
{"op":"mcm","clk":"1362329816","pt":1588439715967,"mc":[{"id":"1.170370564","rc":[{"atl":[[4.9,17.49]],"id":9630572}],"con":true,"img":false}]}
{"op":"mcm","clk":"1362330168","pt":1588439770699,"mc":[{"id":"1.170370564","rc":[{"trd":[[1.27,2501.19]],"ltp":1.27,"tv":2501.19,"id":8509691},{"atl":[[1.27,225.27]],"id":8509691}],"con":true,"img":false}]}
{"op":"mcm","clk":"1362330182","pt":1588439772231,"mc":[{"id":"1.170370564","rc":[{"atb":[[4.1,0]],"id":9630572}],"con":true,"img":false}]}
{"op":"mcm","clk":"1362330200","pt":1588439774526,"mc":[{"id":"1.170370564","rc":[{"atb":[[4.1,2.33]],"id":9630572}],"con":true,"img":false}]}
{"op":"mcm","clk":"1362330332","pt":1588439792936,"mc":[{"id":"1.170370565","rc":[{"atb":[[1.71,0]],"id":11269555}],"con":true,"img":false}]}
{"op":"mcm","clk":"1362330334","pt":1588439793038,"mc":[{"id":"1.170370565","rc":[{"atb":[[3.35,0]],"id":11269557}],"con":true,"img":false}]}
{"op":"mcm","clk":"1362330338","pt":1588439793242,"mc":[{"id":"1.170370565","rc":[{"atb":[[6.6,0]],"id":11340557}],"con":true,"img":false}]}
{"op":"mcm","clk":"1362330341","pt":1588439793447,"mc":[{"id":"1.170370565","rc":[{"atb":[[6.6,0]],"id":11340560}],"con":true,"img":false}]}
{"op":"mcm","clk":"1362330346","pt":1588439793957,"mc":[{"id":"1.170370565","rc":[{"atb":[[6.6,4]],"id":11340557},{"atb":[[6.6,4]],"id":11340560},{"atb":[[1.67,9]],"id":11269555},{"atb":[[3.35,5]],"id":11269557}],"con":true,"img":false}]}
{"op":"mcm","clk":"1362330752","pt":1588439845101,"mc":[{"id":"1.170370564","rc":[{"trd":[[1.25,2232.41]],"ltp":1.25,"tv":2232.41,"id":8509691},{"atb":[[1.25,415.74]],"id":8509691}],"con":true,"img":false}]}
{"op":"mcm","clk":"1362330852","pt":1588439861991,"mc":[{"id":"1.170370564","rc":[{"trd":[[1.25,2264.86]],"ltp":1.25,"tv":2264.86,"id":8509691},{"atb":[[1.25,399.52]],"id":8509691}],"con":true,"img":false}]}
{"op":"mcm","clk":"1362331067","pt":1588439898519,"mc":[{"id":"1.170370564","rc":[{"atb":[[4.1,0]],"id":9630572}],"con":true,"img":false}]}
{"op":"mcm","clk":"1362331079","pt":1588439901214,"mc":[{"id":"1.170370564","rc":[{"atb":[[4.1,2.33]],"id":9630572}],"con":true,"img":false}]}
{"op":"mcm","clk":"1362331487","pt":1588439971187,"mc":[{"id":"1.170370565","rc":[{"trd":[[1.82,33.81]],"ltp":1.82,"tv":33.81,"id":11269555},{"atb":[[1.82,47.19]],"id":11269555}],"con":true,"img":false}]}
{"op":"mcm","clk":"1362331489","pt":1588439971288,"mc":[{"id":"1.170370565","rc":[{"atb":[[1.82,110.97]],"id":11269555}],"con":true,"img":false}]}
{"op":"mcm","clk":"1362331490","pt":1588439971390,"mc":[{"id":"1.170370565","rc":[{"atb":[[1.82,63.78]],"id":11269555}],"con":true,"img":false}]}
{"op":"mcm","clk":"1362331795","pt":1588440012006,"mc":[{"id":"1.170370564","rc":[{"atb":[[4.1,0]],"id":9630572}],"con":true,"img":false}]}
{"op":"mcm","clk":"1362331821","pt":1588440015831,"mc":[{"id":"1.170370564","rc":[{"atb":[[4.1,2.33]],"id":9630572}],"con":true,"img":false}]}
{"op":"mcm","clk":"1362331934","pt":1588440035407,"mc":[{"id":"1.170370564","rc":[{"atb":[[4.5,20.19],[4.4,2.01]],"id":9630572},{"atl":[[5.1,2.05],[5.2,2.03]],"id":9630572},{"atb":[[1.23,133.81],[1.22,2.01]],"id":8509691},{"atl":[[1.3,2.05],[1.29,1311.06]],"id":8509691}],"con":true,"img":false}]}
{"op":"mcm","clk":"1362332152","pt":1588440074524,"mc":[{"id":"1.170370564","rc":[{"atl":[[1.26,74.46]],"id":8509691}],"con":true,"img":false}]}
{"op":"mcm","clk":"1362332153","pt":1588440074626,"mc":[{"id":"1.170370564","rc":[{"atl":[[1.28,106.82]],"id":8509691}],"con":true,"img":false}]}
{"op":"mcm","clk":"1362332156","pt":1588440074830,"mc":[{"id":"1.170370564","rc":[{"atl":[[5.2,0]],"id":9630572},{"atl":[[1.3,0]],"id":8509691}],"con":true,"img":false}]}
{"op":"mcm","clk":"1362332157","pt":1588440074932,"mc":[{"id":"1.170370564","rc":[{"atb":[[4.4,0]],"id":9630572},{"atb":[[1.22,0]],"id":8509691}],"con":true,"img":false}]}
{"op":"mcm","clk":"1362332158","pt":1588440075138,"mc":[{"id":"1.170370564","rc":[{"atl":[[5.2,2.03]],"id":9630572},{"atl":[[1.29,1309.06]],"id":8509691}],"con":true,"img":false}]}
{"op":"mcm","clk":"1362332160","pt":1588440075240,"mc":[{"id":"1.170370564","rc":[{"atb":[[4.6,2.04]],"id":9630572},{"atb":[[1.22,2.02]],"id":8509691}],"con":true,"img":false}]}
{"op":"mcm","clk":"1362332161","pt":1588440075340,"mc":[{"id":"1.170370564","rc":[{"atl":[[1.29,1311.08]],"id":8509691}],"con":true,"img":false}]}
{"op":"mcm","clk":"1362332162","pt":1588440075443,"mc":[{"id":"1.170370564","rc":[{"atb":[[4.6,9.42]],"id":9630572}],"con":true,"img":false}]}
{"op":"mcm","clk":"1362332163","pt":1588440075544,"mc":[{"id":"1.170370564","rc":[{"atb":[[4.5,18.09]],"id":9630572}],"con":true,"img":false}]}
{"op":"mcm","clk":"1362332166","pt":1588440075749,"mc":[{"id":"1.170370564","rc":[{"atb":[[4.5,20.19]],"id":9630572}],"con":true,"img":false}]}
{"op":"mcm","clk":"1362332185","pt":1588440079163,"mc":[{"id":"1.170370564","rc":[{"atl":[[1.31,0]],"id":8509691}],"con":true,"img":false}]}
{"op":"mcm","clk":"1362332191","pt":1588440080235,"mc":[{"id":"1.170370564","rc":[{"atb":[[1.22,4.02]],"id":8509691},{"atl":[[1.27,85.31]],"id":8509691}],"con":true,"img":false}]}
{"op":"mcm","clk":"1362332397","pt":1588440111355,"mc":[{"id":"1.170370564","rc":[{"trd":[[1.25,2268.86]],"ltp":1.25,"tv":2268.86,"id":8509691},{"atb":[[1.25,397.51]],"id":8509691}],"con":true,"img":false}]}
{"op":"mcm","clk":"1362332399","pt":1588440111660,"mc":[{"id":"1.170370564","rc":[{"atb":[[4.5,18.09]],"id":9630572},{"atl":[[5.2,0]],"id":9630572},{"atb":[[1.22,2]],"id":8509691},{"atl":[[1.29,1309.06]],"id":8509691}],"con":true,"img":false}]}
{"op":"mcm","clk":"1362332402","pt":1588440111862,"mc":[{"id":"1.170370564","rc":[{"atb":[[4.5,20.19]],"id":9630572},{"atl":[[5.2,2.03]],"id":9630572},{"atb":[[1.22,4.02]],"id":8509691},{"atl":[[1.29,1311.08]],"id":8509691}],"con":true,"img":false}]}
{"op":"mcm","clk":"1362332433","pt":1588440117264,"mc":[{"id":"1.170370565","rc":[{"atb":[[1.75,0]],"id":11269555}],"con":true,"img":false}]}
{"op":"mcm","clk":"1362332438","pt":1588440117467,"mc":[{"id":"1.170370565","rc":[{"trd":[[1.9,35.39]],"ltp":1.9,"tv":35.39,"id":11269555},{"atl":[[1.9,13.33]],"id":11269555}],"con":true,"img":false}]}
{"op":"mcm","clk":"1362332496","pt":1588440127269,"mc":[{"id":"1.170370566","rc":[{"atb":[[1.14,8.16]],"id":8509691},{"atl":[[2.3,2.06]],"id":8509691}],"con":true,"img":false}]}
{"op":"mcm","clk":"1362332500","pt":1588440127576,"mc":[{"id":"1.170370566","rc":[{"atb":[[1.01,90.65]],"id":9630572}],"con":true,"img":false}]}
{"op":"mcm","clk":"1362332501","pt":1588440127881,"mc":[{"id":"1.170370566","rc":[{"atb":[[1.01,89.85]],"id":9630572},{"atl":[[1000,2]],"id":9630572}],"con":true,"img":false}]}
{"op":"mcm","clk":"1362332504","pt":1588440128187,"mc":[{"id":"1.170370566","rc":[{"atb":[[1.01,88.65]],"id":9630572},{"atl":[[1000,0.97]],"id":9630572}],"con":true,"img":false}]}
{"op":"mcm","clk":"1362332505","pt":1588440128289,"mc":[{"id":"1.170370566","rc":[{"atb":[[2.16,1.2]],"id":9630572}],"con":true,"img":false}]}
{"op":"mcm","clk":"1362332506","pt":1588440128494,"mc":[{"id":"1.170370566","rc":[{"atl":[[1000,0]],"id":9630572}],"con":true,"img":false}]}
{"op":"mcm","clk":"1362332507","pt":1588440128594,"mc":[{"id":"1.170370566","rc":[{"atl":[[6.6,0.97]],"id":9630572}],"con":true,"img":false}]}
{"op":"mcm","clk":"1362332518","pt":1588440130578,"mc":[{"id":"1.170370564","rc":[{"atb":[[4.1,0]],"id":9630572}],"con":true,"img":false}]}
{"op":"mcm","clk":"1362332520","pt":1588440130884,"mc":[{"id":"1.170370564","rc":[{"atb":[[4.5,18.09]],"id":9630572},{"atl":[[5.2,0]],"id":9630572},{"atb":[[1.22,2]],"id":8509691},{"atl":[[1.29,1309.06]],"id":8509691}],"con":true,"img":false}]}
{"op":"mcm","clk":"1362332522","pt":1588440131089,"mc":[{"id":"1.170370564","rc":[{"atb":[[4.5,20.19]],"id":9630572},{"atl":[[5.2,2.03]],"id":9630572},{"atb":[[1.22,4.02]],"id":8509691},{"atl":[[1.29,1311.25]],"id":8509691}],"con":true,"img":false}]}
{"op":"mcm","clk":"1362332539","pt":1588440132975,"mc":[{"id":"1.170370564","rc":[{"atb":[[4.1,2.33]],"id":9630572}],"con":true,"img":false}]}
{"op":"mcm","clk":"1362332789","pt":1588440175534,"mc":[{"id":"1.170370564","rc":[{"atl":[[1.26,74.82]],"id":8509691}],"con":true,"img":false}]}
{"op":"mcm","clk":"1362332790","pt":1588440175840,"mc":[{"id":"1.170370564","rc":[{"atb":[[4.5,18.09]],"id":9630572},{"atl":[[5.2,0]],"id":9630572},{"atb":[[1.22,2]],"id":8509691},{"atl":[[1.29,1309.06]],"id":8509691}],"con":true,"img":false}]}
{"op":"mcm","clk":"1362332794","pt":1588440176044,"mc":[{"id":"1.170370564","rc":[{"atb":[[4.5,20.19]],"id":9630572},{"atl":[[5.2,2.03]],"id":9630572},{"atb":[[1.22,4.02]],"id":8509691},{"atl":[[1.29,1311.25]],"id":8509691}],"con":true,"img":false}]}
{"op":"mcm","clk":"1362332833","pt":1588440183235,"mc":[{"id":"1.170370564","rc":[{"atl":[[1.26,74.46]],"id":8509691}],"con":true,"img":false}]}
{"op":"mcm","clk":"1362332836","pt":1588440183542,"mc":[{"id":"1.170370564","rc":[{"atb":[[4.5,18.09]],"id":9630572},{"atl":[[5.2,0]],"id":9630572},{"atb":[[1.22,2]],"id":8509691},{"atl":[[1.29,1309.06]],"id":8509691}],"con":true,"img":false}]}
{"op":"mcm","clk":"1362332837","pt":1588440183747,"mc":[{"id":"1.170370564","rc":[{"atb":[[4.5,20.19]],"id":9630572},{"atl":[[5.2,2.03]],"id":9630572},{"atb":[[1.22,4.02]],"id":8509691},{"atl":[[1.29,1311.25]],"id":8509691}],"con":true,"img":false}]}
{"op":"mcm","clk":"1362333188","pt":1588440250814,"mc":[{"id":"1.170370564","rc":[{"atb":[[4.1,0]],"id":9630572}],"con":true,"img":false}]}
{"op":"mcm","clk":"1362333190","pt":1588440251068,"mc":[{"id":"1.170370564","rc":[{"atb":[[4.5,18.09]],"id":9630572},{"atl":[[5.2,0]],"id":9630572},{"atb":[[1.22,2]],"id":8509691},{"atl":[[1.29,1309.06]],"id":8509691}],"con":true,"img":false}]}
{"op":"mcm","clk":"1362333191","pt":1588440251272,"mc":[{"id":"1.170370564","rc":[{"atb":[[4.5,20.19]],"id":9630572},{"atl":[[5.2,2.03]],"id":9630572},{"atb":[[1.22,4.02]],"id":8509691},{"atl":[[1.29,1311.25]],"id":8509691}],"con":true,"img":false}]}
{"op":"mcm","clk":"1362333202","pt":1588440253005,"mc":[{"id":"1.170370564","rc":[{"atb":[[4.1,2.33]],"id":9630572}],"con":true,"img":false}]}
{"op":"mcm","clk":"1362333225","pt":1588440256986,"mc":[{"id":"1.170370564","rc":[{"trd":[[1.25,2272.53]],"ltp":1.25,"tv":2272.53,"id":8509691},{"atb":[[1.25,395.68]],"id":8509691}],"con":true,"img":false}]}
{"op":"mcm","clk":"1362333308","pt":1588440273716,"mc":[{"id":"1.170370564","rc":[{"trd":[[1.26,413.79]],"ltp":1.26,"tv":413.79,"id":8509691},{"atl":[[1.26,74.41]],"id":8509691}],"con":true,"img":false}]}
{"op":"mcm","clk":"1362333312","pt":1588440274021,"mc":[{"id":"1.170370564","rc":[{"atb":[[4.5,18.09]],"id":9630572},{"atl":[[5.2,0]],"id":9630572},{"atb":[[1.22,2]],"id":8509691},{"atl":[[1.29,1309.06]],"id":8509691}],"con":true,"img":false}]}
{"op":"mcm","clk":"1362333314","pt":1588440274225,"mc":[{"id":"1.170370564","rc":[{"atb":[[4.5,20.19]],"id":9630572},{"atl":[[5.2,2.03]],"id":9630572},{"atb":[[1.22,4.02]],"id":8509691},{"atl":[[1.29,1311.25]],"id":8509691}],"con":true,"img":false}]}
{"op":"mcm","clk":"1362333454","pt":1588440301040,"mc":[{"id":"1.170370564","rc":[{"atl":[[1000,2.62]],"id":8509691}],"con":true,"img":false}]}
{"op":"mcm","clk":"1362333456","pt":1588440301348,"mc":[{"id":"1.170370564","rc":[{"atb":[[4.5,18.09]],"id":9630572},{"atl":[[5.2,0]],"id":9630572},{"atl":[[1.29,1309.06]],"id":8509691}],"con":true,"img":false}]}
{"op":"mcm","clk":"1362333458","pt":1588440301402,"mc":[{"id":"1.170370564","rc":[{"atb":[[1.22,2]],"id":8509691}],"con":true,"img":false}]}
{"op":"mcm","clk":"1362333459","pt":1588440301608,"mc":[{"id":"1.170370564","rc":[{"atb":[[4.5,20.09]],"id":9630572},{"atl":[[5.2,2.03]],"id":9630572},{"atb":[[1.22,4.01]],"id":8509691},{"atl":[[1.29,1311.08]],"id":8509691}],"con":true,"img":false}]}
{"op":"mcm","clk":"1362333461","pt":1588440301914,"mc":[{"id":"1.170370564","rc":[{"atl":[[1000,0.04]],"id":8509691}],"con":true,"img":false}]}
{"op":"mcm","clk":"1362333466","pt":1588440302832,"mc":[{"id":"1.170370564","rc":[{"atl":[[1000,0]],"id":8509691}],"con":true,"img":false}]}
{"op":"mcm","clk":"1362333467","pt":1588440302935,"mc":[{"id":"1.170370564","rc":[{"trd":[[1.25,2272.62]],"ltp":1.25,"tv":2272.62,"id":8509691},{"atb":[[1.25,395.63]],"id":8509691}],"con":true,"img":false}]}
{"op":"mcm","clk":"1362333498","pt":1588440307129,"mc":[{"id":"1.170370564","rc":[{"atb":[[4.5,9.59]],"id":9630572}],"con":true,"img":false}]}
{"op":"mcm","clk":"1362333602","pt":1588440324465,"mc":[{"id":"1.170370564","rc":[{"atb":[[1.25,398.83]],"id":8509691}],"con":true,"img":false}]}
{"op":"mcm","clk":"1362333604","pt":1588440324766,"mc":[{"id":"1.170370564","rc":[{"atb":[[4.5,7.59]],"id":9630572},{"atl":[[5.2,0]],"id":9630572},{"atb":[[1.22,2]],"id":8509691},{"atl":[[1.29,1309.06]],"id":8509691}],"con":true,"img":false}]}
{"op":"mcm","clk":"1362333606","pt":1588440324922,"mc":[{"id":"1.170370564","rc":[{"atb":[[4.5,9.69]],"id":9630572},{"atl":[[5.2,2.03]],"id":9630572},{"atb":[[1.22,4.02]],"id":8509691},{"atl":[[1.29,1311.08]],"id":8509691}],"con":true,"img":false}]}
{"op":"mcm","clk":"1362333674","pt":1588440336739,"mc":[{"id":"1.170370564","rc":[{"atb":[[1.25,418.83]],"id":8509691}],"con":true,"img":false}]}
{"op":"mcm","clk":"1362333680","pt":1588440337047,"mc":[{"id":"1.170370564","rc":[{"atb":[[4.5,7.59]],"id":9630572},{"atl":[[5.2,0]],"id":9630572},{"atb":[[1.22,2]],"id":8509691},{"atl":[[1.29,1309.06]],"id":8509691}],"con":true,"img":false}]}
{"op":"mcm","clk":"1362333681","pt":1588440337252,"mc":[{"id":"1.170370564","rc":[{"atb":[[4.5,9.69]],"id":9630572},{"atl":[[5.2,2.03]],"id":9630572},{"atb":[[1.22,4.02]],"id":8509691},{"atl":[[1.29,1311.08]],"id":8509691}],"con":true,"img":false}]}
{"op":"mcm","clk":"1362333712","pt":1588440341835,"mc":[{"id":"1.170370564","rc":[{"atb":[[1.25,398.83]],"id":8509691}],"con":true,"img":false}]}
{"op":"mcm","clk":"1362333751","pt":1588440349041,"mc":[{"id":"1.170370564","rc":[{"trd":[[1.26,422.26]],"ltp":1.26,"tv":422.26,"id":8509691},{"atl":[[1.26,70.17]],"id":8509691}],"con":true,"img":false}]}
{"op":"mcm","clk":"1362333754","pt":1588440349348,"mc":[{"id":"1.170370564","rc":[{"atb":[[4.5,7.59]],"id":9630572},{"atl":[[5.2,0]],"id":9630572},{"atb":[[1.22,2]],"id":8509691},{"atl":[[1.29,1309.06]],"id":8509691}],"con":true,"img":false}]}
{"op":"mcm","clk":"1362333756","pt":1588440349552,"mc":[{"id":"1.170370564","rc":[{"atb":[[4.5,9.69]],"id":9630572},{"atl":[[5.2,2.03]],"id":9630572},{"atb":[[1.22,4.02]],"id":8509691},{"atl":[[1.29,1311.08]],"id":8509691}],"con":true,"img":false}]}
{"op":"mcm","clk":"1362333864","pt":1588440369762,"mc":[{"id":"1.170370564","rc":[{"atb":[[4.1,0]],"id":9630572}],"con":true,"img":false}]}
{"op":"mcm","clk":"1362333867","pt":1588440370067,"mc":[{"id":"1.170370564","rc":[{"atb":[[4.5,7.59]],"id":9630572},{"atl":[[5.2,0]],"id":9630572},{"atb":[[1.22,2]],"id":8509691},{"atl":[[1.29,1309.06]],"id":8509691}],"con":true,"img":false}]}
{"op":"mcm","clk":"1362333868","pt":1588440370271,"mc":[{"id":"1.170370564","rc":[{"atb":[[4.5,9.59]],"id":9630572},{"atl":[[5.2,2.03]],"id":9630572},{"atb":[[1.22,4.02]],"id":8509691},{"atl":[[1.29,1311.08]],"id":8509691}],"con":true,"img":false}]}
{"op":"mcm","clk":"1362333871","pt":1588440370577,"mc":[{"id":"1.170370564","rc":[{"atb":[[1.25,418.83]],"id":8509691}],"con":true,"img":false}]}
{"op":"mcm","clk":"1362333879","pt":1588440372055,"mc":[{"id":"1.170370564","rc":[{"trd":[[1.26,430.74]],"ltp":1.26,"tv":430.74,"id":8509691},{"atl":[[1.26,65.93]],"id":8509691}],"con":true,"img":false}]}
{"op":"mcm","clk":"1362333885","pt":1588440372565,"mc":[{"id":"1.170370564","rc":[{"atb":[[1.2,132.97],[1.21,0]],"id":8509691}],"con":true,"img":false}]}
{"op":"mcm","clk":"1362333889","pt":1588440373891,"mc":[{"id":"1.170370564","rc":[{"atb":[[4.1,2.33]],"id":9630572}],"con":true,"img":false}]}
{"op":"mcm","clk":"1362334213","pt":1588440441450,"mc":[{"id":"1.170370564","rc":[{"atb":[[4.4,2]],"id":9630572}],"con":true,"img":false}]}
{"op":"mcm","clk":"1362334216","pt":1588440441756,"mc":[{"id":"1.170370564","rc":[{"atb":[[4.5,7.59]],"id":9630572},{"atl":[[5.2,0]],"id":9630572},{"atb":[[1.22,2]],"id":8509691},{"atl":[[1.29,1309.06]],"id":8509691}],"con":true,"img":false}]}
{"op":"mcm","clk":"1362334218","pt":1588440441961,"mc":[{"id":"1.170370564","rc":[{"atb":[[4.5,9.69]],"id":9630572},{"atl":[[5.2,2.03]],"id":9630572},{"atb":[[1.22,4.02]],"id":8509691},{"atl":[[1.29,1311.08]],"id":8509691}],"con":true,"img":false}]}
{"op":"mcm","clk":"1362334260","pt":1588440451255,"mc":[{"id":"1.170370564","rc":[{"trd":[[1.26,530.74]],"ltp":1.26,"tv":530.74,"id":8509691},{"atl":[[1.26,15.93]],"id":8509691}],"con":true,"img":false}]}
{"op":"mcm","clk":"1362334262","pt":1588440451562,"mc":[{"id":"1.170370564","rc":[{"atb":[[4.5,7.59]],"id":9630572},{"atl":[[5.2,0]],"id":9630572},{"atb":[[1.22,2]],"id":8509691},{"atl":[[1.29,1309.06]],"id":8509691}],"con":true,"img":false}]}
{"op":"mcm","clk":"1362334264","pt":1588440451665,"mc":[{"id":"1.170370564","rc":[{"atb":[[4.6,2.04]],"id":9630572}],"con":true,"img":false}]}
{"op":"mcm","clk":"1362334265","pt":1588440451766,"mc":[{"id":"1.170370564","rc":[{"atb":[[4.5,9.69]],"id":9630572},{"atl":[[5.2,2.03]],"id":9630572},{"atb":[[1.22,4.02]],"id":8509691},{"atl":[[1.29,1311.25]],"id":8509691}],"con":true,"img":false}]}
{"op":"mcm","clk":"1362334289","pt":1588440456306,"mc":[{"id":"1.170370564","rc":[{"trd":[[1.25,2276.17]],"ltp":1.25,"tv":2276.17,"id":8509691},{"atb":[[1.25,417.06]],"id":8509691}],"con":true,"img":false}]}
{"op":"mcm","clk":"1362334457","pt":1588440492499,"mc":[{"id":"1.170370564","rc":[{"atb":[[4.1,0]],"id":9630572}],"con":true,"img":false}]}
{"op":"mcm","clk":"1362334460","pt":1588440492806,"mc":[{"id":"1.170370564","rc":[{"atb":[[4.5,7.59]],"id":9630572},{"atl":[[5.2,0]],"id":9630572},{"atb":[[1.22,2]],"id":8509691},{"atl":[[1.29,1309.06]],"id":8509691}],"con":true,"img":false}]}
{"op":"mcm","clk":"1362334461","pt":1588440493009,"mc":[{"id":"1.170370564","rc":[{"atb":[[4.5,9.69]],"id":9630572},{"atl":[[5.2,2.03]],"id":9630572},{"atb":[[1.22,4.02]],"id":8509691},{"atl":[[1.29,1311.25]],"id":8509691}],"con":true,"img":false}]}
{"op":"mcm","clk":"1362334473","pt":1588440494846,"mc":[{"id":"1.170370564","rc":[{"atb":[[4.1,2.33]],"id":9630572}],"con":true,"img":false}]}
{"op":"mcm","clk":"1362334481","pt":1588440496425,"mc":[{"id":"1.170370564","rc":[{"atb":[[1.25,397.06]],"id":8509691}],"con":true,"img":false}]}
{"op":"mcm","clk":"1362334518","pt":1588440503150,"mc":[{"id":"1.170370564","rc":[{"atb":[[1.24,65.15]],"id":8509691}],"con":true,"img":false}]}
{"op":"mcm","clk":"1362334522","pt":1588440503456,"mc":[{"id":"1.170370564","rc":[{"atb":[[4.5,7.59]],"id":9630572},{"atl":[[5.2,0]],"id":9630572},{"atb":[[1.22,2]],"id":8509691},{"atl":[[1.29,1309.06]],"id":8509691}],"con":true,"img":false}]}
{"op":"mcm","clk":"1362334524","pt":1588440503660,"mc":[{"id":"1.170370564","rc":[{"atb":[[4.5,9.69]],"id":9630572},{"atl":[[5.2,2.03]],"id":9630572},{"atb":[[1.22,4.02]],"id":8509691},{"atl":[[1.29,1311.25]],"id":8509691}],"con":true,"img":false}]}
{"op":"mcm","clk":"1362335654","pt":1588440564127,"mc":[{"id":"1.170370564","rc":[{"trd":[[1.26,562.62]],"ltp":1.26,"tv":562.62,"id":8509691},{"atb":[[1.26,84.06]],"id":8509691},{"atl":[[1.26,0]],"id":8509691}],"con":true,"img":false}]}
{"op":"mcm","clk":"1362335656","pt":1588440564331,"mc":[{"id":"1.170370564","rc":[{"atb":[[1.24,67.17]],"id":8509691},{"atl":[[1.3,2.05]],"id":8509691}],"con":true,"img":false}]}
{"op":"mcm","clk":"1362335657","pt":1588440564434,"mc":[{"id":"1.170370564","rc":[{"atl":[[5.2,0]],"id":9630572},{"atb":[[1.22,2]],"id":8509691},{"atl":[[1.28,104.8]],"id":8509691}],"con":true,"img":false}]}
{"op":"mcm","clk":"1362335659","pt":1588440564535,"mc":[{"id":"1.170370564","rc":[{"atb":[[4.5,7.59]],"id":9630572}],"con":true,"img":false}]}
{"op":"mcm","clk":"1362335660","pt":1588440564638,"mc":[{"id":"1.170370564","rc":[{"atb":[[1.22,90.65]],"id":8509691}],"con":true,"img":false}]}
{"op":"mcm","clk":"1362335661","pt":1588440564691,"mc":[{"id":"1.170370564","rc":[{"atb":[[4.4,4.01]],"id":9630572},{"atl":[[5.2,2.03]],"id":9630572}],"con":true,"img":false}]}
{"op":"mcm","clk":"1362335663","pt":1588440564793,"mc":[{"id":"1.170370564","rc":[{"atb":[[4.6,0]],"id":9630572},{"atb":[[1.23,131.79]],"id":8509691}],"con":true,"img":false}]}
{"op":"mcm","clk":"1362335665","pt":1588440564998,"mc":[{"id":"1.170370564","rc":[{"atb":[[4.5,9.69]],"id":9630572},{"atb":[[1.23,133.81]],"id":8509691}],"con":true,"img":false}]}
{"op":"mcm","clk":"1362335709","pt":1588440574133,"mc":[{"id":"1.170370564","rc":[{"atl":[[1.27,155.29]],"id":8509691}],"con":true,"img":false}]}
{"op":"mcm","clk":"1362335713","pt":1588440574444,"mc":[{"id":"1.170370564","rc":[{"atb":[[4.4,2]],"id":9630572},{"atl":[[5.2,0]],"id":9630572},{"atb":[[1.23,131.79]],"id":8509691},{"atl":[[1.3,0]],"id":8509691}],"con":true,"img":false}]}
{"op":"mcm","clk":"1362335716","pt":1588440574646,"mc":[{"id":"1.170370564","rc":[{"atb":[[4.4,4.01]],"id":9630572},{"atl":[[5.2,2.03]],"id":9630572},{"atb":[[1.23,133.81]],"id":8509691},{"atl":[[1.3,2.05]],"id":8509691}],"con":true,"img":false}]}
{"op":"mcm","clk":"1362335751","pt":1588440580259,"mc":[{"id":"1.170370564","rc":[{"atl":[[1.27,170.29]],"id":8509691}],"con":true,"img":false}]}
{"op":"mcm","clk":"1362335753","pt":1588440580518,"mc":[{"id":"1.170370564","rc":[{"atb":[[4.4,2]],"id":9630572},{"atl":[[5.2,0]],"id":9630572},{"atb":[[1.23,131.79]],"id":8509691},{"atl":[[1.3,0]],"id":8509691}],"con":true,"img":false}]}
{"op":"mcm","clk":"1362335756","pt":1588440580721,"mc":[{"id":"1.170370564","rc":[{"atb":[[4.4,4.01]],"id":9630572},{"atl":[[5.2,2.03]],"id":9630572},{"atb":[[1.23,133.81]],"id":8509691},{"atl":[[1.3,2.05]],"id":8509691}],"con":true,"img":false}]}
{"op":"mcm","clk":"1362335829","pt":1588440593632,"mc":[{"id":"1.170370564","rc":[{"trd":[[1.26,567.77]],"ltp":1.26,"tv":567.77,"id":8509691},{"atb":[[1.26,81.48]],"id":8509691}],"con":true,"img":false}]}
{"op":"mcm","clk":"1362335831","pt":1588440593938,"mc":[{"id":"1.170370564","rc":[{"atb":[[4.4,2]],"id":9630572},{"atl":[[5.2,0]],"id":9630572},{"atb":[[1.23,131.79]],"id":8509691},{"atl":[[1.3,0]],"id":8509691}],"con":true,"img":false}]}
{"op":"mcm","clk":"1362335833","pt":1588440594143,"mc":[{"id":"1.170370564","rc":[{"atb":[[4.4,4.01]],"id":9630572},{"atl":[[5.2,2.03]],"id":9630572},{"atb":[[1.23,133.81]],"id":8509691},{"atl":[[1.3,2.05]],"id":8509691}],"con":true,"img":false}]}
{"op":"mcm","clk":"1362335983","pt":1588440611459,"mc":[{"id":"1.170370564","rc":[{"atb":[[4.1,0]],"id":9630572}],"con":true,"img":false}]}
{"op":"mcm","clk":"1362335991","pt":1588440613292,"mc":[{"id":"1.170370564","rc":[{"atb":[[4.1,2.33]],"id":9630572}],"con":true,"img":false}]}
{"op":"mcm","clk":"1362336036","pt":1588440623293,"mc":[{"id":"1.170370565","rc":[{"trd":[[1.82,36.73]],"ltp":1.82,"tv":36.73,"id":11269555},{"atb":[[1.82,62.32]],"id":11269555}],"con":true,"img":false}]}
{"op":"mcm","clk":"1362336042","pt":1588440624573,"mc":[{"id":"1.170370565","rc":[{"atb":[[1.82,126.1]],"id":11269555}],"con":true,"img":false}]}
{"op":"mcm","clk":"1362336044","pt":1588440624673,"mc":[{"id":"1.170370565","rc":[{"atb":[[1.82,63.78]],"id":11269555}],"con":true,"img":false}]}
{"op":"mcm","clk":"1362336170","pt":1588440641724,"mc":[{"id":"1.170370564","rc":[{"trd":[[1.26,574.78]],"ltp":1.26,"tv":574.78,"id":8509691},{"atb":[[1.26,77.98]],"id":8509691}],"con":true,"img":false}]}
{"op":"mcm","clk":"1362336465","pt":1588440688063,"mc":[{"id":"1.170370564","rc":[{"trd":[[1.27,2506.35]],"ltp":1.27,"tv":2506.35,"id":8509691},{"atl":[[1.27,167.71]],"id":8509691}],"con":true,"img":false}]}
{"op":"mcm","clk":"1362336466","pt":1588440688371,"mc":[{"id":"1.170370564","rc":[{"atb":[[4.5,7.59]],"id":9630572},{"atl":[[5.1,0]],"id":9630572},{"atb":[[1.24,65.15]],"id":8509691}],"con":true,"img":false}]}
{"op":"mcm","clk":"1362336467","pt":1588440688472,"mc":[{"id":"1.170370564","rc":[{"atb":[[4.4,2]],"id":9630572},{"atl":[[5.2,0]],"id":9630572},{"atb":[[1.23,131.79]],"id":8509691},{"atl":[[1.3,0]],"id":8509691}],"con":true,"img":false}]}
{"op":"mcm","clk":"1362336469","pt":1588440688574,"mc":[{"id":"1.170370564","rc":[{"atl":[[1.29,1309.06]],"id":8509691}],"con":true,"img":false}]}
{"op":"mcm","clk":"1362336610","pt":1588440710121,"mc":[{"id":"1.170370564","rc":[{"atb":[[1.24,44.32]],"id":8509691}],"con":true,"img":false}]}
{"op":"mcm","clk":"1362336611","pt":1588440710223,"mc":[{"id":"1.170370564","rc":[{"atb":[[1.25,417.89]],"id":8509691}],"con":true,"img":false}]}
{"op":"mcm","clk":"1362336645","pt":1588440715842,"mc":[{"id":"1.170370564","rc":[{"trd":[[1.26,580.03]],"ltp":1.26,"tv":580.03,"id":8509691},{"atb":[[1.26,75.35]],"id":8509691}],"con":true,"img":false}]}
{"op":"mcm","clk":"1362336662","pt":1588440718909,"mc":[{"id":"1.170370564","rc":[{"trd":[[1.26,704.81]],"ltp":1.26,"tv":704.81,"id":8509691},{"atb":[[1.26,12.96]],"id":8509691}],"con":true,"img":false}]}
{"op":"mcm","clk":"1362336667","pt":1588440719623,"mc":[{"id":"1.170370564","rc":[{"atb":[[1.21,88.65],[1.22,2]],"id":8509691}],"con":true,"img":false}]}
{"op":"mcm","clk":"1362336729","pt":1588440731031,"mc":[{"id":"1.170370564","rc":[{"atl":[[7.2,1.77]],"id":9630572}],"con":true,"img":false}]}
{"op":"mcm","clk":"1362336766","pt":1588440735517,"mc":[{"id":"1.170370564","rc":[{"atb":[[4.1,0]],"id":9630572}],"con":true,"img":false}]}
{"op":"mcm","clk":"1362336775","pt":1588440737457,"mc":[{"id":"1.170370564","rc":[{"atb":[[4.1,2.33]],"id":9630572}],"con":true,"img":false}]}
{"op":"mcm","clk":"1362336935","pt":1588440764695,"mc":[{"id":"1.170370564","rc":[{"atl":[[1.27,237.71]],"id":8509691}],"con":true,"img":false}]}
{"op":"mcm","clk":"1362336968","pt":1588440770509,"mc":[{"id":"1.170370564","rc":[{"trd":[[1.26,709.97]],"ltp":1.26,"tv":709.97,"id":8509691},{"atb":[[1.26,10.38]],"id":8509691}],"con":true,"img":false}]}
{"op":"mcm","clk":"1362337024","pt":1588440782696,"mc":[{"id":"1.170370564","rc":[{"atl":[[1.27,252.71]],"id":8509691}],"con":true,"img":false}]}
{"op":"mcm","clk":"1362337108","pt":1588440798918,"mc":[{"id":"1.170370564","rc":[{"atb":[[4.8,17.49]],"id":9630572}],"con":true,"img":false}]}
{"op":"mcm","clk":"1362337112","pt":1588440799731,"mc":[{"id":"1.170370564","rc":[{"atb":[[4.6,7.38]],"id":9630572}],"con":true,"img":false}]}
{"op":"mcm","clk":"1362337130","pt":1588440803356,"mc":[{"id":"1.170370564","rc":[{"atb":[[3.5,0]],"id":9630572},{"atb":[[1.25,194.85]],"id":8509691}],"con":true,"img":false}]}
{"op":"mcm","clk":"1362337137","pt":1588440804530,"mc":[{"id":"1.170370564","rc":[{"trd":[[1.27,2534.65]],"ltp":1.27,"tv":2534.65,"id":8509691},{"atl":[[1.27,238.56]],"id":8509691}],"con":true,"img":false}]}
{"op":"mcm","clk":"1362337260","pt":1588440830366,"mc":[{"id":"1.170370564","rc":[{"atl":[[1.28,105.39]],"id":8509691}],"con":true,"img":false}]}
{"op":"mcm","clk":"1362337389","pt":1588440850308,"mc":[{"id":"1.170370564","rc":[{"atb":[[4.1,0]],"id":9630572}],"con":true,"img":false}]}
{"op":"mcm","clk":"1362337422","pt":1588440853614,"mc":[{"id":"1.170370564","rc":[{"atb":[[4.1,2.33]],"id":9630572}],"con":true,"img":false}]}
{"op":"mcm","clk":"1362337452","pt":1588440857129,"mc":[{"id":"1.170370564","rc":[{"atl":[[90,2]],"id":8509691}],"con":true,"img":false}]}
{"op":"mcm","clk":"1362337470","pt":1588440860644,"mc":[{"id":"1.170370564","rc":[{"atl":[[90,2.1]],"id":8509691}],"con":true,"img":false}]}
{"op":"mcm","clk":"1362337565","pt":1588440876154,"mc":[{"id":"1.170370564","rc":[{"atl":[[90,0]],"id":8509691}],"con":true,"img":false}]}
{"op":"mcm","clk":"1362337566","pt":1588440876256,"mc":[{"id":"1.170370564","rc":[{"trd":[[1.26,710.17]],"ltp":1.26,"tv":710.17,"id":8509691},{"atb":[[1.26,10.28]],"id":8509691}],"con":true,"img":false}]}
{"op":"mcm","clk":"1362337869","pt":1588440924850,"mc":[{"id":"1.170370564","rc":[{"atb":[[1.26,60.28]],"id":8509691}],"con":true,"img":false}]}
{"op":"mcm","clk":"1362337910","pt":1588440931331,"mc":[{"id":"1.170370564","rc":[{"atb":[[1.25,244.85]],"id":8509691}],"con":true,"img":false}]}
{"op":"mcm","clk":"1362337935","pt":1588440936273,"mc":[{"id":"1.170370565","rc":[{"atl":[[5.1,0]],"id":11269557}],"con":true,"img":false}]}
{"op":"mcm","clk":"1362337938","pt":1588440936579,"mc":[{"id":"1.170370565","rc":[{"atl":[[9,0]],"id":11340557}],"con":true,"img":false}]}
{"op":"mcm","clk":"1362337940","pt":1588440936782,"mc":[{"id":"1.170370565","rc":[{"atl":[[12,0]],"id":11340560}],"con":true,"img":false}]}
{"op":"mcm","clk":"1362337942","pt":1588440937139,"mc":[{"id":"1.170370565","rc":[{"atl":[[9.4,6]],"id":11340557},{"atl":[[12.5,6]],"id":11340560},{"atl":[[1.89,4]],"id":11269555},{"atl":[[5.1,4]],"id":11269557}],"con":true,"img":false}]}
{"op":"mcm","clk":"1362337977","pt":1588440942789,"mc":[{"id":"1.170370564","rc":[{"trd":[[4.8,106.24]],"ltp":4.8,"tv":106.24,"id":9630572},{"atb":[[4.8,15.3]],"id":9630572}],"con":true,"img":false}]}
{"op":"mcm","clk":"1362338002","pt":1588440948289,"mc":[{"id":"1.170370564","rc":[{"trd":[[1.26,792.87]],"ltp":1.26,"tv":792.87,"id":8509691},{"atb":[[1.26,18.93]],"id":8509691}],"con":true,"img":false}]}
{"op":"mcm","clk":"1362338029","pt":1588440953686,"mc":[{"id":"1.170370564","rc":[{"trd":[[1.26,830.73]],"ltp":1.26,"tv":830.73,"id":8509691},{"atb":[[1.26,0]],"id":8509691},{"atl":[[1.26,186.63]],"id":8509691}],"con":true,"img":false}]}
{"op":"mcm","clk":"1362338075","pt":1588440960617,"mc":[{"id":"1.170370564","rc":[{"trd":[[4.8,120.74]],"ltp":4.8,"tv":120.74,"id":9630572},{"atb":[[4.8,8.05]],"id":9630572}],"con":true,"img":false}]}
{"op":"mcm","clk":"1362338081","pt":1588440961694,"mc":[{"id":"1.170370564","rc":[{"atl":[[1.28,155.39]],"id":8509691}],"con":true,"img":false}]}
{"op":"mcm","clk":"1362338089","pt":1588440963629,"mc":[{"id":"1.170370564","rc":[{"atb":[[3.5,22.3]],"id":9630572},{"atb":[[1.25,467.89]],"id":8509691}],"con":true,"img":false}]}
{"op":"mcm","clk":"1362338138","pt":1588440971940,"mc":[{"id":"1.170370564","rc":[{"atb":[[4.1,0]],"id":9630572}],"con":true,"img":false}]}
{"op":"mcm","clk":"1362338158","pt":1588440973828,"mc":[{"id":"1.170370564","rc":[{"atb":[[4.1,2.33]],"id":9630572}],"con":true,"img":false}]}
{"op":"mcm","clk":"1362338178","pt":1588440975918,"mc":[{"id":"1.170370564","rc":[{"atl":[[1.27,288.56]],"id":8509691}],"con":true,"img":false}]}
{"op":"mcm","clk":"1362338211","pt":1588440982545,"mc":[{"id":"1.170370564","rc":[{"trd":[[1.26,831.49]],"ltp":1.26,"tv":831.49,"id":8509691},{"atl":[[1.26,186.25]],"id":8509691}],"con":true,"img":false}]}
{"op":"mcm","clk":"1362338422","pt":1588441009072,"mc":[{"id":"1.170370564","rc":[{"trd":[[1.25,2277.73]],"ltp":1.25,"tv":2277.73,"id":8509691},{"atb":[[1.25,467.11]],"id":8509691}],"con":true,"img":false}]}
{"op":"mcm","clk":"1362338434","pt":1588441011264,"mc":[{"id":"1.170370564","rc":[{"atb":[[1.24,94.32]],"id":8509691}],"con":true,"img":false}]}
{"op":"mcm","clk":"1362338599","pt":1588441039114,"mc":[{"id":"1.170370564","rc":[{"atl":[[4.9,0]],"id":9630572}],"con":true,"img":false}]}
{"op":"mcm","clk":"1362338892","pt":1588441090588,"mc":[{"id":"1.170370564","rc":[{"atb":[[4.1,0]],"id":9630572}],"con":true,"img":false}]}
{"op":"mcm","clk":"1362338906","pt":1588441093696,"mc":[{"id":"1.170370564","rc":[{"atb":[[4.1,2.33]],"id":9630572}],"con":true,"img":false}]}
{"op":"mcm","clk":"1362339151","pt":1588441136322,"mc":[{"id":"1.170370564","rc":[{"trd":[[1.25,2283.56]],"ltp":1.25,"tv":2283.56,"id":8509691},{"atb":[[1.25,464.19]],"id":8509691}],"con":true,"img":false}]}
{"op":"mcm","clk":"1362339397","pt":1588441180618,"mc":[{"id":"1.170370564","rc":[{"atb":[[1.13,63.25]],"id":8509691}],"con":true,"img":false}]}
{"op":"mcm","clk":"1362339488","pt":1588441200550,"mc":[{"id":"1.170370564","rc":[{"atl":[[1.5,13.74]],"id":8509691}],"con":true,"img":false}]}
{"op":"mcm","clk":"1362339503","pt":1588441202955,"mc":[{"id":"1.170370564","rc":[{"trd":[[1.25,2303.31]],"ltp":1.25,"tv":2303.31,"id":8509691},{"atb":[[1.25,454.32]],"id":8509691}],"con":true,"img":false}]}
{"op":"mcm","clk":"1362339554","pt":1588441209638,"mc":[{"id":"1.170370564","rc":[{"atb":[[4.1,0]],"id":9630572}],"con":true,"img":false}]}
{"op":"mcm","clk":"1362339592","pt":1588441213050,"mc":[{"id":"1.170370564","rc":[{"atb":[[4.1,2.33]],"id":9630572}],"con":true,"img":false}]}
{"op":"mcm","clk":"1362339957","pt":1588441292912,"mc":[{"id":"1.170370564","rc":[{"trd":[[1.25,2303.78]],"ltp":1.25,"tv":2303.78,"id":8509691},{"atb":[[1.25,454.09]],"id":8509691}],"con":true,"img":false}]}
{"op":"mcm","clk":"1362340177","pt":1588441332086,"mc":[{"id":"1.170370564","rc":[{"atb":[[4.1,0]],"id":9630572}],"con":true,"img":false}]}
{"op":"mcm","clk":"1362340187","pt":1588441333972,"mc":[{"id":"1.170370564","rc":[{"atb":[[4.1,2.33]],"id":9630572}],"con":true,"img":false}]}
{"op":"mcm","clk":"1362340478","pt":1588441401676,"mc":[{"id":"1.170370564","rc":[{"atl":[[1.27,219.97]],"id":8509691}],"con":true,"img":false}]}
{"op":"mcm","clk":"1362340479","pt":1588441401778,"mc":[{"id":"1.170370564","rc":[{"atl":[[1.26,254.84]],"id":8509691}],"con":true,"img":false}]}
{"op":"mcm","clk":"1362340498","pt":1588441406111,"mc":[{"id":"1.170370564","rc":[{"atl":[[1.26,186.25]],"id":8509691}],"con":true,"img":false}]}
{"op":"mcm","clk":"1362340534","pt":1588441414416,"mc":[{"id":"1.170370564","rc":[{"atl":[[1.26,255.39]],"id":8509691}],"con":true,"img":false}]}
{"op":"mcm","clk":"1362340721","pt":1588441445364,"mc":[{"id":"1.170370564","rc":[{"atl":[[1.26,186.25]],"id":8509691}],"con":true,"img":false}]}
{"op":"mcm","clk":"1362340750","pt":1588441450658,"mc":[{"id":"1.170370564","rc":[{"atl":[[1.26,255.39]],"id":8509691}],"con":true,"img":false}]}
{"op":"mcm","clk":"1362340756","pt":1588441451983,"mc":[{"id":"1.170370564","rc":[{"atb":[[4.1,0]],"id":9630572}],"con":true,"img":false}]}
{"op":"mcm","clk":"1362340762","pt":1588441453153,"mc":[{"id":"1.170370564","rc":[{"atb":[[4.1,2.33]],"id":9630572}],"con":true,"img":false}]}
{"op":"mcm","clk":"1362341778","pt":1588441518996,"mc":[{"id":"1.170370564","marketDefinition":{"bspMarket":false,"turnInPlayEnabled":true,"persistenceEnabled":true,"marketBaseRate":5.0,"eventId":"29788457","eventTypeId":"2","numberOfWinners":1,"bettingType":"ODDS","marketType":"MATCH_ODDS","marketTime":"2020-05-02T19:00:00.000Z","suspendTime":"2020-05-02T19:00:00.000Z","bspReconciled":false,"complete":true,"inPlay":false,"crossMatching":true,"runnersVoidable":false,"numberOfActiveRunners":2,"betDelay":0,"status":"OPEN","runners":[{"status":"ACTIVE","sortPriority":1,"id":8509691,"name":"P Lorenzi"},{"status":"ACTIVE","sortPriority":2,"id":9630572,"name":"S Kirchheimer"}],"regulators":["MR_INT"],"countryCode":"GB","discountAllowed":true,"timezone":"GMT","openDate":"2020-05-02T17:30:00.000Z","version":3237633898,"name":"Match Odds","eventName":"P Lorenzi v S Kirchheimer"},"rc":[],"con":true,"img":false}]}
{"op":"mcm","clk":"1362341779","pt":1588441518996,"mc":[{"id":"1.170370565","marketDefinition":{"bspMarket":false,"turnInPlayEnabled":true,"persistenceEnabled":true,"marketBaseRate":5.0,"eventId":"29788457","eventTypeId":"2","numberOfWinners":1,"bettingType":"ODDS","marketType":"SET_BETTING","marketTime":"2020-05-02T19:00:00.000Z","suspendTime":"2020-05-02T19:00:00.000Z","bspReconciled":false,"complete":true,"inPlay":false,"crossMatching":true,"runnersVoidable":false,"numberOfActiveRunners":4,"betDelay":0,"status":"OPEN","runners":[{"status":"ACTIVE","sortPriority":1,"id":11269555,"name":"P Lorenzi 2-0"},{"status":"ACTIVE","sortPriority":2,"id":11269557,"name":"P Lorenzi 2-1"},{"status":"ACTIVE","sortPriority":3,"id":11340557,"name":"S Kirchheimer 2-0"},{"status":"ACTIVE","sortPriority":4,"id":11340560,"name":"S Kirchheimer 2-1"}],"regulators":["MR_INT"],"countryCode":"GB","discountAllowed":true,"timezone":"GMT","openDate":"2020-05-02T17:30:00.000Z","version":3237633900,"name":"Set Betting","eventName":"P Lorenzi v S Kirchheimer"},"rc":[],"con":true,"img":false}]}
{"op":"mcm","clk":"1362341780","pt":1588441518996,"mc":[{"id":"1.170370567","marketDefinition":{"bspMarket":false,"turnInPlayEnabled":true,"persistenceEnabled":true,"marketBaseRate":5.0,"eventId":"29788457","eventTypeId":"2","numberOfWinners":1,"bettingType":"ODDS","marketType":"SET_WINNER","marketTime":"2020-05-02T19:00:00.000Z","suspendTime":"2020-05-02T19:00:00.000Z","bspReconciled":false,"complete":true,"inPlay":false,"crossMatching":true,"runnersVoidable":false,"numberOfActiveRunners":2,"betDelay":0,"status":"OPEN","runners":[{"status":"ACTIVE","sortPriority":1,"id":8509691,"name":"P Lorenzi"},{"status":"ACTIVE","sortPriority":2,"id":9630572,"name":"S Kirchheimer"}],"regulators":["MR_INT"],"countryCode":"GB","discountAllowed":true,"timezone":"GMT","openDate":"2020-05-02T17:30:00.000Z","version":3237633904,"name":"Set 2 Winner","eventName":"P Lorenzi v S Kirchheimer"},"rc":[],"con":true,"img":false}]}
{"op":"mcm","clk":"1362341781","pt":1588441518996,"mc":[{"id":"1.170370566","marketDefinition":{"bspMarket":false,"turnInPlayEnabled":true,"persistenceEnabled":true,"marketBaseRate":5.0,"eventId":"29788457","eventTypeId":"2","numberOfWinners":1,"bettingType":"ODDS","marketType":"SET_WINNER","marketTime":"2020-05-02T19:00:00.000Z","suspendTime":"2020-05-02T19:00:00.000Z","bspReconciled":false,"complete":true,"inPlay":false,"crossMatching":true,"runnersVoidable":false,"numberOfActiveRunners":2,"betDelay":0,"status":"OPEN","runners":[{"status":"ACTIVE","sortPriority":1,"id":8509691,"name":"P Lorenzi"},{"status":"ACTIVE","sortPriority":2,"id":9630572,"name":"S Kirchheimer"}],"regulators":["MR_INT"],"countryCode":"GB","discountAllowed":true,"timezone":"GMT","openDate":"2020-05-02T17:30:00.000Z","version":3237633902,"name":"Set 1 Winner","eventName":"P Lorenzi v S Kirchheimer"},"rc":[],"con":true,"img":false}]}
{"op":"mcm","clk":"1362341796","pt":1588441522000,"mc":[{"id":"1.170370566","marketDefinition":{"bspMarket":false,"turnInPlayEnabled":true,"persistenceEnabled":true,"marketBaseRate":5.0,"eventId":"29788457","eventTypeId":"2","numberOfWinners":1,"bettingType":"ODDS","marketType":"SET_WINNER","marketTime":"2020-05-02T19:00:00.000Z","suspendTime":"2020-05-02T19:00:00.000Z","bspReconciled":false,"complete":true,"inPlay":false,"crossMatching":true,"runnersVoidable":false,"numberOfActiveRunners":2,"betDelay":0,"status":"OPEN","runners":[{"status":"ACTIVE","sortPriority":1,"id":8509691,"name":"P Lorenzi"},{"status":"ACTIVE","sortPriority":2,"id":9630572,"name":"S Kirchheimer"}],"regulators":["MR_INT"],"countryCode":"GB","discountAllowed":true,"timezone":"GMT","openDate":"2020-05-02T19:00:00.000Z","version":3237633902,"name":"Set 1 Winner","eventName":"P Lorenzi v S Kirchheimer"},"rc":[],"con":true,"img":false}]}
{"op":"mcm","clk":"1362341797","pt":1588441522000,"mc":[{"id":"1.170370564","marketDefinition":{"bspMarket":false,"turnInPlayEnabled":true,"persistenceEnabled":true,"marketBaseRate":5.0,"eventId":"29788457","eventTypeId":"2","numberOfWinners":1,"bettingType":"ODDS","marketType":"MATCH_ODDS","marketTime":"2020-05-02T19:00:00.000Z","suspendTime":"2020-05-02T19:00:00.000Z","bspReconciled":false,"complete":true,"inPlay":false,"crossMatching":true,"runnersVoidable":false,"numberOfActiveRunners":2,"betDelay":0,"status":"OPEN","runners":[{"status":"ACTIVE","sortPriority":1,"id":8509691,"name":"P Lorenzi"},{"status":"ACTIVE","sortPriority":2,"id":9630572,"name":"S Kirchheimer"}],"regulators":["MR_INT"],"countryCode":"GB","discountAllowed":true,"timezone":"GMT","openDate":"2020-05-02T19:00:00.000Z","version":3237633898,"name":"Match Odds","eventName":"P Lorenzi v S Kirchheimer"},"rc":[],"con":true,"img":false}]}
{"op":"mcm","clk":"1362341798","pt":1588441522000,"mc":[{"id":"1.170370567","marketDefinition":{"bspMarket":false,"turnInPlayEnabled":true,"persistenceEnabled":true,"marketBaseRate":5.0,"eventId":"29788457","eventTypeId":"2","numberOfWinners":1,"bettingType":"ODDS","marketType":"SET_WINNER","marketTime":"2020-05-02T19:00:00.000Z","suspendTime":"2020-05-02T19:00:00.000Z","bspReconciled":false,"complete":true,"inPlay":false,"crossMatching":true,"runnersVoidable":false,"numberOfActiveRunners":2,"betDelay":0,"status":"OPEN","runners":[{"status":"ACTIVE","sortPriority":1,"id":8509691,"name":"P Lorenzi"},{"status":"ACTIVE","sortPriority":2,"id":9630572,"name":"S Kirchheimer"}],"regulators":["MR_INT"],"countryCode":"GB","discountAllowed":true,"timezone":"GMT","openDate":"2020-05-02T19:00:00.000Z","version":3237633904,"name":"Set 2 Winner","eventName":"P Lorenzi v S Kirchheimer"},"rc":[],"con":true,"img":false}]}
{"op":"mcm","clk":"1362341799","pt":1588441522000,"mc":[{"id":"1.170370565","marketDefinition":{"bspMarket":false,"turnInPlayEnabled":true,"persistenceEnabled":true,"marketBaseRate":5.0,"eventId":"29788457","eventTypeId":"2","numberOfWinners":1,"bettingType":"ODDS","marketType":"SET_BETTING","marketTime":"2020-05-02T19:00:00.000Z","suspendTime":"2020-05-02T19:00:00.000Z","bspReconciled":false,"complete":true,"inPlay":false,"crossMatching":true,"runnersVoidable":false,"numberOfActiveRunners":4,"betDelay":0,"status":"OPEN","runners":[{"status":"ACTIVE","sortPriority":1,"id":11269555,"name":"P Lorenzi 2-0"},{"status":"ACTIVE","sortPriority":2,"id":11269557,"name":"P Lorenzi 2-1"},{"status":"ACTIVE","sortPriority":3,"id":11340557,"name":"S Kirchheimer 2-0"},{"status":"ACTIVE","sortPriority":4,"id":11340560,"name":"S Kirchheimer 2-1"}],"regulators":["MR_INT"],"countryCode":"GB","discountAllowed":true,"timezone":"GMT","openDate":"2020-05-02T19:00:00.000Z","version":3237633900,"name":"Set Betting","eventName":"P Lorenzi v S Kirchheimer"},"rc":[],"con":true,"img":false}]}
{"op":"mcm","clk":"1362341887","pt":1588441544835,"mc":[{"id":"1.170370564","rc":[{"atb":[[4.7,2.66]],"id":9630572}],"con":true,"img":false}]}
{"op":"mcm","clk":"1362341895","pt":1588441546516,"mc":[{"id":"1.170370564","rc":[{"atb":[[4.7,0]],"id":9630572}],"con":true,"img":false}]}
{"op":"mcm","clk":"1362341926","pt":1588441558227,"mc":[{"id":"1.170370564","rc":[{"atb":[[4.7,2.66]],"id":9630572}],"con":true,"img":false}]}
{"op":"mcm","clk":"1362341930","pt":1588441559860,"mc":[{"id":"1.170370564","rc":[{"atb":[[4.7,0]],"id":9630572}],"con":true,"img":false}]}
{"op":"mcm","clk":"1362341942","pt":1588441563943,"mc":[{"id":"1.170370564","rc":[{"atb":[[4.7,2.66]],"id":9630572}],"con":true,"img":false}]}
{"op":"mcm","clk":"1362341955","pt":1588441566852,"mc":[{"id":"1.170370564","rc":[{"atb":[[4.7,0]],"id":9630572}],"con":true,"img":false}]}
{"op":"mcm","clk":"1362341960","pt":1588441568328,"mc":[{"id":"1.170370564","rc":[{"atb":[[4.7,2.66]],"id":9630572}],"con":true,"img":false}]}
{"op":"mcm","clk":"1362341965","pt":1588441569753,"mc":[{"id":"1.170370564","rc":[{"atb":[[4.1,0]],"id":9630572}],"con":true,"img":false}]}
{"op":"mcm","clk":"1362341974","pt":1588441572251,"mc":[{"id":"1.170370564","rc":[{"atb":[[4.7,0]],"id":9630572}],"con":true,"img":false}]}
{"op":"mcm","clk":"1362341987","pt":1588441575051,"mc":[{"id":"1.170370564","rc":[{"atb":[[4.1,2.33]],"id":9630572}],"con":true,"img":false}]}
{"op":"mcm","clk":"1362341994","pt":1588441577339,"mc":[{"id":"1.170370564","rc":[{"atb":[[4.7,2.66]],"id":9630572}],"con":true,"img":false}]}
{"op":"mcm","clk":"1362342024","pt":1588441588739,"mc":[{"id":"1.170370564","rc":[{"atl":[[1.26,252.82]],"id":8509691}],"con":true,"img":false}]}
{"op":"mcm","clk":"1362342031","pt":1588441592046,"mc":[{"id":"1.170370564","rc":[{"atb":[[4.7,0]],"id":9630572}],"con":true,"img":false}]}
{"op":"mcm","clk":"1362342034","pt":1588441593521,"mc":[{"id":"1.170370564","rc":[{"atb":[[4.7,2.66]],"id":9630572}],"con":true,"img":false}]}
{"op":"mcm","clk":"1362342056","pt":1588441600451,"mc":[{"id":"1.170370564","rc":[{"atl":[[1.26,297.14]],"id":8509691}],"con":true,"img":false}]}
{"op":"mcm","clk":"1362342057","pt":1588441600655,"mc":[{"id":"1.170370564","rc":[{"atb":[[4.7,0]],"id":9630572}],"con":true,"img":false}]}
{"op":"mcm","clk":"1362342065","pt":1588441602133,"mc":[{"id":"1.170370564","rc":[{"atb":[[4.7,2.66]],"id":9630572}],"con":true,"img":false}]}
{"op":"mcm","clk":"1362342120","pt":1588441617867,"mc":[{"id":"1.170370564","rc":[{"atl":[[1.26,252.82]],"id":8509691}],"con":true,"img":false}]}
{"op":"mcm","clk":"1362342121","pt":1588441617968,"mc":[{"id":"1.170370564","rc":[{"atl":[[1.27,264.3]],"id":8509691}],"con":true,"img":false}]}
{"op":"mcm","clk":"1362342259","pt":1588441656885,"mc":[{"id":"1.170370564","rc":[{"trd":[[1.25,2308.93]],"ltp":1.25,"tv":2308.93,"id":8509691},{"atb":[[1.25,451.51]],"id":8509691}],"con":true,"img":false}]}
{"op":"mcm","clk":"1362342266","pt":1588441659533,"mc":[{"id":"1.170370564","rc":[{"atl":[[1.26,250.24]],"id":8509691}],"con":true,"img":false}]}
{"op":"mcm","clk":"1362342370","pt":1588441684191,"mc":[{"id":"1.170370566","marketDefinition":{"bspMarket":false,"turnInPlayEnabled":true,"persistenceEnabled":true,"marketBaseRate":5.0,"eventId":"29788457","eventTypeId":"2","numberOfWinners":1,"bettingType":"ODDS","marketType":"SET_WINNER","marketTime":"2020-05-02T16:00:00.000Z","suspendTime":"2020-05-02T16:00:00.000Z","bspReconciled":false,"complete":true,"inPlay":false,"crossMatching":true,"runnersVoidable":false,"numberOfActiveRunners":2,"betDelay":0,"status":"OPEN","runners":[{"status":"ACTIVE","sortPriority":1,"id":8509691,"name":"P Lorenzi"},{"status":"ACTIVE","sortPriority":2,"id":9630572,"name":"S Kirchheimer"}],"regulators":["MR_INT"],"countryCode":"GB","discountAllowed":true,"timezone":"GMT","openDate":"2020-05-02T19:00:00.000Z","version":3237634204,"name":"Set 1 Winner","eventName":"P Lorenzi v S Kirchheimer"},"rc":[],"con":true,"img":false}]}
{"op":"mcm","clk":"1362342371","pt":1588441684191,"mc":[{"id":"1.170370565","marketDefinition":{"bspMarket":false,"turnInPlayEnabled":true,"persistenceEnabled":true,"marketBaseRate":5.0,"eventId":"29788457","eventTypeId":"2","numberOfWinners":1,"bettingType":"ODDS","marketType":"SET_BETTING","marketTime":"2020-05-02T16:00:00.000Z","suspendTime":"2020-05-02T16:00:00.000Z","bspReconciled":false,"complete":true,"inPlay":false,"crossMatching":true,"runnersVoidable":false,"numberOfActiveRunners":4,"betDelay":0,"status":"OPEN","runners":[{"status":"ACTIVE","sortPriority":1,"id":11269555,"name":"P Lorenzi 2-0"},{"status":"ACTIVE","sortPriority":2,"id":11269557,"name":"P Lorenzi 2-1"},{"status":"ACTIVE","sortPriority":3,"id":11340557,"name":"S Kirchheimer 2-0"},{"status":"ACTIVE","sortPriority":4,"id":11340560,"name":"S Kirchheimer 2-1"}],"regulators":["MR_INT"],"countryCode":"GB","discountAllowed":true,"timezone":"GMT","openDate":"2020-05-02T19:00:00.000Z","version":3237634202,"name":"Set Betting","eventName":"P Lorenzi v S Kirchheimer"},"rc":[],"con":true,"img":false}]}
{"op":"mcm","clk":"1362342372","pt":1588441684191,"mc":[{"id":"1.170370567","marketDefinition":{"bspMarket":false,"turnInPlayEnabled":true,"persistenceEnabled":true,"marketBaseRate":5.0,"eventId":"29788457","eventTypeId":"2","numberOfWinners":1,"bettingType":"ODDS","marketType":"SET_WINNER","marketTime":"2020-05-02T16:00:00.000Z","suspendTime":"2020-05-02T16:00:00.000Z","bspReconciled":false,"complete":true,"inPlay":false,"crossMatching":true,"runnersVoidable":false,"numberOfActiveRunners":2,"betDelay":0,"status":"OPEN","runners":[{"status":"ACTIVE","sortPriority":1,"id":8509691,"name":"P Lorenzi"},{"status":"ACTIVE","sortPriority":2,"id":9630572,"name":"S Kirchheimer"}],"regulators":["MR_INT"],"countryCode":"GB","discountAllowed":true,"timezone":"GMT","openDate":"2020-05-02T19:00:00.000Z","version":3237634206,"name":"Set 2 Winner","eventName":"P Lorenzi v S Kirchheimer"},"rc":[],"con":true,"img":false}]}
{"op":"mcm","clk":"1362342373","pt":1588441684191,"mc":[{"id":"1.170370564","marketDefinition":{"bspMarket":false,"turnInPlayEnabled":true,"persistenceEnabled":true,"marketBaseRate":5.0,"eventId":"29788457","eventTypeId":"2","numberOfWinners":1,"bettingType":"ODDS","marketType":"MATCH_ODDS","marketTime":"2020-05-02T16:00:00.000Z","suspendTime":"2020-05-02T16:00:00.000Z","bspReconciled":false,"complete":true,"inPlay":false,"crossMatching":true,"runnersVoidable":false,"numberOfActiveRunners":2,"betDelay":0,"status":"OPEN","runners":[{"status":"ACTIVE","sortPriority":1,"id":8509691,"name":"P Lorenzi"},{"status":"ACTIVE","sortPriority":2,"id":9630572,"name":"S Kirchheimer"}],"regulators":["MR_INT"],"countryCode":"GB","discountAllowed":true,"timezone":"GMT","openDate":"2020-05-02T19:00:00.000Z","version":3237634200,"name":"Match Odds","eventName":"P Lorenzi v S Kirchheimer"},"rc":[],"con":true,"img":false}]}
{"op":"mcm","clk":"1362342387","pt":1588441688196,"mc":[{"id":"1.170370564","marketDefinition":{"bspMarket":false,"turnInPlayEnabled":true,"persistenceEnabled":true,"marketBaseRate":5.0,"eventId":"29788457","eventTypeId":"2","numberOfWinners":1,"bettingType":"ODDS","marketType":"MATCH_ODDS","marketTime":"2020-05-02T16:00:00.000Z","suspendTime":"2020-05-02T16:00:00.000Z","bspReconciled":false,"complete":true,"inPlay":false,"crossMatching":true,"runnersVoidable":false,"numberOfActiveRunners":2,"betDelay":0,"status":"OPEN","runners":[{"status":"ACTIVE","sortPriority":1,"id":8509691,"name":"P Lorenzi"},{"status":"ACTIVE","sortPriority":2,"id":9630572,"name":"S Kirchheimer"}],"regulators":["MR_INT"],"countryCode":"GB","discountAllowed":true,"timezone":"GMT","openDate":"2020-05-02T16:00:00.000Z","version":3237634200,"name":"Match Odds","eventName":"P Lorenzi v S Kirchheimer"},"rc":[],"con":true,"img":false}]}
{"op":"mcm","clk":"1362342388","pt":1588441688196,"mc":[{"id":"1.170370567","marketDefinition":{"bspMarket":false,"turnInPlayEnabled":true,"persistenceEnabled":true,"marketBaseRate":5.0,"eventId":"29788457","eventTypeId":"2","numberOfWinners":1,"bettingType":"ODDS","marketType":"SET_WINNER","marketTime":"2020-05-02T16:00:00.000Z","suspendTime":"2020-05-02T16:00:00.000Z","bspReconciled":false,"complete":true,"inPlay":false,"crossMatching":true,"runnersVoidable":false,"numberOfActiveRunners":2,"betDelay":0,"status":"OPEN","runners":[{"status":"ACTIVE","sortPriority":1,"id":8509691,"name":"P Lorenzi"},{"status":"ACTIVE","sortPriority":2,"id":9630572,"name":"S Kirchheimer"}],"regulators":["MR_INT"],"countryCode":"GB","discountAllowed":true,"timezone":"GMT","openDate":"2020-05-02T16:00:00.000Z","version":3237634206,"name":"Set 2 Winner","eventName":"P Lorenzi v S Kirchheimer"},"rc":[],"con":true,"img":false}]}
{"op":"mcm","clk":"1362342389","pt":1588441688196,"mc":[{"id":"1.170370566","marketDefinition":{"bspMarket":false,"turnInPlayEnabled":true,"persistenceEnabled":true,"marketBaseRate":5.0,"eventId":"29788457","eventTypeId":"2","numberOfWinners":1,"bettingType":"ODDS","marketType":"SET_WINNER","marketTime":"2020-05-02T16:00:00.000Z","suspendTime":"2020-05-02T16:00:00.000Z","bspReconciled":false,"complete":true,"inPlay":false,"crossMatching":true,"runnersVoidable":false,"numberOfActiveRunners":2,"betDelay":0,"status":"OPEN","runners":[{"status":"ACTIVE","sortPriority":1,"id":8509691,"name":"P Lorenzi"},{"status":"ACTIVE","sortPriority":2,"id":9630572,"name":"S Kirchheimer"}],"regulators":["MR_INT"],"countryCode":"GB","discountAllowed":true,"timezone":"GMT","openDate":"2020-05-02T16:00:00.000Z","version":3237634204,"name":"Set 1 Winner","eventName":"P Lorenzi v S Kirchheimer"},"rc":[],"con":true,"img":false}]}
{"op":"mcm","clk":"1362342390","pt":1588441688196,"mc":[{"id":"1.170370565","marketDefinition":{"bspMarket":false,"turnInPlayEnabled":true,"persistenceEnabled":true,"marketBaseRate":5.0,"eventId":"29788457","eventTypeId":"2","numberOfWinners":1,"bettingType":"ODDS","marketType":"SET_BETTING","marketTime":"2020-05-02T16:00:00.000Z","suspendTime":"2020-05-02T16:00:00.000Z","bspReconciled":false,"complete":true,"inPlay":false,"crossMatching":true,"runnersVoidable":false,"numberOfActiveRunners":4,"betDelay":0,"status":"OPEN","runners":[{"status":"ACTIVE","sortPriority":1,"id":11269555,"name":"P Lorenzi 2-0"},{"status":"ACTIVE","sortPriority":2,"id":11269557,"name":"P Lorenzi 2-1"},{"status":"ACTIVE","sortPriority":3,"id":11340557,"name":"S Kirchheimer 2-0"},{"status":"ACTIVE","sortPriority":4,"id":11340560,"name":"S Kirchheimer 2-1"}],"regulators":["MR_INT"],"countryCode":"GB","discountAllowed":true,"timezone":"GMT","openDate":"2020-05-02T16:00:00.000Z","version":3237634202,"name":"Set Betting","eventName":"P Lorenzi v S Kirchheimer"},"rc":[],"con":true,"img":false}]}
{"op":"mcm","clk":"1362342394","pt":1588441689657,"mc":[{"id":"1.170370564","rc":[{"atb":[[4.1,0]],"id":9630572}],"con":true,"img":false}]}
{"op":"mcm","clk":"1362342411","pt":1588441694242,"mc":[{"id":"1.170370564","rc":[{"atb":[[4.1,2.33]],"id":9630572}],"con":true,"img":false}]}
{"op":"mcm","clk":"1362342531","pt":1588441726163,"mc":[{"id":"1.170370564","rc":[{"atb":[[4.3,0],[4.5,0],[4.6,0]],"id":9630572},{"atb":[[1.2,44.32],[1.21,0]],"id":8509691}],"con":true,"img":false}]}
{"op":"mcm","clk":"1362342552","pt":1588441730952,"mc":[{"id":"1.170370564","rc":[{"atb":[[4.7,0]],"id":9630572}],"con":true,"img":false}]}
{"op":"mcm","clk":"1362342559","pt":1588441732477,"mc":[{"id":"1.170370564","rc":[{"atb":[[4.7,2.66]],"id":9630572}],"con":true,"img":false}]}
{"op":"mcm","clk":"1362342608","pt":1588441743996,"mc":[{"id":"1.170370564","rc":[{"atb":[[4.7,0]],"id":9630572}],"con":true,"img":false}]}
{"op":"mcm","clk":"1362342626","pt":1588441747572,"mc":[{"id":"1.170370564","rc":[{"atb":[[4.7,2.66]],"id":9630572}],"con":true,"img":false}]}
{"op":"mcm","clk":"1362342639","pt":1588441750171,"mc":[{"id":"1.170370564","rc":[{"atb":[[4.7,0]],"id":9630572}],"con":true,"img":false}]}
{"op":"mcm","clk":"1362342643","pt":1588441751696,"mc":[{"id":"1.170370564","rc":[{"atb":[[4.7,2.66]],"id":9630572}],"con":true,"img":false}]}
{"op":"mcm","clk":"1362342652","pt":1588441753276,"mc":[{"id":"1.170370564","rc":[{"atb":[[4.7,0]],"id":9630572}],"con":true,"img":false}]}
{"op":"mcm","clk":"1362342662","pt":1588441755874,"mc":[{"id":"1.170370564","rc":[{"atb":[[4.7,2.66]],"id":9630572}],"con":true,"img":false}]}
{"op":"mcm","clk":"1362342670","pt":1588441758517,"mc":[{"id":"1.170370564","rc":[{"atb":[[4.7,0]],"id":9630572}],"con":true,"img":false}]}
{"op":"mcm","clk":"1362342694","pt":1588441763507,"mc":[{"id":"1.170370564","rc":[{"atb":[[4.7,2.66]],"id":9630572}],"con":true,"img":false}]}
{"op":"mcm","clk":"1362342703","pt":1588441765086,"mc":[{"id":"1.170370564","rc":[{"atb":[[1.25,453.34]],"id":8509691}],"con":true,"img":false}]}
{"op":"mcm","clk":"1362342709","pt":1588441766408,"mc":[{"id":"1.170370564","rc":[{"atb":[[4.7,0]],"id":9630572}],"con":true,"img":false}]}
{"op":"mcm","clk":"1362342724","pt":1588441769309,"mc":[{"id":"1.170370564","rc":[{"atb":[[4.7,2.66]],"id":9630572}],"con":true,"img":false}]}
{"op":"mcm","clk":"1362342732","pt":1588441770888,"mc":[{"id":"1.170370564","rc":[{"atb":[[4.7,0]],"id":9630572}],"con":true,"img":false}]}
{"op":"mcm","clk":"1362342759","pt":1588441776329,"mc":[{"id":"1.170370564","rc":[{"atb":[[4.7,2.66]],"id":9630572}],"con":true,"img":false}]}
{"op":"mcm","clk":"1362342767","pt":1588441779029,"mc":[{"id":"1.170370564","rc":[{"atb":[[4.7,0]],"id":9630572}],"con":true,"img":false}]}
{"op":"mcm","clk":"1362342777","pt":1588441782901,"mc":[{"id":"1.170370564","rc":[{"atb":[[4.7,2.66]],"id":9630572}],"con":true,"img":false}]}
{"op":"mcm","clk":"1362342784","pt":1588441784630,"mc":[{"id":"1.170370564","rc":[{"atb":[[4.7,0]],"id":9630572}],"con":true,"img":false}]}
{"op":"mcm","clk":"1362342851","pt":1588441805068,"mc":[{"id":"1.170370564","rc":[{"atl":[[1.28,154.8]],"id":8509691}],"con":true,"img":false}]}
{"op":"mcm","clk":"1362342868","pt":1588441812251,"mc":[{"id":"1.170370564","rc":[{"atb":[[4.1,0]],"id":9630572}],"con":true,"img":false}]}
{"op":"mcm","clk":"1362342872","pt":1588441813575,"mc":[{"id":"1.170370564","rc":[{"atb":[[4.1,2.33]],"id":9630572}],"con":true,"img":false}]}
{"op":"mcm","clk":"1362342968","pt":1588441856850,"mc":[{"id":"1.170370566","rc":[{"atl":[[4.2,0]],"id":9630572}],"con":true,"img":false}]}
{"op":"mcm","clk":"1362342969","pt":1588441856904,"mc":[{"id":"1.170370566","rc":[{"atl":[[4.1,10]],"id":9630572}],"con":true,"img":false}]}
{"op":"mcm","clk":"1362343073","pt":1588441874749,"mc":[{"id":"1.170370564","rc":[{"trd":[[1.26,862.48]],"ltp":1.26,"tv":862.48,"id":8509691},{"atl":[[1.26,234.75]],"id":8509691}],"con":true,"img":false}]}
{"op":"mcm","clk":"1362343131","pt":1588441902908,"mc":[{"id":"1.170370564","rc":[{"trd":[[1.26,866.48]],"ltp":1.26,"tv":866.48,"id":8509691},{"atl":[[1.26,232.75]],"id":8509691}],"con":true,"img":false}]}
{"op":"mcm","clk":"1362343216","pt":1588441937840,"mc":[{"id":"1.170370564","rc":[{"atb":[[4.1,0]],"id":9630572}],"con":true,"img":false}]}
{"op":"mcm","clk":"1362343219","pt":1588441939622,"mc":[{"id":"1.170370564","rc":[{"atb":[[4.1,2.33]],"id":9630572}],"con":true,"img":false}]}
{"op":"mcm","clk":"1362343309","pt":1588441979684,"mc":[{"id":"1.170370564","rc":[{"atl":[[1.27,194.3]],"id":8509691}],"con":true,"img":false}]}
{"op":"mcm","clk":"1362343311","pt":1588441979785,"mc":[{"id":"1.170370564","rc":[{"atl":[[1.28,224.8]],"id":8509691}],"con":true,"img":false}]}
{"op":"mcm","clk":"1362343391","pt":1588442013219,"mc":[{"id":"1.170370564","rc":[{"atb":[[1.03,3.24]],"id":8509691}],"con":true,"img":false}]}
{"op":"mcm","clk":"1362343392","pt":1588442013599,"mc":[{"id":"1.170370567","marketDefinition":{"bspMarket":false,"turnInPlayEnabled":true,"persistenceEnabled":true,"marketBaseRate":5.0,"eventId":"29788457","eventTypeId":"2","numberOfWinners":1,"bettingType":"ODDS","marketType":"SET_WINNER","marketTime":"2020-05-02T19:00:00.000Z","suspendTime":"2020-05-02T19:00:00.000Z","bspReconciled":false,"complete":true,"inPlay":false,"crossMatching":true,"runnersVoidable":false,"numberOfActiveRunners":2,"betDelay":0,"status":"OPEN","runners":[{"status":"ACTIVE","sortPriority":1,"id":8509691,"name":"P Lorenzi"},{"status":"ACTIVE","sortPriority":2,"id":9630572,"name":"S Kirchheimer"}],"regulators":["MR_INT"],"countryCode":"GB","discountAllowed":true,"timezone":"GMT","openDate":"2020-05-02T16:00:00.000Z","version":3237634488,"name":"Set 2 Winner","eventName":"P Lorenzi v S Kirchheimer"},"rc":[],"con":true,"img":false}]}
{"op":"mcm","clk":"1362343393","pt":1588442013599,"mc":[{"id":"1.170370565","marketDefinition":{"bspMarket":false,"turnInPlayEnabled":true,"persistenceEnabled":true,"marketBaseRate":5.0,"eventId":"29788457","eventTypeId":"2","numberOfWinners":1,"bettingType":"ODDS","marketType":"SET_BETTING","marketTime":"2020-05-02T19:00:00.000Z","suspendTime":"2020-05-02T19:00:00.000Z","bspReconciled":false,"complete":true,"inPlay":false,"crossMatching":true,"runnersVoidable":false,"numberOfActiveRunners":4,"betDelay":0,"status":"OPEN","runners":[{"status":"ACTIVE","sortPriority":1,"id":11269555,"name":"P Lorenzi 2-0"},{"status":"ACTIVE","sortPriority":2,"id":11269557,"name":"P Lorenzi 2-1"},{"status":"ACTIVE","sortPriority":3,"id":11340557,"name":"S Kirchheimer 2-0"},{"status":"ACTIVE","sortPriority":4,"id":11340560,"name":"S Kirchheimer 2-1"}],"regulators":["MR_INT"],"countryCode":"GB","discountAllowed":true,"timezone":"GMT","openDate":"2020-05-02T16:00:00.000Z","version":3237634484,"name":"Set Betting","eventName":"P Lorenzi v S Kirchheimer"},"rc":[],"con":true,"img":false}]}
{"op":"mcm","clk":"1362343394","pt":1588442013599,"mc":[{"id":"1.170370566","marketDefinition":{"bspMarket":false,"turnInPlayEnabled":true,"persistenceEnabled":true,"marketBaseRate":5.0,"eventId":"29788457","eventTypeId":"2","numberOfWinners":1,"bettingType":"ODDS","marketType":"SET_WINNER","marketTime":"2020-05-02T19:00:00.000Z","suspendTime":"2020-05-02T19:00:00.000Z","bspReconciled":false,"complete":true,"inPlay":false,"crossMatching":true,"runnersVoidable":false,"numberOfActiveRunners":2,"betDelay":0,"status":"OPEN","runners":[{"status":"ACTIVE","sortPriority":1,"id":8509691,"name":"P Lorenzi"},{"status":"ACTIVE","sortPriority":2,"id":9630572,"name":"S Kirchheimer"}],"regulators":["MR_INT"],"countryCode":"GB","discountAllowed":true,"timezone":"GMT","openDate":"2020-05-02T16:00:00.000Z","version":3237634486,"name":"Set 1 Winner","eventName":"P Lorenzi v S Kirchheimer"},"rc":[],"con":true,"img":false}]}
{"op":"mcm","clk":"1362343395","pt":1588442013600,"mc":[{"id":"1.170370564","marketDefinition":{"bspMarket":false,"turnInPlayEnabled":true,"persistenceEnabled":true,"marketBaseRate":5.0,"eventId":"29788457","eventTypeId":"2","numberOfWinners":1,"bettingType":"ODDS","marketType":"MATCH_ODDS","marketTime":"2020-05-02T19:00:00.000Z","suspendTime":"2020-05-02T19:00:00.000Z","bspReconciled":false,"complete":true,"inPlay":false,"crossMatching":true,"runnersVoidable":false,"numberOfActiveRunners":2,"betDelay":0,"status":"OPEN","runners":[{"status":"ACTIVE","sortPriority":1,"id":8509691,"name":"P Lorenzi"},{"status":"ACTIVE","sortPriority":2,"id":9630572,"name":"S Kirchheimer"}],"regulators":["MR_INT"],"countryCode":"GB","discountAllowed":true,"timezone":"GMT","openDate":"2020-05-02T16:00:00.000Z","version":3237634482,"name":"Match Odds","eventName":"P Lorenzi v S Kirchheimer"},"rc":[],"con":true,"img":false}]}
{"op":"mcm","clk":"1362343401","pt":1588442014600,"mc":[{"id":"1.170370566","marketDefinition":{"bspMarket":false,"turnInPlayEnabled":true,"persistenceEnabled":true,"marketBaseRate":5.0,"eventId":"29788457","eventTypeId":"2","numberOfWinners":1,"bettingType":"ODDS","marketType":"SET_WINNER","marketTime":"2020-05-02T19:00:00.000Z","suspendTime":"2020-05-02T19:00:00.000Z","bspReconciled":false,"complete":true,"inPlay":false,"crossMatching":true,"runnersVoidable":false,"numberOfActiveRunners":2,"betDelay":0,"status":"OPEN","runners":[{"status":"ACTIVE","sortPriority":1,"id":8509691,"name":"P Lorenzi"},{"status":"ACTIVE","sortPriority":2,"id":9630572,"name":"S Kirchheimer"}],"regulators":["MR_INT"],"countryCode":"GB","discountAllowed":true,"timezone":"GMT","openDate":"2020-05-02T19:00:00.000Z","version":3237634486,"name":"Set 1 Winner","eventName":"P Lorenzi v S Kirchheimer"},"rc":[],"con":true,"img":false}]}
{"op":"mcm","clk":"1362343402","pt":1588442014600,"mc":[{"id":"1.170370564","marketDefinition":{"bspMarket":false,"turnInPlayEnabled":true,"persistenceEnabled":true,"marketBaseRate":5.0,"eventId":"29788457","eventTypeId":"2","numberOfWinners":1,"bettingType":"ODDS","marketType":"MATCH_ODDS","marketTime":"2020-05-02T19:00:00.000Z","suspendTime":"2020-05-02T19:00:00.000Z","bspReconciled":false,"complete":true,"inPlay":false,"crossMatching":true,"runnersVoidable":false,"numberOfActiveRunners":2,"betDelay":0,"status":"OPEN","runners":[{"status":"ACTIVE","sortPriority":1,"id":8509691,"name":"P Lorenzi"},{"status":"ACTIVE","sortPriority":2,"id":9630572,"name":"S Kirchheimer"}],"regulators":["MR_INT"],"countryCode":"GB","discountAllowed":true,"timezone":"GMT","openDate":"2020-05-02T19:00:00.000Z","version":3237634482,"name":"Match Odds","eventName":"P Lorenzi v S Kirchheimer"},"rc":[],"con":true,"img":false}]}
{"op":"mcm","clk":"1362343403","pt":1588442014600,"mc":[{"id":"1.170370567","marketDefinition":{"bspMarket":false,"turnInPlayEnabled":true,"persistenceEnabled":true,"marketBaseRate":5.0,"eventId":"29788457","eventTypeId":"2","numberOfWinners":1,"bettingType":"ODDS","marketType":"SET_WINNER","marketTime":"2020-05-02T19:00:00.000Z","suspendTime":"2020-05-02T19:00:00.000Z","bspReconciled":false,"complete":true,"inPlay":false,"crossMatching":true,"runnersVoidable":false,"numberOfActiveRunners":2,"betDelay":0,"status":"OPEN","runners":[{"status":"ACTIVE","sortPriority":1,"id":8509691,"name":"P Lorenzi"},{"status":"ACTIVE","sortPriority":2,"id":9630572,"name":"S Kirchheimer"}],"regulators":["MR_INT"],"countryCode":"GB","discountAllowed":true,"timezone":"GMT","openDate":"2020-05-02T19:00:00.000Z","version":3237634488,"name":"Set 2 Winner","eventName":"P Lorenzi v S Kirchheimer"},"rc":[],"con":true,"img":false}]}
{"op":"mcm","clk":"1362343404","pt":1588442014600,"mc":[{"id":"1.170370565","marketDefinition":{"bspMarket":false,"turnInPlayEnabled":true,"persistenceEnabled":true,"marketBaseRate":5.0,"eventId":"29788457","eventTypeId":"2","numberOfWinners":1,"bettingType":"ODDS","marketType":"SET_BETTING","marketTime":"2020-05-02T19:00:00.000Z","suspendTime":"2020-05-02T19:00:00.000Z","bspReconciled":false,"complete":true,"inPlay":false,"crossMatching":true,"runnersVoidable":false,"numberOfActiveRunners":4,"betDelay":0,"status":"OPEN","runners":[{"status":"ACTIVE","sortPriority":1,"id":11269555,"name":"P Lorenzi 2-0"},{"status":"ACTIVE","sortPriority":2,"id":11269557,"name":"P Lorenzi 2-1"},{"status":"ACTIVE","sortPriority":3,"id":11340557,"name":"S Kirchheimer 2-0"},{"status":"ACTIVE","sortPriority":4,"id":11340560,"name":"S Kirchheimer 2-1"}],"regulators":["MR_INT"],"countryCode":"GB","discountAllowed":true,"timezone":"GMT","openDate":"2020-05-02T19:00:00.000Z","version":3237634484,"name":"Set Betting","eventName":"P Lorenzi v S Kirchheimer"},"rc":[],"con":true,"img":false}]}
{"op":"mcm","clk":"1362343544","pt":1588442052737,"mc":[{"id":"1.170370564","rc":[{"atb":[[4.1,0]],"id":9630572}],"con":true,"img":false}]}
{"op":"mcm","clk":"1362343548","pt":1588442054061,"mc":[{"id":"1.170370564","rc":[{"atb":[[4.1,2.33]],"id":9630572}],"con":true,"img":false}]}
{"op":"mcm","clk":"1362343564","pt":1588442060120,"mc":[{"id":"1.170370564","rc":[{"atb":[[4.7,2.66]],"id":9630572}],"con":true,"img":false}]}
{"op":"mcm","clk":"1362343567","pt":1588442061851,"mc":[{"id":"1.170370564","rc":[{"atb":[[4.7,0]],"id":9630572}],"con":true,"img":false}]}
{"op":"mcm","clk":"1362343572","pt":1588442063329,"mc":[{"id":"1.170370564","rc":[{"atb":[[4.7,2.66]],"id":9630572}],"con":true,"img":false}]}
{"op":"mcm","clk":"1362343575","pt":1588442065166,"mc":[{"id":"1.170370564","rc":[{"atb":[[4.7,0]],"id":9630572}],"con":true,"img":false}]}
{"op":"mcm","clk":"1362343577","pt":1588442067664,"mc":[{"id":"1.170370564","rc":[{"atb":[[4.7,2.66]],"id":9630572}],"con":true,"img":false}]}
{"op":"mcm","clk":"1362343589","pt":1588442073265,"mc":[{"id":"1.170370564","rc":[{"atb":[[4.7,0]],"id":9630572}],"con":true,"img":false}]}
{"op":"mcm","clk":"1362343592","pt":1588442074743,"mc":[{"id":"1.170370564","rc":[{"atb":[[4.7,2.66]],"id":9630572}],"con":true,"img":false}]}
{"op":"mcm","clk":"1362343595","pt":1588442076371,"mc":[{"id":"1.170370564","rc":[{"atb":[[4.7,0]],"id":9630572}],"con":true,"img":false}]}
{"op":"mcm","clk":"1362343603","pt":1588442081364,"mc":[{"id":"1.170370564","rc":[{"atb":[[4.7,2.66]],"id":9630572}],"con":true,"img":false}]}
{"op":"mcm","clk":"1362343610","pt":1588442085792,"mc":[{"id":"1.170370564","rc":[{"atb":[[4.7,0]],"id":9630572}],"con":true,"img":false}]}
{"op":"mcm","clk":"1362343621","pt":1588442087271,"mc":[{"id":"1.170370564","rc":[{"atb":[[4.7,2.66]],"id":9630572}],"con":true,"img":false}]}
{"op":"mcm","clk":"1362343627","pt":1588442090278,"mc":[{"id":"1.170370564","rc":[{"atb":[[4.7,0]],"id":9630572}],"con":true,"img":false}]}
{"op":"mcm","clk":"1362343630","pt":1588442091810,"mc":[{"id":"1.170370564","rc":[{"atb":[[4.7,2.66]],"id":9630572}],"con":true,"img":false}]}
{"op":"mcm","clk":"1362343631","pt":1588442092475,"mc":[{"id":"1.170370564","rc":[{"trd":[[1.25,2312.93]],"ltp":1.25,"tv":2312.93,"id":8509691},{"atb":[[1.25,451.34]],"id":8509691}],"con":true,"img":false}]}
{"op":"mcm","clk":"1362343633","pt":1588442093371,"mc":[{"id":"1.170370564","rc":[{"atb":[[4.7,0]],"id":9630572}],"con":true,"img":false}]}
{"op":"mcm","clk":"1362343636","pt":1588442094902,"mc":[{"id":"1.170370564","rc":[{"atb":[[4.7,2.66]],"id":9630572}],"con":true,"img":false}]}
{"op":"mcm","clk":"1362343643","pt":1588442097809,"mc":[{"id":"1.170370564","rc":[{"atb":[[4.7,0]],"id":9630572}],"con":true,"img":false}]}
{"op":"mcm","clk":"1362343650","pt":1588442099289,"mc":[{"id":"1.170370564","rc":[{"atb":[[4.7,2.66]],"id":9630572}],"con":true,"img":false}]}
{"op":"mcm","clk":"1362343652","pt":1588442100922,"mc":[{"id":"1.170370564","rc":[{"atb":[[4.7,0]],"id":9630572}],"con":true,"img":false}]}
{"op":"mcm","clk":"1362343654","pt":1588442102509,"mc":[{"id":"1.170370564","rc":[{"atb":[[4.7,2.66]],"id":9630572}],"con":true,"img":false}]}
{"op":"mcm","clk":"1362343712","pt":1588442126021,"mc":[{"id":"1.170370564","rc":[{"atl":[[4.9,5]],"id":9630572},{"atb":[[1.25,456.34]],"id":8509691}],"con":true,"img":false}]}
{"op":"mcm","clk":"1362343893","pt":1588442158068,"mc":[{"id":"1.170370564","rc":[{"trd":[[1.27,2580.6],[1.26,1331.98]],"ltp":1.27,"tv":3912.58,"id":8509691},{"atl":[[1.26,0],[1.27,171.32]],"id":8509691}],"con":true,"img":false}]}
{"op":"mcm","clk":"1362343895","pt":1588442158272,"mc":[{"id":"1.170370564","rc":[{"atl":[[1.28,234.56]],"id":8509691}],"con":true,"img":false}]}
{"op":"mcm","clk":"1362343898","pt":1588442158578,"mc":[{"id":"1.170370564","rc":[{"atb":[[4.7,0]],"id":9630572}],"con":true,"img":false}]}
{"op":"mcm","clk":"1362343899","pt":1588442158782,"mc":[{"id":"1.170370564","rc":[{"atb":[[4.5,2.78]],"id":9630572}],"con":true,"img":false}]}
{"op":"mcm","clk":"1362343904","pt":1588442160410,"mc":[{"id":"1.170370564","rc":[{"atl":[[1.28,224.8]],"id":8509691}],"con":true,"img":false}]}
{"op":"mcm","clk":"1362343906","pt":1588442160564,"mc":[{"id":"1.170370564","rc":[{"atl":[[1.29,1318.74]],"id":8509691}],"con":true,"img":false}]}
{"op":"mcm","clk":"1362343953","pt":1588442172105,"mc":[{"id":"1.170370564","rc":[{"atb":[[4.1,0]],"id":9630572}],"con":true,"img":false}]}
{"op":"mcm","clk":"1362343982","pt":1588442174603,"mc":[{"id":"1.170370564","rc":[{"atb":[[4.1,2.33]],"id":9630572}],"con":true,"img":false}]}
{"op":"mcm","clk":"1362344377","pt":1588442231972,"mc":[{"id":"1.170370564","rc":[{"atl":[[4.9,22.49]],"id":9630572}],"con":true,"img":false}]}
{"op":"mcm","clk":"1362344391","pt":1588442232789,"mc":[{"id":"1.170370564","rc":[{"atb":[[4.5,0]],"id":9630572}],"con":true,"img":false}]}
{"op":"mcm","clk":"1362344396","pt":1588442232992,"mc":[{"id":"1.170370564","rc":[{"atb":[[4.7,2.66]],"id":9630572}],"con":true,"img":false}]}
{"op":"mcm","clk":"1362344437","pt":1588442237999,"mc":[{"id":"1.170370564","rc":[{"atl":[[1.26,10.49]],"id":8509691}],"con":true,"img":false}]}
{"op":"mcm","clk":"1362344534","pt":1588442250010,"mc":[{"id":"1.170370564","rc":[{"trd":[[1.27,2582.66],[1.26,1352.98]],"ltp":1.27,"tv":3935.64,"id":8509691},{"atl":[[1.26,0],[1.27,170.29]],"id":8509691}],"con":true,"img":false}]}
{"op":"mcm","clk":"1362344736","pt":1588442272348,"mc":[{"id":"1.170370564","rc":[{"atl":[[5.1,32.8]],"id":9630572}],"con":true,"img":false}]}
{"op":"mcm","clk":"1362344753","pt":1588442274244,"mc":[{"id":"1.170370564","rc":[{"atb":[[1.26,12]],"id":8509691}],"con":true,"img":false}]}
{"op":"mcm","clk":"1362344762","pt":1588442276343,"mc":[{"id":"1.170370564","rc":[{"atb":[[3.5,0]],"id":9630572},{"atb":[[1.25,233.3]],"id":8509691}],"con":true,"img":false}]}
{"op":"mcm","clk":"1362344775","pt":1588442277366,"mc":[{"id":"1.170370564","rc":[{"atl":[[1.29,1309.06]],"id":8509691}],"con":true,"img":false}]}
{"op":"mcm","clk":"1362344778","pt":1588442277624,"mc":[{"id":"1.170370564","rc":[{"atl":[[1.28,234.56]],"id":8509691}],"con":true,"img":false}]}
{"op":"mcm","clk":"1362344884","pt":1588442291541,"mc":[{"id":"1.170370564","rc":[{"atb":[[4.1,0]],"id":9630572}],"con":true,"img":false}]}
{"op":"mcm","clk":"1362344897","pt":1588442293380,"mc":[{"id":"1.170370564","rc":[{"atb":[[4.1,2.33]],"id":9630572}],"con":true,"img":false}]}
{"op":"mcm","clk":"1362345072","pt":1588442316724,"mc":[{"id":"1.170370564","rc":[{"atb":[[1.25,230.1]],"id":8509691}],"con":true,"img":false}]}
{"op":"mcm","clk":"1362345261","pt":1588442338313,"mc":[{"id":"1.170370565","rc":[{"atl":[[2,0],[1.92,0],[1.9,0]],"id":11269555}],"con":true,"img":false}]}
{"op":"mcm","clk":"1362345275","pt":1588442340047,"mc":[{"id":"1.170370564","rc":[{"atb":[[4.4,0]],"id":9630572}],"con":true,"img":false}]}
{"op":"mcm","clk":"1362345277","pt":1588442340149,"mc":[{"id":"1.170370564","rc":[{"atb":[[4.5,2]],"id":9630572}],"con":true,"img":false}]}
{"op":"mcm","clk":"1362346180","pt":1588442359887,"mc":[{"id":"1.170370564","rc":[{"atb":[[1.26,62]],"id":8509691}],"con":true,"img":false}]}
{"op":"mcm","clk":"1362346199","pt":1588442362085,"mc":[{"id":"1.170370564","rc":[{"atl":[[1.28,224.8]],"id":8509691}],"con":true,"img":false}]}
{"op":"mcm","clk":"1362346370","pt":1588442379976,"mc":[{"id":"1.170370564","rc":[{"atb":[[4.7,5.28]],"id":9630572}],"con":true,"img":false}]}
{"op":"mcm","clk":"1362346509","pt":1588442396533,"mc":[{"id":"1.170370565","rc":[{"atb":[[8,10]],"id":11340557},{"atb":[[7,10]],"id":11340560},{"atb":[[1.73,71.64]],"id":11269555},{"atb":[[3.4,21.79]],"id":11269557}],"con":true,"img":false},{"id":"1.170370566","rc":[{"atb":[[3,26.15]],"id":9630572},{"atb":[[1.33,158.48]],"id":8509691}],"con":true,"img":false},{"id":"1.170370567","rc":[{"atb":[[3.2,23.77]],"id":9630572},{"atb":[[1.3,174.33]],"id":8509691}],"con":true,"img":false}]}
{"op":"mcm","clk":"1362346510","pt":1588442396636,"mc":[{"id":"1.170370565","rc":[{"atb":[[6.4,0]],"id":11340557},{"atb":[[6.4,0]],"id":11340560},{"atb":[[1.82,0]],"id":11269555},{"atb":[[3.3,0]],"id":11269557}],"con":true,"img":false},{"id":"1.170370566","rc":[{"atb":[[2.74,0]],"id":9630572},{"atb":[[1.31,0]],"id":8509691}],"con":true,"img":false},{"id":"1.170370567","rc":[{"atb":[[2.88,0]],"id":9630572},{"atb":[[1.36,0]],"id":8509691}],"con":true,"img":false}]}
{"op":"mcm","clk":"1362346550","pt":1588442400932,"mc":[{"id":"1.170370566","rc":[{"atb":[[3.15,2.62]],"id":9630572}],"con":true,"img":false}]}
{"op":"mcm","clk":"1362346563","pt":1588442402314,"mc":[{"id":"1.170370564","rc":[{"atb":[[4.6,7.38]],"id":9630572},{"atb":[[1.21,88.65]],"id":8509691}],"con":true,"img":false}]}
{"op":"mcm","clk":"1362346666","pt":1588442413648,"mc":[{"id":"1.170370564","rc":[{"atb":[[4.1,0]],"id":9630572}],"con":true,"img":false}]}
{"op":"mcm","clk":"1362346674","pt":1588442414824,"mc":[{"id":"1.170370564","rc":[{"atb":[[4.1,2.33]],"id":9630572}],"con":true,"img":false}]}
{"op":"mcm","clk":"1362346695","pt":1588442417430,"mc":[{"id":"1.170370564","rc":[{"atl":[[1000,3.19]],"id":8509691}],"con":true,"img":false}]}
{"op":"mcm","clk":"1362346698","pt":1588442417942,"mc":[{"id":"1.170370564","rc":[{"atl":[[1000,3.11]],"id":8509691}],"con":true,"img":false}]}
{"op":"mcm","clk":"1362346703","pt":1588442418351,"mc":[{"id":"1.170370564","rc":[{"atl":[[1000,0]],"id":8509691}],"con":true,"img":false}]}
{"op":"mcm","clk":"1362346704","pt":1588442418454,"mc":[{"id":"1.170370564","rc":[{"trd":[[1.26,1359.22]],"ltp":1.26,"tv":1359.22,"id":8509691},{"atb":[[1.26,58.88]],"id":8509691}],"con":true,"img":false}]}
{"op":"mcm","clk":"1362346718","pt":1588442420142,"mc":[{"id":"1.170370564","rc":[{"atl":[[1.28,218.4]],"id":8509691}],"con":true,"img":false}]}
{"op":"mcm","clk":"1362346740","pt":1588442422446,"mc":[{"id":"1.170370564","rc":[{"trd":[[1.26,1476.98]],"ltp":1.26,"tv":1476.98,"id":8509691},{"atb":[[1.26,0]],"id":8509691},{"atl":[[1.26,16.37]],"id":8509691}],"con":true,"img":false}]}
{"op":"mcm","clk":"1362346742","pt":1588442422855,"mc":[{"id":"1.170370564","rc":[{"atl":[[1.28,228.16]],"id":8509691}],"con":true,"img":false}]}
{"op":"mcm","clk":"1362346748","pt":1588442423467,"mc":[{"id":"1.170370564","rc":[{"atb":[[1.2,132.97]],"id":8509691}],"con":true,"img":false}]}
{"op":"mcm","clk":"1362346750","pt":1588442423570,"mc":[{"id":"1.170370564","rc":[{"atb":[[1.21,0]],"id":8509691}],"con":true,"img":false}]}
{"op":"mcm","clk":"1362346755","pt":1588442424133,"mc":[{"id":"1.170370564","rc":[{"atl":[[1.28,129.76]],"id":8509691}],"con":true,"img":false}]}
{"op":"mcm","clk":"1362346762","pt":1588442424952,"mc":[{"id":"1.170370564","rc":[{"atl":[[1.26,0]],"id":8509691}],"con":true,"img":false}]}
{"op":"mcm","clk":"1362346765","pt":1588442425360,"mc":[{"id":"1.170370564","rc":[{"atb":[[1.21,88.65]],"id":8509691}],"con":true,"img":false}]}
{"op":"mcm","clk":"1362346767","pt":1588442425565,"mc":[{"id":"1.170370564","rc":[{"trd":[[1.25,2345.95]],"ltp":1.25,"tv":2345.95,"id":8509691},{"atb":[[1.25,213.59]],"id":8509691}],"con":true,"img":false}]}
{"op":"mcm","clk":"1362346775","pt":1588442426537,"mc":[{"id":"1.170370564","rc":[{"atb":[[4,18.58]],"id":9630572},{"atb":[[1.2,411.77]],"id":8509691}],"con":true,"img":false}]}
{"op":"mcm","clk":"1362346784","pt":1588442427666,"mc":[{"id":"1.170370564","rc":[{"atb":[[1.2,367.45],[1.18,0],[1.12,0],[1.23,87.47],[1.14,0],[1.16,0],[1.13,18.93],[1.24,50]],"id":8509691},{"atl":[[1.34,0],[1.42,0]],"id":8509691}],"con":true,"img":false}]}
{"op":"mcm","clk":"1362346816","pt":1588442431653,"mc":[{"id":"1.170370564","rc":[{"atl":[[1.27,220.29]],"id":8509691}],"con":true,"img":false}]}
{"op":"mcm","clk":"1362346842","pt":1588442434982,"mc":[{"id":"1.170370564","rc":[{"atb":[[4.5,4.1],[4.6,9.42]],"id":9630572},{"atl":[[5.1,34.85],[5.2,2.03]],"id":9630572},{"atb":[[1.23,89.49],[1.22,4.02]],"id":8509691},{"atl":[[1.3,2.05],[1.29,1311.08]],"id":8509691}],"con":true,"img":false}]}
{"op":"mcm","clk":"1362346963","pt":1588442449102,"mc":[{"id":"1.170370564","rc":[{"atl":[[1.26,176.64]],"id":8509691}],"con":true,"img":false}]}
{"op":"mcm","clk":"1362346965","pt":1588442449306,"mc":[{"id":"1.170370564","rc":[{"atl":[[1.28,131.76]],"id":8509691}],"con":true,"img":false}]}
{"op":"mcm","clk":"1362346966","pt":1588442449410,"mc":[{"id":"1.170370564","rc":[{"atb":[[4.5,2]],"id":9630572},{"atl":[[5.2,0]],"id":9630572},{"atb":[[1.22,2]],"id":8509691},{"atl":[[1.3,0]],"id":8509691}],"con":true,"img":false}]}
{"op":"mcm","clk":"1362346969","pt":1588442449672,"mc":[{"id":"1.170370564","rc":[{"atl":[[1.29,1309.06]],"id":8509691}],"con":true,"img":false}]}
{"op":"mcm","clk":"1362346971","pt":1588442449880,"mc":[{"id":"1.170370564","rc":[{"atb":[[4.5,4.1]],"id":9630572},{"atl":[[5.2,2.03]],"id":9630572},{"atb":[[1.22,4]],"id":8509691},{"atl":[[1.29,1311.08]],"id":8509691}],"con":true,"img":false}]}
{"op":"mcm","clk":"1362346973","pt":1588442449975,"mc":[{"id":"1.170370564","rc":[{"atl":[[1.28,122]],"id":8509691}],"con":true,"img":false}]}
{"op":"mcm","clk":"1362346976","pt":1588442450283,"mc":[{"id":"1.170370564","rc":[{"atb":[[4.7,2.62]],"id":9630572}],"con":true,"img":false}]}
{"op":"mcm","clk":"1362346980","pt":1588442450487,"mc":[{"id":"1.170370564","rc":[{"atb":[[4.8,10.66]],"id":9630572}],"con":true,"img":false}]}
{"op":"mcm","clk":"1362346990","pt":1588442451711,"mc":[{"id":"1.170370564","rc":[{"atb":[[4,0]],"id":9630572},{"atb":[[1.2,88.65]],"id":8509691}],"con":true,"img":false}]}
{"op":"mcm","clk":"1362347047","pt":1588442458013,"mc":[{"id":"1.170370565","rc":[{"atb":[[8.2,2.62]],"id":11340557}],"con":true,"img":false}]}
{"op":"mcm","clk":"1362347180","pt":1588442474110,"mc":[{"id":"1.170370564","rc":[{"atl":[[4.9,5]],"id":9630572}],"con":true,"img":false}]}
{"op":"mcm","clk":"1362347185","pt":1588442474413,"mc":[{"id":"1.170370564","rc":[{"atb":[[4.5,2]],"id":9630572},{"atl":[[5.2,0]],"id":9630572},{"atb":[[1.22,2]],"id":8509691},{"atl":[[1.29,1309.06]],"id":8509691}],"con":true,"img":false}]}
{"op":"mcm","clk":"1362347187","pt":1588442474619,"mc":[{"id":"1.170370564","rc":[{"atb":[[4.5,4]],"id":9630572},{"atl":[[5.2,2]],"id":9630572},{"atb":[[1.22,4.02]],"id":8509691},{"atl":[[1.29,1311.06]],"id":8509691}],"con":true,"img":false}]}
{"op":"mcm","clk":"1362347342","pt":1588442492346,"mc":[{"id":"1.170370564","rc":[{"trd":[[1.26,1743.06]],"ltp":1.26,"tv":1743.06,"id":8509691},{"atl":[[1.26,43.6]],"id":8509691}],"con":true,"img":false}]}
{"op":"mcm","clk":"1362347351","pt":1588442492752,"mc":[{"id":"1.170370564","rc":[{"atb":[[4.5,2]],"id":9630572},{"atl":[[5.2,0]],"id":9630572},{"atb":[[1.22,2]],"id":8509691},{"atl":[[1.29,1309.06]],"id":8509691}],"con":true,"img":false}]}
{"op":"mcm","clk":"1362347353","pt":1588442492955,"mc":[{"id":"1.170370564","rc":[{"atb":[[4.5,4.1]],"id":9630572},{"atl":[[5.2,2.03]],"id":9630572},{"atb":[[1.22,4.02]],"id":8509691},{"atl":[[1.29,1311.08]],"id":8509691}],"con":true,"img":false}]}
{"op":"mcm","clk":"1362347357","pt":1588442493465,"mc":[{"id":"1.170370564","rc":[{"atb":[[1.21,0]],"id":8509691}],"con":true,"img":false}]}
{"op":"mcm","clk":"1362347364","pt":1588442494240,"mc":[{"id":"1.170370564","rc":[{"atb":[[4.8,8.05]],"id":9630572}],"con":true,"img":false}]}
{"op":"mcm","clk":"1362347365","pt":1588442494444,"mc":[{"id":"1.170370564","rc":[{"atb":[[4.7,5.28]],"id":9630572}],"con":true,"img":false}]}
{"op":"mcm","clk":"1362347384","pt":1588442496640,"mc":[{"id":"1.170370564","rc":[{"atb":[[4,18.58]],"id":9630572},{"atb":[[1.2,367.45]],"id":8509691}],"con":true,"img":false}]}
{"op":"mcm","clk":"1362347446","pt":1588442504135,"mc":[{"id":"1.170370564","rc":[{"trd":[[1.26,1765.22]],"ltp":1.26,"tv":1765.22,"id":8509691},{"atl":[[1.26,32.52]],"id":8509691}],"con":true,"img":false}]}
{"op":"mcm","clk":"1362347449","pt":1588442504442,"mc":[{"id":"1.170370564","rc":[{"atb":[[4.5,2]],"id":9630572},{"atl":[[5.2,0]],"id":9630572},{"atb":[[1.22,2]],"id":8509691},{"atl":[[1.29,1309.06]],"id":8509691}],"con":true,"img":false}]}
{"op":"mcm","clk":"1362347450","pt":1588442504545,"mc":[{"id":"1.170370564","rc":[{"atb":[[4.5,4.1]],"id":9630572},{"atl":[[5.2,2.03]],"id":9630572},{"atb":[[1.22,4.02]],"id":8509691},{"atl":[[1.29,1311.25]],"id":8509691}],"con":true,"img":false}]}
{"op":"mcm","clk":"1362347502","pt":1588442510765,"mc":[{"id":"1.170370564","rc":[{"trd":[[1.26,1830.26]],"ltp":1.26,"tv":1830.26,"id":8509691},{"atb":[[1.26,17.48]],"id":8509691},{"atl":[[1.26,0]],"id":8509691}],"con":true,"img":false}]}
{"op":"mcm","clk":"1362347504","pt":1588442510970,"mc":[{"id":"1.170370564","rc":[{"atb":[[1.24,52.02]],"id":8509691},{"atl":[[1.3,2.05]],"id":8509691}],"con":true,"img":false}]}
{"op":"mcm","clk":"1362347505","pt":1588442511072,"mc":[{"id":"1.170370564","rc":[{"atb":[[4.5,2]],"id":9630572},{"atl":[[5.2,0]],"id":9630572},{"atb":[[1.22,2]],"id":8509691},{"atl":[[1.28,120]],"id":8509691}],"con":true,"img":false}]}
{"op":"mcm","clk":"1362347509","pt":1588442511280,"mc":[{"id":"1.170370564","rc":[{"atb":[[1.23,87.47]],"id":8509691}],"con":true,"img":false}]}
{"op":"mcm","clk":"1362347511","pt":1588442511377,"mc":[{"id":"1.170370564","rc":[{"atb":[[4.5,4]],"id":9630572},{"atl":[[5.2,2.03]],"id":9630572}],"con":true,"img":false}]}
{"op":"mcm","clk":"1362347513","pt":1588442511477,"mc":[{"id":"1.170370564","rc":[{"atb":[[1.21,88.65],[1.23,89.49]],"id":8509691}],"con":true,"img":false}]}
{"op":"mcm","clk":"1362347517","pt":1588442511886,"mc":[{"id":"1.170370564","rc":[{"atb":[[4,0]],"id":9630572},{"atb":[[1.2,88.65]],"id":8509691}],"con":true,"img":false}]}
{"op":"mcm","clk":"1362347580","pt":1588442519396,"mc":[{"id":"1.170370564","rc":[{"atl":[[1.28,170]],"id":8509691}],"con":true,"img":false}]}
{"op":"mcm","clk":"1362347586","pt":1588442519760,"mc":[{"id":"1.170370564","rc":[{"atb":[[4.5,2]],"id":9630572},{"atl":[[5.2,0]],"id":9630572},{"atb":[[1.23,87.47]],"id":8509691},{"atl":[[1.3,0]],"id":8509691}],"con":true,"img":false}]}
{"op":"mcm","clk":"1362347589","pt":1588442519964,"mc":[{"id":"1.170370564","rc":[{"atb":[[4.5,4.1]],"id":9630572},{"atl":[[5.2,2.03]],"id":9630572},{"atb":[[1.23,89.49]],"id":8509691},{"atl":[[1.3,2]],"id":8509691}],"con":true,"img":false}]}
{"op":"mcm","clk":"1362347754","pt":1588442536878,"mc":[{"id":"1.170370564","rc":[{"atb":[[4.1,0]],"id":9630572}],"con":true,"img":false}]}
{"op":"mcm","clk":"1362347757","pt":1588442537185,"mc":[{"id":"1.170370564","rc":[{"atb":[[4.5,2]],"id":9630572},{"atl":[[5.2,0]],"id":9630572},{"atb":[[1.23,87.47]],"id":8509691},{"atl":[[1.3,0]],"id":8509691}],"con":true,"img":false}]}
{"op":"mcm","clk":"1362347759","pt":1588442537388,"mc":[{"id":"1.170370564","rc":[{"atb":[[4.5,4.1]],"id":9630572},{"atl":[[5.2,2.03]],"id":9630572},{"atb":[[1.23,89.49]],"id":8509691},{"atl":[[1.3,2.05]],"id":8509691}],"con":true,"img":false}]}
{"op":"mcm","clk":"1362347768","pt":1588442538099,"mc":[{"id":"1.170370564","rc":[{"atb":[[4.1,2.33]],"id":9630572}],"con":true,"img":false}]}
{"op":"mcm","clk":"1362348326","pt":1588442598176,"mc":[{"id":"1.170370564","rc":[{"atl":[[1.33,6.39]],"id":8509691}],"con":true,"img":false}]}
{"op":"mcm","clk":"1362348330","pt":1588442598483,"mc":[{"id":"1.170370564","rc":[{"atb":[[4.5,2]],"id":9630572},{"atl":[[5.2,0]],"id":9630572},{"atb":[[1.23,87.47]],"id":8509691},{"atl":[[1.3,0]],"id":8509691}],"con":true,"img":false}]}
{"op":"mcm","clk":"1362348331","pt":1588442598686,"mc":[{"id":"1.170370564","rc":[{"atb":[[4.5,4]],"id":9630572},{"atl":[[5.2,2.03]],"id":9630572},{"atb":[[1.23,89.49]],"id":8509691},{"atl":[[1.3,2]],"id":8509691}],"con":true,"img":false}]}
{"op":"mcm","clk":"1362348486","pt":1588442618010,"mc":[{"id":"1.170370564","rc":[{"trd":[[1.26,1865.22]],"ltp":1.26,"tv":1865.22,"id":8509691},{"atb":[[1.26,0]],"id":8509691},{"atl":[[1.26,8.52]],"id":8509691}],"con":true,"img":false}]}
{"op":"mcm","clk":"1362348488","pt":1588442618215,"mc":[{"id":"1.170370564","rc":[{"atb":[[1.22,4.02]],"id":8509691},{"atl":[[1.28,172.09]],"id":8509691}],"con":true,"img":false}]}
{"op":"mcm","clk":"1362348489","pt":1588442618316,"mc":[{"id":"1.170370564","rc":[{"atb":[[4.5,2]],"id":9630572},{"atl":[[5.2,0]],"id":9630572},{"atl":[[1.3,0]],"id":8509691}],"con":true,"img":false}]}
{"op":"mcm","clk":"1362348492","pt":1588442618520,"mc":[{"id":"1.170370564","rc":[{"atb":[[1.21,0],[1.24,50]],"id":8509691},{"atl":[[1.27,230.13]],"id":8509691}],"con":true,"img":false}]}
{"op":"mcm","clk":"1362348496","pt":1588442618724,"mc":[{"id":"1.170370564","rc":[{"atb":[[4.5,4]],"id":9630572},{"atl":[[5.2,2]],"id":9630572}],"con":true,"img":false}]}
{"op":"mcm","clk":"1362348497","pt":1588442618826,"mc":[{"id":"1.170370564","rc":[{"atl":[[1.29,1309.06]],"id":8509691}],"con":true,"img":false}]}
{"op":"mcm","clk":"1362348500","pt":1588442619031,"mc":[{"id":"1.170370564","rc":[{"atl":[[1.29,1311.08]],"id":8509691}],"con":true,"img":false}]}
{"op":"mcm","clk":"1362348522","pt":1588442621940,"mc":[{"id":"1.170370564","rc":[{"atb":[[4,18.58]],"id":9630572},{"atb":[[1.2,367.45]],"id":8509691}],"con":true,"img":false}]}
{"op":"mcm","clk":"1362348598","pt":1588442630932,"mc":[{"id":"1.170370566","rc":[{"trd":[[1.33,1.68]],"ltp":1.33,"tv":1.68,"id":8509691},{"atb":[[1.33,157.64]],"id":8509691}],"con":true,"img":false}]}
{"op":"mcm","clk":"1362348616","pt":1588442632517,"mc":[{"id":"1.170370566","rc":[{"atb":[[1.33,316.11]],"id":8509691}],"con":true,"img":false}]}
{"op":"mcm","clk":"1362348618","pt":1588442632618,"mc":[{"id":"1.170370566","rc":[{"atb":[[1.33,158.48]],"id":8509691}],"con":true,"img":false}]}
{"op":"mcm","clk":"1362348785","pt":1588442652776,"mc":[{"id":"1.170370564","rc":[{"atb":[[4.1,0]],"id":9630572}],"con":true,"img":false}]}
{"op":"mcm","clk":"1362348788","pt":1588442653085,"mc":[{"id":"1.170370564","rc":[{"atb":[[4.5,2]],"id":9630572},{"atl":[[5.2,0]],"id":9630572},{"atb":[[1.22,2]],"id":8509691},{"atl":[[1.29,1309.06]],"id":8509691}],"con":true,"img":false}]}
{"op":"mcm","clk":"1362348790","pt":1588442653289,"mc":[{"id":"1.170370564","rc":[{"atb":[[4.5,4]],"id":9630572},{"atl":[[5.2,2.03]],"id":9630572},{"atb":[[1.22,4.02]],"id":8509691},{"atl":[[1.29,1311.06]],"id":8509691}],"con":true,"img":false}]}
{"op":"mcm","clk":"1362348799","pt":1588442654566,"mc":[{"id":"1.170370564","rc":[{"atb":[[4.1,2.33]],"id":9630572}],"con":true,"img":false}]}
{"op":"mcm","clk":"1362349114","pt":1588442689983,"mc":[{"id":"1.170370564","rc":[{"trd":[[1.26,1882.26]],"ltp":1.26,"tv":1882.26,"id":8509691},{"atb":[[1.26,35.21]],"id":8509691},{"atl":[[1.26,0]],"id":8509691}],"con":true,"img":false}]}
{"op":"mcm","clk":"1362349115","pt":1588442690085,"mc":[{"id":"1.170370564","rc":[{"atb":[[1.24,52.02]],"id":8509691},{"atl":[[1.3,2.05]],"id":8509691}],"con":true,"img":false}]}
{"op":"mcm","clk":"1362349116","pt":1588442690289,"mc":[{"id":"1.170370564","rc":[{"atb":[[4.5,2]],"id":9630572},{"atl":[[5.2,0]],"id":9630572},{"atb":[[1.22,2]],"id":8509691},{"atl":[[1.28,170]],"id":8509691}],"con":true,"img":false}]}
{"op":"mcm","clk":"1362349119","pt":1588442690492,"mc":[{"id":"1.170370564","rc":[{"atb":[[1.21,88.65]],"id":8509691}],"con":true,"img":false}]}
{"op":"mcm","clk":"1362349120","pt":1588442690594,"mc":[{"id":"1.170370564","rc":[{"atb":[[1.23,87.47]],"id":8509691}],"con":true,"img":false}]}
{"op":"mcm","clk":"1362349123","pt":1588442690798,"mc":[{"id":"1.170370564","rc":[{"atb":[[4.5,4.1]],"id":9630572},{"atl":[[5.2,2.03]],"id":9630572},{"atb":[[1.23,89.49]],"id":8509691}],"con":true,"img":false}]}
{"op":"mcm","clk":"1362349126","pt":1588442691104,"mc":[{"id":"1.170370564","rc":[{"atl":[[1.27,220.29]],"id":8509691}],"con":true,"img":false}]}
{"op":"mcm","clk":"1362349132","pt":1588442692225,"mc":[{"id":"1.170370564","rc":[{"atb":[[4,0]],"id":9630572},{"atb":[[1.2,88.65]],"id":8509691}],"con":true,"img":false}]}
{"op":"mcm","clk":"1362349584","pt":1588442745545,"mc":[{"id":"1.170370564","rc":[{"trd":[[1.26,1885.81]],"ltp":1.26,"tv":1885.81,"id":8509691},{"atb":[[1.26,33.43]],"id":8509691}],"con":true,"img":false}]}
{"op":"mcm","clk":"1362349586","pt":1588442745850,"mc":[{"id":"1.170370564","rc":[{"atb":[[4.5,2]],"id":9630572},{"atl":[[5.2,0]],"id":9630572},{"atb":[[1.23,87.47]],"id":8509691},{"atl":[[1.3,0]],"id":8509691}],"con":true,"img":false}]}
{"op":"mcm","clk":"1362349589","pt":1588442746054,"mc":[{"id":"1.170370564","rc":[{"atb":[[4.5,4.1]],"id":9630572},{"atl":[[5.2,2.03]],"id":9630572},{"atb":[[1.23,89.49]],"id":8509691},{"atl":[[1.3,2.05]],"id":8509691}],"con":true,"img":false}]}
{"op":"mcm","clk":"1362349622","pt":1588442750279,"mc":[{"id":"1.170370564","rc":[{"trd":[[1.27,2618.74]],"ltp":1.27,"tv":2618.74,"id":8509691},{"atl":[[1.27,202.25]],"id":8509691}],"con":true,"img":false}]}
{"op":"mcm","clk":"1362349894","pt":1588442776259,"mc":[{"id":"1.170370564","rc":[{"atl":[[1.27,204.25]],"id":8509691}],"con":true,"img":false}]}
{"op":"mcm","clk":"1362349897","pt":1588442776566,"mc":[{"id":"1.170370564","rc":[{"atb":[[4.5,2]],"id":9630572},{"atl":[[5.2,0]],"id":9630572},{"atb":[[1.23,87.47]],"id":8509691},{"atl":[[1.3,0]],"id":8509691}],"con":true,"img":false}]}
{"op":"mcm","clk":"1362349900","pt":1588442776770,"mc":[{"id":"1.170370564","rc":[{"atb":[[4.5,4.1]],"id":9630572},{"atl":[[5.2,2.03]],"id":9630572},{"atb":[[1.23,89.49]],"id":8509691},{"atl":[[1.3,2.02]],"id":8509691}],"con":true,"img":false}]}
{"op":"mcm","clk":"1362349949","pt":1588442781206,"mc":[{"id":"1.170370564","rc":[{"atb":[[4.1,0]],"id":9630572}],"con":true,"img":false}]}
{"op":"mcm","clk":"1362349960","pt":1588442782278,"mc":[{"id":"1.170370564","rc":[{"atb":[[4.1,2.33]],"id":9630572}],"con":true,"img":false}]}
{"op":"mcm","clk":"1362349964","pt":1588442782583,"mc":[{"id":"1.170370564","rc":[{"atb":[[4.5,2]],"id":9630572},{"atl":[[5.2,0]],"id":9630572},{"atb":[[1.23,87.47]],"id":8509691},{"atl":[[1.3,0]],"id":8509691}],"con":true,"img":false}]}
{"op":"mcm","clk":"1362349968","pt":1588442782788,"mc":[{"id":"1.170370564","rc":[{"atb":[[4.5,4.1]],"id":9630572},{"atl":[[5.2,2]],"id":9630572},{"atb":[[1.23,89.49]],"id":8509691},{"atl":[[1.3,2.05]],"id":8509691}],"con":true,"img":false}]}
{"op":"mcm","clk":"1362350152","pt":1588442800531,"mc":[{"id":"1.170370565","rc":[{"atb":[[1.67,0]],"id":11269555}],"con":true,"img":false}]}
{"op":"mcm","clk":"1362350154","pt":1588442800735,"mc":[{"id":"1.170370565","rc":[{"atb":[[3.35,0]],"id":11269557}],"con":true,"img":false}]}
{"op":"mcm","clk":"1362350157","pt":1588442800939,"mc":[{"id":"1.170370565","rc":[{"atb":[[6.6,0]],"id":11340557}],"con":true,"img":false}]}
{"op":"mcm","clk":"1362350160","pt":1588442801091,"mc":[{"id":"1.170370565","rc":[{"atb":[[6.6,0]],"id":11340560}],"con":true,"img":false}]}
{"op":"mcm","clk":"1362350162","pt":1588442801295,"mc":[{"id":"1.170370565","rc":[{"atl":[[1.89,0]],"id":11269555}],"con":true,"img":false}]}
{"op":"mcm","clk":"1362350165","pt":1588442801499,"mc":[{"id":"1.170370565","rc":[{"atl":[[5.1,0]],"id":11269557}],"con":true,"img":false}]}
{"op":"mcm","clk":"1362350167","pt":1588442801702,"mc":[{"id":"1.170370565","rc":[{"atl":[[9.4,0]],"id":11340557}],"con":true,"img":false}]}
{"op":"mcm","clk":"1362350170","pt":1588442801906,"mc":[{"id":"1.170370565","rc":[{"atl":[[12.5,0]],"id":11340560}],"con":true,"img":false}]}
{"op":"mcm","clk":"1362350179","pt":1588442802721,"mc":[{"id":"1.170370565","rc":[{"atb":[[8,16]],"id":11340557},{"atb":[[7.2,6]],"id":11340560},{"atb":[[1.67,9]],"id":11269555},{"atb":[[3.45,5]],"id":11269557}],"con":true,"img":false}]}
{"op":"mcm","clk":"1362350182","pt":1588442803027,"mc":[{"id":"1.170370564","rc":[{"atl":[[1.6,0.75]],"id":8509691}],"con":true,"img":false}]}
{"op":"mcm","clk":"1362350189","pt":1588442803333,"mc":[{"id":"1.170370564","rc":[{"atb":[[4.5,2]],"id":9630572},{"atl":[[5.2,0]],"id":9630572},{"atb":[[1.23,87.47]],"id":8509691},{"atl":[[1.3,0]],"id":8509691}],"con":true,"img":false}]}
{"op":"mcm","clk":"1362350190","pt":1588442803435,"mc":[{"id":"1.170370564","rc":[{"atb":[[4.5,4.1]],"id":9630572},{"atl":[[5.2,2.03]],"id":9630572},{"atb":[[1.23,89.49]],"id":8509691},{"atl":[[1.3,2.05]],"id":8509691}],"con":true,"img":false}]}
{"op":"mcm","clk":"1362350440","pt":1588442830373,"mc":[{"id":"1.170370564","rc":[{"trd":[[4.8,131.38]],"ltp":4.8,"tv":131.38,"id":9630572},{"atb":[[4.8,2.73]],"id":9630572}],"con":true,"img":false}]}
{"op":"mcm","clk":"1362350443","pt":1588442830677,"mc":[{"id":"1.170370564","rc":[{"atb":[[4.5,2]],"id":9630572},{"atl":[[5.2,0]],"id":9630572},{"atb":[[1.23,87.47]],"id":8509691},{"atl":[[1.3,0]],"id":8509691}],"con":true,"img":false}]}
{"op":"mcm","clk":"1362350445","pt":1588442830829,"mc":[{"id":"1.170370564","rc":[{"atb":[[4.5,4.1]],"id":9630572},{"atl":[[5.2,2]],"id":9630572},{"atb":[[1.23,89.49]],"id":8509691},{"atl":[[1.3,2.05]],"id":8509691}],"con":true,"img":false}]}
{"op":"mcm","clk":"1362350452","pt":1588442831542,"mc":[{"id":"1.170370564","rc":[{"atb":[[4.5,11.69],[4.6,2.04]],"id":9630572}],"con":true,"img":false}]}
{"op":"mcm","clk":"1362350463","pt":1588442832356,"mc":[{"id":"1.170370564","rc":[{"atb":[[4,18.58]],"id":9630572},{"atb":[[1.2,367.45]],"id":8509691}],"con":true,"img":false}]}
{"op":"mcm","clk":"1362350500","pt":1588442835564,"mc":[{"id":"1.170370564","rc":[{"trd":[[1.27,2618.77]],"ltp":1.27,"tv":2618.77,"id":8509691},{"atl":[[1.27,204.24]],"id":8509691}],"con":true,"img":false}]}
{"op":"mcm","clk":"1362350786","pt":1588442863403,"mc":[{"id":"1.170370565","rc":[{"atl":[[9.4,6]],"id":11340557},{"atl":[[12.5,6]],"id":11340560},{"atl":[[1.75,4.5]],"id":11269555},{"atl":[[5.1,4]],"id":11269557}],"con":true,"img":false}]}
{"op":"mcm","clk":"1362350900","pt":1588442878235,"mc":[{"id":"1.170370564","rc":[{"trd":[[1.27,2623.57]],"ltp":1.27,"tv":2623.57,"id":8509691},{"atl":[[1.27,201.84]],"id":8509691}],"con":true,"img":false}]}
{"op":"mcm","clk":"1362350905","pt":1588442878490,"mc":[{"id":"1.170370564","rc":[{"atb":[[4.5,9.59]],"id":9630572},{"atl":[[5.2,0]],"id":9630572},{"atb":[[1.23,87.47]],"id":8509691},{"atl":[[1.3,0]],"id":8509691}],"con":true,"img":false}]}
{"op":"mcm","clk":"1362350907","pt":1588442878694,"mc":[{"id":"1.170370564","rc":[{"atb":[[4.5,11.69]],"id":9630572},{"atl":[[5.2,2.03]],"id":9630572},{"atb":[[1.23,89.49]],"id":8509691},{"atl":[[1.3,2.05]],"id":8509691}],"con":true,"img":false}]}
{"op":"mcm","clk":"1362350923","pt":1588442880892,"mc":[{"id":"1.170370564","rc":[{"atb":[[1.26,77.87]],"id":8509691}],"con":true,"img":false}]}
{"op":"mcm","clk":"1362350929","pt":1588442881609,"mc":[{"id":"1.170370564","rc":[{"atb":[[1.22,90.65]],"id":8509691}],"con":true,"img":false}]}
{"op":"mcm","clk":"1362351003","pt":1588442890340,"mc":[{"id":"1.170370564","rc":[{"atb":[[4.1,0]],"id":9630572}],"con":true,"img":false}]}
{"op":"mcm","clk":"1362351006","pt":1588442890645,"mc":[{"id":"1.170370564","rc":[{"atb":[[4.5,9.59]],"id":9630572},{"atl":[[5.2,0]],"id":9630572},{"atb":[[1.23,87.47]],"id":8509691},{"atl":[[1.3,0]],"id":8509691}],"con":true,"img":false}]}
{"op":"mcm","clk":"1362351008","pt":1588442890848,"mc":[{"id":"1.170370564","rc":[{"atb":[[4.5,11.69]],"id":9630572},{"atl":[[5.2,2.03]],"id":9630572},{"atb":[[1.23,89.49]],"id":8509691},{"atl":[[1.3,2.05]],"id":8509691}],"con":true,"img":false}]}
{"op":"mcm","clk":"1362351112","pt":1588442902718,"mc":[{"id":"1.170370564","rc":[{"atb":[[4.1,2.33]],"id":9630572}],"con":true,"img":false}]}
{"op":"mcm","clk":"1362351115","pt":1588442903022,"mc":[{"id":"1.170370564","rc":[{"atb":[[4.5,9.59]],"id":9630572},{"atl":[[5.2,0]],"id":9630572},{"atb":[[1.23,87.47]],"id":8509691},{"atl":[[1.3,0]],"id":8509691}],"con":true,"img":false}]}
{"op":"mcm","clk":"1362351120","pt":1588442903227,"mc":[{"id":"1.170370564","rc":[{"atb":[[4.5,11.59]],"id":9630572},{"atl":[[5.2,2.03]],"id":9630572},{"atb":[[1.23,89.49]],"id":8509691},{"atl":[[1.3,2.05]],"id":8509691}],"con":true,"img":false}]}
{"op":"mcm","clk":"1362351582","pt":1588442954817,"mc":[{"id":"1.170370564","rc":[{"trd":[[1.26,1943.81]],"ltp":1.26,"tv":1943.81,"id":8509691},{"atb":[[1.26,48.87]],"id":8509691}],"con":true,"img":false}]}
{"op":"mcm","clk":"1362351586","pt":1588442955122,"mc":[{"id":"1.170370564","rc":[{"atb":[[4.5,9.59]],"id":9630572},{"atl":[[5.2,0]],"id":9630572},{"atb":[[1.23,87.47]],"id":8509691},{"atl":[[1.3,0]],"id":8509691}],"con":true,"img":false}]}
{"op":"mcm","clk":"1362351590","pt":1588442955326,"mc":[{"id":"1.170370564","rc":[{"atb":[[4.5,11.69]],"id":9630572},{"atl":[[5.2,2.03]],"id":9630572},{"atb":[[1.23,89.49]],"id":8509691},{"atl":[[1.3,2.05]],"id":8509691}],"con":true,"img":false}]}
{"op":"mcm","clk":"1362351595","pt":1588442955733,"mc":[{"id":"1.170370564","rc":[{"atb":[[1.22,2]],"id":8509691}],"con":true,"img":false}]}
{"op":"mcm","clk":"1362351838","pt":1588442986944,"mc":[{"id":"1.170370564","rc":[{"trd":[[1.26,2041.56]],"ltp":1.26,"tv":2041.56,"id":8509691},{"atb":[[1.26,0]],"id":8509691},{"atl":[[1.26,173.12]],"id":8509691}],"con":true,"img":false}]}
{"op":"mcm","clk":"1362351842","pt":1588442987146,"mc":[{"id":"1.170370564","rc":[{"atb":[[1.22,4.02]],"id":8509691},{"atl":[[1.28,172.09]],"id":8509691}],"con":true,"img":false}]}
{"op":"mcm","clk":"1362351845","pt":1588442987248,"mc":[{"id":"1.170370564","rc":[{"atb":[[1.24,50]],"id":8509691},{"atl":[[1.3,0]],"id":8509691}],"con":true,"img":false}]}
{"op":"mcm","clk":"1362351848","pt":1588442987350,"mc":[{"id":"1.170370564","rc":[{"atb":[[4.5,9.59]],"id":9630572},{"atl":[[5.2,0]],"id":9630572}],"con":true,"img":false}]}
{"op":"mcm","clk":"1362351853","pt":1588442987554,"mc":[{"id":"1.170370564","rc":[{"atb":[[4.5,11.69]],"id":9630572},{"atl":[[5.2,2.03]],"id":9630572},{"atl":[[1.29,1309.06]],"id":8509691}],"con":true,"img":false}]}
{"op":"mcm","clk":"1362351856","pt":1588442987605,"mc":[{"id":"1.170370564","rc":[{"atb":[[4.6,9.42]],"id":9630572}],"con":true,"img":false}]}
{"op":"mcm","clk":"1362351858","pt":1588442987710,"mc":[{"id":"1.170370564","rc":[{"atl":[[1.29,1311.25]],"id":8509691}],"con":true,"img":false}]}
{"op":"mcm","clk":"1362352032","pt":1588443009458,"mc":[{"id":"1.170370564","rc":[{"atb":[[4.1,0]],"id":9630572}],"con":true,"img":false}]}
{"op":"mcm","clk":"1362352035","pt":1588443009765,"mc":[{"id":"1.170370564","rc":[{"atb":[[4.5,9.59]],"id":9630572},{"atl":[[5.2,0]],"id":9630572},{"atb":[[1.22,2]],"id":8509691},{"atl":[[1.29,1309.06]],"id":8509691}],"con":true,"img":false}]}
{"op":"mcm","clk":"1362352039","pt":1588443009971,"mc":[{"id":"1.170370564","rc":[{"atb":[[4.5,11.69]],"id":9630572},{"atl":[[5.2,2.03]],"id":9630572},{"atb":[[1.22,4.02]],"id":8509691},{"atl":[[1.29,1311.25]],"id":8509691}],"con":true,"img":false}]}
{"op":"mcm","clk":"1362352073","pt":1588443013540,"mc":[{"id":"1.170370564","rc":[{"atb":[[4.1,2.33]],"id":9630572}],"con":true,"img":false}]}
{"op":"mcm","clk":"1362352158","pt":1588443022974,"mc":[{"id":"1.170370564","rc":[{"atb":[[1.25,266.08]],"id":8509691}],"con":true,"img":false}]}
{"op":"mcm","clk":"1362352160","pt":1588443023278,"mc":[{"id":"1.170370564","rc":[{"atb":[[4.5,9.59]],"id":9630572},{"atl":[[5.2,0]],"id":9630572},{"atb":[[1.22,2]],"id":8509691},{"atl":[[1.29,1309.06]],"id":8509691}],"con":true,"img":false}]}
{"op":"mcm","clk":"1362352163","pt":1588443023483,"mc":[{"id":"1.170370564","rc":[{"atb":[[4.5,11.59]],"id":9630572},{"atl":[[5.2,2.03]],"id":9630572},{"atb":[[1.22,4.02]],"id":8509691},{"atl":[[1.29,1311.25]],"id":8509691}],"con":true,"img":false}]}
{"op":"mcm","clk":"1362352165","pt":1588443023687,"mc":[{"id":"1.170370564","rc":[{"atb":[[4.5,13.59]],"id":9630572},{"atl":[[5.2,4.03]],"id":9630572},{"atb":[[1.22,6.02]],"id":8509691},{"atl":[[1.29,1313.27]],"id":8509691}],"con":true,"img":false}]}
{"op":"mcm","clk":"1362352204","pt":1588443029851,"mc":[{"id":"1.170370564","rc":[{"atb":[[1.25,789.99]],"id":8509691}],"con":true,"img":false}]}
{"op":"mcm","clk":"1362352207","pt":1588443030158,"mc":[{"id":"1.170370564","rc":[{"atl":[[1.29,1311.08]],"id":8509691}],"con":true,"img":false}]}
{"op":"mcm","clk":"1362352208","pt":1588443030260,"mc":[{"id":"1.170370564","rc":[{"atb":[[4.5,11.59]],"id":9630572},{"atl":[[5.2,0]],"id":9630572},{"atb":[[1.22,2]],"id":8509691},{"atl":[[1.29,1309.06]],"id":8509691}],"con":true,"img":false}]}
{"op":"mcm","clk":"1362352210","pt":1588443030361,"mc":[{"id":"1.170370564","rc":[{"atb":[[4.5,9.59]],"id":9630572}],"con":true,"img":false}]}
{"op":"mcm","clk":"1362352212","pt":1588443030462,"mc":[{"id":"1.170370564","rc":[{"atb":[[4.5,11.69]],"id":9630572},{"atl":[[5.2,2.03]],"id":9630572},{"atb":[[1.22,4.02]],"id":8509691},{"atl":[[1.29,1311.08]],"id":8509691}],"con":true,"img":false}]}
{"op":"mcm","clk":"1362352218","pt":1588443031176,"mc":[{"id":"1.170370564","rc":[{"atl":[[1.29,1320.76]],"id":8509691}],"con":true,"img":false}]}
{"op":"mcm","clk":"1362352220","pt":1588443031481,"mc":[{"id":"1.170370564","rc":[{"atb":[[4.7,2.62]],"id":9630572}],"con":true,"img":false}]}
{"op":"mcm","clk":"1362352222","pt":1588443031687,"mc":[{"id":"1.170370564","rc":[{"atb":[[4.4,2.85]],"id":9630572}],"con":true,"img":false}]}
{"op":"mcm","clk":"1362352234","pt":1588443032960,"mc":[{"id":"1.170370564","rc":[{"atl":[[1.27,228.08]],"id":8509691}],"con":true,"img":false}]}
{"op":"mcm","clk":"1362352399","pt":1588443049677,"mc":[{"id":"1.170370564","rc":[{"atb":[[1.21,138.65]],"id":8509691}],"con":true,"img":false}]}
{"op":"mcm","clk":"1362352404","pt":1588443049983,"mc":[{"id":"1.170370564","rc":[{"atb":[[4.5,9.59]],"id":9630572},{"atl":[[5.2,0]],"id":9630572},{"atb":[[1.22,2]],"id":8509691},{"atl":[[1.29,1318.74]],"id":8509691}],"con":true,"img":false}]}
{"op":"mcm","clk":"1362352407","pt":1588443050189,"mc":[{"id":"1.170370564","rc":[{"atb":[[4.5,11.69]],"id":9630572},{"atl":[[5.2,2.03]],"id":9630572},{"atb":[[1.22,4.02]],"id":8509691},{"atl":[[1.29,1320.93]],"id":8509691}],"con":true,"img":false}]}
{"op":"mcm","clk":"1362352411","pt":1588443050391,"mc":[{"id":"1.170370564","rc":[{"atb":[[4.5,13.69]],"id":9630572},{"atl":[[5.2,4.06]],"id":9630572},{"atb":[[1.22,6.04]],"id":8509691},{"atl":[[1.29,1322.95]],"id":8509691}],"con":true,"img":false}]}
{"op":"mcm","clk":"1362352418","pt":1588443051409,"mc":[{"id":"1.170370564","rc":[{"atb":[[4.4,0]],"id":9630572}],"con":true,"img":false}]}
{"op":"mcm","clk":"1362352423","pt":1588443051614,"mc":[{"id":"1.170370564","rc":[{"atb":[[4.5,16.47]],"id":9630572}],"con":true,"img":false}]}
{"op":"mcm","clk":"1362352473","pt":1588443057221,"mc":[{"id":"1.170370564","rc":[{"atb":[[1.22,56.04]],"id":8509691}],"con":true,"img":false}]}
{"op":"mcm","clk":"1362352480","pt":1588443057628,"mc":[{"id":"1.170370564","rc":[{"atb":[[4.5,12.37]],"id":9630572},{"atl":[[5.2,0]],"id":9630572},{"atb":[[1.22,52]],"id":8509691},{"atl":[[1.29,1318.74]],"id":8509691}],"con":true,"img":false}]}
{"op":"mcm","clk":"1362352485","pt":1588443057833,"mc":[{"id":"1.170370564","rc":[{"atb":[[4.5,14.47]],"id":9630572},{"atl":[[5.2,2.03]],"id":9630572},{"atb":[[1.22,54.02]],"id":8509691},{"atl":[[1.29,1320.93]],"id":8509691}],"con":true,"img":false}]}
{"op":"mcm","clk":"1362352494","pt":1588443058495,"mc":[{"id":"1.170370564","rc":[{"atb":[[4.5,11.69]],"id":9630572}],"con":true,"img":false}]}
{"op":"mcm","clk":"1362352497","pt":1588443058699,"mc":[{"id":"1.170370564","rc":[{"atb":[[4.4,2.85]],"id":9630572}],"con":true,"img":false}]}
{"op":"mcm","clk":"1362352527","pt":1588443063400,"mc":[{"id":"1.170370564","rc":[{"atb":[[1.23,139.49]],"id":8509691}],"con":true,"img":false}]}
{"op":"mcm","clk":"1362352529","pt":1588443063707,"mc":[{"id":"1.170370564","rc":[{"atb":[[4.5,9.59]],"id":9630572},{"atl":[[5.2,0]],"id":9630572},{"atb":[[1.22,52]],"id":8509691},{"atl":[[1.29,1318.74]],"id":8509691}],"con":true,"img":false}]}
{"op":"mcm","clk":"1362352531","pt":1588443063912,"mc":[{"id":"1.170370564","rc":[{"atb":[[4.5,11.69]],"id":9630572},{"atl":[[5.2,2.03]],"id":9630572},{"atb":[[1.22,54.02]],"id":8509691},{"atl":[[1.29,1320.93]],"id":8509691}],"con":true,"img":false}]}
{"op":"mcm","clk":"1362352741","pt":1588443088950,"mc":[{"id":"1.170370564","rc":[{"atl":[[1.26,0]],"id":8509691}],"con":true,"img":false}]}
{"op":"mcm","clk":"1362352743","pt":1588443089052,"mc":[{"id":"1.170370564","rc":[{"trd":[[1.25,2692.19]],"ltp":1.25,"tv":2692.19,"id":8509691},{"atb":[[1.25,616.87]],"id":8509691},{"atl":[[1.3,2.05]],"id":8509691}],"con":true,"img":false}]}
{"op":"mcm","clk":"1362352746","pt":1588443089257,"mc":[{"id":"1.170370564","rc":[{"atb":[[4.5,9.59]],"id":9630572},{"atl":[[5.2,0]],"id":9630572},{"atb":[[1.22,52]],"id":8509691},{"atl":[[1.28,170]],"id":8509691}],"con":true,"img":false}]}
{"op":"mcm","clk":"1362352748","pt":1588443089358,"mc":[{"id":"1.170370564","rc":[{"atb":[[4.5,11.69]],"id":9630572},{"atl":[[5.2,2.03]],"id":9630572},{"atb":[[1.22,54.02]],"id":8509691}],"con":true,"img":false}]}
{"op":"mcm","clk":"1362352752","pt":1588443089765,"mc":[{"id":"1.170370564","rc":[{"atb":[[4.6,2.04]],"id":9630572}],"con":true,"img":false}]}
{"op":"mcm","clk":"1362352773","pt":1588443092363,"mc":[{"id":"1.170370564","rc":[{"atb":[[1.26,80.41]],"id":8509691}],"con":true,"img":false}]}
{"op":"mcm","clk":"1362352775","pt":1588443092467,"mc":[{"id":"1.170370564","rc":[{"atb":[[1.24,52.02]],"id":8509691}],"con":true,"img":false}]}
{"op":"mcm","clk":"1362352776","pt":1588443092568,"mc":[{"id":"1.170370564","rc":[{"atb":[[1.22,142.67]],"id":8509691}],"con":true,"img":false}]}
{"op":"mcm","clk":"1362352777","pt":1588443092771,"mc":[{"id":"1.170370564","rc":[{"atb":[[1.23,137.47]],"id":8509691}],"con":true,"img":false}]}
{"op":"mcm","clk":"1362352779","pt":1588443092976,"mc":[{"id":"1.170370564","rc":[{"atb":[[1.23,139.49]],"id":8509691}],"con":true,"img":false}]}
{"op":"mcm","clk":"1362352782","pt":1588443093179,"mc":[{"id":"1.170370564","rc":[{"atl":[[1.29,1311.25]],"id":8509691}],"con":true,"img":false}]}
{"op":"mcm","clk":"1362352785","pt":1588443093486,"mc":[{"id":"1.170370564","rc":[{"atb":[[4.4,0]],"id":9630572}],"con":true,"img":false}]}
{"op":"mcm","clk":"1362352787","pt":1588443093690,"mc":[{"id":"1.170370564","rc":[{"atb":[[4.7,5.28]],"id":9630572}],"con":true,"img":false}]}
{"op":"mcm","clk":"1362352858","pt":1588443102663,"mc":[{"id":"1.170370564","rc":[{"trd":[[1.26,2201.56]],"ltp":1.26,"tv":2201.56,"id":8509691},{"atb":[[1.26,0.41]],"id":8509691}],"con":true,"img":false}]}
{"op":"mcm","clk":"1362352862","pt":1588443102970,"mc":[{"id":"1.170370564","rc":[{"atb":[[4.5,9.59]],"id":9630572},{"atl":[[5.2,0]],"id":9630572},{"atb":[[1.22,140.65],[1.24,50]],"id":8509691},{"atl":[[1.3,0]],"id":8509691}],"con":true,"img":false}]}
{"op":"mcm","clk":"1362352865","pt":1588443103185,"mc":[{"id":"1.170370564","rc":[{"atb":[[4.5,11.69]],"id":9630572},{"atl":[[5.2,2.03]],"id":9630572},{"atb":[[1.22,142.67]],"id":8509691},{"atl":[[1.3,2]],"id":8509691}],"con":true,"img":false}]}
{"op":"mcm","clk":"1362352870","pt":1588443103785,"mc":[{"id":"1.170370564","rc":[{"atb":[[1.22,54.02]],"id":8509691}],"con":true,"img":false}]}
{"op":"mcm","clk":"1362352877","pt":1588443105009,"mc":[{"id":"1.170370564","rc":[{"atl":[[1.29,1320.93]],"id":8509691}],"con":true,"img":false}]}
{"op":"mcm","clk":"1362353006","pt":1588443117805,"mc":[{"id":"1.170370564","rc":[{"trd":[[4.9,14.6]],"ltp":4.9,"tv":14.6,"id":9630572},{"atb":[[4.9,0.89]],"id":9630572},{"atl":[[4.9,0]],"id":9630572},{"trd":[[1.26,2201.98]],"ltp":1.26,"tv":2201.98,"id":8509691},{"atb":[[1.26,0]],"id":8509691}],"con":true,"img":false}]}
{"op":"mcm","clk":"1362353008","pt":1588443118011,"mc":[{"id":"1.170370564","rc":[{"trd":[[4.9,15.49]],"ltp":4.9,"tv":15.49,"id":9630572},{"atb":[[4.9,0]],"id":9630572},{"atl":[[5.3,2.05]],"id":9630572},{"trd":[[1.26,2205.43]],"ltp":1.26,"tv":2205.43,"id":8509691},{"atb":[[1.26,0]],"id":8509691}],"con":true,"img":false}]}
{"op":"mcm","clk":"1362353010","pt":1588443118113,"mc":[{"id":"1.170370564","rc":[{"atb":[[4.5,9.59]],"id":9630572},{"atl":[[5.1,32.8]],"id":9630572},{"atb":[[1.22,52]],"id":8509691},{"atl":[[1.3,0]],"id":8509691}],"con":true,"img":false}]}
{"op":"mcm","clk":"1362353014","pt":1588443118315,"mc":[{"id":"1.170370564","rc":[{"atb":[[4.5,11.69]],"id":9630572},{"atb":[[1.26,0],[1.22,54]],"id":8509691},{"atl":[[1.3,2.05]],"id":8509691}],"con":true,"img":false}]}
{"op":"mcm","clk":"1362353019","pt":1588443118723,"mc":[{"id":"1.170370564","rc":[{"atb":[[4.7,2.62]],"id":9630572}],"con":true,"img":false}]}
{"op":"mcm","clk":"1362353021","pt":1588443118926,"mc":[{"id":"1.170370564","rc":[{"atb":[[4.4,2.85]],"id":9630572}],"con":true,"img":false}]}
{"op":"mcm","clk":"1362353132","pt":1588443132306,"mc":[{"id":"1.170370564","rc":[{"atb":[[4.1,0]],"id":9630572}],"con":true,"img":false}]}
{"op":"mcm","clk":"1362353136","pt":1588443132613,"mc":[{"id":"1.170370564","rc":[{"atb":[[4.5,9.59]],"id":9630572},{"atl":[[5.3,0]],"id":9630572},{"atb":[[1.22,52]],"id":8509691},{"atl":[[1.3,0]],"id":8509691}],"con":true,"img":false}]}
{"op":"mcm","clk":"1362353137","pt":1588443132815,"mc":[{"id":"1.170370564","rc":[{"atb":[[4.5,11.59]],"id":9630572},{"atl":[[5.3,2.05]],"id":9630572},{"atb":[[1.22,54.02]],"id":8509691},{"atl":[[1.3,2.05]],"id":8509691}],"con":true,"img":false}]}
{"op":"mcm","clk":"1362353144","pt":1588443133531,"mc":[{"id":"1.170370564","rc":[{"atb":[[4.1,2.33]],"id":9630572}],"con":true,"img":false}]}
{"op":"mcm","clk":"1362353516","pt":1588443178986,"mc":[{"id":"1.170370564","rc":[{"trd":[[1.25,2698.59]],"ltp":1.25,"tv":2698.59,"id":8509691},{"atb":[[1.25,613.67]],"id":8509691}],"con":true,"img":false}]}
{"op":"mcm","clk":"1362353519","pt":1588443179240,"mc":[{"id":"1.170370564","rc":[{"atb":[[4.5,9.59]],"id":9630572},{"atl":[[5.3,0]],"id":9630572},{"atb":[[1.22,52]],"id":8509691},{"atl":[[1.3,0]],"id":8509691}],"con":true,"img":false}]}
{"op":"mcm","clk":"1362353521","pt":1588443179444,"mc":[{"id":"1.170370564","rc":[{"atb":[[4.5,11.69]],"id":9630572},{"atl":[[5.3,2.05]],"id":9630572},{"atb":[[1.22,54.02]],"id":8509691},{"atl":[[1.3,2.05]],"id":8509691}],"con":true,"img":false}]}
{"op":"mcm","clk":"1362354024","pt":1588443233518,"mc":[{"id":"1.170370564","rc":[{"trd":[[1.27,2634.77]],"ltp":1.27,"tv":2634.77,"id":8509691},{"atl":[[1.27,222.48]],"id":8509691}],"con":true,"img":false}]}
{"op":"mcm","clk":"1362354028","pt":1588443233722,"mc":[{"id":"1.170370564","rc":[{"atb":[[4.5,9.59]],"id":9630572},{"atl":[[5.3,0]],"id":9630572},{"atb":[[1.22,52]],"id":8509691},{"atl":[[1.3,0]],"id":8509691}],"con":true,"img":false}]}
{"op":"mcm","clk":"1362354033","pt":1588443233925,"mc":[{"id":"1.170370564","rc":[{"atb":[[4.5,11.69]],"id":9630572},{"atl":[[5.3,2.02]],"id":9630572},{"atb":[[1.22,54.01]],"id":8509691},{"atl":[[1.3,2]],"id":8509691}],"con":true,"img":false}]}
{"op":"mcm","clk":"1362354222","pt":1588443252680,"mc":[{"id":"1.170370564","rc":[{"atb":[[4.1,0]],"id":9630572}],"con":true,"img":false}]}
{"op":"mcm","clk":"1362354226","pt":1588443253037,"mc":[{"id":"1.170370564","rc":[{"atb":[[4.5,9.59]],"id":9630572},{"atl":[[5.3,0]],"id":9630572},{"atb":[[1.22,52]],"id":8509691},{"atl":[[1.3,0]],"id":8509691}],"con":true,"img":false}]}
{"op":"mcm","clk":"1362354228","pt":1588443253240,"mc":[{"id":"1.170370564","rc":[{"atb":[[4.5,11.69]],"id":9630572},{"atl":[[5.3,2]],"id":9630572},{"atb":[[1.22,54.02]],"id":8509691},{"atl":[[1.3,2.05]],"id":8509691}],"con":true,"img":false}]}
{"op":"mcm","clk":"1362354235","pt":1588443254055,"mc":[{"id":"1.170370564","rc":[{"atb":[[4.1,2.33]],"id":9630572}],"con":true,"img":false}]}
{"op":"mcm","clk":"1362355250","pt":1588443292606,"mc":[{"id":"1.170370564","rc":[{"trd":[[1.25,2798.59]],"ltp":1.25,"tv":2798.59,"id":8509691},{"atb":[[1.25,563.67]],"id":8509691}],"con":true,"img":false}]}
{"op":"mcm","clk":"1362355252","pt":1588443292914,"mc":[{"id":"1.170370564","rc":[{"atb":[[4.5,9.59]],"id":9630572},{"atl":[[5.3,0]],"id":9630572},{"atb":[[1.22,52]],"id":8509691},{"atl":[[1.3,0]],"id":8509691}],"con":true,"img":false}]}
{"op":"mcm","clk":"1362355256","pt":1588443293117,"mc":[{"id":"1.170370564","rc":[{"atb":[[4.5,11.69]],"id":9630572},{"atl":[[5.3,2.05]],"id":9630572},{"atb":[[1.22,54.02]],"id":8509691},{"atl":[[1.3,2.05]],"id":8509691}],"con":true,"img":false}]}
{"op":"mcm","clk":"1362355268","pt":1588443294136,"mc":[{"id":"1.170370564","rc":[{"atb":[[4.4,0]],"id":9630572}],"con":true,"img":false}]}
{"op":"mcm","clk":"1362355273","pt":1588443294339,"mc":[{"id":"1.170370564","rc":[{"atb":[[4.5,14.47]],"id":9630572}],"con":true,"img":false}]}
{"op":"mcm","clk":"1362355826","pt":1588443361803,"mc":[{"id":"1.170370564","rc":[{"trd":[[1.25,2800.28]],"ltp":1.25,"tv":2800.28,"id":8509691},{"atb":[[1.25,562.82]],"id":8509691}],"con":true,"img":false}]}
{"op":"mcm","clk":"1362355832","pt":1588443362110,"mc":[{"id":"1.170370564","rc":[{"atb":[[4.5,12.37]],"id":9630572},{"atl":[[5.3,0]],"id":9630572},{"atb":[[1.22,52]],"id":8509691},{"atl":[[1.3,0]],"id":8509691}],"con":true,"img":false}]}
{"op":"mcm","clk":"1362355834","pt":1588443362313,"mc":[{"id":"1.170370564","rc":[{"atb":[[4.5,14.37]],"id":9630572},{"atl":[[5.3,2]],"id":9630572},{"atb":[[1.22,54.02]],"id":8509691},{"atl":[[1.3,2.05]],"id":8509691}],"con":true,"img":false}]}
{"op":"mcm","clk":"1362355911","pt":1588443371923,"mc":[{"id":"1.170370564","rc":[{"atb":[[4.1,0]],"id":9630572}],"con":true,"img":false}]}
{"op":"mcm","clk":"1362355915","pt":1588443372229,"mc":[{"id":"1.170370564","rc":[{"atb":[[4.5,12.37]],"id":9630572},{"atl":[[5.3,0]],"id":9630572},{"atb":[[1.22,52]],"id":8509691},{"atl":[[1.3,0]],"id":8509691}],"con":true,"img":false}]}
{"op":"mcm","clk":"1362355916","pt":1588443372384,"mc":[{"id":"1.170370564","rc":[{"atb":[[4.5,14.47]],"id":9630572},{"atl":[[5.3,2.05]],"id":9630572},{"atb":[[1.22,54.02]],"id":8509691},{"atl":[[1.3,2.05]],"id":8509691}],"con":true,"img":false}]}
{"op":"mcm","clk":"1362355930","pt":1588443374424,"mc":[{"id":"1.170370564","rc":[{"atb":[[4.1,2.33]],"id":9630572}],"con":true,"img":false}]}
{"op":"mcm","clk":"1362355981","pt":1588443380136,"mc":[{"id":"1.170370564","rc":[{"trd":[[1.25,2800.89]],"ltp":1.25,"tv":2800.89,"id":8509691},{"atb":[[1.25,562.52]],"id":8509691}],"con":true,"img":false}]}
{"op":"mcm","clk":"1362355983","pt":1588443380391,"mc":[{"id":"1.170370564","rc":[{"atb":[[4.5,12.37]],"id":9630572},{"atl":[[5.3,0]],"id":9630572},{"atb":[[1.22,52]],"id":8509691},{"atl":[[1.3,0]],"id":8509691}],"con":true,"img":false}]}
{"op":"mcm","clk":"1362355987","pt":1588443380596,"mc":[{"id":"1.170370564","rc":[{"atb":[[4.5,14.47]],"id":9630572},{"atl":[[5.3,2.05]],"id":9630572},{"atb":[[1.22,54.02]],"id":8509691},{"atl":[[1.3,2.05]],"id":8509691}],"con":true,"img":false}]}
{"op":"mcm","clk":"1362356026","pt":1588443386305,"mc":[{"id":"1.170370564","rc":[{"atl":[[1.6,0]],"id":8509691}],"con":true,"img":false}]}
{"op":"mcm","clk":"1362356028","pt":1588443386610,"mc":[{"id":"1.170370564","rc":[{"atb":[[4.5,12.37]],"id":9630572},{"atl":[[5.3,0]],"id":9630572},{"atb":[[1.22,52]],"id":8509691},{"atl":[[1.3,0]],"id":8509691}],"con":true,"img":false}]}
{"op":"mcm","clk":"1362356030","pt":1588443386815,"mc":[{"id":"1.170370564","rc":[{"atb":[[4.5,14.37]],"id":9630572},{"atl":[[5.3,2]],"id":9630572},{"atb":[[1.22,54.02]],"id":8509691},{"atl":[[1.3,2.05]],"id":8509691}],"con":true,"img":false}]}
{"op":"mcm","clk":"1362356170","pt":1588443404459,"mc":[{"id":"1.170370564","rc":[{"trd":[[1.25,2804.54]],"ltp":1.25,"tv":2804.54,"id":8509691},{"atb":[[1.25,560.7]],"id":8509691}],"con":true,"img":false}]}
{"op":"mcm","clk":"1362356172","pt":1588443404765,"mc":[{"id":"1.170370564","rc":[{"atb":[[4.5,12.37]],"id":9630572},{"atl":[[5.3,0]],"id":9630572}],"con":true,"img":false}]}
{"op":"mcm","clk":"1362356173","pt":1588443404817,"mc":[{"id":"1.170370564","rc":[{"atb":[[1.22,52]],"id":8509691},{"atl":[[1.3,0]],"id":8509691}],"con":true,"img":false}]}
{"op":"mcm","clk":"1362356175","pt":1588443404919,"mc":[{"id":"1.170370564","rc":[{"atb":[[4.5,14.37]],"id":9630572},{"atl":[[5.3,2.05]],"id":9630572}],"con":true,"img":false}]}
{"op":"mcm","clk":"1362356177","pt":1588443405021,"mc":[{"id":"1.170370564","rc":[{"atb":[[1.22,54.02]],"id":8509691},{"atl":[[1.3,2.05]],"id":8509691}],"con":true,"img":false}]}
{"op":"mcm","clk":"1362356401","pt":1588443437269,"mc":[{"id":"1.170370564","rc":[{"trd":[[5,2.39]],"ltp":5.0,"tv":2.39,"id":9630572},{"trd":[[1.25,2814.14]],"ltp":1.25,"tv":2814.14,"id":8509691},{"atb":[[1.25,551.1]],"id":8509691}],"con":true,"img":false}]}
{"op":"mcm","clk":"1362356406","pt":1588443437574,"mc":[{"id":"1.170370564","rc":[{"atb":[[4.5,12.37]],"id":9630572},{"atl":[[5.3,0]],"id":9630572},{"atb":[[1.22,52]],"id":8509691},{"atl":[[1.3,0]],"id":8509691}],"con":true,"img":false}]}
{"op":"mcm","clk":"1362356408","pt":1588443437675,"mc":[{"id":"1.170370564","rc":[{"atb":[[4.5,14.37]],"id":9630572},{"atl":[[5.3,2.05]],"id":9630572},{"atb":[[1.22,54.02]],"id":8509691},{"atl":[[1.3,2.05]],"id":8509691}],"con":true,"img":false}]}
{"op":"mcm","clk":"1362356805","pt":1588443490137,"mc":[{"id":"1.170370564","rc":[{"atl":[[5,13.99]],"id":9630572}],"con":true,"img":false}]}
{"op":"mcm","clk":"1362356810","pt":1588443490445,"mc":[{"id":"1.170370564","rc":[{"atb":[[4.5,12.37]],"id":9630572},{"atl":[[5.3,0]],"id":9630572},{"atb":[[1.22,52]],"id":8509691},{"atl":[[1.3,0]],"id":8509691}],"con":true,"img":false}]}
{"op":"mcm","clk":"1362356812","pt":1588443490650,"mc":[{"id":"1.170370564","rc":[{"atb":[[4.5,14.47]],"id":9630572},{"atl":[[5.3,2.05]],"id":9630572},{"atb":[[1.22,54.02]],"id":8509691},{"atl":[[1.3,2.02]],"id":8509691}],"con":true,"img":false}]}
{"op":"mcm","clk":"1362356815","pt":1588443490956,"mc":[{"id":"1.170370564","rc":[{"atb":[[4.5,11.69]],"id":9630572}],"con":true,"img":false}]}
{"op":"mcm","clk":"1362356817","pt":1588443491161,"mc":[{"id":"1.170370564","rc":[{"atb":[[4.4,2.85]],"id":9630572}],"con":true,"img":false}]}
{"op":"mcm","clk":"1362356827","pt":1588443492437,"mc":[{"id":"1.170370564","rc":[{"atb":[[4.1,0]],"id":9630572}],"con":true,"img":false}]}
{"op":"mcm","clk":"1362356835","pt":1588443493660,"mc":[{"id":"1.170370564","rc":[{"atb":[[4.1,2.33]],"id":9630572}],"con":true,"img":false}]}
{"op":"mcm","clk":"1362357098","pt":1588443529594,"mc":[{"id":"1.170370564","rc":[{"atl":[[5.1,0]],"id":9630572},{"atl":[[1.27,178.15],[1.29,11.87]],"id":8509691}],"con":true,"img":false}]}
{"op":"mcm","clk":"1362357102","pt":1588443529900,"mc":[{"id":"1.170370564","rc":[{"atb":[[4.5,9.59]],"id":9630572},{"atl":[[5.3,0]],"id":9630572},{"atb":[[1.22,52]],"id":8509691},{"atl":[[1.3,0]],"id":8509691}],"con":true,"img":false}]}
{"op":"mcm","clk":"1362357104","pt":1588443530105,"mc":[{"id":"1.170370564","rc":[{"atb":[[4.5,11.69]],"id":9630572},{"atl":[[5.3,2.05]],"id":9630572},{"atb":[[1.22,54.02]],"id":8509691},{"atl":[[1.3,2.05]],"id":8509691}],"con":true,"img":false}]}
{"op":"mcm","clk":"1362357108","pt":1588443530614,"mc":[{"id":"1.170370564","rc":[{"atl":[[1.29,2.19]],"id":8509691}],"con":true,"img":false}]}
{"op":"mcm","clk":"1362357110","pt":1588443530818,"mc":[{"id":"1.170370564","rc":[{"atl":[[1.33,15.78]],"id":8509691}],"con":true,"img":false}]}
{"op":"mcm","clk":"1362357395","pt":1588443568560,"mc":[{"id":"1.170370564","rc":[{"trd":[[1.27,2740.88]],"ltp":1.27,"tv":2740.88,"id":8509691},{"atl":[[1.27,125.1]],"id":8509691}],"con":true,"img":false}]}
{"op":"mcm","clk":"1362357397","pt":1588443568867,"mc":[{"id":"1.170370564","rc":[{"atb":[[4.5,9.59]],"id":9630572},{"atl":[[5.3,0]],"id":9630572},{"atb":[[1.22,52]],"id":8509691},{"atl":[[1.3,0]],"id":8509691}],"con":true,"img":false}]}
{"op":"mcm","clk":"1362357400","pt":1588443569071,"mc":[{"id":"1.170370564","rc":[{"atb":[[4.5,11.69]],"id":9630572},{"atl":[[5.3,2.05]],"id":9630572},{"atb":[[1.22,54.02]],"id":8509691},{"atl":[[1.3,2.05]],"id":8509691}],"con":true,"img":false}]}
{"op":"mcm","clk":"1362357568","pt":1588443592710,"mc":[{"id":"1.170370564","rc":[{"atb":[[4.8,22.24]],"id":9630572},{"atl":[[4.9,492.02]],"id":9630572}],"con":true,"img":false}]}
{"op":"mcm","clk":"1362357570","pt":1588443592916,"mc":[{"id":"1.170370564","rc":[{"trd":[[4.8,175.87]],"ltp":4.8,"tv":175.87,"id":9630572},{"atb":[[4.8,0]],"id":9630572},{"atl":[[4.8,0.15],[5.1,2]],"id":9630572}],"con":true,"img":false}]}
{"op":"mcm","clk":"1362357572","pt":1588443593018,"mc":[{"id":"1.170370564","rc":[{"atb":[[4.5,9.59]],"id":9630572},{"atl":[[5.3,0]],"id":9630572},{"atb":[[1.22,52]],"id":8509691},{"atl":[[1.3,0]],"id":8509691}],"con":true,"img":false}]}
{"op":"mcm","clk":"1362357575","pt":1588443593069,"mc":[{"id":"1.170370564","rc":[{"atb":[[4.4,4.86]],"id":9630572},{"atl":[[4.8,0]],"id":9630572}],"con":true,"img":false}]}
{"op":"mcm","clk":"1362357577","pt":1588443593273,"mc":[{"id":"1.170370564","rc":[{"atb":[[4.6,0]],"id":9630572},{"atl":[[5.2,0]],"id":9630572}],"con":true,"img":false}]}
{"op":"mcm","clk":"1362357579","pt":1588443593375,"mc":[{"id":"1.170370564","rc":[{"atb":[[4.5,11.69]],"id":9630572},{"atl":[[5.2,2.03]],"id":9630572},{"atb":[[1.22,54.02]],"id":8509691},{"atl":[[1.3,2.05]],"id":8509691}],"con":true,"img":false}]}
{"op":"mcm","clk":"1362357586","pt":1588443594208,"mc":[{"id":"1.170370564","rc":[{"atb":[[4.4,2.01]],"id":9630572}],"con":true,"img":false}]}
{"op":"mcm","clk":"1362357588","pt":1588443594464,"mc":[{"id":"1.170370564","rc":[{"atb":[[4,21.71]],"id":9630572}],"con":true,"img":false}]}
{"op":"mcm","clk":"1362357724","pt":1588443609134,"mc":[{"id":"1.170370564","rc":[{"atl":[[5,0]],"id":9630572}],"con":true,"img":false}]}
{"op":"mcm","clk":"1362357728","pt":1588443609394,"mc":[{"id":"1.170370564","rc":[{"atb":[[4.4,0]],"id":9630572},{"atl":[[5.2,0]],"id":9630572},{"atb":[[1.22,52]],"id":8509691},{"atl":[[1.3,0]],"id":8509691}],"con":true,"img":false}]}
{"op":"mcm","clk":"1362357731","pt":1588443609598,"mc":[{"id":"1.170370564","rc":[{"atb":[[4.4,2.01]],"id":9630572},{"atl":[[5.2,2.03]],"id":9630572},{"atb":[[1.22,54.02]],"id":8509691},{"atl":[[1.3,2]],"id":8509691}],"con":true,"img":false}]}
{"op":"mcm","clk":"1362357747","pt":1588443611897,"mc":[{"id":"1.170370564","rc":[{"atb":[[4.1,0]],"id":9630572}],"con":true,"img":false}]}
{"op":"mcm","clk":"1362357759","pt":1588443613426,"mc":[{"id":"1.170370564","rc":[{"atb":[[4,18.58]],"id":9630572}],"con":true,"img":false}]}
{"op":"mcm","clk":"1362357761","pt":1588443613627,"mc":[{"id":"1.170370564","rc":[{"atb":[[3.8,16.41]],"id":9630572}],"con":true,"img":false}]}
{"op":"mcm","clk":"1362357764","pt":1588443613831,"mc":[{"id":"1.170370564","rc":[{"atb":[[4.1,2.33]],"id":9630572}],"con":true,"img":false}]}
{"op":"mcm","clk":"1362357778","pt":1588443615211,"mc":[{"id":"1.170370564","rc":[{"atb":[[3.8,13.12]],"id":9630572}],"con":true,"img":false}]}
{"op":"mcm","clk":"1362357780","pt":1588443615415,"mc":[{"id":"1.170370564","rc":[{"atb":[[4,21.71]],"id":9630572}],"con":true,"img":false}]}
{"op":"mcm","clk":"1362357782","pt":1588443615517,"mc":[{"id":"1.170370564","rc":[{"atb":[[4.4,0]],"id":9630572},{"atl":[[5.2,0]],"id":9630572},{"atb":[[1.22,52]],"id":8509691},{"atl":[[1.3,0]],"id":8509691}],"con":true,"img":false}]}
{"op":"mcm","clk":"1362357785","pt":1588443615721,"mc":[{"id":"1.170370564","rc":[{"atb":[[4.4,2.01]],"id":9630572},{"atl":[[5.2,2]],"id":9630572},{"atb":[[1.22,54.02]],"id":8509691},{"atl":[[1.3,2.05]],"id":8509691}],"con":true,"img":false}]}
{"op":"mcm","clk":"1362358274","pt":1588443679396,"mc":[{"id":"1.170370564","rc":[{"atb":[[1.25,568.83]],"id":8509691}],"con":true,"img":false}]}
{"op":"mcm","clk":"1362358278","pt":1588443679703,"mc":[{"id":"1.170370564","rc":[{"atb":[[4.4,0]],"id":9630572},{"atl":[[5.2,0]],"id":9630572},{"atb":[[1.22,52]],"id":8509691},{"atl":[[1.3,0]],"id":8509691}],"con":true,"img":false}]}
{"op":"mcm","clk":"1362358280","pt":1588443679905,"mc":[{"id":"1.170370564","rc":[{"atb":[[4.4,2.01]],"id":9630572},{"atl":[[5.2,2.03]],"id":9630572},{"atb":[[1.25,586.56],[1.22,54.02]],"id":8509691},{"atl":[[1.3,2.05]],"id":8509691}],"con":true,"img":false}]}
{"op":"mcm","clk":"1362358288","pt":1588443680977,"mc":[{"id":"1.170370564","rc":[{"atb":[[1.25,604.29]],"id":8509691}],"con":true,"img":false}]}
{"op":"mcm","clk":"1362358293","pt":1588443681487,"mc":[{"id":"1.170370564","rc":[{"atb":[[1.25,622.02]],"id":8509691}],"con":true,"img":false}]}
{"op":"mcm","clk":"1362358361","pt":1588443690214,"mc":[{"id":"1.170370564","rc":[{"atb":[[1.25,551.1]],"id":8509691}],"con":true,"img":false}]}
{"op":"mcm","clk":"1362358364","pt":1588443690520,"mc":[{"id":"1.170370564","rc":[{"atb":[[4.4,0]],"id":9630572},{"atl":[[5.2,0]],"id":9630572},{"atb":[[1.22,52]],"id":8509691},{"atl":[[1.3,0]],"id":8509691}],"con":true,"img":false}]}
{"op":"mcm","clk":"1362358365","pt":1588443690622,"mc":[{"id":"1.170370564","rc":[{"atb":[[4.4,2.01]],"id":9630572},{"atl":[[5.2,2.03]],"id":9630572},{"atb":[[1.22,54.02]],"id":8509691},{"atl":[[1.3,2.05]],"id":8509691}],"con":true,"img":false}]}
{"op":"mcm","clk":"1362358663","pt":1588443732494,"mc":[{"id":"1.170370564","rc":[{"atb":[[4.1,0]],"id":9630572}],"con":true,"img":false}]}
{"op":"mcm","clk":"1362358666","pt":1588443732800,"mc":[{"id":"1.170370564","rc":[{"atb":[[4.4,0]],"id":9630572},{"atl":[[5.2,0]],"id":9630572}],"con":true,"img":false}]}
{"op":"mcm","clk":"1362358667","pt":1588443732902,"mc":[{"id":"1.170370564","rc":[{"atb":[[1.22,52]],"id":8509691},{"atl":[[1.3,0]],"id":8509691}],"con":true,"img":false}]}
{"op":"mcm","clk":"1362358670","pt":1588443733055,"mc":[{"id":"1.170370564","rc":[{"atb":[[4.4,2.01]],"id":9630572},{"atl":[[5.2,2.03]],"id":9630572},{"atb":[[1.22,54.02]],"id":8509691},{"atl":[[1.3,2.05]],"id":8509691}],"con":true,"img":false}]}
{"op":"mcm","clk":"1362358674","pt":1588443733566,"mc":[{"id":"1.170370564","rc":[{"atb":[[4,18.58]],"id":9630572}],"con":true,"img":false}]}
{"op":"mcm","clk":"1362358676","pt":1588443733668,"mc":[{"id":"1.170370564","rc":[{"atb":[[4.1,2.33]],"id":9630572}],"con":true,"img":false}]}
{"op":"mcm","clk":"1362358677","pt":1588443733770,"mc":[{"id":"1.170370564","rc":[{"atb":[[3.8,16.41]],"id":9630572}],"con":true,"img":false}]}
{"op":"mcm","clk":"1362358692","pt":1588443735401,"mc":[{"id":"1.170370564","rc":[{"atb":[[3.8,13.12]],"id":9630572}],"con":true,"img":false}]}
{"op":"mcm","clk":"1362358694","pt":1588443735605,"mc":[{"id":"1.170370564","rc":[{"atb":[[4,21.71]],"id":9630572}],"con":true,"img":false}]}
{"op":"mcm","clk":"1362359252","pt":1588443850885,"mc":[{"id":"1.170370564","rc":[{"atb":[[4.1,0]],"id":9630572}],"con":true,"img":false}]}
{"op":"mcm","clk":"1362359253","pt":1588443851190,"mc":[{"id":"1.170370564","rc":[{"atl":[[1.3,0]],"id":8509691}],"con":true,"img":false}]}
{"op":"mcm","clk":"1362359254","pt":1588443851292,"mc":[{"id":"1.170370564","rc":[{"atb":[[4.4,0]],"id":9630572},{"atl":[[5.2,0]],"id":9630572},{"atb":[[1.22,52]],"id":8509691}],"con":true,"img":false}]}
{"op":"mcm","clk":"1362359256","pt":1588443851496,"mc":[{"id":"1.170370564","rc":[{"atb":[[4.4,2.01]],"id":9630572},{"atl":[[5.2,2.03]],"id":9630572},{"atb":[[1.22,54.02]],"id":8509691},{"atl":[[1.3,2.05]],"id":8509691}],"con":true,"img":false}]}
{"op":"mcm","clk":"1362359257","pt":1588443852265,"mc":[{"id":"1.170370564","rc":[{"atb":[[4,18.58]],"id":9630572}],"con":true,"img":false}]}
{"op":"mcm","clk":"1362359258","pt":1588443852466,"mc":[{"id":"1.170370564","rc":[{"atb":[[3.8,16.41]],"id":9630572}],"con":true,"img":false}]}
{"op":"mcm","clk":"1362359259","pt":1588443852772,"mc":[{"id":"1.170370564","rc":[{"atl":[[1.27,175.1]],"id":8509691}],"con":true,"img":false}]}
{"op":"mcm","clk":"1362359260","pt":1588443853178,"mc":[{"id":"1.170370564","rc":[{"atb":[[4.1,2.33]],"id":9630572}],"con":true,"img":false}]}
{"op":"mcm","clk":"1362359263","pt":1588443854198,"mc":[{"id":"1.170370564","rc":[{"atb":[[3.8,13.12]],"id":9630572}],"con":true,"img":false}]}
{"op":"mcm","clk":"1362359266","pt":1588443854505,"mc":[{"id":"1.170370564","rc":[{"atb":[[4,21.71]],"id":9630572}],"con":true,"img":false}]}
{"op":"mcm","clk":"1362359310","pt":1588443894358,"mc":[{"id":"1.170370564","rc":[{"atl":[[1.27,125.1]],"id":8509691}],"con":true,"img":false}]}
{"op":"mcm","clk":"1362359311","pt":1588443894460,"mc":[{"id":"1.170370564","rc":[{"atl":[[1.29,52.19]],"id":8509691}],"con":true,"img":false}]}
{"op":"mcm","clk":"1362359312","pt":1588443894660,"mc":[{"id":"1.170370564","rc":[{"atb":[[1.22,52]],"id":8509691},{"atl":[[1.3,0]],"id":8509691}],"con":true,"img":false}]}
{"op":"mcm","clk":"1362359313","pt":1588443894762,"mc":[{"id":"1.170370564","rc":[{"atb":[[4.4,0]],"id":9630572},{"atl":[[5.2,0]],"id":9630572}],"con":true,"img":false}]}
{"op":"mcm","clk":"1362359314","pt":1588443894917,"mc":[{"id":"1.170370564","rc":[{"atb":[[4.4,2.01]],"id":9630572},{"atl":[[5.2,2.03]],"id":9630572},{"atb":[[1.22,54.02]],"id":8509691},{"atl":[[1.3,2.05]],"id":8509691}],"con":true,"img":false}]}
{"op":"mcm","clk":"1362359315","pt":1588443895119,"mc":[{"id":"1.170370564","rc":[{"atb":[[4.4,4.02]],"id":9630572},{"atl":[[5.2,4.06]],"id":9630572},{"atb":[[1.22,56.04]],"id":8509691},{"atl":[[1.3,4.1]],"id":8509691}],"con":true,"img":false}]}
{"op":"mcm","clk":"1362359473","pt":1588443969794,"mc":[{"id":"1.170370564","rc":[{"atb":[[4.1,0]],"id":9630572}],"con":true,"img":false}]}
{"op":"mcm","clk":"1362359474","pt":1588443970201,"mc":[{"id":"1.170370564","rc":[{"atl":[[5.2,2.03]],"id":9630572},{"atb":[[1.22,54.02]],"id":8509691},{"atl":[[1.3,0]],"id":8509691}],"con":true,"img":false}]}
{"op":"mcm","clk":"1362359475","pt":1588443970303,"mc":[{"id":"1.170370564","rc":[{"atb":[[4.4,0]],"id":9630572},{"atl":[[5.2,0]],"id":9630572},{"atb":[[1.22,52]],"id":8509691}],"con":true,"img":false}]}
{"op":"mcm","clk":"1362359476","pt":1588443970507,"mc":[{"id":"1.170370564","rc":[{"atb":[[4.4,2.01]],"id":9630572},{"atl":[[5.2,2.03]],"id":9630572},{"atb":[[1.22,54.02]],"id":8509691},{"atl":[[1.3,2.05]],"id":8509691}],"con":true,"img":false}]}
{"op":"mcm","clk":"1362359478","pt":1588443971071,"mc":[{"id":"1.170370564","rc":[{"atb":[[4,18.58]],"id":9630572}],"con":true,"img":false}]}
{"op":"mcm","clk":"1362359480","pt":1588443971272,"mc":[{"id":"1.170370564","rc":[{"atb":[[3.8,16.41]],"id":9630572}],"con":true,"img":false}]}
{"op":"mcm","clk":"1362359491","pt":1588443973209,"mc":[{"id":"1.170370564","rc":[{"atb":[[4.1,2.33]],"id":9630572}],"con":true,"img":false}]}
{"op":"mcm","clk":"1362359494","pt":1588443974790,"mc":[{"id":"1.170370564","rc":[{"atb":[[3.8,13.12]],"id":9630572}],"con":true,"img":false}]}
{"op":"mcm","clk":"1362359497","pt":1588443974994,"mc":[{"id":"1.170370564","rc":[{"atb":[[4,21.71]],"id":9630572}],"con":true,"img":false}]}
{"op":"mcm","clk":"1362359778","pt":1588444089994,"mc":[{"id":"1.170370564","rc":[{"atb":[[4.1,0]],"id":9630572}],"con":true,"img":false}]}
{"op":"mcm","clk":"1362359779","pt":1588444090299,"mc":[{"id":"1.170370564","rc":[{"atb":[[4.4,0]],"id":9630572},{"atl":[[5.2,0]],"id":9630572},{"atb":[[1.22,52]],"id":8509691},{"atl":[[1.3,0]],"id":8509691}],"con":true,"img":false}]}
{"op":"mcm","clk":"1362359783","pt":1588444090504,"mc":[{"id":"1.170370564","rc":[{"atb":[[4,18.58],[4.4,2.01]],"id":9630572},{"atl":[[5.2,2.03]],"id":9630572},{"atb":[[1.22,54.02]],"id":8509691},{"atl":[[1.3,2.05]],"id":8509691}],"con":true,"img":false}]}
{"op":"mcm","clk":"1362359784","pt":1588444090707,"mc":[{"id":"1.170370564","rc":[{"atb":[[3.8,16.41]],"id":9630572}],"con":true,"img":false}]}
{"op":"mcm","clk":"1362359785","pt":1588444093311,"mc":[{"id":"1.170370564","rc":[{"atb":[[4.1,2.33]],"id":9630572}],"con":true,"img":false}]}
{"op":"mcm","clk":"1362359788","pt":1588444094893,"mc":[{"id":"1.170370564","rc":[{"atb":[[3.8,13.12]],"id":9630572}],"con":true,"img":false}]}
{"op":"mcm","clk":"1362359789","pt":1588444095097,"mc":[{"id":"1.170370564","rc":[{"atb":[[4,21.71]],"id":9630572}],"con":true,"img":false}]}
{"op":"mcm","clk":"1362361026","pt":1588444159693,"mc":[{"id":"1.170370564","rc":[{"atb":[[1.01,1896.54]],"id":8509691}],"con":true,"img":false}]}
{"op":"mcm","clk":"1362361034","pt":1588444160408,"mc":[{"id":"1.170370564","rc":[{"atb":[[1.01,1896.49]],"id":8509691}],"con":true,"img":false}]}
{"op":"mcm","clk":"1362361040","pt":1588444161018,"mc":[{"id":"1.170370564","rc":[{"atb":[[4.4,0]],"id":9630572},{"atl":[[5.2,0]],"id":9630572},{"atb":[[1.22,52]],"id":8509691},{"atl":[[1.3,0]],"id":8509691}],"con":true,"img":false}]}
{"op":"mcm","clk":"1362361042","pt":1588444161223,"mc":[{"id":"1.170370564","rc":[{"atb":[[4.4,2.01]],"id":9630572},{"atl":[[5.2,2.03]],"id":9630572},{"atb":[[1.01,1893.34],[1.22,54.02]],"id":8509691},{"atl":[[1.3,2.05]],"id":8509691}],"con":true,"img":false}]}
{"op":"mcm","clk":"1362361044","pt":1588444161325,"mc":[{"id":"1.170370564","rc":[{"trd":[[1.27,2747.18]],"ltp":1.27,"tv":2747.18,"id":8509691},{"atl":[[1.27,121.95]],"id":8509691}],"con":true,"img":false}]}
{"op":"mcm","clk":"1362361471","pt":1588444210484,"mc":[{"id":"1.170370564","rc":[{"atb":[[4.1,0]],"id":9630572}],"con":true,"img":false}]}
{"op":"mcm","clk":"1362361473","pt":1588444210791,"mc":[{"id":"1.170370564","rc":[{"atb":[[4.4,0]],"id":9630572},{"atl":[[5.2,0]],"id":9630572},{"atb":[[1.22,52]],"id":8509691},{"atl":[[1.3,0]],"id":8509691}],"con":true,"img":false}]}
{"op":"mcm","clk":"1362361476","pt":1588444210996,"mc":[{"id":"1.170370564","rc":[{"atb":[[4,18.58],[4.4,2.01]],"id":9630572},{"atl":[[5.2,2.03]],"id":9630572},{"atb":[[1.22,54.02]],"id":8509691},{"atl":[[1.3,2.02]],"id":8509691}],"con":true,"img":false}]}
{"op":"mcm","clk":"1362361479","pt":1588444211201,"mc":[{"id":"1.170370564","rc":[{"atb":[[3.8,16.41]],"id":9630572}],"con":true,"img":false}]}
{"op":"mcm","clk":"1362361502","pt":1588444214418,"mc":[{"id":"1.170370564","rc":[{"atb":[[4.1,2.33]],"id":9630572}],"con":true,"img":false}]}
{"op":"mcm","clk":"1362361508","pt":1588444215235,"mc":[{"id":"1.170370564","rc":[{"atb":[[3.8,13.12]],"id":9630572}],"con":true,"img":false}]}
{"op":"mcm","clk":"1362361512","pt":1588444215389,"mc":[{"id":"1.170370564","rc":[{"atb":[[4,21.71]],"id":9630572}],"con":true,"img":false}]}
{"op":"mcm","clk":"1362362417","pt":1588444332851,"mc":[{"id":"1.170370564","rc":[{"atb":[[4.1,0]],"id":9630572}],"con":true,"img":false}]}
{"op":"mcm","clk":"1362362421","pt":1588444333158,"mc":[{"id":"1.170370564","rc":[{"atl":[[1.3,0]],"id":8509691}],"con":true,"img":false}]}
{"op":"mcm","clk":"1362362423","pt":1588444333260,"mc":[{"id":"1.170370564","rc":[{"atb":[[4.4,0]],"id":9630572},{"atl":[[5.2,0]],"id":9630572},{"atb":[[1.22,52]],"id":8509691}],"con":true,"img":false}]}
{"op":"mcm","clk":"1362362425","pt":1588444333362,"mc":[{"id":"1.170370564","rc":[{"atl":[[1.3,2.05]],"id":8509691}],"con":true,"img":false}]}
{"op":"mcm","clk":"1362362427","pt":1588444333464,"mc":[{"id":"1.170370564","rc":[{"atb":[[4.4,2.01]],"id":9630572},{"atl":[[5.2,2.03]],"id":9630572},{"atb":[[1.22,54.02]],"id":8509691}],"con":true,"img":false}]}
{"op":"mcm","clk":"1362362429","pt":1588444333974,"mc":[{"id":"1.170370564","rc":[{"atb":[[4,18.58]],"id":9630572}],"con":true,"img":false}]}
{"op":"mcm","clk":"1362362431","pt":1588444334180,"mc":[{"id":"1.170370564","rc":[{"atb":[[4.1,2.33],[3.8,16.41]],"id":9630572}],"con":true,"img":false}]}
{"op":"mcm","clk":"1362362448","pt":1588444335766,"mc":[{"id":"1.170370564","rc":[{"atb":[[3.8,13.12]],"id":9630572}],"con":true,"img":false}]}
{"op":"mcm","clk":"1362362450","pt":1588444335971,"mc":[{"id":"1.170370564","rc":[{"atb":[[4,21.71]],"id":9630572}],"con":true,"img":false}]}
{"op":"mcm","clk":"1362362618","pt":1588444356007,"mc":[{"id":"1.170370566","rc":[{"atl":[[1.46,2.62]],"id":8509691}],"con":true,"img":false}]}
{"op":"mcm","clk":"1362362743","pt":1588444369001,"mc":[{"id":"1.170370564","rc":[{"trd":[[1.27,2989.18]],"ltp":1.27,"tv":2989.18,"id":8509691},{"atl":[[1.27,0.95]],"id":8509691}],"con":true,"img":false}]}
{"op":"mcm","clk":"1362362745","pt":1588444369205,"mc":[{"id":"1.170370564","rc":[{"atl":[[1.31,2]],"id":8509691}],"con":true,"img":false}]}
{"op":"mcm","clk":"1362362747","pt":1588444369310,"mc":[{"id":"1.170370564","rc":[{"atb":[[4.4,0]],"id":9630572},{"atl":[[5.2,0]],"id":9630572},{"atl":[[1.29,50]],"id":8509691}],"con":true,"img":false}]}
{"op":"mcm","clk":"1362362748","pt":1588444369410,"mc":[{"id":"1.170370564","rc":[{"atb":[[1.22,52]],"id":8509691}],"con":true,"img":false}]}
{"op":"mcm","clk":"1362362750","pt":1588444369613,"mc":[{"id":"1.170370564","rc":[{"atb":[[4.4,2.01]],"id":9630572},{"atl":[[5.2,2.03]],"id":9630572},{"atb":[[1.22,54.02]],"id":8509691}],"con":true,"img":false}]}
{"op":"mcm","clk":"1362362757","pt":1588444370123,"mc":[{"id":"1.170370564","rc":[{"atb":[[4.3,8.05]],"id":9630572},{"atb":[[1.22,142.67]],"id":8509691}],"con":true,"img":false}]}
{"op":"mcm","clk":"1362362759","pt":1588444370226,"mc":[{"id":"1.170370564","rc":[{"atb":[[4.5,4.1]],"id":9630572}],"con":true,"img":false}]}
{"op":"mcm","clk":"1362362760","pt":1588444370532,"mc":[{"id":"1.170370564","rc":[{"atb":[[4,18.58]],"id":9630572}],"con":true,"img":false}]}
{"op":"mcm","clk":"1362362763","pt":1588444370736,"mc":[{"id":"1.170370564","rc":[{"atb":[[4.1,5.38]],"id":9630572}],"con":true,"img":false}]}
{"op":"mcm","clk":"1362362874","pt":1588444384718,"mc":[{"id":"1.170370564","rc":[{"atb":[[1.26,100]],"id":8509691}],"con":true,"img":false}]}
{"op":"mcm","clk":"1362362881","pt":1588444384924,"mc":[{"id":"1.170370564","rc":[{"atb":[[4.4,0]],"id":9630572},{"atl":[[5.2,0]],"id":9630572},{"atb":[[1.22,140.65],[1.24,52.02]],"id":8509691},{"atl":[[1.31,0]],"id":8509691}],"con":true,"img":false}]}
{"op":"mcm","clk":"1362362886","pt":1588444385128,"mc":[{"id":"1.170370564","rc":[{"atb":[[4.4,2.01]],"id":9630572},{"atl":[[5.2,2.03]],"id":9630572},{"atb":[[1.23,137.47]],"id":8509691},{"atl":[[1.31,2.21]],"id":8509691}],"con":true,"img":false}]}
{"op":"mcm","clk":"1362362890","pt":1588444385335,"mc":[{"id":"1.170370564","rc":[{"atb":[[1.23,139.49]],"id":8509691}],"con":true,"img":false}]}
{"op":"mcm","clk":"1362362902","pt":1588444386257,"mc":[{"id":"1.170370564","rc":[{"atl":[[1.33,6.39]],"id":8509691}],"con":true,"img":false}]}
{"op":"mcm","clk":"1362362904","pt":1588444386410,"mc":[{"id":"1.170370564","rc":[{"atl":[[1.28,179.76]],"id":8509691}],"con":true,"img":false}]}
{"op":"mcm","clk":"1362362992","pt":1588444396963,"mc":[{"id":"1.170370567","rc":[{"atl":[[1.45,2.62]],"id":8509691}],"con":true,"img":false}]}
{"op":"mcm","clk":"1362363012","pt":1588444399675,"mc":[{"id":"1.170370564","rc":[{"atb":[[1.25,651.1]],"id":8509691}],"con":true,"img":false}]}
{"op":"mcm","clk":"1362363016","pt":1588444399933,"mc":[{"id":"1.170370564","rc":[{"atb":[[4.4,0]],"id":9630572},{"atl":[[5.2,0]],"id":9630572},{"atb":[[1.23,137.47]],"id":8509691},{"atl":[[1.31,0]],"id":8509691}],"con":true,"img":false}]}
{"op":"mcm","clk":"1362363018","pt":1588444400148,"mc":[{"id":"1.170370564","rc":[{"atb":[[4.4,2.01]],"id":9630572},{"atl":[[5.2,2.03]],"id":9630572},{"atb":[[1.23,139.49]],"id":8509691},{"atl":[[1.31,2.05]],"id":8509691}],"con":true,"img":false}]}
{"op":"mcm","clk":"1362363162","pt":1588444421181,"mc":[{"id":"1.170370564","rc":[{"atl":[[1.28,129.76]],"id":8509691}],"con":true,"img":false}]}
{"op":"mcm","clk":"1362363164","pt":1588444421281,"mc":[{"id":"1.170370564","rc":[{"atl":[[1.3,52.05]],"id":8509691}],"con":true,"img":false}]}
{"op":"mcm","clk":"1362363166","pt":1588444421485,"mc":[{"id":"1.170370564","rc":[{"atb":[[4.4,0]],"id":9630572},{"atl":[[5.2,0]],"id":9630572},{"atb":[[1.23,137.47]],"id":8509691},{"atl":[[1.31,0]],"id":8509691}],"con":true,"img":false}]}
{"op":"mcm","clk":"1362363167","pt":1588444421690,"mc":[{"id":"1.170370564","rc":[{"atb":[[4.4,2.01]],"id":9630572},{"atl":[[5.2,2.03]],"id":9630572},{"atb":[[1.23,139.49]],"id":8509691},{"atl":[[1.31,2.21]],"id":8509691}],"con":true,"img":false}]}
{"op":"mcm","clk":"1362363200","pt":1588444425566,"mc":[{"id":"1.170370564","rc":[{"atl":[[4.8,48.75]],"id":9630572}],"con":true,"img":false}]}
{"op":"mcm","clk":"1362363203","pt":1588444425666,"mc":[{"id":"1.170370564","rc":[{"atl":[[5,2]],"id":9630572}],"con":true,"img":false}]}
{"op":"mcm","clk":"1362363208","pt":1588444425973,"mc":[{"id":"1.170370564","rc":[{"atl":[[5.1,0]],"id":9630572}],"con":true,"img":false}]}
{"op":"mcm","clk":"1362363209","pt":1588444426176,"mc":[{"id":"1.170370564","rc":[{"atl":[[5.1,2]],"id":9630572},{"atb":[[1.23,228.14]],"id":8509691}],"con":true,"img":false}]}
{"op":"mcm","clk":"1362363225","pt":1588444427806,"mc":[{"id":"1.170370564","rc":[{"atl":[[1.28,120]],"id":8509691}],"con":true,"img":false}]}
{"op":"mcm","clk":"1362363227","pt":1588444428010,"mc":[{"id":"1.170370564","rc":[{"atl":[[1.31,11.75]],"id":8509691}],"con":true,"img":false}]}
{"op":"mcm","clk":"1362363229","pt":1588444428112,"mc":[{"id":"1.170370564","rc":[{"atb":[[4.4,0]],"id":9630572},{"atl":[[5.2,0]],"id":9630572}],"con":true,"img":false}]}
{"op":"mcm","clk":"1362363230","pt":1588444428214,"mc":[{"id":"1.170370564","rc":[{"atb":[[1.23,226.12]],"id":8509691},{"atl":[[1.31,9.54]],"id":8509691}],"con":true,"img":false}]}
{"op":"mcm","clk":"1362363232","pt":1588444428267,"mc":[{"id":"1.170370564","rc":[{"atb":[[4.1,2.33]],"id":9630572}],"con":true,"img":false}]}
{"op":"mcm","clk":"1362363234","pt":1588444428368,"mc":[{"id":"1.170370564","rc":[{"atb":[[4.4,2.01]],"id":9630572},{"atb":[[1.23,228.14]],"id":8509691},{"atl":[[1.31,11.59]],"id":8509691}],"con":true,"img":false}]}
{"op":"mcm","clk":"1362363236","pt":1588444428470,"mc":[{"id":"1.170370564","rc":[{"atb":[[4.4,4.86]],"id":9630572}],"con":true,"img":false}]}
{"op":"mcm","clk":"1362363251","pt":1588444431016,"mc":[{"id":"1.170370564","rc":[{"atb":[[1.27,25.29]],"id":8509691},{"atl":[[1.27,0]],"id":8509691}],"con":true,"img":false}]}
{"op":"mcm","clk":"1362363253","pt":1588444431171,"mc":[{"id":"1.170370564","rc":[{"atb":[[1.25,653.11]],"id":8509691},{"atl":[[1.31,2.05]],"id":8509691}],"con":true,"img":false}]}
{"op":"mcm","clk":"1362363255","pt":1588444431377,"mc":[{"id":"1.170370564","rc":[{"atb":[[1.24,50]],"id":8509691},{"atl":[[1.3,61.66]],"id":8509691}],"con":true,"img":false}]}
{"op":"mcm","clk":"1362363258","pt":1588444431580,"mc":[{"id":"1.170370564","rc":[{"atb":[[1.24,52.02]],"id":8509691}],"con":true,"img":false}]}
{"op":"mcm","clk":"1362363288","pt":1588444436212,"mc":[{"id":"1.170370564","rc":[{"atl":[[1.3,52.05]],"id":8509691}],"con":true,"img":false}]}
{"op":"mcm","clk":"1362363291","pt":1588444436519,"mc":[{"id":"1.170370564","rc":[{"atb":[[4.4,2.85]],"id":9630572},{"atl":[[5.1,0]],"id":9630572},{"atb":[[1.23,226.12]],"id":8509691},{"atl":[[1.31,0]],"id":8509691}],"con":true,"img":false}]}
{"op":"mcm","clk":"1362363293","pt":1588444436722,"mc":[{"id":"1.170370564","rc":[{"atb":[[4.4,4.86]],"id":9630572},{"atl":[[5.1,2.05]],"id":9630572},{"atl":[[1.31,2.05]],"id":8509691}],"con":true,"img":false}]}
{"op":"mcm","clk":"1362363333","pt":1588444443010,"mc":[{"id":"1.170370564","rc":[{"atb":[[4.6,68.26]],"id":9630572}],"con":true,"img":false}]}
{"op":"mcm","clk":"1362363336","pt":1588444443322,"mc":[{"id":"1.170370564","rc":[{"atb":[[4.4,2.85]],"id":9630572},{"atl":[[5.1,0]],"id":9630572},{"atb":[[1.24,50]],"id":8509691},{"atl":[[1.31,0]],"id":8509691}],"con":true,"img":false}]}
{"op":"mcm","clk":"1362363338","pt":1588444443526,"mc":[{"id":"1.170370564","rc":[{"atb":[[4.4,4.86]],"id":9630572},{"atl":[[5.1,2.05]],"id":9630572},{"atb":[[1.24,52]],"id":8509691},{"atl":[[1.31,2.02]],"id":8509691}],"con":true,"img":false}]}
{"op":"mcm","clk":"1362363344","pt":1588444444138,"mc":[{"id":"1.170370564","rc":[{"atb":[[4.4,12.67]],"id":9630572}],"con":true,"img":false}]}
{"op":"mcm","clk":"1362363346","pt":1588444444240,"mc":[{"id":"1.170370564","rc":[{"atb":[[1.23,137.47]],"id":8509691}],"con":true,"img":false}]}
{"op":"mcm","clk":"1362363354","pt":1588444445419,"mc":[{"id":"1.170370564","rc":[{"atb":[[4,0]],"id":9630572},{"atb":[[1.2,88.65]],"id":8509691}],"con":true,"img":false}]}
{"op":"mcm","clk":"1362363371","pt":1588444447148,"mc":[{"id":"1.170370564","rc":[{"atl":[[1.28,129.76]],"id":8509691}],"con":true,"img":false}]}
{"op":"mcm","clk":"1362363375","pt":1588444447454,"mc":[{"id":"1.170370564","rc":[{"atb":[[4.4,9.82]],"id":9630572}],"con":true,"img":false}]}
{"op":"mcm","clk":"1362363376","pt":1588444447659,"mc":[{"id":"1.170370564","rc":[{"atb":[[4.6,70.98]],"id":9630572}],"con":true,"img":false}]}
{"op":"mcm","clk":"1362363441","pt":1588444456580,"mc":[{"id":"1.170370564","rc":[{"atb":[[4.1,0]],"id":9630572}],"con":true,"img":false}]}
{"op":"mcm","clk":"1362363444","pt":1588444456887,"mc":[{"id":"1.170370564","rc":[{"atb":[[4.4,7.81]],"id":9630572},{"atl":[[5.1,0]],"id":9630572},{"atb":[[1.24,50]],"id":8509691},{"atl":[[1.31,0]],"id":8509691}],"con":true,"img":false}]}
{"op":"mcm","clk":"1362363445","pt":1588444457091,"mc":[{"id":"1.170370564","rc":[{"atb":[[4.4,9.82]],"id":9630572},{"atl":[[5.1,2]],"id":9630572},{"atb":[[1.24,52.02]],"id":8509691},{"atl":[[1.31,2.21]],"id":8509691}],"con":true,"img":false}]}
{"op":"mcm","clk":"1362363470","pt":1588444460308,"mc":[{"id":"1.170370564","rc":[{"atb":[[4.1,2.33]],"id":9630572}],"con":true,"img":false}]}
{"op":"mcm","clk":"1362363960","pt":1588444522668,"mc":[{"id":"1.170370564","rc":[{"trd":[[1.27,3008.42]],"ltp":1.27,"tv":3008.42,"id":8509691},{"atb":[[1.27,15.66]],"id":8509691}],"con":true,"img":false}]}
{"op":"mcm","clk":"1362363963","pt":1588444522974,"mc":[{"id":"1.170370564","rc":[{"atb":[[4.4,7.81]],"id":9630572},{"atl":[[5.1,0]],"id":9630572},{"atb":[[1.24,50]],"id":8509691},{"atl":[[1.31,0]],"id":8509691}],"con":true,"img":false}]}
{"op":"mcm","clk":"1362363965","pt":1588444523179,"mc":[{"id":"1.170370564","rc":[{"atb":[[4.4,9.82]],"id":9630572},{"atl":[[5.1,2.05]],"id":9630572},{"atb":[[1.24,52.02]],"id":8509691},{"atl":[[1.31,2.21]],"id":8509691}],"con":true,"img":false}]}
{"op":"mcm","clk":"1362364370","pt":1588444567941,"mc":[{"id":"1.170370566","rc":[{"trd":[[1.46,3.59]],"ltp":1.46,"tv":3.59,"id":8509691},{"atl":[[1.46,0.82]],"id":8509691}],"con":true,"img":false}]}
{"op":"mcm","clk":"1362364410","pt":1588444571560,"mc":[{"id":"1.170370564","rc":[{"trd":[[1.28,3633.35]],"ltp":1.28,"tv":3633.35,"id":8509691},{"atl":[[1.28,93.77]],"id":8509691}],"con":true,"img":false}]}
{"op":"mcm","clk":"1362364412","pt":1588444571865,"mc":[{"id":"1.170370564","rc":[{"atl":[[5.1,0]],"id":9630572},{"atl":[[1.31,0]],"id":8509691}],"con":true,"img":false}]}
{"op":"mcm","clk":"1362364415","pt":1588444571918,"mc":[{"id":"1.170370564","rc":[{"atb":[[4.4,7.81]],"id":9630572},{"atb":[[1.24,50]],"id":8509691}],"con":true,"img":false}]}
{"op":"mcm","clk":"1362364418","pt":1588444572121,"mc":[{"id":"1.170370564","rc":[{"atb":[[4.4,9.82]],"id":9630572},{"atl":[[5.1,2.05]],"id":9630572},{"atb":[[1.24,52.02]],"id":8509691},{"atl":[[1.31,2]],"id":8509691}],"con":true,"img":false}]}
{"op":"mcm","clk":"1362364430","pt":1588444573240,"mc":[{"id":"1.170370564","rc":[{"atb":[[4.1,0]],"id":9630572}],"con":true,"img":false}]}
{"op":"mcm","clk":"1362364445","pt":1588444574463,"mc":[{"id":"1.170370564","rc":[{"atb":[[4.1,2.33]],"id":9630572}],"con":true,"img":false}]}
{"op":"mcm","clk":"1362364476","pt":1588444578031,"mc":[{"id":"1.170370566","rc":[{"atl":[[1.46,0]],"id":8509691}],"con":true,"img":false}]}
{"op":"mcm","clk":"1362364523","pt":1588444583340,"mc":[{"id":"1.170370567","rc":[{"trd":[[1.45,3.59]],"ltp":1.45,"tv":3.59,"id":8509691},{"atl":[[1.45,0.82]],"id":8509691}],"con":true,"img":false}]}
{"op":"mcm","clk":"1362364658","pt":1588444598949,"mc":[{"id":"1.170370566","rc":[{"atb":[[1.34,2.62]],"id":8509691}],"con":true,"img":false}]}
{"op":"mcm","clk":"1362364937","pt":1588444628287,"mc":[{"id":"1.170370564","rc":[{"trd":[[1.27,3039.76]],"ltp":1.27,"tv":3039.76,"id":8509691},{"atb":[[1.27,0]],"id":8509691},{"atl":[[1.27,9.33]],"id":8509691}],"con":true,"img":false}]}
{"op":"mcm","clk":"1362364939","pt":1588444628391,"mc":[{"id":"1.170370564","rc":[{"atb":[[1.23,139.49]],"id":8509691},{"atl":[[1.29,52.19]],"id":8509691}],"con":true,"img":false}]}
{"op":"mcm","clk":"1362364940","pt":1588444628492,"mc":[{"id":"1.170370564","rc":[{"atl":[[5.1,0]],"id":9630572},{"trd":[[1.27,3058.42]],"ltp":1.27,"tv":3058.42,"id":8509691},{"atb":[[1.27,0.01],[1.25,651.1]],"id":8509691},{"atl":[[1.27,0],[1.31,0]],"id":8509691}],"con":true,"img":false}]}
{"op":"mcm","clk":"1362364942","pt":1588444628594,"mc":[{"id":"1.170370564","rc":[{"atb":[[4.4,7.81]],"id":9630572}],"con":true,"img":false}]}
{"op":"mcm","clk":"1362364943","pt":1588444628696,"mc":[{"id":"1.170370564","rc":[{"atl":[[5.1,2.05]],"id":9630572},{"atb":[[1.27,0]],"id":8509691},{"atl":[[1.31,2.05]],"id":8509691}],"con":true,"img":false}]}
{"op":"mcm","clk":"1362364945","pt":1588444628902,"mc":[{"id":"1.170370564","rc":[{"atl":[[1.29,50]],"id":8509691}],"con":true,"img":false}]}
{"op":"mcm","clk":"1362364947","pt":1588444629002,"mc":[{"id":"1.170370564","rc":[{"atb":[[4.4,9.82]],"id":9630572}],"con":true,"img":false}]}
{"op":"mcm","clk":"1362364960","pt":1588444630583,"mc":[{"id":"1.170370564","rc":[{"atb":[[4,18.58]],"id":9630572},{"atb":[[1.2,367.45]],"id":8509691}],"con":true,"img":false}]}
{"op":"mcm","clk":"1362365253","pt":1588444666959,"mc":[{"id":"1.170370565","rc":[{"atb":[[1.67,0]],"id":11269555}],"con":true,"img":false}]}
{"op":"mcm","clk":"1362365256","pt":1588444667163,"mc":[{"id":"1.170370565","rc":[{"atb":[[3.45,0]],"id":11269557}],"con":true,"img":false}]}
{"op":"mcm","clk":"1362365258","pt":1588444667367,"mc":[{"id":"1.170370565","rc":[{"atb":[[8,10]],"id":11340557}],"con":true,"img":false}]}
{"op":"mcm","clk":"1362365259","pt":1588444667571,"mc":[{"id":"1.170370565","rc":[{"atb":[[7.2,0]],"id":11340560}],"con":true,"img":false}]}
{"op":"mcm","clk":"1362365267","pt":1588444668031,"mc":[{"id":"1.170370565","rc":[{"atb":[[7.8,6]],"id":11340557},{"atb":[[7.2,6]],"id":11340560},{"atb":[[1.67,9]],"id":11269555},{"atb":[[3.45,5]],"id":11269557}],"con":true,"img":false}]}
{"op":"mcm","clk":"1362365469","pt":1588444696459,"mc":[{"id":"1.170370564","rc":[{"atb":[[4.1,0]],"id":9630572}],"con":true,"img":false}]}
{"op":"mcm","clk":"1362365472","pt":1588444696766,"mc":[{"id":"1.170370564","rc":[{"atb":[[4.4,7.81]],"id":9630572},{"atl":[[5.1,0]],"id":9630572},{"atb":[[1.23,137.47]],"id":8509691},{"atl":[[1.31,0]],"id":8509691}],"con":true,"img":false}]}
{"op":"mcm","clk":"1362365476","pt":1588444696968,"mc":[{"id":"1.170370564","rc":[{"atb":[[4.4,9.82]],"id":9630572},{"atl":[[5.1,2.05]],"id":9630572},{"atb":[[1.23,139.49]],"id":8509691},{"atl":[[1.31,2.21]],"id":8509691}],"con":true,"img":false}]}
{"op":"mcm","clk":"1362365488","pt":1588444698394,"mc":[{"id":"1.170370564","rc":[{"atb":[[4.1,2.33]],"id":9630572}],"con":true,"img":false}]}
{"op":"mcm","clk":"1362365526","pt":1588444701708,"mc":[{"id":"1.170370564","rc":[{"atb":[[1.26,1084.92]],"id":8509691}],"con":true,"img":false}]}
{"op":"mcm","clk":"1362365531","pt":1588444702373,"mc":[{"id":"1.170370564","rc":[{"atl":[[1.28,84.01]],"id":8509691}],"con":true,"img":false}]}
{"op":"mcm","clk":"1362365534","pt":1588444702579,"mc":[{"id":"1.170370564","rc":[{"atb":[[4.4,7.81]],"id":9630572},{"atl":[[5.1,0]],"id":9630572},{"atb":[[1.23,137.47]],"id":8509691},{"atl":[[1.33,15.78],[1.31,0]],"id":8509691}],"con":true,"img":false}]}
{"op":"mcm","clk":"1362365535","pt":1588444702782,"mc":[{"id":"1.170370564","rc":[{"atb":[[4.4,9.82]],"id":9630572},{"atl":[[5.1,2.05]],"id":9630572},{"atb":[[1.26,100],[1.23,139.49]],"id":8509691},{"atl":[[1.31,2]],"id":8509691}],"con":true,"img":false}]}
{"op":"mcm","clk":"1362365544","pt":1588444704210,"mc":[{"id":"1.170370564","rc":[{"atl":[[1.33,6.39]],"id":8509691}],"con":true,"img":false}]}
{"op":"mcm","clk":"1362365548","pt":1588444704414,"mc":[{"id":"1.170370564","rc":[{"atl":[[1.28,93.77]],"id":8509691}],"con":true,"img":false}]}
{"op":"mcm","clk":"1362365681","pt":1588444722894,"mc":[{"id":"1.170370564","rc":[{"trd":[[1.28,3637.35]],"ltp":1.28,"tv":3637.35,"id":8509691},{"atl":[[1.28,91.77]],"id":8509691}],"con":true,"img":false}]}
{"op":"mcm","clk":"1362365685","pt":1588444723199,"mc":[{"id":"1.170370564","rc":[{"atb":[[4.4,7.81]],"id":9630572},{"atl":[[5.1,0]],"id":9630572},{"atb":[[1.23,137.47]],"id":8509691},{"atl":[[1.31,0]],"id":8509691}],"con":true,"img":false}]}
{"op":"mcm","clk":"1362365687","pt":1588444723402,"mc":[{"id":"1.170370564","rc":[{"atb":[[4.4,9.82]],"id":9630572},{"atl":[[5.1,2]],"id":9630572},{"atb":[[1.23,139.47]],"id":8509691},{"atl":[[1.31,2]],"id":8509691}],"con":true,"img":false}]}
{"op":"mcm","clk":"1362365772","pt":1588444734923,"mc":[{"id":"1.170370564","rc":[{"atb":[[1.26,150.46]],"id":8509691}],"con":true,"img":false}]}
{"op":"mcm","clk":"1362365775","pt":1588444735228,"mc":[{"id":"1.170370564","rc":[{"atb":[[4.4,7.81]],"id":9630572},{"atl":[[5.1,0]],"id":9630572},{"atb":[[1.23,137.47]],"id":8509691},{"atl":[[1.31,0]],"id":8509691}],"con":true,"img":false}]}
{"op":"mcm","clk":"1362365779","pt":1588444735432,"mc":[{"id":"1.170370564","rc":[{"atb":[[4.4,9.82]],"id":9630572},{"atl":[[5.1,2.05]],"id":9630572},{"atb":[[1.23,139.49]],"id":8509691},{"atl":[[1.31,2.21]],"id":8509691}],"con":true,"img":false}]}
{"op":"mcm","clk":"1362365788","pt":1588444736405,"mc":[{"id":"1.170370564","rc":[{"atl":[[1.28,82.01]],"id":8509691}],"con":true,"img":false}]}
{"op":"mcm","clk":"1362365909","pt":1588444749745,"mc":[{"id":"1.170370564","rc":[{"trd":[[4.7,164.97]],"ltp":4.7,"tv":164.97,"id":9630572},{"atb":[[4.7,1.35]],"id":9630572}],"con":true,"img":false}]}
{"op":"mcm","clk":"1362365911","pt":1588444749949,"mc":[{"id":"1.170370564","rc":[{"atb":[[4.3,10.13]],"id":9630572}],"con":true,"img":false}]}
{"op":"mcm","clk":"1362365913","pt":1588444750051,"mc":[{"id":"1.170370564","rc":[{"atb":[[4.5,2]],"id":9630572},{"atl":[[5.1,0]],"id":9630572},{"atl":[[1.31,0]],"id":8509691}],"con":true,"img":false}]}
{"op":"mcm","clk":"1362365914","pt":1588444750154,"mc":[{"id":"1.170370564","rc":[{"atb":[[1.23,137.47]],"id":8509691}],"con":true,"img":false}]}
{"op":"mcm","clk":"1362365915","pt":1588444750256,"mc":[{"id":"1.170370564","rc":[{"atl":[[5.1,2.05]],"id":9630572},{"atl":[[1.31,2.21]],"id":8509691}],"con":true,"img":false}]}
{"op":"mcm","clk":"1362365916","pt":1588444750357,"mc":[{"id":"1.170370564","rc":[{"atb":[[1.23,139.49]],"id":8509691}],"con":true,"img":false}]}
{"op":"mcm","clk":"1362366067","pt":1588444767548,"mc":[{"id":"1.170370564","rc":[{"trd":[[4.7,167.67]],"ltp":4.7,"tv":167.67,"id":9630572},{"atb":[[4.7,0]],"id":9630572},{"atl":[[4.7,123.16]],"id":9630572}],"con":true,"img":false}]}
{"op":"mcm","clk":"1362366068","pt":1588444767650,"mc":[{"id":"1.170370564","rc":[{"atl":[[4.9,494.07]],"id":9630572}],"con":true,"img":false}]}
{"op":"mcm","clk":"1362366069","pt":1588444767750,"mc":[{"id":"1.170370564","rc":[{"atl":[[4.7,124.93]],"id":9630572}],"con":true,"img":false}]}
{"op":"mcm","clk":"1362366070","pt":1588444767855,"mc":[{"id":"1.170370564","rc":[{"atb":[[4.3,8.05]],"id":9630572},{"atl":[[5.1,0]],"id":9630572},{"atb":[[1.23,137.47]],"id":8509691},{"atl":[[1.31,0]],"id":8509691}],"con":true,"img":false}]}
{"op":"mcm","clk":"1362366071","pt":1588444767955,"mc":[{"id":"1.170370564","rc":[{"atb":[[4.3,10.05]],"id":9630572},{"atl":[[4.7,123.16]],"id":9630572},{"atb":[[1.26,100],[1.25,653.11]],"id":8509691},{"atl":[[1.31,2.21]],"id":8509691}],"con":true,"img":false}]}
{"op":"mcm","clk":"1362366072","pt":1588444768081,"mc":[{"id":"1.170370564","rc":[{"atl":[[5,0]],"id":9630572}],"con":true,"img":false}]}
{"op":"mcm","clk":"1362366074","pt":1588444768181,"mc":[{"id":"1.170370564","rc":[{"atb":[[1.23,226.12]],"id":8509691}],"con":true,"img":false}]}
{"op":"mcm","clk":"1362366075","pt":1588444768284,"mc":[{"id":"1.170370564","rc":[{"atb":[[1.24,50]],"id":8509691}],"con":true,"img":false}]}
{"op":"mcm","clk":"1362366076","pt":1588444768386,"mc":[{"id":"1.170370564","rc":[{"atl":[[5,2]],"id":9630572}],"con":true,"img":false}]}
{"op":"mcm","clk":"1362366078","pt":1588444768488,"mc":[{"id":"1.170370564","rc":[{"atb":[[1.24,52.02]],"id":8509691}],"con":true,"img":false}]}
{"op":"mcm","clk":"1362366091","pt":1588444769970,"mc":[{"id":"1.170370564","rc":[{"atl":[[1.3,61.66]],"id":8509691}],"con":true,"img":false}]}
{"op":"mcm","clk":"1362366093","pt":1588444770277,"mc":[{"id":"1.170370564","rc":[{"atb":[[4.6,68.26]],"id":9630572}],"con":true,"img":false}]}
{"op":"mcm","clk":"1362366110","pt":1588444771451,"mc":[{"id":"1.170370564","rc":[{"atb":[[4.4,12.67]],"id":9630572}],"con":true,"img":false}]}
{"op":"mcm","clk":"1362366263","pt":1588444787507,"mc":[{"id":"1.170370564","rc":[{"trd":[[4.6,71.16]],"ltp":4.6,"tv":71.16,"id":9630572},{"atb":[[4.6,29.3]],"id":9630572},{"trd":[[1.28,3941.36]],"ltp":1.28,"tv":3941.36,"id":8509691},{"atl":[[1.28,0]],"id":8509691}],"con":true,"img":false}]}
{"op":"mcm","clk":"1362366268","pt":1588444787661,"mc":[{"id":"1.170370564","rc":[{"trd":[[4.6,90.9]],"ltp":4.6,"tv":90.9,"id":9630572},{"atb":[[4.6,9.57]],"id":9630572},{"trd":[[1.28,4012.29]],"ltp":1.28,"tv":4012.29,"id":8509691},{"atl":[[1.32,2.05]],"id":8509691}],"con":true,"img":false}]}
{"op":"mcm","clk":"1362366269","pt":1588444787764,"mc":[{"id":"1.170370564","rc":[{"atl":[[5,0]],"id":9630572},{"atb":[[1.24,50]],"id":8509691},{"atl":[[1.3,59.61]],"id":8509691}],"con":true,"img":false}]}
{"op":"mcm","clk":"1362366270","pt":1588444787867,"mc":[{"id":"1.170370564","rc":[{"atb":[[4.3,8.05]],"id":9630572}],"con":true,"img":false}]}
{"op":"mcm","clk":"1362366272","pt":1588444787969,"mc":[{"id":"1.170370564","rc":[{"atl":[[1.3,50]],"id":8509691}],"con":true,"img":false}]}
{"op":"mcm","clk":"1362366273","pt":1588444788069,"mc":[{"id":"1.170370564","rc":[{"atb":[[4.3,10.13]],"id":9630572},{"atl":[[5,2]],"id":9630572},{"atb":[[1.24,52.02]],"id":8509691},{"atl":[[1.3,52]],"id":8509691}],"con":true,"img":false}]}
{"op":"mcm","clk":"1362366274","pt":1588444788171,"mc":[{"id":"1.170370564","rc":[{"atl":[[1.32,11.51]],"id":8509691}],"con":true,"img":false}]}
{"op":"mcm","clk":"1362366277","pt":1588444788375,"mc":[{"id":"1.170370564","rc":[{"atl":[[1.31,0]],"id":8509691}],"con":true,"img":false}]}
{"op":"mcm","clk":"1362366278","pt":1588444788479,"mc":[{"id":"1.170370564","rc":[{"atb":[[4.4,9.82]],"id":9630572}],"con":true,"img":false}]}
{"op":"mcm","clk":"1362366280","pt":1588444788578,"mc":[{"id":"1.170370564","rc":[{"atl":[[1.31,2.21]],"id":8509691}],"con":true,"img":false}]}
{"op":"mcm","clk":"1362366283","pt":1588444788679,"mc":[{"id":"1.170370564","rc":[{"atb":[[4.1,5.38]],"id":9630572}],"con":true,"img":false}]}
{"op":"mcm","clk":"1362366378","pt":1588444798887,"mc":[{"id":"1.170370564","rc":[{"atb":[[1.27,100]],"id":8509691}],"con":true,"img":false}]}
{"op":"mcm","clk":"1362366380","pt":1588444799083,"mc":[{"id":"1.170370564","rc":[{"trd":[[4.6,110.05]],"ltp":4.6,"tv":110.05,"id":9630572},{"atb":[[4.6,0]],"id":9630572},{"atl":[[4.6,0]],"id":9630572}],"con":true,"img":false}]}
{"op":"mcm","clk":"1362366382","pt":1588444799194,"mc":[{"id":"1.170370564","rc":[{"atb":[[4.3,8.05]],"id":9630572},{"atl":[[5,0]],"id":9630572},{"atb":[[1.24,50]],"id":8509691},{"atl":[[1.32,9.46],[1.31,0]],"id":8509691}],"con":true,"img":false}]}
{"op":"mcm","clk":"1362366384","pt":1588444799286,"mc":[{"id":"1.170370564","rc":[{"atb":[[4.2,2.02]],"id":9630572},{"atl":[[4.6,0]],"id":9630572}],"con":true,"img":false}]}
{"op":"mcm","clk":"1362366388","pt":1588444799490,"mc":[{"id":"1.170370564","rc":[{"atb":[[4.4,7.81]],"id":9630572},{"atl":[[1.3,50]],"id":8509691}],"con":true,"img":false}]}
{"op":"mcm","clk":"1362366390","pt":1588444799594,"mc":[{"id":"1.170370564","rc":[{"atb":[[4.3,10.05]],"id":9630572},{"atl":[[5,2]],"id":9630572},{"atb":[[1.24,52.02]],"id":8509691},{"atl":[[1.32,11.46],[1.31,2]],"id":8509691}],"con":true,"img":false}]}
{"op":"mcm","clk":"1362366397","pt":1588444800306,"mc":[{"id":"1.170370564","rc":[{"atb":[[4.2,10.33]],"id":9630572}],"con":true,"img":false}]}
{"op":"mcm","clk":"1362366399","pt":1588444800408,"mc":[{"id":"1.170370564","rc":[{"atb":[[4.3,2],[4.4,0]],"id":9630572}],"con":true,"img":false}]}
{"op":"mcm","clk":"1362366402","pt":1588444800510,"mc":[{"id":"1.170370564","rc":[{"atl":[[1.32,1.99]],"id":8509691}],"con":true,"img":false}]}
{"op":"mcm","clk":"1362366404","pt":1588444800815,"mc":[{"id":"1.170370564","rc":[{"atb":[[4.1,2.33]],"id":9630572}],"con":true,"img":false}]}
{"op":"mcm","clk":"1362366416","pt":1588444801685,"mc":[{"id":"1.170370564","rc":[{"atb":[[1.27,108]],"id":8509691}],"con":true,"img":false}]}
{"op":"mcm","clk":"1362366510","pt":1588444811801,"mc":[{"id":"1.170370564","rc":[{"atb":[[4.1,0]],"id":9630572}],"con":true,"img":false}]}
{"op":"mcm","clk":"1362366516","pt":1588444812108,"mc":[{"id":"1.170370564","rc":[{"atb":[[4.2,8.31]],"id":9630572},{"atl":[[5,0]],"id":9630572},{"atb":[[1.24,50]],"id":8509691},{"atl":[[1.32,0]],"id":8509691}],"con":true,"img":false}]}
{"op":"mcm","clk":"1362366517","pt":1588444812209,"mc":[{"id":"1.170370566","rc":[{"atl":[[1.46,2.62]],"id":8509691}],"con":true,"img":false}]}
{"op":"mcm","clk":"1362366519","pt":1588444812311,"mc":[{"id":"1.170370564","rc":[{"atb":[[4.2,10.33]],"id":9630572},{"atl":[[5,2]],"id":9630572},{"atb":[[1.24,52.02]],"id":8509691},{"atl":[[1.32,2.11]],"id":8509691}],"con":true,"img":false}]}
{"op":"mcm","clk":"1362366531","pt":1588444813735,"mc":[{"id":"1.170370564","rc":[{"atb":[[4.1,2.33]],"id":9630572}],"con":true,"img":false}]}
{"op":"mcm","clk":"1362366548","pt":1588444815724,"mc":[{"id":"1.170370564","rc":[{"atl":[[4.7,0]],"id":9630572}],"con":true,"img":false}]}
{"op":"mcm","clk":"1362366550","pt":1588444815928,"mc":[{"id":"1.170370564","rc":[{"atl":[[5.1,2.05]],"id":9630572}],"con":true,"img":false}]}
{"op":"mcm","clk":"1362366551","pt":1588444816030,"mc":[{"id":"1.170370564","rc":[{"atl":[[4.9,492.02]],"id":9630572}],"con":true,"img":false}]}
{"op":"mcm","clk":"1362366582","pt":1588444819240,"mc":[{"id":"1.170370564","rc":[{"trd":[[1.27,3068.42]],"ltp":1.27,"tv":3068.42,"id":8509691},{"atb":[[1.27,103]],"id":8509691}],"con":true,"img":false}]}
{"op":"mcm","clk":"1362366584","pt":1588444819545,"mc":[{"id":"1.170370564","rc":[{"atb":[[4.2,8.31]],"id":9630572},{"atb":[[1.24,50]],"id":8509691},{"atl":[[1.32,0]],"id":8509691}],"con":true,"img":false}]}
{"op":"mcm","clk":"1362366585","pt":1588444819700,"mc":[{"id":"1.170370564","rc":[{"atb":[[4.2,10.33]],"id":9630572},{"atb":[[1.24,52.02]],"id":8509691},{"atl":[[1.32,2.02]],"id":8509691}],"con":true,"img":false}]}
{"op":"mcm","clk":"1362366598","pt":1588444821127,"mc":[{"id":"1.170370567","rc":[{"atl":[[1.45,0]],"id":8509691}],"con":true,"img":false}]}
{"op":"mcm","clk":"1362366605","pt":1588444822147,"mc":[{"id":"1.170370566","rc":[{"atl":[[1.46,0]],"id":8509691}],"con":true,"img":false}]}
{"op":"mcm","clk":"1362366696","pt":1588444833030,"mc":[{"id":"1.170370564","rc":[{"atb":[[4.5,4.62]],"id":9630572}],"con":true,"img":false}]}
{"op":"mcm","clk":"1362366700","pt":1588444833323,"mc":[{"id":"1.170370564","rc":[{"atb":[[4.2,8.31]],"id":9630572},{"atl":[[5.1,0]],"id":9630572},{"atb":[[1.24,50]],"id":8509691},{"atl":[[1.32,0]],"id":8509691}],"con":true,"img":false}]}
{"op":"mcm","clk":"1362366701","pt":1588444833529,"mc":[{"id":"1.170370564","rc":[{"atb":[[4.2,10.33]],"id":9630572},{"atl":[[5.1,2.05]],"id":9630572},{"atb":[[1.24,52.02]],"id":8509691},{"atl":[[1.32,2.05]],"id":8509691}],"con":true,"img":false}]}
{"op":"mcm","clk":"1362367005","pt":1588444872490,"mc":[{"id":"1.170370564","rc":[{"trd":[[4.4,181.59],[4.5,519.58]],"ltp":4.4,"tv":701.17,"id":9630572},{"atb":[[4.5,0]],"id":9630572},{"atl":[[4.4,105.23]],"id":9630572},{"trd":[[1.29,21574.61]],"ltp":1.29,"tv":21574.61,"id":8509691},{"atl":[[1.29,0]],"id":8509691}],"con":true,"img":false}]}
{"op":"mcm","clk":"1362367007","pt":1588444872643,"mc":[{"id":"1.170370564","rc":[{"atb":[[4,20.6],[4.1,4.37]],"id":9630572},{"atl":[[4.6,2.01],[4.7,2.01]],"id":9630572},{"atb":[[1.26,102.21],[1.27,105.05]],"id":8509691},{"atl":[[1.33,8.41]],"id":8509691}],"con":true,"img":false}]}
{"op":"mcm","clk":"1362367009","pt":1588444872849,"mc":[{"id":"1.170370564","rc":[{"atb":[[4.3,0],[4.2,8.31]],"id":9630572},{"atl":[[5.1,0]],"id":9630572},{"atb":[[1.24,50]],"id":8509691},{"atl":[[1.31,0]],"id":8509691}],"con":true,"img":false}]}
{"op":"mcm","clk":"1362367012","pt":1588444873152,"mc":[{"id":"1.170370564","rc":[{"atl":[[5,0]],"id":9630572},{"atb":[[1.25,651.1]],"id":8509691}],"con":true,"img":false}]}
{"op":"mcm","clk":"1362367013","pt":1588444873255,"mc":[{"id":"1.170370564","rc":[{"atb":[[4.1,12.95]],"id":9630572},{"atb":[[1.24,138.65]],"id":8509691}],"con":true,"img":false}]}
{"op":"mcm","clk":"1362367014","pt":1588444873358,"mc":[{"id":"1.170370564","rc":[{"atb":[[4.2,0]],"id":9630572}],"con":true,"img":false}]}
{"op":"mcm","clk":"1362367083","pt":1588444882182,"mc":[{"id":"1.170370564","rc":[{"atl":[[1.3,0]],"id":8509691}],"con":true,"img":false}]}
{"op":"mcm","clk":"1362367085","pt":1588444882384,"mc":[{"id":"1.170370564","rc":[{"atl":[[1.34,2.02],[1.35,2.02]],"id":8509691}],"con":true,"img":false}]}
{"op":"mcm","clk":"1362367086","pt":1588444882486,"mc":[{"id":"1.170370564","rc":[{"atb":[[4,18.58]],"id":9630572},{"atl":[[4.7,0]],"id":9630572},{"atb":[[1.26,100]],"id":8509691},{"atl":[[1.32,0],[1.33,6.39]],"id":8509691}],"con":true,"img":false}]}
{"op":"mcm","clk":"1362367088","pt":1588444882690,"mc":[{"id":"1.170370564","rc":[{"atb":[[3.95,2.09],[3.9,2.06]],"id":9630572}],"con":true,"img":false}]}
{"op":"mcm","clk":"1362367089","pt":1588444882793,"mc":[{"id":"1.170370564","rc":[{"atb":[[4.1,10.91]],"id":9630572}],"con":true,"img":false}]}
{"op":"mcm","clk":"1362367091","pt":1588444882997,"mc":[{"id":"1.170370564","rc":[{"atl":[[4.7,2.05]],"id":9630572},{"atb":[[1.26,102.05]],"id":8509691},{"atl":[[1.36,2.07],[1.34,0]],"id":8509691}],"con":true,"img":false}]}
{"op":"mcm","clk":"1362367094","pt":1588444883253,"mc":[{"id":"1.170370564","rc":[{"atb":[[3.9,11.22]],"id":9630572}],"con":true,"img":false}]}
{"op":"mcm","clk":"1362367097","pt":1588444883457,"mc":[{"id":"1.170370564","rc":[{"atb":[[4.1,2.33]],"id":9630572},{"atb":[[1.2,278.8]],"id":8509691}],"con":true,"img":false}]}
{"op":"mcm","clk":"1362367102","pt":1588444884272,"mc":[{"id":"1.170370564","rc":[{"atb":[[1.26,190.7]],"id":8509691}],"con":true,"img":false}]}
{"op":"mcm","clk":"1362367165","pt":1588444892699,"mc":[{"id":"1.170370564","rc":[{"atl":[[1.32,5]],"id":8509691}],"con":true,"img":false}]}
{"op":"mcm","clk":"1362367168","pt":1588444892903,"mc":[{"id":"1.170370564","rc":[{"atl":[[1.34,2]],"id":8509691}],"con":true,"img":false}]}
{"op":"mcm","clk":"1362367170","pt":1588444893005,"mc":[{"id":"1.170370564","rc":[{"atb":[[3.9,9.16]],"id":9630572},{"atl":[[4.7,0]],"id":9630572},{"atb":[[1.26,188.65]],"id":8509691},{"atl":[[1.36,0]],"id":8509691}],"con":true,"img":false}]}
{"op":"mcm","clk":"1362367172","pt":1588444893209,"mc":[{"id":"1.170370564","rc":[{"atb":[[3.9,11.22]],"id":9630572},{"atl":[[4.7,2.05]],"id":9630572},{"atb":[[1.26,190.86]],"id":8509691}],"con":true,"img":false}]}
{"op":"mcm","clk":"1362367173","pt":1588444893313,"mc":[{"id":"1.170370564","rc":[{"atl":[[1.35,0]],"id":8509691}],"con":true,"img":false}]}
{"op":"mcm","clk":"1362367179","pt":1588444893469,"mc":[{"id":"1.170370564","rc":[{"atl":[[1.35,2.02]],"id":8509691}],"con":true,"img":false}]}
{"op":"mcm","clk":"1362367237","pt":1588444900100,"mc":[{"id":"1.170370564","rc":[{"atl":[[1.31,13.12]],"id":8509691}],"con":true,"img":false}]}
{"op":"mcm","clk":"1362367240","pt":1588444900293,"mc":[{"id":"1.170370564","rc":[{"atl":[[1.33,8.53]],"id":8509691}],"con":true,"img":false}]}
{"op":"mcm","clk":"1362367241","pt":1588444900395,"mc":[{"id":"1.170370564","rc":[{"atb":[[3.9,9.16]],"id":9630572},{"atl":[[4.7,0]],"id":9630572},{"atb":[[1.26,188.65]],"id":8509691},{"atl":[[1.35,0]],"id":8509691}],"con":true,"img":false}]}
{"op":"mcm","clk":"1362367242","pt":1588444900598,"mc":[{"id":"1.170370564","rc":[{"atb":[[4,20.6]],"id":9630572}],"con":true,"img":false}]}
{"op":"mcm","clk":"1362367243","pt":1588444900703,"mc":[{"id":"1.170370564","rc":[{"atl":[[1.34,0]],"id":8509691}],"con":true,"img":false}]}
{"op":"mcm","clk":"1362367246","pt":1588444900907,"mc":[{"id":"1.170370564","rc":[{"atl":[[4.7,2.05]],"id":9630572},{"atb":[[1.26,190.86]],"id":8509691},{"atl":[[1.34,2.25]],"id":8509691}],"con":true,"img":false}]}
{"op":"mcm","clk":"1362367247","pt":1588444901009,"mc":[{"id":"1.170370564","rc":[{"atb":[[3.95,0.09]],"id":9630572}],"con":true,"img":false}]}
{"op":"mcm","clk":"1362367251","pt":1588444901213,"mc":[{"id":"1.170370564","rc":[{"atb":[[3.95,2.2]],"id":9630572}],"con":true,"img":false}]}
{"op":"mcm","clk":"1362367252","pt":1588444901311,"mc":[{"id":"1.170370564","rc":[{"atb":[[3.95,11.21]],"id":9630572},{"atb":[[1.26,102.21]],"id":8509691}],"con":true,"img":false}]}
{"op":"mcm","clk":"1362367266","pt":1588444902997,"mc":[{"id":"1.170370564","rc":[{"atb":[[4.2,2.62]],"id":9630572}],"con":true,"img":false}]}
{"op":"mcm","clk":"1362367268","pt":1588444903300,"mc":[{"id":"1.170370564","rc":[{"atb":[[4,29.46]],"id":9630572},{"atb":[[1.26,190.86]],"id":8509691}],"con":true,"img":false}]}
{"op":"mcm","clk":"1362367400","pt":1588444917370,"mc":[{"id":"1.170370564","rc":[{"atl":[[1.32,0]],"id":8509691}],"con":true,"img":false}]}
{"op":"mcm","clk":"1362367402","pt":1588444917471,"mc":[{"id":"1.170370564","rc":[{"atl":[[1.31,18.12]],"id":8509691}],"con":true,"img":false}]}
{"op":"mcm","clk":"1362367404","pt":1588444917676,"mc":[{"id":"1.170370564","rc":[{"atb":[[3.95,9.1]],"id":9630572},{"atl":[[4.7,0]],"id":9630572},{"atb":[[1.26,188.65]],"id":8509691},{"atl":[[1.34,0]],"id":8509691}],"con":true,"img":false}]}
{"op":"mcm","clk":"1362367406","pt":1588444917880,"mc":[{"id":"1.170370564","rc":[{"atb":[[3.95,11.21]],"id":9630572},{"atl":[[4.7,2.05]],"id":9630572},{"atb":[[1.26,190.7]],"id":8509691},{"atl":[[1.34,2.25]],"id":8509691}],"con":true,"img":false}]}
{"op":"mcm","clk":"1362367408","pt":1588444918084,"mc":[{"id":"1.170370564","rc":[{"atb":[[1.3,1969.85]],"id":8509691}],"con":true,"img":false}]}
{"op":"mcm","clk":"1362367412","pt":1588444918287,"mc":[{"id":"1.170370564","rc":[{"atb":[[1.28,2.16]],"id":8509691}],"con":true,"img":false}]}
{"op":"mcm","clk":"1362367414","pt":1588444918594,"mc":[{"id":"1.170370564","rc":[{"atb":[[1.27,103]],"id":8509691}],"con":true,"img":false}]}
{"op":"mcm","clk":"1362367417","pt":1588444918798,"mc":[{"id":"1.170370564","rc":[{"atb":[[1.27,105.24]],"id":8509691}],"con":true,"img":false}]}
{"op":"mcm","clk":"1362367429","pt":1588444919972,"mc":[{"id":"1.170370564","rc":[{"atb":[[1.27,97.24]],"id":8509691}],"con":true,"img":false}]}
{"op":"mcm","clk":"1362367478","pt":1588444922994,"mc":[{"id":"1.170370565","rc":[{"trd":[[1.73,17.49]],"ltp":1.73,"tv":17.49,"id":11269555},{"atb":[[1.73,62.89]],"id":11269555}],"con":true,"img":false}]}
{"op":"mcm","clk":"1362367527","pt":1588444926275,"mc":[{"id":"1.170370565","rc":[{"atb":[[1.73,134.53]],"id":11269555}],"con":true,"img":false}]}
{"op":"mcm","clk":"1362367528","pt":1588444926377,"mc":[{"id":"1.170370565","rc":[{"atb":[[1.73,71.64]],"id":11269555}],"con":true,"img":false}]}
{"op":"mcm","clk":"1362367555","pt":1588444929180,"mc":[{"id":"1.170370564","rc":[{"trd":[[1.3,763.73]],"ltp":1.3,"tv":763.73,"id":8509691},{"atb":[[1.3,1967.85]],"id":8509691}],"con":true,"img":false}]}
{"op":"mcm","clk":"1362367559","pt":1588444929487,"mc":[{"id":"1.170370564","rc":[{"atb":[[3.95,9.1]],"id":9630572},{"atl":[[4.7,0]],"id":9630572},{"atb":[[1.26,188.65],[1.27,95]],"id":8509691},{"atl":[[1.34,0]],"id":8509691}],"con":true,"img":false}]}
{"op":"mcm","clk":"1362367562","pt":1588444929588,"mc":[{"id":"1.170370564","rc":[{"atb":[[3.95,11.21]],"id":9630572},{"atl":[[4.7,2.05]],"id":9630572},{"atb":[[1.27,97.24]],"id":8509691},{"atl":[[1.34,2]],"id":8509691}],"con":true,"img":false}]}
{"op":"mcm","clk":"1362367585","pt":1588444932400,"mc":[{"id":"1.170370564","rc":[{"atb":[[4.1,0]],"id":9630572}],"con":true,"img":false}]}
{"op":"mcm","clk":"1362367590","pt":1588444933113,"mc":[{"id":"1.170370565","rc":[{"atb":[[8.2,0]],"id":11340557}],"con":true,"img":false}]}
{"op":"mcm","clk":"1362367599","pt":1588444934184,"mc":[{"id":"1.170370564","rc":[{"atb":[[4.1,2.33]],"id":9630572}],"con":true,"img":false}]}
{"op":"mcm","clk":"1362367806","pt":1588444956620,"mc":[{"id":"1.170370564","rc":[{"atl":[[1.32,2078.01]],"id":8509691}],"con":true,"img":false}]}
{"op":"mcm","clk":"1362367813","pt":1588444956926,"mc":[{"id":"1.170370564","rc":[{"atb":[[3.95,9.1]],"id":9630572},{"atl":[[4.7,0]],"id":9630572},{"atb":[[1.27,95]],"id":8509691},{"atl":[[1.34,0]],"id":8509691}],"con":true,"img":false}]}
{"op":"mcm","clk":"1362367817","pt":1588444957130,"mc":[{"id":"1.170370564","rc":[{"atb":[[3.95,11.21]],"id":9630572},{"atl":[[4.7,2.05]],"id":9630572},{"atb":[[1.27,97.24]],"id":8509691},{"atl":[[1.34,2.02]],"id":8509691}],"con":true,"img":false}]}
{"op":"mcm","clk":"1362367840","pt":1588444959526,"mc":[{"id":"1.170370564","rc":[{"atb":[[4.2,8.22]],"id":9630572}],"con":true,"img":false}]}
{"op":"mcm","clk":"1362367856","pt":1588444960804,"mc":[{"id":"1.170370564","rc":[{"atl":[[4.4,0]],"id":9630572}],"con":true,"img":false}]}
{"op":"mcm","clk":"1362367858","pt":1588444960903,"mc":[{"id":"1.170370564","rc":[{"trd":[[1.3,894.94]],"ltp":1.3,"tv":894.94,"id":8509691},{"atb":[[1.3,1902.25]],"id":8509691}],"con":true,"img":false}]}
{"op":"mcm","clk":"1362367859","pt":1588444961005,"mc":[{"id":"1.170370564","rc":[{"atl":[[4.8,50.77],[4.9,494.07]],"id":9630572}],"con":true,"img":false}]}
{"op":"mcm","clk":"1362367861","pt":1588444961107,"mc":[{"id":"1.170370564","rc":[{"atl":[[4.6,0],[4.7,0]],"id":9630572}],"con":true,"img":false}]}
{"op":"mcm","clk":"1362367864","pt":1588444961311,"mc":[{"id":"1.170370564","rc":[{"atl":[[4.6,2.01],[4.7,2.05]],"id":9630572}],"con":true,"img":false}]}
{"op":"mcm","clk":"1362367905","pt":1588444965546,"mc":[{"id":"1.170370564","rc":[{"trd":[[4.4,192.59]],"ltp":4.4,"tv":192.59,"id":9630572},{"trd":[[1.3,932.17]],"ltp":1.3,"tv":932.17,"id":8509691},{"atb":[[1.3,1865.01]],"id":8509691}],"con":true,"img":false}]}
{"op":"mcm","clk":"1362367907","pt":1588444965852,"mc":[{"id":"1.170370564","rc":[{"atb":[[3.95,9.1]],"id":9630572},{"atb":[[1.27,95]],"id":8509691},{"atl":[[1.34,0]],"id":8509691}],"con":true,"img":false}]}
{"op":"mcm","clk":"1362367910","pt":1588444966005,"mc":[{"id":"1.170370564","rc":[{"atb":[[3.95,11.21]],"id":9630572},{"atb":[[1.27,97.24]],"id":8509691},{"atl":[[1.34,2.02]],"id":8509691}],"con":true,"img":false}]}
{"op":"mcm","clk":"1362367935","pt":1588444969419,"mc":[{"id":"1.170370564","rc":[{"trd":[[1.3,948.16]],"ltp":1.3,"tv":948.16,"id":8509691},{"atb":[[1.3,1857.02]],"id":8509691}],"con":true,"img":false}]}
{"op":"mcm","clk":"1362367938","pt":1588444969725,"mc":[{"id":"1.170370564","rc":[{"atl":[[4.8,48.75],[4.9,492.02],[4.7,0]],"id":9630572}],"con":true,"img":false}]}
{"op":"mcm","clk":"1362367942","pt":1588444969931,"mc":[{"id":"1.170370564","rc":[{"atl":[[4.7,2.05]],"id":9630572}],"con":true,"img":false}]}
{"op":"mcm","clk":"1362367944","pt":1588444970132,"mc":[{"id":"1.170370564","rc":[{"atl":[[4.7,4.1]],"id":9630572}],"con":true,"img":false}]}
{"op":"mcm","clk":"1362367966","pt":1588444972632,"mc":[{"id":"1.170370564","rc":[{"atb":[[4.2,2.62]],"id":9630572}],"con":true,"img":false}]}
{"op":"mcm","clk":"1362367973","pt":1588444972939,"mc":[{"id":"1.170370564","rc":[{"atb":[[3.95,9.1]],"id":9630572},{"atb":[[1.27,95]],"id":8509691},{"atl":[[1.34,0]],"id":8509691}],"con":true,"img":false}]}
{"op":"mcm","clk":"1362367976","pt":1588444973143,"mc":[{"id":"1.170370564","rc":[{"atb":[[3.95,11.21]],"id":9630572},{"atb":[[1.27,97.01]],"id":8509691},{"atl":[[1.34,2.02]],"id":8509691}],"con":true,"img":false}]}
{"op":"mcm","clk":"1362368004","pt":1588444975948,"mc":[{"id":"1.170370564","rc":[{"atl":[[1.31,44.36]],"id":8509691}],"con":true,"img":false}]}
{"op":"mcm","clk":"1362368008","pt":1588444976255,"mc":[{"id":"1.170370564","rc":[{"atl":[[4.7,2.05]],"id":9630572}],"con":true,"img":false}]}
{"op":"mcm","clk":"1362368011","pt":1588444976510,"mc":[{"id":"1.170370564","rc":[{"atl":[[4.7,0]],"id":9630572}],"con":true,"img":false}]}
{"op":"mcm","clk":"1362368013","pt":1588444976715,"mc":[{"id":"1.170370564","rc":[{"atl":[[4.7,2.05]],"id":9630572}],"con":true,"img":false}]}
{"op":"mcm","clk":"1362368014","pt":1588444976816,"mc":[{"id":"1.170370564","rc":[{"atl":[[4.7,4.1]],"id":9630572}],"con":true,"img":false}]}
{"op":"mcm","clk":"1362368101","pt":1588444985769,"mc":[{"id":"1.170370564","rc":[{"trd":[[4.1,110.38],[4.2,19.08]],"ltp":4.1,"tv":129.45,"id":9630572},{"atb":[[4.1,0],[4.2,0]],"id":9630572},{"trd":[[1.32,328.36],[1.31,44.36]],"ltp":1.32,"tv":372.72,"id":8509691},{"atl":[[1.32,1749.64],[1.31,0]],"id":8509691}],"con":true,"img":false}]}
{"op":"mcm","clk":"1362368104","pt":1588444985922,"mc":[{"id":"1.170370564","rc":[{"atb":[[3.85,2.17],[3.9,11.22]],"id":9630572},{"atl":[[1.35,2.1]],"id":8509691}],"con":true,"img":false}]}
{"op":"mcm","clk":"1362368106","pt":1588444986024,"mc":[{"id":"1.170370564","rc":[{"atb":[[1.31,0.34]],"id":8509691},{"atl":[[1.33,6.39]],"id":8509691}],"con":true,"img":false}]}
{"op":"mcm","clk":"1362368108","pt":1588444986126,"mc":[{"id":"1.170370564","rc":[{"atb":[[3.95,9.1]],"id":9630572},{"atl":[[4.7,2.05]],"id":9630572},{"atb":[[1.27,95]],"id":8509691}],"con":true,"img":false}]}
{"op":"mcm","clk":"1362368110","pt":1588444986228,"mc":[{"id":"1.170370564","rc":[{"atb":[[4,27.44]],"id":9630572},{"atl":[[4.7,0]],"id":9630572}],"con":true,"img":false}]}
{"op":"mcm","clk":"1362368112","pt":1588444986331,"mc":[{"id":"1.170370564","rc":[{"atb":[[4,18.58],[3.95,11.21]],"id":9630572},{"atb":[[1.27,97.24]],"id":8509691}],"con":true,"img":false}]}
{"op":"mcm","clk":"1362368114","pt":1588444986433,"mc":[{"id":"1.170370564","rc":[{"atl":[[4.7,2.05]],"id":9630572}],"con":true,"img":false}]}
{"op":"mcm","clk":"1362368184","pt":1588444995250,"mc":[{"id":"1.170370564","rc":[{"atb":[[4.2,7.59]],"id":9630572}],"con":true,"img":false}]}
{"op":"mcm","clk":"1362368185","pt":1588444995453,"mc":[{"id":"1.170370564","rc":[{"atb":[[4,20.6]],"id":9630572}],"con":true,"img":false}]}
{"op":"mcm","clk":"1362368187","pt":1588444995555,"mc":[{"id":"1.170370564","rc":[{"atb":[[1.27,95]],"id":8509691},{"atl":[[1.35,0]],"id":8509691}],"con":true,"img":false}]}
{"op":"mcm","clk":"1362368188","pt":1588444995657,"mc":[{"id":"1.170370564","rc":[{"atb":[[3.85,0],[3.9,9.16]],"id":9630572},{"atl":[[4.7,0]],"id":9630572}],"con":true,"img":false}]}
