{"op":"mcm","clk":"1362368190","pt":1588444995861,"mc":[{"id":"1.170370564","rc":[{"atl":[[4.7,2.05]],"id":9630572},{"atb":[[1.27,97.01]],"id":8509691},{"atl":[[1.35,2.1]],"id":8509691}],"con":true,"img":false}]}
{"op":"mcm","clk":"1362368191","pt":1588444995963,"mc":[{"id":"1.170370564","rc":[{"atb":[[3.95,9.1]],"id":9630572}],"con":true,"img":false}]}
{"op":"mcm","clk":"1362368192","pt":1588444996065,"mc":[{"id":"1.170370564","rc":[{"atb":[[3.95,11.21]],"id":9630572}],"con":true,"img":false}]}
{"op":"mcm","clk":"1362368195","pt":1588444996269,"mc":[{"id":"1.170370564","rc":[{"atb":[[4,29.46]],"id":9630572}],"con":true,"img":false}]}
{"op":"mcm","clk":"1362368312","pt":1588445012478,"mc":[{"id":"1.170370564","rc":[{"atb":[[1.31,0]],"id":8509691}],"con":true,"img":false}]}
{"op":"mcm","clk":"1362368314","pt":1588445012784,"mc":[{"id":"1.170370564","rc":[{"atb":[[3.95,9.1]],"id":9630572},{"atl":[[4.7,0]],"id":9630572},{"atb":[[1.27,95]],"id":8509691},{"atl":[[1.35,0]],"id":8509691}],"con":true,"img":false}]}
{"op":"mcm","clk":"1362368315","pt":1588445012988,"mc":[{"id":"1.170370564","rc":[{"atb":[[3.95,11.1]],"id":9630572},{"atl":[[4.7,2.05]],"id":9630572},{"atb":[[1.27,97.24]],"id":8509691},{"atl":[[1.35,2.02]],"id":8509691}],"con":true,"img":false}]}
{"op":"mcm","clk":"1362368331","pt":1588445014977,"mc":[{"id":"1.170370564","rc":[{"atl":[[1.31,6]],"id":8509691}],"con":true,"img":false}]}
{"op":"mcm","clk":"1362368332","pt":1588445015180,"mc":[{"id":"1.170370564","rc":[{"atl":[[1.33,8.47]],"id":8509691}],"con":true,"img":false}]}
{"op":"mcm","clk":"1362368336","pt":1588445015486,"mc":[{"id":"1.170370564","rc":[{"atl":[[1.34,0]],"id":8509691}],"con":true,"img":false}]}
{"op":"mcm","clk":"1362368339","pt":1588445015690,"mc":[{"id":"1.170370564","rc":[{"atl":[[1.34,2.25]],"id":8509691}],"con":true,"img":false}]}
{"op":"mcm","clk":"1362368368","pt":1588445020376,"mc":[{"id":"1.170370564","rc":[{"atb":[[1.08,1012.61]],"id":8509691}],"con":true,"img":false}]}
{"op":"mcm","clk":"1362368371","pt":1588445020682,"mc":[{"id":"1.170370564","rc":[{"atb":[[3.95,9.1]],"id":9630572},{"atl":[[4.7,0]],"id":9630572},{"atb":[[1.27,95]],"id":8509691},{"atl":[[1.35,0]],"id":8509691}],"con":true,"img":false}]}
{"op":"mcm","clk":"1362368372","pt":1588445020886,"mc":[{"id":"1.170370564","rc":[{"atb":[[3.95,11.21]],"id":9630572},{"atl":[[4.7,2.05]],"id":9630572},{"atb":[[1.27,97.24]],"id":8509691}],"con":true,"img":false}]}
{"op":"mcm","clk":"1362368429","pt":1588445027871,"mc":[{"id":"1.170370564","rc":[{"atb":[[1.28,6.71]],"id":8509691}],"con":true,"img":false}]}
{"op":"mcm","clk":"1362368430","pt":1588445028177,"mc":[{"id":"1.170370564","rc":[{"atb":[[3.95,9.1]],"id":9630572},{"atl":[[4.7,0]],"id":9630572},{"atb":[[1.27,95]],"id":8509691},{"atl":[[1.34,0]],"id":8509691}],"con":true,"img":false}]}
{"op":"mcm","clk":"1362368432","pt":1588445028381,"mc":[{"id":"1.170370564","rc":[{"atb":[[3.95,11.21]],"id":9630572},{"atl":[[4.7,2.01]],"id":9630572},{"atb":[[1.27,97.24]],"id":8509691},{"atl":[[1.34,2.02]],"id":8509691}],"con":true,"img":false}]}
{"op":"mcm","clk":"1362368463","pt":1588445032815,"mc":[{"id":"1.170370564","rc":[{"atl":[[1.31,0]],"id":8509691}],"con":true,"img":false}]}
{"op":"mcm","clk":"1362368465","pt":1588445032968,"mc":[{"id":"1.170370564","rc":[{"atl":[[1.35,2.1]],"id":8509691}],"con":true,"img":false}]}
{"op":"mcm","clk":"1362368467","pt":1588445033070,"mc":[{"id":"1.170370564","rc":[{"atl":[[1.33,6.39]],"id":8509691}],"con":true,"img":false}]}
{"op":"mcm","clk":"1362368603","pt":1588445051837,"mc":[{"id":"1.170370564","rc":[{"trd":[[4.4,201.59]],"ltp":4.4,"tv":201.59,"id":9630572},{"trd":[[1.3,978.63]],"ltp":1.3,"tv":978.63,"id":8509691},{"atb":[[1.3,1826.56]],"id":8509691}],"con":true,"img":false}]}
{"op":"mcm","clk":"1362368607","pt":1588445052143,"mc":[{"id":"1.170370564","rc":[{"atl":[[4.7,0]],"id":9630572},{"atb":[[1.27,95]],"id":8509691}],"con":true,"img":false}]}
{"op":"mcm","clk":"1362368610","pt":1588445052194,"mc":[{"id":"1.170370564","rc":[{"atb":[[3.95,9.1]],"id":9630572},{"atl":[[1.35,0]],"id":8509691}],"con":true,"img":false}]}
{"op":"mcm","clk":"1362368612","pt":1588445052398,"mc":[{"id":"1.170370564","rc":[{"atb":[[3.95,11.21]],"id":9630572},{"atl":[[4.7,2.05]],"id":9630572},{"atb":[[1.27,97.09],[1.29,2.5]],"id":8509691},{"atl":[[1.35,2.1]],"id":8509691}],"con":true,"img":false}]}
{"op":"mcm","clk":"1362368618","pt":1588445052704,"mc":[{"id":"1.170370564","rc":[{"atl":[[4.4,2.12]],"id":9630572}],"con":true,"img":false}]}
{"op":"mcm","clk":"1362368629","pt":1588445054944,"mc":[{"id":"1.170370564","rc":[{"atl":[[4.3,4.54]],"id":9630572}],"con":true,"img":false}]}
{"op":"mcm","clk":"1362368631","pt":1588445055098,"mc":[{"id":"1.170370564","rc":[{"atl":[[4.5,2.01]],"id":9630572}],"con":true,"img":false}]}
{"op":"mcm","clk":"1362368634","pt":1588445055403,"mc":[{"id":"1.170370564","rc":[{"atl":[[4.6,0]],"id":9630572}],"con":true,"img":false}]}
{"op":"mcm","clk":"1362368636","pt":1588445055607,"mc":[{"id":"1.170370564","rc":[{"atl":[[4.6,2.01]],"id":9630572}],"con":true,"img":false}]}
{"op":"mcm","clk":"1362369402","pt":1588445062333,"mc":[{"id":"1.170370564","rc":[{"atb":[[1.01,464.79]],"id":9630572},{"atb":[[1.01,1843.34]],"id":8509691}],"con":true,"img":false}]}
{"op":"mcm","clk":"1362369405","pt":1588445062640,"mc":[{"id":"1.170370564","rc":[{"atb":[[3.95,9.1]],"id":9630572},{"atl":[[4.6,0],[4.7,0]],"id":9630572},{"atb":[[1.27,95]],"id":8509691},{"atl":[[1.35,0]],"id":8509691}],"con":true,"img":false}]}
{"op":"mcm","clk":"1362369407","pt":1588445062845,"mc":[{"id":"1.170370564","rc":[{"atb":[[3.95,11.1]],"id":9630572},{"atl":[[4.6,2.01]],"id":9630572},{"atb":[[1.27,97.05]],"id":8509691},{"atl":[[1.35,2.1]],"id":8509691}],"con":true,"img":false}]}
{"op":"mcm","clk":"1362369409","pt":1588445062947,"mc":[{"id":"1.170370564","rc":[{"atl":[[4.3,6.9]],"id":9630572}],"con":true,"img":false}]}
{"op":"mcm","clk":"1362369435","pt":1588445065954,"mc":[{"id":"1.170370564","rc":[{"atl":[[1.31,52.48]],"id":8509691}],"con":true,"img":false}]}
{"op":"mcm","clk":"1362369437","pt":1588445066056,"mc":[{"id":"1.170370564","rc":[{"trd":[[1.31,45.04]],"ltp":1.31,"tv":45.04,"id":8509691},{"atl":[[1.31,52.13]],"id":8509691}],"con":true,"img":false}]}
{"op":"mcm","clk":"1362369439","pt":1588445066159,"mc":[{"id":"1.170370564","rc":[{"atl":[[1.33,8.68]],"id":8509691}],"con":true,"img":false}]}
{"op":"mcm","clk":"1362369441","pt":1588445066413,"mc":[{"id":"1.170370564","rc":[{"atl":[[1.34,0]],"id":8509691}],"con":true,"img":false}]}
{"op":"mcm","clk":"1362369444","pt":1588445066617,"mc":[{"id":"1.170370564","rc":[{"atl":[[1.34,2.25]],"id":8509691}],"con":true,"img":false}]}
{"op":"mcm","clk":"1362369634","pt":1588445089389,"mc":[{"id":"1.170370565","rc":[{"atb":[[1.67,0]],"id":11269555}],"con":true,"img":false}]}
{"op":"mcm","clk":"1362369636","pt":1588445089593,"mc":[{"id":"1.170370565","rc":[{"atb":[[3.45,0]],"id":11269557}],"con":true,"img":false}]}
{"op":"mcm","clk":"1362369640","pt":1588445089848,"mc":[{"id":"1.170370565","rc":[{"atb":[[7.8,0]],"id":11340557}],"con":true,"img":false}]}
{"op":"mcm","clk":"1362369642","pt":1588445090153,"mc":[{"id":"1.170370564","rc":[{"trd":[[4.3,15.61]],"ltp":4.3,"tv":15.61,"id":9630572},{"atb":[[4.3,3.09]],"id":9630572},{"atl":[[4.3,0]],"id":9630572}],"con":true,"img":false},{"id":"1.170370565","rc":[{"atb":[[7.2,0]],"id":11340560}],"con":true,"img":false}]}
{"op":"mcm","clk":"1362369646","pt":1588445090358,"mc":[{"id":"1.170370564","rc":[{"trd":[[4.3,21.8]],"ltp":4.3,"tv":21.8,"id":9630572},{"atb":[[4.3,0],[4.1,2.04]],"id":9630572},{"atl":[[4.7,2.05]],"id":9630572}],"con":true,"img":false}]}
{"op":"mcm","clk":"1362369647","pt":1588445090459,"mc":[{"id":"1.170370564","rc":[{"atb":[[3.95,9.1]],"id":9630572},{"atl":[[4.5,0]],"id":9630572},{"atb":[[1.27,95]],"id":8509691},{"atl":[[1.34,0],[1.35,0]],"id":8509691}],"con":true,"img":false}]}
{"op":"mcm","clk":"1362369649","pt":1588445090561,"mc":[{"id":"1.170370565","rc":[{"atb":[[7,4]],"id":11340557},{"atb":[[7.2,6]],"id":11340560},{"atb":[[1.74,9]],"id":11269555},{"atb":[[3.45,5]],"id":11269557}],"con":true,"img":false}]}
{"op":"mcm","clk":"1362369650","pt":1588445090765,"mc":[{"id":"1.170370564","rc":[{"atb":[[4.1,0]],"id":9630572}],"con":true,"img":false}]}
{"op":"mcm","clk":"1362369652","pt":1588445090867,"mc":[{"id":"1.170370564","rc":[{"atb":[[3.95,11.21]],"id":9630572},{"atb":[[1.27,97.24]],"id":8509691},{"atl":[[1.34,2.02]],"id":8509691}],"con":true,"img":false}]}
{"op":"mcm","clk":"1362369701","pt":1588445095960,"mc":[{"id":"1.170370564","rc":[{"atl":[[4.3,17.49]],"id":9630572}],"con":true,"img":false}]}
{"op":"mcm","clk":"1362369702","pt":1588445096062,"mc":[{"id":"1.170370564","rc":[{"atl":[[4.5,2.01]],"id":9630572}],"con":true,"img":false}]}
{"op":"mcm","clk":"1362369704","pt":1588445096367,"mc":[{"id":"1.170370564","rc":[{"atl":[[4.6,0]],"id":9630572}],"con":true,"img":false}]}
{"op":"mcm","clk":"1362369708","pt":1588445096673,"mc":[{"id":"1.170370564","rc":[{"atb":[[3.95,9.1]],"id":9630572},{"atl":[[4.7,0]],"id":9630572},{"atb":[[1.27,95]],"id":8509691},{"atl":[[1.34,0]],"id":8509691}],"con":true,"img":false}]}
{"op":"mcm","clk":"1362369710","pt":1588445096876,"mc":[{"id":"1.170370564","rc":[{"atb":[[3.95,11.21]],"id":9630572},{"atl":[[4.6,2.01]],"id":9630572},{"atb":[[1.27,97.24]],"id":8509691},{"atl":[[1.34,2.25]],"id":8509691}],"con":true,"img":false}]}
{"op":"mcm","clk":"1362369786","pt":1588445106981,"mc":[{"id":"1.170370564","rc":[{"atb":[[4.2,10.22]],"id":9630572}],"con":true,"img":false}]}
{"op":"mcm","clk":"1362369788","pt":1588445107287,"mc":[{"id":"1.170370564","rc":[{"atb":[[3.95,9.1]],"id":9630572},{"atl":[[4.6,0]],"id":9630572},{"atb":[[1.27,95]],"id":8509691},{"atl":[[1.34,0]],"id":8509691}],"con":true,"img":false}]}
{"op":"mcm","clk":"1362369791","pt":1588445107490,"mc":[{"id":"1.170370564","rc":[{"atb":[[3.95,11.1]],"id":9630572},{"atl":[[4.6,2.01]],"id":9630572},{"atb":[[1.27,97.24]],"id":8509691},{"atl":[[1.34,2.02]],"id":8509691}],"con":true,"img":false}]}
{"op":"mcm","clk":"1362369823","pt":1588445111561,"mc":[{"id":"1.170370564","rc":[{"atb":[[4,10.88]],"id":9630572},{"atb":[[1.2,0]],"id":8509691}],"con":true,"img":false}]}
{"op":"mcm","clk":"1362370142","pt":1588445151245,"mc":[{"id":"1.170370565","rc":[{"atl":[[1.75,0]],"id":11269555}],"con":true,"img":false}]}
{"op":"mcm","clk":"1362370144","pt":1588445151449,"mc":[{"id":"1.170370565","rc":[{"atl":[[5.1,0]],"id":11269557}],"con":true,"img":false}]}
{"op":"mcm","clk":"1362370146","pt":1588445151605,"mc":[{"id":"1.170370565","rc":[{"atl":[[9.4,0]],"id":11340557}],"con":true,"img":false}]}
{"op":"mcm","clk":"1362370149","pt":1588445151810,"mc":[{"id":"1.170370565","rc":[{"atl":[[12.5,0]],"id":11340560}],"con":true,"img":false}]}
{"op":"mcm","clk":"1362370152","pt":1588445152316,"mc":[{"id":"1.170370565","rc":[{"atl":[[8.4,6]],"id":11340557},{"atl":[[11,6]],"id":11340560},{"atl":[[1.84,4]],"id":11269555},{"atl":[[5.1,4]],"id":11269557}],"con":true,"img":false}]}
{"op":"mcm","clk":"1362370505","pt":1588445198963,"mc":[{"id":"1.170370564","rc":[{"trd":[[4.3,56.78]],"ltp":4.3,"tv":56.78,"id":9630572},{"atb":[[4.3,3.51]],"id":9630572},{"atl":[[4.3,0]],"id":9630572}],"con":true,"img":false}]}
{"op":"mcm","clk":"1362370507","pt":1588445199166,"mc":[{"id":"1.170370564","rc":[{"trd":[[4.3,63.8]],"ltp":4.3,"tv":63.8,"id":9630572},{"atb":[[4.3,0],[4.1,2.04]],"id":9630572},{"atl":[[4.3,0],[4.7,2.01]],"id":9630572}],"con":true,"img":false}]}
{"op":"mcm","clk":"1362370510","pt":1588445199268,"mc":[{"id":"1.170370564","rc":[{"atl":[[4.5,0]],"id":9630572},{"atb":[[1.27,95]],"id":8509691},{"atl":[[1.34,0]],"id":8509691}],"con":true,"img":false}]}
{"op":"mcm","clk":"1362370513","pt":1588445199384,"mc":[{"id":"1.170370564","rc":[{"atb":[[3.95,9.1]],"id":9630572}],"con":true,"img":false}]}
{"op":"mcm","clk":"1362370514","pt":1588445199486,"mc":[{"id":"1.170370564","rc":[{"atl":[[4.3,0]],"id":9630572},{"atb":[[1.26,100],[1.25,739.75]],"id":8509691}],"con":true,"img":false}]}
{"op":"mcm","clk":"1362370516","pt":1588445199589,"mc":[{"id":"1.170370564","rc":[{"atb":[[1.27,97]],"id":8509691},{"atl":[[1.34,2.25]],"id":8509691}],"con":true,"img":false}]}
{"op":"mcm","clk":"1362370518","pt":1588445199691,"mc":[{"id":"1.170370564","rc":[{"atb":[[4.1,0]],"id":9630572}],"con":true,"img":false}]}
{"op":"mcm","clk":"1362370519","pt":1588445199792,"mc":[{"id":"1.170370564","rc":[{"atb":[[3.95,11.21]],"id":9630572}],"con":true,"img":false}]}
{"op":"mcm","clk":"1362370525","pt":1588445200457,"mc":[{"id":"1.170370564","rc":[{"atb":[[1.21,50]],"id":8509691}],"con":true,"img":false}]}
{"op":"mcm","clk":"1362370535","pt":1588445201475,"mc":[{"id":"1.170370564","rc":[{"atb":[[1.22,52]],"id":8509691}],"con":true,"img":false}]}
{"op":"mcm","clk":"1362370542","pt":1588445202397,"mc":[{"id":"1.170370564","rc":[{"atb":[[1.26,188.65]],"id":8509691}],"con":true,"img":false}]}
{"op":"mcm","clk":"1362371284","pt":1588445300310,"mc":[{"id":"1.170370564","rc":[{"atl":[[1.31,67.13]],"id":8509691}],"con":true,"img":false}]}
{"op":"mcm","clk":"1362371287","pt":1588445300615,"mc":[{"id":"1.170370564","rc":[{"atl":[[1.34,0]],"id":8509691}],"con":true,"img":false}]}
{"op":"mcm","clk":"1362371288","pt":1588445300717,"mc":[{"id":"1.170370564","rc":[{"atb":[[3.95,9.1]],"id":9630572},{"atl":[[4.7,0]],"id":9630572},{"atb":[[1.27,95]],"id":8509691}],"con":true,"img":false}]}
{"op":"mcm","clk":"1362371290","pt":1588445300921,"mc":[{"id":"1.170370564","rc":[{"atb":[[3.95,11.1]],"id":9630572},{"atl":[[4.7,2.05]],"id":9630572},{"atb":[[1.27,97.09]],"id":8509691},{"atl":[[1.34,2.02]],"id":8509691}],"con":true,"img":false}]}
{"op":"mcm","clk":"1362371295","pt":1588445301483,"mc":[{"id":"1.170370564","rc":[{"atb":[[1.26,100]],"id":8509691}],"con":true,"img":false}]}
{"op":"mcm","clk":"1362371436","pt":1588445322837,"mc":[{"id":"1.170370564","rc":[{"atb":[[4.2,21.22]],"id":9630572}],"con":true,"img":false}]}
{"op":"mcm","clk":"1362371437","pt":1588445323143,"mc":[{"id":"1.170370564","rc":[{"atb":[[3.95,9.1]],"id":9630572},{"atl":[[4.7,0]],"id":9630572},{"atb":[[1.27,95]],"id":8509691},{"atl":[[1.34,0]],"id":8509691}],"con":true,"img":false}]}
{"op":"mcm","clk":"1362371439","pt":1588445323346,"mc":[{"id":"1.170370564","rc":[{"atb":[[3.95,11.1]],"id":9630572},{"atl":[[4.7,2.05]],"id":9630572},{"atb":[[1.27,97.01]],"id":8509691},{"atl":[[1.34,2.02]],"id":8509691}],"con":true,"img":false}]}
{"op":"mcm","clk":"1362371771","pt":1588445367400,"mc":[{"id":"1.170370564","rc":[{"atb":[[4.2,13.62]],"id":9630572}],"con":true,"img":false}]}
{"op":"mcm","clk":"1362371774","pt":1588445367706,"mc":[{"id":"1.170370564","rc":[{"atb":[[3.95,9.1]],"id":9630572},{"atl":[[4.7,0]],"id":9630572},{"atb":[[1.27,95]],"id":8509691},{"atl":[[1.34,0]],"id":8509691}],"con":true,"img":false}]}
{"op":"mcm","clk":"1362371776","pt":1588445367910,"mc":[{"id":"1.170370564","rc":[{"atb":[[3.95,11.21]],"id":9630572},{"atl":[[4.7,2.05]],"id":9630572},{"atb":[[1.27,97.09]],"id":8509691},{"atl":[[1.34,2.25]],"id":8509691}],"con":true,"img":false}]}
{"op":"mcm","clk":"1362371921","pt":1588445389076,"mc":[{"id":"1.170370564","rc":[{"atb":[[1.25,712.56]],"id":8509691}],"con":true,"img":false}]}
{"op":"mcm","clk":"1362371922","pt":1588445389384,"mc":[{"id":"1.170370564","rc":[{"atb":[[3.95,9.1]],"id":9630572},{"atl":[[4.7,0]],"id":9630572},{"atb":[[1.27,95]],"id":8509691},{"atl":[[1.34,0]],"id":8509691}],"con":true,"img":false}]}
{"op":"mcm","clk":"1362371925","pt":1588445389584,"mc":[{"id":"1.170370564","rc":[{"atb":[[3.95,11.21]],"id":9630572},{"atl":[[4.7,2.05]],"id":9630572},{"atb":[[1.27,97.24]],"id":8509691},{"atl":[[1.34,2.25]],"id":8509691}],"con":true,"img":false}]}
{"op":"mcm","clk":"1362372332","pt":1588445461764,"mc":[{"id":"1.170370564","rc":[{"trd":[[1.3,979.99]],"ltp":1.3,"tv":979.99,"id":8509691},{"atb":[[1.3,1825.87]],"id":8509691}],"con":true,"img":false}]}
{"op":"mcm","clk":"1362372334","pt":1588445462070,"mc":[{"id":"1.170370564","rc":[{"atb":[[3.95,9.1]],"id":9630572},{"atl":[[4.7,0]],"id":9630572},{"atb":[[1.27,95]],"id":8509691},{"atl":[[1.34,0]],"id":8509691}],"con":true,"img":false}]}
{"op":"mcm","clk":"1362372336","pt":1588445462274,"mc":[{"id":"1.170370564","rc":[{"atb":[[3.95,11.21]],"id":9630572},{"atl":[[4.7,2.05]],"id":9630572},{"atb":[[1.27,97]],"id":8509691},{"atl":[[1.34,2.02]],"id":8509691}],"con":true,"img":false}]}
{"op":"mcm","clk":"1362372619","pt":1588445548985,"mc":[{"id":"1.170370564","rc":[{"atl":[[1.31,77.63]],"id":8509691}],"con":true,"img":false}]}
{"op":"mcm","clk":"1362372622","pt":1588445549239,"mc":[{"id":"1.170370564","rc":[{"atb":[[3.95,9.1]],"id":9630572},{"atl":[[4.7,0]],"id":9630572},{"atb":[[1.27,95]],"id":8509691},{"atl":[[1.34,0]],"id":8509691}],"con":true,"img":false}]}
{"op":"mcm","clk":"1362372624","pt":1588445549441,"mc":[{"id":"1.170370564","rc":[{"atb":[[3.95,11.21]],"id":9630572},{"atl":[[4.7,2.05]],"id":9630572},{"atb":[[1.27,97.01]],"id":8509691},{"atl":[[1.34,2.25]],"id":8509691}],"con":true,"img":false}]}
{"op":"mcm","clk":"1362372733","pt":1588445568982,"mc":[{"id":"1.170370564","rc":[{"atb":[[4.2,39.86]],"id":9630572}],"con":true,"img":false}]}
{"op":"mcm","clk":"1362372738","pt":1588445569287,"mc":[{"id":"1.170370564","rc":[{"atb":[[3.95,9.1]],"id":9630572},{"atl":[[4.7,0]],"id":9630572},{"atb":[[1.27,95]],"id":8509691},{"atl":[[1.34,0]],"id":8509691}],"con":true,"img":false}]}
{"op":"mcm","clk":"1362372739","pt":1588445569490,"mc":[{"id":"1.170370564","rc":[{"atb":[[3.95,11.21]],"id":9630572},{"atl":[[4.7,2.05]],"id":9630572},{"atb":[[1.27,97.09]],"id":8509691},{"atl":[[1.34,2.25]],"id":8509691}],"con":true,"img":false}]}
{"op":"mcm","clk":"1362372748","pt":1588445573098,"mc":[{"id":"1.170370566","rc":[{"atb":[[1.34,0]],"id":8509691}],"con":true,"img":false}]}
{"op":"mcm","clk":"1362372749","pt":1588445573200,"mc":[{"id":"1.170370566","rc":[{"atb":[[1.34,2.62]],"id":8509691}],"con":true,"img":false}]}
{"op":"mcm","clk":"1362372766","pt":1588445584085,"mc":[{"id":"1.170370564","rc":[{"atl":[[1.31,137.36]],"id":8509691}],"con":true,"img":false}]}
{"op":"mcm","clk":"1362372768","pt":1588445584391,"mc":[{"id":"1.170370564","rc":[{"atb":[[3.95,9.1]],"id":9630572},{"atl":[[4.7,0]],"id":9630572},{"atb":[[1.27,95]],"id":8509691},{"atl":[[1.34,0]],"id":8509691}],"con":true,"img":false}]}
{"op":"mcm","clk":"1362372770","pt":1588445584597,"mc":[{"id":"1.170370564","rc":[{"atb":[[3.95,11.1]],"id":9630572},{"atl":[[4.7,2.05]],"id":9630572},{"atb":[[1.27,97.09]],"id":8509691},{"atl":[[1.34,2.25]],"id":8509691}],"con":true,"img":false}]}
{"op":"mcm","clk":"1362372825","pt":1588445614605,"mc":[{"id":"1.170370564","rc":[{"trd":[[1.31,143.01]],"ltp":1.31,"tv":143.01,"id":8509691},{"atl":[[1.31,88.38]],"id":8509691}],"con":true,"img":false}]}
{"op":"mcm","clk":"1362372828","pt":1588445614912,"mc":[{"id":"1.170370564","rc":[{"atb":[[3.95,9.1]],"id":9630572},{"atl":[[4.7,0]],"id":9630572},{"atb":[[1.27,95]],"id":8509691},{"atl":[[1.34,0]],"id":8509691}],"con":true,"img":false}]}
{"op":"mcm","clk":"1362372830","pt":1588445615115,"mc":[{"id":"1.170370564","rc":[{"atb":[[3.95,11.21]],"id":9630572},{"atl":[[4.7,2.05]],"id":9630572},{"atb":[[1.27,97.05]],"id":8509691},{"atl":[[1.34,2.02]],"id":8509691}],"con":true,"img":false}]}
{"op":"mcm","clk":"1362372944","pt":1588445656943,"mc":[{"id":"1.170370564","rc":[{"atl":[[1.31,158.35]],"id":8509691}],"con":true,"img":false}]}
{"op":"mcm","clk":"1362372946","pt":1588445657248,"mc":[{"id":"1.170370564","rc":[{"atb":[[3.95,9.1]],"id":9630572},{"atl":[[4.7,0]],"id":9630572},{"atb":[[1.27,95]],"id":8509691},{"atl":[[1.34,0]],"id":8509691}],"con":true,"img":false}]}
{"op":"mcm","clk":"1362372947","pt":1588445657348,"mc":[{"id":"1.170370564","rc":[{"atb":[[3.95,11.21]],"id":9630572},{"atl":[[4.7,2.05]],"id":9630572},{"atb":[[1.27,97.05]],"id":8509691},{"atl":[[1.34,2.02]],"id":8509691}],"con":true,"img":false}]}
{"op":"mcm","clk":"1362373041","pt":1588445677975,"mc":[{"id":"1.170370565","rc":[{"trd":[[8.4,11.54]],"ltp":8.4,"tv":11.54,"id":11340557},{"atl":[[8.4,0.23]],"id":11340557}],"con":true,"img":false}]}
{"op":"mcm","clk":"1362373080","pt":1588445687122,"mc":[{"id":"1.170370564","rc":[{"trd":[[1.3,980.49]],"ltp":1.3,"tv":980.49,"id":8509691},{"atb":[[1.3,1825.62]],"id":8509691}],"con":true,"img":false}]}
{"op":"mcm","clk":"1362373083","pt":1588445687482,"mc":[{"id":"1.170370564","rc":[{"atb":[[3.95,9.1]],"id":9630572},{"atl":[[4.7,0]],"id":9630572},{"atb":[[1.27,95]],"id":8509691},{"atl":[[1.34,0]],"id":8509691}],"con":true,"img":false}]}
{"op":"mcm","clk":"1362373085","pt":1588445687686,"mc":[{"id":"1.170370564","rc":[{"atb":[[3.95,11.1]],"id":9630572},{"atl":[[4.7,2.05]],"id":9630572},{"atb":[[1.27,97.09]],"id":8509691},{"atl":[[1.34,2.02]],"id":8509691}],"con":true,"img":false}]}
{"op":"mcm","clk":"1362373117","pt":1588445696734,"mc":[{"id":"1.170370564","rc":[{"trd":[[1.3,1012.4]],"ltp":1.3,"tv":1012.4,"id":8509691},{"atb":[[1.3,1809.67]],"id":8509691}],"con":true,"img":false}]}
{"op":"mcm","clk":"1362373118","pt":1588445697039,"mc":[{"id":"1.170370564","rc":[{"atb":[[3.95,9.1]],"id":9630572},{"atl":[[4.7,0]],"id":9630572},{"atb":[[1.27,95]],"id":8509691},{"atl":[[1.34,0]],"id":8509691}],"con":true,"img":false}]}
{"op":"mcm","clk":"1362373119","pt":1588445697195,"mc":[{"id":"1.170370564","rc":[{"atb":[[3.95,11.21]],"id":9630572},{"atl":[[4.7,2.05]],"id":9630572},{"atb":[[1.27,97]],"id":8509691},{"atl":[[1.34,2.25]],"id":8509691}],"con":true,"img":false}]}
{"op":"mcm","clk":"1362373134","pt":1588445701923,"mc":[{"id":"1.170370565","rc":[{"atb":[[8,5.77]],"id":11340560}],"con":true,"img":false}]}
{"op":"mcm","clk":"1362373145","pt":1588445707441,"mc":[{"id":"1.170370564","rc":[{"trd":[[1.31,143.5]],"ltp":1.31,"tv":143.5,"id":8509691},{"atl":[[1.31,158.11]],"id":8509691}],"con":true,"img":false}]}
{"op":"mcm","clk":"1362373146","pt":1588445707746,"mc":[{"id":"1.170370564","rc":[{"atb":[[3.95,9.1]],"id":9630572},{"atl":[[4.7,0]],"id":9630572},{"atb":[[1.27,95]],"id":8509691},{"atl":[[1.34,0]],"id":8509691}],"con":true,"img":false}]}
{"op":"mcm","clk":"1362373147","pt":1588445707902,"mc":[{"id":"1.170370564","rc":[{"atb":[[3.95,11.21]],"id":9630572},{"atl":[[4.7,2.05]],"id":9630572},{"atb":[[1.27,97.05]],"id":8509691},{"atl":[[1.34,2.25]],"id":8509691}],"con":true,"img":false}]}
{"op":"mcm","clk":"1362373153","pt":1588445709727,"mc":[{"id":"1.170370564","rc":[{"trd":[[4.2,48.23]],"ltp":4.2,"tv":48.23,"id":9630572},{"atb":[[4.2,25.28]],"id":9630572}],"con":true,"img":false}]}
{"op":"mcm","clk":"1362373180","pt":1588445721416,"mc":[{"id":"1.170370564","rc":[{"trd":[[1.3,1041.55]],"ltp":1.3,"tv":1041.55,"id":8509691},{"atb":[[1.3,1795.09]],"id":8509691}],"con":true,"img":false}]}
{"op":"mcm","clk":"1362373183","pt":1588445721724,"mc":[{"id":"1.170370564","rc":[{"atb":[[3.95,9.1]],"id":9630572},{"atl":[[4.7,0]],"id":9630572},{"atb":[[1.27,95]],"id":8509691},{"atl":[[1.34,0]],"id":8509691}],"con":true,"img":false}]}
{"op":"mcm","clk":"1362373184","pt":1588445721824,"mc":[{"id":"1.170370564","rc":[{"atb":[[3.95,11.21]],"id":9630572},{"atl":[[4.7,2.05]],"id":9630572},{"atb":[[1.27,97.09]],"id":8509691},{"atl":[[1.34,2.02]],"id":8509691}],"con":true,"img":false}]}
{"op":"mcm","clk":"1362373219","pt":1588445740055,"mc":[{"id":"1.170370564","rc":[{"trd":[[1.31,163.5]],"ltp":1.31,"tv":163.5,"id":8509691},{"atl":[[1.31,148.1]],"id":8509691}],"con":true,"img":false}]}
{"op":"mcm","clk":"1362373221","pt":1588445740357,"mc":[{"id":"1.170370564","rc":[{"atb":[[3.95,9.1]],"id":9630572},{"atl":[[4.7,0]],"id":9630572},{"atb":[[1.27,95]],"id":8509691},{"atl":[[1.34,0]],"id":8509691}],"con":true,"img":false}]}
{"op":"mcm","clk":"1362373222","pt":1588445740563,"mc":[{"id":"1.170370564","rc":[{"atb":[[3.95,11.1]],"id":9630572},{"atl":[[4.7,2.05]],"id":9630572},{"atb":[[1.27,97.09]],"id":8509691},{"atl":[[1.34,2.02]],"id":8509691}],"con":true,"img":false}]}
{"op":"mcm","clk":"1362373224","pt":1588445742649,"mc":[{"id":"1.170370564","rc":[{"atl":[[1.31,155.39]],"id":8509691}],"con":true,"img":false}]}
{"op":"mcm","clk":"1362373239","pt":1588445751059,"mc":[{"id":"1.170370564","rc":[{"atb":[[4.2,36.28]],"id":9630572}],"con":true,"img":false}]}
{"op":"mcm","clk":"1362373240","pt":1588445751363,"mc":[{"id":"1.170370564","rc":[{"atb":[[3.95,9.1]],"id":9630572},{"atl":[[4.7,0]],"id":9630572},{"atb":[[1.27,95]],"id":8509691},{"atl":[[1.34,0]],"id":8509691}],"con":true,"img":false}]}
{"op":"mcm","clk":"1362373241","pt":1588445751567,"mc":[{"id":"1.170370564","rc":[{"atb":[[3.95,11.1]],"id":9630572},{"atl":[[4.7,2.05]],"id":9630572},{"atb":[[1.27,97.24]],"id":8509691},{"atl":[[1.34,2.02]],"id":8509691}],"con":true,"img":false}]}
{"op":"mcm","clk":"1362373264","pt":1588445760976,"mc":[{"id":"1.170370564","rc":[{"atl":[[4.3,17.49]],"id":9630572}],"con":true,"img":false}]}
{"op":"mcm","clk":"1362373266","pt":1588445761187,"mc":[{"id":"1.170370564","rc":[{"atl":[[4.5,2.01]],"id":9630572}],"con":true,"img":false}]}
{"op":"mcm","clk":"1362373267","pt":1588445761280,"mc":[{"id":"1.170370564","rc":[{"atl":[[4.7,0]],"id":9630572},{"atb":[[1.27,95]],"id":8509691},{"atl":[[1.34,0]],"id":8509691}],"con":true,"img":false}]}
{"op":"mcm","clk":"1362373268","pt":1588445761385,"mc":[{"id":"1.170370564","rc":[{"atb":[[3.95,9.1]],"id":9630572}],"con":true,"img":false}]}
{"op":"mcm","clk":"1362373269","pt":1588445761588,"mc":[{"id":"1.170370564","rc":[{"atb":[[3.95,11.1]],"id":9630572},{"atb":[[1.27,97.24]],"id":8509691},{"atl":[[1.34,2.02]],"id":8509691}],"con":true,"img":false}]}
{"op":"mcm","clk":"1362373270","pt":1588445761690,"mc":[{"id":"1.170370564","rc":[{"atl":[[4.6,0]],"id":9630572},{"atb":[[1.26,188.65]],"id":8509691}],"con":true,"img":false}]}
{"op":"mcm","clk":"1362373271","pt":1588445761892,"mc":[{"id":"1.170370564","rc":[{"atl":[[4.6,2.01]],"id":9630572}],"con":true,"img":false}]}
{"op":"mcm","clk":"1362373273","pt":1588445763173,"mc":[{"id":"1.170370564","rc":[{"atl":[[1.62,5]],"id":8509691}],"con":true,"img":false}]}
{"op":"mcm","clk":"1362373286","pt":1588445769092,"mc":[{"id":"1.170370564","rc":[{"atb":[[4.2,11]],"id":9630572}],"con":true,"img":false}]}
{"op":"mcm","clk":"1362373287","pt":1588445769398,"mc":[{"id":"1.170370564","rc":[{"atb":[[3.95,9.1]],"id":9630572},{"atl":[[4.6,0]],"id":9630572},{"atb":[[1.27,95]],"id":8509691},{"atl":[[1.34,0]],"id":8509691}],"con":true,"img":false}]}
{"op":"mcm","clk":"1362373288","pt":1588445769550,"mc":[{"id":"1.170370564","rc":[{"atb":[[3.95,11.21]],"id":9630572},{"atl":[[4.6,2.01]],"id":9630572},{"atb":[[1.27,97.24]],"id":8509691},{"atl":[[1.34,2.25]],"id":8509691}],"con":true,"img":false}]}
{"op":"mcm","clk":"1362373289","pt":1588445769956,"mc":[{"id":"1.170370564","rc":[{"trd":[[1.3,1060.8]],"ltp":1.3,"tv":1060.8,"id":8509691},{"atb":[[1.3,1785.47]],"id":8509691}],"con":true,"img":false}]}
{"op":"mcm","clk":"1362373301","pt":1588445775657,"mc":[{"id":"1.170370564","rc":[{"trd":[[1.3,1160.8]],"ltp":1.3,"tv":1160.8,"id":8509691},{"atb":[[1.3,1735.47]],"id":8509691}],"con":true,"img":false}]}
{"op":"mcm","clk":"1362373303","pt":1588445775961,"mc":[{"id":"1.170370564","rc":[{"atb":[[3.95,9.1]],"id":9630572},{"atl":[[4.6,0]],"id":9630572},{"atb":[[1.27,95]],"id":8509691},{"atl":[[1.34,0]],"id":8509691}],"con":true,"img":false}]}
{"op":"mcm","clk":"1362373304","pt":1588445776165,"mc":[{"id":"1.170370564","rc":[{"atb":[[3.95,11.21]],"id":9630572},{"atl":[[4.6,2.01]],"id":9630572},{"atb":[[1.27,97.24]],"id":8509691},{"atl":[[1.34,2.02]],"id":8509691}],"con":true,"img":false}]}
{"op":"mcm","clk":"1362373347","pt":1588445793114,"mc":[{"id":"1.170370564","rc":[{"trd":[[1.3,1161]],"ltp":1.3,"tv":1161.0,"id":8509691},{"atb":[[1.3,1735.37]],"id":8509691}],"con":true,"img":false}]}
{"op":"mcm","clk":"1362373349","pt":1588445793420,"mc":[{"id":"1.170370564","rc":[{"atb":[[3.95,9.1]],"id":9630572},{"atl":[[4.6,0]],"id":9630572},{"atb":[[1.27,95]],"id":8509691},{"atl":[[1.34,0]],"id":8509691}],"con":true,"img":false}]}
{"op":"mcm","clk":"1362373352","pt":1588445793572,"mc":[{"id":"1.170370564","rc":[{"atb":[[3.95,11.21]],"id":9630572},{"atl":[[4.6,2.01]],"id":9630572},{"atb":[[1.27,97.24]],"id":8509691},{"atl":[[1.34,2.02]],"id":8509691}],"con":true,"img":false}]}
{"op":"mcm","clk":"1362373377","pt":1588445803997,"mc":[{"id":"1.170370565","rc":[{"atl":[[8.6,1.83]],"id":11340557}],"con":true,"img":false}]}
{"op":"mcm","clk":"1362373381","pt":1588445806185,"mc":[{"id":"1.170370566","rc":[{"atl":[[1.42,199.73]],"id":8509691}],"con":true,"img":false}]}
{"op":"mcm","clk":"1362373408","pt":1588445818006,"mc":[{"id":"1.170370564","rc":[{"atl":[[1.31,162.39]],"id":8509691}],"con":true,"img":false}]}
{"op":"mcm","clk":"1362373409","pt":1588445818310,"mc":[{"id":"1.170370564","rc":[{"atb":[[3.95,9.1]],"id":9630572},{"atl":[[4.6,0]],"id":9630572},{"atb":[[1.27,95]],"id":8509691},{"atl":[[1.34,0]],"id":8509691}],"con":true,"img":false}]}
{"op":"mcm","clk":"1362373410","pt":1588445818516,"mc":[{"id":"1.170370564","rc":[{"atb":[[3.95,11.1]],"id":9630572},{"atl":[[4.6,2.01]],"id":9630572},{"atb":[[1.27,97.09]],"id":8509691},{"atl":[[1.34,2.02]],"id":8509691}],"con":true,"img":false}]}
{"op":"mcm","clk":"1362373424","pt":1588445823911,"mc":[{"id":"1.170370564","rc":[{"trd":[[1.3,1381.86]],"ltp":1.3,"tv":1381.86,"id":8509691},{"atb":[[1.3,1624.94]],"id":8509691}],"con":true,"img":false}]}
{"op":"mcm","clk":"1362373436","pt":1588445830235,"mc":[{"id":"1.170370564","rc":[{"trd":[[1.3,1581.86]],"ltp":1.3,"tv":1581.86,"id":8509691},{"atb":[[1.3,1524.94]],"id":8509691}],"con":true,"img":false}]}
{"op":"mcm","clk":"1362373438","pt":1588445830541,"mc":[{"id":"1.170370564","rc":[{"atb":[[3.95,9.1]],"id":9630572},{"atl":[[4.6,0]],"id":9630572},{"atb":[[1.27,95]],"id":8509691},{"atl":[[1.34,0]],"id":8509691}],"con":true,"img":false}]}
{"op":"mcm","clk":"1362373439","pt":1588445830643,"mc":[{"id":"1.170370564","rc":[{"atb":[[3.95,11.21]],"id":9630572},{"atl":[[4.6,2.01]],"id":9630572},{"atb":[[1.27,97.24]],"id":8509691},{"atl":[[1.34,2.02]],"id":8509691}],"con":true,"img":false}]}
{"op":"mcm","clk":"1362373468","pt":1588445838424,"mc":[{"id":"1.170370564","rc":[{"trd":[[1.3,2061.78]],"ltp":1.3,"tv":2061.78,"id":8509691},{"atb":[[1.3,1284.98]],"id":8509691}],"con":true,"img":false}]}
{"op":"mcm","clk":"1362373469","pt":1588445838729,"mc":[{"id":"1.170370564","rc":[{"atb":[[3.95,9.1]],"id":9630572},{"atl":[[4.6,0]],"id":9630572},{"atb":[[1.27,95]],"id":8509691},{"atl":[[1.34,0]],"id":8509691}],"con":true,"img":false}]}
{"op":"mcm","clk":"1362373470","pt":1588445838933,"mc":[{"id":"1.170370564","rc":[{"atb":[[3.95,11.1]],"id":9630572},{"atl":[[4.6,2.01]],"id":9630572},{"atb":[[1.27,97.24]],"id":8509691},{"atl":[[1.34,2.02]],"id":8509691}],"con":true,"img":false}]}
{"op":"mcm","clk":"1362373596","pt":1588445869321,"mc":[{"id":"1.170370564","rc":[{"atb":[[1.27,2.24]],"id":8509691}],"con":true,"img":false}]}
{"op":"mcm","clk":"1362373598","pt":1588445869627,"mc":[{"id":"1.170370564","rc":[{"atl":[[4.6,0]],"id":9630572},{"atb":[[1.27,0]],"id":8509691}],"con":true,"img":false}]}
{"op":"mcm","clk":"1362373599","pt":1588445869729,"mc":[{"id":"1.170370564","rc":[{"atb":[[3.95,9.1]],"id":9630572},{"atl":[[1.34,0]],"id":8509691}],"con":true,"img":false}]}
{"op":"mcm","clk":"1362373601","pt":1588445869882,"mc":[{"id":"1.170370564","rc":[{"atb":[[3.95,11.21]],"id":9630572},{"atl":[[4.6,2.01]],"id":9630572},{"atb":[[1.27,2.24]],"id":8509691},{"atl":[[1.34,2]],"id":8509691}],"con":true,"img":false}]}
{"op":"mcm","clk":"1362373634","pt":1588445878899,"mc":[{"id":"1.170370564","rc":[{"atb":[[1.26,88.65]],"id":8509691}],"con":true,"img":false}]}
{"op":"mcm","clk":"1362373636","pt":1588445879205,"mc":[{"id":"1.170370564","rc":[{"atb":[[3.95,9.1]],"id":9630572},{"atl":[[4.6,0]],"id":9630572},{"atb":[[1.27,0]],"id":8509691},{"atl":[[1.34,0]],"id":8509691}],"con":true,"img":false}]}
{"op":"mcm","clk":"1362373637","pt":1588445879409,"mc":[{"id":"1.170370564","rc":[{"atb":[[3.95,11.21]],"id":9630572},{"atl":[[4.6,2.01]],"id":9630572},{"atb":[[1.27,2.24]],"id":8509691},{"atl":[[1.34,2.02]],"id":8509691}],"con":true,"img":false}]}
{"op":"mcm","clk":"1362373660","pt":1588445886713,"mc":[{"id":"1.170370566","rc":[{"atl":[[1.42,0]],"id":8509691}],"con":true,"img":false}]}
{"op":"mcm","clk":"1362373666","pt":1588445888241,"mc":[{"id":"1.170370564","rc":[{"atb":[[1.25,612.56]],"id":8509691}],"con":true,"img":false}]}
{"op":"mcm","clk":"1362373669","pt":1588445888547,"mc":[{"id":"1.170370564","rc":[{"atb":[[3.95,9.1]],"id":9630572},{"atl":[[4.6,0]],"id":9630572},{"atb":[[1.27,0]],"id":8509691},{"atl":[[1.34,0]],"id":8509691}],"con":true,"img":false}]}
{"op":"mcm","clk":"1362373673","pt":1588445888702,"mc":[{"id":"1.170370564","rc":[{"atb":[[3.95,11.21]],"id":9630572},{"atl":[[4.6,2.01]],"id":9630572},{"atb":[[1.27,2.24]],"id":8509691},{"atl":[[1.34,2.25]],"id":8509691}],"con":true,"img":false}]}
{"op":"mcm","clk":"1362373693","pt":1588445893945,"mc":[{"id":"1.170370564","rc":[{"trd":[[1.3,2066.42]],"ltp":1.3,"tv":2066.42,"id":8509691},{"atb":[[1.3,1282.65]],"id":8509691}],"con":true,"img":false}]}
{"op":"mcm","clk":"1362373740","pt":1588445900412,"mc":[{"id":"1.170370564","rc":[{"atb":[[1.24,88.65]],"id":8509691}],"con":true,"img":false}]}
{"op":"mcm","clk":"1362373741","pt":1588445900716,"mc":[{"id":"1.170370564","rc":[{"atb":[[3.95,9.1]],"id":9630572},{"atl":[[4.6,0]],"id":9630572},{"atb":[[1.27,0]],"id":8509691},{"atl":[[1.34,0]],"id":8509691}],"con":true,"img":false}]}
{"op":"mcm","clk":"1362373743","pt":1588445900921,"mc":[{"id":"1.170370564","rc":[{"atb":[[3.95,11.1]],"id":9630572},{"atl":[[4.6,2.01]],"id":9630572},{"atb":[[1.27,2.24]],"id":8509691},{"atl":[[1.34,2.25]],"id":8509691}],"con":true,"img":false}]}
{"op":"mcm","clk":"1362373756","pt":1588445903215,"mc":[{"id":"1.170370564","rc":[{"atl":[[1.31,155.39]],"id":8509691}],"con":true,"img":false}]}
{"op":"mcm","clk":"1362373770","pt":1588445909731,"mc":[{"id":"1.170370564","rc":[{"atb":[[1.23,176.12]],"id":8509691}],"con":true,"img":false}]}
{"op":"mcm","clk":"1362373771","pt":1588445910038,"mc":[{"id":"1.170370564","rc":[{"atb":[[3.95,9.1]],"id":9630572},{"atl":[[4.6,0]],"id":9630572},{"atb":[[1.27,0]],"id":8509691},{"atl":[[1.34,0]],"id":8509691}],"con":true,"img":false}]}
{"op":"mcm","clk":"1362373772","pt":1588445910140,"mc":[{"id":"1.170370564","rc":[{"atb":[[3.95,11.1]],"id":9630572},{"atl":[[4.6,2.01]],"id":9630572},{"atb":[[1.27,2.09]],"id":8509691},{"atl":[[1.34,2.25]],"id":8509691}],"con":true,"img":false}]}
{"op":"mcm","clk":"1362373810","pt":1588445918956,"mc":[{"id":"1.170370564","rc":[{"atb":[[4.2,0]],"id":9630572}],"con":true,"img":false}]}
{"op":"mcm","clk":"1362373811","pt":1588445919160,"mc":[{"id":"1.170370564","rc":[{"atb":[[3.9,11.22]],"id":9630572}],"con":true,"img":false}]}
{"op":"mcm","clk":"1362373813","pt":1588445919261,"mc":[{"id":"1.170370564","rc":[{"atb":[[4,8.86]],"id":9630572},{"atl":[[4.6,0]],"id":9630572},{"atb":[[1.27,0]],"id":8509691},{"atl":[[1.34,0]],"id":8509691}],"con":true,"img":false}]}
{"op":"mcm","clk":"1362373816","pt":1588445919567,"mc":[{"id":"1.170370564","rc":[{"atb":[[3.95,9.1]],"id":9630572}],"con":true,"img":false}]}
{"op":"mcm","clk":"1362373818","pt":1588445919772,"mc":[{"id":"1.170370564","rc":[{"atb":[[4,10.88],[3.95,11.1]],"id":9630572},{"atl":[[4.6,2.01]],"id":9630572},{"atb":[[1.27,2.09]],"id":8509691},{"atl":[[1.34,2.02]],"id":8509691}],"con":true,"img":false}]}
{"op":"mcm","clk":"1362373831","pt":1588445921552,"mc":[{"id":"1.170370564","rc":[{"atb":[[1.22,2]],"id":8509691}],"con":true,"img":false}]}
{"op":"mcm","clk":"1362373846","pt":1588445922877,"mc":[{"id":"1.170370564","rc":[{"atb":[[4,29.46]],"id":9630572},{"atb":[[1.2,278.8]],"id":8509691}],"con":true,"img":false}]}
{"op":"mcm","clk":"1362373899","pt":1588445934348,"mc":[{"id":"1.170370564","rc":[{"atl":[[1.31,391.21]],"id":8509691}],"con":true,"img":false}]}
{"op":"mcm","clk":"1362373901","pt":1588445934653,"mc":[{"id":"1.170370564","rc":[{"atb":[[3.95,9.1],[3.9,9.16]],"id":9630572},{"atl":[[4.6,0]],"id":9630572},{"atb":[[1.27,0]],"id":8509691},{"atl":[[1.34,0]],"id":8509691}],"con":true,"img":false}]}
{"op":"mcm","clk":"1362373903","pt":1588445934857,"mc":[{"id":"1.170370564","rc":[{"atb":[[3.95,11.1]],"id":9630572},{"atl":[[4.6,2.01]],"id":9630572},{"atb":[[1.27,2.24]],"id":8509691},{"atl":[[1.34,2.25]],"id":8509691}],"con":true,"img":false}]}
{"op":"mcm","clk":"1362373928","pt":1588445942461,"mc":[{"id":"1.170370564","rc":[{"atb":[[1.21,0]],"id":8509691}],"con":true,"img":false}]}
{"op":"mcm","clk":"1362373930","pt":1588445942766,"mc":[{"id":"1.170370564","rc":[{"atb":[[3.95,9.1]],"id":9630572},{"atl":[[4.6,0]],"id":9630572},{"atb":[[1.27,0]],"id":8509691},{"atl":[[1.34,0]],"id":8509691}],"con":true,"img":false}]}
{"op":"mcm","clk":"1362373932","pt":1588445942869,"mc":[{"id":"1.170370564","rc":[{"atb":[[3.95,11.21]],"id":9630572},{"atl":[[4.6,2.01]],"id":9630572},{"atb":[[1.27,2.09]],"id":8509691},{"atl":[[1.34,2.25]],"id":8509691}],"con":true,"img":false}]}
{"op":"mcm","clk":"1362373934","pt":1588445943380,"mc":[{"id":"1.170370564","rc":[{"atl":[[4.8,0],[4.9,0]],"id":9630572}],"con":true,"img":false}]}
{"op":"mcm","clk":"1362374734","pt":1588445965407,"mc":[{"id":"1.170370564","rc":[{"trd":[[1.3,2166.42]],"ltp":1.3,"tv":2166.42,"id":8509691},{"atb":[[1.3,1232.65]],"id":8509691}],"con":true,"img":false}]}
{"op":"mcm","clk":"1362374735","pt":1588445965713,"mc":[{"id":"1.170370564","rc":[{"atb":[[3.95,9.1]],"id":9630572},{"atl":[[4.6,0]],"id":9630572},{"atb":[[1.27,0]],"id":8509691},{"atl":[[1.34,0]],"id":8509691}],"con":true,"img":false}]}
{"op":"mcm","clk":"1362374737","pt":1588445965916,"mc":[{"id":"1.170370564","rc":[{"atb":[[3.95,11.1]],"id":9630572},{"atl":[[4.6,2.01]],"id":9630572},{"atb":[[1.27,2.24]],"id":8509691},{"atl":[[1.34,2.02]],"id":8509691}],"con":true,"img":false}]}
{"op":"mcm","clk":"1362374843","pt":1588445984016,"mc":[{"id":"1.170370564","rc":[{"atl":[[4.3,19.06]],"id":9630572}],"con":true,"img":false}]}
{"op":"mcm","clk":"1362374849","pt":1588445985390,"mc":[{"id":"1.170370564","rc":[{"atb":[[3.95,9.1]],"id":9630572},{"atl":[[4.6,0]],"id":9630572},{"atb":[[1.27,0]],"id":8509691},{"atl":[[1.34,0]],"id":8509691}],"con":true,"img":false}]}
{"op":"mcm","clk":"1362374853","pt":1588445986588,"mc":[{"id":"1.170370564","rc":[{"atb":[[3.95,11.21]],"id":9630572},{"atl":[[4.6,2.01]],"id":9630572},{"atb":[[1.27,2.09]],"id":8509691},{"atl":[[1.34,2]],"id":8509691}],"con":true,"img":false}]}
{"op":"mcm","clk":"1362374931","pt":1588445991820,"mc":[{"id":"1.170370564","rc":[{"atl":[[4.3,30.06]],"id":9630572}],"con":true,"img":false}]}
{"op":"mcm","clk":"1362374935","pt":1588445992025,"mc":[{"id":"1.170370565","rc":[{"atb":[[1.81,7.69]],"id":11269555}],"con":true,"img":false}]}
{"op":"mcm","clk":"1362374938","pt":1588445992127,"mc":[{"id":"1.170370564","rc":[{"atb":[[3.95,9.1]],"id":9630572},{"atl":[[4.6,0]],"id":9630572},{"atb":[[1.27,0]],"id":8509691},{"atl":[[1.34,0]],"id":8509691}],"con":true,"img":false}]}
{"op":"mcm","clk":"1362374945","pt":1588445992331,"mc":[{"id":"1.170370564","rc":[{"atb":[[3.95,11.21]],"id":9630572},{"atl":[[4.6,2.01]],"id":9630572},{"atb":[[1.27,2.09]],"id":8509691},{"atl":[[1.34,2.02]],"id":8509691}],"con":true,"img":false}]}
{"op":"mcm","clk":"1362375009","pt":1588445999113,"mc":[{"id":"1.170370565","rc":[{"atb":[[1.81,0]],"id":11269555}],"con":true,"img":false}]}
{"op":"mcm","clk":"1362375013","pt":1588445999316,"mc":[{"id":"1.170370565","rc":[{"trd":[[1.84,8]],"ltp":1.84,"tv":8.0,"id":11269555},{"atb":[[1.84,3.69]],"id":11269555},{"atl":[[1.84,0]],"id":11269555}],"con":true,"img":false}]}
{"op":"mcm","clk":"1362375035","pt":1588446002132,"mc":[{"id":"1.170370565","rc":[{"atb":[[1.84,0]],"id":11269555}],"con":true,"img":false}]}
{"op":"mcm","clk":"1362375053","pt":1588446003619,"mc":[{"id":"1.170370564","rc":[{"trd":[[1.3,2565.89]],"ltp":1.3,"tv":2565.89,"id":8509691},{"atb":[[1.3,1032.92]],"id":8509691}],"con":true,"img":false}]}
{"op":"mcm","clk":"1362375120","pt":1588446011027,"mc":[{"id":"1.170370564","rc":[{"atl":[[4.4,0]],"id":9630572}],"con":true,"img":false}]}
{"op":"mcm","clk":"1362375353","pt":1588446035065,"mc":[{"id":"1.170370564","rc":[{"atb":[[1.29,987.43]],"id":8509691}],"con":true,"img":false}]}
{"op":"mcm","clk":"1362375365","pt":1588446036341,"mc":[{"id":"1.170370564","rc":[{"atb":[[1.29,2.5]],"id":8509691}],"con":true,"img":false}]}
{"op":"mcm","clk":"1362375413","pt":1588446044149,"mc":[{"id":"1.170370564","rc":[{"atl":[[1.4,4.37]],"id":8509691}],"con":true,"img":false}]}
{"op":"mcm","clk":"1362375435","pt":1588446047057,"mc":[{"id":"1.170370564","rc":[{"atl":[[1.4,0]],"id":8509691}],"con":true,"img":false}]}
{"op":"mcm","clk":"1362375503","pt":1588446053962,"mc":[{"id":"1.170370564","rc":[{"atb":[[4.2,10.93]],"id":9630572}],"con":true,"img":false}]}
{"op":"mcm","clk":"1362375553","pt":1588446058302,"mc":[{"id":"1.170370564","rc":[{"atb":[[4,10.88]],"id":9630572},{"atb":[[1.2,0]],"id":8509691}],"con":true,"img":false}]}
{"op":"mcm","clk":"1362375567","pt":1588446059073,"mc":[{"id":"1.170370564","rc":[{"atb":[[4.2,0]],"id":9630572}],"con":true,"img":false}]}
{"op":"mcm","clk":"1362375570","pt":1588446059276,"mc":[{"id":"1.170370564","rc":[{"atb":[[4.2,10.93]],"id":9630572}],"con":true,"img":false}]}
{"op":"mcm","clk":"1362375664","pt":1588446067127,"mc":[{"id":"1.170370564","rc":[{"atl":[[4.3,12.57]],"id":9630572}],"con":true,"img":false}]}
{"op":"mcm","clk":"1362375665","pt":1588446067476,"mc":[{"id":"1.170370564","rc":[{"atb":[[4,8.86],[3.95,9.1]],"id":9630572},{"atl":[[4.5,0]],"id":9630572},{"atb":[[1.28,4.55]],"id":8509691},{"atl":[[1.33,6.39]],"id":8509691}],"con":true,"img":false}]}
{"op":"mcm","clk":"1362375666","pt":1588446067577,"mc":[{"id":"1.170370564","rc":[{"atl":[[4.6,0]],"id":9630572},{"atb":[[1.27,0]],"id":8509691},{"atl":[[1.34,0]],"id":8509691}],"con":true,"img":false}]}
{"op":"mcm","clk":"1362375838","pt":1588446080999,"mc":[{"id":"1.170370564","rc":[{"trd":[[1.31,216.4]],"ltp":1.31,"tv":216.4,"id":8509691},{"atl":[[1.31,364.76]],"id":8509691}],"con":true,"img":false}]}
{"op":"mcm","clk":"1362375955","pt":1588446091727,"mc":[{"id":"1.170370564","rc":[{"atl":[[1.33,0]],"id":8509691}],"con":true,"img":false}]}
{"op":"mcm","clk":"1362376030","pt":1588446098207,"mc":[{"id":"1.170370564","rc":[{"trd":[[4.3,79.92]],"ltp":4.3,"tv":79.92,"id":9630572},{"atl":[[4.3,4.52]],"id":9630572}],"con":true,"img":false}]}
{"op":"mcm","clk":"1362376038","pt":1588446098817,"mc":[{"id":"1.170370564","rc":[{"atb":[[1.26,0]],"id":8509691}],"con":true,"img":false}]}
{"op":"mcm","clk":"1362376089","pt":1588446102904,"mc":[{"id":"1.170370564","rc":[{"atb":[[1.01,1846]],"id":8509691}],"con":true,"img":false}]}
{"op":"mcm","clk":"1362376145","pt":1588446107910,"mc":[{"id":"1.170370564","rc":[{"trd":[[1.3,2618.8]],"ltp":1.3,"tv":2618.8,"id":8509691},{"atb":[[1.3,1006.47]],"id":8509691}],"con":true,"img":false}]}
{"op":"mcm","clk":"1362376420","pt":1588446131777,"mc":[{"id":"1.170370564","rc":[{"trd":[[4.2,73.74]],"ltp":4.2,"tv":73.74,"id":9630572},{"atb":[[4.2,0]],"id":9630572},{"trd":[[1.31,228.07]],"ltp":1.31,"tv":228.07,"id":8509691},{"atl":[[1.31,353.08]],"id":8509691}],"con":true,"img":false}]}
{"op":"mcm","clk":"1362376422","pt":1588446131982,"mc":[{"id":"1.170370564","rc":[{"atl":[[1.62,0]],"id":8509691}],"con":true,"img":false}]}
{"op":"mcm","clk":"1362376437","pt":1588446133256,"mc":[{"id":"1.170370564","rc":[{"atb":[[4,27.44]],"id":9630572},{"atb":[[1.2,278.8]],"id":8509691}],"con":true,"img":false}]}
{"op":"mcm","clk":"1362376805","pt":1588446164468,"mc":[{"id":"1.170370564","rc":[{"atb":[[1.27,1969.85]],"id":8509691}],"con":true,"img":false}]}
{"op":"mcm","clk":"1362377134","pt":1588446192704,"mc":[{"id":"1.170370564","rc":[{"atb":[[1.3,0]],"id":8509691}],"con":true,"img":false}]}
{"op":"mcm","clk":"1362377136","pt":1588446192805,"mc":[{"id":"1.170370564","rc":[{"atb":[[1.28,1011.02]],"id":8509691}],"con":true,"img":false}]}
{"op":"mcm","clk":"1362377138","pt":1588446192908,"mc":[{"id":"1.170370564","rc":[{"trd":[[4.3,88.96]],"ltp":4.3,"tv":88.96,"id":9630572},{"atb":[[4.3,0]],"id":9630572},{"atl":[[4.3,0]],"id":9630572}],"con":true,"img":false}]}
{"op":"mcm","clk":"1362377140","pt":1588446193214,"mc":[{"id":"1.170370564","rc":[{"atb":[[4.3,0]],"id":9630572}],"con":true,"img":false}]}
{"op":"mcm","clk":"1362377536","pt":1588446227934,"mc":[{"id":"1.170370564","rc":[{"atb":[[1.28,1006.47]],"id":8509691}],"con":true,"img":false}]}
{"op":"mcm","clk":"1362377538","pt":1588446228036,"mc":[{"id":"1.170370564","rc":[{"atb":[[1.29,7.05]],"id":8509691}],"con":true,"img":false}]}
{"op":"mcm","clk":"1362377594","pt":1588446233748,"mc":[{"id":"1.170370564","rc":[{"atb":[[1.25,88.65]],"id":8509691}],"con":true,"img":false}]}
{"op":"mcm","clk":"1362377743","pt":1588446249127,"mc":[{"id":"1.170370564","rc":[{"atl":[[1.3,69.97]],"id":8509691}],"con":true,"img":false}]}
{"op":"mcm","clk":"1362377748","pt":1588446249841,"mc":[{"id":"1.170370564","rc":[{"atb":[[4.1,8.58]],"id":9630572},{"atb":[[1.25,0]],"id":8509691}],"con":true,"img":false}]}
{"op":"mcm","clk":"1362377829","pt":1588446258453,"mc":[{"id":"1.170370565","rc":[{"trd":[[8,2.91]],"ltp":8.0,"tv":2.91,"id":11340560},{"atb":[[8,4.31]],"id":11340560}],"con":true,"img":false}]}
{"op":"mcm","clk":"1362377831","pt":1588446258862,"mc":[{"id":"1.170370564","rc":[{"trd":[[1.29,21575.41]],"ltp":1.29,"tv":21575.41,"id":8509691},{"atb":[[1.29,6.65]],"id":8509691}],"con":true,"img":false}]}
{"op":"mcm","clk":"1362378187","pt":1588446293401,"mc":[{"id":"1.170370564","rc":[{"atl":[[1.33,127.97]],"id":8509691}],"con":true,"img":false}]}
{"op":"mcm","clk":"1362378585","pt":1588446326241,"mc":[{"id":"1.170370564","rc":[{"atl":[[1.5,25.46]],"id":8509691}],"con":true,"img":false}]}
{"op":"mcm","clk":"1362378878","pt":1588446348936,"mc":[{"id":"1.170370564","rc":[{"atb":[[1.29,405.59]],"id":8509691}],"con":true,"img":false}]}
{"op":"mcm","clk":"1362378884","pt":1588446349752,"mc":[{"id":"1.170370564","rc":[{"atb":[[1.25,88.65]],"id":8509691}],"con":true,"img":false}]}
{"op":"mcm","clk":"1362379046","pt":1588446362387,"mc":[{"id":"1.170370564","rc":[{"trd":[[1.31,485.58],[1.3,2758.75]],"ltp":1.31,"tv":3244.33,"id":8509691},{"atl":[[1.3,0],[1.31,224.33]],"id":8509691}],"con":true,"img":false}]}
{"op":"mcm","clk":"1362379053","pt":1588446362999,"mc":[{"id":"1.170370564","rc":[{"atb":[[4.1,0]],"id":9630572}],"con":true,"img":false}]}
{"op":"mcm","clk":"1362379182","pt":1588446372772,"mc":[{"id":"1.170370564","rc":[{"atl":[[1.3,2]],"id":8509691}],"con":true,"img":false}]}
{"op":"mcm","clk":"1362379275","pt":1588446381371,"mc":[{"id":"1.170370564","rc":[{"atl":[[1.3,0]],"id":8509691}],"con":true,"img":false}]}
{"op":"mcm","clk":"1362379627","pt":1588446407133,"mc":[{"id":"1.170370564","rc":[{"atb":[[1.3,69.97]],"id":8509691}],"con":true,"img":false}]}
{"op":"mcm","clk":"1362379775","pt":1588446415941,"mc":[{"id":"1.170370564","rc":[{"atb":[[1.29,412.88]],"id":8509691}],"con":true,"img":false}]}
{"op":"mcm","clk":"1362379777","pt":1588446416145,"mc":[{"id":"1.170370564","rc":[{"atb":[[1.3,139.95]],"id":8509691}],"con":true,"img":false}]}
{"op":"mcm","clk":"1362379852","pt":1588446421344,"mc":[{"id":"1.170370564","rc":[{"trd":[[1.3,2759.23]],"ltp":1.3,"tv":2759.23,"id":8509691},{"atb":[[1.3,139.71]],"id":8509691}],"con":true,"img":false}]}
{"op":"mcm","clk":"1362380459","pt":1588446463193,"mc":[{"id":"1.170370567","rc":[{"atb":[[1.31,2.62]],"id":8509691}],"con":true,"img":false}]}
{"op":"mcm","clk":"1362380548","pt":1588446469097,"mc":[{"id":"1.170370567","rc":[{"atb":[[1.31,0]],"id":8509691}],"con":true,"img":false}]}
{"op":"mcm","clk":"1362380552","pt":1588446469300,"mc":[{"id":"1.170370567","rc":[{"atb":[[1.31,2.62]],"id":8509691}],"con":true,"img":false}]}
{"op":"mcm","clk":"1362380699","pt":1588446479992,"mc":[{"id":"1.170370564","rc":[{"trd":[[1.3,2981.23]],"ltp":1.3,"tv":2981.23,"id":8509691},{"atb":[[1.3,28.71]],"id":8509691}],"con":true,"img":false}]}
{"op":"mcm","clk":"1362380793","pt":1588446485112,"mc":[{"id":"1.170370564","rc":[{"trd":[[1.3,3038.66]],"ltp":1.3,"tv":3038.66,"id":8509691},{"atb":[[1.3,0]],"id":8509691},{"atl":[[1.3,46.92]],"id":8509691}],"con":true,"img":false}]}
{"op":"mcm","clk":"1362380812","pt":1588446485876,"mc":[{"id":"1.170370564","rc":[{"atb":[[4.1,8.58]],"id":9630572}],"con":true,"img":false}]}
{"op":"mcm","clk":"1362380847","pt":1588446487913,"mc":[{"id":"1.170370564","rc":[{"atl":[[1.3,54.64]],"id":8509691}],"con":true,"img":false}]}
{"op":"mcm","clk":"1362381056","pt":1588446501182,"mc":[{"id":"1.170370564","rc":[{"trd":[[1.3,3046.95]],"ltp":1.3,"tv":3046.95,"id":8509691},{"atl":[[1.3,50.5]],"id":8509691}],"con":true,"img":false}]}
{"op":"mcm","clk":"1362381115","pt":1588446504492,"mc":[{"id":"1.170370564","rc":[{"atb":[[1.29,13.94]],"id":8509691}],"con":true,"img":false}]}
{"op":"mcm","clk":"1362381127","pt":1588446505002,"mc":[{"id":"1.170370564","rc":[{"atb":[[1.25,0]],"id":8509691}],"con":true,"img":false}]}
{"op":"mcm","clk":"1362381600","pt":1588446534876,"mc":[{"id":"1.170370564","rc":[{"atl":[[1.3,42.78]],"id":8509691}],"con":true,"img":false}]}
{"op":"mcm","clk":"1362381604","pt":1588446534981,"mc":[{"id":"1.170370564","rc":[{"trd":[[1.29,21590.97]],"ltp":1.29,"tv":21590.97,"id":8509691},{"atb":[[1.29,6.16]],"id":8509691}],"con":true,"img":false}]}
{"op":"mcm","clk":"1362381715","pt":1588446542210,"mc":[{"id":"1.170370564","rc":[{"atl":[[1.3,112.76]],"id":8509691}],"con":true,"img":false}]}
{"op":"mcm","clk":"1362381857","pt":1588446553171,"mc":[{"id":"1.170370564","rc":[{"atl":[[4.5,2.62]],"id":9630572}],"con":true,"img":false}]}
{"op":"mcm","clk":"1362381860","pt":1588446553627,"mc":[{"id":"1.170370564","rc":[{"atl":[[1.3,69.97]],"id":8509691}],"con":true,"img":false}]}
{"op":"mcm","clk":"1362381861","pt":1588446553680,"mc":[{"id":"1.170370564","rc":[{"trd":[[1.29,21603.31]],"ltp":1.29,"tv":21603.31,"id":8509691},{"atb":[[1.29,0]],"id":8509691},{"atl":[[1.29,36.61]],"id":8509691}],"con":true,"img":false}]}
{"op":"mcm","clk":"1362381865","pt":1588446553882,"mc":[{"id":"1.170370564","rc":[{"trd":[[1.29,21676.53]],"ltp":1.29,"tv":21676.53,"id":8509691},{"atb":[[1.29,0.06]],"id":8509691},{"atl":[[1.29,0]],"id":8509691}],"con":true,"img":false}]}
{"op":"mcm","clk":"1362381867","pt":1588446554187,"mc":[{"id":"1.170370564","rc":[{"atb":[[1.29,0]],"id":8509691}],"con":true,"img":false}]}
{"op":"mcm","clk":"1362382047","pt":1588446568034,"mc":[{"id":"1.170370564","rc":[{"atl":[[4.8,2.62]],"id":9630572}],"con":true,"img":false}]}
{"op":"mcm","clk":"1362382211","pt":1588446578926,"mc":[{"id":"1.170370564","rc":[{"atl":[[5.1,2.62]],"id":9630572}],"con":true,"img":false}]}
{"op":"mcm","clk":"1362382234","pt":1588446580249,"mc":[{"id":"1.170370564","rc":[{"atl":[[1.3,77.26]],"id":8509691}],"con":true,"img":false}]}
{"op":"mcm","clk":"1362382256","pt":1588446582334,"mc":[{"id":"1.170370564","rc":[{"trd":[[1.28,4209.09]],"ltp":1.28,"tv":4209.09,"id":8509691},{"atb":[[1.28,908.06]],"id":8509691}],"con":true,"img":false},{"id":"1.170370565","rc":[{"atb":[[1.81,6.25]],"id":11269555}],"con":true,"img":false}]}
{"op":"mcm","clk":"1362382403","pt":1588446592461,"mc":[{"id":"1.170370564","rc":[{"atb":[[1.23,276.3]],"id":8509691}],"con":true,"img":false}]}
{"op":"mcm","clk":"1362382448","pt":1588446594953,"mc":[{"id":"1.170370565","rc":[{"atb":[[1.74,0]],"id":11269555}],"con":true,"img":false}]}
{"op":"mcm","clk":"1362382456","pt":1588446595260,"mc":[{"id":"1.170370565","rc":[{"atb":[[3.45,0]],"id":11269557}],"con":true,"img":false}]}
{"op":"mcm","clk":"1362382461","pt":1588446595464,"mc":[{"id":"1.170370565","rc":[{"atb":[[7,0]],"id":11340557}],"con":true,"img":false}]}
{"op":"mcm","clk":"1362382463","pt":1588446595664,"mc":[{"id":"1.170370565","rc":[{"atb":[[7.2,0]],"id":11340560}],"con":true,"img":false}]}
{"op":"mcm","clk":"1362382470","pt":1588446596070,"mc":[{"id":"1.170370565","rc":[{"atb":[[7,4]],"id":11340557},{"atb":[[8.2,6]],"id":11340560},{"atb":[[1.73,80.64]],"id":11269555},{"atb":[[3.45,5]],"id":11269557}],"con":true,"img":false}]}
{"op":"mcm","clk":"1362382504","pt":1588446597956,"mc":[{"id":"1.170370564","rc":[{"atl":[[5.4,3.06]],"id":9630572}],"con":true,"img":false}]}
{"op":"mcm","clk":"1362382535","pt":1588446600249,"mc":[{"id":"1.170370565","rc":[{"atb":[[1.51,7.15]],"id":11269555}],"con":true,"img":false}]}
{"op":"mcm","clk":"1362382588","pt":1588446604384,"mc":[{"id":"1.170370564","rc":[{"atl":[[1.3,83.26]],"id":8509691}],"con":true,"img":false}]}
{"op":"mcm","clk":"1362382672","pt":1588446609287,"mc":[{"id":"1.170370564","rc":[{"trd":[[1.3,3099.85]],"ltp":1.3,"tv":3099.85,"id":8509691},{"atl":[[1.3,56.81]],"id":8509691}],"con":true,"img":false}]}
{"op":"mcm","clk":"1362383481","pt":1588446664044,"mc":[{"id":"1.170370564","rc":[{"atl":[[5.4,0]],"id":9630572}],"con":true,"img":false}]}
{"op":"mcm","clk":"1362383805","pt":1588446683388,"mc":[{"id":"1.170370564","rc":[{"atb":[[1.2,289.1]],"id":8509691}],"con":true,"img":false}]}
{"op":"mcm","clk":"1362383889","pt":1588446688590,"mc":[{"id":"1.170370564","rc":[{"trd":[[1.28,4215.09]],"ltp":1.28,"tv":4215.09,"id":8509691},{"atb":[[1.28,905.07]],"id":8509691}],"con":true,"img":false}]}
{"op":"mcm","clk":"1362384155","pt":1588446707912,"mc":[{"id":"1.170370565","rc":[{"atl":[[2,3.06]],"id":11269555}],"con":true,"img":false}]}
{"op":"mcm","clk":"1362384567","pt":1588446737763,"mc":[{"id":"1.170370564","rc":[{"trd":[[1.3,3119.85]],"ltp":1.3,"tv":3119.85,"id":8509691},{"atl":[[1.3,46.81]],"id":8509691}],"con":true,"img":false}]}
{"op":"mcm","clk":"1362385364","pt":1588446787805,"mc":[{"id":"1.170370564","rc":[{"atb":[[1.28,0],[1.27,0]],"id":8509691},{"atl":[[1.32,0]],"id":8509691}],"con":true,"img":false}]}
{"op":"mcm","clk":"1362385381","pt":1588446789126,"mc":[{"id":"1.170370564","rc":[{"atb":[[3.9,0]],"id":9630572},{"atb":[[1.24,0]],"id":8509691}],"con":true,"img":false}]}
{"op":"mcm","clk":"1362385397","pt":1588446790143,"mc":[{"id":"1.170370564","rc":[{"atb":[[3.95,0.09]],"id":9630572}],"con":true,"img":false}]}
{"op":"mcm","clk":"1362385410","pt":1588446791008,"mc":[{"id":"1.170370564","rc":[{"atb":[[4.2,8.31]],"id":9630572}],"con":true,"img":false}]}
{"op":"mcm","clk":"1362385598","pt":1588446803936,"mc":[{"id":"1.170370564","rc":[{"atb":[[1.28,34.98]],"id":8509691}],"con":true,"img":false}]}
{"op":"mcm","clk":"1362385751","pt":1588446813886,"mc":[{"id":"1.170370564","rc":[{"atl":[[1.3,50.01]],"id":8509691}],"con":true,"img":false}]}
{"op":"mcm","clk":"1362385791","pt":1588446816177,"mc":[{"id":"1.170370564","rc":[{"atb":[[1.29,3.19]],"id":8509691}],"con":true,"img":false}]}
{"op":"mcm","clk":"1362385801","pt":1588446816991,"mc":[{"id":"1.170370564","rc":[{"atb":[[1.24,88.65]],"id":8509691}],"con":true,"img":false}]}
{"op":"mcm","clk":"1362386103","pt":1588446836189,"mc":[{"id":"1.170370564","rc":[{"atl":[[1.3,53.21]],"id":8509691}],"con":true,"img":false}]}
{"op":"mcm","clk":"1362387232","pt":1588446860217,"mc":[{"id":"1.170370564","rc":[{"trd":[[1.29,21680.08]],"ltp":1.29,"tv":21680.08,"id":8509691},{"atb":[[1.29,1.42]],"id":8509691}],"con":true,"img":false}]}
{"op":"mcm","clk":"1362387290","pt":1588446863430,"mc":[{"id":"1.170370564","rc":[{"trd":[[1.29,21682.93]],"ltp":1.29,"tv":21682.93,"id":8509691},{"atb":[[1.29,0]],"id":8509691},{"atl":[[1.29,0.34]],"id":8509691}],"con":true,"img":false}]}
{"op":"mcm","clk":"1362387308","pt":1588446864652,"mc":[{"id":"1.170370564","rc":[{"atl":[[1.29,0]],"id":8509691}],"con":true,"img":false}]}
{"op":"mcm","clk":"1362387335","pt":1588446865570,"mc":[{"id":"1.170370564","rc":[{"atb":[[1.29,1.77]],"id":8509691}],"con":true,"img":false}]}
{"op":"mcm","clk":"1362387340","pt":1588446865723,"mc":[{"id":"1.170370564","rc":[{"trd":[[1.3,3124.22]],"ltp":1.3,"tv":3124.22,"id":8509691},{"atl":[[1.3,51.03]],"id":8509691}],"con":true,"img":false}]}
{"op":"mcm","clk":"1362387353","pt":1588446866131,"mc":[{"id":"1.170370564","rc":[{"atb":[[1.29,3.54]],"id":8509691}],"con":true,"img":false}]}
{"op":"mcm","clk":"1362387725","pt":1588446887678,"mc":[{"id":"1.170370564","rc":[{"trd":[[1.3,3129.02]],"ltp":1.3,"tv":3129.02,"id":8509691},{"atl":[[1.3,48.63]],"id":8509691}],"con":true,"img":false}]}
{"op":"mcm","clk":"1362388103","pt":1588446918517,"mc":[{"id":"1.170370564","rc":[{"trd":[[1.29,21684.41]],"ltp":1.29,"tv":21684.41,"id":8509691},{"atb":[[1.29,2.81]],"id":8509691}],"con":true,"img":false}]}
{"op":"mcm","clk":"1362388586","pt":1588446950994,"mc":[{"id":"1.170370564","rc":[{"atb":[[1.28,48.37]],"id":8509691}],"con":true,"img":false}]}
{"op":"mcm","clk":"1362388652","pt":1588446956290,"mc":[{"id":"1.170370564","rc":[{"atl":[[1.3,135.83]],"id":8509691}],"con":true,"img":false}]}
{"op":"mcm","clk":"1362388860","pt":1588446974507,"mc":[{"id":"1.170370564","rc":[{"atl":[[1.3,129.83]],"id":8509691}],"con":true,"img":false}]}
{"op":"mcm","clk":"1362389844","pt":1588447055736,"mc":[{"id":"1.170370564","rc":[{"atb":[[1.28,1033.3]],"id":8509691}],"con":true,"img":false}]}
{"op":"mcm","clk":"1362389851","pt":1588447056244,"mc":[{"id":"1.170370564","rc":[{"atb":[[4.2,0]],"id":9630572}],"con":true,"img":false}]}
{"op":"mcm","clk":"1362389856","pt":1588447056752,"mc":[{"id":"1.170370564","rc":[{"atb":[[1.28,48.37]],"id":8509691}],"con":true,"img":false}]}
{"op":"mcm","clk":"1362389862","pt":1588447057109,"mc":[{"id":"1.170370564","rc":[{"atb":[[4.2,8.31]],"id":9630572}],"con":true,"img":false}]}
{"op":"mcm","clk":"1362389876","pt":1588447058226,"mc":[{"id":"1.170370564","rc":[{"atl":[[1.3,1114.75]],"id":8509691}],"con":true,"img":false}]}
{"op":"mcm","clk":"1362389880","pt":1588447058430,"mc":[{"id":"1.170370564","rc":[{"trd":[[1.29,21690.03]],"ltp":1.29,"tv":21690.03,"id":8509691},{"atb":[[1.29,0]],"id":8509691},{"atl":[[1.29,0]],"id":8509691}],"con":true,"img":false}]}
{"op":"mcm","clk":"1362389886","pt":1588447058735,"mc":[{"id":"1.170370564","rc":[{"atl":[[1.29,0]],"id":8509691}],"con":true,"img":false}]}
{"op":"mcm","clk":"1362389895","pt":1588447059142,"mc":[{"id":"1.170370564","rc":[{"atl":[[1.3,129.83]],"id":8509691}],"con":true,"img":false}]}
{"op":"mcm","clk":"1362389911","pt":1588447060262,"mc":[{"id":"1.170370564","rc":[{"atb":[[1.27,984.92]],"id":8509691}],"con":true,"img":false}]}
{"op":"mcm","clk":"1362389924","pt":1588447061227,"mc":[{"id":"1.170370564","rc":[{"atb":[[4.2,0]],"id":9630572}],"con":true,"img":false}]}
{"op":"mcm","clk":"1362389957","pt":1588447063464,"mc":[{"id":"1.170370564","rc":[{"atb":[[1.27,0]],"id":8509691}],"con":true,"img":false}]}
{"op":"mcm","clk":"1362389967","pt":1588447064127,"mc":[{"id":"1.170370564","rc":[{"atb":[[4.2,8.31]],"id":9630572}],"con":true,"img":false}]}
{"op":"mcm","clk":"1362389973","pt":1588447064432,"mc":[{"id":"1.170370564","rc":[{"atl":[[1.3,329.83]],"id":8509691}],"con":true,"img":false}]}
{"op":"mcm","clk":"1362390491","pt":1588447119052,"mc":[{"id":"1.170370564","rc":[{"atb":[[1.09,936.01]],"id":8509691}],"con":true,"img":false}]}
{"op":"mcm","clk":"1362390683","pt":1588447137161,"mc":[{"id":"1.170370564","rc":[{"atb":[[1.28,34.98]],"id":8509691}],"con":true,"img":false}]}
{"op":"mcm","clk":"1362390686","pt":1588447137364,"mc":[{"id":"1.170370564","rc":[{"atb":[[1.28,48.37]],"id":8509691}],"con":true,"img":false}]}
{"op":"mcm","clk":"1362390753","pt":1588447145067,"mc":[{"id":"1.170370564","rc":[{"atb":[[1.25,124.11]],"id":8509691}],"con":true,"img":false}]}
{"op":"mcm","clk":"1362390872","pt":1588447162823,"mc":[{"id":"1.170370564","rc":[{"atl":[[1.3,330.03]],"id":8509691}],"con":true,"img":false}]}
{"op":"mcm","clk":"1362391392","pt":1588447220627,"mc":[{"id":"1.170370564","rc":[{"atl":[[1.3,130.03]],"id":8509691}],"con":true,"img":false}]}
{"op":"mcm","clk":"1362391820","pt":1588447260023,"mc":[{"id":"1.170370564","rc":[{"atb":[[1.29,239.96]],"id":8509691}],"con":true,"img":false}]}
{"op":"mcm","clk":"1362391837","pt":1588447261195,"mc":[{"id":"1.170370564","rc":[{"atb":[[1.25,212.76]],"id":8509691}],"con":true,"img":false}]}
{"op":"mcm","clk":"1362391838","pt":1588447261297,"mc":[{"id":"1.170370564","rc":[{"atb":[[4.2,0]],"id":9630572}],"con":true,"img":false}]}
{"op":"mcm","clk":"1362392357","pt":1588447297993,"mc":[{"id":"1.170370564","rc":[{"trd":[[1.3,3287.72]],"ltp":1.3,"tv":3287.72,"id":8509691},{"atl":[[1.3,50.68]],"id":8509691}],"con":true,"img":false}]}
{"op":"mcm","clk":"1362392360","pt":1588447298095,"mc":[{"id":"1.170370564","rc":[{"trd":[[1.3,3319.63]],"ltp":1.3,"tv":3319.63,"id":8509691},{"atl":[[1.3,34.72]],"id":8509691}],"con":true,"img":false}]}
{"op":"mcm","clk":"1362392411","pt":1588447300996,"mc":[{"id":"1.170370564","rc":[{"atl":[[4.4,12.24]],"id":9630572}],"con":true,"img":false}]}
{"op":"mcm","clk":"1362392506","pt":1588447307207,"mc":[{"id":"1.170370564","rc":[{"trd":[[1.29,21694.83]],"ltp":1.29,"tv":21694.83,"id":8509691},{"atb":[[1.29,237.56]],"id":8509691}],"con":true,"img":false}]}
{"op":"mcm","clk":"1362392829","pt":1588447330998,"mc":[{"id":"1.170370564","rc":[{"atb":[[4.3,492.02]],"id":9630572},{"atl":[[4.4,690.43]],"id":9630572}],"con":true,"img":false}]}
{"op":"mcm","clk":"1362392893","pt":1588447335425,"mc":[{"id":"1.170370564","rc":[{"atb":[[4,8.86]],"id":9630572},{"atb":[[1.2,10.3]],"id":8509691}],"con":true,"img":false}]}
{"op":"mcm","clk":"1362393284","pt":1588447366675,"mc":[{"id":"1.170370564","rc":[{"trd":[[1.29,21695.29]],"ltp":1.29,"tv":21695.29,"id":8509691},{"atb":[[1.29,237.33]],"id":8509691}],"con":true,"img":false}]}
{"op":"mcm","clk":"1362393379","pt":1588447373696,"mc":[{"id":"1.170370564","rc":[{"trd":[[1.3,3324.39]],"ltp":1.3,"tv":3324.39,"id":8509691},{"atl":[[1.3,32.35]],"id":8509691}],"con":true,"img":false}]}
{"op":"mcm","clk":"1362393433","pt":1588447377822,"mc":[{"id":"1.170370565","rc":[{"atl":[[5.1,0]],"id":11269557}],"con":true,"img":false}]}
{"op":"mcm","clk":"1362393435","pt":1588447378026,"mc":[{"id":"1.170370565","rc":[{"atl":[[8.4,0]],"id":11340557}],"con":true,"img":false}]}
{"op":"mcm","clk":"1362393440","pt":1588447378178,"mc":[{"id":"1.170370565","rc":[{"atl":[[11,0]],"id":11340560}],"con":true,"img":false}]}
{"op":"mcm","clk":"1362393446","pt":1588447378588,"mc":[{"id":"1.170370565","rc":[{"atl":[[8.6,7.83]],"id":11340557},{"atl":[[11.5,6]],"id":11340560},{"atl":[[1.99,2]],"id":11269555},{"atl":[[5.1,4]],"id":11269557}],"con":true,"img":false}]}
{"op":"mcm","clk":"1362393841","pt":1588447411039,"mc":[{"id":"1.170370564","rc":[{"atb":[[3.8,0]],"id":9630572}],"con":true,"img":false}]}
{"op":"mcm","clk":"1362393867","pt":1588447413073,"mc":[{"id":"1.170370564","rc":[{"atb":[[1.23,188.82]],"id":8509691}],"con":true,"img":false}]}
{"op":"mcm","clk":"1362394643","pt":1588447475171,"mc":[{"id":"1.170370564","rc":[{"trd":[[1.3,3388.38]],"ltp":1.3,"tv":3388.38,"id":8509691},{"atl":[[1.3,0.35]],"id":8509691}],"con":true,"img":false}]}
{"op":"mcm","clk":"1362394646","pt":1588447475373,"mc":[{"id":"1.170370564","rc":[{"trd":[[1.29,21705.29]],"ltp":1.29,"tv":21705.29,"id":8509691},{"atb":[[1.29,232.33]],"id":8509691}],"con":true,"img":false}]}
{"op":"mcm","clk":"1362394673","pt":1588447477970,"mc":[{"id":"1.170370564","rc":[{"trd":[[1.29,21705.98]],"ltp":1.29,"tv":21705.98,"id":8509691},{"atb":[[1.29,231.98]],"id":8509691}],"con":true,"img":false}]}
{"op":"mcm","clk":"1362394731","pt":1588447483565,"mc":[{"id":"1.170370564","rc":[{"trd":[[4.4,220.49]],"ltp":4.4,"tv":220.49,"id":9630572},{"atl":[[4.4,680.99]],"id":9630572}],"con":true,"img":false}]}
{"op":"mcm","clk":"1362394916","pt":1588447499282,"mc":[{"id":"1.170370564","rc":[{"trd":[[1.29,21706.02]],"ltp":1.29,"tv":21706.02,"id":8509691},{"atb":[[1.29,231.96]],"id":8509691}],"con":true,"img":false}]}
{"op":"mcm","clk":"1362395147","pt":1588447516152,"mc":[{"id":"1.170370564","rc":[{"trd":[[1.3,3389.09]],"ltp":1.3,"tv":3389.09,"id":8509691},{"atb":[[1.3,37.67]],"id":8509691},{"atl":[[1.3,0]],"id":8509691}],"con":true,"img":false}]}
{"op":"mcm","clk":"1362395166","pt":1588447517429,"mc":[{"id":"1.170370564","rc":[{"atb":[[1.29,0]],"id":8509691}],"con":true,"img":false}]}
{"op":"mcm","clk":"1362395167","pt":1588447517529,"mc":[{"id":"1.170370564","rc":[{"trd":[[4.3,229.24]],"ltp":4.3,"tv":229.24,"id":9630572},{"atb":[[4.3,421.87]],"id":9630572}],"con":true,"img":false}]}
{"op":"mcm","clk":"1362395214","pt":1588447520542,"mc":[{"id":"1.170370564","rc":[{"trd":[[1.31,485.62]],"ltp":1.31,"tv":485.62,"id":8509691},{"atl":[[1.31,224.31]],"id":8509691}],"con":true,"img":false}]}
{"op":"mcm","clk":"1362395336","pt":1588447530572,"mc":[{"id":"1.170370564","rc":[{"trd":[[1.3,3464.28]],"ltp":1.3,"tv":3464.28,"id":8509691},{"atb":[[1.3,0.08]],"id":8509691}],"con":true,"img":false}]}
{"op":"mcm","clk":"1362395341","pt":1588447530724,"mc":[{"id":"1.170370564","rc":[{"atb":[[1.2,289.1]],"id":8509691}],"con":true,"img":false}]}
{"op":"mcm","clk":"1362395458","pt":1588447539781,"mc":[{"id":"1.170370564","rc":[{"trd":[[4.3,251.95]],"ltp":4.3,"tv":251.95,"id":9630572},{"atb":[[4.3,410.52]],"id":9630572}],"con":true,"img":false}]}
{"op":"mcm","clk":"1362395492","pt":1588447542372,"mc":[{"id":"1.170370564","rc":[{"trd":[[1.31,485.67]],"ltp":1.31,"tv":485.67,"id":8509691},{"atl":[[1.31,224.29]],"id":8509691}],"con":true,"img":false}]}
{"op":"mcm","clk":"1362395692","pt":1588447554084,"mc":[{"id":"1.170370564","rc":[{"atb":[[1.27,89.25]],"id":8509691}],"con":true,"img":false}]}
{"op":"mcm","clk":"1362395784","pt":1588447560084,"mc":[{"id":"1.170370564","rc":[{"trd":[[4.4,220.98]],"ltp":4.4,"tv":220.98,"id":9630572},{"atl":[[4.4,680.49]],"id":9630572},{"trd":[[1.29,21707.72],[1.3,3464.44]],"ltp":1.29,"tv":25172.16,"id":8509691},{"atb":[[1.3,0]],"id":8509691}],"con":true,"img":false}]}
{"op":"mcm","clk":"1362396021","pt":1588447577598,"mc":[{"id":"1.170370564","rc":[{"trd":[[4.4,250.3]],"ltp":4.4,"tv":250.3,"id":9630572},{"atl":[[4.4,651.17]],"id":9630572},{"trd":[[1.29,21807.72]],"ltp":1.29,"tv":21807.72,"id":8509691}],"con":true,"img":false}]}
{"op":"mcm","clk":"1362396175","pt":1588447589922,"mc":[{"id":"1.170370564","rc":[{"atb":[[1.3,9.62]],"id":8509691}],"con":true,"img":false}]}
{"op":"mcm","clk":"1362396190","pt":1588447590953,"mc":[{"id":"1.170370564","rc":[{"atb":[[1.3,0.17]],"id":8509691}],"con":true,"img":false}]}
{"op":"mcm","clk":"1362396507","pt":1588447614051,"mc":[{"id":"1.170370564","rc":[{"atb":[[1.28,13.38]],"id":8509691}],"con":true,"img":false}]}
{"op":"mcm","clk":"1362396664","pt":1588447628065,"mc":[{"id":"1.170370564","rc":[{"atb":[[1.3,0]],"id":8509691}],"con":true,"img":false}]}
{"op":"mcm","clk":"1362396965","pt":1588447651636,"mc":[{"id":"1.170370564","rc":[{"atb":[[1.01,466.57]],"id":9630572}],"con":true,"img":false}]}
{"op":"mcm","clk":"1362396993","pt":1588447653519,"mc":[{"id":"1.170370564","rc":[{"atb":[[1.01,465.24]],"id":9630572}],"con":true,"img":false}]}
{"op":"mcm","clk":"1362396996","pt":1588447653723,"mc":[{"id":"1.170370564","rc":[{"atb":[[1.01,464.79]],"id":9630572}],"con":true,"img":false}]}
{"op":"mcm","clk":"1362396998","pt":1588447653824,"mc":[{"id":"1.170370564","rc":[{"trd":[[4.4,251.19]],"ltp":4.4,"tv":251.19,"id":9630572},{"atl":[[4.4,650.73]],"id":9630572}],"con":true,"img":false}]}
{"op":"mcm","clk":"1362397235","pt":1588447669140,"mc":[{"id":"1.170370564","rc":[{"atl":[[1.35,984.92]],"id":8509691}],"con":true,"img":false}]}
{"op":"mcm","clk":"1362397261","pt":1588447670464,"mc":[{"id":"1.170370564","rc":[{"atl":[[1.35,0]],"id":8509691}],"con":true,"img":false}]}
{"op":"mcm","clk":"1362397295","pt":1588447673266,"mc":[{"id":"1.170370564","rc":[{"atb":[[1.3,177.3]],"id":8509691}],"con":true,"img":false}]}
{"op":"mcm","clk":"1362397330","pt":1588447676064,"mc":[{"id":"1.170370564","rc":[{"atb":[[1.2,10.3]],"id":8509691}],"con":true,"img":false}]}
{"op":"mcm","clk":"1362398204","pt":1588447739876,"mc":[{"id":"1.170370564","rc":[{"atl":[[1.32,984.92]],"id":8509691}],"con":true,"img":false}]}
{"op":"mcm","clk":"1362398214","pt":1588447740790,"mc":[{"id":"1.170370564","rc":[{"atl":[[1.32,0]],"id":8509691}],"con":true,"img":false}]}
{"op":"mcm","clk":"1362399884","pt":1588447799785,"mc":[{"id":"1.170370565","rc":[{"atl":[[1.99,0]],"id":11269555}],"con":true,"img":false}]}
{"op":"mcm","clk":"1362399888","pt":1588447799887,"mc":[{"id":"1.170370565","rc":[{"atl":[[5.1,0]],"id":11269557}],"con":true,"img":false}]}
{"op":"mcm","clk":"1362399891","pt":1588447800090,"mc":[{"id":"1.170370565","rc":[{"atl":[[8.6,1.83]],"id":11340557}],"con":true,"img":false}]}
{"op":"mcm","clk":"1362399895","pt":1588447800294,"mc":[{"id":"1.170370565","rc":[{"atl":[[11.5,0]],"id":11340560}],"con":true,"img":false}]}
{"op":"mcm","clk":"1362399898","pt":1588447800498,"mc":[{"id":"1.170370564","rc":[{"atb":[[4,0],[4.1,0]],"id":9630572},{"atb":[[1.23,100.17],[1.25,124.11],[1.24,0]],"id":8509691}],"con":true,"img":false}]}
{"op":"mcm","clk":"1362399901","pt":1588447800702,"mc":[{"id":"1.170370565","rc":[{"atl":[[8.4,6]],"id":11340557},{"atl":[[11,6]],"id":11340560},{"atl":[[1.99,2]],"id":11269555},{"atl":[[5,10]],"id":11269557}],"con":true,"img":false}]}
{"op":"mcm","clk":"1362400079","pt":1588447814122,"mc":[{"id":"1.170370564","rc":[{"atl":[[1.44,10.6]],"id":8509691}],"con":true,"img":false}]}
{"op":"mcm","clk":"1362400146","pt":1588447818705,"mc":[{"id":"1.170370564","rc":[{"atl":[[1.44,0]],"id":8509691}],"con":true,"img":false}]}
{"op":"mcm","clk":"1362400203","pt":1588447821409,"mc":[{"id":"1.170370564","rc":[{"trd":[[1.3,3467.72]],"ltp":1.3,"tv":3467.72,"id":8509691},{"atb":[[1.3,175.66]],"id":8509691}],"con":true,"img":false}]}
{"op":"mcm","clk":"1362400223","pt":1588447822836,"mc":[{"id":"1.170370564","rc":[{"atl":[[1.31,0]],"id":8509691}],"con":true,"img":false}]}
{"op":"mcm","clk":"1362400225","pt":1588447822938,"mc":[{"id":"1.170370564","rc":[{"trd":[[1.3,3819.05]],"ltp":1.3,"tv":3819.05,"id":8509691},{"atb":[[1.3,0]],"id":8509691},{"atl":[[1.3,48.62]],"id":8509691}],"con":true,"img":false}]}
{"op":"mcm","clk":"1362400286","pt":1588447826255,"mc":[{"id":"1.170370564","rc":[{"atb":[[1.2,289.1]],"id":8509691}],"con":true,"img":false}]}
{"op":"mcm","clk":"1362400302","pt":1588447827427,"mc":[{"id":"1.170370564","rc":[{"atl":[[1.3,0]],"id":8509691}],"con":true,"img":false}]}
{"op":"mcm","clk":"1362400306","pt":1588447827532,"mc":[{"id":"1.170370564","rc":[{"atl":[[1.31,48.62]],"id":8509691}],"con":true,"img":false}]}
{"op":"mcm","clk":"1362400313","pt":1588447827835,"mc":[{"id":"1.170370564","rc":[{"atb":[[1.3,3.21]],"id":8509691}],"con":true,"img":false}]}
{"op":"mcm","clk":"1362400355","pt":1588447830333,"mc":[{"id":"1.170370564","rc":[{"atl":[[1.44,10.6]],"id":8509691}],"con":true,"img":false}]}
{"op":"mcm","clk":"1362400697","pt":1588447857575,"mc":[{"id":"1.170370564","rc":[{"trd":[[1.3,3822.98]],"ltp":1.3,"tv":3822.98,"id":8509691},{"atb":[[1.3,1.24]],"id":8509691}],"con":true,"img":false}]}
{"op":"mcm","clk":"1362400718","pt":1588447859505,"mc":[{"id":"1.170370564","rc":[{"trd":[[1.3,3825.48]],"ltp":1.3,"tv":3825.48,"id":8509691},{"atb":[[1.3,0]],"id":8509691},{"atl":[[1.3,98.75]],"id":8509691}],"con":true,"img":false}]}
{"op":"mcm","clk":"1362400782","pt":1588447864369,"mc":[{"id":"1.170370564","rc":[{"atl":[[1.44,0]],"id":8509691}],"con":true,"img":false}]}
{"op":"mcm","clk":"1362401257","pt":1588447904470,"mc":[{"id":"1.170370564","rc":[{"atl":[[1.48,3]],"id":8509691}],"con":true,"img":false}]}
{"op":"mcm","clk":"1362401288","pt":1588447907272,"mc":[{"id":"1.170370564","rc":[{"atb":[[1.25,0]],"id":8509691}],"con":true,"img":false}]}
{"op":"mcm","clk":"1362401571","pt":1588447932518,"mc":[{"id":"1.170370564","rc":[{"trd":[[4.4,251.34]],"ltp":4.4,"tv":251.34,"id":9630572},{"atl":[[4.4,650.58]],"id":9630572},{"trd":[[1.29,21808.24]],"ltp":1.29,"tv":21808.24,"id":8509691}],"con":true,"img":false}]}
{"op":"mcm","clk":"1362402012","pt":1588447968691,"mc":[{"id":"1.170370564","rc":[{"atl":[[1.34,984.92]],"id":8509691}],"con":true,"img":false}]}
{"op":"mcm","clk":"1362402028","pt":1588447969914,"mc":[{"id":"1.170370564","rc":[{"atl":[[1.34,0]],"id":8509691}],"con":true,"img":false}]}
{"op":"mcm","clk":"1362402042","pt":1588447970883,"mc":[{"id":"1.170370564","rc":[{"trd":[[1.3,3829.48]],"ltp":1.3,"tv":3829.48,"id":8509691},{"atl":[[1.3,96.75]],"id":8509691}],"con":true,"img":false}]}
{"op":"mcm","clk":"1362402347","pt":1588447996023,"mc":[{"id":"1.170370564","rc":[{"atb":[[1.29,7.28]],"id":8509691}],"con":true,"img":false}]}
{"op":"mcm","clk":"1362402738","pt":1588448027705,"mc":[{"id":"1.170370564","rc":[{"atb":[[1.09,936.29]],"id":8509691}],"con":true,"img":false}]}
{"op":"mcm","clk":"1362403191","pt":1588448063281,"mc":[{"id":"1.170370564","rc":[{"atl":[[1.38,984.92]],"id":8509691}],"con":true,"img":false}]}
{"op":"mcm","clk":"1362403204","pt":1588448064354,"mc":[{"id":"1.170370564","rc":[{"atl":[[1.38,0]],"id":8509691}],"con":true,"img":false}]}
{"op":"mcm","clk":"1362403443","pt":1588448083162,"mc":[{"id":"1.170370564","rc":[{"trd":[[4.4,252.21]],"ltp":4.4,"tv":252.21,"id":9630572},{"atl":[[4.4,649.71]],"id":9630572},{"trd":[[1.29,21825.79]],"ltp":1.29,"tv":21825.79,"id":8509691},{"atb":[[1.29,0]],"id":8509691}],"con":true,"img":false}]}
{"op":"mcm","clk":"1362403631","pt":1588448098128,"mc":[{"id":"1.170370564","rc":[{"trd":[[4.4,265.03]],"ltp":4.4,"tv":265.03,"id":9630572},{"atl":[[4.4,636.89]],"id":9630572},{"trd":[[1.29,21869.52]],"ltp":1.29,"tv":21869.52,"id":8509691}],"con":true,"img":false}]}
{"op":"mcm","clk":"1362403955","pt":1588448124246,"mc":[{"id":"1.170370564","rc":[{"atl":[[1.37,984.92]],"id":8509691}],"con":true,"img":false}]}
{"op":"mcm","clk":"1362403978","pt":1588448125266,"mc":[{"id":"1.170370564","rc":[{"atl":[[1.37,0]],"id":8509691}],"con":true,"img":false}]}
{"op":"mcm","clk":"1362404562","pt":1588448154928,"mc":[{"id":"1.170370564","rc":[{"atl":[[1.32,984.92]],"id":8509691}],"con":true,"img":false}]}
{"op":"mcm","clk":"1362404595","pt":1588448155998,"mc":[{"id":"1.170370564","rc":[{"atl":[[1.32,0]],"id":8509691}],"con":true,"img":false}]}
{"op":"mcm","clk":"1362404608","pt":1588448156507,"mc":[{"id":"1.170370564","rc":[{"trd":[[4.3,257.27]],"ltp":4.3,"tv":257.27,"id":9630572},{"atb":[[4.3,407.86]],"id":9630572}],"con":true,"img":false}]}
{"op":"mcm","clk":"1362404816","pt":1588448169634,"mc":[{"id":"1.170370564","rc":[{"atl":[[1.8,799.87]],"id":8509691}],"con":true,"img":false}]}
{"op":"mcm","clk":"1362404900","pt":1588448175958,"mc":[{"id":"1.170370564","rc":[{"trd":[[4.4,270.94]],"ltp":4.4,"tv":270.94,"id":9630572},{"atl":[[4.4,630.98]],"id":9630572},{"trd":[[1.29,21889.7]],"ltp":1.29,"tv":21889.7,"id":8509691}],"con":true,"img":false}]}
{"op":"mcm","clk":"1362404944","pt":1588448179063,"mc":[{"id":"1.170370565","marketDefinition":{"bspMarket":false,"turnInPlayEnabled":true,"persistenceEnabled":true,"marketBaseRate":5.0,"eventId":"29788457","eventTypeId":"2","numberOfWinners":1,"bettingType":"ODDS","marketType":"SET_BETTING","marketTime":"2020-05-02T19:36:16.000Z","suspendTime":"2020-05-02T19:36:16.000Z","bspReconciled":false,"complete":true,"inPlay":false,"crossMatching":true,"runnersVoidable":false,"numberOfActiveRunners":4,"betDelay":0,"status":"OPEN","runners":[{"status":"ACTIVE","sortPriority":1,"id":11269555,"name":"P Lorenzi 2-0"},{"status":"ACTIVE","sortPriority":2,"id":11269557,"name":"P Lorenzi 2-1"},{"status":"ACTIVE","sortPriority":3,"id":11340557,"name":"S Kirchheimer 2-0"},{"status":"ACTIVE","sortPriority":4,"id":11340560,"name":"S Kirchheimer 2-1"}],"regulators":["MR_INT"],"countryCode":"GB","discountAllowed":true,"timezone":"GMT","openDate":"2020-05-02T19:00:00.000Z","version":3237642674,"name":"Set Betting","eventName":"P Lorenzi v S Kirchheimer"},"rc":[],"con":true,"img":false}]}
{"op":"mcm","clk":"1362404945","pt":1588448179063,"mc":[{"id":"1.170370567","marketDefinition":{"bspMarket":false,"turnInPlayEnabled":true,"persistenceEnabled":true,"marketBaseRate":5.0,"eventId":"29788457","eventTypeId":"2","numberOfWinners":1,"bettingType":"ODDS","marketType":"SET_WINNER","marketTime":"2020-05-02T19:36:16.000Z","suspendTime":"2020-05-02T19:36:16.000Z","bspReconciled":false,"complete":true,"inPlay":false,"crossMatching":true,"runnersVoidable":false,"numberOfActiveRunners":2,"betDelay":0,"status":"OPEN","runners":[{"status":"ACTIVE","sortPriority":1,"id":8509691,"name":"P Lorenzi"},{"status":"ACTIVE","sortPriority":2,"id":9630572,"name":"S Kirchheimer"}],"regulators":["MR_INT"],"countryCode":"GB","discountAllowed":true,"timezone":"GMT","openDate":"2020-05-02T19:00:00.000Z","version":3237642678,"name":"Set 2 Winner","eventName":"P Lorenzi v S Kirchheimer"},"rc":[],"con":true,"img":false}]}
{"op":"mcm","clk":"1362404946","pt":1588448179063,"mc":[{"id":"1.170370566","marketDefinition":{"bspMarket":false,"turnInPlayEnabled":true,"persistenceEnabled":true,"marketBaseRate":5.0,"eventId":"29788457","eventTypeId":"2","numberOfWinners":1,"bettingType":"ODDS","marketType":"SET_WINNER","marketTime":"2020-05-02T19:36:16.000Z","suspendTime":"2020-05-02T19:36:16.000Z","bspReconciled":false,"complete":true,"inPlay":false,"crossMatching":true,"runnersVoidable":false,"numberOfActiveRunners":2,"betDelay":0,"status":"OPEN","runners":[{"status":"ACTIVE","sortPriority":1,"id":8509691,"name":"P Lorenzi"},{"status":"ACTIVE","sortPriority":2,"id":9630572,"name":"S Kirchheimer"}],"regulators":["MR_INT"],"countryCode":"GB","discountAllowed":true,"timezone":"GMT","openDate":"2020-05-02T19:00:00.000Z","version":3237642676,"name":"Set 1 Winner","eventName":"P Lorenzi v S Kirchheimer"},"rc":[],"con":true,"img":false}]}
{"op":"mcm","clk":"1362404947","pt":1588448179064,"mc":[{"id":"1.170370564","marketDefinition":{"bspMarket":false,"turnInPlayEnabled":true,"persistenceEnabled":true,"marketBaseRate":5.0,"eventId":"29788457","eventTypeId":"2","numberOfWinners":1,"bettingType":"ODDS","marketType":"MATCH_ODDS","marketTime":"2020-05-02T19:36:16.000Z","suspendTime":"2020-05-02T19:36:16.000Z","bspReconciled":false,"complete":true,"inPlay":false,"crossMatching":true,"runnersVoidable":false,"numberOfActiveRunners":2,"betDelay":0,"status":"OPEN","runners":[{"status":"ACTIVE","sortPriority":1,"id":8509691,"name":"P Lorenzi"},{"status":"ACTIVE","sortPriority":2,"id":9630572,"name":"S Kirchheimer"}],"regulators":["MR_INT"],"countryCode":"GB","discountAllowed":true,"timezone":"GMT","openDate":"2020-05-02T19:00:00.000Z","version":3237642672,"name":"Match Odds","eventName":"P Lorenzi v S Kirchheimer"},"rc":[],"con":true,"img":false}]}
{"op":"mcm","clk":"1362404953","pt":1588448179423,"mc":[{"id":"1.170370565","rc":[{"atb":[[7.4,10]],"id":11340560}],"con":true,"img":false}]}
{"op":"mcm","clk":"1362404956","pt":1588448179528,"mc":[{"id":"1.170370565","rc":[{"atb":[[8,0]],"id":11340557},{"atb":[[7,0]],"id":11340560}],"con":true,"img":false}]}
{"op":"mcm","clk":"1362404980","pt":1588448181064,"mc":[{"id":"1.170370567","marketDefinition":{"bspMarket":false,"turnInPlayEnabled":true,"persistenceEnabled":true,"marketBaseRate":5.0,"eventId":"29788457","eventTypeId":"2","numberOfWinners":1,"bettingType":"ODDS","marketType":"SET_WINNER","marketTime":"2020-05-02T19:36:16.000Z","suspendTime":"2020-05-02T19:36:16.000Z","bspReconciled":false,"complete":true,"inPlay":false,"crossMatching":true,"runnersVoidable":false,"numberOfActiveRunners":2,"betDelay":0,"status":"OPEN","runners":[{"status":"ACTIVE","sortPriority":1,"id":8509691,"name":"P Lorenzi"},{"status":"ACTIVE","sortPriority":2,"id":9630572,"name":"S Kirchheimer"}],"regulators":["MR_INT"],"countryCode":"GB","discountAllowed":true,"timezone":"GMT","openDate":"2020-05-02T19:36:16.000Z","version":3237642678,"name":"Set 2 Winner","eventName":"P Lorenzi v S Kirchheimer"},"rc":[],"con":true,"img":false}]}
{"op":"mcm","clk":"1362404981","pt":1588448181065,"mc":[{"id":"1.170370566","marketDefinition":{"bspMarket":false,"turnInPlayEnabled":true,"persistenceEnabled":true,"marketBaseRate":5.0,"eventId":"29788457","eventTypeId":"2","numberOfWinners":1,"bettingType":"ODDS","marketType":"SET_WINNER","marketTime":"2020-05-02T19:36:16.000Z","suspendTime":"2020-05-02T19:36:16.000Z","bspReconciled":false,"complete":true,"inPlay":false,"crossMatching":true,"runnersVoidable":false,"numberOfActiveRunners":2,"betDelay":0,"status":"OPEN","runners":[{"status":"ACTIVE","sortPriority":1,"id":8509691,"name":"P Lorenzi"},{"status":"ACTIVE","sortPriority":2,"id":9630572,"name":"S Kirchheimer"}],"regulators":["MR_INT"],"countryCode":"GB","discountAllowed":true,"timezone":"GMT","openDate":"2020-05-02T19:36:16.000Z","version":3237642676,"name":"Set 1 Winner","eventName":"P Lorenzi v S Kirchheimer"},"rc":[],"con":true,"img":false}]}
{"op":"mcm","clk":"1362404982","pt":1588448181065,"mc":[{"id":"1.170370565","marketDefinition":{"bspMarket":false,"turnInPlayEnabled":true,"persistenceEnabled":true,"marketBaseRate":5.0,"eventId":"29788457","eventTypeId":"2","numberOfWinners":1,"bettingType":"ODDS","marketType":"SET_BETTING","marketTime":"2020-05-02T19:36:16.000Z","suspendTime":"2020-05-02T19:36:16.000Z","bspReconciled":false,"complete":true,"inPlay":false,"crossMatching":true,"runnersVoidable":false,"numberOfActiveRunners":4,"betDelay":0,"status":"OPEN","runners":[{"status":"ACTIVE","sortPriority":1,"id":11269555,"name":"P Lorenzi 2-0"},{"status":"ACTIVE","sortPriority":2,"id":11269557,"name":"P Lorenzi 2-1"},{"status":"ACTIVE","sortPriority":3,"id":11340557,"name":"S Kirchheimer 2-0"},{"status":"ACTIVE","sortPriority":4,"id":11340560,"name":"S Kirchheimer 2-1"}],"regulators":["MR_INT"],"countryCode":"GB","discountAllowed":true,"timezone":"GMT","openDate":"2020-05-02T19:36:16.000Z","version":3237642674,"name":"Set Betting","eventName":"P Lorenzi v S Kirchheimer"},"rc":[],"con":true,"img":false}]}
{"op":"mcm","clk":"1362404983","pt":1588448181065,"mc":[{"id":"1.170370564","marketDefinition":{"bspMarket":false,"turnInPlayEnabled":true,"persistenceEnabled":true,"marketBaseRate":5.0,"eventId":"29788457","eventTypeId":"2","numberOfWinners":1,"bettingType":"ODDS","marketType":"MATCH_ODDS","marketTime":"2020-05-02T19:36:16.000Z","suspendTime":"2020-05-02T19:36:16.000Z","bspReconciled":false,"complete":true,"inPlay":false,"crossMatching":true,"runnersVoidable":false,"numberOfActiveRunners":2,"betDelay":0,"status":"OPEN","runners":[{"status":"ACTIVE","sortPriority":1,"id":8509691,"name":"P Lorenzi"},{"status":"ACTIVE","sortPriority":2,"id":9630572,"name":"S Kirchheimer"}],"regulators":["MR_INT"],"countryCode":"GB","discountAllowed":true,"timezone":"GMT","openDate":"2020-05-02T19:36:16.000Z","version":3237642672,"name":"Match Odds","eventName":"P Lorenzi v S Kirchheimer"},"rc":[],"con":true,"img":false}]}
{"op":"mcm","clk":"1362405072","pt":1588448187282,"mc":[{"id":"1.170370564","rc":[{"atb":[[1.2,10.3],[1.22,255.46]],"id":8509691}],"con":true,"img":false}]}
{"op":"mcm","clk":"1362405105","pt":1588448189471,"mc":[{"id":"1.170370565","rc":[{"atb":[[7,14]],"id":11340557},{"atb":[[1.83,63.01]],"id":11269555},{"atb":[[3.1,24.9]],"id":11269557}],"con":true,"img":false},{"id":"1.170370566","rc":[{"atb":[[2.62,32.28]],"id":9630572},{"atb":[[1.44,118.86]],"id":8509691}],"con":true,"img":false},{"id":"1.170370567","rc":[{"atb":[[3.2,0],[3,26.15]],"id":9630572},{"atb":[[1.3,0],[1.33,158.48]],"id":8509691}],"con":true,"img":false}]}
{"op":"mcm","clk":"1362405109","pt":1588448189573,"mc":[{"id":"1.170370565","rc":[{"atb":[[1.73,9]],"id":11269555},{"atb":[[3.4,0]],"id":11269557}],"con":true,"img":false},{"id":"1.170370566","rc":[{"atb":[[3,0]],"id":9630572},{"atb":[[1.33,0]],"id":8509691}],"con":true,"img":false}]}
{"op":"mcm","clk":"1362405206","pt":1588448197086,"mc":[{"id":"1.170370566","marketDefinition":{"bspMarket":false,"turnInPlayEnabled":true,"persistenceEnabled":true,"marketBaseRate":5.0,"eventId":"29788457","eventTypeId":"2","numberOfWinners":1,"bettingType":"ODDS","marketType":"SET_WINNER","marketTime":"2020-05-02T19:36:16.000Z","suspendTime":"2020-05-02T19:36:16.000Z","bspReconciled":false,"complete":true,"inPlay":true,"crossMatching":true,"runnersVoidable":false,"numberOfActiveRunners":2,"betDelay":5,"status":"SUSPENDED","runners":[{"status":"ACTIVE","sortPriority":1,"id":8509691,"name":"P Lorenzi"},{"status":"ACTIVE","sortPriority":2,"id":9630572,"name":"S Kirchheimer"}],"regulators":["MR_INT"],"countryCode":"GB","discountAllowed":true,"timezone":"GMT","openDate":"2020-05-02T19:36:16.000Z","version":3237642706,"name":"Set 1 Winner","eventName":"P Lorenzi v S Kirchheimer"},"rc":[],"con":true,"img":false}]}
{"op":"mcm","clk":"1362405207","pt":1588448197086,"mc":[{"id":"1.170370565","marketDefinition":{"bspMarket":false,"turnInPlayEnabled":true,"persistenceEnabled":true,"marketBaseRate":5.0,"eventId":"29788457","eventTypeId":"2","numberOfWinners":1,"bettingType":"ODDS","marketType":"SET_BETTING","marketTime":"2020-05-02T19:36:16.000Z","suspendTime":"2020-05-02T19:36:16.000Z","bspReconciled":false,"complete":true,"inPlay":false,"crossMatching":true,"runnersVoidable":false,"numberOfActiveRunners":4,"betDelay":0,"status":"SUSPENDED","runners":[{"status":"ACTIVE","sortPriority":1,"id":11269555,"name":"P Lorenzi 2-0"},{"status":"ACTIVE","sortPriority":2,"id":11269557,"name":"P Lorenzi 2-1"},{"status":"ACTIVE","sortPriority":3,"id":11340557,"name":"S Kirchheimer 2-0"},{"status":"ACTIVE","sortPriority":4,"id":11340560,"name":"S Kirchheimer 2-1"}],"regulators":["MR_INT"],"countryCode":"GB","discountAllowed":true,"timezone":"GMT","openDate":"2020-05-02T19:36:16.000Z","version":3237642704,"name":"Set Betting","eventName":"P Lorenzi v S Kirchheimer"},"rc":[],"con":true,"img":false}]}
{"op":"mcm","clk":"1362405208","pt":1588448197087,"mc":[{"id":"1.170370567","marketDefinition":{"bspMarket":false,"turnInPlayEnabled":true,"persistenceEnabled":true,"marketBaseRate":5.0,"eventId":"29788457","eventTypeId":"2","numberOfWinners":1,"bettingType":"ODDS","marketType":"SET_WINNER","marketTime":"2020-05-02T19:36:16.000Z","suspendTime":"2020-05-02T19:36:16.000Z","bspReconciled":false,"complete":true,"inPlay":false,"crossMatching":true,"runnersVoidable":false,"numberOfActiveRunners":2,"betDelay":0,"status":"SUSPENDED","runners":[{"status":"ACTIVE","sortPriority":1,"id":8509691,"name":"P Lorenzi"},{"status":"ACTIVE","sortPriority":2,"id":9630572,"name":"S Kirchheimer"}],"regulators":["MR_INT"],"countryCode":"GB","discountAllowed":true,"timezone":"GMT","openDate":"2020-05-02T19:36:16.000Z","version":3237642700,"name":"Set 2 Winner","eventName":"P Lorenzi v S Kirchheimer"},"rc":[],"con":true,"img":false}]}
{"op":"mcm","clk":"1362405209","pt":1588448197087,"mc":[{"id":"1.170370564","marketDefinition":{"bspMarket":false,"turnInPlayEnabled":true,"persistenceEnabled":true,"marketBaseRate":5.0,"eventId":"29788457","eventTypeId":"2","numberOfWinners":1,"bettingType":"ODDS","marketType":"MATCH_ODDS","marketTime":"2020-05-02T19:36:16.000Z","suspendTime":"2020-05-02T19:36:16.000Z","bspReconciled":false,"complete":true,"inPlay":true,"crossMatching":true,"runnersVoidable":false,"numberOfActiveRunners":2,"betDelay":5,"status":"SUSPENDED","runners":[{"status":"ACTIVE","sortPriority":1,"id":8509691,"name":"P Lorenzi"},{"status":"ACTIVE","sortPriority":2,"id":9630572,"name":"S Kirchheimer"}],"regulators":["MR_INT"],"countryCode":"GB","discountAllowed":true,"timezone":"GMT","openDate":"2020-05-02T19:36:16.000Z","version":3237642702,"name":"Match Odds","eventName":"P Lorenzi v S Kirchheimer"},"rc":[],"con":true,"img":false}]}
{"op":"mcm","clk":"1362405211","pt":1588448197176,"mc":[{"id":"1.170370564","marketDefinition":{"bspMarket":false,"turnInPlayEnabled":true,"persistenceEnabled":true,"marketBaseRate":5.0,"eventId":"29788457","eventTypeId":"2","numberOfWinners":1,"bettingType":"ODDS","marketType":"MATCH_ODDS","marketTime":"2020-05-02T19:36:16.000Z","suspendTime":"2020-05-02T19:36:16.000Z","bspReconciled":false,"complete":true,"inPlay":true,"crossMatching":true,"runnersVoidable":false,"numberOfActiveRunners":2,"betDelay":5,"status":"OPEN","runners":[{"status":"ACTIVE","sortPriority":1,"id":8509691,"name":"P Lorenzi"},{"status":"ACTIVE","sortPriority":2,"id":9630572,"name":"S Kirchheimer"}],"regulators":["MR_INT"],"countryCode":"GB","discountAllowed":true,"timezone":"GMT","openDate":"2020-05-02T19:36:16.000Z","version":3237642708,"name":"Match Odds","eventName":"P Lorenzi v S Kirchheimer"},"rc":[],"con":true,"img":false},{"id":"1.170370564","rc":[{"atb":[[4.3,0],[3.95,0],[1.02,0.21]],"id":9630572},{"atl":[[4.8,0],[7.2,0],[4.5,0],[5.1,0],[7.6,0],[4.4,0],[990,0]],"id":9630572},{"atb":[[1.01,1843.34],[1.03,3],[1.09,936.01],[1.1,0],[1.08,1002.65],[1.27,0],[1.02,1378.75],[1.06,156.91],[1.22,2],[1.05,0],[1.04,0]],"id":8509691},{"atl":[[3,0],[1.33,0],[990,0],[1.8,0],[1.81,0],[1.9,0],[1.3,0]],"id":8509691}],"con":true,"img":false},{"id":"1.170370565","marketDefinition":{"bspMarket":false,"turnInPlayEnabled":true,"persistenceEnabled":true,"marketBaseRate":5.0,"eventId":"29788457","eventTypeId":"2","numberOfWinners":1,"bettingType":"ODDS","marketType":"SET_BETTING","marketTime":"2020-05-02T19:36:16.000Z","suspendTime":"2020-05-02T19:36:16.000Z","bspReconciled":false,"complete":true,"inPlay":true,"crossMatching":true,"runnersVoidable":false,"numberOfActiveRunners":4,"betDelay":5,"status":"OPEN","runners":[{"status":"ACTIVE","sortPriority":1,"id":11269555,"name":"P Lorenzi 2-0"},{"status":"ACTIVE","sortPriority":2,"id":11269557,"name":"P Lorenzi 2-1"},{"status":"ACTIVE","sortPriority":3,"id":11340557,"name":"S Kirchheimer 2-0"},{"status":"ACTIVE","sortPriority":4,"id":11340560,"name":"S Kirchheimer 2-1"}],"regulators":["MR_INT"],"countryCode":"GB","discountAllowed":true,"timezone":"GMT","openDate":"2020-05-02T19:36:16.000Z","version":3237642718,"name":"Set Betting","eventName":"P Lorenzi v S Kirchheimer"},"rc":[],"con":true,"img":false},{"id":"1.170370565","rc":[{"atb":[[1.02,0],[1.1,0],[7,0]],"id":11340557},{"atl":[[8.6,0],[8.4,0]],"id":11340557},{"atb":[[8,0],[8.2,0],[7.4,0],[1.02,0],[1.1,0]],"id":11340560},{"atl":[[11,0]],"id":11340560},{"atb":[[1.73,0],[1.83,0],[1.02,0],[1.1,0]],"id":11269555},{"atl":[[2,0],[1.99,0]],"id":11269555},{"atb":[[3.45,0],[3.1,0],[1.02,0],[1.1,0]],"id":11269557},{"atl":[[5,0]],"id":11269557}],"con":true,"img":false},{"id":"1.170370566","marketDefinition":{"bspMarket":false,"turnInPlayEnabled":true,"persistenceEnabled":true,"marketBaseRate":5.0,"eventId":"29788457","eventTypeId":"2","numberOfWinners":1,"bettingType":"ODDS","marketType":"SET_WINNER","marketTime":"2020-05-02T19:36:16.000Z","suspendTime":"2020-05-02T19:36:16.000Z","bspReconciled":false,"complete":true,"inPlay":true,"crossMatching":true,"runnersVoidable":false,"numberOfActiveRunners":2,"betDelay":5,"status":"OPEN","runners":[{"status":"ACTIVE","sortPriority":1,"id":8509691,"name":"P Lorenzi"},{"status":"ACTIVE","sortPriority":2,"id":9630572,"name":"S Kirchheimer"}],"regulators":["MR_INT"],"countryCode":"GB","discountAllowed":true,"timezone":"GMT","openDate":"2020-05-02T19:36:16.000Z","version":3237642710,"name":"Set 1 Winner","eventName":"P Lorenzi v S Kirchheimer"},"rc":[],"con":true,"img":false},{"id":"1.170370566","rc":[{"atb":[[3.15,0],[1.1,0],[2.62,0],[2.16,0]],"id":9630572},{"atl":[[6.6,0]],"id":9630572},{"atb":[[1.44,0],[1.14,0],[1.1,0]],"id":8509691},{"atl":[[2.3,0]],"id":8509691}],"con":true,"img":false},{"id":"1.170370567","marketDefinition":{"bspMarket":false,"turnInPlayEnabled":true,"persistenceEnabled":true,"marketBaseRate":5.0,"eventId":"29788457","eventTypeId":"2","numberOfWinners":1,"bettingType":"ODDS","marketType":"SET_WINNER","marketTime":"2020-05-02T19:36:16.000Z","suspendTime":"2020-05-02T19:36:16.000Z","bspReconciled":false,"complete":true,"inPlay":true,"crossMatching":true,"runnersVoidable":false,"numberOfActiveRunners":2,"betDelay":5,"status":"OPEN","runners":[{"status":"ACTIVE","sortPriority":1,"id":8509691,"name":"P Lorenzi"},{"status":"ACTIVE","sortPriority":2,"id":9630572,"name":"S Kirchheimer"}],"regulators":["MR_INT"],"countryCode":"GB","discountAllowed":true,"timezone":"GMT","openDate":"2020-05-02T19:36:16.000Z","version":3237642714,"name":"Set 2 Winner","eventName":"P Lorenzi v S Kirchheimer"},"rc":[],"con":true,"img":false},{"id":"1.170370567","rc":[{"atb":[[3,0],[1.1,0]],"id":9630572},{"atb":[[1.33,0],[1.1,0]],"id":8509691}],"con":true,"img":false}]}
{"op":"mcm","clk":"1362405305","pt":1588448205385,"mc":[{"id":"1.170370564","rc":[{"trd":[[1.31,489.21]],"ltp":1.31,"tv":489.21,"id":8509691},{"atl":[[1.31,46.85]],"id":8509691}],"con":true,"img":false}]}
{"op":"mcm","clk":"1362405388","pt":1588448211904,"mc":[{"id":"1.170370564","rc":[{"trd":[[1.31,582.92]],"ltp":1.31,"tv":582.92,"id":8509691},{"atb":[[1.31,19.63]],"id":8509691},{"atl":[[1.31,0]],"id":8509691}],"con":true,"img":false}]}
{"op":"mcm","clk":"1362405422","pt":1588448214505,"mc":[{"id":"1.170370564","rc":[{"atb":[[1.32,66.48]],"id":8509691}],"con":true,"img":false}]}
{"op":"mcm","clk":"1362405425","pt":1588448214710,"mc":[{"id":"1.170370564","rc":[{"atb":[[1.29,87.87]],"id":8509691}],"con":true,"img":false}]}
{"op":"mcm","clk":"1362405457","pt":1588448217306,"mc":[{"id":"1.170370564","rc":[{"atb":[[1.31,1004.56]],"id":8509691}],"con":true,"img":false}]}
{"op":"mcm","clk":"1362405471","pt":1588448218374,"mc":[{"id":"1.170370564","rc":[{"atb":[[1.31,19.63]],"id":8509691}],"con":true,"img":false}]}
{"op":"mcm","clk":"1362405475","pt":1588448218679,"mc":[{"id":"1.170370564","rc":[{"atb":[[1.25,799.87]],"id":9630572}],"con":true,"img":false}]}
{"op":"mcm","clk":"1362405493","pt":1588448219801,"mc":[{"id":"1.170370564","rc":[{"atl":[[1.44,66.48]],"id":8509691}],"con":true,"img":false}]}
{"op":"mcm","clk":"1362405522","pt":1588448222320,"mc":[{"id":"1.170370564","rc":[{"atl":[[1.45,15]],"id":8509691}],"con":true,"img":false}]}
{"op":"mcm","clk":"1362405541","pt":1588448223616,"mc":[{"id":"1.170370564","rc":[{"atl":[[1.45,0]],"id":8509691}],"con":true,"img":false}]}
{"op":"mcm","clk":"1362405574","pt":1588448226114,"mc":[{"id":"1.170370564","rc":[{"atl":[[1.44,68.48]],"id":8509691}],"con":true,"img":false}]}
{"op":"mcm","clk":"1362405594","pt":1588448227795,"mc":[{"id":"1.170370564","rc":[{"atb":[[1.31,22.07]],"id":8509691}],"con":true,"img":false}]}
{"op":"mcm","clk":"1362405651","pt":1588448231921,"mc":[{"id":"1.170370564","rc":[{"atl":[[4.4,2.44]],"id":9630572}],"con":true,"img":false}]}
{"op":"mcm","clk":"1362405654","pt":1588448232129,"mc":[{"id":"1.170370564","rc":[{"atb":[[1.29,0]],"id":8509691}],"con":true,"img":false}]}
{"op":"mcm","clk":"1362405700","pt":1588448238645,"mc":[{"id":"1.170370566","rc":[{"atb":[[1.2,523.11]],"id":9630572}],"con":true,"img":false}]}
{"op":"mcm","clk":"1362405737","pt":1588448243236,"mc":[{"id":"1.170370567","rc":[{"atb":[[1.2,523.11]],"id":9630572}],"con":true,"img":false}]}
{"op":"mcm","clk":"1362405744","pt":1588448244049,"mc":[{"id":"1.170370564","rc":[{"atl":[[1.43,3.99]],"id":8509691}],"con":true,"img":false}]}
{"op":"mcm","clk":"1362405754","pt":1588448245120,"mc":[{"id":"1.170370564","rc":[{"atl":[[1.4,7.28]],"id":8509691}],"con":true,"img":false}]}
{"op":"mcm","clk":"1362405774","pt":1588448247469,"mc":[{"id":"1.170370564","rc":[{"atb":[[1.32,0]],"id":8509691}],"con":true,"img":false}]}
{"op":"mcm","clk":"1362405780","pt":1588448247928,"mc":[{"id":"1.170370564","rc":[{"atb":[[1.31,2.44]],"id":8509691}],"con":true,"img":false}]}
{"op":"mcm","clk":"1362405825","pt":1588448253279,"mc":[{"id":"1.170370564","rc":[{"atl":[[1.39,10.6]],"id":8509691}],"con":true,"img":false}]}
{"op":"mcm","clk":"1362405828","pt":1588448253535,"mc":[{"id":"1.170370564","rc":[{"atl":[[1.37,66.48]],"id":8509691}],"con":true,"img":false}]}
{"op":"mcm","clk":"1362405857","pt":1588448256451,"mc":[{"id":"1.170370564","rc":[{"atl":[[1.44,66.48]],"id":8509691}],"con":true,"img":false}]}
{"op":"mcm","clk":"1362405906","pt":1588448261239,"mc":[{"id":"1.170370564","rc":[{"atl":[[1.43,0]],"id":8509691}],"con":true,"img":false}]}
{"op":"mcm","clk":"1362405909","pt":1588448261549,"mc":[{"id":"1.170370564","rc":[{"atl":[[1.43,2]],"id":8509691}],"con":true,"img":false}]}
{"op":"mcm","clk":"1362405931","pt":1588448264865,"mc":[{"id":"1.170370564","rc":[{"atl":[[1.57,66.48]],"id":8509691}],"con":true,"img":false}]}
{"op":"mcm","clk":"1362405941","pt":1588448266388,"mc":[{"id":"1.170370564","rc":[{"atl":[[1.37,70.48]],"id":8509691}],"con":true,"img":false}]}
{"op":"mcm","clk":"1362406052","pt":1588448279379,"mc":[{"id":"1.170370564","rc":[{"trd":[[3.7,0.99]],"ltp":3.7,"tv":0.99,"id":9630572},{"trd":[[1.37,2.69]],"ltp":1.37,"tv":2.69,"id":8509691},{"atl":[[1.37,67.79]],"id":8509691}],"con":true,"img":false}]}
{"op":"mcm","clk":"1362406122","pt":1588448288214,"mc":[{"id":"1.170370564","rc":[{"trd":[[3.7,3.43]],"ltp":3.7,"tv":3.43,"id":9630572},{"trd":[[1.37,9.28]],"ltp":1.37,"tv":9.28,"id":8509691},{"atl":[[1.37,61.2]],"id":8509691}],"con":true,"img":false}]}
{"op":"mcm","clk":"1362406140","pt":1588448290704,"mc":[{"id":"1.170370564","rc":[{"trd":[[1.31,587.8]],"ltp":1.31,"tv":587.8,"id":8509691},{"atb":[[1.31,0]],"id":8509691},{"atl":[[1.31,64.05]],"id":8509691}],"con":true,"img":false}]}
{"op":"mcm","clk":"1362406149","pt":1588448291213,"mc":[{"id":"1.170370564","rc":[{"atl":[[1.31,74.65]],"id":8509691}],"con":true,"img":false}]}
{"op":"mcm","clk":"1362406163","pt":1588448292793,"mc":[{"id":"1.170370564","rc":[{"atl":[[1.39,0]],"id":8509691}],"con":true,"img":false}]}
{"op":"mcm","clk":"1362406190","pt":1588448296106,"mc":[{"id":"1.170370564","rc":[{"atl":[[1.51,2.12]],"id":8509691}],"con":true,"img":false}]}
{"op":"mcm","clk":"1362406194","pt":1588448296409,"mc":[{"id":"1.170370564","rc":[{"atl":[[1.34,66.48]],"id":8509691}],"con":true,"img":false}]}
{"op":"mcm","clk":"1362406220","pt":1588448299823,"mc":[{"id":"1.170370564","rc":[{"trd":[[4.2,76.4]],"ltp":4.2,"tv":76.4,"id":9630572},{"trd":[[1.31,596.32]],"ltp":1.31,"tv":596.32,"id":8509691},{"atl":[[1.31,66.12]],"id":8509691}],"con":true,"img":false}]}
{"op":"mcm","clk":"1362406255","pt":1588448304615,"mc":[{"id":"1.170370564","rc":[{"atl":[[1.31,55.52]],"id":8509691}],"con":true,"img":false}]}
{"op":"mcm","clk":"1362406259","pt":1588448305022,"mc":[{"id":"1.170370564","rc":[{"trd":[[4.2,78.98]],"ltp":4.2,"tv":78.98,"id":9630572},{"trd":[[1.31,604.59]],"ltp":1.31,"tv":604.59,"id":8509691},{"atl":[[1.31,47.26]],"id":8509691}],"con":true,"img":false}]}
{"op":"mcm","clk":"1362406283","pt":1588448308153,"mc":[{"id":"1.170370564","rc":[{"trd":[[4.2,87.85],[4.4,271.04]],"ltp":4.2,"tv":358.88,"id":9630572},{"atl":[[4.4,2.34]],"id":9630572},{"trd":[[1.31,633.01],[1.29,21890.06]],"ltp":1.31,"tv":22523.07,"id":8509691},{"atl":[[1.31,18.83]],"id":8509691}],"con":true,"img":false}]}
{"op":"mcm","clk":"1362406291","pt":1588448308863,"mc":[{"id":"1.170370564","rc":[{"trd":[[4.4,273.38]],"ltp":4.4,"tv":273.38,"id":9630572},{"atl":[[4.4,0]],"id":9630572},{"trd":[[1.29,21898.04]],"ltp":1.29,"tv":21898.04,"id":8509691},{"atl":[[1.29,2.62]],"id":8509691}],"con":true,"img":false}]}
{"op":"mcm","clk":"1362406298","pt":1588448309327,"mc":[{"id":"1.170370564","rc":[{"atb":[[1.25,66.48]],"id":8509691}],"con":true,"img":false}]}
{"op":"mcm","clk":"1362406311","pt":1588448311059,"mc":[{"id":"1.170370564","rc":[{"atb":[[1.19,66.48]],"id":8509691}],"con":true,"img":false}]}
{"op":"mcm","clk":"1362406312","pt":1588448311260,"mc":[{"id":"1.170370564","rc":[{"trd":[[1.29,21903.03]],"ltp":1.29,"tv":21903.03,"id":8509691},{"atl":[[1.29,0.12]],"id":8509691}],"con":true,"img":false}]}
{"op":"mcm","clk":"1362406317","pt":1588448311826,"mc":[{"id":"1.170370564","rc":[{"trd":[[1.31,642.03],[1.29,21903.29]],"ltp":1.31,"tv":22545.32,"id":8509691},{"atl":[[1.29,0],[1.31,14.32]],"id":8509691}],"con":true,"img":false}]}
{"op":"mcm","clk":"1362406334","pt":1588448314068,"mc":[{"id":"1.170370564","rc":[{"atb":[[3.2,3.36]],"id":9630572}],"con":true,"img":false}]}
{"op":"mcm","clk":"1362406342","pt":1588448314837,"mc":[{"id":"1.170370564","rc":[{"atl":[[1.37,57.2]],"id":8509691}],"con":true,"img":false}]}
{"op":"mcm","clk":"1362406411","pt":1588448323046,"mc":[{"id":"1.170370564","rc":[{"atl":[[1.43,0]],"id":8509691}],"con":true,"img":false}]}
{"op":"mcm","clk":"1362406413","pt":1588448323150,"mc":[{"id":"1.170370564","rc":[{"atl":[[1.31,0]],"id":8509691}],"con":true,"img":false}]}
{"op":"mcm","clk":"1362406423","pt":1588448323863,"mc":[{"id":"1.170370564","rc":[{"atl":[[1.34,0]],"id":8509691}],"con":true,"img":false}]}
{"op":"mcm","clk":"1362406455","pt":1588448326057,"mc":[{"id":"1.170370564","rc":[{"atb":[[1.25,0]],"id":8509691}],"con":true,"img":false}]}
{"op":"mcm","clk":"1362406459","pt":1588448326158,"mc":[{"id":"1.170370564","rc":[{"atb":[[1.23,111.29]],"id":8509691}],"con":true,"img":false}]}
{"op":"mcm","clk":"1362406550","pt":1588448331568,"mc":[{"id":"1.170370564","rc":[{"trd":[[1.28,4241.86]],"ltp":1.28,"tv":4241.86,"id":8509691},{"atb":[[1.28,0]],"id":8509691},{"atl":[[1.27,53.1]],"id":8509691}],"con":true,"img":false}]}
{"op":"mcm","clk":"1362406583","pt":1588448333201,"mc":[{"id":"1.170370564","rc":[{"atl":[[1.36,15]],"id":8509691}],"con":true,"img":false}]}
{"op":"mcm","clk":"1362406603","pt":1588448334072,"mc":[{"id":"1.170370564","rc":[{"atl":[[1.36,0]],"id":8509691}],"con":true,"img":false}]}
{"op":"mcm","clk":"1362406712","pt":1588448340195,"mc":[{"id":"1.170370564","rc":[{"atl":[[1.35,6.39]],"id":8509691}],"con":true,"img":false}]}
{"op":"mcm","clk":"1362406719","pt":1588448340602,"mc":[{"id":"1.170370564","rc":[{"atb":[[1.24,91.41]],"id":8509691}],"con":true,"img":false}]}
{"op":"mcm","clk":"1362406736","pt":1588448341677,"mc":[{"id":"1.170370564","rc":[{"atl":[[1.33,66.48]],"id":8509691}],"con":true,"img":false}]}
{"op":"mcm","clk":"1362406911","pt":1588448355895,"mc":[{"id":"1.170370564","rc":[{"trd":[[4.7,172.96]],"ltp":4.7,"tv":172.96,"id":9630572},{"trd":[[1.27,3087.99]],"ltp":1.27,"tv":3087.99,"id":8509691},{"atl":[[1.27,33.52]],"id":8509691}],"con":true,"img":false}]}
{"op":"mcm","clk":"1362407004","pt":1588448363428,"mc":[{"id":"1.170370564","rc":[{"atl":[[1.28,295.21]],"id":8509691}],"con":true,"img":false}]}
{"op":"mcm","clk":"1362407024","pt":1588448365515,"mc":[{"id":"1.170370564","rc":[{"trd":[[1.27,3153.99]],"ltp":1.27,"tv":3153.99,"id":8509691},{"atl":[[1.27,0.53]],"id":8509691}],"con":true,"img":false}]}
{"op":"mcm","clk":"1362407028","pt":1588448365824,"mc":[{"id":"1.170370564","rc":[{"trd":[[1.24,132.97]],"ltp":1.24,"tv":132.97,"id":8509691},{"atb":[[1.24,24.92]],"id":8509691}],"con":true,"img":false}]}
{"op":"mcm","clk":"1362407032","pt":1588448366026,"mc":[{"id":"1.170370564","rc":[{"trd":[[4.7,173.1]],"ltp":4.7,"tv":173.1,"id":9630572},{"atl":[[4.7,8.72]],"id":9630572},{"trd":[[1.27,3154.52]],"ltp":1.27,"tv":3154.52,"id":8509691},{"atl":[[1.27,0]],"id":8509691}],"con":true,"img":false}]}
{"op":"mcm","clk":"1362407037","pt":1588448366638,"mc":[{"id":"1.170370564","rc":[{"atl":[[1.28,0]],"id":8509691}],"con":true,"img":false}]}
{"op":"mcm","clk":"1362407050","pt":1588448367351,"mc":[{"id":"1.170370564","rc":[{"atl":[[4.7,10.49]],"id":9630572}],"con":true,"img":false}]}
{"op":"mcm","clk":"1362407095","pt":1588448371737,"mc":[{"id":"1.170370564","rc":[{"atl":[[1000,3.19]],"id":9630572}],"con":true,"img":false}]}
{"op":"mcm","clk":"1362407102","pt":1588448372448,"mc":[{"id":"1.170370564","rc":[{"trd":[[4.7,183.6]],"ltp":4.7,"tv":183.6,"id":9630572},{"atl":[[4.7,0]],"id":9630572},{"trd":[[1.27,3193.37]],"ltp":1.27,"tv":3193.37,"id":8509691},{"atl":[[1.27,27.64]],"id":8509691}],"con":true,"img":false}]}
{"op":"mcm","clk":"1362407110","pt":1588448373567,"mc":[{"id":"1.170370564","rc":[{"trd":[[1.27,3213.37]],"ltp":1.27,"tv":3213.37,"id":8509691},{"atl":[[1.27,17.64]],"id":8509691}],"con":true,"img":false}]}
{"op":"mcm","clk":"1362407114","pt":1588448373926,"mc":[{"id":"1.170370564","rc":[{"atb":[[1.25,66.48]],"id":8509691}],"con":true,"img":false}]}
{"op":"mcm","clk":"1362407122","pt":1588448375044,"mc":[{"id":"1.170370564","rc":[{"atb":[[1.24,91.41]],"id":8509691}],"con":true,"img":false}]}
{"op":"mcm","clk":"1362407133","pt":1588448376825,"mc":[{"id":"1.170370564","rc":[{"atl":[[1.3,66.48]],"id":8509691}],"con":true,"img":false}]}
{"op":"mcm","clk":"1362407142","pt":1588448377946,"mc":[{"id":"1.170370564","rc":[{"atb":[[1.24,95.85]],"id":8509691}],"con":true,"img":false}]}
{"op":"mcm","clk":"1362407146","pt":1588448378352,"mc":[{"id":"1.170370567","rc":[{"atb":[[1.4,472.51]],"id":9630572}],"con":true,"img":false}]}
{"op":"mcm","clk":"1362407180","pt":1588448381964,"mc":[{"id":"1.170370564","rc":[{"atl":[[1000,3.59]],"id":9630572}],"con":true,"img":false}]}
{"op":"mcm","clk":"1362407195","pt":1588448382929,"mc":[{"id":"1.170370564","rc":[{"atl":[[6.2,688.82]],"id":9630572}],"con":true,"img":false}]}
{"op":"mcm","clk":"1362407213","pt":1588448385370,"mc":[{"id":"1.170370564","rc":[{"trd":[[4.7,183.7]],"ltp":4.7,"tv":183.7,"id":9630572},{"trd":[[1.27,3213.75]],"ltp":1.27,"tv":3213.75,"id":8509691},{"atl":[[1.27,17.26]],"id":8509691}],"con":true,"img":false}]}
{"op":"mcm","clk":"1362407223","pt":1588448386337,"mc":[{"id":"1.170370564","rc":[{"trd":[[1.27,3242.9]],"ltp":1.27,"tv":3242.9,"id":8509691},{"atl":[[1.27,2.68]],"id":8509691}],"con":true,"img":false}]}
{"op":"mcm","clk":"1362407235","pt":1588448387863,"mc":[{"id":"1.170370564","rc":[{"atl":[[6.2,0]],"id":9630572}],"con":true,"img":false}]}
{"op":"mcm","clk":"1362407237","pt":1588448387965,"mc":[{"id":"1.170370564","rc":[{"atb":[[1.24,70.92]],"id":8509691}],"con":true,"img":false}]}
{"op":"mcm","clk":"1362407245","pt":1588448389082,"mc":[{"id":"1.170370564","rc":[{"atb":[[1.26,200]],"id":8509691}],"con":true,"img":false}]}
{"op":"mcm","clk":"1362407312","pt":1588448395094,"mc":[{"id":"1.170370564","rc":[{"atl":[[1000,0]],"id":9630572}],"con":true,"img":false}]}
{"op":"mcm","clk":"1362407379","pt":1588448400185,"mc":[{"id":"1.170370564","rc":[{"trd":[[4.7,184.1]],"ltp":4.7,"tv":184.1,"id":9630572},{"trd":[[1.27,3244.38]],"ltp":1.27,"tv":3244.38,"id":8509691},{"atl":[[1.27,1.2]],"id":8509691}],"con":true,"img":false}]}
{"op":"mcm","clk":"1362407382","pt":1588448400289,"mc":[{"id":"1.170370564","rc":[{"trd":[[1.27,3246.8]],"ltp":1.27,"tv":3246.8,"id":8509691},{"atb":[[1.27,120.79]],"id":8509691},{"atl":[[1.27,0]],"id":8509691}],"con":true,"img":false}]}
{"op":"mcm","clk":"1362407387","pt":1588448400493,"mc":[{"id":"1.170370566","rc":[{"atl":[[1.9,8.86]],"id":8509691}],"con":true,"img":false}]}
{"op":"mcm","clk":"1362407419","pt":1588448402995,"mc":[{"id":"1.170370566","rc":[{"trd":[[4.1,3.48]],"ltp":4.1,"tv":3.48,"id":9630572},{"atl":[[4.1,6.52]],"id":9630572},{"trd":[[1.32,10.8],[1.34,5.24]],"ltp":1.32,"tv":16.04,"id":8509691},{"atb":[[1.34,0]],"id":8509691}],"con":true,"img":false}]}
{"op":"mcm","clk":"1362407438","pt":1588448404688,"mc":[{"id":"1.170370564","rc":[{"atb":[[1.01,1846.54]],"id":8509691}],"con":true,"img":false}]}
{"op":"mcm","clk":"1362407452","pt":1588448405500,"mc":[{"id":"1.170370564","rc":[{"atb":[[1.01,1843.41]],"id":8509691}],"con":true,"img":false}]}
{"op":"mcm","clk":"1362407465","pt":1588448406315,"mc":[{"id":"1.170370566","rc":[{"atb":[[1.5,314.71]],"id":9630572}],"con":true,"img":false}]}
{"op":"mcm","clk":"1362407468","pt":1588448406572,"mc":[{"id":"1.170370564","rc":[{"atb":[[1.01,1843.34]],"id":8509691}],"con":true,"img":false}]}
{"op":"mcm","clk":"1362407477","pt":1588448407286,"mc":[{"id":"1.170370564","rc":[{"atl":[[1.32,14.57]],"id":8509691}],"con":true,"img":false}]}
{"op":"mcm","clk":"1362407490","pt":1588448408710,"mc":[{"id":"1.170370564","rc":[{"trd":[[1.27,3488.38]],"ltp":1.27,"tv":3488.38,"id":8509691},{"atb":[[1.26,120.79],[1.27,0]],"id":8509691}],"con":true,"img":false}]}
{"op":"mcm","clk":"1362407523","pt":1588448411714,"mc":[{"id":"1.170370564","rc":[{"atb":[[1.27,0.07]],"id":8509691}],"con":true,"img":false}]}
{"op":"mcm","clk":"1362407572","pt":1588448416093,"mc":[{"id":"1.170370564","rc":[{"atl":[[1.4,11.59]],"id":8509691}],"con":true,"img":false}]}
{"op":"mcm","clk":"1362407700","pt":1588448426229,"mc":[{"id":"1.170370564","rc":[{"atb":[[1.01,467.99]],"id":9630572}],"con":true,"img":false}]}
{"op":"mcm","clk":"1362407722","pt":1588448428216,"mc":[{"id":"1.170370564","rc":[{"trd":[[1.26,2208.5],[1.27,3488.52]],"ltp":1.26,"tv":5697.02,"id":8509691},{"atb":[[1.26,119.26],[1.27,0]],"id":8509691}],"con":true,"img":false}]}
{"op":"mcm","clk":"1362407736","pt":1588448429640,"mc":[{"id":"1.170370564","rc":[{"atl":[[1.31,2]],"id":8509691}],"con":true,"img":false}]}
{"op":"mcm","clk":"1362407761","pt":1588448431427,"mc":[{"id":"1.170370564","rc":[{"atb":[[1.27,120.79]],"id":8509691}],"con":true,"img":false}]}
{"op":"mcm","clk":"1362407786","pt":1588448433216,"mc":[{"id":"1.170370564","rc":[{"atl":[[1.35,0]],"id":8509691}],"con":true,"img":false}]}
{"op":"mcm","clk":"1362407795","pt":1588448434135,"mc":[{"id":"1.170370564","rc":[{"atb":[[1.28,50]],"id":8509691}],"con":true,"img":false}]}
{"op":"mcm","clk":"1362407818","pt":1588448436121,"mc":[{"id":"1.170370564","rc":[{"atb":[[1.01,468.39]],"id":9630572}],"con":true,"img":false}]}
{"op":"mcm","clk":"1362407825","pt":1588448436731,"mc":[{"id":"1.170370564","rc":[{"atl":[[1.3,0]],"id":8509691}],"con":true,"img":false}]}
{"op":"mcm","clk":"1362407862","pt":1588448440143,"mc":[{"id":"1.170370564","rc":[{"trd":[[1.28,4277.86]],"ltp":1.28,"tv":4277.86,"id":8509691},{"atb":[[1.28,32]],"id":8509691}],"con":true,"img":false}]}
{"op":"mcm","clk":"1362407873","pt":1588448441055,"mc":[{"id":"1.170370564","rc":[{"atb":[[1.28,0]],"id":8509691}],"con":true,"img":false}]}
{"op":"mcm","clk":"1362407890","pt":1588448442433,"mc":[{"id":"1.170370564","rc":[{"atb":[[1.28,88.65]],"id":8509691}],"con":true,"img":false}]}
{"op":"mcm","clk":"1362407915","pt":1588448444728,"mc":[{"id":"1.170370564","rc":[{"atb":[[1.26,0],[1.27,209.44]],"id":8509691}],"con":true,"img":false}]}
{"op":"mcm","clk":"1362407920","pt":1588448445139,"mc":[{"id":"1.170370564","rc":[{"trd":[[1.28,4316.71]],"ltp":1.28,"tv":4316.71,"id":8509691},{"atb":[[1.28,69.22]],"id":8509691}],"con":true,"img":false}]}
{"op":"mcm","clk":"1362407929","pt":1588448446152,"mc":[{"id":"1.170370564","rc":[{"trd":[[1.28,4364.67]],"ltp":1.28,"tv":4364.67,"id":8509691},{"atb":[[1.28,45.24],[1.3,32]],"id":8509691}],"con":true,"img":false}]}
{"op":"mcm","clk":"1362407954","pt":1588448448445,"mc":[{"id":"1.170370566","rc":[{"atb":[[1.51,523.11]],"id":9630572}],"con":true,"img":false}]}
{"op":"mcm","clk":"1362407957","pt":1588448448750,"mc":[{"id":"1.170370564","rc":[{"atb":[[1.01,464.79]],"id":9630572}],"con":true,"img":false}]}
{"op":"mcm","clk":"1362408008","pt":1588448452873,"mc":[{"id":"1.170370564","rc":[{"atb":[[1.16,303.94]],"id":8509691},{"atl":[[1.58,343.22]],"id":8509691}],"con":true,"img":false},{"id":"1.170370566","rc":[{"atb":[[2.52,201.24]],"id":9630572},{"atb":[[1.2,280.07]],"id":8509691}],"con":true,"img":false},{"id":"1.170370567","rc":[{"atb":[[1.41,523.11]],"id":9630572}],"con":true,"img":false}]}
{"op":"mcm","clk":"1362408015","pt":1588448453282,"mc":[{"id":"1.170370564","rc":[{"trd":[[1.3,3893.48]],"ltp":1.3,"tv":3893.48,"id":8509691},{"atb":[[1.3,0]],"id":8509691},{"atl":[[1.3,56.64]],"id":8509691}],"con":true,"img":false}]}
{"op":"mcm","clk":"1362408021","pt":1588448453843,"mc":[{"id":"1.170370564","rc":[{"atb":[[4,0.39]],"id":9630572}],"con":true,"img":false}]}
{"op":"mcm","clk":"1362408035","pt":1588448455064,"mc":[{"id":"1.170370564","rc":[{"trd":[[1.3,3904.92]],"ltp":1.3,"tv":3904.92,"id":8509691},{"atl":[[1.3,50.93]],"id":8509691}],"con":true,"img":false}]}
{"op":"mcm","clk":"1362408055","pt":1588448457097,"mc":[{"id":"1.170370566","rc":[{"atl":[[1.6,159.97]],"id":8509691}],"con":true,"img":false}]}
{"op":"mcm","clk":"1362408065","pt":1588448457557,"mc":[{"id":"1.170370564","rc":[{"atb":[[1.23,127.29]],"id":8509691}],"con":true,"img":false}]}
{"op":"mcm","clk":"1362408157","pt":1588448466588,"mc":[{"id":"1.170370566","rc":[{"atb":[[1.5,0]],"id":9630572}],"con":true,"img":false}]}
{"op":"mcm","clk":"1362408185","pt":1588448469490,"mc":[{"id":"1.170370564","rc":[{"atb":[[1.28,0]],"id":8509691}],"con":true,"img":false}]}
{"op":"mcm","clk":"1362408194","pt":1588448470204,"mc":[{"id":"1.170370564","rc":[{"atb":[[1.27,120.79]],"id":8509691}],"con":true,"img":false}]}
{"op":"mcm","clk":"1362408203","pt":1588448470913,"mc":[{"id":"1.170370564","rc":[{"atl":[[1.3,0]],"id":8509691}],"con":true,"img":false}]}
{"op":"mcm","clk":"1362408220","pt":1588448472188,"mc":[{"id":"1.170370564","rc":[{"atb":[[1.25,0]],"id":8509691}],"con":true,"img":false}]}
{"op":"mcm","clk":"1362408239","pt":1588448474423,"mc":[{"id":"1.170370564","rc":[{"atb":[[1.24,4.43]],"id":8509691}],"con":true,"img":false}]}
{"op":"mcm","clk":"1362408252","pt":1588448475593,"mc":[{"id":"1.170370564","rc":[{"atl":[[1.36,47]],"id":8509691}],"con":true,"img":false}]}
{"op":"mcm","clk":"1362408258","pt":1588448476002,"mc":[{"id":"1.170370564","rc":[{"atl":[[4.5,2.62]],"id":9630572}],"con":true,"img":false}]}
{"op":"mcm","clk":"1362408314","pt":1588448481396,"mc":[{"id":"1.170370567","rc":[{"atb":[[1.4,0]],"id":9630572}],"con":true,"img":false}]}
{"op":"mcm","clk":"1362408353","pt":1588448485413,"mc":[{"id":"1.170370566","rc":[{"trd":[[4.1,10]],"ltp":4.1,"tv":10.0,"id":9630572},{"atl":[[4.1,0]],"id":9630572},{"trd":[[1.32,31.05]],"ltp":1.32,"tv":31.05,"id":8509691},{"atl":[[1.32,59.73]],"id":8509691}],"con":true,"img":false}]}
{"op":"mcm","clk":"1362408365","pt":1588448486536,"mc":[{"id":"1.170370567","rc":[{"atb":[[1.5,472.51]],"id":9630572}],"con":true,"img":false}]}
{"op":"mcm","clk":"1362408384","pt":1588448488525,"mc":[{"id":"1.170370564","rc":[{"trd":[[1.31,646.03]],"ltp":1.31,"tv":646.03,"id":8509691},{"atl":[[1.31,0]],"id":8509691}],"con":true,"img":false}]}
{"op":"mcm","clk":"1362408393","pt":1588448489438,"mc":[{"id":"1.170370564","rc":[{"atb":[[1.31,26]],"id":8509691}],"con":true,"img":false}]}
{"op":"mcm","clk":"1362408409","pt":1588448490613,"mc":[{"id":"1.170370564","rc":[{"atb":[[1.31,40.57]],"id":8509691}],"con":true,"img":false}]}
{"op":"mcm","clk":"1362408434","pt":1588448492853,"mc":[{"id":"1.170370567","rc":[{"atb":[[1.41,0]],"id":9630572}],"con":true,"img":false}]}
{"op":"mcm","clk":"1362408437","pt":1588448493056,"mc":[{"id":"1.170370564","rc":[{"trd":[[4.5,522.21]],"ltp":4.5,"tv":522.21,"id":9630572},{"atl":[[4.5,0]],"id":9630572},{"trd":[[1.27,3730.1],[1.28,4373.9],[1.31,731.42]],"ltp":1.27,"tv":8835.42,"id":8509691},{"atb":[[1.27,0],[1.31,0]],"id":8509691},{"atl":[[1.27,122.5]],"id":8509691}],"con":true,"img":false}]}
{"op":"mcm","clk":"1362408449","pt":1588448494026,"mc":[{"id":"1.170370564","rc":[{"atl":[[1.27,0]],"id":8509691}],"con":true,"img":false}]}
{"op":"mcm","clk":"1362408452","pt":1588448494128,"mc":[{"id":"1.170370564","rc":[{"atb":[[1.25,119.26]],"id":8509691}],"con":true,"img":false}]}
{"op":"mcm","clk":"1362408472","pt":1588448495349,"mc":[{"id":"1.170370564","rc":[{"atb":[[1.25,0]],"id":8509691}],"con":true,"img":false},{"id":"1.170370566","rc":[{"atb":[[2.52,0]],"id":9630572},{"atb":[[1.2,0]],"id":8509691}],"con":true,"img":false}]}
{"op":"mcm","clk":"1362408500","pt":1588448497942,"mc":[{"id":"1.170370567","rc":[{"atb":[[1.51,523.11]],"id":9630572}],"con":true,"img":false}]}
{"op":"mcm","clk":"1362408505","pt":1588448498251,"mc":[{"id":"1.170370564","rc":[{"atb":[[1.26,174.08]],"id":8509691}],"con":true,"img":false}]}
{"op":"mcm","clk":"1362408509","pt":1588448498554,"mc":[{"id":"1.170370564","rc":[{"atb":[[1.19,0]],"id":8509691}],"con":true,"img":false}]}
{"op":"mcm","clk":"1362408523","pt":1588448499928,"mc":[{"id":"1.170370567","rc":[{"atb":[[1.5,0]],"id":9630572}],"con":true,"img":false}]}
{"op":"mcm","clk":"1362408530","pt":1588448500338,"mc":[{"id":"1.170370564","rc":[{"atl":[[1.31,100]],"id":8509691}],"con":true,"img":false}]}
{"op":"mcm","clk":"1362408539","pt":1588448500947,"mc":[{"id":"1.170370565","rc":[{"trd":[[1.81,6.12]],"ltp":1.81,"tv":6.12,"id":11269555},{"atb":[[1.81,3.19]],"id":11269555}],"con":true,"img":false},{"id":"1.170370566","rc":[{"atb":[[2.72,199.54]],"id":9630572},{"atb":[[1.16,303.94]],"id":8509691}],"con":true,"img":false}]}
{"op":"mcm","clk":"1362408548","pt":1588448501657,"mc":[{"id":"1.170370564","rc":[{"atl":[[1.27,88.65]],"id":8509691}],"con":true,"img":false}]}
{"op":"mcm","clk":"1362408569","pt":1588448503746,"mc":[{"id":"1.170370566","rc":[{"trd":[[4.1,12.3]],"ltp":4.1,"tv":12.3,"id":9630572},{"trd":[[1.32,38.21]],"ltp":1.32,"tv":38.21,"id":8509691},{"atl":[[1.32,52.57]],"id":8509691}],"con":true,"img":false}]}
{"op":"mcm","clk":"1362408571","pt":1588448503951,"mc":[{"id":"1.170370564","rc":[{"atl":[[1.27,0]],"id":8509691}],"con":true,"img":false},{"id":"1.170370567","rc":[{"atb":[[1.32,2.62]],"id":8509691}],"con":true,"img":false}]}
{"op":"mcm","clk":"1362408577","pt":1588448504560,"mc":[{"id":"1.170370564","rc":[{"atl":[[1.31,0]],"id":8509691}],"con":true,"img":false}]}
{"op":"mcm","clk":"1362408580","pt":1588448504765,"mc":[{"id":"1.170370564","rc":[{"trd":[[1.26,2385.8]],"ltp":1.26,"tv":2385.8,"id":8509691},{"atb":[[1.26,85.43]],"id":8509691}],"con":true,"img":false}]}
{"op":"mcm","clk":"1362408613","pt":1588448507864,"mc":[{"id":"1.170370567","rc":[{"atb":[[2,132.97]],"id":9630572}],"con":true,"img":false}]}
{"op":"mcm","clk":"1362408634","pt":1588448510051,"mc":[{"id":"1.170370564","rc":[{"atb":[[1.25,88.65]],"id":8509691}],"con":true,"img":false}]}
{"op":"mcm","clk":"1362408680","pt":1588448514577,"mc":[{"id":"1.170370564","rc":[{"atb":[[4.2,100]],"id":9630572}],"con":true,"img":false}]}
{"op":"mcm","clk":"1362408688","pt":1588448515036,"mc":[{"id":"1.170370567","rc":[{"atb":[[1.32,0]],"id":8509691}],"con":true,"img":false}]}
{"op":"mcm","clk":"1362408714","pt":1588448517272,"mc":[{"id":"1.170370564","rc":[{"atb":[[1.27,2]],"id":8509691}],"con":true,"img":false}]}
{"op":"mcm","clk":"1362408717","pt":1588448517476,"mc":[{"id":"1.170370564","rc":[{"trd":[[1.26,2394.92],[1.27,3734.1]],"ltp":1.26,"tv":6129.02,"id":8509691},{"atb":[[1.26,80.87],[1.27,0]],"id":8509691}],"con":true,"img":false}]}
{"op":"mcm","clk":"1362408746","pt":1588448520272,"mc":[{"id":"1.170370567","rc":[{"atb":[[1.31,0]],"id":8509691}],"con":true,"img":false}]}
{"op":"mcm","clk":"1362408753","pt":1588448520882,"mc":[{"id":"1.170370566","rc":[{"atl":[[1.6,0]],"id":8509691}],"con":true,"img":false}]}
{"op":"mcm","clk":"1362408761","pt":1588448521596,"mc":[{"id":"1.170370564","rc":[{"atl":[[1.3,132.97]],"id":8509691}],"con":true,"img":false}]}
{"op":"mcm","clk":"1362408786","pt":1588448523951,"mc":[{"id":"1.170370564","rc":[{"atl":[[4.8,2.62]],"id":9630572}],"con":true,"img":false}]}
{"op":"mcm","clk":"1362408793","pt":1588448524461,"mc":[{"id":"1.170370567","rc":[{"atb":[[2.04,79.98]],"id":9630572}],"con":true,"img":false}]}
{"op":"mcm","clk":"1362408806","pt":1588448525480,"mc":[{"id":"1.170370567","rc":[{"atb":[[1.27,2.62]],"id":8509691}],"con":true,"img":false}]}
{"op":"mcm","clk":"1362408811","pt":1588448525786,"mc":[{"id":"1.170370564","rc":[{"atb":[[1.26,0]],"id":8509691}],"con":true,"img":false}]}
{"op":"mcm","clk":"1362408817","pt":1588448525990,"mc":[{"id":"1.170370566","rc":[{"atl":[[1.58,159.97]],"id":8509691}],"con":true,"img":false}]}
{"op":"mcm","clk":"1362408830","pt":1588448527267,"mc":[{"id":"1.170370566","rc":[{"atl":[[7,3]],"id":9630572}],"con":true,"img":false}]}
{"op":"mcm","clk":"1362408842","pt":1588448528387,"mc":[{"id":"1.170370564","rc":[{"trd":[[4.8,178.49]],"ltp":4.8,"tv":178.49,"id":9630572},{"atl":[[4.8,0]],"id":9630572},{"trd":[[1.23,258.68],[1.26,2404.92],[1.25,2991.44],[1.24,141.84]],"ltp":1.23,"tv":5796.88,"id":8509691},{"atb":[[1.23,0],[1.25,0],[1.24,0]],"id":8509691},{"atl":[[1.23,64.82]],"id":8509691}],"con":true,"img":false}]}
{"op":"mcm","clk":"1362408862","pt":1588448530574,"mc":[{"id":"1.170370564","rc":[{"atl":[[1.23,0]],"id":8509691}],"con":true,"img":false}]}
{"op":"mcm","clk":"1362408867","pt":1588448530981,"mc":[{"id":"1.170370567","rc":[{"atb":[[2,0]],"id":9630572}],"con":true,"img":false}]}
{"op":"mcm","clk":"1362408872","pt":1588448531388,"mc":[{"id":"1.170370564","rc":[{"atb":[[1.16,0]],"id":8509691},{"atl":[[1.58,0]],"id":8509691}],"con":true,"img":false},{"id":"1.170370566","rc":[{"atb":[[2.72,0]],"id":9630572},{"atb":[[1.16,0]],"id":8509691}],"con":true,"img":false}]}
{"op":"mcm","clk":"1362408880","pt":1588448532100,"mc":[{"id":"1.170370564","rc":[{"atl":[[1.25,295.21]],"id":8509691}],"con":true,"img":false}]}
{"op":"mcm","clk":"1362408882","pt":1588448532306,"mc":[{"id":"1.170370564","rc":[{"atb":[[1.2,96.71]],"id":8509691}],"con":true,"img":false}]}
{"op":"mcm","clk":"1362408897","pt":1588448533578,"mc":[{"id":"1.170370564","rc":[{"atb":[[1.22,234.27]],"id":8509691},{"atl":[[1.25,0]],"id":8509691}],"con":true,"img":false}]}
{"op":"mcm","clk":"1362408903","pt":1588448534189,"mc":[{"id":"1.170370567","rc":[{"atb":[[1.07,800.67]],"id":8509691}],"con":true,"img":false}]}
{"op":"mcm","clk":"1362408926","pt":1588448536271,"mc":[{"id":"1.170370564","rc":[{"atl":[[1.27,295.21]],"id":8509691}],"con":true,"img":false}]}
{"op":"mcm","clk":"1362408934","pt":1588448537086,"mc":[{"id":"1.170370564","rc":[{"atb":[[1.11,421.02]],"id":8509691},{"atl":[[1.49,401.83]],"id":8509691}],"con":true,"img":false},{"id":"1.170370566","rc":[{"atb":[[3,200.92]],"id":9630572},{"atb":[[1.11,361.02]],"id":8509691}],"con":true,"img":false}]}
{"op":"mcm","clk":"1362408942","pt":1588448538002,"mc":[{"id":"1.170370564","rc":[{"atl":[[5.1,2.62]],"id":9630572}],"con":true,"img":false}]}
{"op":"mcm","clk":"1362408949","pt":1588448538510,"mc":[{"id":"1.170370564","rc":[{"trd":[[5.1,2.62]],"ltp":5.1,"tv":2.62,"id":9630572},{"atl":[[5.1,0]],"id":9630572},{"trd":[[1.22,244.35],[1.24,152.64]],"ltp":1.22,"tv":396.99,"id":8509691},{"atb":[[1.22,112.1]],"id":8509691}],"con":true,"img":false}]}
{"op":"mcm","clk":"1362408952","pt":1588448538715,"mc":[{"id":"1.170370567","rc":[{"atb":[[2.5,88.65]],"id":9630572}],"con":true,"img":false}]}
{"op":"mcm","clk":"1362408972","pt":1588448540901,"mc":[{"id":"1.170370564","rc":[{"atl":[[1.29,295.21]],"id":8509691}],"con":true,"img":false}]}
{"op":"mcm","clk":"1362408997","pt":1588448543194,"mc":[{"id":"1.170370564","rc":[{"atl":[[1.26,132.97]],"id":8509691}],"con":true,"img":false}]}
{"op":"mcm","clk":"1362409003","pt":1588448543705,"mc":[{"id":"1.170370564","rc":[{"atl":[[1.29,0]],"id":8509691}],"con":true,"img":false}]}
{"op":"mcm","clk":"1362409020","pt":1588448544985,"mc":[{"id":"1.170370564","rc":[{"atb":[[1.01,5842.69]],"id":8509691}],"con":true,"img":false}]}
{"op":"mcm","clk":"1362409022","pt":1588448545189,"mc":[{"id":"1.170370567","rc":[{"atb":[[1.27,0]],"id":8509691}],"con":true,"img":false}]}
{"op":"mcm","clk":"1362409027","pt":1588448545495,"mc":[{"id":"1.170370564","rc":[{"trd":[[1.22,468.55]],"ltp":1.22,"tv":468.55,"id":8509691},{"atb":[[1.22,0]],"id":8509691},{"atl":[[1.22,87.9]],"id":8509691}],"con":true,"img":false}]}
{"op":"mcm","clk":"1362409028","pt":1588448545597,"mc":[{"id":"1.170370565","rc":[{"trd":[[1.51,12.81],[1.81,12.5]],"ltp":1.51,"tv":25.31,"id":11269555},{"atb":[[1.81,0],[1.51,0.74]],"id":11269555}],"con":true,"img":false}]}
{"op":"mcm","clk":"1362409031","pt":1588448545699,"mc":[{"id":"1.170370564","rc":[{"atb":[[1.02,3378.43]],"id":8509691}],"con":true,"img":false}]}
{"op":"mcm","clk":"1362409033","pt":1588448546004,"mc":[{"id":"1.170370564","rc":[{"atb":[[1.03,1336.11]],"id":8509691}],"con":true,"img":false}]}
{"op":"mcm","clk":"1362409035","pt":1588448546106,"mc":[{"id":"1.170370564","rc":[{"trd":[[5.5,0.78]],"ltp":5.5,"tv":0.78,"id":9630572},{"trd":[[1.22,472.1]],"ltp":1.22,"tv":472.1,"id":8509691},{"atl":[[1.22,84.35]],"id":8509691}],"con":true,"img":false}]}
{"op":"mcm","clk":"1362409039","pt":1588448546310,"mc":[{"id":"1.170370564","rc":[{"atb":[[1.04,999.83]],"id":8509691}],"con":true,"img":false}]}
{"op":"mcm","clk":"1362409045","pt":1588448546717,"mc":[{"id":"1.170370564","rc":[{"atb":[[1.05,799.86]],"id":8509691}],"con":true,"img":false}]}
{"op":"mcm","clk":"1362409053","pt":1588448547124,"mc":[{"id":"1.170370564","rc":[{"atb":[[1.06,823.47]],"id":8509691}],"con":true,"img":false}]}
{"op":"mcm","clk":"1362409058","pt":1588448547481,"mc":[{"id":"1.170370564","rc":[{"atb":[[1.07,1417.07]],"id":8509691}],"con":true,"img":false}]}
{"op":"mcm","clk":"1362409063","pt":1588448547890,"mc":[{"id":"1.170370564","rc":[{"trd":[[1.2,33.61]],"ltp":1.2,"tv":33.61,"id":8509691},{"atb":[[1.2,79.91]],"id":8509691}],"con":true,"img":false}]}
{"op":"mcm","clk":"1362409067","pt":1588448547991,"mc":[{"id":"1.170370564","rc":[{"atb":[[1.08,1502.57]],"id":8509691}],"con":true,"img":false}]}
{"op":"mcm","clk":"1362409076","pt":1588448548806,"mc":[{"id":"1.170370564","rc":[{"atb":[[1.09,1380.38]],"id":8509691}],"con":true,"img":false}]}
{"op":"mcm","clk":"1362409079","pt":1588448548908,"mc":[{"id":"1.170370564","rc":[{"atb":[[1.1,399.92]],"id":8509691}],"con":true,"img":false}]}
{"op":"mcm","clk":"1362409095","pt":1588448550383,"mc":[{"id":"1.170370567","rc":[{"atb":[[1.28,2.62]],"id":8509691}],"con":true,"img":false}]}
{"op":"mcm","clk":"1362409130","pt":1588448554001,"mc":[{"id":"1.170370564","rc":[{"atb":[[1.2,0]],"id":8509691},{"atl":[[1.27,0]],"id":8509691}],"con":true,"img":false}]}
{"op":"mcm","clk":"1362409136","pt":1588448554409,"mc":[{"id":"1.170370564","rc":[{"atb":[[1.2,177.3]],"id":8509691}],"con":true,"img":false}]}
{"op":"mcm","clk":"1362409146","pt":1588448555123,"mc":[{"id":"1.170370564","rc":[{"atb":[[1.2,0]],"id":8509691}],"con":true,"img":false}]}
{"op":"mcm","clk":"1362409153","pt":1588448556038,"mc":[{"id":"1.170370567","rc":[{"atb":[[1.28,0]],"id":8509691}],"con":true,"img":false}]}
{"op":"mcm","clk":"1362409158","pt":1588448556292,"mc":[{"id":"1.170370564","rc":[{"atl":[[1.26,0]],"id":8509691}],"con":true,"img":false}]}
{"op":"mcm","clk":"1362409162","pt":1588448556800,"mc":[{"id":"1.170370564","rc":[{"trd":[[1.22,472.46]],"ltp":1.22,"tv":472.46,"id":8509691},{"atl":[[1.22,84.17]],"id":8509691}],"con":true,"img":false}]}
{"op":"mcm","clk":"1362409166","pt":1588448557106,"mc":[{"id":"1.170370564","rc":[{"trd":[[1.22,477.62]],"ltp":1.22,"tv":477.62,"id":8509691},{"atl":[[1.22,81.59]],"id":8509691}],"con":true,"img":false}]}
{"op":"mcm","clk":"1362409188","pt":1588448558837,"mc":[{"id":"1.170370564","rc":[{"trd":[[1.22,482.34]],"ltp":1.22,"tv":482.34,"id":8509691},{"atl":[[1.22,79.23]],"id":8509691}],"con":true,"img":false}]}
{"op":"mcm","clk":"1362409194","pt":1588448559244,"mc":[{"id":"1.170370564","rc":[{"trd":[[1.22,513.02],[1.2,163.61]],"ltp":1.22,"tv":676.63,"id":8509691},{"atl":[[1.22,63.89]],"id":8509691}],"con":true,"img":false}]}
{"op":"mcm","clk":"1362409201","pt":1588448559806,"mc":[{"id":"1.170370564","rc":[{"atb":[[1.12,200]],"id":8509691}],"con":true,"img":false}]}
{"op":"mcm","clk":"1362409216","pt":1588448561127,"mc":[{"id":"1.170370567","rc":[{"atb":[[1.23,2.62]],"id":8509691}],"con":true,"img":false}]}
{"op":"mcm","clk":"1362409242","pt":1588448563314,"mc":[{"id":"1.170370564","rc":[{"atb":[[1.2,0.35]],"id":8509691}],"con":true,"img":false}]}
{"op":"mcm","clk":"1362409248","pt":1588448563925,"mc":[{"id":"1.170370564","rc":[{"trd":[[5.5,2.24]],"ltp":5.5,"tv":2.24,"id":9630572},{"trd":[[1.22,519.59]],"ltp":1.22,"tv":519.59,"id":8509691},{"atl":[[1.22,57.32]],"id":8509691}],"con":true,"img":false}]}
{"op":"mcm","clk":"1362409277","pt":1588448566418,"mc":[{"id":"1.170370564","rc":[{"atb":[[1.11,60]],"id":8509691}],"con":true,"img":false},{"id":"1.170370566","rc":[{"atb":[[1.11,0]],"id":8509691}],"con":true,"img":false}]}
{"op":"mcm","clk":"1362409303","pt":1588448568861,"mc":[{"id":"1.170370564","rc":[{"trd":[[1.22,619.59]],"ltp":1.22,"tv":619.59,"id":8509691},{"atl":[[1.22,7.32]],"id":8509691}],"con":true,"img":false}]}
{"op":"mcm","clk":"1362409314","pt":1588448569525,"mc":[{"id":"1.170370566","rc":[{"atl":[[1.58,0]],"id":8509691}],"con":true,"img":false}]}
{"op":"mcm","clk":"1362409318","pt":1588448570134,"mc":[{"id":"1.170370564","rc":[{"trd":[[1.22,634.23]],"ltp":1.22,"tv":634.23,"id":8509691},{"atb":[[1.22,287.89]],"id":8509691},{"atl":[[1.22,0]],"id":8509691}],"con":true,"img":false}]}
{"op":"mcm","clk":"1362409342","pt":1588448572169,"mc":[{"id":"1.170370564","rc":[{"atb":[[1.22,465.19],[1.13,351.28]],"id":8509691}],"con":true,"img":false},{"id":"1.170370566","rc":[{"atb":[[1.14,331.27]],"id":8509691}],"con":true,"img":false}]}
{"op":"mcm","clk":"1362409347","pt":1588448572528,"mc":[{"id":"1.170370564","rc":[{"atb":[[1.23,177.3]],"id":8509691}],"con":true,"img":false}]}
{"op":"mcm","clk":"1362409353","pt":1588448573240,"mc":[{"id":"1.170370564","rc":[{"atb":[[1.24,177.3]],"id":8509691}],"con":true,"img":false}]}
{"op":"mcm","clk":"1362409365","pt":1588448574054,"mc":[{"id":"1.170370564","rc":[{"atb":[[1.22,287.89]],"id":8509691}],"con":true,"img":false}]}
{"op":"mcm","clk":"1362409396","pt":1588448576444,"mc":[{"id":"1.170370564","rc":[{"atb":[[1.22,0]],"id":8509691}],"con":true,"img":false}]}
{"op":"mcm","clk":"1362409455","pt":1588448580054,"mc":[{"id":"1.170370564","rc":[{"atl":[[1.26,7.09]],"id":8509691}],"con":true,"img":false}]}
{"op":"mcm","clk":"1362409490","pt":1588448582247,"mc":[{"id":"1.170370564","rc":[{"atb":[[1.12,0]],"id":8509691}],"con":true,"img":false}]}
{"op":"mcm","clk":"1362409503","pt":1588448583268,"mc":[{"id":"1.170370564","rc":[{"atb":[[1.23,0]],"id":8509691}],"con":true,"img":false}]}
{"op":"mcm","clk":"1362409519","pt":1588448585258,"mc":[{"id":"1.170370567","rc":[{"atb":[[2.04,0]],"id":9630572}],"con":true,"img":false}]}
{"op":"mcm","clk":"1362409525","pt":1588448586175,"mc":[{"id":"1.170370564","rc":[{"trd":[[1.24,164.3]],"ltp":1.24,"tv":164.3,"id":8509691},{"atb":[[1.24,171.47]],"id":8509691}],"con":true,"img":false}]}
{"op":"mcm","clk":"1362409553","pt":1588448588062,"mc":[{"id":"1.170370564","rc":[{"atl":[[1000,2.62]],"id":8509691}],"con":true,"img":false}]}
{"op":"mcm","clk":"1362409558","pt":1588448588469,"mc":[{"id":"1.170370564","rc":[{"trd":[[1.24,364.3]],"ltp":1.24,"tv":364.3,"id":8509691},{"atb":[[1.24,71.47]],"id":8509691}],"con":true,"img":false}]}
{"op":"mcm","clk":"1362409570","pt":1588448589182,"mc":[{"id":"1.170370564","rc":[{"atb":[[1.22,1.39]],"id":8509691}],"con":true,"img":false}]}
{"op":"mcm","clk":"1362409575","pt":1588448589385,"mc":[{"id":"1.170370564","rc":[{"atl":[[1000,0.04]],"id":8509691}],"con":true,"img":false}]}
{"op":"mcm","clk":"1362409584","pt":1588448589895,"mc":[{"id":"1.170370564","rc":[{"atb":[[1.24,0]],"id":8509691}],"con":true,"img":false}]}
{"op":"mcm","clk":"1362409596","pt":1588448590761,"mc":[{"id":"1.170370564","rc":[{"atl":[[1000,0]],"id":8509691}],"con":true,"img":false}]}
{"op":"mcm","clk":"1362409634","pt":1588448593765,"mc":[{"id":"1.170370564","rc":[{"atl":[[1.29,70.38]],"id":8509691}],"con":true,"img":false}]}
{"op":"mcm","clk":"1362409639","pt":1588448594171,"mc":[{"id":"1.170370565","rc":[{"atb":[[2,97.58]],"id":11340557}],"con":true,"img":false}]}
{"op":"mcm","clk":"1362409642","pt":1588448594274,"mc":[{"id":"1.170370564","rc":[{"atl":[[1.32,114.57]],"id":8509691}],"con":true,"img":false}]}
{"op":"mcm","clk":"1362409666","pt":1588448595903,"mc":[{"id":"1.170370564","rc":[{"atl":[[1.24,0.04]],"id":8509691}],"con":true,"img":false}]}
{"op":"mcm","clk":"1362409721","pt":1588448599265,"mc":[{"id":"1.170370564","rc":[{"atl":[[1.24,8.04]],"id":8509691}],"con":true,"img":false}]}
{"op":"mcm","clk":"1362409757","pt":1588448601965,"mc":[{"id":"1.170370564","rc":[{"atl":[[5.5,5.29]],"id":9630572}],"con":true,"img":false}]}
{"op":"mcm","clk":"1362409768","pt":1588448602680,"mc":[{"id":"1.170370564","rc":[{"atb":[[1.13,18.93]],"id":8509691}],"con":true,"img":false},{"id":"1.170370566","rc":[{"atb":[[1.14,0]],"id":8509691}],"con":true,"img":false}]}
{"op":"mcm","clk":"1362409791","pt":1588448604409,"mc":[{"id":"1.170370564","rc":[{"trd":[[5.5,7.53]],"ltp":5.5,"tv":7.53,"id":9630572},{"atl":[[5.5,0]],"id":9630572},{"trd":[[1.22,660.86]],"ltp":1.22,"tv":660.86,"id":8509691},{"atb":[[1.22,0]],"id":8509691},{"atl":[[1.21,269.97]],"id":8509691}],"con":true,"img":false}]}
{"op":"mcm","clk":"1362409801","pt":1588448605276,"mc":[{"id":"1.170370564","rc":[{"atl":[[1.21,0]],"id":8509691}],"con":true,"img":false}]}
{"op":"mcm","clk":"1362409816","pt":1588448605785,"mc":[{"id":"1.170370564","rc":[{"atl":[[1.22,175]],"id":8509691}],"con":true,"img":false}]}
{"op":"mcm","clk":"1362409845","pt":1588448607619,"mc":[{"id":"1.170370564","rc":[{"atl":[[1.26,0]],"id":8509691}],"con":true,"img":false}]}
{"op":"mcm","clk":"1362409851","pt":1588448608130,"mc":[{"id":"1.170370564","rc":[{"atb":[[1.09,1791.39]],"id":8509691}],"con":true,"img":false},{"id":"1.170370566","rc":[{"atb":[[1.08,435.07]],"id":8509691}],"con":true,"img":false}]}
{"op":"mcm","clk":"1362409862","pt":1588448608385,"mc":[{"id":"1.170370564","rc":[{"atl":[[1.21,177.3]],"id":8509691}],"con":true,"img":false}]}
{"op":"mcm","clk":"1362409887","pt":1588448609712,"mc":[{"id":"1.170370564","rc":[{"atb":[[1.2,25.8]],"id":8509691}],"con":true,"img":false}]}
{"op":"mcm","clk":"1362409898","pt":1588448610322,"mc":[{"id":"1.170370564","rc":[{"atl":[[1.22,0]],"id":8509691}],"con":true,"img":false}]}
{"op":"mcm","clk":"1362409911","pt":1588448610781,"mc":[{"id":"1.170370564","rc":[{"trd":[[1.2,215.22]],"ltp":1.2,"tv":215.22,"id":8509691},{"atb":[[1.2,0]],"id":8509691},{"atl":[[1.2,151.49]],"id":8509691}],"con":true,"img":false}]}
{"op":"mcm","clk":"1362409917","pt":1588448611088,"mc":[{"id":"1.170370564","rc":[{"atb":[[5.5,50]],"id":9630572}],"con":true,"img":false}]}
{"op":"mcm","clk":"1362409924","pt":1588448611393,"mc":[{"id":"1.170370564","rc":[{"atl":[[1.2,0],[1.32,14.57]],"id":8509691}],"con":true,"img":false}]}
{"op":"mcm","clk":"1362409965","pt":1588448613130,"mc":[{"id":"1.170370564","rc":[{"atl":[[1.28,175]],"id":8509691}],"con":true,"img":false}]}
{"op":"mcm","clk":"1362409972","pt":1588448613334,"mc":[{"id":"1.170370564","rc":[{"trd":[[1.21,20]],"ltp":1.21,"tv":20.0,"id":8509691},{"atl":[[1.21,167.3]],"id":8509691}],"con":true,"img":false}]}
{"op":"mcm","clk":"1362409975","pt":1588448613385,"mc":[{"id":"1.170370564","rc":[{"atl":[[1.28,350]],"id":8509691}],"con":true,"img":false}]}
{"op":"mcm","clk":"1362409998","pt":1588448614609,"mc":[{"id":"1.170370564","rc":[{"trd":[[1.21,27]],"ltp":1.21,"tv":27.0,"id":8509691},{"atl":[[1.21,163.8]],"id":8509691}],"con":true,"img":false}]}
{"op":"mcm","clk":"1362410012","pt":1588448615525,"mc":[{"id":"1.170370566","rc":[{"atb":[[3,0]],"id":9630572},{"atb":[[1.08,0]],"id":8509691}],"con":true,"img":false}]}
{"op":"mcm","clk":"1362410021","pt":1588448616187,"mc":[{"id":"1.170370564","rc":[{"atl":[[1.19,7.5]],"id":8509691}],"con":true,"img":false}]}
{"op":"mcm","clk":"1362410022","pt":1588448616290,"mc":[{"id":"1.170370564","rc":[{"atb":[[5.5,0]],"id":9630572}],"con":true,"img":false}]}
{"op":"mcm","clk":"1362410100","pt":1588448622613,"mc":[{"id":"1.170370564","rc":[{"atl":[[1.28,0]],"id":8509691}],"con":true,"img":false}]}
{"op":"mcm","clk":"1362410124","pt":1588448624653,"mc":[{"id":"1.170370564","rc":[{"atl":[[1.21,0]],"id":8509691}],"con":true,"img":false}]}
{"op":"mcm","clk":"1362410128","pt":1588448624806,"mc":[{"id":"1.170370564","rc":[{"atb":[[1.15,0.35]],"id":8509691}],"con":true,"img":false}]}
{"op":"mcm","clk":"1362410146","pt":1588448626130,"mc":[{"id":"1.170370564","rc":[{"atl":[[1000,2.63]],"id":8509691}],"con":true,"img":false}]}
{"op":"mcm","clk":"1362410156","pt":1588448627048,"mc":[{"id":"1.170370564","rc":[{"atl":[[1000,0.06]],"id":8509691}],"con":true,"img":false}]}
{"op":"mcm","clk":"1362410166","pt":1588448627963,"mc":[{"id":"1.170370564","rc":[{"atl":[[1000,0]],"id":8509691}],"con":true,"img":false}]}
{"op":"mcm","clk":"1362410208","pt":1588448631942,"mc":[{"id":"1.170370564","rc":[{"trd":[[6.8,0.73]],"ltp":6.8,"tv":0.73,"id":9630572},{"atl":[[6.8,2.27]],"id":9630572},{"trd":[[1.17,4.23]],"ltp":1.17,"tv":4.23,"id":8509691}],"con":true,"img":false}]}
{"op":"mcm","clk":"1362410218","pt":1588448633061,"mc":[{"id":"1.170370564","rc":[{"trd":[[6.8,0.74]],"ltp":6.8,"tv":0.74,"id":9630572},{"atl":[[6.8,2.26]],"id":9630572},{"trd":[[1.17,4.29]],"ltp":1.17,"tv":4.29,"id":8509691}],"con":true,"img":false}]}
{"op":"mcm","clk":"1362410250","pt":1588448635674,"mc":[{"id":"1.170370564","rc":[{"trd":[[1.19,5.15]],"ltp":1.19,"tv":5.15,"id":8509691},{"atl":[[1.19,4.92]],"id":8509691}],"con":true,"img":false}]}
{"op":"mcm","clk":"1362410268","pt":1588448637151,"mc":[{"id":"1.170370564","rc":[{"trd":[[6.2,0.94]],"ltp":6.2,"tv":0.94,"id":9630572},{"atl":[[5.7,0.51]],"id":9630572},{"trd":[[1.19,10.08]],"ltp":1.19,"tv":10.08,"id":8509691},{"atl":[[1.19,0]],"id":8509691}],"con":true,"img":false}]}
{"op":"mcm","clk":"1362410294","pt":1588448639748,"mc":[{"id":"1.170370564","rc":[{"trd":[[6.8,3],[5.7,0.51]],"ltp":6.8,"tv":3.51,"id":9630572},{"atl":[[6.8,0],[5.7,0]],"id":9630572},{"trd":[[1.17,17.43],[1.21,29.41]],"ltp":1.17,"tv":46.84,"id":8509691},{"atl":[[1.17,4.45]],"id":8509691}],"con":true,"img":false}]}
{"op":"mcm","clk":"1362410325","pt":1588448642449,"mc":[{"id":"1.170370564","rc":[{"atb":[[7,7]],"id":9630572},{"atb":[[1.01,5845.89]],"id":8509691}],"con":true,"img":false}]}
{"op":"mcm","clk":"1362410333","pt":1588448643168,"mc":[{"id":"1.170370564","rc":[{"atb":[[1.01,5842.73]],"id":8509691}],"con":true,"img":false}]}
{"op":"mcm","clk":"1362410337","pt":1588448643373,"mc":[{"id":"1.170370564","rc":[{"trd":[[1.17,17.79]],"ltp":1.17,"tv":17.79,"id":8509691},{"atl":[[1.17,4.27]],"id":8509691}],"con":true,"img":false}]}
{"op":"mcm","clk":"1362410344","pt":1588448643880,"mc":[{"id":"1.170370564","rc":[{"atb":[[1.01,5842.69]],"id":8509691}],"con":true,"img":false}]}
{"op":"mcm","clk":"1362410354","pt":1588448645163,"mc":[{"id":"1.170370564","rc":[{"trd":[[1.13,9.03],[1.15,0.71]],"ltp":1.13,"tv":9.73,"id":8509691},{"atb":[[1.15,0],[1.13,14.41]],"id":8509691}],"con":true,"img":false}]}
{"op":"mcm","clk":"1362410379","pt":1588448647555,"mc":[{"id":"1.170370564","rc":[{"trd":[[7,5.76]],"ltp":7.0,"tv":5.76,"id":9630572},{"atb":[[7,4.12]],"id":9630572}],"con":true,"img":false}]}
{"op":"mcm","clk":"1362410392","pt":1588448648979,"mc":[{"id":"1.170370564","rc":[{"trd":[[1.17,17.87]],"ltp":1.17,"tv":17.87,"id":8509691},{"atl":[[1.17,4.23]],"id":8509691}],"con":true,"img":false}]}
{"op":"mcm","clk":"1362410441","pt":1588448653299,"mc":[{"id":"1.170370564","rc":[{"atb":[[1.1,0]],"id":8509691}],"con":true,"img":false}]}
{"op":"mcm","clk":"1362410497","pt":1588448657573,"mc":[{"id":"1.170370564","rc":[{"atb":[[1.09,1380.38]],"id":8509691},{"atl":[[1.49,0]],"id":8509691}],"con":true,"img":false}]}
{"op":"mcm","clk":"1362410515","pt":1588448658999,"mc":[{"id":"1.170370564","rc":[{"atl":[[1.14,295.21]],"id":8509691}],"con":true,"img":false}]}
{"op":"mcm","clk":"1362411260","pt":1588448660884,"mc":[{"id":"1.170370564","rc":[{"trd":[[1.14,4]],"ltp":1.14,"tv":4.0,"id":8509691},{"atl":[[1.14,293.2]],"id":8509691}],"con":true,"img":false}]}
{"op":"mcm","clk":"1362411266","pt":1588448661392,"mc":[{"id":"1.170370564","rc":[{"atl":[[1.14,0]],"id":8509691}],"con":true,"img":false},{"id":"1.170370566","rc":[{"trd":[[7,3]],"ltp":7.0,"tv":3.0,"id":9630572},{"atl":[[7,0]],"id":9630572},{"trd":[[1.16,18.1]],"ltp":1.16,"tv":18.1,"id":8509691},{"atl":[[1.16,0.29]],"id":8509691}],"con":true,"img":false}]}
{"op":"mcm","clk":"1362411269","pt":1588448661699,"mc":[{"id":"1.170370564","rc":[{"trd":[[1.13,37.86]],"ltp":1.13,"tv":37.86,"id":8509691},{"atb":[[1.13,0]],"id":8509691},{"atl":[[1.13,280.79]],"id":8509691}],"con":true,"img":false}]}
{"op":"mcm","clk":"1362411279","pt":1588448662411,"mc":[{"id":"1.170370566","rc":[{"atb":[[4,195.16]],"id":9630572},{"atb":[[1.02,1241.11]],"id":8509691}],"con":true,"img":false}]}
{"op":"mcm","clk":"1362411284","pt":1588448662615,"mc":[{"id":"1.170370564","rc":[{"atb":[[1.08,2002.48]],"id":8509691}],"con":true,"img":false}]}
{"op":"mcm","clk":"1362411290","pt":1588448663072,"mc":[{"id":"1.170370564","rc":[{"atb":[[1.07,1988.4]],"id":8509691}],"con":true,"img":false}]}
{"op":"mcm","clk":"1362411291","pt":1588448663175,"mc":[{"id":"1.170370566","rc":[{"atl":[[1.16,0]],"id":8509691}],"con":true,"img":false}]}
{"op":"mcm","clk":"1362411292","pt":1588448663275,"mc":[{"id":"1.170370564","rc":[{"atb":[[1.06,1327.63]],"id":8509691},{"atl":[[1.4,501.02]],"id":8509691}],"con":true,"img":false}]}
{"op":"mcm","clk":"1362411297","pt":1588448663582,"mc":[{"id":"1.170370564","rc":[{"atb":[[1.06,1994.18]],"id":8509691}],"con":true,"img":false}]}
{"op":"mcm","clk":"1362411303","pt":1588448663988,"mc":[{"id":"1.170370564","rc":[{"atb":[[1.05,1599.72]],"id":8509691}],"con":true,"img":false}]}
{"op":"mcm","clk":"1362411305","pt":1588448664090,"mc":[{"id":"1.170370564","rc":[{"trd":[[1.13,204.96]],"ltp":1.13,"tv":204.96,"id":8509691},{"atl":[[1.13,197.25]],"id":8509691}],"con":true,"img":false}]}
{"op":"mcm","clk":"1362411309","pt":1588448664295,"mc":[{"id":"1.170370564","rc":[{"atl":[[1.14,177.3],[1.13,322.77]],"id":8509691}],"con":true,"img":false}]}
{"op":"mcm","clk":"1362411312","pt":1588448664396,"mc":[{"id":"1.170370564","rc":[{"atb":[[1.04,1999.66]],"id":8509691}],"con":true,"img":false}]}
{"op":"mcm","clk":"1362411316","pt":1588448664702,"mc":[{"id":"1.170370566","rc":[{"atb":[[7,3.48]],"id":9630572}],"con":true,"img":false}]}
{"op":"mcm","clk":"1362411318","pt":1588448664906,"mc":[{"id":"1.170370564","rc":[{"atl":[[1.29,0]],"id":8509691}],"con":true,"img":false},{"id":"1.170370566","rc":[{"atb":[[7,0]],"id":9630572}],"con":true,"img":false}]}
{"op":"mcm","clk":"1362411331","pt":1588448665619,"mc":[{"id":"1.170370564","rc":[{"atl":[[1.13,500.07]],"id":8509691}],"con":true,"img":false}]}
{"op":"mcm","clk":"1362411334","pt":1588448665721,"mc":[{"id":"1.170370564","rc":[{"atl":[[1.13,374.55]],"id":8509691}],"con":true,"img":false}]}
{"op":"mcm","clk":"1362411340","pt":1588448666076,"mc":[{"id":"1.170370564","rc":[{"trd":[[1.13,209]],"ltp":1.13,"tv":209.0,"id":8509691},{"atl":[[1.13,372.53]],"id":8509691}],"con":true,"img":false}]}
{"op":"mcm","clk":"1362411341","pt":1588448666178,"mc":[{"id":"1.170370564","rc":[{"atl":[[1.13,177.3]],"id":8509691}],"con":true,"img":false}]}
{"op":"mcm","clk":"1362411352","pt":1588448667097,"mc":[{"id":"1.170370564","rc":[{"atb":[[1.11,237.3]],"id":8509691},{"atl":[[1.13,190.6]],"id":8509691}],"con":true,"img":false}]}
{"op":"mcm","clk":"1362411360","pt":1588448668114,"mc":[{"id":"1.170370564","rc":[{"atl":[[1000,2.68]],"id":8509691}],"con":true,"img":false}]}
{"op":"mcm","clk":"1362411372","pt":1588448668981,"mc":[{"id":"1.170370564","rc":[{"atl":[[1000,0.1]],"id":8509691}],"con":true,"img":false}]}
{"op":"mcm","clk":"1362411382","pt":1588448669896,"mc":[{"id":"1.170370564","rc":[{"atl":[[1000,0]],"id":8509691}],"con":true,"img":false}]}
{"op":"mcm","clk":"1362411393","pt":1588448670712,"mc":[{"id":"1.170370564","rc":[{"atb":[[1.1,177.3]],"id":8509691}],"con":true,"img":false}]}
{"op":"mcm","clk":"1362411396","pt":1588448670915,"mc":[{"id":"1.170370564","rc":[{"trd":[[1.13,386.3]],"ltp":1.13,"tv":386.3,"id":8509691},{"atl":[[1.13,101.95]],"id":8509691}],"con":true,"img":false}]}
{"op":"mcm","clk":"1362411397","pt":1588448671118,"mc":[{"id":"1.170370564","rc":[{"trd":[[1.11,255.56]],"ltp":1.11,"tv":255.56,"id":8509691},{"atb":[[1.11,109.52]],"id":8509691}],"con":true,"img":false}]}
{"op":"mcm","clk":"1362411400","pt":1588448671321,"mc":[{"id":"1.170370564","rc":[{"trd":[[1.13,394.96]],"ltp":1.13,"tv":394.96,"id":8509691},{"atl":[[1.13,97.62]],"id":8509691}],"con":true,"img":false}]}
{"op":"mcm","clk":"1362411413","pt":1588448671984,"mc":[{"id":"1.170370564","rc":[{"atb":[[1.11,211.3]],"id":8509691}],"con":true,"img":false}]}
{"op":"mcm","clk":"1362411443","pt":1588448674686,"mc":[{"id":"1.170370564","rc":[{"atb":[[1.12,77]],"id":8509691}],"con":true,"img":false}]}
{"op":"mcm","clk":"1362411448","pt":1588448674993,"mc":[{"id":"1.170370564","rc":[{"trd":[[1.12,0.2]],"ltp":1.12,"tv":0.2,"id":8509691},{"atb":[[1.12,76.9]],"id":8509691}],"con":true,"img":false}]}
{"op":"mcm","clk":"1362411458","pt":1588448675808,"mc":[{"id":"1.170370566","rc":[{"atl":[[1.9,0]],"id":8509691}],"con":true,"img":false}]}
{"op":"mcm","clk":"1362411464","pt":1588448676419,"mc":[{"id":"1.170370566","rc":[{"atb":[[1.03,183.97]],"id":8509691}],"con":true,"img":false}]}
{"op":"mcm","clk":"1362411466","pt":1588448676521,"mc":[{"id":"1.170370564","rc":[{"atl":[[1.4,496.71]],"id":8509691}],"con":true,"img":false}]}
{"op":"mcm","clk":"1362411475","pt":1588448677235,"mc":[{"id":"1.170370564","rc":[{"trd":[[1.13,494.82]],"ltp":1.13,"tv":494.82,"id":8509691},{"atl":[[1.5,16.59],[1.13,47.69]],"id":8509691}],"con":true,"img":false}]}
{"op":"mcm","clk":"1362411498","pt":1588448678918,"mc":[{"id":"1.170370564","rc":[{"trd":[[1.12,2.06]],"ltp":1.12,"tv":2.06,"id":8509691},{"atb":[[1.12,75.97]],"id":8509691}],"con":true,"img":false}]}
{"op":"mcm","clk":"1362411526","pt":1588448681308,"mc":[{"id":"1.170370564","rc":[{"atb":[[1.12,78.23]],"id":8509691}],"con":true,"img":false}]}
{"op":"mcm","clk":"1362411545","pt":1588448682937,"mc":[{"id":"1.170370564","rc":[{"trd":[[1.12,150.76]],"ltp":1.12,"tv":150.76,"id":8509691},{"atb":[[1.12,3.88]],"id":8509691}],"con":true,"img":false}]}
{"op":"mcm","clk":"1362411565","pt":1588448684717,"mc":[{"id":"1.170370564","rc":[{"trd":[[1.13,514.82]],"ltp":1.13,"tv":514.82,"id":8509691},{"atl":[[1.13,37.69]],"id":8509691}],"con":true,"img":false}]}
{"op":"mcm","clk":"1362411639","pt":1588448692555,"mc":[{"id":"1.170370564","rc":[{"atb":[[1.11,109.52]],"id":8509691}],"con":true,"img":false}]}
{"op":"mcm","clk":"1362411643","pt":1588448692958,"mc":[{"id":"1.170370564","rc":[{"atb":[[1.12,104.75]],"id":8509691}],"con":true,"img":false}]}
{"op":"mcm","clk":"1362411651","pt":1588448693623,"mc":[{"id":"1.170370564","rc":[{"trd":[[1.13,555.24]],"ltp":1.13,"tv":555.24,"id":8509691},{"atl":[[1.13,17.48]],"id":8509691}],"con":true,"img":false}]}
{"op":"mcm","clk":"1362411673","pt":1588448694943,"mc":[{"id":"1.170370564","rc":[{"atb":[[1.1,354.6]],"id":8509691}],"con":true,"img":false}]}
{"op":"mcm","clk":"1362411683","pt":1588448695657,"mc":[{"id":"1.170370564","rc":[{"trd":[[1.12,182.74]],"ltp":1.12,"tv":182.74,"id":8509691},{"atb":[[1.12,88.76]],"id":8509691}],"con":true,"img":false}]}
{"op":"mcm","clk":"1362411700","pt":1588448696829,"mc":[{"id":"1.170370564","rc":[{"atl":[[1.13,13.29]],"id":8509691}],"con":true,"img":false}]}
{"op":"mcm","clk":"1362411706","pt":1588448697440,"mc":[{"id":"1.170370564","rc":[{"atl":[[1.14,0]],"id":8509691}],"con":true,"img":false}]}
{"op":"mcm","clk":"1362411713","pt":1588448698148,"mc":[{"id":"1.170370564","rc":[{"atl":[[1.15,15]],"id":8509691}],"con":true,"img":false}]}
{"op":"mcm","clk":"1362411737","pt":1588448700334,"mc":[{"id":"1.170370567","rc":[{"atb":[[2.5,0]],"id":9630572}],"con":true,"img":false}]}
{"op":"mcm","clk":"1362411754","pt":1588448701663,"mc":[{"id":"1.170370564","rc":[{"trd":[[1.12,342.72]],"ltp":1.12,"tv":342.72,"id":8509691},{"atb":[[1.12,8.77]],"id":8509691}],"con":true,"img":false}]}
{"op":"mcm","clk":"1362411762","pt":1588448702276,"mc":[{"id":"1.170370564","rc":[{"trd":[[1.13,581.84]],"ltp":1.13,"tv":581.84,"id":8509691},{"atb":[[1.13,6.7]],"id":8509691},{"atl":[[1.13,0]],"id":8509691}],"con":true,"img":false}]}
{"op":"mcm","clk":"1362411774","pt":1588448703456,"mc":[{"id":"1.170370564","rc":[{"trd":[[7,6.1],[7.6,2.27]],"ltp":7.0,"tv":8.37,"id":9630572},{"atb":[[7,3.95]],"id":9630572},{"trd":[[1.15,15.71]],"ltp":1.15,"tv":15.71,"id":8509691},{"atl":[[1.15,0]],"id":8509691}],"con":true,"img":false}]}
{"op":"mcm","clk":"1362411798","pt":1588448705439,"mc":[{"id":"1.170370567","rc":[{"atb":[[2.2,88.65]],"id":9630572}],"con":true,"img":false}]}
{"op":"mcm","clk":"1362411809","pt":1588448706662,"mc":[{"id":"1.170370564","rc":[{"atb":[[1.12,11.21]],"id":8509691}],"con":true,"img":false}]}
{"op":"mcm","clk":"1362411824","pt":1588448707932,"mc":[{"id":"1.170370566","rc":[{"atl":[[2.96,30.17]],"id":8509691}],"con":true,"img":false}]}
{"op":"mcm","clk":"1362411833","pt":1588448708439,"mc":[{"id":"1.170370564","rc":[{"atb":[[1.14,295.21]],"id":8509691}],"con":true,"img":false}]}
{"op":"mcm","clk":"1362411836","pt":1588448708644,"mc":[{"id":"1.170370564","rc":[{"atb":[[4.5,3.8]],"id":9630572}],"con":true,"img":false}]}
{"op":"mcm","clk":"1362411841","pt":1588448709053,"mc":[{"id":"1.170370564","rc":[{"trd":[[1.14,20.62]],"ltp":1.14,"tv":20.62,"id":8509691},{"atb":[[1.14,286.9]],"id":8509691}],"con":true,"img":false}]}
{"op":"mcm","clk":"1362411856","pt":1588448710576,"mc":[{"id":"1.170370564","rc":[{"atb":[[1.06,1490.02]],"id":8509691}],"con":true,"img":false}]}
{"op":"mcm","clk":"1362411858","pt":1588448710677,"mc":[{"id":"1.170370566","rc":[{"atb":[[1.02,88.86]],"id":8509691}],"con":true,"img":false}]}
{"op":"mcm","clk":"1362411870","pt":1588448711847,"mc":[{"id":"1.170370564","rc":[{"trd":[[1.14,52.62]],"ltp":1.14,"tv":52.62,"id":8509691},{"atb":[[1.14,270.9]],"id":8509691}],"con":true,"img":false}]}
{"op":"mcm","clk":"1362411878","pt":1588448712561,"mc":[{"id":"1.170370564","rc":[{"atb":[[1.13,301.91]],"id":8509691}],"con":true,"img":false}]}
{"op":"mcm","clk":"1362411887","pt":1588448713374,"mc":[{"id":"1.170370564","rc":[{"atb":[[1.14,0]],"id":8509691}],"con":true,"img":false}]}
{"op":"mcm","clk":"1362411890","pt":1588448713578,"mc":[{"id":"1.170370564","rc":[{"atb":[[1.13,6.7]],"id":8509691}],"con":true,"img":false}]}
{"op":"mcm","clk":"1362411901","pt":1588448714442,"mc":[{"id":"1.170370564","rc":[{"atb":[[1.13,35.85]],"id":8509691},{"atl":[[1.15,8.23]],"id":8509691}],"con":true,"img":false}]}
{"op":"mcm","clk":"1362411905","pt":1588448714547,"mc":[{"id":"1.170370564","rc":[{"atb":[[1.13,85.85]],"id":8509691}],"con":true,"img":false}]}
{"op":"mcm","clk":"1362411921","pt":1588448716070,"mc":[{"id":"1.170370564","rc":[{"atb":[[1.11,404.73]],"id":8509691}],"con":true,"img":false}]}
{"op":"mcm","clk":"1362411926","pt":1588448716478,"mc":[{"id":"1.170370564","rc":[{"atb":[[1.08,2437.56]],"id":8509691}],"con":true,"img":false},{"id":"1.170370566","rc":[{"atb":[[1.04,666.32]],"id":8509691}],"con":true,"img":false}]}
{"op":"mcm","clk":"1362411929","pt":1588448716681,"mc":[{"id":"1.170370564","rc":[{"trd":[[1.15,32.18]],"ltp":1.15,"tv":32.18,"id":8509691},{"atb":[[1.15,169.06]],"id":8509691},{"atl":[[1.15,0]],"id":8509691}],"con":true,"img":false}]}
{"op":"mcm","clk":"1362411934","pt":1588448717088,"mc":[{"id":"1.170370564","rc":[{"trd":[[1.15,63.9]],"ltp":1.15,"tv":63.9,"id":8509691},{"atb":[[1.15,153.2]],"id":8509691}],"con":true,"img":false}]}
{"op":"mcm","clk":"1362411937","pt":1588448717494,"mc":[{"id":"1.170370564","rc":[{"atb":[[1.12,2.44]],"id":8509691}],"con":true,"img":false}]}
{"op":"mcm","clk":"1362411940","pt":1588448717749,"mc":[{"id":"1.170370564","rc":[{"atl":[[1.16,2.26]],"id":8509691}],"con":true,"img":false}]}
{"op":"mcm","clk":"1362411943","pt":1588448717953,"mc":[{"id":"1.170370566","rc":[{"atb":[[1.03,0]],"id":8509691}],"con":true,"img":false}]}
{"op":"mcm","clk":"1362411944","pt":1588448718054,"mc":[{"id":"1.170370564","rc":[{"atb":[[1.13,35.85]],"id":8509691}],"con":true,"img":false}]}
{"op":"mcm","clk":"1362411946","pt":1588448718158,"mc":[{"id":"1.170370564","rc":[{"atb":[[1.15,0]],"id":8509691}],"con":true,"img":false}]}
{"op":"mcm","clk":"1362411959","pt":1588448719174,"mc":[{"id":"1.170370564","rc":[{"atb":[[1.13,213.15]],"id":8509691}],"con":true,"img":false}]}
{"op":"mcm","clk":"1362411983","pt":1588448721264,"mc":[{"id":"1.170370564","rc":[{"atb":[[1.14,8.62]],"id":8509691}],"con":true,"img":false}]}
{"op":"mcm","clk":"1362412006","pt":1588448723096,"mc":[{"id":"1.170370566","rc":[{"atb":[[1.05,183.97]],"id":8509691}],"con":true,"img":false}]}
{"op":"mcm","clk":"1362412020","pt":1588448724010,"mc":[{"id":"1.170370564","rc":[{"atb":[[1.14,185.93]],"id":8509691}],"con":true,"img":false}]}
{"op":"mcm","clk":"1362412026","pt":1588448724578,"mc":[{"id":"1.170370564","rc":[{"atb":[[1.13,35.85]],"id":8509691}],"con":true,"img":false}]}
{"op":"mcm","clk":"1362412044","pt":1588448725902,"mc":[{"id":"1.170370564","rc":[{"atb":[[1.06,1540.02]],"id":8509691}],"con":true,"img":false}]}
{"op":"mcm","clk":"1362412045","pt":1588448726106,"mc":[{"id":"1.170370564","rc":[{"atb":[[1.15,20]],"id":8509691}],"con":true,"img":false}]}
{"op":"mcm","clk":"1362412047","pt":1588448726207,"mc":[{"id":"1.170370564","rc":[{"atb":[[1.14,8.62]],"id":8509691}],"con":true,"img":false}]}
{"op":"mcm","clk":"1362412076","pt":1588448728704,"mc":[{"id":"1.170370564","rc":[{"atb":[[1.15,0]],"id":8509691}],"con":true,"img":false}]}
{"op":"mcm","clk":"1362412098","pt":1588448730890,"mc":[{"id":"1.170370564","rc":[{"trd":[[1.16,4.52]],"ltp":1.16,"tv":4.52,"id":8509691},{"atb":[[1.16,11.92]],"id":8509691},{"atl":[[1.16,0]],"id":8509691}],"con":true,"img":false}]}
{"op":"mcm","clk":"1362412105","pt":1588448731398,"mc":[{"id":"1.170370564","rc":[{"atb":[[1.16,12.98]],"id":8509691}],"con":true,"img":false}]}
{"op":"mcm","clk":"1362412120","pt":1588448732721,"mc":[{"id":"1.170370564","rc":[{"atb":[[1.08,2002.48]],"id":8509691}],"con":true,"img":false},{"id":"1.170370566","rc":[{"atb":[[1.04,0]],"id":8509691}],"con":true,"img":false}]}
{"op":"mcm","clk":"1362412125","pt":1588448732975,"mc":[{"id":"1.170370564","rc":[{"atl":[[1.23,15.99]],"id":8509691}],"con":true,"img":false}]}
{"op":"mcm","clk":"1362412131","pt":1588448733485,"mc":[{"id":"1.170370564","rc":[{"trd":[[1.14,58.64],[1.16,30.48]],"ltp":1.14,"tv":89.12,"id":8509691},{"atb":[[1.14,5.61],[1.16,0]],"id":8509691}],"con":true,"img":false}]}
{"op":"mcm","clk":"1362412146","pt":1588448735014,"mc":[{"id":"1.170370564","rc":[{"trd":[[7,10.05]],"ltp":7.0,"tv":10.05,"id":9630572},{"atb":[[7,0]],"id":9630572},{"trd":[[1.17,49.96]],"ltp":1.17,"tv":49.96,"id":8509691},{"atb":[[1.17,267.34]],"id":8509691},{"atl":[[1.17,0]],"id":8509691}],"con":true,"img":false}]}
{"op":"mcm","clk":"1362412152","pt":1588448735523,"mc":[{"id":"1.170370564","rc":[{"atb":[[1.13,6.7]],"id":8509691}],"con":true,"img":false}]}
{"op":"mcm","clk":"1362412165","pt":1588448737000,"mc":[{"id":"1.170370567","rc":[{"atb":[[1.23,0]],"id":8509691}],"con":true,"img":false}]}
{"op":"mcm","clk":"1362412179","pt":1588448738123,"mc":[{"id":"1.170370564","rc":[{"atb":[[1.17,444.65]],"id":8509691}],"con":true,"img":false}]}
{"op":"mcm","clk":"1362412180","pt":1588448738227,"mc":[{"id":"1.170370564","rc":[{"atb":[[1.17,177.3]],"id":8509691}],"con":true,"img":false}]}
{"op":"mcm","clk":"1362412184","pt":1588448738581,"mc":[{"id":"1.170370564","rc":[{"atb":[[1.09,1791.39]],"id":8509691}],"con":true,"img":false},{"id":"1.170370566","rc":[{"atb":[[1.08,435.07]],"id":8509691}],"con":true,"img":false}]}
{"op":"mcm","clk":"1362412198","pt":1588448740008,"mc":[{"id":"1.170370564","rc":[{"atb":[[1.18,177.3]],"id":8509691}],"con":true,"img":false}]}
{"op":"mcm","clk":"1362412203","pt":1588448740313,"mc":[{"id":"1.170370564","rc":[{"trd":[[1.18,55.24]],"ltp":1.18,"tv":55.24,"id":8509691},{"atb":[[1.18,149.68]],"id":8509691}],"con":true,"img":false}]}
{"op":"mcm","clk":"1362412209","pt":1588448740619,"mc":[{"id":"1.170370564","rc":[{"atb":[[1.18,178.83]],"id":8509691}],"con":true,"img":false}]}
{"op":"mcm","clk":"1362412222","pt":1588448741534,"mc":[{"id":"1.170370564","rc":[{"trd":[[1.18,155.24]],"ltp":1.18,"tv":155.24,"id":8509691},{"atb":[[1.18,128.83]],"id":8509691}],"con":true,"img":false}]}
{"op":"mcm","clk":"1362412226","pt":1588448742094,"mc":[{"id":"1.170370567","rc":[{"atb":[[1.2,2.62]],"id":8509691}],"con":true,"img":false}]}
{"op":"mcm","clk":"1362412248","pt":1588448744134,"mc":[{"id":"1.170370564","rc":[{"atb":[[1.15,295.21]],"id":8509691}],"con":true,"img":false}]}
{"op":"mcm","clk":"1362412255","pt":1588448744639,"mc":[{"id":"1.170370564","rc":[{"atb":[[1.01,5845.89]],"id":8509691}],"con":true,"img":false}]}
{"op":"mcm","clk":"1362412262","pt":1588448745199,"mc":[{"id":"1.170370564","rc":[{"atb":[[1.01,5842.73]],"id":8509691}],"con":true,"img":false}]}
{"op":"mcm","clk":"1362412266","pt":1588448745503,"mc":[{"id":"1.170370564","rc":[{"atl":[[8,12.41]],"id":9630572},{"atb":[[1.12,18.71]],"id":8509691}],"con":true,"img":false}]}
{"op":"mcm","clk":"1362412269","pt":1588448745910,"mc":[{"id":"1.170370564","rc":[{"atb":[[1.01,5842.69]],"id":8509691}],"con":true,"img":false}]}
{"op":"mcm","clk":"1362412294","pt":1588448748201,"mc":[{"id":"1.170370567","rc":[{"atb":[[1.2,0]],"id":8509691}],"con":true,"img":false}]}
{"op":"mcm","clk":"1362412297","pt":1588448748403,"mc":[{"id":"1.170370564","rc":[{"atl":[[1.21,177.3]],"id":8509691}],"con":true,"img":false}]}
{"op":"mcm","clk":"1362412319","pt":1588448749926,"mc":[{"id":"1.170370565","rc":[{"atb":[[2.02,46.73]],"id":11340557}],"con":true,"img":false}]}
{"op":"mcm","clk":"1362412321","pt":1588448750029,"mc":[{"id":"1.170370566","rc":[{"atl":[[1.9,8.86]],"id":8509691}],"con":true,"img":false}]}
{"op":"mcm","clk":"1362412330","pt":1588448750842,"mc":[{"id":"1.170370564","rc":[{"trd":[[1.18,169.25]],"ltp":1.18,"tv":169.25,"id":8509691},{"atb":[[1.18,121.83]],"id":8509691}],"con":true,"img":false}]}
{"op":"mcm","clk":"1362412333","pt":1588448751045,"mc":[{"id":"1.170370564","rc":[{"atb":[[1.17,177.34]],"id":8509691}],"con":true,"img":false}]}
{"op":"mcm","clk":"1362412336","pt":1588448751350,"mc":[{"id":"1.170370564","rc":[{"trd":[[7.8,37.22],[7,39.69],[6.6,21.78]],"ltp":7.8,"tv":98.69,"id":9630572},{"trd":[[1.15,316.38],[1.18,291.08],[1.17,227.31]],"ltp":1.15,"tv":834.77,"id":8509691},{"atb":[[1.18,0],[1.15,42.73],[1.17,0]],"id":8509691}],"con":true,"img":false}]}
{"op":"mcm","clk":"1362412339","pt":1588448751503,"mc":[{"id":"1.170370564","rc":[{"atb":[[6.6,10]],"id":9630572}],"con":true,"img":false}]}
{"op":"mcm","clk":"1362412347","pt":1588448752011,"mc":[{"id":"1.170370564","rc":[{"atb":[[1.15,0]],"id":8509691}],"con":true,"img":false}]}
{"op":"mcm","clk":"1362412361","pt":1588448753334,"mc":[{"id":"1.170370567","rc":[{"atb":[[1.16,2.62]],"id":8509691}],"con":true,"img":false}]}
{"op":"mcm","clk":"1362412365","pt":1588448753742,"mc":[{"id":"1.170370564","rc":[{"atb":[[1.09,1380.38]],"id":8509691}],"con":true,"img":false},{"id":"1.170370566","rc":[{"atb":[[1.08,0]],"id":8509691}],"con":true,"img":false}]}
{"op":"mcm","clk":"1362412374","pt":1588448754352,"mc":[{"id":"1.170370566","rc":[{"atb":[[1.05,0]],"id":8509691}],"con":true,"img":false}]}
{"op":"mcm","clk":"1362412394","pt":1588448756542,"mc":[{"id":"1.170370564","rc":[{"atl":[[1.16,250.3]],"id":8509691}],"con":true,"img":false}]}
{"op":"mcm","clk":"1362412434","pt":1588448759137,"mc":[{"id":"1.170370567","rc":[{"atb":[[1.16,0]],"id":8509691}],"con":true,"img":false}]}
{"op":"mcm","clk":"1362412439","pt":1588448759443,"mc":[{"id":"1.170370564","rc":[{"atb":[[1.08,2437.56]],"id":8509691}],"con":true,"img":false},{"id":"1.170370566","rc":[{"atb":[[1.06,504.15],[1.07,183.97]],"id":8509691}],"con":true,"img":false}]}
{"op":"mcm","clk":"1362412440","pt":1588448759545,"mc":[{"id":"1.170370564","rc":[{"atl":[[1.17,177.3]],"id":8509691}],"con":true,"img":false}]}
{"op":"mcm","clk":"1362412449","pt":1588448760562,"mc":[{"id":"1.170370564","rc":[{"atl":[[1.16,0]],"id":8509691}],"con":true,"img":false}]}
{"op":"mcm","clk":"1362412452","pt":1588448760714,"mc":[{"id":"1.170370566","rc":[{"atl":[[1.8,8.86]],"id":8509691}],"con":true,"img":false}]}
{"op":"mcm","clk":"1362412476","pt":1588448763017,"mc":[{"id":"1.170370564","rc":[{"atb":[[6.6,0]],"id":9630572}],"con":true,"img":false}]}
{"op":"mcm","clk":"1362412486","pt":1588448763733,"mc":[{"id":"1.170370564","rc":[{"atb":[[1.11,454.73]],"id":8509691}],"con":true,"img":false}]}
{"op":"mcm","clk":"1362412494","pt":1588448764347,"mc":[{"id":"1.170370567","rc":[{"atb":[[1.12,2.62]],"id":8509691}],"con":true,"img":false}]}
{"op":"mcm","clk":"1362412506","pt":1588448765417,"mc":[{"id":"1.170370564","rc":[{"atl":[[1.18,2]],"id":8509691}],"con":true,"img":false}]}
{"op":"mcm","clk":"1362412513","pt":1588448765724,"mc":[{"id":"1.170370564","rc":[{"trd":[[8,12.41]],"ltp":8.0,"tv":12.41,"id":9630572},{"atl":[[8,0]],"id":9630572},{"trd":[[1.14,156.97]],"ltp":1.14,"tv":156.97,"id":8509691},{"atb":[[1.14,0]],"id":8509691},{"atl":[[1.14,160.62]],"id":8509691}],"con":true,"img":false}]}
{"op":"mcm","clk":"1362412536","pt":1588448767659,"mc":[{"id":"1.170370565","rc":[{"atb":[[3,88.65]],"id":11340557}],"con":true,"img":false}]}
{"op":"mcm","clk":"1362412540","pt":1588448767965,"mc":[{"id":"1.170370564","rc":[{"atl":[[1000,3.19]],"id":8509691}],"con":true,"img":false}]}
{"op":"mcm","clk":"1362412542","pt":1588448768167,"mc":[{"id":"1.170370564","rc":[{"atb":[[8,10]],"id":9630572}],"con":true,"img":false}]}
{"op":"mcm","clk":"1362412556","pt":1588448769438,"mc":[{"id":"1.170370564","rc":[{"atl":[[1000,1.59]],"id":8509691}],"con":true,"img":false}]}
{"op":"mcm","clk":"1362412562","pt":1588448770047,"mc":[{"id":"1.170370564","rc":[{"atl":[[1000,0]],"id":8509691}],"con":true,"img":false}]}
{"op":"mcm","clk":"1362412576","pt":1588448771065,"mc":[{"id":"1.170370564","rc":[{"atl":[[1.4,516.71]],"id":8509691}],"con":true,"img":false}]}
{"op":"mcm","clk":"1362412580","pt":1588448771370,"mc":[{"id":"1.170370564","rc":[{"trd":[[1.14,196.97]],"ltp":1.14,"tv":196.97,"id":8509691},{"atl":[[1.14,140.62]],"id":8509691}],"con":true,"img":false}]}
{"op":"mcm","clk":"1362412583","pt":1588448771471,"mc":[{"id":"1.170370564","rc":[{"trd":[[1.14,197.68]],"ltp":1.14,"tv":197.68,"id":8509691},{"atl":[[1.14,140.27]],"id":8509691}],"con":true,"img":false}]}
{"op":"mcm","clk":"1362412602","pt":1588448773152,"mc":[{"id":"1.170370564","rc":[{"atl":[[1.14,340.27]],"id":8509691}],"con":true,"img":false}]}
{"op":"mcm","clk":"1362412617","pt":1588448774066,"mc":[{"id":"1.170370564","rc":[{"atb":[[1.01,8551.11]],"id":8509691}],"con":true,"img":false}]}
{"op":"mcm","clk":"1362412634","pt":1588448775136,"mc":[{"id":"1.170370564","rc":[{"atl":[[1.14,341.87]],"id":8509691}],"con":true,"img":false}]}
{"op":"mcm","clk":"1362412647","pt":1588448776457,"mc":[{"id":"1.170370566","rc":[{"atb":[[1.07,0]],"id":8509691}],"con":true,"img":false}]}
{"op":"mcm","clk":"1362412653","pt":1588448776966,"mc":[{"id":"1.170370564","rc":[{"trd":[[1.14,306.36]],"ltp":1.14,"tv":306.36,"id":8509691},{"atl":[[1.14,287.53]],"id":8509691}],"con":true,"img":false}]}
{"op":"mcm","clk":"1362412675","pt":1588448778848,"mc":[{"id":"1.170370564","rc":[{"trd":[[9.4,2.23],[8.8,0.85]],"ltp":9.4,"tv":3.08,"id":9630572},{"atb":[[9.4,15.52]],"id":9630572},{"trd":[[1.12,361.44],[1.13,588.54]],"ltp":1.12,"tv":949.98,"id":8509691},{"atb":[[1.12,0],[1.13,0]],"id":8509691}],"con":true,"img":false}]}
{"op":"mcm","clk":"1362412693","pt":1588448780173,"mc":[{"id":"1.170370566","rc":[{"atb":[[1.51,0]],"id":9630572}],"con":true,"img":false}]}
{"op":"mcm","clk":"1362412697","pt":1588448780376,"mc":[{"id":"1.170370564","rc":[{"atl":[[1.13,3328.38]],"id":8509691}],"con":true,"img":false}]}
{"op":"mcm","clk":"1362412702","pt":1588448780784,"mc":[{"id":"1.170370564","rc":[{"atb":[[1.08,2002.48]],"id":8509691}],"con":true,"img":false},{"id":"1.170370566","rc":[{"atb":[[1.06,0]],"id":8509691}],"con":true,"img":false}]}
{"op":"mcm","clk":"1362412711","pt":1588448781547,"mc":[{"id":"1.170370566","rc":[{"atb":[[1.05,183.97]],"id":8509691}],"con":true,"img":false}]}
{"op":"mcm","clk":"1362412720","pt":1588448782463,"mc":[{"id":"1.170370564","rc":[{"atb":[[1.11,345.21]],"id":8509691}],"con":true,"img":false}]}
{"op":"mcm","clk":"1362412731","pt":1588448783278,"mc":[{"id":"1.170370564","rc":[{"atb":[[1.1,0]],"id":8509691}],"con":true,"img":false}]}
{"op":"mcm","clk":"1362412738","pt":1588448784041,"mc":[{"id":"1.170370564","rc":[{"atb":[[1.02,5184.04]],"id":8509691}],"con":true,"img":false}]}
{"op":"mcm","clk":"1362412743","pt":1588448784347,"mc":[{"id":"1.170370564","rc":[{"atl":[[1.32,16.64]],"id":8509691}],"con":true,"img":false}]}
{"op":"mcm","clk":"1362412744","pt":1588448784449,"mc":[{"id":"1.170370564","rc":[{"atl":[[1.13,0]],"id":8509691}],"con":true,"img":false}]}
{"op":"mcm","clk":"1362412755","pt":1588448785263,"mc":[{"id":"1.170370566","rc":[{"atb":[[1.53,523.11]],"id":9630572}],"con":true,"img":false}]}
{"op":"mcm","clk":"1362412759","pt":1588448785365,"mc":[{"id":"1.170370564","rc":[{"atb":[[8,0]],"id":9630572}],"con":true,"img":false}]}
{"op":"mcm","clk":"1362412774","pt":1588448786690,"mc":[{"id":"1.170370564","rc":[{"trd":[[9.4,2.65]],"ltp":9.4,"tv":2.65,"id":9630572},{"atb":[[9.4,15.1]],"id":9630572},{"trd":[[1.12,364.94]],"ltp":1.12,"tv":364.94,"id":8509691}],"con":true,"img":false}]}
{"op":"mcm","clk":"1362412777","pt":1588448786792,"mc":[{"id":"1.170370564","rc":[{"atb":[[1.09,1791.39]],"id":8509691}],"con":true,"img":false},{"id":"1.170370566","rc":[{"atb":[[1.07,471.64]],"id":8509691}],"con":true,"img":false}]}
{"op":"mcm","clk":"1362412779","pt":1588448786996,"mc":[{"id":"1.170370564","rc":[{"trd":[[9.4,3.83]],"ltp":9.4,"tv":3.83,"id":9630572},{"atb":[[9.4,13.91]],"id":9630572},{"trd":[[1.12,374.94]],"ltp":1.12,"tv":374.94,"id":8509691}],"con":true,"img":false}]}
{"op":"mcm","clk":"1362412801","pt":1588448789291,"mc":[{"id":"1.170370564","rc":[{"atl":[[1.14,87.53]],"id":8509691}],"con":true,"img":false}]}
{"op":"mcm","clk":"1362412803","pt":1588448789596,"mc":[{"id":"1.170370564","rc":[{"trd":[[9.4,6.22]],"ltp":9.4,"tv":6.22,"id":9630572},{"atb":[[9.4,11.53]],"id":9630572},{"trd":[[1.12,394.94]],"ltp":1.12,"tv":394.94,"id":8509691},{"atl":[[1.14,1.59]],"id":8509691}],"con":true,"img":false}]}
{"op":"mcm","clk":"1362412812","pt":1588448790460,"mc":[{"id":"1.170370564","rc":[{"trd":[[10.5,10]],"ltp":10.5,"tv":10.0,"id":9630572},{"trd":[[1.11,350.15]],"ltp":1.11,"tv":350.15,"id":8509691},{"atb":[[1.11,250.62]],"id":8509691}],"con":true,"img":false}]}
{"op":"mcm","clk":"1362412821","pt":1588448791273,"mc":[{"id":"1.170370564","rc":[{"atb":[[1.03,2238.91]],"id":8509691}],"con":true,"img":false}]}
{"op":"mcm","clk":"1362412825","pt":1588448791781,"mc":[{"id":"1.170370564","rc":[{"trd":[[9.4,17.75]],"ltp":9.4,"tv":17.75,"id":9630572},{"atb":[[9.4,0]],"id":9630572},{"trd":[[1.12,491.74]],"ltp":1.12,"tv":491.74,"id":8509691},{"atb":[[1.12,50.36],[1.09,1380.38]],"id":8509691}],"con":true,"img":false},{"id":"1.170370566","rc":[{"atb":[[4,0]],"id":9630572},{"atb":[[1.07,0]],"id":8509691}],"con":true,"img":false}]}
{"op":"mcm","clk":"1362412827","pt":1588448791883,"mc":[{"id":"1.170370564","rc":[{"atb":[[1.12,227.66]],"id":8509691}],"con":true,"img":false}]}
{"op":"mcm","clk":"1362412832","pt":1588448792392,"mc":[{"id":"1.170370564","rc":[{"trd":[[1.14,309.56]],"ltp":1.14,"tv":309.56,"id":8509691},{"atb":[[1.14,38.39]],"id":8509691},{"atl":[[1.14,0]],"id":8509691}],"con":true,"img":false}]}
{"op":"mcm","clk":"1362412836","pt":1588448792697,"mc":[{"id":"1.170370564","rc":[{"trd":[[1.17,581.92]],"ltp":1.17,"tv":581.92,"id":8509691},{"atb":[[1.17,117.9]],"id":8509691},{"atl":[[1.17,0]],"id":8509691}],"con":true,"img":false}]}
{"op":"mcm","clk":"1362412842","pt":1588448793103,"mc":[{"id":"1.170370565","rc":[{"atb":[[2.02,0]],"id":11340557}],"con":true,"img":false}]}
{"op":"mcm","clk":"1362412856","pt":1588448794479,"mc":[{"id":"1.170370564","rc":[{"atb":[[1.17,0]],"id":8509691}],"con":true,"img":false}]}
{"op":"mcm","clk":"1362412860","pt":1588448794785,"mc":[{"id":"1.170370564","rc":[{"atl":[[9.4,20.84]],"id":9630572}],"con":true,"img":false}]}
{"op":"mcm","clk":"1362412862","pt":1588448794886,"mc":[{"id":"1.170370564","rc":[{"atl":[[9.4,0]],"id":9630572}],"con":true,"img":false}]}
{"op":"mcm","clk":"1362412864","pt":1588448795090,"mc":[{"id":"1.170370564","rc":[{"atl":[[1.18,0]],"id":8509691}],"con":true,"img":false}]}
{"op":"mcm","clk":"1362412869","pt":1588448795600,"mc":[{"id":"1.170370564","rc":[{"atl":[[1000,3.54]],"id":9630572},{"atb":[[1.12,247.66]],"id":8509691},{"atl":[[1.2,81.63]],"id":8509691}],"con":true,"img":false}]}
{"op":"mcm","clk":"1362412873","pt":1588448795805,"mc":[{"id":"1.170370564","rc":[{"atl":[[1000,1.88]],"id":9630572}],"con":true,"img":false}]}
{"op":"mcm","clk":"1362412875","pt":1588448795906,"mc":[{"id":"1.170370564","rc":[{"atl":[[1.21,0]],"id":8509691}],"con":true,"img":false}]}
{"op":"mcm","clk":"1362412877","pt":1588448796007,"mc":[{"id":"1.170370564","rc":[{"atl":[[1000,0]],"id":9630572}],"con":true,"img":false}]}
{"op":"mcm","clk":"1362412885","pt":1588448796979,"mc":[{"id":"1.170370564","rc":[{"atb":[[1.04,2984.53]],"id":8509691}],"con":true,"img":false}]}
{"op":"mcm","clk":"1362412890","pt":1588448797386,"mc":[{"id":"1.170370567","rc":[{"atb":[[2.3,79.98]],"id":9630572}],"con":true,"img":false}]}
{"op":"mcm","clk":"1362412895","pt":1588448797792,"mc":[{"id":"1.170370564","rc":[{"atb":[[1.11,611.64]],"id":8509691}],"con":true,"img":false},{"id":"1.170370566","rc":[{"atb":[[3,200.92]],"id":9630572},{"atb":[[1.11,361.02]],"id":8509691}],"con":true,"img":false}]}
{"op":"mcm","clk":"1362412899","pt":1588448797996,"mc":[{"id":"1.170370564","rc":[{"atl":[[1.18,175.8]],"id":8509691}],"con":true,"img":false}]}
{"op":"mcm","clk":"1362412900","pt":1588448798200,"mc":[{"id":"1.170370565","rc":[{"atb":[[3,93.46]],"id":11340557}],"con":true,"img":false}]}
{"op":"mcm","clk":"1362412910","pt":1588448799374,"mc":[{"id":"1.170370564","rc":[{"atl":[[1.17,182.41]],"id":8509691}],"con":true,"img":false}]}
{"op":"mcm","clk":"1362412919","pt":1588448800187,"mc":[{"id":"1.170370564","rc":[{"trd":[[1.14,313.56]],"ltp":1.14,"tv":313.56,"id":8509691},{"atb":[[1.14,36.39]],"id":8509691}],"con":true,"img":false}]}
{"op":"mcm","clk":"1362412923","pt":1588448800391,"mc":[{"id":"1.170370564","rc":[{"atb":[[1.01,8554.31]],"id":8509691}],"con":true,"img":false}]}
{"op":"mcm","clk":"1362412931","pt":1588448801105,"mc":[{"id":"1.170370564","rc":[{"atl":[[9.4,1.88]],"id":9630572},{"atb":[[1.01,8551.15]],"id":8509691}],"con":true,"img":false}]}
{"op":"mcm","clk":"1362412936","pt":1588448801409,"mc":[{"id":"1.170370564","rc":[{"atl":[[9.4,0]],"id":9630572}],"con":true,"img":false}]}
{"op":"mcm","clk":"1362412939","pt":1588448801717,"mc":[{"id":"1.170370564","rc":[{"atb":[[1.01,8551.11]],"id":8509691}],"con":true,"img":false}]}
{"op":"mcm","clk":"1362412952","pt":1588448802885,"mc":[{"id":"1.170370564","rc":[{"trd":[[1.17,936.53]],"ltp":1.17,"tv":936.53,"id":8509691},{"atl":[[1.17,5.1]],"id":8509691}],"con":true,"img":false}]}
{"op":"mcm","clk":"1362412955","pt":1588448803088,"mc":[{"id":"1.170370564","rc":[{"atl":[[1.18,0],[1.2,0]],"id":8509691}],"con":true,"img":false}]}
{"op":"mcm","clk":"1362412961","pt":1588448803699,"mc":[{"id":"1.170370564","rc":[{"atb":[[1.05,2502.53]],"id":8509691}],"con":true,"img":false}]}
{"op":"mcm","clk":"1362412972","pt":1588448805072,"mc":[{"id":"1.170370565","rc":[{"atb":[[3,88.65]],"id":11340557}],"con":true,"img":false}]}
{"op":"mcm","clk":"1362412994","pt":1588448806800,"mc":[{"id":"1.170370564","rc":[{"atb":[[1.12,247.7]],"id":8509691}],"con":true,"img":false}]}
{"op":"mcm","clk":"1362413002","pt":1588448807716,"mc":[{"id":"1.170370564","rc":[{"trd":[[1.17,938.39]],"ltp":1.17,"tv":938.39,"id":8509691},{"atl":[[1.17,4.17]],"id":8509691}],"con":true,"img":false}]}
{"op":"mcm","clk":"1362413011","pt":1588448808275,"mc":[{"id":"1.170370564","rc":[{"atl":[[1.16,263.28]],"id":8509691}],"con":true,"img":false}]}
{"op":"mcm","clk":"1362413016","pt":1588448808987,"mc":[{"id":"1.170370564","rc":[{"atb":[[1.1,52.89]],"id":8509691}],"con":true,"img":false}]}
{"op":"mcm","clk":"1362413019","pt":1588448809291,"mc":[{"id":"1.170370564","rc":[{"trd":[[1.16,59.28]],"ltp":1.16,"tv":59.28,"id":8509691},{"atl":[[1.16,248.88]],"id":8509691}],"con":true,"img":false}]}
{"op":"mcm","clk":"1362413022","pt":1588448809393,"mc":[{"id":"1.170370564","rc":[{"trd":[[1.16,66.28]],"ltp":1.16,"tv":66.28,"id":8509691},{"atl":[[1.16,245.38]],"id":8509691}],"con":true,"img":false}]}
{"op":"mcm","clk":"1362413024","pt":1588448809494,"mc":[{"id":"1.170370564","rc":[{"trd":[[1.16,420.89]],"ltp":1.16,"tv":420.89,"id":8509691},{"atl":[[1.16,68.07]],"id":8509691}],"con":true,"img":false}]}
{"op":"mcm","clk":"1362413025","pt":1588448809697,"mc":[{"id":"1.170370564","rc":[{"atl":[[1.19,19.5]],"id":8509691}],"con":true,"img":false}]}
{"op":"mcm","clk":"1362413029","pt":1588448810003,"mc":[{"id":"1.170370564","rc":[{"atb":[[1.06,2524.9]],"id":8509691}],"con":true,"img":false}]}
{"op":"mcm","clk":"1362413032","pt":1588448810206,"mc":[{"id":"1.170370565","rc":[{"atb":[[3.05,4.81]],"id":11340557}],"con":true,"img":false}]}
{"op":"mcm","clk":"1362413036","pt":1588448810716,"mc":[{"id":"1.170370564","rc":[{"atl":[[1.22,177.3]],"id":8509691}],"con":true,"img":false}]}
{"op":"mcm","clk":"1362413041","pt":1588448811019,"mc":[{"id":"1.170370564","rc":[{"trd":[[1.16,432.65]],"ltp":1.16,"tv":432.65,"id":8509691},{"atl":[[1.16,62.19]],"id":8509691}],"con":true,"img":false}]}
{"op":"mcm","clk":"1362413052","pt":1588448812391,"mc":[{"id":"1.170370564","rc":[{"atl":[[1.16,0]],"id":8509691}],"con":true,"img":false}]}
{"op":"mcm","clk":"1362413057","pt":1588448812900,"mc":[{"id":"1.170370564","rc":[{"atb":[[1.11,250.62]],"id":8509691},{"atl":[[1.4,27.28]],"id":8509691}],"con":true,"img":false},{"id":"1.170370566","rc":[{"atb":[[3,0]],"id":9630572},{"atb":[[1.11,0]],"id":8509691}],"con":true,"img":false}]}
{"op":"mcm","clk":"1362413058","pt":1588448813000,"mc":[{"id":"1.170370564","rc":[{"atl":[[1.23,0]],"id":8509691}],"con":true,"img":false}]}
{"op":"mcm","clk":"1362413076","pt":1588448814320,"mc":[{"id":"1.170370564","rc":[{"atb":[[1.12,70.4]],"id":8509691}],"con":true,"img":false}]}
{"op":"mcm","clk":"1362413088","pt":1588448815896,"mc":[{"id":"1.170370564","rc":[{"atl":[[1.22,0]],"id":8509691}],"con":true,"img":false}]}
{"op":"mcm","clk":"1362413099","pt":1588448816714,"mc":[{"id":"1.170370564","rc":[{"atl":[[1.16,15.99]],"id":8509691}],"con":true,"img":false}]}
{"op":"mcm","clk":"1362413108","pt":1588448817628,"mc":[{"id":"1.170370564","rc":[{"atl":[[1.18,61.14]],"id":8509691}],"con":true,"img":false}]}
{"op":"mcm","clk":"1362413110","pt":1588448817833,"mc":[{"id":"1.170370564","rc":[{"trd":[[1.16,439.05]],"ltp":1.16,"tv":439.05,"id":8509691},{"atl":[[1.16,12.79]],"id":8509691}],"con":true,"img":false}]}
{"op":"mcm","clk":"1362413113","pt":1588448818239,"mc":[{"id":"1.170370564","rc":[{"trd":[[1.16,439.75]],"ltp":1.16,"tv":439.75,"id":8509691},{"atl":[[1.16,12.44]],"id":8509691}],"con":true,"img":false}]}
{"op":"mcm","clk":"1362413116","pt":1588448818595,"mc":[{"id":"1.170370564","rc":[{"atb":[[1.15,10.51]],"id":8509691},{"atl":[[1.18,0]],"id":8509691}],"con":true,"img":false}]}
{"op":"mcm","clk":"1362413141","pt":1588448821496,"mc":[{"id":"1.170370564","rc":[{"atl":[[1.18,9]],"id":8509691}],"con":true,"img":false}]}
{"op":"mcm","clk":"1362413158","pt":1588448823851,"mc":[{"id":"1.170370564","rc":[{"trd":[[1.15,337.4]],"ltp":1.15,"tv":337.4,"id":8509691},{"atb":[[1.15,0]],"id":8509691},{"atl":[[1.15,52.22]],"id":8509691}],"con":true,"img":false}]}
{"op":"mcm","clk":"1362413184","pt":1588448826252,"mc":[{"id":"1.170370564","rc":[{"trd":[[1.15,337.61]],"ltp":1.15,"tv":337.61,"id":8509691},{"atl":[[1.15,52.11]],"id":8509691}],"con":true,"img":false}]}
{"op":"mcm","clk":"1362413198","pt":1588448827828,"mc":[{"id":"1.170370564","rc":[{"atb":[[1.01,8554.31]],"id":8509691}],"con":true,"img":false}]}
{"op":"mcm","clk":"1362413204","pt":1588448828437,"mc":[{"id":"1.170370564","rc":[{"atb":[[1.01,8551.15]],"id":8509691}],"con":true,"img":false}]}
{"op":"mcm","clk":"1362413207","pt":1588448828642,"mc":[{"id":"1.170370564","rc":[{"trd":[[1.15,377.61]],"ltp":1.15,"tv":377.61,"id":8509691},{"atl":[[1.15,32.11]],"id":8509691}],"con":true,"img":false}]}
{"op":"mcm","clk":"1362413209","pt":1588448828946,"mc":[{"id":"1.170370564","rc":[{"atl":[[1.19,0]],"id":8509691}],"con":true,"img":false}]}
{"op":"mcm","clk":"1362413211","pt":1588448829050,"mc":[{"id":"1.170370564","rc":[{"atb":[[1.01,8551.11]],"id":8509691}],"con":true,"img":false}]}
{"op":"mcm","clk":"1362413245","pt":1588448831946,"mc":[{"id":"1.170370564","rc":[{"atb":[[1.09,1791.39]],"id":8509691},{"atl":[[1.47,423.75]],"id":8509691}],"con":true,"img":false},{"id":"1.170370566","rc":[{"atb":[[3.25,196.92]],"id":9630572},{"atb":[[1.08,435.07]],"id":8509691}],"con":true,"img":false}]}
{"op":"mcm","clk":"1362413247","pt":1588448832050,"mc":[{"id":"1.170370567","rc":[{"atb":[[2.2,0]],"id":9630572}],"con":true,"img":false}]}
{"op":"mcm","clk":"1362413256","pt":1588448832969,"mc":[{"id":"1.170370564","rc":[{"trd":[[1.15,422.01]],"ltp":1.15,"tv":422.01,"id":8509691},{"atl":[[1.15,9.92]],"id":8509691}],"con":true,"img":false}]}
{"op":"mcm","clk":"1362413269","pt":1588448834035,"mc":[{"id":"1.170370564","rc":[{"trd":[[1.14,352.56]],"ltp":1.14,"tv":352.56,"id":8509691},{"atb":[[1.14,16.89]],"id":8509691}],"con":true,"img":false}]}
{"op":"mcm","clk":"1362413270","pt":1588448834134,"mc":[{"id":"1.170370564","rc":[{"trd":[[1.15,422.1]],"ltp":1.15,"tv":422.1,"id":8509691},{"atl":[[1.15,9.87]],"id":8509691}],"con":true,"img":false}]}
{"op":"mcm","clk":"1362413293","pt":1588448836071,"mc":[{"id":"1.170370564","rc":[{"trd":[[1.15,426.6]],"ltp":1.15,"tv":426.6,"id":8509691},{"atl":[[1.15,7.62]],"id":8509691}],"con":true,"img":false}]}
{"op":"mcm","clk":"1362413303","pt":1588448837445,"mc":[{"id":"1.170370564","rc":[{"trd":[[1.15,440.61]],"ltp":1.15,"tv":440.61,"id":8509691},{"atl":[[1.15,0.62]],"id":8509691}],"con":true,"img":false}]}
{"op":"mcm","clk":"1362413308","pt":1588448838364,"mc":[{"id":"1.170370566","rc":[{"atb":[[1.05,0]],"id":8509691}],"con":true,"img":false}]}
{"op":"mcm","clk":"1362413324","pt":1588448839632,"mc":[{"id":"1.170370564","rc":[{"trd":[[1.15,441.85]],"ltp":1.15,"tv":441.85,"id":8509691},{"atb":[[1.15,51.38]],"id":8509691},{"atl":[[1.15,0]],"id":8509691}],"con":true,"img":false}]}
{"op":"mcm","clk":"1362413325","pt":1588448839733,"mc":[{"id":"1.170370564","rc":[{"atb":[[1.15,101.38]],"id":8509691}],"con":true,"img":false}]}
{"op":"mcm","clk":"1362413340","pt":1588448840956,"mc":[{"id":"1.170370564","rc":[{"trd":[[1.15,641.29]],"ltp":1.15,"tv":641.29,"id":8509691},{"atb":[[1.15,1.66]],"id":8509691}],"con":true,"img":false}]}
{"op":"mcm","clk":"1362413345","pt":1588448841364,"mc":[{"id":"1.170370567","rc":[{"atb":[[3,88.65]],"id":9630572}],"con":true,"img":false}]}
{"op":"mcm","clk":"1362413347","pt":1588448841568,"mc":[{"id":"1.170370564","rc":[{"trd":[[1.14,386.35],[1.15,644.61]],"ltp":1.14,"tv":1030.96,"id":8509691},{"atb":[[1.14,0],[1.15,0]],"id":8509691},{"atl":[[1.14,11.45]],"id":8509691}],"con":true,"img":false}]}
{"op":"mcm","clk":"1362413354","pt":1588448842740,"mc":[{"id":"1.170370564","rc":[{"trd":[[8,14.04]],"ltp":8.0,"tv":14.04,"id":9630572},{"atl":[[7.6,98.37]],"id":9630572},{"trd":[[1.14,397.8]],"ltp":1.14,"tv":397.8,"id":8509691},{"atl":[[1.14,0]],"id":8509691}],"con":true,"img":false}]}
{"op":"mcm","clk":"1362413361","pt":1588448843451,"mc":[{"id":"1.170370566","rc":[{"atb":[[1.06,183.97]],"id":8509691}],"con":true,"img":false}]}
{"op":"mcm","clk":"1362413387","pt":1588448846048,"mc":[{"id":"1.170370564","rc":[{"atb":[[1.15,12.41]],"id":8509691}],"con":true,"img":false}]}
{"op":"mcm","clk":"1362413397","pt":1588448847269,"mc":[{"id":"1.170370564","rc":[{"atb":[[1.15,22.41]],"id":8509691}],"con":true,"img":false}]}
{"op":"mcm","clk":"1362413402","pt":1588448847779,"mc":[{"id":"1.170370564","rc":[{"atl":[[1.17,0]],"id":8509691}],"con":true,"img":false}]}
{"op":"mcm","clk":"1362413419","pt":1588448849761,"mc":[{"id":"1.170370564","rc":[{"atb":[[1.15,10]],"id":8509691}],"con":true,"img":false}]}
{"op":"mcm","clk":"1362413421","pt":1588448849966,"mc":[{"id":"1.170370564","rc":[{"trd":[[1.16,464.64]],"ltp":1.16,"tv":464.64,"id":8509691},{"atb":[[1.16,5.54]],"id":8509691},{"atl":[[1.16,0]],"id":8509691}],"con":true,"img":false}]}
{"op":"mcm","clk":"1362413435","pt":1588448852050,"mc":[{"id":"1.170370567","rc":[{"atb":[[1.12,0]],"id":8509691}],"con":true,"img":false}]}
{"op":"mcm","clk":"1362413444","pt":1588448853678,"mc":[{"id":"1.170370564","rc":[{"trd":[[1.16,473.14]],"ltp":1.16,"tv":473.14,"id":8509691},{"atb":[[1.16,1.3]],"id":8509691}],"con":true,"img":false}]}
{"op":"mcm","clk":"1362413451","pt":1588448854392,"mc":[{"id":"1.170370566","rc":[{"atb":[[1.01,2797.06]],"id":8509691}],"con":true,"img":false}]}
{"op":"mcm","clk":"1362413457","pt":1588448854898,"mc":[{"id":"1.170370564","rc":[{"atb":[[1.16,13.71]],"id":8509691}],"con":true,"img":false}]}
{"op":"mcm","clk":"1362413470","pt":1588448856986,"mc":[{"id":"1.170370564","rc":[{"atb":[[1.09,1380.38]],"id":8509691}],"con":true,"img":false},{"id":"1.170370566","rc":[{"atb":[[3.25,0]],"id":9630572},{"atb":[[1.08,0]],"id":8509691}],"con":true,"img":false}]}
{"op":"mcm","clk":"1362413473","pt":1588448857294,"mc":[{"id":"1.170370564","rc":[{"trd":[[1.18,309.08]],"ltp":1.18,"tv":309.08,"id":8509691},{"atb":[[1.2,286.21]],"id":8509691},{"atl":[[1.18,0]],"id":8509691}],"con":true,"img":false}]}
{"op":"mcm","clk":"1362413501","pt":1588448859999,"mc":[{"id":"1.170370564","rc":[{"atl":[[1.47,0]],"id":8509691}],"con":true,"img":false}]}
{"op":"mcm","clk":"1362413503","pt":1588448860100,"mc":[{"id":"1.170370564","rc":[{"atb":[[1.15,0]],"id":8509691}],"con":true,"img":false}]}
{"op":"mcm","clk":"1362413504","pt":1588448860202,"mc":[{"id":"1.170370564","rc":[{"atb":[[1.16,22.45]],"id":8509691}],"con":true,"img":false}]}
{"op":"mcm","clk":"1362413513","pt":1588448860967,"mc":[{"id":"1.170370564","rc":[{"atb":[[1.16,26.83]],"id":8509691}],"con":true,"img":false}]}
{"op":"mcm","clk":"1362413522","pt":1588448861881,"mc":[{"id":"1.170370564","rc":[{"trd":[[1.2,569.83]],"ltp":1.2,"tv":569.83,"id":8509691},{"atb":[[1.2,108.9]],"id":8509691}],"con":true,"img":false}]}
{"op":"mcm","clk":"1362413530","pt":1588448862495,"mc":[{"id":"1.170370564","rc":[{"atl":[[1.21,8.92]],"id":8509691}],"con":true,"img":false}]}
{"op":"mcm","clk":"1362413533","pt":1588448862698,"mc":[{"id":"1.170370564","rc":[{"trd":[[7.6,8.56]],"ltp":7.6,"tv":8.56,"id":9630572},{"atl":[[7.6,92.08]],"id":9630572},{"trd":[[1.15,686.17],[1.2,787.65],[1.16,526.8]],"ltp":1.15,"tv":2000.62,"id":8509691},{"atb":[[1.2,0],[1.16,0]],"id":8509691}],"con":true,"img":false}]}
{"op":"mcm","clk":"1362413539","pt":1588448863003,"mc":[{"id":"1.170370564","rc":[{"atb":[[1.08,2437.56]],"id":8509691}],"con":true,"img":false},{"id":"1.170370566","rc":[{"atb":[[3.6,197.42]],"id":9630572},{"atb":[[1.05,564.26]],"id":8509691}],"con":true,"img":false}]}
{"op":"mcm","clk":"1362413544","pt":1588448863971,"mc":[{"id":"1.170370564","rc":[{"atb":[[1.08,2002.48]],"id":8509691}],"con":true,"img":false},{"id":"1.170370566","rc":[{"atb":[[3.6,0]],"id":9630572},{"atb":[[1.05,0]],"id":8509691}],"con":true,"img":false}]}
{"op":"mcm","clk":"1362413552","pt":1588448864376,"mc":[{"id":"1.170370564","rc":[{"atl":[[7.6,0]],"id":9630572},{"atb":[[1.18,0.46]],"id":8509691}],"con":true,"img":false}]}
{"op":"mcm","clk":"1362413553","pt":1588448864477,"mc":[{"id":"1.170370566","rc":[{"atb":[[1.01,88.65]],"id":8509691}],"con":true,"img":false}]}
{"op":"mcm","clk":"1362413561","pt":1588448865092,"mc":[{"id":"1.170370564","rc":[{"atb":[[1.18,0]],"id":8509691},{"atl":[[1.13,27.1]],"id":8509691}],"con":true,"img":false}]}
{"op":"mcm","clk":"1362413567","pt":1588448865704,"mc":[{"id":"1.170370564","rc":[{"atl":[[1.3,0]],"id":8509691}],"con":true,"img":false}]}
{"op":"mcm","clk":"1362413580","pt":1588448866775,"mc":[{"id":"1.170370564","rc":[{"atl":[[1.19,6.24]],"id":8509691}],"con":true,"img":false}]}
{"op":"mcm","clk":"1362413583","pt":1588448866977,"mc":[{"id":"1.170370564","rc":[{"atl":[[1.21,184.76]],"id":8509691}],"con":true,"img":false}]}
{"op":"mcm","clk":"1362413598","pt":1588448868098,"mc":[{"id":"1.170370564","rc":[{"atl":[[1.21,292.77]],"id":8509691}],"con":true,"img":false}]}
{"op":"mcm","clk":"1362413604","pt":1588448868604,"mc":[{"id":"1.170370564","rc":[{"trd":[[1.21,317.32],[1.13,642.75],[1.19,22.56]],"ltp":1.21,"tv":982.62,"id":8509691},{"atl":[[1.21,148.82],[1.19,0],[1.13,0]],"id":8509691}],"con":true,"img":false}]}
{"op":"mcm","clk":"1362413607","pt":1588448869011,"mc":[{"id":"1.170370564","rc":[{"atl":[[1.23,10],[1.56,356.42]],"id":8509691}],"con":true,"img":false}]}
{"op":"mcm","clk":"1362413610","pt":1588448869217,"mc":[{"id":"1.170370564","rc":[{"trd":[[1.21,614.96]],"ltp":1.21,"tv":614.96,"id":8509691},{"atb":[[1.22,28.48]],"id":8509691},{"atl":[[1.21,0]],"id":8509691}],"con":true,"img":false}]}
{"op":"mcm","clk":"1362413617","pt":1588448869979,"mc":[{"id":"1.170370564","rc":[{"atb":[[1.14,331.27]],"id":8509691}],"con":true,"img":false},{"id":"1.170370566","rc":[{"atb":[[2.62,200.08]],"id":9630572},{"atb":[[1.18,290.01]],"id":8509691}],"con":true,"img":false}]}
{"op":"mcm","clk":"1362413630","pt":1588448870896,"mc":[{"id":"1.170370564","rc":[{"atb":[[1.1,643.32]],"id":8509691}],"con":true,"img":false}]}
{"op":"mcm","clk":"1362413637","pt":1588448871504,"mc":[{"id":"1.170370564","rc":[{"atl":[[8.6,130.51]],"id":9630572}],"con":true,"img":false}]}
{"op":"mcm","clk":"1362413640","pt":1588448871708,"mc":[{"id":"1.170370564","rc":[{"atl":[[8.6,0]],"id":9630572}],"con":true,"img":false}]}
{"op":"mcm","clk":"1362413642","pt":1588448871810,"mc":[{"id":"1.170370564","rc":[{"atb":[[1.13,590.42]],"id":8509691}],"con":true,"img":false}]}
{"op":"mcm","clk":"1362413648","pt":1588448872417,"mc":[{"id":"1.170370564","rc":[{"trd":[[1.24,380.39],[1.23,278.68]],"ltp":1.24,"tv":659.06,"id":8509691},{"atb":[[1.24,159.26]],"id":8509691},{"atl":[[1.23,0],[1.24,0]],"id":8509691}],"con":true,"img":false}]}
{"op":"mcm","clk":"1362413667","pt":1588448873894,"mc":[{"id":"1.170370564","rc":[{"atb":[[1.13,688.82]],"id":8509691}],"con":true,"img":false}]}
{"op":"mcm","clk":"1362413691","pt":1588448875979,"mc":[{"id":"1.170370566","rc":[{"atl":[[1.31,2.62]],"id":8509691}],"con":true,"img":false}]}
{"op":"mcm","clk":"1362413692","pt":1588448876084,"mc":[{"id":"1.170370564","rc":[{"atb":[[1.16,590.42]],"id":8509691}],"con":true,"img":false}]}
{"op":"mcm","clk":"1362413697","pt":1588448876894,"mc":[{"id":"1.170370564","rc":[{"atb":[[1.13,590.42]],"id":8509691}],"con":true,"img":false}]}
{"op":"mcm","clk":"1362413705","pt":1588448878216,"mc":[{"id":"1.170370564","rc":[{"atb":[[1.15,98.4]],"id":8509691}],"con":true,"img":false}]}
{"op":"mcm","clk":"1362413724","pt":1588448879489,"mc":[{"id":"1.170370564","rc":[{"atl":[[1.27,177.3]],"id":8509691}],"con":true,"img":false}]}
{"op":"mcm","clk":"1362413736","pt":1588448881985,"mc":[{"id":"1.170370564","rc":[{"atl":[[1.25,3.54]],"id":8509691}],"con":true,"img":false}]}
{"op":"mcm","clk":"1362413739","pt":1588448882804,"mc":[{"id":"1.170370564","rc":[{"atb":[[1.23,62.5]],"id":8509691}],"con":true,"img":false}]}
{"op":"mcm","clk":"1362413741","pt":1588448883317,"mc":[{"id":"1.170370564","rc":[{"atb":[[1.14,333.59]],"id":8509691}],"con":true,"img":false}]}
{"op":"mcm","clk":"1362413760","pt":1588448885918,"mc":[{"id":"1.170370564","rc":[{"trd":[[1.24,429.04]],"ltp":1.24,"tv":429.04,"id":8509691},{"atb":[[1.24,134.93]],"id":8509691}],"con":true,"img":false}]}
{"op":"mcm","clk":"1362413772","pt":1588448888307,"mc":[{"id":"1.170370564","rc":[{"trd":[[1.24,475.97]],"ltp":1.24,"tv":475.97,"id":8509691},{"atb":[[1.24,111.47]],"id":8509691}],"con":true,"img":false}]}
{"op":"mcm","clk":"1362413775","pt":1588448888917,"mc":[{"id":"1.170370564","rc":[{"trd":[[1.25,2998.53]],"ltp":1.25,"tv":2998.53,"id":8509691},{"atl":[[1.25,0]],"id":8509691}],"con":true,"img":false}]}
{"op":"mcm","clk":"1362413788","pt":1588448891206,"mc":[{"id":"1.170370564","rc":[{"trd":[[1.24,489.98]],"ltp":1.24,"tv":489.98,"id":8509691},{"atb":[[1.24,104.46]],"id":8509691}],"con":true,"img":false}]}
{"op":"mcm","clk":"1362413790","pt":1588448891714,"mc":[{"id":"1.170370564","rc":[{"atl":[[1.36,0]],"id":8509691}],"con":true,"img":false}]}
{"op":"mcm","clk":"1362413795","pt":1588448892881,"mc":[{"id":"1.170370566","rc":[{"atb":[[1.53,0]],"id":9630572}],"con":true,"img":false}]}
{"op":"mcm","clk":"1362413796","pt":1588448893185,"mc":[{"id":"1.170370566","rc":[{"atb":[[1.19,97.58]],"id":8509691}],"con":true,"img":false}]}
{"op":"mcm","clk":"1362413798","pt":1588448893287,"mc":[{"id":"1.170370564","rc":[{"atb":[[1.17,98.4]],"id":8509691}],"con":true,"img":false}]}
{"op":"mcm","clk":"1362413799","pt":1588448893491,"mc":[{"id":"1.170370564","rc":[{"trd":[[1.24,589.98]],"ltp":1.24,"tv":589.98,"id":8509691},{"atb":[[1.24,54.46]],"id":8509691}],"con":true,"img":false}]}
{"op":"mcm","clk":"1362413802","pt":1588448893795,"mc":[{"id":"1.170370564","rc":[{"trd":[[1.24,614.5]],"ltp":1.24,"tv":614.5,"id":8509691},{"atb":[[1.24,42.2]],"id":8509691}],"con":true,"img":false}]}
{"op":"mcm","clk":"1362413811","pt":1588448894507,"mc":[{"id":"1.170370566","rc":[{"atb":[[1.2,0]],"id":9630572}],"con":true,"img":false}]}
{"op":"mcm","clk":"1362413814","pt":1588448895218,"mc":[{"id":"1.170370564","rc":[{"atb":[[1.15,0]],"id":8509691}],"con":true,"img":false}]}
{"op":"mcm","clk":"1362413817","pt":1588448895573,"mc":[{"id":"1.170370564","rc":[{"atb":[[1.15,16.13]],"id":8509691}],"con":true,"img":false}]}
{"op":"mcm","clk":"1362413823","pt":1588448896795,"mc":[{"id":"1.170370564","rc":[{"atl":[[1.31,47]],"id":8509691}],"con":true,"img":false}]}
{"op":"mcm","clk":"1362413827","pt":1588448897303,"mc":[{"id":"1.170370564","rc":[{"trd":[[1.24,640.5]],"ltp":1.24,"tv":640.5,"id":8509691},{"atb":[[1.24,29.21]],"id":8509691}],"con":true,"img":false}]}
{"op":"mcm","clk":"1362413828","pt":1588448897608,"mc":[{"id":"1.170370566","rc":[{"atb":[[1.06,0]],"id":8509691}],"con":true,"img":false}]}
{"op":"mcm","clk":"1362413832","pt":1588448897913,"mc":[{"id":"1.170370564","rc":[{"trd":[[1.24,654.5]],"ltp":1.24,"tv":654.5,"id":8509691},{"atb":[[1.24,22.2]],"id":8509691}],"con":true,"img":false}]}
{"op":"mcm","clk":"1362413834","pt":1588448898524,"mc":[{"id":"1.170370564","rc":[{"trd":[[1.24,673.3]],"ltp":1.24,"tv":673.3,"id":8509691},{"atb":[[1.24,12.81]],"id":8509691}],"con":true,"img":false}]}
{"op":"mcm","clk":"1362413842","pt":1588448899998,"mc":[{"id":"1.170370564","rc":[{"trd":[[1.22,710.24],[1.24,698.92],[1.23,403.68]],"ltp":1.22,"tv":1812.84,"id":8509691},{"atb":[[1.23,0],[1.22,3.79],[1.24,0]],"id":8509691}],"con":true,"img":false}]}
{"op":"mcm","clk":"1362413850","pt":1588448901523,"mc":[{"id":"1.170370564","rc":[{"trd":[[1.27,3736.46]],"ltp":1.27,"tv":3736.46,"id":8509691},{"atl":[[1.27,176.12]],"id":8509691}],"con":true,"img":false}]}
{"op":"mcm","clk":"1362413855","pt":1588448901982,"mc":[{"id":"1.170370564","rc":[{"atl":[[1.24,2.62]],"id":8509691}],"con":true,"img":false}]}
{"op":"mcm","clk":"1362413864","pt":1588448903914,"mc":[{"id":"1.170370564","rc":[{"atl":[[1.3,4.43]],"id":8509691}],"con":true,"img":false}]}
{"op":"mcm","clk":"1362413865","pt":1588448904117,"mc":[{"id":"1.170370564","rc":[{"atb":[[1.1,647.69]],"id":8509691}],"con":true,"img":false}]}
{"op":"mcm","clk":"1362413866","pt":1588448904218,"mc":[{"id":"1.170370564","rc":[{"atl":[[1.32,32.64]],"id":8509691}],"con":true,"img":false}]}
{"op":"mcm","clk":"1362413869","pt":1588448904625,"mc":[{"id":"1.170370564","rc":[{"atl":[[1.24,32.62]],"id":8509691}],"con":true,"img":false}]}
{"op":"mcm","clk":"1362413876","pt":1588448906711,"mc":[{"id":"1.170370564","rc":[{"atl":[[1.3,19]],"id":8509691}],"con":true,"img":false}]}
{"op":"mcm","clk":"1362413882","pt":1588448907527,"mc":[{"id":"1.170370564","rc":[{"trd":[[4.7,231.69],[5.1,10.55]],"ltp":4.7,"tv":242.24,"id":9630572},{"atl":[[4.7,44.48]],"id":9630572},{"trd":[[1.27,3912.59],[1.24,731.54]],"ltp":1.27,"tv":4644.13,"id":8509691},{"atl":[[1.27,0],[1.24,0]],"id":8509691}],"con":true,"img":false}]}
{"op":"mcm","clk":"1362413884","pt":1588448907730,"mc":[{"id":"1.170370564","rc":[{"atl":[[1.31,50]],"id":8509691}],"con":true,"img":false}]}
{"op":"mcm","clk":"1362413920","pt":1588448913840,"mc":[{"id":"1.170370564","rc":[{"atb":[[1.16,0]],"id":8509691}],"con":true,"img":false}]}
{"op":"mcm","clk":"1362413921","pt":1588448913940,"mc":[{"id":"1.170370564","rc":[{"atb":[[1.18,50]],"id":8509691}],"con":true,"img":false}]}
{"op":"mcm","clk":"1362413922","pt":1588448914044,"mc":[{"id":"1.170370564","rc":[{"trd":[[4.7,276.17]],"ltp":4.7,"tv":276.17,"id":9630572},{"atl":[[4.7,0]],"id":9630572},{"trd":[[1.27,4077.2]],"ltp":1.27,"tv":4077.2,"id":8509691},{"atl":[[1.27,12.69]],"id":8509691}],"con":true,"img":false}]}
{"op":"mcm","clk":"1362413927","pt":1588448914398,"mc":[{"id":"1.170370564","rc":[{"atl":[[1.24,13]],"id":8509691}],"con":true,"img":false}]}
{"op":"mcm","clk":"1362413935","pt":1588448916233,"mc":[{"id":"1.170370564","rc":[{"atb":[[1.17,0]],"id":8509691}],"con":true,"img":false}]}
{"op":"mcm","clk":"1362413941","pt":1588448917303,"mc":[{"id":"1.170370564","rc":[{"atl":[[1.27,14.46]],"id":8509691}],"con":true,"img":false}]}
{"op":"mcm","clk":"1362413943","pt":1588448917814,"mc":[{"id":"1.170370564","rc":[{"trd":[[1.24,757.54]],"ltp":1.24,"tv":757.54,"id":8509691},{"atb":[[1.24,164.3]],"id":8509691},{"atl":[[1.24,0]],"id":8509691}],"con":true,"img":false}]}
{"op":"mcm","clk":"1362413954","pt":1588448920005,"mc":[{"id":"1.170370564","rc":[{"atl":[[1.35,5.31]],"id":8509691}],"con":true,"img":false}]}
{"op":"mcm","clk":"1362413956","pt":1588448920106,"mc":[{"id":"1.170370564","rc":[{"atb":[[1.24,341.61]],"id":8509691}],"con":true,"img":false}]}
{"op":"mcm","clk":"1362413959","pt":1588448920819,"mc":[{"id":"1.170370564","rc":[{"atl":[[1.27,16.46]],"id":8509691}],"con":true,"img":false}]}
{"op":"mcm","clk":"1362413962","pt":1588448921736,"mc":[{"id":"1.170370565","rc":[{"atb":[[24,3]],"id":11269555}],"con":true,"img":false}]}
{"op":"mcm","clk":"1362413966","pt":1588448922652,"mc":[{"id":"1.170370564","rc":[{"atb":[[1.15,114.53]],"id":8509691}],"con":true,"img":false}]}
{"op":"mcm","clk":"1362413979","pt":1588448925150,"mc":[{"id":"1.170370565","rc":[{"atb":[[24,0]],"id":11269555}],"con":true,"img":false}]}
{"op":"mcm","clk":"1362414005","pt":1588448929778,"mc":[{"id":"1.170370564","rc":[{"atl":[[1.27,14.46]],"id":8509691}],"con":true,"img":false}]}
{"op":"mcm","clk":"1362414010","pt":1588448931055,"mc":[{"id":"1.170370567","rc":[{"atb":[[3,0]],"id":9630572}],"con":true,"img":false}]}
{"op":"mcm","clk":"1362414028","pt":1588448934256,"mc":[{"id":"1.170370564","rc":[{"atl":[[1.4,33.49]],"id":8509691}],"con":true,"img":false}]}
{"op":"mcm","clk":"1362414047","pt":1588448936849,"mc":[{"id":"1.170370564","rc":[{"trd":[[1.24,773.54]],"ltp":1.24,"tv":773.54,"id":8509691},{"atb":[[1.24,333.61]],"id":8509691}],"con":true,"img":false}]}
{"op":"mcm","clk":"1362414050","pt":1588448937460,"mc":[{"id":"1.170370564","rc":[{"atl":[[1.27,32.19]],"id":8509691}],"con":true,"img":false}]}
{"op":"mcm","clk":"1362414052","pt":1588448938067,"mc":[{"id":"1.170370564","rc":[{"atl":[[1.28,177.3]],"id":8509691}],"con":true,"img":false}]}
{"op":"mcm","clk":"1362414078","pt":1588448940764,"mc":[{"id":"1.170370564","rc":[{"trd":[[1.24,1299.07]],"ltp":1.24,"tv":1299.07,"id":8509691},{"atb":[[1.24,70.85]],"id":8509691}],"con":true,"img":false}]}
{"op":"mcm","clk":"1362414082","pt":1588448941271,"mc":[{"id":"1.170370567","rc":[{"atb":[[2.5,48.75]],"id":9630572}],"con":true,"img":false}]}
{"op":"mcm","clk":"1362414108","pt":1588448948201,"mc":[{"id":"1.170370564","rc":[{"atl":[[1.27,209.5]],"id":8509691}],"con":true,"img":false}]}
{"op":"mcm","clk":"1362414113","pt":1588448948557,"mc":[{"id":"1.170370564","rc":[{"trd":[[1.24,1387.07]],"ltp":1.24,"tv":1387.07,"id":8509691},{"atb":[[1.24,26.85]],"id":8509691}],"con":true,"img":false}]}
{"op":"mcm","clk":"1362414153","pt":1588448952981,"mc":[{"id":"1.170370565","rc":[{"atl":[[24,3.93]],"id":11269555}],"con":true,"img":false}]}
{"op":"mcm","clk":"1362414159","pt":1588448953387,"mc":[{"id":"1.170370564","rc":[{"atl":[[1.28,0]],"id":8509691}],"con":true,"img":false}]}
{"op":"mcm","clk":"1362414167","pt":1588448955270,"mc":[{"id":"1.170370564","rc":[{"trd":[[1.24,1393.15]],"ltp":1.24,"tv":1393.15,"id":8509691},{"atb":[[1.24,23.81]],"id":8509691}],"con":true,"img":false}]}
{"op":"mcm","clk":"1362414177","pt":1588448957911,"mc":[{"id":"1.170370564","rc":[{"trd":[[1.24,1396.06]],"ltp":1.24,"tv":1396.06,"id":8509691},{"atb":[[1.24,22.35]],"id":8509691},{"atl":[[1.26,10]],"id":8509691}],"con":true,"img":false}]}
{"op":"mcm","clk":"1362414182","pt":1588448958876,"mc":[{"id":"1.170370564","rc":[{"atl":[[1.26,187.3]],"id":8509691}],"con":true,"img":false}]}
{"op":"mcm","clk":"1362414195","pt":1588448960706,"mc":[{"id":"1.170370564","rc":[{"atl":[[1.27,191.77]],"id":8509691}],"con":true,"img":false}]}
{"op":"mcm","clk":"1362414205","pt":1588448962282,"mc":[{"id":"1.170370564","rc":[{"atb":[[1.22,13.79]],"id":8509691}],"con":true,"img":false}]}
{"op":"mcm","clk":"1362414209","pt":1588448963605,"mc":[{"id":"1.170370564","rc":[{"atl":[[1.45,7.09]],"id":8509691}],"con":true,"img":false}]}
{"op":"mcm","clk":"1362414217","pt":1588448965130,"mc":[{"id":"1.170370564","rc":[{"trd":[[1.24,1433.29],[1.26,2405]],"ltp":1.24,"tv":3838.29,"id":8509691},{"atb":[[1.24,3.74]],"id":8509691},{"atl":[[1.26,187.26]],"id":8509691}],"con":true,"img":false}]}
{"op":"mcm","clk":"1362414220","pt":1588448965790,"mc":[{"id":"1.170370564","rc":[{"trd":[[1.24,1440.78]],"ltp":1.24,"tv":1440.78,"id":8509691},{"atb":[[1.24,0]],"id":8509691},{"atl":[[1.24,13.98]],"id":8509691}],"con":true,"img":false}]}
{"op":"mcm","clk":"1362414224","pt":1588448966505,"mc":[{"id":"1.170370564","rc":[{"atl":[[1.25,240]],"id":8509691}],"con":true,"img":false}]}
{"op":"mcm","clk":"1362414249","pt":1588448972909,"mc":[{"id":"1.170370564","rc":[{"atb":[[1.21,10]],"id":8509691}],"con":true,"img":false}]}
{"op":"mcm","clk":"1362414253","pt":1588448973925,"mc":[{"id":"1.170370564","rc":[{"trd":[[1.25,3258.55],[1.24,1468.75]],"ltp":1.25,"tv":4727.3,"id":8509691},{"atl":[[1.25,109.99],[1.24,0]],"id":8509691}],"con":true,"img":false}]}
{"op":"mcm","clk":"1362414269","pt":1588448976617,"mc":[{"id":"1.170370564","rc":[{"atl":[[1.25,0]],"id":8509691}],"con":true,"img":false},{"id":"1.170370566","rc":[{"trd":[[1.19,195.16]],"ltp":1.19,"tv":195.16,"id":8509691},{"atb":[[1.19,0]],"id":8509691},{"atl":[[1.19,52.42]],"id":8509691}],"con":true,"img":false}]}
{"op":"mcm","clk":"1362414285","pt":1588448980024,"mc":[{"id":"1.170370564","rc":[{"atl":[[1.26,9.96]],"id":8509691}],"con":true,"img":false}]}
{"op":"mcm","clk":"1362414291","pt":1588448980635,"mc":[{"id":"1.170370564","rc":[{"atl":[[1.27,1.77]],"id":8509691}],"con":true,"img":false}]}
{"op":"mcm","clk":"1362414293","pt":1588448980737,"mc":[{"id":"1.170370564","rc":[{"trd":[[1.26,2424.91]],"ltp":1.26,"tv":2424.91,"id":8509691},{"atb":[[1.26,285.25]],"id":8509691},{"atl":[[1.26,0]],"id":8509691}],"con":true,"img":false}]}
{"op":"mcm","clk":"1362414309","pt":1588448982669,"mc":[{"id":"1.170370566","rc":[{"trd":[[1.19,241.48]],"ltp":1.19,"tv":241.48,"id":8509691},{"atl":[[1.19,29.26]],"id":8509691}],"con":true,"img":false}]}
{"op":"mcm","clk":"1362414310","pt":1588448982721,"mc":[{"id":"1.170370564","rc":[{"atb":[[1.12,20.03]],"id":8509691}],"con":true,"img":false}]}
{"op":"mcm","clk":"1362414313","pt":1588448983127,"mc":[{"id":"1.170370564","rc":[{"atb":[[1.26,525.25]],"id":8509691}],"con":true,"img":false}]}
{"op":"mcm","clk":"1362414314","pt":1588448983332,"mc":[{"id":"1.170370564","rc":[{"atb":[[1.26,240]],"id":8509691}],"con":true,"img":false}]}
{"op":"mcm","clk":"1362414317","pt":1588448983536,"mc":[{"id":"1.170370566","rc":[{"trd":[[6.2,5.61]],"ltp":6.2,"tv":5.61,"id":9630572},{"atl":[[6.2,4.44]],"id":9630572},{"trd":[[1.19,270.74]],"ltp":1.19,"tv":270.74,"id":8509691},{"atl":[[1.19,0]],"id":8509691}],"con":true,"img":false}]}
{"op":"mcm","clk":"1362414319","pt":1588448983943,"mc":[{"id":"1.170370566","rc":[{"atl":[[6.2,0]],"id":9630572}],"con":true,"img":false}]}
{"op":"mcm","clk":"1362414325","pt":1588448984452,"mc":[{"id":"1.170370564","rc":[{"atb":[[1.2,10]],"id":8509691}],"con":true,"img":false}]}
{"op":"mcm","clk":"1362414326","pt":1588448984964,"mc":[{"id":"1.170370564","rc":[{"atl":[[1.35,7.31]],"id":8509691}],"con":true,"img":false}]}
{"op":"mcm","clk":"1362414331","pt":1588448985935,"mc":[{"id":"1.170370564","rc":[{"atl":[[1.27,11.64]],"id":8509691}],"con":true,"img":false}]}
{"op":"mcm","clk":"1362414332","pt":1588448986339,"mc":[{"id":"1.170370564","rc":[{"atb":[[1.26,0]],"id":8509691}],"con":true,"img":false}]}
